File: Experimental_Data/Fig3B/Lifetime_160Oe.dat
[Header]
; MPMS3 Data File (default extension .dat)
; Copyright (c) 2007, Quantum Design, Inc. All rights reserved.
TITLE,260Oe
FILEOPENTIME,3754638359.52831,12/22/2018,11:05 am
BYAPP,SQUID AC,0.9.1.0
INFO,MPMS3 Measurement Release 1.1.16 Build 347, MultiVu Release 2.3.3.2,APPNAME
INFO,0,MOMENT_UNITS
INFO,CoIINO3,SAMPLE_MATERIAL
INFO,40 Hours Pumped Turbo,SAMPLE_COMMENT
INFO,,SAMPLE_MASS
INFO,,SAMPLE_VOLUME
INFO,,SAMPLE_MOLECULAR_WEIGHT
INFO,,SAMPLE_SIZE
INFO,,SAMPLE_SHAPE
INFO,Brass,SAMPLE_HOLDER
INFO,Standard,SAMPLE_HOLDER_DETAIL
INFO,65.37,SAMPLE_OFFSET
DATATYPE,COMMENT,1
DATATYPE,TIME,2
STARTUPAXIS,X,2
STARTUPAXIS,Y1,5
FIELDGROUP, VSM,2,3,4,5,6,8,9,10,11,14,15
FIELDGROUP, DC, 2,3,4,14,56,57,58,59,60,61,62,63,64,65,66,67,68,69
FIELDGROUP, AC, 2,3,4,11,16,17,18,19,20,21,22,23,24,25,26,27,28,29,30
STARTUPGROUP, All
[Data]
Comment,Time Stamp (sec),Temperature (K),Magnetic Field (Oe),Moment (emu),M. Std. Err. (emu),Transport Action,Averaging Time (sec),Frequency (Hz),Peak Amplitude (mm),Center Position (mm),Lockin Signal' (V),Lockin Signal (V),Range,M. Quad. Signal (emu),AC Moment (emu),AC M. Std Err. (emu),AC Phase (deg),AC Phase Std. Err. (deg),AC Susceptibility (emu/Oe),AC Suscept. Std Err. (emu/Oe),AC X' (emu/Oe),AC X' Std Err. (emu/Oe),AC X'' (emu/Oe),AC X'' Std Err. (emu/Oe),AC Drive (Oe),AC Frequency (Hz),AC Averaging Time (sec),AC Cycles,AC Range,AC Measure Type,AC Signal' (V),AC Signal'' (V),AC Trim Coil Ratio,AC Trim Coil Phase,Min. Temperature (K),Max. Temperature (K),Min. Field (Oe),Max. Field (Oe),Mass (grams),Motor Lag (deg),Pressure (Torr),Measure Count,Measurement Number,SQUID Status (code),Motor Status (code),Measure Status (code),Motor Current (amps),Motor Temp. (C),Temp. Status (code),Field Status (code),Chamber Status (code),Chamber Temp (K),Redirection State,Average Temp (K),Rotation Angle (deg),Rotator state,DC Moment Fixed Ctr (emu),DC Moment Err Fixed Ctr (emu),DC Moment Free Ctr (emu),DC Moment Err Free Ctr (emu),DC Fixed Fit,DC Free Fit,DC Calculated Center (mm),DC Calculated Center Err (mm),DC Scan Length (mm),DC Scan Time (s),DC Number of Points,DC Squid Drift,DC Min V (V),DC Max V (V),DC Scans per Measure,Map 01,Map 02,Map 03,Map 04,Map 05,Map 06,Map 07,Map 08,Map 09,Map 10,Map 11,Map 12,Map 13,Map 14,Map 15,Map 16
,3754638363.97717,49.0945682525635,159.99365234375,,,5,,,,-2.40999995730817,,,,,0.000687965093507498,1.27853449504331E-7,0.0958010424560127,5.16515387201131E-5,0.000687875337421239,1.27836768970172E-7,0.000687874375864653,1.22833010800647E-7,1.15015703178705E-6,3.54159703859911E-8,1.00013048307066,10.005763053894,2,20,10,5,2.25013899120346,0.201676443767908,0.0404026173055172,172.741912841797,49.0934066772461,49.1078453063965,159.99365234375,159.99365234375,,,20.8459205627441,0,1,,,,,,1,1,1,49.0953521728516,0,49.0981369018555,,,,,,,,,,,,,,,,,,,,,,,,,,,,,,,,,
,3754638569.12278,48.9047622680664,159.99365234375,,,5,,,,-2.43999995291233,,,,,0.000702413048417043,5.39861898148853E-8,0.0345914235366198,4.04501056183419E-5,0.00070232122295832,5.39791322770796E-8,0.000702321094962028,4.59057712510511E-8,4.24015339571441E-7,2.83973042247433E-8,1.00013074566982,10.005763053894,2,20,10,5,2.29761275659649,0.20345818065085,0.0404026173055172,172.741912841797,48.8993453979492,48.9427032470703,159.99365234375,159.99365234375,,,22.3836231231689,0,1,,,,,,1,1,1,48.907299041748,0,48.9209619409898,,,,,,,,,,,,,,,,,,,,,,,,,,,,,,,,,
,3754638774.02734,48.9992084503174,159.99365234375,,,5,,,,-2.43999995291233,,,,,0.000707659046116773,5.36680629795251E-8,0.0304664231645972,3.65434366377762E-5,0.000707566723698006,5.36610613515349E-8,0.000707566623666901,4.70278898130108E-8,3.7624108422481E-7,2.58435114701643E-8,1.00013047874593,10.005763053894,2,20,10,5,2.31478734788874,0.204810681044287,0.0404026173055172,172.741912841797,48.9983520507812,48.9997673034668,159.99365234375,159.99365234375,,,22.3859176635742,0,1,,,,,,1,1,1,48.9990577697754,0,48.9991931915283,,,,,,,,,,,,,,,,,,,,,,,,,,,,,,,,,
,3754638977.66272,49.0001010894775,159.99365234375,,,5,,,,-2.43999995291233,,,,,0.000709590371289987,3.99919733395418E-8,0.0284565890694397,4.38789124419757E-5,0.000709497849320438,3.99867588717456E-8,0.000709497761813699,2.50970916162605E-8,3.52380019702938E-7,3.1129999638165E-8,1.00013040486259,10.005763053894,2,20,10,5,2.32111200984677,0.20528822159569,0.0404026173055172,172.741912841797,48.99951171875,49.0004997253418,159.99365234375,159.99365234375,,,22.4169139862061,0,1,,,,,,1,1,1,48.9998321533203,0,48.9999968584846,,,,,,,,,,,,,,,,,,,,,,,,,,,,,,,,,
,3754639181.29518,48.9996147155762,159.99365234375,,,5,,,,-2.43999995291233,,,,,0.000711624131486136,7.3312716426677E-8,0.0266074138121049,8.96717897305203E-5,0.0007115312785473,7.33031505605504E-8,0.000711531201824569,3.60894875959508E-8,3.30425847226266E-7,6.38036109257496E-8,1.00013049733952,10.005763053894,2,20,10,5,2.32777120286028,0.205801472073415,0.0404026173055172,172.741912841797,48.9992561340332,49.0004425048828,159.99365234375,159.99365234375,,,22.4225635528564,0,1,,,,,,1,1,1,48.9998779296875,0,48.9998738905963,,,,,,,,,,,,,,,,,,,,,,,,,,,,,,,,,
,3754639386.21613,49.000467300415,159.99365234375,,,5,,,,-2.43999995291233,,,,,0.000712006323792415,8.13464914558804E-8,0.0292843736191246,5.55953886645306E-5,0.000711913474881576,8.13358834979454E-8,0.000711913381894237,7.10674715843057E-8,3.63865182608593E-7,3.95593279392516E-8,1.00013042162301,10.005763053894,2,20,10,5,2.32901175705996,0.206020816164589,0.0404026173055172,172.741912841797,49.0001525878906,49.0009078979492,159.99365234375,159.99365234375,,,22.4796123504639,0,1,,,,,,1,1,1,49.0002517700195,0,49.0005421357996,,,,,,,,,,,,,,,,,,,,,,,,,,,,,,,,,
,3754639593.86782,48.9995613098145,159.99365234375,,,5,,,,-2.43999995291233,,,,,0.000712949224495922,6.90850203918341E-8,0.0293240181083503,8.06742042437426E-5,0.000712856200400692,6.90760063256214E-8,0.000712856107037946,3.82672991729487E-8,3.64840262131985E-7,5.75074644190242E-8,1.00013049489529,10.005763053894,2,20,10,5,2.33209589397912,0.206295263631187,0.0404026173055172,172.741912841797,48.9988021850586,48.9999771118164,159.99365234375,159.99365234375,,,22.5255298614502,0,1,,,,,,1,1,1,48.9995002746582,0,48.9996091057273,,,,,,,,,,,,,,,,,,,,,,,,,,,,,,,,,
,3754639797.4626,49.0014629364014,159.99365234375,,,5,,,,-2.43999995291233,,,,,0.000713458738371955,6.30635608722591E-8,0.026439192011023,5.86750876689266E-5,0.000713365667557574,6.30553342199631E-8,0.000713365591606609,4.7165342115776E-8,3.29183254849671E-7,4.18497990042134E-8,1.00013046719041,10.005763053894,2,20,10,5,2.33377293372595,0.206325182407706,0.0404026173055172,172.741912841797,48.9990768432617,49.0022087097168,159.99365234375,159.99365234375,,,22.598539352417,0,1,,,,,,1,1,1,49.001163482666,0,49.0003702500287,,,,,,,,,,,,,,,,,,,,,,,,,,,,,,,,,
,3754640003.55323,49.0005359649658,159.99365234375,,,5,,,,-2.43999995291233,,,,,0.000713907477325068,4.7268493049365E-8,0.0236883268931756,5.30670339644604E-5,0.000713814378252108,4.72623288712007E-8,0.00071381431724523,2.82662360109644E-8,2.95118907449492E-7,3.7878062676198E-8,1.00013042476559,10.005763053894,2,20,10,5,2.33525069907727,0.20634283854374,0.0404026173055172,172.741912841797,48.9992561340332,49.0010528564453,159.99365234375,159.99365234375,,,22.6469306945801,0,1,,,,,,1,1,1,49.0001373291016,0,49.0000069562127,,,,,,,,,,,,,,,,,,,,,,,,,,,,,,,,,
,3754640208.46953,49.000020980835,159.99365234375,,,5,,,,-2.43999995291233,,,,,0.000714527654986415,4.54528238494351E-8,0.0298942495484003,3.74940267970971E-5,0.000714434409912755,4.54468923058786E-8,0.000714434312668847,3.67187533811592E-8,3.72758338369551E-7,2.67797156518835E-8,1.00013051593312,10.005763053894,2,20,10,5,2.33725696886242,0.206775248679619,0.0404026173055172,172.741912841797,48.9998092651367,49.000545501709,159.99365234375,159.99365234375,,,22.7078514099121,0,1,,,,,,1,1,1,49.0001487731934,0,49.0000666450052,,,,,,,,,,,,,,,,,,,,,,,,,,,,,,,,,
,3754640413.51126,49.0002765655518,159.99365234375,,,5,,,,-2.43999995291233,,,,,0.000714931010035917,4.90525025308751E-8,0.0309735166209091,4.46287639010462E-5,0.00071483770396423,4.9046100659571E-8,0.000714837599513083,3.72577494669042E-8,3.86433985447858E-7,3.18963962630604E-8,1.00013052763049,10.005763053894,2,20,10,5,2.33857246659767,0.206936024957909,0.0404026173055172,172.741912841797,48.9993209838867,49.0004997253418,159.99365234375,159.99365234375,,,22.7821159362793,0,1,,,,,,1,1,1,49.0003242492676,0,48.9999534205386,,,,,,,,,,,,,,,,,,,,,,,,,,,,,,,,,
,3754640618.49034,48.9998550415039,159.99365234375,,,5,,,,-2.43999995291233,,,,,0.000715172089822558,7.91802054274958E-8,0.0330783346365946,8.52772382395393E-5,0.000715078848116065,7.91698821814133E-8,0.000715078728946341,5.04957690964904E-8,4.12833481219228E-7,6.0975794771145E-8,1.00013039360168,10.005763053894,2,20,10,5,2.33935344343991,0.207091745741813,0.0404026173055172,172.741912841797,48.9994964599609,49.0004348754883,159.99365234375,159.99365234375,,,22.8699607849121,0,1,,,,,,1,1,1,48.9998817443848,0,48.9999673631456,,,,,,,,,,,,,,,,,,,,,,,,,,,,,,,,,
,3754640823.36718,49.0004291534424,159.99365234375,,,5,,,,-2.43999995291233,,,,,0.000715458669086567,6.55939058886519E-8,0.0333982352813864,3.85887547969711E-5,0.000715365371222745,6.55853522550689E-8,0.000715365249688217,5.95026560253348E-8,4.16993011183056E-7,2.75839148119364E-8,1.00013041987714,10.005763053894,2,20,10,5,2.34028969796578,0.207187793743296,0.0404026173055172,172.741912841797,49.0001678466797,49.0007934570313,159.99365234375,159.99365234375,,,22.9595050811768,0,1,,,,,,1,1,1,49.000617980957,0,49.0003917918486,,,,,,,,,,,,,,,,,,,,,,,,,,,,,,,,,
,3754641027.43155,48.9992752075195,159.99365234375,,,5,,,,-2.43999995291233,,,,,0.000715732578434245,5.64795392955041E-8,0.0334699547043549,4.53693204690557E-5,0.000715639200542341,5.64721707049522E-8,0.000715639078438564,4.62122517697227E-8,4.18048422904772E-7,3.24581861862462E-8,1.00013048180121,10.005763053894,2,20,10,5,2.34118540461298,0.207270052961532,0.0404026173055172,172.741912841797,48.9986763000488,48.9999504089355,159.99365234375,159.99365234375,,,23.0505027770996,0,1,,,,,,1,1,1,48.9987182617188,0,48.9991181317498,,,,,,,,,,,,,,,,,,,,,,,,,,,,,,,,,
,3754641233.45032,48.9999961853027,159.99365234375,,,5,,,,-2.43999995291233,,,,,0.000716393968144323,5.35547819790162E-8,0.0303049388084169,4.9185685568886E-5,0.000716300480331614,5.35477931995876E-8,0.000716300380136442,4.03302443771446E-8,3.78866321345651E-7,3.52255240560818E-8,1.0001305147983,10.005763053894,2,20,10,5,2.34336028956698,0.207332135535915,0.0404026173055172,172.741912841797,48.9992790222168,49.0005187988281,159.99365234375,159.99365234375,,,23.1689300537109,0,1,,,,,,1,1,1,48.9995422363281,0,48.9998889249914,,,,,,,,,,,,,,,,,,,,,,,,,,,,,,,,,
,3754641437.4107,49.0005264282227,159.99365234375,,,5,,,,-2.43999995291233,,,,,0.000716306854862327,5.0968290835742E-8,0.031842156555598,5.40741156631497E-5,0.000716213443204489,5.09616441974865E-8,0.000716213332600155,3.31272383186493E-8,3.98035939219114E-7,3.87256408686883E-8,1.00013042432912,10.005763053894,2,20,10,5,2.34306977514969,0.207369784779589,0.0404026173055172,172.741912841797,48.9995994567871,49.0009536743164,159.99365234375,159.99365234375,,,23.2609786987305,0,1,,,,,,1,1,1,49.0001907348633,0,49.0001892513699,,,,,,,,,,,,,,,,,,,,,,,,,,,,,,,,,
,3754641643.3094,49.0003967285156,159.99365234375,,,5,,,,-2.43999995291233,,,,,0.000716579021646975,3.71874733110617E-8,0.034747268525698,3.26643275136384E-5,0.000716485496552504,3.71826197473242E-8,0.000716485364795573,2.88974116821246E-8,4.34515641972005E-7,2.33984360449136E-8,1.00013053313001,10.005763053894,2,20,10,5,2.34394952280224,0.207567422692203,0.0404026173055172,172.741912841797,48.9994010925293,49.0004959106445,159.99365234375,159.99365234375,,,23.3664302825928,0,1,,,,,,1,1,1,49.0005035400391,0,48.9999409843894,,,,,,,,,,,,,,,,,,,,,,,,,,,,,,,,,
,3754641848.31295,49.0002155303955,159.99365234375,,,5,,,,-2.43999995291233,,,,,0.000716579642305101,6.32488835750479E-8,0.0343171880191786,3.01688652423293E-5,0.000716486205267263,6.32406363573224E-8,0.000716486076751634,5.94419877028726E-8,4.29137897383733E-7,2.15876859531221E-8,1.00013041010022,10.005763053894,2,20,10,5,2.34395311081809,0.207550009972364,0.0404026173055172,172.741912841797,48.9995880126953,49.0005836486816,159.99365234375,159.99365234375,,,23.5008354187012,0,1,,,,,,1,1,1,49.0000381469727,0,49.0000693377327,,,,,,,,,,,,,,,,,,,,,,,,,,,,,,,,,
,3754642052.33304,48.9999656677246,159.99365234375,,,5,,,,-2.43999995291233,,,,,0.000716746745788092,6.08873583583841E-8,0.0323782194945865,4.59932476218152E-5,0.000716653295155332,6.08794197633376E-8,0.000716653180725369,5.11924348960659E-8,4.04985439664837E-7,3.29490266947707E-8,1.00013039866473,10.005763053894,2,20,10,5,2.34450673515461,0.207519070245748,0.0404026173055172,172.741912841797,48.9996032714844,49.0004539489746,159.99365234375,159.99365234375,,,23.5948581695557,0,1,,,,,,1,1,1,48.9996376037598,0,48.999979355756,,,,,,,,,,,,,,,,,,,,,,,,,,,,,,,,,
,3754642258.25055,48.9999923706055,159.99365234375,,,5,,,,-2.43999995291233,,,,,0.000716846158133507,4.33846816069152E-8,0.0322320085881564,3.22550538348849E-5,0.000716752611436134,4.33790200104417E-8,0.00071675249802159,3.67106416710162E-8,4.0321251068051E-7,2.31099148671852E-8,1.00013051462371,10.005763053894,2,20,10,5,2.34483244663337,0.207541867452765,0.0404026173055172,172.741912841797,48.9989776611328,49.0004043579102,159.99365234375,159.99365234375,,,23.7561283111572,0,1,,,,,,1,1,1,49.0000839233398,0,48.9997429847717,,,,,,,,,,,,,,,,,,,,,,,,,,,,,,,,,
,3754642463.16366,48.9997501373291,159.99365234375,,,5,,,,-2.43999995291233,,,,,0.000717115049003655,5.78394737101749E-8,0.032182683660511,5.2759268228996E-5,0.000717021475164765,5.78319264392008E-8,0.00071702136205466,4.37490504593452E-8,4.02746490155634E-7,3.78226426836465E-8,1.00013050353739,10.005763053894,2,20,10,5,2.34571217806964,0.207617698530914,0.0404026173055172,172.741912841797,48.9992980957031,49.0002899169922,159.99365234375,159.99365234375,,,23.8778762817383,0,1,,,,,,1,1,1,48.9998550415039,0,48.9998438218061,,,,,,,,,,,,,,,,,,,,,,,,,,,,,,,,,
,3754642668.08852,49.0010452270508,159.99365234375,,,5,,,,-2.43999995291233,,,,,0.000717134849667943,6.41176516349337E-8,0.0327484042011026,6.81763294777776E-5,0.000717041313010361,6.41092887017577E-8,0.000717041195885472,4.14799795520309E-8,4.09837472643861E-7,4.88816140712274E-8,1.00013044807305,10.005763053894,2,20,10,5,2.34577489716718,0.207646587644371,0.0404026173055172,172.741912841797,48.9997062683105,49.0012741088867,159.99365234375,159.99365234375,,,23.985954284668,0,1,,,,,,1,1,1,49.0010414123535,0,49.0004155900743,,,,,,,,,,,,,,,,,,,,,,,,,,,,,,,,,
,3754642873.13962,48.9999828338623,159.99365234375,,,5,,,,-2.43999995291233,,,,,0.000717614138530266,6.695419140177E-8,0.0330627928530829,4.87002077157676E-5,0.000717520491926436,6.69454540702427E-8,0.000717520372462145,5.7111038074547E-8,4.14048474030822E-7,3.49288297931468E-8,1.00013051418724,10.005763053894,2,20,10,5,2.34734152828588,0.207798251382279,0.0404026173055172,172.741912841797,48.9990234375,49.0002021789551,159.99365234375,159.99365234375,,,24.1214656829834,0,1,,,,,,1,1,1,48.9997634887695,0,48.9996696920956,,,,,,,,,,,,,,,,,,,,,,,,,,,,,,,,,
,3754643077.97649,49.0001258850098,159.99365234375,,,5,,,,-2.43999995291233,,,,,0.000717471779087442,5.65203606105327E-8,0.0322929687022038,3.81877241468187E-5,0.000717378146365023,5.65129844943002E-8,0.000717378032421718,4.94368760051602E-8,4.04327665991499E-7,2.73808821498402E-8,1.00013052073428,10.005763053894,2,20,10,5,2.34687865683098,0.207725494137708,0.0404026173055172,172.741912841797,48.9995040893555,49.000415802002,159.99365234375,159.99365234375,,,24.2581958770752,0,1,,,,,,1,1,1,49.0002174377441,0,48.999939388699,,,,,,,,,,,,,,,,,,,,,,,,,,,,,,,,,
,3754643282.94794,49.0011005401611,159.99365234375,,,5,,,,-2.43999995291233,,,,,0.000717186504251692,5.25006515135064E-8,0.0334660865666603,4.54322249609959E-5,0.000717092959041648,5.24938036650818E-8,0.000717092836718107,4.11665511793132E-8,4.18849239560262E-7,3.25716822904367E-8,1.00013045060458,10.005763053894,2,20,10,5,2.34594125975304,0.207690931017127,0.0404026173055172,172.741912841797,48.9995040893555,49.001708984375,159.99365234375,159.99365234375,,,24.3663177490234,0,1,,,,,,1,1,1,49.0006408691406,0,49.0004369947645,,,,,,,,,,,,,,,,,,,,,,,,,,,,,,,,,
,3754643487.92426,49.0000171661377,159.99365234375,,,5,,,,-2.43999995291233,,,,,0.000717915699624779,4.87851500020108E-8,0.0360139060496714,4.86661779295494E-5,0.000717822012540324,4.87787836020689E-8,0.000717821870738456,3.404833665355E-8,4.51195062488518E-7,3.49296507400802E-8,1.00013051575853,10.005763053894,2,20,10,5,2.34831723486601,0.208006527541243,0.0404026173055172,172.741912841797,48.9992179870605,49.000244140625,159.99365234375,159.99365234375,,,24.5034961700439,0,1,,,,,,1,1,1,48.9998970031738,0,48.9998774808996,,,,,,,,,,,,,,,,,,,,,,,,,,,,,,,,,
,3754643692.93568,49.000301361084,159.99365234375,,,5,,,,-2.43999995291233,,,,,0.000718043026218239,6.57789074966023E-8,0.0373061037135312,4.06263089918364E-5,0.00071794931318083,6.57703225776019E-8,0.000717949160993571,5.89589194407762E-8,4.67467060814879E-7,2.91475753766565E-8,1.00013052876531,10.005763053894,2,20,10,5,2.34872903036828,0.208096387919075,0.0404026173055172,172.741912841797,48.9996490478516,49.0005226135254,159.99365234375,159.99365234375,,,24.6558303833008,0,1,,,,,,1,1,1,49.0003700256348,0,49.0000921885172,,,,,,,,,,,,,,,,,,,,,,,,,,,,,,,,,
,3754643897.89243,49.0005779266357,159.99365234375,,,5,,,,-2.43999995291233,,,,,0.000718206894524991,4.95463638693818E-8,0.0368092268235793,4.80431600333366E-5,0.000718113233395746,4.95399025440653E-8,0.000718113085201601,3.55562048008422E-8,4.61346216063585E-7,3.44957713964489E-8,1.00013042668606,10.005763053894,2,20,10,5,2.34926685094293,0.208123505175049,0.0404026173055172,172.741912841797,48.9992980957031,49.0008354187012,159.99365234375,159.99365234375,,,24.7657985687256,0,1,,,,,,1,1,1,49.0004501342773,0,49.0000089009603,,,,,,,,,,,,,,,,,,,,,,,,,,,,,,,,,
,3754644102.90043,48.9999523162842,159.99365234375,,,5,,,,-2.43999995291233,,,,,0.000718286660865141,5.38992151326519E-8,0.0354552404419399,5.82990334296181E-5,0.000718192927502029,5.38921815136545E-8,0.000718192789994424,3.39336322164042E-8,4.44425427484572E-7,4.18673599944216E-8,1.00013051279054,10.005763053894,2,20,10,5,2.34953268605736,0.208091098089994,0.0404026173055172,172.741912841797,48.9995040893555,49.0009994506836,159.99365234375,159.99365234375,,,24.9044361114502,0,1,,,,,,1,1,1,49.0002059936523,0,49.0002033009249,,,,,,,,,,,,,,,,,,,,,,,,,,,,,,,,,
,3754644307.80558,49.00119972229,159.99365234375,,,5,,,,-2.43999995291233,,,,,0.00071859446192372,5.0079490872393E-8,0.0341535728749953,3.65471679645787E-5,0.000718500729807652,5.00729585973759E-8,0.000718500602156651,4.26418582417433E-8,4.28292725773527E-7,2.62482972473567E-8,1.00013045514386,10.005763053894,2,20,10,5,2.35054423982495,0.208126865709401,0.0404026173055172,172.741912841797,49.000072479248,49.0012741088867,159.99365234375,159.99365234375,,,25.0287322998047,0,1,,,,,,1,1,1,49.0009918212891,0,49.000673505995,,,,,,,,,,,,,,,,,,,,,,,,,,,,,,,,,
,3754644512.75854,49.0009880065918,159.99365234375,,,5,,,,-2.43999995291233,,,,,0.000718485911864685,5.54214571406972E-8,0.035648559888255,2.56387764454362E-5,0.000718392200867721,5.54142286064754E-8,0.000718392061817939,5.22726810250676E-8,4.46972638494824E-7,1.83930299434938E-8,1.00013044545424,10.005763053894,2,20,10,5,2.35018373879149,0.208156748254271,0.0404026173055172,172.741912841797,48.9999237060547,49.0012969970703,159.99365234375,159.99365234375,,,25.1534843444824,0,1,,,,,,1,1,1,49.0010299682617,0,49.0007230970595,,,,,,,,,,,,,,,,,,,,,,,,,,,,,,,,,
,3754644717.66779,49.0004596710205,159.99365234375,,,5,,,,-2.43999995291233,,,,,0.000718305213466709,7.34887368863487E-8,0.0327348395744327,6.15954027658642E-5,0.000718211461007745,7.34791452118626E-8,0.000718211343788886,5.86782808112784E-8,4.10336256481028E-7,4.42271878158533E-8,1.00013053601071,10.005763053894,2,20,10,5,2.349603249996,0.207984912091892,0.0404026173055172,172.741912841797,48.9996070861816,49.0007133483887,159.99365234375,159.99365234375,,,25.2785415649414,0,1,,,,,,1,1,1,49.0006713867188,0,49.0001790663775,,,,,,,,,,,,,,,,,,,,,,,,,,,,,,,,,
,3754644922.71533,49.0001811981201,159.99365234375,,,5,,,,-2.43999995291233,,,,,0.00071871357248212,5.81402002591848E-8,0.037723102866094,5.11777969760718E-5,0.000718619775882102,5.81326126007386E-8,0.000718619620128283,4.50267417612545E-8,4.73133728157316E-7,3.67694598022987E-8,1.0001305232658,10.005763053894,2,20,10,5,2.35092088077246,0.208307829628613,0.0404026173055172,172.741912841797,48.9993896484375,49.0007400512695,159.99365234375,159.99365234375,,,25.4624557495117,0,1,,,,,,1,1,1,49.0002861022949,0,48.9999374813504,,,,,,,,,,,,,,,,,,,,,,,,,,,,,,,,,
,3754645127.61852,49.0004367828369,159.99365234375,,,5,,,,-2.43999995291233,,,,,0.00071873995256404,4.98487263282939E-8,0.0350294189191311,3.18026780024655E-5,0.000718646226560535,4.9842225893913E-8,0.000718646092251341,4.4300636779477E-8,4.39364964933171E-7,2.28407763220233E-8,1.00013042022631,10.005763053894,2,20,10,5,2.35101696146867,0.208204945234158,0.0404026173055172,172.741912841797,48.9998092651367,49.0009422302246,159.99365234375,159.99365234375,,,25.589485168457,0,1,,,,,,1,1,1,49.0004234313965,0,49.0003666347928,,,,,,,,,,,,,,,,,,,,,,,,,,,,,,,,,
,3754645331.30915,48.9990940093994,159.99365234375,,,5,,,,-2.43999995291233,,,,,0.000718828626196316,5.60891954818709E-8,0.0338593223362622,4.47960339061442E-5,0.00071873485033886,5.60818782824597E-8,0.00071873472483706,4.59260243561999E-8,4.24741119891795E-7,3.21866021586988E-8,1.00013047350829,10.005763053894,2,20,10,5,2.35131126682568,0.208182618041663,0.0404026173055172,172.741912841797,48.9986991882324,49.0000953674316,159.99365234375,159.99365234375,,,25.7597713470459,0,1,,,,,,1,1,1,48.9994010925293,0,48.999345667222,,,,,,,,,,,,,,,,,,,,,,,,,,,,,,,,,
,3754645537.45462,48.9999847412109,159.99365234375,,,5,,,,-2.43999995291233,,,,,0.000718912431019045,4.81927285667998E-8,0.0344866134414588,3.87113994179141E-5,0.00071881869739324,4.81864450766401E-8,0.000718818567182985,3.93457396822274E-8,4.32660507725468E-7,2.78180922779124E-8,1.00013039953767,10.005763053894,2,20,10,5,2.35158311554054,0.20823263347334,0.0404026173055172,172.741912841797,48.9995498657227,49.0007858276367,159.99365234375,159.99365234375,,,25.8882522583008,0,1,,,,,,1,1,1,48.9997406005859,0,48.9999728732639,,,,,,,,,,,,,,,,,,,,,,,,,,,,,,,,,
,3754645742.39197,49.0002975463867,159.99365234375,,,5,,,,-2.43999995291233,,,,,0.000719083080768246,4.8446614628288E-8,0.035895222114454,3.83438629753552E-5,0.000718989314600846,4.84402973424295E-8,0.000718989173502978,3.98360162545735E-8,4.50439450804175E-7,2.75600111681461E-8,1.00013041385386,10.005763053894,2,20,10,5,2.35213619476435,0.208339885646806,0.0404026173055172,172.741912841797,48.9998512268066,49.0007858276367,159.99365234375,159.99365234375,,,26.0747947692871,0,1,,,,,,1,1,1,49.0005569458008,0,49.0003253089057,,,,,,,,,,,,,,,,,,,,,,,,,,,,,,,,,
,3754645946.47834,48.9991474151611,159.99365234375,,,5,,,,-2.43999995291233,,,,,0.000718811350861719,6.37998987059704E-8,0.0361101712272216,5.90409607059735E-5,0.000718717575501462,6.37915754394021E-8,0.000718717432762647,4.76377402773192E-8,4.52965527615133E-7,4.24265341303248E-8,1.00013047595252,10.005763053894,2,20,10,5,2.3512465785456,0.208269984179542,0.0404026173055172,172.741912841797,48.9989547729492,49.0002899169922,159.99365234375,159.99365234375,,,26.1732063293457,0,1,,,,,,1,1,1,48.9991455078125,0,48.9994536505805,,,,,,,,,,,,,,,,,,,,,,,,,,,,,,,,,
,3754646152.34886,49.00075340271,159.99365234375,,,5,,,,-2.43999995291233,,,,,0.000719090735701929,4.93210047350054E-8,0.0351164180402703,4.16337060036878E-5,0.000718996953537704,4.93145724027055E-8,0.000718996818494667,3.91956997797368E-8,4.40671131869377E-7,2.99269806368506E-8,1.00013043471709,10.005763053894,2,20,10,5,2.35216406590839,0.208310131521224,0.0404026173055172,172.741912841797,48.9996910095215,49.0012130737305,159.99365234375,159.99365234375,,,26.3608570098877,0,1,,,,,,1,1,1,49.0004997253418,0,49.0004267973058,,,,,,,,,,,,,,,,,,,,,,,,,,,,,,,,,
,3754646357.23772,49.0002593994141,159.99365234375,,,5,,,,-2.43999995291233,,,,,0.000719119090002113,6.44728955992244E-8,0.038886663112228,4.65397365050418E-5,0.000719025320394387,6.44644886493697E-8,0.000719025154790601,5.51077948135096E-8,4.8800266781188E-7,3.3448486477221E-8,1.00013041210798,10.005763053894,2,20,10,5,2.35224310034567,0.208473131946706,0.0404026173055172,172.741912841797,48.9989433288574,49.0003471374512,159.99365234375,159.99365234375,,,26.5048313140869,0,1,,,,,,1,1,1,49.0002517700195,0,48.9997367858887,,,,,,,,,,,,,,,,,,,,,,,,,,,,,,,,,
,3754646561.38748,49.0001411437988,159.99365234375,,,5,,,,-2.43999995291233,,,,,0.000719079992251596,5.01216349624788E-8,0.0380438053770487,4.2564937453782E-5,0.000718986149149368,5.01150938686307E-8,0.00071898599065525,3.96914235928899E-8,4.77399336383586E-7,3.05959723923174E-8,1.00013052143263,10.005763053894,2,20,10,5,2.35211827759204,0.20842719761951,0.0404026173055172,172.741912841797,48.9995918273926,49.0003356933594,159.99365234375,159.99365234375,,,26.6633796691895,0,1,,,,,,1,1,1,48.9999465942383,0,48.9999701182047,,,,,,,,,,,,,,,,,,,,,,,,,,,,,,,,,
,3754646767.26912,49.0009365081787,159.99365234375,,,5,,,,-2.43999995291233,,,,,0.0007197028440871,4.21691951790391E-8,0.0393908795573834,3.53848478674065E-5,0.000719608976063415,4.21636952160414E-8,0.000719608805999313,3.3611601724492E-8,4.94731523201673E-7,2.54565791846697E-8,1.0001304430973,10.005763053894,2,20,10,5,2.35415072768195,0.208663077345525,0.0404026173055172,172.741912841797,48.9996528625488,49.001049041748,159.99365234375,159.99365234375,,,26.8382301330566,0,1,,,,,,1,1,1,49.0008239746094,0,49.00036351821,,,,,,,,,,,,,,,,,,,,,,,,,,,,,,,,,
,3754646973.50473,48.9992065429687,159.99365234375,,,5,,,,-2.43999995291233,,,,,0.000719132338384123,6.99871257192363E-8,0.03765991445011,8.1863529402078E-5,0.000719038601692103,6.9978003112313E-8,0.000719038446369168,3.78441091959519E-8,4.72616491238281E-7,5.88620787838126E-8,1.00013036392177,10.005763053894,2,20,10,5,2.35229089837434,0.20842661527155,0.0404026173055172,172.741912841797,48.9981536865234,49.0002021789551,159.99365234375,159.99365234375,,,26.983024597168,0,1,,,,,,1,1,1,48.998592376709,0,48.9993635813395,,,,,,,,,,,,,,,,,,,,,,,,,,,,,,,,,
,3754647180.5097,49.000602722168,159.99365234375,,,5,,,,-2.43999995291233,,,,,0.000719312866475189,4.98546971897148E-8,0.0376708148191147,5.64942454769251E-5,0.00071921906030042,4.98481955981882E-8,0.000719218904848554,2.88792967278977E-8,4.72871934254233E-7,4.06303928715594E-8,1.00013042782088,10.005763053894,2,20,10,5,2.35288136915814,0.208479376676913,0.0404026173055172,172.741912841797,48.9995307922363,49.0006141662598,159.99365234375,159.99365234375,,,27.158540725708,0,1,,,,,,1,1,1,49.0006790161133,0,49.0000504886403,,,,,,,,,,,,,,,,,,,,,,,,,,,,,,,,,
,3754647385.58833,49.0006122589111,159.99365234375,,,5,,,,-2.43999995291233,,,,,0.000719450209052379,5.75202509714435E-8,0.0373990457788258,4.26174294223988E-5,0.000719356384652717,5.7512749683727E-8,0.000719356231406463,4.86683912959486E-8,4.69550125316884E-7,3.0644804859021E-8,1.00013042825735,10.005763053894,2,20,10,5,2.35333160735618,0.208508021733382,0.0404026173055172,172.741912841797,48.9996528625488,49.0011329650879,159.99365234375,159.99365234375,,,27.3037643432617,0,1,,,,,,1,1,1,49.000358581543,0,49.0003142886692,,,,,,,,,,,,,,,,,,,,,,,,,,,,,,,,,
,3754647590.42155,48.9995727539063,159.99365234375,,,5,,,,-2.43999995291233,,,,,0.000719351347501094,6.00083723457342E-8,0.0349911626203152,6.85114974050466E-5,0.000719257487693828,6.00005425497907E-8,0.000719257353563847,3.42337964733431E-8,4.3925842997865E-7,4.92758793456896E-8,1.00013049541906,10.005763053894,2,20,10,5,2.35301698896933,0.208380486374581,0.0404026173055172,172.741912841797,48.99951171875,49.0000076293945,159.99365234375,159.99365234375,,,27.4175758361816,0,1,,,,,,1,1,1,48.999698638916,0,48.9997393290202,,,,,,,,,,,,,,,,,,,,,,,,,,,,,,,,,
,3754647794.42562,48.9994087219238,159.99365234375,,,5,,,,-2.43999995291233,,,,,0.000719553140889918,5.00107808800586E-8,0.0382033169013321,3.91086687678303E-5,0.000719459260153448,5.00042559291222E-8,0.000719459100222294,4.13432403412414E-8,4.79716452244632E-7,2.81276036859079E-8,1.00013048791178,10.005763053894,2,20,10,5,2.35366537089061,0.208570896467514,0.0404026173055172,172.741912841797,48.9989738464355,49.000186920166,159.99365234375,159.99365234375,,,27.6102561950684,0,1,,,,,,1,1,1,48.9992637634277,0,48.9997632768419,,,,,,,,,,,,,,,,,,,,,,,,,,,,,,,,,
,3754648000.26353,49.0004539489746,159.99365234375,,,5,,,,-2.43999995291233,,,,,0.000719485324234497,5.49698528030197E-8,0.036304531175686,4.0146754120401E-5,0.000719391500467014,5.49626845140856E-8,0.000719391356052217,4.67703660232431E-8,4.55830597481054E-7,2.88691799510615E-8,1.00013042101196,10.005763053894,2,20,10,5,2.35345045254591,0.208473240210474,0.0404026173055172,172.741912841797,48.9994659423828,49.0005989074707,159.99365234375,159.99365234375,,,27.7404556274414,0,1,,,,,,1,1,1,49.0005493164063,0,49.0001326168285,,,,,,,,,,,,,,,,,,,,,,,,,,,,,,,,,
,3754648205.1673,48.9999961853027,159.99365234375,,,5,,,,-2.43999995291233,,,,,0.000719162190349802,6.48979067271357E-8,0.0375224706657598,3.57679481985102E-5,0.000719068341290278,6.48894376952634E-8,0.000719068187092631,5.95849172754933E-8,4.70911104507353E-7,2.56958509818237E-8,1.0001305147983,10.005763053894,2,20,10,5,2.35238904504991,0.208429618474383,0.0404026173055172,172.741912841797,48.9989356994629,49.0003128051758,159.99365234375,159.99365234375,,,27.870964050293,0,1,,,,,,1,1,1,48.9999656677246,0,48.9995514364804,,,,,,,,,,,,,,,,,,,,,,,,,,,,,,,,,
,3754648413.03204,49.0010967254639,159.99365234375,,,5,,,,-2.43999995291233,,,,,0.000719681016315659,5.43008980898928E-8,0.0371197602721622,5.92996979819199E-5,0.000719587145863068,5.42938154383231E-8,0.000719586994848638,3.35734439291743E-8,4.66193159562962E-7,4.26689847264413E-8,1.00013045042999,10.005763053894,2,20,10,5,2.35408759810346,0.208563434797329,0.0404026173055172,172.741912841797,48.9997520446777,49.0012893676758,159.99365234375,159.99365234375,,,28.033655166626,0,1,,,,,,1,1,1,49.001220703125,0,49.000462214152,,,,,,,,,,,,,,,,,,,,,,,,,,,,,,,,,
,3754648617.93921,49.0002555847168,159.99365234375,,,5,,,,-2.43999995291233,,,,,0.000719620432065704,4.0662201264059E-8,0.0358601840470323,4.34647131935545E-5,0.000719526514665579,4.06568944550026E-8,0.000719526373737817,2.59817568858132E-8,4.50335989445274E-7,3.12718943438308E-8,1.00013052667026,10.005763053894,2,20,10,5,2.353894009885,0.208494133033644,0.0404026173055172,172.741912841797,48.9994239807129,49.0005187988281,159.99365234375,159.99365234375,,,28.164680480957,0,1,,,,,,1,1,1,49.0005302429199,0,48.999994614545,,,,,,,,,,,,,,,,,,,,,,,,,,,,,,,,,
,3754648822.87326,49.0001602172852,159.99365234375,,,5,,,,-2.43999995291233,,,,,0.000719698210586359,6.47361159535732E-8,0.0348255538971074,6.29300457666304E-5,0.000719604368730206,6.47276749748521E-8,0.000719604235802784,4.62547600583698E-8,4.37390317361775E-7,4.5278792823934E-8,1.0001304075687,10.005763053894,2,20,10,5,2.35415218983652,0.208474159544148,0.0404026173055172,172.741912841797,48.9996452331543,49.0003967285156,159.99365234375,159.99365234375,,,28.3280277252197,0,1,,,,,,1,1,1,48.9999504089355,0,49.0000845591227,,,,,,,,,,,,,,,,,,,,,,,,,,,,,,,,,
,3754649027.94949,49.000057220459,159.99365234375,,,5,,,,-2.43999995291233,,,,,0.000719785810363231,4.55799517583987E-8,0.0369327092949661,4.56111084857209E-5,0.000719691877912561,4.55740035492114E-8,0.000719691728394498,3.16178024975415E-8,4.63911465976676E-7,3.28223150422086E-8,1.0001305175917,10.005763053894,2,20,10,5,2.35443106163102,0.208586121860082,0.0404026173055172,172.741912841797,48.9995384216309,49.0002250671387,159.99365234375,159.99365234375,,,28.5081176757813,0,1,,,,,,1,1,1,49.0002326965332,0,48.9999044206407,,,,,,,,,,,,,,,,,,,,,,,,,,,,,,,,,
,3754649232.97009,48.9998817443848,159.99365234375,,,5,,,,-2.43999995291233,,,,,0.000719434022950731,5.86338070838851E-8,0.0387038385123049,6.16246286013505E-5,0.000719340142184808,5.8626155810047E-8,0.000719339978062696,3.83700972035231E-8,4.8592100182173E-7,4.4325633505412E-8,1.00013050956066,10.005763053894,2,20,10,5,2.3532739133214,0.208556924283412,0.0404026173055172,172.741912841797,48.9990272521973,49.0002212524414,159.99365234375,159.99365234375,,,28.6564502716064,0,1,,,,,,1,1,1,48.999755859375,0,48.9997417225557,,,,,,,,,,,,,,,,,,,,,,,,,,,,,,,,,
,3754649437.93307,48.9997138977051,159.99365234375,,,5,,,,-2.43999995291233,,,,,0.000719908198641092,7.19254237403448E-8,0.0382572228988876,6.8020729713704E-5,0.000719814261527575,7.19160385621964E-8,0.000719814101065629,5.2681530549124E-8,4.80630385637648E-7,4.89548050908289E-8,1.0001305018788,10.005763053894,2,20,10,5,2.35482657196183,0.208676029409767,0.0404026173055172,172.741912841797,48.9989051818848,49.0001792907715,159.99365234375,159.99365234375,,,28.8213729858398,0,1,,,,,,1,1,1,48.9993133544922,0,48.999748468399,,,,,,,,,,,,,,,,,,,,,,,,,,,,,,,,,
,3754649642.89765,49.00075340271,159.99365234375,,,5,,,,-2.43999995291233,,,,,0.000719934781662849,4.62860012746665E-8,0.0377956785452449,4.35715870183477E-5,0.000719840806838575,4.62799594512307E-8,0.000719840650219203,3.4035330994855E-8,4.74849456575242E-7,3.13597017026346E-8,1.00013054945396,10.005763053894,2,20,10,5,2.3549152068162,0.208664758670683,0.0404026173055172,172.741912841797,48.9997215270996,49.0010452270508,159.99365234375,159.99365234375,,,29.0029468536377,0,1,,,,,,1,1,1,49.0008010864258,0,49.0003859576057,,,,,,,,,,,,,,,,,,,,,,,,,,,,,,,,,
,3754649846.36289,49.0007286071777,159.99365234375,,,5,,,,-2.43999995291233,,,,,0.000719899848752638,5.28244371223804E-8,0.0379443183367325,6.1182218714937E-5,0.000719805961882489,5.28175479403957E-8,0.000719805804036455,2.91600969215299E-8,4.76693829702717E-7,4.40384163880013E-8,1.00013043358227,10.005763053894,2,20,10,5,2.35480039920371,0.208660746458428,0.0404026173055172,172.741912841797,48.9989929199219,49.0015411376953,159.99365234375,159.99365234375,,,29.1523971557617,0,1,,,,,,1,1,1,48.9999160766602,0,48.9998768700494,,,,,,,,,,,,,,,,,,,,,,,,,,,,,,,,,
,3754650052.71541,49.0002765655518,159.99365234375,,,5,,,,-2.43999995291233,,,,,0.000720029481001753,6.84181451483853E-8,0.0396696503242646,3.43356140276799E-5,0.00071993559211796,6.84092237035714E-8,0.000719935419559955,6.37982272149562E-8,4.98458894463927E-7,2.46902428492328E-8,1.00013041289363,10.005763053894,2,20,10,5,2.35521814211589,0.208769242882842,0.0404026173055172,172.741912841797,48.9995346069336,49.0007743835449,159.99365234375,159.99365234375,,,29.3020725250244,0,1,,,,,,1,1,1,48.9997291564941,0,49.0000116560194,,,,,,,,,,,,,,,,,,,,,,,,,,,,,,,,,
,3754650257.67221,49.0002365112305,159.99365234375,,,5,,,,-2.43999995291233,,,,,0.000720016393610312,4.22271385497288E-8,0.0404091631858812,4.34137405393643E-5,0.000719922425161757,4.22216275381301E-8,0.000719922246113483,2.83901156763822E-8,5.07741767282597E-7,3.12516745767362E-8,1.00013052579732,10.005763053894,2,20,10,5,2.35517263865948,0.208795844670371,0.0404026173055172,172.741912841797,48.9992218017578,49.0003471374512,159.99365234375,159.99365234375,,,29.4686279296875,0,1,,,,,,1,1,1,49.0001220703125,0,48.9998035430908,,,,,,,,,,,,,,,,,,,,,,,,,,,,,,,,,
,3754650462.58288,49.0011596679687,159.99365234375,,,5,,,,-2.43999995291233,,,,,0.000720004643301163,5.4427266944996E-8,0.0401793916517166,4.71626400079105E-5,0.000719910728563224,5.44201676539574E-8,0.000719910551548219,4.25357247814702E-8,5.0484648245033E-7,3.3945055086122E-8,1.00013045331069,10.005763053894,2,20,10,5,2.35513504098054,0.208782989504667,0.0404026173055172,172.741912841797,48.9996719360352,49.0017471313477,159.99365234375,159.99365234375,,,29.6189746856689,0,1,,,,,,1,1,1,49.0008316040039,0,49.0006186167399,,,,,,,,,,,,,,,,,,,,,,,,,,,,,,,,,
,3754650667.59312,49.0009593963623,159.99365234375,,,5,,,,-2.43999995291233,,,,,0.000720125037869049,4.35992176363685E-8,0.037269904639186,4.17088419707299E-5,0.000720031114026129,4.3593531115482E-8,0.000720030961693636,3.1603064462001E-8,4.6836764055895E-7,3.00273587204588E-8,1.00013044414483,10.005763053894,2,20,10,5,2.35553945234289,0.208698286614794,0.0404026173055172,172.741912841797,49.0000190734863,49.0019874572754,159.99365234375,159.99365234375,,,29.8030834197998,0,1,,,,,,1,1,1,49.0008125305176,0,49.0006581356651,,,,,,,,,,,,,,,,,,,,,,,,,,,,,,,,,
,3754650872.4251,49.000186920166,159.99365234375,,,5,,,,-2.43999995291233,,,,,0.000720234947202275,5.57485364511691E-8,0.0385613251244559,4.64224462305199E-5,0.000720141034480752,5.5741267299902E-8,0.000720140871383674,4.46102656381632E-8,4.84670785626025E-7,3.34217456140706E-8,1.00013040879081,10.005763053894,2,20,10,5,2.35589426178738,0.208783243407303,0.0404026173055172,172.741912841797,48.9993171691895,49.0003471374512,159.99365234375,159.99365234375,,,29.9542255401611,0,1,,,,,,1,1,1,49.0000267028809,0,48.9999398624196,,,,,,,,,,,,,,,,,,,,,,,,,,,,,,,,,
,3754651077.39952,49.000373840332,159.99365234375,,,5,,,,-2.43999995291233,,,,,0.000720788875524513,5.19746698945472E-8,0.0395600285498379,4.24675435798994E-5,0.000720694884410691,5.19678923799659E-8,0.000720694712624063,4.20055559021714E-8,4.97605725587598E-7,3.0597305629177E-8,1.00013041734561,10.005763053894,2,20,10,5,2.3577025235346,0.208984911794526,0.0404026173055172,172.741912841797,48.9996109008789,49.0008964538574,159.99365234375,159.99365234375,,,30.0780906677246,0,1,,,,,,1,1,1,49.0004730224609,0,49.0001835542567,,,,,,,,,,,,,,,,,,,,,,,,,,,,,,,,,
,3754651282.34094,49.0009689331055,159.99365234375,,,5,,,,-2.43999995291233,,,,,0.000720873646525841,4.32829003614916E-8,0.0352320720864094,3.98133494358792E-5,0.000720779624729484,4.32772550780732E-8,0.000720779488458435,3.23991907899166E-8,4.4321865087315E-7,2.86916929310766E-8,1.0001304445813,10.005763053894,2,20,10,5,2.35799559103255,0.208831374003215,0.0404026173055172,172.741912841797,48.9999580383301,49.0013313293457,159.99365234375,159.99365234375,,,30.2024612426758,0,1,,,,,,1,1,1,49.0006370544434,0,49.0006619621726,,,,,,,,,,,,,,,,,,,,,,,,,,,,,,,,,
,3754651487.27829,49.0008182525635,159.99365234375,,,5,,,,-2.43999995291233,,,,,0.000720353456470019,4.5451933938649E-8,0.0381634392967394,3.54321732426444E-5,0.000720259507487203,4.54460060668213E-8,0.000720259347712236,3.76097454295158E-8,4.79748738789569E-7,2.55116937139144E-8,1.00013043768508,10.005763053894,2,20,10,5,2.35628335688356,0.208801231069779,0.0404026173055172,172.741912841797,48.9998207092285,49.0008773803711,159.99365234375,159.99365234375,,,30.3392677307129,0,1,,,,,,1,1,1,49.0007476806641,0,49.0003352445715,,,,,,,,,,,,,,,,,,,,,,,,,,,,,,,,,
,3754651692.35633,49.0009078979492,159.99365234375,,,5,,,,-2.43999995291233,,,,,0.000720416370196297,5.79483119913708E-8,0.0353746131775532,6.9364705125223E-5,0.000720322410053268,5.79407540958145E-8,0.000720322272764487,2.93370832865437E-8,4.44729528360693E-7,4.9964652800055E-8,1.0001304417879,10.005763053894,2,20,10,5,2.35649930970094,0.208704766061885,0.0404026173055172,172.741912841797,48.9999504089355,49.0011787414551,159.99365234375,159.99365234375,,,30.4885139465332,0,1,,,,,,1,1,1,49.0009078979492,0,49.0005360771628,,,,,,,,,,,,,,,,,,,,,,,,,,,,,,,,,
,3754651899.92512,49.0002174377441,159.99365234375,,,5,,,,-2.43999995291233,,,,,0.000720360221765882,6.14458527834418E-8,0.0384900704609121,4.8976491329673E-5,0.000720266209073406,6.14378336148549E-8,0.000720266046550277,5.03089117860745E-8,4.8385928751251E-7,3.52650080701475E-8,1.00013052492438,10.005763053894,2,20,10,5,2.35630429562231,0.208816627398512,0.0404026173055172,172.741912841797,48.9995536804199,49.0005416870117,159.99365234375,159.99365234375,,,30.6004486083984,0,1,,,,,,1,1,1,49.0001449584961,0,49.0000127156576,,,,,,,,,,,,,,,,,,,,,,,,,,,,,,,,,
,3754652053.64216,49.0023651123047,159.99365234375,,,5,,,,-2.43999995291233,,,,,0.000720396846085243,9.49735341040597E-8,0.0420858950835505,4.4225405681059E-5,0.000720302840456102,9.4961140869867E-8,0.000720302646138124,8.94748576516409E-8,5.29089355331693E-7,3.18098746229111E-8,1.00013050848041,10.005763053894,2,20,10,5,2.35641098444062,0.208975121625222,0.0404026173055172,172.741912841797,49.0006828308105,49.0026245117188,159.99365234375,159.99365234375,,,30.7123832702637,0,1,,,,,,1,1,1,49.0022087097168,0,49.0015422596651,,,,,,,,,,,,,,,,,,,,,,,,,,,,,,,,,