File: Experimental_Data/Fig3B/Lifetime_400Oe.dat
[Header]
; MPMS3 Data File (default extension .dat)
; Copyright (c) 2007, Quantum Design, Inc. All rights reserved.
TITLE,400Oe
FILEOPENTIME,3755424491.80779,12/31/2018,1:27 pm
BYAPP,SQUID AC,0.9.1.0
INFO,MPMS3 Measurement Release 1.1.16 Build 347, MultiVu Release 2.3.3.2,APPNAME
INFO,0,MOMENT_UNITS
INFO,CoIINO3,SAMPLE_MATERIAL
INFO,40 Hours Pumped Turbo,SAMPLE_COMMENT
INFO,,SAMPLE_MASS
INFO,,SAMPLE_VOLUME
INFO,,SAMPLE_MOLECULAR_WEIGHT
INFO,,SAMPLE_SIZE
INFO,,SAMPLE_SHAPE
INFO,Brass,SAMPLE_HOLDER
INFO,Standard,SAMPLE_HOLDER_DETAIL
INFO,65.37,SAMPLE_OFFSET
DATATYPE,COMMENT,1
DATATYPE,TIME,2
STARTUPAXIS,X,2
STARTUPAXIS,Y1,5
FIELDGROUP, VSM,2,3,4,5,6,8,9,10,11,14,15
FIELDGROUP, DC, 2,3,4,14,56,57,58,59,60,61,62,63,64,65,66,67,68,69
FIELDGROUP, AC, 2,3,4,11,16,17,18,19,20,21,22,23,24,25,26,27,28,29,30
STARTUPGROUP, All
[Data]
Comment,Time Stamp (sec),Temperature (K),Magnetic Field (Oe),Moment (emu),M. Std. Err. (emu),Transport Action,Averaging Time (sec),Frequency (Hz),Peak Amplitude (mm),Center Position (mm),Lockin Signal' (V),Lockin Signal (V),Range,M. Quad. Signal (emu),AC Moment (emu),AC M. Std Err. (emu),AC Phase (deg),AC Phase Std. Err. (deg),AC Susceptibility (emu/Oe),AC Suscept. Std Err. (emu/Oe),AC X' (emu/Oe),AC X' Std Err. (emu/Oe),AC X'' (emu/Oe),AC X'' Std Err. (emu/Oe),AC Drive (Oe),AC Frequency (Hz),AC Averaging Time (sec),AC Cycles,AC Range,AC Measure Type,AC Signal' (V),AC Signal'' (V),AC Trim Coil Ratio,AC Trim Coil Phase,Min. Temperature (K),Max. Temperature (K),Min. Field (Oe),Max. Field (Oe),Mass (grams),Motor Lag (deg),Pressure (Torr),Measure Count,Measurement Number,SQUID Status (code),Motor Status (code),Measure Status (code),Motor Current (amps),Motor Temp. (C),Temp. Status (code),Field Status (code),Chamber Status (code),Chamber Temp (K),Redirection State,Average Temp (K),Rotation Angle (deg),Rotator state,DC Moment Fixed Ctr (emu),DC Moment Err Fixed Ctr (emu),DC Moment Free Ctr (emu),DC Moment Err Free Ctr (emu),DC Fixed Fit,DC Free Fit,DC Calculated Center (mm),DC Calculated Center Err (mm),DC Scan Length (mm),DC Scan Time (s),DC Number of Points,DC Squid Drift,DC Min V (V),DC Max V (V),DC Scans per Measure,Map 01,Map 02,Map 03,Map 04,Map 05,Map 06,Map 07,Map 08,Map 09,Map 10,Map 11,Map 12,Map 13,Map 14,Map 15,Map 16
,3755424496.35725,48.9526176452637,399.546997070313,,,5,,,,-2.43000010959804,,,,,0.000743827456636114,3.22632200010777E-7,-0.0106891504322943,0.000119370743773929,0.000743730977430739,3.22590352539286E-7,0.000743730964487976,3.10166274459242E-7,-1.38751096858427E-7,8.86646363523537E-8,1.00012972325788,10.005763053894,2,20,10,5,2.43321138423792,0.214154869285353,0.0404026173055172,172.741912841797,48.9201011657715,48.9678382873535,399.546997070313,399.546997070313,,,11.5960884094238,0,1,,,,,,1,1,1,48.9449768066406,0,48.9341458214654,,,,,,,,,,,,,,,,,,,,,,,,,,,,,,,,,
,3755424704.25372,48.999927520752,399.546997070313,,,5,,,,-2.43000010959804,,,,,0.000770608745228687,1.54906584499093E-7,-0.0213949726694302,0.000155161494975642,0.00077050818492973,1.54886370022494E-7,0.000770508131211033,9.84856957520717E-8,-2.87717547699591E-7,1.1954227432576E-7,1.00013051165572,10.005763053894,2,20,10,5,2.52085987828296,0.221394177585189,0.0404026173055172,172.741912841797,48.9994087219238,49.0004425048828,399.546997070313,399.546997070313,,,11.5657749176025,0,1,,,,,,1,1,1,49.0004425048828,0,48.9998154640198,,,,,,,,,,,,,,,,,,,,,,,,,,,,,,,,,
,3755424909.16455,49.0003643035889,399.546997070313,,,5,,,,-2.43000010959804,,,,,0.000772175065809952,1.18200429779845E-7,-0.0197107369735923,7.63013754656187E-5,0.000772074374256432,1.18185016455291E-7,0.000772074328569752,1.0246641408931E-7,-2.65606904106644E-7,5.88925470515214E-8,1.00013041690914,10.005763053894,2,20,10,5,2.52597719424836,0.221918432256093,0.0404026173055172,172.741912841797,48.9992904663086,49.0011100769043,399.546997070313,399.546997070313,,,11.2964687347412,0,1,,,,,,1,1,1,49.0000228881836,0,48.9999370574951,,,,,,,,,,,,,,,,,,,,,,,,,,,,,,,,,
,3755425114.12769,49.0001373291016,399.546997070313,,,5,,,,-2.43000010959804,,,,,0.000772688891876407,1.79431147740274E-7,-0.021813441342819,0.000150907384373155,0.000772588141344594,1.7940775179949E-7,0.000772588085353217,1.36375215977598E-7,-2.94136947598528E-7,1.16571616926296E-7,1.00013040652117,10.005763053894,2,20,10,5,2.5276661954253,0.221973339168411,0.0404026173055172,172.741912841797,48.9994735717773,49.0004844665527,399.546997070313,399.546997070313,,,11.0620460510254,0,1,,,,,,1,1,1,49.0001602172852,0,48.9999298519558,,,,,,,,,,,,,,,,,,,,,,,,,,,,,,,,,
,3755425319.10889,48.9996109008789,399.546997070313,,,5,,,,-2.43000010959804,,,,,0.000773397104560668,1.08342407858558E-7,-0.017296541221385,0.000103875607916104,0.000773296191600011,1.08328271326268E-7,0.000773296156363805,7.2690966456256E-8,-2.33443883037507E-7,8.03183525988482E-8,1.00013049716493,10.005763053894,2,20,10,5,2.52996541983307,0.222376242745933,0.0404026173055172,172.741912841797,48.999397277832,49.0001754760742,399.546997070313,399.546997070313,,,10.8571701049805,0,1,,,,,,1,1,1,48.999584197998,0,48.9997847080231,,,,,,,,,,,,,,,,,,,,,,,,,,,,,,,,,
,3755425524.04113,49.0001544952393,399.546997070313,,,5,,,,-2.43000010959804,,,,,0.000773210354701765,1.15377157475917E-7,-0.0161073466272095,0.000109922584709176,0.000773109535569354,1.15362113413398E-7,0.000773109505019174,7.80253685452011E-8,-2.17341368108025E-7,8.49732844757179E-8,1.00013040730682,10.005763053894,2,20,10,5,2.52934990210472,0.222375040541409,0.0404026173055172,172.741912841797,48.9999580383301,49.0008735656738,399.546997070313,399.546997070313,,,10.6691255569458,0,1,,,,,,1,1,1,49.0003128051758,0,49.0002941804774,,,,,,,,,,,,,,,,,,,,,,,,,,,,,,,,,
,3755425728.87736,48.9998683929443,399.546997070313,,,5,,,,-2.43000010959804,,,,,0.000773385836028082,1.59775360210295E-7,-0.0177226061861591,0.000178175972059827,0.000773284915426023,1.59754510816893E-7,0.000773284878433032,8.08714033600474E-8,-2.39190808183806E-7,1.37772710813576E-7,1.00013050894961,10.005763053894,2,20,10,5,2.52993021142939,0.222354188510599,0.0404026173055172,172.741912841797,48.9993591308594,49.0002021789551,399.546997070313,399.546997070313,,,10.4829397201538,0,1,,,,,,1,1,1,48.9998092651367,0,48.9997446272108,,,,,,,,,,,,,,,,,,,,,,,,,,,,,,,,,
,3755425932.52995,48.9990272521973,399.546997070313,,,5,,,,-2.43000010959804,,,,,0.000773406941712961,1.50205326899197E-7,-0.0181680749101272,0.000142882175268479,0.000773306048122549,1.50185732098695E-7,0.00077330600924544,1.01734602231469E-7,-2.45209718668654E-7,1.10479974813654E-7,1.00013047045301,10.005763053894,2,20,10,5,2.53000098157914,0.222340589958451,0.0404026173055172,172.741912841797,48.9989433288574,49.0003242492676,399.546997070313,399.546997070313,,,10.2697992324829,0,1,,,,,,1,1,1,48.998950958252,0,48.9993571113138,,,,,,,,,,,,,,,,,,,,,,,,,,,,,,,,,
,3755426138.64614,49.0008945465088,399.546997070313,,,5,,,,-2.43000010959804,,,,,0.00077372089803812,1.34749796951613E-7,-0.0168351971648741,0.000117689181433507,0.000773619986136702,1.34732222321975E-7,0.000773619952741135,9.9325504195696E-8,-2.27312463859887E-7,9.10341471541806E-8,1.00013044117684,10.005763053894,2,20,10,5,2.53102283422619,0.222489717749864,0.0404026173055172,172.741912841797,48.9997024536133,49.0012321472168,399.546997070313,399.546997070313,,,10.0740928649902,0,1,,,,,,1,1,1,49.0008277893066,0,49.0004683101878,,,,,,,,,,,,,,,,,,,,,,,,,,,,,,,,,
,3755426343.49488,49.0006637573242,399.546997070313,,,5,,,,-2.43000010959804,,,,,0.000773634011008731,1.92885267602313E-7,-0.0173269057213057,0.000204275105675538,0.000773533118608904,1.92860112739338E-7,0.00077353308323804,1.10590817931498E-7,-2.33925348918493E-7,1.58002196424836E-7,1.00013043061428,10.005763053894,2,20,10,5,2.53074051537299,0.222443014613235,0.0404026173055172,172.741912841797,48.9996337890625,49.0009231567383,399.546997070313,399.546997070313,,,9.9001522064209,0,1,,,,,,1,1,1,49.0007019042969,0,49.0002519944135,,,,,,,,,,,,,,,,,,,,,,,,,,,,,,,,,
,3755426548.43184,49.0004997253418,399.546997070313,,,5,,,,-2.43000010959804,,,,,0.000774103470279931,1.25810174377884E-7,-0.0176307213217122,7.44330992517894E-5,0.000774002522466118,1.25793767963824E-7,0.000774002485821747,1.11836980864566E-7,-2.38171514141473E-7,5.75895977554561E-8,1.00013042310701,10.005763053894,2,20,10,5,2.53227740816582,0.222564572188765,0.0404026173055172,172.741912841797,48.9994621276855,49.0007438659668,399.546997070313,399.546997070313,,,9.74285697937012,0,1,,,,,,1,1,1,49.0003623962402,0,49.0001707638011,,,,,,,,,,,,,,,,,,,,,,,,,,,,,,,,,
,3755426753.34655,49.0009708404541,399.546997070313,,,5,,,,-2.43000010959804,,,,,0.000773818678000826,1.50675243059132E-7,-0.0185226757955492,0.000131901907969582,0.000773717750645258,1.50655590840513E-7,0.000773717710214234,1.10836604187024E-7,-2.50128769075586E-7,1.02040943859772E-7,1.00013044466859,10.005763053894,2,20,10,5,2.53134924810507,0.222443280281297,0.0404026173055172,172.741912841797,48.9999923706055,49.0013236999512,399.546997070313,399.546997070313,,,9.60186290740967,0,1,,,,,,1,1,1,49.0011672973633,0,49.0006397471708,,,,,,,,,,,,,,,,,,,,,,,,,,,,,,,,,
,3755426958.24086,49.0003623962402,399.546997070313,,,5,,,,-2.43000010959804,,,,,0.000774157363336877,1.61134194041427E-7,-0.016649361326305,0.00013394009249315,0.000774056413359513,1.6111318217225E-7,0.000774056380678726,1.23336629796399E-7,-2.24930088064379E-7,1.03660663803271E-7,1.00013041682185,10.005763053894,2,20,10,5,2.53244989252647,0.222623442763569,0.0404026173055172,172.741912841797,48.9993286132812,49.0004119873047,399.546997070313,399.546997070313,,,9.47325325012207,0,1,,,,,,1,1,1,49.0003852844238,0,48.9998850822449,,,,,,,,,,,,,,,,,,,,,,,,,,,,,,,,,
,3755427163.17976,48.9998302459717,399.546997070313,,,5,,,,-2.43000010959804,,,,,0.000773819490494651,1.23014087204011E-7,-0.016734313288655,0.000103581284596017,0.000773718514654831,1.2299803507439E-7,0.000773718481654103,9.33146763225412E-8,-2.25979085151096E-7,8.01304424983423E-8,1.00013050720373,10.005763053894,2,20,10,5,2.53134496119374,0.222522529422868,0.0404026173055172,172.741912841797,48.9991912841797,49.0002212524414,399.546997070313,399.546997070313,,,9.35875701904297,0,1,,,,,,1,1,1,49.0000495910645,0,48.9997374590705,,,,,,,,,,,,,,,,,,,,,,,,,,,,,,,,,
,3755427368.16912,48.9998588562012,399.546997070313,,,5,,,,-2.43000010959804,,,,,0.000773626080382075,1.33368042515336E-7,-0.0225685941070699,9.07053100486707E-5,0.000773525128767646,1.33350639121699E-7,0.000773525068759781,1.13411194759272E-7,-3.04688658740717E-7,7.01448063468701E-8,1.00013050851314,10.005763053894,2,20,10,5,2.53073491142571,0.222209215273995,0.0404026173055172,172.741912841797,48.9993667602539,49.0005378723145,399.546997070313,399.546997070313,,,9.25660228729248,0,1,,,,,,1,1,1,48.9999084472656,0,48.9999483893899,,,,,,,,,,,,,,,,,,,,,,,,,,,,,,,,,
,3755427573.12716,48.9997749328613,399.546997070313,,,5,,,,-2.43000010959804,,,,,0.00077394811206791,1.11609423621969E-7,-0.0139821833280802,0.000109967244398478,0.000773847121402994,1.11594859971349E-7,0.000773847098360479,7.22018559664768E-8,-1.88845885402403E-7,8.50899804149765E-8,1.00013050467221,10.005763053894,2,20,10,5,2.53175501907619,0.222681127929677,0.0404026173055172,172.741912841797,48.9993019104004,49.0001258850098,399.546997070313,399.546997070313,,,9.16388320922852,0,1,,,,,,1,1,1,48.9996757507324,0,48.9997103074018,,,,,,,,,,,,,,,,,,,,,,,,,,,,,,,,,
,3755427777.98124,49.0005683898926,399.546997070313,,,5,,,,-2.43000010959804,,,,,0.000773838541533819,9.65104416201802E-8,-0.0201891823116567,8.53105332916411E-5,0.000773737625837116,9.64978557667593E-8,0.000773737577802324,7.0398386740956E-8,-2.7264014555533E-7,6.59992675099737E-8,1.00013042624959,10.005763053894,2,20,10,5,2.53142069543302,0.222375363751477,0.0404026173055172,172.741912841797,49.0000457763672,49.000789642334,399.546997070313,399.546997070313,,,9.08044719696045,0,1,,,,,,1,1,1,49.0006523132324,0,49.0004350874159,,,,,,,,,,,,,,,,,,,,,,,,,,,,,,,,,
,3755427982.93001,49.0006141662598,399.546997070313,,,5,,,,-2.43000010959804,,,,,0.000773766911364378,1.36067761189503E-7,-0.0187496052248939,0.000120423125857888,0.000773666003388251,1.36050016411075E-7,0.000773665961963252,9.91552022199283E-8,-2.53176272385616E-7,9.31549936298574E-8,1.00013042834464,10.005763053894,2,20,10,5,2.53118078756881,0.222418376565349,0.0404026173055172,172.741912841797,48.9997749328613,49.0008926391602,399.546997070313,399.546997070313,,,9.00531959533691,0,1,,,,,,1,1,1,49.0006446838379,0,49.0003132539637,,,,,,,,,,,,,,,,,,,,,,,,,,,,,,,,,
,3755428188.22824,49.000940322876,399.546997070313,,,5,,,,-2.43000010959804,,,,,0.000773915243015757,1.50379093750213E-7,-0.0102747340824312,0.000134255036994819,0.000773814304146088,1.50359480367634E-7,0.00077381429170373,1.08710520814476E-7,-1.38766523978493E-7,1.03874905538683E-7,1.00013044327189,10.005763053894,2,20,10,5,2.53163308384697,0.222835481136285,0.0404026173055172,172.741912841797,48.9998054504395,49.0012512207031,399.546997070313,399.546997070313,,,8.93840980529785,0,1,,,,,,1,1,1,49.0007820129395,0,49.0005046620088,,,,,,,,,,,,,,,,,,,,,,,,,,,,,,,,,
,3755428393.16547,48.9993190765381,399.546997070313,,,5,,,,-2.43000010959804,,,,,0.000774332723106388,1.26145819240226E-7,-0.0179426018189224,0.000108999468403187,0.000774231698405355,1.26129361400728E-7,0.000774231660441831,9.37486915820338E-8,-2.42456442186088E-7,8.4378899222567E-8,1.00013048380897,10.005763053894,2,20,10,5,2.53302856035954,0.222616701533146,0.0404026173055172,172.741912841797,48.9992408752441,49.000186920166,399.546997070313,399.546997070313,,,8.87822437286377,0,1,,,,,,1,1,1,48.999397277832,0,48.999568939209,,,,,,,,,,,,,,,,,,,,,,,,,,,,,,,,,
,3755428598.11994,48.999906539917,399.546997070313,,,5,,,,-2.43000010959804,,,,,0.000774013193764705,1.36155955537346E-7,-0.0182603465886073,0.000125175729154392,0.000773912189946553,1.36138188047742E-7,0.00077391215064276,9.56610713232135E-8,-2.46648264469668E-7,9.68636447704582E-8,1.00013051069548,10.005763053894,2,20,10,5,2.53198453715876,0.222510795698264,0.0404026173055172,172.741912841797,48.9995231628418,49.0002746582031,399.546997070313,399.546997070313,,,8.82455348968506,0,1,,,,,,1,1,1,48.9996566772461,0,48.9998061236213,,,,,,,,,,,,,,,,,,,,,,,,,,,,,,,,,
,3755428802.99776,49.0009708404541,399.546997070313,,,5,,,,-2.43000010959804,,,,,0.000773928964421829,1.79076429840133E-7,-0.0235530542956397,0.000139450744595676,0.000773828022681862,1.79053073321323E-7,0.000773827957299041,1.42896774222938E-7,-3.18103934971862E-7,1.07891218282536E-7,1.00013044466859,10.005763053894,2,20,10,5,2.53172954461853,0.222252707057915,0.0404026173055172,172.741912841797,49.0001945495605,49.0013084411621,399.546997070313,399.546997070313,,,8.77577877044678,0,1,,,,,,1,1,1,49.0011215209961,0,49.000747905058,,,,,,,,,,,,,,,,,,,,,,,,,,,,,,,,,
,3755429008.05017,49.0007781982422,399.546997070313,,,5,,,,-2.43000010959804,,,,,0.000773860301559455,1.1983298087387E-7,-0.0155438889167874,9.17885543387365E-5,0.000773759375596124,1.19817352395436E-7,0.000773759347122022,9.65094565507876E-8,-2.09914757025166E-7,7.10079061184304E-8,1.00013043585191,10.005763053894,2,20,10,5,2.53147383975022,0.222586860156306,0.0404026173055172,172.741912841797,48.9994430541992,49.0013122558594,399.546997070313,399.546997070313,,,8.73235988616943,0,1,,,,,,1,1,1,49.0002899169922,0,49.000159157647,,,,,,,,,,,,,,,,,,,,,,,,,,,,,,,,,
,3755429211.60058,49.0003490447998,399.546997070313,,,5,,,,-2.43000010959804,,,,,0.0007740391067116,1.21938657257157E-7,-0.0247699654671516,0.000101713634331758,0.000773938172627737,1.21922756553238E-7,0.000773938100303843,9.31138581587642E-8,-3.34586969153091E-7,7.87081189225713E-8,1.00013041621079,10.005763053894,2,20,10,5,2.53209456982723,0.22223056174526,0.0404026173055172,172.741912841797,48.9996719360352,49.0004425048828,399.546997070313,399.546997070313,,,8.69375801086426,0,1,,,,,,1,1,1,49.0002403259277,0,49.0001429389505,,,,,,,,,,,,,,,,,,,,,,,,,,,,,,,,,
,3755429415.41195,48.9998054504395,399.546997070313,,,5,,,,-2.43000010959804,,,,,0.00077403809410791,1.59510747991872E-7,-0.0147428529583022,0.0001239527946062,0.000773937090620631,1.59489933587609E-7,0.000773937064999785,1.27427415397169E-7,-1.99142776257767E-7,9.59129434486157E-8,1.00013050606891,10.005763053894,2,20,10,5,2.53205232656921,0.222673402652759,0.0404026173055172,172.741912841797,48.9991645812988,49.0002593994141,399.546997070313,399.546997070313,,,8.65786552429199,0,1,,,,,,1,1,1,48.9994583129883,0,48.9997513714959,,,,,,,,,,,,,,,,,,,,,,,,,,,,,,,,,
,3755429620.55517,49.0004119873047,399.546997070313,,,5,,,,-2.43000010959804,,,,,0.000774062541043475,1.33092347272628E-7,-0.0172977384933208,0.000116981332036328,0.000773961512884195,1.33074976486489E-7,0.000773961477612791,9.75389264428879E-8,-2.3366090424404E-7,9.05268313553963E-8,1.00013053382836,10.005763053894,2,20,10,5,2.53214222554988,0.222567518909526,0.0404026173055172,172.741912841797,48.9995460510254,49.0006980895996,399.546997070313,399.546997070313,,,8.62735271453857,0,1,,,,,,1,1,1,49.0006980895996,0,49.000244140625,,,,,,,,,,,,,,,,,,,,,,,,,,,,,,,,,
,3755429825.51853,49.0012626647949,399.546997070313,,,5,,,,-2.43000010959804,,,,,0.000774040344500689,1.61119187955156E-7,-0.0135225030535855,0.00016003373575529,0.000773939377898324,1.61098171405955E-7,0.000773939356343432,1.03028886822219E-7,-1.82659134629137E-7,1.23845344323139E-7,1.00013045802455,10.005763053894,2,20,10,5,2.53205494544448,0.2227279731609,0.0404026173055172,172.741912841797,48.9998664855957,49.0017776489258,399.546997070313,399.546997070313,,,8.59847545623779,0,1,,,,,,1,1,1,49.001106262207,0,49.0006139543321,,,,,,,,,,,,,,,,,,,,,,,,,,,,,,,,,
,3755430030.42119,49.0004005432129,399.546997070313,,,5,,,,-2.43000010959804,,,,,0.000774214535933094,1.26169461082782E-7,-0.0163500406836681,0.000110514409092798,0.000774113577149103,1.26153008388114E-7,0.00077411354563049,9.27235585793245E-8,-2.20902628709343E-7,8.55390157165609E-8,1.00013041856773,10.005763053894,2,20,10,5,2.53263575432676,0.222653114706545,0.0404026173055172,172.741912841797,48.9996643066406,49.0004997253418,399.546997070313,399.546997070313,,,8.57384967803955,0,1,,,,,,1,1,1,49.0003700256348,0,49.0000863916734,,,,,,,,,,,,,,,,,,,,,,,,,,,,,,,,,
,3755430235.38739,49.0005950927734,399.546997070313,,,5,,,,-2.43000010959804,,,,,0.00077410832415727,1.70507711457208E-7,-0.0160117241239508,0.000150625859838458,0.000774007372332618,1.70485475467681E-7,0.000774007342109029,1.24405529398244E-7,-2.16302011416977E-7,1.16569985847919E-7,1.0001304274717,10.005763053894,2,20,10,5,2.53228699646734,0.222637520798818,0.0404026173055172,172.741912841797,48.9995269775391,49.0006370544434,399.546997070313,399.546997070313,,,8.55097579956055,0,1,,,,,,1,1,1,49.0006790161133,0,49.0001542833116,,,,,,,,,,,,,,,,,,,,,,,,,,,,,,,,,
,3755430440.47155,49.0005054473877,399.546997070313,,,5,,,,-2.43000010959804,,,,,0.000774090328611647,1.1396872097579E-7,-0.0217018464733894,8.76788290356974E-5,0.000773989382308921,1.13953858729636E-7,0.000773989326788454,9.15528289122129E-8,-2.93162925576991E-7,6.78495500172618E-8,1.00013042336889,10.005763053894,2,20,10,5,2.53225022622984,0.222380866050545,0.0404026173055172,172.741912841797,48.9993743896484,49.0006332397461,399.546997070313,399.546997070313,,,8.53107738494873,0,1,,,,,,1,1,1,49.0004577636719,0,49.0001015133328,,,,,,,,,,,,,,,,,,,,,,,,,,,,,,,,,
,3755430645.39622,49.0009307861328,399.546997070313,,,5,,,,-2.43000010959804,,,,,0.000774219233030402,1.28989910786586E-7,-0.0162767679991695,0.00013813259361579,0.000774118254850288,1.28973087171403E-7,0.000774118223613354,7.21205707516294E-8,-2.19913982770134E-7,1.06923713408118E-7,1.00013044283542,10.005763053894,2,20,10,5,2.53265083501111,0.22265770294965,0.0404026173055172,172.741912841797,48.9999809265137,49.0015449523926,399.546997070313,399.546997070313,,,8.51327991485596,0,1,,,,,,1,1,1,49.0006904602051,0,49.0004088083903,,,,,,,,,,,,,,,,,,,,,,,,,,,,,,,,,
,3755430850.34389,49.0010662078857,399.546997070313,,,5,,,,-2.43000010959804,,,,,0.000774257234917974,1.7091554725952E-7,-0.0171377534651755,0.000183255722600601,0.000774156246983943,1.70893254399689E-7,0.000774156212353253,9.52919601139456E-8,-2.31558045274108E-7,1.41858897278101E-7,1.00013044903329,10.005763053894,2,20,10,5,2.53277849382076,0.222630571224225,0.0404026173055172,172.741912841797,48.9997367858887,49.0016059875488,399.546997070313,399.546997070313,,,8.49652767181396,0,1,,,,,,1,1,1,49.0008163452148,0,49.0004285176595,,,,,,,,,,,,,,,,,,,,,,,,,,,,,,,,,
,3755431055.44806,48.9999046325684,399.546997070313,,,5,,,,-2.43000010959804,,,,,0.000773749460802514,1.16728715422498E-7,-0.0156358768214435,9.29661623511076E-5,0.000773648491467368,1.16713483074838E-7,0.000773648462659382,9.19291895091892E-8,-2.11126761313567E-7,7.19100914172977E-8,1.00013051060819,10.005763053894,2,20,10,5,2.53111161147593,0.222550916739873,0.0404026173055172,172.741912841797,48.9991035461426,49.0001792907715,399.546997070313,399.546997070313,,,8.48294639587402,0,1,,,,,,1,1,1,48.9999389648438,0,48.9996945998248,,,,,,,,,,,,,,,,,,,,,,,,,,,,,,,,,
,3755431260.37562,49.000617980957,399.546997070313,,,5,,,,-2.43000010959804,,,,,0.000774284255021926,1.26220528880376E-7,-0.0201927478646722,9.28705666013545E-5,0.000774183279443177,1.26204068270631E-7,0.00077418323136374,1.03731661107006E-7,-2.72845357408097E-7,7.18833035693221E-8,1.00013042851923,10.005763053894,2,20,10,5,2.53287875023842,0.222503290154911,0.0404026173055172,172.741912841797,48.9998245239258,49.0008201599121,399.546997070313,399.546997070313,,,8.47011947631836,0,1,,,,,,1,1,1,49.0004653930664,0,49.0003033806296,,,,,,,,,,,,,,,,,,,,,,,,,,,,,,,,,
,3755431465.26021,49.0002212524414,399.546997070313,,,5,,,,-2.43000010959804,,,,,0.000774128103286083,1.32646049638786E-7,-0.0193237224041605,0.000118712416194739,0.000774027162123592,1.3262875347502E-7,0.000774027118102327,9.56523966087144E-8,-2.61050392502116E-7,9.18749436535713E-8,1.0001304103621,10.005763053894,2,20,10,5,2.53236456398706,0.222496829028202,0.0404026173055172,172.741912841797,48.9997253417969,49.0006561279297,399.546997070313,399.546997070313,,,8.45869255065918,0,1,,,,,,1,1,1,48.9999504089355,0,49.0001063627355,,,,,,,,,,,,,,,,,,,,,,,,,,,,,,,,,
,3755431667.62521,49.0012989044189,399.546997070313,,,5,,,,-2.43000010959804,,,,,0.000774206350318703,1.46428007108344E-7,-0.0222119731091608,0.000140525137679583,0.000774105360778621,1.46408906648774E-7,0.000774105302608618,9.80033003089691E-8,-3.000990155419E-7,1.08770037577632E-7,1.00013045968314,10.005763053894,2,20,10,5,2.5326317438878,0.222391643069296,0.0404026173055172,172.741912841797,48.9997482299805,49.0015144348145,399.546997070313,399.546997070313,,,8.4483003616333,0,1,,,,,,1,1,1,49.0014991760254,0,49.0005708582261,,,,,,,,,,,,,,,,,,,,,,,,,,,,,,,,,
,3755431872.62394,49.0006923675537,399.546997070313,,,5,,,,-2.43000010959804,,,,,0.000774231791352388,1.09159839548746E-7,-0.0184838174594928,0.000100658955595298,0.000774130819980351,1.09145603477722E-7,0.000774130779697293,7.64339537428365E-8,-2.49737286754642E-7,7.79141416801475E-8,1.00013043192369,10.005763053894,2,20,10,5,2.53270049141592,0.222563753079679,0.0404026173055172,172.741912841797,48.9996910095215,49.0011711120605,399.546997070313,399.546997070313,,,8.4391040802002,0,1,,,,,,1,1,1,49.0009880065918,0,49.0003581327551,,,,,,,,,,,,,,,,,,,,,,,,,,,,,,,,,
,3755432077.52211,49.0013790130615,399.546997070313,,,5,,,,-2.43000010959804,,,,,0.000774265898127919,1.44951416104164E-7,-0.0173411712358194,0.000108600017575958,0.000774164897982279,1.44932507723758E-7,0.000774164862524211,1.18067459458893E-7,-2.34309158018254E-7,8.40565691187768E-8,1.00013046334948,10.005763053894,2,20,10,5,2.53280762394028,0.222624066535802,0.0404026173055172,172.741912841797,48.9995193481445,49.0016021728516,399.546997070313,399.546997070313,,,8.43093585968018,0,1,,,,,,1,1,1,49.001579284668,0,49.0004710029153,,,,,,,,,,,,,,,,,,,,,,,,,,,,,,,,,
,3755432282.47865,49.0011463165283,399.546997070313,,,5,,,,-2.43000010959804,,,,,0.000774301824682102,1.80043583584979E-7,-0.0146741989010808,0.000153817793128426,0.000774200828094022,1.80020099477015E-7,0.000774200802702592,1.35018500677099E-7,-1.98282961034495E-7,1.19068218642183E-7,1.00013045269963,10.005763053894,2,20,10,5,2.53291478222152,0.222752299682955,0.0404026173055172,172.741912841797,48.9998207092285,49.0014038085937,399.546997070313,399.546997070313,,,8.42379665374756,0,1,,,,,,1,1,1,49.0010833740234,0,49.0004595588235,,,,,,,,,,,,,,,,,,,,,,,,,,,,,,,,,
,3755432488.63993,48.9999160766602,399.546997070313,,,5,,,,-2.43000010959804,,,,,0.000774450635647953,1.59912569709508E-7,-0.019850222205231,9.68907247761433E-5,0.00077434957440847,1.59891702062482E-7,0.000774349527936344,1.41209696423743E-7,-2.68274747977389E-7,7.50011868196225E-8,1.00013051113195,10.005763053894,2,20,10,5,2.533421692381,0.222566250750222,0.0404026173055172,172.741912841797,48.9992256164551,49.0001907348633,399.546997070313,399.546997070313,,,8.41739940643311,0,1,,,,,,1,1,1,48.9997863769531,0,48.9999024868011,,,,,,,,,,,,,,,,,,,,,,,,,,,,,,,,,
,3755432695.14854,48.9998111724854,399.546997070313,,,5,,,,-2.43000010959804,,,,,0.000774169911871756,1.33385241838592E-7,-0.0150760665764542,0.000115726836032452,0.000774068890981016,1.33367836491606E-7,0.00077406886418437,9.88158515465624E-8,-2.03678422733818E-7,8.95678920907455E-8,1.00013050633079,10.005763053894,2,20,10,5,2.53248482738229,0.222696593900247,0.0404026173055172,172.741912841797,48.9992790222168,49.0002708435059,399.546997070313,399.546997070313,,,8.41118431091309,0,1,,,,,,1,1,1,48.9998245239258,0,48.999833948472,,,,,,,,,,,,,,,,,,,,,,,,,,,,,,,,,
,3755432899.89441,49.0001926422119,399.546997070313,,,5,,,,-2.43000010959804,,,,,0.000774365108295158,1.60918050752167E-7,-0.0165758610110069,0.000153958873264024,0.000774264137242483,1.60897068317906E-7,0.000774264104840911,1.08078677108248E-7,-2.23997206334896E-7,1.19192559112673E-7,1.0001304090527,10.005763053894,2,20,10,5,2.5331291892085,0.22268643354803,0.0404026173055172,172.741912841797,48.9993286132812,49.0003814697266,399.546997070313,399.546997070313,,,8.40615558624268,0,1,,,,,,1,1,1,49.0003242492676,0,48.9998292361989,,,,,,,,,,,,,,,,,,,,,,,,,,,,,,,,,
,3755433104.83171,49.0001068115234,399.546997070313,,,5,,,,-2.43000010959804,,,,,0.000774429206034028,1.37695954974661E-7,-0.0276892260567045,0.000109157892777521,0.000774328229664855,1.37678001057796E-7,0.000774328139243407,1.08689168727396E-7,-3.74208165783238E-7,8.45097424952787E-8,1.00013040512447,10.005763053894,2,20,10,5,2.5333820169552,0.222213485602862,0.0404026173055172,172.741912841797,48.9998359680176,49.000373840332,399.546997070313,399.546997070313,,,8.40086650848389,0,1,,,,,,1,1,1,48.999870300293,0,49.0001097785102,,,,,,,,,,,,,,,,,,,,,,,,,,,,,,,,,
,3755433309.75488,49.0004444122314,399.546997070313,,,5,,,,-2.43000010959804,,,,,0.00077440408674021,1.67453223346567E-7,-0.01238004108854,0.000171244801004392,0.000774303012854569,1.67431367640694E-7,0.000774302994779504,1.02247286273986E-7,-1.67305569816728E-7,1.32584898535387E-7,1.00013053531236,10.005763053894,2,20,10,5,2.53324038168934,0.22288315452072,0.0404026173055172,172.741912841797,48.9993438720703,49.0005416870117,399.546997070313,399.546997070313,,,8.39727210998535,0,1,,,,,,1,1,1,49.0003623962402,0,48.9998406802907,,,,,,,,,,,,,,,,,,,,,,,,,,,,,,,,,
,3755433514.70593,49.0004463195801,399.546997070313,,,5,,,,-2.43000010959804,,,,,0.000774257987109771,1.39099123266575E-7,-0.0183215805864023,0.000154748701726716,0.000774157021037991,1.39080984232431E-7,0.000774156981457638,7.06628530513498E-8,-2.4755366147891E-7,1.19792659932507E-7,1.00013042066278,10.005763053894,2,20,10,5,2.53278555370265,0.222578457076364,0.0404026173055172,172.741912841797,48.9994049072266,49.0006217956543,399.546997070313,399.546997070313,,,8.394606590271,0,1,,,,,,1,1,1,49.0005683898926,0,49.0000994065229,,,,,,,,,,,,,,,,,,,,,,,,,,,,,,,,,
,3755433719.8006,49.0008277893066,399.546997070313,,,5,,,,-2.43000010959804,,,,,0.000774416883306109,1.44468615286405E-7,-0.0202253893386315,9.91979624917343E-5,0.000774315882996842,1.44449773529287E-7,0.000774315834753578,1.22347470233261E-7,-2.73333219524053E-7,7.67908432053165E-8,1.00013043812155,10.005763053894,2,20,10,5,2.53331273760434,0.222539959023762,0.0404026173055172,172.741912841797,48.9997673034668,49.001106262207,399.546997070313,399.546997070313,,,8.39125537872314,0,1,,,,,,1,1,1,49.0006446838379,0,49.0003980000814,,,,,,,,,,,,,,,,,,,,,,,,,,,,,,,,,
,3755433924.71452,48.9996356964111,399.546997070313,,,5,,,,-2.43000010959804,,,,,0.000774445592303171,1.60837289242114E-7,-0.0225254898546625,0.00012609278183937,0.000774344541657061,1.60816302988002E-7,0.000774344481814873,1.27796303639473E-7,-3.04428874447933E-7,9.76216578573452E-8,1.00013049829975,10.005763053894,2,20,10,5,2.53341558355105,0.222446511600449,0.0404026173055172,172.741912841797,48.9995613098145,49.0001449584961,399.546997070313,399.546997070313,,,8.38806056976318,0,1,,,,,,1,1,1,48.9996070861816,0,48.9997935824924,,,,,,,,,,,,,,,,,,,,,,,,,,,,,,,,,
,3755434128.72011,48.9997501373291,399.546997070313,,,5,,,,-2.43000010959804,,,,,0.000774319251559797,1.59553638689574E-7,-0.0140858990033221,0.000139354588237832,0.000774218213344247,1.59532819092353E-7,0.000774218189947404,1.17530894548157E-7,-1.90337919171766E-7,1.07875897188684E-7,1.00013050353739,10.005763053894,2,20,10,5,2.53296950147469,0.222783327877011,0.0404026173055172,172.741912841797,48.9995384216309,49.0001029968262,399.546997070313,399.546997070313,,,8.38473129272461,0,1,,,,,,1,1,1,48.9995765686035,0,48.9997895184685,,,,,,,,,,,,,,,,,,,,,,,,,,,,,,,,,
,3755434334.60669,48.9996719360352,399.546997070313,,,5,,,,-2.43000010959804,,,,,0.000774642175761698,9.95580543952058E-8,-0.0177152527975091,8.47848081726373E-5,0.000774541098180655,9.95450637685314E-8,0.000774541061158312,7.48200070833812E-8,-2.39479962648516E-7,6.56596242810128E-8,1.00013049995834,10.005763053894,2,20,10,5,2.53403997087747,0.222715720693499,0.0404026173055172,172.741912841797,48.9995193481445,49.0004386901855,399.546997070313,399.546997070313,,,8.38299560546875,0,1,,,,,,1,1,1,48.9998245239258,0,48.9999872095445,,,,,,,,,,,,,,,,,,,,,,,,,,,,,,,,,
,3755434539.53829,48.9999694824219,399.546997070313,,,5,,,,-2.43000010959804,,,,,0.0007745379781682,1.43688214422962E-7,-0.0178840820045973,0.000141089165995628,0.00077443690363838,1.43669463607478E-7,0.000774436865912092,9.32974161014352E-8,-2.4172972223884E-7,1.09254322212241E-7,1.00013051357618,10.005763053894,2,20,10,5,2.53369977181776,0.222678296664764,0.0404026173055172,172.741912841797,48.9992294311523,49.0001106262207,399.546997070313,399.546997070313,,,8.3812894821167,0,1,,,,,,1,1,1,48.999942779541,0,48.9997611045837,,,,,,,,,,,,,,,,,,,,,,,,,,,,,,,,,
,3755434744.5242,49.0011501312256,399.546997070313,,,5,,,,-2.43000010959804,,,,,0.000774438731287129,1.87803628208844E-7,-0.017719903442889,0.000108076283245302,0.00077433771670637,1.87779131881372E-7,0.000774337679674312,1.6811615721576E-7,-2.39479931507978E-7,8.36538107507817E-8,1.00013045287422,10.005763053894,2,20,10,5,2.53337447397735,0.222657016503481,0.0404026173055172,172.741912841797,48.9996948242188,49.0012130737305,399.546997070313,399.546997070313,,,8.3786792755127,0,1,,,,,,1,1,1,49.001293182373,0,49.000410416547,,,,,,,,,,,,,,,,,,,,,,,,,,,,,,,,,
,3755434949.53856,49.0000591278076,399.546997070313,,,5,,,,-2.43000010959804,,,,,0.000774380867376786,1.71250190932217E-7,-0.0192947986213792,0.000126604159924457,0.000774279898999927,1.71227862315197E-7,0.000774279855096015,1.40405874344321E-7,-2.60744762919263E-7,9.80059757496397E-8,1.00013040294213,10.005763053894,2,20,10,5,2.53319130553893,0.222570755962335,0.0404026173055172,172.741912841797,48.9992408752441,49.0004920959473,399.546997070313,399.546997070313,,,8.37882709503174,0,1,,,,,,1,1,1,49.0000190734863,0,48.9997984942268,,,,,,,,,,,,,,,,,,,,,,,,,,,,,,,,,
,3755435154.47324,49.0016021728516,399.546997070313,,,5,,,,-2.43000010959804,,,,,0.000774581095383614,9.95202884177561E-8,-0.0244158073416658,8.17634736736721E-5,0.000774480046212619,9.95073053450969E-8,0.000774479975892897,7.67659932410429E-8,-3.30033995290524E-7,6.33141856044798E-8,1.00013047356286,10.005763053894,2,20,10,5,2.53386618954699,0.222401825818938,0.0404026173055172,172.741912841797,48.9996109008789,49.0021553039551,399.546997070313,399.546997070313,,,8.37710189819336,0,1,,,,,,1,1,1,49.0015678405762,0,49.0006298738367,,,,,,,,,,,,,,,,,,,,,,,,,,,,,,,,,
,3755435359.43472,49.000171661377,399.546997070313,,,5,,,,-2.43000010959804,,,,,0.000774372091343924,1.54170100009537E-7,-0.022566235747365,0.000112617408997004,0.00077427103129825,1.54149979918017E-7,0.000774270971245073,1.27130955768022E-7,-3.04950597083989E-7,8.71776140659643E-8,1.00013052282933,10.005763053894,2,20,10,5,2.53317530107399,0.222423594316164,0.0404026173055172,172.741912841797,48.9998664855957,49.0012092590332,399.546997070313,399.546997070313,,,8.37553405761719,0,1,,,,,,1,1,1,49.0004653930664,0,49.0006194644504,,,,,,,,,,,,,,,,,,,,,,,,,,,,,,,,,
,3755435564.43457,49.0001201629639,399.546997070313,,,5,,,,-2.43000010959804,,,,,0.000774393496417499,1.84613728164361E-7,-0.0203398898498577,0.000173845019422461,0.000774292524231361,1.84589656614419E-7,0.000774292475441791,1.26326052528147E-7,-2.74872328424237E-7,1.34592235220629E-7,1.00013040573553,10.005763053894,2,20,10,5,2.53323667790101,0.222528176082966,0.0404026173055172,172.741912841797,48.999454498291,49.0008201599121,399.546997070313,399.546997070313,,,8.37494277954102,0,1,,,,,,1,1,1,49.0006294250488,0,49.0001667870416,,,,,,,,,,,,,,,,,,,,,,,,,,,,,,,,,
,3755435769.4105,49.0004539489746,399.546997070313,,,5,,,,-2.43000010959804,,,,,0.000774406545544915,1.3066830935371E-7,-0.0221859410837313,9.08125645393879E-5,0.000774305559830239,1.30651269682904E-7,0.000774305501781495,1.10125996010556E-7,-2.99824825631147E-7,7.02994969572192E-8,1.00013042101196,10.005763053894,2,20,10,5,2.53328653350296,0.222450304082838,0.0404026173055172,172.741912841797,48.9997825622559,49.0008201599121,399.546997070313,399.546997070313,,,8.37435150146484,0,1,,,,,,1,1,1,49.0006790161133,0,49.0002448138069,,,,,,,,,,,,,,,,,,,,,,,,,,,,,,,,,
,3755435974.37379,48.9999694824219,399.546997070313,,,5,,,,-2.43000010959804,,,,,0.000774591416532401,1.5151106666828E-7,-0.0186998689316562,0.000133174545557491,0.000774490423880066,1.5149131237698E-7,0.00077449038263064,1.10968982442165E-7,-2.52773751947185E-7,1.03128573448148E-7,1.00013039883931,10.005763053894,2,20,10,5,2.53387775194417,0.222657583368173,0.0404026173055172,172.741912841797,48.999397277832,49.0002326965332,399.546997070313,399.546997070313,,,8.37396621704102,0,1,,,,,,1,1,1,48.9997177124023,0,48.9997899672564,,,,,,,,,,,,,,,,,,,,,,,,,,,,,,,,,
,3755436179.31527,49.000659942627,399.546997070313,,,5,,,,-2.43000010959804,,,,,0.000774386500964879,1.25296987652596E-7,-0.0168958264985042,9.1768728185364E-5,0.000774285510565288,1.25280647242691E-7,0.000774285476899812,1.03192393568616E-7,-2.28327349211258E-7,7.1039217923112E-8,1.00013043043969,10.005763053894,2,20,10,5,2.5332004131901,0.222678439143006,0.0404026173055172,172.741912841797,48.9996109008789,49.0009956359863,399.546997070313,399.546997070313,,,8.37338638305664,0,1,,,,,,1,1,1,49.0002861022949,0,49.0002110799154,,,,,,,,,,,,,,,,,,,,,,,,,,,,,,,,,
,3755436384.25882,48.9999980926514,399.546997070313,,,5,,,,-2.43000010959804,,,,,0.000774419496375718,1.58548744469681E-7,-0.0186747055609233,0.000149217876152253,0.000774318436293596,1.58528054198825E-7,0.000774318395164245,1.08554427738151E-7,-2.52377551628381E-7,1.15529564123249E-7,1.00013051488559,10.005763053894,2,20,10,5,2.53331526160291,0.222609274366485,0.0404026173055172,172.741912841797,48.9992752075195,49.0008583068848,399.546997070313,399.546997070313,,,8.37361907958984,0,1,,,,,,1,1,1,49.0003471374512,0,48.9999955121209,,,,,,,,,,,,,,,,,,,,,,,,,,,,,,,,,
,3755436589.24405,48.9999961853027,399.546997070313,,,5,,,,-2.43000010959804,,,,,0.000774399277752387,1.0888114247462E-7,-0.0166641251231665,9.40420480041009E-5,0.000774298220376334,1.08866933728723E-7,0.000774298187627335,8.0939868160458E-8,-2.25199872568958E-7,7.28062291405199E-8,1.0001305147983,10.005763053894,2,20,10,5,2.53324130838503,0.222692359104214,0.0404026173055172,172.741912841797,48.9994850158691,49.0004577636719,399.546997070313,399.546997070313,,,8.37246990203857,0,1,,,,,,1,1,1,48.999927520752,0,48.9998823801676,,,,,,,,,,,,,,,,,,,,,,,,,,,,,,,,,
,3755436794.16555,49.00022315979,399.546997070313,,,5,,,,-2.43000010959804,,,,,0.000774531872053929,1.24672394104242E-7,-0.0214744825035087,0.000120792983226892,0.000774430878175078,1.24656137641312E-7,0.000774430823780851,8.24019512982948E-8,-2.90257015359879E-7,9.35364692186062E-8,1.0001304104494,10.005763053894,2,20,10,5,2.53369374617334,0.222517769156647,0.0404026173055172,172.741912841797,48.999942779541,49.0005912780762,399.546997070313,399.546997070313,,,8.37259960174561,0,1,,,,,,1,1,1,49.0000038146973,0,49.0002611945657,,,,,,,,,,,,,,,,,,,,,,,,,,,,,,,,,
,3755436999.14814,48.9998893737793,399.546997070313,,,5,,,,-2.43000010959804,,,,,0.000774549700932733,1.26435692646617E-7,-0.019610820137923,0.000100019643835605,0.000774448627712156,1.26419193689047E-7,0.000774448582348415,9.99194832163803E-8,-2.65073144595521E-7,7.74461710271098E-8,1.00013050990984,10.005763053894,2,20,10,5,2.5337448297758,0.222605305633487,0.0404026173055172,172.741912841797,48.9988899230957,49.0005569458008,399.546997070313,399.546997070313,,,8.37282943725586,0,1,,,,,,1,1,1,49.0002212524414,0,48.9997699961943,,,,,,,,,,,,,,,,,,,,,,,,,,,,,,,,,
,3755437203.9759,49.0007095336914,399.546997070313,,,5,,,,-2.43000010959804,,,,,0.000774581919428123,1.63896848369628E-7,-0.0174248413804197,0.000148313470042445,0.000774480901785775,1.63875473647606E-7,0.000774480865970103,1.16894116695427E-7,-2.35535789414868E-7,1.1485180166294E-7,1.00013043270933,10.005763053894,2,20,10,5,2.53384172917665,0.222711239663591,0.0404026173055172,172.741912841797,48.9993286132812,49.0020217895508,399.546997070313,399.546997070313,,,8.3727331161499,0,1,,,,,,1,1,1,48.9998207092285,0,49.0000483194987,,,,,,,,,,,,,,,,,,,,,,,,,,,,,,,,,
,3755437408.94505,49.0005970001221,399.546997070313,,,5,,,,-2.43000010959804,,,,,0.000774491179984795,1.01547210880074E-7,-0.0192346239909078,8.770414206827E-5,0.000774390178164147,1.01533968052465E-7,0.000774390134527439,7.5483096908504E-8,-2.59968600585318E-7,6.79076486824601E-8,1.000130427559,10.005763053894,2,20,10,5,2.53355193175258,0.222605120563317,0.0404026173055172,172.741912841797,48.9997901916504,49.000846862793,399.546997070313,399.546997070313,,,8.37268829345703,0,1,,,,,,1,1,1,49.0004692077637,0,49.000209596422,,,,,,,,,,,,,,,,,,,,,,,,,,,,,,,,,
,3755437613.78122,49.0009174346924,399.546997070313,,,5,,,,-2.43000010959804,,,,,0.000774489015957642,1.81415657893722E-7,-0.0248121558506744,0.000192988917306319,0.000774388003064,1.81391996718188E-7,0.00077438793045134,1.02818584288375E-7,-3.35351667847899E-7,1.49436927157732E-7,1.00013044222437,10.005763053894,2,20,10,5,2.53356651052993,0.222357864913383,0.0404026173055172,172.741912841797,49.0002822875977,49.0011558532715,399.546997070313,399.546997070313,,,8.37303066253662,0,1,,,,,,1,1,1,49.0007781982422,0,49.0006648169623,,,,,,,,,,,,,,,,,,,,,,,,,,,,,,,,,
,3755437818.72252,49.0000381469727,399.546997070313,,,5,,,,-2.43000010959804,,,,,0.0007745997716453,1.21707619424003E-7,-0.0187800934890321,8.1178326656166E-5,0.000774498775470004,1.21691750578547E-7,0.000774498733865441,1.04202397788744E-7,-2.53860917394458E-7,6.28549318188147E-8,1.00013040198189,10.005763053894,2,20,10,5,2.53390539547724,0.222656435395774,0.0404026173055172,172.741912841797,48.9995536804199,49.0004005432129,399.546997070313,399.546997070313,,,8.37314987182617,0,1,,,,,,1,1,1,49.0000991821289,0,49.0001218459185,,,,,,,,,,,,,,,,,,,,,,,,,,,,,,,,,
,3755438024.07987,49.0010261535645,399.546997070313,,,5,,,,-2.43000010959804,,,,,0.000774546393036276,1.28513136784468E-7,-0.0199185236437538,0.000112485359188609,0.000774445368806273,1.28496374792151E-7,0.000774445322008002,9.44699146911167E-8,-2.69231140753111E-7,8.71019721532073E-8,1.00013044720012,10.005763053894,2,20,10,5,2.53373520446421,0.222590745511053,0.0404026173055172,172.741912841797,48.999683380127,49.0014724731445,399.546997070313,399.546997070313,,,8.37372779846191,0,1,,,,,,1,1,1,49.0006980895996,0,49.0003729926215,,,,,,,,,,,,,,,,,,,,,,,,,,,,,,,,,
,3755438178.03717,49.0001544952393,399.546997070313,,,5,,,,-2.43000010959804,,,,,0.000774152677290591,1.28769235934681E-7,-0.0213119378404398,9.70018659651845E-5,0.000774051735288453,1.28752445674994E-7,0.00077405168174078,1.04603009775036E-7,-2.87918974618085E-7,7.50693187214062E-8,1.00013040730682,10.005763053894,2,20,10,5,2.53245267105338,0.222416015334942,0.0404026173055172,172.741912841797,48.9989738464355,49.0008544921875,399.546997070313,399.546997070313,,,8.37334442138672,0,1,,,,,,1,1,1,48.9995956420898,0,48.9996786678539,,,,,,,,,,,,,,,,,,,,,,,,,,,,,,,,,