File: Experimental_Data/Fig3B/Lifetime_300Oe.dat
[Header]
; MPMS3 Data File (default extension .dat)
; Copyright (c) 2007, Quantum Design, Inc. All rights reserved.
TITLE,300Oe
FILEOPENTIME,3754834273.222,12/24/2018,5:30 pm
BYAPP,SQUID AC,0.9.1.0
INFO,MPMS3 Measurement Release 1.1.16 Build 347, MultiVu Release 2.3.3.2,APPNAME
INFO,0,MOMENT_UNITS
INFO,CoIINO3,SAMPLE_MATERIAL
INFO,40 Hours Pumped Turbo,SAMPLE_COMMENT
INFO,,SAMPLE_MASS
INFO,,SAMPLE_VOLUME
INFO,,SAMPLE_MOLECULAR_WEIGHT
INFO,,SAMPLE_SIZE
INFO,,SAMPLE_SHAPE
INFO,Brass,SAMPLE_HOLDER
INFO,Standard,SAMPLE_HOLDER_DETAIL
INFO,65.37,SAMPLE_OFFSET
DATATYPE,COMMENT,1
DATATYPE,TIME,2
STARTUPAXIS,X,2
STARTUPAXIS,Y1,5
FIELDGROUP, VSM,2,3,4,5,6,8,9,10,11,14,15
FIELDGROUP, DC, 2,3,4,14,56,57,58,59,60,61,62,63,64,65,66,67,68,69
FIELDGROUP, AC, 2,3,4,11,16,17,18,19,20,21,22,23,24,25,26,27,28,29,30
STARTUPGROUP, All
[Data]
Comment,Time Stamp (sec),Temperature (K),Magnetic Field (Oe),Moment (emu),M. Std. Err. (emu),Transport Action,Averaging Time (sec),Frequency (Hz),Peak Amplitude (mm),Center Position (mm),Lockin Signal' (V),Lockin Signal (V),Range,M. Quad. Signal (emu),AC Moment (emu),AC M. Std Err. (emu),AC Phase (deg),AC Phase Std. Err. (deg),AC Susceptibility (emu/Oe),AC Suscept. Std Err. (emu/Oe),AC X' (emu/Oe),AC X' Std Err. (emu/Oe),AC X'' (emu/Oe),AC X'' Std Err. (emu/Oe),AC Drive (Oe),AC Frequency (Hz),AC Averaging Time (sec),AC Cycles,AC Range,AC Measure Type,AC Signal' (V),AC Signal'' (V),AC Trim Coil Ratio,AC Trim Coil Phase,Min. Temperature (K),Max. Temperature (K),Min. Field (Oe),Max. Field (Oe),Mass (grams),Motor Lag (deg),Pressure (Torr),Measure Count,Measurement Number,SQUID Status (code),Motor Status (code),Measure Status (code),Motor Current (amps),Motor Temp. (C),Temp. Status (code),Field Status (code),Chamber Status (code),Chamber Temp (K),Redirection State,Average Temp (K),Rotation Angle (deg),Rotator state,DC Moment Fixed Ctr (emu),DC Moment Err Fixed Ctr (emu),DC Moment Free Ctr (emu),DC Moment Err Free Ctr (emu),DC Fixed Fit,DC Free Fit,DC Calculated Center (mm),DC Calculated Center Err (mm),DC Scan Length (mm),DC Scan Time (s),DC Number of Points,DC Squid Drift,DC Min V (V),DC Max V (V),DC Scans per Measure,Map 01,Map 02,Map 03,Map 04,Map 05,Map 06,Map 07,Map 08,Map 09,Map 10,Map 11,Map 12,Map 13,Map 14,Map 15,Map 16
,3754834277.00701,48.9800643920898,299.696685791016,,,5,,,,-2.43999995291233,,,,,0.000673484413219554,1.50496285431591E-7,0.0328327328217508,0.000166490949747404,0.000673396984708003,1.50476748726701E-7,0.000673396874144966,1.00378445214026E-7,3.85882908998792E-7,1.12104503227005E-7,1.00012983205083,10.005763053894,2,20,10,5,2.20297178252839,0.195340333373004,0.0404026173055172,172.741912841797,48.9168853759766,48.9930229187012,299.696685791016,299.696685791016,,,71.0707931518555,0,1,,,,,,1,1,1,48.9738006591797,0,48.9505725187414,,,,,,,,,,,,,,,,,,,,,,,,,,,,,,,,,
,3754834481.95806,48.99853515625,299.696685791016,,,5,,,,-2.43999995291233,,,,,0.000681058172143348,1.58115398029926E-7,-0.00921341470247494,0.000115453744603984,0.000680969341101599,1.5809477489361E-7,0.000680969332297326,1.37174930321425E-7,-1.09502880762246E-7,7.85938696080895E-8,1.00013044793119,10.005763053894,2,20,10,5,2.2278899663259,0.195902089817306,0.0404026173055172,172.741912841797,48.9983978271484,49.0004043579102,299.696685791016,299.696685791016,,,71.3319778442383,0,1,,,,,,1,1,1,48.9986114501953,0,48.9990052117242,,,,,,,,,,,,,,,,,,,,,,,,,,,,,,,,,
,3754834686.80746,49.0011005401611,299.696685791016,,,5,,,,-2.43999995291233,,,,,0.000685207700593596,1.0130905306182E-7,-0.00636525751464845,0.000110673802291851,0.000685118326493699,1.01295838958387E-7,0.000685118322265822,6.71757190927433E-8,-7.61130157269462E-8,7.58173446821793E-8,1.00013045060458,10.005763053894,2,20,10,5,2.24145418030608,0.197207088300682,0.0404026173055172,172.741912841797,48.9993705749512,49.0013771057129,299.696685791016,299.696685791016,,,71.6055908203125,0,1,,,,,,1,1,1,49.0009803771973,0,49.0003547668457,,,,,,,,,,,,,,,,,,,,,,,,,,,,,,,,,
,3754834891.70298,49.0009613037109,299.696685791016,,,5,,,,-2.43999995291233,,,,,0.000687469924499326,1.09392732602987E-7,-0.0044565938747132,0.000106566431553472,0.000687380259709171,1.09378464813134E-7,0.00068738025762982,8.12368037674983E-8,-5.34659738983089E-8,7.32409057734744E-8,1.00013044423212,10.005763053894,2,20,10,5,2.2488477837133,0.197933086703184,0.0404026173055172,172.741912841797,48.9997177124023,49.0014991760254,299.696685791016,299.696685791016,,,71.8418960571289,0,1,,,,,,1,1,1,49.0006446838379,0,49.000271903144,,,,,,,,,,,,,,,,,,,,,,,,,,,,,,,,,
,3754835096.67476,49.0006332397461,299.696685791016,,,5,,,,-2.43999995291233,,,,,0.000689565283152439,8.11066590085259E-8,-0.009863269096825,9.21160874753247E-5,0.000689475276323373,8.10960724065437E-8,0.000689475266107271,5.04329422245629E-8,-1.18690769375856E-7,6.35066240508915E-8,1.00013054395445,10.005763053894,2,20,10,5,2.25572083402037,0.198323513125061,0.0404026173055172,172.741912841797,48.9996147155762,49.0010261535645,299.696685791016,299.696685791016,,,72.0160140991211,0,1,,,,,,1,1,1,49.0008239746094,0,49.0001970178941,,,,,,,,,,,,,,,,,,,,,,,,,,,,,,,,,
,3754835301.70541,49.0006046295166,299.696685791016,,,5,,,,-2.43999995291233,,,,,0.00069124231022496,7.76862926496938E-8,-0.00413281488005879,6.9363603606268E-5,0.000691152164693891,7.76761615104332E-8,0.000691152162895888,6.11240556258894E-8,-4.9853653662267E-8,4.79315750923969E-8,1.00013042790817,10.005763053894,2,20,10,5,2.26118686607143,0.199031993219983,0.0404026173055172,172.741912841797,48.9996719360352,49.0010299682617,299.696685791016,299.696685791016,,,71.9165191650391,0,1,,,,,,1,1,1,49.0003776550293,0,49.0002071156221,,,,,,,,,,,,,,,,,,,,,,,,,,,,,,,,,
,3754835506.58511,49.0008945465088,299.696685791016,,,5,,,,-2.43999995291233,,,,,0.00069274730081191,1.22665533115111E-7,-0.00399335346093732,9.87831716191992E-5,0.000692656949824229,1.22649534565483E-7,0.000692656948141871,1.01802066095413E-7,-4.82762264356992E-8,6.84050266269582E-8,1.00013044117684,10.005763053894,2,20,10,5,2.26610949521797,0.199470843357076,0.0404026173055172,172.741912841797,48.9995918273926,49.001277923584,299.696685791016,299.696685791016,,,72.1155166625977,0,1,,,,,,1,1,1,49.0011901855469,0,49.0004384657916,,,,,,,,,,,,,,,,,,,,,,,,,,,,,,,,,
,3754835711.45701,49.0002117156982,299.696685791016,,,5,,,,-2.43999995291233,,,,,0.000694208551674404,7.52662886232127E-8,-0.014058758318872,8.27033984179324E-5,0.000694117952162961,7.52564657984133E-8,0.000694117931267501,4.86693099985199E-8,-1.70316845660506E-7,5.74006438007076E-8,1.0001305246625,10.005763053894,2,20,10,5,2.27092460803705,0.199492660956931,0.0404026173055172,172.741912841797,48.9989929199219,49.0004806518555,299.696685791016,299.696685791016,,,72.3518218994141,0,1,,,,,,1,1,1,49.0004806518555,0,48.9999001446892,,,,,,,,,,,,,,,,,,,,,,,,,,,,,,,,,
,3754835919.50507,49.0000438690186,299.696685791016,,,5,,,,-2.43999995291233,,,,,0.000695246170369323,9.06933874575965E-8,-0.0114995289886188,8.86916015916136E-5,0.000695155440780116,9.06815519752328E-8,0.000695155426778867,6.65049741241826E-8,-1.39520923829172E-7,6.16460240841097E-8,1.00013051698064,10.005763053894,2,20,10,5,2.2743099840097,0.199892427510181,0.0404026173055172,172.741912841797,48.9994888305664,49.0004577636719,299.696685791016,299.696685791016,,,72.5508117675781,0,1,,,,,,1,1,1,48.9998970031738,0,48.9999277451459,,,,,,,,,,,,,,,,,,,,,,,,,,,,,,,,,
,3754836124.64346,48.9999694824219,299.696685791016,,,5,,,,-2.43999995291233,,,,,0.000696117478906337,1.33498478490916E-7,-0.00472890065033482,0.000156549174337134,0.000696026637980697,1.33481057400762E-7,0.000696026635610028,7.71096442080123E-8,-5.74464793957268E-8,1.08955474644184E-7,1.00013051357618,10.005763053894,2,20,10,5,2.2771365678268,0.200412028966703,0.0404026173055172,172.741912841797,48.9995536804199,49.0013999938965,299.696685791016,299.696685791016,,,72.7249298095703,0,1,,,,,,1,1,1,49.0002136230469,0,49.0003395080566,,,,,,,,,,,,,,,,,,,,,,,,,,,,,,,,,
,3754836329.77213,49.0008697509766,299.696685791016,,,5,,,,-2.43999995291233,,,,,0.00069712518534133,1.15036710470419E-7,-0.00234537419139169,8.25592262238843E-5,0.000697034264162624,1.1502170703412E-7,0.000697034263578637,9.96029117513873E-8,-2.85327503547253E-8,5.7526107635476E-8,1.00013044004202,10.005763053894,2,20,10,5,2.28042462186369,0.20079701133932,0.0404026173055172,172.741912841797,49.0000305175781,49.0010299682617,299.696685791016,299.696685791016,,,72.911491394043,0,1,,,,,,1,1,1,49.0008850097656,0,49.0005407894359,,,,,,,,,,,,,,,,,,,,,,,,,,,,,,,,,
,3754836534.8753,49.0007286071777,299.696685791016,,,5,,,,-2.43999995291233,,,,,0.000697991637758645,8.8667404857137E-8,-0.0100122739258151,7.87794939125416E-5,0.000697900528017783,8.86558309874194E-8,0.000697900517362041,6.9556712562979E-8,-1.21956124575054E-7,5.49701746904719E-8,1.00013054831914,10.005763053894,2,20,10,5,2.28328582905817,0.200741050611933,0.0404026173055172,172.741912841797,48.9996719360352,49.0008811950684,299.696685791016,299.696685791016,,,73.0482940673828,0,1,,,,,,1,1,1,49.0007209777832,0,49.0003626206342,,,,,,,,,,,,,,,,,,,,,,,,,,,,,,,,,
,3754836740.42945,49.0000133514404,299.696685791016,,,5,,,,-2.43999995291233,,,,,0.000698645145467912,1.63895548204033E-7,-0.0107332661489599,0.000134202378810768,0.000698553973288175,1.63874160072338E-7,0.000698553961031053,1.34425326919059E-7,-1.3086069749955E-7,9.37260466578977E-8,1.00013051558394,10.005763053894,2,20,10,5,2.28542612606998,0.200900241816539,0.0404026173055172,172.741912841797,48.9988784790039,49.0002479553223,299.696685791016,299.696685791016,,,73.2224197387695,0,1,,,,,,1,1,1,49.000057220459,0,48.9996681213379,,,,,,,,,,,,,,,,,,,,,,,,,,,,,,,,,
,3754836945.38667,49.000171661377,299.696685791016,,,5,,,,-2.43999995291233,,,,,0.000699423658818906,9.83345087099914E-8,-0.00701823651159117,7.87427892026138E-5,0.000699332379978029,9.83216754867223E-8,0.000699332374731593,8.14632411044456E-8,-8.56621564858109E-8,5.50535395708151E-8,1.00013052282933,10.005763053894,2,20,10,5,2.2879597735729,0.201272459004091,0.0404026173055172,172.741912841797,48.9994697570801,49.000373840332,299.696685791016,299.696685791016,,,73.3716583251953,0,1,,,,,,1,1,1,49.000129699707,0,49.0000381469727,,,,,,,,,,,,,,,,,,,,,,,,,,,,,,,,,
,3754837150.61323,48.9997711181641,299.696685791016,,,5,,,,-2.43999995291233,,,,,0.000700180021737884,1.02555942046828E-7,-0.009583398666269,9.9366053885953E-5,0.000700088657019412,1.02542559781579E-7,0.000700088647226386,7.5346001242905E-8,-1.17098130572331E-7,6.95554215231489E-8,1.00013050449762,10.005763053894,2,20,10,5,2.29044301184903,0.20138757428077,0.0404026173055172,172.741912841797,48.9989051818848,48.9998741149902,299.696685791016,299.696685791016,,,73.5084686279297,0,1,,,,,,1,1,1,48.9997406005859,0,48.9995245092055,,,,,,,,,,,,,,,,,,,,,,,,,,,,,,,,,
,3754837355.66261,48.9999885559082,299.696685791016,,,5,,,,-2.43999995291233,,,,,0.000700919520434785,9.50071650974817E-8,-0.00830585444143495,8.04433416158821E-5,0.000700828052247619,9.49947669078095E-8,0.00070082804488377,7.6465588527413E-8,-1.01595192866279E-7,5.6365055761752E-8,1.00013051444912,10.005763053894,2,20,10,5,2.29285757928326,0.201651394369162,0.0404026173055172,172.741912841797,48.9996109008789,49.0004844665527,299.696685791016,299.696685791016,,,73.65771484375,0,1,,,,,,1,1,1,49.0000152587891,0,49.0000661962173,,,,,,,,,,,,,,,,,,,,,,,,,,,,,,,,,
,3754837560.57845,49.0008068084717,299.696685791016,,,5,,,,-2.43999995291233,,,,,0.000701532959330201,1.33504499191795E-7,-0.0110072203908498,0.000141607064783341,0.000701441465296635,1.33487087515027E-7,0.000701441452352545,8.91880447920259E-8,-1.3475548841333E-7,9.93191582697923E-8,1.00013043716132,10.005763053894,2,20,10,5,2.29487378241404,0.201719677886636,0.0404026173055172,172.741912841797,48.9994697570801,49.0011863708496,299.696685791016,299.696685791016,,,73.8069610595703,0,1,,,,,,1,1,1,49.0005569458008,0,49.0002649095323,,,,,,,,,,,,,,,,,,,,,,,,,,,,,,,,,
,3754837765.53432,49.0006427764893,299.696685791016,,,5,,,,-2.43999995291233,,,,,0.00070191458282301,1.4874516219367E-7,-0.00532418584626715,0.000186467825362857,0.000701823044286141,1.48725763943731E-7,0.000701823041256028,7.06714369958479E-8,-6.5216606621812E-8,1.30862144463508E-7,1.00013042965405,10.005763053894,2,20,10,5,2.29610212914784,0.202057158385648,0.0404026173055172,172.741912841797,48.9990348815918,49.0016136169434,299.696685791016,299.696685791016,,,73.9437713623047,0,1,,,,,,1,1,1,49.000072479248,0,48.9997830110438,,,,,,,,,,,,,,,,,,,,,,,,,,,,,,,,,
,3754837970.3926,49.0013179779053,299.696685791016,,,5,,,,-2.43999995291233,,,,,0.000702676477717803,1.16884412276519E-7,-0.00552419818714789,0.000112870161432322,0.000702584818111741,1.16869165460205E-7,0.000702584814846148,8.58576351918621E-8,-6.77400291173463E-8,7.92897743383469E-8,1.00013046055608,10.005763053894,2,20,10,5,2.29859514529239,0.202268453439846,0.0404026173055172,172.741912841797,49.0001258850098,49.0015258789063,299.696685791016,299.696685791016,,,74.0681381225586,0,1,,,,,,1,1,1,49.0011100769043,0,49.0008630191579,,,,,,,,,,,,,,,,,,,,,,,,,,,,,,,,,
,3754838175.46171,48.9999694824219,299.696685791016,,,5,,,,-2.43999995291233,,,,,0.000703085576114467,1.00997475144035E-7,-0.00839498802622263,0.000100715678909645,0.000702993825876219,1.00984295322514E-7,0.000702993818330226,7.20144113630673E-8,-1.03002782749044E-7,7.07937317692438E-8,1.00013051357618,10.005763053894,2,20,10,5,2.29994352532085,0.202270978384015,0.0404026173055172,172.741912841797,48.9992599487305,49.0006065368652,299.696685791016,299.696685791016,,,74.2173843383789,0,1,,,,,,1,1,1,49.0006217956543,0,48.9998348460478,,,,,,,,,,,,,,,,,,,,,,,,,,,,,,,,,
,3754838380.33982,48.9998722076416,299.696685791016,,,5,,,,-2.43999995291233,,,,,0.000703708694198889,1.11930122955474E-7,-0.00726879409147241,9.8300422206199E-5,0.000703616865777969,1.11915516959372E-7,0.000703616860115762,8.79941523372616E-8,-8.9263923911539E-8,6.915281693995E-8,1.00013050912419,10.005763053894,2,20,10,5,2.30197789799675,0.202495493947926,0.0404026173055172,172.741912841797,48.9992523193359,49.0001068115234,299.696685791016,299.696685791016,,,74.3417587280273,0,1,,,,,,1,1,1,48.9998397827148,0,48.9997702205882,,,,,,,,,,,,,,,,,,,,,,,,,,,,,,,,,
,3754838586.85572,48.9994316101074,299.696685791016,,,5,,,,-2.43999995291233,,,,,0.000704131814391383,2.0998332918428E-7,-0.00639700122868181,0.000116494229569583,0.000704039944951655,2.0995593225318E-7,0.000704039940563571,1.93295661360514E-7,-7.86051681609744E-8,8.19651193344053E-8,1.00013048895931,10.005763053894,2,20,10,5,2.30335892875438,0.202652300518837,0.0404026173055172,172.741912841797,48.9989051818848,49.0002670288086,299.696685791016,299.696685791016,,,74.4661254882813,0,1,,,,,,1,1,1,48.9987258911133,0,48.9997379078585,,,,,,,,,,,,,,,,,,,,,,,,,,,,,,,,,
,3754838791.75721,49.0009880065918,299.696685791016,,,5,,,,-2.43999995291233,,,,,0.000704506262157359,1.3371099877857E-7,-0.0094209158795282,0.000134290683467568,0.000704414293692554,1.33693543723951E-7,0.000704414284170314,9.44862497726415E-8,-1.15824024591494E-7,9.45849472028721E-8,1.00013056019111,10.005763053894,2,20,10,5,2.30459452271641,0.202638427710214,0.0404026173055172,172.741912841797,48.999755859375,49.001163482666,299.696685791016,299.696685791016,,,74.6153717041016,0,1,,,,,,1,1,1,49.0013008117676,0,49.000452153823,,,,,,,,,,,,,,,,,,,,,,,,,,,,,,,,,
,3754838997.57402,49.0002021789551,299.696685791016,,,5,,,,-2.43999995291233,,,,,0.000704961217697385,9.366091235331E-8,-0.00401517387183148,9.01566124680509E-5,0.000704869296052558,9.36486996742245E-8,0.000704869294321777,6.87952354135341E-8,-4.93958333807781E-8,6.3539708333211E-8,1.00013040948917,10.005763053894,2,20,10,5,2.30606364055639,0.202986865131262,0.0404026173055172,172.741912841797,48.9999580383301,49.0010070800781,299.696685791016,299.696685791016,,,74.7273025512695,0,1,,,,,,1,1,1,49.0002517700195,0,49.000291038962,,,,,,,,,,,,,,,,,,,,,,,,,,,,,,,,,
,3754839202.51945,49.0008144378662,299.696685791016,,,5,,,,-2.43999995291233,,,,,0.000705342454704367,1.27420224953285E-7,-0.00789107714183057,0.000114349789873194,0.00070525046358962,1.27403606743994E-7,0.000705250456900936,9.86422295663892E-8,-9.71308156062896E-8,8.06311946925625E-8,1.0001304375105,10.005763053894,2,20,10,5,2.30732447407395,0.202940551193314,0.0404026173055172,172.741912841797,48.999927520752,49.0013389587402,299.696685791016,299.696685791016,,,74.839241027832,0,1,,,,,,1,1,1,49.0011596679687,0,49.000415802002,,,,,,,,,,,,,,,,,,,,,,,,,,,,,,,,,
,3754839407.39243,48.9989757537842,299.696685791016,,,5,,,,-2.43999995291233,,,,,0.000705714148330356,1.31736695957746E-7,-0.00621275210269268,0.000122088428903395,0.000705622087160098,1.31719510763961E-7,0.000705622083011848,9.96536376146541E-8,-7.6512705375073E-8,8.61346737734835E-8,1.00013046809607,10.005763053894,2,20,10,5,2.30853441326417,0.203115123858654,0.0404026173055172,172.741912841797,48.998104095459,49.000057220459,299.696685791016,299.696685791016,,,74.9760513305664,0,1,,,,,,1,1,1,48.9994888305664,0,48.9993034811581,,,,,,,,,,,,,,,,,,,,,,,,,,,,,,,,,
,3754839612.35673,48.9996528625488,299.696685791016,,,5,,,,-2.43999995291233,,,,,0.000706008821994934,1.51401391856971E-7,-0.0134724502717845,0.000198636534825186,0.00070591670051115,1.51381636691837E-7,0.000705916680996024,5.7060899231456E-8,-1.65988274124943E-7,1.4021573986681E-7,1.0001304990854,10.005763053894,2,20,10,5,2.30952407891788,0.202907305410784,0.0404026173055172,172.741912841797,48.9992179870605,49.0003280639648,299.696685791016,299.696685791016,,,75.1004180908203,0,1,,,,,,1,1,1,48.9999389648438,0,48.9999122619629,,,,,,,,,,,,,,,,,,,,,,,,,,,,,,,,,
,3754839817.29529,49.0007266998291,299.696685791016,,,5,,,,-2.43999995291233,,,,,0.000706474286042055,1.73966223422351E-7,-0.00444316689164914,0.000117953434373385,0.000706382069111922,1.73943515403974E-7,0.000706382066987946,1.52707293078306E-7,-5.4778439980389E-8,8.32876292842399E-8,1.00013054823185,10.005763053894,2,20,10,5,2.31101469753452,0.203405274354201,0.0404026173055172,172.741912841797,48.9996871948242,49.0008697509766,299.696685791016,299.696685791016,,,75.2372283935547,0,1,,,,,,1,1,1,49.0005836486816,0,49.000348259421,,,,,,,,,,,,,,,,,,,,,,,,,,,,,,,,,
,3754840022.29819,49.0001335144043,299.696685791016,,,5,,,,-2.43999995291233,,,,,0.000706783038383121,8.6398193957477E-8,-0.00613873652401775,9.13914768951285E-5,0.000706690800334194,8.63869186432594E-8,0.000706690796278062,5.73778544873771E-8,-7.57156749723333E-8,6.45792654580594E-8,1.00013052108345,10.005763053894,2,20,10,5,2.31203070737265,0.203425750013127,0.0404026173055172,172.741912841797,48.9996490478516,49.0003395080566,299.696685791016,299.696685791016,,,75.386474609375,0,1,,,,,,1,1,1,49.0002517700195,0,49.0000711328843,,,,,,,,,,,,,,,,,,,,,,,,,,,,,,,,,
,3754840227.26656,49.000036239624,299.696685791016,,,5,,,,-2.43999995291233,,,,,0.000707128147198558,9.04231607468374E-8,-0.00842674437778523,9.43620397885883E-5,0.000707035867258837,9.04113605606107E-8,0.00070703585961193,6.10239454175997E-8,-1.03986900055632E-7,6.67105104469346E-8,1.00013051663147,10.005763053894,2,20,10,5,2.31316775388401,0.203432706949681,0.0404026173055172,172.741912841797,48.9998626708984,49.0014877319336,299.696685791016,299.696685791016,,,75.498405456543,0,1,,,,,,1,1,1,49.0002098083496,0,49.0008010864258,,,,,,,,,,,,,,,,,,,,,,,,,,,,,,,,,
,3754840432.23235,49.0006523132324,299.696685791016,,,5,,,,-2.43999995291233,,,,,0.000708002175039535,1.26855403931379E-7,-0.0105660189811401,0.000150656398537603,0.000707909842294726,1.26838860327345E-7,0.000707909830257526,6.86656045260817E-8,-1.30546941708315E-7,1.06644883816372E-7,1.00013043009052,10.005763053894,2,20,10,5,2.31603448972054,0.203597680408027,0.0404026173055172,172.741912841797,48.9993743896484,49.0014343261719,299.696685791016,299.696685791016,,,75.6352157592773,0,1,,,,,,1,1,1,49.0001754760742,0,49.0001826816135,,,,,,,,,,,,,,,,,,,,,,,,,,,,,,,,,
,3754840637.11414,49.000904083252,299.696685791016,,,5,,,,-2.43999995291233,,,,,0.000707794096278293,1.404229787053E-7,-0.0115725514344733,0.000131304744498124,0.000707701782516041,1.40404664094399E-7,0.000707701768080493,1.05266614435433E-7,-1.42940986096192E-7,9.29107614044948E-8,1.00013044161331,10.005763053894,2,20,10,5,2.31535739275856,0.20349716657294,0.0404026173055172,172.741912841797,48.9999389648438,49.001033782959,299.696685791016,299.696685791016,,,75.7471466064453,0,1,,,,,,1,1,1,49.0008506774902,0,49.000452153823,,,,,,,,,,,,,,,,,,,,,,,,,,,,,,,,,
,3754840840.9616,49.000940322876,299.696685791016,,,5,,,,-2.43999995291233,,,,,0.000708211486815474,1.87631925972598E-7,-0.00905196031542399,0.000202322043089242,0.000708119117440906,1.87607453842487E-7,0.000708119108603672,1.21138278756859E-7,-1.11873268458453E-7,1.43255276192839E-7,1.00013044327189,10.005763053894,2,20,10,5,2.31671381344167,0.203719087886098,0.0404026173055172,172.741912841797,48.999382019043,49.0010757446289,299.696685791016,299.696685791016,,,75.8839569091797,0,1,,,,,,1,1,1,49.0010223388672,0,49.0004234313965,,,,,,,,,,,,,,,,,,,,,,,,,,,,,,,,,
,3754841047.10562,48.9999809265137,299.696685791016,,,5,,,,-2.43999995291233,,,,,0.00070841530366407,1.13335478894768E-7,-0.0108844713844434,0.000140822826329287,0.000708322857543848,1.13320688947045E-7,0.000708322844762676,5.37850143321337E-8,-1.34559995396358E-7,9.97434247292781E-8,1.00013051409994,10.005763053894,2,20,10,5,2.31738705859272,0.20370360316225,0.0404026173055172,172.741912841797,48.9992637634277,49.0001945495605,299.696685791016,299.696685791016,,,75.9958877563477,0,1,,,,,,1,1,1,48.9999465942383,0,48.9997771768009,,,,,,,,,,,,,,,,,,,,,,,,,,,,,,,,,
,3754841252.05255,48.9994049072266,299.696685791016,,,5,,,,-2.43999995291233,,,,,0.000708667714494326,1.12547636173373E-7,-0.00886061371955549,0.000110295342640741,0.000708575254112785,1.12532952003106E-7,0.000708575245639763,8.09778196120048E-8,-1.09578954091554E-7,7.8142549340414E-8,1.00013048773719,10.005763053894,2,20,10,5,2.31820555188949,0.203858073117485,0.0404026173055172,172.741912841797,48.9990234375,49.0003356933594,299.696685791016,299.696685791016,,,76.1202621459961,0,1,,,,,,1,1,1,48.999080657959,0,48.9995914035373,,,,,,,,,,,,,,,,,,,,,,,,,,,,,,,,,
,3754841456.97453,48.9998416900635,299.696685791016,,,5,,,,-2.43999995291233,,,,,0.000708946579850159,1.31443920465534E-7,-0.0113294762600109,0.000142371701096919,0.000708854068916502,1.31426768256677E-7,0.00070885405505848,8.42009353665416E-8,-1.40166437415049E-7,1.00911832298268E-7,1.00013050772749,10.005763053894,2,20,10,5,2.31912656663443,0.203838359053361,0.0404026173055172,172.741912841797,48.9992752075195,49.0003662109375,299.696685791016,299.696685791016,,,76.2446365356445,0,1,,,,,,1,1,1,48.9998207092285,0,48.9998241223787,,,,,,,,,,,,,,,,,,,,,,,,,,,,,,,,,
,3754841660.62065,48.9997138977051,299.696685791016,,,5,,,,-2.43999995291233,,,,,0.000709210112532706,1.54442411389473E-7,-0.00634095067688456,9.56069684985245E-5,0.000709117571357352,1.54422258994545E-7,0.000709117567014733,1.3875961303203E-7,-7.84783726327291E-8,6.77643258962978E-8,1.0001305018788,10.005763053894,2,20,10,5,2.31997087963013,0.204116121652602,0.0404026173055172,172.741912841797,48.999137878418,49.0003929138184,299.696685791016,299.696685791016,,,76.3690032958984,0,1,,,,,,1,1,1,49.0000343322754,0,48.999885559082,,,,,,,,,,,,,,,,,,,,,,,,,,,,,,,,,
,3754841866.99511,48.9995994567871,299.696685791016,,,5,,,,-2.43999995291233,,,,,0.000709519146248319,1.38282401249993E-7,-0.0109968556034605,0.000104055983595252,0.000709426568463978,1.38264358215652E-7,0.000709426555397178,1.16921517407299E-7,-1.36161189411476E-7,7.37996715437191E-8,1.00013049664117,10.005763053894,2,20,10,5,2.32099837794747,0.20401646041532,0.0404026173055172,172.741912841797,48.999137878418,49.000358581543,299.696685791016,299.696685791016,,,76.4933776855469,0,1,,,,,,1,1,1,48.9995155334473,0,48.9997181362576,,,,,,,,,,,,,,,,,,,,,,,,,,,,,,,,,
,3754842073.82608,49.0001525878906,299.696685791016,,,5,,,,-2.43999995291233,,,,,0.000709796299277352,9.08557764279795E-8,-0.00585988644602331,0.000105168504812979,0.000709703667366228,9.08439193019058E-8,0.000709703663654465,5.17919743078389E-8,-7.25844543731647E-8,7.46338332891145E-8,1.00013052195639,10.005763053894,2,20,10,5,2.32188670077107,0.204304324852402,0.0404026173055172,172.741912841797,48.9996452331543,49.0003471374512,299.696685791016,299.696685791016,,,76.6177444458008,0,1,,,,,,1,1,1,49.0002212524414,0,49.0000269272748,,,,,,,,,,,,,,,,,,,,,,,,,,,,,,,,,
,3754842279.68345,49.0002460479736,299.696685791016,,,5,,,,-2.43999995291233,,,,,0.000709916116981126,9.77914507275196E-8,-0.00636646068639912,0.000113156666885647,0.000709823547829701,9.77786992609816E-8,0.000709823543447712,5.57671590264725E-8,-7.88725407114332E-8,8.03162374821282E-8,1.00013041149692,10.005763053894,2,20,10,5,2.32228045514696,0.204318280662011,0.0404026173055172,172.741912841797,48.9994010925293,49.0005035400391,299.696685791016,299.696685791016,,,76.7421188354492,0,1,,,,,,1,1,1,49.0001640319824,0,48.9998783784754,,,,,,,,,,,,,,,,,,,,,,,,,,,,,,,,,
,3754842484.58443,49.0004825592041,299.696685791016,,,5,,,,-2.43999995291233,,,,,0.000710177171867799,1.45956028840916E-7,-0.00523761026817482,0.00017994502632125,0.00071008456099099,1.45936995399203E-7,0.000710084558024102,7.0513923721341E-8,-6.49113462517745E-8,1.27770862044396E-7,1.00013042232136,10.005763053894,2,20,10,5,2.32313039157806,0.204439183728963,0.0404026173055172,172.741912841797,48.999584197998,49.000804901123,299.696685791016,299.696685791016,,,76.8664855957031,0,1,,,,,,1,1,1,49.000373840332,0,49.0001006656223,,,,,,,,,,,,,,,,,,,,,,,,,,,,,,,,,
,3754842689.60279,49.0002593994141,299.696685791016,,,5,,,,-2.43999995291233,,,,,0.000710504120730338,9.52443495160316E-8,-0.00471948188012572,8.91764209647066E-5,0.000710411392972668,9.52319191940902E-8,0.000710411390562633,7.11115637278758E-8,-5.8516940013225E-8,6.33424339409688E-8,1.00013052684485,10.005763053894,2,20,10,5,2.324198056408,0.204554321115032,0.0404026173055172,172.741912841797,48.9992942810059,49.000431060791,299.696685791016,299.696685791016,,,76.9908599853516,0,1,,,,,,1,1,1,49.0002403259277,0,48.9999508577235,,,,,,,,,,,,,,,,,,,,,,,,,,,,,,,,,
,3754842894.58134,49.0009346008301,299.696685791016,,,5,,,,-2.43999995291233,,,,,0.000710609599732794,8.6955860854759E-8,-0.00916330624376904,9.14777463038875E-5,0.000710516917767378,8.6944519549925E-8,0.000710516908680733,5.77549181804818E-8,-1.13632873772844E-7,6.49901446815834E-8,1.00013044301001,10.005763053894,2,20,10,5,2.32455895959189,0.204404395027713,0.0404026173055172,172.741912841797,48.9992523193359,49.0009994506836,299.696685791016,299.696685791016,,,77.1152267456055,0,1,,,,,,1,1,1,49.0009155273438,0,49.000129924101,,,,,,,,,,,,,,,,,,,,,,,,,,,,,,,,,
,3754843099.47538,49.0015106201172,299.696685791016,,,5,,,,-2.43999995291233,,,,,0.000710297763273909,1.09629257860056E-7,-0.00598461795434435,9.52092211959596E-5,0.000710205103259558,1.09614956465441E-7,0.000710205099385363,8.62842899248945E-8,-7.41818374865663E-8,6.76051772653344E-8,1.00013046937276,10.005763053894,2,20,10,5,2.32352753595715,0.204443601693644,0.0404026173055172,172.741912841797,48.9996490478516,49.0018692016602,299.696685791016,299.696685791016,,,77.2396011352539,0,1,,,,,,1,1,1,49.001148223877,0,49.0005437065573,,,,,,,,,,,,,,,,,,,,,,,,,,,,,,,,,
,3754843302.85669,48.9997291564941,299.696685791016,,,5,,,,-2.43999995291233,,,,,0.000711118931531576,1.21236074375456E-7,-0.00673673588343249,0.000127381565949161,0.000711026222358055,1.21220268726418E-7,0.000711026217443215,8.05774593023219E-8,-8.36011988298475E-8,9.05628323457677E-8,1.00013038784029,10.005763053894,2,20,10,5,2.3262164291541,0.20464942924347,0.0404026173055172,172.741912841797,48.998706817627,49.0003814697266,299.696685791016,299.696685791016,,,77.3515319824219,0,1,,,,,,1,1,1,48.999137878418,0,48.9994895037483,,,,,,,,,,,,,,,,,,,,,,,,,,,,,,,,,
,3754843506.94649,48.9994926452637,299.696685791016,,,5,,,,-2.43999995291233,,,,,0.000711244829834048,1.28819531821189E-7,-0.010360962932789,0.000148044314553866,0.000711152030359161,1.28802724127964E-7,0.000711152018731632,7.42113763244171E-8,-1.28599695275793E-7,1.05274941780179E-7,1.00013049175271,10.005763053894,2,20,10,5,2.32664121117565,0.204538489436601,0.0404026173055172,172.741912841797,48.9992485046387,49.0004272460937,299.696685791016,299.696685791016,,,77.4634704589844,0,1,,,,,,1,1,1,48.9993515014648,0,48.9998038442511,,,,,,,,,,,,,,,,,,,,,,,,,,,,,,,,,
,3754843712.06139,49.0010986328125,299.696685791016,,,5,,,,-2.43999995291233,,,,,0.000711351330275843,9.98674454268515E-8,-0.0102593568455447,0.0001175967867492,0.000711258546230566,9.98544193661923E-8,0.000711258534828265,5.45509094720277E-8,-1.27357638873962E-7,8.36367344097917E-8,1.00013045051728,10.005763053894,2,20,10,5,2.32698923582933,0.20457323629131,0.0404026173055172,172.741912841797,48.9992904663086,49.0017433166504,299.696685791016,299.696685791016,,,77.5878372192383,0,1,,,,,,1,1,1,49.0010147094727,0,49.000324048494,,,,,,,,,,,,,,,,,,,,,,,,,,,,,,,,,
,3754843916.97768,49.0009956359863,299.696685791016,,,5,,,,-2.43999995291233,,,,,0.000711626614116924,1.38626981387407E-7,-0.00501841850996598,0.000142997728932691,0.000711533797519051,1.38608900438029E-7,0.000711533794789734,9.41381128943684E-8,-6.23217696960569E-8,1.01737126858029E-7,1.00013044580341,10.005763053894,2,20,10,5,2.32787102122448,0.204865338140953,0.0404026173055172,172.741912841797,48.9998817443848,49.0013427734375,299.696685791016,299.696685791016,,,77.7122116088867,0,1,,,,,,1,1,1,49.001106262207,0,49.0006150638356,,,,,,,,,,,,,,,,,,,,,,,,,,,,,,,,,
,3754844122.10469,48.999942779541,299.696685791016,,,5,,,,-2.43999995291233,,,,,0.000711731984182534,1.21416392891783E-7,-0.0105058189976752,0.000111015137455476,0.000711639106487501,1.21400548620398E-7,0.000711639094524383,9.21880327512788E-8,-1.30486951500918E-7,7.89902514414448E-8,1.00013051235407,10.005763053894,2,20,10,5,2.32823531997333,0.204672694770782,0.0404026173055172,172.741912841797,48.9997596740723,49.0005798339844,299.696685791016,299.696685791016,,,77.8365859985352,0,1,,,,,,1,1,1,49.0001525878906,0,49.0000960032145,,,,,,,,,,,,,,,,,,,,,,,,,,,,,,,,,
,3754844327.47656,49.0003623962402,299.696685791016,,,5,,,,-2.43999995291233,,,,,0.000711426891207239,1.06720867696213E-7,-0.00872990943177587,0.000131430621630389,0.000711334121271869,1.06706951314753E-7,0.000711334113014953,5.14449143111492E-8,-1.08382894572366E-7,9.34868667268707E-8,1.00013041682185,10.005763053894,2,20,10,5,2.32723095003342,0.204657091893427,0.0404026173055172,172.741912841797,48.9997100830078,49.0005226135254,299.696685791016,299.696685791016,,,77.9609527587891,0,1,,,,,,1,1,1,49.0004005432129,0,49.0001155628878,,,,,,,,,,,,,,,,,,,,,,,,,,,,,,,,,
,3754844532.53943,49.000316619873,299.696685791016,,,5,,,,-2.43999995291233,,,,,0.000712163996438727,9.22506457789022E-8,-0.0056494737880346,7.13649990875288E-5,0.000712071050186454,9.22386059231417E-8,0.000712071046724956,7.69868346730631E-8,-7.02115716186314E-8,5.08034222239711E-8,1.00013052946367,10.005763053894,2,20,10,5,2.32963116249225,0.204994385753728,0.0404026173055172,172.741912841797,48.9996490478516,49.0011253356934,299.696685791016,299.696685791016,,,78.0604476928711,0,1,,,,,,1,1,1,49.0004348754883,0,49.0002355575562,,,,,,,,,,,,,,,,,,,,,,,,,,,,,,,,,
,3754844737.6171,48.9997406005859,299.696685791016,,,5,,,,-2.43999995291233,,,,,0.000712244198977355,9.10823535985341E-8,-0.0103260114322801,0.000102521542955045,0.000712151261029469,9.10704686199773E-8,0.000712151249464029,5.44428941794317E-8,-1.2834596344772E-7,7.30054897115927E-8,1.00013050310092,10.005763053894,2,20,10,5,2.3299102467128,0.204827306554626,0.0404026173055172,172.741912841797,48.9993095397949,49.0002098083496,299.696685791016,299.696685791016,,,78.1599502563477,0,1,,,,,,1,1,1,48.9995727539063,0,48.9997329711914,,,,,,,,,,,,,,,,,,,,,,,,,,,,,,,,,
,3754844942.59683,49.000244140625,299.696685791016,,,5,,,,-2.43999995291233,,,,,0.000712359153930332,1.18796410310443E-7,-0.00711124887845394,0.000136419458012077,0.000712266184569979,1.18780906296467E-7,0.000712266179083941,6.83279082495981E-8,-8.8402708475643E-8,9.71606950100941E-8,1.0001305261465,10.005763053894,2,20,10,5,2.33027479240341,0.204991109654912,0.0404026173055172,172.741912841797,48.9988174438477,49.0006408691406,299.696685791016,299.696685791016,,,78.2594451904297,0,1,,,,,,1,1,1,49.0004081726074,0,48.9997208539177,,,,,,,,,,,,,,,,,,,,,,,,,,,,,,,,,
,3754845147.44731,49.0000667572022,299.696685791016,,,5,,,,-2.43999995291233,,,,,0.000712642606631762,1.29102423399052E-7,-0.00947313298594921,9.98206242126141E-5,0.000712549606062207,1.29085575404285E-7,0.000712549596322921,1.07734027856661E-7,-1.17811070971081E-7,7.1108825185314E-8,1.00013051802817,10.005763053894,2,20,10,5,2.33121047669352,0.204976579055579,0.0404026173055172,172.741912841797,48.9993858337402,49.0004463195801,299.696685791016,299.696685791016,,,78.3465042114258,0,1,,,,,,1,1,1,49.0002861022949,0,48.9998523487764,,,,,,,,,,,,,,,,,,,,,,,,,,,,,,,,,
,3754845352.48268,48.9997291564941,299.696685791016,,,5,,,,-2.43999995291233,,,,,0.000712693075369577,1.03791783074672E-7,-0.00844767256035883,0.000117294923625471,0.00071260007922276,1.03778239746932E-7,0.000712600071477343,6.15187990771365E-8,-1.05065541739857E-7,8.35784685494936E-8,1.00013050257715,10.005763053894,2,20,10,5,2.33137190164976,0.205032822956253,0.0404026173055172,172.741912841797,48.998908996582,49.0000114440918,299.696685791016,299.696685791016,,,78.4584350585938,0,1,,,,,,1,1,1,48.999927520752,0,48.9995341581457,,,,,,,,,,,,,,,,,,,,,,,,,,,,,,,,,
,3754845557.57784,49.0011024475098,299.696685791016,,,5,,,,-2.43999995291233,,,,,0.000712922464970928,1.36532990255863E-7,-0.0114516543243548,0.000157229468126766,0.000712829475872615,1.36515181755952E-7,0.000712829461634686,7.7952777959158E-8,-1.42472565430252E-7,1.12070331748911E-7,1.00013045069187,10.005763053894,2,20,10,5,2.33213303470963,0.204976538122566,0.0404026173055172,172.741912841797,48.999626159668,49.0012245178223,299.696685791016,299.696685791016,,,78.5454940795898,0,1,,,,,,1,1,1,49.0012054443359,0,49.0003399568446,,,,,,,,,,,,,,,,,,,,,,,,,,,,,,,,,
,3754845762.56045,49.0009822845459,299.696685791016,,,5,,,,-2.43999995291233,,,,,0.000713147177882957,1.06760731180913E-7,-0.00765303928752825,0.000117260903064447,0.000713054163395453,1.06746806573196E-7,0.000713054157034603,6.63686626847707E-8,-9.5243167241112E-8,8.36067062322777E-8,1.00013044519236,10.005763053894,2,20,10,5,2.33285452295969,0.2051958143118,0.0404026173055172,172.741912841797,48.9996681213379,49.0014343261719,299.696685791016,299.696685791016,,,78.6698684692383,0,1,,,,,,1,1,1,49.0005302429199,0,49.0003350201775,,,,,,,,,,,,,,,,,,,,,,,,,,,,,,,,,
,3754845967.49362,49.000394821167,299.696685791016,,,5,,,,-2.43999995291233,,,,,0.000713119532275693,1.13328183879752E-7,-0.0105309053473404,0.00011360289682647,0.000713026458762494,1.13313392737818E-7,0.000713026446718743,7.92473121105678E-8,-1.31053529054185E-7,8.09925212411934E-8,1.00013053304271,10.005763053894,2,20,10,5,2.33277439172885,0.205070687902286,0.0404026173055172,172.741912841797,48.999439239502,49.0007476806641,299.696685791016,299.696685791016,,,78.7693634033203,0,1,,,,,,1,1,1,49.0007629394531,0,49.0000870648552,,,,,,,,,,,,,,,,,,,,,,,,,,,,,,,,,
,3754846172.42904,48.9999446868897,299.696685791016,,,5,,,,-2.43999995291233,,,,,0.000713323137488683,1.72165260631623E-7,-0.00908789733941528,0.000192592178424483,0.000713230052093333,1.72142793855334E-7,0.000713230043121499,1.03766443559642E-7,-1.13128078904166E-7,1.37352344964706E-7,1.00013051244136,10.005763053894,2,20,10,5,2.33343526295586,0.205188009343704,0.0404026173055172,172.741912841797,48.9994316101074,49.0003776550293,299.696685791016,299.696685791016,,,78.8688659667969,0,1,,,,,,1,1,1,49.0000915527344,0,48.9999205645393,,,,,,,,,,,,,,,,,,,,,,,,,,,,,,,,,
,3754846377.38196,49.0001983642578,299.696685791016,,,5,,,,-2.43999995291233,,,,,0.000713431212985589,1.06680204094536E-7,-0.00660334761855097,0.00012234693834899,0.000713338187041554,1.06666293816271E-7,0.000713338182304062,6.13334653753879E-8,-8.2212338294813E-8,8.72691483947518E-8,1.00013040931458,10.005763053894,2,20,10,5,2.33377990027114,0.205320297846554,0.0404026173055172,172.741912841797,48.9994621276855,49.0004653930664,299.696685791016,299.696685791016,,,78.9807968139648,0,1,,,,,,1,1,1,49.0002670288086,0,49.0000489178826,,,,,,,,,,,,,,,,,,,,,,,,,,,,,,,,,
,3754846582.28701,48.9997596740723,299.696685791016,,,5,,,,-2.43999995291233,,,,,0.000713637458966103,1.07888124288368E-7,-0.0102199630052029,8.08622943606649E-5,0.000713544338594395,1.0787404629665E-7,0.000713544327243128,9.11564563377187E-8,-1.27276332852261E-7,5.76828426168597E-8,1.00013050397385,10.005763053894,2,20,10,5,2.33446753233157,0.205232300199658,0.0404026173055172,172.741912841797,48.9988136291504,49.0001907348633,299.696685791016,299.696685791016,,,79.0802917480469,0,1,,,,,,1,1,1,48.9998474121094,0,48.9995420119342,,,,,,,,,,,,,,,,,,,,,,,,,,,,,,,,,
,3754846787.11258,49.0000476837158,299.696685791016,,,5,,,,-2.43999995291233,,,,,0.000713433993035023,8.16225486771268E-8,-0.00562686887075792,8.76207392056268E-5,0.000713340889811376,8.16118969245074E-8,0.0007133408863714,5.2483337962259E-8,-7.00553456952235E-8,6.2498007615889E-8,1.00013051715523,10.005763053894,2,20,10,5,2.33378549475698,0.205360872648706,0.0404026173055172,172.741912841797,48.9993591308594,49.0004692077637,299.696685791016,299.696685791016,,,79.1797866821289,0,1,,,,,,1,1,1,49.0001411437988,0,49.0000292460124,,,,,,,,,,,,,,,,,,,,,,,,,,,,,,,,,
,3754846992.16092,49.0005016326904,299.696685791016,,,5,,,,-2.43999995291233,,,,,0.000713856959504094,1.00157649088751E-7,-0.00381273205689858,8.01907277757108E-5,0.000713763786256091,1.00144576422927E-7,0.000713763784675746,8.21853322001523E-8,-4.74972168985336E-8,5.72233113169623E-8,1.00013053793117,10.005763053894,2,20,10,5,2.33516259569009,0.20555655836446,0.0404026173055172,172.741912841797,48.9994239807129,49.0006904602051,299.696685791016,299.696685791016,,,79.2917251586914,0,1,,,,,,1,1,1,49.0006408691406,0,49.000129699707,,,,,,,,,,,,,,,,,,,,,,,,,,,,,,,,,
,3754847197.93533,49.0006370544434,299.696685791016,,,5,,,,-2.43999995291233,,,,,0.000714017803416043,1.20981603662434E-7,-0.00847065494029842,0.000124023383891942,0.00071392468665311,1.20965826163255E-7,0.000713924678851017,8.24285314969794E-8,-1.05547209643753E-7,8.85339951352604E-8,1.00013042939217,10.005763053894,2,20,10,5,2.33570545386762,0.205412990667651,0.0404026173055172,172.741912841797,48.9995193481445,49.0011329650879,299.696685791016,299.696685791016,,,79.3912200927734,0,1,,,,,,1,1,1,49.0006370544434,0,49.0003176795112,,,,,,,,,,,,,,,,,,,,,,,,,,,,,,,,,
,3754847404.5334,49.0010299682617,299.696685791016,,,5,,,,-2.43999995291233,,,,,0.000714286017409251,1.30866505007797E-7,-0.00930900650534738,0.000141843209134203,0.000714192852826568,1.30849436042384E-7,0.000714192843400146,8.28307513121824E-8,-1.16036921746861E-7,1.01294824890857E-7,1.0001304473747,10.005763053894,2,20,10,5,2.33658584587539,0.205455963212219,0.0404026173055172,172.741912841797,48.9994888305664,49.0014228820801,299.696685791016,299.696685791016,,,79.5031585693359,0,1,,,,,,1,1,1,49.0006370544434,0,49.0003085416906,,,,,,,,,,,,,,,,,,,,,,,,,,,,,,,,,
,3754847609.42175,49.0003490447998,299.696685791016,,,5,,,,-2.43999995291233,,,,,0.000714367361286966,8.73156296092683E-8,-0.00804548313962883,0.000101764191773838,0.000714274208351245,8.73042437206161E-8,0.000714274201309279,4.83650984786851E-8,-1.00298505933831E-7,7.26832045301789E-8,1.00013041621079,10.005763053894,2,20,10,5,2.33684740746545,0.205530895651164,0.0404026173055172,172.741912841797,48.9996147155762,49.0005226135254,299.696685791016,299.696685791016,,,79.590217590332,0,1,,,,,,1,1,1,49.0003700256348,0,49.0000967137954,,,,,,,,,,,,,,,,,,,,,,,,,,,,,,,,,
,3754847814.40168,49.0001239776611,299.696685791016,,,5,,,,-2.43999995291233,,,,,0.000714347981027103,8.56614105255926E-8,-0.00481701300566773,9.26593580318061E-5,0.000714254837974901,8.56502412279335E-8,0.000714254835450644,5.43744910305944E-8,-6.00493591163635E-8,6.61768732078436E-8,1.00013040591012,10.005763053894,2,20,10,5,2.33677242582609,0.205656992963286,0.0404026173055172,172.741912841797,48.9992904663086,49.0003623962402,299.696685791016,299.696685791016,,,79.6897125244141,0,1,,,,,,1,1,1,48.9999504089355,0,48.9998303581687,,,,,,,,,,,,,,,,,,,,,,,,,,,,,,,,,
,3754847968.07082,48.999849319458,299.696685791016,,,5,,,,-2.43999995291233,,,,,0.000714324616440798,1.4027020007368E-7,-0.0101350143879584,8.15580069497065E-5,0.000714231485412024,1.4025191215844E-7,0.000714231474237926,1.27596671623387E-7,-1.26339957406131E-7,5.82210293170134E-8,1.0001303933398,10.005763053894,2,20,10,5,2.33671507331498,0.205433382000203,0.0404026173055172,172.741912841797,48.9995269775391,49.0004806518555,299.696685791016,299.696685791016,,,79.7767715454102,0,1,,,,,,1,1,1,48.9997787475586,0,48.9999222225613,,,,,,,,,,,,,,,,,,,,,,,,,,,,,,,,,