File: Experimental_Data/Fig3B/Lifetime_360Oe.dat
[Header]
; MPMS3 Data File (default extension .dat)
; Copyright (c) 2007, Quantum Design, Inc. All rights reserved.
TITLE,360Oe
FILEOPENTIME,3755388880.4679,12/31/2018,3:34 am
BYAPP,SQUID AC,0.9.1.0
INFO,MPMS3 Measurement Release 1.1.16 Build 347, MultiVu Release 2.3.3.2,APPNAME
INFO,0,MOMENT_UNITS
INFO,CoIINO3,SAMPLE_MATERIAL
INFO,40 Hours Pumped Turbo,SAMPLE_COMMENT
INFO,,SAMPLE_MASS
INFO,,SAMPLE_VOLUME
INFO,,SAMPLE_MOLECULAR_WEIGHT
INFO,,SAMPLE_SIZE
INFO,,SAMPLE_SHAPE
INFO,Brass,SAMPLE_HOLDER
INFO,Standard,SAMPLE_HOLDER_DETAIL
INFO,65.37,SAMPLE_OFFSET
DATATYPE,COMMENT,1
DATATYPE,TIME,2
STARTUPAXIS,X,2
STARTUPAXIS,Y1,5
FIELDGROUP, VSM,2,3,4,5,6,8,9,10,11,14,15
FIELDGROUP, DC, 2,3,4,14,56,57,58,59,60,61,62,63,64,65,66,67,68,69
FIELDGROUP, AC, 2,3,4,11,16,17,18,19,20,21,22,23,24,25,26,27,28,29,30
STARTUPGROUP, All
[Data]
Comment,Time Stamp (sec),Temperature (K),Magnetic Field (Oe),Moment (emu),M. Std. Err. (emu),Transport Action,Averaging Time (sec),Frequency (Hz),Peak Amplitude (mm),Center Position (mm),Lockin Signal' (V),Lockin Signal (V),Range,M. Quad. Signal (emu),AC Moment (emu),AC M. Std Err. (emu),AC Phase (deg),AC Phase Std. Err. (deg),AC Susceptibility (emu/Oe),AC Suscept. Std Err. (emu/Oe),AC X' (emu/Oe),AC X' Std Err. (emu/Oe),AC X'' (emu/Oe),AC X'' Std Err. (emu/Oe),AC Drive (Oe),AC Frequency (Hz),AC Averaging Time (sec),AC Cycles,AC Range,AC Measure Type,AC Signal' (V),AC Signal'' (V),AC Trim Coil Ratio,AC Trim Coil Phase,Min. Temperature (K),Max. Temperature (K),Min. Field (Oe),Max. Field (Oe),Mass (grams),Motor Lag (deg),Pressure (Torr),Measure Count,Measurement Number,SQUID Status (code),Motor Status (code),Measure Status (code),Motor Current (amps),Motor Temp. (C),Temp. Status (code),Field Status (code),Chamber Status (code),Chamber Temp (K),Redirection State,Average Temp (K),Rotation Angle (deg),Rotator state,DC Moment Fixed Ctr (emu),DC Moment Err Fixed Ctr (emu),DC Moment Free Ctr (emu),DC Moment Err Free Ctr (emu),DC Fixed Fit,DC Free Fit,DC Calculated Center (mm),DC Calculated Center Err (mm),DC Scan Length (mm),DC Scan Time (s),DC Number of Points,DC Squid Drift,DC Min V (V),DC Max V (V),DC Scans per Measure,Map 01,Map 02,Map 03,Map 04,Map 05,Map 06,Map 07,Map 08,Map 09,Map 10,Map 11,Map 12,Map 13,Map 14,Map 15,Map 16
,3755388885.08517,48.9762401580811,359.888580322266,,,5,,,,-2.43000010959804,,,,,0.000696726072474662,2.32393340663021E-7,0.00643617507647765,0.00011958388010867,0.000696635508996892,2.32363133168322E-7,0.000696635504601617,2.16944754206625E-7,7.82547707539571E-8,8.32322009682953E-8,1.0001300012368,10.005763053894,2,20,10,5,2.27907912087149,0.201178305671896,0.0404026173055172,172.741912841797,48.9226531982422,48.9869041442871,359.888580322266,359.888580322266,,,11.7670373916626,0,1,,,,,,1,1,1,48.9714469909668,0,48.9504728878246,,,,,,,,,,,,,,,,,,,,,,,,,,,,,,,,,
,3755389090.34258,49.0002670288086,359.888580322266,,,5,,,,-2.43000010959804,,,,,0.000737424353676472,1.1054379275735E-7,-0.0163039478552154,8.83904730217842E-5,0.000737328112306897,1.10529365669392E-7,0.000737328082455058,8.92803259244834E-8,-2.09812293944913E-7,6.51595279149274E-8,1.00013052719403,10.005763053894,2,20,10,5,2.41229267808435,0.211972332531982,0.0404026173055172,172.741912841797,48.9997367858887,49.000358581543,359.888580322266,359.888580322266,,,11.7389059066772,0,1,,,,,,1,1,1,49.000301361084,0,49.0000731524299,,,,,,,,,,,,,,,,,,,,,,,,,,,,,,,,,
,3755389296.84,49.0023422241211,359.888580322266,,,5,,,,-2.43000010959804,,,,,0.000745024689560004,1.26990481156921E-7,-0.0237982759086668,0.000139524886471662,0.000744927556447592,1.26973924684559E-7,0.000744927492189213,7.29476460666696E-8,-3.09411812898273E-7,1.03927948517865E-7,1.000130392696,10.005763053894,2,20,10,5,2.4371831989466,0.213838256822543,0.0404026173055172,172.741912841797,49.0001907348633,49.0031929016113,359.888580322266,359.888580322266,,,11.4249353408813,0,1,,,,,,1,1,1,49.0016174316406,0,49.0011589947869,,,,,,,,,,,,,,,,,,,,,,,,,,,,,,,,,
,3755389503.2107,49.0006942749023,359.888580322266,,,5,,,,-2.43000010959804,,,,,0.000747675790761744,9.94586000822577E-8,-0.0191110689757172,0.000104911897040778,0.000747578282622975,9.94456291888592E-8,0.00074757824103657,6.11491798738285E-8,-2.49355536837989E-7,7.84232807623236E-8,1.00013043201098,10.005763053894,2,20,10,5,2.44583812471478,0.214799273584842,0.0404026173055172,172.741912841797,48.9995269775391,49.0010299682617,359.888580322266,359.888580322266,,,11.1524124145508,0,1,,,,,,1,1,1,49.0004081726074,0,49.0001745784984,,,,,,,,,,,,,,,,,,,,,,,,,,,,,,,,,
,3755389708.55138,48.9998989105225,359.888580322266,,,5,,,,-2.43000010959804,,,,,0.000749435544436136,1.17542339560224E-7,-0.0154779695072333,9.9048065454636E-5,0.000749337834072585,1.17527014553535E-7,0.000749337806730579,9.11360683318988E-8,-2.02427266089945E-7,7.42079254451329E-8,1.00013039560944,10.005763053894,2,20,10,5,2.45158106994208,0.215460290169089,0.0404026173055172,172.741912841797,48.9989624023438,49.0003662109375,359.888580322266,359.888580322266,,,10.9242467880249,0,1,,,,,,1,1,1,48.9994850158691,0,48.9995767929975,,,,,,,,,,,,,,,,,,,,,,,,,,,,,,,,,
,3755389913.76298,48.9998054504395,359.888580322266,,,5,,,,-2.43000010959804,,,,,0.000750531661613042,1.05594758272873E-7,-0.0203709577715481,9.56575987795582E-5,0.000750433725457557,1.05580979314311E-7,0.000750433678026808,7.74317818557312E-8,-2.66809414925247E-7,7.17750816900647E-8,1.00013050606891,10.005763053894,2,20,10,5,2.45518514687904,0.215565749303277,0.0404026173055172,172.741912841797,48.9996719360352,49.0007286071777,359.888580322266,359.888580322266,,,10.7147216796875,0,1,,,,,,1,1,1,48.9999465942383,0,49.0001339631922,,,,,,,,,,,,,,,,,,,,,,,,,,,,,,,,,
,3755390120.40949,48.9997596740723,359.888580322266,,,5,,,,-2.43000010959804,,,,,0.000751309447018622,1.55678743027213E-7,-0.0222629682633944,0.000165925057619156,0.000751211410944289,1.55658428983667E-7,0.000751211354235151,9.32510131460495E-8,-2.91892274129823E-7,1.2463464631032E-7,1.00013050397385,10.005763053894,2,20,10,5,2.45773661050459,0.215707984523031,0.0404026173055172,172.741912841797,48.9993667602539,49.0001945495605,359.888580322266,359.888580322266,,,10.5014820098877,0,1,,,,,,1,1,1,48.999828338623,0,48.99975047392,,,,,,,,,,,,,,,,,,,,,,,,,,,,,,,,,
,3755390329.09885,48.9998950958252,359.888580322266,,,5,,,,-2.43000010959804,,,,,0.000751978829293997,1.2992378963683E-7,-0.0146348181384308,0.000113824159464259,0.000751880787471756,1.29906850376584E-7,0.000751880762944533,9.77428790749684E-8,-1.92049720944391E-7,8.55693833383199E-8,1.00013039543485,10.005763053894,2,20,10,5,2.4598975751636,0.216227674483108,0.0404026173055172,172.741912841797,48.9988212585449,49.0002517700195,359.888580322266,359.888580322266,,,10.2634239196777,0,1,,,,,,1,1,1,48.9997444152832,0,48.9995240105523,,,,,,,,,,,,,,,,,,,,,,,,,,,,,,,,,
,3755390534.38576,49.0002880096436,359.888580322266,,,5,,,,-2.43000010959804,,,,,0.000752427273484268,1.37999492683365E-7,-0.0161471420536765,8.02245765995782E-5,0.000752329073358928,1.3798148221517E-7,0.000752329043482827,1.24093717522641E-7,-2.12021973713773E-7,6.03294182443864E-8,1.00013052815426,10.005763053894,2,20,10,5,2.46137025047452,0.216291651942372,0.0404026173055172,172.741912841797,48.9998054504395,49.0005073547363,359.888580322266,359.888580322266,,,10.0555648803711,0,1,,,,,,1,1,1,49.0003128051758,0,49.0000511618222,,,,,,,,,,,,,,,,,,,,,,,,,,,,,,,,,
,3755390739.44698,48.9995727539063,359.888580322266,,,5,,,,-2.43000010959804,,,,,0.000752584579744117,1.12209441166946E-7,-0.0183178589725594,8.41654567766713E-5,0.000752486383718141,1.1219480025947E-7,0.000752486345261371,9.2619428691024E-8,-2.40575123299573E-7,6.33191490325853E-8,1.00013049541906,10.005763053894,2,20,10,5,2.46189303119513,0.216243601985846,0.0404026173055172,172.741912841797,48.9994049072266,49.0004730224609,359.888580322266,359.888580322266,,,9.87068271636963,0,1,,,,,,1,1,1,48.9997406005859,0,48.9999239304486,,,,,,,,,,,,,,,,,,,,,,,,,,,,,,,,,
,3755390944.50158,48.9996376037598,359.888580322266,,,5,,,,-2.43000010959804,,,,,0.000752827318897353,1.05828862948291E-7,-0.0163572983492442,8.62195476383633E-5,0.00075272908896536,1.05815054254386E-7,0.000752729058290218,8.35844354051649E-8,-2.14895655871052E-7,6.48881180560695E-8,1.00013049838705,10.005763053894,2,20,10,5,2.46267968869078,0.216397616804311,0.0404026173055172,172.741912841797,48.9992141723633,49.0001983642578,359.888580322266,359.888580322266,,,9.70883750915527,0,1,,,,,,1,1,1,49.0000190734863,0,48.9997381322524,,,,,,,,,,,,,,,,,,,,,,,,,,,,,,,,,
,3755391149.7885,48.9997425079346,359.888580322266,,,5,,,,-2.43000010959804,,,,,0.000753296819003034,9.02815379850855E-8,-0.0201511757924955,8.14394631508157E-5,0.000753198524194272,9.02697574939336E-8,0.000753198477610465,6.62346774870502E-8,-2.64903203757185E-7,6.13318564548638E-8,1.00013050318821,10.005763053894,2,20,10,5,2.46422986909638,0.216369403920751,0.0404026173055172,172.741912841797,48.9993782043457,49.0002021789551,359.888580322266,359.888580322266,,,9.56292819976807,0,1,,,,,,1,1,1,48.9997825622559,0,48.999735215131,,,,,,,,,,,,,,,,,,,,,,,,,,,,,,,,,
,3755391354.89178,49.0002479553223,359.888580322266,,,5,,,,-2.43000010959804,,,,,0.000753384120349579,1.06440382978571E-7,-0.018135723198502,7.68993567003303E-5,0.000753285796725805,1.06426491520167E-7,0.000753285758989944,8.92899414902478E-8,-2.38436104487252E-7,5.79129039675981E-8,1.00013052632109,10.005763053894,2,20,10,5,2.46450784118869,0.216481170123135,0.0404026173055172,172.741912841797,48.9992866516113,49.0004043579102,359.888580322266,359.888580322266,,,9.43237209320068,0,1,,,,,,1,1,1,49.000171661377,0,48.9999585151672,,,,,,,,,,,,,,,,,,,,,,,,,,,,,,,,,
,3755391560.16532,49.0003871917725,359.888580322266,,,5,,,,-2.43000010959804,,,,,0.00075324913352994,9.16004263002342E-8,-0.0187968012205388,6.08667959581352E-5,0.000753150909127307,9.15884815176201E-8,0.00075315086859749,7.92984132128974E-8,-2.47083254548584E-7,4.58280657307289E-8,1.00013041795667,10.005763053894,2,20,10,5,2.46406876290543,0.216413949592465,0.0404026173055172,172.741912841797,48.9994926452637,49.0008010864258,359.888580322266,359.888580322266,,,9.3170223236084,0,1,,,,,,1,1,1,49.0007057189941,0,49.0000850453096,,,,,,,,,,,,,,,,,,,,,,,,,,,,,,,,,
,3755391766.44714,49.0001468658447,359.888580322266,,,5,,,,-2.43000010959804,,,,,0.000753973925313387,1.12955835533086E-7,-0.0182834343142879,7.03494442951137E-5,0.000753875528201996,1.12941094270082E-7,0.000753875489818906,9.97245981104814E-8,-2.40566296230567E-7,5.30159910463491E-8,1.00013052169451,10.005763053894,2,20,10,5,2.46643779919204,0.216644289506153,0.0404026173055172,172.741912841797,48.9995613098145,49.0004463195801,359.888580322266,359.888580322266,,,9.21418285369873,0,1,,,,,,1,1,1,49.0000686645508,0,49.0000996589661,,,,,,,,,,,,,,,,,,,,,,,,,,,,,,,,,
,3755391970.3214,49.0000667572022,359.888580322266,,,5,,,,-2.43000010959804,,,,,0.000754477958796396,1.39511915543105E-7,-0.0131837678779885,0.000118429653833888,0.000754379498671738,1.39493709099252E-7,0.000754379478701019,1.07141573412805E-7,-1.73582839768635E-7,8.93262454427318E-8,1.00013051802817,10.005763053894,2,20,10,5,2.46806731381847,0.217008790365258,0.0404026173055172,172.741912841797,48.999683380127,49.0006637573242,359.888580322266,359.888580322266,,,9.12375831604004,0,1,,,,,,1,1,1,49.0000648498535,0,49.0000549765194,,,,,,,,,,,,,,,,,,,,,,,,,,,,,,,,,
,3755392175.3262,49.0001697540283,359.888580322266,,,5,,,,-2.43000010959804,,,,,0.000754205591984382,9.06002269360561E-8,-0.0168958819404619,5.47813411778643E-5,0.000754107250362178,9.05884134817624E-8,0.000754107217573826,8.06286249542683E-8,-2.22377756200939E-7,4.12951025561953E-8,1.00013040800517,10.005763053894,2,20,10,5,2.4671903900713,0.216770604862275,0.0404026173055172,172.741912841797,48.9992828369141,49.0004768371582,359.888580322266,359.888580322266,,,9.04202270507812,0,1,,,,,,1,1,1,49.0000343322754,0,48.9998996959013,,,,,,,,,,,,,,,,,,,,,,,,,,,,,,,,,
,3755392380.24775,49.0011577606201,359.888580322266,,,5,,,,-2.43000010959804,,,,,0.000754538593713274,1.12948972716031E-7,-0.0149865949966808,0.000104527729956598,0.000754440174560646,1.12934240080381E-7,0.000754440148752578,8.08505299347294E-8,-1.97335463668121E-7,7.8850075407742E-8,1.00013045322339,10.005763053894,2,20,10,5,2.46827249219298,0.216948562117036,0.0404026173055172,172.741912841797,48.9997749328613,49.0014572143555,359.888580322266,359.888580322266,,,8.97041797637939,0,1,,,,,,1,1,1,49.000919342041,0,49.0005026424632,,,,,,,,,,,,,,,,,,,,,,,,,,,,,,,,,
,3755392585.26954,49.0010204315186,359.888580322266,,,5,,,,-2.43000010959804,,,,,0.000754678795536878,2.07272677731465E-7,-0.0143135491773814,0.000249052060665998,0.000754580362838894,2.07245643171851E-7,0.000754580339292473,8.73850966533247E-8,-1.88508178285111E-7,1.8792179622546E-7,1.00013044693823,10.005763053894,2,20,10,5,2.46872857609715,0.217017873389175,0.0404026173055172,172.741912841797,48.999568939209,49.0012435913086,359.888580322266,359.888580322266,,,8.90411758422852,0,1,,,,,,1,1,1,49.0009346008301,0,49.0004427433014,,,,,,,,,,,,,,,,,,,,,,,,,,,,,,,,,
,3755392790.20321,49.0006771087646,359.888580322266,,,5,,,,-2.43000010959804,,,,,0.000754700337810687,1.19898504857242E-7,-0.0147678712369999,0.00010687453969221,0.000754601914158381,1.19882868387821E-7,0.000754601889092762,8.87111709497345E-8,-1.94497114356416E-7,8.0636407916143E-8,1.00013043122534,10.005763053894,2,20,10,5,2.4688007664781,0.217004493871488,0.0404026173055172,172.741912841797,48.9995231628418,49.0009727478027,359.888580322266,359.888580322266,,,8.8477144241333,0,1,,,,,,1,1,1,49.0005149841309,0,49.0001887153177,,,,,,,,,,,,,,,,,,,,,,,,,,,,,,,,,
,3755392995.07545,49.0012130737305,359.888580322266,,,5,,,,-2.43000010959804,,,,,0.000754938083586607,1.07657196917279E-7,-0.0185197912536124,6.74843851712876E-5,0.000754839610415391,1.0764315424833E-7,0.000754839570983138,9.48365488192833E-8,-2.43987810100978E-7,5.0922270811281E-8,1.00013045575491,10.005763053894,2,20,10,5,2.46959269789638,0.216911135780992,0.0404026173055172,172.741912841797,48.9999313354492,49.0014343261719,359.888580322266,359.888580322266,,,8.79626178741455,0,1,,,,,,1,1,1,49.0009918212891,0,49.0006132686839,,,,,,,,,,,,,,,,,,,,,,,,,,,,,,,,,
,3755393200.12675,49.0011520385742,359.888580322266,,,5,,,,-2.43000010959804,,,,,0.000754971792697889,8.66362018784842E-8,-0.0187721297970747,6.72318473917139E-5,0.00075487331723809,8.66249014035556E-8,0.000754873276722151,7.02082710819596E-8,-2.47323271599485E-7,5.07412279596957E-8,1.00013045296151,10.005763053894,2,20,10,5,2.46970392438223,0.21690994244661,0.0404026173055172,172.741912841797,49.0000762939453,49.0017395019531,359.888580322266,359.888580322266,,,8.75108432769775,0,1,,,,,,1,1,1,49.0014038085937,0,49.0007468329536,,,,,,,,,,,,,,,,,,,,,,,,,,,,,,,,,
,3755393405.47584,49.0007381439209,359.888580322266,,,5,,,,-2.43000010959804,,,,,0.000754893973853284,1.12495389897735E-7,-0.0190221847055563,9.28848958014998E-5,0.00075479543624834,1.12480705681578E-7,0.000754795394650116,8.79676726580209E-8,-2.50591894577252E-7,7.00970592661132E-8,1.00013054875561,10.005763053894,2,20,10,5,2.46945030551505,0.216876809881125,0.0404026173055172,172.741912841797,48.9995498657227,49.0008811950684,359.888580322266,359.888580322266,,,8.70938587188721,0,1,,,,,,1,1,1,49.0007629394531,0,49.0002004835341,,,,,,,,,,,,,,,,,,,,,,,,,,,,,,,,,
,3755393609.25422,48.9997386932373,359.888580322266,,,5,,,,-2.43000010959804,,,,,0.000755278772311604,1.21337204639213E-7,-0.0105960273615553,0.000131218806380762,0.000755180219017195,1.21321371834572E-7,0.000755180206103174,7.0004396837723E-8,-1.39659679753061E-7,9.908713179424E-8,1.00013050301362,10.005763053894,2,20,10,5,2.47067714108263,0.217350714485671,0.0404026173055172,172.741912841797,48.9994010925293,49.0003280639648,359.888580322266,359.888580322266,,,8.6740026473999,0,1,,,,,,1,1,1,48.9999313354492,0,48.999916749842,,,,,,,,,,,,,,,,,,,,,,,,,,,,,,,,,
,3755393815.31162,49.0008544921875,359.888580322266,,,5,,,,-2.43000010959804,,,,,0.0007556520723966,1.15825860700555E-7,-0.018493832949714,0.000109897921763834,0.000755553518491542,1.15810754421758E-7,0.000755553479132563,8.07409685753697E-8,-2.43876258106026E-7,8.30242544877575E-8,1.00013043934367,10.005763053894,2,20,10,5,2.47192823668854,0.217117402811888,0.0404026173055172,172.741912841797,48.9997100830078,49.001277923584,359.888580322266,359.888580322266,,,8.64164638519287,0,1,,,,,,1,1,1,49.0006217956543,0,49.0002921609318,,,,,,,,,,,,,,,,,,,,,,,,,,,,,,,,,
,3755394020.21267,49.0011119842529,359.888580322266,,,5,,,,-2.43000010959804,,,,,0.00075536939513248,1.01031214788477E-7,-0.0175226168069242,9.22738863511595E-5,0.000755270869195392,1.01018036871584E-7,0.000755270833875009,7.31365388260362E-8,-2.30982490028255E-7,6.96827845449396E-8,1.00013045112834,10.005763053894,2,20,10,5,2.47099984904116,0.21707806629419,0.0404026173055172,172.741912841797,49.0000877380371,49.0011177062988,359.888580322266,359.888580322266,,,8.61270523071289,0,1,,,,,,1,1,1,49.001106262207,0,49.0006251615636,,,,,,,,,,,,,,,,,,,,,,,,,,,,,,,,,
,3755394225.13146,49.0001354217529,359.888580322266,,,5,,,,-2.43000010959804,,,,,0.000755388826410329,8.53416289420764E-8,-0.014331062820272,5.78087377651187E-5,0.000755290245043292,8.53304915064245E-8,0.000755290221417009,7.33214246727548E-8,-1.88916390149109E-7,4.36493008499051E-8,1.00013052117075,10.005763053894,2,20,10,5,2.47105131719192,0.21722129926752,0.0404026173055172,172.741912841797,48.999885559082,49.0013580322266,359.888580322266,359.888580322266,,,8.58765029907227,0,1,,,,,,1,1,1,49.0003852844238,0,49.0006736306583,,,,,,,,,,,,,,,,,,,,,,,,,,,,,,,,,
,3755394430.01164,49.0004463195801,359.888580322266,,,5,,,,-2.43000010959804,,,,,0.000755540674094406,1.30299940155565E-7,-0.0204047455401311,9.53900896911459E-5,0.000755442148828664,1.30282948567064E-7,0.00075544210092284,1.08550295213248E-7,-2.69035601265948E-7,7.20449866156202E-8,1.00013042066278,10.005763053894,2,20,10,5,2.47157106347065,0.217002965577648,0.0404026173055172,172.741912841797,48.9994201660156,49.0007095336914,359.888580322266,359.888580322266,,,8.56530475616455,0,1,,,,,,1,1,1,49.0003395080566,0,49.0000455644396,,,,,,,,,,,,,,,,,,,,,,,,,,,,,,,,,
,3755394634.92101,48.9996585845947,359.888580322266,,,5,,,,-2.43000010959804,,,,,0.00075541325227806,1.38718716282897E-7,-0.0196750924776925,0.000105035317191028,0.000755314684204781,1.38700615943049E-7,0.000755314639671342,1.13782959022349E-7,-2.59371389929837E-7,7.93177098704915E-8,1.00013049934728,10.005763053894,2,20,10,5,2.47115146977577,0.216997842145454,0.0404026173055172,172.741912841797,48.9988021850586,48.9999732971191,359.888580322266,359.888580322266,,,8.54455375671387,0,1,,,,,,1,1,1,48.9993629455566,0,48.9995088016286,,,,,,,,,,,,,,,,,,,,,,,,,,,,,,,,,
,3755394840.23861,49.000301361084,359.888580322266,,,5,,,,-2.43000010959804,,,,,0.000755704843960641,9.37276870484653E-8,-0.0157670866263402,8.1805198608844E-5,0.000755606215614253,9.37154544859003E-8,0.000755606187003903,7.04480959513633E-8,-2.07933439563441E-7,6.1803334750856E-8,1.00013052876531,10.005763053894,2,20,10,5,2.47209052940904,0.217250214873353,0.0404026173055172,172.741912841797,48.9994049072266,49.0004615783691,359.888580322266,359.888580322266,,,8.52652740478516,0,1,,,,,,1,1,1,49.0004577636719,0,49.0000489178826,,,,,,,,,,,,,,,,,,,,,,,,,,,,,,,,,
,3755395044.91609,49.0003929138184,359.888580322266,,,5,,,,-2.43000010959804,,,,,0.000755802386982753,1.19735714074244E-7,-0.0166050531651623,0.000111011503075006,0.000755703742739791,1.19720086657509E-7,0.00075570371100345,8.54212926118566E-8,-2.19012652524955E-7,8.38814754150228E-8,1.00013053295542,10.005763053894,2,20,10,5,2.47241279340897,0.217242096279437,0.0404026173055172,172.741912841797,48.9996185302734,49.000675201416,359.888580322266,359.888580322266,,,8.5102653503418,0,1,,,,,,1,1,1,49.0005912780762,0,49.0001007528866,,,,,,,,,,,,,,,,,,,,,,,,,,,,,,,,,
,3755395249.82545,49.0002365112305,359.888580322266,,,5,,,,-2.43000010959804,,,,,0.000755730082505844,8.04924152589502E-8,-0.0154119973984042,7.10018501053001E-5,0.000755631539795426,8.04819195264772E-8,0.000755631512458312,5.99976118043302E-8,-2.0325740017867E-7,5.36435079804001E-8,1.00013041106046,10.005763053894,2,20,10,5,2.47217174417105,0.217272792075098,0.0404026173055172,172.741912841797,48.9994621276855,49.000358581543,359.888580322266,359.888580322266,,,8.49603843688965,0,1,,,,,,1,1,1,49.0003700256348,0,48.9999717263614,,,,,,,,,,,,,,,,,,,,,,,,,,,,,,,,,
,3755395454.84289,49.0002307891846,359.888580322266,,,5,,,,-2.43000010959804,,,,,0.000756404950666333,1.03442804945002E-7,-0.0162418508200126,8.85007124006228E-5,0.000756306320155155,1.03429316645222E-7,0.000756306289767758,7.88600975248221E-8,-2.14393003569698E-7,6.69231541402013E-8,1.00013041079857,10.005763053894,2,20,10,5,2.474382546896,0.217430979080044,0.0404026173055172,172.741912841797,48.9994506835937,49.000560760498,359.888580322266,359.888580322266,,,8.48297023773193,0,1,,,,,,1,1,1,49.0003280639648,0,49.0000716315375,,,,,,,,,,,,,,,,,,,,,,,,,,,,,,,,,
,3755395658.39403,49.0008716583252,359.888580322266,,,5,,,,-2.43000010959804,,,,,0.000755883101993526,1.02356569168578E-7,-0.01535239944642,8.9754350161106E-5,0.000755784517363349,1.02343219505792E-7,0.000755784490231759,7.66413958854599E-8,-2.02512397348351E-7,6.78250028790183E-8,1.00013044012931,10.005763053894,2,20,10,5,2.47267208124336,0.217319354982745,0.0404026173055172,172.741912841797,49.0001373291016,49.0008888244629,359.888580322266,359.888580322266,,,8.47101211547852,0,1,,,,,,1,1,1,49.0008888244629,0,49.0005309581757,,,,,,,,,,,,,,,,,,,,,,,,,,,,,,,,,
,3755395862.11334,49.0011310577393,359.888580322266,,,5,,,,-2.43000010959804,,,,,0.000756137692662,1.13580183776597E-7,-0.0189344646948939,9.9902080662235E-5,0.000756039065852815,1.13565368946942E-7,0.000756039024569456,8.48172445816275E-8,-2.4984728127353E-7,7.55190574996506E-8,1.00013045200128,10.005763053894,2,20,10,5,2.4735184936989,0.217237909970799,0.0404026173055172,172.741912841797,48.9995040893555,49.0014266967773,359.888580322266,359.888580322266,,,8.460524559021,0,1,,,,,,1,1,1,49.0008354187012,0,49.0003130171034,,,,,,,,,,,,,,,,,,,,,,,,,,,,,,,,,
,3755396065.42992,49.0005531311035,359.888580322266,,,5,,,,-2.43000010959804,,,,,0.00075631070326158,1.74390996085812E-7,-0.0184417273428767,0.000169999603003458,0.000756212073884992,1.74368254010164E-7,0.000756212034713371,1.17818377318727E-7,-2.43401115364818E-7,1.28542280874953E-7,1.00013042555124,10.005763053894,2,20,10,5,2.47408258646669,0.217308893960286,0.0404026173055172,172.741912841797,48.9999351501465,49.0008773803711,359.888580322266,359.888580322266,,,8.45223903656006,0,1,,,,,,1,1,1,49.0005416870117,0,49.0003007253011,,,,,,,,,,,,,,,,,,,,,,,,,,,,,,,,,
,3755396272.02643,49.0000076293945,359.888580322266,,,5,,,,-2.43000010959804,,,,,0.000756203591751375,8.70374359683249E-8,-0.013497432924205,7.72065040938269E-5,0.000756104908475736,8.70260777317623E-8,0.000756104887495558,6.45501742253466E-8,-1.78119143820888E-7,5.83679125277933E-8,1.00013051532206,10.005763053894,2,20,10,5,2.47371343860582,0.21749158704814,0.0404026173055172,172.741912841797,48.9996223449707,49.0002975463867,359.888580322266,359.888580322266,,,8.44354057312012,0,1,,,,,,1,1,1,49.0002708435059,0,48.9999459210564,,,,,,,,,,,,,,,,,,,,,,,,,,,,,,,,,
,3755396476.95868,49.0004100799561,359.888580322266,,,5,,,,-2.43000010959804,,,,,0.000756174465523423,1.34509928045662E-7,-0.013415053524322,0.00012935492926072,0.000756075772124358,1.34492372253167E-7,0.000756075751400297,9.23310827844765E-8,-1.77025200547346E-7,9.77914584518027E-8,1.00013053374107,10.005763053894,2,20,10,5,2.47361784744127,0.217486766267854,0.0404026173055172,172.741912841797,48.9999504089355,49.0007019042969,359.888580322266,359.888580322266,,,8.4377498626709,0,1,,,,,,1,1,1,49.0003471374512,0,49.0002780241125,,,,,,,,,,,,,,,,,,,,,,,,,,,,,,,,,
,3755396681.88546,49.0000877380371,359.888580322266,,,5,,,,-2.43000010959804,,,,,0.000756246577207735,9.96329844266521E-8,-0.018004316232286,6.74781136729858E-5,0.000756147885550631,9.96199821273604E-8,0.000756147848218332,8.55701261271765E-8,-2.3760782280084E-7,5.10087674192849E-8,1.0001305189884,10.005763053894,2,20,10,5,2.47387115484371,0.217309357678344,0.0404026173055172,172.741912841797,48.9993896484375,49.0003280639648,359.888580322266,359.888580322266,,,8.43120670318604,0,1,,,,,,1,1,1,48.9999313354492,0,48.9997991674087,,,,,,,,,,,,,,,,,,,,,,,,,,,,,,,,,
,3755396886.8265,49.0002422332764,359.888580322266,,,5,,,,-2.43000010959804,,,,,0.000756388086217704,1.21340816099598E-7,-0.0121906775961484,0.000106120208221693,0.000756289370746522,1.21324980028072E-7,0.000756289353627915,9.09966683507741E-8,-1.60913768814285E-7,8.02456050377296E-8,1.0001305260592,10.005763053894,2,20,10,5,2.47431199962023,0.217601081613523,0.0404026173055172,172.741912841797,48.9997291564941,49.0006065368652,359.888580322266,359.888580322266,,,8.42557811737061,0,1,,,,,,1,1,1,49.0002708435059,0,49.0001438365263,,,,,,,,,,,,,,,,,,,,,,,,,,,,,,,,,
,3755397091.58714,49.0002708435059,359.888580322266,,,5,,,,-2.43000010959804,,,,,0.000756194519461556,1.45436330534387E-7,-0.0189025850082825,0.000103551503257191,0.000756095828262674,1.45417349590394E-7,0.000756095787115124,1.22552866499952E-7,-2.49445343624561E-7,7.82751587321279E-8,1.00013052736861,10.005763053894,2,20,10,5,2.47370426762152,0.217255613708238,0.0404026173055172,172.741912841797,48.9997749328613,49.0007286071777,359.888580322266,359.888580322266,,,8.42026233673096,0,1,,,,,,1,1,1,49.0005989074707,0,49.0002102571375,,,,,,,,,,,,,,,,,,,,,,,,,,,,,,,,,
,3755397297.48864,48.9999523162842,359.888580322266,,,5,,,,-2.43000010959804,,,,,0.000756485050517964,7.15737309287225E-8,-0.0169284911266683,6.86836415824525E-5,0.000756386332426995,7.15643908603683E-8,0.000756386299412481,4.92251070687713E-8,-2.23480319830619E-7,5.19456530739923E-8,1.00013051279054,10.005763053894,2,20,10,5,2.47464717845927,0.217424349103151,0.0404026173055172,172.741912841797,48.9992980957031,49.0005302429199,359.888580322266,359.888580322266,,,8.41611576080322,0,1,,,,,,1,1,1,48.9999771118164,0,48.9998874664307,,,,,,,,,,,,,,,,,,,,,,,,,,,,,,,,,
,3755397504.12365,48.9990501403809,359.888580322266,,,5,,,,-2.43000010959804,,,,,0.000756524045765461,1.28222745575366E-7,-0.0147891130852704,9.97113414960225E-5,0.000756425353814507,1.28206018343775E-7,0.000756425328615985,1.03683796414475E-7,-1.95247539504247E-7,7.54085771026488E-8,1.00013047150053,10.005763053894,2,20,10,5,2.47476662028101,0.217527968994382,0.0404026173055172,172.741912841797,48.9980010986328,48.9997406005859,359.888580322266,359.888580322266,,,8.41283130645752,0,1,,,,,,1,1,1,48.9985847473145,0,48.9991251627604,,,,,,,,,,,,,,,,,,,,,,,,,,,,,,,,,
,3755397708.99184,49.0000305175781,359.888580322266,,,5,,,,-2.43000010959804,,,,,0.000756561233138923,1.45077975010869E-7,-0.0131576084884699,9.22316011680291E-5,0.000756462502399383,1.45059042431275E-7,0.000756462482452912,1.27191788985573E-7,-1.7371676308242E-7,6.97450686839436E-8,1.00013051636958,10.005763053894,2,20,10,5,2.47488207411169,0.217609126554755,0.0404026173055172,172.741912841797,48.9997138977051,49.0005302429199,359.888580322266,359.888580322266,,,8.40868663787842,0,1,,,,,,1,1,1,49.0003471374512,0,49.000057220459,,,,,,,,,,,,,,,,,,,,,,,,,,,,,,,,,
,3755397913.94523,48.9997119903564,359.888580322266,,,5,,,,-2.43000010959804,,,,,0.000756541724696099,1.40796011258633E-7,-0.0150379792831874,0.000111219841249211,0.000756443007528443,1.40777639524471E-7,0.000756442981474113,1.12885074078946E-7,-1.98537732485616E-7,8.41148253298591E-8,1.00013050179151,10.005763053894,2,20,10,5,2.47482539743761,0.217522298249662,0.0404026173055172,172.741912841797,48.9995384216309,49.0005683898926,359.888580322266,359.888580322266,,,8.40585327148438,0,1,,,,,,1,1,1,48.9996185302734,0,48.9998662612017,,,,,,,,,,,,,,,,,,,,,,,,,,,,,,,,,
,3755398118.83273,48.9996185302734,359.888580322266,,,5,,,,-2.43000010959804,,,,,0.000756933909063357,9.08510394395497E-8,-0.0163991381172046,6.2187260352976E-5,0.000756835143958481,9.08391851517038E-8,0.000756835112958026,7.77036311194866E-8,-2.16620560776827E-7,4.70521335315656E-8,1.00013049751411,10.005763053894,2,20,10,5,2.47611349394497,0.217576236958661,0.0404026173055172,172.741912841797,48.9991302490234,49.0004997253418,359.888580322266,359.888580322266,,,8.40380096435547,0,1,,,,,,1,1,1,48.9993133544922,0,48.9997408249799,,,,,,,,,,,,,,,,,,,,,,,,,,,,,,,,,
,3755398323.93795,49.0002822875977,359.888580322266,,,5,,,,-2.43000010959804,,,,,0.000756640863520553,1.14847644937991E-7,-0.0175420064585285,8.96298767876966E-5,0.000756542113672962,1.14832656073418E-7,0.000756542078214787,9.26841619259154E-8,-2.31627295232694E-7,6.77951696580698E-8,1.00013052789238,10.005763053894,2,20,10,5,2.47515920939616,0.217442627162637,0.0404026173055172,172.741912841797,48.9994964599609,49.0008125305176,359.888580322266,359.888580322266,,,8.40281391143799,0,1,,,,,,1,1,1,49.0002288818359,0,49.0002777576447,,,,,,,,,,,,,,,,,,,,,,,,,,,,,,,,,
,3755398528.93925,48.9999141693115,359.888580322266,,,5,,,,-2.43000010959804,,,,,0.000756530152425881,1.29590629377762E-7,-0.0131281730589725,9.17752166595558E-5,0.000756431429769769,1.29573718576391E-7,0.00075643140991326,1.09419276361959E-7,-1.73321014475471E-7,6.94029574740071E-8,1.00013051104466,10.005763053894,2,20,10,5,2.47478029014389,0.217601460118505,0.0404026173055172,172.741912841797,48.9989585876465,49.0002365112305,359.888580322266,359.888580322266,,,8.40143394470215,0,1,,,,,,1,1,1,48.9999237060547,0,48.999636257396,,,,,,,,,,,,,,,,,,,,,,,,,,,,,,,,,
,3755398733.87981,49.0012664794922,359.888580322266,,,5,,,,-2.43000010959804,,,,,0.000756647262483642,1.06248928781849E-7,-0.016255545144606,8.076587601668E-5,0.000756548564520352,1.06235069545991E-7,0.000756548534071941,8.69131701825132E-8,-2.14642496954846E-7,6.10900225099564E-8,1.00013045819914,10.005763053894,2,20,10,5,2.47517525943794,0.217500037274461,0.0404026173055172,172.741912841797,49.0004081726074,49.0014724731445,359.888580322266,359.888580322266,,,8.40044021606445,0,1,,,,,,1,1,1,49.0011177062988,0,49.0008517371284,,,,,,,,,,,,,,,,,,,,,,,,,,,,,,,,,
,3755398938.92699,48.9996891021729,359.888580322266,,,5,,,,-2.43000010959804,,,,,0.000756681502604919,1.40562497832212E-7,-0.0171354671731923,0.000166054029688826,0.000756582767990813,1.40544156715198E-7,0.000756582734155276,6.30111785612195E-8,-2.26271447942981E-7,1.2562743077494E-7,1.00013050074398,10.005763053894,2,20,10,5,2.47529060657684,0.217471872702472,0.0404026173055172,172.741912841797,48.998779296875,48.9999771118164,359.888580322266,359.888580322266,,,8.39925956726074,0,1,,,,,,1,1,1,48.9994583129883,0,48.9993944168091,,,,,,,,,,,,,,,,,,,,,,,,,,,,,,,,,
,3755399143.89921,48.9998054504395,359.888580322266,,,5,,,,-2.43000010959804,,,,,0.000756695833198193,9.46706325015073E-8,-0.014963783274033,7.56355021483761E-5,0.00075659709268588,9.46582790216227E-8,0.00075659706688276,7.5410052316443E-8,-1.97598407565532E-7,5.72146292216134E-8,1.00013050606891,10.005763053894,2,20,10,5,2.47532924086926,0.217569811891409,0.0404026173055172,172.741912841797,48.9995613098145,49.0003395080566,359.888580322266,359.888580322266,,,8.39885902404785,0,1,,,,,,1,1,1,48.9999313354492,0,48.9998929640826,,,,,,,,,,,,,,,,,,,,,,,,,,,,,,,,,
,3755399349.06642,49.0000095367432,359.888580322266,,,5,,,,-2.43000010959804,,,,,0.000756739454597265,1.4482984785759E-7,-0.0175056375450042,0.000147353249567296,0.000756640701326399,1.4481094779746E-7,0.000756640666010497,9.2421123103346E-8,-2.31177196221191E-7,1.11483391616486E-7,1.00013051540935,10.005763053894,2,20,10,5,2.47548158703124,0.217472532538689,0.0404026173055172,172.741912841797,48.9990882873535,49.0001525878906,359.888580322266,359.888580322266,,,8.39954662322998,0,1,,,,,,1,1,1,48.9999923706055,0,48.9997500251321,,,,,,,,,,,,,,,,,,,,,,,,,,,,,,,,,
,3755399553.68302,49.0002403259277,359.888580322266,,,5,,,,-2.43000010959804,,,,,0.00075677307709713,1.08759787786924E-7,-0.0139872652612842,0.000110258088552227,0.000756674398254329,1.08745606138122E-7,0.000756674375706776,6.97594716322429E-8,-1.84722251963832E-7,8.34219573729709E-8,1.00013041123504,10.005763053894,2,20,10,5,2.47557821486754,0.217634213982723,0.0404026173055172,172.741912841797,48.9995536804199,49.0007400512695,359.888580322266,359.888580322266,,,8.39935111999512,0,1,,,,,,1,1,1,48.999927520752,0,49.0000133514404,,,,,,,,,,,,,,,,,,,,,,,,,,,,,,,,,
,3755399758.5849,49.000301361084,359.888580322266,,,5,,,,-2.43000010959804,,,,,0.000756979648155319,1.29168352972756E-7,-0.0150231274456427,0.000139663501121365,0.000756880940262845,1.29151509804083E-7,0.000756880914244899,7.42116453096727E-8,-1.9845647957124E-7,1.05701202382496E-7,1.00013041402845,10.005763053894,2,20,10,5,2.47625789155298,0.217648850469117,0.0404026173055172,172.741912841797,48.9997825622559,49.0006370544434,359.888580322266,359.888580322266,,,8.40039348602295,0,1,,,,,,1,1,1,49.0001220703125,0,49.0001907348633,,,,,,,,,,,,,,,,,,,,,,,,,,,,,,,,,
,3755399963.61307,48.99875831604,359.888580322266,,,5,,,,-2.43000010959804,,,,,0.000756887908554671,1.03274081860916E-7,-0.0167997069158865,8.62111956368052E-5,0.000756789179242516,1.0326061067324E-7,0.000756789146711093,8.00464790831288E-8,-2.21898302706796E-7,6.5232774760888E-8,1.00013045814457,10.005763053894,2,20,10,5,2.4759645360563,0.217545705413731,0.0404026173055172,172.741912841797,48.998176574707,49.0024681091309,359.888580322266,359.888580322266,,,8.40031147003174,0,1,,,,,,1,1,1,48.9990653991699,0,49.0003639669979,,,,,,,,,,,,,,,,,,,,,,,,,,,,,,,,,
,3755400168.54512,49.0002136230469,359.888580322266,,,5,,,,-2.43000010959804,,,,,0.000757070346645407,8.24757388694444E-8,-0.0152697214589521,9.09875803892323E-5,0.000756971543124137,8.2464975149196E-8,0.000756971516241831,4.5357691292815E-8,-2.01738148555795E-7,6.88705449879933E-8,1.0001305247498,10.005763053894,2,20,10,5,2.47655552428622,0.217664270827085,0.0404026173055172,172.741912841797,48.999584197998,49.0009384155273,359.888580322266,359.888580322266,,,8.40149593353271,0,1,,,,,,1,1,1,48.9998359680176,0,49.0003840128581,,,,,,,,,,,,,,,,,,,,,,,,,,,,,,,,,
,3755400373.42312,49.0001831054687,359.888580322266,,,5,,,,-2.43000010959804,,,,,0.000756950006864229,1.17153527977892E-7,-0.0154181041739347,8.83704466628905E-5,0.000756851220105187,1.17138238702201E-7,0.000756851192702244,9.61768719607125E-8,-2.03666149829642E-7,6.68683502571031E-8,1.00013052335309,10.005763053894,2,20,10,5,2.47616242842527,0.217623255826019,0.0404026173055172,172.741912841797,48.9995651245117,49.0007820129395,359.888580322266,359.888580322266,,,8.40228080749512,0,1,,,,,,1,1,1,49.0006446838379,0,49.0000507831574,,,,,,,,,,,,,,,,,,,,,,,,,,,,,,,,,
,3755400578.36387,49.0009231567383,359.888580322266,,,5,,,,-2.43000010959804,,,,,0.000757665544197133,1.11033160780313E-7,-0.0189906732629197,9.76077786998831E-5,0.000757566725309986,1.11018679227775E-7,0.000757566683697242,8.28186655303602E-8,-2.51095316514876E-7,7.39338608301355E-8,1.00013044248625,10.005763053894,2,20,10,5,2.47851669777317,0.217674429340583,0.0404026173055172,172.741912841797,49.0000648498535,49.001335144043,359.888580322266,359.888580322266,,,8.40159606933594,0,1,,,,,,1,1,1,49.0008316040039,0,49.0006525376264,,,,,,,,,,,,,,,,,,,,,,,,,,,,,,,,,
,3755400783.47377,49.0005569458008,359.888580322266,,,5,,,,-2.43000010959804,,,,,0.000757092684810451,1.12295231779111E-7,-0.016039588909476,0.0001030587157307,0.000756993953324643,1.1228058750199E-7,0.000756993923662426,8.07598809169847E-8,-2.11915637816291E-7,7.80049483306439E-8,1.00013042572582,10.005763053894,2,20,10,5,2.47663152246137,0.217637413048027,0.0404026173055172,172.741912841797,48.9998054504395,49.0008430480957,359.888580322266,359.888580322266,,,8.40291881561279,0,1,,,,,,1,1,1,49.0003776550293,0,49.0002905527751,,,,,,,,,,,,,,,,,,,,,,,,,,,,,,,,,
,3755400987.42908,48.9993000030518,359.888580322266,,,5,,,,-2.43000010959804,,,,,0.000757013277347208,1.15997704199688E-7,-0.019657851415297,8.14092552611763E-5,0.000756914599753914,1.15982583759109E-7,0.000756914555204323,9.82695953435171E-8,-2.59693027489357E-7,6.16039476532148E-8,1.00013036819917,10.005763053894,2,20,10,5,2.47638549825726,0.217458211724306,0.0404026173055172,172.741912841797,48.9959297180176,49.000846862793,359.888580322266,359.888580322266,,,8.40332508087158,0,1,,,,,,1,1,1,48.9980583190918,0,48.9973741419175,,,,,,,,,,,,,,,,,,,,,,,,,,,,,,,,,
,3755401193.22339,49.0020141601562,359.888580322266,,,5,,,,-2.43000010959804,,,,,0.000757040775603273,8.89877480517848E-8,-0.0168740671909857,7.83957768194018E-5,0.000756942000411099,8.89761373404489E-8,0.000756941967584424,6.63053542888695E-8,-2.22925494661606E-7,5.93325628020055E-8,1.00013049241834,10.005763053894,2,20,10,5,2.47646488494091,0.217586415514698,0.0404026173055172,172.741912841797,49.0001945495605,49.0021133422852,359.888580322266,359.888580322266,,,8.40274047851562,0,1,,,,,,1,1,1,49.0020179748535,0,49.0010115679573,,,,,,,,,,,,,,,,,,,,,,,,,,,,,,,,,
,3755401398.13623,49.0006332397461,359.888580322266,,,5,,,,-2.43000010959804,,,,,0.000757096343908449,1.00983475301459E-7,-0.0164184837582635,7.59754088486566E-5,0.000756997609302558,1.00970305823472E-7,0.000756997578222249,8.29982398861783E-8,-2.16922657984666E-7,5.75003898585207E-8,1.00013042921758,10.005763053894,2,20,10,5,2.47664493154227,0.217622085683397,0.0404026173055172,172.741912841797,48.9993934631348,49.0007820129395,359.888580322266,359.888580322266,,,8.4035120010376,0,1,,,,,,1,1,1,49.0006637573242,0,49.0001797395594,,,,,,,,,,,,,,,,,,,,,,,,,,,,,,,,,
,3755401603.15283,49.0004425048828,359.888580322266,,,5,,,,-2.43000010959804,,,,,0.000757203598965804,1.19237091219131E-7,-0.0246261145674271,7.56771097770581E-5,0.000757104856980743,1.19221542287383E-7,0.000757104787049289,1.04561141204178E-7,-3.25408791571804E-7,5.72777783740087E-8,1.00013042048819,10.005763053894,2,20,10,5,2.47702694200441,0.217298084533684,0.0404026173055172,172.741912841797,48.9995460510254,49.0008735656738,359.888580322266,359.888580322266,,,8.40332412719727,0,1,,,,,,1,1,1,49.0003356933594,0,49.0000401665183,,,,,,,,,,,,,,,,,,,,,,,,,,,,,,,,,
,3755401808.01702,49.0005035400391,359.888580322266,,,5,,,,-2.43000010959804,,,,,0.000757078407741784,1.45092294876655E-7,-0.0187868694399631,0.00012771712556589,0.000756979679967821,1.45073373931154E-7,0.000756979639275001,1.08176088417889E-7,-2.48208127758924E-7,9.66654939384968E-8,1.0001304232816,10.005763053894,2,20,10,5,2.47659525124954,0.217514558349696,0.0404026173055172,172.741912841797,48.999454498291,49.0006637573242,359.888580322266,359.888580322266,,,8.40375328063965,0,1,,,,,,1,1,1,49.0004463195801,0,48.9999758402506,,,,,,,,,,,,,,,,,,,,,,,,,,,,,,,,,
,3755402013.10635,49.0001068115234,359.888580322266,,,5,,,,-2.43000010959804,,,,,0.000757240915807426,9.96394391923542E-8,-0.0161488747206535,7.12693189542109E-5,0.000757142180587123,9.96264473930811E-8,0.000757142150513434,8.37563181055961E-8,-2.13401303936299E-7,5.39472723829533E-8,1.00013040512447,10.005763053894,2,20,10,5,2.47711683655919,0.217675301582696,0.0404026173055172,172.741912841797,48.9991455078125,49.0005035400391,359.888580322266,359.888580322266,,,8.40374660491943,0,1,,,,,,1,1,1,48.9998817443848,0,48.999849207261,,,,,,,,,,,,,,,,,,,,,,,,,,,,,,,,,
,3755402218.16521,49.0004177093506,359.888580322266,,,5,,,,-2.43000010959804,,,,,0.000757135854334564,1.04270413725446E-7,-0.0140495544466139,7.63457838643401E-5,0.000757037122042628,1.04256816618838E-7,0.000757037099282903,8.67794293819062E-8,-1.85633815405711E-7,5.77824752640871E-8,1.00013041935337,10.005763053894,2,20,10,5,2.47676517910436,0.217735849315936,0.0404026173055172,172.741912841797,48.999382019043,49.0008964538574,359.888580322266,359.888580322266,,,8.40359878540039,0,1,,,,,,1,1,1,48.9999732971191,0,48.9999296400282,,,,,,,,,,,,,,,,,,,,,,,,,,,,,,,,,
,3755402423.11407,49.0000858306885,359.888580322266,,,5,,,,-2.43000010959804,,,,,0.000757214251668441,9.47966884314883E-8,-0.0171579678839642,8.58124173546064E-5,0.000757115433794011,9.47843172865538E-8,0.000757115399845671,6.90223882273503E-8,-2.26728080387904E-7,6.49613479453055E-8,1.00013051890111,10.005763053894,2,20,10,5,2.4770334451131,0.217624009310478,0.0404026173055172,172.741912841797,48.9993324279785,49.0003509521484,359.888580322266,359.888580322266,,,8.40430736541748,0,1,,,,,,1,1,1,49.0003242492676,0,48.9997668546789,,,,,,,,,,,,,,,,,,,,,,,,,,,,,,,,,
,3755402576.8061,49.0006694793701,359.888580322266,,,5,,,,-2.43000010959804,,,,,0.000757411175722539,1.12655379605124E-7,-0.0162830755070136,0.000110439144840951,0.000757312398802834,1.12640687781525E-7,0.000757312368220356,7.54600173955693E-8,-2.15223091664129E-7,8.36284061701244E-8,1.00013043087616,10.005763053894,2,20,10,5,2.4776743077498,0.217718438964322,0.0404026173055172,172.741912841797,48.9998092651367,49.0011215209961,359.888580322266,359.888580322266,,,8.40399551391602,0,1,,,,,,1,1,1,49.0003204345703,0,49.0003805721507,,,,,,,,,,,,,,,,,,,,,,,,,,,,,,,,,