File: Experimental_Data/Fig3B/Lifetime_240Oe.dat
[Header]
; MPMS3 Data File (default extension .dat)
; Copyright (c) 2007, Quantum Design, Inc. All rights reserved.
TITLE,240Oe
FILEOPENTIME,3754569060.81557,12/21/2018,3:50 pm
BYAPP,SQUID AC,0.9.1.0
INFO,MPMS3 Measurement Release 1.1.16 Build 347, MultiVu Release 2.3.3.2,APPNAME
INFO,0,MOMENT_UNITS
INFO,CoIINO3,SAMPLE_MATERIAL
INFO,40 Hours Pumped Turbo,SAMPLE_COMMENT
INFO,,SAMPLE_MASS
INFO,,SAMPLE_VOLUME
INFO,,SAMPLE_MOLECULAR_WEIGHT
INFO,,SAMPLE_SIZE
INFO,,SAMPLE_SHAPE
INFO,Brass,SAMPLE_HOLDER
INFO,Standard,SAMPLE_HOLDER_DETAIL
INFO,65.37,SAMPLE_OFFSET
DATATYPE,COMMENT,1
DATATYPE,TIME,2
STARTUPAXIS,X,2
STARTUPAXIS,Y1,5
FIELDGROUP, VSM,2,3,4,5,6,8,9,10,11,14,15
FIELDGROUP, DC, 2,3,4,14,56,57,58,59,60,61,62,63,64,65,66,67,68,69
FIELDGROUP, AC, 2,3,4,11,16,17,18,19,20,21,22,23,24,25,26,27,28,29,30
STARTUPGROUP, All
[Data]
Comment,Time Stamp (sec),Temperature (K),Magnetic Field (Oe),Moment (emu),M. Std. Err. (emu),Transport Action,Averaging Time (sec),Frequency (Hz),Peak Amplitude (mm),Center Position (mm),Lockin Signal' (V),Lockin Signal (V),Range,M. Quad. Signal (emu),AC Moment (emu),AC M. Std Err. (emu),AC Phase (deg),AC Phase Std. Err. (deg),AC Susceptibility (emu/Oe),AC Suscept. Std Err. (emu/Oe),AC X' (emu/Oe),AC X' Std Err. (emu/Oe),AC X'' (emu/Oe),AC X'' Std Err. (emu/Oe),AC Drive (Oe),AC Frequency (Hz),AC Averaging Time (sec),AC Cycles,AC Range,AC Measure Type,AC Signal' (V),AC Signal'' (V),AC Trim Coil Ratio,AC Trim Coil Phase,Min. Temperature (K),Max. Temperature (K),Min. Field (Oe),Max. Field (Oe),Mass (grams),Motor Lag (deg),Pressure (Torr),Measure Count,Measurement Number,SQUID Status (code),Motor Status (code),Measure Status (code),Motor Current (amps),Motor Temp. (C),Temp. Status (code),Field Status (code),Chamber Status (code),Chamber Temp (K),Redirection State,Average Temp (K),Rotation Angle (deg),Rotator state,DC Moment Fixed Ctr (emu),DC Moment Err Fixed Ctr (emu),DC Moment Free Ctr (emu),DC Moment Err Free Ctr (emu),DC Fixed Fit,DC Free Fit,DC Calculated Center (mm),DC Calculated Center Err (mm),DC Scan Length (mm),DC Scan Time (s),DC Number of Points,DC Squid Drift,DC Min V (V),DC Max V (V),DC Scans per Measure,Map 01,Map 02,Map 03,Map 04,Map 05,Map 06,Map 07,Map 08,Map 09,Map 10,Map 11,Map 12,Map 13,Map 14,Map 15,Map 16
,3754569065.25622,48.9552173614502,240.063339233398,,,5,,,,-2.43000010959804,,,,,0.00066063281414591,9.63230745740782E-8,0.0344534953741302,0.000110300914824575,0.000660547123017055,9.63105804429689E-8,0.000660547003592094,6.29931630013737E-8,3.97204751713535E-7,7.28532039126897E-8,1.00012972750296,10.005763053894,2,20,10,5,2.16093732923501,0.191536108709599,0.0404026173055172,172.741912841797,48.9194679260254,48.9705200195313,240.063339233398,240.063339233398,,,732.52587890625,0,1,,,,,,1,1,1,48.9478607177734,0,48.9338971306296,,,,,,,,,,,,,,,,,,,,,,,,,,,,,,,,,
,3754569324.31559,49.0004615783691,240.063339233398,,,5,,,,-2.43000010959804,,,,,0.000663267970361483,8.33970659012902E-8,-0.00114580228669059,7.59680914833436E-5,0.000663181477330532,8.33861905608177E-8,0.000663181477197922,6.64538152973763E-8,-1.32623180908468E-8,5.03701023293301E-8,1.00013042136113,10.005763053894,2,20,10,5,2.16967603533144,0.190951871656093,0.0404026173055172,172.741912841797,48.9997749328613,49.0008430480957,240.063339233398,240.063339233398,,,739.328979492188,0,1,,,,,,1,1,1,49.000789642334,0,49.0003020342659,,,,,,,,,,,,,,,,,,,,,,,,,,,,,,,,,
,3754569583.16609,49.0003089904785,240.063339233398,,,5,,,,-2.43000010959804,,,,,0.000664009679430148,8.03041578472612E-8,-0.000436507798743158,7.56915970247153E-5,0.000663923094313015,8.02936863961229E-8,0.000663923094293747,6.26308090169576E-8,-5.05809696444299E-9,5.02439830921107E-8,1.00013041437762,10.005763053894,2,20,10,5,2.17209994029687,0.191192297729055,0.0404026173055172,172.741912841797,48.9995994567871,49.0003929138184,240.063339233398,240.063339233398,,,743.097473144531,0,1,,,,,,1,1,1,49.0003318786621,0,49.0000744987937,,,,,,,,,,,,,,,,,,,,,,,,,,,,,,,,,
,3754569839.55097,49.0000228881836,240.063339233398,,,5,,,,-2.43000010959804,,,,,0.000665271710495856,1.26085223885698E-7,0.00211871379504558,0.000174683622801779,0.000665184893210758,1.26068769891554E-7,0.000665184892755967,4.89090737452316E-8,2.45975606084314E-8,1.16194824529121E-7,1.00013051602041,10.005763053894,2,20,10,5,2.17621973512791,0.191652735194742,0.0404026173055172,172.741912841797,48.9993858337402,49.0002937316895,240.063339233398,240.063339233398,,,744.813781738281,0,1,,,,,,1,1,1,49.0002937316895,0,48.9998410542806,,,,,,,,,,,,,,,,,,,,,,,,,,,,,,,,,
,3754570097.58157,49.0008277893066,240.063339233398,,,5,,,,-2.43000010959804,,,,,0.000666136963451093,5.86021788304232E-8,0.00182558579190584,6.11404886292586E-5,0.000666050085129128,5.85945358692312E-8,0.000666050084791036,4.21356958393242E-8,2.12220094086692E-8,4.07173521961654E-8,1.00013043812155,10.005763053894,2,20,10,5,2.17905111041486,0.191890847572301,0.0404026173055172,172.741912841797,48.9997673034668,49.0012702941895,240.063339233398,240.063339233398,,,745.634582519531,0,1,,,,,,1,1,1,49.0011138916016,0,49.0003433227539,,,,,,,,,,,,,,,,,,,,,,,,,,,,,,,,,
,3754570352.16833,49.0000343322754,240.063339233398,,,5,,,,-2.43000010959804,,,,,0.000666742600490951,7.15756774689278E-8,-0.00272545581798944,8.67312860112167E-5,0.000666655667387073,7.1566345088186E-8,0.000666655666632842,4.21786538384761E-8,-3.17115952000559E-8,5.78161128895339E-8,1.00013040180731,10.005763053894,2,20,10,5,2.18104750418489,0.191892074059193,0.0404026173055172,172.741912841797,48.9994049072266,49.0003929138184,240.063339233398,240.063339233398,,,745.982849121094,0,1,,,,,,1,1,1,48.9998359680176,0,48.9998173433192,,,,,,,,,,,,,,,,,,,,,,,,,,,,,,,,,
,3754570605.72187,49.0005302429199,240.063339233398,,,5,,,,-2.43000010959804,,,,,0.000667337041168122,6.82331192218065E-8,-0.00235730394436739,8.23041292826173E-5,0.00066725001541601,6.82242211116269E-8,0.000667250014851276,4.0484836724133E-8,-2.74524774100765E-8,5.4913771876538E-8,1.00013042450371,10.005763053894,2,20,10,5,2.18299080373662,0.192077182400764,0.0404026173055172,172.741912841797,48.9995002746582,49.0012664794922,240.063339233398,240.063339233398,,,746.045043945313,0,1,,,,,,1,1,1,49.0002403259277,0,49.000067392985,,,,,,,,,,,,,,,,,,,,,,,,,,,,,,,,,
,3754570862.20246,49.0002918243408,240.063339233398,,,5,,,,-2.43000010959804,,,,,0.000667883461467825,7.52531081604359E-8,-0.00406001897093145,9.22223967338867E-5,0.000667796371744276,7.5243295412009E-8,0.000667796370067694,4.32344168922726E-8,-4.73205174756878E-8,6.15819673317119E-8,1.00013041359198,10.005763053894,2,20,10,5,2.18478396398607,0.192169528717545,0.0404026173055172,172.741912841797,48.9994735717773,49.0005264282227,240.063339233398,240.063339233398,,,746.045043945313,0,1,,,,,,1,1,1,49.0003814697266,0,49.0000886356129,,,,,,,,,,,,,,,,,,,,,,,,,,,,,,,,,
,3754571118.16458,48.9996891021729,240.063339233398,,,5,,,,-2.43000010959804,,,,,0.000668428777617855,1.06039020997855E-7,-0.000727999534328561,0.000124049292113205,0.000668341558547231,1.06025184632379E-7,0.000668341558493282,6.60966991573416E-8,-8.491940375305E-9,8.29009417125887E-8,1.00013050074398,10.005763053894,2,20,10,5,2.18655661647981,0.192453593598462,0.0404026173055172,172.741912841797,48.9991989135742,49.0001029968262,240.063339233398,240.063339233398,,,745.970397949219,0,1,,,,,,1,1,1,48.9997062683105,0,48.9996721744537,,,,,,,,,,,,,,,,,,,,,,,,,,,,,,,,,
,3754571374.28816,49.0002956390381,240.063339233398,,,5,,,,-2.43000010959804,,,,,0.0006688411967273,1.05065716433349E-7,-0.000693721145760939,0.00012717064726729,0.000668753905280879,1.05052004152464E-7,0.00066875390523186,6.1676914528681E-8,-8.09708375267484E-9,8.50404714866463E-8,1.00013052850343,10.005763053894,2,20,10,5,2.18790560236281,0.19257364163942,0.0404026173055172,172.741912841797,48.9997062683105,49.0008697509766,240.063339233398,240.063339233398,,,745.908203125,0,1,,,,,,1,1,1,49.0008201599121,0,49.0001626856187,,,,,,,,,,,,,,,,,,,,,,,,,,,,,,,,,
,3754571630.73951,49.0001888275146,240.063339233398,,,5,,,,-2.43000010959804,,,,,0.000669390264797786,1.06686734361178E-7,-0.0031579079695554,9.23938217882503E-5,0.000669302904963116,1.06672811040262E-7,0.000669302903946525,8.69296195452191E-8,-3.68892263011607E-8,6.18249938209039E-8,1.00013052361498,10.005763053894,2,20,10,5,2.1897099943166,0.192637556966798,0.0404026173055172,172.741912841797,48.9999580383301,49.0008163452148,240.063339233398,240.063339233398,,,745.870910644531,0,1,,,,,,1,1,1,49.0002670288086,0,49.0003350201775,,,,,,,,,,,,,,,,,,,,,,,,,,,,,,,,,
,3754571887.28302,48.9984893798828,240.063339233398,,,5,,,,-2.43000010959804,,,,,0.000669272015179542,6.83704966916626E-8,-0.00386053797725516,6.114174285285E-5,0.000669184646048716,6.83615713657343E-8,0.000669184644529686,5.47719414347735E-8,-4.50890582145321E-8,4.09064649054172E-8,1.00013056057299,10.005763053894,2,20,10,5,2.18932553745681,0.192576683131429,0.0404026173055172,172.741912841797,48.9974517822266,49.0026168823242,240.063339233398,240.063339233398,,,745.808715820312,0,1,,,,,,1,1,1,48.9991836547852,0,49.000467412612,,,,,,,,,,,,,,,,,,,,,,,,,,,,,,,,,
,3754572143.75193,49.0004539489746,240.063339233398,,,5,,,,-2.43000010959804,,,,,0.000669911005292268,8.7881566484547E-8,0.00234893637199018,5.80329548291571E-5,0.000669823646214497,8.78701063763527E-8,0.000669823645651601,7.88142056202957E-8,2.74605413931463E-8,3.88519830514904E-8,1.00013042101196,10.005763053894,2,20,10,5,2.19139490163501,0.192998037564432,0.0404026173055172,172.741912841797,48.999641418457,49.0012130737305,240.063339233398,240.063339233398,,,745.846069335938,0,1,,,,,,1,1,1,49.000244140625,0,49.0001303728889,,,,,,,,,,,,,,,,,,,,,,,,,,,,,,,,,
,3754572400.35018,49.0002422332764,240.063339233398,,,5,,,,-2.43000010959804,,,,,0.000670598993061626,7.59925176745972E-8,-0.000145408439757411,6.8424390995771E-5,0.000670511550763649,7.59826086821244E-8,0.00067051155076149,6.05749909161267E-8,-1.70166178493998E-9,4.58696773223009E-8,1.00013041132234,10.005763053894,2,20,10,5,2.19365383744893,0.193100743277872,0.0404026173055172,172.741912841797,48.9998321533203,49.0005569458008,240.063339233398,240.063339233398,,,745.758972167969,0,1,,,,,,1,1,1,49.0004081726074,0,49.0002221001519,,,,,,,,,,,,,,,,,,,,,,,,,,,,,,,,,
,3754572659.34166,48.9994411468506,240.063339233398,,,5,,,,-2.43000010959804,,,,,0.000671039339461684,8.29391736068987E-8,0.00148869813842012,8.4333060614475E-5,0.000670951787368355,8.29283523363095E-8,0.000670951787141875,6.06326570801555E-8,1.74331283246521E-8,5.65755469846766E-8,1.00013048939578,10.005763053894,2,20,10,5,2.19508877999221,0.193290152467841,0.0404026173055172,172.741912841797,48.9986610412598,49.0003547668457,240.063339233398,240.063339233398,,,745.945556640625,0,1,,,,,,1,1,1,48.9991149902344,0,48.9995381972369,,,,,,,,,,,,,,,,,,,,,,,,,,,,,,,,,
,3754572918.30918,49.000207901001,240.063339233398,,,5,,,,-2.43000010959804,,,,,0.0006712709730619,9.28673446425359E-8,0.00111734447782563,0.000120782990198633,0.0006711833671966,9.28552247618735E-8,0.000671183367068974,4.52837547678086E-8,1.30889750566491E-8,8.10646305099026E-8,1.00013052448792,10.005763053894,2,20,10,5,2.195847748198,0.193342636857302,0.0404026173055172,172.741912841797,48.9996070861816,49.0003471374512,240.063339233398,240.063339233398,,,746.007751464844,0,1,,,,,,1,1,1,49.0003051757812,0,49.0000163184272,,,,,,,,,,,,,,,,,,,,,,,,,,,,,,,,,
,3754573174.81688,49.000280380249,240.063339233398,,,5,,,,-2.43000010959804,,,,,0.000671652734822515,6.72146428528287E-8,0.00190999847628515,7.83741244008218E-5,0.000671565153950283,6.72058783280339E-8,0.000671565153577136,4.17944546015266E-8,2.23871362155182E-8,5.26293990693741E-8,1.00013041306821,10.005763053894,2,20,10,5,2.19709388283329,0.1934829896616,0.0404026173055172,172.741912841797,48.9995498657227,49.0007247924805,240.063339233398,240.063339233398,,,746.045043945313,0,1,,,,,,1,1,1,49.0001945495605,0,49.0000902063706,,,,,,,,,,,,,,,,,,,,,,,,,,,,,,,,,
,3754573431.22676,49.0002784729004,240.063339233398,,,5,,,,-2.43000010959804,,,,,0.000672014436756238,1.13869727699696E-7,-0.00299725618950664,0.000148030399427445,0.000671926808778145,1.13854879545462E-7,0.000671926807858766,5.54104531015734E-8,-3.51498278355277E-8,9.946162719054E-8,1.00013041298092,10.005763053894,2,20,10,5,2.19829364559358,0.193398906271163,0.0404026173055172,172.741912841797,48.9992179870605,49.0005912780762,240.063339233398,240.063339233398,,,746.069885253906,0,1,,,,,,1,1,1,49.0003623962402,0,49.0000661962173,,,,,,,,,,,,,,,,,,,,,,,,,,,,,,,,,
,3754573688.71685,49.001163482666,240.063339233398,,,5,,,,-2.43000010959804,,,,,0.000672308122991021,1.03638365959051E-7,-0.00345466623505608,0.000131855001980168,0.000672220429493122,1.03624847736503E-7,0.000672220428271186,5.36895882294329E-8,-4.05317326793225E-8,8.86314683629202E-8,1.00013045348527,10.005763053894,2,20,10,5,2.19925589672649,0.193465867228646,0.0404026173055172,172.741912841797,48.9992828369141,49.0022010803223,240.063339233398,240.063339233398,,,746.132080078125,0,1,,,,,,1,1,1,49.0007705688477,0,49.0002721898696,,,,,,,,,,,,,,,,,,,,,,,,,,,,,,,,,
,3754573946.37877,49.0008125305176,240.063339233398,,,5,,,,-2.43000010959804,,,,,0.000672514363239832,7.28992760860063E-8,-0.00402864035494233,8.05131419417187E-5,0.000672426653639839,7.28897685324211E-8,0.000672426651977626,4.8810303385856E-8,-4.72803611955675E-8,5.41338400641467E-8,1.0001304374232,10.005763053894,2,20,10,5,2.19993248896135,0.193503176473206,0.0404026173055172,172.741912841797,48.9996719360352,49.0009918212891,240.063339233398,240.063339233398,,,746.194274902344,0,1,,,,,,1,1,1,49.0009918212891,0,49.0003067465389,,,,,,,,,,,,,,,,,,,,,,,,,,,,,,,,,
,3754574202.46861,49.0009937286377,240.063339233398,,,5,,,,-2.43000010959804,,,,,0.000672889247206332,5.98751507124526E-8,-0.00248221632993673,5.47970700282816E-5,0.000672801483135058,5.98673412742479E-8,0.000672801482503678,4.71742815932683E-8,-2.91476761798792E-8,3.68603541410861E-8,1.00013044571612,10.005763053894,2,20,10,5,2.20115358498023,0.193670451416293,0.0404026173055172,172.741912841797,48.9994850158691,49.0012130737305,240.063339233398,240.063339233398,,,746.14453125,0,1,,,,,,1,1,1,49.001091003418,0,49.0004333047306,,,,,,,,,,,,,,,,,,,,,,,,,,,,,,,,,
,3754574458.76918,48.9999294281006,240.063339233398,,,5,,,,-2.43000010959804,,,,,0.000673137887449274,1.15434722712914E-7,-0.00165974030862426,0.000134037914915915,0.000673050046514571,1.15419659092028E-7,0.000673050046232179,7.20024266454379E-8,-1.94968687267859E-8,9.02072517156376E-8,1.00013051174301,10.005763053894,2,20,10,5,2.20196415456761,0.193773627918191,0.0404026173055172,172.741912841797,48.9991416931152,49.000373840332,240.063339233398,240.063339233398,,,746.14453125,0,1,,,,,,1,1,1,49.0000686645508,0,48.9996897379557,,,,,,,,,,,,,,,,,,,,,,,,,,,,,,,,,
,3754574714.91406,49.0003967285156,240.063339233398,,,5,,,,-2.43000010959804,,,,,0.000673348315877899,5.94963101880099E-8,-0.00394439538207347,7.63545297937504E-5,0.000673260510323977,5.94885517866757E-8,0.00067326050872858,2.9941512127538E-8,-4.63490621530046E-8,5.14042181653655E-8,1.00013041839314,10.005763053894,2,20,10,5,2.20266023402162,0.1937463722531,0.0404026173055172,172.741912841797,48.9996376037598,49.0009078979492,240.063339233398,240.063339233398,,,746.132080078125,0,1,,,,,,1,1,1,49.0001983642578,0,49.0001934275908,,,,,,,,,,,,,,,,,,,,,,,,,,,,,,,,,
,3754574971.1735,48.9998550415039,240.063339233398,,,5,,,,-2.43000010959804,,,,,0.000673595328290404,8.52134266192785E-8,-0.000784564620860628,8.7185921101212E-5,0.000673507429954721,8.52023070077504E-8,0.000673507429891578,6.17435849684412E-8,-9.22249607044925E-9,5.87125440999437E-8,1.00013050833855,10.005763053894,2,20,10,5,2.20345756984319,0.193938967299952,0.0404026173055172,172.741912841797,48.9994812011719,49.0006866455078,240.063339233398,240.063339233398,,,746.16943359375,0,1,,,,,,1,1,1,48.9999504089355,0,48.9999907998478,,,,,,,,,,,,,,,,,,,,,,,,,,,,,,,,,
,3754575227.35401,49.0010547637939,240.063339233398,,,5,,,,-2.43000010959804,,,,,0.000673892726582869,1.02169968639693E-7,-0.00252105982160167,0.000105503935618014,0.000673804829747119,1.02156642457947E-7,0.000673804829094853,7.33731460811449E-8,-2.96479478552276E-8,7.10799622427853E-8,1.00013044850952,10.005763053894,2,20,10,5,2.20443629554705,0.193957778652531,0.0404026173055172,172.741912841797,48.9995727539063,49.0014228820801,240.063339233398,240.063339233398,,,746.219177246094,0,1,,,,,,1,1,1,49.0008163452148,0,49.000462251551,,,,,,,,,,,,,,,,,,,,,,,,,,,,,,,,,
,3754575482.69348,49.0006465911865,240.063339233398,,,5,,,,-2.43000010959804,,,,,0.000674145438912373,7.24582868047257E-8,-0.00207485168393795,8.16692074279848E-5,0.000674057521705326,7.24488373152898E-8,0.000674057521263353,4.71051761557934E-8,-2.44096405627281E-8,5.50448581401478E-8,1.00013042982864,10.005763053894,2,20,10,5,2.20526145640078,0.19404768751808,0.0404026173055172,172.741912841797,48.9997749328613,49.0009689331055,240.063339233398,240.063339233398,,,746.231567382813,0,1,,,,,,1,1,1,49.000862121582,0,49.0002670288086,,,,,,,,,,,,,,,,,,,,,,,,,,,,,,,,,
,3754575739.82248,49.0000057220459,240.063339233398,,,5,,,,-2.43000010959804,,,,,0.000674494958884356,8.40304504150536E-8,-0.00558219890573763,9.55317955530349E-5,0.00067440693850445,8.40194845922973E-8,0.000674406935303659,5.39361988497009E-8,-6.57059507729711E-8,6.44217373624835E-8,1.00013051523476,10.005763053894,2,20,10,5,2.20641668477991,0.194013233220757,0.0404026173055172,172.741912841797,48.9990692138672,49.000732421875,240.063339233398,240.063339233398,,,746.281372070312,0,1,,,,,,1,1,1,48.9998741149902,0,48.999726144891,,,,,,,,,,,,,,,,,,,,,,,,,,,,,,,,,
,3754576239.23118,48.9998741149902,240.063339233398,,,5,,,,-2.43000010959804,,,,,0.000675151102349489,8.57861671121991E-8,-0.00225821724296438,6.21500415811518E-5,0.000675063077854116,8.57749825284167E-8,0.000675063077329791,7.48227030350188E-8,-2.66064812287965E-8,4.19393697888222E-8,1.00013039447462,10.005763053894,2,20,10,5,2.20855179955365,0.194330096355211,0.0404026173055172,172.741912841797,48.9991111755371,49.0001373291016,240.063339233398,240.063339233398,,,747.151916503906,0,1,,,,,,1,1,1,48.9997787475586,0,48.9996499454274,,,,,,,,,,,,,,,,,,,,,,,,,,,,,,,,,
,3754576495.35807,49.00119972229,240.063339233398,,,5,,,,-2.43000010959804,,,,,0.000675503700815613,9.68961221815664E-8,-0.00200678451040037,6.70802465617342E-5,0.000675415589377738,9.68834832328239E-8,0.000675415588963454,8.56470908769877E-8,-2.36564290439504E-8,4.5287803519644E-8,1.00013045514386,10.005763053894,2,20,10,5,2.209704365507,0.194441277932169,0.0404026173055172,172.741912841797,48.9998817443848,49.0014953613281,240.063339233398,240.063339233398,,,746.654479980469,0,1,,,,,,1,1,1,49.000904083252,0,49.0005906048943,,,,,,,,,,,,,,,,,,,,,,,,,,,,,,,,,
,3754576751.48834,48.9995861053467,240.063339233398,,,5,,,,-2.43000010959804,,,,,0.000675738589201528,1.07757395530226E-7,-0.0024862459400703,7.1799054333286E-5,0.000675650419504039,1.07743335452678E-7,0.000675650418867925,9.62158562350596E-8,-2.93186186861805E-8,4.8488507333416E-8,1.00013049603011,10.005763053894,2,20,10,5,2.21047435838244,0.194490397166415,0.0404026173055172,172.741912841797,48.9989852905273,48.999870300293,240.063339233398,240.063339233398,,,746.418151855469,0,1,,,,,,1,1,1,48.9996147155762,0,48.9994473176844,,,,,,,,,,,,,,,,,,,,,,,,,,,,,,,,,
,3754577007.58393,49.0002822875977,240.063339233398,,,5,,,,-2.43000010959804,,,,,0.000676450325317159,1.23649089805699E-7,-0.00280802141209069,0.000147518919601216,0.00067636211879898,1.23632966440421E-7,0.000676362117986702,7.301460578744E-8,-3.3147979262951E-8,9.97696232956856E-8,1.00013041315551,10.005763053894,2,20,10,5,2.21280368132453,0.194682819082646,0.0404026173055172,172.741912841797,48.9995231628418,49.000431060791,240.063339233398,240.063339233398,,,746.343505859375,0,1,,,,,,1,1,1,49.0001335144043,0,48.9999284183278,,,,,,,,,,,,,,,,,,,,,,,,,,,,,,,,,
,3754577263.72023,48.9999618530273,240.063339233398,,,5,,,,-2.43000010959804,,,,,0.00067649325917617,7.61498037871716E-8,-0.00172771939669136,8.15201023968845E-5,0.000676404979379549,7.61398665274873E-8,0.000676404979072025,5.25115048784208E-8,-2.0396580911317E-8,5.51345729123493E-8,1.00013051322701,10.005763053894,2,20,10,5,2.21294045520777,0.194736899890835,0.0404026173055172,172.741912841797,48.998706817627,49.0005073547363,240.063339233398,240.063339233398,,,746.380859375,0,1,,,,,,1,1,1,49.0001907348633,0,48.9995352801155,,,,,,,,,,,,,,,,,,,,,,,,,,,,,,,,,
,3754577520.25267,49.0007171630859,240.063339233398,,,5,,,,-2.43000010959804,,,,,0.000676357559328104,8.59439503563407E-8,-0.00148616379080124,8.77535280637572E-5,0.000676269351448218,8.59327418859904E-8,0.00067626935122072,6.21573338846545E-8,-1.75413796858947E-8,5.9337188780695E-8,1.00013043305851,10.005763053894,2,20,10,5,2.21249573405826,0.194707162700794,0.0404026173055172,172.741912841797,48.999870300293,49.0012550354004,240.063339233398,240.063339233398,,,746.343505859375,0,1,,,,,,1,1,1,49.0007133483887,0,49.0004528893365,,,,,,,,,,,,,,,,,,,,,,,,,,,,,,,,,
,3754577776.51863,49.0004253387451,240.063339233398,,,5,,,,-2.43000010959804,,,,,0.000676882393624365,7.44191448251818E-8,0.00175526697948225,7.61611836209697E-5,0.000676794126335722,7.44094403681022E-8,0.000676794126018131,5.36705643546678E-8,2.07337153237887E-8,5.15386780752632E-8,1.00013041970255,10.005763053894,2,20,10,5,2.21420154053221,0.194983517070209,0.0404026173055172,172.741912841797,48.9997940063477,49.000602722168,240.063339233398,240.063339233398,,,746.318664550781,0,1,,,,,,1,1,1,49.0003662109375,0,49.0002555847168,,,,,,,,,,,,,,,,,,,,,,,,,,,,,,,,,
,3754578032.828,49.0004367828369,240.063339233398,,,5,,,,-2.43000010959804,,,,,0.000677182955147976,5.91664496446918E-8,-0.00224068113059417,6.45448239425051E-5,0.00067709464831071,5.91587341491957E-8,0.000677094647792943,3.98772108591857E-8,-2.64793186270024E-8,4.36985569581795E-8,1.00013042022631,10.005763053894,2,20,10,5,2.21519832947256,0.194915604567242,0.0404026173055172,172.741912841797,48.9994735717773,49.001106262207,240.063339233398,240.063339233398,,,746.306213378906,0,1,,,,,,1,1,1,49.0002937316895,0,49.0002225240072,,,,,,,,,,,,,,,,,,,,,,,,,,,,,,,,,
,3754578288.93526,49.0011787414551,240.063339233398,,,5,,,,-2.43000010959804,,,,,0.000676998402751949,1.23996510255756E-7,0.000849682527175766,0.000162899850569249,0.000676910096997858,1.23980336502172E-7,0.000676910096923425,5.66807264382205E-8,1.00384127200072E-8,1.10265221577919E-7,1.00013045418362,10.005763053894,2,20,10,5,2.21458410917546,0.194981928999144,0.0404026173055172,172.741912841797,48.9995880126953,49.0012397766113,240.063339233398,240.063339233398,,,746.318664550781,0,1,,,,,,1,1,1,49.0012130737305,0,49.0004944271512,,,,,,,,,,,,,,,,,,,,,,,,,,,,,,,,,
,3754578545.22752,49.000036239624,240.063339233398,,,5,,,,-2.43000010959804,,,,,0.000677378664767011,8.13013338853511E-8,-0.000488608263402135,7.56462152269204E-5,0.000677290267122821,8.12907240938729E-8,0.000677290267098194,6.31203160678206E-8,-5.77581148291172E-9,5.12250673323578E-8,1.00013051663147,10.005763053894,2,20,10,5,2.21583257086081,0.195039695387068,0.0404026173055172,172.741912841797,48.9996223449707,49.0004234313965,240.063339233398,240.063339233398,,,746.368408203125,0,1,,,,,,1,1,1,49.0002632141113,0,49.0001213971306,,,,,,,,,,,,,,,,,,,,,,,,,,,,,,,,,
,3754578801.42544,49.0000648498535,240.063339233398,,,5,,,,-2.43000010959804,,,,,0.000677395324523067,1.16549248519662E-7,0.0013655561845507,0.000140628408971149,0.00067730692381803,1.16534038736885E-7,0.000677306923625663,6.71486998525706E-8,1.61425617459306E-8,9.52430275266337E-8,1.00013051794087,10.005763053894,2,20,10,5,2.21588075487542,0.195116202457653,0.0404026173055172,172.741912841797,48.9996223449707,49.0008277893066,240.063339233398,240.063339233398,,,746.393249511719,0,1,,,,,,1,1,1,48.9999237060547,0,49.0001274557675,,,,,,,,,,,,,,,,,,,,,,,,,,,,,,,,,
,3754579057.56748,49.0002708435059,240.063339233398,,,5,,,,-2.43000010959804,,,,,0.000677653594078765,9.73551508146851E-8,0.00122241540975931,9.98370609119893E-5,0.000677565231013809,9.73424561288008E-8,0.000677565230859599,7.00052912885258E-8,1.44559719142394E-8,6.76373636150624E-8,1.00013041263174,10.005763053894,2,20,10,5,2.2167260883967,0.195185054228287,0.0404026173055172,172.741912841797,48.9996185302734,49.0005302429199,240.063339233398,240.063339233398,,,746.380859375,0,1,,,,,,1,1,1,49.0004043579102,0,48.9999783039093,,,,,,,,,,,,,,,,,,,,,,,,,,,,,,,,,
,3754579313.95331,48.9999656677246,240.063339233398,,,5,,,,-2.43000010959804,,,,,0.00067777656337276,8.83315939504749E-8,0.000278018784801937,0.000100778771484925,0.000677688115991523,8.83200669981021E-8,0.000677688115983545,5.60068240763045E-8,3.28837530587952E-9,6.82910674351713E-8,1.00013051340159,10.005763053894,2,20,10,5,2.2171315602878,0.195183930193061,0.0404026173055172,172.741912841797,48.9991912841797,49.0007629394531,240.063339233398,240.063339233398,,,746.393249511719,0,1,,,,,,1,1,1,49,0,49.0000080781824,,,,,,,,,,,,,,,,,,,,,,,,,,,,,,,,,
,3754579570.15443,49.0000038146973,240.063339233398,,,5,,,,-2.43000010959804,,,,,0.000678085689289769,6.50086740031681E-8,-0.0032362501124954,5.57066185703704E-5,0.000677997278166308,6.5000197950666E-8,0.000677997277084782,5.29074218856831E-8,-3.82954693210797E-8,3.77601700610062E-8,1.0001304004106,10.005763053894,2,20,10,5,2.21815474084404,0.195136900658379,0.0404026173055172,172.741912841797,48.999454498291,49.0004272460937,240.063339233398,240.063339233398,,,746.430603027344,0,1,,,,,,1,1,1,48.9998054504395,0,48.9999802533318,,,,,,,,,,,,,,,,,,,,,,,,,,,,,,,,,
,3754579828.92133,48.9986248016357,240.063339233398,,,5,,,,-2.43000010959804,,,,,0.000678294476756793,1.17560407910047E-7,-0.00325994220247505,9.62867746788301E-5,0.000678206003404178,1.17545073916068E-7,0.000678206002306421,9.7748210416574E-8,-3.85877003518475E-8,6.52850041149652E-8,1.000130452034,10.005763053894,2,20,10,5,2.21883780693601,0.195196072132595,0.0404026173055172,172.741912841797,48.9984130859375,48.9998321533203,240.063339233398,240.063339233398,,,746.480346679688,0,1,,,,,,1,1,1,48.9985694885254,0,48.9990097848993,,,,,,,,,,,,,,,,,,,,,,,,,,,,,,,,,
,3754580085.20658,48.9995613098145,240.063339233398,,,5,,,,-2.43000010959804,,,,,0.000678427321838093,6.4250591970106E-8,-0.0030336470130452,6.71627993575118E-5,0.000678338802087142,6.42422086898097E-8,0.000678338801136315,4.52981297694093E-8,-3.59160918537283E-8,4.55537135340119E-8,1.00013049489529,10.005763053894,2,20,10,5,2.21927159923748,0.195243062306298,0.0404026173055172,172.741912841797,48.9993934631348,49.0004386901855,240.063339233398,240.063339233398,,,746.492797851562,0,1,,,,,,1,1,1,48.9997062683105,0,48.9997462104349,,,,,,,,,,,,,,,,,,,,,,,,,,,,,,,,,
,3754580341.48279,49.0001239776611,240.063339233398,,,5,,,,-2.43000010959804,,,,,0.000678670826980834,8.12568844020756E-8,-0.00362145885724185,8.46634927114996E-5,0.000678582257985489,8.12462800850338E-8,0.000678582256630005,5.74553546925789E-8,-4.28907285631979E-8,5.74442359580637E-8,1.00013052064698,10.005763053894,2,20,10,5,2.22007015719386,0.195290361269211,0.0404026173055172,172.741912841797,48.9994201660156,49.0004615783691,240.063339233398,240.063339233398,,,746.480346679688,0,1,,,,,,1,1,1,49.0003547668457,0,49.0000511618222,,,,,,,,,,,,,,,,,,,,,,,,,,,,,,,,,
,3754580597.6981,49.0005073547363,240.063339233398,,,5,,,,-2.43000010959804,,,,,0.000679245221998948,8.2683504300207E-8,-0.00137444557336242,9.67541296795956E-5,0.000679156644042142,8.26727218380927E-8,0.00067915664384673,5.01739620668045E-8,-1.62920175075152E-8,6.57065633452056E-8,1.00013042345618,10.005763053894,2,20,10,5,2.22194145307816,0.195542784164702,0.0404026173055172,172.741912841797,48.9998893737793,49.0010986328125,240.063339233398,240.063339233398,,,746.467895507812,0,1,,,,,,1,1,1,49.0007133483887,0,49.0004503586713,,,,,,,,,,,,,,,,,,,,,,,,,,,,,,,,,
,3754580853.96025,48.999849319458,240.063339233398,,,5,,,,-2.43000010959804,,,,,0.000678896389961837,6.26775397148736E-8,0.00139477863051241,7.37482568938068E-5,0.000678807877935549,6.26693680466707E-8,0.000678807877734417,3.77053403015266E-8,1.65245456178546E-8,5.00575369361612E-8,1.0001303933398,10.005763053894,2,20,10,5,2.22079090741367,0.195549701754617,0.0404026173055172,172.741912841797,48.9991760253906,49.00048828125,240.063339233398,240.063339233398,,,746.542541503906,0,1,,,,,,1,1,1,48.9995727539063,0,48.9996619754367,,,,,,,,,,,,,,,,,,,,,,,,,,,,,,,,,
,3754581108.71641,49.0023574829102,240.063339233398,,,5,,,,-2.43000010959804,,,,,0.00067893679290595,8.73106070783945E-8,-0.00115886197067461,0.000109175277109859,0.000678848197696278,8.72992138211407E-8,0.000678848197557423,4.61396721614758E-8,-1.37303544310441E-8,7.41099412131786E-8,1.00013050813123,10.005763053894,2,20,10,5,2.22093178749542,0.195462342732264,0.0404026173055172,172.741912841797,49.0006675720215,49.0024032592773,240.063339233398,240.063339233398,,,746.554931640625,0,1,,,,,,1,1,1,49.0023918151855,0,49.0014886295094,,,,,,,,,,,,,,,,,,,,,,,,,,,,,,,,,
,3754581366.45382,49.000114440918,240.063339233398,,,5,,,,-2.43000010959804,,,,,0.000679217322668921,6.28312477234012E-8,0.00130462087313887,5.51792467889622E-5,0.000679128682650294,6.2823048045945E-8,0.00067912868247424,5.04288569736726E-8,1.54637123778727E-8,3.74655274901073E-8,1.00013052021052,10.005763053894,2,20,10,5,2.22184104349771,0.19563864458756,0.0404026173055172,172.741912841797,48.999137878418,49.0003776550293,240.063339233398,240.063339233398,,,746.492797851562,0,1,,,,,,1,1,1,49.0002326965332,0,48.9997029024012,,,,,,,,,,,,,,,,,,,,,,,,,,,,,,,,,
,3754581622.69207,49.0000839233398,240.063339233398,,,5,,,,-2.43000010959804,,,,,0.000679469780615297,5.69426916215681E-8,-0.00247206850388082,5.5828232854499E-5,0.000679381108598875,5.69352604989037E-8,0.000679381107966523,4.24673234665361E-8,-2.93123970814354E-8,3.79229524914215E-8,1.00013051881381,10.005763053894,2,20,10,5,2.22267977415247,0.195564851820017,0.0404026173055172,172.741912841797,48.9997253417969,49.0004920959473,240.063339233398,240.063339233398,,,746.480346679688,0,1,,,,,,1,1,1,49.0003852844238,0,49.0001213971306,,,,,,,,,,,,,,,,,,,,,,,,,,,,,,,,,
,3754581879.04684,49.0004005432129,240.063339233398,,,5,,,,-2.43000010959804,,,,,0.00068015843321575,5.90516417554363E-8,0.000772792772334441,5.46716918652393E-5,0.00068006973949437,5.90439413291752E-8,0.000680069739432511,4.58726885760684E-8,9.17262988330023E-9,3.71736929896147E-8,1.00013041856773,10.005763053894,2,20,10,5,2.22492140243327,0.195889065007169,0.0404026173055172,172.741912841797,48.9999656677246,49.0011177062988,240.063339233398,240.063339233398,,,746.530090332031,0,1,,,,,,1,1,1,49.0004081726074,0,49.0004721747504,,,,,,,,,,,,,,,,,,,,,,,,,,,,,,,,,
,3754582135.32022,48.9998340606689,240.063339233398,,,5,,,,-2.43000010959804,,,,,0.000679826106148787,7.19859082535057E-8,-0.00179454321671901,6.91194188330974E-5,0.00067973739540337,7.19765147872605E-8,0.000679737395069964,5.45337016922693E-8,-2.12898426766916E-8,4.69754623251258E-8,1.00013050737832,10.005763053894,2,20,10,5,2.22384307113046,0.195693709162009,0.0404026173055172,172.741912841797,48.9995155334473,49.0005722045898,240.063339233398,240.063339233398,,,746.517639160156,0,1,,,,,,1,1,1,48.999698638916,0,48.9999939413632,,,,,,,,,,,,,,,,,,,,,,,,,,,,,,,,,
,3754582390.7575,48.9999256134033,240.063339233398,,,5,,,,-2.43000010959804,,,,,0.000680002956289825,5.95343533498588E-8,9.14872080741702E-5,6.0421742517013E-5,0.00067991421961863,5.95265844419605E-8,0.000679914219617763,4.30832244714515E-8,1.08565507287683E-9,4.10761490949234E-8,1.00013051156842,10.005763053894,2,20,10,5,2.22441513780526,0.19581783720183,0.0404026173055172,172.741912841797,48.9995956420898,49.0010299682617,240.063339233398,240.063339233398,,,746.492797851562,0,1,,,,,,1,1,1,49.0001831054687,0,49.00024952608,,,,,,,,,,,,,,,,,,,,,,,,,,,,,,,,,
,3754582647.78775,49.0004997253418,240.063339233398,,,5,,,,-2.43000010959804,,,,,0.000680675112377726,5.39522232519374E-8,0.000605316403314404,6.1766992512916E-5,0.000680586348191607,5.39451875529686E-8,0.000680586348153625,3.38109812101781E-8,7.19023432311449E-9,4.20345192636949E-8,1.00013042310701,10.005763053894,2,20,10,5,2.2266121266078,0.196031362128331,0.0404026173055172,172.741912841797,48.9995002746582,49.0005836486816,240.063339233398,240.063339233398,,,746.480346679688,0,1,,,,,,1,1,1,49.0005760192871,0,49.0000919765896,,,,,,,,,,,,,,,,,,,,,,,,,,,,,,,,,
,3754582902.89927,49.0006427764893,240.063339233398,,,5,,,,-2.43000010959804,,,,,0.000680462343687161,1.02493135222625E-7,-0.00311172424969186,0.000120386524342077,0.000680373602793525,1.02479768821831E-7,0.000680373601790124,6.15966587766468E-8,-3.6950977115839E-8,8.19021040348123E-8,1.00013042965405,10.005763053894,2,20,10,5,2.22592883034698,0.1958256794534,0.0404026173055172,172.741912841797,48.9993896484375,49.0007019042969,240.063339233398,240.063339233398,,,746.455444335938,0,1,,,,,,1,1,1,49.0006828308105,0,49.0000794354607,,,,,,,,,,,,,,,,,,,,,,,,,,,,,,,,,
,3754583160.45795,49.0004367828369,240.063339233398,,,5,,,,-2.43000010959804,,,,,0.00068036040367454,9.38638590021138E-8,-0.0011398900781483,5.36231468950432E-5,0.000680271604445701,9.38516080859079E-8,0.000680271604311074,8.6482653847104E-8,-1.3533891307395E-8,3.64537367614465E-8,1.00013053496318,10.005763053894,2,20,10,5,2.22558862438373,0.195872937497001,0.0404026173055172,172.741912841797,48.9994163513184,49.0005302429199,240.063339233398,240.063339233398,,,746.405700683594,0,1,,,,,,1,1,1,49.0004501342773,0,48.9999840680291,,,,,,,,,,,,,,,,,,,,,,,,,,,,,,,,,
,3754583416.77832,49.0012893676758,240.063339233398,,,5,,,,-2.43000010959804,,,,,0.000680770372240297,1.34067001041966E-7,0.000271909906447654,0.000184546964919568,0.000680681571035318,1.34049513043479E-7,0.000680681571027653,4.67969232380455E-8,3.23032628010411E-9,1.25615763034128E-7,1.00013045924667,10.005763053894,2,20,10,5,2.22692487992896,0.196045836375662,0.0404026173055172,172.741912841797,48.999755859375,49.0022392272949,240.063339233398,240.063339233398,,,746.418151855469,0,1,,,,,,1,1,1,49.0009765625,0,49.0005564970129,,,,,,,,,,,,,,,,,,,,,,,,,,,,,,,,,
,3754583673.04481,48.9999103546143,240.063339233398,,,5,,,,-2.43000010959804,,,,,0.000680819313537948,6.61519699177182E-8,-0.00205754152332904,8.04917628338001E-5,0.000680730470811918,6.61433374931926E-8,0.000680730470372986,3.70538076098364E-8,-2.4445626213533E-8,5.47901125783804E-8,1.00013051087007,10.005763053894,2,20,10,5,2.22709294469024,0.195969390002917,0.0404026173055172,172.741912841797,48.9990005493164,49.0003280639648,240.063339233398,240.063339233398,,,746.405700683594,0,1,,,,,,1,1,1,48.9995880126953,0,48.9996844397651,,,,,,,,,,,,,,,,,,,,,,,,,,,,,,,,,
,3754583929.22972,49.0002593994141,240.063339233398,,,5,,,,-2.43000010959804,,,,,0.000681411799843431,5.52799022031725E-8,-0.000798192544807286,5.25957728801121E-5,0.000681322868919027,5.52726876336493E-8,0.000681322868852914,4.20876544037991E-8,-9.49156882377553E-9,3.58287502577656E-8,1.00013052684485,10.005763053894,2,20,10,5,2.22902677180366,0.19618892308124,0.0404026173055172,172.741912841797,48.9996147155762,49.000675201416,240.063339233398,240.063339233398,,,746.368408203125,0,1,,,,,,1,1,1,49.0005416870117,0,49.0000424385071,,,,,,,,,,,,,,,,,,,,,,,,,,,,,,,,,
,3754584185.28986,49.0000782012939,240.063339233398,,,5,,,,-2.43000010959804,,,,,0.000681224582567183,8.69939768674312E-8,-0.000310801146155448,0.000106269743516883,0.000681135759865519,8.69826340001132E-8,0.000681135759855498,4.8239773581252E-8,-3.694823190324E-9,7.23802656974067E-8,1.00013040381506,10.005763053894,2,20,10,5,2.2284126799789,0.196153978917891,0.0404026173055172,172.741912841797,48.9995994567871,49.0002784729004,240.063339233398,240.063339233398,,,746.343505859375,0,1,,,,,,1,1,1,48.9999465942383,0,48.9999504089355,,,,,,,,,,,,,,,,,,,,,,,,,,,,,,,,,
,3754584441.48931,49.000057220459,240.063339233398,,,5,,,,-2.43000010959804,,,,,0.00068135985121769,8.58209921493399E-8,-0.00230949787515922,7.11671274313961E-5,0.000681270933376171,8.58097924618836E-8,0.000681270932822719,7.08082320498373E-8,-2.74609017624882E-8,4.84717934094451E-8,1.0001305175917,10.005763053894,2,20,10,5,2.22886201163329,0.196115176790235,0.0404026173055172,172.741912841797,48.999568939209,49.000659942627,240.063339233398,240.063339233398,,,746.380859375,0,1,,,,,,1,1,1,49.000114440918,0,49.0001274557675,,,,,,,,,,,,,,,,,,,,,,,,,,,,,,,,,
,3754584697.74001,49.0001258850098,240.063339233398,,,5,,,,-2.43000010959804,,,,,0.000681490200983586,7.22858922901147E-8,-0.00582460732465417,6.90249284504447E-5,0.000681401263990272,7.22764587136523E-8,0.000681401260469313,5.48856095358241E-8,-6.92702816884456E-8,4.70261241233779E-8,1.00013052073428,10.005763053894,2,20,10,5,2.22930044121271,0.196015926914752,0.0404026173055172,172.741912841797,48.9990768432617,49.0002708435059,240.063339233398,240.063339233398,,,746.318664550781,0,1,,,,,,1,1,1,49.0002632141113,0,48.9998290118049,,,,,,,,,,,,,,,,,,,,,,,,,,,,,,,,,
,3754584953.9688,48.9999084472656,240.063339233398,,,5,,,,-2.43000010959804,,,,,0.000681628308346278,5.55120022740583E-8,-0.00368277257723193,6.49153412429928E-5,0.000681539360110897,5.55047583046041E-8,0.000681539358703017,3.35211852857239E-8,-4.38069694717952E-8,4.42392171211549E-8,1.00013051078278,10.005763053894,2,20,10,5,2.22974488929987,0.196139004894767,0.0404026173055172,172.741912841797,48.9992523193359,49.0005836486816,240.063339233398,240.063339233398,,,746.281372070312,0,1,,,,,,1,1,1,48.9998207092285,0,48.9999421437581,,,,,,,,,,,,,,,,,,,,,,,,,,,,,,,,,
,3754585210.26316,48.9997825622559,240.063339233398,,,5,,,,-2.43000010959804,,,,,0.000681896207815318,1.25503799152952E-7,-0.00325226616020657,0.000132366226657476,0.000681807228548378,1.25487422414206E-7,0.000681807227449984,8.7201948543311E-8,-3.87012550461079E-8,9.02380925907193E-8,1.00013050502138,10.005763053894,2,20,10,5,2.23061976865384,0.196232852780299,0.0404026173055172,172.741912841797,48.9993591308594,49.0006217956543,240.063339233398,240.063339233398,,,746.244018554687,0,1,,,,,,1,1,1,48.9999961853027,0,48.9998779296875,,,,,,,,,,,,,,,,,,,,,,,,,,,,,,,,,
,3754585466.49147,49.0001125335693,240.063339233398,,,5,,,,-2.43000010959804,,,,,0.000682042471682565,1.02686125907954E-7,-0.00521507726524817,0.000101440832484584,0.000681953463032538,1.02672725051229E-7,0.000681953460207652,7.58780044424058E-8,-6.20715875816916E-8,6.9168033883315E-8,1.00013052012322,10.005763053894,2,20,10,5,2.23110494980742,0.196198511719152,0.0404026173055172,172.741912841797,48.9991149902344,49.0002021789551,240.063339233398,240.063339233398,,,746.231567382813,0,1,,,,,,1,1,1,49.0000419616699,0,48.9997340931612,,,,,,,,,,,,,,,,,,,,,,,,,,,,,,,,,
,3754585722.6497,49.0010833740234,240.063339233398,,,5,,,,-2.43000010959804,,,,,0.000682155862763636,9.23321323197703E-8,0.00150052095057251,9.18314705679287E-5,0.000682066887261694,9.23200891808529E-8,0.000682066887027791,6.78302672755046E-8,1.78626709088979E-8,6.26263020439036E-8,1.00013044981893,10.005763053894,2,20,10,5,2.23145286085226,0.19649267502572,0.0404026173055172,172.741912841797,48.9995880126953,49.0016212463379,240.063339233398,240.063339233398,,,746.231567382813,0,1,,,,,,1,1,1,49.000919342041,0,49.0004938910989,,,,,,,,,,,,,,,,,,,,,,,,,,,,,,,,,
,3754585979.45975,48.9999847412109,240.063339233398,,,5,,,,-2.43000010959804,,,,,0.000682332544253862,8.89503567674558E-8,-0.002696283446741,8.85216698697473E-5,0.000682243501738178,8.89387489911535E-8,0.000682243500982746,6.52975361147931E-8,-3.21057131142494E-8,6.03848726871946E-8,1.00013051427453,10.005763053894,2,20,10,5,2.23204520756684,0.196380077695629,0.0404026173055172,172.741912841797,48.9997024536133,49.0004234313965,240.063339233398,240.063339233398,,,746.231567382813,0,1,,,,,,1,1,1,49.0002670288086,0,49.0000839233398,,,,,,,,,,,,,,,,,,,,,,,,,,,,,,,,,
,3754586234.70421,49.0003070831299,240.063339233398,,,5,,,,-2.43000010959804,,,,,0.000682351603649315,8.09163116228975E-8,-0.00479693042169504,6.26327614534593E-5,0.000682262626853016,8.09057603555772E-8,0.000682262624461886,6.87081896511903E-8,-5.71205483951253E-8,4.27191611992811E-8,1.00013041429033,10.005763053894,2,20,10,5,2.23211475331066,0.19630372617613,0.0404026173055172,172.741912841797,48.999813079834,49.0005722045898,240.063339233398,240.063339233398,,,746.244018554687,0,1,,,,,,1,1,1,49.000415802002,0,49.000213174259,,,,,,,,,,,,,,,,,,,,,,,,,,,,,,,,,
,3754586489.29082,49.0003776550293,240.063339233398,,,5,,,,-2.43000010959804,,,,,0.000682608649927361,6.67073134177366E-8,-0.00343237573292932,6.2309749374452E-5,0.000682519637408762,6.66986147498001E-8,0.000682519636184062,5.13880711203382E-8,-4.08871972629928E-8,4.25202464253596E-8,1.0001304175202,10.005763053894,2,20,10,5,2.23295092767296,0.196430857185543,0.0404026173055172,172.741912841797,48.9992866516113,49.0008811950684,240.063339233398,240.063339233398,,,746.206726074219,0,1,,,,,,1,1,1,48.9998741149902,0,49.0000747231876,,,,,,,,,,,,,,,,,,,,,,,,,,,,,,,,,
,3754586745.3959,49.0003433227539,240.063339233398,,,5,,,,-2.43000010959804,,,,,0.00068313591919256,9.39083015021483E-8,-0.00187369101155443,8.05041813592558E-5,0.000683046838990901,9.38960559589114E-8,0.000683046838625667,7.61193765591817E-8,-2.23370505355912E-8,5.49755385319736E-8,1.00013041594891,10.005763053894,2,20,10,5,2.23467038351859,0.196643377561773,0.0404026173055172,172.741912841797,48.9998664855957,49.0006332397461,240.063339233398,240.063339233398,,,746.181823730469,0,1,,,,,,1,1,1,49.0002975463867,0,49.0002957512351,,,,,,,,,,,,,,,,,,,,,,,,,,,,,,,,,
,3754587001.47272,49.0006618499756,240.063339233398,,,5,,,,-2.43000010959804,,,,,0.000682711767781844,1.28712938507972E-7,0.00013902783144637,7.15318170512925E-5,0.000682622732939054,1.28696152600967E-7,0.000682622732937044,1.19087581456594E-7,1.65637956343274E-9,4.87939303306316E-8,1.00013043052699,10.005763053894,2,20,10,5,2.23327599704584,0.196599734363759,0.0404026173055172,172.741912841797,49.0001068115234,49.000862121582,240.063339233398,240.063339233398,,,746.132080078125,0,1,,,,,,1,1,1,49.000659942627,0,49.0004734712489,,,,,,,,,,,,,,,,,,,,,,,,,,,,,,,,,
,3754587257.85047,49.0000610351562,240.063339233398,,,5,,,,-2.43000010959804,,,,,0.000682878390516139,6.92025697271958E-8,0.000334277256948567,8.03601992127219E-5,0.000682789352716089,6.91935466790925E-8,0.000682789352704469,4.2161062523937E-8,3.98355609851182E-9,5.4865214014751E-8,1.00013040302942,10.005763053894,2,20,10,5,2.23382038028553,0.196655332039825,0.0404026173055172,172.741912841797,48.9996337890625,49.0007286071777,240.063339233398,240.063339233398,,,746.069885253906,0,1,,,,,,1,1,1,48.9998550415039,0,48.9999854143928,,,,,,,,,,,,,,,,,,,,,,,,,,,,,,,,,
,3754587514.03572,48.9987888336182,240.063339233398,,,5,,,,-2.43000010959804,,,,,0.000682693148674217,1.0137788889473E-7,0.000375567025606038,0.000123251915343081,0.000682604096456922,1.01364664907045E-7,0.000682604096442258,5.65448241286097E-8,4.47438873071711E-9,8.41277490248138E-8,1.00013045954127,10.005763053894,2,20,10,5,2.23321427824128,0.196603599289172,0.0404026173055172,172.741912841797,48.9981575012207,49.0026397705078,240.063339233398,240.063339233398,,,746.057495117187,0,1,,,,,,1,1,1,48.998893737793,0,49.0004023501748,,,,,,,,,,,,,,,,,,,,,,,,,,,,,,,,,
,3754587770.44168,48.9998455047607,240.063339233398,,,5,,,,-2.43000010959804,,,,,0.000683068922138099,8.11920164582067E-8,-0.0048718661838425,6.81319631450835E-5,0.00068297978787882,8.11814216411805E-8,0.000682979785409808,6.652938705593E-8,-5.80738434328386E-8,4.65216495585161E-8,1.00013050790208,10.005763053894,2,20,10,5,2.23446150880383,0.196507169928664,0.0404026173055172,172.741912841797,48.9995574951172,49.0005378723145,240.063339233398,240.063339233398,,,746.069885253906,0,1,,,,,,1,1,1,48.9996910095215,0,48.9999093448415,,,,,,,,,,,,,,,,,,,,,,,,,,,,,,,,,
,3754588026.71943,49.0000553131103,240.063339233398,,,5,,,,-2.43000010959804,,,,,0.000683357273512944,7.66321085628017E-8,-0.000530431334293979,6.44529008507278E-5,0.000683268173452155,7.66221168267128E-8,0.000683268173422874,6.27096280773407E-8,-6.32554181127611E-9,4.40278472493038E-8,1.00013040276754,10.005763053894,2,20,10,5,2.23538986413523,0.196759503807533,0.0404026173055172,172.741912841797,48.9995002746582,49.0005226135254,240.063339233398,240.063339233398,,,746.082336425781,0,1,,,,,,1,1,1,48.9999694824219,0,48.9998512268066,,,,,,,,,,,,,,,,,,,,,,,,,,,,,,,,,
,3754588281.70147,49.0006713867188,240.063339233398,,,5,,,,-2.43000010959804,,,,,0.000683392331737151,8.42813471019265E-8,-0.00295146138031033,6.3506183957795E-5,0.000683303207841419,8.42703556382498E-8,0.000683303206934826,7.22474004585622E-8,-3.5198806006884E-8,4.33797875326428E-8,1.00013043096346,10.005763053894,2,20,10,5,2.23551285887749,0.196675134399691,0.0404026173055172,172.741912841797,48.9996681213379,49.0008926391602,240.063339233398,240.063339233398,,,746.032592773437,0,1,,,,,,1,1,1,49.0005798339844,0,49.0002577039931,,,,,,,,,,,,,,,,,,,,,,,,,,,,,,,,,
,3754588539.05327,49.0007839202881,240.063339233398,,,5,,,,-2.43000010959804,,,,,0.000683486020368973,9.07568143662233E-8,-0.00230638710264408,7.75154029632848E-5,0.00068339688073567,9.0744977943954E-8,0.000683396880181986,7.36866491049557E-8,-2.75094913566956E-8,5.29615782028049E-8,1.00013043611379,10.005763053894,2,20,10,5,2.23581711830912,0.196727270244689,0.0404026173055172,172.741912841797,48.9991912841797,49.0012702941895,240.063339233398,240.063339233398,,,746.020141601562,0,1,,,,,,1,1,1,49.0004234313965,0,49.0000731150309,,,,,,,,,,,,,,,,,,,,,,,,,,,,,,,,,
,3754588795.17223,49.0005397796631,240.063339233398,,,5,,,,-2.43000010959804,,,,,0.000683635139835105,7.20144139553599E-8,-0.00126394118418638,6.77989520735674E-5,0.000683545988390459,7.20050227045811E-8,0.000683545988224138,5.51154657500824E-8,-1.50789802195595E-8,4.63358255547339E-8,1.00013042494018,10.005763053894,2,20,10,5,2.23630133702482,0.196810878069155,0.0404026173055172,172.741912841797,49.0000877380371,49.0009117126465,240.063339233398,240.063339233398,,,745.995300292969,0,1,,,,,,1,1,1,49.0005912780762,0,49.000522825453,,,,,,,,,,,,,,,,,,,,,,,,,,,,,,,,,
,3754589051.39042,49.0002613067627,240.063339233398,,,5,,,,-2.43000010959804,,,,,0.000683721576762415,8.66890234417175E-8,-0.00625213221390109,8.08062804907954E-5,0.000683632422757401,8.66777196100216E-8,0.000683632418687314,6.68013275260786E-8,-7.45981697191263E-8,5.52323249333856E-8,1.00013041219528,10.005763053894,2,20,10,5,2.23660121661296,0.196641046564463,0.0404026173055172,172.741912841797,48.999626159668,49.0008010864258,240.063339233398,240.063339233398,,,746.020141601562,0,1,,,,,,1,1,1,48.999885559082,0,49.0003408544204,,,,,,,,,,,,,,,,,,,,,,,,,,,,,,,,,
,3754589307.49005,49.0009326934814,240.063339233398,,,5,,,,-2.43000010959804,,,,,0.000683938658435484,6.74563851187E-8,-0.00450733835122019,5.24459074960078E-5,0.000683849455113862,6.74475870583139E-8,0.000683849452997813,5.71282022080014E-8,-5.37969968907169E-8,3.58545047723511E-8,1.00013044292272,10.005763053894,2,20,10,5,2.23730534695802,0.196771607603413,0.0404026173055172,172.741912841797,48.9998817443848,49.0010032653809,240.063339233398,240.063339233398,,,746.020141601562,0,1,,,,,,1,1,1,49.000862121582,0,49.0003713719985,,,,,,,,,,,,,,,,,,,,,,,,,,,,,,,,,
,3754589563.6895,49.0011940002441,240.063339233398,,,5,,,,-2.43000010959804,,,,,0.000684079100192814,1.27905437965099E-7,-0.0037120537082993,7.94853820547367E-5,0.000683989870375002,1.27888754252757E-7,0.000683989868939503,1.15770736060117E-7,-4.43140342022703E-8,5.43384774945037E-8,1.00013045488198,10.005763053894,2,20,10,5,2.23776202920766,0.196843072592739,0.0404026173055172,172.741912841797,48.9997711181641,49.0013313293457,240.063339233398,240.063339233398,,,746.032592773437,0,1,,,,,,1,1,1,49.0012397766113,0,49.0005708582261,,,,,,,,,,,,,,,,,,,,,,,,,,,,,,,,,
,3754589819.97659,48.9998054504395,240.063339233398,,,5,,,,-2.43000010959804,,,,,0.000684044153861428,7.47733017475759E-8,-0.00332909977444729,5.48710068774179E-5,0.000683954893596954,7.47635446512658E-8,0.000683954892442423,6.46693290898065E-8,-3.97403456253642E-8,3.75162029514733E-8,1.00013050606891,10.005763053894,2,20,10,5,2.2376463963863,0.196847979632959,0.0404026173055172,172.741912841797,48.9989280700684,49.0007133483887,240.063339233398,240.063339233398,,,746.020141601562,0,1,,,,,,1,1,1,48.9995422363281,0,48.9997213027057,,,,,,,,,,,,,,,,,,,,,,,,,,,,,,,,,
,3754590076.13271,48.9995002746582,240.063339233398,,,5,,,,-2.43000010959804,,,,,0.000684757706982038,7.27468005521518E-8,-0.00163570997388263,6.61891464626127E-5,0.000684668363168232,7.27373089078268E-8,0.000684668362889224,5.69017212521959E-8,-1.95462716416719E-8,4.53090523592142E-8,1.00013049210189,10.005763053894,2,20,10,5,2.23997474749721,0.197119523969257,0.0404026173055172,172.741912841797,48.9987640380859,48.9999732971191,240.063339233398,240.063339233398,,,745.970397949219,0,1,,,,,,1,1,1,48.9991722106934,0,48.9994040595161,,,,,,,,,,,,,,,,,,,,,,,,,,,,,,,,,
,3754590332.32684,49.000072479248,240.063339233398,,,5,,,,-2.43000010959804,,,,,0.000684246645403423,5.8912798297107E-8,-0.000646432533003782,5.7370573151603E-5,0.000684157350355929,5.89051101028612E-8,0.000684157350312385,4.39280699670454E-8,-7.71892053328946E-9,3.92445749779579E-8,1.00013051829005,10.005763053894,2,20,10,5,2.23829956540012,0.197011048908256,0.0404026173055172,172.741912841797,48.9992408752441,49.0004005432129,240.063339233398,240.063339233398,,,745.908203125,0,1,,,,,,1,1,1,49.0001335144043,0,48.9999952877269,,,,,,,,,,,,,,,,,,,,,,,,,,,,,,,,,
,3754590591.20468,48.9992942810059,240.063339233398,,,5,,,,-2.43000010959804,,,,,0.000684213871843039,9.37504402834912E-8,0.0019188978936846,0.000121978027071961,0.00068412460543507,9.37382090713016E-8,0.000684124605051395,4.27042739249996E-8,2.29120761650867E-8,8.3445771782839E-8,1.00013048267415,10.005763053894,2,20,10,5,2.2381835339759,0.197101826838181,0.0404026173055172,172.741912841797,48.9988441467285,49.0001487731934,240.063339233398,240.063339233398,,,745.833618164062,0,1,,,,,,1,1,1,48.9994354248047,0,48.9994464450412,,,,,,,,,,,,,,,,,,,,,,,,,,,,,,,,,
,3754590847.34986,49.0005664825439,240.063339233398,,,5,,,,-2.43000010959804,,,,,0.000684651784203802,1.13190143064344E-7,-0.00145042297344844,5.55936241106697E-5,0.000684562420809856,1.13175369049906E-7,0.000684562420590511,1.06597451284998E-7,-1.73294624880588E-8,3.80216719664572E-8,1.00013054089916,10.005763053894,2,20,10,5,2.23962761674479,0.197096269446421,0.0404026173055172,172.741912841797,48.9999198913574,49.0007400512695,240.063339233398,240.063339233398,,,745.895812988281,0,1,,,,,,1,1,1,49.0005302429199,0,49.0003399568446,,,,,,,,,,,,,,,,,,,,,,,,,,,,,,,,,
,3754591103.65422,49.0005340576172,240.063339233398,,,5,,,,-2.43000010959804,,,,,0.000684598480386106,8.11888851341161E-8,-0.0027433136596926,6.8685398088203E-5,0.000684509203493448,8.11782974807824E-8,0.000684509202708836,6.61851294729412E-8,-3.27742019284795E-8,4.70047297463607E-8,1.0001304246783,10.005763053894,2,20,10,5,2.23945769628438,0.197030390960062,0.0404026173055172,172.741912841797,48.9997520446777,49.0006065368652,240.063339233398,240.063339233398,,,745.945556640625,0,1,,,,,,1,1,1,49.0004615783691,0,49.0002109303194,,,,,,,,,,,,,,,,,,,,,,,,,,,,,,,,,
,3754591206.25398,48.9996013641357,240.063339233398,,,5,,,,-2.43000010959804,,,,,0.000684652477557816,9.57416460039712E-8,-0.00291799664895542,6.43900570974874E-5,0.000684563144307057,9.57291536625997E-8,0.000684563143419272,8.49871000500512E-8,-3.48638761388483E-8,4.40597740125866E-8,1.00013049672846,10.005763053894,2,20,10,5,2.23963493219339,0.197039106888321,0.0404026173055172,172.741912841797,48.9992332458496,49.0004425048828,240.063339233398,240.063339233398,,,745.945556640625,0,1,,,,,,1,1,1,48.9995918273926,0,48.9997432933134,,,,,,,,,,,,,,,,,,,,,,,,,,,,,,,,,