File: Experimental_Data/Fig3B/Lifetime_180Oe.dat
[Header]
; MPMS3 Data File (default extension .dat)
; Copyright (c) 2007, Quantum Design, Inc. All rights reserved.
TITLE,175Oe
FILEOPENTIME,3755226412.5318,12/29/2018,6:26 am
BYAPP,SQUID AC,0.9.1.0
INFO,MPMS3 Measurement Release 1.1.16 Build 347, MultiVu Release 2.3.3.2,APPNAME
INFO,0,MOMENT_UNITS
INFO,CoIINO3,SAMPLE_MATERIAL
INFO,40 Hours Pumped Turbo,SAMPLE_COMMENT
INFO,,SAMPLE_MASS
INFO,,SAMPLE_VOLUME
INFO,,SAMPLE_MOLECULAR_WEIGHT
INFO,,SAMPLE_SIZE
INFO,,SAMPLE_SHAPE
INFO,Brass,SAMPLE_HOLDER
INFO,Standard,SAMPLE_HOLDER_DETAIL
INFO,65.37,SAMPLE_OFFSET
DATATYPE,COMMENT,1
DATATYPE,TIME,2
STARTUPAXIS,X,2
STARTUPAXIS,Y1,5
FIELDGROUP, VSM,2,3,4,5,6,8,9,10,11,14,15
FIELDGROUP, DC, 2,3,4,14,56,57,58,59,60,61,62,63,64,65,66,67,68,69
FIELDGROUP, AC, 2,3,4,11,16,17,18,19,20,21,22,23,24,25,26,27,28,29,30
STARTUPGROUP, All
[Data]
Comment,Time Stamp (sec),Temperature (K),Magnetic Field (Oe),Moment (emu),M. Std. Err. (emu),Transport Action,Averaging Time (sec),Frequency (Hz),Peak Amplitude (mm),Center Position (mm),Lockin Signal' (V),Lockin Signal (V),Range,M. Quad. Signal (emu),AC Moment (emu),AC M. Std Err. (emu),AC Phase (deg),AC Phase Std. Err. (deg),AC Susceptibility (emu/Oe),AC Suscept. Std Err. (emu/Oe),AC X' (emu/Oe),AC X' Std Err. (emu/Oe),AC X'' (emu/Oe),AC X'' Std Err. (emu/Oe),AC Drive (Oe),AC Frequency (Hz),AC Averaging Time (sec),AC Cycles,AC Range,AC Measure Type,AC Signal' (V),AC Signal'' (V),AC Trim Coil Ratio,AC Trim Coil Phase,Min. Temperature (K),Max. Temperature (K),Min. Field (Oe),Max. Field (Oe),Mass (grams),Motor Lag (deg),Pressure (Torr),Measure Count,Measurement Number,SQUID Status (code),Motor Status (code),Measure Status (code),Motor Current (amps),Motor Temp. (C),Temp. Status (code),Field Status (code),Chamber Status (code),Chamber Temp (K),Redirection State,Average Temp (K),Rotation Angle (deg),Rotator state,DC Moment Fixed Ctr (emu),DC Moment Err Fixed Ctr (emu),DC Moment Free Ctr (emu),DC Moment Err Free Ctr (emu),DC Fixed Fit,DC Free Fit,DC Calculated Center (mm),DC Calculated Center Err (mm),DC Scan Length (mm),DC Scan Time (s),DC Number of Points,DC Squid Drift,DC Min V (V),DC Max V (V),DC Scans per Measure,Map 01,Map 02,Map 03,Map 04,Map 05,Map 06,Map 07,Map 08,Map 09,Map 10,Map 11,Map 12,Map 13,Map 14,Map 15,Map 16
,3755226416.40999,48.9810657501221,174.577163696289,,,5,,,,-2.43999995291233,,,,,0.00066219822841709,1.84466907479731E-7,0.24381933524403,6.39917168302592E-5,0.000662112158724899,1.84442931260429E-7,0.000662106163686999,1.79602382898644E-7,2.81757680118053E-6,4.19783152242703E-8,1.0001299926169,10.005763053894,2,20,10,5,2.16535186622752,0.199751820996012,0.0404026173055172,172.741912841797,48.9151229858398,48.9908905029297,174.577163696289,174.577163696289,,,136.738723754883,0,1,,,,,,1,1,1,48.9757614135742,0,48.9489218393962,,,,,,,,,,,,,,,,,,,,,,,,,,,,,,,,,
,3755226622.48384,48.999979019165,174.577163696289,,,5,,,,-2.43999995291233,,,,,0.000682089049656973,8.65780424415636E-8,0.0885913060193557,5.07782406105066E-5,0.000682000039095243,8.65667442684071E-8,0.000681999223844392,7.93571452004671E-8,1.05451484572593E-6,3.45867708649387E-8,1.00013051401265,10.005763053894,2,20,10,5,2.23094301400348,0.199708361977468,0.0404026173055172,172.741912841797,48.9992942810059,49.0002822875977,174.577163696289,174.577163696289,,,137.422760009766,0,1,,,,,,1,1,1,48.9999465942383,0,48.999770716617,,,,,,,,,,,,,,,,,,,,,,,,,,,,,,,,,
,3755226827.43668,48.9997406005859,174.577163696289,,,5,,,,-2.43999995291233,,,,,0.00068778660443936,6.39405038072843E-8,0.0813307139872883,7.32983118454977E-5,0.000687696857866919,6.39321604620957E-8,0.000687696165030231,3.93267849025228E-8,9.76177619878473E-7,5.04056061423911E-8,1.00013050310092,10.005763053894,2,20,10,5,2.24960379396796,0.201091474982802,0.0404026173055172,172.741912841797,48.9992370605469,49.0001487731934,174.577163696289,174.577163696289,,,138.231170654297,0,1,,,,,,1,1,1,48.999698638916,0,48.9997516208225,,,,,,,,,,,,,,,,,,,,,,,,,,,,,,,,,
,3755227032.3821,49.0014533996582,174.577163696289,,,5,,,,-2.43999995291233,,,,,0.000691565841852375,4.47278972857442E-8,0.0753990591448055,4.30205952595558E-5,0.000691475627271855,4.47220625434146E-8,0.000691475028538564,3.3398758341407E-8,9.09955272673815E-7,2.97419874821671E-8,1.00013046675394,10.005763053894,2,20,10,5,2.26198579743083,0.201962247845547,0.0404026173055172,172.741912841797,48.9996528625488,49.0018920898438,174.577163696289,174.577163696289,,,138.902770996094,0,1,,,,,,1,1,1,49.0010871887207,0,49.0004993014865,,,,,,,,,,,,,,,,,,,,,,,,,,,,,,,,,
,3755227237.30183,48.9997406005859,174.577163696289,,,5,,,,-2.43999995291233,,,,,0.000694072125047038,6.94058436405255E-8,0.0692494440616365,5.36597277808585E-5,0.000693981558301701,6.93967871446095E-8,0.000693981051421651,5.85704517319592E-8,8.38767284596593E-7,3.72211801251448E-8,1.00013050310092,10.005763053894,2,20,10,5,2.27020513478051,0.202450515183519,0.0404026173055172,172.741912841797,48.999210357666,49.000560760498,174.577163696289,174.577163696289,,,139.549499511719,0,1,,,,,,1,1,1,49.0000419616699,0,48.9999086856842,,,,,,,,,,,,,,,,,,,,,,,,,,,,,,,,,
,3755227442.16613,48.9996490478516,174.577163696289,,,5,,,,-2.43999995291233,,,,,0.000695910420006841,4.86688283167959E-8,0.066612040271198,3.08458279173861E-5,0.000695819696130546,4.86624834990828E-8,0.000695819225882629,4.36824693191628E-8,8.08959395834141E-7,2.1444793645053E-8,1.00013038417395,10.005763053894,2,20,10,5,2.27622726113894,0.202881943771896,0.0404026173055172,172.741912841797,48.9960556030273,49.0005683898926,174.577163696289,174.577163696289,,,140.146484375,0,1,,,,,,1,1,1,48.9993171691895,0,48.997750899371,,,,,,,,,,,,,,,,,,,,,,,,,,,,,,,,,
,3755227647.09636,49.0014877319336,174.577163696289,,,5,,,,-2.43999995291233,,,,,0.000697578847910919,9.05316749056251E-8,0.0643946572317686,0.000100404842280593,0.000697487847839542,9.05198649304476E-8,0.000697487407324228,5.73584219139981E-8,7.83905582767833E-7,7.00275473121989E-8,1.00013046832523,10.005763053894,2,20,10,5,2.28169232881968,0.203280037431789,0.0404026173055172,172.741912841797,49.0004806518555,49.001953125,174.577163696289,174.577163696289,,,140.755905151367,0,1,,,,,,1,1,1,49.0012626647949,0,49.0010952949524,,,,,,,,,,,,,,,,,,,,,,,,,,,,,,,,,
,3755227852.06722,49.000545501709,174.577163696289,,,5,,,,-2.43999995291233,,,,,0.000698920744638269,4.74661544581257E-8,0.0614375071858308,3.73965122096174E-5,0.000698829599646528,4.74599644826682E-8,0.000698829197889797,3.96237440414397E-8,7.49345600796083E-7,2.61229235889592E-8,1.00013042520206,10.005763053894,2,20,10,5,2.28609201216652,0.203553089910678,0.0404026173055172,172.741912841797,48.9992866516113,49.0009117126465,174.577163696289,174.577163696289,,,141.328002929688,0,1,,,,,,1,1,1,49.0006294250488,0,49.0000902811686,,,,,,,,,,,,,,,,,,,,,,,,,,,,,,,,,
,3755228057.11601,49.0008068084717,174.577163696289,,,5,,,,-2.43999995291233,,,,,0.000700130115255483,4.91081715409783E-8,0.0607709042316076,4.96898022349823E-5,0.000700038804181051,4.91017668458951E-8,0.000700038410415054,3.46598237874228E-8,7.42497676309241E-7,3.47804560409067E-8,1.00013043716132,10.005763053894,2,20,10,5,2.29005010107554,0.203878662844613,0.0404026173055172,172.741912841797,48.9994850158691,49.0010414123535,174.577163696289,174.577163696289,,,141.887680053711,0,1,,,,,,1,1,1,49.0005722045898,0,49.0001896128935,,,,,,,,,,,,,,,,,,,,,,,,,,,,,,,,,
,3755228262.2838,49.000244140625,174.577163696289,,,5,,,,-2.43999995291233,,,,,0.00070094493698442,5.61702473592935E-8,0.0602276975038256,4.51825670601368E-5,0.000700853537686625,5.61629230733265E-8,0.000700853150478474,4.63926299205624E-8,7.36717214556546E-7,3.16543491039404E-8,1.00013041140963,10.005763053894,2,20,10,5,2.29271723005454,0.204094204159635,0.0404026173055172,172.741912841797,48.9995727539063,49.0006675720215,174.577163696289,174.577163696289,,,142.447341918945,0,1,,,,,,1,1,1,49.0003318786621,0,49.0001759248621,,,,,,,,,,,,,,,,,,,,,,,,,,,,,,,,,
,3755228467.27354,49.0001373291016,174.577163696289,,,5,,,,-2.43999995291233,,,,,0.000702117251165587,6.30765532131196E-8,0.0595510619047044,5.48764242680382E-5,0.000702025702435957,6.30683286917786E-8,0.000702025323246082,4.9942793982177E-8,7.29658779279862E-7,3.85140417669719E-8,1.00013040652117,10.005763053894,2,20,10,5,2.29655416048399,0.204408427894972,0.0404026173055172,172.741912841797,48.9994773864746,49.0006790161133,174.577163696289,174.577163696289,,,142.994583129883,0,1,,,,,,1,1,1,48.9998245239258,0,48.9999712775735,,,,,,,,,,,,,,,,,,,,,,,,,,,,,,,,,
,3755228672.16427,49.000846862793,174.577163696289,,,5,,,,-2.43999995291233,,,,,0.000702523943030281,7.1690053102525E-8,0.0571863942257318,6.76071847312978E-5,0.000702432318464962,7.16807031436824E-8,0.000702431968588589,5.37002046644761E-8,7.01091165049436E-7,4.74806404986928E-8,1.00013043899449,10.005763053894,2,20,10,5,2.29789284771225,0.204431988029365,0.0404026173055172,172.741912841797,48.9995956420898,49.0009574890137,174.577163696289,174.577163696289,,,143.529373168945,0,1,,,,,,1,1,1,49.0007858276367,0,49.0004063774558,,,,,,,,,,,,,,,,,,,,,,,,,,,,,,,,,
,3755228877.08176,49.0001316070557,174.577163696289,,,5,,,,-2.43999995291233,,,,,0.000703747656244972,6.77763999559835E-8,0.0566819127582505,3.74937136676714E-5,0.000703655814387124,6.77675548672149E-8,0.000703655470057824,6.24335465580494E-8,6.9611673523129E-7,2.63532494555199E-8,1.00013052099616,10.005763053894,2,20,10,5,2.30189730684582,0.204767817996077,0.0404026173055172,172.741912841797,48.9996528625488,49.0005226135254,174.577163696289,174.577163696289,,,144.051742553711,0,1,,,,,,1,1,1,49.0003929138184,0,49.0000455519732,,,,,,,,,,,,,,,,,,,,,,,,,,,,,,,,,
,3755229084.70201,49.0010318756103,174.577163696289,,,5,,,,-2.43999995291233,,,,,0.000704313315187729,5.09077740711182E-8,0.0527542127646043,4.74312471313107E-5,0.000704221451286725,5.0901134147356E-8,0.000704221152784033,3.84142529739047E-8,6.48401040027811E-7,3.33956677720926E-8,1.000130447462,10.005763053894,2,20,10,5,2.30376157118536,0.204774478657884,0.0404026173055172,172.741912841797,49.0002632141113,49.0019035339355,174.577163696289,174.577163696289,,,144.598968505859,0,1,,,,,,1,1,1,49.0009841918945,0,49.0008953942193,,,,,,,,,,,,,,,,,,,,,,,,,,,,,,,,,
,3755229289.6233,48.9997386932373,174.577163696289,,,5,,,,-2.43999995291233,,,,,0.000704930034558623,5.6286251461496E-8,0.056138260977356,4.71224550275061E-5,0.000704838131929208,5.62789133509664E-8,0.000704837793605831,4.54406759067745E-8,6.90598522305419E-7,3.32033290665418E-8,1.00013038827676,10.005763053894,2,20,10,5,2.30576670893066,0.205089979408904,0.0404026173055172,172.741912841797,48.9985885620117,49.0009689331055,174.577163696289,174.577163696289,,,145.121322631836,0,1,,,,,,1,1,1,48.9989814758301,0,48.9996392991808,,,,,,,,,,,,,,,,,,,,,,,,,,,,,,,,,
,3755229495.60064,48.9997310638428,174.577163696289,,,5,,,,-2.43999995291233,,,,,0.000705739527650666,4.58831506381649E-8,0.0561293511191439,3.82556260703614E-5,0.000705647519732965,4.58771688092006E-8,0.000705647181128588,3.7100481332561E-8,6.91281825691649E-7,2.69864577675578E-8,1.00013038792758,10.005763053894,2,20,10,5,2.30841452467179,0.205325129903359,0.0404026173055172,172.741912841797,48.9990005493164,49.0004577636719,174.577163696289,174.577163696289,,,145.668563842773,0,1,,,,,,1,1,1,48.9994010925293,0,48.9996187546674,,,,,,,,,,,,,,,,,,,,,,,,,,,,,,,,,
,3755229698.12918,48.9994411468506,174.577163696289,,,5,,,,-2.43999995291233,,,,,0.00070628788753576,6.90987680895522E-8,0.0533010069234505,5.0631033410927E-5,0.000706195736480806,6.90897526094798E-8,0.000706195430903832,5.91286135581223E-8,6.56958308799921E-7,3.57379486587206E-8,1.00013048939578,10.005763053894,2,20,10,5,2.31021830438983,0.205370626114363,0.0404026173055172,172.741912841797,48.9992637634277,49.0005226135254,174.577163696289,174.577163696289,,,146.19091796875,0,1,,,,,,1,1,1,48.9994773864746,0,48.9998772144318,,,,,,,,,,,,,,,,,,,,,,,,,,,,,,,,,
,3755229901.88655,48.9994945526123,174.577163696289,,,5,,,,-2.43999995291233,,,,,0.00070718918515735,5.87597888057699E-8,0.0537801284344779,3.99461702116566E-5,0.000707096914779877,5.87521221332484E-8,0.000707096603287574,5.15263667018198E-8,6.63709572181836E-7,2.82284500047335E-8,1.00013049184001,10.005763053894,2,20,10,5,2.31316466617271,0.20565204495485,0.0404026173055172,172.741912841797,48.9987602233887,49.0003623962402,174.577163696289,174.577163696289,,,146.713272094727,0,1,,,,,,1,1,1,48.9992218017578,0,48.9996669993681,,,,,,,,,,,,,,,,,,,,,,,,,,,,,,,,,
,3755230106.89503,48.9997673034668,174.577163696289,,,5,,,,-2.43999995291233,,,,,0.000707195355483985,5.83105142465576E-8,0.0533176165755522,4.16122251140449E-5,0.000707103075475807,5.83029054653492E-8,0.000707102769315498,5.03424770211721E-8,6.58007370468857E-7,2.94085666613353E-8,1.00013050432303,10.005763053894,2,20,10,5,2.31318650911553,0.205635164069427,0.0404026173055172,172.741912841797,48.999626159668,49.0003852844238,174.577163696289,174.577163696289,,,147.248077392578,0,1,,,,,,1,1,1,48.9997940063477,0,49.0000125660616,,,,,,,,,,,,,,,,,,,,,,,,,,,,,,,,,
,3755230313.12843,49.0005168914795,174.577163696289,,,5,,,,-2.43999995291233,,,,,0.000707961583320654,5.50398014702224E-8,0.0544333041179659,5.17181080857788E-5,0.000707869260256241,5.50326239011903E-8,0.000707868940803106,4.10950883382418E-8,6.72504279555056E-7,3.66030518935507E-8,1.00013042389265,10.005763053894,2,20,10,5,2.3156887781191,0.205903052443082,0.0404026173055172,172.741912841797,48.9994964599609,49.0009613037109,174.577163696289,174.577163696289,,,147.770431518555,0,1,,,,,,1,1,1,49.0007820129395,0,49.0001429389505,,,,,,,,,,,,,,,,,,,,,,,,,,,,,,,,,
,3755230518.04741,49.0007781982422,174.577163696289,,,5,,,,-2.43999995291233,,,,,0.000708293786566008,6.40596337836293E-8,0.0526474404001354,5.73109071840577E-5,0.000708201411711545,6.40512792004606E-8,0.000708201112735757,4.95576183302923E-8,6.50745773675911E-7,4.05784281687258E-8,1.00013043585191,10.005763053894,2,20,10,5,2.31678180948143,0.205927458506771,0.0404026173055172,172.741912841797,48.999340057373,49.000904083252,174.577163696289,174.577163696289,,,148.305221557617,0,1,,,,,,1,1,1,49.000675201416,0,49.0001699659559,,,,,,,,,,,,,,,,,,,,,,,,,,,,,,,,,
,3755230723.2257,48.999174118042,174.577163696289,,,5,,,,-2.43999995291233,,,,,0.000708705480088447,8.15065967345341E-8,0.0530064294785459,6.5958976325874E-5,0.000708613022263392,8.14959633714892E-8,0.000708612719020284,6.67721427902276E-8,6.55563833033505E-7,4.67233666707415E-8,1.00013047717464,10.005763053894,2,20,10,5,2.31812713982335,0.206061685365034,0.0404026173055172,172.741912841797,48.9981575012207,49.0000152587891,174.577163696289,174.577163696289,,,148.790267944336,0,1,,,,,,1,1,1,48.9987869262695,0,48.9994042714437,,,,,,,,,,,,,,,,,,,,,,,,,,,,,,,,,
,3755230928.15933,49.0013332366943,174.577163696289,,,5,,,,-2.43999995291233,,,,,0.000709087736767603,5.39529074150883E-8,0.0509525939574118,4.32104045042563E-5,0.000708995240359163,5.39458695692731E-8,0.000708994960009119,4.44100636310959E-8,6.30502667827197E-7,3.062520354001E-8,1.00013046125443,10.005763053894,2,20,10,5,2.3193848652582,0.206089677837256,0.0404026173055172,172.741912841797,48.9999923706055,49.0013847351074,174.577163696289,174.577163696289,,,149.312637329102,0,1,,,,,,1,1,1,49.0013542175293,0,49.0006256103516,,,,,,,,,,,,,,,,,,,,,,,,,,,,,,,,,
,3755231133.09079,48.9999313354492,174.577163696289,,,5,,,,-2.43999995291233,,,,,0.000709424594182133,5.33411183818922E-8,0.0519654433987524,3.84833455052617E-5,0.000709332017962175,5.33341576433604E-8,0.000709331726217091,4.58271585841892E-8,6.43341413452024E-7,2.72837663753815E-8,1.0001305118303,10.005763053894,2,20,10,5,2.3204830606213,0.206228607731768,0.0404026173055172,172.741912841797,48.9995155334473,49.0004577636719,174.577163696289,174.577163696289,,,149.85986328125,0,1,,,,,,1,1,1,49.0001640319824,0,49.0000336590935,,,,,,,,,,,,,,,,,,,,,,,,,,,,,,,,,
,3755231338.09953,49.0009384155273,174.577163696289,,,5,,,,-2.43999995291233,,,,,0.000709684291197257,6.77514067682439E-8,0.0489670501769464,5.78089906907167E-5,0.000709591729792259,6.77425702116527E-8,0.000709591470648267,5.39190772552401E-8,6.06442741565475E-7,4.10096199302572E-8,1.0001304431846,10.005763053894,2,20,10,5,2.32134330650801,0.206182618594703,0.0404026173055172,172.741912841797,48.9999084472656,49.0010566711426,174.577163696289,174.577163696289,,,150.407089233398,0,1,,,,,,1,1,1,49.0008316040039,0,49.000379450181,,,,,,,,,,,,,,,,,,,,,,,,,,,,,,,,,
,3755231543.01066,49.0002765655518,174.577163696289,,,5,,,,-2.43999995291233,,,,,0.000710059068889241,4.94789801994922E-8,0.0501936535750476,4.40789452247771E-5,0.000709966480106192,4.94725283439159E-8,0.000709966207672903,3.83226504853597E-8,6.21962163654106E-7,3.12874658692026E-8,1.00013041289363,10.005763053894,2,20,10,5,2.32256476922267,0.206341226941244,0.0404026173055172,172.741912841797,48.9994773864746,49.0009117126465,174.577163696289,174.577163696289,,,150.929458618164,0,1,,,,,,1,1,1,49.0000915527344,0,49.0000345566694,,,,,,,,,,,,,,,,,,,,,,,,,,,,,,,,,
,3755231747.94499,48.9999771118164,174.577163696289,,,5,,,,-2.43999995291233,,,,,0.000710587198623033,5.25015105025033E-8,0.0505954941844706,4.57115425230168E-5,0.000710494469200914,5.24946592184684E-8,0.000710494192182207,4.12481606087072E-8,6.27407715159529E-7,3.2469654954456E-8,1.00013051392536,10.005763053894,2,20,10,5,2.32429080461496,0.206511002125824,0.0404026173055172,172.741912841797,48.9993286132812,49.0002479553223,174.577163696289,174.577163696289,,,151.45182800293,0,1,,,,,,1,1,1,48.9998893737793,0,48.9998516506619,,,,,,,,,,,,,,,,,,,,,,,,,,,,,,,,,
,3755231952.94278,48.9990272521973,174.577163696289,,,5,,,,-2.43999995291233,,,,,0.00071087430660468,6.64934732790531E-8,0.0531037952417668,6.14256198829508E-5,0.000710781570611173,6.64847989772125E-8,0.000710781265321588,5.01472629738498E-8,6.58777904832009E-7,4.36518099426805E-8,1.00013047045301,10.005763053894,2,20,10,5,2.32522087162165,0.206696241307709,0.0404026173055172,172.741912841797,48.9984931945801,48.9999542236328,174.577163696289,174.577163696289,,,151.974182128906,0,1,,,,,,1,1,1,48.9984931945801,0,48.9990508135627,,,,,,,,,,,,,,,,,,,,,,,,,,,,,,,,,
,3755232157.92777,49.0001983642578,174.577163696289,,,5,,,,-2.43999995291233,,,,,0.000711044844298263,5.24341289900547E-8,0.0510567786041323,4.59643924596727E-5,0.000710952129518354,5.2427291982842E-8,0.000710951847243696,4.10031376060871E-8,6.33535680628189E-7,3.26705318461524E-8,1.00013040931458,10.005763053894,2,20,10,5,2.3257860742864,0.206662726513218,0.0404026173055172,172.741912841797,48.9997138977051,49.0006523132324,174.577163696289,174.577163696289,,,152.533843994141,0,1,,,,,,1,1,1,49.0002365112305,0,49.0001642563764,,,,,,,,,,,,,,,,,,,,,,,,,,,,,,,,,
,3755232362.78413,49.0009136199951,174.577163696289,,,5,,,,-2.43999995291233,,,,,0.00071137812884556,4.10394767583232E-8,0.0480514528261748,3.85019435002778E-5,0.000711285347326878,4.10341241830539E-8,0.000711285097187755,3.05626366357693E-8,5.96523698551074E-7,2.73810991258609E-8,1.00013044204978,10.005763053894,2,20,10,5,2.32688707069634,0.206637540393375,0.0404026173055172,172.741912841797,48.9998664855957,49.001579284668,174.577163696289,174.577163696289,,,153.068649291992,0,1,,,,,,1,1,1,49.0008583068848,0,49.0004859500461,,,,,,,,,,,,,,,,,,,,,,,,,,,,,,,,,
,3755232567.75658,49.0015659332275,174.577163696289,,,5,,,,-2.43999995291233,,,,,0.000711283171167017,6.1608451489083E-8,0.047725863421765,4.03155779836741E-5,0.000711190380803729,6.16004143657163E-8,0.000711190134075878,5.45306389233848E-8,5.92402640202527E-7,2.86534547417128E-8,1.00013047190428,10.005763053894,2,20,10,5,2.32657764244683,0.206596734759048,0.0404026173055172,172.741912841797,48.9996681213379,49.0018997192383,174.577163696289,174.577163696289,,,153.603439331055,0,1,,,,,,1,1,1,49.0012855529785,0,49.0006654527452,,,,,,,,,,,,,,,,,,,,,,,,,,,,,,,,,
,3755232772.64872,49.0007648468018,174.577163696289,,,5,,,,-2.43999995291233,,,,,0.000711786101207728,7.10399984161703E-8,0.0482193447457373,6.04378445284344E-5,0.000711693271324467,7.10307335053374E-8,0.000711693019289858,5.653522849742E-8,5.98951256861756E-7,4.30015469611358E-8,1.00013043524086,10.005763053894,2,20,10,5,2.32822092467146,0.206762869608771,0.0404026173055172,172.741912841797,48.9998359680176,49.0011253356934,174.577163696289,174.577163696289,,,154.125793457031,0,1,,,,,,1,1,1,49.0005836486816,0,49.00037044949,,,,,,,,,,,,,,,,,,,,,,,,,,,,,,,,,
,3755232978.46668,49.0002956390381,174.577163696289,,,5,,,,-2.43999995291233,,,,,0.000712161405358546,6.69045404434899E-8,0.0513875478665105,6.61022223893718E-5,0.000712068541817955,6.68958163081177E-8,0.000712068255425021,4.75405435568741E-8,6.38641304511348E-7,4.70632229861744E-8,1.00013041376657,10.005763053894,2,20,10,5,2.32943708503248,0.2070007007683,0.0404026173055172,172.741912841797,48.9991455078125,49.0013084411621,174.577163696289,174.577163696289,,,154.660598754883,0,1,,,,,,1,1,1,48.999813079834,0,48.9998456169577,,,,,,,,,,,,,,,,,,,,,,,,,,,,,,,,,
,3755233182.57146,49.0000133514404,174.577163696289,,,5,,,,-2.43999995291233,,,,,0.000712450321387597,6.91254199483334E-8,0.0509943712285494,5.36620089721648E-5,0.000712357429375387,6.91164071102995E-8,0.00071235714723377,5.75928687108408E-8,6.34012046154483E-7,3.82117678927907E-8,1.00013040084707,10.005763053894,2,20,10,5,2.33038353309948,0.207068685715386,0.0404026173055172,172.741912841797,48.999626159668,49.0004806518555,174.577163696289,174.577163696289,,,155.220260620117,0,1,,,,,,1,1,1,49.0001335144043,0,49.0000642140706,,,,,,,,,,,,,,,,,,,,,,,,,,,,,,,,,
,3755233386.31701,48.9989032745361,174.577163696289,,,5,,,,-2.43999995291233,,,,,0.000712653542312303,5.82938513229209E-8,0.0486645124357725,5.66063840107916E-5,0.000712560578254005,5.82862470205901E-8,0.000712560321231437,4.20808796324901E-8,6.05217508987252E-7,4.03297180885402E-8,1.00013046477891,10.005763053894,2,20,10,5,2.33105667723527,0.207032964915475,0.0404026173055172,172.741912841797,48.9981689453125,49.0005111694336,174.577163696289,174.577163696289,,,155.742630004883,0,1,,,,,,1,1,1,48.9992485046387,0,48.9994727240668,,,,,,,,,,,,,,,,,,,,,,,,,,,,,,,,,
,3755233592.48084,48.999885559082,174.577163696289,,,5,,,,-2.43999995291233,,,,,0.000712764591286073,5.94125065573104E-8,0.0499538894302676,4.58602211104978E-5,0.000712671580706754,5.94047536586378E-8,0.00071267130984183,4.96141432976312E-8,6.21349654983545E-7,3.26704995689622E-8,1.00013050973525,10.005763053894,2,20,10,5,2.33141525321915,0.207117688344579,0.0404026173055172,172.741912841797,48.999584197998,49.000244140625,174.577163696289,174.577163696289,,,156.289855957031,0,1,,,,,,1,1,1,49.0000457763672,0,48.9998643663194,,,,,,,,,,,,,,,,,,,,,,,,,,,,,,,,,
,3755233797.36971,49.0003128051758,174.577163696289,,,5,,,,-2.43999995291233,,,,,0.000713227891463302,6.29675104920867E-8,0.0521175281525084,5.4613460872274E-5,0.000713134888296179,6.2959299683211E-8,0.000713134593267651,4.94751365737348E-8,6.48683424988393E-7,3.89369269153418E-8,1.00013041455221,10.005763053894,2,20,10,5,2.33292285562946,0.207340412030932,0.0404026173055172,172.741912841797,48.9992332458496,49.0004501342773,174.577163696289,174.577163696289,,,156.83708190918,0,1,,,,,,1,1,1,49.0003242492676,0,48.999903678894,,,,,,,,,,,,,,,,,,,,,,,,,,,,,,,,,
,3755234002.28832,49.0000228881836,174.577163696289,,,5,,,,-2.43999995291233,,,,,0.000713455842322449,5.3406035138293E-8,0.0503641538580748,3.48225893084828E-5,0.0007133627370569,5.33990657047436E-8,0.000713362461457533,4.72778392779425E-8,6.27060253378196E-7,2.48247080818397E-8,1.00013051602041,10.005763053894,2,20,10,5,2.33367481422161,0.207335264685523,0.0404026173055172,172.741912841797,48.9990577697754,49.0008888244629,174.577163696289,174.577163696289,,,157.396759033203,0,1,,,,,,1,1,1,49.0000610351562,0,48.9999548968147,,,,,,,,,,,,,,,,,,,,,,,,,,,,,,,,,
,3755234207.22931,48.9998073577881,174.577163696289,,,5,,,,-2.43999995291233,,,,,0.000713645476824194,4.82079780880983E-8,0.0514277926315989,4.65900359841078E-5,0.000713552435709331,4.82016930009335E-8,0.000713552148269882,3.4907512012864E-8,6.40473383551645E-7,3.32395669831602E-8,1.00013039141934,10.005763053894,2,20,10,5,2.33429124770511,0.207433709195924,0.0404026173055172,172.741912841797,48.9995460510254,49.0006980895996,174.577163696289,174.577163696289,,,157.906677246094,0,1,,,,,,1,1,1,48.999683380127,0,48.9999349257525,,,,,,,,,,,,,,,,,,,,,,,,,,,,,,,,,
,3755234412.2018,49.0001010894775,174.577163696289,,,5,,,,-2.43999995291233,,,,,0.000714052903193152,5.37760518620258E-8,0.0516488570776259,5.62168808998357E-5,0.000713959717456801,5.37690339492515E-8,0.000713959427375422,3.57831007858441E-8,6.43593624615313E-7,4.01332618906797E-8,1.00013051959946,10.005763053894,2,20,10,5,2.33562311415326,0.207561143990441,0.0404026173055172,172.741912841797,48.9996948242188,49.0003509521484,174.577163696289,174.577163696289,,,158.478775024414,0,1,,,,,,1,1,1,49.0002670288086,0,49.0000370250029,,,,,,,,,,,,,,,,,,,,,,,,,,,,,,,,,
,3755234617.09202,49.0001525878906,174.577163696289,,,5,,,,-2.43999995291233,,,,,0.000714099871651471,5.97898413643785E-8,0.0481156194417709,5.55125638763845E-5,0.000714006760015175,5.97820453540664E-8,0.000714006508247946,4.4759569183159E-8,5.99605656781735E-7,3.96292053068649E-8,1.00013040721953,10.005763053894,2,20,10,5,2.33578954096744,0.207430758249272,0.0404026173055172,172.741912841797,48.9994468688965,49.0005493164063,174.577163696289,174.577163696289,,,159.038452148438,0,1,,,,,,1,1,1,48.9999504089355,0,49.0000008975758,,,,,,,,,,,,,,,,,,,,,,,,,,,,,,,,,
,3755234823.32767,49.0003929138184,174.577163696289,,,5,,,,-2.43999995291233,,,,,0.00071415900284196,5.03364783052004E-8,0.047694114416009,4.26250246934381E-5,0.00071406587564253,5.03299143674287E-8,0.000714065628246588,4.00897536054951E-8,5.94402169405446E-7,3.0428801095071E-8,1.00013041821855,10.005763053894,2,20,10,5,2.33598448280207,0.20743074704064,0.0404026173055172,172.741912841797,48.9994125366211,49.0005493164063,174.577163696289,174.577163696289,,,159.5732421875,0,1,,,,,,1,1,1,49.0005569458008,0,49.0000486373901,,,,,,,,,,,,,,,,,,,,,,,,,,,,,,,,,
,3755235027.03086,49.0000743865967,174.577163696289,,,5,,,,-2.43999995291233,,,,,0.000714388277445043,5.6795115487929E-8,0.0508241598375152,3.81352638861946E-5,0.000714295048814327,5.67877036489957E-8,0.000714294767790744,4.98370892132483E-8,6.33614574750076E-7,2.72232956211566E-8,1.00013051837734,10.005763053894,2,20,10,5,2.33672309144492,0.207624996473775,0.0404026173055172,172.741912841797,48.9995460510254,49.0003623962402,174.577163696289,174.577163696289,,,160.120483398438,0,1,,,,,,1,1,1,49.0003128051758,0,48.9999713897705,,,,,,,,,,,,,,,,,,,,,,,,,,,,,,,,,
,3755235232.03953,49.0001010894775,174.577163696289,,,5,,,,-2.43999995291233,,,,,0.000714411393413392,8.09723057138874E-8,0.051278747680561,3.955873818461E-5,0.000714318160893146,8.09617386201913E-8,0.000714317874810692,7.58851656496072E-8,6.39302513333202E-7,2.82178091767565E-8,1.00013051959946,10.005763053894,2,20,10,5,2.33679705487634,0.207650256575469,0.0404026173055172,172.741912841797,48.9991645812988,49.0003089904785,174.577163696289,174.577163696289,,,160.692581176758,0,1,,,,,,1,1,1,48.999942779541,0,48.9997320175171,,,,,,,,,,,,,,,,,,,,,,,,,,,,,,,,,
,3755235437.07151,48.9997901916504,174.577163696289,,,5,,,,-2.43999995291233,,,,,0.000714736016150123,6.75286788372494E-8,0.0471451591072229,3.96987040988942E-5,0.000714642751433032,6.75198671319694E-8,0.000714642509504038,6.12815552041525E-8,5.88035326607503E-7,2.83461364083223E-8,1.00013050537056,10.005763053894,2,20,10,5,2.33787385812789,0.207575945899248,0.0404026173055172,172.741912841797,48.9989280700684,49.0000686645508,174.577163696289,174.577163696289,,,161.264694213867,0,1,,,,,,1,1,1,49.0000686645508,0,48.9997336443733,,,,,,,,,,,,,,,,,,,,,,,,,,,,,,,,,
,3755235641.98211,48.9999980926514,174.577163696289,,,5,,,,-2.43999995291233,,,,,0.000714904380310975,5.27173837564207E-8,0.0523154490354054,4.26557148614708E-5,0.00071481108682376,5.27105042509891E-8,0.000714810788851453,4.30037754672466E-8,6.52677354323236E-7,3.0480691494062E-8,1.00013051488559,10.005763053894,2,20,10,5,2.33840582551834,0.207835857748566,0.0404026173055172,172.741912841797,48.9995498657227,49.0003089904785,174.577163696289,174.577163696289,,,161.824356079102,0,1,,,,,,1,1,1,49.0001373291016,0,49.000036127427,,,,,,,,,,,,,,,,,,,,,,,,,,,,,,,,,
,3755235847.02537,48.9988307952881,174.577163696289,,,5,,,,-2.43999995291233,,,,,0.000714982291661825,9.66138975273044E-8,0.0466815709605495,5.31088053594328E-5,0.000714889026194487,9.66012947811814E-8,0.000714888788918236,8.88439246191326E-8,5.82453705956709E-7,3.79284485798008E-8,1.00013046146174,10.005763053894,2,20,10,5,2.33868109538067,0.207628552368948,0.0404026173055172,172.741912841797,48.9986152648926,49.0001182556152,174.577163696289,174.577163696289,,,162.371597290039,0,1,,,,,,1,1,1,48.998893737793,0,48.9992072161506,,,,,,,,,,,,,,,,,,,,,,,,,,,,,,,,,
,3755236052.072,48.998161315918,174.577163696289,,,5,,,,-2.43999995291233,,,,,0.000715162741472464,6.25178942853273E-8,0.0499020578720453,6.11180681525979E-5,0.000715069392339314,6.25097339172048E-8,0.000715069121126745,4.46986643219184E-8,6.22793336454073E-7,4.36977830357125E-8,1.00013054555845,10.005763053894,2,20,10,5,2.33925966305768,0.207812440625819,0.0404026173055172,172.741912841797,48.9971160888672,49.0033874511719,174.577163696289,174.577163696289,,,162.931259155273,0,1,,,,,,1,1,1,48.9987640380859,0,49.0002450382008,,,,,,,,,,,,,,,,,,,,,,,,,,,,,,,,,
,3755236257.13505,49.0002307891846,174.577163696289,,,5,,,,-2.43999995291233,,,,,0.000715183197616574,6.70643590368051E-8,0.0451188387831705,6.01215928179445E-5,0.000715089860129692,6.70556065678535E-8,0.000715089638411583,5.14673383772947E-8,5.63113392544909E-7,4.29833392437093E-8,1.00013052553544,10.005763053894,2,20,10,5,2.33934391568378,0.207623084482639,0.0404026173055172,172.741912841797,48.9997100830078,49.0004959106445,174.577163696289,174.577163696289,,,163.515808105469,0,1,,,,,,1,1,1,49.0001373291016,0,49.0000731524299,,,,,,,,,,,,,,,,,,,,,,,,,,,,,,,,,
,3755236462.03937,49.00071144104,174.577163696289,,,5,,,,-2.43999995291233,,,,,0.000715407601088958,6.14660840300511E-8,0.0495462168169869,6.41908824776948E-5,0.000715314218582047,6.1458060831796E-8,0.000715313951132068,4.0854660732647E-8,6.18564041719729E-7,4.59128515518808E-8,1.0001305475335,10.005763053894,2,20,10,5,2.34006187790233,0.20786904900016,0.0404026173055172,172.741912841797,48.9999618530273,49.0012741088867,174.577163696289,174.577163696289,,,164.075485229492,0,1,,,,,,1,1,1,49.0011253356934,0,49.0004775103401,,,,,,,,,,,,,,,,,,,,,,,,,,,,,,,,,
,3755236667.00092,49.0001544952393,174.577163696289,,,5,,,,-2.43999995291233,,,,,0.000715651652049411,6.64607440424304E-8,0.0452492262595037,3.52104279799631E-5,0.000715558255923471,6.64520705823708E-8,0.00071555803277597,6.15018340612625E-8,5.65110630024561E-7,2.51674808390772E-8,1.00013052204369,10.005763053894,2,20,10,5,2.34087574409814,0.207764406588249,0.0404026173055172,172.741912841797,48.9993858337402,49.0006675720215,174.577163696289,174.577163696289,,,164.647583007813,0,1,,,,,,1,1,1,49.0003433227539,0,49.0000011219698,,,,,,,,,,,,,,,,,,,,,,,,,,,,,,,,,
,3755236871.93589,49.0003871917725,174.577163696289,,,5,,,,-2.43999995291233,,,,,0.000715511778403233,6.76686817573576E-8,0.047204199851361,6.14376335859648E-5,0.000715418392913398,6.76598499349011E-8,0.000715418150114844,5.14461094001767E-8,5.89410760496628E-7,4.39448873112491E-8,1.00013053269354,10.005763053894,2,20,10,5,2.34041113257912,0.207803654058193,0.0404026173055172,172.741912841797,48.9997253417969,49.0014953613281,174.577163696289,174.577163696289,,,165.244567871094,0,1,,,,,,1,1,1,49.0007629394531,0,49.001049490536,,,,,,,,,,,,,,,,,,,,,,,,,,,,,,,,,
,3755237076.93268,49.0005397796631,174.577163696289,,,5,,,,-2.43999995291233,,,,,0.000716113394205269,6.1284698318647E-8,0.046208639912539,6.58357096118418E-5,0.000716019925195474,6.12766992781126E-8,0.000716019692334775,3.91531158018339E-8,5.77464930017763E-7,4.71366884435938E-8,1.00013053967705,10.005763053894,2,20,10,5,2.34238260782985,0.207937678777625,0.0404026173055172,172.741912841797,48.9994583129883,49.0010108947754,174.577163696289,174.577163696289,,,165.791793823242,0,1,,,,,,1,1,1,49.0007095336914,0,49.000202852137,,,,,,,,,,,,,,,,,,,,,,,,,,,,,,,,,
,3755237281.81132,49.0012321472168,174.577163696289,,,5,,,,-2.43999995291233,,,,,0.000716168394992909,6.02326929598567E-8,0.0468790128448724,5.2786199955628E-5,0.000716074978265955,6.0224836230809E-8,0.000716074738581356,4.68928386853463E-8,5.85887558279299E-7,3.77901121863625E-8,1.00013045662785,10.005763053894,2,20,10,5,2.34256008041328,0.207981056307949,0.0404026173055172,172.741912841797,49.0003890991211,49.0018157958984,174.577163696289,174.577163696289,,,166.351470947266,0,1,,,,,,1,1,1,49.0010681152344,0,49.0009284549289,,,,,,,,,,,,,,,,,,,,,,,,,,,,,,,,,
,3755237486.81115,49.0003223419189,174.577163696289,,,5,,,,-2.43999995291233,,,,,0.00071625615020059,5.37285012081714E-8,0.0469195258768122,4.38454420232016E-5,0.000716162751843416,5.37214951199934E-8,0.000716162511714934,4.35960882218644E-8,5.86465762349604E-7,3.1390765038127E-8,1.00013041498868,10.005763053894,2,20,10,5,2.3428469770385,0.208008201068329,0.0404026173055172,172.741912841797,48.9996376037598,49.0011749267578,174.577163696289,174.577163696289,,,166.960891723633,0,1,,,,,,1,1,1,49.0002708435059,0,49.0002136230469,,,,,,,,,,,,,,,,,,,,,,,,,,,,,,,,,
,3755237691.73721,49.0012836456299,174.577163696289,,,5,,,,-2.43999995291233,,,,,0.000716316576497012,5.19549175958376E-8,0.0455333490943284,3.79042062521144E-5,0.00071622313875345,5.19481404941672E-8,0.000716222912584879,4.42974883210819E-8,5.69187382573485E-7,2.7135619197751E-8,1.00013045898479,10.005763053894,2,20,10,5,2.34304966168638,0.207969059503243,0.0404026173055172,172.741912841797,48.9995956420898,49.0015754699707,174.577163696289,174.577163696289,,,167.545425415039,0,1,,,,,,1,1,1,49.0011825561523,0,49.0005334218343,,,,,,,,,,,,,,,,,,,,,,,,,,,,,,,,,
,3755237896.59775,49.0009269714355,174.577163696289,,,5,,,,-2.43999995291233,,,,,0.000716399694703353,6.96171901735078E-8,0.0474615709683786,4.28258702183472E-5,0.000716306257809112,6.96081103063838E-8,0.000716306012051104,6.24953080837781E-8,5.93359872070819E-7,3.06533112067744E-8,1.00013044266083,10.005763053894,2,20,10,5,2.34331453768703,0.208072053173655,0.0404026173055172,172.741912841797,48.9998092651367,49.0011215209961,174.577163696289,174.577163696289,,,168.129974365234,0,1,,,,,,1,1,1,49.0011215209961,0,49.0004819982192,,,,,,,,,,,,,,,,,,,,,,,,,,,,,,,,,
,3755238100.33245,48.999927520752,174.577163696289,,,5,,,,-2.43999995291233,,,,,0.000716651526330305,5.54514738789562E-8,0.0456781911900226,6.24226074715372E-5,0.000716558089363275,5.5444244120355E-8,0.000716557861647081,3.2763958512766E-8,5.71265007922584E-7,4.47279244840544E-8,1.00013039691885,10.005763053894,2,20,10,5,2.34414474597809,0.208072236218943,0.0404026173055172,172.741912841797,48.9997177124023,49.000560760498,174.577163696289,174.577163696289,,,168.71452331543,0,1,,,,,,1,1,1,49.0001373291016,0,49.0001281289493,,,,,,,,,,,,,,,,,,,,,,,,,,,,,,,,,
,3755238306.38735,49.000467300415,174.577163696289,,,5,,,,-2.43999995291233,,,,,0.000716766177608199,5.64484229204009E-8,0.04734386973744,5.53838265762351E-5,0.000716672707990454,5.64410617855182E-8,0.000716672463324755,4.01315311341514E-8,5.92191183341711E-7,3.96869457669059E-8,1.00013042162301,10.005763053894,2,20,10,5,2.34451371595191,0.208173680897933,0.0404026173055172,172.741912841797,48.9999160766602,49.0007820129395,174.577163696289,174.577163696289,,,169.299057006836,0,1,,,,,,1,1,1,49.0005912780762,0,49.0002957512351,,,,,,,,,,,,,,,,,,,,,,,,,,,,,,,,,
,3755238510.54604,48.9998188018799,174.577163696289,,,5,,,,-2.43999995291233,,,,,0.0007168096411859,5.4954986081506E-8,0.0484046647834608,5.67286655208769E-5,0.000716716104946566,5.49478150245958E-8,0.000716715849178505,3.69656438717556E-8,6.05496582346624E-7,4.06546866809194E-8,1.00013050667996,10.005763053894,2,20,10,5,2.3446520282993,0.208229718977388,0.0404026173055172,172.741912841797,48.9990692138672,49.0002021789551,174.577163696289,174.577163696289,,,169.896041870117,0,1,,,,,,1,1,1,48.9994087219238,0,48.9996149399701,,,,,,,,,,,,,,,,,,,,,,,,,,,,,,,,,
,3755238714.05418,48.999792098999,174.577163696289,,,5,,,,-2.43999995291233,,,,,0.000717037507436405,4.43339190631681E-8,0.0483523006157878,3.45201585786779E-5,0.000716943942338957,4.43281339997448E-8,0.000716943687042846,3.6782065472322E-8,6.05033829795575E-7,2.4739909528718E-8,1.00013050545785,10.005763053894,2,20,10,5,2.34539755904461,0.208293767905677,0.0404026173055172,172.741912841797,48.9995574951172,49.0003395080566,174.577163696289,174.577163696289,,,170.480590820313,0,1,,,,,,1,1,1,48.9997863769531,0,48.9998819687787,,,,,,,,,,,,,,,,,,,,,,,,,,,,,,,,,
,3755238918.94487,48.99853515625,174.577163696289,,,5,,,,-2.43999995291233,,,,,0.000717207233636343,5.72113627570215E-8,0.0482710973209972,4.31879719974155E-5,0.000717113687639364,5.72039006265289E-8,0.000717113433139785,4.81028787027834E-8,6.04160739332706E-7,3.09580249272317E-8,1.00013044793119,10.005763053894,2,20,10,5,2.34595302081946,0.208339750455604,0.0404026173055172,172.741912841797,48.9976997375488,49.0027198791504,174.577163696289,174.577163696289,,,171.09001159668,0,1,,,,,,1,1,1,48.9990119934082,0,49.0004142312443,,,,,,,,,,,,,,,,,,,,,,,,,,,,,,,,,
,3755239123.88654,48.9998874664307,174.577163696289,,,5,,,,-2.43999995291233,,,,,0.000717123534102495,4.4085741784581E-8,0.0441973968674798,4.13161939551598E-5,0.000717029954650355,4.40799889130502E-8,0.000717029741318652,3.26450521215464E-8,5.53109750804853E-7,2.96200269168708E-8,1.00013050982254,10.005763053894,2,20,10,5,2.34569404883358,0.208148656558686,0.0404026173055172,172.741912841797,48.9995193481445,49.0001564025879,174.577163696289,174.577163696289,,,171.662109375,0,1,,,,,,1,1,1,48.9997520446777,0,48.9998885706851,,,,,,,,,,,,,,,,,,,,,,,,,,,,,,,,,
,3755239328.99675,49.0002040863037,174.577163696289,,,5,,,,-2.43999995291233,,,,,0.000717322702742023,5.54504206503581E-8,0.0474493792829716,5.61792368749921E-5,0.000717229086907956,5.54431839668422E-8,0.000717228840959739,3.80884015141549E-8,5.93971691748679E-7,4.02892084617907E-8,1.00013052431333,10.005763053894,2,20,10,5,2.34633370379356,0.208339637215505,0.0404026173055172,172.741912841797,49.0000038146973,49.0003662109375,174.577163696289,174.577163696289,,,172.271530151367,0,1,,,,,,1,1,1,49.0002517700195,0,49.0002116035013,,,,,,,,,,,,,,,,,,,,,,,,,,,,,,,,,
,3755239533.89074,49.0013427734375,174.577163696289,,,5,,,,-2.43999995291233,,,,,0.000717377439909077,4.79660112694926E-8,0.049044429689812,5.32013646886014E-5,0.000717283861843608,4.79597543588439E-8,0.000717283599061888,2.90522326366954E-8,6.13985426724145E-7,3.8158954610733E-8,1.0001304616909,10.005763053894,2,20,10,5,2.34650694597814,0.208420854826613,0.0404026173055172,172.741912841797,49.0001983642578,49.001537322998,174.577163696289,174.577163696289,,,172.856079101562,0,1,,,,,,1,1,1,49.0013198852539,0,49.0010435316298,,,,,,,,,,,,,,,,,,,,,,,,,,,,,,,,,
,3755239738.93128,48.9998664855957,174.577163696289,,,5,,,,-2.43999995291233,,,,,0.000717558233721644,4.92648875749637E-8,0.0472361908020735,4.26886712405952E-5,0.00071746459823318,4.92584589095322E-8,0.000717464354410035,3.85849564971267E-8,5.91497159211265E-7,3.06202042164469E-8,1.00013050886231,10.005763053894,2,20,10,5,2.34710489144861,0.208399313329666,0.0404026173055172,172.741912841797,48.9988594055176,49.0004348754883,174.577163696289,174.577163696289,,,173.477935791016,0,1,,,,,,1,1,1,48.9998817443848,0,48.9997946795295,,,,,,,,,,,,,,,,,,,,,,,,,,,,,,,,,
,3755239943.74739,49.0003509521484,174.577163696289,,,5,,,,-2.43999995291233,,,,,0.000717703719200385,5.60420096760963E-8,0.0505123323073518,3.79199465905942E-5,0.000717610131143611,5.60347018377182E-8,0.000717609852269553,4.89925900848275E-8,6.32649682471732E-7,2.71958439255347E-8,1.00013041629809,10.005763053894,2,20,10,5,2.34756884659296,0.208575796721886,0.0404026173055172,172.741912841797,48.9995880126953,49.0006141662598,174.577163696289,174.577163696289,,,174.087356567383,0,1,,,,,,1,1,1,49.0005416870117,0,49.0001249874339,,,,,,,,,,,,,,,,,,,,,,,,,,,,,,,,,
,3755240097.53717,49.0002040863037,174.577163696289,,,5,,,,-2.43999995291233,,,,,0.000717415235171218,8.3962294364595E-8,0.0479717304113363,9.79604255367832E-5,0.000717321689553498,8.39513463050801E-8,0.000717321438127926,4.59366585872997E-8,6.00588018549736E-7,7.02684277913585E-8,1.00013040957646,10.005763053894,2,20,10,5,2.3466344738796,0.208387906569027,0.0404026173055172,172.741912841797,48.9992980957031,49.0002861022949,174.577163696289,174.577163696289,,,174.559951782227,0,1,,,,,,1,1,1,49.0001335144043,0,48.999877081977,,,,,,,,,,,,,,,,,,,,,,,,,,,,,,,,,