File: Experimental_Data/Fig3B/Lifetime_165Oe.dat
[Header]
; MPMS3 Data File (default extension .dat)
; Copyright (c) 2007, Quantum Design, Inc. All rights reserved.
TITLE,165Oe
FILEOPENTIME,3755212433.35423,12/29/2018,2:33 am
BYAPP,SQUID AC,0.9.1.0
INFO,MPMS3 Measurement Release 1.1.16 Build 347, MultiVu Release 2.3.3.2,APPNAME
INFO,0,MOMENT_UNITS
INFO,CoIINO3,SAMPLE_MATERIAL
INFO,40 Hours Pumped Turbo,SAMPLE_COMMENT
INFO,,SAMPLE_MASS
INFO,,SAMPLE_VOLUME
INFO,,SAMPLE_MOLECULAR_WEIGHT
INFO,,SAMPLE_SIZE
INFO,,SAMPLE_SHAPE
INFO,Brass,SAMPLE_HOLDER
INFO,Standard,SAMPLE_HOLDER_DETAIL
INFO,65.37,SAMPLE_OFFSET
DATATYPE,COMMENT,1
DATATYPE,TIME,2
STARTUPAXIS,X,2
STARTUPAXIS,Y1,5
FIELDGROUP, VSM,2,3,4,5,6,8,9,10,11,14,15
FIELDGROUP, DC, 2,3,4,14,56,57,58,59,60,61,62,63,64,65,66,67,68,69
FIELDGROUP, AC, 2,3,4,11,16,17,18,19,20,21,22,23,24,25,26,27,28,29,30
STARTUPGROUP, All
[Data]
Comment,Time Stamp (sec),Temperature (K),Magnetic Field (Oe),Moment (emu),M. Std. Err. (emu),Transport Action,Averaging Time (sec),Frequency (Hz),Peak Amplitude (mm),Center Position (mm),Lockin Signal' (V),Lockin Signal (V),Range,M. Quad. Signal (emu),AC Moment (emu),AC M. Std Err. (emu),AC Phase (deg),AC Phase Std. Err. (deg),AC Susceptibility (emu/Oe),AC Suscept. Std Err. (emu/Oe),AC X' (emu/Oe),AC X' Std Err. (emu/Oe),AC X'' (emu/Oe),AC X'' Std Err. (emu/Oe),AC Drive (Oe),AC Frequency (Hz),AC Averaging Time (sec),AC Cycles,AC Range,AC Measure Type,AC Signal' (V),AC Signal'' (V),AC Trim Coil Ratio,AC Trim Coil Phase,Min. Temperature (K),Max. Temperature (K),Min. Field (Oe),Max. Field (Oe),Mass (grams),Motor Lag (deg),Pressure (Torr),Measure Count,Measurement Number,SQUID Status (code),Motor Status (code),Measure Status (code),Motor Current (amps),Motor Temp. (C),Temp. Status (code),Field Status (code),Chamber Status (code),Chamber Temp (K),Redirection State,Average Temp (K),Rotation Angle (deg),Rotator state,DC Moment Fixed Ctr (emu),DC Moment Err Fixed Ctr (emu),DC Moment Free Ctr (emu),DC Moment Err Free Ctr (emu),DC Fixed Fit,DC Free Fit,DC Calculated Center (mm),DC Calculated Center Err (mm),DC Scan Length (mm),DC Scan Time (s),DC Number of Points,DC Squid Drift,DC Min V (V),DC Max V (V),DC Scans per Measure,Map 01,Map 02,Map 03,Map 04,Map 05,Map 06,Map 07,Map 08,Map 09,Map 10,Map 11,Map 12,Map 13,Map 14,Map 15,Map 16
,3755212438.17108,48.9665241241455,164.729354858398,,,5,,,,-2.43999995291233,,,,,0.000669453350486364,1.89521800339996E-7,0.239284457735512,4.53723572981602E-5,0.000669366476065517,1.89497206248966E-7,0.000669360638697859,1.87144069745645E-7,2.79546818309205E-6,2.97705951435372E-8,1.00012978603493,10.005763053894,2,20,10,5,2.18909321363285,0.201744048977392,0.0404026173055172,172.741912841797,48.9111251831055,48.981803894043,164.729354858398,164.729354858398,,,105.09871673584,0,1,,,,,,1,1,1,48.9602470397949,0,48.9410877227783,,,,,,,,,,,,,,,,,,,,,,,,,,,,,,,,,
,3755212643.0875,48.9992561340332,164.729354858398,,,5,,,,-2.43999995291233,,,,,0.000692099592184273,6.91566997969449E-8,0.0707664911905699,7.3900483805402E-5,0.000692009298168675,6.91476773438173E-8,0.000692008770341265,4.65464376546545E-8,8.5470619071746E-7,5.11354126189084E-8,1.00013048092827,10.005763053894,2,20,10,5,2.26374943865579,0.201911236641044,0.0404026173055172,172.741912841797,48.9988479614258,49.0002975463867,164.729354858398,164.729354858398,,,105.720573425293,0,1,,,,,,1,1,1,48.9996643066406,0,48.9995096992044,,,,,,,,,,,,,,,,,,,,,,,,,,,,,,,,,
,3755212848.00992,48.9996757507324,164.729354858398,,,5,,,,-2.43999995291233,,,,,0.000697839830915454,4.79926469107648E-8,0.0575400992886346,5.04804938080891E-5,0.00069774885465469,4.79863901862749E-8,0.000697748502798618,3.25927833585275E-8,7.00724066727873E-7,3.52193713182605E-8,1.00013038539606,10.005763053894,2,20,10,5,2.28257179681168,0.203058965918443,0.0404026173055172,172.741912841797,48.9990615844727,49.0005493164063,164.729354858398,164.729354858398,,,106.39217376709,0,1,,,,,,1,1,1,48.9995269775391,0,48.9995367262099,,,,,,,,,,,,,,,,,,,,,,,,,,,,,,,,,
,3755213052.96167,49.0008144378662,164.729354858398,,,5,,,,-2.43999995291233,,,,,0.000700782405551339,5.45040814838806E-8,0.0539526002182225,4.22978955553872E-5,0.000700691009160477,5.44969730343884E-8,0.000700690698507147,4.57411684930378E-8,6.59805951296194E-7,2.96254210907183E-8,1.0001304375105,10.005763053894,2,20,10,5,2.29220945953785,0.203771675483149,0.0404026173055172,172.741912841797,48.9986190795898,49.0011253356934,164.729354858398,164.729354858398,,,106.951843261719,0,1,,,,,,1,1,1,49.0005035400391,0,48.9998195872587,,,,,,,,,,,,,,,,,,,,,,,,,,,,,,,,,
,3755213257.94677,49.0007038116455,164.729354858398,,,5,,,,-2.43999995291233,,,,,0.000702884415995812,5.23110680022293E-8,0.0523343318313039,3.46508859621426E-5,0.000702792749017506,5.23042458314333E-8,0.000702792455843576,4.62978139796457E-8,6.41935307171523E-7,2.43361162205709E-8,1.00013043244745,10.005763053894,2,20,10,5,2.29909075820171,0.204317955269899,0.0404026173055172,172.741912841797,48.9993019104004,49.0009536743164,164.729354858398,164.729354858398,,,107.511512756348,0,1,,,,,,1,1,1,49.0008964538574,0,49.0001833438873,,,,,,,,,,,,,,,,,,,,,,,,,,,,,,,,,
,3755213463.12711,49.0006370544434,164.729354858398,,,5,,,,-2.43999995291233,,,,,0.00070469706257713,4.70919474734698E-8,0.0500519961949566,4.8305610837704E-5,0.000704605161354217,4.70858061004004E-8,0.000704604892502175,3.25399274255934E-8,6.15523353888018E-7,3.40327233594613E-8,1.00013042939217,10.005763053894,2,20,10,5,2.3050279691166,0.204753047366975,0.0404026173055172,172.741912841797,48.999195098877,49.0008316040039,164.729354858398,164.729354858398,,,108.021438598633,0,1,,,,,,1,1,1,49.0004425048828,0,48.9999477162081,,,,,,,,,,,,,,,,,,,,,,,,,,,,,,,,,
,3755213668.16469,49.0012836456299,164.729354858398,,,5,,,,-2.43999995291233,,,,,0.00070561638122588,5.82346433241775E-8,0.0488541717845044,6.48004017148988E-5,0.000705524339236841,5.8227047082728E-8,0.000705524082764802,3.60615176552589E-8,6.01576649860904E-7,4.57160360964692E-8,1.00013045898479,10.005763053894,2,20,10,5,2.30803929916313,0.204971905437855,0.0404026173055172,172.741912841797,48.9999961853027,49.0016708374023,164.729354858398,164.729354858398,,,108.531356811523,0,1,,,,,,1,1,1,49.001049041748,0,49.0007510465734,,,,,,,,,,,,,,,,,,,,,,,,,,,,,,,,,
,3755213873.18149,49.0003795623779,164.729354858398,,,5,,,,-2.43999995291233,,,,,0.000706890414482708,4.90144758607976E-8,0.0483404231454339,3.80375785639135E-5,0.000706798235547846,4.90080843436896E-8,0.000706797983988147,4.0982434515043E-8,5.96325279482876E-7,2.68743817093232E-8,1.0001304176075,10.005763053894,2,20,10,5,2.3122084451301,0.205321266160636,0.0404026173055172,172.741912841797,48.9994316101074,49.0008087158203,164.729354858398,164.729354858398,,,109.028839111328,0,1,,,,,,1,1,1,49.0000495910645,0,49.0000534057617,,,,,,,,,,,,,,,,,,,,,,,,,,,,,,,,,
,3755214078.14407,49.000545501709,164.729354858398,,,5,,,,-2.43999995291233,,,,,0.00070783457287233,4.29005660663024E-8,0.0473535910571519,4.41605475254667E-5,0.000707742265444352,4.28949714809795E-8,0.000707742023728192,2.93827619176222E-8,5.84931984190662E-7,3.1251110067426E-8,1.00013042520206,10.005763053894,2,20,10,5,2.31530028793677,0.205555623959664,0.0404026173055172,172.741912841797,48.9994888305664,49.0007362365723,164.729354858398,164.729354858398,,,109.538764953613,0,1,,,,,,1,1,1,49.0005645751953,0,49.0002496507433,,,,,,,,,,,,,,,,,,,,,,,,,,,,,,,,,
,3755214283.37921,49.0004539489746,164.729354858398,,,5,,,,-2.43999995291233,,,,,0.000708495494228807,4.63018861172538E-8,0.0472215895807304,5.21643503886313E-5,0.000708403103579165,4.62958481658867E-8,0.000708402862984289,2.78901301785137E-8,5.83846089749107E-7,3.69519444146636E-8,1.00013042101196,10.005763053894,2,20,10,5,2.31746261065748,0.205742219127654,0.0404026173055172,172.741912841797,48.9993591308594,49.0011215209961,164.729354858398,164.729354858398,,,109.99893951416,0,1,,,,,,1,1,1,49.0000152587891,0,48.9998221927219,,,,,,,,,,,,,,,,,,,,,,,,,,,,,,,,,
,3755214487.11124,48.9994316101074,164.729354858398,,,5,,,,-2.43999995291233,,,,,0.000709251509812963,7.84103063177693E-8,0.0465493407157123,6.15741726640773E-5,0.000709158972396671,7.84000759734458E-8,0.000709158738353816,6.51249807687512E-8,5.76148527460841E-7,4.36498429838169E-8,1.00013048895931,10.005763053894,2,20,10,5,2.31993792603413,0.205934541963626,0.0404026173055172,172.741912841797,48.9988098144531,49.0006065368652,164.729354858398,164.729354858398,,,110.459106445312,0,1,,,,,,1,1,1,48.9998168945313,0,48.9999046325684,,,,,,,,,,,,,,,,,,,,,,,,,,,,,,,,,
,3755214690.80482,48.999906539917,164.729354858398,,,5,,,,-2.43999995291233,,,,,0.000710016008736809,5.92491791434406E-8,0.0427384719675903,4.87129666920521E-5,0.000709923356145859,5.92414475009258E-8,0.000709923158642646,4.8107460512399E-8,5.2955098787316E-7,3.45719734040873E-8,1.00013051069548,10.005763053894,2,20,10,5,2.32245228331351,0.206002045501133,0.0404026173055172,172.741912841797,48.9996643066406,49.0002975463867,164.729354858398,164.729354858398,,,110.931716918945,0,1,,,,,,1,1,1,49.0001487731934,0,48.9999526528751,,,,,,,,,,,,,,,,,,,,,,,,,,,,,,,,,
,3755214895.77824,49.0004806518555,164.729354858398,,,5,,,,-2.43999995291233,,,,,0.000710569478941943,5.23713391148679E-8,0.045312611597855,3.44504519099408E-5,0.000710476816968219,5.23645096185375E-8,0.000710476594784201,4.63002136819875E-8,5.61883562353799E-7,2.44608274715351E-8,1.00013042223407,10.005763053894,2,20,10,5,2.32425341195629,0.20626704891818,0.0404026173055172,172.741912841797,48.9999542236328,49.0005302429199,164.729354858398,164.729354858398,,,111.168022155762,0,1,,,,,,1,1,1,49.0004615783691,0,49.0003372641171,,,,,,,,,,,,,,,,,,,,,,,,,,,,,,,,,
,3755215102.30095,49.0004253387451,164.729354858398,,,5,,,,-2.43999995291233,,,,,0.000711034313474543,3.83078529671778E-8,0.0443335839413015,3.16641250876411E-5,0.000710941511122931,3.8302853125717E-8,0.000710941298297131,3.09943647534965E-8,5.50103031732335E-7,2.2504619772337E-8,1.00013053443942,10.005763053894,2,20,10,5,2.32577739960336,0.206362241361114,0.0404026173055172,172.741912841797,48.9997100830078,49.0010795593262,164.729354858398,164.729354858398,,,111.677947998047,0,1,,,,,,1,1,1,49.0005874633789,0,49.0002573798684,,,,,,,,,,,,,,,,,,,,,,,,,,,,,,,,,
,3755215308.81447,49.0000953674316,164.729354858398,,,5,,,,-2.43999995291233,,,,,0.000712168860748818,6.52269681790946E-8,0.0427038400390565,5.56121316627045E-5,0.000712075921071295,6.52184559094316E-8,0.000712075723290154,5.18276042270498E-8,5.3072623624592E-7,3.9589726335184E-8,1.00013051933758,10.005763053894,2,20,10,5,2.3294943565315,0.206625260309796,0.0404026173055172,172.741912841797,48.9994087219238,49.0002861022949,164.729354858398,164.729354858398,,,112.175430297852,0,1,,,,,,1,1,1,49.0000457763672,0,48.9999073252958,,,,,,,,,,,,,,,,,,,,,,,,,,,,,,,,,
,3755215513.87239,48.9998111724854,164.729354858398,,,5,,,,-2.43999995291233,,,,,0.000712101292562595,7.1784641099634E-8,0.0460620466019117,4.56202916869367E-5,0.000712008370962609,7.17752739719865E-8,0.000712008140873387,6.40161767119943E-8,5.72407941913923E-7,3.24594989630531E-8,1.00013050633079,10.005763053894,2,20,10,5,2.32926122841664,0.206742178890509,0.0404026173055172,172.741912841797,48.9992790222168,49.0003318786621,164.729354858398,164.729354858398,,,112.660484313965,0,1,,,,,,1,1,1,49.0000381469727,0,48.9997899672564,,,,,,,,,,,,,,,,,,,,,,,,,,,,,,,,,
,3755215718.98579,49.0008373260498,164.729354858398,,,5,,,,-2.43999995291233,,,,,0.000712509547976788,5.00126657058597E-8,0.0460116938306889,5.9201385205399E-5,0.000712416621379984,5.00061429766776E-8,0.000712416391661891,2.68667410165918E-8,5.72110061476789E-7,4.21757342858581E-8,1.00013043855802,10.005763053894,2,20,10,5,2.33059680110764,0.206858657055294,0.0404026173055172,172.741912841797,48.9993629455566,49.0015830993652,164.729354858398,164.729354858398,,,113.133094787598,0,1,,,,,,1,1,1,49.0003242492676,0,49.0000273760627,,,,,,,,,,,,,,,,,,,,,,,,,,,,,,,,,
,3755215924.32113,49.0012054443359,164.729354858398,,,5,,,,-2.43999995291233,,,,,0.000712918047941073,4.45320363710086E-8,0.0433522404891074,4.77911851376792E-5,0.000712825056059164,4.45262276839101E-8,0.000712824852011903,2.86740211025707E-8,5.39351424676E-7,3.40644310912238E-8,1.00013045540574,10.005763053894,2,20,10,5,2.33194259690972,0.206869010238139,0.0404026173055172,172.741912841797,48.9997138977051,49.001407623291,164.729354858398,164.729354858398,,,113.60570526123,0,1,,,,,,1,1,1,49.0013885498047,0,49.0006548563639,,,,,,,,,,,,,,,,,,,,,,,,,,,,,,,,,
,3755216133.28052,48.9996452331543,164.729354858398,,,5,,,,-2.43999995291233,,,,,0.000713150079443905,4.92224912506095E-8,0.0409700593572451,4.77863322730406E-5,0.000713057108206367,4.92160742620146E-8,0.000713056925908234,3.55173829514739E-8,5.09880305443117E-7,3.40695975033824E-8,1.00013038399936,10.005763053894,2,20,10,5,2.33271016899127,0.206839360431525,0.0404026173055172,172.741912841797,48.9995269775391,49.0002708435059,164.729354858398,164.729354858398,,,114.078315734863,0,1,,,,,,1,1,1,48.9995269775391,0,48.9999263987822,,,,,,,,,,,,,,,,,,,,,,,,,,,,,,,,,
,3755216339.94925,49.0003719329834,164.729354858398,,,5,,,,-2.43999995291233,,,,,0.000713582861764492,3.76027545122995E-8,0.0429815379275569,3.19867747324356E-5,0.000713489810379583,3.75978511036398E-8,0.000713489609619949,2.98833793336853E-8,5.35238140226959E-7,2.2816267162061E-8,1.00013041725832,10.005763053894,2,20,10,5,2.33411853066664,0.207046823368809,0.0404026173055172,172.741912841797,48.9998626708984,49.0004768371582,164.729354858398,164.729354858398,,,114.538482666016,0,1,,,,,,1,1,1,49.0003547668457,0,49.0001988130457,,,,,,,,,,,,,,,,,,,,,,,,,,,,,,,,,
,3755216545.11575,49.0002002716064,164.729354858398,,,5,,,,-2.43999995291233,,,,,0.000713744802615512,6.52789947600548E-8,0.0447930886865677,6.23082574360004E-5,0.000713651653848034,6.52704753874697E-8,0.000713651435759409,4.77868909706735E-8,5.57923442834808E-7,4.44595097663397E-8,1.00013052413874,10.005763053894,2,20,10,5,2.33464168769912,0.207167626725809,0.0404026173055172,172.741912841797,48.9993667602539,49.0004959106445,164.729354858398,164.729354858398,,,115.011093139648,0,1,,,,,,1,1,1,49.0002708435059,0,48.9999497357537,,,,,,,,,,,,,,,,,,,,,,,,,,,,,,,,,
,3755216750.14214,49.0001220703125,164.729354858398,,,5,,,,-2.43999995291233,,,,,0.000714304413845577,5.22404936047336E-8,0.0441855296391394,4.46008861358332E-5,0.00071421119460072,5.22336760361027E-8,0.000714210982221755,4.14025949407512E-8,5.50787458479449E-7,3.18462249633549E-8,1.00013052055969,10.005763053894,2,20,10,5,2.33647436072588,0.20730527970734,0.0404026173055172,172.741912841797,48.9996070861816,49.0009078979492,164.729354858398,164.729354858398,,,115.446388244629,0,1,,,,,,1,1,1,49.0004959106445,0,49.0000937966739,,,,,,,,,,,,,,,,,,,,,,,,,,,,,,,,,
,3755216955.7757,49.0004272460937,164.729354858398,,,5,,,,-2.43999995291233,,,,,0.000714691203272525,8.34896584255109E-8,0.0411550116422292,8.61592510067729E-5,0.000714597923570783,8.34787615648796E-8,0.000714597739225543,5.63794676699228E-8,5.1328882485041E-7,6.15634571613888E-8,1.00013053452671,10.005763053894,2,20,10,5,2.33775050828743,0.207293883253179,0.0404026173055172,172.741912841797,48.9994888305664,49.000904083252,164.729354858398,164.729354858398,,,115.931442260742,0,1,,,,,,1,1,1,49.0007781982422,0,49.0002140718348,,,,,,,,,,,,,,,,,,,,,,,,,,,,,,,,,
,3755217160.72035,49.0013065338135,164.729354858398,,,5,,,,-2.43999995291233,,,,,0.000714518751810324,4.62319412866581E-8,0.0442232070925597,3.57345461832526E-5,0.000714425547830269,4.62259106528606E-8,0.000714425335025104,3.85429191255617E-8,5.51422566992457E-7,2.55201528397983E-8,1.00013046003231,10.005763053894,2,20,10,5,2.33717531954999,0.207369018210834,0.0404026173055172,172.741912841797,49.000301361084,49.0015830993652,164.729354858398,164.729354858398,,,116.379173278809,0,1,,,,,,1,1,1,49.0013389587402,0,49.0008307562934,,,,,,,,,,,,,,,,,,,,,,,,,,,,,,,,,
,3755217365.79936,48.9994297027588,164.729354858398,,,5,,,,-2.43999995291233,,,,,0.000714789533848127,5.58665909036521E-8,0.0433490953851354,4.29844418634521E-5,0.000714696273937508,5.58593018863574E-8,0.000714696069384291,4.66605069096944E-8,5.40728030194817E-7,3.07092608533904E-8,1.00013048887201,10.005763053894,2,20,10,5,2.33806420563821,0.20741194251437,0.0404026173055172,172.741912841797,48.9990921020508,49.0001258850098,164.729354858398,164.729354858398,,,116.864219665527,0,1,,,,,,1,1,1,48.9996223449707,0,48.9996562284582,,,,,,,,,,,,,,,,,,,,,,,,,,,,,,,,,
,3755217570.89069,49.000129699707,164.729354858398,,,5,,,,-2.43999995291233,,,,,0.000715281318588624,5.35319262176514E-8,0.0431776829355375,4.3133479284324E-5,0.00071518797160456,5.35249400938233E-8,0.000715187768526228,4.37480676577733E-8,5.3896040540619E-7,3.08387060081688E-8,1.00013052090887,10.005763053894,2,20,10,5,2.33967344622064,0.207547642127448,0.0404026173055172,172.741912841797,48.9998550415039,49.0008583068848,164.729354858398,164.729354858398,,,117.324394226074,0,1,,,,,,1,1,1,49.0003242492676,0,49.0002208285862,,,,,,,,,,,,,,,,,,,,,,,,,,,,,,,,,
,3755217777.77236,49.0001640319824,164.729354858398,,,5,,,,-2.43999995291233,,,,,0.000715570950676993,4.92644562965531E-8,0.0444565526669516,4.37016919923283E-5,0.000715477646851694,4.92580326676741E-8,0.00071547743147815,3.80672932708957E-8,5.55148507761166E-7,3.12607575934632E-8,1.00013040774329,10.005763053894,2,20,10,5,2.34061619294806,0.207683926766649,0.0404026173055172,172.741912841797,48.9992713928223,49.0003700256348,164.729354858398,164.729354858398,,,117.784568786621,0,1,,,,,,1,1,1,49.0001831054687,0,48.99987523696,,,,,,,,,,,,,,,,,,,,,,,,,,,,,,,,,
,3755217984.23567,49.001091003418,164.729354858398,,,5,,,,-2.43999995291233,,,,,0.000715694795984771,4.64263037484238E-8,0.0465854930175498,3.84600714078747E-5,0.000715601445655888,4.64202482192401E-8,0.000715601209119851,3.73873906330953E-8,5.81834172782129E-7,2.75140412586773E-8,1.00013045016811,10.005763053894,2,20,10,5,2.34101356852946,0.207806853148796,0.0404026173055172,172.741912841797,48.9997863769531,49.0015068054199,164.729354858398,164.729354858398,,,118.244743347168,0,1,,,,,,1,1,1,49.0009269714355,0,49.0004236557904,,,,,,,,,,,,,,,,,,,,,,,,,,,,,,,,,
,3755218189.33227,49.0010147094727,164.729354858398,,,5,,,,-2.43999995291233,,,,,0.000716142389871283,6.3476803984295E-8,0.0455454664250228,7.35442416897303E-5,0.000716048983661259,6.34685247261915E-8,0.00071604875742732,3.54279291894699E-8,5.69200415572068E-7,5.26603785047648E-8,1.00013044667635,10.005763053894,2,20,10,5,2.34248140720728,0.207894293626818,0.0404026173055172,172.741912841797,48.9997253417969,49.0013694763184,164.729354858398,164.729354858398,,,118.70491027832,0,1,,,,,,1,1,1,49.0011711120605,0,49.0005917268641,,,,,,,,,,,,,,,,,,,,,,,,,,,,,,,,,
,3755218394.71818,49.0002460479736,164.729354858398,,,5,,,,-2.43999995291233,,,,,0.000716000843785595,4.05845038050011E-8,0.0420464067505781,3.1134768095571E-5,0.000715907399089048,4.0579207153921E-8,0.000715907206319093,3.39148601294642E-8,5.25367335114311E-7,2.22812548039761E-8,1.00013052623379,10.005763053894,2,20,10,5,2.34203110291954,0.207710178923828,0.0404026173055172,172.741912841797,48.9997406005859,49.0003433227539,164.729354858398,164.729354858398,,,119.152648925781,0,1,,,,,,1,1,1,49.0003433227539,0,49.0001209483427,,,,,,,,,,,,,,,,,,,,,,,,,,,,,,,,,
,3755218599.72386,48.9995231628418,164.729354858398,,,5,,,,-2.43999995291233,,,,,0.000716108851277485,5.31277937124867E-8,0.043915861673467,5.0193007212451E-5,0.0007160154161708,5.31208618039304E-8,0.000716015205846279,3.91232744187118E-8,5.48808850512036E-7,3.59332068920997E-8,1.00013049314941,10.005763053894,2,20,10,5,2.34237761443806,0.207817943227359,0.0404026173055172,172.741912841797,48.9990730285645,49.0017395019531,164.729354858398,164.729354858398,,,119.6376953125,0,1,,,,,,1,1,1,48.999382019043,0,49.0002365112305,,,,,,,,,,,,,,,,,,,,,,,,,,,,,,,,,
,3755218804.9379,48.9998302459717,164.729354858398,,,5,,,,-2.43999995291233,,,,,0.000716462759824648,7.62508317484809E-8,0.0430655878871775,8.52457877485458E-5,0.000716369268474583,7.62408817641921E-8,0.000716369066115628,4.56479118570796E-8,5.38449097794691E-7,6.10650488845281E-8,1.00013050720373,10.005763053894,2,20,10,5,2.34353832775545,0.207885867526033,0.0404026173055172,172.741912841797,48.9995040893555,49.000301361084,164.729354858398,164.729354858398,,,120.085433959961,0,1,,,,,,1,1,1,49.0001564025879,0,48.9999010562897,,,,,,,,,,,,,,,,,,,,,,,,,,,,,,,,,
,3755219010.11906,49.0000438690186,164.729354858398,,,5,,,,-2.43999995291233,,,,,0.000716672738479392,5.32776953550566E-8,0.0428918989623499,5.9991242879787E-5,0.000716579212724157,5.32707426185735E-8,0.000716579011935362,3.14625637178526E-8,5.36434630633297E-7,4.29869643430933E-8,1.00013051698064,10.005763053894,2,20,10,5,2.34422579493053,0.207939688156652,0.0404026173055172,172.741912841797,48.9993133544922,49.0005035400391,164.729354858398,164.729354858398,,,120.558044433594,0,1,,,,,,1,1,1,49.0000419616699,0,48.999901266659,,,,,,,,,,,,,,,,,,,,,,,,,,,,,,,,,
,3755219215.13361,49.0008373260498,164.729354858398,,,5,,,,-2.43999995291233,,,,,0.000717017969564751,5.69556773950098E-8,0.0421352683958807,4.50755695000935E-5,0.000716924454972634,5.69482491475091E-8,0.000716924261111993,4.68987592289349E-8,5.27225597832297E-7,3.23049448808253E-8,1.00013043855802,10.005763053894,2,20,10,5,2.3453577881667,0.2080088788592,0.0404026173055172,172.741912841797,48.9995269775391,49.0012664794922,164.729354858398,164.729354858398,,,121.018211364746,0,1,,,,,,1,1,1,49.0011444091797,0,49.0003141515395,,,,,,,,,,,,,,,,,,,,,,,,,,,,,,,,,
,3755219420.10789,49.0003471374512,164.729354858398,,,5,,,,-2.43999995291233,,,,,0.000717018257412878,5.31041515349747E-8,0.0438129898509603,3.18336351803556E-5,0.000716924758864986,5.30972268004868E-8,0.000716924549258807,4.79507547082113E-8,5.48218636517964E-7,2.2804399067182E-8,1.0001304161235,10.005763053894,2,20,10,5,2.34535263754511,0.208077641771167,0.0404026173055172,172.741912841797,48.9992027282715,49.0005073547363,164.729354858398,164.729354858398,,,121.490821838379,0,1,,,,,,1,1,1,49.0003700256348,0,48.999791986802,,,,,,,,,,,,,,,,,,,,,,,,,,,,,,,,,
,3755219625.06482,49.0005683898926,164.729354858398,,,5,,,,-2.43999995291233,,,,,0.000717247246972485,6.26744365143724E-8,0.0424028882496774,5.71869623394603E-5,0.000717153711303542,6.2666263188689E-8,0.000717153514909707,4.73890587237634E-8,5.30743907505674E-7,4.1004117540922E-8,1.00013042624959,10.005763053894,2,20,10,5,2.34610677978888,0.208086354591192,0.0404026173055172,172.741912841797,48.9993438720703,49.0010452270508,164.729354858398,164.729354858398,,,121.963432312012,0,1,,,,,,1,1,1,49.0003318786621,0,48.9999811384413,,,,,,,,,,,,,,,,,,,,,,,,,,,,,,,,,
,3755219830.02561,49.0008487701416,164.729354858398,,,5,,,,-2.43999995291233,,,,,0.000717259022972084,4.91488329348046E-8,0.043855474611239,3.23382417685734E-5,0.000717165476565832,4.91424228422923E-8,0.000717165266482438,4.33332129326363E-8,5.48934486026256E-7,2.31777992860722E-8,1.00013043908179,10.005763053894,2,20,10,5,2.34614002295883,0.208149247487181,0.0404026173055172,172.741912841797,48.999828338623,49.0012969970703,164.729354858398,164.729354858398,,,122.411170959473,0,1,,,,,,1,1,1,49.0012626647949,0,49.0003413032083,,,,,,,,,,,,,,,,,,,,,,,,,,,,,,,,,
,3755220034.9386,49.0004215240479,164.729354858398,,,5,,,,-2.43999995291233,,,,,0.000717424850448229,5.58277274730456E-8,0.0444438825273803,4.85144923119255E-5,0.000717331214145551,5.58204409928181E-8,0.00071733099833711,4.36507324811198E-8,5.56428087522692E-7,3.47927461763857E-8,1.00013053426483,10.005763053894,2,20,10,5,2.34668030287208,0.208221472922888,0.0404026173055172,172.741912841797,49.0000305175781,49.0011253356934,164.729354858398,164.729354858398,,,122.896217346191,0,1,,,,,,1,1,1,49.000659942627,0,49.0004083970014,,,,,,,,,,,,,,,,,,,,,,,,,,,,,,,,,
,3755220239.93003,48.9999256134033,164.729354858398,,,5,,,,-2.43999995291233,,,,,0.000717563587433156,4.98419531518165E-8,0.0410146343252666,4.70857544168015E-5,0.000717469949304777,4.9835449049198E-8,0.000717469765479121,3.66424124802194E-8,5.13593939152242E-7,3.37772939941121E-8,1.00013051156842,10.005763053894,2,20,10,5,2.3471465686349,0.20812126284777,0.0404026173055172,172.741912841797,48.9994430541992,49.0002021789551,164.729354858398,164.729354858398,,,123.356391906738,0,1,,,,,,1,1,1,48.9997253417969,0,48.9999405356014,,,,,,,,,,,,,,,,,,,,,,,,,,,,,,,,,
,3755220444.91981,49.0003986358643,164.729354858398,,,5,,,,-2.43999995291233,,,,,0.000718005418960157,4.30211597914277E-8,0.0466324196482155,3.32657725349014E-5,0.00071791170763522,4.30155448339665E-8,0.000717911469857229,3.57829035080588E-8,5.8430056470589E-7,2.38730164389826E-8,1.0001305332173,10.005763053894,2,20,10,5,2.34857136760034,0.208479682846777,0.0404026173055172,172.741912841797,48.9996337890625,49.0008316040039,164.729354858398,164.729354858398,,,123.829002380371,0,1,,,,,,1,1,1,49.000675201416,0,49.0002365112305,,,,,,,,,,,,,,,,,,,,,,,,,,,,,,,,,
,3755220649.89499,49.0015716552734,164.729354858398,,,5,,,,-2.43999995291233,,,,,0.000717981690140435,5.19598091810894E-8,0.0429939576359804,3.74967782827275E-5,0.000717888025734657,5.1953030756628E-8,0.000717887823620713,4.44429192304936E-8,5.38693159104443E-7,2.69062136888667E-8,1.00013047216616,10.005763053894,2,20,10,5,2.34850698557437,0.208323653638453,0.0404026173055172,172.741912841797,48.999755859375,49.0020713806152,164.729354858398,164.729354858398,,,124.31404876709,0,1,,,,,,1,1,1,49.0011901855469,0,49.0007458855124,,,,,,,,,,,,,,,,,,,,,,,,,,,,,,,,,
,3755220854.97378,49.0002536773682,164.729354858398,,,5,,,,-2.43999995291233,,,,,0.000717983257819235,6.03228087613083E-8,0.0432839925938833,3.28988582324782E-5,0.000717889554148784,6.03149360588026E-8,0.000717889349298306,5.5508596107566E-8,5.42328308533179E-7,2.35942211133268E-8,1.00013052658297,10.005763053894,2,20,10,5,2.34851105865081,0.2083359989899,0.0404026173055172,172.741912841797,48.9998321533203,49.0010032653809,164.729354858398,164.729354858398,,,124.761779785156,0,1,,,,,,1,1,1,49.000675201416,0,49.0003439959358,,,,,,,,,,,,,,,,,,,,,,,,,,,,,,,,,
,3755221060.44028,49.0012493133545,164.729354858398,,,5,,,,-2.43999995291233,,,,,0.000717893891317924,9.66416030236548E-8,0.0435544463245492,5.66358263048466E-5,0.000717800248954038,9.66289970546302E-8,0.000717800041561408,8.76767956102817E-8,5.45649080430457E-7,4.06194852662687E-8,1.0001304574135,10.005763053894,2,20,10,5,2.34821775932071,0.208321148731281,0.0404026173055172,172.741912841797,49.0001754760742,49.0015716552734,164.729354858398,164.729354858398,,,125.259269714355,0,1,,,,,,1,1,1,49.0014457702637,0,49.0007864634196,,,,,,,,,,,,,,,,,,,,,,,,,,,,,,,,,
,3755221264.21559,48.9985618591309,164.729354858398,,,5,,,,-2.43999995291233,,,,,0.000718200311716759,6.37276969548126E-8,0.0438237124150227,4.26972491646831E-5,0.000718106635314201,6.37193848150146E-8,0.000718106425259702,5.5867075109516E-8,5.49256784152619E-7,3.06435950879073E-8,1.0001304491533,10.005763053894,2,20,10,5,2.34921907433542,0.208421118644165,0.0404026173055172,172.741912841797,48.9982452392578,48.9999656677246,164.729354858398,164.729354858398,,,125.719436645508,0,1,,,,,,1,1,1,48.9987525939941,0,48.9990119934082,,,,,,,,,,,,,,,,,,,,,,,,,,,,,,,,,
,3755221470.43679,49.0004196166992,164.729354858398,,,5,,,,-2.43999995291233,,,,,0.000718281560874708,4.62307202701563E-8,0.0448833952059697,3.74473776930847E-5,0.000718187895211121,4.62246916717235E-8,0.000718187674850392,3.76014766828604E-8,5.62601785157635E-7,2.68858898200191E-8,1.00013041944067,10.005763053894,2,20,10,5,2.34948098383673,0.208488143121,0.0404026173055172,172.741912841797,48.9994277954102,49.0007705688477,164.729354858398,164.729354858398,,,126.192047119141,0,1,,,,,,1,1,1,49.0005416870117,0,49.0000983344184,,,,,,,,,,,,,,,,,,,,,,,,,,,,,,,,,
,3755221675.383,49.0002040863037,164.729354858398,,,5,,,,-2.43999995291233,,,,,0.000718457107872554,5.53762759632749E-8,0.0395748489946843,4.09543409439467E-5,0.000718363426402372,5.53690553082232E-8,0.000718363255043155,4.69137774157127E-8,4.96181779954344E-7,2.94079882738355E-8,1.00013040957646,10.005763053894,2,20,10,5,2.3500745049615,0.208321361161794,0.0404026173055172,172.741912841797,48.9997367858887,49.0004768371582,164.729354858398,164.729354858398,,,126.677101135254,0,1,,,,,,1,1,1,49.0002746582031,0,49.0001854366726,,,,,,,,,,,,,,,,,,,,,,,,,,,,,,,,,
,3755221880.28399,49.0030727386475,164.729354858398,,,5,,,,-2.43999995291233,,,,,0.000718395348763933,6.28908238508704E-8,0.0448179537337143,5.54545695394347E-5,0.000718301581053184,6.28826150998118E-8,0.000718301361299792,4.8664639998249E-8,5.61870420772948E-7,3.98243153818356E-8,1.00013054086643,10.005763053894,2,20,10,5,2.34985342030358,0.208518476535089,0.0404026173055172,172.741912841797,49.0014038085937,49.0031929016113,164.729354858398,164.729354858398,,,127.162147521973,0,1,,,,,,1,1,1,49.0030784606934,0,49.0021966298421,,,,,,,,,,,,,,,,,,,,,,,,,,,,,,,,,
,3755222085.53754,49.001335144043,164.729354858398,,,5,,,,-2.43999995291233,,,,,0.000718416880051712,4.9212855005696E-8,0.0426274899580603,4.04592524923933E-5,0.000718323166647602,4.92064354681035E-8,0.000718322967844062,3.97129246930067E-8,5.34425240537816E-7,2.90543783930102E-8,1.00013046134172,10.005763053894,2,20,10,5,2.34993181809847,0.208434896047494,0.0404026173055172,172.741912841797,49.0000228881836,49.002025604248,164.729354858398,164.729354858398,,,127.622314453125,0,1,,,,,,1,1,1,49.0008087158203,0,49.0007226732042,,,,,,,,,,,,,,,,,,,,,,,,,,,,,,,,,
,3755222290.42204,48.9998798370361,164.729354858398,,,5,,,,-2.43999995291233,,,,,0.000718578443839117,5.06296878120912E-8,0.0438105159652542,4.48276945923327E-5,0.000718484674782588,5.06230810204469E-8,0.000718484464744061,3.90613291559526E-8,5.49380452025564E-7,3.22010698047915E-8,1.00013050947337,10.005763053894,2,20,10,5,2.35045598553773,0.208530305951359,0.0404026173055172,172.741912841797,48.9993019104004,49.0001907348633,164.729354858398,164.729354858398,,,128.107360839844,0,1,,,,,,1,1,1,48.999927520752,0,48.9998177422418,,,,,,,,,,,,,,,,,,,,,,,,,,,,,,,,,
,3755222495.32487,49.001256942749,164.729354858398,,,5,,,,-2.43999995291233,,,,,0.00071867944431646,4.81818466920676E-8,0.0444681797177751,4.61518534274593E-5,0.000718585699233849,4.81755618160576E-8,0.000718585482811557,3.49478304771268E-8,5.57705909226512E-7,3.31592204557767E-8,1.00013045776267,10.005763053894,2,20,10,5,2.35078396252673,0.208586593907611,0.0404026173055172,172.741912841797,49.0000534057617,49.0015869140625,164.729354858398,164.729354858398,,,128.579971313477,0,1,,,,,,1,1,1,49.0012245178223,0,49.0008483462863,,,,,,,,,,,,,,,,,,,,,,,,,,,,,,,,,
,3755222700.22879,49.0007438659668,164.729354858398,,,5,,,,-2.43999995291233,,,,,0.000718727269328376,6.37933362424383E-8,0.0428376254071523,3.85660845149152E-5,0.000718633534880222,6.37850164896979E-8,0.00071863333402507,5.74593483542301E-8,5.37291779006777E-7,2.76938912993149E-8,1.00013043428062,10.005763053894,2,20,10,5,2.35094633228222,0.208533573048191,0.0404026173055172,172.741912841797,48.9999504089355,49.0011978149414,164.729354858398,164.729354858398,,,129.07746887207,0,1,,,,,,1,1,1,49.0005073547363,0,49.0003706988166,,,,,,,,,,,,,,,,,,,,,,,,,,,,,,,,,
,3755222905.13472,49.0010185241699,164.729354858398,,,5,,,,-2.43999995291233,,,,,0.000718945499953074,4.4942532336993E-8,0.0431754710655712,4.3233440316406E-5,0.000718851728008862,4.49366704898359E-8,0.000718851523911116,3.24608896929887E-8,5.4169363449636E-7,3.10740244424778E-8,1.00013044685094,10.005763053894,2,20,10,5,2.35165893169653,0.208610754554919,0.0404026173055172,172.741912841797,49.0007629394531,49.0014495849609,164.729354858398,164.729354858398,,,129.550079345703,0,1,,,,,,1,1,1,49.0012550354004,0,49.0011493458467,,,,,,,,,,,,,,,,,,,,,,,,,,,,,,,,,
,3755223110.0697,48.9998321533203,164.729354858398,,,5,,,,-2.43999995291233,,,,,0.000719053029611092,5.67683422685161E-8,0.0436798723030911,5.5930231044828E-5,0.000718959200193519,5.67609345527118E-8,0.000718958991267907,4.0065351346415E-8,5.48103949025894E-7,4.0206607824903E-8,1.00013050729102,10.005763053894,2,20,10,5,2.35200882205018,0.208662667273975,0.0404026173055172,172.741912841797,48.9996337890625,49.0002708435059,164.729354858398,164.729354858398,,,130.035125732422,0,1,,,,,,1,1,1,48.9998664855957,0,48.9999026130227,,,,,,,,,,,,,,,,,,,,,,,,,,,,,,,,,
,3755223314.99895,49.0003261566162,164.729354858398,,,5,,,,-2.43999995291233,,,,,0.000719352974273683,6.11274163021067E-8,0.040529837592473,5.11000748029005E-5,0.000719259089456565,6.11194383879176E-8,0.000719258909503269,4.88409593997016E-8,5.08788813053309E-7,3.67443387989383E-8,1.00013052990014,10.005763053894,2,20,10,5,2.35300140882461,0.208620341204875,0.0404026173055172,172.741912841797,48.9994163513184,49.000617980957,164.729354858398,164.729354858398,,,130.532608032227,0,1,,,,,,1,1,1,49.000617980957,0,48.9999535504509,,,,,,,,,,,,,,,,,,,,,,,,,,,,,,,,,
,3755223519.85848,49.0003395080566,164.729354858398,,,5,,,,-2.43999995291233,,,,,0.000719402156904678,4.6956029901605E-8,0.0433856301148987,4.04503716706931E-5,0.000719308265229113,4.69499015069609E-8,0.00071930805900873,3.68525051493451E-8,5.44676058458377E-7,2.90892783638718E-8,1.00013053051119,10.005763053894,2,20,10,5,2.35315188303131,0.208751894593156,0.0404026173055172,172.741912841797,48.9998359680176,49.0004730224609,164.729354858398,164.729354858398,,,131.005218505859,0,1,,,,,,1,1,1,49.0002593994141,0,49.0001552806181,,,,,,,,,,,,,,,,,,,,,,,,,,,,,,,,,
,3755223724.91002,49.0001125335693,164.729354858398,,,5,,,,-2.43999995291233,,,,,0.00071937020036527,4.90459011753538E-8,0.044217813978559,3.18774288416874E-5,0.00071927632033131,4.90395005337014E-8,0.000719276106133504,4.33567165948011E-8,5.550988858998E-7,2.29143566070051E-8,1.00013052012322,10.005763053894,2,20,10,5,2.35304432158502,0.208776798813971,0.0404026173055172,172.741912841797,48.9992828369141,49.0001831054687,164.729354858398,164.729354858398,,,131.490264892578,0,1,,,,,,1,1,1,49.0000877380371,0,48.999823177562,,,,,,,,,,,,,,,,,,,,,,,,,,,,,,,,,
,3755223929.8252,48.9993705749512,164.729354858398,,,5,,,,-2.43999995291233,,,,,0.000719579446619418,6.41216735090343E-8,0.041995758372936,4.43109850181201E-5,0.000719485563706787,6.41133076093409E-8,0.000719485370439806,5.56341182654611E-8,5.27357153311481E-7,3.18647312468607E-8,1.0001304861659,10.005763053894,2,20,10,5,2.35373685851359,0.208746248514078,0.0404026173055172,172.741912841797,48.9982223510742,49.0000114440918,164.729354858398,164.729354858398,,,131.987747192383,0,1,,,,,,1,1,1,48.9989471435547,0,48.9991540347829,,,,,,,,,,,,,,,,,,,,,,,,,,,,,,,,,
,3755224133.44077,49.0006484985352,164.729354858398,,,5,,,,-2.43999995291233,,,,,0.0007196063376988,6.37097836245867E-8,0.0429206061813501,6.17923247288357E-5,0.000719512491744991,6.37014750465517E-8,0.000719512289864314,4.56255089720923E-8,5.38990998550199E-7,4.44543682234264E-8,1.00013042991593,10.005763053894,2,20,10,5,2.35382144974035,0.208792036022201,0.0404026173055172,172.741912841797,48.9996948242188,49.001033782959,164.729354858398,164.729354858398,,,132.44792175293,0,1,,,,,,1,1,1,49.000846862793,0,49.0003435471479,,,,,,,,,,,,,,,,,,,,,,,,,,,,,,,,,
,3755224338.47101,48.9990215301514,164.729354858398,,,5,,,,-2.43999995291233,,,,,0.000719396067847755,4.69307292183296E-8,0.0445922195522943,3.89203422287779E-5,0.000719302220349589,4.69246069558916E-8,0.000719302002501228,3.76644898113777E-8,5.59819232214894E-7,2.79875855552697E-8,1.00013047019113,10.005763053894,2,20,10,5,2.35312756882768,0.208799686836067,0.0404026173055172,172.741912841797,48.9986305236816,49.0001564025879,164.729354858398,164.729354858398,,,132.95783996582,0,1,,,,,,1,1,1,48.999153137207,0,48.9994715522317,,,,,,,,,,,,,,,,,,,,,,,,,,,,,,,,,
,3755224544.71531,48.9999389648438,164.729354858398,,,5,,,,-2.43999995291233,,,,,0.000719597422894005,6.50033411197314E-8,0.044171198794408,6.85106613084362E-5,0.000719503518921608,6.49948584990937E-8,0.00071950330510767,4.23653733657281E-8,5.54688846011187E-7,4.92900270937202E-8,1.00013051217948,10.005763053894,2,20,10,5,2.35378773137161,0.20884082966032,0.0404026173055172,172.741912841797,48.9994964599609,49.0001678466797,164.729354858398,164.729354858398,,,133.455322265625,0,1,,,,,,1,1,1,48.9998588562012,0,48.9997279518529,,,,,,,,,,,,,,,,,,,,,,,,,,,,,,,,,
,3755224749.81702,49.0001411437988,164.729354858398,,,5,,,,-2.43999995291233,,,,,0.000719702855090084,7.06451717834303E-8,0.0448872094048012,4.56953113786337E-5,0.000719609013256424,7.0635960381235E-8,0.000719608792422126,6.25262892631221E-8,5.63762940969086E-7,3.28618631541758E-8,1.00013040669576,10.005763053894,2,20,10,5,2.35412998747916,0.208900846477857,0.0404026173055172,172.741912841797,48.9997291564941,49.000602722168,164.729354858398,164.729354858398,,,133.965240478516,0,1,,,,,,1,1,1,48.9999961853027,0,49.0001480579376,,,,,,,,,,,,,,,,,,,,,,,,,,,,,,,,,
,3755224954.83679,49.0001659393311,164.729354858398,,,5,,,,-2.43999995291233,,,,,0.00071970045107086,6.448373076414E-8,0.0447891122821034,5.60877886320151E-5,0.000719606526179509,6.44753152804525E-8,0.000719606306310145,5.02871902166701E-8,5.6252894177039E-7,4.03517630423527E-8,1.00013052256745,10.005763053894,2,20,10,5,2.35412248176893,0.208896116848668,0.0404026173055172,172.741912841797,48.9996299743652,49.0006713867188,164.729354858398,164.729354858398,,,134.450286865234,0,1,,,,,,1,1,1,49.0003051757812,0,49.0001087188721,,,,,,,,,,,,,,,,,,,,,,,,,,,,,,,,,
,3755225159.69237,49.0000267028809,164.729354858398,,,5,,,,-2.43999995291233,,,,,0.000720346146958826,5.51324079265041E-8,0.0413961661992337,3.08488530190275E-5,0.000720252142389763,5.51252131934297E-8,0.000720251954402024,5.04579777998779E-8,5.20381693924286E-7,2.21986847801419E-8,1.000130516195,10.005763053894,2,20,10,5,2.3562469145324,0.208944000837801,0.0404026173055172,172.741912841797,48.9997138977051,49.0003051757812,164.729354858398,164.729354858398,,,134.935333251953,0,1,,,,,,1,1,1,49.0002899169922,0,49.0000682406955,,,,,,,,,,,,,,,,,,,,,,,,,,,,,,,,,
,3755225364.59996,49.000638961792,164.729354858398,,,5,,,,-2.43999995291233,,,,,0.000719975946559861,6.30955101152466E-8,0.0463462134967347,5.42335940979566E-5,0.000719882052718452,6.30872816739373E-8,0.000719881817205618,4.95630131142775E-8,5.82308225019662E-7,3.90322026029874E-8,1.00013042947946,10.005763053894,2,20,10,5,2.35501794072551,0.209040080781971,0.0404026173055172,172.741912841797,48.9994773864746,49.0008544921875,164.729354858398,164.729354858398,,,135.445266723633,0,1,,,,,,1,1,1,49.0005722045898,0,49.0001737806532,,,,,,,,,,,,,,,,,,,,,,,,,,,,,,,,,
,3755225569.53369,49.0005054473877,164.729354858398,,,5,,,,-2.43999995291233,,,,,0.000720021320756181,5.15975251081213E-8,0.0459469987464152,5.06260350638604E-5,0.000719927425396004,5.15907964626429E-8,0.000719927193908405,3.65178645982991E-8,5.77328753494669E-7,3.64425005293289E-8,1.00013042336889,10.005763053894,2,20,10,5,2.3551678148382,0.209036844479453,0.0404026173055172,172.741912841797,48.9998207092285,49.0007133483887,164.729354858398,164.729354858398,,,135.942749023438,0,1,,,,,,1,1,1,49.0006904602051,0,49.0002123514811,,,,,,,,,,,,,,,,,,,,,,,,,,,,,,,,,
,3755225774.4582,48.999605178833,164.729354858398,,,5,,,,-2.43999995291233,,,,,0.000720050853254198,5.210462582273E-8,0.04369567435928,4.72737996411389E-5,0.000719956901108274,5.20978272176225E-8,0.000719956691741332,3.94491785496405E-8,5.49063116365907E-7,3.40286043286501E-8,1.00013049690305,10.005763053894,2,20,10,5,2.35527262656446,0.20895287698126,0.0404026173055172,172.741912841797,48.9992599487305,49.0000839233398,164.729354858398,164.729354858398,,,136.440231323242,0,1,,,,,,1,1,1,48.9996871948242,0,48.9996548702842,,,,,,,,,,,,,,,,,,,,,,,,,,,,,,,,,
,3755225979.52428,49.0002822875977,164.729354858398,,,5,,,,-2.43999995291233,,,,,0.000720193340071606,4.45715544150967E-8,0.0452802998921094,3.36679231290812E-5,0.000720099429632708,4.45657424559955E-8,0.000720099204760506,3.74003451775992E-8,5.69087549011656E-7,2.42346772466758E-8,1.00013041315551,10.005763053894,2,20,10,5,2.35573291741635,0.209059375421724,0.0404026173055172,172.741912841797,48.9995956420898,49.0004005432129,164.729354858398,164.729354858398,,,136.912841796875,0,1,,,,,,1,1,1,49.0002784729004,0,48.9999947018094,,,,,,,,,,,,,,,,,,,,,,,,,,,,,,,,,
,3755226133.23037,49.0008449554443,164.729354858398,,,5,,,,-2.43999995291233,,,,,0.000720371473657606,4.99169973617107E-8,0.0417655660567489,4.18024152535924E-5,0.00072027752144483,4.99104870923167E-8,0.000720277330080351,3.98116497961026E-8,5.25043833814635E-7,3.01013166207857E-8,1.0001304389072,10.005763053894,2,20,10,5,2.35632841104461,0.208966535879888,0.0404026173055172,172.741912841797,49.0000381469727,49.001148223877,164.729354858398,164.729354858398,,,137.285949707031,0,1,,,,,,1,1,1,49.0010147094727,0,49.0005443797392,,,,,,,,,,,,,,,,,,,,,,,,,,,,,,,,,