File: Experimental_Data/Fig3B/Lifetime_150Oe.dat
[Header]
; MPMS3 Data File (default extension .dat)
; Copyright (c) 2007, Quantum Design, Inc. All rights reserved.
TITLE,150Oe
FILEOPENTIME,3754812330.56269,12/24/2018,11:25 am
BYAPP,SQUID AC,0.9.1.0
INFO,MPMS3 Measurement Release 1.1.16 Build 347, MultiVu Release 2.3.3.2,APPNAME
INFO,0,MOMENT_UNITS
INFO,CoIINO3,SAMPLE_MATERIAL
INFO,40 Hours Pumped Turbo,SAMPLE_COMMENT
INFO,,SAMPLE_MASS
INFO,,SAMPLE_VOLUME
INFO,,SAMPLE_MOLECULAR_WEIGHT
INFO,,SAMPLE_SIZE
INFO,,SAMPLE_SHAPE
INFO,Brass,SAMPLE_HOLDER
INFO,Standard,SAMPLE_HOLDER_DETAIL
INFO,65.37,SAMPLE_OFFSET
DATATYPE,COMMENT,1
DATATYPE,TIME,2
STARTUPAXIS,X,2
STARTUPAXIS,Y1,5
FIELDGROUP, VSM,2,3,4,5,6,8,9,10,11,14,15
FIELDGROUP, DC, 2,3,4,14,56,57,58,59,60,61,62,63,64,65,66,67,68,69
FIELDGROUP, AC, 2,3,4,11,16,17,18,19,20,21,22,23,24,25,26,27,28,29,30
STARTUPGROUP, All
[Data]
Comment,Time Stamp (sec),Temperature (K),Magnetic Field (Oe),Moment (emu),M. Std. Err. (emu),Transport Action,Averaging Time (sec),Frequency (Hz),Peak Amplitude (mm),Center Position (mm),Lockin Signal' (V),Lockin Signal (V),Range,M. Quad. Signal (emu),AC Moment (emu),AC M. Std Err. (emu),AC Phase (deg),AC Phase Std. Err. (deg),AC Susceptibility (emu/Oe),AC Suscept. Std Err. (emu/Oe),AC X' (emu/Oe),AC X' Std Err. (emu/Oe),AC X'' (emu/Oe),AC X'' Std Err. (emu/Oe),AC Drive (Oe),AC Frequency (Hz),AC Averaging Time (sec),AC Cycles,AC Range,AC Measure Type,AC Signal' (V),AC Signal'' (V),AC Trim Coil Ratio,AC Trim Coil Phase,Min. Temperature (K),Max. Temperature (K),Min. Field (Oe),Max. Field (Oe),Mass (grams),Motor Lag (deg),Pressure (Torr),Measure Count,Measurement Number,SQUID Status (code),Motor Status (code),Measure Status (code),Motor Current (amps),Motor Temp. (C),Temp. Status (code),Field Status (code),Chamber Status (code),Chamber Temp (K),Redirection State,Average Temp (K),Rotation Angle (deg),Rotator state,DC Moment Fixed Ctr (emu),DC Moment Err Fixed Ctr (emu),DC Moment Free Ctr (emu),DC Moment Err Free Ctr (emu),DC Fixed Fit,DC Free Fit,DC Calculated Center (mm),DC Calculated Center Err (mm),DC Scan Length (mm),DC Scan Time (s),DC Number of Points,DC Squid Drift,DC Min V (V),DC Max V (V),DC Scans per Measure,Map 01,Map 02,Map 03,Map 04,Map 05,Map 06,Map 07,Map 08,Map 09,Map 10,Map 11,Map 12,Map 13,Map 14,Map 15,Map 16
,3754812334.81141,48.9713764190674,149.975830078125,,,5,,,,-2.43999995291233,,,,,0.000683722890016499,1.45951677663719E-7,0.0746594472069866,5.26602790140129E-5,0.00068363416890565,1.45932738711753E-7,0.000683633588518245,1.4145610236351E-7,8.90811419833251E-7,3.58683053967816E-8,1.0001297786373,10.005763053894,2,20,10,5,2.23633921929733,0.199584210307508,0.0404026173055172,172.741912841797,48.9074630737305,48.9814796447754,149.975830078125,149.975830078125,,,53.1862335205078,0,1,,,,,,1,1,1,48.9661140441895,0,48.9392070770264,,,,,,,,,,,,,,,,,,,,,,,,,,,,,,,,,
,3754812541.42335,49.0000648498535,149.975830078125,,,5,,,,-2.43999995291233,,,,,0.000699382637177322,4.6984498267315E-8,0.0256756927618147,4.14493196313814E-5,0.000699291447332055,4.69783721370693E-8,0.000699291377117477,3.69757528842213E-8,3.13370232577549E-7,2.89786325987609E-8,1.00013040320401,10.005763053894,2,20,10,5,2.28773325602663,0.202199506693923,0.0404026173055172,172.741912841797,48.9989471435547,49.0008201599121,149.975830078125,149.975830078125,,,53.4971618652344,0,1,,,,,,1,1,1,48.9995002746582,0,48.9997758304372,,,,,,,,,,,,,,,,,,,,,,,,,,,,,,,,,
,3754812746.31443,49.0002193450928,149.975830078125,,,5,,,,-2.43999995291233,,,,,0.00070199204877009,4.53871923274023E-8,0.0265367682564142,3.4895905302866E-5,0.000701900433207849,4.53812689367444E-8,0.000701900357924955,3.82094347712865E-8,3.25087966818549E-7,2.44846618267012E-8,1.00013052501168,10.005763053894,2,20,10,5,2.29626578776406,0.202988423160099,0.0404026173055172,172.741912841797,48.9994163513184,49.0006103515625,149.975830078125,149.975830078125,,,53.8080863952637,0,1,,,,,,1,1,1,49.0004501342773,0,49.0000170539407,,,,,,,,,,,,,,,,,,,,,,,,,,,,,,,,,
,3754812951.24944,49.0003871917725,149.975830078125,,,5,,,,-2.43999995291233,,,,,0.000703754506422909,4.18329979902335E-8,0.0268190850421304,3.32265657760549E-5,0.000703662736166673,4.18275429275523E-8,0.000703662659080373,3.46879825532612E-8,3.29371381862345E-7,2.33727878897849E-8,1.00013041795667,10.005763053894,2,20,10,5,2.30202990897784,0.203509399950128,0.0404026173055172,172.741912841797,48.9998092651367,49.0012893676758,149.975830078125,149.975830078125,,,54.0568313598633,0,1,,,,,,1,1,1,49.0003051757812,0,49.0002885706284,,,,,,,,,,,,,,,,,,,,,,,,,,,,,,,,,
,3754813155.38901,49.0006694793701,149.975830078125,,,5,,,,-2.43999995291233,,,,,0.00070430534880447,5.37541892071014E-8,0.0256036765870862,6.28113716765324E-5,0.000704213416832264,5.3747172749486E-8,0.000704213346519577,3.0534897131794E-8,3.14690752547586E-7,4.42309691925674E-8,1.00013054561303,10.005763053894,2,20,10,5,2.30383607285562,0.203619816704264,0.0404026173055172,172.741912841797,48.9995460510254,49.0010070800781,149.975830078125,149.975830078125,,,54.2682609558105,0,1,,,,,,1,1,1,49.001049041748,0,49.0002044228946,,,,,,,,,,,,,,,,,,,,,,,,,,,,,,,,,
,3754813361.2316,49.0000610351562,149.975830078125,,,5,,,,-2.43999995291233,,,,,0.000704815894718128,6.18004786085525E-8,0.029525768123416,5.83308215476614E-5,0.000704723915726799,6.17924136007558E-8,0.000704723822154748,4.6141858783902E-8,3.63159628556853E-7,4.11002584733153E-8,1.00013051776629,10.005763053894,2,20,10,5,2.30549215283958,0.203925242333717,0.0404026173055172,172.741912841797,48.9994659423828,49.0004348754883,149.975830078125,149.975830078125,,,54.504566192627,0,1,,,,,,1,1,1,49.000129699707,0,48.9998559390797,,,,,,,,,,,,,,,,,,,,,,,,,,,,,,,,,
,3754813566.13552,49.0012168884277,149.975830078125,,,5,,,,-2.43999995291233,,,,,0.000705407483108301,4.75631520263639E-8,0.0305562652084772,3.71653660761948E-5,0.000705315470523002,4.7556947940516E-8,0.000705315370221213,3.96862594380228E-8,3.76149966620243E-7,2.62042765447722E-8,1.0001304559295,10.005763053894,2,20,10,5,2.30742360073231,0.204137903323163,0.0404026173055172,172.741912841797,48.9999771118164,49.0013008117676,149.975830078125,149.975830078125,,,54.7284355163574,0,1,,,,,,1,1,1,49.0011825561523,0,49.0006330153521,,,,,,,,,,,,,,,,,,,,,,,,,,,,,,,,,
,3754813771.09992,49.0002536773682,149.975830078125,,,5,,,,-2.43999995291233,,,,,0.000705836464282684,4.2545826835916E-8,0.0262836452373945,4.12552719464625E-5,0.000705744426849104,4.25402790795876E-8,0.000705744352591081,3.10193181928064E-8,3.23750469068044E-7,2.91114623992446E-8,1.0001304118461,10.005763053894,2,20,10,5,2.30884204509622,0.20408987839409,0.0404026173055172,172.741912841797,48.9995956420898,49.0005187988281,149.975830078125,149.975830078125,,,54.9274253845215,0,1,,,,,,1,1,1,48.9999885559082,0,48.9998920665068,,,,,,,,,,,,,,,,,,,,,,,,,,,,,,,,,
,3754813975.99011,48.9999389648438,149.975830078125,,,5,,,,-2.43999995291233,,,,,0.000706007807756802,7.00253511267265E-8,0.0273340986435819,5.98569896918626E-5,0.000705915677163247,7.00162131581484E-8,0.000705915596831526,5.58368271801497E-8,3.36771193021183E-7,4.22435656101774E-8,1.00013051217948,10.005763053894,2,20,10,5,2.30939877880817,0.204181763180415,0.0404026173055172,172.741912841797,48.9995994567871,49.0003089904785,149.975830078125,149.975830078125,,,55.1264228820801,0,1,,,,,,1,1,1,48.9996910095215,0,48.9999239179823,,,,,,,,,,,,,,,,,,,,,,,,,,,,,,,,,
,3754814181.50254,49.0009174346924,149.975830078125,,,5,,,,-2.43999995291233,,,,,0.000706249122745327,6.11275086941579E-8,0.028871961866221,5.25745772475136E-5,0.000706157010054185,6.11195361259134E-8,0.000706156920398342,4.8558560046323E-8,3.55840126031397E-7,3.71168956470566E-8,1.00013044222437,10.005763053894,2,20,10,5,2.31018265358779,0.204313555597669,0.0404026173055172,172.741912841797,48.998851776123,49.0013160705566,149.975830078125,149.975830078125,,,55.3378524780273,0,1,,,,,,1,1,1,49.0007820129395,0,49.0000769671272,,,,,,,,,,,,,,,,,,,,,,,,,,,,,,,,,
,3754814386.42758,49.0000133514404,149.975830078125,,,5,,,,-2.43999995291233,,,,,0.000706480330610668,5.092681080656E-8,0.0291949948909336,4.58426868217871E-5,0.00070638821698881,5.0920170773158E-8,0.000706388125285506,3.93020081389986E-8,3.59939242800062E-7,3.23761632657371E-8,1.00013040084707,10.005763053894,2,20,10,5,2.31093779556516,0.204393474923558,0.0404026173055172,172.741912841797,48.9995307922363,49.0004386901855,149.975830078125,149.975830078125,,,55.5244102478027,0,1,,,,,,1,1,1,48.9999961853027,0,49.0000417497423,,,,,,,,,,,,,,,,,,,,,,,,,,,,,,,,,
,3754814591.46181,49.0006294250488,149.975830078125,,,5,,,,-2.43999995291233,,,,,0.000706080009828975,5.20974078456547E-8,0.031064681227682,4.3087476194133E-5,0.000705987928499097,5.20906137167587E-8,0.000705987824732922,4.22921637193313E-8,3.82773200073501E-7,3.04106054745027E-8,1.00013042904299,10.005763053894,2,20,10,5,2.30962165619611,0.204353023201998,0.0404026173055172,172.741912841797,48.999439239502,49.0008316040039,149.975830078125,149.975830078125,,,55.7358436584473,0,1,,,,,,1,1,1,49.0004997253418,0,49.0003557707134,,,,,,,,,,,,,,,,,,,,,,,,,,,,,,,,,
,3754814797.50499,48.9993934631348,149.975830078125,,,5,,,,-2.43999995291233,,,,,0.000706597604504024,6.59024642037788E-8,0.0271376579688987,6.65644309896477E-5,0.000706505414581202,6.58938658968357E-8,0.000706505335333814,4.61613729085648E-8,3.34630259683246E-7,4.70226457574069E-8,1.00013048721343,10.005763053894,2,20,10,5,2.31132874380118,0.204344414257554,0.0404026173055172,172.741912841797,48.998836517334,49.000072479248,149.975830078125,149.975830078125,,,55.9223976135254,0,1,,,,,,1,1,1,48.9990310668945,0,48.9994453854031,,,,,,,,,,,,,,,,,,,,,,,,,,,,,,,,,
,3754815004.29371,49.0001525878906,149.975830078125,,,5,,,,-2.43999995291233,,,,,0.000706891199293988,5.1120375516413E-8,0.0310813960587248,4.51946248734349E-5,0.000706799027598035,5.11137099196227E-8,0.000706798923600821,3.99082871136371E-8,3.83419156173982E-7,3.19364988908122E-8,1.00013040721953,10.005763053894,2,20,10,5,2.31227503595327,0.20458847473769,0.0404026173055172,172.741912841797,48.9991149902344,49.0008544921875,149.975830078125,149.975830078125,,,56.1213912963867,0,1,,,,,,1,1,1,48.9997100830078,0,48.9997722401338,,,,,,,,,,,,,,,,,,,,,,,,,,,,,,,,,
,3754815209.90463,48.9999561309814,149.975830078125,,,5,,,,-2.43999995291233,,,,,0.000707108708079832,5.61524126723959E-8,0.0304258705702116,4.29652148326935E-5,0.000707016433268734,5.6145085010874E-8,0.000707016333581335,4.72247409844291E-8,3.75448063739322E-7,3.03660074726965E-8,1.00013051296512,10.005763053894,2,20,10,5,2.31298885896567,0.204624962463818,0.0404026173055172,172.741912841797,48.9991989135742,49.0002861022949,149.975830078125,149.975830078125,,,56.320384979248,0,1,,,,,,1,1,1,48.9998550415039,0,48.9998229531681,,,,,,,,,,,,,,,,,,,,,,,,,,,,,,,,,
,3754815415.01266,49.0001163482666,149.975830078125,,,5,,,,-2.43999995291233,,,,,0.000707341593942472,6.26318647102095E-8,0.0302373307325308,6.10392364047616E-5,0.000707249364692343,6.26236982317133E-8,0.000707249266204144,4.53718751909703E-8,3.73244454297342E-7,4.31638798287609E-8,1.00013040556094,10.005763053894,2,20,10,5,2.31375131421174,0.204684740908979,0.0404026173055172,172.741912841797,48.9992256164551,49.0002174377441,149.975830078125,149.975830078125,,,56.4945030212402,0,1,,,,,,1,1,1,49.0000839233398,0,48.999866909451,,,,,,,,,,,,,,,,,,,,,,,,,,,,,,,,,
,3754815622.70226,49.0008411407471,149.975830078125,,,5,,,,-2.43999995291233,,,,,0.000707385483404509,4.53977574892794E-8,0.0285508198099222,4.50429525802728E-5,0.000707293224972659,4.53918366356378E-8,0.000707293137159137,3.23374345012865E-8,3.52448308668989E-7,3.18544998866948E-8,1.00013043873261,10.005763053894,2,20,10,5,2.31390090338812,0.204629329631614,0.0404026173055172,172.741912841797,48.9997673034668,49.0011367797852,149.975830078125,149.975830078125,,,56.6810607910156,0,1,,,,,,1,1,1,49.00048828125,0,49.0003242492676,,,,,,,,,,,,,,,,,,,,,,,,,,,,,,,,,
,3754815826.48497,48.9998722076416,149.975830078125,,,5,,,,-2.43999995291233,,,,,0.00070743506347903,4.13594807918349E-8,0.0340555081521279,4.21401564047336E-5,0.00070734274879638,4.13540837065885E-8,0.000707342623848365,2.86682185698109E-8,4.20430885735555E-7,2.98042527711244E-8,1.00013050912419,10.005763053894,2,20,10,5,2.31404341086713,0.204865996114664,0.0404026173055172,172.741912841797,48.9992942810059,49.0003700256348,149.975830078125,149.975830078125,,,56.867618560791,0,1,,,,,,1,1,1,49.0000877380371,0,48.999897480011,,,,,,,,,,,,,,,,,,,,,,,,,,,,,,,,,
,3754816032.95291,49.0001735687256,149.975830078125,,,5,,,,-2.43999995291233,,,,,0.000707742387909781,6.7877095913248E-8,0.0344019879968709,7.74526906945795E-5,0.000707650104547741,6.786824533891E-8,0.000707649976988954,4.00283764492397E-8,4.24892882979602E-7,5.48071875233571E-8,1.00013040817976,10.005763053894,2,20,10,5,2.31504743979533,0.204968993353923,0.0404026173055172,172.741912841797,48.9999771118164,49.0004615783691,149.975830078125,149.975830078125,,,57.0541725158691,0,1,,,,,,1,1,1,49.0001792907715,0,49.0001653783462,,,,,,,,,,,,,,,,,,,,,,,,,,,,,,,,,
,3754816237.98159,49.0000553131103,149.975830078125,,,5,,,,-2.43999995291233,,,,,0.000707590395025941,5.30286429845912E-8,0.0318815811037858,2.9563200660463E-5,0.000707498054145542,5.30217227216623E-8,0.000707497944616402,4.8729951280714E-8,3.93679178845522E-7,2.08972469132199E-8,1.00013051750441,10.005763053894,2,20,10,5,2.31455927850685,0.204823160085201,0.0404026173055172,172.741912841797,48.9994506835937,49.0002861022949,149.975830078125,149.975830078125,,,57.2282943725586,0,1,,,,,,1,1,1,48.9998893737793,0,48.9998092651367,,,,,,,,,,,,,,,,,,,,,,,,,,,,,,,,,
,3754816443.22686,49.0006675720215,149.975830078125,,,5,,,,-2.43999995291233,,,,,0.000708180797545463,4.60329877818878E-8,0.031049827455325,5.00953712004007E-5,0.000708088441011513,4.60269844459972E-8,0.000708088337036109,2.93325160913249E-8,3.83728487983274E-7,3.54695192657617E-8,1.00013043078887,10.005763053894,2,20,10,5,2.31649348695397,0.204960430599734,0.0404026173055172,172.741912841797,48.9994087219238,49.0009269714355,149.975830078125,149.975830078125,,,57.414852142334,0,1,,,,,,1,1,1,49.0005226135254,0,49.0002914004856,,,,,,,,,,,,,,,,,,,,,,,,,,,,,,,,,
,3754816648.21816,49.0005321502686,149.975830078125,,,5,,,,-2.43999995291233,,,,,0.00070802122633992,7.55248529727543E-8,0.0338874054533429,7.55746335031402E-5,0.000707928895003329,7.55150039592482E-8,0.000707928771183271,5.32992247925145E-8,4.18702255250587E-7,5.3494938634251E-8,1.000130424591,10.005763053894,2,20,10,5,2.31596137073174,0.205028945001404,0.0404026173055172,172.741912841797,49.0002899169922,49.0009460449219,149.975830078125,149.975830078125,,,57.613842010498,0,1,,,,,,1,1,1,49.0008125305176,0,49.0004669638241,,,,,,,,,,,,,,,,,,,,,,,,,,,,,,,,,
,3754816855.99854,49.0024528503418,149.975830078125,,,5,,,,-2.43999995291233,,,,,0.000707974330063028,4.53729165308635E-8,0.029028003192904,5.08941801959893E-5,0.000707881942623875,4.53669955710389E-8,0.00070788185177493,2.75744779021742E-8,3.58637208294524E-7,3.60251641990036E-8,1.00013051249593,10.005763053894,2,20,10,5,2.31582535148569,0.204818948751959,0.0404026173055172,172.741912841797,49.0013275146484,49.0027313232422,149.975830078125,149.975830078125,,,57.7879638671875,0,1,,,,,,1,1,1,49.0021743774414,0,49.001958061667,,,,,,,,,,,,,,,,,,,,,,,,,,,,,,,,,
,3754817061.3118,48.9999942779541,149.975830078125,,,5,,,,-2.43999995291233,,,,,0.000707935083797024,4.01541022618034E-8,0.0319655697712946,4.17900664221197E-5,0.000707842781116675,4.01488668506045E-8,0.000707842670956039,2.71491356984673E-8,3.94908609768429E-7,2.9577963760438E-8,1.00013039997413,10.005763053894,2,20,10,5,2.31568647018316,0.204926330705592,0.0404026173055172,172.741912841797,48.9992523193359,49.0002250671387,149.975830078125,149.975830078125,,,57.9496459960937,0,1,,,,,,1,1,1,48.9997634887695,0,48.9997769524069,,,,,,,,,,,,,,,,,,,,,,,,,,,,,,,,,
,3754817267.64562,49.0002269744873,149.975830078125,,,5,,,,-2.43999995291233,,,,,0.000708239771771847,6.46080221883178E-8,0.0316847059241372,5.33695740091074E-5,0.000708147421824692,6.45995977144706E-8,0.000708147313544812,5.23981446271052E-8,3.91607232828079E-7,3.77828329338656E-8,1.00013041062399,10.005763053894,2,20,10,5,2.31668412287296,0.205003171288776,0.0404026173055172,172.741912841797,48.9993515014648,49.0008316040039,149.975830078125,149.975830078125,,,58.1362037658691,0,1,,,,,,1,1,1,49.000057220459,0,48.9999425676134,,,,,,,,,,,,,,,,,,,,,,,,,,,,,,,,,
,3754817474.33392,48.9997825622559,149.975830078125,,,5,,,,-2.43999995291233,,,,,0.000708324227219182,6.21241820457507E-8,0.0316844179684948,7.52732787070773E-5,0.000708231799413057,6.21160755859782E-8,0.000708231691122243,3.18813255252859E-8,3.91650334425562E-7,5.33102985262108E-8,1.00013050502138,10.005763053894,2,20,10,5,2.31696038136553,0.205027606776648,0.0404026173055172,172.741912841797,48.999698638916,49.0005073547363,149.975830078125,149.975830078125,,,58.3351936340332,0,1,,,,,,1,1,1,48.9997863769531,0,49.000041737276,,,,,,,,,,,,,,,,,,,,,,,,,,,,,,,,,
,3754817682.06709,49.0001659393311,149.975830078125,,,5,,,,-2.43999995291233,,,,,0.00070799637426825,4.89217201688869E-8,0.0339768059428875,4.53649966661474E-5,0.000707903976823687,4.89153356136949E-8,0.000707903852353833,3.69021483958499E-8,4.19792083141985E-7,3.21082777795864E-8,1.00013052256745,10.005763053894,2,20,10,5,2.31587975859089,0.205025364854503,0.0404026173055172,172.741912841797,48.9991455078125,49.0004196166992,149.975830078125,149.975830078125,,,58.5093154907227,0,1,,,,,,1,1,1,49.0000953674316,0,48.9997850305894,,,,,,,,,,,,,,,,,,,,,,,,,,,,,,,,,
,3754817887.25847,49.0004959106445,149.975830078125,,,5,,,,-2.43999995291233,,,,,0.000708179537554488,5.21167184371081E-8,0.0319084769369189,4.73412908333838E-5,0.000708087186747182,5.21099221082585E-8,0.000708087076941804,3.99020668013652E-8,3.9433938575849E-7,3.35152062071554E-8,1.00013042293242,10.005763053894,2,20,10,5,2.31648629366497,0.204994780902756,0.0404026173055172,172.741912841797,48.9989814758301,49.0006484985352,149.975830078125,149.975830078125,,,58.7207450866699,0,1,,,,,,1,1,1,49.0006484985352,0,48.9998898506165,,,,,,,,,,,,,,,,,,,,,,,,,,,,,,,,,
,3754818092.61277,49.0005512237549,149.975830078125,,,5,,,,-2.43999995291233,,,,,0.000708310881100399,5.30876762228781E-8,0.0345798173572236,4.54274191171248E-5,0.000708218511372481,5.30807531410232E-8,0.00070821838238802,4.2225772963789E-8,4.27432273260552E-7,3.21644283584955E-8,1.00013042546394,10.005763053894,2,20,10,5,2.31690636207013,0.205140825538788,0.0404026173055172,172.741912841797,48.9992446899414,49.0013198852539,149.975830078125,149.975830078125,,,58.8824272155762,0,1,,,,,,1,1,1,49.0001564025879,0,48.9998938242594,,,,,,,,,,,,,,,,,,,,,,,,,,,,,,,,,
,3754818297.71965,49.0005226135254,149.975830078125,,,5,,,,-2.43999995291233,,,,,0.000708434654309171,4.08817497366527E-8,0.0324782013688489,3.50985167162567E-5,0.000708342269367568,4.0876418464334E-8,0.000708342155565062,3.24511710112511E-8,4.0152489111874E-7,2.4855644961857E-8,1.00013042415454,10.005763053894,2,20,10,5,2.31731875240805,0.205091672492566,0.0404026173055172,172.741912841797,48.9992027282715,49.000560760498,149.975830078125,149.975830078125,,,59.0689888000488,0,1,,,,,,1,1,1,49.0003547668457,0,49.0000341203478,,,,,,,,,,,,,,,,,,,,,,,,,,,,,,,,,
,3754818502.90448,48.9996719360352,149.975830078125,,,5,,,,-2.43999995291233,,,,,0.000708565401021155,4.93819687032794E-8,0.0332477258425579,3.66557648897934E-5,0.000708472945331307,4.93755251992981E-8,0.000708472826050138,4.20008445391736E-8,4.11114276330317E-7,2.59590359355407E-8,1.00013049995834,10.005763053894,2,20,10,5,2.31774367480187,0.205160654908666,0.0404026173055172,172.741912841797,48.9993133544922,49.0011367797852,149.975830078125,149.975830078125,,,59.243106842041,0,1,,,,,,1,1,1,48.999813079834,0,49.0002371844123,,,,,,,,,,,,,,,,,,,,,,,,,,,,,,,,,
,3754818707.959,49.0002536773682,149.975830078125,,,5,,,,-2.43999995291233,,,,,0.000708502719033091,3.71203817917514E-8,0.0330903109870278,3.72510605034308E-5,0.000708410252663471,3.71155372275021E-8,0.000708410134519582,2.61026518607341E-8,4.09131605558162E-7,2.63858801165208E-8,1.00013052658297,10.005763053894,2,20,10,5,2.31753920348302,0.205136136464526,0.0404026173055172,172.741912841797,48.9997444152832,49.0007705688477,149.975830078125,149.975830078125,,,59.4296607971191,0,1,,,,,,1,1,1,49.0003051757812,0,49.0001463048598,,,,,,,,,,,,,,,,,,,,,,,,,,,,,,,,,
,3754818913.61622,49.000638961792,149.975830078125,,,5,,,,-2.43999995291233,,,,,0.000708439239663953,6.30686660905442E-8,0.0374550414457788,5.69855698123511E-5,0.000708346769090092,6.30604339156172E-8,0.000708346617737032,4.84552058705722E-8,4.63056021404683E-7,4.03572961144127E-8,1.00013054421633,10.005763053894,2,20,10,5,2.31731592780368,0.205294286961166,0.0404026173055172,172.741912841797,48.9996147155762,49.0013084411621,149.975830078125,149.975830078125,,,59.5913429260254,0,1,,,,,,1,1,1,49.000602722168,0,49.0003532833523,,,,,,,,,,,,,,,,,,,,,,,,,,,,,,,,,
,3754819121.42438,49.0005989074707,149.975830078125,,,5,,,,-2.43999995291233,,,,,0.000708638409934007,5.18305738308878E-8,0.0317754391856466,5.52287361150826E-5,0.000708545914661729,5.18238086274052E-8,0.000708545805699533,3.3979887338833E-8,3.92949649324942E-7,3.91289457702369E-8,1.00013054238316,10.005763053894,2,20,10,5,2.31798776174599,0.205122225693068,0.0404026173055172,172.741912841797,49.0001258850098,49.0011405944824,149.975830078125,149.975830078125,,,59.7654609680176,0,1,,,,,,1,1,1,49.0010070800781,0,49.0005926244399,,,,,,,,,,,,,,,,,,,,,,,,,,,,,,,,,
,3754819327.02541,49.000129699707,149.975830078125,,,5,,,,-2.43999995291233,,,,,0.000708565020518639,4.7689739888863E-8,0.0333181702601193,5.30401549506271E-5,0.000708472550037501,4.76835161929915E-8,0.000708472430250403,2.93565020832756E-8,4.11985104609988E-7,3.75754374819764E-8,1.00013052090887,10.005763053894,2,20,10,5,2.31774217806906,0.205163392721888,0.0404026173055172,172.741912841797,48.9994621276855,49.0002098083496,149.975830078125,149.975830078125,,,59.939582824707,0,1,,,,,,1,1,1,49.0002098083496,0,48.9998254215016,,,,,,,,,,,,,,,,,,,,,,,,,,,,,,,,,
,3754819532.11035,48.9999370574951,149.975830078125,,,5,,,,-2.43999995291233,,,,,0.000709152298790887,5.92550566817315E-8,0.0335512993011422,6.19572291522807E-5,0.000709059757918397,5.92473241894952E-8,0.000709059636348444,3.97571657893984E-8,4.15211643909543E-7,4.39273626798768E-8,1.00013051209218,10.005763053894,2,20,10,5,2.31966235129083,0.205342876867322,0.0404026173055172,172.741912841797,48.9991035461426,49.0002555847168,149.975830078125,149.975830078125,,,60.1137046813965,0,1,,,,,,1,1,1,49.0000534057617,0,48.9997861525592,,,,,,,,,,,,,,,,,,,,,,,,,,,,,,,,,
,3754819737.0006,49.0006980895996,149.975830078125,,,5,,,,-2.43999995291233,,,,,0.000708676267365655,4.11678464106819E-8,0.0364389656908424,3.95126062459279E-5,0.000708583845226062,4.11624774987782E-8,0.000708583701925447,3.0177832456593E-8,4.50645072012795E-7,2.79937132595736E-8,1.00013043218557,10.005763053894,2,20,10,5,2.31809489056251,0.205321866207453,0.0404026173055172,172.741912841797,48.9989242553711,49.0011711120605,149.975830078125,149.975830078125,,,60.2878227233887,0,1,,,,,,1,1,1,49.000316619873,0,48.9997132245232,,,,,,,,,,,,,,,,,,,,,,,,,,,,,,,,,
,3754819942.01536,48.9986610412598,149.975830078125,,,5,,,,-2.43999995291233,,,,,0.000708773344319419,5.54167242272558E-8,0.03271016493232,4.66572858810089E-5,0.000708680894279897,5.54094958539175E-8,0.000708680778790818,4.44689603297974E-8,4.04585955092282E-7,3.30563730311146E-8,1.00013045369258,10.005763053894,2,20,10,5,2.31842578997656,0.205199115841806,0.0404026173055172,172.741912841797,48.9984436035156,49.0003890991211,149.975830078125,149.975830078125,,,60.4743766784668,0,1,,,,,,1,1,1,48.9988021850586,0,48.9994488884421,,,,,,,,,,,,,,,,,,,,,,,,,,,,,,,,,
,3754820146.97874,48.9995498657227,149.975830078125,,,5,,,,-2.43999995291233,,,,,0.000708875395877487,4.9672049604218E-8,0.0339595881989032,4.89378060002025E-5,0.000708782903697919,4.96655685270665E-8,0.0007087827791998,3.55506536541017E-8,4.20100299310993E-7,3.46816914507186E-8,1.00013049437153,10.005763053894,2,20,10,5,2.3187551291199,0.205279221658007,0.0404026173055172,172.741912841797,48.9992370605469,49.0002784729004,149.975830078125,149.975830078125,,,60.6236228942871,0,1,,,,,,1,1,1,48.9996528625488,0,48.9997890696806,,,,,,,,,,,,,,,,,,,,,,,,,,,,,,,,,
,3754820351.93533,49.000114440918,149.975830078125,,,5,,,,-2.43999995291233,,,,,0.000708863095348135,6.32369649763423E-8,0.0317777114428015,5.61233178652305E-5,0.000708770586461983,6.32287123514956E-8,0.000708770477449647,4.91550136286704E-8,3.9310235784244E-7,3.97700226400916E-8,1.00013052021052,10.005763053894,2,20,10,5,2.31872270933516,0.205187357865708,0.0404026173055172,172.741912841797,48.9991645812988,49.0003814697266,149.975830078125,149.975830078125,,,60.7977409362793,0,1,,,,,,1,1,1,49.0003204345703,0,48.9997359381782,,,,,,,,,,,,,,,,,,,,,,,,,,,,,,,,,
,3754820556.92949,48.9994525909424,149.975830078125,,,5,,,,-2.43999995291233,,,,,0.000709432599028738,4.60704230837163E-8,0.0344760206812627,3.99224910122597E-5,0.000709340037304343,4.60644121422822E-8,0.00070933990889002,3.63368698574821E-8,4.26824113891844E-7,2.83118695068772E-8,1.00013048991954,10.005763053894,2,20,10,5,2.32057590733861,0.205461496510706,0.0404026173055172,172.741912841797,48.9991645812988,48.9999122619629,149.975830078125,149.975830078125,,,60.9718627929688,0,1,,,,,,1,1,1,48.9993782043457,0,48.9995305678424,,,,,,,,,,,,,,,,,,,,,,,,,,,,,,,,,
,3754820762.05311,49.0006237030029,149.975830078125,,,5,,,,-2.43999995291233,,,,,0.000708995491724802,4.581381462924E-8,0.033693643463101,3.5652815197035E-5,0.000708903030366626,4.58078399685076E-8,0.000708902907790043,3.82100910298941E-8,4.16881047459129E-7,2.5265532768331E-8,1.00013042878111,10.005763053894,2,20,10,5,2.31914891989125,0.205303231904787,0.0404026173055172,172.741912841797,48.9995231628418,49.000862121582,149.975830078125,149.975830078125,,,61.1459846496582,0,1,,,,,,1,1,1,49.0003852844238,0,49.000119377585,,,,,,,,,,,,,,,,,,,,,,,,,,,,,,,,,
,3754820966.99058,49.0002517700195,149.975830078125,,,5,,,,-2.43999995291233,,,,,0.000709015724091197,5.14146373330593E-8,0.0359045298011313,4.83241946564651E-5,0.000708923272160416,5.14079331340826E-8,0.000708923132965797,3.83347319790455E-8,4.44248342590079E-7,3.42523563162166E-8,1.00013041175881,10.005763053894,2,20,10,5,2.31920717650185,0.205398583925024,0.0404026173055172,172.741912841797,48.9991722106934,49.0004501342773,149.975830078125,149.975830078125,,,61.3449745178223,0,1,,,,,,1,1,1,49.0000534057617,0,48.999750922708,,,,,,,,,,,,,,,,,,,,,,,,,,,,,,,,,
,3754821171.94888,48.9998874664307,149.975830078125,,,5,,,,-2.43999995291233,,,,,0.000709469546284705,6.42450167053728E-8,0.0328671699826408,8.31180723663822E-5,0.000709376965622805,6.42366331937738E-8,0.00070937684890787,2.5488988388295E-8,4.06927215762456E-7,5.89631793156781E-8,1.00013050982254,10.005763053894,2,20,10,5,2.32070253193756,0.205407029046023,0.0404026173055172,172.741912841797,48.9990577697754,49.0001602172852,149.975830078125,149.975830078125,,,61.5315322875977,0,1,,,,,,1,1,1,49.0001602172852,0,48.9995381972369,,,,,,,,,,,,,,,,,,,,,,,,,,,,,,,,,
,3754821376.79762,49.0007038116455,149.975830078125,,,5,,,,-2.43999995291233,,,,,0.000709042999829881,3.87278957098637E-8,0.0362989367115336,3.59317988528862E-5,0.000708950529677173,3.87228449944188E-8,0.000708950387402216,2.91680339349488E-8,4.4914562478389E-7,2.54692858327724E-8,1.00013043244745,10.005763053894,2,20,10,5,2.3192949821977,0.205422449566078,0.0404026173055172,172.741912841797,48.9991645812988,49.0012474060059,149.975830078125,149.975830078125,,,61.6807746887207,0,1,,,,,,1,1,1,49.0003776550293,0,48.9998825920953,,,,,,,,,,,,,,,,,,,,,,,,,,,,,,,,,
,3754821581.80304,49.0007076263428,149.975830078125,,,5,,,,-2.43999995291233,,,,,0.00070898865644415,5.99501552506319E-8,0.0325617285670257,6.73441463363415E-5,0.00070889619325491,5.994233681447E-8,0.000708896078776846,3.625189345716E-8,4.02872329874822E-7,4.77376577090883E-8,1.00013043262204,10.005763053894,2,20,10,5,2.31913061690748,0.205255436173565,0.0404026173055172,172.741912841797,49.0000991821289,49.001163482666,149.975830078125,149.975830078125,,,61.830020904541,0,1,,,,,,1,1,1,49.0005226135254,0,49.0003736159381,,,,,,,,,,,,,,,,,,,,,,,,,,,,,,,,,
,3754821787.10932,49.0001544952393,149.975830078125,,,5,,,,-2.43999995291233,,,,,0.000709108754270292,5.2388114736764E-8,0.0355610019763946,3.97662485061854E-5,0.000709016212025291,5.23812778253314E-8,0.000709016075463606,4.41526474682096E-8,4.40055541832944E-7,2.81840733067907E-8,1.00013052204369,10.005763053894,2,20,10,5,2.31951271215716,0.205411625974358,0.0404026173055172,172.741912841797,48.9998893737793,49.0007972717285,149.975830078125,149.975830078125,,,62.0041427612305,0,1,,,,,,1,1,1,49.0003623962402,0,49.0003350201775,,,,,,,,,,,,,,,,,,,,,,,,,,,,,,,,,
,3754821990.42715,49.0018463134766,149.975830078125,,,5,,,,-2.43999995291233,,,,,0.000709205447086046,8.16095764537447E-8,0.0338290792178979,9.79865889881937E-5,0.00070911291867372,8.15989290389922E-8,0.000709112795073149,4.2784947193369E-8,4.18680676139614E-7,6.94826130335576E-8,1.00013048473648,10.005763053894,2,20,10,5,2.31983520606768,0.205369508464706,0.0404026173055172,172.741912841797,49.0000648498535,49.0024681091309,149.975830078125,149.975830078125,,,62.1533851623535,0,1,,,,,,1,1,1,49.0012664794922,0,49.0007884502411,,,,,,,,,,,,,,,,,,,,,,,,,,,,,,,,,
,3754822196.95799,49.0010185241699,149.975830078125,,,5,,,,-2.43999995291233,,,,,0.000709225423823186,4.22898444897272E-8,0.0336459255409558,3.81749088485018E-5,0.000709132919666918,4.2284328632213E-8,0.000709132797397644,3.24871581880061E-8,4.16425646796868E-7,2.70656424410074E-8,1.00013044685094,10.005763053894,2,20,10,5,2.31990120702366,0.205367878834373,0.0404026173055172,172.741912841797,48.9997215270996,49.0014114379883,149.975830078125,149.975830078125,,,62.3523826599121,0,1,,,,,,1,1,1,49.000919342041,0,49.0003211077522,,,,,,,,,,,,,,,,,,,,,,,,,,,,,,,,,
,3754822403.41643,49.0001373291016,149.975830078125,,,5,,,,-2.43999995291233,,,,,0.000709220700592626,6.88271969380327E-8,0.0379778702994118,8.43509869303295E-5,0.00070912814429512,6.88182146980742E-8,0.000709127988515493,3.4029842714597E-8,4.70037670252727E-7,5.98156875664739E-8,1.00013052125804,10.005763053894,2,20,10,5,2.31987022318083,0.205541912508984,0.0404026173055172,172.741912841797,48.9997253417969,49.0002517700195,149.975830078125,149.975830078125,,,62.5140647888184,0,1,,,,,,1,1,1,49.000186920166,0,49.0000171661377,,,,,,,,,,,,,,,,,,,,,,,,,,,,,,,,,
,3754822609.94237,48.9998798370361,149.975830078125,,,5,,,,-2.43999995291233,,,,,0.000709216614385269,5.08745749717256E-8,0.0338024179738454,4.27438443943952E-5,0.000709124066976735,5.08679362241576E-8,0.00070912394356897,4.08570807673718E-8,4.18357284261994E-7,3.03025722814652E-8,1.00013050947337,10.005763053894,2,20,10,5,2.31987182974325,0.20537166835985,0.0404026173055172,172.741912841797,48.9993095397949,49.0006370544434,149.975830078125,149.975830078125,,,62.6633110046387,0,1,,,,,,1,1,1,48.9999198913574,0,48.99991162618,,,,,,,,,,,,,,,,,,,,,,,,,,,,,,,,,
,3754822815.14829,48.9996471405029,149.975830078125,,,5,,,,-2.43999995291233,,,,,0.000709185259296247,5.17815455260375E-8,0.0340118189056584,5.9611267375019E-5,0.000709092723530062,5.17747889769882E-8,0.000709092598594098,2.98999595305145E-8,4.2093033882338E-7,4.22684420541526E-8,1.00013049882352,10.005763053894,2,20,10,5,2.31976851557324,0.205371067268774,0.0404026173055172,172.741912841797,48.9994354248047,49.0003890991211,149.975830078125,149.975830078125,,,62.8374290466309,0,1,,,,,,1,1,1,48.9998168945313,0,48.9997987186208,,,,,,,,,,,,,,,,,,,,,,,,,,,,,,,,,
,3754823019.94365,48.9999847412109,149.975830078125,,,5,,,,-2.43999995291233,,,,,0.000709385959923959,6.51807095229717E-8,0.0350973753177746,6.0466178799093E-5,0.000709293387012123,6.51722036200966E-8,0.000709293253936068,4.90782141799635E-8,4.34488104866825E-7,4.28805902198765E-8,1.00013051427453,10.005763053894,2,20,10,5,2.32042112147188,0.205473150792292,0.0404026173055172,172.741912841797,48.9993553161621,49.0004196166992,149.975830078125,149.975830078125,,,63.0364189147949,0,1,,,,,,1,1,1,49.0000114440918,0,48.9999293159036,,,,,,,,,,,,,,,,,,,,,,,,,,,,,,,,,
,3754823224.9894,49.0003108978271,149.975830078125,,,5,,,,-2.43999995291233,,,,,0.000709362181460996,6.90550990512091E-8,0.0360547527537944,8.47657811673286E-5,0.000709269601066119,6.90460865206492E-8,0.000709269460635725,3.39519772214395E-8,4.46324993425644E-7,6.01217540210848E-8,1.00013052920178,10.005763053894,2,20,10,5,2.32033990803768,0.205505033580978,0.0404026173055172,172.741912841797,48.9997062683105,49.0006141662598,149.975830078125,149.975830078125,,,63.1732292175293,0,1,,,,,,1,1,1,49.0003204345703,0,49.0000971625833,,,,,,,,,,,,,,,,,,,,,,,,,,,,,,,,,
,3754823430.01636,49.0006446838379,149.975830078125,,,5,,,,-2.43999995291233,,,,,0.000709166198845136,4.44540344508514E-8,0.0367334114350708,4.07108034840462E-5,0.000709073714543956,4.44482370787861E-8,0.000709073568817421,3.38032952371744E-8,4.54600581947673E-7,2.88614450525333E-8,1.00013042974134,10.005763053894,2,20,10,5,2.31969641092061,0.205475731284451,0.0404026173055172,172.741912841797,48.9999504089355,49.0009803771973,149.975830078125,149.975830078125,,,63.3224754333496,0,1,,,,,,1,1,1,49.0007476806641,0,49.0004680857939,,,,,,,,,,,,,,,,,,,,,,,,,,,,,,,,,
,3754823634.88383,49.000659942627,149.975830078125,,,5,,,,-2.43999995291233,,,,,0.000709418699911398,4.07474259229137E-8,0.036942845720727,3.68574365346527E-5,0.00070932618218557,4.07421119113431E-8,0.000709326034740109,3.12520329112375E-8,4.57355255852406E-7,2.61386710050709E-8,1.00013043043969,10.005763053894,2,20,10,5,2.3205215953948,0.205557374490263,0.0404026173055172,172.741912841797,48.9997901916504,49.0007438659668,149.975830078125,149.975830078125,,,63.5090293884277,0,1,,,,,,1,1,1,49.0005989074707,0,49.0003496805827,,,,,,,,,,,,,,,,,,,,,,,,,,,,,,,,,
,3754823839.92164,48.9999942779541,149.975830078125,,,5,,,,-2.43999995291233,,,,,0.000709283722612874,5.86324226510651E-8,0.0340205993774578,6.47741349128907E-5,0.000709191162733225,5.86247712559871E-8,0.000709191037715393,3.64263166956658E-8,4.21097456334361E-7,4.59345976014145E-8,1.000130514711,10.005763053894,2,20,10,5,2.32009056092941,0.20539993591274,0.0404026173055172,172.741912841797,48.9993476867676,49.0001487731934,149.975830078125,149.975830078125,,,63.670711517334,0,1,,,,,,1,1,1,48.9999694824219,0,48.9998619977166,,,,,,,,,,,,,,,,,,,,,,,,,,,,,,,,,
,3754824044.67164,49.0008487701416,149.975830078125,,,5,,,,-2.43999995291233,,,,,0.000709813792635707,4.21534095358928E-8,0.0342755913727366,4.203109933306E-5,0.000709721217251805,4.21479118009783E-8,0.000709721090258031,2.97794295107024E-8,4.24570765715838E-7,2.98267002398882E-8,1.00013043908179,10.005763053894,2,20,10,5,2.32182352299693,0.20556376774272,0.0404026173055172,172.741912841797,49.0000038146973,49.0010185241699,149.975830078125,149.975830078125,,,63.8323936462402,0,1,,,,,,1,1,1,49.0007286071777,0,49.0005782632267,,,,,,,,,,,,,,,,,,,,,,,,,,,,,,,,,
,3754824249.5303,49.0003890991211,149.975830078125,,,5,,,,-2.43999995291233,,,,,0.000709992549915124,7.67391405212167E-8,0.0327104340104176,9.94709968336199E-5,0.000709899966150129,7.672913365769E-8,0.000709899850460481,3.00126264891703E-8,4.05285257180764E-7,7.06158778397692E-8,1.00013041804396,10.005763053894,2,20,10,5,2.32241385961744,0.205552095708052,0.0404026173055172,172.741912841797,48.9993019104004,49.0006980895996,149.975830078125,149.975830078125,,,63.9940795898438,0,1,,,,,,1,1,1,49.0004692077637,0,49.0000943077935,,,,,,,,,,,,,,,,,,,,,,,,,,,,,,,,,
,3754824454.42393,49.0003662109375,149.975830078125,,,5,,,,-2.43999995291233,,,,,0.00070942585144113,5.93306125486582E-8,0.0373195141355742,6.41063036393768E-5,0.000709333342317151,5.93228758373714E-8,0.000709333191848142,3.81014458338634E-8,4.62023102724077E-7,4.54695878910878E-8,1.00013041699644,10.005763053894,2,20,10,5,2.32054363657396,0.205574704242426,0.0404026173055172,172.741912841797,48.9997749328613,49.0009155273438,149.975830078125,149.975830078125,,,64.1060180664062,0,1,,,,,,1,1,1,49.0001029968262,0,49.0002398771398,,,,,,,,,,,,,,,,,,,,,,,,,,,,,,,,,
,3754824659.4091,49.0003890991211,149.975830078125,,,5,,,,-2.43999995291233,,,,,0.000709470178273429,4.55507049529843E-8,0.0351169839940617,4.99106562540206E-5,0.000709377662626237,4.55447650938079E-8,0.000709377529385614,2.86518862668649E-8,4.34782503636815E-7,3.54033196296729E-8,1.00013041804396,10.005763053894,2,20,10,5,2.32069653177127,0.205498337979147,0.0404026173055172,172.741912841797,48.9995460510254,49.0007514953613,149.975830078125,149.975830078125,,,64.2677001953125,0,1,,,,,,1,1,1,49.0002098083496,0,49.0002138614655,,,,,,,,,,,,,,,,,,,,,,,,,,,,,,,,,
,3754824864.34583,49.0005855560303,149.975830078125,,,5,,,,-2.43999995291233,,,,,0.000709444368557799,3.39722045447451E-8,0.034480892492474,2.88747554014805E-5,0.00070935184989908,3.3967774228659E-8,0.000709351721446323,2.71016266367729E-8,4.26891537338006E-7,2.04770974429999E-8,1.00013042703523,10.005763053894,2,20,10,5,2.32061438881538,0.20546509741724,0.0404026173055172,172.741912841797,49.0000076293945,49.0008811950684,149.975830078125,149.975830078125,,,64.4542541503906,0,1,,,,,,1,1,1,49.0005874633789,0,49.0004509819878,,,,,,,,,,,,,,,,,,,,,,,,,,,,,,,,,
,3754825069.39506,49.0001544952393,149.975830078125,,,5,,,,-2.43999995291233,,,,,0.000709603494716653,9.97287641053924E-8,0.0352069469084944,0.000129965628769465,0.000709510969301987,9.97157604416257E-8,0.000709510835352649,3.79439409436574E-8,4.3597824599844E-7,9.22143710389868E-8,1.00013040730682,10.005763053894,2,20,10,5,2.32113229072201,0.205540598635869,0.0404026173055172,172.741912841797,48.9994163513184,49.0008010864258,149.975830078125,149.975830078125,,,64.591064453125,0,1,,,,,,1,1,1,48.9999771118164,0,49.0001063346863,,,,,,,,,,,,,,,,,,,,,,,,,,,,,,,,,
,3754825274.32993,49.0003337860107,149.975830078125,,,5,,,,-2.43999995291233,,,,,0.000709620538792864,4.70659429416814E-8,0.0377332080501098,3.91715331659309E-5,0.000709528005334456,4.70598056130169E-8,0.000709527851468788,3.79815030302184E-8,4.67272914949515E-7,2.77854410060458E-8,1.00013041551244,10.005763053894,2,20,10,5,2.32117897750073,0.205647877690802,0.0404026173055172,172.741912841797,48.9994697570801,49.0006980895996,149.975830078125,149.975830078125,,,64.7527465820312,0,1,,,,,,1,1,1,49.0005760192871,0,49.0000252193875,,,,,,,,,,,,,,,,,,,,,,,,,,,,,,,,,
,3754825479.36302,49.0004653930664,149.975830078125,,,5,,,,-2.43999995291233,,,,,0.000709752636779788,5.40342240416629E-8,0.0369428094808608,5.20151310129285E-5,0.00070966000040853,5.40271715360721E-8,0.000709659852893969,3.94559127479528E-8,4.57570044382758E-7,3.69075359975993E-8,1.00013053627259,10.005763053894,2,20,10,5,2.32161390925585,0.205654131658323,0.0404026173055172,172.741912841797,48.9998741149902,49.000846862793,149.975830078125,149.975830078125,,,64.9019927978516,0,1,,,,,,1,1,1,49.0008697509766,0,49.0002914877499,,,,,,,,,,,,,,,,,,,,,,,,,,,,,,,,,
,3754825684.35932,49.0005569458008,149.975830078125,,,5,,,,-2.43999995291233,,,,,0.000709539052006404,6.69424307112729E-8,0.036143633852161,5.43990033346924E-5,0.000709446521928847,6.69337008347594E-8,0.000709446380770028,5.46954958853927E-8,4.47536866476637E-7,3.85813820033454E-8,1.00013042572582,10.005763053894,2,20,10,5,2.32091813682449,0.205559873314129,0.0404026173055172,172.741912841797,48.9995803833008,49.000919342041,149.975830078125,149.975830078125,,,65.0636749267578,0,1,,,,,,1,1,1,49.0004959106445,0,49.000446543974,,,,,,,,,,,,,,,,,,,,,,,,,,,,,,,,,
,3754825889.37511,48.999870300293,149.975830078125,,,5,,,,-2.43999995291233,,,,,0.000709742442127946,7.25930862032002E-8,0.0351087794997378,4.65723065527506E-5,0.000709649826412566,7.25836133857225E-8,0.000709649693183098,6.46331976228707E-8,4.34847696114903E-7,3.30292400332035E-8,1.0001305090369,10.005763053894,2,20,10,5,2.32158714376899,0.205576867117562,0.0404026173055172,172.741912841797,48.9995002746582,49.0004463195801,149.975830078125,149.975830078125,,,65.2129211425781,0,1,,,,,,1,1,1,49.0001525878906,0,49.0001047919778,,,,,,,,,,,,,,,,,,,,,,,,,,,,,,,,,
,3754826043.08344,49.0011081695557,149.975830078125,,,5,,,,-2.43999995291233,,,,,0.000709455778486552,4.92811160015548E-8,0.0362644554885811,3.9584306953644E-5,0.000709363241375159,4.92746880715001E-8,0.000709363099287706,4.04972947479315E-8,4.48980190044132E-7,2.80706965115365E-8,1.00013045095375,10.005763053894,2,20,10,5,2.32064531409213,0.205540639168019,0.0404026173055172,172.741912841797,48.9999237060547,49.001277923584,149.975830078125,149.975830078125,,,65.337287902832,0,1,,,,,,1,1,1,49.0011405944824,0,49.0006968180338,,,,,,,,,,,,,,,,,,,,,,,,,,,,,,,,,