File: Experimental_Data/Fig3B/Lifetime_340Oe.dat
[Header]
; MPMS3 Data File (default extension .dat)
; Copyright (c) 2007, Quantum Design, Inc. All rights reserved.
TITLE,340Oe
FILEOPENTIME,3755371078.50577,12/30/2018,10:37 pm
BYAPP,SQUID AC,0.9.1.0
INFO,MPMS3 Measurement Release 1.1.16 Build 347, MultiVu Release 2.3.3.2,APPNAME
INFO,0,MOMENT_UNITS
INFO,CoIINO3,SAMPLE_MATERIAL
INFO,40 Hours Pumped Turbo,SAMPLE_COMMENT
INFO,,SAMPLE_MASS
INFO,,SAMPLE_VOLUME
INFO,,SAMPLE_MOLECULAR_WEIGHT
INFO,,SAMPLE_SIZE
INFO,,SAMPLE_SHAPE
INFO,Brass,SAMPLE_HOLDER
INFO,Standard,SAMPLE_HOLDER_DETAIL
INFO,65.37,SAMPLE_OFFSET
DATATYPE,COMMENT,1
DATATYPE,TIME,2
STARTUPAXIS,X,2
STARTUPAXIS,Y1,5
FIELDGROUP, VSM,2,3,4,5,6,8,9,10,11,14,15
FIELDGROUP, DC, 2,3,4,14,56,57,58,59,60,61,62,63,64,65,66,67,68,69
FIELDGROUP, AC, 2,3,4,11,16,17,18,19,20,21,22,23,24,25,26,27,28,29,30
STARTUPGROUP, All
[Data]
Comment,Time Stamp (sec),Temperature (K),Magnetic Field (Oe),Moment (emu),M. Std. Err. (emu),Transport Action,Averaging Time (sec),Frequency (Hz),Peak Amplitude (mm),Center Position (mm),Lockin Signal' (V),Lockin Signal (V),Range,M. Quad. Signal (emu),AC Moment (emu),AC M. Std Err. (emu),AC Phase (deg),AC Phase Std. Err. (deg),AC Susceptibility (emu/Oe),AC Suscept. Std Err. (emu/Oe),AC X' (emu/Oe),AC X' Std Err. (emu/Oe),AC X'' (emu/Oe),AC X'' Std Err. (emu/Oe),AC Drive (Oe),AC Frequency (Hz),AC Averaging Time (sec),AC Cycles,AC Range,AC Measure Type,AC Signal' (V),AC Signal'' (V),AC Trim Coil Ratio,AC Trim Coil Phase,Min. Temperature (K),Max. Temperature (K),Min. Field (Oe),Max. Field (Oe),Mass (grams),Motor Lag (deg),Pressure (Torr),Measure Count,Measurement Number,SQUID Status (code),Motor Status (code),Measure Status (code),Motor Current (amps),Motor Temp. (C),Temp. Status (code),Field Status (code),Chamber Status (code),Chamber Temp (K),Redirection State,Average Temp (K),Rotation Angle (deg),Rotator state,DC Moment Fixed Ctr (emu),DC Moment Err Fixed Ctr (emu),DC Moment Free Ctr (emu),DC Moment Err Free Ctr (emu),DC Fixed Fit,DC Free Fit,DC Calculated Center (mm),DC Calculated Center Err (mm),DC Scan Length (mm),DC Scan Time (s),DC Number of Points,DC Squid Drift,DC Min V (V),DC Max V (V),DC Scans per Measure,Map 01,Map 02,Map 03,Map 04,Map 05,Map 06,Map 07,Map 08,Map 09,Map 10,Map 11,Map 12,Map 13,Map 14,Map 15,Map 16
,3755371082.41947,48.9886169433594,339.74365234375,,,5,,,,-2.43000010959804,,,,,0.00068554729979099,1.74648222733123E-7,0.017048199919774,9.12319381793654E-5,0.00068545819433639,1.74625522462425E-7,0.000685458163993093,1.6306789584903E-7,2.03956177236283E-7,6.24734698783773E-8,1.00012999400304,10.005763053894,2,20,10,5,2.24247826169117,0.198317402336931,0.0404026173055172,172.741912841797,48.9272994995117,48.9977111816406,339.74365234375,339.74365234375,,,12.0475120544434,0,1,,,,,,1,1,1,48.9834442138672,0,48.9602396347943,,,,,,,,,,,,,,,,,,,,,,,,,,,,,,,,,
,3755371287.49113,48.9996356964111,339.74365234375,,,5,,,,-2.43000010959804,,,,,0.000714154642533105,9.36650938684344E-8,-0.0131017383529128,8.47113773298246E-5,0.000714061458726822,9.36528723278286E-8,0.000714061440057945,7.15059119107954E-8,-1.63283341253266E-7,6.0479459794695E-8,1.00013049829975,10.005763053894,2,20,10,5,2.33616348849182,0.205363663700061,0.0404026173055172,172.741912841797,48.9993209838867,49.0002403259277,339.74365234375,339.74365234375,,,12.0141353607178,0,1,,,,,,1,1,1,48.9997787475586,0,48.9997170392205,,,,,,,,,,,,,,,,,,,,,,,,,,,,,,,,,
,3755371492.33388,48.9998645782471,339.74365234375,,,5,,,,-2.43000010959804,,,,,0.000722830257105222,1.00085071590331E-7,-0.00954372057054265,9.75573539303127E-5,0.00072273593372385,1.00072011314721E-7,0.00072273592369757,7.10226118079246E-8,-1.20385651866028E-7,7.04996174497034E-8,1.00013050877502,10.005763053894,2,20,10,5,2.36453049937385,0.208005276287551,0.0404026173055172,172.741912841797,48.9993782043457,49.0004730224609,339.74365234375,339.74365234375,,,11.6061353683472,0,1,,,,,,1,1,1,48.9996070861816,0,49.0000400543213,,,,,,,,,,,,,,,,,,,,,,,,,,,,,,,,,
,3755371697.68247,49.0007991790771,339.74365234375,,,5,,,,-2.43000010959804,,,,,0.000728354018592796,1.93043262777035E-7,-0.0152035455422999,0.000139966637572635,0.000728259026806923,1.93018086113196E-7,0.000728259001167965,1.63925419344335E-7,-1.93244934353107E-7,1.01904064980673E-7,1.00013043681215,10.005763053894,2,20,10,5,2.38262058330512,0.209359458154552,0.0404026173055172,172.741912841797,48.9997634887695,49.0013046264648,339.74365234375,339.74365234375,,,11.2591514587402,0,1,,,,,,1,1,1,49.0003509521484,0,49.000347810633,,,,,,,,,,,,,,,,,,,,,,,,,,,,,,,,,
,3755371902.69363,48.9988880157471,339.74365234375,,,5,,,,-2.43000010959804,,,,,0.000730811863504784,9.89667373219431E-8,-0.0161653016057448,9.1273673257234E-5,0.00073071653124439,9.89538274018338E-8,0.00073071650216125,7.31084667277048E-8,-2.06162706215726E-7,6.66859209293536E-8,1.00013046408055,10.005763053894,2,20,10,5,2.39066430836948,0.210025823067414,0.0404026173055172,172.741912841797,48.998420715332,49.0005493164063,339.74365234375,339.74365234375,,,10.9612617492676,0,1,,,,,,1,1,1,48.9988288879395,0,48.9993452184341,,,,,,,,,,,,,,,,,,,,,,,,,,,,,,,,,
,3755372107.56687,48.9996147155762,339.74365234375,,,5,,,,-2.43000010959804,,,,,0.000732710736836394,1.01895867155086E-7,-0.015909181394254,7.18159038553777E-5,0.000732615132510709,1.0188257175053E-7,0.000732615104268654,8.72552494925981E-8,-2.03423480482672E-7,5.25982876383468E-8,1.00013049733952,10.005763053894,2,20,10,5,2.39687504638008,0.210582245293696,0.0404026173055172,172.741912841797,48.9994239807129,48.9999732971191,339.74365234375,339.74365234375,,,10.7037935256958,0,1,,,,,,1,1,1,48.9996757507324,0,48.9997217655182,,,,,,,,,,,,,,,,,,,,,,,,,,,,,,,,,
,3755372312.60897,48.9991703033447,339.74365234375,,,5,,,,-2.43000010959804,,,,,0.000734640432032428,1.23717280434895E-7,-0.0151934852275417,0.000125474262663285,0.000734544590857812,1.23701140281209E-7,0.000734544565031778,8.2516818403808E-8,-1.94783845410896E-7,9.21571852184318E-8,1.00013047700005,10.005763053894,2,20,10,5,2.40318491098428,0.211166863994038,0.0404026173055172,172.741912841797,48.9988746643066,49.0001258850098,339.74365234375,339.74365234375,,,10.4866418838501,0,1,,,,,,1,1,1,48.9991226196289,0,48.9994025230408,,,,,,,,,,,,,,,,,,,,,,,,,,,,,,,,,
,3755372517.58483,48.9998760223389,339.74365234375,,,5,,,,-2.43000010959804,,,,,0.000735419437469167,7.81427870157608E-8,-0.0137454186976411,6.32318309904684E-5,0.0007353234709186,7.81325899862298E-8,0.000735323449758432,6.2798966885891E-8,-1.76406167695464E-7,4.64864644388134E-8,1.00013050929878,10.005763053894,2,20,10,5,2.40572788136869,0.211451581533589,0.0404026173055172,172.741912841797,48.9994468688965,49.0002899169922,339.74365234375,339.74365234375,,,10.2791566848755,0,1,,,,,,1,1,1,48.9998207092285,0,48.9998038796818,,,,,,,,,,,,,,,,,,,,,,,,,,,,,,,,,
,3755372722.66708,49.0014133453369,339.74365234375,,,5,,,,-2.43000010959804,,,,,0.000736838549428144,7.7423660718415E-8,-0.0145428850703615,6.00829773872978E-5,0.000736742430385336,7.74135609643173E-8,0.000736742406652941,6.35160278177704E-8,-1.87000865815265E-7,4.4255775119506E-8,1.00013046492077,10.005763053894,2,20,10,5,2.41037307541012,0.211826057505343,0.0404026173055172,172.741912841797,48.9997291564941,49.0016975402832,339.74365234375,339.74365234375,,,10.0397491455078,0,1,,,,,,1,1,1,49.0011749267578,0,49.000534955193,,,,,,,,,,,,,,,,,,,,,,,,,,,,,,,,,
,3755372927.62763,49.0021457672119,339.74365234375,,,5,,,,-2.43000010959804,,,,,0.000737454380084015,1.3908091495996E-7,-0.01687002481773,8.50142722575079E-5,0.000737358155993747,1.39062767485517E-7,0.000737358124031694,1.24145193311463E-7,-2.1710587266897E-7,6.26611863787351E-8,1.00013049844161,10.005763053894,2,20,10,5,2.41239621221775,0.211905109755722,0.0404026173055172,172.741912841797,49.0005340576172,49.0022315979004,339.74365234375,339.74365234375,,,9.82976627349854,0,1,,,,,,1,1,1,49.0021438598633,0,49.0015079975128,,,,,,,,,,,,,,,,,,,,,,,,,,,,,,,,,
,3755373132.60272,49.0009307861328,339.74365234375,,,5,,,,-2.43000010959804,,,,,0.000737920537138377,9.85730755967986E-8,-0.0142418202888441,8.46084013394412E-5,0.000737824293245523,9.85602191223565E-8,0.000737824270452145,7.62784853846392E-8,-1.83398515043163E-7,6.24156187253824E-8,1.00013044283542,10.005763053894,2,20,10,5,2.41391139815022,0.212149792170531,0.0404026173055172,172.741912841797,48.9992866516113,49.0011444091797,339.74365234375,339.74365234375,,,9.64563179016113,0,1,,,,,,1,1,1,49.0009002685547,0,49.0002661810981,,,,,,,,,,,,,,,,,,,,,,,,,,,,,,,,,
,3755373337.97282,49.0002326965332,339.74365234375,,,5,,,,-2.43000010959804,,,,,0.000738655457750073,9.79935644558754E-8,-0.0135025413232412,6.89459093168772E-5,0.000738559141598151,9.79807866946845E-8,0.000738559121089314,8.37187406199708E-8,-1.74051654790777E-7,5.09058644000405E-8,1.00013041088587,10.005763053894,2,20,10,5,2.41631275560043,0.212392259316427,0.0404026173055172,172.741912841797,48.9995727539063,49.0007095336914,339.74365234375,339.74365234375,,,9.48433876037598,0,1,,,,,,1,1,1,49.0003280639648,0,49.000026029699,,,,,,,,,,,,,,,,,,,,,,,,,,,,,,,,,
,3755373542.88711,49.0007495880127,339.74365234375,,,5,,,,-2.43000010959804,,,,,0.000739018631542026,1.34788178855735E-7,-0.015072631715749,0.000134392770219412,0.000738922250556328,1.34770600114166E-7,0.000738922224988039,9.11237002877253E-8,-1.94386094672199E-7,9.92954475341406E-8,1.00013043454251,10.005763053894,2,20,10,5,2.41750660340486,0.212430436431692,0.0404026173055172,172.741912841797,48.9995460510254,49.0008735656738,339.74365234375,339.74365234375,,,9.34353733062744,0,1,,,,,,1,1,1,49.000804901123,0,49.0002661312328,,,,,,,,,,,,,,,,,,,,,,,,,,,,,,,,,
,3755373747.95712,49.0001125335693,339.74365234375,,,5,,,,-2.43000010959804,,,,,0.0007394670664976,1.30049079456054E-7,-0.0119140885759474,0.000118718288660319,0.000739370648582512,1.30032122566872E-7,0.000739370632597661,9.59465476482819E-8,-1.53744785550475E-7,8.7764530954264E-8,1.00013040538635,10.005763053894,2,20,10,5,2.41896181937259,0.212692695157635,0.0404026173055172,172.741912841797,48.998706817627,49.000804901123,339.74365234375,339.74365234375,,,9.23135089874268,0,1,,,,,,1,1,1,48.9994201660156,0,48.9996901119457,,,,,,,,,,,,,,,,,,,,,,,,,,,,,,,,,
,3755373952.83214,48.9997577667236,339.74365234375,,,5,,,,-2.43000010959804,,,,,0.000739912374194112,1.27190415757449E-7,-0.0178125347052935,0.00010809576832897,0.000739815825353564,1.2717381907979E-7,0.000739815789601608,9.88937899942703E-8,-2.29999398984513E-7,7.9957479699577E-8,1.00013050388656,10.005763053894,2,20,10,5,2.42044041692337,0.212571600117386,0.0404026173055172,172.741912841797,48.9993667602539,49.0005378723145,339.74365234375,339.74365234375,,,9.13610458374023,0,1,,,,,,1,1,1,48.9998970031738,0,48.9999331306009,,,,,,,,,,,,,,,,,,,,,,,,,,,,,,,,,
,3755374157.74633,49.0006980895996,339.74365234375,,,5,,,,-2.43000010959804,,,,,0.000740389003223188,1.00593136870152E-7,-0.0146264881128086,8.08425665619465E-5,0.000740292445261591,1.0058001799858E-7,0.000740292421139876,8.08461300969311E-8,-1.88982131407132E-7,5.98351340680766E-8,1.00013043218557,10.005763053894,2,20,10,5,2.42198775942035,0.212843208900931,0.0404026173055172,172.741912841797,48.9998474121094,49.0008659362793,339.74365234375,339.74365234375,,,9.0512638092041,0,1,,,,,,1,1,1,49.0006294250488,0,49.0002629756927,,,,,,,,,,,,,,,,,,,,,,,,,,,,,,,,,
,3755374362.64006,48.99973487854,339.74365234375,,,5,,,,-2.43000010959804,,,,,0.00074053490389464,9.27399993240756E-8,-0.0124957643590102,8.67242093461673E-5,0.000740438274597675,9.27278980701197E-8,0.00074043825698849,6.69036312120964E-8,-1.61483833661873E-7,6.42056633883517E-8,1.00013050283903,10.005763053894,2,20,10,5,2.42245711627727,0.212975241969507,0.0404026173055172,172.741912841797,48.9992637634277,49.0001068115234,339.74365234375,339.74365234375,,,8.97748374938965,0,1,,,,,,1,1,1,48.9998321533203,0,48.9996932534611,,,,,,,,,,,,,,,,,,,,,,,,,,,,,,,,,
,3755374567.62578,48.9999465942383,339.74365234375,,,5,,,,-2.43000010959804,,,,,0.000740853736217521,1.11165170632253E-7,-0.0149559557608301,9.10748428826173E-5,0.000740757058140745,1.11150664078022E-7,0.000740757032904259,8.83445416019044E-8,-1.93360309597221E-7,6.74515536821406E-8,1.00013051252865,10.005763053894,2,20,10,5,2.42350923542136,0.212962875567435,0.0404026173055172,172.741912841797,48.9996795654297,49.0002861022949,339.74365234375,339.74365234375,,,8.91105461120605,0,1,,,,,,1,1,1,48.9998207092285,0,49.0000197887421,,,,,,,,,,,,,,,,,,,,,,,,,,,,,,,,,
,3755374772.65993,49.0001125335693,339.74365234375,,,5,,,,-2.43000010959804,,,,,0.000741016524346682,9.89676451752584E-8,-0.0132556910600234,8.56639301020065E-5,0.000740919819400556,9.89547295917588E-8,0.000740919799571562,7.59269291764909E-8,-1.7141583938768E-7,6.34597505069649E-8,1.00013052012322,10.005763053894,2,20,10,5,2.42403543216875,0.213081602376628,0.0404026173055172,172.741912841797,48.9998245239258,49.0004386901855,339.74365234375,339.74365234375,,,8.85355567932129,0,1,,,,,,1,1,1,49.0001640319824,0,49.0001815347111,,,,,,,,,,,,,,,,,,,,,,,,,,,,,,,,,
,3755374977.54013,49.0009307861328,339.74365234375,,,5,,,,-2.43000010959804,,,,,0.000741417644401717,8.99992216653994E-8,-0.0162471460165312,8.57895363381845E-5,0.000741320944395772,8.99874834429066E-8,0.000741320914591044,6.36715332740659E-8,-2.10213554465158E-7,6.3589960110987E-8,1.00013044283542,10.005763053894,2,20,10,5,2.42535871620908,0.213070313461118,0.0404026173055172,172.741912841797,48.9999923706055,49.0012168884277,339.74365234375,339.74365234375,,,8.80323123931885,0,1,,,,,,1,1,1,49.0007972717285,0,49.0004422929552,,,,,,,,,,,,,,,,,,,,,,,,,,,,,,,,,
,3755375182.4023,49.0012283325195,339.74365234375,,,5,,,,-2.43000010959804,,,,,0.000741613006657406,9.99854547964615E-8,-0.0159290988957252,7.50130761283727E-5,0.000741516271074643,9.99724127500698E-8,0.000741516242417833,8.30782125307441E-8,-2.06152808513259E-7,5.56101961313467E-8,1.00013045645326,10.005763053894,2,20,10,5,2.4259966111667,0.213139920816412,0.0404026173055172,172.741912841797,48.9996109008789,49.0014724731445,339.74365234375,339.74365234375,,,8.76047897338867,0,1,,,,,,1,1,1,49.0014724731445,0,49.0005059493215,,,,,,,,,,,,,,,,,,,,,,,,,,,,,,,,,
,3755375387.38851,49.0010509490967,339.74365234375,,,5,,,,-2.43000010959804,,,,,0.000741174261693182,1.31056377219583E-7,-0.0169933914542542,8.91511690866573E-5,0.000741077589355593,1.31039283363257E-7,0.000741077556760776,1.13176655353741E-7,-2.19796667333708E-7,6.60480012361956E-8,1.00013044833494,10.005763053894,2,20,10,5,2.4245653259287,0.212968789115535,0.0404026173055172,172.741912841797,49.0000839233398,49.0012741088867,339.74365234375,339.74365234375,,,8.72440242767334,0,1,,,,,,1,1,1,49.0012283325195,0,49.0006251864963,,,,,,,,,,,,,,,,,,,,,,,,,,,,,,,,,
,3755375592.27758,49.0010757446289,339.74365234375,,,5,,,,-2.43000010959804,,,,,0.000742023498929406,9.5452936442212E-8,-0.0114611135718556,8.4284428000497E-5,0.000741926714982838,9.54404862813834E-8,0.000741926700139234,7.2109166103779E-8,-1.48410691991064E-7,6.25232323656138E-8,1.00013044946976,10.005763053894,2,20,10,5,2.42732279365733,0.213447184168503,0.0404026173055172,172.741912841797,48.9996566772461,49.0014533996582,339.74365234375,339.74365234375,,,8.69265174865723,0,1,,,,,,1,1,1,49.001049041748,0,49.0004450480143,,,,,,,,,,,,,,,,,,,,,,,,,,,,,,,,,
,3755375797.33639,48.9997959136963,339.74365234375,,,5,,,,-2.43000010959804,,,,,0.000742205939621404,1.10459219772651E-7,-0.0154776970894162,8.71032138162347E-5,0.000742109090205248,1.10444806103381E-7,0.00074210906312796,8.95625878395233E-8,-2.0047095376682E-7,6.46266048520353E-8,1.00013050563244,10.005763053894,2,20,10,5,2.42793455792272,0.213329465361143,0.0404026173055172,172.741912841797,48.9990882873535,49.0002517700195,339.74365234375,339.74365234375,,,8.66475963592529,0,1,,,,,,1,1,1,48.999870300293,0,48.9997119903564,,,,,,,,,,,,,,,,,,,,,,,,,,,,,,,,,
,3755376002.28548,49.0000171661377,339.74365234375,,,5,,,,-2.43000010959804,,,,,0.000742570371600524,1.09820591030365E-7,-0.0186190252242282,7.33631905841626E-5,0.000742473467112777,1.09806259583105E-7,0.000742473427909754,9.53532300112354E-8,-2.41276619092496E-7,5.44534312055409E-8,1.00013051575853,10.005763053894,2,20,10,5,2.4291384010405,0.213301031196218,0.0404026173055172,172.741912841797,48.9995765686035,49.000431060791,339.74365234375,339.74365234375,,,8.63984298706055,0,1,,,,,,1,1,1,49.0000076293945,0,48.9999942779541,,,,,,,,,,,,,,,,,,,,,,,,,,,,,,,,,
,3755376207.08705,49.0009651184082,339.74365234375,,,5,,,,-2.43000010959804,,,,,0.00074260781031213,1.12768767833872E-7,-0.0134825191051116,0.00010246383518521,0.000742510953911271,1.1275405969745E-7,0.000742510933353799,8.322768448646E-8,-1.74723480761592E-7,7.60699054375546E-8,1.00013044440671,10.005763053894,2,20,10,5,2.42924174006407,0.213529561591446,0.0404026173055172,172.741912841797,48.9998664855957,49.0011024475098,339.74365234375,339.74365234375,,,8.61869239807129,0,1,,,,,,1,1,1,49.0008277893066,0,49.0004474415499,,,,,,,,,,,,,,,,,,,,,,,,,,,,,,,,,
,3755376412.18885,49.0000495910645,339.74365234375,,,5,,,,-2.43000010959804,,,,,0.00074261779165895,1.18623148445291E-7,-0.0186481122949864,0.000105674839038613,0.000742520965064603,1.18607681706406E-7,0.000742520925736481,8.89533236091448E-8,-2.41669006183601E-7,7.84543713164218E-8,1.00013040250566,10.005763053894,2,20,10,5,2.42929363245713,0.213313419924042,0.0404026173055172,172.741912841797,48.9988784790039,49.0007476806641,339.74365234375,339.74365234375,,,8.59922218322754,0,1,,,,,,1,1,1,48.9998397827148,0,48.9996647554285,,,,,,,,,,,,,,,,,,,,,,,,,,,,,,,,,
,3755376616.99477,49.0005950927734,339.74365234375,,,5,,,,-2.43000010959804,,,,,0.000742396833171742,1.10790074918444E-7,-0.0174585755172698,0.000116276031829119,0.000742300016857299,1.10775626733523E-7,0.00074229998239678,6.94465208176934E-8,-2.26185956633523E-7,8.63042306293405E-8,1.0001304274717,10.005763053894,2,20,10,5,2.42856639277216,0.213300368914674,0.0404026173055172,172.741912841797,48.9993171691895,49.000919342041,339.74365234375,339.74365234375,,,8.58345413208008,0,1,,,,,,1,1,1,49.0003128051758,0,49.0000184003045,,,,,,,,,,,,,,,,,,,,,,,,,,,,,,,,,
,3755376822.13723,48.9997062683105,339.74365234375,,,5,,,,-2.43000010959804,,,,,0.000742933876747951,1.05832889720813E-7,-0.0158103064144672,8.98720402836823E-5,0.000742836935391619,1.05819080168988E-7,0.000742836907110356,8.21112020834315E-8,-2.04979834732828E-7,6.67489941514068E-8,1.00013050152963,10.005763053894,2,20,10,5,2.43031705526305,0.213524586062241,0.0404026173055172,172.741912841797,48.9993515014648,48.9999580383301,339.74365234375,339.74365234375,,,8.5728120803833,0,1,,,,,,1,1,1,48.9996948242188,0,48.9997117784288,,,,,,,,,,,,,,,,,,,,,,,,,,,,,,,,,
,3755377028.41633,49.0008220672607,339.74365234375,,,5,,,,-2.43000010959804,,,,,0.000743039708840072,7.61788845069224E-8,-0.0203653250397036,7.69661984903945E-5,0.000742942800971254,7.61689491922164E-8,0.00074294275403993,5.0325297980676E-8,-2.64073051063772E-7,5.71758096068836E-8,1.00013043785967,10.005763053894,2,20,10,5,2.43068022784762,0.213361762564569,0.0404026173055172,172.741912841797,48.9997444152832,49.0015335083008,339.74365234375,339.74365234375,,,8.56272602081299,0,1,,,,,,1,1,1,49.000114440918,0,49.0002310903449,,,,,,,,,,,,,,,,,,,,,,,,,,,,,,,,,
,3755377238.74281,49.0006084442139,339.74365234375,,,5,,,,-2.43000010959804,,,,,0.000743087698021813,9.74828104176484E-8,-0.0156426216415122,9.0634977204671E-5,0.000742990791157415,9.74700975796948E-8,0.000742990763467141,7.04754163159926E-8,-2.02847815032636E-7,6.73322776778177E-8,1.00013042808276,10.005763053894,2,20,10,5,2.43081961724334,0.213575906166334,0.0404026173055172,172.741912841797,48.9992332458496,49.0007171630859,339.74365234375,339.74365234375,,,8.55520057678223,0,1,,,,,,1,1,1,49.0004768371582,0,48.9999870724148,,,,,,,,,,,,,,,,,,,,,,,,,,,,,,,,,
,3755377443.75202,48.9998455047607,339.74365234375,,,5,,,,-2.43000010959804,,,,,0.000743228659676534,1.17248561962479E-7,-0.0149395598239499,0.000126810329179627,0.000743131675120645,1.17233262095389E-7,0.000743131649858739,6.9745332242201E-8,-1.93767500609735E-7,9.42296469904839E-8,1.00013050790208,10.005763053894,2,20,10,5,2.43127811541493,0.213646255471701,0.0404026173055172,172.741912841797,48.9992332458496,49.000373840332,339.74365234375,339.74365234375,,,8.54854774475098,0,1,,,,,,1,1,1,49.0002593994141,0,48.9998297691345,,,,,,,,,,,,,,,,,,,,,,,,,,,,,,,,,
,3755377648.74288,49.0000667572022,339.74365234375,,,5,,,,-2.43000010959804,,,,,0.000743320504154598,1.03292453589937E-7,-0.0147907844209509,9.32165997820422E-5,0.000743223500088878,1.03278973821923E-7,0.000743223475324548,7.66033935234373E-8,-1.91861574058777E-7,6.92709645840363E-8,1.00013051802817,10.005763053894,2,20,10,5,2.43157800574049,0.213678970925874,0.0404026173055172,172.741912841797,48.9995422363281,49.0005683898926,339.74365234375,339.74365234375,,,8.54136180877686,0,1,,,,,,1,1,1,49.0002059936523,0,49.0000307419721,,,,,,,,,,,,,,,,,,,,,,,,,,,,,,,,,
,3755377853.69943,49.0007400512695,339.74365234375,,,5,,,,-2.43000010959804,,,,,0.000743473234246784,1.36561045847846E-7,-0.0210990738249768,0.000104119294938586,0.000743376272627216,1.3654323595293E-7,0.000743376222223772,1.12498518383121E-7,-2.73747047944915E-7,7.73830643364552E-8,1.00013043410604,10.005763053894,2,20,10,5,2.43210113847753,0.213455100657199,0.0404026173055172,172.741912841797,48.9995574951172,49.0011444091797,339.74365234375,339.74365234375,,,8.53619956970215,0,1,,,,,,1,1,1,49.0003967285156,0,49.0000784132216,,,,,,,,,,,,,,,,,,,,,,,,,,,,,,,,,
,3755378058.65606,48.9997291564941,339.74365234375,,,5,,,,-2.43000010959804,,,,,0.000743301029696296,1.14362544347275E-7,-0.0191746611229169,0.000136066925700866,0.000743204039653771,1.14347621687953E-7,0.000743203998035102,5.33864970977089E-8,-2.48721379840589E-7,1.01120030228079E-7,1.00013050257715,10.005763053894,2,20,10,5,2.43153064152114,0.213487333088054,0.0404026173055172,172.741912841797,48.9990882873535,49.0005645751953,339.74365234375,339.74365234375,,,8.53159523010254,0,1,,,,,,1,1,1,48.9993629455566,0,48.9997426083213,,,,,,,,,,,,,,,,,,,,,,,,,,,,,,,,,
,3755378263.72083,49.0003623962402,339.74365234375,,,5,,,,-2.43000010959804,,,,,0.000743741750178343,1.02732670726851E-7,-0.014683392284665,8.10994810282285E-5,0.000743644766391324,1.0271927440554E-7,0.00074364474197147,8.31598604137419E-8,-1.90576475241891E-7,6.02966578706279E-8,1.00013041682185,10.005763053894,2,20,10,5,2.43295560085944,0.213804624660117,0.0404026173055172,172.741912841797,48.9992942810059,49.0006484985352,339.74365234375,339.74365234375,,,8.5278434753418,0,1,,,,,,1,1,1,49.0002403259277,0,48.9998633440803,,,,,,,,,,,,,,,,,,,,,,,,,,,,,,,,,
,3755378468.74282,49.001335144043,339.74365234375,,,5,,,,-2.43000010959804,,,,,0.000743849802929088,1.10964124571337E-7,-0.02024279564964,8.73655881670973E-5,0.000743752771944551,1.10949649931143E-7,0.000743752725525708,8.99406809344389E-8,-2.62770402829994E-7,6.49653656411836E-8,1.00013046134172,10.005763053894,2,20,10,5,2.43332980442619,0.213599577554303,0.0404026173055172,172.741912841797,48.9998359680176,49.0014495849609,339.74365234375,339.74365234375,,,8.52378177642822,0,1,,,,,,1,1,1,49.0012664794922,0,49.0005562726189,,,,,,,,,,,,,,,,,,,,,,,,,,,,,,,,,
,3755378673.69323,49.0002479553223,339.74365234375,,,5,,,,-2.43000010959804,,,,,0.000743876526755796,1.45685840359374E-7,-0.0156426651156787,0.00014790257042005,0.000743779529289072,1.45666843715517E-7,0.000743779501569249,9.54967613623264E-8,-2.03063716924773E-7,1.09996354154798E-7,1.00013041158422,10.005763053894,2,20,10,5,2.43340006684026,0.213802628933424,0.0404026173055172,172.741912841797,48.9993362426758,49.0005989074707,339.74365234375,339.74365234375,,,8.52040672302246,0,1,,,,,,1,1,1,49.0000267028809,0,48.9998168945313,,,,,,,,,,,,,,,,,,,,,,,,,,,,,,,,,
,3755378878.72265,48.9984283447266,339.74365234375,,,5,,,,-2.43000010959804,,,,,0.000744090538888051,1.05982091553229E-7,-0.0164212111465618,0.000102368507510087,0.000743993404761097,1.05968256572943E-7,0.000743993374204556,7.36886343970877E-8,-2.13231632902095E-7,7.61528499913268E-8,1.00013055777959,10.005763053894,2,20,10,5,2.43410305759001,0.213831070242882,0.0404026173055172,172.741912841797,48.9978370666504,49.0019111633301,339.74365234375,339.74365234375,,,8.51757144927978,0,1,,,,,,1,1,1,48.9987297058105,0,48.999854592716,,,,,,,,,,,,,,,,,,,,,,,,,,,,,,,,,
,3755379083.67198,49.0000400543213,339.74365234375,,,5,,,,-2.43000010959804,,,,,0.000744135277770403,1.45591427627397E-7,-0.0158858205827475,8.40449230816655E-5,0.000744038168285096,1.45572427979047E-7,0.000744038139686859,1.3147054588329E-7,-2.06291925812072E-7,6.25046186522621E-8,1.00013051680605,10.005763053894,2,20,10,5,2.43424741161831,0.213866668016213,0.0404026173055172,172.741912841797,48.9992446899414,49.0002021789551,339.74365234375,339.74365234375,,,8.51641845703125,0,1,,,,,,1,1,1,48.9999580383301,0,48.9998171189252,,,,,,,,,,,,,,,,,,,,,,,,,,,,,,,,,
,3755379288.61143,48.9998188018799,339.74365234375,,,5,,,,-2.43000010959804,,,,,0.000744228370914682,9.0867385541665E-8,-0.0154357459598806,8.18744791058413E-5,0.000744131256814897,9.08555282883116E-8,0.000744131229810808,6.74082853386929E-8,-2.00472373352317E-7,6.09167471902888E-8,1.00013050667996,10.005763053894,2,20,10,5,2.43455026166679,0.213912547250272,0.0404026173055172,172.741912841797,48.999324798584,49.0004997253418,339.74365234375,339.74365234375,,,8.51635837554932,0,1,,,,,,1,1,1,48.9999809265137,0,48.9998844371122,,,,,,,,,,,,,,,,,,,,,,,,,,,,,,,,,
,3755379493.56779,48.9995670318604,339.74365234375,,,5,,,,-2.43000010959804,,,,,0.000744268025315877,9.00085028434277E-8,-0.0157501334547865,9.19867574830062E-5,0.000744170914615411,8.99967587022558E-8,0.00074417088649861,5.84325329045499E-8,-2.04566395122918E-7,6.84474665365399E-8,1.00013049515717,10.005763053894,2,20,10,5,2.43468115448658,0.213910586432031,0.0404026173055172,172.741912841797,48.9992752075195,49.0001487731934,339.74365234375,339.74365234375,,,8.51525688171387,0,1,,,,,,1,1,1,48.9998207092285,0,48.9998323777143,,,,,,,,,,,,,,,,,,,,,,,,,,,,,,,,,
,3755379698.59822,48.999813079834,339.74365234375,,,5,,,,-2.43000010959804,,,,,0.000744368992143206,1.08240577886797E-7,-0.0137281632600921,7.07542697501538E-5,0.000744271859888692,1.08226453639991E-7,0.000744271838524759,9.45607667706457E-8,-1.78328763331492E-7,5.26424415774637E-8,1.00013050641808,10.005763053894,2,20,10,5,2.43500388992549,0.214025537771566,0.0404026173055172,172.741912841797,48.999210357666,49.000675201416,339.74365234375,339.74365234375,,,8.51566886901855,0,1,,,,,,1,1,1,48.9996185302734,0,49.0000392689424,,,,,,,,,,,,,,,,,,,,,,,,,,,,,,,,,
,3755379903.57977,49.0015068054199,339.74365234375,,,5,,,,-2.43000010959804,,,,,0.000744487719575238,8.15234261035139E-8,-0.0189665836242749,7.00187973206248E-5,0.000744390599530593,8.15127911950061E-8,0.000744390558745276,6.26783080296012E-8,-2.46415118482588E-7,5.21130005943536E-8,1.00013046919817,10.005763053894,2,20,10,5,2.43541183649893,0.213837003348462,0.0404026173055172,172.741912841797,49.0002632141113,49.0016403198242,339.74365234375,339.74365234375,,,8.51593208312988,0,1,,,,,,1,1,1,49.0015640258789,0,49.001109653049,,,,,,,,,,,,,,,,,,,,,,,,,,,,,,,,,
,3755380108.67754,49.0004062652588,339.74365234375,,,5,,,,-2.43000010959804,,,,,0.000744468868175967,1.04578499032057E-7,-0.0151415654874745,9.30753517421851E-5,0.00074437170268283,1.04564849809284E-7,0.000744371676689846,7.83270687152869E-8,-1.96715235359176E-7,6.92724918139138E-8,1.00013053356648,10.005763053894,2,20,10,5,2.43533588750175,0.21399417631919,0.0404026173055172,172.741912841797,48.9997177124023,49.0006561279297,339.74365234375,339.74365234375,,,8.51614570617676,0,1,,,,,,1,1,1,49.0001564025879,0,49.0001386754653,,,,,,,,,,,,,,,,,,,,,,,,,,,,,,,,,
,3755380313.3346,48.9972820281982,339.74365234375,,,5,,,,-2.43000010959804,,,,,0.000744219235614671,1.01708243187849E-7,-0.0130010335763693,0.000100287183469496,0.000744122123721799,1.01694971453467E-7,0.000744122104564922,6.90942530423512E-8,-1.68849376247646E-7,7.46180367970178E-8,1.00013050531596,10.005763053894,2,20,10,5,2.43451128501436,0.214013382713589,0.0404026173055172,172.741912841797,48.9961547851562,49.0028419494629,339.74365234375,339.74365234375,,,8.51592636108398,0,1,,,,,,1,1,1,48.997802734375,0,48.9994850158691,,,,,,,,,,,,,,,,,,,,,,,,,,,,,,,,,
,3755380518.62538,48.9998512268066,339.74365234375,,,5,,,,-2.43000010959804,,,,,0.000744594018189426,1.23455795426896E-7,-0.0177672396401372,0.000123954407810325,0.00074449685527177,1.23439685540176E-7,0.000744496819476345,8.19925729463579E-8,-2.30866111594249E-7,9.22744490522366E-8,1.00013050816396,10.005763053894,2,20,10,5,2.43575508872786,0.213918529575084,0.0404026173055172,172.741912841797,48.9993286132812,49.0004959106445,339.74365234375,339.74365234375,,,8.51681041717529,0,1,,,,,,1,1,1,48.999755859375,0,48.9998860078699,,,,,,,,,,,,,,,,,,,,,,,,,,,,,,,,,
,3755380723.61351,49.0003814697266,339.74365234375,,,5,,,,-2.43000010959804,,,,,0.000744753392448001,1.32812212512329E-7,-0.0210909090436431,0.000123464626287521,0.000744656190664684,1.3279487847393E-7,0.000744656140213527,9.58326517408992E-8,-2.74112260359799E-7,9.19270504759795E-8,1.00013053243166,10.005763053894,2,20,10,5,2.43628885028922,0.213822986829501,0.0404026173055172,172.741912841797,48.9995460510254,49.0009536743164,339.74365234375,339.74365234375,,,8.5174036026001,0,1,,,,,,1,1,1,49.0006713867188,0,49.000233594109,,,,,,,,,,,,,,,,,,,,,,,,,,,,,,,,,
,3755380927.17026,49.000394821167,339.74365234375,,,5,,,,-2.43000010959804,,,,,0.000744833503286524,9.73157922990129E-8,-0.0177925719955514,7.70182582152129E-5,0.00074473637603006,9.73031021932712E-8,0.000744736340120939,7.86081525804473E-8,-2.31269658740282E-7,5.73467701298277E-8,1.00013041830585,10.005763053894,2,20,10,5,2.43653859992234,0.213986251431261,0.0404026173055172,172.741912841797,49.0000419616699,49.0007286071777,339.74365234375,339.74365234375,,,8.51686477661133,0,1,,,,,,1,1,1,49.0006408691406,0,49.0003316542682,,,,,,,,,,,,,,,,,,,,,,,,,,,,,,,,,
,3755381130.98877,48.9998378753662,339.74365234375,,,5,,,,-2.43000010959804,,,,,0.000744861208547789,1.41322285374716E-7,-0.0141295691640728,9.0453906923263E-5,0.000744764011219195,1.413038441558E-7,0.000744763988572686,1.24224513240925E-7,-1.83664391866234E-7,6.73427552396082E-8,1.0001305075529,10.005763053894,2,20,10,5,2.4366155446172,0.214149990865131,0.0404026173055172,172.741912841797,48.9993782043457,49.0001182556152,339.74365234375,339.74365234375,,,8.5177001953125,0,1,,,,,,1,1,1,48.999942779541,0,48.9998000649845,,,,,,,,,,,,,,,,,,,,,,,,,,,,,,,,,
,3755381336.1085,49.0004348754883,339.74365234375,,,5,,,,-2.43000010959804,,,,,0.000744976329195414,1.09982040458973E-7,-0.0151551279166204,0.000115078303148355,0.000744879181948953,1.09967698456453E-7,0.00074487915589163,6.88935918920545E-8,-1.97025666622659E-7,8.57121210799295E-8,1.00013042013902,10.005763053894,2,20,10,5,2.43699596476286,0.214139465745977,0.0404026173055172,172.741912841797,48.9997253417969,49.0006294250488,339.74365234375,339.74365234375,,,8.51898574829102,0,1,,,,,,1,1,1,49.0004005432129,0,49.0001481000115,,,,,,,,,,,,,,,,,,,,,,,,,,,,,,,,,
,3755381541.01174,49.0003414154053,339.74365234375,,,5,,,,-2.43000010959804,,,,,0.000745069446825827,8.1012297177289E-8,-0.0161203066942797,7.86528873077644E-5,0.000744972290622664,8.10017332664525E-8,0.000744972261136963,5.5935328751535E-8,-2.09599760177725E-7,5.8587710226866E-8,1.00013041586162,10.005763053894,2,20,10,5,2.43730418227487,0.214125173734813,0.0404026173055172,172.741912841797,48.9997100830078,49.001106262207,339.74365234375,339.74365234375,,,8.52070236206055,0,1,,,,,,1,1,1,49.0005111694336,0,49.0002304525936,,,,,,,,,,,,,,,,,,,,,,,,,,,,,,,,,
,3755381745.96887,48.999361038208,339.74365234375,,,5,,,,-2.43000010959804,,,,,0.000744925826386662,8.66966866371585E-8,-0.0106293449730073,6.69913109195379E-5,0.000744828636878674,8.66853754327138E-8,0.000744828624061446,7.08926497569018E-8,-1.38178423420133E-7,4.98857346779197E-8,1.00013048572944,10.005763053894,2,20,10,5,2.43681383600755,0.214317440723427,0.0404026173055172,172.741912841797,48.9983940124512,49.0000991821289,339.74365234375,339.74365234375,,,8.52254199981689,0,1,,,,,,1,1,1,48.9986610412598,0,48.9993813832601,,,,,,,,,,,,,,,,,,,,,,,,,,,,,,,,,
,3755381950.85852,49.0009059906006,339.74365234375,,,5,,,,-2.43000010959804,,,,,0.000745170002861363,1.50509937225085E-7,-0.00944419891598436,8.56191513545728E-5,0.000745072814296394,1.50490307013514E-7,0.000745072804174689,1.36315518726167E-7,-1.22812114488065E-7,6.37605823329564E-8,1.0001304417006,10.005763053894,2,20,10,5,2.43760815586506,0.214438103913663,0.0404026173055172,172.741912841797,48.9997100830078,49.0015907287598,339.74365234375,339.74365234375,,,8.52201557159424,0,1,,,,,,1,1,1,49.0005760192871,0,49.000306297751,,,,,,,,,,,,,,,,,,,,,,,,,,,,,,,,,
,3755382155.78717,49.0013160705566,339.74365234375,,,5,,,,-2.43000010959804,,,,,0.000745424040517688,9.43573997947012E-8,-0.0174292753116783,7.38143664315471E-5,0.000745326804833333,9.43450914898381E-8,0.000745326770348341,7.66518803739889E-8,-2.26727099075388E-7,5.50044136716103E-8,1.00013046046878,10.005763053894,2,20,10,5,2.43846903873665,0.214171368021208,0.0404026173055172,172.741912841797,48.9998664855957,49.0016326904297,339.74365234375,339.74365234375,,,8.52312278747559,0,1,,,,,,1,1,1,49.0013084411621,0,49.0006743038402,,,,,,,,,,,,,,,,,,,,,,,,,,,,,,,,,
,3755382360.8053,49.0007572174072,339.74365234375,,,5,,,,-2.43000010959804,,,,,0.000745008086820709,9.40191243905348E-8,-0.01513831025727,8.45844929964435E-5,0.000744910924444967,9.40068626155923E-8,0.000744910898444336,6.97740506722523E-8,-1.96815413856112E-7,6.29989846871584E-8,1.00013043489168,10.005763053894,2,20,10,5,2.43709978881429,0.21414930840165,0.0404026173055172,172.741912841797,48.9998321533203,49.0009307861328,339.74365234375,339.74365234375,,,8.52457237243652,0,1,,,,,,1,1,1,49.0006866455078,0,49.0002820632037,,,,,,,,,,,,,,,,,,,,,,,,,,,,,,,,,
,3755382565.81943,48.9994850158691,339.74365234375,,,5,,,,-2.43000010959804,,,,,0.000745840365689467,1.10310594130157E-7,-0.0163189316110754,8.64051366530716E-5,0.000745743052631852,1.10296201424028E-7,0.000745743022383801,8.95264150277109E-8,-2.12401852531154E-7,6.44226129620329E-8,1.00013049140354,10.005763053894,2,20,10,5,2.43982678891364,0.214338273653661,0.0404026173055172,172.741912841797,48.9993591308594,49.0000381469727,339.74365234375,339.74365234375,,,8.52596092224121,0,1,,,,,,1,1,1,48.9996109008789,0,48.9997004340677,,,,,,,,,,,,,,,,,,,,,,,,,,,,,,,,,
,3755382770.91489,49.0005664825439,339.74365234375,,,5,,,,-2.43000010959804,,,,,0.000745349682434718,1.61987288094862E-7,-0.0155594656756914,7.78206000070009E-5,0.000745252482013549,1.61966163469739E-7,0.000745252454533499,1.51241770996951E-7,-2.02383672403673E-7,5.79565769763191E-8,1.00013042616229,10.005763053894,2,20,10,5,2.43821880453938,0.214229577090143,0.0404026173055172,172.741912841797,48.998893737793,49.0007629394531,339.74365234375,339.74365234375,,,8.52629661560059,0,1,,,,,,1,1,1,49.0005111694336,0,48.9998667099897,,,,,,,,,,,,,,,,,,,,,,,,,,,,,,,,,
,3755382975.89062,49.0010738372803,339.74365234375,,,5,,,,-2.43000010959804,,,,,0.000745416271574477,1.1347889522159E-7,-0.015478850513241,0.000114159199811443,0.000745319045165298,1.13464093900609E-7,0.000745319017966835,7.50737080965154E-8,-2.01353084686061E-7,8.50766651751544E-8,1.00013044938246,10.005763053894,2,20,10,5,2.43843633240877,0.214252145307591,0.0404026173055172,172.741912841797,48.999626159668,49.001407623291,339.74365234375,339.74365234375,,,8.52794647216797,0,1,,,,,,1,1,1,49.0009269714355,0,49.0005011558533,,,,,,,,,,,,,,,,,,,,,,,,,,,,,,,,,
,3755383180.85891,49.0000076293945,339.74365234375,,,5,,,,-2.43000010959804,,,,,0.000745365488923412,1.45212111557073E-7,-0.0160845042676243,0.00014046982566826,0.000745268220001659,1.45193161624823E-7,0.000745268190635124,1.00618099935625E-7,-2.09217324723816E-7,1.04675938724984E-7,1.00013051532206,10.005763053894,2,20,10,5,2.43827247441265,0.214211777111107,0.0404026173055172,172.741912841797,48.9995880126953,49.0005722045898,339.74365234375,339.74365234375,,,8.52935218811035,0,1,,,,,,1,1,1,49.0004272460937,0,48.9999618530273,,,,,,,,,,,,,,,,,,,,,,,,,,,,,,,,,
,3755383385.94422,49.0015716552734,339.74365234375,,,5,,,,-2.43000010959804,,,,,0.000745362734975316,7.7938108184396E-8,-0.0160540923229071,6.79414032541263E-5,0.000745265498571353,7.7927940757161E-8,0.00074526546931587,5.92428683930374E-8,-2.08820982352693E-7,5.06265394355257E-8,1.00013047216616,10.005763053894,2,20,10,5,2.4382633524689,0.214212273231434,0.0404026173055172,172.741912841797,49.0000915527344,49.0019683837891,339.74365234375,339.74365234375,,,8.53039073944092,0,1,,,,,,1,1,1,49.0019416809082,0,49.0008634679458,,,,,,,,,,,,,,,,,,,,,,,,,,,,,,,,,
,3755383590.89608,49.0004119873047,339.74365234375,,,5,,,,-2.43000010959804,,,,,0.000745657791609785,1.0345121310191E-7,-0.0178866035014424,9.94844997213559E-5,0.000745560556279383,1.0343772284807E-7,0.000745560519949549,7.21053163474916E-8,-2.32749182456511E-7,7.41632379445663E-8,1.00013041909149,10.005763053894,2,20,10,5,2.4392354068492,0.21421906182492,0.0404026173055172,172.741912841797,48.9990730285645,49.000545501709,339.74365234375,339.74365234375,,,8.53060245513916,0,1,,,,,,1,1,1,49.000545501709,0,48.9998200360466,,,,,,,,,,,,,,,,,,,,,,,,,,,,,,,,,
,3755383795.8613,49.0009117126465,339.74365234375,,,5,,,,-2.43000010959804,,,,,0.000745550423952811,1.42103881239756E-7,-0.00940242176912864,9.93802456042747E-5,0.000745453185576345,1.42085347348207E-7,0.000745453175538868,1.21256721569456E-7,-1.22331265723858E-7,7.40611463946394E-8,1.00013044196248,10.005763053894,2,20,10,5,2.43885243708688,0.214549355365047,0.0404026173055172,172.741912841797,48.9997711181641,49.0010452270508,339.74365234375,339.74365234375,,,8.53164863586426,0,1,,,,,,1,1,1,49.0007781982422,0,49.0003514009364,,,,,,,,,,,,,,,,,,,,,,,,,,,,,,,,,
,3755384000.78256,49.0001888275146,339.74365234375,,,5,,,,-2.43000010959804,,,,,0.000745274298445846,9.1817066605039E-8,-0.0120603236907737,0.000100164268163226,0.000745177035245408,9.18050838736186E-8,0.000745177018737116,5.34584802424469E-8,-1.5685406956674E-7,7.46348733181082E-8,1.00013052361498,10.005763053894,2,20,10,5,2.43795911866981,0.214356801361266,0.0404026173055172,172.741912841797,48.9994773864746,49.0003547668457,339.74365234375,339.74365234375,,,8.53225040435791,0,1,,,,,,1,1,1,49.000301361084,0,49.0001043431899,,,,,,,,,,,,,,,,,,,,,,,,,,,,,,,,,
,3755384205.73358,48.9999103546143,339.74365234375,,,5,,,,-2.43000010959804,,,,,0.000745736687228876,1.24128211551979E-7,-0.0155948633365881,9.63564546299449E-5,0.000745639373185523,1.241120135851E-7,0.000745639345565965,1.0121260860748E-7,-2.02949398340553E-7,7.18317462896255E-8,1.00013051087007,10.005763053894,2,20,10,5,2.43948492295506,0.214339305090395,0.0404026173055172,172.741912841797,48.9990119934082,49.0002593994141,339.74365234375,339.74365234375,,,8.53335952758789,0,1,,,,,,1,1,1,49.0001449584961,0,48.9996936321259,,,,,,,,,,,,,,,,,,,,,,,,,,,,,,,,,
,3755384410.683,48.9998760223389,339.74365234375,,,5,,,,-2.43000010959804,,,,,0.000745685438106809,9.58267850330253E-8,-0.0160314406176951,8.6835365129063E-5,0.000745588131922532,9.58142803784799E-8,0.000745588102736919,7.06386701317007E-8,-2.08616617276019E-7,6.47344931738152E-8,1.00013050929878,10.005763053894,2,20,10,5,2.43931890765974,0.214305988775748,0.0404026173055172,172.741912841797,48.9992828369141,49.0003929138184,339.74365234375,339.74365234375,,,8.53409385681152,0,1,,,,,,1,1,1,49.0000114440918,0,48.9997854793773,,,,,,,,,,,,,,,,,,,,,,,,,,,,,,,,,
,3755384615.62155,49.0007801055908,339.74365234375,,,5,,,,-2.43000010959804,,,,,0.000745754850465774,9.86183401658752E-8,-0.0204246135385056,7.7554283909629E-5,0.000745657589917706,9.86054784676803E-8,0.000745657542540235,7.98760832126366E-8,-2.65809592137405E-7,5.78173997551612E-8,1.00013043593921,10.005763053894,2,20,10,5,2.43956239898406,0.214138881317713,0.0404026173055172,172.741912841797,48.9994659423828,49.0010833740234,339.74365234375,339.74365234375,,,8.53506374359131,0,1,,,,,,1,1,1,49.0005989074707,0,49.0002085367839,,,,,,,,,,,,,,,,,,,,,,,,,,,,,,,,,
,3755384769.38032,48.9985198974609,339.74365234375,,,5,,,,-2.43000010959804,,,,,0.000745682710112409,7.55645029501934E-8,-0.0179434770065532,7.49480505111383E-5,0.000745585450553541,7.55546470555571E-8,0.000745585413991084,5.08582065917016E-8,-2.33497044344907E-7,5.58743905019607E-8,1.00013044723284,10.005763053894,2,20,10,5,2.43931713345229,0.214223807916713,0.0404026173055172,172.741912841797,48.9983367919922,49.0013427734375,339.74365234375,339.74365234375,,,8.53315258026123,0,1,,,,,,1,1,1,48.9985733032227,0,48.9996638827854,,,,,,,,,,,,,,,,,,,,,,,,,,,,,,,,,