File: Experimental_Data/Fig3B/Lifetime_220Oe.dat
[Header]
; MPMS3 Data File (default extension .dat)
; Copyright (c) 2007, Quantum Design, Inc. All rights reserved.
TITLE,220Oe
FILEOPENTIME,3754594576.48073,12/21/2018,10:55 pm
BYAPP,SQUID AC,0.9.1.0
INFO,MPMS3 Measurement Release 1.1.16 Build 347, MultiVu Release 2.3.3.2,APPNAME
INFO,0,MOMENT_UNITS
INFO,CoIINO3,SAMPLE_MATERIAL
INFO,40 Hours Pumped Turbo,SAMPLE_COMMENT
INFO,,SAMPLE_MASS
INFO,,SAMPLE_VOLUME
INFO,,SAMPLE_MOLECULAR_WEIGHT
INFO,,SAMPLE_SIZE
INFO,,SAMPLE_SHAPE
INFO,Brass,SAMPLE_HOLDER
INFO,Standard,SAMPLE_HOLDER_DETAIL
INFO,65.37,SAMPLE_OFFSET
DATATYPE,COMMENT,1
DATATYPE,TIME,2
STARTUPAXIS,X,2
STARTUPAXIS,Y1,5
FIELDGROUP, VSM,2,3,4,5,6,8,9,10,11,14,15
FIELDGROUP, DC, 2,3,4,14,56,57,58,59,60,61,62,63,64,65,66,67,68,69
FIELDGROUP, AC, 2,3,4,11,16,17,18,19,20,21,22,23,24,25,26,27,28,29,30
STARTUPGROUP, All
[Data]
Comment,Time Stamp (sec),Temperature (K),Magnetic Field (Oe),Moment (emu),M. Std. Err. (emu),Transport Action,Averaging Time (sec),Frequency (Hz),Peak Amplitude (mm),Center Position (mm),Lockin Signal' (V),Lockin Signal (V),Range,M. Quad. Signal (emu),AC Moment (emu),AC M. Std Err. (emu),AC Phase (deg),AC Phase Std. Err. (deg),AC Susceptibility (emu/Oe),AC Suscept. Std Err. (emu/Oe),AC X' (emu/Oe),AC X' Std Err. (emu/Oe),AC X'' (emu/Oe),AC X'' Std Err. (emu/Oe),AC Drive (Oe),AC Frequency (Hz),AC Averaging Time (sec),AC Cycles,AC Range,AC Measure Type,AC Signal' (V),AC Signal'' (V),AC Trim Coil Ratio,AC Trim Coil Phase,Min. Temperature (K),Max. Temperature (K),Min. Field (Oe),Max. Field (Oe),Mass (grams),Motor Lag (deg),Pressure (Torr),Measure Count,Measurement Number,SQUID Status (code),Motor Status (code),Measure Status (code),Motor Current (amps),Motor Temp. (C),Temp. Status (code),Field Status (code),Chamber Status (code),Chamber Temp (K),Redirection State,Average Temp (K),Rotation Angle (deg),Rotator state,DC Moment Fixed Ctr (emu),DC Moment Err Fixed Ctr (emu),DC Moment Free Ctr (emu),DC Moment Err Free Ctr (emu),DC Fixed Fit,DC Free Fit,DC Calculated Center (mm),DC Calculated Center Err (mm),DC Scan Length (mm),DC Scan Time (s),DC Number of Points,DC Squid Drift,DC Min V (V),DC Max V (V),DC Scans per Measure,Map 01,Map 02,Map 03,Map 04,Map 05,Map 06,Map 07,Map 08,Map 09,Map 10,Map 11,Map 12,Map 13,Map 14,Map 15,Map 16
,3754594580.30762,48.9861106872559,219.675567626953,,,5,,,,-2.43000010959804,,,,,0.000654863458383745,1.02248329184859E-7,0.0378575276797637,0.000114001227554031,0.000654778341104705,1.02235039239519E-7,0.000654778198174662,6.98654196646643E-8,4.32637230516461E-7,7.46379687785406E-8,1.00012999403569,10.005763053894,2,20,10,5,2.1420573579897,0.189943806220472,0.0404026173055172,172.741912841797,48.91943359375,48.996452331543,219.675567626953,219.675567626953,,,734.142700195313,0,1,,,,,,1,1,1,48.9804725646973,0,48.9542447258444,,,,,,,,,,,,,,,,,,,,,,,,,,,,,,,,,
,3754594791.90273,48.9985103607178,219.675567626953,,,5,,,,-2.43000010959804,,,,,0.000657202096268823,7.71397654999272E-8,0.00248356672927841,8.43162590532723E-5,0.000657116377542532,7.71297041771125E-8,0.0006571163769252,5.36647432891589E-8,2.84836402591379E-8,5.53993374884354E-8,1.00013044679637,10.005763053894,2,20,10,5,2.14982432406961,0.189294812078328,0.0404026173055172,172.741912841797,48.9979972839355,48.9994583129883,219.675567626953,219.675567626953,,,740.112548828125,0,1,,,,,,1,1,1,48.9986305236816,0,48.9989493874943,,,,,,,,,,,,,,,,,,,,,,,,,,,,,,,,,
,3754595001.98003,48.9994411468506,219.675567626953,,,5,,,,-2.43000010959804,,,,,0.000658190835478585,8.44701853571746E-8,0.000909226575412703,0.000104411004688293,0.000658104959760028,8.4459164331853E-8,0.000658104959677164,4.91160850801006E-8,1.04434658867498E-8,6.87092470198828E-8,1.00013048939578,10.005763053894,2,20,10,5,2.15306387343324,0.189520437817535,0.0404026173055172,172.741912841797,48.9983139038086,49.0002555847168,219.675567626953,219.675567626953,,,743.756591796875,0,1,,,,,,1,1,1,48.9990425109863,0,48.9996481502757,,,,,,,,,,,,,,,,,,,,,,,,,,,,,,,,,
,3754595211.9224,48.9994430541992,219.675567626953,,,5,,,,-2.43000010959804,,,,,0.000659213083033944,8.91334816926044E-8,0.00325296749472592,5.65714743265764E-5,0.000659127073882794,8.91218522281767E-8,0.000659127072820479,8.09565930903408E-8,3.74219351460797E-8,3.72657292936278E-8,1.00013048948307,10.005763053894,2,20,10,5,2.15640006774685,0.189902995252153,0.0404026173055172,172.741912841797,48.9989280700684,48.999755859375,219.675567626953,219.675567626953,,,745.472900390625,0,1,,,,,,1,1,1,48.9990119934082,0,48.9993419647217,,,,,,,,,,,,,,,,,,,,,,,,,,,,,,,,,
,3754595421.96863,49.0013790130615,219.675567626953,,,5,,,,-2.43000010959804,,,,,0.000659820531544335,7.73510392617003E-8,0.00269502727793114,9.6072059491854E-5,0.000659734460376867,7.73409491024284E-8,0.00065973445964704,4.43259709495753E-8,3.10319953993336E-8,6.33784719557188E-8,1.00013046334948,10.005763053894,2,20,10,5,2.15838898860644,0.190056958994138,0.0404026173055172,172.741912841797,48.9999465942383,49.0017623901367,219.675567626953,219.675567626953,,,746.194274902344,0,1,,,,,,1,1,1,49.0013389587402,0,49.0008004132439,,,,,,,,,,,,,,,,,,,,,,,,,,,,,,,,,
,3754595629.82179,48.999475479126,219.675567626953,,,5,,,,-2.43000010959804,,,,,0.000660501683396478,6.38138530683232E-8,0.000367076949408407,8.12400998004244E-5,0.000660415505138546,6.38055270233977E-8,0.000660415505124992,3.453790322705E-8,4.23108492504686E-9,5.36495901141142E-8,1.00013049096707,10.005763053894,2,20,10,5,2.16062488373266,0.190165380545366,0.0404026173055172,172.741912841797,48.9992752075195,49.0003700256348,219.675567626953,219.675567626953,,,746.467895507812,0,1,,,,,,1,1,1,48.9994964599609,0,48.9997758304372,,,,,,,,,,,,,,,,,,,,,,,,,,,,,,,,,
,3754595840.01021,49.0010757446289,219.675567626953,,,5,,,,-2.43000010959804,,,,,0.000661122821640623,1.20292399424898E-7,0.000371505760803359,9.97887516375269E-5,0.000661036589767999,1.20276709391934E-7,0.000661036589754103,1.00586733438087E-7,4.28616039935061E-9,6.59454007373301E-8,1.00013044946976,10.005763053894,2,20,10,5,2.16265672926915,0.190344373732632,0.0404026173055172,172.741912841797,49,49.001277923584,219.675567626953,219.675567626953,,,746.530090332031,0,1,,,,,,1,1,1,49.0010986328125,0,49.0006018744575,,,,,,,,,,,,,,,,,,,,,,,,,,,,,,,,,
,3754596047.69744,48.9992790222168,219.675567626953,,,5,,,,-2.43000010959804,,,,,0.000661769117632473,1.08153830013755E-7,0.00336739661293883,6.55789395699438E-5,0.000661682779955993,1.08139719729462E-7,0.000661682778813212,9.90644336678164E-8,3.88885249440105E-8,4.33640054104957E-8,1.0001304819758,10.005763053894,2,20,10,5,2.16476091861682,0.190643647545746,0.0404026173055172,172.741912841797,48.9991111755371,49.0000915527344,219.675567626953,219.675567626953,,,746.554931640625,0,1,,,,,,1,1,1,48.9993934631348,0,48.9996154308319,,,,,,,,,,,,,,,,,,,,,,,,,,,,,,,,,
,3754596257.97324,48.9995937347412,219.675567626953,,,5,,,,-2.43000010959804,,,,,0.000662373868023592,4.87602877028805E-8,0.0019737590379334,5.18845157818491E-5,0.000662287441910375,4.87539254921277E-8,0.000662287441517405,3.45898132151983E-8,2.28148710957563E-8,3.43582606170574E-8,1.00013049637929,10.005763053894,2,20,10,5,2.16674380229791,0.190765160910748,0.0404026173055172,172.741912841797,48.9988441467285,49.0000305175781,219.675567626953,219.675567626953,,,746.492797851562,0,1,,,,,,1,1,1,48.9997406005859,0,48.9996593699736,,,,,,,,,,,,,,,,,,,,,,,,,,,,,,,,,
,3754596467.86376,49.0016460418701,219.675567626953,,,5,,,,-2.43000010959804,,,,,0.000662869652282127,7.04686383469541E-8,0.0018229874984419,7.90829792232244E-5,0.000662783175269136,7.04594451106477E-8,0.000662783174933658,4.70929512445266E-8,2.10878611436559E-8,5.24098020257758E-8,1.00013047557062,10.005763053894,2,20,10,5,2.16836610454509,0.190902235278321,0.0404026173055172,172.741912841797,48.9998931884766,49.0021553039551,219.675567626953,219.675567626953,,,746.443054199219,0,1,,,,,,1,1,1,49.0014495849609,0,49.0008685588837,,,,,,,,,,,,,,,,,,,,,,,,,,,,,,,,,
,3754596677.9859,48.9999008178711,219.675567626953,,,5,,,,-2.43000010959804,,,,,0.000663353876512564,9.58939777992895E-8,0.00618813153906927,0.00011765333520633,0.000663267313207924,9.58814642678136E-8,0.000663267309339514,5.57170281216687E-8,7.16350385071405E-8,7.80311986799459E-8,1.0001305104336,10.005763053894,2,20,10,5,2.16993552777715,0.191207013597054,0.0404026173055172,172.741912841797,48.9996109008789,49.0001754760742,219.675567626953,219.675567626953,,,746.368408203125,0,1,,,,,,1,1,1,49.0000953674316,0,48.9999532699585,,,,,,,,,,,,,,,,,,,,,,,,,,,,,,,,,
,3754596888.10777,48.999195098877,219.675567626953,,,5,,,,-2.43000010959804,,,,,0.000663616154383013,7.98756925782106E-8,0.00438168378023196,7.62677963415828E-5,0.00066352957828121,7.98652719064915E-8,0.000663529576340918,6.17935527424165E-8,5.07432975470937E-8,5.05966253436731E-8,1.00013047813487,10.005763053894,2,20,10,5,2.17079950979812,0.191214173390769,0.0404026173055172,172.741912841797,48.9985542297363,49.0026359558105,219.675567626953,219.675567626953,,,746.331115722656,0,1,,,,,,1,1,1,48.9995956420898,0,49.0005878872342,,,,,,,,,,,,,,,,,,,,,,,,,,,,,,,,,
,3754597097.43777,49.0000476837158,219.675567626953,,,5,,,,-2.43000010959804,,,,,0.000664003339638145,6.87771287916967E-8,0.00295380824852298,6.82083496160376E-5,0.000663916687120833,6.87681533679487E-8,0.00066391668623856,5.17591748807501E-8,3.42273480271458E-8,4.52774417707277E-8,1.00013051715523,10.005763053894,2,20,10,5,2.17207082526733,0.19127160290752,0.0404026173055172,172.741912841797,48.9992713928223,49.0007095336914,219.675567626953,219.675567626953,,,746.293762207031,0,1,,,,,,1,1,1,49.0005035400391,0,49.0003089904785,,,,,,,,,,,,,,,,,,,,,,,,,,,,,,,,,
,3754597307.25038,49.0006904602051,219.675567626953,,,5,,,,-2.43000010959804,,,,,0.000664344246655955,6.78422436738077E-8,0.00172649674309522,7.27171305405796E-5,0.000664257606316524,6.78333960393934E-8,0.00066425760601495,4.76313511923718E-8,2.00161094491487E-8,4.82972463172191E-8,1.0001304318364,10.005763053894,2,20,10,5,2.17319009037687,0.191323253066261,0.0404026173055172,172.741912841797,48.999626159668,49.0011825561523,219.675567626953,219.675567626953,,,746.281372070312,0,1,,,,,,1,1,1,49.0004653930664,0,49.000287161933,,,,,,,,,,,,,,,,,,,,,,,,,,,,,,,,,
,3754597515.94671,49.0010452270508,219.675567626953,,,5,,,,-2.43000010959804,,,,,0.000664782357366445,9.2164010785222E-8,-0.00102453688372428,7.44291607699417E-5,0.000664695649099852,9.21519897357329E-8,0.000664695648993584,7.77553076409714E-8,-1.18857831188433E-8,4.94580766499518E-8,1.00013044807305,10.005763053894,2,20,10,5,2.17463241979408,0.191345007107771,0.0404026173055172,172.741912841797,48.9999465942383,49.0014457702637,219.675567626953,219.675567626953,,,746.256469726563,0,1,,,,,,1,1,1,49.0011749267578,0,49.0006834665934,,,,,,,,,,,,,,,,,,,,,,,,,,,,,,,,,
,3754597725.21236,49.0002040863037,219.675567626953,,,5,,,,-2.43000010959804,,,,,0.00066502142778554,8.53130607356313E-8,0.000472041637229914,8.96754612886821E-5,0.000664934713931123,8.53019365462151E-8,0.000664934713908556,6.1006396710772E-8,5.47818484500824E-9,5.96208012266056E-8,1.00013040957646,10.005763053894,2,20,10,5,2.17540946471359,0.191470645885996,0.0404026173055172,172.741912841797,48.9996376037598,49.0006866455078,219.675567626953,219.675567626953,,,746.256469726563,0,1,,,,,,1,1,1,48.9999847412109,0,48.9999717263614,,,,,,,,,,,,,,,,,,,,,,,,,,,,,,,,,
,3754597934.02587,49.0012607574463,219.675567626953,,,5,,,,-2.43000010959804,,,,,0.000665358724612873,9.24320725682075E-8,0.00233131669926312,0.000107278469387706,0.000665271934608567,9.2420015643605E-8,0.000665271934057852,5.87255638034218E-8,2.70693510666338E-8,7.13636283237788E-8,1.00013045793726,10.005763053894,2,20,10,5,2.17650660840781,0.191638384641939,0.0404026173055172,172.741912841797,48.9999237060547,49.0018043518066,219.675567626953,219.675567626953,,,746.306213378906,0,1,,,,,,1,1,1,49.0008392333984,0,49.0005840974696,,,,,,,,,,,,,,,,,,,,,,,,,,,,,,,,,
,3754598142.7567,49.0005836486816,219.675567626953,,,5,,,,-2.43000010959804,,,,,0.000666228728698852,7.52565283645197E-8,0.000196627722113263,5.51140186488133E-5,0.000666141845851003,7.52467141652487E-8,0.000666141845847081,6.56902985966483E-8,2.28606635369788E-9,3.66994913173171E-8,1.00013042694794,10.005763053894,2,20,10,5,2.17935969389672,0.191807770934715,0.0404026173055172,172.741912841797,48.999870300293,49.0011253356934,219.675567626953,219.675567626953,,,746.331115722656,0,1,,,,,,1,1,1,49.0002136230469,0,49.0003300835105,,,,,,,,,,,,,,,,,,,,,,,,,,,,,,,,,
,3754598351.9512,48.9994125366211,219.675567626953,,,5,,,,-2.43000010959804,,,,,0.000666236346324934,6.86964142756895E-8,0.00413161273757989,8.43274529820588E-5,0.000666149421761652,6.86874513816011E-8,0.000666149420029701,3.95313188569482E-8,4.80361984265917E-8,5.61715302153156E-8,1.00013048808637,10.005763053894,2,20,10,5,2.17937143373304,0.191959645953246,0.0404026173055172,172.741912841797,48.9984397888184,49.0000877380371,219.675567626953,219.675567626953,,,746.343505859375,0,1,,,,,,1,1,1,48.998779296875,0,48.999298993279,,,,,,,,,,,,,,,,,,,,,,,,,,,,,,,,,
,3754598561.78982,48.9991016387939,219.675567626953,,,5,,,,-2.43000010959804,,,,,0.000666430889046383,1.32121427320072E-7,-0.000134222108481019,0.000113493378537813,0.000666343948581011,1.32104191176662E-7,0.000666343948579182,1.08328747304548E-7,-1.56098914286711E-9,7.56068768953419E-8,1.00013047385747,10.005763053894,2,20,10,5,2.18002210599166,0.191853388799705,0.0404026173055172,172.741912841797,48.9988212585449,49.0001449584961,219.675567626953,219.675567626953,,,746.343505859375,0,1,,,,,,1,1,1,48.9991645812988,0,48.9994982551126,,,,,,,,,,,,,,,,,,,,,,,,,,,,,,,,,
,3754598770.51247,48.9999465942383,219.675567626953,,,5,,,,-2.43000010959804,,,,,0.000666790793084857,1.12551312072788E-7,-0.000829214983443016,6.81251268236096E-5,0.00066670377988868,1.12536624633341E-7,0.000666703779818858,1.02976346135021E-7,-9.64889156724466E-9,4.53912328599458E-8,1.00013051252865,10.005763053894,2,20,10,5,2.18120174909393,0.191930537271137,0.0404026173055172,172.741912841797,48.9995307922363,49.0002975463867,219.675567626953,219.675567626953,,,746.393249511719,0,1,,,,,,1,1,1,49.0000877380371,0,48.9999194425695,,,,,,,,,,,,,,,,,,,,,,,,,,,,,,,,,
,3754598980.67345,48.9994411468506,219.675567626953,,,5,,,,-2.43000010959804,,,,,0.000666952617653985,1.17454676824827E-7,0.00535749479376602,9.56342075375503E-5,0.000666865598764938,1.17439352234713E-7,0.000666865595849615,9.86265076974055E-8,6.23558837785386E-8,6.37558893963738E-8,1.00013048939578,10.005763053894,2,20,10,5,2.18171036610741,0.192212700093212,0.0404026173055172,172.741912841797,48.9987335205078,48.9999923706055,219.675567626953,219.675567626953,,,746.380859375,0,1,,,,,,1,1,1,48.9990539550781,0,48.999361038208,,,,,,,,,,,,,,,,,,,,,,,,,,,,,,,,,
,3754599189.87676,49.0005798339844,219.675567626953,,,5,,,,-2.43000010959804,,,,,0.000667266777411512,9.88536894885604E-8,0.00422544748255049,9.41317970429271E-5,0.00066717975930826,9.88407980022015E-8,0.000667179757493944,7.63331156756069E-8,4.92031534570292E-8,6.27913911373718E-8,1.00013042677335,10.005763053894,2,20,10,5,2.18274183320673,0.192260108564385,0.0404026173055172,172.741912841797,48.9997367858887,49.0012741088867,219.675567626953,219.675567626953,,,746.368408203125,0,1,,,,,,1,1,1,49.0001945495605,0,49.0002383063821,,,,,,,,,,,,,,,,,,,,,,,,,,,,,,,,,
,3754599398.60099,48.9999885559082,219.675567626953,,,5,,,,-2.43000010959804,,,,,0.000667553559624988,8.72784830474884E-8,0.00467169321067651,7.93337656710573E-5,0.000667466445609533,8.72670934308631E-8,0.000667466443390812,6.93740696436372E-8,5.44228298376043E-8,5.29413265507275E-8,1.00013051444912,10.005763053894,2,20,10,5,2.18367844788042,0.192359747411803,0.0404026173055172,172.741912841797,48.9994583129883,49.0001411437988,219.675567626953,219.675567626953,,,746.405700683594,0,1,,,,,,1,1,1,49.0000495910645,0,48.9997926599839,,,,,,,,,,,,,,,,,,,,,,,,,,,,,,,,,
,3754599609.56927,49.0003604888916,219.675567626953,,,5,,,,-2.43000010959804,,,,,0.000668028275417374,6.36532960722786E-8,-0.00141366594568915,7.66123934957986E-5,0.000667941088084321,6.36449883982942E-8,0.000667941087881012,3.78470702257212E-8,-1.64801941413496E-8,5.1169168681427E-8,1.00013053147143,10.005763053894,2,20,10,5,2.18525175484681,0.192264443961293,0.0404026173055172,172.741912841797,48.9992904663086,49.0008239746094,219.675567626953,219.675567626953,,,746.405700683594,0,1,,,,,,1,1,1,49.0006256103516,0,48.9999959609088,,,,,,,,,,,,,,,,,,,,,,,,,,,,,,,,,
,3754599819.66552,49.0017929077148,219.675567626953,,,5,,,,-2.43000010959804,,,,,0.000667882076289018,6.42962801788432E-8,0.000223738690012354,6.79682553342623E-5,0.000667794940874381,6.42878917473642E-8,0.000667794940869289,4.55333312476174E-8,2.60772375448032E-9,4.53833534549351E-8,1.00013048229225,10.005763053894,2,20,10,5,2.18476801476526,0.192284800516532,0.0404026173055172,172.741912841797,49.0002250671387,49.0022850036621,219.675567626953,219.675567626953,,,746.418151855469,0,1,,,,,,1,1,1,49.0013008117676,0,49.0010196461397,,,,,,,,,,,,,,,,,,,,,,,,,,,,,,,,,
,3754600029.8136,49.0004844665527,219.675567626953,,,5,,,,-2.43000010959804,,,,,0.000668206060020485,5.97941948286451E-8,0.00537160611025289,6.75542366590059E-5,0.000668118922341363,5.97863973426987E-8,0.000668118919405155,3.9213190516525E-8,6.26376272539867E-8,4.51302448113653E-8,1.00013042240866,10.005763053894,2,20,10,5,2.18581053293895,0.192574467641252,0.0404026173055172,172.741912841797,48.9997177124023,49.0010528564453,219.675567626953,219.675567626953,,,746.430603027344,0,1,,,,,,1,1,1,49.0008811950684,0,49.0002169889562,,,,,,,,,,,,,,,,,,,,,,,,,,,,,,,,,
,3754600239.91258,49.0004043579102,219.675567626953,,,5,,,,-2.43000010959804,,,,,0.000668418339394458,8.06107242753652E-8,0.00552557817223853,7.27441279109695E-5,0.00066833117648297,8.0600212497021E-8,0.000668331173375035,6.42946270866318E-8,6.44535459026824E-8,4.86065343586219E-8,1.00013041874232,10.005763053894,2,20,10,5,2.18650441528225,0.192641524703826,0.0404026173055172,172.741912841797,48.999755859375,49.0007209777832,219.675567626953,219.675567626953,,,746.455444335938,0,1,,,,,,1,1,1,49.0000877380371,0,49.0002984439625,,,,,,,,,,,,,,,,,,,,,,,,,,,,,,,,,
,3754600451.0035,48.9994983673096,219.675567626953,,,5,,,,-2.43000010959804,,,,,0.000668783796255424,7.21070134470294E-8,0.00289275466846028,7.24843973580235E-5,0.00066869661341134,7.2097613556443E-8,0.00066869661255907,5.33798794693437E-8,3.37612170712462E-8,4.84629172499194E-8,1.00013037727773,10.005763053894,2,20,10,5,2.18770873801997,0.192646327536535,0.0404026173055172,172.741912841797,48.998649597168,49.0003776550293,219.675567626953,219.675567626953,,,746.492797851562,0,1,,,,,,1,1,1,48.9989433288574,0,48.9996122472426,,,,,,,,,,,,,,,,,,,,,,,,,,,,,,,,,
,3754600662.81394,48.9998168945313,219.675567626953,,,5,,,,-2.43000010959804,,,,,0.000668956968169336,6.31504162758778E-8,0.0040017312229601,6.12535730630092E-5,0.00066886975300095,6.31421830494504E-8,0.000668869751369544,4.80510886111115E-8,4.67161280507617E-8,4.0963742059746E-8,1.00013039185581,10.005763053894,2,20,10,5,2.188271483805,0.192738562124782,0.0404026173055172,172.741912841797,48.9996910095215,49.0002822875977,219.675567626953,219.675567626953,,,746.542541503906,0,1,,,,,,1,1,1,48.9997253417969,0,49.0000069562127,,,,,,,,,,,,,,,,,,,,,,,,,,,,,,,,,
,3754600871.80481,49.0002861022949,219.675567626953,,,5,,,,-2.43000010959804,,,,,0.00066923721586522,7.01234870341506E-8,0.00494026524383973,7.48907115485896E-5,0.000669149873025785,7.01143351455176E-8,0.000669149870538367,4.90436142120553E-8,5.76967079360195E-8,5.01073237952004E-8,1.00013052806696,10.005763053894,2,20,10,5,2.18918506295044,0.19285516359428,0.0404026173055172,172.741912841797,48.9997749328613,49.0008850097656,219.675567626953,219.675567626953,,,746.629577636719,0,1,,,,,,1,1,1,49.0004730224609,0,49.0002417564392,,,,,,,,,,,,,,,,,,,,,,,,,,,,,,,,,
,3754601080.4907,49.0003528594971,219.675567626953,,,5,,,,-2.43000010959804,,,,,0.000669340457210754,6.63358036650454E-8,-0.0017913528097413,6.81554397065663E-5,0.000669253175630683,6.6327153517431E-8,0.000669253175303586,4.81589062771242E-8,-2.09242036077938E-8,4.56071380368911E-8,1.00013041638538,10.005763053894,2,20,10,5,2.18954542905452,0.192627669436018,0.0404026173055172,172.741912841797,48.9991073608398,49.0004577636719,219.675567626953,219.675567626953,,,746.654479980469,0,1,,,,,,1,1,1,49.0003280639648,0,48.999932607015,,,,,,,,,,,,,,,,,,,,,,,,,,,,,,,,,
,3754601290.64114,49.0011138916016,219.675567626953,,,5,,,,-2.43000010959804,,,,,0.000669529174719385,5.88150768082227E-8,0.00507691116826958,5.47283097887623E-5,0.000669441845216881,5.88074053107117E-8,0.000669441842588812,4.60058248067462E-8,5.93184490188333E-8,3.66302471084935E-8,1.00013045121563,10.005763053894,2,20,10,5,2.19013964844729,0.1929445190304,0.0404026173055172,172.741912841797,48.9997901916504,49.0016860961914,219.675567626953,219.675567626953,,,746.716613769531,0,1,,,,,,1,1,1,49.0010147094727,0,49.0005078035242,,,,,,,,,,,,,,,,,,,,,,,,,,,,,,,,,
,3754601500.73719,48.9996929168701,219.675567626953,,,5,,,,-2.43000010959804,,,,,0.000669685808803723,8.33425366857473E-8,0.00391500354927121,8.23030711077154E-5,0.00066959842559411,8.3331661827333E-8,0.00066959842403095,6.25140753074964E-8,4.57534609534175E-8,5.51013271287875E-8,1.00013050091857,10.005763053894,2,20,10,5,2.19065593699905,0.192945237841727,0.0404026173055172,172.741912841797,48.9987258911133,48.9999504089355,219.675567626953,219.675567626953,,,746.741516113281,0,1,,,,,,1,1,1,48.9998397827148,0,48.9995305803087,,,,,,,,,,,,,,,,,,,,,,,,,,,,,,,,,
,3754601709.927,48.9996929168701,219.675567626953,,,5,,,,-2.43000010959804,,,,,0.000670308966868445,1.21285979263689E-7,-0.00130229780729696,0.000153886194676985,0.000670221502346744,1.21270153397276E-7,0.000670221502173618,6.37967894544731E-8,-1.52337222785317E-8,1.03133019738105E-7,1.00013050091857,10.005763053894,2,20,10,5,2.19271196949622,0.192925111918868,0.0404026173055172,172.741912841797,48.9992942810059,49.0003242492676,219.675567626953,219.675567626953,,,746.77880859375,0,1,,,,,,1,1,1,48.9999313354492,0,48.9997686498305,,,,,,,,,,,,,,,,,,,,,,,,,,,,,,,,,
,3754601918.58691,48.9998435974121,219.675567626953,,,5,,,,-2.43000010959804,,,,,0.000670378952248002,1.0714293694258E-7,0.00555480954181942,0.000128399823545945,0.000670291473972464,1.07128955776662E-7,0.000670291470822347,6.37988815721886E-8,6.49845678203842E-8,8.6059955123947E-8,1.00013050781479,10.005763053894,2,20,10,5,2.19291779823369,0.193207701837552,0.0404026173055172,172.741912841797,48.9992713928223,49.0002975463867,219.675567626953,219.675567626953,,,746.816162109375,0,1,,,,,,1,1,1,49.0001220703125,0,48.9997327467974,,,,,,,,,,,,,,,,,,,,,,,,,,,,,,,,,
,3754602126.44047,49.0012588500977,219.675567626953,,,5,,,,-2.43000010959804,,,,,0.000670645059583865,1.02615208180508E-7,0.000544328963836271,0.000116759802441664,0.000670557580083689,1.02601822967281E-7,0.000670557580053427,6.63190073620224E-8,6.37052006021979E-9,7.82874404915971E-8,1.00013045784997,10.005763053894,2,20,10,5,2.19380517291334,0.193092545096103,0.0404026173055172,172.741912841797,48.9995651245117,49.0014457702637,219.675567626953,219.675567626953,,,746.841003417969,0,1,,,,,,1,1,1,49.0012626647949,0,49.0004543977625,,,,,,,,,,,,,,,,,,,,,,,,,,,,,,,,,
,3754602336.26349,49.0007266998291,219.675567626953,,,5,,,,-2.43000010959804,,,,,0.000671111685769752,6.50785546873668E-8,0.0039051965529433,6.80508202709442E-5,0.00067102416174312,6.50700673710611E-8,0.00067102416018447,4.63622305394239E-8,4.57360256483398E-8,4.56580469039549E-8,1.00013043349498,10.005763053894,2,20,10,5,2.19532025574734,0.193355674737527,0.0404026173055172,172.741912841797,48.9994201660156,49.0014762878418,219.675567626953,219.675567626953,,,746.890747070312,0,1,,,,,,1,1,1,49.000129699707,0,49.0001648796929,,,,,,,,,,,,,,,,,,,,,,,,,,,,,,,,,
,3754602545.08831,49.0002479553223,219.675567626953,,,5,,,,-2.43000010959804,,,,,0.000671268279425819,6.17502948233163E-8,0.00279322385858993,6.12497030054054E-5,0.000671180749680957,6.1742242919604E-8,0.000671180748883374,4.60719070191896E-8,3.27207012213605E-8,4.11033325213241E-8,1.00013041158422,10.005763053894,2,20,10,5,2.19583625320654,0.193358175517766,0.0404026173055172,172.741912841797,48.999584197998,49.0005874633789,219.675567626953,219.675567626953,,,746.890747070312,0,1,,,,,,1,1,1,49.0001220703125,0,48.999932681813,,,,,,,,,,,,,,,,,,,,,,,,,,,,,,,,,
,3754602754.94819,49.0001773834229,219.675567626953,,,5,,,,-2.43000010959804,,,,,0.000671440278320592,1.15752561831574E-7,0.00164483271686144,0.00015353753352397,0.00067135265129725,1.15737455421123E-7,0.000671352651020608,5.26377531982689E-8,1.92730217589862E-8,1.03074853992594E-7,1.00013052309121,10.005763053894,2,20,10,5,2.19640276790856,0.19336369575532,0.0404026173055172,172.741912841797,48.999153137207,49.0003662109375,219.675567626953,219.675567626953,,,746.940490722656,0,1,,,,,,1,1,1,49.0003662109375,0,48.9997987747192,,,,,,,,,,,,,,,,,,,,,,,,,,,,,,,,,
,3754602965.12598,49.0009956359863,219.675567626953,,,5,,,,-2.43000010959804,,,,,0.000671382035481849,9.25302885055152E-8,0.00238454888431772,7.60819029694031E-5,0.000671294467935652,9.2518219891991E-8,0.000671294467354285,7.71530982362018E-8,2.79380870232688E-8,5.10589898503466E-8,1.00013044580341,10.005763053894,2,20,10,5,2.19620974883747,0.193375274821968,0.0404026173055172,172.741912841797,48.9999351501465,49.0014724731445,219.675567626953,219.675567626953,,,746.8037109375,0,1,,,,,,1,1,1,49.0009002685547,0,49.0007290559657,,,,,,,,,,,,,,,,,,,,,,,,,,,,,,,,,
,3754603174.39817,49.0008716583252,219.675567626953,,,5,,,,-2.43000010959804,,,,,0.000671631426348165,7.98250727065022E-8,0.00971274648458298,7.17049567623816E-5,0.00067154383008413,7.98146616717128E-8,0.00067154382043511,6.36608684656091E-8,1.13839710343137E-7,4.81422272435997E-8,1.00013044012931,10.005763053894,2,20,10,5,2.1970007905599,0.193728105962281,0.0404026173055172,172.741912841797,48.9998588562012,49.0009994506836,219.675567626953,219.675567626953,,,746.915649414062,0,1,,,,,,1,1,1,49.0010032653809,0,49.0004633735208,,,,,,,,,,,,,,,,,,,,,,,,,,,,,,,,,
,3754603384.39905,49.0007514953613,219.675567626953,,,5,,,,-2.43000010959804,,,,,0.000671748339155483,1.09491666405651E-7,0.00336303981977526,7.6406026349684E-5,0.000671660731336641,1.09477386763237E-7,0.000671660730179626,9.67161207795853E-8,3.94238773390231E-8,5.12961031059482E-8,1.0001304346298,10.005763053894,2,20,10,5,2.1974046886132,0.193518306345496,0.0404026173055172,172.741912841797,48.999584197998,49.0011787414551,219.675567626953,219.675567626953,,,746.965393066406,0,1,,,,,,1,1,1,49.0010032653809,0,49.0004086213953,,,,,,,,,,,,,,,,,,,,,,,,,,,,,,,,,
,3754603594.29609,49.000602722168,219.675567626953,,,5,,,,-2.43000010959804,,,,,0.000671858150309707,8.54654595620723E-8,0.000352145491175015,6.8722512470592E-5,0.000671770532742991,8.54543139421203E-8,0.000671770532730304,7.19195237639236E-8,4.12876770712543E-9,4.6152160002419E-8,1.00013042782088,10.005763053894,2,20,10,5,2.19777406773994,0.193434449433501,0.0404026173055172,172.741912841797,48.9994583129883,49.000789642334,219.675567626953,219.675567626953,,,747.01513671875,0,1,,,,,,1,1,1,49.0006675720215,0,49.0002176496718,,,,,,,,,,,,,,,,,,,,,,,,,,,,,,,,,
,3754603804.34789,49.0006618499756,219.675567626953,,,5,,,,-2.43000010959804,,,,,0.000672066106591613,5.50363246677794E-8,0.00190091459260078,5.20411474349394E-5,0.00067197846008694,5.50291471871122E-8,0.000671978459717108,4.24936377431389E-8,2.22943761532498E-8,3.49642358917757E-8,1.00013043052699,10.005763053894,2,20,10,5,2.19844910054136,0.193553749148956,0.0404026173055172,172.741912841797,48.9998054504395,49.0007781982422,219.675567626953,219.675567626953,,,747.052429199219,0,1,,,,,,1,1,1,49.000545501709,0,49.0002957512351,,,,,,,,,,,,,,,,,,,,,,,,,,,,,,,,,
,3754604014.488,48.9997539520264,219.675567626953,,,5,,,,-2.43000010959804,,,,,0.000672347438507498,8.20215488516789E-8,-0.000423596737109122,9.14912305641875E-5,0.000672259783243355,8.20108555402773E-8,0.000672259783224982,5.4254181007455E-8,-4.97012263536716E-9,6.15001160133746E-8,1.00013038897511,10.005763053894,2,20,10,5,2.19937724153742,0.193545546378524,0.0404026173055172,172.741912841797,48.9993553161621,49.0005302429199,219.675567626953,219.675567626953,,,747.102172851562,0,1,,,,,,1,1,1,48.9996376037598,0,48.9997381322524,,,,,,,,,,,,,,,,,,,,,,,,,,,,,,,,,
,3754604224.52943,49.0000324249268,219.675567626953,,,5,,,,-2.43000010959804,,,,,0.000672439183049406,8.70452384450841E-8,0.00182446269526082,8.60666270102871E-5,0.000672351430122969,8.70338790915567E-8,0.000672351429782097,6.50179252513007E-8,2.14096066513456E-8,5.78581498644744E-8,1.00013051645688,10.005763053894,2,20,10,5,2.19966975891532,0.193658261819128,0.0404026173055172,172.741912841797,48.9990272521973,49.0004692077637,219.675567626953,219.675567626953,,,747.139526367187,0,1,,,,,,1,1,1,48.9999198913574,0,48.9996719360352,,,,,,,,,,,,,,,,,,,,,,,,,,,,,,,,,
,3754604433.02026,48.9999046325684,219.675567626953,,,5,,,,-2.43000010959804,,,,,0.000672613408645582,9.38614832331578E-8,0.00425464942324627,0.000104991787086558,0.000672525636915686,9.38492349124313E-8,0.000672525635061466,6.18292824319273E-8,4.99401672323637E-8,7.06032487043031E-8,1.00013051060819,10.005763053894,2,20,10,5,2.20023146417121,0.193801760084892,0.0404026173055172,172.741912841797,48.9995002746582,49.000244140625,219.675567626953,219.675567626953,,,747.189270019531,0,1,,,,,,1,1,1,48.9999389648438,0,48.9998016357422,,,,,,,,,,,,,,,,,,,,,,,,,,,,,,,,,
,3754604643.94254,49.0002880096436,219.675567626953,,,5,,,,-2.43000010959804,,,,,0.000672866461323777,6.57059516136911E-8,0.00318122697052825,6.62553232653098E-5,0.0006727787219515,6.56973837933571E-8,0.000672778720914482,4.82676599968165E-8,3.73546155154637E-8,4.45688146098074E-8,1.00013041341739,10.005763053894,2,20,10,5,2.20106287383874,0.193833436058693,0.0404026173055172,172.741912841797,48.9999351501465,49.0006523132324,219.675567626953,219.675567626953,,,747.263854980469,0,1,,,,,,1,1,1,49.0000343322754,0,49.0002046472886,,,,,,,,,,,,,,,,,,,,,,,,,,,,,,,,,
,3754604852.56432,48.9996089935303,219.675567626953,,,5,,,,-2.43000010959804,,,,,0.000672931106671805,7.81225829443485E-8,0.00320878156425675,8.75620623114978E-5,0.000672843302587108,7.81123895057906E-8,0.000672843301531947,5.12945341581922E-8,3.76817839323327E-8,5.89102381577124E-8,1.00013049707764,10.005763053894,2,20,10,5,2.20127424657198,0.193853119186424,0.0404026173055172,172.741912841797,48.9993896484375,49.0005187988281,219.675567626953,219.675567626953,,,747.350952148438,0,1,,,,,,1,1,1,48.9995193481445,0,48.9998758104112,,,,,,,,,,,,,,,,,,,,,,,,,,,,,,,,,
,3754605062.74423,49.0004978179932,219.675567626953,,,5,,,,-2.43000010959804,,,,,0.000673022398939606,9.46104151059396E-8,0.00266695096157488,7.98949017311637E-5,0.000672934632772729,9.45980773390338E-8,0.000672934632043729,7.7844194448674E-8,3.13231389912833E-8,5.3750140714968E-8,1.00013042301972,10.005763053894,2,20,10,5,2.20157471304866,0.193858595154742,0.0404026173055172,172.741912841797,48.9996681213379,49.0013656616211,219.675567626953,219.675567626953,,,747.425537109375,0,1,,,,,,1,1,1,49.0003204345703,0,49.0002343027215,,,,,,,,,,,,,,,,,,,,,,,,,,,,,,,,,
,3754605271.91262,49.0009708404541,219.675567626953,,,5,,,,-2.43000010959804,,,,,0.000673167520084588,9.05973701511603E-8,0.000675417906070841,0.000102628977747044,0.000673079720423521,9.05855537486223E-8,0.000673079720376754,5.86077332076382E-8,7.93444297712839E-9,6.90715292736945E-8,1.00013044466859,10.005763053894,2,20,10,5,2.20205616858592,0.193823851871242,0.0404026173055172,172.741912841797,48.9998588562012,49.0012550354004,219.675567626953,219.675567626953,,,747.43798828125,0,1,,,,,,1,1,1,49.0012092590332,0,49.0004386901855,,,,,,,,,,,,,,,,,,,,,,,,,,,,,,,,,
,3754605482.05172,48.9998607635498,219.675567626953,,,5,,,,-2.43000010959804,,,,,0.000673350447952234,8.03249403881125E-8,0.00248746631622598,8.3461220507895E-5,0.000673262581395015,8.03144586605185E-8,0.000673262580760526,5.73911538604332E-8,2.92293430144707E-8,5.61842302474654E-8,1.00013050860043,10.005763053894,2,20,10,5,2.20264842648345,0.193946189041561,0.0404026173055172,172.741912841797,48.9986190795898,49.0003280639648,219.675567626953,219.675567626953,,,747.475280761719,0,1,,,,,,1,1,1,48.9997978210449,0,48.9995568593343,,,,,,,,,,,,,,,,,,,,,,,,,,,,,,,,,
,3754605693.21381,48.9999542236328,219.675567626953,,,5,,,,-2.43000010959804,,,,,0.00067341428691327,1.14216502741706E-7,0.00520475223336625,0.000140617167598691,0.000673326409145893,1.14201597962503E-7,0.000673326406367777,6.38620699750097E-8,6.11650134922518E-8,9.46765070949286E-8,1.00013051287783,10.005763053894,2,20,10,5,2.20284805375424,0.194069047171047,0.0404026173055172,172.741912841797,48.9995269775391,49.0005531311035,219.675567626953,219.675567626953,,,747.512634277344,0,1,,,,,,1,1,1,49.000072479248,0,48.9999385409885,,,,,,,,,,,,,,,,,,,,,,,,,,,,,,,,,
,3754605903.22624,49.0008907318115,219.675567626953,,,5,,,,-2.43000010959804,,,,,0.000673776152004271,1.19419607449187E-7,0.00194023686421474,7.62286740335269E-5,0.000673688275430419,1.19404032267545E-7,0.000673688275044147,1.07809681600795E-7,2.28134574280655E-8,5.13263623772836E-8,1.00013044100225,10.005763053894,2,20,10,5,2.20404283354437,0.194047750532843,0.0404026173055172,172.741912841797,48.9999694824219,49.0012283325195,219.675567626953,219.675567626953,,,747.537475585938,0,1,,,,,,1,1,1,49.0008125305176,0,49.0006123711081,,,,,,,,,,,,,,,,,,,,,,,,,,,,,,,,,
,3754606113.41846,49.0001678466797,219.675567626953,,,5,,,,-2.43000010959804,,,,,0.000673705577121706,8.29637160671714E-8,-0.000808391910026351,5.88268531238213E-5,0.000673617732035827,8.29528983524155E-8,0.000673617731968779,7.2884673923255E-8,-9.50414026369356E-9,3.96107012329619E-8,1.00013040791788,10.005763053894,2,20,10,5,2.20382127549944,0.193921706468375,0.0404026173055172,172.741912841797,48.9995460510254,49.0012588500977,219.675567626953,219.675567626953,,,747.475280761719,0,1,,,,,,1,1,1,48.9997024536133,0,49.0000595516629,,,,,,,,,,,,,,,,,,,,,,,,,,,,,,,,,
,3754606323.48477,48.9998760223389,219.675567626953,,,5,,,,-2.43000010959804,,,,,0.000673945503650568,7.99148679319048E-8,0.000111521771731127,6.13075407156009E-5,0.000673857558973068,7.99044396595154E-8,0.000673857558971792,6.84041418440875E-8,1.31161124797826E-9,4.12988239042601E-8,1.00013050929878,10.005763053894,2,20,10,5,2.20460300670642,0.194026163559104,0.0404026173055172,172.741912841797,48.9995765686035,49.0005683898926,219.675567626953,219.675567626953,,,747.67431640625,0,1,,,,,,1,1,1,48.9997673034668,0,49.0000543033375,,,,,,,,,,,,,,,,,,,,,,,,,,,,,,,,,
,3754606533.58225,48.9993171691895,219.675567626953,,,5,,,,-2.43000010959804,,,,,0.000674142224981292,8.48452393282047E-8,-0.00120495214848226,7.5316258967437E-5,0.000674054271871287,8.48341698499974E-8,0.000674054271722228,6.79752259096601E-8,-1.41756190408342E-8,5.07563300157614E-8,1.00013048372168,10.005763053894,2,20,10,5,2.20525097789131,0.194032132110215,0.0404026173055172,172.741912841797,48.9984436035156,49.0000457763672,219.675567626953,219.675567626953,,,747.711608886719,0,1,,,,,,1,1,1,48.9990463256836,0,48.9994706546559,,,,,,,,,,,,,,,,,,,,,,,,,,,,,,,,,
,3754606742.05553,49.0007286071777,219.675567626953,,,5,,,,-2.43000010959804,,,,,0.000674574422321498,8.1687857061051E-8,0.00309060106313463,9.04394401819607E-5,0.000674486446638069,8.1677203610794E-8,0.000674486445656809,5.43217068674501E-8,3.63825842977257E-8,6.09944075525447E-8,1.00013043358227,10.005763053894,2,20,10,5,2.20665021794201,0.194321958496656,0.0404026173055172,172.741912841797,48.9998168945313,49.0010185241699,219.675567626953,219.675567626953,,,747.761352539063,0,1,,,,,,1,1,1,49.0004386901855,0,49.0004110897289,,,,,,,,,,,,,,,,,,,,,,,,,,,,,,,,,
,3754606952.15477,49.0003070831299,219.675567626953,,,5,,,,-2.43000010959804,,,,,0.000674624637200084,1.21710886244674E-7,0.00274061519292079,0.000105096058065369,0.000674536667979228,1.21695015475594E-7,0.000674536667207568,9.89269150129319E-8,3.22649496254606E-8,7.08741298192029E-8,1.00013041429033,10.005763053894,2,20,10,5,2.20681566646137,0.194322944947756,0.0404026173055172,172.741912841797,48.9990386962891,49.0007057189941,219.675567626953,219.675567626953,,,747.786254882813,0,1,,,,,,1,1,1,49.0000915527344,0,48.9997421713436,,,,,,,,,,,,,,,,,,,,,,,,,,,,,,,,,
,3754607159.9095,48.9998531341553,219.675567626953,,,5,,,,-2.43000010959804,,,,,0.000674786056523976,8.48809380878483E-8,0.002252626102206,6.98578312314475E-5,0.000674698002867497,8.48698618705914E-8,0.000674698002346048,7.05875798746274E-8,2.65262528041357E-8,4.71199217038436E-8,1.00013050825125,10.005763053894,2,20,10,5,2.2073453527345,0.194350641726656,0.0404026173055172,172.741912841797,48.9995307922363,49.0001602172852,219.675567626953,219.675567626953,,,747.823547363281,0,1,,,,,,1,1,1,48.9999465942383,0,48.9998577342314,,,,,,,,,,,,,,,,,,,,,,,,,,,,,,,,,
,3754607368.6268,49.0010147094727,219.675567626953,,,5,,,,-2.43000010959804,,,,,0.000674835053162469,1.04011125191363E-7,0.00359213515561851,7.48852740869018E-5,0.00067474703465442,1.03997559055436E-7,0.000674747033328336,9.09088672321201E-8,4.23029857232371E-8,5.05081196250818E-8,1.00013044667635,10.005763053894,2,20,10,5,2.20750108511188,0.194416359473726,0.0404026173055172,172.741912841797,48.9999885559082,49.0013542175293,219.675567626953,219.675567626953,,,747.873291015625,0,1,,,,,,1,1,1,49.0007171630859,0,49.0005728403727,,,,,,,,,,,,,,,,,,,,,,,,,,,,,,,,,
,3754607576.09789,49.0008602142334,219.675567626953,,,5,,,,-2.43000010959804,,,,,0.000675010428904172,1.33916034468328E-7,0.00237148278423494,7.22517582890098E-5,0.000674922392293545,1.33898568791831E-7,0.000674922391715425,1.24718654335876E-7,2.79351611438735E-8,4.87245727036059E-8,1.00013043960555,10.005763053894,2,20,10,5,2.20807891169397,0.194419842721999,0.0404026173055172,172.741912841797,48.9994926452637,49.001407623291,219.675567626953,219.675567626953,,,747.898193359375,0,1,,,,,,1,1,1,49.0006675720215,0,49.0003193126005,,,,,,,,,,,,,,,,,,,,,,,,,,,,,,,,,
,3754607784.98638,48.999137878418,219.675567626953,,,5,,,,-2.43000010959804,,,,,0.000674851103069674,7.73904193471159E-8,0.000696489692888491,7.63935369638152E-5,0.000674763063010815,7.73803231095259E-8,0.00067476306296096,5.77180346779113E-8,8.20244566896972E-9,5.15397213559994E-8,1.00013047551605,10.005763053894,2,20,10,5,2.20756340952347,0.194309422349556,0.0404026173055172,172.741912841797,48.998722076416,49.0003089904785,219.675567626953,219.675567626953,,,747.935485839844,0,1,,,,,,1,1,1,48.9992561340332,0,48.9995960908778,,,,,,,,,,,,,,,,,,,,,,,,,,,,,,,,,
,3754607993.66662,49.0008506774902,219.675567626953,,,5,,,,-2.43000010959804,,,,,0.000675335035115236,5.26551232288934E-8,0.000101563925253068,4.23780502289461E-5,0.000675246956463312,5.26482558341489E-8,0.000675246956462251,4.41979248643519E-8,1.19695956659262E-9,2.86073815660067E-8,1.00013043916908,10.005763053894,2,20,10,5,2.20914846061795,0.19442581663027,0.0404026173055172,172.741912841797,48.9997138977051,49.0010681152344,219.675567626953,219.675567626953,,,747.960327148438,0,1,,,,,,1,1,1,49.0006332397461,0,49.0003110100241,,,,,,,,,,,,,,,,,,,,,,,,,,,,,,,,,
,3754608203.80071,49.001148223877,219.675567626953,,,5,,,,-2.43000010959804,,,,,0.000675386809977357,6.90087391262779E-8,0.00417467295161522,6.85342291711058E-5,0.00067529871537793,6.89997379181695E-8,0.000675298713585404,5.11826730830644E-8,4.92034719278172E-8,4.62741591911537E-8,1.00013045278692,10.005763053894,2,20,10,5,2.20930399794542,0.194597778381561,0.0404026173055172,172.741912841797,48.9993476867676,49.0012588500977,219.675567626953,219.675567626953,,,748.010070800781,0,1,,,,,,1,1,1,49.0011520385742,0,49.0002104815315,,,,,,,,,,,,,,,,,,,,,,,,,,,,,,,,,
,3754608412.97151,49.0009994506836,219.675567626953,,,5,,,,-2.43000010959804,,,,,0.000675660656025948,6.25497643871969E-8,0.00206183272895633,6.04709747498697E-5,0.000675572530306522,6.25416060862252E-8,0.000675572529869097,4.73610528408579E-8,2.43109975168616E-8,4.0845846369613E-8,1.000130445978,10.005763053894,2,20,10,5,2.21020697182601,0.194595178245987,0.0404026173055172,172.741912841797,49.000072479248,49.0011367797852,219.675567626953,219.675567626953,,,747.972778320312,0,1,,,,,,1,1,1,49.0009803771973,0,49.0005731021657,,,,,,,,,,,,,,,,,,,,,,,,,,,,,,,,,