File: Experimental_Data/Fig3B/Lifetime_200Oe.dat
[Header]
; MPMS3 Data File (default extension .dat)
; Copyright (c) 2007, Quantum Design, Inc. All rights reserved.
TITLE,200Oe
FILEOPENTIME,3754608690.19848,12/22/2018,2:51 am
BYAPP,SQUID AC,0.9.1.0
INFO,MPMS3 Measurement Release 1.1.16 Build 347, MultiVu Release 2.3.3.2,APPNAME
INFO,0,MOMENT_UNITS
INFO,CoIINO3,SAMPLE_MATERIAL
INFO,40 Hours Pumped Turbo,SAMPLE_COMMENT
INFO,,SAMPLE_MASS
INFO,,SAMPLE_VOLUME
INFO,,SAMPLE_MOLECULAR_WEIGHT
INFO,,SAMPLE_SIZE
INFO,,SAMPLE_SHAPE
INFO,Brass,SAMPLE_HOLDER
INFO,Standard,SAMPLE_HOLDER_DETAIL
INFO,65.37,SAMPLE_OFFSET
DATATYPE,COMMENT,1
DATATYPE,TIME,2
STARTUPAXIS,X,2
STARTUPAXIS,Y1,5
FIELDGROUP, VSM,2,3,4,5,6,8,9,10,11,14,15
FIELDGROUP, DC, 2,3,4,14,56,57,58,59,60,61,62,63,64,65,66,67,68,69
FIELDGROUP, AC, 2,3,4,11,16,17,18,19,20,21,22,23,24,25,26,27,28,29,30
STARTUPGROUP, All
[Data]
Comment,Time Stamp (sec),Temperature (K),Magnetic Field (Oe),Moment (emu),M. Std. Err. (emu),Transport Action,Averaging Time (sec),Frequency (Hz),Peak Amplitude (mm),Center Position (mm),Lockin Signal' (V),Lockin Signal (V),Range,M. Quad. Signal (emu),AC Moment (emu),AC M. Std Err. (emu),AC Phase (deg),AC Phase Std. Err. (deg),AC Susceptibility (emu/Oe),AC Suscept. Std Err. (emu/Oe),AC X' (emu/Oe),AC X' Std Err. (emu/Oe),AC X'' (emu/Oe),AC X'' Std Err. (emu/Oe),AC Drive (Oe),AC Frequency (Hz),AC Averaging Time (sec),AC Cycles,AC Range,AC Measure Type,AC Signal' (V),AC Signal'' (V),AC Trim Coil Ratio,AC Trim Coil Phase,Min. Temperature (K),Max. Temperature (K),Min. Field (Oe),Max. Field (Oe),Mass (grams),Motor Lag (deg),Pressure (Torr),Measure Count,Measurement Number,SQUID Status (code),Motor Status (code),Measure Status (code),Motor Current (amps),Motor Temp. (C),Temp. Status (code),Field Status (code),Chamber Status (code),Chamber Temp (K),Redirection State,Average Temp (K),Rotation Angle (deg),Rotator state,DC Moment Fixed Ctr (emu),DC Moment Err Fixed Ctr (emu),DC Moment Free Ctr (emu),DC Moment Err Free Ctr (emu),DC Fixed Fit,DC Free Fit,DC Calculated Center (mm),DC Calculated Center Err (mm),DC Scan Length (mm),DC Scan Time (s),DC Number of Points,DC Squid Drift,DC Min V (V),DC Max V (V),DC Scans per Measure,Map 01,Map 02,Map 03,Map 04,Map 05,Map 06,Map 07,Map 08,Map 09,Map 10,Map 11,Map 12,Map 13,Map 14,Map 15,Map 16
,3754608695.82578,48.9711093902588,199.494216918945,,,5,,,,-2.43000010959804,,,,,0.000654659901665405,7.61858017864512E-8,0.0816641108145468,4.99447873835318E-5,0.00065457495981877,7.6175916710743E-8,0.000654574294933779,6.88194906623202E-8,9.32970358554602E-7,3.26595773350004E-8,1.00012976641615,10.005763053894,2,20,10,5,2.14124864545582,0.191475756943365,0.0404026173055172,172.741912841797,48.9161567687988,48.986083984375,199.494216918945,199.494216918945,,,734.565612792969,0,1,,,,,,1,1,1,48.9655418395996,0,48.9456000857883,,,,,,,,,,,,,,,,,,,,,,,,,,,,,,,,,
,3754608903.41339,49.0001258850098,199.494216918945,,,5,,,,-2.43000010959804,,,,,0.000658007817190953,7.69837427920404E-8,0.0209109736065995,8.98320126219171E-5,0.000657921944735628,7.69736961287015E-8,0.000657921900918126,4.93191085400518E-8,2.40118700418516E-7,5.90980154364617E-8,1.00013052073428,10.005763053894,2,20,10,5,2.15240181161881,0.190172649655845,0.0404026173055172,172.741912841797,48.9997177124023,49.0010795593262,199.494216918945,199.494216918945,,,741.617431640625,0,1,,,,,,1,1,1,49.0003623962402,0,49.0001889397116,,,,,,,,,,,,,,,,,,,,,,,,,,,,,,,,,
,3754609108.47124,49.0002765655518,199.494216918945,,,5,,,,-2.43000010959804,,,,,0.000660055842647162,7.01321194204929E-8,0.0234916677887584,7.92177182482261E-5,0.000659969774079219,7.01229744804812E-8,0.000659969718606879,4.67374785261448E-8,2.705921863821E-7,5.2276568852674E-8,1.00013041289363,10.005763053894,2,20,10,5,2.15909248959733,0.19086180466389,0.0404026173055172,172.741912841797,48.9996604919434,49.0003929138184,199.494216918945,199.494216918945,,,745.69677734375,0,1,,,,,,1,1,1,49.0002746582031,0,49.0000785378849,,,,,,,,,,,,,,,,,,,,,,,,,,,,,,,,,
,3754609313.40438,49.0001583099365,199.494216918945,,,5,,,,-2.43000010959804,,,,,0.000661656447723747,6.51604296443639E-8,0.0219824582552768,5.7510590744155E-5,0.000661570098126995,6.51519258704745E-8,0.000661570049435499,5.28957218594302E-8,2.53822128467755E-7,3.80370352893283E-8,1.00013052221827,10.005763053894,2,20,10,5,2.16433322845406,0.191267626381494,0.0404026173055172,172.741912841797,48.9994659423828,49.0010986328125,199.494216918945,199.494216918945,,,747.549926757812,0,1,,,,,,1,1,1,49.0001335144043,0,49.0002070532905,,,,,,,,,,,,,,,,,,,,,,,,,,,,,,,,,
,3754609518.48703,49.000825881958,199.494216918945,,,5,,,,-2.43000010959804,,,,,0.000663280518333476,1.02352238952184E-7,0.0222569127306471,6.91522045291772E-5,0.000663194012610139,1.02338890068535E-7,0.000663193962572688,9.15012737576021E-8,2.57621957784078E-7,4.58341065277387E-8,1.00013043803426,10.005763053894,2,20,10,5,2.16964478009067,0.191747493824805,0.0404026173055172,172.741912841797,49.0005989074707,49.0013427734375,199.494216918945,199.494216918945,,,748.395629882813,0,1,,,,,,1,1,1,49.0006256103516,0,49.0009346008301,,,,,,,,,,,,,,,,,,,,,,,,,,,,,,,,,
,3754609723.60797,49.000171661377,199.494216918945,,,5,,,,-2.43000010959804,,,,,0.00066429244259545,8.61833402869058E-8,0.0194300602206425,8.76560147873507E-5,0.000664205748581887,8.61720928615361E-8,0.0006642057103896,6.35365921038358E-8,2.2524446924641E-7,5.82128083154214E-8,1.00013052282933,10.005763053894,2,20,10,5,2.17296433909792,0.191932823076772,0.0404026173055172,172.741912841797,48.9994926452637,49.0005416870117,199.494216918945,199.494216918945,,,748.806091308594,0,1,,,,,,1,1,1,49.000186920166,0,48.9999661165125,,,,,,,,,,,,,,,,,,,,,,,,,,,,,,,,,
,3754609928.4978,49.0009136199951,199.494216918945,,,5,,,,-2.43000010959804,,,,,0.000665548192560024,7.87391125102042E-8,0.0216205978210233,8.0102491635588E-5,0.000665461388412471,7.87288429585521E-8,0.000665461341033788,5.79452603816634E-8,2.51112260363765E-7,5.3297068520638E-8,1.00013044204978,10.005763053894,2,20,10,5,2.17706466456445,0.192378875651689,0.0404026173055172,172.741912841797,48.9992523193359,49.0010108947754,199.494216918945,199.494216918945,,,748.880676269531,0,1,,,,,,1,1,1,49.0009269714355,0,49.0003673329073,,,,,,,,,,,,,,,,,,,,,,,,,,,,,,,,,
,3754610133.6335,49.0000896453857,199.494216918945,,,5,,,,-2.43000010959804,,,,,0.000666300830936204,8.25282361797973E-8,0.019681736182795,6.91300854364417E-5,0.000666213877316722,8.25174660763963E-8,0.000666213838010145,6.84787446131086E-8,2.28851856597865E-7,4.60412178800895E-8,1.00013051907569,10.005763053894,2,20,10,5,2.1795331244729,0.192522676937571,0.0404026173055172,172.741912841797,48.9996376037598,49.0004005432129,199.494216918945,199.494216918945,,,748.868286132813,0,1,,,,,,1,1,1,49.000171661377,0,48.999963760376,,,,,,,,,,,,,,,,,,,,,,,,,,,,,,,,,
,3754610339.13877,48.9993515014648,199.494216918945,,,5,,,,-2.43000010959804,,,,,0.000667352975745755,4.7881955605593E-8,0.019983105962627,4.38568925167095E-5,0.000667265907358347,4.78757085297396E-8,0.000667265866774833,3.78956165919131E-8,2.32722988935293E-7,2.92575752642507E-8,1.00013048529297,10.005763053894,2,20,10,5,2.18297377530429,0.192838170941306,0.0404026173055172,172.741912841797,48.9992294311523,49.0007133483887,199.494216918945,199.494216918945,,,748.843383789063,0,1,,,,,,1,1,1,48.999568939209,0,49.0000583424288,,,,,,,,,,,,,,,,,,,,,,,,,,,,,,,,,
,3754610544.37017,49.0003528594971,199.494216918945,,,5,,,,-2.43000010959804,,,,,0.000668119257376485,7.67213560106827E-8,0.0209537836496203,6.17286298720203E-5,0.000668032058402203,7.67113427930186E-8,0.000668032013729014,6.46943194110245E-8,2.44307679024596E-7,4.12222652101063E-8,1.00013053112225,10.005763053894,2,20,10,5,2.18547708324434,0.19309661694824,0.0404026173055172,172.741912841797,48.9995040893555,49.0011177062988,199.494216918945,199.494216918945,,,748.806091308594,0,1,,,,,,1,1,1,49.0005645751953,0,49.0002257403205,,,,,,,,,,,,,,,,,,,,,,,,,,,,,,,,,
,3754610751.15387,48.9995956420898,199.494216918945,,,5,,,,-2.43000010959804,,,,,0.000668973289145618,6.93556909422968E-8,0.0169454892496947,7.28488861183645E-5,0.000668886001885826,6.93466414506182E-8,0.000668885972631839,4.93474928314482E-8,1.97826096185645E-7,4.87214699258014E-8,1.00013049646658,10.005763053894,2,20,10,5,2.18828421675253,0.193190361835677,0.0404026173055172,172.741912841797,48.9989433288574,49.0000228881836,199.494216918945,199.494216918945,,,748.743896484375,0,1,,,,,,1,1,1,48.9995193481445,0,48.9995043137494,,,,,,,,,,,,,,,,,,,,,,,,,,,,,,,,,
,3754610959.97225,48.9995765686035,199.494216918945,,,5,,,,-2.43000010959804,,,,,0.000669808676198319,7.67214586485993E-8,0.020487904037866,6.99882914152213E-5,0.000669721280522242,7.67114481426347E-8,0.000669721237705473,6.07338553034662E-8,2.39479856136958E-7,4.6861979216821E-8,1.00013049559364,10.005763053894,2,20,10,5,2.19100489507579,0.193567072593094,0.0404026173055172,172.741912841797,48.9992866516113,49.0003089904785,199.494216918945,199.494216918945,,,748.694152832031,0,1,,,,,,1,1,1,48.9997291564941,0,48.9997677273221,,,,,,,,,,,,,,,,,,,,,,,,,,,,,,,,,
,3754611165.26692,49.0001754760742,199.494216918945,,,5,,,,-2.43000010959804,,,,,0.000670256305244243,8.93451017359256E-8,0.0186844818395899,0.000100498649543217,0.000670168909678099,8.93334519152716E-8,0.000670168874043562,5.86947635608248E-8,2.18545915716908E-7,6.73453069013499E-8,1.00013040826705,10.005763053894,2,20,10,5,2.19247522602377,0.193627421377122,0.0404026173055172,172.741912841797,48.9994697570801,49.0010757446289,199.494216918945,199.494216918945,,,748.656799316406,0,1,,,,,,1,1,1,49.0000877380371,0,48.9999306996663,,,,,,,,,,,,,,,,,,,,,,,,,,,,,,,,,
,3754611370.77264,48.9997653961182,199.494216918945,,,5,,,,-2.43000010959804,,,,,0.00067095705162754,6.80961891648084E-8,0.0219571403961938,6.4428969322312E-5,0.000670869500316123,6.80873034833039E-8,0.000670869451053862,5.26151790012403E-8,2.57093551577378E-7,4.32148566386026E-8,1.00013050423574,10.005763053894,2,20,10,5,2.19475636233098,0.19395522016968,0.0404026173055172,172.741912841797,48.999195098877,49.0007667541504,199.494216918945,199.494216918945,,,748.631958007812,0,1,,,,,,1,1,1,48.9997444152832,0,48.999707116021,,,,,,,,,,,,,,,,,,,,,,,,,,,,,,,,,
,3754611578.5625,48.999755859375,199.494216918945,,,5,,,,-2.43000010959804,,,,,0.000671822244151583,6.60733768113631E-8,0.0191392810133584,5.23754003285467E-5,0.000671734580236763,6.60647551098236E-8,0.000671734542758999,5.59252448112495E-8,2.24388546027322E-7,3.51698572718568E-8,1.00013050379927,10.005763053894,2,20,10,5,2.19759602768163,0.194097243380093,0.0404026173055172,172.741912841797,48.9992179870605,49.000617980957,199.494216918945,199.494216918945,,,748.619506835938,0,1,,,,,,1,1,1,48.9998893737793,0,49.0000076293945,,,,,,,,,,,,,,,,,,,,,,,,,,,,,,,,,
,3754611783.77134,49.0014266967773,199.494216918945,,,5,,,,-2.43000010959804,,,,,0.000672336700060329,6.96068004111329E-8,0.0192726141547928,6.31653395671829E-5,0.00067224899473771,6.95977203075391E-8,0.00067224895670685,5.5150430742012E-8,2.26124774936537E-7,4.2453181988833E-8,1.00013046553183,10.005763053894,2,20,10,5,2.19927841163858,0.194250987141031,0.0404026173055172,172.741912841797,49.0000991821289,49.0016441345215,199.494216918945,199.494216918945,,,748.582214355469,0,1,,,,,,1,1,1,49.0015296936035,0,49.0009072621663,,,,,,,,,,,,,,,,,,,,,,,,,,,,,,,,,
,3754611988.91194,49.0012435913086,199.494216918945,,,5,,,,-2.43000010959804,,,,,0.000672908154377626,7.32813925982395E-8,0.0203786446046168,8.35990202955501E-5,0.000672820380147283,7.32718337635131E-8,0.000672820337589944,4.69627482952464E-8,2.39305010547016E-7,5.62428830664398E-8,1.00013045715162,10.005763053894,2,20,10,5,2.2011439405653,0.194458582511434,0.0404026173055172,172.741912841797,48.9997253417969,49.0013771057129,199.494216918945,199.494216918945,,,748.569763183594,0,1,,,,,,1,1,1,49.0013771057129,0,49.000456866096,,,,,,,,,,,,,,,,,,,,,,,,,,,,,,,,,
,3754612195.53623,49.0004596710205,199.494216918945,,,5,,,,-2.43000010959804,,,,,0.000673511106160548,1.05933611439088E-7,0.0201562688475949,8.60370003968735E-5,0.000673423277438872,1.05919797244207E-7,0.000673423235767947,8.8680621599508E-8,2.36905762757104E-7,5.79202106434258E-8,1.00013042127384,10.005763053894,2,20,10,5,2.20311700579576,0.19462427898636,0.0404026173055172,172.741912841797,48.9990043640137,49.0008735656738,199.494216918945,199.494216918945,,,748.532470703125,0,1,,,,,,1,1,1,49.000171661377,0,49.0002061843872,,,,,,,,,,,,,,,,,,,,,,,,,,,,,,,,,
,3754612404.87858,49.0005035400391,199.494216918945,,,5,,,,-2.43000010959804,,,,,0.000674160176992106,6.20105018107267E-8,0.0212270192648871,5.85228408971408E-5,0.000674072262275626,6.20024152522626E-8,0.000674072216015244,4.7840521304146E-8,2.4973121391359E-7,3.94408927188718E-8,1.0001304232816,10.005763053894,2,20,10,5,2.20523653544465,0.19485305153143,0.0404026173055172,172.741912841797,48.999641418457,49.0006446838379,199.494216918945,199.494216918945,,,748.370788574219,0,1,,,,,,1,1,1,49.0004234313965,0,49.000228657442,,,,,,,,,,,,,,,,,,,,,,,,,,,,,,,,,
,3754612612.407,49.0002555847168,199.494216918945,,,5,,,,-2.43000010959804,,,,,0.000674523029333964,6.08583029210305E-8,0.0203853222737553,6.69735165858161E-5,0.000674434997579421,6.08503603261129E-8,0.000674434954891993,4.07784795016646E-8,2.39957892276359E-7,4.51650524338243E-8,1.00013052667026,10.005763053894,2,20,10,5,2.20642632080543,0.194925513320689,0.0404026173055172,172.741912841797,48.9997329711914,49.0005950927734,199.494216918945,199.494216918945,,,748.544921875,0,1,,,,,,1,1,1,49.000545501709,0,49.0001882665298,,,,,,,,,,,,,,,,,,,,,,,,,,,,,,,,,
,3754612817.76275,49.0002574920654,199.494216918945,,,5,,,,-2.43000010959804,,,,,0.000674778182314545,8.42960268927303E-8,0.0222501182301285,6.43923547936597E-5,0.000674690117201192,8.42850254416489E-8,0.000674690066327445,7.22358781968672E-8,2.62007684103197E-7,4.34274500152469E-8,1.00013052675756,10.005763053894,2,20,10,5,2.20725460164428,0.19507108786847,0.0404026173055172,172.741912841797,48.9993515014648,49.0004196166992,199.494216918945,199.494216918945,,,748.569763183594,0,1,,,,,,1,1,1,49.0004196166992,0,48.999790403578,,,,,,,,,,,,,,,,,,,,,,,,,,,,,,,,,
,3754613022.95189,49.0001277923584,199.494216918945,,,5,,,,-2.43000010959804,,,,,0.000675458408982089,5.64405940803621E-8,0.0161384976688099,5.44359649190311E-5,0.000675370336580769,5.64332348431589E-8,0.000675370309789522,4.28200688210869E-8,1.90231506596048E-7,3.67580154662967E-8,1.00013040608471,10.005763053894,2,20,10,5,2.2095004947963,0.195032053713517,0.0404026173055172,172.741912841797,48.9996376037598,49.000862121582,199.494216918945,199.494216918945,,,748.594665527344,0,1,,,,,,1,1,1,49.0000839233398,0,49.0001779444077,,,,,,,,,,,,,,,,,,,,,,,,,,,,,,,,,
,3754613228.00424,49.00026512146,199.494216918945,,,5,,,,-2.43000010959804,,,,,0.000675497265673596,8.02160971698959E-8,0.0217456683780943,4.38269749405443E-5,0.000675409106477068,8.02056281613084E-8,0.000675409057832184,7.45546876123342E-8,2.56340383553672E-7,2.95726451941205E-8,1.00013052710673,10.005763053894,2,20,10,5,2.20960850119508,0.195259514331907,0.0404026173055172,172.741912841797,48.9991455078125,49.0004348754883,199.494216918945,199.494216918945,,,748.582214355469,0,1,,,,,,1,1,1,49.0000915527344,0,48.9998370899874,,,,,,,,,,,,,,,,,,,,,,,,,,,,,,,,,
,3754613433.14721,49.0011367797852,199.494216918945,,,5,,,,-2.43000010959804,,,,,0.000676399890160882,1.24727120267192E-7,0.0192678644495627,8.03577450853617E-5,0.000676311663773742,1.24710851454379E-7,0.000676311625531902,1.12262586651499E-7,2.27435272342572E-7,5.43130565222672E-8,1.00013045226316,10.005763053894,2,20,10,5,2.21256951577286,0.195424738525702,0.0404026173055172,172.741912841797,49.0003433227539,49.0013084411621,199.494216918945,199.494216918945,,,748.669250488281,0,1,,,,,,1,1,1,49.0012435913086,0,49.0008495555205,,,,,,,,,,,,,,,,,,,,,,,,,,,,,,,,,
,3754613638.31779,48.9996738433838,199.494216918945,,,5,,,,-2.43000010959804,,,,,0.000676415103324855,5.90078765851628E-8,0.0214873629530077,6.72693436094082E-5,0.000676326842641029,5.90001770593644E-8,0.000676326795080399,3.75689978794884E-8,2.53639624515807E-7,4.54927608677176E-8,1.00013050004563,10.005763053894,2,20,10,5,2.21261170678186,0.195514852040275,0.0404026173055172,172.741912841797,48.9994316101074,49.0003089904785,199.494216918945,199.494216918945,,,748.681701660156,0,1,,,,,,1,1,1,48.9995231628418,0,48.9997573428684,,,,,,,,,,,,,,,,,,,,,,,,,,,,,,,,,
,3754613845.25876,48.9993896484375,199.494216918945,,,5,,,,-2.43000010959804,,,,,0.000677149120218224,6.57222770007469E-8,0.0170766975508689,5.13467627958354E-5,0.000677060772562895,6.57137022143336E-8,0.000677060742491044,5.57723686242711E-8,2.01794302541923E-7,3.47524611610822E-8,1.00013048703884,10.005763053894,2,20,10,5,2.21502779946317,0.195556503200598,0.0404026173055172,172.741912841797,48.9991302490234,49.0004959106445,199.494216918945,199.494216918945,,,748.681701660156,0,1,,,,,,1,1,1,48.9994163513184,0,48.999775144789,,,,,,,,,,,,,,,,,,,,,,,,,,,,,,,,,
,3754614054.35307,49.0010013580322,199.494216918945,,,5,,,,-2.43000010959804,,,,,0.00067757942593586,9.58298862068111E-8,0.0191665577185107,5.1375095967678E-5,0.000677491049894128,9.58173872056633E-8,0.000677491011987379,8.92853032090452E-8,2.26633989095562E-7,3.4772206167985E-8,1.0001304460653,10.005763053894,2,20,10,5,2.21642823747785,0.195761611244028,0.0404026173055172,172.741912841797,48.9999656677246,49.0011940002441,199.494216918945,199.494216918945,,,748.694152832031,0,1,,,,,,1,1,1,49.0008811950684,0,49.0005053351907,,,,,,,,,,,,,,,,,,,,,,,,,,,,,,,,,
,3754614259.25226,49.0003623962402,199.494216918945,,,5,,,,-2.43000010959804,,,,,0.000677535138064923,6.83171452035117E-8,0.0215770129816342,6.5472457561322E-5,0.00067744678760791,6.83082366603803E-8,0.00067744673957017,5.19561340998881E-8,2.55119625028246E-7,4.43460857917016E-8,1.00013041682185,10.005763053894,2,20,10,5,2.21627513006117,0.19584205885141,0.0404026173055172,172.741912841797,48.9997177124023,49.0010070800781,199.494216918945,199.494216918945,,,748.7314453125,0,1,,,,,,1,1,1,49.0000648498535,0,49.0001225191004,,,,,,,,,,,,,,,,,,,,,,,,,,,,,,,,,
,3754614464.2861,49.000316619873,199.494216918945,,,5,,,,-2.43000010959804,,,,,0.000678785340295721,8.91084098253164E-8,0.0182100432286045,8.45497273568423E-5,0.000678696750372903,8.90967800703995E-8,0.000678696716094352,6.8165750266769E-8,2.15706934443762E-7,5.73730486333227E-8,1.00013052946367,10.005763053894,2,20,10,5,2.22037617413247,0.196072950099567,0.0404026173055172,172.741912841797,48.9994201660156,49.0007362365723,199.494216918945,199.494216918945,,,748.7314453125,0,1,,,,,,1,1,1,49.0003814697266,0,49.0000850453096,,,,,,,,,,,,,,,,,,,,,,,,,,,,,,,,,
,3754614670.2241,48.9993324279785,199.494216918945,,,5,,,,-2.43000010959804,,,,,0.000678756165155488,6.55293161520187E-8,0.0143827252599618,5.47574963095144E-5,0.000678667609606058,6.55207667127745E-8,0.000678667588223274,5.39696822689035E-8,1.70363153311422E-7,3.71516388120824E-8,1.00013048442003,10.005763053894,2,20,10,5,2.22029383072872,0.195916215185807,0.0404026173055172,172.741912841797,48.9985847473145,49.0000343322754,199.494216918945,199.494216918945,,,748.743896484375,0,1,,,,,,1,1,1,48.9988212585449,0,48.9995386335585,,,,,,,,,,,,,,,,,,,,,,,,,,,,,,,,,
,3754614876.83711,49.0000915527344,199.494216918945,,,5,,,,-2.43000010959804,,,,,0.000678846768753558,6.69142765995828E-8,0.0173895265044814,6.35431993203453E-5,0.000678758177804319,6.69055441439618E-8,0.000678758146542422,5.11546241343826E-8,2.06006153370456E-7,4.31225725910418E-8,1.00013051916299,10.005763053894,2,20,10,5,2.2205799208772,0.196058893362933,0.0404026173055172,172.741912841797,48.9992790222168,49.0006484985352,199.494216918945,199.494216918945,,,748.743896484375,0,1,,,,,,1,1,1,49.0005302429199,0,48.9999012417263,,,,,,,,,,,,,,,,,,,,,,,,,,,,,,,,,
,3754615081.82095,48.9989700317383,199.494216918945,,,5,,,,-2.43000010959804,,,,,0.000679627902082072,5.1529951904302E-8,0.0167885362156168,6.29202651359646E-5,0.000679539244068651,5.1523229780102E-8,0.000679539214896736,2.87514829244668E-8,1.99115347459812E-7,4.27550632863207E-8,1.00013046783419,10.005763053894,2,20,10,5,2.22313714934769,0.196261179353206,0.0404026173055172,172.741912841797,48.9985466003418,49.0019416809082,199.494216918945,199.494216918945,,,748.75634765625,0,1,,,,,,1,1,1,48.9993782043457,0,49.000192081227,,,,,,,,,,,,,,,,,,,,,,,,,,,,,,,,,
,3754615286.80625,49.000072479248,199.494216918945,,,5,,,,-2.43000010959804,,,,,0.000679677488841178,1.18117945796275E-7,0.0217147010229164,0.000122608993901014,0.000679588790074361,1.18102531255845E-7,0.00067958874126775,8.37083609517602E-8,2.57559407815494E-7,8.33133734511316E-8,1.00013051829005,10.005763053894,2,20,10,5,2.22328246975258,0.196466649787204,0.0404026173055172,172.741912841797,48.9995155334473,49.0011749267578,199.494216918945,199.494216918945,,,748.781188964844,0,1,,,,,,1,1,1,49.0000686645508,0,49.0000282736386,,,,,,,,,,,,,,,,,,,,,,,,,,,,,,,,,
,3754615492.03046,49.0006713867188,199.494216918945,,,5,,,,-2.43000010959804,,,,,0.000680040312095485,6.61258306081008E-8,0.0211133615452921,6.828111063082E-5,0.000679951625349887,6.61172068771068E-8,0.00067995157918439,4.70795734115942E-8,2.50560587471199E-7,4.64219647646721E-8,1.00013043096346,10.005763053894,2,20,10,5,2.22447135850569,0.19654817727628,0.0404026173055172,172.741912841797,48.9999008178711,49.0009651184082,199.494216918945,199.494216918945,,,748.806091308594,0,1,,,,,,1,1,1,49.000846862793,0,49.0004425048828,,,,,,,,,,,,,,,,,,,,,,,,,,,,,,,,,
,3754615697.07107,49.0000438690186,199.494216918945,,,5,,,,-2.43000010959804,,,,,0.000680812935943355,6.17650702077177E-8,0.0195667015747638,5.77188145242521E-5,0.000680724089890492,6.17570098692561E-8,0.000680724050195922,4.76526877041987E-8,2.32469563656106E-7,3.92829431503993E-8,1.00013051698064,10.005763053894,2,20,10,5,2.22700398942062,0.196711370070333,0.0404026173055172,172.741912841797,48.9992637634277,49.0004692077637,199.494216918945,199.494216918945,,,748.855834960937,0,1,,,,,,1,1,1,49.0003242492676,0,48.9998642416561,,,,,,,,,,,,,,,,,,,,,,,,,,,,,,,,,
,3754615902.12362,49.0002822875977,199.494216918945,,,5,,,,-2.43000010959804,,,,,0.000680805471557615,8.21432242547634E-8,0.0194200860982354,5.12991951967683E-5,0.000680716697145133,8.21325130945609E-8,0.000680716658043631,7.43501647748549E-8,2.30725137633014E-7,3.48970300338028E-8,1.00013041315551,10.005763053894,2,20,10,5,2.22698007611079,0.196703514107497,0.0404026173055172,172.741912841797,48.9999008178711,49.0008392333984,199.494216918945,199.494216918945,,,748.880676269531,0,1,,,,,,1,1,1,49.0004653930664,0,49.0002158669864,,,,,,,,,,,,,,,,,,,,,,,,,,,,,,,,,
,3754616107.06478,49.0004920959473,199.494216918945,,,5,,,,-2.43000010959804,,,,,0.000681185535513112,6.27013037656825E-8,0.0190545220516931,6.4586118976165E-5,0.000681096705002494,6.26931271551417E-8,0.000681096667338217,4.46749700038829E-8,2.26508340681836E-7,4.39838066524822E-8,1.00013042275783,10.005763053894,2,20,10,5,2.22822455748923,0.196799108358167,0.0404026173055172,172.741912841797,48.9998893737793,49.0006294250488,199.494216918945,199.494216918945,,,748.880676269531,0,1,,,,,,1,1,1,49.0004653930664,0,49.0002297794118,,,,,,,,,,,,,,,,,,,,,,,,,,,,,,,,,
,3754616311.99271,49.0002460479736,199.494216918945,,,5,,,,-2.43000010959804,,,,,0.000681397150488162,7.22106634228491E-8,0.0172315263333456,7.34045089702138E-5,0.000681308221891906,7.22012392670124E-8,0.000681308191080192,5.20824623655466E-8,2.04901311919441E-7,5.00043604662012E-8,1.00013052623379,10.005763053894,2,20,10,5,2.2289230331665,0.196789327710916,0.0404026173055172,172.741912841797,48.9998588562012,49.0005722045898,199.494216918945,199.494216918945,,,748.930419921875,0,1,,,,,,1,1,1,49.0003356933594,0,49.0001303728889,,,,,,,,,,,,,,,,,,,,,,,,,,,,,,,,,
,3754616516.88475,49.0022430419922,199.494216918945,,,5,,,,-2.43000010959804,,,,,0.000681932148199699,6.4254141521136E-8,0.0152889783635493,3.7345568728789E-5,0.000681843165693595,6.42457572639115E-8,0.000681843141418208,5.89923606773589E-8,1.81945081688395E-7,2.54444239102762E-8,1.0001305028936,10.005763053894,2,20,10,5,2.23067974448183,0.196868200765547,0.0404026173055172,172.741912841797,48.9999618530273,49.0026168823242,199.494216918945,199.494216918945,,,748.980163574219,0,1,,,,,,1,1,1,49.0021324157715,0,49.0009799284094,,,,,,,,,,,,,,,,,,,,,,,,,,,,,,,,,
,3754616721.81711,49.0000839233398,199.494216918945,,,5,,,,-2.43000010959804,,,,,0.000681871696401843,7.31732124648649E-8,0.0186100541146352,6.1862014395407E-5,0.000681782710931134,7.31636632303258E-8,0.000681782674967299,5.97917128925526E-8,2.21447601020207E-7,4.21648276013917E-8,1.00013051881381,10.005763053894,2,20,10,5,2.23047058486103,0.196980044151939,0.0404026173055172,172.741912841797,48.9996681213379,49.0004043579102,199.494216918945,199.494216918945,,,748.855834960937,0,1,,,,,,1,1,1,48.9999694824219,0,49.0001337387983,,,,,,,,,,,,,,,,,,,,,,,,,,,,,,,,,
,3754616926.77147,48.9991283416748,199.494216918945,,,5,,,,-2.43000010959804,,,,,0.00068220743751122,6.36808930925015E-8,0.01651126861025,5.94928277431135E-5,0.00068211843805373,6.36725854068534E-8,0.000682118409730328,4.90713324564922E-8,1.96570160918268E-7,4.05734206511782E-8,1.00013047507958,10.005763053894,2,20,10,5,2.23157604496138,0.196995292265953,0.0404026173055172,172.741912841797,48.9988441467285,49.0000419616699,199.494216918945,199.494216918945,,,749.104553222656,0,1,,,,,,1,1,1,48.9992561340332,0,48.9994343028349,,,,,,,,,,,,,,,,,,,,,,,,,,,,,,,,,
,3754617131.71865,48.999963760376,199.494216918945,,,5,,,,-2.43000010959804,,,,,0.000682548152125452,6.88324909905059E-8,0.0181411692101179,7.25735236378149E-5,0.000682459082128769,6.8823508606296E-8,0.000682459047920437,4.77928331399913E-8,2.16082329034256E-7,4.95229284002255E-8,1.0001305133143,10.005763053894,2,20,10,5,2.23268495285845,0.197157187436297,0.0404026173055172,172.741912841797,48.9995651245117,49.0004425048828,199.494216918945,199.494216918945,,,749.129455566406,0,1,,,,,,1,1,1,49.0001754760742,0,49.0000177271226,,,,,,,,,,,,,,,,,,,,,,,,,,,,,,,,,
,3754617336.6192,49.0001087188721,199.494216918945,,,5,,,,-2.43000010959804,,,,,0.000682965629113483,5.6602996614873E-8,0.0170356265852902,4.53393025637689E-5,0.00068287657844866,5.65956162515507E-8,0.000682876548264216,4.73823728016359E-8,2.03038170031916E-7,3.09511635739204E-8,1.00013040521177,10.005763053894,2,20,10,5,2.23405436896988,0.197234671070166,0.0404026173055172,172.741912841797,48.9996299743652,49.0005798339844,199.494216918945,199.494216918945,,,749.117004394531,0,1,,,,,,1,1,1,49.0000953674316,0,49.0001099904378,,,,,,,,,,,,,,,,,,,,,,,,,,,,,,,,,
,3754617543.21719,48.9993305206299,199.494216918945,,,5,,,,-2.43000010959804,,,,,0.000683182316125141,6.26051513172496E-8,0.0162587141926487,7.6568775424937E-5,0.000683093183166941,6.25969833916407E-8,0.00068309315566413,3.4393634038015E-8,1.93840048558351E-7,5.23016277700076E-8,1.00013048433273,10.005763053894,2,20,10,5,2.23476585054968,0.197266947200287,0.0404026173055172,172.741912841797,48.9986114501953,49.0006217956543,199.494216918945,199.494216918945,,,749.104553222656,0,1,,,,,,1,1,1,48.9997329711914,0,48.9994780596565,,,,,,,,,,,,,,,,,,,,,,,,,,,,,,,,,
,3754617749.06978,49.0002288818359,199.494216918945,,,5,,,,-2.43000010959804,,,,,0.000683440955589217,7.84449997861972E-8,0.0149610819096226,8.03779433057034E-5,0.000683351839189814,7.84347710519152E-8,0.000683351815893076,5.59988548688248E-8,1.78436925196109E-7,5.49194097141134E-8,1.00013041071128,10.005763053894,2,20,10,5,2.23561635822618,0.19729099408732,0.0404026173055172,172.741912841797,48.9998931884766,49.0008163452148,199.494216918945,199.494216918945,,,749.117004394531,0,1,,,,,,1,1,1,49.0003395080566,0,49.0002999305725,,,,,,,,,,,,,,,,,,,,,,,,,,,,,,,,,
,3754617951.67425,48.9991874694824,199.494216918945,,,5,,,,-2.43000010959804,,,,,0.000683648255280541,5.9876458463092E-8,0.0191779459086687,7.3449938454971E-5,0.000683559066007219,5.98686469346076E-8,0.000683559027715491,3.26135747035897E-8,2.28799724166206E-7,5.0205673293305E-8,1.00013047778569,10.005763053894,2,20,10,5,2.23627992890153,0.197515427719295,0.0404026173055172,172.741912841797,48.998649597168,49.0003814697266,199.494216918945,199.494216918945,,,749.129455566406,0,1,,,,,,1,1,1,48.9990501403809,0,48.9995126163258,,,,,,,,,,,,,,,,,,,,,,,,,,,,,,,,,
,3754618154.97547,48.9991760253906,199.494216918945,,,5,,,,-2.43000010959804,,,,,0.000683830802174198,9.54139534531543E-8,0.017157692018297,0.000114887573881858,0.00068374158944374,9.54015057259033E-8,0.0006837415587864,5.41419010171001E-8,2.04752034724678E-7,7.85499958562958E-8,1.00013047726193,10.005763053894,2,20,10,5,2.23688402239676,0.197489295738542,0.0404026173055172,172.741912841797,48.9987525939941,49.000171661377,199.494216918945,199.494216918945,,,749.141845703125,0,1,,,,,,1,1,1,48.9989776611328,0,48.9996356964111,,,,,,,,,,,,,,,,,,,,,,,,,,,,,,,,,
,3754618359.01853,48.9996452331543,199.494216918945,,,5,,,,-2.43000010959804,,,,,0.000684160138363615,7.45712764061572E-8,0.0175177328000444,6.72424364863065E-5,0.000684070867979858,7.45615462186049E-8,0.000684070836006987,5.86895996109546E-8,2.09149270621793E-7,4.59886406845754E-8,1.00013049873622,10.005763053894,2,20,10,5,2.23796007501646,0.197598468362903,0.0404026173055172,172.741912841797,48.999080657959,48.9998931884766,199.494216918945,199.494216918945,,,749.17919921875,0,1,,,,,,1,1,1,48.9995460510254,0,48.9995521096622,,,,,,,,,,,,,,,,,,,,,,,,,,,,,,,,,
,3754618564.05511,48.9999942779541,199.494216918945,,,5,,,,-2.43000010959804,,,,,0.000684347192840422,7.39667766539163E-8,0.016476041903549,7.75443221286595E-5,0.000684257887120034,7.39571241612299E-8,0.000684257858828902,5.15257044881329E-8,1.96766001989276E-7,5.30542928630773E-8,1.000130514711,10.005763053894,2,20,10,5,2.23857554319698,0.197611792863884,0.0404026173055172,172.741912841797,48.9993133544922,49.000186920166,199.494216918945,199.494216918945,,,749.228942871094,0,1,,,,,,1,1,1,48.9998016357422,0,48.9998067968032,,,,,,,,,,,,,,,,,,,,,,,,,,,,,,,,,
,3754618768.91958,49.0005302429199,199.494216918945,,,5,,,,-2.43000010959804,,,,,0.000684584137266086,8.37539157686629E-8,0.0131765472332068,8.38770241324376E-5,0.00068449486236337,8.37429936302794E-8,0.000684494844262553,6.0971415991145E-8,1.57416111308109E-7,5.74053605005296E-8,1.00013042450371,10.005763053894,2,20,10,5,2.23936199504135,0.19755125212998,0.0404026173055172,172.741912841797,48.9997901916504,49.0007667541504,199.494216918945,199.494216918945,,,749.266235351562,0,1,,,,,,1,1,1,49.0004959106445,0,49.0003352445715,,,,,,,,,,,,,,,,,,,,,,,,,,,,,,,,,
,3754618973.87786,49.0003147125244,199.494216918945,,,5,,,,-2.43000010959804,,,,,0.000684748238454846,7.33352709468502E-8,0.0173360115091974,5.66581160354184E-5,0.00068465887035947,7.33256997889847E-8,0.000684658839019589,6.22330790835484E-8,2.07157559879483E-7,3.87775981376506E-8,1.00013052937637,10.005763053894,2,20,10,5,2.23988444010998,0.197761214982702,0.0404026173055172,172.741912841797,48.999454498291,49.0006332397461,199.494216918945,199.494216918945,,,749.315979003906,0,1,,,,,,1,1,1,49.00048828125,0,48.999989677878,,,,,,,,,,,,,,,,,,,,,,,,,,,,,,,,,
,3754619178.84767,49.0003719329834,199.494216918945,,,5,,,,-2.43000010959804,,,,,0.000685086368422307,6.44963621510816E-8,0.0194076076196845,5.45384577028849E-5,0.000684997032987307,6.4487951809212E-8,0.000684996993690485,5.25717163583913E-8,2.32026747792326E-7,3.7348501545311E-8,1.00013041725832,10.005763053894,2,20,10,5,2.24098334389298,0.197939896242082,0.0404026173055172,172.741912841797,48.9999847412109,49.0006408691406,199.494216918945,199.494216918945,,,749.328430175781,0,1,,,,,,1,1,1,49.0002670288086,0,49.000311458812,,,,,,,,,,,,,,,,,,,,,,,,,,,,,,,,,
,3754619383.77364,49.0007038116455,199.494216918945,,,5,,,,-2.43000010959804,,,,,0.000684969197701914,6.60544555937042E-8,0.0165306071915952,6.94103011981455E-5,0.000684879867144632,6.6045841073009E-8,0.000684879838639914,4.58554571990696E-8,1.9759710045568E-7,4.75324117640317E-8,1.00013043244745,10.005763053894,2,20,10,5,2.24061000195686,0.197793533647584,0.0404026173055172,172.741912841797,48.9992904663086,49.0010108947754,199.494216918945,199.494216918945,,,749.36572265625,0,1,,,,,,1,1,1,49.0005226135254,0,49.000322005328,,,,,,,,,,,,,,,,,,,,,,,,,,,,,,,,,
,3754619589.0693,49.0002384185791,199.494216918945,,,5,,,,-2.43000010959804,,,,,0.00068556238819492,6.88183582401619E-8,0.0154706346628304,5.94985879003381E-5,0.000685472994874907,6.88093847293234E-8,0.000685472969886916,5.5427073934276E-8,1.85086968642507E-7,4.07746355215144E-8,1.00013041114775,10.005763053894,2,20,10,5,2.24255405543793,0.197923339840352,0.0404026173055172,172.741912841797,48.9997444152832,49.0004920959473,199.494216918945,199.494216918945,,,749.390625,0,1,,,,,,1,1,1,48.9999847412109,0,49.0000659718233,,,,,,,,,,,,,,,,,,,,,,,,,,,,,,,,,
,3754619793.95629,49.0003910064697,199.494216918945,,,5,,,,-2.43000010959804,,,,,0.000685687544531071,6.63280260998397E-8,0.0168342667860477,5.08732331008916E-5,0.000685598130104149,6.63193768506446E-8,0.000685598100511573,5.64147691635416E-8,2.01437902795213E-7,3.48659370458064E-8,1.00013041813126,10.005763053894,2,20,10,5,2.24295874441036,0.198012853470382,0.0404026173055172,172.741912841797,48.9991798400879,49.0006332397461,199.494216918945,199.494216918945,,,749.415466308594,0,1,,,,,,1,1,1,49.0003471374512,0,48.99973005407,,,,,,,,,,,,,,,,,,,,,,,,,,,,,,,,,
,3754619998.95102,49.0014533996582,199.494216918945,,,5,,,,-2.43000010959804,,,,,0.000685994782441336,7.05133876632301E-8,0.0150079392325848,4.84347467644483E-5,0.000685905294604038,7.05041892105246E-8,0.000685905271073545,6.21951670785673E-8,1.79664627141698E-7,3.32054496777645E-8,1.00013046675394,10.005763053894,2,20,10,5,2.24397006696108,0.198030045746536,0.0404026173055172,172.741912841797,48.9999122619629,49.0017433166504,199.494216918945,199.494216918945,,,749.440368652344,0,1,,,,,,1,1,1,49.0014610290527,0,49.0006603914149,,,,,,,,,,,,,,,,,,,,,,,,,,,,,,,,,
,3754620203.86919,49.0009212493897,199.494216918945,,,5,,,,-2.43000010959804,,,,,0.000686398726482467,1.0662546197942E-7,0.0201984556406325,6.23930285957118E-5,0.000686309202663648,1.06611555312389E-7,0.000686309160017394,9.76484657034695E-8,2.41944272622469E-7,4.27878589308343E-8,1.00013044239895,10.005763053894,2,20,10,5,2.24527345594089,0.198350059624589,0.0404026173055172,172.741912841797,48.9997711181641,49.001522064209,199.494216918945,199.494216918945,,,749.490112304687,0,1,,,,,,1,1,1,49.0011367797852,0,49.0005358527688,,,,,,,,,,,,,,,,,,,,,,,,,,,,,,,,,
,3754620408.83186,49.0012054443359,199.494216918945,,,5,,,,-2.43000010959804,,,,,0.000686441861216542,6.08232953759754E-8,0.0136513886567347,5.99747340082149E-5,0.000686352322845785,6.08153616832919E-8,0.000686352303364145,4.47722167684695E-8,1.63531455642917E-7,4.11577067182658E-8,1.00013045540574,10.005763053894,2,20,10,5,2.24543720535496,0.198105945188801,0.0404026173055172,172.741912841797,48.999382019043,49.0014915466309,199.494216918945,199.494216918945,,,749.415466308594,0,1,,,,,,1,1,1,49.000919342041,0,49.0005636776195,,,,,,,,,,,,,,,,,,,,,,,,,,,,,,,,,
,3754620615.1275,48.9989814758301,199.494216918945,,,5,,,,-2.43000010959804,,,,,0.000686817092636804,7.57715883071788E-8,0.0144146743391227,6.00452510680035E-5,0.000686727496427983,7.57617038020879E-8,0.000686727474695025,6.35659183723396E-8,1.72769324380091E-7,4.12214723715244E-8,1.00013046835795,10.005763053894,2,20,10,5,2.24666199278859,0.198244173879056,0.0404026173055172,172.741912841797,48.9987564086914,48.9999542236328,199.494216918945,199.494216918945,,,749.589599609375,0,1,,,,,,1,1,1,48.9989738464355,0,48.999080657959,,,,,,,,,,,,,,,,,,,,,,,,,,,,,,,,,
,3754620818.7556,49.0000171661377,199.494216918945,,,5,,,,-2.43000010959804,,,,,0.000686811969363027,6.35722227247599E-8,0.0144370784837689,5.75275042458553E-5,0.000686722341275758,6.35639266306607E-8,0.000686722319475353,4.98030235337968E-8,1.73036553772351E-7,3.94972355437706E-8,1.00013051575853,10.005763053894,2,20,10,5,2.24664515684837,0.198243568835962,0.0404026173055172,172.741912841797,48.9993476867676,49.0002555847168,199.494216918945,199.494216918945,,,749.614501953125,0,1,,,,,,1,1,1,49.0001525878906,0,48.9998682807474,,,,,,,,,,,,,,,,,,,,,,,,,,,,,,,,,
,3754621023.75364,49.0000743865967,199.494216918945,,,5,,,,-2.43000010959804,,,,,0.000686830345001428,9.43403750655882E-8,0.0178898078350489,0.000102077949604985,0.000686740712717948,9.43280635197996E-8,0.000686740679242308,6.31232212378648E-8,2.14425203528284E-7,7.00945255205492E-8,1.00013051837734,10.005763053894,2,20,10,5,2.24669331491541,0.19838426251212,0.0404026173055172,172.741912841797,48.9990386962891,49.0001983642578,199.494216918945,199.494216918945,,,749.614501953125,0,1,,,,,,1,1,1,49.0000991821289,0,48.9998451681698,,,,,,,,,,,,,,,,,,,,,,,,,,,,,,,,,
,3754621228.73449,48.9996795654297,199.494216918945,,,5,,,,-2.43000010959804,,,,,0.000687395734902129,9.11502470218149E-8,0.0196531269895281,8.13288422214478E-5,0.00068730604125239,9.1138353438665E-8,0.000687306000819181,7.19932739063668E-8,2.35754060060204E-7,5.5885310947993E-8,1.00013050030751,10.005763053894,2,20,10,5,2.24853665235142,0.198616771169516,0.0404026173055172,172.741912841797,48.9994316101074,49.0005874633789,199.494216918945,199.494216918945,,,749.626953125,0,1,,,,,,1,1,1,48.9998893737793,0,48.9999021642348,,,,,,,,,,,,,,,,,,,,,,,,,,,,,,,,,
,3754621433.56218,49.0009250640869,199.494216918945,,,5,,,,-2.43000010959804,,,,,0.00068720059494041,8.12921037844996E-8,0.0157588901907308,9.01574696896201E-5,0.000687110966417643,8.12815012162997E-8,0.000687110940427847,5.2628181848691E-8,1.88986103760518E-7,6.19431748885738E-8,1.00013044257354,10.005763053894,2,20,10,5,2.24791182171709,0.198407600219356,0.0404026173055172,172.741912841797,49.0002479553223,49.0011940002441,199.494216918945,199.494216918945,,,749.664245605469,0,1,,,,,,1,1,1,49.0006561279297,0,49.0005964981882,,,,,,,,,,,,,,,,,,,,,,,,,,,,,,,,,
,3754621638.62853,48.9997863769531,199.494216918945,,,5,,,,-2.43000010959804,,,,,0.00068751605233868,6.5253532472501E-8,0.0180179185881792,6.12323522755375E-5,0.000687426339629512,6.52450176586855E-8,0.000687426305638809,4.98574212159843E-8,2.16176334870168E-7,4.20850315311049E-8,1.00013050519597,10.005763053894,2,20,10,5,2.2489358905527,0.198587352877122,0.0404026173055172,172.741912841797,48.999382019043,49.0000801086426,199.494216918945,199.494216918945,,,749.701538085938,0,1,,,,,,1,1,1,48.9996147155762,0,48.9996776580811,,,,,,,,,,,,,,,,,,,,,,,,,,,,,,,,,
,3754621843.7359,48.9998683929443,199.494216918945,,,5,,,,-2.43000010959804,,,,,0.000687943505813266,6.52506024403377E-8,0.0143427102961127,5.36459671167057E-5,0.000687853734744862,6.52420877639936E-8,0.000687853713193075,5.3811275328985E-8,1.72188716592206E-7,3.68900618496745E-8,1.00013050894961,10.005763053894,2,20,10,5,2.250346876625,0.198566473601331,0.0404026173055172,172.741912841797,48.9993133544922,49,199.494216918945,199.494216918945,,,749.751281738281,0,1,,,,,,1,1,1,48.9999237060547,0,48.9997835159302,,,,,,,,,,,,,,,,,,,,,,,,,,,,,,,,,
,3754622047.30707,49.0012855529785,199.494216918945,,,5,,,,-2.43000010959804,,,,,0.000688070506061424,9.07896528180968E-8,0.0171876658933732,0.000107346876870116,0.000687980752730813,9.07778100292348E-8,0.000687980721775527,5.2791469578007E-8,2.06381399156267E-7,7.38489778771393E-8,1.00013045907208,10.005763053894,2,20,10,5,2.25075244611866,0.198714884771286,0.0404026173055172,172.741912841797,48.9998474121094,49.0017433166504,199.494216918945,199.494216918945,,,749.788635253906,0,1,,,,,,1,1,1,49.0010757446289,0,49.0006408691406,,,,,,,,,,,,,,,,,,,,,,,,,,,,,,,,,
,3754622253.43584,48.9996566772461,199.494216918945,,,5,,,,-2.43000010959804,,,,,0.000688246111525693,6.6278927507825E-8,0.0171970927036291,4.92633201031698E-5,0.000688156386583396,6.6270286888072E-8,0.000688156355586233,5.69507603572081E-8,2.06547307629874E-7,3.38874876460799E-8,1.00013038452312,10.005763053894,2,20,10,5,2.25132683713704,0.19876597664426,0.0404026173055172,172.741912841797,48.9993591308594,49.0005989074707,199.494216918945,199.494216918945,,,749.825927734375,0,1,,,,,,1,1,1,48.9994468688965,0,48.9999079984777,,,,,,,,,,,,,,,,,,,,,,,,,,,,,,,,,
,3754622407.11886,49.0002384185791,199.494216918945,,,5,,,,-2.43000010959804,,,,,0.000688392841623683,8.5254103191671E-8,0.0176823989814414,6.23246733843105E-5,0.000688303079229121,8.52429865559567E-8,0.000688303046450791,7.36724783625118E-8,2.12421396083898E-7,4.28804464634434E-8,1.00013041114775,10.005763053894,2,20,10,5,2.25180512327317,0.198827422567778,0.0404026173055172,172.741912841797,48.999267578125,49.0004653930664,199.494216918945,199.494216918945,,,749.875671386719,0,1,,,,,,1,1,1,49.0002059936523,0,48.9998745637782,,,,,,,,,,,,,,,,,,,,,,,,,,,,,,,,,