File: Experimental_Data/Fig3B/Lifetime_260Oe.dat
[Header]
; MPMS3 Data File (default extension .dat)
; Copyright (c) 2007, Quantum Design, Inc. All rights reserved.
TITLE,260Oe
FILEOPENTIME,3754503369.05174,12/20/2018,9:35 pm
BYAPP,SQUID AC,0.9.1.0
INFO,MPMS3 Measurement Release 1.1.16 Build 347, MultiVu Release 2.3.3.2,APPNAME
INFO,0,MOMENT_UNITS
INFO,CoIINO3,SAMPLE_MATERIAL
INFO,40 Hours Pumped Turbo,SAMPLE_COMMENT
INFO,,SAMPLE_MASS
INFO,,SAMPLE_VOLUME
INFO,,SAMPLE_MOLECULAR_WEIGHT
INFO,,SAMPLE_SIZE
INFO,,SAMPLE_SHAPE
INFO,Brass,SAMPLE_HOLDER
INFO,Standard,SAMPLE_HOLDER_DETAIL
INFO,65.37,SAMPLE_OFFSET
DATATYPE,COMMENT,1
DATATYPE,TIME,2
STARTUPAXIS,X,2
STARTUPAXIS,Y1,5
FIELDGROUP, VSM,2,3,4,5,6,8,9,10,11,14,15
FIELDGROUP, DC, 2,3,4,14,56,57,58,59,60,61,62,63,64,65,66,67,68,69
FIELDGROUP, AC, 2,3,4,11,16,17,18,19,20,21,22,23,24,25,26,27,28,29,30
STARTUPGROUP, All
[Data]
Comment,Time Stamp (sec),Temperature (K),Magnetic Field (Oe),Moment (emu),M. Std. Err. (emu),Transport Action,Averaging Time (sec),Frequency (Hz),Peak Amplitude (mm),Center Position (mm),Lockin Signal' (V),Lockin Signal (V),Range,M. Quad. Signal (emu),AC Moment (emu),AC M. Std Err. (emu),AC Phase (deg),AC Phase Std. Err. (deg),AC Susceptibility (emu/Oe),AC Suscept. Std Err. (emu/Oe),AC X' (emu/Oe),AC X' Std Err. (emu/Oe),AC X'' (emu/Oe),AC X'' Std Err. (emu/Oe),AC Drive (Oe),AC Frequency (Hz),AC Averaging Time (sec),AC Cycles,AC Range,AC Measure Type,AC Signal' (V),AC Signal'' (V),AC Trim Coil Ratio,AC Trim Coil Phase,Min. Temperature (K),Max. Temperature (K),Min. Field (Oe),Max. Field (Oe),Mass (grams),Motor Lag (deg),Pressure (Torr),Measure Count,Measurement Number,SQUID Status (code),Motor Status (code),Measure Status (code),Motor Current (amps),Motor Temp. (C),Temp. Status (code),Field Status (code),Chamber Status (code),Chamber Temp (K),Redirection State,Average Temp (K),Rotation Angle (deg),Rotator state,DC Moment Fixed Ctr (emu),DC Moment Err Fixed Ctr (emu),DC Moment Free Ctr (emu),DC Moment Err Free Ctr (emu),DC Fixed Fit,DC Free Fit,DC Calculated Center (mm),DC Calculated Center Err (mm),DC Scan Length (mm),DC Scan Time (s),DC Number of Points,DC Squid Drift,DC Min V (V),DC Max V (V),DC Scans per Measure,Map 01,Map 02,Map 03,Map 04,Map 05,Map 06,Map 07,Map 08,Map 09,Map 10,Map 11,Map 12,Map 13,Map 14,Map 15,Map 16
,3754503373.17485,48.9739723205566,259.673980712891,,,5,,,,-2.43000010959804,,,,,0.000666366475433998,1.13228348040502E-7,0.0301483007709606,6.74939017153731E-5,0.000666279927374227,1.13213641877759E-7,0.000666279835136809,1.03916082331755E-7,3.50587894813643E-7,4.49307972335842E-8,1.00012989744433,10.005763053894,2,20,10,5,2.17970385604929,0.193080348504581,0.0404026173055172,172.741912841797,48.9125061035156,48.9843406677246,259.673980712891,259.673980712891,,,73.8069610595703,0,1,,,,,,1,1,1,48.9676475524902,0,48.9423947053797,,,,,,,,,,,,,,,,,,,,,,,,,,,,,,,,,
,3754504156.8255,48.9990100860596,259.673980712891,,,5,,,,-2.43000010959804,,,,,0.000672048274019367,9.37707727777337E-8,-0.00678190834267323,0.000112144206717797,0.000671960603542942,9.37585401321903E-8,0.000671960598835636,5.57930081183147E-8,-7.95377120479453E-8,7.53512049859138E-8,1.00013046966736,10.005763053894,2,20,10,5,2.19841424855125,0.19330957468371,0.0404026173055172,172.741912841797,48.998607635498,48.9996681213379,259.673980712891,259.673980712891,,,76.8540496826172,0,1,,,,,,1,1,1,48.9992485046387,0,48.9992390800925,,,,,,,,,,,,,,,,,,,,,,,,,,,,,,,,,
,3754504944.57478,49.0008087158203,259.673980712891,,,5,,,,-2.43000010959804,,,,,0.000674898999954521,6.82366575818312E-8,-0.00187497456525598,5.7714230675516E-5,0.000674810979467024,6.82277581407801E-8,0.000674810979105699,5.6026519666455E-8,-2.20828380970265E-8,3.89365647557809E-8,1.00013043724861,10.005763053894,2,20,10,5,2.2077229521796,0.194318632738348,0.0404026173055172,172.741912841797,48.9996948242188,49.0010528564453,259.673980712891,259.673980712891,,,79.5777740478516,0,1,,,,,,1,1,1,49.0008735656738,0,49.0004337535185,,,,,,,,,,,,,,,,,,,,,,,,,,,,,,,,,
,3754505731.37485,48.99951171875,259.673980712891,,,5,,,,-2.43000010959804,,,,,0.000676241139598772,5.73607342718247E-8,-0.00758465496033978,6.20980678491127E-5,0.000676152906630644,5.73532500956301E-8,0.000676152900706286,3.90741890348407E-8,-8.95072294299659E-8,4.19833663228835E-8,1.00013049262565,10.005763053894,2,20,10,5,2.21213273762175,0.194484625704075,0.0404026173055172,172.741912841797,48.999382019043,49.0008506774902,259.673980712891,259.673980712891,,,82.2268829345703,0,1,,,,,,1,1,1,48.9996643066406,0,48.9998929640826,,,,,,,,,,,,,,,,,,,,,,,,,,,,,,,,,
,3754506519.03641,48.9994640350342,259.673980712891,,,5,,,,-2.43000010959804,,,,,0.000677741312236052,9.90416484814559E-8,-0.00380515889838851,8.58147811119744E-5,0.000677652885010681,9.90287261790769E-8,0.000677652883516244,8.01653044829906E-8,-4.50046569823306E-8,5.81395955077089E-8,1.0001304904433,10.005763053894,2,20,10,5,2.21702726793833,0.19506231874675,0.0404026173055172,172.741912841797,48.9984321594238,48.999942779541,259.673980712891,259.673980712891,,,84.8386764526367,0,1,,,,,,1,1,1,48.9989852905273,0,48.9994688034058,,,,,,,,,,,,,,,,,,,,,,,,,,,,,,,,,
,3754507304.00797,48.999454498291,259.673980712891,,,5,,,,-2.43000010959804,,,,,0.000678897442568395,9.97401638584842E-8,-0.00348807155815756,0.000128426004738526,0.000678808864794988,9.97271504619388E-8,0.000678808863537097,4.84390059744747E-8,-4.13247522483477E-8,8.71732025307261E-8,1.00013049000683,10.005763053894,2,20,10,5,2.22080812008746,0.195407355645567,0.0404026173055172,172.741912841797,48.9988746643066,48.9996070861816,259.673980712891,259.673980712891,,,87.4255905151367,0,1,,,,,,1,1,1,48.9995193481445,0,48.9992738611558,,,,,,,,,,,,,,,,,,,,,,,,,,,,,,,,,
,3754508089.16775,49.0002040863037,259.673980712891,,,5,,,,-2.43000010959804,,,,,0.000680064625889638,7.1200414499946E-8,0.00106280235846956,7.08669939396009E-5,0.000679975950513929,7.11911304947705E-8,0.000679975950396946,5.24096725762837E-8,1.26131462039422E-8,4.81809431369933E-8,1.00013040957646,10.005763053894,2,20,10,5,2.2246106539023,0.195920000145378,0.0404026173055172,172.741912841797,48.9998321533203,49.0006256103516,259.673980712891,259.673980712891,,,90.0000686645508,0,1,,,,,,1,1,1,49.0002212524414,0,49.0001797146267,,,,,,,,,,,,,,,,,,,,,,,,,,,,,,,,,
,3754508878.36377,49.0001564025879,259.673980712891,,,5,,,,-2.43000010959804,,,,,0.000681032793717744,1.02008456865157E-7,-0.00334460595554997,0.000113193948384481,0.000680943915466819,1.01995144241581E-7,0.000680943914306637,6.68054311424517E-8,-3.97496830155242E-8,7.70716797451049E-8,1.00013052213098,10.005763053894,2,20,10,5,2.22779278636621,0.196027550883238,0.0404026173055172,172.741912841797,48.9993286132812,49.0002899169922,259.673980712891,259.673980712891,,,92.5869903564453,0,1,,,,,,1,1,1,49.0000495910645,0,48.9998727686265,,,,,,,,,,,,,,,,,,,,,,,,,,,,,,,,,
,3754509667.67744,48.9996147155762,259.673980712891,,,5,,,,-2.43000010959804,,,,,0.000682166375738601,9.34896721337226E-8,-0.0045337706633708,0.000111664289003482,0.000682077366456931,9.34774735721164E-8,0.00068207736432154,5.42021459336955E-8,-5.39722537548937E-8,7.61588172282638E-8,1.00013049733952,10.005763053894,2,20,10,5,2.23150503172615,0.196307526748692,0.0404026173055172,172.741912841797,48.9993553161621,48.9999694824219,259.673980712891,259.673980712891,,,95.1490325927734,0,1,,,,,,1,1,1,48.9996376037598,0,48.9996191660563,,,,,,,,,,,,,,,,,,,,,,,,,,,,,,,,,
,3754510454.42156,48.9999027252197,259.673980712891,,,5,,,,-2.43000010959804,,,,,0.000682968656441161,9.88334640321599E-8,4.53038244438986E-5,0.000102017802812806,0.000682879533477538,9.88205669084974E-8,0.000682879533477325,7.00953433748642E-8,5.39953461911286E-10,6.96573562610347E-8,1.0001305105209,10.005763053894,2,20,10,5,2.23411374081499,0.196716949154076,0.0404026173055172,172.741912841797,48.9989814758301,49.0003509521484,259.673980712891,259.673980712891,,,97.5742721557617,0,1,,,,,,1,1,1,48.9999732971191,0,48.9998411290786,,,,,,,,,,,,,,,,,,,,,,,,,,,,,,,,,
,3754511241.07126,48.9998607635498,259.673980712891,,,5,,,,-2.43000010959804,,,,,0.000683891634105062,8.96674797376225E-8,-0.000336043076519132,6.4857245382568E-5,0.000683802470459024,8.96557891728813E-8,0.000683802470447262,7.79278337856761E-8,-4.01054122757242E-9,4.4332981556446E-8,1.00013039386356,10.005763053894,2,20,10,5,2.23713427829305,0.196967907317156,0.0404026173055172,172.741912841797,48.9992790222168,49.0002174377441,259.673980712891,259.673980712891,,,99.9995040893555,0,1,,,,,,1,1,1,48.9997940063477,0,48.9997132245232,,,,,,,,,,,,,,,,,,,,,,,,,,,,,,,,,
,3754512025.48387,49.0000019073486,259.673980712891,,,5,,,,-2.43000010959804,,,,,0.000684292408260326,9.08240277695228E-8,-0.00428867759699703,4.9935766540191E-5,0.000684203109450323,9.08121754129839E-8,0.000684203107533612,8.41496132295194E-8,-5.12136595311572E-8,3.41422582229246E-8,1.00013051506018,10.005763053894,2,20,10,5,2.23845887449415,0.196928910642748,0.0404026173055172,172.741912841797,48.9996223449707,49.0003967285156,259.673980712891,259.673980712891,,,102.424743652344,0,1,,,,,,1,1,1,49.0000076293945,0,48.9999991522895,,,,,,,,,,,,,,,,,,,,,,,,,,,,,,,,,
,3754512809.30727,49.0008583068848,259.673980712891,,,5,,,,-2.43000010959804,,,,,0.000684958396644779,1.06683562529873E-7,-0.00471778197746797,9.77895561666932E-5,0.000684869062654179,1.06669648592298E-7,0.000684869060332468,8.3034046155305E-8,-5.63926862418621E-8,6.69608923916276E-8,1.00013043951826,10.005763053894,2,20,10,5,2.24063893377506,0.19710378735759,0.0404026173055172,172.741912841797,48.9999961853027,49.0010185241699,259.673980712891,259.673980712891,,,104.862411499023,0,1,,,,,,1,1,1,49.0009536743164,0,49.0005336337619,,,,,,,,,,,,,,,,,,,,,,,,,,,,,,,,,
,3754513595.99731,49.0007953643799,259.673980712891,,,5,,,,-2.43000010959804,,,,,0.000685654969809469,1.11458072235947E-7,-0.00120313815901962,6.74616861137442E-5,0.0006855655469447,1.11443535915844E-7,0.000685565546793551,1.01405712959632E-7,-1.43960004905663E-8,4.62227549652205E-8,1.00013043663756,10.005763053894,2,20,10,5,2.24290545974252,0.19744181799315,0.0404026173055172,172.741912841797,48.9995880126953,49.0011672973633,259.673980712891,259.673980712891,,,107.312522888184,0,1,,,,,,1,1,1,49.0010375976562,0,49.0002919365378,,,,,,,,,,,,,,,,,,,,,,,,,,,,,,,,,
,3754514382.07405,49.0011787414551,259.673980712891,,,5,,,,-2.43000010959804,,,,,0.000686219299785381,1.0940630392658E-7,-0.00108500203655026,0.000120246279107155,0.000686129791283599,1.09392033278184E-7,0.000686129791160575,7.18391430530912E-8,-1.29931423773725E-8,8.24969967340191E-8,1.00013045418362,10.005763053894,2,20,10,5,2.24475108096898,0.197608952235825,0.0404026173055172,172.741912841797,48.9996871948242,49.0018463134766,259.673980712891,259.673980712891,,,109.84969329834,0,1,,,,,,1,1,1,49.0008125305176,0,49.000500149197,,,,,,,,,,,,,,,,,,,,,,,,,,,,,,,,,
,3754515171.04228,49.0000438690186,259.673980712891,,,5,,,,-2.43000010959804,,,,,0.000686582267870205,1.19295976850989E-7,-0.00237291431812459,9.66506753485236E-5,0.000686492747675573,1.19280422416268E-7,0.000686492747086831,9.91354441123703E-8,-2.84312122747266E-8,6.63323668539449E-8,1.00013040224378,10.005763053894,2,20,10,5,2.24594286029091,0.197662996509419,0.0404026173055172,172.741912841797,48.9988670349121,49.0008239746094,259.673980712891,259.673980712891,,,112.424171447754,0,1,,,,,,1,1,1,48.9992828369141,0,48.9995865821838,,,,,,,,,,,,,,,,,,,,,,,,,,,,,,,,,
,3754515955.08191,49.0007801055908,259.673980712891,,,5,,,,-2.43000010959804,,,,,0.000687231526834207,8.20790117701852E-8,-0.00175171013373188,8.80230588813453E-5,0.000687141898835265,8.20683071134677E-8,0.000687141898514124,5.54760893494212E-8,-2.10080644253936E-8,6.0478182371542E-8,1.00013043593921,10.005763053894,2,20,10,5,2.24806456663305,0.197874283207457,0.0404026173055172,172.741912841797,48.9992980957031,49.001350402832,259.673980712891,259.673980712891,,,115.023529052734,0,1,,,,,,1,1,1,49.0004730224609,0,49.0000928990981,,,,,,,,,,,,,,,,,,,,,,,,,,,,,,,,,
,3754516740.90701,48.9998512268066,259.673980712891,,,5,,,,-2.43000010959804,,,,,0.000687727778800179,9.3816505618364E-8,-0.00477287690896944,7.43635974637714E-5,0.000687638036422576,9.38042633961764E-8,0.000687638034036715,7.86502928035758E-8,-5.72819102884395E-8,5.11211431133054E-8,1.00013050816396,10.005763053894,2,20,10,5,2.24969833892674,0.197898545358663,0.0404026173055172,172.741912841797,48.9994430541992,49.0001525878906,259.673980712891,259.673980712891,,,117.647758483887,0,1,,,,,,1,1,1,49.0001525878906,0,48.999766405891,,,,,,,,,,,,,,,,,,,,,,,,,,,,,,,,,
,3754517527.01431,49.0000667572022,259.673980712891,,,5,,,,-2.43000010959804,,,,,0.000688114040473644,7.05603211536463E-8,-0.00334415199016558,7.66719795404746E-5,0.000688024319837842,7.05511210552557E-8,0.000688024318665915,4.68529711709334E-8,-4.01575459259842E-8,5.2747130486966E-8,1.0001304032913,10.005763053894,2,20,10,5,2.25095694163008,0.198065825114869,0.0404026173055172,172.741912841797,48.9989433288574,49.0002555847168,259.673980712891,259.673980712891,,,120.321739196777,0,1,,,,,,1,1,1,49.0000534057617,0,48.9997386932373,,,,,,,,,,,,,,,,,,,,,,,,,,,,,,,,,
,3754518317.43079,49.0007362365723,259.673980712891,,,5,,,,-2.43000010959804,,,,,0.000688749696690802,8.2595815238775E-8,-0.00455923661527446,7.1977343202972E-5,0.000688659872076257,8.25850433468925E-8,0.000688659869895969,6.60631373205065E-8,-5.47992073344584E-8,4.95575551453056E-8,1.00013043393145,10.005763053894,2,20,10,5,2.25304050268949,0.198201008417721,0.0404026173055172,172.741912841797,49.0002136230469,49.0008659362793,259.673980712891,259.673980712891,,,123.08277130127,0,1,,,,,,1,1,1,49.0006561279297,0,49.0005147722032,,,,,,,,,,,,,,,,,,,,,,,,,,,,,,,,,
,3754519105.13429,49.0008583068848,259.673980712891,,,5,,,,-2.43000010959804,,,,,0.000689199313205028,1.26870133240507E-7,-0.00124115837077454,0.000109610295476025,0.000689109426103462,1.26853586519793E-7,0.000689109425941778,1.01926544899499E-7,-1.49276951948227E-8,7.55169640397769E-8,1.00013043951826,10.005763053894,2,20,10,5,2.25449980056913,0.198460954912419,0.0404026173055172,172.741912841797,49.0001487731934,49.0011558532715,259.673980712891,259.673980712891,,,125.856246948242,0,1,,,,,,1,1,1,49.0008735656738,0,49.0005331039429,,,,,,,,,,,,,,,,,,,,,,,,,,,,,,,,,
,3754519889.12132,49.0006866455078,259.673980712891,,,5,,,,-2.43000010959804,,,,,0.000689517162300632,1.0800769943361E-7,-0.00612212885351226,0.00011602042401388,0.000689427239160133,1.07993613647118E-7,0.000689427235224468,7.25663975671242E-8,-7.36662005665579E-8,7.9979613231704E-8,1.00013043166181,10.005763053894,2,20,10,5,2.25555645055167,0.198360335953187,0.0404026173055172,172.741912841797,48.9995765686035,49.0009002685547,259.673980712891,259.673980712891,,,128.679473876953,0,1,,,,,,1,1,1,49.0004997253418,0,49.0003588199615,,,,,,,,,,,,,,,,,,,,,,,,,,,,,,,,,
,3754520674.59612,48.9999847412109,259.673980712891,,,5,,,,-2.43000010959804,,,,,0.000689997347595115,1.12691345642059E-7,-0.00441595293187813,9.50222931539273E-5,0.000689907304843729,1.12676639732167E-7,0.000689907302794623,9.16533291653269E-8,-5.31731692704683E-8,6.55415318271158E-8,1.00013051427453,10.005763053894,2,20,10,5,2.25712132601899,0.198565691553726,0.0404026173055172,172.741912841797,48.9994468688965,49.0002975463867,259.673980712891,259.673980712891,,,131.564880371094,0,1,,,,,,1,1,1,48.9999198913574,0,48.999849431655,,,,,,,,,,,,,,,,,,,,,,,,,,,,,,,,,
,3754521462.25171,49.0001316070557,259.673980712891,,,5,,,,-2.43000010959804,,,,,0.000690491037292846,9.59813287843869E-8,-0.00305710493686639,7.51152018716627E-5,0.000690401004680414,9.59688138503639E-8,0.000690401003697655,8.07597381764206E-8,-3.6837413449321E-8,5.18447482540112E-8,1.00013040625929,10.005763053894,2,20,10,5,2.25873157180787,0.198761334643545,0.0404026173055172,172.741912841797,48.9990768432617,49.0009384155273,259.673980712891,259.673980712891,,,134.512481689453,0,1,,,,,,1,1,1,48.9995880126953,0,48.9998319289264,,,,,,,,,,,,,,,,,,,,,,,,,,,,,,,,,
,3754522250.62947,48.9996814727783,259.673980712891,,,5,,,,-2.43000010959804,,,,,0.000690362684836282,6.48925578290479E-8,-0.00231804631978072,5.99690114949959E-5,0.000690272603988938,6.48840904296302E-8,0.000690272603424014,4.99699853359941E-8,-2.79267318201013E-8,4.13877488684872E-8,1.00013050039481,10.005763053894,2,20,10,5,2.25830914223171,0.19875351757692,0.0404026173055172,172.741912841797,48.9995002746582,49.0007209777832,259.673980712891,259.673980712891,,,137.497375488281,0,1,,,,,,1,1,1,48.9996185302734,0,49.0000302931842,,,,,,,,,,,,,,,,,,,,,,,,,,,,,,,,,
,3754523035.11861,49.0003051757812,259.673980712891,,,5,,,,-2.43000010959804,,,,,0.000691161123560415,7.51645422914143E-8,-0.00439875485303975,8.54568797831619E-5,0.000691070998086959,7.51547410457566E-8,0.000691070996050353,4.64872910367579E-8,-5.30554244916028E-8,5.90522385157286E-8,1.00013041420303,10.005763053894,2,20,10,5,2.2609282138538,0.1989012762305,0.0404026173055172,172.741912841797,48.9998817443848,49.0005302429199,259.673980712891,259.673980712891,,,140.532028198242,0,1,,,,,,1,1,1,49.0005302429199,0,49.0002149694106,,,,,,,,,,,,,,,,,,,,,,,,,,,,,,,,,
,3754523821.10005,48.9992504119873,259.673980712891,,,5,,,,-2.43000010959804,,,,,0.000691486169224617,8.82170998517092E-8,-0.00477745050868705,8.09719845405339E-5,0.000691395955419614,8.82055907274517E-8,0.000691395953016115,6.81700016530454E-8,-5.76501442718285E-8,5.59738966858884E-8,1.00013048066639,10.005763053894,2,20,10,5,2.26199281894285,0.198979871295346,0.0404026173055172,172.741912841797,48.9989013671875,49.0020484924316,259.673980712891,259.673980712891,,,143.66618347168,0,1,,,,,,1,1,1,48.9994125366211,0,49.0002926097197,,,,,,,,,,,,,,,,,,,,,,,,,,,,,,,,,
,3754524614.64693,49.0001697540283,259.673980712891,,,5,,,,-2.43000010959804,,,,,0.000691915542297549,1.0042059974701E-7,-0.00529364813138855,0.000121141108119903,0.000691825322737284,1.00407505804474E-7,0.000691825319784503,5.5304588574991E-8,-6.39188410188044E-8,8.38037571020921E-8,1.00013040800517,10.005763053894,2,20,10,5,2.26339918012486,0.199083031693533,0.0404026173055172,172.741912841797,48.9993858337402,49.0002708435059,259.673980712891,259.673980712891,,,146.899826049805,0,1,,,,,,1,1,1,49.0001258850098,0,48.999968846639,,,,,,,,,,,,,,,,,,,,,,,,,,,,,,,,,
,3754525400.89691,48.9995784759521,259.673980712891,,,5,,,,-2.43000010959804,,,,,0.000692189697422561,9.31868539450508E-8,-0.0018514234370608,8.95363551634225E-5,0.000692099381442504,9.31746950497742E-8,0.000692099381081173,6.95891306423075E-8,-2.23641082509814E-8,6.19586692406016E-8,1.00013049568094,10.005763053894,2,20,10,5,2.2642840290088,0.199297947973482,0.0404026173055172,172.741912841797,48.998592376709,49.0019912719727,259.673980712891,259.673980712891,,,150.183227539062,0,1,,,,,,1,1,1,49.000129699707,0,49.0002484041102,,,,,,,,,,,,,,,,,,,,,,,,,,,,,,,,,
,3754526187.22564,49.0003204345703,259.673980712891,,,5,,,,-2.43000010959804,,,,,0.000692609456570863,9.1183944016795E-8,-0.00236866316118167,8.54033593418631E-5,0.000692519141755284,9.11720538223866E-8,0.0006925191411635,6.93941448617032E-8,-2.8629413771168E-8,5.91337133715203E-8,1.00013041490139,10.005763053894,2,20,10,5,2.26565894100718,0.199398354526705,0.0404026173055172,172.741912841797,48.9989814758301,49.0010604858398,259.673980712891,259.673980712891,,,153.503952026367,0,1,,,,,,1,1,1,48.9998397827148,0,48.9996082782745,,,,,,,,,,,,,,,,,,,,,,,,,,,,,,,,,
,3754526974.10707,49.0000915527344,259.673980712891,,,5,,,,-2.43000010959804,,,,,0.000692811580879316,7.41777641232174E-8,-0.00436962530811513,8.01294381273218E-5,0.00069272116749235,7.41680837670036E-8,0.00069272116547783,4.91978427648167E-8,-5.28299286218152E-8,5.5502044259267E-8,1.00013051916299,10.005763053894,2,20,10,5,2.2663270930967,0.199377394741472,0.0404026173055172,172.741912841797,48.9995002746582,49.0006332397461,259.673980712891,259.673980712891,,,156.911712646484,0,1,,,,,,1,1,1,49.0004692077637,0,49.0000511618222,,,,,,,,,,,,,,,,,,,,,,,,,,,,,,,,,
,3754527760.19744,49.0015048980713,259.673980712891,,,5,,,,-2.43000010959804,,,,,0.000693111658614944,8.87790671311273E-8,-0.00148100827405973,8.33797809353181E-5,0.000693021240749846,8.87674857161913E-8,0.000693021240518327,6.73926722259878E-8,-1.7913539186617E-8,5.77745121192278E-8,1.00013046911088,10.005763053894,2,20,10,5,2.26729864941589,0.199578056460519,0.0404026173055172,172.741912841797,48.9999694824219,49.0019760131836,259.673980712891,259.673980712891,,,160.406539916992,0,1,,,,,,1,1,1,49.0011558532715,0,49.0007557868958,,,,,,,,,,,,,,,,,,,,,,,,,,,,,,,,,
,3754528548.82335,49.000036239624,259.673980712891,,,5,,,,-2.43000010959804,,,,,0.000693212311376923,1.22988535742793E-7,-0.00266996902907657,0.000118666887414312,0.000693121847448198,1.22972485788184E-7,0.000693121846695628,9.14279616786381E-8,-3.22993051341712E-8,8.22384343492428E-8,1.00013051663147,10.005763053894,2,20,10,5,2.26763204473967,0.199559987289718,0.0404026173055172,172.741912841797,48.9990348815918,49.0002479553223,259.673980712891,259.673980712891,,,164.038162231445,0,1,,,,,,1,1,1,49.0000267028809,0,48.9997798071967,,,,,,,,,,,,,,,,,,,,,,,,,,,,,,,,,
,3754529336.36899,49.0002155303955,259.673980712891,,,5,,,,-2.43000010959804,,,,,0.000693707727860414,1.27966348008946E-7,-0.0103829520199286,0.000101069496942022,0.000693617273162304,1.2794966208069E-7,0.000693617261773285,1.07047434956897E-7,-1.2569503180206E-7,7.00853957377126E-8,1.00013041010022,10.005763053894,2,20,10,5,2.26927951113563,0.199397123491237,0.0404026173055172,172.741912841797,48.9994163513184,49.0007171630859,259.673980712891,259.673980712891,,,167.794174194336,0,1,,,,,,1,1,1,49.0003242492676,0,48.9999470430262,,,,,,,,,,,,,,,,,,,,,,,,,,,,,,,,,
,3754530124.29329,49.0000057220459,259.673980712891,,,5,,,,-2.43000010959804,,,,,0.000693818375176107,1.10646581061306E-7,-0.0014878902257971,9.54410557434286E-5,0.000693727912710884,1.10632154573266E-7,0.00069372791247697,8.8642980044251E-8,-1.80151311203202E-8,6.6195888953903E-8,1.0001304004979,10.005763053894,2,20,10,5,2.26961047556849,0.199781287040813,0.0404026173055172,172.741912841797,48.9990386962891,49.0010261535645,259.673980712891,259.673980712891,,,171.662109375,0,1,,,,,,1,1,1,48.9992713928223,0,48.9998366411994,,,,,,,,,,,,,,,,,,,,,,,,,,,,,,,,,
,3754530910.29579,49.000150680542,259.673980712891,,,5,,,,-2.43000010959804,,,,,0.000694343211461675,8.1349342038449E-8,-0.00468902345496325,6.85109280428566E-5,0.000694252675961159,8.1338734887293E-8,0.000694252673636243,6.59900474786459E-8,-5.68168738654776E-8,4.75531642147124E-8,1.00013040713223,10.005763053894,2,20,10,5,2.27133848079722,0.199805508223602,0.0404026173055172,172.741912841797,48.9992332458496,49.0006942749023,259.673980712891,259.673980712891,,,175.641983032227,0,1,,,,,,1,1,1,48.9998931884766,0,48.9999766879612,,,,,,,,,,,,,,,,,,,,,,,,,,,,,,,,,
,3754531697.28476,48.9995899200439,259.673980712891,,,5,,,,-2.43000010959804,,,,,0.000694410112910387,9.47815099010003E-8,-0.00432628496132192,9.30368095980014E-5,0.000694319506849894,9.47691428875308E-8,0.000694319504870581,6.93507926500261E-8,-5.24266196133509E-8,6.45883735857338E-8,1.0001304962047,10.005763053894,2,20,10,5,2.27155606386521,0.199839142258004,0.0404026173055172,172.741912841797,48.9994773864746,49.0012702941895,259.673980712891,259.673980712891,,,179.733795166016,0,1,,,,,,1,1,1,48.9996070861816,0,49.0001888275146,,,,,,,,,,,,,,,,,,,,,,,,,,,,,,,,,
,3754532485.23205,49.0001888275146,259.673980712891,,,5,,,,-2.43000010959804,,,,,0.000695060890909661,1.32605080618025E-7,-0.00424055436305437,8.93241790448604E-5,0.000694970260617655,1.32587789993081E-7,0.000694970258714228,1.17171152980008E-7,-5.14358857355593E-8,6.20519376376354E-8,1.00013040887811,10.005763053894,2,20,10,5,2.27368459141348,0.200029824016549,0.0404026173055172,172.741912841797,48.9991569519043,49.000617980957,259.673980712891,259.673980712891,,,184.012161254883,0,1,,,,,,1,1,1,49.000316619873,0,48.9997500251321,,,,,,,,,,,,,,,,,,,,,,,,,,,,,,,,,
,3754533270.42124,49.0007781982422,259.673980712891,,,5,,,,-2.43000010959804,,,,,0.000694975375671379,8.63742184005721E-8,-0.00606113342726466,9.66029402240731E-5,0.000694884737788625,8.63629535751488E-8,0.000694884733900455,5.43427931931864E-8,-7.35095872722951E-8,6.71224297696819E-8,1.00013043585191,10.005763053894,2,20,10,5,2.27341120797613,0.199932974419074,0.0404026173055172,172.741912841797,48.9993019104004,49.0011672973633,259.673980712891,259.673980712891,,,188.365142822266,0,1,,,,,,1,1,1,49.0007133483887,0,49.0000960826874,,,,,,,,,,,,,,,,,,,,,,,,,,,,,,,,,
,3754534054.31176,49.0010204315186,259.673980712891,,,5,,,,-2.43000010959804,,,,,0.000695278443082394,7.17998299617784E-8,-0.00462918596341222,5.71642262561909E-5,0.00069518775796787,7.17904651154097E-8,0.000695187755698861,5.97950544206427E-8,-5.61673727972381E-8,3.97293638046123E-8,1.00013044693823,10.005763053894,2,20,10,5,2.27439760580828,0.200077004321608,0.0404026173055172,172.741912841797,48.9999542236328,49.0013885498047,259.673980712891,259.673980712891,,,192.867370605469,0,1,,,,,,1,1,1,49.0006790161133,0,49.0005669063992,,,,,,,,,,,,,,,,,,,,,,,,,,,,,,,,,
,3754534842.81968,49.0001106262207,259.673980712891,,,5,,,,-2.43000010959804,,,,,0.000695509857602026,1.20465997843395E-7,-0.00360819449204186,0.000154515848537474,0.000695419091477222,1.20450276668957E-7,0.000695419090098263,5.44321277453673E-8,-4.37939295912262E-8,1.07449581752282E-7,1.00013052003593,10.005763053894,2,20,10,5,2.27515104292461,0.200184141260775,0.0404026173055172,172.741912841797,48.9995346069336,49.0005645751953,259.673980712891,259.673980712891,,,197.618347167969,0,1,,,,,,1,1,1,49.0003318786621,0,49.0000006731819,,,,,,,,,,,,,,,,,,,,,,,,,,,,,,,,,
,3754535630.44346,49.0010223388672,259.673980712891,,,5,,,,-2.43000010959804,,,,,0.000695743490396358,1.50029819944982E-7,-0.0041616268087612,0.000198233102702424,0.00069565274456503,1.50010251553868E-7,0.000695652742729998,5.90532703700481E-8,-5.05281040493312E-8,1.37897740481332E-7,1.00013044702553,10.005763053894,2,20,10,5,2.27591723658184,0.200229400885455,0.0404026173055172,172.741912841797,48.9998970031738,49.001392364502,259.673980712891,259.673980712891,,,202.493698120117,0,1,,,,,,1,1,1,49.0007820129395,0,49.0006875991821,,,,,,,,,,,,,,,,,,,,,,,,,,,,,,,,,
,3754536415.1626,49.00075340271,259.673980712891,,,5,,,,-2.43000010959804,,,,,0.000696031377271694,1.24266658813588E-7,-0.00460643808137551,0.000112038615666738,0.000695940602456099,1.24250452241002E-7,0.000695940600206903,9.67508033387957E-8,-5.59518923962561E-8,7.7958045995209E-8,1.00013043471709,10.005763053894,2,20,10,5,2.27686052759416,0.200294576666872,0.0404026173055172,172.741912841797,48.9997825622559,49.0008697509766,259.673980712891,259.673980712891,,,207.530715942383,0,1,,,,,,1,1,1,49.0006675720215,0,49.000363742604,,,,,,,,,,,,,,,,,,,,,,,,,,,,,,,,,
,3754537199.20888,48.9994068145752,259.673980712891,,,5,,,,-2.43000010959804,,,,,0.00069617733869455,1.10504030759803E-7,-0.00445719701980352,6.78722806215819E-5,0.000696086507880481,1.10489613210547E-7,0.000696086505774223,9.98908108194321E-8,-5.41504929627944E-8,4.72205521066057E-8,1.00013048782449,10.005763053894,2,20,10,5,2.27733747490879,0.200342516067319,0.0404026173055172,172.741912841797,48.9988746643066,48.999927520752,259.673980712891,259.673980712891,,,212.704559326172,0,1,,,,,,1,1,1,48.9995193481445,0,48.9994654935949,,,,,,,,,,,,,,,,,,,,,,,,,,,,,,,,,
,3754537986.99159,49.0000438690186,259.673980712891,,,5,,,,-2.43000010959804,,,,,0.00069620843576787,9.02603457696717E-8,-0.00428191761393304,6.72617547969728E-5,0.000696117580603078,9.02485667992258E-8,0.000696117578659133,7.71614220253786E-8,-5.20233453896475E-8,4.68072511512452E-8,1.00013051698064,10.005763053894,2,20,10,5,2.27743858707018,0.200358429452434,0.0404026173055172,172.741912841797,48.9993782043457,49.000186920166,259.673980712891,259.673980712891,,,218.152008056641,0,1,,,,,,1,1,1,49.000186920166,0,48.9997940063477,,,,,,,,,,,,,,,,,,,,,,,,,,,,,,,,,
,3754538773.94356,49.000804901123,259.673980712891,,,5,,,,-2.43000010959804,,,,,0.000696479847145256,8.79048228996368E-8,-0.00533288967428103,4.78883297313498E-5,0.00069638901220012,8.78933583471476E-8,0.000696389009183631,8.13302040646319E-8,-6.48174402834439E-8,3.33262711437303E-8,1.00013043707403,10.005763053894,2,20,10,5,2.27833010492571,0.200394744804118,0.0404026173055172,172.741912841797,48.9998626708984,49.0010566711426,259.673980712891,259.673980712891,,,223.83576965332,0,1,,,,,,1,1,1,49.0005798339844,0,49.0004680857939,,,,,,,,,,,,,,,,,,,,,,,,,,,,,,,,,
,3754539560.7821,49.000207901001,259.673980712891,,,5,,,,-2.43000010959804,,,,,0.000696777325048205,8.50410637215085E-8,-0.00338217212638892,5.60061792634803E-5,0.000696686390413858,8.50299652288396E-8,0.000696686389200041,7.555773260487E-8,-4.11254251037076E-8,3.90015901012847E-8,1.00013052448792,10.005763053894,2,20,10,5,2.279296389878,0.200557939095498,0.0404026173055172,172.741912841797,48.9987869262695,49.00048828125,259.673980712891,259.673980712891,,,229.755844116211,0,1,,,,,,1,1,1,49.00048828125,0,48.9995867411296,,,,,,,,,,,,,,,,,,,,,,,,,,,,,,,,,
,3754540347.77449,49.0011310577393,259.673980712891,,,5,,,,-2.43000010959804,,,,,0.000696806815386767,7.27420327473383E-8,-0.0090736122281232,7.4082577328445E-5,0.000696715927399716,7.27325446413318E-8,0.000696715918663147,5.12503229239744E-8,-1.10335005225206E-7,5.16084048406039E-8,1.00013045200128,10.005763053894,2,20,10,5,2.27941277072354,0.200340001956204,0.0404026173055172,172.741912841797,48.9998359680176,49.0015678405762,259.673980712891,259.673980712891,,,235.887344360352,0,1,,,,,,1,1,1,49.0010986328125,0,49.0006480746799,,,,,,,,,,,,,,,,,,,,,,,,,,,,,,,,,
,3754541133.36706,49.0012817382812,259.673980712891,,,5,,,,-2.43000010959804,,,,,0.000697071501437659,1.02160073488032E-7,-0.00628404671452465,0.000111058413719329,0.000696980574120385,1.02146747535966E-7,0.000696980569928356,6.6659073678172E-8,-7.64429512143681E-8,7.73984878957228E-8,1.00013045889749,10.005763053894,2,20,10,5,2.28026885827231,0.200527122578526,0.0404026173055172,172.741912841797,48.9999504089355,49.0017585754395,259.673980712891,259.673980712891,,,242.192947387695,0,1,,,,,,1,1,1,49.0009994506836,0,49.0005989074707,,,,,,,,,,,,,,,,,,,,,,,,,,,,,,,,,
,3754541921.41275,49.0015258789063,259.673980712891,,,5,,,,-2.43000010959804,,,,,0.000697361177262705,1.14451435845308E-7,0.000430167922107039,8.73146171424082E-5,0.000697270204369559,1.14436505306323E-7,0.000697270204349907,9.69092163327548E-8,5.23499771723151E-9,6.08631048870778E-8,1.00013047007111,10.005763053894,2,20,10,5,2.28119292539828,0.200877774523629,0.0404026173055172,172.741912841797,49.0004196166992,49.0018043518066,259.673980712891,259.673980712891,,,248.772171020508,0,1,,,,,,1,1,1,49.0016479492188,0,49.0011196136475,,,,,,,,,,,,,,,,,,,,,,,,,,,,,,,,,
,3754542705.76435,49.0003929138184,259.673980712891,,,5,,,,-2.43000010959804,,,,,0.000697194534593734,7.81732582320682E-8,-0.00579920204503548,7.08441655997752E-5,0.000697103619581521,7.81630643444598E-8,0.000697103616010779,6.05918896700083E-8,-7.05574610160117E-8,4.93769939742559E-8,1.00013041821855,10.005763053894,2,20,10,5,2.28066962844182,0.200581816451324,0.0404026173055172,172.741912841797,48.9995155334473,49.0006828308105,259.673980712891,259.673980712891,,,255.612579345703,0,1,,,,,,1,1,1,49.0006370544434,0,49.0001200507669,,,,,,,,,,,,,,,,,,,,,,,,,,,,,,,,,
,3754543493.4968,49.0004940032959,259.673980712891,,,5,,,,-2.43000010959804,,,,,0.000697739386145386,1.05273908981962E-7,-0.00369443032529571,0.000108165252136474,0.00069764839685657,1.05260180649723E-7,0.000697648395406275,7.33934251729515E-8,-4.49843498746071E-8,7.54527055299855E-8,1.00013042284513,10.005763053894,2,20,10,5,2.28244457640058,0.200822416637151,0.0404026173055172,172.741912841797,48.9996223449707,49.000602722168,259.673980712891,259.673980712891,,,262.676849365234,0,1,,,,,,1,1,1,49.0003852844238,0,49.000052690506,,,,,,,,,,,,,,,,,,,,,,,,,,,,,,,,,
,3754544275.32835,49.0013332366943,259.673980712891,,,5,,,,-2.43000010959804,,,,,0.00069778762996407,7.52400445480776E-8,-0.000904660534210677,7.04298710299346E-5,0.000697696607589434,7.52302299179117E-8,0.000697696607502465,5.69715675991077E-8,-1.10161444887663E-8,4.91307233694168E-8,1.00013046125443,10.005763053894,2,20,10,5,2.2825926102371,0.200947440511554,0.0404026173055172,172.741912841797,48.999683380127,49.0018768310547,259.673980712891,259.673980712891,,,269.964996337891,0,1,,,,,,1,1,1,49.0010681152344,0,49.0007104312672,,,,,,,,,,,,,,,,,,,,,,,,,,,,,,,,,
,3754545062.3486,48.9995670318604,259.673980712891,,,5,,,,-2.43000010959804,,,,,0.000698055290515147,8.97704236038951E-8,-0.00639741086501822,8.05274951502885E-5,0.000697964289637703,8.97587208241476E-8,0.00069796428528693,6.99909678323704E-8,-7.79318190378323E-8,5.61951277770178E-8,1.00013038042031,10.005763053894,2,20,10,5,2.28348743788011,0.200805618840422,0.0404026173055172,172.741912841797,48.9987449645996,49.0001335144043,259.673980712891,259.673980712891,,,277.613830566406,0,1,,,,,,1,1,1,48.9993095397949,0,48.999262641458,,,,,,,,,,,,,,,,,,,,,,,,,,,,,,,,,
,3754545852.64949,48.9997615814209,259.673980712891,,,5,,,,-2.43000010959804,,,,,0.000698240382112052,1.08652780263125E-7,-0.00255594340137044,9.14749564199031E-5,0.000698149270796925,1.08638602484304E-7,0.00069814927010226,8.78958466680544E-8,-3.11441791426488E-8,6.38487751507295E-8,1.00013050406115,10.005763053894,2,20,10,5,2.28407944007402,0.201012000831325,0.0404026173055172,172.741912841797,48.9993095397949,49.000244140625,259.673980712891,259.673980712891,,,285.585998535156,0,1,,,,,,1,1,1,48.9997215270996,0,48.9996965196398,,,,,,,,,,,,,,,,,,,,,,,,,,,,,,,,,
,3754546642.7739,49.0004177093506,259.673980712891,,,5,,,,-2.43000010959804,,,,,0.000698318794733628,8.27118630235354E-8,-0.00224165581844282,8.81386115489922E-5,0.000698227652222263,8.27010677148993E-8,0.000698227651687872,5.52533606895535E-8,-2.73176504814813E-8,6.15348091221096E-8,1.00013053409024,10.005763053894,2,20,10,5,2.2843348404346,0.201047101836816,0.0404026173055172,172.741912841797,48.9997863769531,49.0006790161133,259.673980712891,259.673980712891,,,293.931304931641,0,1,,,,,,1,1,1,49.0004768371582,0,49.0002086863798,,,,,,,,,,,,,,,,,,,,,,,,,,,,,,,,,
,3754547426.81336,49.0004177093506,259.673980712891,,,5,,,,-2.43000010959804,,,,,0.000698579520752172,6.53869847915986E-8,-0.00202145591156899,6.98919645488518E-5,0.000698488344211616,6.53784506750184E-8,0.000698488343776893,4.34917475922426E-8,-2.4643410112839E-8,4.88140318355129E-8,1.00013053409024,10.005763053894,2,20,10,5,2.28518695232021,0.201130947769866,0.0404026173055172,172.741912841797,48.9999504089355,49.0006561279297,259.673980712891,259.673980712891,,,302.50048828125,0,1,,,,,,1,1,1,49.0004692077637,0,49.0002479553223,,,,,,,,,,,,,,,,,,,,,,,,,,,,,,,,,
,3754548212.42949,48.9999675750732,259.673980712891,,,5,,,,-2.43000010959804,,,,,0.000698752968114954,1.27617143217221E-7,-0.00556675006348772,9.61660563522042E-5,0.00069866178332806,1.27600489632135E-7,0.000698661780030481,1.08491636590813E-7,-6.78806633513199E-8,6.71673264631519E-8,1.00013051348889,10.005763053894,2,20,10,5,2.28576677570093,0.201039451310747,0.0404026173055172,172.741912841797,48.9993896484375,49.0003089904785,259.673980712891,259.673980712891,,,311.455200195313,0,1,,,,,,1,1,1,49.0000495910645,0,48.9999097936294,,,,,,,,,,,,,,,,,,,,,,,,,,,,,,,,,
,3754549000.33412,48.9999923706055,259.673980712891,,,5,,,,-2.43000010959804,,,,,0.000698926534270309,1.03796134267027E-7,-0.0014066084950155,7.37589629515068E-5,0.000698835326040697,1.0378258912146E-7,0.000698835325830103,9.00879790082756E-8,-1.71563719785432E-8,5.15265159210119E-8,1.00013051462371,10.005763053894,2,20,10,5,2.28631994007191,0.201255394196036,0.0404026173055172,172.741912841797,48.9994621276855,49.000545501709,259.673980712891,259.673980712891,,,320.832763671875,0,1,,,,,,1,1,1,49.0000915527344,0,48.9999593846938,,,,,,,,,,,,,,,,,,,,,,,,,,,,,,,,,
,3754549784.77772,48.9999771118164,259.673980712891,,,5,,,,-2.43000010959804,,,,,0.000699057414033298,9.77230237875146E-8,-0.00183616623480098,0.000116569143538404,0.000698966189212253,9.77102712364679E-8,0.000698966188853326,5.39385383892023E-8,-2.23998717983465E-8,8.14734998729076E-8,1.00013051392536,10.005763053894,2,20,10,5,2.28674958141901,0.201275936770646,0.0404026173055172,172.741912841797,48.9995002746582,49.0005760192871,259.673980712891,259.673980712891,,,330.347137451172,0,1,,,,,,1,1,1,49.0000801086426,0,49.0000127904555,,,,,,,,,,,,,,,,,,,,,,,,,,,,,,,,,
,3754550570.40245,49.0001811981201,259.673980712891,,,5,,,,-2.43000010959804,,,,,0.000699191263175094,8.95402885066888E-8,-0.00315553335686225,7.38294802528983E-5,0.000699100094560185,8.95286132119423E-8,0.000699100093499932,7.31615661882457E-8,-3.8502550899954E-8,5.16019167913028E-8,1.00013040852893,10.005763053894,2,20,10,5,2.28719206257671,0.201261806680682,0.0404026173055172,172.741912841797,48.9992790222168,49.0003356933594,259.673980712891,259.673980712891,,,341.092803955078,0,1,,,,,,1,1,1,49.0002670288086,0,48.9998579586253,,,,,,,,,,,,,,,,,,,,,,,,,,,,,,,,,
,3754551357.38356,49.001049041748,259.673980712891,,,5,,,,-2.43000010959804,,,,,0.000699364735372703,1.0015581838162E-7,-0.00169507972789251,0.000112474778325918,0.00069927351636787,1.00142754934725E-7,0.000699273516061849,6.19966412602336E-8,-2.0687812815318E-8,7.86446936440491E-8,1.00013044824764,10.005763053894,2,20,10,5,2.28775439247349,0.201370050811239,0.0404026173055172,172.741912841797,49.0003700256348,49.0012626647949,259.673980712891,259.673980712891,,,352.248901367188,0,1,,,,,,1,1,1,49.0012512207031,0,49.0008241990033,,,,,,,,,,,,,,,,,,,,,,,,,,,,,,,,,
,3754552144.24141,48.9999389648438,259.673980712891,,,5,,,,-2.43000010959804,,,,,0.000699493326192741,8.88410482193163E-8,-0.00281118705789662,6.79149111013168E-5,0.000699402045707424,8.88294548935562E-8,0.000699402044865581,7.5071782965729E-8,-3.43157907105766E-8,4.74857816512776E-8,1.00013051217948,10.005763053894,2,20,10,5,2.28817895983755,0.201362508412204,0.0404026173055172,172.741912841797,48.9990081787109,49.000415802002,259.673980712891,259.673980712891,,,363.964630126953,0,1,,,,,,1,1,1,48.9999847412109,0,48.9997668546789,,,,,,,,,,,,,,,,,,,,,,,,,,,,,,,,,
,3754552928.32295,48.9982318878174,259.673980712891,,,5,,,,-2.43000010959804,,,,,0.000699657220088272,9.72259618219706E-8,-0.00141504185757313,8.55497115876153E-5,0.000699565892608643,9.7213270747266E-8,0.000699565892395293,7.66164936411876E-8,-1.72772764151865E-8,5.98358831430699E-8,1.00013054878832,10.005763053894,2,20,10,5,2.28871017971325,0.201465463711587,0.0404026173055172,172.741912841797,48.9974212646484,49.001579284668,259.673980712891,259.673980712891,,,376.252502441406,0,1,,,,,,1,1,1,48.9986457824707,0,48.9997280345244,,,,,,,,,,,,,,,,,,,,,,,,,,,,,,,,,
,3754553713.84575,48.9999237060547,259.673980712891,,,5,,,,-2.43000010959804,,,,,0.000699731855026495,8.31043550830161E-8,-0.000782188745496626,7.90341999818069E-5,0.000699640624166951,8.30935199585443E-8,0.000699640624101754,6.20311566777785E-8,-9.55133217052525E-9,5.52871473338777E-8,1.00013039674426,10.005763053894,2,20,10,5,2.2889520992498,0.201512234051845,0.0404026173055172,172.741912841797,48.9993858337402,49.0004615783691,259.673980712891,259.673980712891,,,389.398559570313,0,1,,,,,,1,1,1,48.9993858337402,0,48.9997782987707,,,,,,,,,,,,,,,,,,,,,,,,,,,,,,,,,
,3754554498.08448,48.9992523193359,259.673980712891,,,5,,,,-2.43000010959804,,,,,0.000700497756068565,8.517773626606E-8,-0.00764647602237112,0.000101139887192868,0.000700406366517977,8.5166623660816E-8,0.000700406360280664,4.72840764253299E-8,-9.34735597824464E-8,7.08348071387691E-8,1.00013048075368,10.005763053894,2,20,10,5,2.29148165504526,0.201458273484586,0.0404026173055172,172.741912841797,48.9982490539551,48.9995079040527,259.673980712891,259.673980712891,,,403.377838134766,0,1,,,,,,1,1,1,48.9994735717773,0,48.9989710913764,,,,,,,,,,,,,,,,,,,,,,,,,,,,,,,,,
,3754555283.3673,49.0001316070557,259.673980712891,,,5,,,,-2.43000010959804,,,,,0.000700259278075956,1.01209185407324E-7,-0.00161105815522511,8.52112553588792E-5,0.000700167891465282,1.01195977207571E-7,0.000700167891188493,8.17474812583683E-8,-1.96875092896801E-8,5.9648764537985E-8,1.00013052099616,10.005763053894,2,20,10,5,2.29068031484483,0.201630982721058,0.0404026173055172,172.741912841797,48.9996604919434,49.0003776550293,259.673980712891,259.673980712891,,,418.451629638672,0,1,,,,,,1,1,1,49.0001449584961,0,48.9999868869782,,,,,,,,,,,,,,,,,,,,,,,,,,,,,,,,,
,3754556068.91024,48.9998226165771,259.673980712891,,,5,,,,-2.43000010959804,,,,,0.000700257440688516,6.23342445119583E-8,-0.0023700216571152,5.09946658516823E-5,0.00070016606421781,6.23261105273169E-8,0.000700166063618805,5.10914626927759E-8,-2.89621460673418E-8,3.56960290981505E-8,1.00013050685455,10.005763053894,2,20,10,5,2.2906769750123,0.201600111218219,0.0404026173055172,172.741912841797,48.9994621276855,49.0003929138184,259.673980712891,259.673980712891,,,434.731781005859,0,1,,,,,,1,1,1,48.9999542236328,0,48.9999409843894,,,,,,,,,,,,,,,,,,,,,,,,,,,,,,,,,
,3754556856.46107,48.9998741149902,259.673980712891,,,5,,,,-2.43000010959804,,,,,0.000700427112518654,7.67006627681533E-8,-0.00480078467724976,6.43020852685688E-5,0.000700335712257071,7.66906539313803E-8,0.000700335709798654,6.20836865977758E-8,-5.86807786013759E-8,4.50230192107536E-8,1.00013050921149,10.005763053894,2,20,10,5,2.29124055707622,0.20155175386131,0.0404026173055172,172.741912841797,48.999153137207,49.0005340576172,259.673980712891,259.673980712891,,,452.579040527344,0,1,,,,,,1,1,1,48.9998626708984,0,48.9997579786513,,,,,,,,,,,,,,,,,,,,,,,,,,,,,,,,,
,3754557643.39622,49.0007343292236,259.673980712891,,,5,,,,-2.43000010959804,,,,,0.00070061183636474,9.61368671726271E-8,-0.000433471019792186,6.02696593570332E-5,0.000700520464787609,9.61243293068389E-8,0.000700520464767561,8.63663719166888E-8,-5.29978512962811E-9,4.21987735205396E-8,1.00013043384415,10.005763053894,2,20,10,5,2.2918294531294,0.201779598762919,0.0404026173055172,172.741912841797,48.9999809265137,49.0009384155273,259.673980712891,259.673980712891,,,472.179901123047,0,1,,,,,,1,1,1,49.0006904602051,0,49.000497341156,,,,,,,,,,,,,,,,,,,,,,,,,,,,,,,,,
,3754558427.70372,49.0001754760742,259.673980712891,,,5,,,,-2.43000010959804,,,,,0.00070071909266587,9.28845110287476E-8,-0.00532433517027631,7.38941969001209E-5,0.000700627644641063,9.28723890455482E-8,0.000700627641615942,7.71121861505341E-8,-6.51073505930674E-8,5.17589740442471E-8,1.00013052300392,10.005763053894,2,20,10,5,2.29219752640762,0.201614826564682,0.0404026173055172,172.741912841797,48.9999542236328,49.0007591247559,259.673980712891,259.673980712891,,,493.870208740234,0,1,,,,,,1,1,1,49.0000648498535,0,49.0002376332002,,,,,,,,,,,,,,,,,,,,,,,,,,,,,,,,,
,3754559217.42579,49.0003471374512,259.673980712891,,,5,,,,-2.43000010959804,,,,,0.000700798342555889,7.7325669588311E-8,-0.00164021615775489,8.96090528151606E-5,0.000700706959070578,7.7315586389248E-8,0.000700706958783458,4.51181993379841E-8,-2.00592589145149E-8,6.27857307611467E-8,1.0001304161235,10.005763053894,2,20,10,5,2.29244379933472,0.201785031851056,0.0404026173055172,172.741912841797,48.9995498657227,49.0005950927734,259.673980712891,259.673980712891,,,518.246948242188,0,1,,,,,,1,1,1,49.000431060791,0,49.0001321680406,,,,,,,,,,,,,,,,,,,,,,,,,,,,,,,,,
,3754560002.92604,48.999698638916,259.673980712891,,,5,,,,-2.43000010959804,,,,,0.000700816967040961,7.68229638909283E-8,-0.00407694665618585,6.49886793983138E-5,0.000700725521533229,7.6812939711622E-8,0.000700725519759274,6.18652448147856E-8,-4.98609250766178E-8,4.552932232252E-8,1.00013050118045,10.005763053894,2,20,10,5,2.2925133031879,0.201692898924125,0.0404026173055172,172.741912841797,48.9994354248047,49.0004692077637,259.673980712891,259.673980712891,,,545.78271484375,0,1,,,,,,1,1,1,48.9998321533203,0,48.9999587115119,,,,,,,,,,,,,,,,,,,,,,,,,,,,,,,,,
,3754560789.50414,49.0004844665527,259.673980712891,,,5,,,,-2.43000010959804,,,,,0.000701052508511472,8.51255750216862E-8,-0.00823897924710515,7.43219849407522E-5,0.000700961087478068,8.51144741869511E-8,0.000700961080230947,6.73159618557741E-8,-1.00796321857153E-7,5.20868025084391E-8,1.00013042240866,10.005763053894,2,20,10,5,2.29329845707572,0.201594096706538,0.0404026173055172,172.741912841797,48.9997520446777,49.0008316040039,259.673980712891,259.673980712891,,,577.795837402344,0,1,,,,,,1,1,1,49.0005493164063,0,49.0002867754768,,,,,,,,,,,,,,,,,,,,,,,,,,,,,,,,,
,3754561578.94519,48.9995346069336,259.673980712891,,,5,,,,-2.43000010959804,,,,,0.000701165814507355,6.46460791309888E-8,-0.00489707773974502,5.92071666029461E-5,0.000701074328743027,6.46376443273549E-8,0.000701074326182303,4.95544125912321E-8,-5.99209141439507E-8,4.15016295695432E-8,1.00013049367318,10.005763053894,2,20,10,5,2.29365734140387,0.201760467720794,0.0404026173055172,172.741912841797,48.9989547729492,49.0001525878906,259.673980712891,259.673980712891,,,615.06982421875,0,1,,,,,,1,1,1,48.9991111755371,0,48.9996647554285,,,,,,,,,,,,,,,,,,,,,,,,,,,,,,,,,
,3754562365.56873,48.9999675750732,259.673980712891,,,5,,,,-2.43000010959804,,,,,0.000701825769009929,8.15371784234214E-8,-0.00248058840400756,7.33281121862536E-5,0.000701734263737687,8.15265474633757E-8,0.000701734263080019,6.32433894059303E-8,-3.03811884849429E-8,5.14475620194767E-8,1.00013039875202,10.005763053894,2,20,10,5,2.29580766876755,0.202047195715502,0.0404026173055172,172.741912841797,48.999267578125,49.0006484985352,259.673980712891,259.673980712891,,,655.689453125,0,1,,,,,,1,1,1,48.9994468688965,0,48.999842537774,,,,,,,,,,,,,,,,,,,,,,,,,,,,,,,,,
,3754563152.22363,48.999195098877,259.673980712891,,,5,,,,-2.43000010959804,,,,,0.000701625155570438,9.54548669843007E-8,-0.0022114139742202,6.64067979958907E-5,0.000701533620772052,9.54424138361561E-8,0.00070153362024952,8.33102125529413E-8,-2.70767108006831E-8,4.65689042522563E-8,1.00013047813487,10.005763053894,2,20,10,5,2.29515047432546,0.202000225867206,0.0404026173055172,172.741912841797,48.9985961914063,49.0000877380371,259.673980712891,259.673980712891,,,695.450927734375,0,1,,,,,,1,1,1,48.9990158081055,0,48.9993900722928,,,,,,,,,,,,,,,,,,,,,,,,,,,,,,,,,
,3754563937.61113,48.9997406005859,259.673980712891,,,5,,,,-2.43000010959804,,,,,0.000701748552818964,8.00847287103768E-8,-0.00321754704942556,9.25079434142517E-5,0.00070165698440672,8.00742787686939E-8,0.000701656983300353,4.68964578409153E-8,-3.94028037996167E-8,6.49046405297938E-8,1.00013050310092,10.005763053894,2,20,10,5,2.29555767797209,0.201995440344899,0.0404026173055172,172.741912841797,48.9988327026367,49.0002593994141,259.673980712891,259.673980712891,,,724.802490234375,0,1,,,,,,1,1,1,48.999324798584,0,48.9996130201552,,,,,,,,,,,,,,,,,,,,,,,,,,,,,,,,,
,3754564724.57306,48.9998149871826,259.673980712891,,,5,,,,-2.43000010959804,,,,,0.00070174013494865,9.65208378824757E-8,-0.00162385217811956,0.000111060713877157,0.000701648645740858,9.65082540005606E-8,0.000701648645459061,5.69406225538291E-8,-1.98858221528908E-8,7.79205274200521E-8,1.00013039176851,10.005763053894,2,20,10,5,2.29552452219237,0.202056866784753,0.0404026173055172,172.741912841797,48.9995422363281,49.0007476806641,259.673980712891,259.673980712891,,,738.59521484375,0,1,,,,,,1,1,1,48.9995956420898,0,48.9999205645393,,,,,,,,,,,,,,,,,,,,,,,,,,,,,,,,,
,3754565509.99488,49.0000801086426,259.673980712891,,,5,,,,-2.43000010959804,,,,,0.000701823510548849,8.62376767949794E-8,-0.00106338399073458,9.15261965355625E-5,0.000701731921453359,8.62264226396312E-8,0.000701731921332501,5.7538741640916E-8,-1.3023829981189E-8,6.42206288633818E-8,1.00013051863923,10.005763053894,2,20,10,5,2.29579528296215,0.202103327848701,0.0404026173055172,172.741912841797,48.9997177124023,49.0004539489746,259.673980712891,259.673980712891,,,743.060119628906,0,1,,,,,,1,1,1,49.0004119873047,0,49.000051835004,,,,,,,,,,,,,,,,,,,,,,,,,,,,,,,,,
,3754566298.38674,49.0005950927734,259.673980712891,,,5,,,,-2.43000010959804,,,,,0.000701821323202083,8.91974369949523E-8,-0.00499267209419063,9.84878330046568E-5,0.000701729798358665,8.91858047159315E-8,0.000701729795694502,5.63777096809024E-8,-6.1147728633199E-8,6.91061619102388E-8,1.0001304274717,10.005763053894,2,20,10,5,2.29580198244645,0.201945253514613,0.0404026173055172,172.741912841797,48.9994277954102,49.0010566711426,259.673980712891,259.673980712891,,,744.341125488281,0,1,,,,,,1,1,1,49.000675201416,0,49.0001044803196,,,,,,,,,,,,,,,,,,,,,,,,,,,,,,,,,
,3754567082.48271,49.0006141662598,259.673980712891,,,5,,,,-2.43000010959804,,,,,0.000701999217197383,1.45370276946403E-7,-4.24264774423477E-5,0.000119535385714633,0.000701907668542084,1.45351319014473E-7,0.000701907668541892,1.18704417702816E-7,-5.1974979866029E-10,8.38824603661726E-8,1.00013042834464,10.005763053894,2,20,10,5,2.29636644951336,0.20219484535592,0.0404026173055172,172.741912841797,48.999698638916,49.0010261535645,259.673980712891,259.673980712891,,,744.8759765625,0,1,,,,,,1,1,1,49.0003356933594,0,49.0001752376556,,,,,,,,,,,,,,,,,,,,,,,,,,,,,,,,,
,3754567870.36337,49.0006294250488,259.673980712891,,,5,,,,-2.43000010959804,,,,,0.000701931931227858,1.33936454839968E-7,-0.00206492347960374,0.000110169460520559,0.000701840390857346,1.33918987914536E-7,0.000701840390401549,1.09355176469601E-7,-2.52941266183658E-8,7.73029152319379E-8,1.00013042904299,10.005763053894,2,20,10,5,2.296153480202,0.202094412165433,0.0404026173055172,172.741912841797,48.9995231628418,49.0010375976562,259.673980712891,259.673980712891,,,745.08740234375,0,1,,,,,,1,1,1,49.0004997253418,0,49.0001292509191,,,,,,,,,,,,,,,,,,,,,,,,,,,,,,,,,
,3754568664.57847,48.9998950958252,259.673980712891,,,5,,,,-2.43000010959804,,,,,0.000702229297966232,8.06933029496809E-8,-0.00524817079081608,6.82644767777912E-5,0.000702137742409983,8.06827822831999E-8,0.000702137739464456,6.49100104837099E-8,-6.431431454478E-8,4.79207877226878E-8,1.00013039543485,10.005763053894,2,20,10,5,2.2971374524784,0.202052407052366,0.0404026173055172,172.741912841797,48.9990653991699,49.0004577636719,259.673980712891,259.673980712891,,,745.149536132813,0,1,,,,,,1,1,1,48.9995498657227,0,48.9998175677131,,,,,,,,,,,,,,,,,,,,,,,,,,,,,,,,,