File: Experimental_Data/Fig3B/Lifetime_380Oe.dat
[Header]
; MPMS3 Data File (default extension .dat)
; Copyright (c) 2007, Quantum Design, Inc. All rights reserved.
TITLE,380Oe
FILEOPENTIME,3755406686.23997,12/31/2018,8:30 am
BYAPP,SQUID AC,0.9.1.0
INFO,MPMS3 Measurement Release 1.1.16 Build 347, MultiVu Release 2.3.3.2,APPNAME
INFO,0,MOMENT_UNITS
INFO,CoIINO3,SAMPLE_MATERIAL
INFO,40 Hours Pumped Turbo,SAMPLE_COMMENT
INFO,,SAMPLE_MASS
INFO,,SAMPLE_VOLUME
INFO,,SAMPLE_MOLECULAR_WEIGHT
INFO,,SAMPLE_SIZE
INFO,,SAMPLE_SHAPE
INFO,Brass,SAMPLE_HOLDER
INFO,Standard,SAMPLE_HOLDER_DETAIL
INFO,65.37,SAMPLE_OFFSET
DATATYPE,COMMENT,1
DATATYPE,TIME,2
STARTUPAXIS,X,2
STARTUPAXIS,Y1,5
FIELDGROUP, VSM,2,3,4,5,6,8,9,10,11,14,15
FIELDGROUP, DC, 2,3,4,14,56,57,58,59,60,61,62,63,64,65,66,67,68,69
FIELDGROUP, AC, 2,3,4,11,16,17,18,19,20,21,22,23,24,25,26,27,28,29,30
STARTUPGROUP, All
[Data]
Comment,Time Stamp (sec),Temperature (K),Magnetic Field (Oe),Moment (emu),M. Std. Err. (emu),Transport Action,Averaging Time (sec),Frequency (Hz),Peak Amplitude (mm),Center Position (mm),Lockin Signal' (V),Lockin Signal (V),Range,M. Quad. Signal (emu),AC Moment (emu),AC M. Std Err. (emu),AC Phase (deg),AC Phase Std. Err. (deg),AC Susceptibility (emu/Oe),AC Suscept. Std Err. (emu/Oe),AC X' (emu/Oe),AC X' Std Err. (emu/Oe),AC X'' (emu/Oe),AC X'' Std Err. (emu/Oe),AC Drive (Oe),AC Frequency (Hz),AC Averaging Time (sec),AC Cycles,AC Range,AC Measure Type,AC Signal' (V),AC Signal'' (V),AC Trim Coil Ratio,AC Trim Coil Phase,Min. Temperature (K),Max. Temperature (K),Min. Field (Oe),Max. Field (Oe),Mass (grams),Motor Lag (deg),Pressure (Torr),Measure Count,Measurement Number,SQUID Status (code),Motor Status (code),Measure Status (code),Motor Current (amps),Motor Temp. (C),Temp. Status (code),Field Status (code),Chamber Status (code),Chamber Temp (K),Redirection State,Average Temp (K),Rotation Angle (deg),Rotator state,DC Moment Fixed Ctr (emu),DC Moment Err Fixed Ctr (emu),DC Moment Free Ctr (emu),DC Moment Err Free Ctr (emu),DC Fixed Fit,DC Free Fit,DC Calculated Center (mm),DC Calculated Center Err (mm),DC Scan Length (mm),DC Scan Time (s),DC Number of Points,DC Squid Drift,DC Min V (V),DC Max V (V),DC Scans per Measure,Map 01,Map 02,Map 03,Map 04,Map 05,Map 06,Map 07,Map 08,Map 09,Map 10,Map 11,Map 12,Map 13,Map 14,Map 15,Map 16
,3755406691.26553,48.9702701568604,380.45849609375,,,5,,,,-2.43000010959804,,,,,0.000718039880284425,3.7382166944243E-7,-0.00560476360803897,0.000115056953233873,0.000717946660120366,3.73773137712772E-7,0.000717946656685329,3.64572334819509E-7,-7.02306756437347E-8,8.24219094652771E-8,1.00012984274353,10.005763053894,2,20,10,5,2.34883959178948,0.206890748337782,0.0404026173055172,172.741912841797,48.9252738952637,48.9821357727051,380.45849609375,380.45849609375,,,11.6859521865845,0,1,,,,,,1,1,1,48.9652938842773,0,48.9500283633961,,,,,,,,,,,,,,,,,,,,,,,,,,,,,,,,,
,3755406898.07057,49.0003356933594,380.45849609375,,,5,,,,-2.43000010959804,,,,,0.000757864387740634,1.32076209345843E-7,-0.0138398085481599,0.000100626587409864,0.000757765563290238,1.32058986793879E-7,0.000757765541183749,1.07832552637728E-7,-1.83038442053968E-7,7.62346153965349E-8,1.00013041559974,10.005763053894,2,20,10,5,2.47914420283149,0.218009014504057,0.0404026173055172,172.741912841797,48.9994049072266,49.0010185241699,380.45849609375,380.45849609375,,,11.660231590271,0,1,,,,,,1,1,1,48.999828338623,0,48.9999302134794,,,,,,,,,,,,,,,,,,,,,,,,,,,,,,,,,
,3755407102.69808,49.0007305145264,380.45849609375,,,5,,,,-2.43000010959804,,,,,0.000761482646994092,1.90220076289415E-7,-0.0183375149588754,0.000204878868111651,0.000761383336971504,1.9019526842262E-7,0.000761383297976491,1.0883223962106E-7,-2.4368074248136E-7,1.55980074847452E-7,1.00013043366957,10.005763053894,2,20,10,5,2.49099752728824,0.218854307864279,0.0404026173055172,172.741912841797,48.9988479614258,49.0017700195313,380.45849609375,380.45849609375,,,11.3764162063599,0,1,,,,,,1,1,1,49.0001258850098,0,48.9998124066521,,,,,,,,,,,,,,,,,,,,,,,,,,,,,,,,,
,3755407307.66913,49.0006980895996,380.45849609375,,,5,,,,-2.43000010959804,,,,,0.000763163187952416,2.01163210214219E-7,-0.0211496053135543,0.000182306686152933,0.000763063659891527,2.01136975478909E-7,0.000763063607905092,1.45289265876869E-7,-2.81669871785924E-7,1.39093896795523E-7,1.00013043218557,10.005763053894,2,20,10,5,2.49650575340291,0.219214774845592,0.0404026173055172,172.741912841797,48.9999580383301,49.0011749267578,380.45849609375,380.45849609375,,,11.1261463165283,0,1,,,,,,1,1,1,49.0003318786621,0,49.0003662109375,,,,,,,,,,,,,,,,,,,,,,,,,,,,,,,,,
,3755407512.61976,49.0004405975342,380.45849609375,,,5,,,,-2.43000010959804,,,,,0.000763668038024932,1.39329049904638E-7,-0.0168487629055658,9.99247825685598E-5,0.000763568453121162,1.39310880923698E-7,0.000763568420106356,1.1657094670322E-7,-2.2453981345085E-7,7.62806392766331E-8,1.0001304204009,10.005763053894,2,20,10,5,2.49814077670388,0.219547309806876,0.0404026173055172,172.741912841797,49.0001678466797,49.0012664794922,380.45849609375,380.45849609375,,,10.9068460464478,0,1,,,,,,1,1,1,49.0006408691406,0,49.000529794132,,,,,,,,,,,,,,,,,,,,,,,,,,,,,,,,,
,3755407717.53065,49.0005397796631,380.45849609375,,,5,,,,-2.43000010959804,,,,,0.000764071108127316,1.37491139162555E-7,-0.0134414647181389,0.00010542515918948,0.000763971467194408,1.37473209227466E-7,0.00076397144617139,1.1142102926159E-7,-1.79226035757492E-7,8.05247632321042E-8,1.00013042494018,10.005763053894,2,20,10,5,2.49944624790512,0.219811827726926,0.0404026173055172,172.741912841797,48.9992637634277,49.0007247924805,380.45849609375,380.45849609375,,,10.7107801437378,0,1,,,,,,1,1,1,49.0005950927734,0,49.00003119076,,,,,,,,,,,,,,,,,,,,,,,,,,,,,,,,,
,3755407922.44333,49.0008907318115,380.45849609375,,,5,,,,-2.43000010959804,,,,,0.000764928527713577,9.33456405898745E-8,-0.018262482056433,8.19525606668023E-5,0.000764828762683223,9.33334660790156E-8,0.000764828723831655,6.91627930294973E-8,-2.43781853339621E-7,6.26709179020195E-8,1.00013044100225,10.005763053894,2,20,10,5,2.50226956526112,0.219847947009033,0.0404026173055172,172.741912841797,48.9991264343262,49.0013580322266,380.45849609375,380.45849609375,,,10.4711647033691,0,1,,,,,,1,1,1,49.0007629394531,0,49.0001288021312,,,,,,,,,,,,,,,,,,,,,,,,,,,,,,,,,
,3755408127.35338,48.9995403289795,380.45849609375,,,5,,,,-2.43000010959804,,,,,0.000764867495174269,1.21461063465414E-7,-0.00960585930220947,0.000108748895570474,0.000764767697628,1.21445215601336E-7,0.000764767686880023,8.85095788081262E-8,-1.28216265321905E-7,8.3156448046216E-8,1.00013049393506,10.005763053894,2,20,10,5,2.50203667024548,0.220208438674622,0.0404026173055172,172.741912841797,48.9993362426758,49.0004844665527,380.45849609375,380.45849609375,,,10.2417507171631,0,1,,,,,,1,1,1,48.9993438720703,0,48.999839109533,,,,,,,,,,,,,,,,,,,,,,,,,,,,,,,,,
,3755408332.38523,49.0015296936035,380.45849609375,,,5,,,,-2.43000010959804,,,,,0.000764926945388838,1.41442144593327E-7,-0.0177924038569905,9.2496899772598E-5,0.000764827158201593,1.41423693009353E-7,0.000764827121324447,1.22470345874572E-7,-2.37506384876027E-7,7.07225234685973E-8,1.0001304702457,10.005763053894,2,20,10,5,2.50226258559065,0.219868018411993,0.0404026173055172,172.741912841797,48.9998054504395,49.0017776489258,380.45849609375,380.45849609375,,,10.0365180969238,0,1,,,,,,1,1,1,49.0015258789063,0,49.0006547815659,,,,,,,,,,,,,,,,,,,,,,,,,,,,,,,,,
,3755408537.2896,48.999828338623,380.45849609375,,,5,,,,-2.43000010959804,,,,,0.000764949030288723,1.52572423353229E-7,-0.0135321373591069,0.000117031513888622,0.000764849212023555,1.52552514164501E-7,0.000764849190691468,1.23544904590211E-7,-1.80642354250914E-7,8.94926037597853E-8,1.00013050711643,10.005763053894,2,20,10,5,2.50231847422463,0.220060435682964,0.0404026173055172,172.741912841797,48.9990119934082,49.000129699707,380.45849609375,380.45849609375,,,9.85254573822022,0,1,,,,,,1,1,1,48.9999504089355,0,48.9996113496668,,,,,,,,,,,,,,,,,,,,,,,,,,,,,,,,,
,3755408742.37925,49.0010757446289,380.45849609375,,,5,,,,-2.43000010959804,,,,,0.000765238713267518,1.54686158339785E-7,-0.0192753337151883,0.000142568098681761,0.000765138901303554,1.54665982244412E-7,0.000765138858005455,1.0965868696706E-7,-2.57406522927853E-7,1.09071253941124E-7,1.00013044946976,10.005763053894,2,20,10,5,2.50328814618342,0.219892844965579,0.0404026173055172,172.741912841797,48.9995651245117,49.0015182495117,380.45849609375,380.45849609375,,,9.68566799163818,0,1,,,,,,1,1,1,49.0008354187012,0,49.0002887950224,,,,,,,,,,,,,,,,,,,,,,,,,,,,,,,,,
,3755408947.3318,49.0015392303467,380.45849609375,,,5,,,,-2.43000010959804,,,,,0.000765429690638564,1.03587647755123E-7,-0.0224130800769515,8.04107500655517E-5,0.00076532983753258,1.03574134367157E-7,0.000765329778975897,8.33173468197638E-8,-2.99383281669165E-7,6.15290259050244E-8,1.00013047068216,10.005763053894,2,20,10,5,2.50392492279475,0.219810596142053,0.0404026173055172,172.741912841797,49.0001106262207,49.0018844604492,380.45849609375,380.45849609375,,,9.53638362884521,0,1,,,,,,1,1,1,49.0012626647949,0,49.0008616727941,,,,,,,,,,,,,,,,,,,,,,,,,,,,,,,,,
,3755409152.27441,49.0009765625,380.45849609375,,,5,,,,-2.43000010959804,,,,,0.000765398533350019,1.27412046888842E-7,-0.0169162276641908,0.000110415900878261,0.000765298704013782,1.27395428800989E-7,0.000765298670658643,9.53479451709629E-8,-2.25949747610472E-7,8.44888432342579E-8,1.00013044493047,10.005763053894,2,20,10,5,2.50380189981558,0.220041862890761,0.0404026173055172,172.741912841797,48.9995002746582,49.0016593933105,380.45849609375,380.45849609375,,,9.40228843688965,0,1,,,,,,1,1,1,49.0005760192871,0,49.0003060733571,,,,,,,,,,,,,,,,,,,,,,,,,,,,,,,,,
,3755409357.38807,49.000114440918,380.45849609375,,,5,,,,-2.43000010959804,,,,,0.000765525109359026,1.35593393530273E-7,-0.0141980526505883,0.000133275793546476,0.000765425293711057,1.3557571371511E-7,0.000765425270210124,8.93096167151921E-8,-1.89674503101886E-7,1.02002776979586E-7,1.00013040547365,10.005763053894,2,20,10,5,2.50420551629112,0.220197058658762,0.0404026173055172,172.741912841797,48.9988479614258,49.0007629394531,380.45849609375,380.45849609375,,,9.2830982208252,0,1,,,,,,1,1,1,48.9996109008789,0,48.999443951775,,,,,,,,,,,,,,,,,,,,,,,,,,,,,,,,,
,3755409562.40668,49.0011501312256,380.45849609375,,,5,,,,-2.43000010959804,,,,,0.000765661726774674,1.38365089098473E-7,-0.0156874318634594,0.000127517380388832,0.000765561857030034,1.38347041329293E-7,0.000765561828334868,9.80411307318178E-8,-2.09608795297546E-7,9.76106578678558E-8,1.00013045287422,10.005763053894,2,20,10,5,2.50465814739549,0.220171241629388,0.0404026173055172,172.741912841797,48.9999504089355,49.0013084411621,380.45849609375,380.45849609375,,,9.17464923858643,0,1,,,,,,1,1,1,49.0010528564453,0,49.0004782676697,,,,,,,,,,,,,,,,,,,,,,,,,,,,,,,,,
,3755409766.49963,49.0010509490967,380.45849609375,,,5,,,,-2.43000010959804,,,,,0.000765850213260714,1.23941682929373E-7,-0.0229264703681302,0.000111545586597455,0.000765750322406179,1.23925517052018E-7,0.000765750261102531,8.97969820022301E-8,-3.06409158872353E-7,8.54051274801527E-8,1.00013044833494,10.005763053894,2,20,10,5,2.50530253497401,0.219908912412274,0.0404026173055172,172.741912841797,48.9997711181641,49.0012664794922,380.45849609375,380.45849609375,,,9.07798194885254,0,1,,,,,,1,1,1,49.0008201599121,0,49.0004151288201,,,,,,,,,,,,,,,,,,,,,,,,,,,,,,,,,
,3755409972.32872,49.0005378723145,380.45849609375,,,5,,,,-2.43000010959804,,,,,0.000765997970138207,1.88185842716621E-7,-0.0172602750652162,0.000169776457663633,0.000765898077994059,1.88161301806514E-7,0.000765898043241152,1.36017801137092E-7,-2.30725742986553E-7,1.30014742515426E-7,1.00013042485289,10.005763053894,2,20,10,5,2.50576412343224,0.220199145996159,0.0404026173055172,172.741912841797,48.99951171875,49.0006980895996,380.45849609375,380.45849609375,,,8.98992824554443,0,1,,,,,,1,1,1,49.0006790161133,0,49.0001112994026,,,,,,,,,,,,,,,,,,,,,,,,,,,,,,,,,
,3755410177.2542,49.0004730224609,380.45849609375,,,5,,,,-2.43000010959804,,,,,0.000765888172127789,1.00716292034594E-7,-0.0193292486298109,9.17447097545826E-5,0.00076578829657472,1.00703158138895E-7,0.00076578825299711,7.21547325917686E-8,-2.58345592420786E-7,7.0248278439814E-8,1.00013042188489,10.005763053894,2,20,10,5,2.5054128961442,0.220077113803371,0.0404026173055172,172.741912841797,48.9994125366211,49.0009727478027,380.45849609375,380.45849609375,,,8.91232395172119,0,1,,,,,,1,1,1,49.0001373291016,0,49.0000944698558,,,,,,,,,,,,,,,,,,,,,,,,,,,,,,,,,
,3755410382.18389,49.0000858306885,380.45849609375,,,5,,,,-2.43000010959804,,,,,0.000765894814748791,1.14806300479967E-7,-0.0197392409596384,0.000113000798066185,0.000765794864044662,1.14791318043279E-7,0.000765794818598409,7.54329653612855E-8,-2.63827618307467E-7,8.65269578508128E-8,1.00013051890111,10.005763053894,2,20,10,5,2.50543620068895,0.22006109323765,0.0404026173055172,172.741912841797,48.999454498291,49.0004844665527,380.45849609375,380.45849609375,,,8.84305667877197,0,1,,,,,,1,1,1,49.0003890991211,0,48.9999277451459,,,,,,,,,,,,,,,,,,,,,,,,,,,,,,,,,
,3755410587.17335,48.9997234344482,380.45849609375,,,5,,,,-2.43000010959804,,,,,0.000765733263917077,1.14716030384181E-7,-0.0212018265942477,9.35772175425356E-5,0.000765633346992645,1.14701061630074E-7,0.000765633294573235,8.95820213134496E-8,-2.83316244672834E-7,7.16337559846111E-8,1.00013050231527,10.005763053894,2,20,10,5,2.50491334215647,0.219950735895149,0.0404026173055172,172.741912841797,48.9992332458496,49.000057220459,380.45849609375,380.45849609375,,,8.77961921691895,0,1,,,,,,1,1,1,48.9997177124023,0,48.9997266881606,,,,,,,,,,,,,,,,,,,,,,,,,,,,,,,,,
,3755410792.02735,48.9996871948242,380.45849609375,,,5,,,,-2.43000010959804,,,,,0.000766102319008553,1.10086166146175E-7,-0.0149143758822996,8.10987860138017E-5,0.000766002443075426,1.10071814331417E-7,0.000766002417123771,9.08760920675176E-8,-1.99394236902922E-7,6.21074890874358E-8,1.00013038591982,10.005763053894,2,20,10,5,2.50609645411706,0.220331757948181,0.0404026173055172,172.741912841797,48.9991645812988,49.0003547668457,380.45849609375,380.45849609375,,,8.7247257232666,0,1,,,,,,1,1,1,48.9993133544922,0,48.9996234669405,,,,,,,,,,,,,,,,,,,,,,,,,,,,,,,,,
,3755410997.01488,48.9998474121094,380.45849609375,,,5,,,,-2.43000010959804,,,,,0.000766138540380947,1.07768408634522E-7,-0.0170164544396014,9.06980328838095E-5,0.000766038566227886,1.07754345831501E-7,0.000766038532443695,8.23729664494105E-8,-2.2750820881299E-7,6.9467211286326E-8,1.00013050798937,10.005763053894,2,20,10,5,2.50622302493349,0.220250225183358,0.0404026173055172,172.741912841797,48.9991493225098,49.0000648498535,380.45849609375,380.45849609375,,,8.67297267913818,0,1,,,,,,1,1,1,48.9996299743652,0,48.9997296052821,,,,,,,,,,,,,,,,,,,,,,,,,,,,,,,,,
,3755411201.93495,49.0007419586182,380.45849609375,,,5,,,,-2.43000010959804,,,,,0.000765838904471054,1.19838715827341E-7,-0.0199613427235166,0.000102854710235194,0.000765739025918908,1.19823086799672E-7,0.000765738979447586,9.03121668323141E-8,-2.66776697233677E-7,7.87482358675679E-8,1.00013043419333,10.005763053894,2,20,10,5,2.50525415706838,0.220035316139161,0.0404026173055172,172.741912841797,48.9995994567871,49.0013732910156,380.45849609375,380.45849609375,,,8.62873935699463,0,1,,,,,,1,1,1,49.0006713867188,0,49.0003475613064,,,,,,,,,,,,,,,,,,,,,,,,,,,,,,,,,
,3755411406.83298,49.0008583068848,380.45849609375,,,5,,,,-2.43000010959804,,,,,0.000766391983906647,1.32528659977346E-7,-0.0152256329809104,6.94653909970874E-5,0.000766292029143523,1.32511375257394E-7,0.000766292002087139,1.21362033460607E-7,-2.03632469158667E-7,5.32026447360684E-8,1.00013043951826,10.005763053894,2,20,10,5,2.50704521241373,0.220401439773173,0.0404026173055172,172.741912841797,48.9995079040527,49.0013122558594,380.45849609375,380.45849609375,,,8.58870983123779,0,1,,,,,,1,1,1,49.0007934570313,0,49.0004243289723,,,,,,,,,,,,,,,,,,,,,,,,,,,,,,,,,
,3755411611.86402,49.0007019042969,380.45849609375,,,5,,,,-2.43000010959804,,,,,0.000766456504837531,1.33791211961877E-7,-0.0152235452454219,0.000144128129025981,0.000766356547144364,1.33773763534172E-7,0.000766356520093122,7.54791176732655E-8,-2.03621689615755E-7,1.10446016702106E-7,1.00013043236016,10.005763053894,2,20,10,5,2.50725626719718,0.220420086866565,0.0404026173055172,172.741912841797,48.9991111755371,49.0013961791992,380.45849609375,380.45849609375,,,8.55204391479492,0,1,,,,,,1,1,1,49.000659942627,0,48.9999595218235,,,,,,,,,,,,,,,,,,,,,,,,,,,,,,,,,
,3755411816.71779,49.0004959106445,380.45849609375,,,5,,,,-2.43000010959804,,,,,0.000766459223754282,1.19508515903719E-7,-0.0139718181369073,9.97263981206308E-5,0.000766359272930618,1.19492931285217E-7,0.000766359250144886,9.1866792759061E-8,-1.86879947769188E-7,7.64136965163797E-8,1.00013042293242,10.005763053894,2,20,10,5,2.50726034522643,0.220475645410921,0.0404026173055172,172.741912841797,48.999828338623,49.0008506774902,380.45849609375,380.45849609375,,,8.51942920684814,0,1,,,,,,1,1,1,49.0004234313965,0,49.0003731671502,,,,,,,,,,,,,,,,,,,,,,,,,,,,,,,,,
,3755412021.69831,49.0009746551514,380.45849609375,,,5,,,,-2.43000010959804,,,,,0.000766552460735096,1.01679615546146E-7,-0.0203048270372843,9.55659146314405E-5,0.000766452480961411,1.01666353694581E-7,0.00076645243283222,7.05136535415186E-8,-2.71620089031407E-7,7.3238460782422E-8,1.00013044484318,10.005763053894,2,20,10,5,2.50758970169478,0.220225296883033,0.0404026173055172,172.741912841797,48.999698638916,49.0019874572754,380.45849609375,380.45849609375,,,8.48898696899414,0,1,,,,,,1,1,1,49.000732421875,0,49.000366411711,,,,,,,,,,,,,,,,,,,,,,,,,,,,,,,,,
,3755412226.84047,49.0007667541504,380.45849609375,,,5,,,,-2.43000010959804,,,,,0.000766306469400452,1.29538537521685E-7,-0.0165902407106922,0.000143449597272748,0.000766206529000412,1.29521643323636E-7,0.000766206496880381,6.85324388030036E-8,-2.21858410525543E-7,1.09905236094409E-7,1.00013043532815,10.005763053894,2,20,10,5,2.50677072267547,0.220317143988775,0.0404026173055172,172.741912841797,48.9998741149902,49.0012474060059,380.45849609375,380.45849609375,,,8.46374893188477,0,1,,,,,,1,1,1,49.0007514953613,0,49.0004386901855,,,,,,,,,,,,,,,,,,,,,,,,,,,,,,,,,
,3755412431.73304,49.0005016326904,380.45849609375,,,5,,,,-2.43000010959804,,,,,0.000766242609819877,1.3914558130462E-7,-0.0218059105291797,0.000142040018017217,0.000766142687043342,1.3912743586002E-7,0.000766142631557415,8.66953999957474E-8,-2.91582357809283E-7,1.08813377066248E-7,1.0001304231943,10.005763053894,2,20,10,5,2.50658186626176,0.220070610199363,0.0404026173055172,172.741912841797,48.999683380127,49.0005416870117,380.45849609375,380.45849609375,,,8.4398193359375,0,1,,,,,,1,1,1,49.0005416870117,0,49.0002409617106,,,,,,,,,,,,,,,,,,,,,,,,,,,,,,,,,
,3755412636.58519,49.0008563995361,380.45849609375,,,5,,,,-2.43000010959804,,,,,0.000766633980846473,1.21684661906116E-7,-0.0176950559052305,0.000112072347595094,0.000766533994588406,1.21668791498187E-7,0.000766533958032291,8.61685077658499E-8,-2.3673404545938E-7,8.58969329722312E-8,1.00013043943096,10.005763053894,2,20,10,5,2.50784634025802,0.220362946275862,0.0404026173055172,172.741912841797,48.9997634887695,49.0011367797852,380.45849609375,380.45849609375,,,8.41890048980713,0,1,,,,,,1,1,1,49.0009880065918,0,49.0004219479031,,,,,,,,,,,,,,,,,,,,,,,,,,,,,,,,,
,3755412841.45455,49.0014877319336,380.45849609375,,,5,,,,-2.43000010959804,,,,,0.000767038613191607,1.56828030203466E-7,-0.0199757870876978,0.000123821753307193,0.000766938552003172,1.56807571782192E-7,0.00076693850539167,1.24795203113588E-7,-2.67387948012774E-7,9.4946152360512E-8,1.00013046832523,10.005763053894,2,20,10,5,2.50917876584214,0.22037937122079,0.0404026173055172,172.741912841797,49.0000114440918,49.0016212463379,380.45849609375,380.45849609375,,,8.40064239501953,0,1,,,,,,1,1,1,49.0015640258789,0,49.0009552450741,,,,,,,,,,,,,,,,,,,,,,,,,,,,,,,,,
,3755413046.47622,49.0002822875977,380.45849609375,,,5,,,,-2.43000010959804,,,,,0.000766109935938627,1.48420618813807E-7,-0.0144857333401358,0.000115870993598244,0.0007660100381524,1.48401265336513E-7,0.000766010013670779,1.18945440159145E-7,-1.93665521695152E-7,8.87407337068238E-8,1.00013041315551,10.005763053894,2,20,10,5,2.50611972282533,0.220352692753071,0.0404026173055172,172.741912841797,48.9995307922363,49.0004425048828,380.45849609375,380.45849609375,,,8.38406658172607,0,1,,,,,,1,1,1,49.0003547668457,0,48.9999856948853,,,,,,,,,,,,,,,,,,,,,,,,,,,,,,,,,
,3755413249.0461,49.0005626678467,380.45849609375,,,5,,,,-2.43000010959804,,,,,0.00076659552354089,1.40618196175231E-7,-0.0115869302893659,0.000129717154950744,0.00076649555260137,1.40599858299841E-7,0.000766495536927683,9.94225624161675E-8,-1.55008458738859E-7,9.94156639395354E-8,1.00013042598771,10.005763053894,2,20,10,5,2.50769703153435,0.220619233698699,0.0404026173055172,172.741912841797,48.9996147155762,49.0007133483887,380.45849609375,380.45849609375,,,8.36877536773682,0,1,,,,,,1,1,1,49.0004081726074,0,49.0001467536478,,,,,,,,,,,,,,,,,,,,,,,,,,,,,,,,,
,3755413453.98507,48.9998950958252,380.45849609375,,,5,,,,-2.43000010959804,,,,,0.00076660019254801,1.15424889234677E-7,-0.021088244065349,9.09736550209912E-5,0.000766500156480964,1.15409827078327E-7,0.00076650010456298,9.19715298877685E-8,-2.82117498852686E-7,6.97184758607983E-8,1.00013051017172,10.005763053894,2,20,10,5,2.50774885558837,0.220204723721579,0.0404026173055172,172.741912841797,48.9993171691895,49.000415802002,380.45849609375,380.45849609375,,,8.35470581054687,0,1,,,,,,1,1,1,49.0001182556152,0,48.9998817443848,,,,,,,,,,,,,,,,,,,,,,,,,,,,,,,,,
,3755413658.78273,49.0001659393311,380.45849609375,,,5,,,,-2.43000010959804,,,,,0.000766728464509426,1.33364184067985E-7,-0.0168985013058558,9.39805670556368E-5,0.000766628490151163,1.33346794601785E-7,0.000766628456808055,1.12218849760609E-7,-2.26105176754799E-7,7.20298367968207E-8,1.00013040783058,10.005763053894,2,20,10,5,2.50815235471184,0.220424978799965,0.0404026173055172,172.741912841797,48.9994621276855,49.0003471374512,380.45849609375,380.45849609375,,,8.34239196777344,0,1,,,,,,1,1,1,49.0000267028809,0,48.9999313354492,,,,,,,,,,,,,,,,,,,,,,,,,,,,,,,,,
,3755413863.70363,49.0009365081787,380.45849609375,,,5,,,,-2.43000010959804,,,,,0.000766986408509032,1.3192938522718E-7,-0.0182037041895819,0.000101502378941526,0.000766886373475195,1.31912178194084E-7,0.000766886334769462,1.06508498831242E-7,-2.43650973484245E-7,7.78252043532378E-8,1.0001304430973,10.005763053894,2,20,10,5,2.50900117400731,0.220441975019174,0.0404026173055172,172.741912841797,48.9994087219238,49.001091003418,380.45849609375,380.45849609375,,,8.33201217651367,0,1,,,,,,1,1,1,49.0009803771973,0,49.0003823174371,,,,,,,,,,,,,,,,,,,,,,,,,,,,,,,,,
,3755414068.69102,49.0001182556152,380.45849609375,,,5,,,,-2.43000010959804,,,,,0.000766930353330735,1.53394439213375E-7,-0.0168473757405501,0.000138570612991401,0.000766830354321293,1.53374438320323E-7,0.00076683032117091,1.10613659617304E-7,-2.25480463519909E-7,1.06246584115169E-7,1.00013040564824,10.005763053894,2,20,10,5,2.50881258441319,0.220485260472113,0.0404026173055172,172.741912841797,48.9988479614258,49.000659942627,380.45849609375,380.45849609375,,,8.32353782653809,0,1,,,,,,1,1,1,48.9994735717773,0,48.9995029673857,,,,,,,,,,,,,,,,,,,,,,,,,,,,,,,,,
,3755414274.73949,48.9993667602539,380.45849609375,,,5,,,,-2.43000010959804,,,,,0.000766890200173781,1.87476232103556E-7,-0.0143470167744022,0.000131921668022852,0.000766790144801605,1.87451772273227E-7,0.000766790120762158,1.57831991079774E-7,-1.92006305672798E-7,1.01129765747617E-7,1.00013048599132,10.005763053894,2,20,10,5,2.50867160982218,0.22058319711041,0.0404026173055172,172.741912841797,48.9982070922852,48.999942779541,380.45849609375,380.45849609375,,,8.31507778167725,0,1,,,,,,1,1,1,48.9988250732422,0,48.9993582332835,,,,,,,,,,,,,,,,,,,,,,,,,,,,,,,,,
,3755414478.49081,49.000732421875,380.45849609375,,,5,,,,-2.43000010959804,,,,,0.00076678355983806,1.26102181674671E-7,-0.0132229521225904,0.000124376226301276,0.000766683558421212,1.26085735838459E-7,0.000766683538003939,8.25005466830617E-8,-1.76938336162683E-7,9.53481650527249E-8,1.00013043375686,10.005763053894,2,20,10,5,2.50831843853055,0.220601724357418,0.0404026173055172,172.741912841797,48.9993095397949,49.0008888244629,380.45849609375,380.45849609375,,,8.30828952789307,0,1,,,,,,1,1,1,49.0008811950684,0,49.0001354217529,,,,,,,,,,,,,,,,,,,,,,,,,,,,,,,,,
,3755414683.47284,49.0002613067627,380.45849609375,,,5,,,,-2.43000010959804,,,,,0.000766866387180987,9.77457282919565E-8,-0.0200667339537786,8.16133254965689E-5,0.000766766303527716,9.77329715070164E-8,0.000766766256501381,7.50794722560158E-8,-2.68544999890345E-7,6.25684150778125E-8,1.00013052693214,10.005763053894,2,20,10,5,2.50861572001723,0.220325910969665,0.0404026173055172,172.741912841797,48.9995346069336,49.0008277893066,380.45849609375,380.45849609375,,,8.30207252502441,0,1,,,,,,1,1,1,49.000602722168,0,48.9999878827263,,,,,,,,,,,,,,,,,,,,,,,,,,,,,,,,,
,3755414888.39889,49.0005531311035,380.45849609375,,,5,,,,-2.43000010959804,,,,,0.00076681776639238,1.22830054830691E-7,-0.0164324063411883,8.76597415485891E-5,0.000766717766805001,1.22814036742249E-7,0.000766717735272197,1.02802244403073E-7,-2.19894341738583E-7,6.71936467727217E-8,1.00013042555124,10.005763053894,2,20,10,5,2.50844268934396,0.220471055453645,0.0404026173055172,172.741912841797,48.9997482299805,49.0007667541504,380.45849609375,380.45849609375,,,8.29741954803467,0,1,,,,,,1,1,1,49.0005722045898,0,49.0003139271456,,,,,,,,,,,,,,,,,,,,,,,,,,,,,,,,,
,3755415093.27039,49.0002479553223,380.45849609375,,,5,,,,-2.43000010959804,,,,,0.000766850085143401,1.28225456522874E-7,-0.0195361703763934,0.000102597291328991,0.000766750004086175,1.28208721910072E-7,0.00076674995951466,1.01248577346631E-7,-2.61439124364394E-7,7.86524122903905E-8,1.00013052632109,10.005763053894,2,20,10,5,2.50856035147984,0.22034445800144,0.0404026173055172,172.741912841797,48.9994049072266,49.0003471374512,380.45849609375,380.45849609375,,,8.2924690246582,0,1,,,,,,1,1,1,49.0003280639648,0,48.9998705246869,,,,,,,,,,,,,,,,,,,,,,,,,,,,,,,,,
,3755415298.21955,49.0011825561523,380.45849609375,,,5,,,,-2.43000010959804,,,,,0.000767084958008203,1.45434089809713E-7,-0.0168038647617141,0.000127728656248398,0.000766984901485122,1.45415119773589E-7,0.000766984868499103,1.07475106368827E-7,-2.24943451046436E-7,9.79523280467416E-8,1.00013045435821,10.005763053894,2,20,10,5,2.5093181664996,0.220531605791115,0.0404026173055172,172.741912841797,48.999942779541,49.0015144348145,380.45849609375,380.45849609375,,,8.28754329681396,0,1,,,,,,1,1,1,49.0011787414551,0,49.0006432533264,,,,,,,,,,,,,,,,,,,,,,,,,,,,,,,,,
,3755415503.24209,49.0007400512695,380.45849609375,,,5,,,,-2.43000010959804,,,,,0.000766860483480991,1.19264096653921E-7,-0.0176466606812253,9.77882321483244E-5,0.000766760471764313,1.19248542576874E-7,0.000766760435397142,9.27366885978805E-8,-2.36156341183767E-7,7.49674695758658E-8,1.00013043410604,10.005763053894,2,20,10,5,2.50858709930429,0.220430171718442,0.0404026173055172,172.741912841797,48.9991912841797,49.0010070800781,380.45849609375,380.45849609375,,,8.28383445739746,0,1,,,,,,1,1,1,49.0009574890137,0,49.0001824322869,,,,,,,,,,,,,,,,,,,,,,,,,,,,,,,,,
,3755415708.22021,48.999885559082,380.45849609375,,,5,,,,-2.43000010959804,,,,,0.000767032489842523,1.49807819588471E-7,-0.0153327558165595,0.000147565231617592,0.000766932397698344,1.4978827076091E-7,0.00076693237023697,9.81374195048067E-8,-2.05236531229658E-7,1.13161711503854E-7,1.00013050973525,10.005763053894,2,20,10,5,2.50914086739626,0.220580950644946,0.0404026173055172,172.741912841797,48.9995002746582,49.0002670288086,380.45849609375,380.45849609375,,,8.28052997589111,0,1,,,,,,1,1,1,49.0000495910645,0,48.9999055301442,,,,,,,,,,,,,,,,,,,,,,,,,,,,,,,,,
,3755415913.18831,48.9998168945313,380.45849609375,,,5,,,,-2.43000010959804,,,,,0.000766982023207173,1.6746078659076E-7,-0.012563509035151,0.000136647559886529,0.000766881940058196,1.67438934705911E-7,0.000766881921621836,1.30607022257313E-7,-1.68157727977275E-7,1.04774054958888E-7,1.00013050659267,10.005763053894,2,20,10,5,2.50896511575957,0.220687703857688,0.0404026173055172,172.741912841797,48.9993896484375,49.0001258850098,380.45849609375,380.45849609375,,,8.27674865722656,0,1,,,,,,1,1,1,48.9997138977051,0,48.9997686498305,,,,,,,,,,,,,,,,,,,,,,,,,,,,,,,,,
,3755416116.84301,49.0004787445068,380.45849609375,,,5,,,,-2.43000010959804,,,,,0.00076704138575964,1.56429869164261E-7,-0.0223996420779828,0.000152922796669706,0.000766941359621066,1.5640946990542E-7,0.000766941301011427,1.03496002985303E-7,-2.99833803793161E-7,1.17271052021206E-7,1.00013042214678,10.005763053894,2,20,10,5,2.50919715566818,0.220274026371868,0.0404026173055172,172.741912841797,48.9990348815918,49.0012474060059,380.45849609375,380.45849609375,,,8.27447605133057,0,1,,,,,,1,1,1,48.9997711181641,0,48.9999825954437,,,,,,,,,,,,,,,,,,,,,,,,,,,,,,,,,
,3755416321.56043,49.001163482666,380.45849609375,,,5,,,,-2.43000010959804,,,,,0.000766935914730432,1.12070001069827E-7,-0.0238072417648505,7.85270120857453E-5,0.000766835878317473,1.12055383054564E-7,0.000766835812119404,9.45094099113671E-8,-3.18631612640264E-7,6.02028264262583E-8,1.00013045348527,10.005763053894,2,20,10,5,2.50885754227097,0.220182096948158,0.0404026173055172,172.741912841797,48.9998359680176,49.0015602111816,380.45849609375,380.45849609375,,,8.27150726318359,0,1,,,,,,1,1,1,49.0009422302246,0,49.000462214152,,,,,,,,,,,,,,,,,,,,,,,,,,,,,,,,,
,3755416528.43815,49.0006046295166,380.45849609375,,,5,,,,-2.43000010959804,,,,,0.000766947472370464,1.61185495944376E-7,-0.00985618758675155,0.000164284449593245,0.000766847454061144,1.61164475598952E-7,0.000766847442714913,1.00525355606785E-7,-1.31915341489452E-7,1.25970794532759E-7,1.00013042790817,10.005763053894,2,20,10,5,2.50884166270012,0.220796304671673,0.0404026173055172,172.741912841797,48.9997711181641,49.0009651184082,380.45849609375,380.45849609375,,,8.26957416534424,0,1,,,,,,1,1,1,49.000804901123,0,49.0003588059369,,,,,,,,,,,,,,,,,,,,,,,,,,,,,,,,,
,3755416733.2593,48.9998397827148,380.45849609375,,,5,,,,-2.43000010959804,,,,,0.000766964550926665,1.3713584292808E-7,-0.0130188656717909,9.83436677598075E-5,0.000766864469254431,1.3711794798826E-7,0.000766864449457875,1.14527658809713E-7,-1.74248531264044E-7,7.53972614096635E-8,1.0001305076402,10.005763053894,2,20,10,5,2.50890971402571,0.220662735782583,0.0404026173055172,172.741912841797,48.99951171875,49.0004348754883,380.45849609375,380.45849609375,,,8.26769638061523,0,1,,,,,,1,1,1,48.9999809265137,0,48.9999672384823,,,,,,,,,,,,,,,,,,,,,,,,,,,,,,,,,
,3755416938.19822,48.9998588562012,380.45849609375,,,5,,,,-2.43000010959804,,,,,0.000766982476602413,9.9346318905513E-8,-0.015826917307681,9.09597503418917E-5,0.000766882391921694,9.93333550570397E-8,0.00076688236266359,7.07282694694603E-8,-2.11837314204526E-7,6.97468803943468E-8,1.00013050851314,10.005763053894,2,20,10,5,2.50897916468673,0.22054492933894,0.0404026173055172,172.741912841797,48.9994659423828,49.0000915527344,380.45849609375,380.45849609375,,,8.26553821563721,0,1,,,,,,1,1,1,48.9999046325684,0,48.9998238507439,,,,,,,,,,,,,,,,,,,,,,,,,,,,,,,,,
,3755417143.15883,49.0027942657471,380.45849609375,,,5,,,,-2.43000010959804,,,,,0.000766927939080685,1.80267592666983E-7,-0.0121795865220999,0.000162256898540582,0.000766827846482349,1.80244065747665E-7,0.000766827829156772,1.30425643979119E-7,-1.63007574254494E-7,1.24406891408316E-7,1.00013052812153,10.005763053894,2,20,10,5,2.5087867173276,0.220688938887489,0.0404026173055172,172.741912841797,49.002197265625,49.0031394958496,380.45849609375,380.45849609375,,,8.26354312896729,0,1,,,,,,1,1,1,49.0027656555176,0,49.0027441136977,,,,,,,,,,,,,,,,,,,,,,,,,,,,,,,,,
,3755417349.42084,49.0009441375732,380.45849609375,,,5,,,,-2.43000010959804,,,,,0.000767245888137555,1.36388497607107E-7,-0.0223254728802917,0.000102860862029056,0.000767145818992973,1.36370708941833E-7,0.000767145760755303,1.11233237882572E-7,-2.98920669014578E-7,7.88932002612226E-8,1.00013044344648,10.005763053894,2,20,10,5,2.50986585277877,0.220335997967956,0.0404026173055172,172.741912841797,48.9997863769531,49.0011253356934,380.45849609375,380.45849609375,,,8.26269149780273,0,1,,,,,,1,1,1,49.000904083252,0,49.0004618027631,,,,,,,,,,,,,,,,,,,,,,,,,,,,,,,,,
,3755417553.38923,48.9998569488525,380.45849609375,,,5,,,,-2.43000010959804,,,,,0.000767172954523104,1.24945346408521E-7,-0.0166965478804961,0.00013333424605347,0.000767072845053589,1.24929042115892E-7,0.000767072812483817,7.17506977279545E-8,-2.2353249074958E-7,1.02269755742087E-7,1.00013050842584,10.005763053894,2,20,10,5,2.50960561046823,0.220561610778184,0.0404026173055172,172.741912841797,48.9997367858887,49.0003776550293,380.45849609375,380.45849609375,,,8.26201725006104,0,1,,,,,,1,1,1,48.9998397827148,0,49.0000170539407,,,,,,,,,,,,,,,,,,,,,,,,,,,,,,,,,
,3755417758.2826,49.0001029968262,380.45849609375,,,5,,,,-2.43000010959804,,,,,0.000767338353985384,1.19193028919334E-7,-0.013685483446757,0.000123181454719606,0.00076723821429399,1.19177473912771E-7,0.000767238192407544,7.2612915531748E-8,-1.83260021433169E-7,9.45020358839351E-8,1.00013051968675,10.005763053894,2,20,10,5,2.51013507464788,0.220741075631142,0.0404026173055172,172.741912841797,48.9996299743652,49.0007133483887,380.45849609375,380.45849609375,,,8.26026248931885,0,1,,,,,,1,1,1,49.0004539489746,0,49.0000958442688,,,,,,,,,,,,,,,,,,,,,,,,,,,,,,,,,
,3755417963.1569,48.9997653961182,380.45849609375,,,5,,,,-2.43000010959804,,,,,0.000766949906303869,1.04590676428626E-7,-0.013697403489461,0.000105437550807306,0.000766849829152991,1.04577028683422E-7,0.0007668498072395,6.63325316917277E-8,-1.83326791518419E-7,8.08476973550838E-8,1.00013050423574,10.005763053894,2,20,10,5,2.50886442124024,0.220628810903938,0.0404026173055172,172.741912841797,48.9994697570801,49.0003547668457,380.45849609375,380.45849609375,,,8.25887203216553,0,1,,,,,,1,1,1,48.9999198913574,0,48.9998413534725,,,,,,,,,,,,,,,,,,,,,,,,,,,,,,,,,
,3755418168.13387,49.0000247955322,380.45849609375,,,5,,,,-2.43000010959804,,,,,0.000767144075583938,1.26775412451606E-7,-0.0142674915027863,9.63183093035755E-5,0.000767044051988067,1.26758882919508E-7,0.00076704402820651,1.03013746892745E-7,-1.91005244607985E-7,7.38646217760508E-8,1.00013040137084,10.005763053894,2,20,10,5,2.50950178798069,0.2206596984201,0.0404026173055172,172.741912841797,48.9988174438477,49.0003929138184,380.45849609375,380.45849609375,,,8.25806903839111,0,1,,,,,,1,1,1,48.9999046325684,0,48.9995458266314,,,,,,,,,,,,,,,,,,,,,,,,,,,,,,,,,
,3755418373.16147,48.9998683929443,380.45849609375,,,5,,,,-2.43000010959804,,,,,0.000767270025880288,2.23009946912616E-7,-0.0138773896359874,0.000196959619535049,0.000767169903342034,2.22980845916634E-7,0.000767169880839478,1.63997217626069E-7,-1.85813259756019E-7,1.51080674662927E-7,1.00013050894961,10.005763053894,2,20,10,5,2.50991229724662,0.220713014966188,0.0404026173055172,172.741912841797,48.9993629455566,49.000373840332,380.45849609375,380.45849609375,,,8.25686740875244,0,1,,,,,,1,1,1,49,0,48.9998851102941,,,,,,,,,,,,,,,,,,,,,,,,,,,,,,,,,
,3755418577.94123,49.0003414154053,380.45849609375,,,5,,,,-2.43000010959804,,,,,0.000767127823326243,1.49665222677378E-7,-0.0133140556521862,0.000145510459099699,0.000767027790736029,1.49645706503627E-7,0.000767027770027151,9.96965684618473E-8,-1.78237397021447E-7,1.11599425231056E-7,1.00013041586162,10.005763053894,2,20,10,5,2.50944495104078,0.220696781792973,0.0404026173055172,172.741912841797,48.9997406005859,49.0010566711426,380.45849609375,380.45849609375,,,8.25642681121826,0,1,,,,,,1,1,1,49.0000267028809,0,49.0003960553338,,,,,,,,,,,,,,,,,,,,,,,,,,,,,,,,,
,3755418783.10219,48.9995231628418,380.45849609375,,,5,,,,-2.43000010959804,,,,,0.000767275514327797,1.51897677234866E-7,-0.0159670491946606,0.000120931342629978,0.000767175403193281,1.51877858214821E-7,0.000767175373403402,1.20261253474767E-7,-2.13794582240942E-7,9.27583674317263E-8,1.00013049314941,10.005763053894,2,20,10,5,2.50993829896283,0.22062305660044,0.0404026173055172,172.741912841797,48.9983100891113,49.0002250671387,380.45849609375,380.45849609375,,,8.25641250610352,0,1,,,,,,1,1,1,48.9991683959961,0,48.9995545779958,,,,,,,,,,,,,,,,,,,,,,,,,,,,,,,,,
,3755418988.06336,49.0004177093506,380.45849609375,,,5,,,,-2.43000010959804,,,,,0.000767291203524861,1.63101530994991E-7,-0.0162964968924655,0.000117999794713954,0.000767191058937941,1.63080243463774E-7,0.00076719102790544,1.35660204589633E-7,-2.18210252929382E-7,9.05067660393572E-8,1.00013053409024,10.005763053894,2,20,10,5,2.50999089114203,0.220613129136272,0.0404026173055172,172.741912841797,49.0002632141113,49.0011444091797,380.45849609375,380.45849609375,,,8.25688171386719,0,1,,,,,,1,1,1,49.0005989074707,0,49.0007008446587,,,,,,,,,,,,,,,,,,,,,,,,,,,,,,,,,
,3755419193.17021,49.0001087188721,380.45849609375,,,5,,,,-2.43000010959804,,,,,0.000767345472479945,1.20568943094721E-7,-0.0159927337367138,0.000121052084072207,0.000767245331658668,1.20553208496141E-7,0.000767245301770148,7.68670958054607E-8,-2.14158010326381E-7,9.28683243153883E-8,1.00013051994863,10.005763053894,2,20,10,5,2.51016724773664,0.220642043512663,0.0404026173055172,172.741912841797,48.9993934631348,49.0006103515625,380.45849609375,380.45849609375,,,8.25648403167725,0,1,,,,,,1,1,1,48.9999809265137,0,48.9999439015108,,,,,,,,,,,,,,,,,,,,,,,,,,,,,,,,,
,3755419397.98928,49.0020484924316,380.45849609375,,,5,,,,-2.43000010959804,,,,,0.00076735184620192,1.08558847523538E-7,-0.0145267847471828,8.96738369405731E-5,0.000767251724463347,1.08544683094788E-7,0.000767251699802862,8.39629032340423E-8,-1.94529171668333E-7,6.87908359351658E-8,1.00013049398963,10.005763053894,2,20,10,5,2.51018245239009,0.220708091454217,0.0404026173055172,172.741912841797,49.0002975463867,49.0021476745605,380.45849609375,380.45849609375,,,8.25564002990723,0,1,,,,,,1,1,1,49.0020790100098,0,49.0011543697781,,,,,,,,,,,,,,,,,,,,,,,,,,,,,,,,,
,3755419603.079,48.9993991851807,380.45849609375,,,5,,,,-2.43000010959804,,,,,0.000767296786973199,1.79208723556819E-7,-0.0193797387477357,0.000174196454373216,0.000767196677415695,1.79185342113914E-7,0.000767196633529565,1.1937574103835E-7,-2.59496790501849E-7,1.33629410236014E-7,1.00013048747531,10.005763053894,2,20,10,5,2.5100210235428,0.220479670709815,0.0404026173055172,172.741912841797,48.998291015625,49.0000152587891,380.45849609375,380.45849609375,,,8.25578308105469,0,1,,,,,,1,1,1,48.9990539550781,0,48.9994199416217,,,,,,,,,,,,,,,,,,,,,,,,,,,,,,,,,
,3755419807.89949,48.9996395111084,380.45849609375,,,5,,,,-2.43000010959804,,,,,0.000766866760346185,9.1218638095265E-8,-0.0178300376574807,6.7660447008626E-5,0.000766766786426798,9.12067462188099E-8,0.000766766749299568,7.50223240108814E-8,-2.38612347576381E-7,5.18683087812657E-8,1.00013038373748,10.005763053894,2,20,10,5,2.50860833727826,0.220423954504101,0.0404026173055172,172.741912841797,48.9983749389648,49.0005722045898,380.45849609375,380.45849609375,,,8.25610446929932,0,1,,,,,,1,1,1,48.9993095397949,0,48.9992667304145,,,,,,,,,,,,,,,,,,,,,,,,,,,,,,,,,
,3755420013.12834,49.0016136169434,380.45849609375,,,5,,,,-2.43000010959804,,,,,0.000767413262641954,9.84259553053269E-8,-0.0170359925446579,7.25465050494598E-5,0.000767313148159792,9.84131149440427E-8,0.000767313114241634,8.11655742963837E-8,-2.2814840796212E-7,5.56533084562596E-8,1.00013047408663,10.005763053894,2,20,10,5,2.51039302341787,0.22061581825773,0.0404026173055172,172.741912841797,48.9998588562012,49.0018692016602,380.45849609375,380.45849609375,,,8.25523281097412,0,1,,,,,,1,1,1,49.0016784667969,0,49.00080018885,,,,,,,,,,,,,,,,,,,,,,,,,,,,,,,,,
,3755420217.86176,48.9997978210449,380.45849609375,,,5,,,,-2.43000010959804,,,,,0.000767564874155371,1.15349340135441E-7,-0.0210888762343533,0.000111485357016537,0.00076746471562029,1.1533428835113E-7,0.000767464663633856,7.73486462656226E-8,-2.82480981567041E-7,8.55522354490944E-8,1.00013050571973,10.005763053894,2,20,10,5,2.51090458257782,0.220481801417843,0.0404026173055172,172.741912841797,48.998950958252,49.0001945495605,380.45849609375,380.45849609375,,,8.25502490997314,0,1,,,,,,1,1,1,48.9996528625488,0,48.9997755686442,,,,,,,,,,,,,,,,,,,,,,,,,,,,,,,,,
,3755420371.5101,49.0011787414551,380.45849609375,,,5,,,,-2.43000010959804,,,,,0.0007673214538129,1.74558143821637E-7,-0.016777123220912,0.000127457844485936,0.000767221366575864,1.74535374951784E-7,0.000767221333684611,1.44583779070967E-7,-2.24654718553581E-7,9.77656787380815E-8,1.00013045418362,10.005763053894,2,20,10,5,2.51009169781296,0.220600768293504,0.0404026173055172,172.741912841797,48.9994621276855,49.0015182495117,380.45849609375,380.45849609375,,,8.25424861907959,0,1,,,,,,1,1,1,49.001163482666,0,49.0003920162425,,,,,,,,,,,,,,,,,,,,,,,,,,,,,,,,,