File: Experimental_Data/Fig3B/Lifetime_320Oe.dat
[Header]
; MPMS3 Data File (default extension .dat)
; Copyright (c) 2007, Quantum Design, Inc. All rights reserved.
TITLE,49K_320Oe
FILEOPENTIME,3755914236.6695,01/06/2019,5:29 am
BYAPP,SQUID AC,0.9.1.0
INFO,MPMS3 Measurement Release 1.1.16 Build 347, MultiVu Release 2.3.3.2,APPNAME
INFO,0,MOMENT_UNITS
INFO,CoIINO3,SAMPLE_MATERIAL
INFO,40 Hours Pumped Turbo,SAMPLE_COMMENT
INFO,,SAMPLE_MASS
INFO,,SAMPLE_VOLUME
INFO,,SAMPLE_MOLECULAR_WEIGHT
INFO,,SAMPLE_SIZE
INFO,,SAMPLE_SHAPE
INFO,Brass,SAMPLE_HOLDER
INFO,Standard,SAMPLE_HOLDER_DETAIL
INFO,65.37,SAMPLE_OFFSET
DATATYPE,COMMENT,1
DATATYPE,TIME,2
STARTUPAXIS,X,2
STARTUPAXIS,Y1,5
FIELDGROUP, VSM,2,3,4,5,6,8,9,10,11,14,15
FIELDGROUP, DC, 2,3,4,14,56,57,58,59,60,61,62,63,64,65,66,67,68,69
FIELDGROUP, AC, 2,3,4,11,16,17,18,19,20,21,22,23,24,25,26,27,28,29,30
STARTUPGROUP, All
[Data]
Comment,Time Stamp (sec),Temperature (K),Magnetic Field (Oe),Moment (emu),M. Std. Err. (emu),Transport Action,Averaging Time (sec),Frequency (Hz),Peak Amplitude (mm),Center Position (mm),Lockin Signal' (V),Lockin Signal (V),Range,M. Quad. Signal (emu),AC Moment (emu),AC M. Std Err. (emu),AC Phase (deg),AC Phase Std. Err. (deg),AC Susceptibility (emu/Oe),AC Suscept. Std Err. (emu/Oe),AC X' (emu/Oe),AC X' Std Err. (emu/Oe),AC X'' (emu/Oe),AC X'' Std Err. (emu/Oe),AC Drive (Oe),AC Frequency (Hz),AC Averaging Time (sec),AC Cycles,AC Range,AC Measure Type,AC Signal' (V),AC Signal'' (V),AC Trim Coil Ratio,AC Trim Coil Phase,Min. Temperature (K),Max. Temperature (K),Min. Field (Oe),Max. Field (Oe),Mass (grams),Motor Lag (deg),Pressure (Torr),Measure Count,Measurement Number,SQUID Status (code),Motor Status (code),Measure Status (code),Motor Current (amps),Motor Temp. (C),Temp. Status (code),Field Status (code),Chamber Status (code),Chamber Temp (K),Redirection State,Average Temp (K),Rotation Angle (deg),Rotator state,DC Moment Fixed Ctr (emu),DC Moment Err Fixed Ctr (emu),DC Moment Free Ctr (emu),DC Moment Err Free Ctr (emu),DC Fixed Fit,DC Free Fit,DC Calculated Center (mm),DC Calculated Center Err (mm),DC Scan Length (mm),DC Scan Time (s),DC Number of Points,DC Squid Drift,DC Min V (V),DC Max V (V),DC Scans per Measure,Map 01,Map 02,Map 03,Map 04,Map 05,Map 06,Map 07,Map 08,Map 09,Map 10,Map 11,Map 12,Map 13,Map 14,Map 15,Map 16
,3755914240.18033,48.9604778289795,319.635162353516,,,5,,,,-2.43000010959804,,,,,0.000692373810573905,1.10875212630099E-7,0.0205339099683401,8.12518017249351E-5,0.000692283915068543,1.10860816962442E-7,0.000692283870610301,9.55446167072333E-8,2.4810370678352E-7,5.62258566484135E-8,1.00012985352311,10.005763053894,2,20,10,5,2.26479915088942,0.200381358609553,0.0404026173055172,172.741912841797,48.9070243835449,48.9736442565918,319.635162353516,319.635162353516,,,12.2519779205322,0,1,,,,,,1,1,1,48.9543533325195,0,48.9339902541217,,,,,,,,,,,,,,,,,,,,,,,,,,,,,,,,,
,3755914445.11838,48.99928855896,319.635162353516,,,5,,,,-2.43000010959804,,,,,0.000705099495801629,8.68075346487545E-8,-0.0101384287022022,6.88060105255517E-5,0.000705007504721746,8.67962092699932E-8,0.000705007493684524,7.1983633221673E-8,-1.2475034539336E-7,4.84967884694245E-8,1.00013048241227,10.005763053894,2,20,10,5,2.30653461244288,0.202829402307723,0.0404026173055172,172.741912841797,48.9988670349121,49.000057220459,319.635162353516,319.635162353516,,,12.0709562301636,0,1,,,,,,1,1,1,48.9997100830078,0,48.9994776108686,,,,,,,,,,,,,,,,,,,,,,,,,,,,,,,,,
,3755914649.97892,48.9997425079346,319.635162353516,,,5,,,,-2.43000010959804,,,,,0.000711672955294303,8.6038020804876E-8,-0.0136657906221549,9.85011374696678E-5,0.000711580091823653,8.6026794033983E-8,0.000711580071583301,4.98847871835823E-8,-1.69721130180894E-7,7.00864986956407E-8,1.00013050318821,10.005763053894,2,20,10,5,2.32805043474087,0.204577003351104,0.0404026173055172,172.741912841797,48.9994773864746,49.0004615783691,319.635162353516,319.635162353516,,,11.3618459701538,0,1,,,,,,1,1,1,48.999927520752,0,48.9999631993911,,,,,,,,,,,,,,,,,,,,,,,,,,,,,,,,,
,3755914856.52211,48.9989624023438,319.635162353516,,,5,,,,-2.43000010959804,,,,,0.000715681212262009,1.00018722737872E-7,-0.0119840628411945,4.59893013794266E-5,0.000715587851314741,1.00005675248935E-7,0.000715587835661803,9.44455928067811E-8,-1.49673323042311E-7,3.28810748208015E-8,1.00013046748502,10.005763053894,2,20,10,5,2.34115635061954,0.205797936303936,0.0404026173055172,172.741912841797,48.9979438781738,48.9998893737793,319.635162353516,319.635162353516,,,10.7587985992432,0,1,,,,,,1,1,1,48.9986724853516,0,48.9992471582749,,,,,,,,,,,,,,,,,,,,,,,,,,,,,,,,,
,3755915062.34778,49.0005054473877,319.635162353516,,,5,,,,-2.43000010959804,,,,,0.000718585578863478,9.53086899245664E-8,-0.0095056344811173,7.40731756578653E-5,0.000718491870733177,9.52962610651556E-8,0.000718491860845169,7.90589186097133E-8,-1.19201119655833E-7,5.32077509509754E-8,1.00013042336889,10.005763053894,2,20,10,5,2.35064825587311,0.206734776554528,0.0404026173055172,172.741912841797,48.9998435974121,49.0006217956543,319.635162353516,319.635162353516,,,10.2594919204712,0,1,,,,,,1,1,1,49.0004196166992,0,49.0002356136546,,,,,,,,,,,,,,,,,,,,,,,,,,,,,,,,,
,3755915267.28457,49.001974105835,319.635162353516,,,5,,,,-2.43000010959804,,,,,0.000720612275090743,1.3999813872232E-7,-0.0102740786440254,6.83697500736559E-5,0.000720518254242124,1.39979872666824E-7,0.000720518242658205,1.31039442709116E-7,-1.29200810806281E-7,4.92242745635177E-8,1.00013049058517,10.005763053894,2,20,10,5,2.35728079668354,0.207286229845969,0.0404026173055172,172.741912841797,49.0003662109375,49.0023002624512,319.635162353516,319.635162353516,,,9.84530258178711,0,1,,,,,,1,1,1,49.0016479492188,0,49.0010218900793,,,,,,,,,,,,,,,,,,,,,,,,,,,,,,,,,
,3755915473.60907,49.0001220703125,319.635162353516,,,5,,,,-2.43000010959804,,,,,0.000722327159667483,1.02260929277225E-7,-0.0132845782149271,8.51803950609061E-5,0.000722232893426006,1.02247583865352E-7,0.000722232874012787,8.16782241827401E-8,-1.67456649646502E-7,6.15080165560241E-8,1.00013052055969,10.005763053894,2,20,10,5,2.36290147374984,0.207655374346098,0.0404026173055172,172.741912841797,48.9992485046387,49.000358581543,319.635162353516,319.635162353516,,,9.49902439117432,0,1,,,,,,1,1,1,49.0000228881836,0,48.9998229531681,,,,,,,,,,,,,,,,,,,,,,,,,,,,,,,,,
,3755915679.74504,48.9990844726562,319.635162353516,,,5,,,,-2.43000010959804,,,,,0.00072437946175965,7.59194951465656E-8,-0.0173389177955929,7.35270282744703E-5,0.000724284962075773,7.59095909890484E-8,0.000724284928910912,5.41009800049351E-8,-2.19183984109468E-7,5.32480043441087E-8,1.00013047307182,10.005763053894,2,20,10,5,2.36962976431565,0.208077700070502,0.0404026173055172,172.741912841797,48.9977531433105,49.0001754760742,319.635162353516,319.635162353516,,,9.20752239227295,0,1,,,,,,1,1,1,48.9986190795898,0,48.9993902842204,,,,,,,,,,,,,,,,,,,,,,,,,,,,,,,,,
,3755915884.66695,49.0001029968262,319.635162353516,,,5,,,,-2.43000010959804,,,,,0.000725060291266388,9.89381926303875E-8,-0.00917849485123678,0.000100804912263255,0.000724965752143812,9.89252922826051E-8,0.000724965742841623,6.66828566609745E-8,-1.16135855929766E-7,7.30726356492687E-8,1.00013040494988,10.005763053894,2,20,10,5,2.37182724401045,0.208611074340675,0.0404026173055172,172.741912841797,48.9996757507324,49.0002517700195,319.635162353516,319.635162353516,,,8.96632862091064,0,1,,,,,,1,1,1,49.0000991821289,0,49.0000099605984,,,,,,,,,,,,,,,,,,,,,,,,,,,,,,,,,
,3755916089.55295,48.9998626708984,319.635162353516,,,5,,,,-2.43000010959804,,,,,0.000726185553079577,1.15681781996293E-7,-0.018951713103168,0.000117867326594844,0.000726090791923155,1.15666686488826E-7,0.000726090752202846,7.78200125768247E-8,-2.40168896232838E-7,8.55735239770295E-8,1.00013050868772,10.005763053894,2,20,10,5,2.3755438200931,0.208529628818517,0.0404026173055172,172.741912841797,48.9984588623047,49.0005035400391,319.635162353516,319.635162353516,,,8.76320362091064,0,1,,,,,,1,1,1,48.9991149902344,0,48.9998154891165,,,,,,,,,,,,,,,,,,,,,,,,,,,,,,,,,
,3755916294.48961,48.9998779296875,319.635162353516,,,5,,,,-2.43000010959804,,,,,0.000727467767252263,8.89486202128978E-8,-0.0116276375751969,0.00010334389443322,0.000727372838269693,8.89370130979191E-8,0.000727372823291315,4.75393520219366E-8,-1.47613450052753E-7,7.51651668534956E-8,1.00013050938607,10.005763053894,2,20,10,5,2.3797115571375,0.209202022970256,0.0404026173055172,172.741912841797,48.9989738464355,49.0002479553223,319.635162353516,319.635162353516,,,8.54697132110596,0,1,,,,,,1,1,1,48.9995079040527,0,48.999568939209,,,,,,,,,,,,,,,,,,,,,,,,,,,,,,,,,
,3755916499.47884,49.0002021789551,319.635162353516,,,5,,,,-2.43000010959804,,,,,0.000727829489463018,9.08699625071473E-8,-0.011740048585426,0.00011434571384426,0.000727734502480324,9.08581033235321E-8,0.000727734487203345,3.64863011842558E-8,-1.49114619422795E-7,8.3210244353934E-8,1.00013052422603,10.005763053894,2,20,10,5,2.38089524323822,0.209301370761066,0.0404026173055172,172.741912841797,48.9997673034668,49.000560760498,319.635162353516,319.635162353516,,,8.36113166809082,0,1,,,,,,1,1,1,49.0003356933594,0,49.0001362694634,,,,,,,,,,,,,,,,,,,,,,,,,,,,,,,,,
,3755916703.55691,49.0017280578613,319.635162353516,,,5,,,,-2.43000010959804,,,,,0.000728661852799694,1.08894878751268E-7,-0.017692741308168,8.92369622600915E-5,0.000728566789897272,1.08880672074751E-7,0.000728566755160908,8.73480403553666E-8,-2.24978936390438E-7,6.50024660880399E-8,1.00013047932426,10.005763053894,2,20,10,5,2.38363985005237,0.20929308251371,0.0404026173055172,172.741912841797,49.001335144043,49.0026321411133,319.635162353516,319.635162353516,,,8.20438480377197,0,1,,,,,,1,1,1,49.001594543457,0,49.0019903743968,,,,,,,,,,,,,,,,,,,,,,,,,,,,,,,,,
,3755916909.66119,49.0008964538574,319.635162353516,,,5,,,,-2.43000010959804,,,,,0.000729241603715526,8.1778366931419E-8,-0.0130156810905477,8.16593978780789E-5,0.000729146492925251,8.1767701049129E-8,0.00072914647411159,5.60492223282144E-8,-1.65637647645849E-7,5.95352132041376E-8,1.00013044126413,10.005763053894,2,20,10,5,2.38551925759902,0.209654337894598,0.0404026173055172,172.741912841797,49.0000419616699,49.0010757446289,319.635162353516,319.635162353516,,,8.07074928283691,0,1,,,,,,1,1,1,49.0008888244629,0,49.0005408393012,,,,,,,,,,,,,,,,,,,,,,,,,,,,,,,,,
,3755917114.63823,48.9996566772461,319.635162353516,,,5,,,,-2.43000010959804,,,,,0.000729957626825448,1.09269790753256E-7,-0.011521379023069,0.00011816644501245,0.000729862380324924,1.09255532987052E-7,0.00072986236556872,6.70798638596576E-8,-1.46765104396776E-7,8.62384099624671E-8,1.00013049925999,10.005763053894,2,20,10,5,2.38785606159421,0.209922473164359,0.0404026173055172,172.741912841797,48.9995155334473,49.0002326965332,319.635162353516,319.635162353516,,,7.95884895324707,0,1,,,,,,1,1,1,48.9997978210449,0,48.9998837639304,,,,,,,,,,,,,,,,,,,,,,,,,,,,,,,,,
,3755917318.65336,49.0006408691406,319.635162353516,,,5,,,,-2.43000010959804,,,,,0.000730469704628444,8.06195185430135E-8,-0.0118965421296515,5.6269144817312E-5,0.000730374442206378,8.0609004745448E-8,0.000730374426462497,6.9353064885154E-8,-1.51650441507867E-7,4.1084839504217E-8,1.00013042956675,10.005763053894,2,20,10,5,2.38953255930786,0.210054088286204,0.0404026173055172,172.741912841797,48.9992485046387,49.001106262207,319.635162353516,319.635162353516,,,7.86450481414795,0,1,,,,,,1,1,1,49.0004615783691,0,48.9999829460593,,,,,,,,,,,,,,,,,,,,,,,,,,,,,,,,,
,3755917524.4817,49.0012454986572,319.635162353516,,,5,,,,-2.43000010959804,,,,,0.00073083398189581,9.68134329256345E-8,-0.0103962750124946,0.000107065136604492,0.000730738651748938,9.68008045599474E-8,0.000730738639719583,5.70113342869549E-8,-1.32591964167624E-7,7.82310905348648E-8,1.00013045723891,10.005763053894,2,20,10,5,2.39071868957434,0.210221437715334,0.0404026173055172,172.741912841797,49.0000839233398,49.0014839172363,319.635162353516,319.635162353516,,,7.78429746627808,0,1,,,,,,1,1,1,49.0010070800781,0,49.0007093092974,,,,,,,,,,,,,,,,,,,,,,,,,,,,,,,,,
,3755917729.33762,49.0005207061768,319.635162353516,,,5,,,,-2.43000010959804,,,,,0.000731514662901932,1.25089732343595E-7,-0.0152800124172181,0.000112635568687343,0.000731419268226111,1.25073419759487E-7,0.00073141924221622,9.41184881850215E-8,-1.9505966169216E-7,8.23715394544662E-8,1.00013042406724,10.005763053894,2,20,10,5,2.39296327342994,0.210213265268719,0.0404026173055172,172.741912841797,48.9993057250977,49.0006866455078,319.635162353516,319.635162353516,,,7.71700048446655,0,1,,,,,,1,1,1,49.0006866455078,0,48.9998974519617,,,,,,,,,,,,,,,,,,,,,,,,,,,,,,,,,
,3755917934.3281,48.9997787475586,319.635162353516,,,5,,,,-2.43000010959804,,,,,0.000731773696211609,8.76859890076555E-8,-0.0144473966929777,7.55331656130742E-5,0.000731678208659086,8.76745470543245E-8,0.000731678185398318,6.80701085822213E-8,-1.84496053809204E-7,5.52565518177308E-8,1.00013050484679,10.005763053894,2,20,10,5,2.39380757831425,0.210322492384717,0.0404026173055172,172.741912841797,48.999340057373,49.0002708435059,319.635162353516,319.635162353516,,,7.6598334312439,0,1,,,,,,1,1,1,49.0000114440918,0,48.9998514512006,,,,,,,,,,,,,,,,,,,,,,,,,,,,,,,,,
,3755918139.26509,49.0007972717285,319.635162353516,,,5,,,,-2.43000010959804,,,,,0.000732149952304242,8.67042630599087E-8,-0.0138099757966206,6.72140286690127E-5,0.000732054465517346,8.66929551147758E-8,0.000732054444252906,7.13842630488304E-8,-1.7644675469346E-7,4.91930427551288E-8,1.00013043672485,10.005763053894,2,20,10,5,2.39503606139364,0.210457276590452,0.0404026173055172,172.741912841797,48.9999313354492,49.0012550354004,319.635162353516,319.635162353516,,,7.61264038085938,0,1,,,,,,1,1,1,49.0005531311035,0,49.0004308363971,,,,,,,,,,,,,,,,,,,,,,,,,,,,,,,,,
,3755918344.21514,49.0000343322754,319.635162353516,,,5,,,,-2.43000010959804,,,,,0.000732576746745919,1.14727356194813E-7,-0.0149175287905186,0.000133837556358895,0.000732481229869727,1.1471239749086E-7,0.000732481205043255,5.9577554113865E-8,-1.90708806207119E-7,9.80277980162286E-8,1.00013040180731,10.005763053894,2,20,10,5,2.39643627708278,0.210533637910039,0.0404026173055172,172.741912841797,48.9990997314453,49.0002021789551,319.635162353516,319.635162353516,,,7.57233333587646,0,1,,,,,,1,1,1,48.9998664855957,0,48.9997444152832,,,,,,,,,,,,,,,,,,,,,,,,,,,,,,,,,
,3755918549.12693,48.9999713897705,319.635162353516,,,5,,,,-2.43000010959804,,,,,0.000732965027580396,1.24913009978374E-7,-0.0161365526853219,0.000136586695572777,0.000732869378113009,1.24896709251294E-7,0.000732869349047842,7.47039728642471E-8,-2.06402378596529E-7,1.0009247933836E-7,1.00013051366347,10.005763053894,2,20,10,5,2.39771091905758,0.21059421127796,0.0404026173055172,172.741912841797,48.9993286132812,49.0002365112305,319.635162353516,319.635162353516,,,7.53785800933838,0,1,,,,,,1,1,1,48.9999160766602,0,48.999734990737,,,,,,,,,,,,,,,,,,,,,,,,,,,,,,,,,
,3755918754.07141,49.0002765655518,319.635162353516,,,5,,,,-2.43000010959804,,,,,0.000733165887885526,9.36598808897725E-8,-0.0124396243889429,7.6794734799522E-5,0.000733070201969077,9.3647657282966E-8,0.000733070184691421,7.48458767762436E-8,-1.59158632085582E-7,5.62847976294063E-8,1.00013052763049,10.005763053894,2,20,10,5,2.39835438612133,0.210806672358473,0.0404026173055172,172.741912841797,48.9987106323242,49.0024948120117,319.635162353516,319.635162353516,,,7.51030254364014,0,1,,,,,,1,1,1,49.0000495910645,0,49.0014670876896,,,,,,,,,,,,,,,,,,,,,,,,,,,,,,,,,
,3755918959.00408,49.0016593933105,319.635162353516,,,5,,,,-2.43000010959804,,,,,0.000733660034962618,7.04661082178569E-8,-0.0188029403100902,6.91699996592056E-5,0.00073356432229083,7.04569152685798E-8,0.00073356428278925,4.88891017499606E-8,-2.40736159544089E-7,5.07349252413546E-8,1.00013047618168,10.005763053894,2,20,10,5,2.39999426886041,0.210682203815654,0.0404026173055172,172.741912841797,49.0005645751953,49.0019874572754,319.635162353516,319.635162353516,,,7.4851861000061,0,1,,,,,,1,1,1,49.0015106201172,0,49.001134024726,,,,,,,,,,,,,,,,,,,,,,,,,,,,,,,,,
,3755919163.95728,49.0001697540283,319.635162353516,,,5,,,,-2.43000010959804,,,,,0.000733646265848414,8.44662762514679E-8,-0.0114020106531756,7.93476375796654E-5,0.000733550604977327,8.44552626091449E-8,0.000733550590452275,6.12020979806997E-8,-1.45978496644421E-7,5.81978915867273E-8,1.00013040800517,10.005763053894,2,20,10,5,2.39992199251666,0.210988256540678,0.0404026173055172,172.741912841797,48.9992561340332,49.0002861022949,319.635162353516,319.635162353516,,,7.4650068283081,0,1,,,,,,1,1,1,49.0001983642578,0,48.9999868604872,,,,,,,,,,,,,,,,,,,,,,,,,,,,,,,,,
,3755919369.08693,49.0006809234619,319.635162353516,,,5,,,,-2.43000010959804,,,,,0.000733863494835459,1.04414867657733E-7,-0.0152453044380705,8.88052387795559E-5,0.000733767704296358,1.04401238479372E-7,0.000733767678321359,8.15779403955006E-8,-1.95241464587613E-7,6.51510417173427E-8,1.0001305461368,10.005763053894,2,20,10,5,2.40064674924243,0.210889694794124,0.0404026173055172,172.741912841797,49.0002021789551,49.0015678405762,319.635162353516,319.635162353516,,,7.44685935974121,0,1,,,,,,1,1,1,49.0011024475098,0,49.000763837029,,,,,,,,,,,,,,,,,,,,,,,,,,,,,,,,,
,3755919572.7855,49.0014610290527,319.635162353516,,,5,,,,-2.43000010959804,,,,,0.000734130421837572,9.89781662631871E-8,-0.0171772924604872,8.04174415596264E-5,0.000734034654462618,9.89652545531164E-8,0.000734034621475018,7.9442043709275E-8,-2.2006381367198E-7,5.90176524444743E-8,1.00013046710312,10.005763053894,2,20,10,5,2.40152704517586,0.21088542105083,0.0404026173055172,172.741912841797,48.9999198913574,49.0017929077148,319.635162353516,319.635162353516,,,7.43290567398071,0,1,,,,,,1,1,1,49.0015716552734,0,49.0007227729349,,,,,,,,,,,,,,,,,,,,,,,,,,,,,,,,,
,3755919779.0157,48.9995670318604,319.635162353516,,,5,,,,-2.43000010959804,,,,,0.000734884884288846,7.9637992972651E-8,-0.0127694202240267,7.6539512364089E-5,0.000734788997883078,7.96276019562184E-8,0.00073478897963447,5.63767179006624E-8,-1.63761266397351E-7,5.62336258127385E-8,1.00013049515717,10.005763053894,2,20,10,5,2.40397883486578,0.211287101271409,0.0404026173055172,172.741912841797,48.9982643127441,49.0005798339844,319.635162353516,319.635162353516,,,7.4200758934021,0,1,,,,,,1,1,1,48.9990196228027,0,48.9996497210334,,,,,,,,,,,,,,,,,,,,,,,,,,,,,,,,,
,3755919982.63753,49.0003318786621,319.635162353516,,,5,,,,-2.43000010959804,,,,,0.00073460903189161,1.26555511863486E-7,-0.0152733943205083,9.34911043351697E-5,0.000734513240035134,1.265390092248E-7,0.000734513213937839,1.06296249059646E-7,-1.95799940434784E-7,6.86529554458057E-8,1.00013041542515,10.005763053894,2,20,10,5,2.4030856863648,0.211102763123892,0.0404026173055172,172.741912841797,48.9995574951172,49.0010719299316,319.635162353516,319.635162353516,,,7.41079950332642,0,1,,,,,,1,1,1,49.000602722168,0,49.0002849803251,,,,,,,,,,,,,,,,,,,,,,,,,,,,,,,,,
,3755920188.77549,49.0005130767822,319.635162353516,,,5,,,,-2.43000010959804,,,,,0.000734832020841742,6.78967073434188E-8,-0.0108242083667909,7.31956058472106E-5,0.000734736193815547,6.78878531571985E-8,0.000734736180704165,4.14364504609987E-8,-1.38804946485799E-7,5.37752840948939E-8,1.00013042371807,10.005763053894,2,20,10,5,2.40379873265164,0.211353506639171,0.0404026173055172,172.741912841797,48.9995269775391,49.0008239746094,319.635162353516,319.635162353516,,,7.40253639221191,0,1,,,,,,1,1,1,49.000358581543,0,49.0000357376902,,,,,,,,,,,,,,,,,,,,,,,,,,,,,,,,,
,3755920393.8054,49.0007858276367,319.635162353516,,,5,,,,-2.43000010959804,,,,,0.000735052254780178,9.1321531346449E-8,-0.0154407004415589,8.29904281369158E-5,0.000734956389860719,9.13096212663282E-8,0.000734956363172457,6.79573373875611E-8,-1.98064175276575E-7,6.09856313486503E-8,1.00013043620109,10.005763053894,2,20,10,5,2.40453619357262,0.211223109384537,0.0404026173055172,172.741912841797,48.9997634887695,49.0009574890137,319.635162353516,319.635162353516,,,7.39515066146851,0,1,,,,,,1,1,1,49.000659942627,0,49.0002977583143,,,,,,,,,,,,,,,,,,,,,,,,,,,,,,,,,
,3755920598.69659,49.0009860992432,319.635162353516,,,5,,,,-2.43000010959804,,,,,0.00073518854338195,9.83660155774604E-8,-0.0149943958755259,8.00013093860869E-5,0.000735092653950967,9.83531858600408E-8,0.000735092628778559,7.88434409975045E-8,-1.92374904860139E-7,5.87967769566729E-8,1.00013044536694,10.005763053894,2,20,10,5,2.40498038130575,0.211281006675909,0.0404026173055172,172.741912841797,48.9998970031738,49.0014457702637,319.635162353516,319.635162353516,,,7.38883829116821,0,1,,,,,,1,1,1,49.0006332397461,0,49.000538720025,,,,,,,,,,,,,,,,,,,,,,,,,,,,,,,,,
,3755920803.60376,49.0009613037109,319.635162353516,,,5,,,,-2.43000010959804,,,,,0.000735312501306408,7.66152477630969E-8,-0.0113140322583867,8.6519125000187E-5,0.000735216596542028,7.66052550494254E-8,0.000735216582207781,4.26919923624633E-8,-1.45181098971157E-7,6.36062802662668E-8,1.00013044423212,10.005763053894,2,20,10,5,2.40537229913893,0.211471137112911,0.0404026173055172,172.741912841797,48.9995155334473,49.0012359619141,319.635162353516,319.635162353516,,,7.38351440429688,0,1,,,,,,1,1,1,49.0009231567383,0,49.0003590053982,,,,,,,,,,,,,,,,,,,,,,,,,,,,,,,,,
,3755921008.54355,49.0010604858398,319.635162353516,,,5,,,,-2.43000010959804,,,,,0.00073533199221606,5.57744907443969E-8,-0.0153728223082474,5.29694500819137E-5,0.000735236081572526,5.57672159795877E-8,0.000735236055108327,3.99204574042917E-8,-1.97268517804807E-7,3.89402036300031E-8,1.0001304487714,10.005763053894,2,20,10,5,2.40545103318483,0.211306341801904,0.0404026173055172,172.741912841797,49.000244140625,49.0011901855469,319.635162353516,319.635162353516,,,7.37730407714844,0,1,,,,,,1,1,1,49.0011444091797,0,49.0007490270278,,,,,,,,,,,,,,,,,,,,,,,,,,,,,,,,,
,3755921212.5533,49.0003509521484,319.635162353516,,,5,,,,-2.43000010959804,,,,,0.000735719930702428,1.68293409349835E-7,-0.0132405038087802,9.27458655122491E-5,0.000735623993344431,1.68271464008425E-7,0.000735623973702253,1.53835664688973E-7,-1.69995631123097E-7,6.81899836430588E-8,1.00013041629809,10.005763053894,2,20,10,5,2.40671220476876,0.211507393549583,0.0404026173055172,172.741912841797,48.9996528625488,49.0008544921875,319.635162353516,319.635162353516,,,7.37372303009033,0,1,,,,,,1,1,1,49.0000457763672,0,49.0000875261095,,,,,,,,,,,,,,,,,,,,,,,,,,,,,,,,,
,3755921417.57786,49.001220703125,319.635162353516,,,5,,,,-2.43000010959804,,,,,0.00073564498127481,1.4095035387616E-7,-0.0169079470654383,8.75938550603122E-5,0.000735549024414718,1.40931968440615E-7,0.000735548992387581,1.25354772046593E-7,-2.17060032938287E-7,6.44049753799594E-8,1.00013045610409,10.005763053894,2,20,10,5,2.40648056018061,0.211331805536929,0.0404026173055172,172.741912841797,48.999683380127,49.0014724731445,319.635162353516,319.635162353516,,,7.37020349502563,0,1,,,,,,1,1,1,49.0012969970703,0,49.0006121467142,,,,,,,,,,,,,,,,,,,,,,,,,,,,,,,,,
,3755921623.44262,49.0005645751953,319.635162353516,,,5,,,,-2.43000010959804,,,,,0.000735960443371929,1.31132409039959E-7,-0.0147368998562367,7.14344558480172E-5,0.000735864467457706,1.3111530818494E-7,0.000735864443116907,1.20128986595741E-7,-1.89269802021662E-7,5.25380873263592E-8,1.000130426075,10.005763053894,2,20,10,5,2.40750450302817,0.211513659550819,0.0404026173055172,172.741912841797,48.9998397827148,49.0009384155273,319.635162353516,319.635162353516,,,7.36691522598267,0,1,,,,,,1,1,1,49.0001907348633,0,49.0003121319939,,,,,,,,,,,,,,,,,,,,,,,,,,,,,,,,,
,3755921827.58,49.0011253356934,319.635162353516,,,5,,,,-2.43000010959804,,,,,0.000736037078229205,1.35462209896092E-7,-0.0161000165723477,6.2807948350774E-5,0.000735941073436082,1.35444540920137E-7,0.000735941044381113,1.27325809351336E-7,-2.06798186940775E-7,4.61883311897486E-8,1.0001304517394,10.005763053894,2,20,10,5,2.40776022656256,0.211478396531549,0.0404026173055172,172.741912841797,49.000186920166,49.0016288757324,319.635162353516,319.635162353516,,,7.36480760574341,0,1,,,,,,1,1,1,49.0013656616211,0,49.0007422952091,,,,,,,,,,,,,,,,,,,,,,,,,,,,,,,,,
,3755922033.35115,49.0019836425781,319.635162353516,,,5,,,,-2.43000010959804,,,,,0.000735944351746563,8.63027165941975E-8,-0.0124816202993161,0.00010099311275881,0.000735848330146194,8.62914563339021E-8,0.000735848312685762,4.38634069923646E-8,-1.60301150628881E-7,7.43116206474325E-8,1.00013049102164,10.005763053894,2,20,10,5,2.40744353685659,0.211603788914899,0.0404026173055172,172.741912841797,49.0017242431641,49.0025100708008,319.635162353516,319.635162353516,,,7.36281728744507,0,1,,,,,,1,1,1,49.0020484924316,0,49.0020188724293,,,,,,,,,,,,,,,,,,,,,,,,,,,,,,,,,
,3755922238.28652,49.0010070800781,319.635162353516,,,5,,,,-2.43000010959804,,,,,0.000736150621292431,1.10127535129337E-7,-0.012332843257628,0.000125176699274048,0.00073605460567252,1.10113171270571E-7,0.000736054588621074,6.03054939224054E-8,-1.58434811217536E-7,9.21311993302854E-8,1.00013044632718,10.005763053894,2,20,10,5,2.40811774198765,0.211669355065897,0.0404026173055172,172.741912841797,49.0003776550293,49.0017204284668,319.635162353516,319.635162353516,,,7.36155986785889,0,1,,,,,,1,1,1,49.0008735656738,0,49.000872892492,,,,,,,,,,,,,,,,,,,,,,,,,,,,,,,,,
,3755922443.167,49.0005512237549,319.635162353516,,,5,,,,-2.43000010959804,,,,,0.000736326350143779,1.24502114879346E-7,-0.0113081622027682,8.24543678062125E-5,0.000736230242500079,1.244858644696E-7,0.000736230228160961,1.08692914584461E-7,-1.45305832601922E-7,6.06842712066208E-8,1.00013054020081,10.005763053894,2,20,10,5,2.4086888045651,0.21176296112012,0.0404026173055172,172.741912841797,49.0003204345703,49.0025749206543,319.635162353516,319.635162353516,,,7.36000967025757,0,1,,,,,,1,1,1,49.0007286071777,0,49.0017399787903,,,,,,,,,,,,,,,,,,,,,,,,,,,,,,,,,
,3755922648.11899,49.0000305175781,319.635162353516,,,5,,,,-2.43000010959804,,,,,0.000736360516174871,9.27683735633343E-8,-0.0125092464151155,9.42505018507188E-5,0.000736264506081165,9.27562779932391E-8,0.000736264488533437,6.1556827991514E-8,-1.6074681483302E-7,6.93864830841153E-8,1.00013040163272,10.005763053894,2,20,10,5,2.40880500776567,0.211722296031511,0.0404026173055172,172.741912841797,48.998779296875,49.000301361084,319.635162353516,319.635162353516,,,7.35939073562622,0,1,,,,,,1,1,1,48.9997100830078,0,48.9999037349925,,,,,,,,,,,,,,,,,,,,,,,,,,,,,,,,,
,3755922853.23002,49.0019187927246,319.635162353516,,,5,,,,-2.43000010959804,,,,,0.000736477487665502,1.01285606356568E-7,-0.0135476760664135,7.35470932634082E-5,0.000736381398690047,1.01272391519311E-7,0.000736381378104749,8.55833466935885E-8,-1.7411852395771E-7,5.41441414445329E-8,1.00013048805364,10.005763053894,2,20,10,5,2.40919148669385,0.211712255817379,0.0404026173055172,172.741912841797,48.999870300293,49.0024337768555,319.635162353516,319.635162353516,,,7.35923337936401,0,1,,,,,,1,1,1,49.0016288757324,0,49.0009119370404,,,,,,,,,,,,,,,,,,,,,,,,,,,,,,,,,
,3755923058.16801,49.001256942749,319.635162353516,,,5,,,,-2.43000010959804,,,,,0.000736619698187776,8.0754024814945E-8,-0.0151568377972531,8.51952631428174E-5,0.000736523612965073,8.07434911997327E-8,0.000736523587194231,5.08216294115124E-8,-1.94837541267904E-7,6.27429147799193E-8,1.00013045776267,10.005763053894,2,20,10,5,2.40966263677293,0.211685463462001,0.0404026173055172,172.741912841797,48.9997673034668,49.001895904541,319.635162353516,319.635162353516,,,7.35905265808105,0,1,,,,,,1,1,1,49.0010147094727,0,49.0003991968492,,,,,,,,,,,,,,,,,,,,,,,,,,,,,,,,,
,3755923263.10868,49.0001087188721,319.635162353516,,,5,,,,-2.43000010959804,,,,,0.000736711275868027,1.13673192584112E-7,-0.0131419885192203,9.78897422688587E-5,0.000736615132898718,1.13658357901077E-7,0.000736615113521673,8.78666314592033E-8,-1.68958126008989E-7,7.20949193548472E-8,1.00013051994863,10.005763053894,2,20,10,5,2.40995476282351,0.211796532714205,0.0404026173055172,172.741912841797,48.9988250732422,49.0023498535156,319.635162353516,319.635162353516,,,7.35750675201416,0,1,,,,,,1,1,1,49.0000457763672,0,49.0013618469238,,,,,,,,,,,,,,,,,,,,,,,,,,,,,,,,,
,3755923468.11211,49.0004501342773,319.635162353516,,,5,,,,-2.43000010959804,,,,,0.000736883561353518,8.70374888716129E-8,-0.0156624945437756,6.82206042842571E-5,0.000736787384389206,8.70261288659078E-8,0.00073678735686031,7.10503944222117E-8,-2.01409743305089E-7,5.02532442518265E-8,1.00013053557424,10.005763053894,2,20,10,5,2.41052766607344,0.211740019669231,0.0404026173055172,172.741912841797,48.9996299743652,49.0008811950684,319.635162353516,319.635162353516,,,7.3560528755188,0,1,,,,,,1,1,1,49.0004234313965,0,49.0001745784984,,,,,,,,,,,,,,,,,,,,,,,,,,,,,,,,,
,3755923673.08889,49.0030574798584,319.635162353516,,,5,,,,-2.43000010959804,,,,,0.00073685785906459,7.38073984943644E-8,-0.0151849348698336,7.03991439385967E-5,0.000736761682070777,7.37977649217276E-8,0.00073676165619594,5.25027617938593E-8,-1.95261817204356E-7,5.18610654678424E-8,1.00013054016808,10.005763053894,2,20,10,5,2.41044182373286,0.211752713529305,0.0404026173055172,172.741912841797,49.0022354125977,49.0031585693359,319.635162353516,319.635162353516,,,7.35476684570312,0,1,,,,,,1,1,1,49.0031356811523,0,49.0027001324822,,,,,,,,,,,,,,,,,,,,,,,,,,,,,,,,,
,3755923878.0885,49.0001277923584,319.635162353516,,,5,,,,-2.43000010959804,,,,,0.000737115479315304,1.16911102582596E-7,-0.0107448988321428,8.64077735760365E-5,0.000737019367505236,1.16895858651351E-7,0.000737019354545138,9.80361991596419E-8,-1.38216087852459E-7,6.36674596962025E-8,1.00013040608471,10.005763053894,2,20,10,5,2.41126813885302,0.212013617376387,0.0404026173055172,172.741912841797,48.9989433288574,49.0001564025879,319.635162353516,319.635162353516,,,7.3534369468689,0,1,,,,,,1,1,1,49.0000762939453,0,48.9995516608743,,,,,,,,,,,,,,,,,,,,,,,,,,,,,,,,,
,3755924082.92144,49.0020809173584,319.635162353516,,,5,,,,-2.43000010959804,,,,,0.000737318420897897,7.81737405793822E-8,-0.00810224290729344,7.45892815891506E-5,0.000737222216735559,7.81635405911328E-8,0.000737222209364436,5.55563094745506E-8,-1.04251194546946E-7,5.49821385116078E-8,1.00013049547362,10.005763053894,2,20,10,5,2.4119222224282,0.212183226947574,0.0404026173055172,172.741912841797,48.9998054504395,49.002742767334,319.635162353516,319.635162353516,,,7.3518533706665,0,1,,,,,,1,1,1,49.0017280578613,0,49.0009157517377,,,,,,,,,,,,,,,,,,,,,,,,,,,,,,,,,
,3755924287.90366,49.0001678466797,319.635162353516,,,5,,,,-2.43000010959804,,,,,0.000737222972552743,9.47415469918378E-8,-0.0134088340617717,7.68961671509627E-5,0.000737126845375626,9.47291935549442E-8,0.000737126825189685,7.59079962222811E-8,-1.72508543314939E-7,5.66709468871683E-8,1.00013040791788,10.005763053894,2,20,10,5,2.4116296293668,0.211932407875802,0.0404026173055172,172.741912841797,48.9994583129883,49.0004348754883,319.635162353516,319.635162353516,,,7.34925508499145,0,1,,,,,,1,1,1,49.0001258850098,0,48.9999631245931,,,,,,,,,,,,,,,,,,,,,,,,,,,,,,,,,
,3755924492.8714,49.0010375976562,319.635162353516,,,5,,,,-2.43000010959804,,,,,0.000737423999862609,6.65282145566049E-8,-0.0155632970171276,5.22607738383561E-5,0.000737327817127113,6.65195372343792E-8,0.000737327789925881,5.42279220174294E-8,-2.0028092423816E-7,3.85250737513578E-8,1.00013044772388,10.005763053894,2,20,10,5,2.41229520692354,0.211899486265818,0.0404026173055172,172.741912841797,48.9996604919434,49.0012092590332,319.635162353516,319.635162353516,,,7.34702634811401,0,1,,,,,,1,1,1,49.0009613037109,0,49.000446955363,,,,,,,,,,,,,,,,,,,,,,,,,,,,,,,,,
,3755924697.76631,49.0015258789063,319.635162353516,,,5,,,,-2.43000010959804,,,,,0.000737245130519033,9.15356117685698E-8,-0.0145472158048534,7.15646442272732E-5,0.000737148954642503,9.15236706687496E-8,0.000737148930882869,7.4798635631381E-8,-1.8715976812648E-7,5.27422638911683E-8,1.00013047007111,10.005763053894,2,20,10,5,2.4117063241909,0.211890855434344,0.0404026173055172,172.741912841797,49.0001258850098,49.002025604248,319.635162353516,319.635162353516,,,7.34412050247192,0,1,,,,,,1,1,1,49.0013542175293,0,49.000848558214,,,,,,,,,,,,,,,,,,,,,,,,,,,,,,,,,
,3755924902.73149,49.0001564025879,319.635162353516,,,5,,,,-2.43000010959804,,,,,0.000737450173867051,9.08828306558334E-8,-0.00755068337267417,9.61736413535948E-5,0.000737353932860447,9.0870969983187E-8,0.000737353926457598,5.68291453757517E-8,-9.71716610163016E-8,7.09082606016178E-8,1.00013052213098,10.005763053894,2,20,10,5,2.41235117018133,0.212244371707469,0.0404026173055172,172.741912841797,48.999641418457,49.0005264282227,319.635162353516,319.635162353516,,,7.34096050262451,0,1,,,,,,1,1,1,49.0001754760742,0,49.0000283090692,,,,,,,,,,,,,,,,,,,,,,,,,,,,,,,,,
,3755925108.64338,49.0002384185791,319.635162353516,,,5,,,,-2.43000010959804,,,,,0.00073748619437142,7.86930844866097E-8,-0.0112281129322094,7.01904205595652E-5,0.000737390030491204,7.86828233693059E-8,0.000737390016332108,5.92700668990207E-8,-1.44504508967485E-7,5.17498392572479E-8,1.00013041114775,10.005763053894,2,20,10,5,2.41248261881807,0.212099898956805,0.0404026173055172,172.741912841797,48.9996185302734,49.000602722168,319.635162353516,319.635162353516,,,7.33750104904175,0,1,,,,,,1,1,1,48.9999923706055,0,48.9999474918141,,,,,,,,,,,,,,,,,,,,,,,,,,,,,,,,,
,3755925311.53017,48.9985866546631,319.635162353516,,,5,,,,-2.43000010959804,,,,,0.000737627449143562,1.1294129990652E-7,-0.0106871010243701,9.65366432519126E-5,0.000737531237981069,1.12926568603109E-7,0.000737531225151118,8.76635899326225E-8,-1.37568087391633E-7,7.1186409493651E-8,1.00013045028812,10.005763053894,2,20,10,5,2.41294269128998,0.212163311169174,0.0404026173055172,172.741912841797,48.997875213623,49.0005187988281,319.635162353516,319.635162353516,,,7.33457612991333,0,1,,,,,,1,1,1,48.9991874694824,0,48.9994953379912,,,,,,,,,,,,,,,,,,,,,,,,,,,,,,,,,
,3755925515.23207,48.9995994567871,319.635162353516,,,5,,,,-2.43000010959804,,,,,0.000737556936220064,8.94711590648995E-8,-0.0148599126813478,0.000100742512219142,0.000737460700075709,8.9459484902599E-8,0.000737460675273171,4.98415701674985E-8,-1.91263677348066E-7,7.4288742904135E-8,1.00013049664117,10.005763053894,2,20,10,5,2.412727471843,0.211967311697278,0.0404026173055172,172.741912841797,48.9989128112793,49.0002899169922,319.635162353516,319.635162353516,,,7.33152723312378,0,1,,,,,,1,1,1,48.9994621276855,0,48.9996566772461,,,,,,,,,,,,,,,,,,,,,,,,,,,,,,,,,
,3755925720.12954,49.0008525848389,319.635162353516,,,5,,,,-2.43000010959804,,,,,0.000737719113210949,9.48577477331009E-8,-0.00572120386089914,9.86997453337169E-5,0.000737622813607125,9.48453652919213E-8,0.000737622809929783,6.07968406320378E-8,-7.36544736444306E-8,7.27968920114078E-8,1.00013055399324,10.005763053894,2,20,10,5,2.4132241458684,0.212398824061614,0.0404026173055172,172.741912841797,49.0001258850098,49.0031356811523,319.635162353516,319.635162353516,,,7.32930278778076,0,1,,,,,,1,1,1,49.001579284668,0,49.0021882898667,,,,,,,,,,,,,,,,,,,,,,,,,,,,,,,,,
,3755925925.11777,49.0000858306885,319.635162353516,,,5,,,,-2.43000010959804,,,,,0.000737876720679555,8.15439499071134E-8,-0.0174287798907224,6.97386638689213E-5,0.000737780426389045,8.15333082693144E-8,0.00073778039225515,6.32556329980818E-8,-2.24425124680919E-7,5.14432235707585E-8,1.00013051890111,10.005763053894,2,20,10,5,2.41378306976493,0.21195099078348,0.0404026173055172,172.741912841797,48.9993057250977,49.0004806518555,319.635162353516,319.635162353516,,,7.32685422897339,0,1,,,,,,1,1,1,48.9999046325684,0,48.9998916177189,,,,,,,,,,,,,,,,,,,,,,,,,,,,,,,,,
,3755926130.05988,49.0017585754395,319.635162353516,,,5,,,,-2.43000010959804,,,,,0.000737751647154375,1.03121968280041E-7,-0.012023961421546,7.70295867871808E-5,0.00073765539734631,1.03108514606718E-7,0.000737655381103042,8.60484416935288E-8,-1.54802675700734E-7,5.68069667076073E-8,1.00013048072096,10.005763053894,2,20,10,5,2.41335392203622,0.212142712609214,0.0404026173055172,172.741912841797,49.0002250671387,49.0020370483398,319.635162353516,319.635162353516,,,7.32540416717529,0,1,,,,,,1,1,1,49.0019035339355,0,49.0011224185719,,,,,,,,,,,,,,,,,,,,,,,,,,,,,,,,,
,3755926334.79625,49.0015697479248,319.635162353516,,,5,,,,-2.43000010959804,,,,,0.000737759848410452,7.44159848270996E-8,-0.0150047565839673,7.18662290905231E-5,0.000737663603906546,7.44062768854736E-8,0.000737663578611178,5.22164817763141E-8,-1.93181117091278E-7,5.30069153116988E-8,1.00013047207887,10.005763053894,2,20,10,5,2.4133917836038,0.21201951665241,0.0404026173055172,172.741912841797,49.0001373291016,49.0018501281738,319.635162353516,319.635162353516,,,7.32387828826904,0,1,,,,,,1,1,1,49.0015754699707,0,49.0007885203642,,,,,,,,,,,,,,,,,,,,,,,,,,,,,,,,,
,3755926538.37626,49.0003623962402,319.635162353516,,,5,,,,-2.43000010959804,,,,,0.000737809513096161,1.04471440917114E-7,-0.0146683938995951,6.13323284854189E-5,0.000737713302871763,1.04457817860491E-7,0.000737713278696151,9.41599115485548E-8,-1.88863286009011E-7,4.52255101612343E-8,1.00013041682185,10.005763053894,2,20,10,5,2.41355300371864,0.212047962190788,0.0404026173055172,172.741912841797,48.9996757507324,49.0008239746094,319.635162353516,319.635162353516,,,7.32190465927124,0,1,,,,,,1,1,1,49.0007286071777,0,49.000238979564,,,,,,,,,,,,,,,,,,,,,,,,,,,,,,,,,
,3755926742.11053,49.0007553100586,319.635162353516,,,5,,,,-2.43000010959804,,,,,0.000737899044693913,1.16664590141395E-7,-0.0138395180626567,7.93057366981573E-5,0.000737802809528776,1.16649375002985E-7,0.000737802788005569,1.00923656837266E-7,-1.7821269379066E-7,5.84935225403708E-8,1.00013043480439,10.005763053894,2,20,10,5,2.41384281494032,0.212108613955221,0.0404026173055172,172.741912841797,48.9991760253906,49.0010261535645,319.635162353516,319.635162353516,,,7.32015132904053,0,1,,,,,,1,1,1,49.0007171630859,0,49.0001549190945,,,,,,,,,,,,,,,,,,,,,,,,,,,,,,,,,
,3755926946.97414,48.9999942779541,319.635162353516,,,5,,,,-2.43000010959804,,,,,0.000738010218540462,9.28219606946943E-8,-0.0117897933385169,6.8077147922297E-5,0.000737913909919765,9.28098476442509E-8,0.000737913894297543,7.80476923495279E-8,-1.51841069483841E-7,5.02217635957014E-8,1.000130514711,10.005763053894,2,20,10,5,2.41419889993851,0.212226940574494,0.0404026173055172,172.741912841797,48.9991493225098,49.0004463195801,319.635162353516,319.635162353516,,,7.31795787811279,0,1,,,,,,1,1,1,49.0000228881836,0,48.9998171064589,,,,,,,,,,,,,,,,,,,,,,,,,,,,,,,,,
,3755927150.6814,49.0027523040771,319.635162353516,,,5,,,,-2.43000010959804,,,,,0.000738089305650222,1.09711647533757E-7,-0.0105252288572801,7.99094660760664E-5,0.000737993062894335,1.09697341742803E-7,0.000737993050442306,9.25074789488107E-8,-1.35569249678986E-7,5.89565358885063E-8,1.00013041146418,10.005763053894,2,20,10,5,2.41445292783105,0.212302959878638,0.0404026173055172,172.741912841797,49.0021057128906,49.0029449462891,319.635162353516,319.635162353516,,,7.31515884399414,0,1,,,,,,1,1,1,49.0029067993164,0,49.0025811195374,,,,,,,,,,,,,,,,,,,,,,,,,,,,,,,,,
,3755927354.39048,49.001148223877,319.635162353516,,,5,,,,-2.43000010959804,,,,,0.00073815201936181,8.17050718800782E-8,-0.0146324644497673,7.65909370825293E-5,0.000738055737933892,8.16944146160155E-8,0.000738055713865402,5.89859277023023E-8,-1.88488128124774E-7,5.65211262498565E-8,1.00013045278692,10.005763053894,2,20,10,5,2.4146732915946,0.212147910677396,0.0404026173055172,172.741912841797,48.9999198913574,49.001579284668,319.635162353516,319.635162353516,,,7.31450510025024,0,1,,,,,,1,1,1,49.0013580322266,0,49.0006574742934,,,,,,,,,,,,,,,,,,,,,,,,,,,,,,,,,
,3755927559.32784,49.0009727478027,319.635162353516,,,5,,,,-2.43000010959804,,,,,0.000738110688150681,8.48166939799362E-8,-0.00902583528949208,9.42209839387273E-5,0.000738014418040079,8.48056315300334E-8,0.000738014408882843,4.85521281599641E-8,-1.1625981193656E-7,6.9531906275797E-8,1.00013044475589,10.005763053894,2,20,10,5,2.41451731708228,0.212372305709682,0.0404026173055172,172.741912841797,48.9997520446777,49.0011100769043,319.635162353516,319.635162353516,,,7.31313896179199,0,1,,,,,,1,1,1,49.0008354187012,0,49.0004911983714,,,,,,,,,,,,,,,,,,,,,,,,,,,,,,,,,
,3755927764.28426,49.0002613067627,319.635162353516,,,5,,,,-2.43000010959804,,,,,0.000738236490045204,1.02543007746127E-7,-0.0148978768945804,0.000116537734200228,0.000738140227557707,1.02529636631133E-7,0.000738140202605304,5.57997822752435E-8,-1.91929007871668E-7,8.60157583571032E-8,1.00013041219528,10.005763053894,2,20,10,5,2.41495059808924,0.212161004508809,0.0404026173055172,172.741912841797,48.9999580383301,49.0010528564453,319.635162353516,319.635162353516,,,7.31097412109375,0,1,,,,,,1,1,1,49.0005645751953,0,49.0003659990099,,,,,,,,,,,,,,,,,,,,,,,,,,,,,,,,,
,3755927918.1594,49.0003147125244,319.635162353516,,,5,,,,-2.43000010959804,,,,,0.000738121512813131,7.26015944910793E-8,-0.0130799416406209,6.59341472710366E-5,0.00073802517884679,7.25921190870453E-8,0.000738025159615539,5.38738483082347E-8,-1.6848232569334E-7,4.86541285196754E-8,1.00013052937637,10.005763053894,2,20,10,5,2.41456774785997,0.212204573193245,0.0404026173055172,172.741912841797,48.999927520752,49.0016174316406,319.635162353516,319.635162353516,,,7.30990219116211,0,1,,,,,,1,1,1,49.0005531311035,0,49.0009323568905,,,,,,,,,,,,,,,,,,,,,,,,,,,,,,,,,