File: Experimental_Data/Fig3B/Lifetime_140Oe.dat
[Header]
; MPMS3 Data File (default extension .dat)
; Copyright (c) 2007, Quantum Design, Inc. All rights reserved.
TITLE,140Oe
FILEOPENTIME,3754652333.62846,12/22/2018,2:58 pm
BYAPP,SQUID AC,0.9.1.0
INFO,MPMS3 Measurement Release 1.1.16 Build 347, MultiVu Release 2.3.3.2,APPNAME
INFO,0,MOMENT_UNITS
INFO,CoIINO3,SAMPLE_MATERIAL
INFO,40 Hours Pumped Turbo,SAMPLE_COMMENT
INFO,,SAMPLE_MASS
INFO,,SAMPLE_VOLUME
INFO,,SAMPLE_MOLECULAR_WEIGHT
INFO,,SAMPLE_SIZE
INFO,,SAMPLE_SHAPE
INFO,Brass,SAMPLE_HOLDER
INFO,Standard,SAMPLE_HOLDER_DETAIL
INFO,65.37,SAMPLE_OFFSET
DATATYPE,COMMENT,1
DATATYPE,TIME,2
STARTUPAXIS,X,2
STARTUPAXIS,Y1,5
FIELDGROUP, VSM,2,3,4,5,6,8,9,10,11,14,15
FIELDGROUP, DC, 2,3,4,14,56,57,58,59,60,61,62,63,64,65,66,67,68,69
FIELDGROUP, AC, 2,3,4,11,16,17,18,19,20,21,22,23,24,25,26,27,28,29,30
STARTUPGROUP, All
[Data]
Comment,Time Stamp (sec),Temperature (K),Magnetic Field (Oe),Moment (emu),M. Std. Err. (emu),Transport Action,Averaging Time (sec),Frequency (Hz),Peak Amplitude (mm),Center Position (mm),Lockin Signal' (V),Lockin Signal (V),Range,M. Quad. Signal (emu),AC Moment (emu),AC M. Std Err. (emu),AC Phase (deg),AC Phase Std. Err. (deg),AC Susceptibility (emu/Oe),AC Suscept. Std Err. (emu/Oe),AC X' (emu/Oe),AC X' Std Err. (emu/Oe),AC X'' (emu/Oe),AC X'' Std Err. (emu/Oe),AC Drive (Oe),AC Frequency (Hz),AC Averaging Time (sec),AC Cycles,AC Range,AC Measure Type,AC Signal' (V),AC Signal'' (V),AC Trim Coil Ratio,AC Trim Coil Phase,Min. Temperature (K),Max. Temperature (K),Min. Field (Oe),Max. Field (Oe),Mass (grams),Motor Lag (deg),Pressure (Torr),Measure Count,Measurement Number,SQUID Status (code),Motor Status (code),Measure Status (code),Motor Current (amps),Motor Temp. (C),Temp. Status (code),Field Status (code),Chamber Status (code),Chamber Temp (K),Redirection State,Average Temp (K),Rotation Angle (deg),Rotator state,DC Moment Fixed Ctr (emu),DC Moment Err Fixed Ctr (emu),DC Moment Free Ctr (emu),DC Moment Err Free Ctr (emu),DC Fixed Fit,DC Free Fit,DC Calculated Center (mm),DC Calculated Center Err (mm),DC Scan Length (mm),DC Scan Time (s),DC Number of Points,DC Squid Drift,DC Min V (V),DC Max V (V),DC Scans per Measure,Map 01,Map 02,Map 03,Map 04,Map 05,Map 06,Map 07,Map 08,Map 09,Map 10,Map 11,Map 12,Map 13,Map 14,Map 15,Map 16
,3754652338.09755,48.9577026367188,140.225158691406,,,5,,,,-2.43999995291233,,,,,0.00070410162063695,5.95793857066055E-8,0.0338160644238279,3.43617908293656E-5,0.000704010291838522,5.9571657683337E-8,0.000704010169221755,5.44477779092073E-8,4.15508021778021E-7,2.41706822388266E-8,1.00012972651038,10.005763053894,2,20,10,5,2.30314194527352,0.203867207251031,0.0404026173055172,172.741912841797,48.9088973999023,48.9743957519531,140.225158691406,140.225158691406,,,31.3715476989746,0,1,,,,,,1,1,1,48.9511337280273,0,48.9341436687269,,,,,,,,,,,,,,,,,,,,,,,,,,,,,,,,,
,3754652542.98428,48.9990310668945,140.225158691406,,,5,,,,-2.43999995291233,,,,,0.00070231604849527,5.78530562905192E-8,0.0237452936583908,5.2863874874606E-5,0.000702224428833328,5.78455091506368E-8,0.00070222436852799,4.4368496933628E-8,2.91025358955335E-7,3.71152180210092E-8,1.00013047062759,10.005763053894,2,20,10,5,2.29733699892745,0.20294621450536,0.0404026173055172,172.741912841797,48.9986152648926,48.999683380127,140.225158691406,140.225158691406,,,31.607852935791,0,1,,,,,,1,1,1,48.9992561340332,0,48.999179166906,,,,,,,,,,,,,,,,,,,,,,,,,,,,,,,,,
,3754652748.24727,48.999002456665,140.225158691406,,,5,,,,-2.43999995291233,,,,,0.000703438492324923,5.921344609433E-8,0.0255960222917251,3.08244047758729E-5,0.000703346727156982,5.92057215642048E-8,0.000703346656972813,5.5102057760733E-8,3.14209494334562E-7,2.16582708559798E-8,1.00013046931819,10.005763053894,2,20,10,5,2.30100204326504,0.203344890856608,0.0404026173055172,172.741912841797,48.9988098144531,48.9993934631348,140.225158691406,140.225158691406,,,31.5705413818359,0,1,,,,,,1,1,1,48.9988784790039,0,48.9990732529584,,,,,,,,,,,,,,,,,,,,,,,,,,,,,,,,,
,3754652956.20417,49.0006866455078,140.225158691406,,,5,,,,-2.43999995291233,,,,,0.000703636687986035,7.7499196542682E-8,0.0260047511564965,9.78339940915282E-5,0.000703544923452512,7.7489089511965E-8,0.000703544850988568,3.55939607828036E-8,3.19316888419084E-7,6.88304362123731E-8,1.00013043166181,10.005763053894,2,20,10,5,2.30164890616969,0.203418597063909,0.0404026173055172,172.741912841797,48.9995460510254,49.0015335083008,140.225158691406,140.225158691406,,,31.607852935791,0,1,,,,,,1,1,1,49.0003204345703,0,49.0002715166877,,,,,,,,,,,,,,,,,,,,,,,,,,,,,,,,,
,3754653161.31262,48.9999847412109,140.225158691406,,,5,,,,-2.43999995291233,,,,,0.000703938098037694,5.67939797454018E-8,0.0279605465234489,4.86509980647902E-5,0.000703846316803396,5.67865748023019E-8,0.000703846232993773,4.5307016341631E-8,3.43479521047882E-7,3.42343299627233E-8,1.00013039953767,10.005763053894,2,20,10,5,2.30262789315412,0.203584335137321,0.0404026173055172,172.741912841797,48.9994354248047,49.0004348754883,140.225158691406,140.225158691406,,,31.7819747924805,0,1,,,,,,1,1,1,49.0000457763672,0,48.9999486137839,,,,,,,,,,,,,,,,,,,,,,,,,,,,,,,,,
,3754653366.49621,49.0009307861328,140.225158691406,,,5,,,,-2.43999995291233,,,,,0.000704250747126738,3.47802378374207E-8,0.0271394241582597,3.04904134975686E-5,0.000704158894643933,3.47757015963007E-8,0.000704158815649468,2.73604231465749E-8,3.33540556814801E-7,2.14652432260928E-8,1.00013044283542,10.005763053894,2,20,10,5,2.30365350793208,0.203641737757643,0.0404026173055172,172.741912841797,49.000415802002,49.0013198852539,140.225158691406,140.225158691406,,,31.9685287475586,0,1,,,,,,1,1,1,49.000919342041,0,49.0008217306698,,,,,,,,,,,,,,,,,,,,,,,,,,,,,,,,,
,3754653571.69349,49.0001697540283,140.225158691406,,,5,,,,-2.43999995291233,,,,,0.000704275761384238,4.57025646605193E-8,0.0280114270592033,3.15954613380095E-5,0.000704183930162633,4.56966054573585E-8,0.000704183846007364,3.99205422838329E-8,3.44269615980007E-7,2.22380317044967E-8,1.00013040800517,10.005763053894,2,20,10,5,2.30373223147332,0.203684034168023,0.0404026173055172,172.741912841797,48.9994239807129,49.0007057189941,140.225158691406,140.225158691406,,,32.1302108764648,0,1,,,,,,1,1,1,49.0004348754883,0,49.0000754462348,,,,,,,,,,,,,,,,,,,,,,,,,,,,,,,,,
,3754653776.5978,49.0009460449219,140.225158691406,,,5,,,,-2.43999995291233,,,,,0.000704600134503092,3.47220631071997E-8,0.0257481519332483,3.54554224365218E-5,0.000704508235959222,3.47175344293248E-8,0.000704508164821012,2.41145987351577E-8,3.16598964902847E-7,2.4975854834093E-8,1.00013044353377,10.005763053894,2,20,10,5,2.30480132522626,0.203686800453467,0.0404026173055172,172.741912841797,48.9998245239258,49.0010833740234,140.225158691406,140.225158691406,,,32.2794570922852,0,1,,,,,,1,1,1,49.0010833740234,0,49.0005320380716,,,,,,,,,,,,,,,,,,,,,,,,,,,,,,,,,
,3754653981.55964,49.0005798339844,140.225158691406,,,5,,,,-2.43999995291233,,,,,0.000704649051558225,4.26937530442857E-8,0.0272170038061486,4.14029924213991E-5,0.000704557158441408,4.26881853620088E-8,0.000704557078949744,3.11704312564885E-8,3.3468318791955E-7,2.91665113578183E-8,1.00013042677335,10.005763053894,2,20,10,5,2.30495611360125,0.2037600341308,0.0404026173055172,172.741912841797,48.9992523193359,49.0015144348145,140.225158691406,140.225158691406,,,32.4162673950195,0,1,,,,,,1,1,1,49.0005874633789,0,49.000047181782,,,,,,,,,,,,,,,,,,,,,,,,,,,,,,,,,
,3754654186.44669,49.000846862793,140.225158691406,,,5,,,,-2.43999995291233,,,,,0.000704765705540716,3.73970283878201E-8,0.0250631619868695,4.06168421592164E-5,0.000704673788600286,3.73921509932427E-8,0.000704673721180935,2.40644605376507E-8,3.08248755814729E-7,2.86194810388538E-8,1.00013043899449,10.005763053894,2,20,10,5,2.30534535627749,0.203707104137241,0.0404026173055172,172.741912841797,49.0000419616699,49.0011711120605,140.225158691406,140.225158691406,,,32.5779495239258,0,1,,,,,,1,1,1,49.0007629394531,0,49.0005221647375,,,,,,,,,,,,,,,,,,,,,,,,,,,,,,,,,
,3754654391.36258,48.9998073577881,140.225158691406,,,5,,,,-2.43999995291233,,,,,0.000704805745621877,5.67622459807425E-8,0.0268920459252664,6.1001145920876E-5,0.000704713776135731,5.67548391248425E-8,0.000704713698513668,3.70595463809478E-8,3.3076074184273E-7,4.29849018391938E-8,1.0001305061562,10.005763053894,2,20,10,5,2.30546982636913,0.203792272132916,0.0404026173055172,172.741912841797,48.9995040893555,49.0004539489746,140.225158691406,140.225158691406,,,32.7645034790039,0,1,,,,,,1,1,1,48.9998168945313,0,48.9998839883243,,,,,,,,,,,,,,,,,,,,,,,,,,,,,,,,,
,3754654596.24885,48.9997653961182,140.225158691406,,,5,,,,-2.43999995291233,,,,,0.000704932573134996,5.96877660853932E-8,0.0286588003241475,6.31111092765856E-5,0.000704840588452684,5.96799775955283E-8,0.00070484050028049,3.97905911860201E-8,3.52554499025617E-7,4.44793050628018E-8,1.00013050423574,10.005763053894,2,20,10,5,2.30587840191021,0.203900047242461,0.0404026173055172,172.741912841797,48.9990463256836,48.999927520752,140.225158691406,140.225158691406,,,32.9137496948242,0,1,,,,,,1,1,1,48.9998359680176,0,48.9996008031508,,,,,,,,,,,,,,,,,,,,,,,,,,,,,,,,,
,3754654801.17996,49.000171661377,140.225158691406,,,5,,,,-2.43999995291233,,,,,0.000705036739413449,4.05334681509448E-8,0.0307667161902039,4.10270414882711E-5,0.000704944808905627,4.05281829479155E-8,0.000704944707270897,2.83946908297521E-8,3.78541596036449E-7,2.89184222554153E-8,1.00013040809246,10.005763053894,2,20,10,5,2.30621163228223,0.20401502129313,0.0404026173055172,172.741912841797,48.9995727539063,49.0008163452148,140.225158691406,140.225158691406,,,33.0629959106445,0,1,,,,,,1,1,1,49.0002288818359,0,49.0001572502984,,,,,,,,,,,,,,,,,,,,,,,,,,,,,,,,,
,3754655006.60576,48.9998950958252,140.225158691406,,,5,,,,-2.43999995291233,,,,,0.000705072320055352,6.50967347965962E-8,0.0315736695643896,5.01547875733575E-5,0.000704980312953649,6.50882401192013E-8,0.000704980205912235,5.46551900151376E-8,3.88489597544487E-7,3.53452854879403E-8,1.00013051017172,10.005763053894,2,20,10,5,2.30632514453508,0.204057801102757,0.0404026173055172,172.741912841797,48.9996948242188,49.0002937316895,140.225158691406,140.225158691406,,,33.2122421264648,0,1,,,,,,1,1,1,48.9998359680176,0,48.9999347262912,,,,,,,,,,,,,,,,,,,,,,,,,,,,,,,,,
,3754655212.44823,49.0000762939453,140.225158691406,,,5,,,,-2.43999995291233,,,,,0.000705087291865083,4.9473661575609E-8,0.0303832610910595,3.66853685988978E-5,0.000704995357842359,4.94672108669096E-8,0.000704995258718145,4.21740857395215E-8,3.73850520988424E-7,2.58524939413354E-8,1.00013040372777,10.005763053894,2,20,10,5,2.30637835719824,0.204014216155496,0.0404026173055172,172.741912841797,48.9990348815918,49.0004463195801,140.225158691406,140.225158691406,,,33.336612701416,0,1,,,,,,1,1,1,48.9997062683105,0,48.999787050135,,,,,,,,,,,,,,,,,,,,,,,,,,,,,,,,,
,3754655417.95855,49.00022315979,140.225158691406,,,5,,,,-2.43999995291233,,,,,0.000705096818053479,3.93111502388327E-8,0.026526894688427,3.7263231965889E-5,0.00070500479717101,3.93060198132752E-8,0.000705004721611413,2.92409639943098E-8,3.26404274454466E-7,2.62665037308937E-8,1.00013052518627,10.005763053894,2,20,10,5,2.30642324454494,0.203861733175265,0.0404026173055172,172.741912841797,48.999698638916,49.0005493164063,140.225158691406,140.225158691406,,,33.4609832763672,0,1,,,,,,1,1,1,49.0004348754883,0,49.0001029968262,,,,,,,,,,,,,,,,,,,,,,,,,,,,,,,,,
,3754655629.6197,49.0000877380371,140.225158691406,,,5,,,,-2.43999995291233,,,,,0.000705304178598073,5.64259796535248E-8,0.030519917139169,5.40603609450483E-5,0.000705212135023602,5.64186159528437E-8,0.000705212034974958,4.15941257524145E-8,3.75647475111444E-7,3.81180918846523E-8,1.0001305189884,10.005763053894,2,20,10,5,2.30708731877648,0.204082472004,0.0404026173055172,172.741912841797,48.9996681213379,49.0004730224609,140.225158691406,140.225158691406,,,33.6102294921875,0,1,,,,,,1,1,1,49.0002136230469,0,48.9999860875747,,,,,,,,,,,,,,,,,,,,,,,,,,,,,,,,,
,3754655834.73165,49.0005512237549,140.225158691406,,,5,,,,-2.43999995291233,,,,,0.000704849536395419,6.67833437514164E-8,0.0311692779442101,4.46707110641239E-5,0.000704757618056117,6.67746346387141E-8,0.000704757513772042,5.88967897167314E-8,3.83392724275414E-7,3.1464583140364E-8,1.00013042546394,10.005763053894,2,20,10,5,2.30559784857652,0.203977048413974,0.0404026173055172,172.741912841797,48.9999961853027,49.0005340576172,140.225158691406,140.225158691406,,,33.7719078063965,0,1,,,,,,1,1,1,49.0005989074707,0,49.000233968099,,,,,,,,,,,,,,,,,,,,,,,,,,,,,,,,,
,3754656039.75977,49.0005531311035,140.225158691406,,,5,,,,-2.43999995291233,,,,,0.000705270528567622,5.05770903742567E-8,0.0289414470563951,4.86717667951156E-5,0.000705178555265831,5.05704946896104E-8,0.000705178465302752,3.71444875524337E-8,3.56202274025857E-7,3.43170799692953E-8,1.00013042555124,10.005763053894,2,20,10,5,2.30698286902537,0.204009178491546,0.0404026173055172,172.741912841797,48.999324798584,49.0010070800781,140.225158691406,140.225158691406,,,33.9709014892578,0,1,,,,,,1,1,1,49.000358581543,0,48.9999220106337,,,,,,,,,,,,,,,,,,,,,,,,,,,,,,,,,
,3754656243.42517,48.9991836547852,140.225158691406,,,5,,,,-2.43999995291233,,,,,0.000705225186210135,4.71897781030145E-8,0.0278576997728512,3.71708009415877E-5,0.000705133182117022,4.71836216967722E-8,0.000705133098770709,3.92398276057827E-8,3.42841791843683E-7,2.62017191400215E-8,1.0001304776111,10.005763053894,2,20,10,5,2.30683840929811,0.203952431953353,0.0404026173055172,172.741912841797,48.9988479614258,49.0002098083496,140.225158691406,140.225158691406,,,34.1325836181641,0,1,,,,,,1,1,1,48.9996147155762,0,48.9996654286104,,,,,,,,,,,,,,,,,,,,,,,,,,,,,,,,,
,3754656449.57439,49.0008602142334,140.225158691406,,,5,,,,-2.43999995291233,,,,,0.000705811335125412,5.53728670000529E-8,0.0364624392076154,5.6824137160046E-5,0.00070571928138072,5.53656451271416E-8,0.000705719138475483,3.81776889117108E-8,4.49112393212486E-7,4.00976150126813E-8,1.00013043960555,10.005763053894,2,20,10,5,2.30872506041727,0.204468672128519,0.0404026173055172,172.741912841797,48.9995269775391,49.0011825561523,140.225158691406,140.225158691406,,,34.3191413879395,0,1,,,,,,1,1,1,49.0006294250488,0,49.0002021789551,,,,,,,,,,,,,,,,,,,,,,,,,,,,,,,,,
,3754656654.49947,49.0011215209961,140.225158691406,,,5,,,,-2.43999995291233,,,,,0.00070544857933222,5.7778921380069E-8,0.0287599107976311,4.43627718130665E-5,0.000705356564464638,5.7771385012493E-8,0.000705356475604187,4.85703148117618E-8,3.54057335375317E-7,3.12803044318314E-8,1.00013045156481,10.005763053894,2,20,10,5,2.30756593072204,0.204053367911056,0.0404026173055172,172.741912841797,49.0002746582031,49.0014610290527,140.225158691406,140.225158691406,,,34.4808235168457,0,1,,,,,,1,1,1,49.0010604858398,0,49.0007410049438,,,,,,,,,,,,,,,,,,,,,,,,,,,,,,,,,
,3754656858.48722,49.0008811950684,140.225158691406,,,5,,,,-2.43999995291233,,,,,0.000705267379551814,4.00469492363762E-8,0.0320213495828643,4.13005203196896E-5,0.000705175396074174,4.00417261709596E-8,0.000705175285945314,2.74827683550147E-8,3.9410698120057E-7,2.91210796210358E-8,1.00013044056578,10.005763053894,2,20,10,5,2.30696159883082,0.204132276087818,0.0404026173055172,172.741912841797,48.9996757507324,49.0011329650879,140.225158691406,140.225158691406,,,34.6549415588379,0,1,,,,,,1,1,1,49.0006561279297,0,49.0003433227539,,,,,,,,,,,,,,,,,,,,,,,,,,,,,,,,,
,3754657064.37871,49.0006885528564,140.225158691406,,,5,,,,-2.43999995291233,,,,,0.000704862009983277,5.34585400092903E-8,0.0287665216779613,4.64200516338729E-5,0.0007047700855883,5.34515682277542E-8,0.000704769996760911,4.22761495441224E-8,3.53844266813295E-7,3.27077563542543E-8,1.0001304317491,10.005763053894,2,20,10,5,2.30564720242057,0.203883968570602,0.0404026173055172,172.741912841797,48.9992446899414,49.0010719299316,140.225158691406,140.225158691406,,,34.8414993286133,0,1,,,,,,1,1,1,49.0006294250488,0,49.0002398771398,,,,,,,,,,,,,,,,,,,,,,,,,,,,,,,,,
,3754657269.34661,49.0008754730225,140.225158691406,,,5,,,,-2.43999995291233,,,,,0.000705882937947961,4.74100618108089E-8,0.0323006688930647,3.56907398157192E-5,0.000705790874371818,4.74038784344999E-8,0.000705790762215485,4.01631521390157E-8,3.97891717801841E-7,2.51803276565482E-8,1.0001304403039,10.005763053894,2,20,10,5,2.3089741223707,0.204321697772285,0.0404026173055172,172.741912841797,48.9994888305664,49.0011787414551,140.225158691406,140.225158691406,,,35.0031814575195,0,1,,,,,,1,1,1,49.0010452270508,0,49.0003958309398,,,,,,,,,,,,,,,,,,,,,,,,,,,,,,,,,
,3754657474.28211,49.0001049041748,140.225158691406,,,5,,,,-2.43999995291233,,,,,0.000705951716774703,5.76334395300313E-8,0.031204670787079,5.88983249586273E-5,0.000705859588140751,5.76259182082076E-8,0.000705859483456281,3.99090445494757E-8,3.84428227840493E-7,4.15693951421835E-8,1.00013051977405,10.005763053894,2,20,10,5,2.30920300909637,0.204297436457083,0.0404026173055172,172.741912841797,48.9990386962891,49.0005264282227,140.225158691406,140.225158691406,,,35.1772994995117,0,1,,,,,,1,1,1,49.0004501342773,0,48.9997107561897,,,,,,,,,,,,,,,,,,,,,,,,,,,,,,,,,
,3754657679.19458,49.0004920959473,140.225158691406,,,5,,,,-2.43999995291233,,,,,0.00070549766181186,5.14406158028305E-8,0.0288546208988185,3.95891987767198E-5,0.000705405660860179,5.14339076507485E-8,0.000705405571407281,4.31985893581045E-8,3.55248017159398E-7,2.791645990622E-8,1.00013042275783,10.005763053894,2,20,10,5,2.30772614496302,0.204071382718599,0.0404026173055172,172.741912841797,48.9998550415039,49.0007133483887,140.225158691406,140.225158691406,,,35.3638572692871,0,1,,,,,,1,1,1,49.0003700256348,0,49.0002710678998,,,,,,,,,,,,,,,,,,,,,,,,,,,,,,,,,
,3754657887.3403,49.0005378723145,140.225158691406,,,5,,,,-2.43999995291233,,,,,0.000705271394381785,3.6092193030845E-8,0.0270145227024488,4.03241844993759E-5,0.000705179340559964,3.60874821857252E-8,0.000705179262177501,2.22217640744613E-8,3.32486664130011E-7,2.84341268887233E-8,1.00013053958976,10.005763053894,2,20,10,5,2.30699256096103,0.203931841823404,0.0404026173055172,172.741912841797,48.9997253417969,49.0006828308105,140.225158691406,140.225158691406,,,35.5255393981934,0,1,,,,,,1,1,1,49.0004463195801,0,49.0002109303194,,,,,,,,,,,,,,,,,,,,,,,,,,,,,,,,,
,3754658092.25247,48.9997043609619,140.225158691406,,,5,,,,-2.43999995291233,,,,,0.000705531921455159,4.66999941226941E-8,0.0273556066076059,4.02646176833039E-5,0.00070543986053588,4.66939005013305E-8,0.000705439780131922,3.70662137807673E-8,3.36809006544214E-7,2.83974671403386E-8,1.00013050144233,10.005763053894,2,20,10,5,2.30784354870547,0.204020915275262,0.0404026173055172,172.741912841797,48.9990997314453,49.0002365112305,140.225158691406,140.225158691406,,,35.7120971679687,0,1,,,,,,1,1,1,48.9998664855957,0,48.9996708140654,,,,,,,,,,,,,,,,,,,,,,,,,,,,,,,,,
,3754658298.49543,49.0012397766113,140.225158691406,,,5,,,,-2.43999995291233,,,,,0.000705326282881286,4.75935352708642E-8,0.0274169407209364,4.68644686955293E-5,0.000705234280149001,4.75873271720165E-8,0.000705234199407628,3.42420412066014E-8,3.37465793809625E-7,3.30459728466564E-8,1.00013045697703,10.005763053894,2,20,10,5,2.30717067284554,0.203963915148529,0.0404026173055172,172.741912841797,49.0001907348633,49.0014991760254,140.225158691406,140.225158691406,,,35.873779296875,0,1,,,,,,1,1,1,49.0010147094727,0,49.0007297992706,,,,,,,,,,,,,,,,,,,,,,,,,,,,,,,,,
,3754658503.51247,49.0002288818359,140.225158691406,,,5,,,,-2.43999995291233,,,,,0.000705474916837313,3.80013942836196E-8,0.0301818815357926,3.27991915172109E-5,0.000705382927348032,3.79964391409651E-8,0.000705382829479676,3.01448909856033E-8,3.71576809791213E-7,2.31303898553215E-8,1.00013041071128,10.005763053894,2,20,10,5,2.30764701693134,0.204118260721974,0.0404026173055172,172.741912841797,48.9997863769531,49.0012130737305,140.225158691406,140.225158691406,,,36.0478973388672,0,1,,,,,,1,1,1,49.0002899169922,0,49.0003289615407,,,,,,,,,,,,,,,,,,,,,,,,,,,,,,,,,
,3754658709.97767,49.0002632141113,140.225158691406,,,5,,,,-2.43999995291233,,,,,0.000705608081694857,6.62178743977824E-8,0.0320437980498829,5.45918520342144E-5,0.000705515992795152,6.62092323040305E-8,0.000705515882458561,5.38616975383324E-8,3.94573754082428E-7,3.85042852235731E-8,1.00013052701944,10.005763053894,2,20,10,5,2.30807597087905,0.204231794204334,0.0404026173055172,172.741912841797,48.9998550415039,49.0005340576172,140.225158691406,140.225158691406,,,36.2220191955566,0,1,,,,,,1,1,1,49.0003814697266,0,49.0001900990804,,,,,,,,,,,,,,,,,,,,,,,,,,,,,,,,,
,3754658914.97008,49.0003395080566,140.225158691406,,,5,,,,-2.43999995291233,,,,,0.000705575290312417,3.11983330057094E-8,0.0329137446495889,3.5615165138145E-5,0.000705483203229262,3.11942612028483E-8,0.000705483086825774,1.84885136526197E-8,4.05267070731947E-7,2.512482427617E-8,1.00013053051119,10.005763053894,2,20,10,5,2.30796560781266,0.204257344892349,0.0404026173055172,172.741912841797,48.999683380127,49.0007362365723,140.225158691406,140.225158691406,,,36.4085731506348,0,1,,,,,,1,1,1,49.0006256103516,0,49.0001501195571,,,,,,,,,,,,,,,,,,,,,,,,,,,,,,,,,
,3754659119.95477,48.9996681213379,140.225158691406,,,5,,,,-2.43999995291233,,,,,0.000705869115748979,6.20018828804681E-8,0.0308201487367858,3.83551123121993E-5,0.000705777012001537,6.19937927039265E-8,0.000705776909893084,5.57802320816418E-8,3.79646661948735E-7,2.70517290156394E-8,1.00013049978375,10.005763053894,2,20,10,5,2.30893418760527,0.20425804008836,0.0404026173055172,172.741912841797,48.9993743896484,49.0001373291016,140.225158691406,140.225158691406,,,36.5826988220215,0,1,,,,,,1,1,1,48.9996185302734,0,48.9997634887695,,,,,,,,,,,,,,,,,,,,,,,,,,,,,,,,,
,3754659324.93393,48.9998989105225,140.225158691406,,,5,,,,-2.43999995291233,,,,,0.000705557417422701,5.7961062797707E-8,0.0294738508208017,3.82426399748582E-5,0.00070546534689597,5.7953499266448E-8,0.000705465253554598,5.12988658588067E-8,3.62902462508012E-7,2.69635761505469E-8,1.00013051034631,10.005763053894,2,20,10,5,2.30791940312994,0.204113613509815,0.0404026173055172,172.741912841797,48.9993209838867,49.0003890991211,140.225158691406,140.225158691406,,,36.7692565917969,0,1,,,,,,1,1,1,48.9996757507324,0,48.9998426998363,,,,,,,,,,,,,,,,,,,,,,,,,,,,,,,,,
,3754659529.79443,49.0002632141113,140.225158691406,,,5,,,,-2.43999995291233,,,,,0.00070559183328454,5.85533577919056E-8,0.030589012388397,3.77301526958478E-5,0.000705499827441691,5.85457227105723E-8,0.000705499726898526,5.21528000601972E-8,3.76651511155831E-7,2.660238886988E-8,1.00013041228257,10.005763053894,2,20,10,5,2.30802800636293,0.204168488371471,0.0404026173055172,172.741912841797,48.999813079834,49.0004653930664,140.225158691406,140.225158691406,,,36.9433746337891,0,1,,,,,,1,1,1,49.0004463195801,0,49.0001430511475,,,,,,,,,,,,,,,,,,,,,,,,,,,,,,,,,
,3754659734.67177,49.0009250640869,140.225158691406,,,5,,,,-2.43999995291233,,,,,0.000705923129613508,5.44868659560614E-8,0.0335954309360087,4.5823212987441E-5,0.000705831059193662,5.44797594760295E-8,0.00070583093785871,4.38464665000369E-8,4.13864641416556E-7,3.2334680577163E-8,1.00013044257354,10.005763053894,2,20,10,5,2.30910097286003,0.204385513702326,0.0404026173055172,172.741912841797,48.9999542236328,49.00146484375,140.225158691406,140.225158691406,,,37.1174926757812,0,1,,,,,,1,1,1,49.0006980895996,0,49.0005863414091,,,,,,,,,,,,,,,,,,,,,,,,,,,,,,,,,
,3754659939.59532,49.0009536743164,140.225158691406,,,5,,,,-2.43999995291233,,,,,0.000705237161237502,4.75651789685679E-8,0.0306963800997471,3.44802321157371E-5,0.000705145179362264,4.75589751911749E-8,0.000705145078162943,4.08805873965449E-8,3.77783557526812E-7,2.43029565145528E-8,1.00013044388295,10.005763053894,2,20,10,5,2.30686747319522,0.204070182325478,0.0404026173055172,172.741912841797,48.9997138977051,49.0012092590332,140.225158691406,140.225158691406,,,37.3040504455566,0,1,,,,,,1,1,1,49.0008850097656,0,49.0003439959358,,,,,,,,,,,,,,,,,,,,,,,,,,,,,,,,,
,3754660144.54879,49.0001754760742,140.225158691406,,,5,,,,-2.43999995291233,,,,,0.000705477067694904,5.11780339526669E-8,0.0307074014933253,3.95890380966133E-5,0.000705385079649062,5.11713607841843E-8,0.000705384978342604,4.28862331386602E-8,3.780477723719E-7,2.79155722076701E-8,1.00013040826705,10.005763053894,2,20,10,5,2.30765218017351,0.20414004944662,0.0404026173055172,172.741912841797,48.9993896484375,49.0002784729004,140.225158691406,140.225158691406,,,37.490608215332,0,1,,,,,,1,1,1,49.000171661377,0,49.0000035903033,,,,,,,,,,,,,,,,,,,,,,,,,,,,,,,,,
,3754660349.46286,49.0001907348633,140.225158691406,,,5,,,,-2.43999995291233,,,,,0.000705701930513627,5.15899469844117E-8,0.0311223002870511,5.32546794693974E-5,0.000705609831706035,5.15832141523256E-8,0.000705609727610349,3.53424165523945E-8,3.83277794186177E-7,3.75731496486748E-8,1.00013052370227,10.005763053894,2,20,10,5,2.30838623942585,0.20422183196417,0.0404026173055172,172.741912841797,48.9995384216309,49.0006141662598,140.225158691406,140.225158691406,,,37.6647262573242,0,1,,,,,,1,1,1,49.0003280639648,0,49.0000661962173,,,,,,,,,,,,,,,,,,,,,,,,,,,,,,,,,
,3754660554.47714,49.000846862793,140.225158691406,,,5,,,,-2.43999995291233,,,,,0.000705486453183112,4.50671205367873E-8,0.0304890387329069,3.8975037069613E-5,0.000705394442241346,4.50612427935868E-8,0.000705394342369235,3.57075144877281E-8,3.75364427174979E-7,2.74861603577376E-8,1.00013043899449,10.005763053894,2,20,10,5,2.30768365890465,0.204133966923923,0.0404026173055172,172.741912841797,48.9997024536133,49.001033782959,140.225158691406,140.225158691406,,,37.8264083862305,0,1,,,,,,1,1,1,49.0009994506836,0,49.0004985332489,,,,,,,,,,,,,,,,,,,,,,,,,,,,,,,,,
,3754660759.48038,49.0006542205811,140.225158691406,,,5,,,,-2.43999995291233,,,,,0.000705647182923051,4.65208130576305E-8,0.0299789257425553,4.1876153877142E-5,0.000705555157238436,4.65147461310218E-8,0.000705555060658296,3.59307149053039E-8,3.69168285705503E-7,2.95398939406894E-8,1.00013043017781,10.005763053894,2,20,10,5,2.30821123212055,0.204159924708861,0.0404026173055172,172.741912841797,48.9999656677246,49.0010986328125,140.225158691406,140.225158691406,,,38.0005264282227,0,1,,,,,,1,1,1,49.0008430480957,0,49.0004187191234,,,,,,,,,,,,,,,,,,,,,,,,,,,,,,,,,
,3754660964.58419,49.0010299682617,140.225158691406,,,5,,,,-2.43999995291233,,,,,0.000705574219713384,6.8919206415838E-8,0.0341762061809421,4.32560793109068E-5,0.000705482191413614,6.89102172589063E-8,0.00070548206590935,6.17949947303289E-8,4.20811159318918E-7,3.04958467491607E-8,1.0001304473747,10.005763053894,2,20,10,5,2.3079576048426,0.204307886754247,0.0404026173055172,172.741912841797,48.9993476867676,49.0012702941895,140.225158691406,140.225158691406,,,38.1746482849121,0,1,,,,,,1,1,1,49.0011215209961,0,49.0003657870822,,,,,,,,,,,,,,,,,,,,,,,,,,,,,,,,,
,3754661169.46654,49.0003833770752,140.225158691406,,,5,,,,-2.43999995291233,,,,,0.000706191112654555,5.34226374916214E-8,0.0332437574929276,3.67634792710906E-5,0.000706099024785812,5.34156711382631E-8,0.000706098905932702,4.6691301325398E-8,4.0968782741792E-7,2.59452558995274E-8,1.00013041778208,10.005763053894,2,20,10,5,2.30997881024766,0.204448925350454,0.0404026173055172,172.741912841797,48.9994964599609,49.000675201416,140.225158691406,140.225158691406,,,38.3612060546875,0,1,,,,,,1,1,1,49.0004577636719,0,49.0002313501695,,,,,,,,,,,,,,,,,,,,,,,,,,,,,,,,,
,3754661374.44041,49.0001487731934,140.225158691406,,,5,,,,-2.43999995291233,,,,,0.000705683801312171,7.28296453342556E-8,0.0306321213613172,4.54715101848049E-5,0.000705591706225447,7.28201407197376E-8,0.000705591605385562,6.53814593388878E-8,3.77231445852921E-7,3.20630265127879E-8,1.0001305217818,10.005763053894,2,20,10,5,2.30832868490826,0.204196837644414,0.0404026173055172,172.741912841797,48.9994621276855,49.0003356933594,140.225158691406,140.225158691406,,,38.5228881835937,0,1,,,,,,1,1,1,49.000244140625,0,48.9999485015869,,,,,,,,,,,,,,,,,,,,,,,,,,,,,,,,,
,3754661579.37519,49.0000667572022,140.225158691406,,,5,,,,-2.43999995291233,,,,,0.000705448864026573,3.69229805432444E-8,0.0327583916835454,3.54859065052045E-5,0.000705356802247588,3.69181620575291E-8,0.000705356686961015,2.71409538410136E-8,4.03281940522969E-7,2.50263723760746E-8,1.00013051802817,10.005763053894,2,20,10,5,2.3075526157841,0.204214491163543,0.0404026173055172,172.741912841797,48.9998474121094,49.0002517700195,140.225158691406,140.225158691406,,,38.6970062255859,0,1,,,,,,1,1,1,49.0000877380371,0,49.0000955793593,,,,,,,,,,,,,,,,,,,,,,,,,,,,,,,,,
,3754661784.35333,49.0000076293945,140.225158691406,,,5,,,,-2.43999995291233,,,,,0.000705641516855743,5.24143210117877E-8,0.0335874422581846,4.41913495275263E-5,0.000705549431844418,5.24074810325224E-8,0.000705549310615553,4.21298644107413E-8,4.13601135136011E-7,3.11707971169612E-8,1.00013051532206,10.005763053894,2,20,10,5,2.30817983521752,0.204303659570902,0.0404026173055172,172.741912841797,48.9997024536133,49.0005149841309,140.225158691406,140.225158691406,,,38.8462524414063,0,1,,,,,,1,1,1,49.0000038146973,0,49.0000693377327,,,,,,,,,,,,,,,,,,,,,,,,,,,,,,,,,
,3754661989.29397,48.9996643066406,140.225158691406,,,5,,,,-2.43999995291233,,,,,0.000705643772883774,3.55684910933396E-8,0.0319411872123752,3.49615606892478E-5,0.000705551698662855,3.55638500248111E-8,0.000705551589026225,2.56219380517797E-8,3.93330153096981E-7,2.46638139600917E-8,1.00013049960916,10.005763053894,2,20,10,5,2.30819308382396,0.204237994524434,0.0404026173055172,172.741912841797,48.9989318847656,49.0003890991211,140.225158691406,140.225158691406,,,39.0203704833984,0,1,,,,,,1,1,1,48.9995193481445,0,48.9995418124729,,,,,,,,,,,,,,,,,,,,,,,,,,,,,,,,,
,3754662194.23301,49.0012187957764,140.225158691406,,,5,,,,-2.43999995291233,,,,,0.000705456105149235,4.94244787812429E-8,0.0304595386511082,5.15009345839769E-5,0.000705364086160164,4.94180319016432E-8,0.000705363986485514,3.3507530678094E-8,3.749851004048E-7,3.6323370780923E-8,1.0001304560168,10.005763053894,2,20,10,5,2.30758449398799,0.204123997369623,0.0404026173055172,172.741912841797,48.9999389648438,49.0015335083008,140.225158691406,140.225158691406,,,39.1944885253906,0,1,,,,,,1,1,1,49.0010414123535,0,49.0006705390082,,,,,,,,,,,,,,,,,,,,,,,,,,,,,,,,,
,3754662399.23694,49.0011959075928,140.225158691406,,,5,,,,-2.43999995291233,,,,,0.000705614558651416,6.02961481301574E-8,0.0318771738780921,6.00906526299912E-5,0.000705522519732786,6.02882832240222E-8,0.000705522410539677,4.28692359562998E-8,3.92525646169813E-7,4.23899245413695E-8,1.00013045496927,10.005763053894,2,20,10,5,2.30809775152556,0.204226953329205,0.0404026173055172,172.741912841797,49.0001792907715,49.00146484375,140.225158691406,140.225158691406,,,39.3561744689941,0,1,,,,,,1,1,1,49.0011787414551,0,49.0006516400505,,,,,,,,,,,,,,,,,,,,,,,,,,,,,,,,,
,3754662604.20079,49.0002918243408,140.225158691406,,,5,,,,-2.43999995291233,,,,,0.000705737923304165,4.16146659332957E-8,0.0347354559846815,3.64530220039071E-5,0.000705645897488009,4.160923952291E-8,0.000705645767812621,3.27103765235007E-8,4.27796440153584E-7,2.57169220818844E-8,1.00013041359198,10.005763053894,2,20,10,5,2.30849108985856,0.204377825165484,0.0404026173055172,172.741912841797,48.999885559082,49.0008544921875,140.225158691406,140.225158691406,,,39.5178565979004,0,1,,,,,,1,1,1,49.0003089904785,0,49.0002430186552,,,,,,,,,,,,,,,,,,,,,,,,,,,,,,,,,
,3754662809.49208,48.9998741149902,140.225158691406,,,5,,,,-2.43999995291233,,,,,0.000705623903757419,3.65717228725847E-8,0.0316734748368894,3.44962789987913E-5,0.000705531825355213,3.65669505487021E-8,0.000705531717551738,2.72945315736227E-8,3.90022503729797E-7,2.4334141008216E-8,1.00013050921149,10.005763053894,2,20,10,5,2.30812904544545,0.204221456834095,0.0404026173055172,172.741912841797,48.9991264343262,49.0002288818359,140.225158691406,140.225158691406,,,39.6422271728516,0,1,,,,,,1,1,1,49.000057220459,0,48.9997183855842,,,,,,,,,,,,,,,,,,,,,,,,,,,,,,,,,
,3754663014.38306,49.0006160736084,140.225158691406,,,5,,,,-2.43999995291233,,,,,0.000705761285108942,4.42902914536128E-8,0.0336927948255727,3.10042142086478E-5,0.000705669245775751,4.4284515493698E-8,0.000705669123764468,3.85086020752978E-8,4.14968919951772E-7,2.18679189388919E-8,1.00013042843193,10.005763053894,2,20,10,5,2.30857122617913,0.20434257807003,0.0404026173055172,172.741912841797,48.9998054504395,49.0009346008301,140.225158691406,140.225158691406,,,39.8412208557129,0,1,,,,,,1,1,1,49.0006713867188,0,49.000384162454,,,,,,,,,,,,,,,,,,,,,,,,,,,,,,,,,
,3754663219.33236,49.0020236968994,140.225158691406,,,5,,,,-2.43999995291233,,,,,0.000705543514803541,5.11868537444575E-8,0.0356523150759607,3.66704510056554E-5,0.000705451458428804,5.11801750972996E-8,0.000705451321855022,4.41680837193778E-8,4.38967342051779E-7,2.5857120944689E-8,1.00013049285481,10.005763053894,2,20,10,5,2.30785190423326,0.204358449359266,0.0404026173055172,172.741912841797,48.9997291564941,49.0020637512207,140.225158691406,140.225158691406,,,39.97802734375,0,1,,,,,,1,1,1,49.0019836425781,0,49.0007160411162,,,,,,,,,,,,,,,,,,,,,,,,,,,,,,,,,
,3754663424.32181,49.0004482269287,140.225158691406,,,5,,,,-2.43999995291233,,,,,0.000705889809821799,4.57668402667618E-8,0.0350526030304836,3.40644692684734E-5,0.00070579775914865,4.57608720994986E-8,0.000705797627066068,3.8942107430106E-8,4.31795279481523E-7,2.4032679505389E-8,1.00013042075007,10.005763053894,2,20,10,5,2.30898678399721,0.204434590469857,0.0404026173055172,172.741912841797,48.9999694824219,49.0007286071777,140.225158691406,140.225158691406,,,40.1397094726562,0,1,,,,,,1,1,1,49.000560760498,0,49.0004328559427,,,,,,,,,,,,,,,,,,,,,,,,,,,,,,,,,
,3754663629.27434,49.0006637573242,140.225158691406,,,5,,,,-2.43999995291233,,,,,0.000705512160011745,5.68385360795731E-8,0.0322854237668659,3.68124932382055E-5,0.000705420151628041,5.68311235612168E-8,0.00070542003963641,5.05593410554228E-8,3.97495025241179E-7,2.59524495428029E-8,1.00013043061428,10.005763053894,2,20,10,5,2.30776134561386,0.204213761831356,0.0404026173055172,172.741912841797,48.9992485046387,49.0007209777832,140.225158691406,140.225158691406,,,40.3013916015625,0,1,,,,,,1,1,1,49.0006065368652,0,49.0001235538059,,,,,,,,,,,,,,,,,,,,,,,,,,,,,,,,,
,3754663834.2197,49.0011558532715,140.225158691406,,,5,,,,-2.43999995291233,,,,,0.000705631307788954,3.96669223042979E-8,0.0311967199558909,4.70700278312174E-5,0.000705539267978806,3.96617483048484E-8,0.000705539163395158,2.16845527424361E-8,3.84155867334658E-7,3.32089513679317E-8,1.0001304531361,10.005763053894,2,20,10,5,2.30815496404083,0.204204389189901,0.0404026173055172,172.741912841797,49.0003929138184,49.001293182373,140.225158691406,140.225158691406,,,40.4506378173828,0,1,,,,,,1,1,1,49.0011444091797,0,49.0007290559657,,,,,,,,,,,,,,,,,,,,,,,,,,,,,,,,,
,3754664039.10749,49.0005722045898,140.225158691406,,,5,,,,-2.43999995291233,,,,,0.000705077218923784,3.64265725940196E-8,0.0309054075909323,3.61261348830823E-5,0.000704985189338648,3.64218180476043E-8,0.000704985086779673,2.60399619177428E-8,3.80269781661045E-7,2.54650586729207E-8,1.00013054116105,10.005763053894,2,20,10,5,2.30634354920769,0.204032314979494,0.0404026173055172,172.741912841797,48.9998588562012,49.0008239746094,140.225158691406,140.225158691406,,,40.6371955871582,0,1,,,,,,1,1,1,49.0008506774902,0,49.0002849803251,,,,,,,,,,,,,,,,,,,,,,,,,,,,,,,,,
,3754664244.08772,49.0002574920654,140.225158691406,,,5,,,,-2.43999995291233,,,,,0.000705721066564973,4.29255595454283E-8,0.0310334992572887,4.26266428017382E-5,0.000705628963104381,4.29199573425619E-8,0.000705628859599073,3.06208235881892E-8,3.82194552859004E-7,3.00747053363509E-8,1.00013052675756,10.005763053894,2,20,10,5,2.30844915100942,0.204223791015543,0.0404026173055172,172.741912841797,48.9995803833008,49.0007820129395,140.225158691406,140.225158691406,,,40.7740020751953,0,1,,,,,,1,1,1,49.000545501709,0,49.0002683751723,,,,,,,,,,,,,,,,,,,,,,,,,,,,,,,,,
,3754664449.05483,48.9994239807129,140.225158691406,,,5,,,,-2.43999995291233,,,,,0.000705753532942773,5.02652110598256E-8,0.0342484423606368,5.56735689980866E-5,0.000705661452160656,5.02586528780644E-8,0.000705661326093264,3.13475635494977E-8,4.21807755067288E-7,3.92843791936181E-8,1.00013048861013,10.005763053894,2,20,10,5,2.30854388638138,0.204362725956894,0.0404026173055172,172.741912841797,48.9989738464355,48.9999122619629,140.225158691406,140.225158691406,,,40.9605598449707,0,1,,,,,,1,1,1,48.9996032714844,0,48.9994053560145,,,,,,,,,,,,,,,,,,,,,,,,,,,,,,,,,
,3754664654.04146,49.0001316070557,140.225158691406,,,5,,,,-2.43999995291233,,,,,0.000705827303127179,6.62402362131124E-8,0.0326926118748725,7.1938283577757E-5,0.000705735270830459,6.6231599198014E-8,0.000705735155944808,4.25377563932068E-8,4.02688090462744E-7,5.0765776004692E-8,1.00013040625929,10.005763053894,2,20,10,5,2.30879074023899,0.204321393691843,0.0404026173055172,172.741912841797,48.9995536804199,49.0006637573242,140.225158691406,140.225158691406,,,41.0973663330078,0,1,,,,,,1,1,1,48.9995994567871,0,49.0000498154584,,,,,,,,,,,,,,,,,,,,,,,,,,,,,,,,,
,3754664859.0676,49.0002212524414,140.225158691406,,,5,,,,-2.43999995291233,,,,,0.000705686559451239,4.94462727139418E-8,0.0312648623871157,5.60439673953734E-5,0.000705594461664296,4.94398195765984E-8,0.000705594356615051,2.96764586425461E-8,3.85025089766424E-7,3.9542427368636E-8,1.00013052509897,10.005763053894,2,20,10,5,2.30833545177576,0.204223127325634,0.0404026173055172,172.741912841797,48.9997215270996,49.0005340576172,140.225158691406,140.225158691406,,,41.2839241027832,0,1,,,,,,1,1,1,49.0003242492676,0,49.0000805574305,,,,,,,,,,,,,,,,,,,,,,,,,,,,,,,,,
,3754665063.87115,49.0010204315186,140.225158691406,,,5,,,,-2.43999995291233,,,,,0.000705652846342453,4.13958046038145E-8,0.0338108396306174,3.5275492841656E-5,0.000705560808095299,4.13904053521641E-8,0.000705560685246451,3.30760264341644E-8,4.16358799031107E-7,2.48825667997276E-8,1.00013044693823,10.005763053894,2,20,10,5,2.30821609824798,0.204315934372961,0.0404026173055172,172.741912841797,48.9998970031738,49.0014343261719,140.225158691406,140.225158691406,,,41.4456062316895,0,1,,,,,,1,1,1,49.0012588500977,0,49.0006294250488,,,,,,,,,,,,,,,,,,,,,,,,,,,,,,,,,
,3754665269.10882,49.0015392303467,140.225158691406,,,5,,,,-2.43999995291233,,,,,0.000705641005636749,4.2734275619965E-8,0.0323547453893696,5.17296224035491E-5,0.000705548952183657,4.27287007772266E-8,0.000705548839690047,2.22191281944749E-8,3.98421239546839E-7,3.64972904800789E-8,1.00013047068216,10.005763053894,2,20,10,5,2.30818255853098,0.204253845827437,0.0404026173055172,172.741912841797,49.0001945495605,49.0016250610352,140.225158691406,140.225158691406,,,41.5824127197266,0,1,,,,,,1,1,1,49.0014801025391,0,49.0010384952321,,,,,,,,,,,,,,,,,,,,,,,,,,,,,,,,,
,3754665473.80825,48.9998016357422,140.225158691406,,,5,,,,-2.43999995291233,,,,,0.000705665882839904,3.96952641939898E-8,0.03438260429433,3.06001105022199E-5,0.000705573801299957,3.9690084404029E-8,0.000705573674258721,3.33090197274953E-8,4.23407510303628E-7,2.1582678350758E-8,1.00013050589432,10.005763053894,2,20,10,5,2.30825670155529,0.204342748939466,0.0404026173055172,172.741912841797,48.9993209838867,49.0000534057617,140.225158691406,140.225158691406,,,41.7316589355469,0,1,,,,,,1,1,1,48.999942779541,0,48.9997124142117,,,,,,,,,,,,,,,,,,,,,,,,,,,,,,,,,
,3754665678.75023,48.9991760253906,140.225158691406,,,5,,,,-2.43999995291233,,,,,0.000705995841181518,4.73034139023427E-8,0.0322738776010434,5.71139760530996E-5,0.000705903736794756,4.729724268762E-8,0.000705903624806494,2.47309179162061E-8,3.97625266438099E-7,4.03163845709595E-8,1.00013047726193,10.005763053894,2,20,10,5,2.3093435285058,0.204353307918773,0.0404026173055172,172.741912841797,48.9985618591309,48.9997444152832,140.225158691406,140.225158691406,,,41.8809051513672,0,1,,,,,,1,1,1,48.9987449645996,0,48.9992150200738,,,,,,,,,,,,,,,,,,,,,,,,,,,,,,,,,
,3754665883.71047,49.0002956390381,140.225158691406,,,5,,,,-2.43999995291233,,,,,0.000705529029741912,5.14951128955109E-8,0.0346740079253038,6.1602723901241E-5,0.000705437031041619,5.14883980995803E-8,0.000705436901862872,2.76156258658315E-8,4.2691325469281E-7,4.34560967747827E-8,1.00013041376657,10.005763053894,2,20,10,5,2.30780801151052,0.204314855854238,0.0404026173055172,172.741912841797,49.0000534057617,49.0005760192871,140.225158691406,140.225158691406,,,42.0425872802734,0,1,,,,,,1,1,1,49.0002670288086,0,49.000339296129,,,,,,,,,,,,,,,,,,,,,,,,,,,,,,,,,
,3754666037.48856,49.0010356903076,140.225158691406,,,5,,,,-2.43999995291233,,,,,0.000705665752979976,6.87306858498121E-8,0.0332330461311843,7.55059232985769E-5,0.000705573712556736,6.87217212636912E-8,0.00070557359386857,4.34144476317565E-8,4.09251128492025E-7,5.32715750684541E-8,1.00013044763658,10.005763053894,2,20,10,5,2.30826037649219,0.204296395742925,0.0404026173055172,172.741912841797,48.9997596740723,49.0012817382812,140.225158691406,140.225158691406,,,42.1420860290527,0,1,,,,,,1,1,1,49.0008316040039,0,49.0004925447352,,,,,,,,,,,,,,,,,,,,,,,,,,,,,,,,,