File: Experimental_Data/Fig3B/Lifetime_120Oe.dat
[Header]
; MPMS3 Data File (default extension .dat)
; Copyright (c) 2007, Quantum Design, Inc. All rights reserved.
TITLE,120Oe
FILEOPENTIME,3754666314.91976,12/22/2018,6:51 pm
BYAPP,SQUID AC,0.9.1.0
INFO,MPMS3 Measurement Release 1.1.16 Build 347, MultiVu Release 2.3.3.2,APPNAME
INFO,0,MOMENT_UNITS
INFO,CoIINO3,SAMPLE_MATERIAL
INFO,40 Hours Pumped Turbo,SAMPLE_COMMENT
INFO,,SAMPLE_MASS
INFO,,SAMPLE_VOLUME
INFO,,SAMPLE_MOLECULAR_WEIGHT
INFO,,SAMPLE_SIZE
INFO,,SAMPLE_SHAPE
INFO,Brass,SAMPLE_HOLDER
INFO,Standard,SAMPLE_HOLDER_DETAIL
INFO,65.37,SAMPLE_OFFSET
DATATYPE,COMMENT,1
DATATYPE,TIME,2
STARTUPAXIS,X,2
STARTUPAXIS,Y1,5
FIELDGROUP, VSM,2,3,4,5,6,8,9,10,11,14,15
FIELDGROUP, DC, 2,3,4,14,56,57,58,59,60,61,62,63,64,65,66,67,68,69
FIELDGROUP, AC, 2,3,4,11,16,17,18,19,20,21,22,23,24,25,26,27,28,29,30
STARTUPGROUP, All
[Data]
Comment,Time Stamp (sec),Temperature (K),Magnetic Field (Oe),Moment (emu),M. Std. Err. (emu),Transport Action,Averaging Time (sec),Frequency (Hz),Peak Amplitude (mm),Center Position (mm),Lockin Signal' (V),Lockin Signal (V),Range,M. Quad. Signal (emu),AC Moment (emu),AC M. Std Err. (emu),AC Phase (deg),AC Phase Std. Err. (deg),AC Susceptibility (emu/Oe),AC Suscept. Std Err. (emu/Oe),AC X' (emu/Oe),AC X' Std Err. (emu/Oe),AC X'' (emu/Oe),AC X'' Std Err. (emu/Oe),AC Drive (Oe),AC Frequency (Hz),AC Averaging Time (sec),AC Cycles,AC Range,AC Measure Type,AC Signal' (V),AC Signal'' (V),AC Trim Coil Ratio,AC Trim Coil Phase,Min. Temperature (K),Max. Temperature (K),Min. Field (Oe),Max. Field (Oe),Mass (grams),Motor Lag (deg),Pressure (Torr),Measure Count,Measurement Number,SQUID Status (code),Motor Status (code),Measure Status (code),Motor Current (amps),Motor Temp. (C),Temp. Status (code),Field Status (code),Chamber Status (code),Chamber Temp (K),Redirection State,Average Temp (K),Rotation Angle (deg),Rotator state,DC Moment Fixed Ctr (emu),DC Moment Err Fixed Ctr (emu),DC Moment Free Ctr (emu),DC Moment Err Free Ctr (emu),DC Fixed Fit,DC Free Fit,DC Calculated Center (mm),DC Calculated Center Err (mm),DC Scan Length (mm),DC Scan Time (s),DC Number of Points,DC Squid Drift,DC Min V (V),DC Max V (V),DC Scans per Measure,Map 01,Map 02,Map 03,Map 04,Map 05,Map 06,Map 07,Map 08,Map 09,Map 10,Map 11,Map 12,Map 13,Map 14,Map 15,Map 16
,3754666370.60803,48.8964328765869,120.104522705078,,,5,,,,-2.43999995291233,,,,,0.000681157287654071,5.92781660541732E-8,0.0189309040973056,3.56948495187591E-5,0.000681068344263508,5.92704256964456E-8,0.000681068307087895,5.40631957481597E-8,2.25029476585268E-7,2.42930901232026E-8,1.00013059392837,10.005763053894,2,20,10,5,2.22814432812756,0.196597231991309,0.0404026173055172,172.741912841797,48.89404296875,48.9139785766602,120.104522705078,120.104522705078,,,42.502758026123,0,1,,,,,,1,1,1,48.8976402282715,0,48.9019165039063,,,,,,,,,,,,,,,,,,,,,,,,,,,,,,,,,
,3754666575.65507,48.999906539917,120.104522705078,,,5,,,,-2.43999995291233,,,,,0.000679667159559214,4.50981723071532E-8,0.0150823165672742,3.51465008866683E-5,0.000679578467300811,4.50922872813792E-8,0.000679578443755716,3.82521749635756E-8,1.78889571707843E-7,2.38764629462246E-8,1.00013051069548,10.005763053894,2,20,10,5,2.22328315508926,0.196017400214752,0.0404026173055172,172.741912841797,48.9991760253906,49.000186920166,120.104522705078,120.104522705078,,,42.7888145446777,0,1,,,,,,1,1,1,48.9997634887695,0,48.9996820337632,,,,,,,,,,,,,,,,,,,,,,,,,,,,,,,,,
,3754666780.56269,49.0006294250488,120.104522705078,,,5,,,,-2.43999995291233,,,,,0.00067964840081375,3.1500476813442E-8,0.0128303889029002,3.36718993393395E-5,0.000679559766483752,3.14963687722053E-8,0.000679559749445226,2.16458634170751E-8,1.52175536976323E-7,2.2879638169431E-8,1.00013042904299,10.005763053894,2,20,10,5,2.22322949517451,0.19592460696452,0.0404026173055172,172.741912841797,49.0001220703125,49.001091003418,120.104522705078,120.104522705078,,,42.9753684997559,0,1,,,,,,1,1,1,49.0003967285156,0,49.0004142312443,,,,,,,,,,,,,,,,,,,,,,,,,,,,,,,,,
,3754666985.62699,48.9996948242188,120.104522705078,,,5,,,,-2.43999995291233,,,,,0.000679701683693096,3.21539273876422E-8,0.0161148312583412,2.9258747365749E-5,0.000679612993513845,3.21497318153021E-8,0.000679612966633308,2.52660753808989E-8,1.9114581667502E-7,1.98804097201889E-8,1.00013050100586,10.005763053894,2,20,10,5,2.22339255519982,0.196067425138489,0.0404026173055172,172.741912841797,48.999210357666,48.9998245239258,120.104522705078,120.104522705078,,,43.1246147155762,0,1,,,,,,1,1,1,48.9995651245117,0,48.9995727539063,,,,,,,,,,,,,,,,,,,,,,,,,,,,,,,,,
,3754667188.23664,49.0001277923584,120.104522705078,,,5,,,,-2.43999995291233,,,,,0.000679611329260874,4.41269991022333E-8,0.0150205473656646,4.34948062318818E-5,0.000679522637407962,4.41212403616925E-8,0.000679522614057247,3.27630012635687E-8,1.78142298281911E-7,2.95511353294191E-8,1.00013052082157,10.005763053894,2,20,10,5,2.22310073812412,0.195998899918277,0.0404026173055172,172.741912841797,48.9994354248047,49.0010452270508,120.104522705078,120.104522705078,,,43.2987327575684,0,1,,,,,,1,1,1,49.0002784729004,0,49.000154071384,,,,,,,,,,,,,,,,,,,,,,,,,,,,,,,,,
,3754667393.04314,48.99973487854,120.104522705078,,,5,,,,-2.43999995291233,,,,,0.000679137164385022,4.8223181066926E-8,0.0146578638973986,3.1299370862834E-5,0.000679048546621846,4.82168886260709E-8,0.000679048524400675,4.32858681479126E-8,1.73719620400052E-7,2.12415151874921E-8,1.00013050283903,10.005763053894,2,20,10,5,2.22155092013545,0.195848091260606,0.0404026173055172,172.741912841797,48.9991607666016,49.0001029968262,120.104522705078,120.104522705078,,,43.4355430603027,0,1,,,,,,1,1,1,48.9997138977051,0,48.9996575249566,,,,,,,,,,,,,,,,,,,,,,,,,,,,,,,,,
,3754667597.95307,49.0006446838379,120.104522705078,,,5,,,,-2.43999995291233,,,,,0.000679610211097166,5.18408002144392E-8,0.0120132953370842,5.73799810022715E-5,0.000679521581273084,5.18340395140726E-8,0.000679521566336465,3.41576229159181E-8,1.42476347356081E-7,3.89874909308151E-8,1.00013042974134,10.005763053894,2,20,10,5,2.22310736483329,0.195881892844244,0.0404026173055172,172.741912841797,48.9990653991699,49.0008659362793,120.104522705078,120.104522705078,,,43.584789276123,0,1,,,,,,1,1,1,49.0007438659668,0,49.0001369052463,,,,,,,,,,,,,,,,,,,,,,,,,,,,,,,,,
,3754667802.89276,49.0009288787842,120.104522705078,,,5,,,,-2.43999995291233,,,,,0.000679747147199576,6.24206248712254E-8,0.013139337301534,3.8482734520917E-5,0.000679658490678264,6.24124836153451E-8,0.000679658472806706,5.66755129773561E-8,1.55862476372465E-7,2.61381778207522E-8,1.00013044274813,10.005763053894,2,20,10,5,2.2235514525834,0.195965060942545,0.0404026173055172,172.741912841797,49.0001029968262,49.0011558532715,120.104522705078,120.104522705078,,,43.7215957641602,0,1,,,,,,1,1,1,49.0008354187012,0,49.0006391737196,,,,,,,,,,,,,,,,,,,,,,,,,,,,,,,,,
,3754668007.83833,48.9998550415039,120.104522705078,,,5,,,,-2.43999995291233,,,,,0.00067972994527198,3.38839333873976E-8,0.0123722053259323,3.33879592418719E-5,0.000679641246422101,3.3879511828598E-8,0.000679641230576865,2.51606837418131E-8,1.46758819843615E-7,2.26883519760376E-8,1.00013050833855,10.005763053894,2,20,10,5,2.22349780569425,0.195930335842815,0.0404026173055172,172.741912841797,48.999340057373,49.0003967285156,120.104522705078,120.104522705078,,,43.8584022521973,0,1,,,,,,1,1,1,48.9997291564941,0,48.9998830907485,,,,,,,,,,,,,,,,,,,,,,,,,,,,,,,,,
,3754668212.72164,49.0005626678467,120.104522705078,,,5,,,,-2.43999995291233,,,,,0.00067972636832878,6.57292742393618E-8,0.0135501755202432,4.44661808234664E-5,0.000679637725907096,6.57207025518187E-8,0.000679637706901038,5.83681701580537E-8,1.60731042820915E-7,3.0205420975466E-8,1.00013042598771,10.005763053894,2,20,10,5,2.22348207661424,0.195975015050844,0.0404026173055172,172.741912841797,48.9997367858887,49.0009994506836,120.104522705078,120.104522705078,,,44.0325241088867,0,1,,,,,,1,1,1,49.0005760192871,0,49.0002723269992,,,,,,,,,,,,,,,,,,,,,,,,,,,,,,,,,
,3754668417.72118,49.0000495910645,120.104522705078,,,5,,,,-2.43999995291233,,,,,0.000679700749671105,4.86839663529784E-8,0.00940162579580761,5.61966156120004E-5,0.000679612048580538,4.86776130851459E-8,0.000679612039431157,3.01843025621551E-8,1.11517081933487E-7,3.81892379408577E-8,1.00013051724252,10.005763053894,2,20,10,5,2.22341245755977,0.195806642810131,0.0404026173055172,172.741912841797,48.999439239502,49.0005950927734,120.104522705078,120.104522705078,,,44.1568946838379,0,1,,,,,,1,1,1,49.000186920166,0,48.9998848859002,,,,,,,,,,,,,,,,,,,,,,,,,,,,,,,,,
,3754668622.75985,49.0001811981201,120.104522705078,,,5,,,,-2.43999995291233,,,,,0.000679767035269346,5.23101955433534E-8,0.00917400138313962,5.40489286634162E-5,0.000679678399409131,5.23033747371957E-8,0.000679678390696571,3.72351096568083E-8,1.08827746172871E-7,3.67313165806098E-8,1.00013040852893,10.005763053894,2,20,10,5,2.22363006645497,0.195816905405088,0.0404026173055172,172.741912841797,48.9995765686035,49.0008506774902,120.104522705078,120.104522705078,,,44.3185768127441,0,1,,,,,,1,1,1,48.9998817443848,0,48.9999901266659,,,,,,,,,,,,,,,,,,,,,,,,,,,,,,,,,
,3754668828.77218,49.0010280609131,120.104522705078,,,5,,,,-2.43999995291233,,,,,0.000679834928631552,4.31366693345869E-8,0.015418622828987,3.35753012205637E-5,0.000679746257576125,4.31310430070236E-8,0.000679746232963228,3.6602974462505E-8,1.82923613703338E-7,2.28146692145848E-8,1.00013044728741,10.005763053894,2,20,10,5,2.2238307998944,0.196078834197478,0.0404026173055172,172.741912841797,49.0000686645508,49.001277923584,120.104522705078,120.104522705078,,,44.4429512023926,0,1,,,,,,1,1,1,49.0007858276367,0,49.000628751867,,,,,,,,,,,,,,,,,,,,,,,,,,,,,,,,,
,3754669035.30183,49.0001430511475,120.104522705078,,,5,,,,-2.43999995291233,,,,,0.000679692963315481,3.49922167488237E-8,0.0124537094041051,2.69293074229942E-5,0.000679604260334476,3.49876501075531E-8,0.00067960424428066,2.98234285935415E-8,1.47717580130342E-7,1.82947743078316E-8,1.00013052151992,10.005763053894,2,20,10,5,2.22337655370175,0.195922836549422,0.0404026173055172,172.741912841797,48.9993934631348,49.0007629394531,120.104522705078,120.104522705078,,,44.6046333312988,0,1,,,,,,1,1,1,49.0002632141113,0,48.9999542236328,,,,,,,,,,,,,,,,,,,,,,,,,,,,,,,,,
,3754669240.33906,48.9995193481445,120.104522705078,,,5,,,,-2.43999995291233,,,,,0.000680276357082432,2.61483964424667E-8,0.0138212025970352,2.87461078204733E-5,0.00068018759737941,2.61449847056356E-8,0.000680187577589441,1.73585647578494E-8,1.64078586173196E-7,1.95509706870393E-8,1.00013049297483,10.005763053894,2,20,10,5,2.22528024017142,0.196144116046636,0.0404026173055172,172.741912841797,48.9986724853516,48.9999847412109,120.104522705078,120.104522705078,,,44.7538757324219,0,1,,,,,,1,1,1,48.9993362426758,0,48.9995559243595,,,,,,,,,,,,,,,,,,,,,,,,,,,,,,,,,
,3754669445.2881,49.0004558563232,120.104522705078,,,5,,,,-2.43999995291233,,,,,0.000679627511279652,3.28607176348686E-8,0.0119964020044332,2.4051280513449E-5,0.00067953880711329,3.28564286934773E-8,0.000679538792218272,2.85069079372054E-8,1.42279601001335E-7,1.63371082615393E-8,1.00013053583612,10.005763053894,2,20,10,5,2.22316401407697,0.195886223900986,0.0404026173055172,172.741912841797,49.0001220703125,49.0007781982422,120.104522705078,120.104522705078,,,44.9031219482422,0,1,,,,,,1,1,1,49.0007019042969,0,49.0003164079454,,,,,,,,,,,,,,,,,,,,,,,,,,,,,,,,,
,3754669650.30897,48.9995384216309,120.104522705078,,,5,,,,-2.43999995291233,,,,,0.000679676233919777,3.93832801259073E-8,0.0111874379071031,4.91577481161452E-5,0.000679587551925233,3.93781415207025E-8,0.000679587538970411,2.08492462527421E-8,1.32694651436889E-7,3.34057923168571E-8,1.00013049384777,10.005763053894,2,20,10,5,2.22332615841918,0.195868880910836,0.0404026173055172,172.741912841797,48.9990730285645,48.9998626708984,120.104522705078,120.104522705078,,,45.0150566101074,0,1,,,,,,1,1,1,48.999397277832,0,48.9995256311753,,,,,,,,,,,,,,,,,,,,,,,,,,,,,,,,,
,3754669855.05649,49.0006561279297,120.104522705078,,,5,,,,-2.43999995291233,,,,,0.000679592368714149,3.58357048023693E-8,0.0151407484255746,4.41046563137586E-5,0.000679503662907132,3.58310272408473E-8,0.000679503639181859,1.964112155849E-8,1.79562857544241E-7,2.99681306901008E-8,1.00013054500198,10.005763053894,2,20,10,5,2.22303830449766,0.195998094655996,0.0404026173055172,172.741912841797,48.999454498291,49.0007591247559,120.104522705078,120.104522705078,,,45.1767387390137,0,1,,,,,,1,1,1,49.0004768371582,0,49.0001523634967,,,,,,,,,,,,,,,,,,,,,,,,,,,,,,,,,
,3754670060.30179,48.9995460510254,120.104522705078,,,5,,,,-2.43999995291233,,,,,0.000679527488736868,3.61488726616269E-8,0.0124095295529045,4.21992894689037E-5,0.000679438825912911,3.61441560590079E-8,0.000679438809976675,2.20097601148309E-8,1.47157717292448E-7,2.8670027500955E-8,1.00013049419694,10.005763053894,2,20,10,5,2.22283541260608,0.195873426707401,0.0404026173055172,172.741912841797,48.9988899230957,49.0006790161133,120.104522705078,120.104522705078,,,45.3135452270508,0,1,,,,,,1,1,1,48.9996299743652,0,48.9998869895935,,,,,,,,,,,,,,,,,,,,,,,,,,,,,,,,,
,3754670265.17808,48.9995307922363,120.104522705078,,,5,,,,-2.43999995291233,,,,,0.000679942238643976,3.56706908466285E-8,0.0144445882473905,3.85847735851818E-5,0.000679853522179339,3.56660366607238E-8,0.00067985350057453,2.41678599646837E-8,1.71394894630106E-7,2.62293864932356E-8,1.00013049349859,10.005763053894,2,20,10,5,2.22418515832393,0.196071979009247,0.0404026173055172,172.741912841797,48.9991760253906,49.0001411437988,120.104522705078,120.104522705078,,,45.4503517150879,0,1,,,,,,1,1,1,48.9993591308594,0,48.999477174547,,,,,,,,,,,,,,,,,,,,,,,,,,,,,,,,,
,3754670470.20113,48.9999160766602,120.104522705078,,,5,,,,-2.43999995291233,,,,,0.000679692976703922,4.15035513017162E-8,0.0124916359818048,4.8371394086982E-5,0.000679604280779957,4.14981353331E-8,0.000679604264628211,2.53292701270155E-8,1.48167444305164E-7,3.28713144087205E-8,1.00013051113195,10.005763053894,2,20,10,5,2.22337646771939,0.195924313131957,0.0404026173055172,172.741912841797,48.9995536804199,49.0000610351562,120.104522705078,120.104522705078,,,45.5871620178223,0,1,,,,,,1,1,1,49.0000190734863,0,48.9998177422418,,,,,,,,,,,,,,,,,,,,,,,,,,,,,,,,,
,3754670675.08774,49.0003967285156,120.104522705078,,,5,,,,-2.43999995291233,,,,,0.000679718486366832,3.89955487276945E-8,0.01178255715259,4.18004949440821E-5,0.000679629850133847,3.89904636540769E-8,0.000679629835763201,2.67088326112159E-8,1.39762083061264E-7,2.84058887645845E-8,1.00013041839314,10.005763053894,2,20,10,5,2.22346233841586,0.195904147429424,0.0404026173055172,172.741912841797,48.9997138977051,49.0007629394531,120.104522705078,120.104522705078,,,45.7488441467285,0,1,,,,,,1,1,1,49.0005073547363,0,49.0002085367839,,,,,,,,,,,,,,,,,,,,,,,,,,,,,,,,,
,3754670880.21053,49.0004940032959,120.104522705078,,,5,,,,-2.43999995291233,,,,,0.000679766937097407,5.62625344897065E-8,0.015536542915366,6.09986033738522E-5,0.000679678291520856,5.62551975267919E-8,0.000679678266532544,3.80276291929316E-8,1.84304165248937E-7,4.14553575155645E-8,1.00013042284513,10.005763053894,2,20,10,5,2.22360798670982,0.196063803582841,0.0404026173055172,172.741912841797,48.9997291564941,49.0010833740234,120.104522705078,120.104522705078,,,45.8856544494629,0,1,,,,,,1,1,1,48.9999847412109,0,49.0001438365263,,,,,,,,,,,,,,,,,,,,,,,,,,,,,,,,,
,3754671085.01621,48.9999046325684,120.104522705078,,,5,,,,-2.43999995291233,,,,,0.000679529896940473,3.09404495978969E-8,0.0134612384593753,3.15087499736552E-5,0.000679441222653276,3.09364120679427E-8,0.000679441203901316,2.2335332423076E-8,1.5962991185128E-7,2.14054786722521E-8,1.00013051060819,10.005763053894,2,20,10,5,2.22283969443756,0.195914922456744,0.0404026173055172,172.741912841797,48.9992141723633,49.0005340576172,120.104522705078,120.104522705078,,,46.0224609375,0,1,,,,,,1,1,1,48.9997329711914,0,48.9998422510484,,,,,,,,,,,,,,,,,,,,,,,,,,,,,,,,,
,3754671290.88318,49.0000820159912,120.104522705078,,,5,,,,-2.43999995291233,,,,,0.00067968081189078,3.6631887409034E-8,0.0135281862603422,4.24269397519505E-5,0.000679592112393717,3.66271068856872E-8,0.000679592093450567,2.25900841888165E-8,1.60459438203477E-7,2.88311126243463E-8,1.00013051872652,10.005763053894,2,20,10,5,2.22333313004159,0.19596102897865,0.0404026173055172,172.741912841797,48.9995994567871,49.0001754760742,120.104522705078,120.104522705078,,,46.1343955993652,0,1,,,,,,1,1,1,49.0001258850098,0,48.9998833151425,,,,,,,,,,,,,,,,,,,,,,,,,,,,,,,,,
,3754671494.91755,49.0010108947754,120.104522705078,,,5,,,,-2.43999995291233,,,,,0.000679634421053784,3.60402998768297E-8,0.013551742479283,2.65980416216089E-5,0.000679545776684427,3.60355991589804E-8,0.000679545757676545,3.11791215042201E-8,1.60727881894787E-7,1.8067285047062E-8,1.00013044650176,10.005763053894,2,20,10,5,2.22318129865166,0.195948565322044,0.0404026173055172,172.741912841797,48.9995918273926,49.0014724731445,120.104522705078,120.104522705078,,,46.2836418151855,0,1,,,,,,1,1,1,49.0007743835449,0,49.0004384782579,,,,,,,,,,,,,,,,,,,,,,,,,,,,,,,,,
,3754671699.87855,48.9997386932373,120.104522705078,,,5,,,,-2.43999995291233,,,,,0.000679509177738941,4.62990764648084E-8,0.0128730494964824,2.92722468194611E-5,0.000679420511314698,4.62930350842202E-8,0.000679420494166193,4.18089206515245E-8,1.52650227849644E-7,1.98760974857583E-8,1.00013050301362,10.005763053894,2,20,10,5,2.22277392998106,0.195886130630755,0.0404026173055172,172.741912841797,48.9993133544922,49.0002288818359,120.104522705078,120.104522705078,,,46.4328880310059,0,1,,,,,,1,1,1,48.9996490478516,0,48.9998423258463,,,,,,,,,,,,,,,,,,,,,,,,,,,,,,,,,
,3754671904.72123,49.0005798339844,120.104522705078,,,5,,,,-2.43999995291233,,,,,0.000679683963115734,4.210440357997E-8,0.014601611456464,4.6291749553144E-5,0.00067959532569022,4.20989127546178E-8,0.000679595303621523,2.79783591878387E-8,1.73192281705131E-7,3.14567937380338E-8,1.00013042677335,10.005763053894,2,20,10,5,2.22333976662557,0.196003589441257,0.0404026173055172,172.741912841797,48.999382019043,49.000675201416,120.104522705078,120.104522705078,,,46.5572547912598,0,1,,,,,,1,1,1,49.0006141662598,0,49.0000552009134,,,,,,,,,,,,,,,,,,,,,,,,,,,,,,,,,
,3754672109.71844,49.0005302429199,120.104522705078,,,5,,,,-2.43999995291233,,,,,0.000679669268576674,3.94822100026963E-8,0.0135647572790019,3.94413869125316E-5,0.000679580634609673,3.94770612265778E-8,0.000679580615564287,2.89864488428321E-8,1.60890494068068E-7,2.67997042253987E-8,1.00013042450371,10.005763053894,2,20,10,5,2.22329524530836,0.195959118036329,0.0404026173055172,172.741912841797,48.9998054504395,49.0006141662598,120.104522705078,120.104522705078,,,46.7065010070801,0,1,,,,,,1,1,1,49.0006141662598,0,49.000273598565,,,,,,,,,,,,,,,,,,,,,,,,,,,,,,,,,
,3754672314.78304,49.0002822875977,120.104522705078,,,5,,,,-2.43999995291233,,,,,0.000680135398461631,3.92616534339813E-8,0.0139219894919833,5.2435313091764E-5,0.000680046633407855,3.92565293619417E-8,0.00068004661333237,1.64185786329689E-8,1.65240827014798E-7,3.56581740028567E-8,1.00013052789238,10.005763053894,2,20,10,5,2.224818799835,0.196107384556957,0.0404026173055172,172.741912841797,48.9993209838867,49.0005722045898,120.104522705078,120.104522705078,,,46.8184356689453,0,1,,,,,,1,1,1,48.9999580383301,0,48.9999277451459,,,,,,,,,,,,,,,,,,,,,,,,,,,,,,,,,
,3754672518.87011,48.9996891021729,120.104522705078,,,5,,,,-2.43999995291233,,,,,0.00067959298383702,3.17349307515016E-8,0.0144374556516782,3.4839674713661E-5,0.000679504308019285,3.17307898598178E-8,0.000679504286446894,2.11305821524107E-8,1.7122226613735E-7,2.36715340235511E-8,1.00013050074398,10.005763053894,2,20,10,5,2.22304272213675,0.195970986704072,0.0404026173055172,172.741912841797,48.9993476867676,49.0003280639648,120.104522705078,120.104522705078,,,46.9552421569824,0,1,,,,,,1,1,1,48.9999809265137,0,48.9998611874051,,,,,,,,,,,,,,,,,,,,,,,,,,,,,,,,,
,3754672722.29166,48.9997291564941,120.104522705078,,,5,,,,-2.43999995291233,,,,,0.00067971227996133,2.88085216716871E-8,0.0142782190424962,2.94426641356241E-5,0.00067962358733169,2.88047625759367E-8,0.000679623566228833,2.07225132996328E-8,1.6936351033877E-7,2.00072934102198E-8,1.00013050257715,10.005763053894,2,20,10,5,2.22343350091816,0.195999209128695,0.0404026173055172,172.741912841797,48.9992370605469,49.0001945495605,120.104522705078,120.104522705078,,,47.1169242858887,0,1,,,,,,1,1,1,48.9997444152832,0,48.9996889899759,,,,,,,,,,,,,,,,,,,,,,,,,,,,,,,,,
,3754672927.16169,49.0006999969482,120.104522705078,,,5,,,,-2.43999995291233,,,,,0.000679314006075377,4.43632776758212E-8,0.0145690619945631,3.91627678882387E-5,0.000679225335238925,4.43574869385421E-8,0.000679225313280469,3.55012678046385E-8,1.72712126352628E-7,2.65941089673309E-8,1.00013054700973,10.005763053894,2,20,10,5,2.22212969778058,0.195895638050721,0.0404026173055172,172.741912841797,48.9997253417969,49.0016098022461,120.104522705078,120.104522705078,,,47.253734588623,0,1,,,,,,1,1,1,49.0013160705566,0,49.0007339053684,,,,,,,,,,,,,,,,,,,,,,,,,,,,,,,,,
,3754673132.91552,49.0002765655518,120.104522705078,,,5,,,,-2.43999995291233,,,,,0.000679541516985936,5.35452241805949E-8,0.00930225360860604,4.25738313989671E-5,0.000679452907566177,5.35382421035225E-8,0.000679452898611283,4.50566750267847E-8,1.10312544610294E-7,2.89178042573447E-8,1.00013041289363,10.005763053894,2,20,10,5,2.22289192087342,0.195756916282678,0.0404026173055172,172.741912841797,48.9997901916504,49.0005874633789,120.104522705078,120.104522705078,,,47.4029808044434,0,1,,,,,,1,1,1,49.0001411437988,0,49.0001519147088,,,,,,,,,,,,,,,,,,,,,,,,,,,,,,,,,
,3754673337.00359,49.0006332397461,120.104522705078,,,5,,,,-2.43999995291233,,,,,0.00068024031064223,3.82381984823375E-8,0.011864159620278,3.17773437162644E-5,0.000680151599001337,3.82332117544428E-8,0.000680151584419762,3.15420371537372E-8,1.40838071275924E-7,2.16073684943892E-8,1.00013042921758,10.005763053894,2,20,10,5,2.225169025676,0.196057712568245,0.0404026173055172,172.741912841797,49.0001602172852,49.0011329650879,120.104522705078,120.104522705078,,,47.5522270202637,0,1,,,,,,1,1,1,49.000732421875,0,49.0005253062529,,,,,,,,,,,,,,,,,,,,,,,,,,,,,,,,,
,3754673541.97864,49.0001945495605,120.104522705078,,,5,,,,-2.43999995291233,,,,,0.000679564121703923,4.76336624356384E-8,0.0123194797065045,5.20021904540691E-5,0.000679475511886773,4.76274513806639E-8,0.000679475496180133,3.19390859835523E-8,1.46097754256844E-7,3.53308492900009E-8,1.00013040913999,10.005763053894,2,20,10,5,2.22295555248021,0.195880490921073,0.0404026173055172,172.741912841797,48.9992179870605,49.000675201416,120.104522705078,120.104522705078,,,47.6641578674316,0,1,,,,,,1,1,1,49,0,48.9999131096734,,,,,,,,,,,,,,,,,,,,,,,,,,,,,,,,,
,3754673746.90894,49.000171661377,120.104522705078,,,5,,,,-2.43999995291233,,,,,0.000679078375906089,3.81505860788464E-8,0.0116904992979459,2.80921599506939E-5,0.000678989830137539,3.81456115824041E-8,0.000678989816003895,3.30386283242194E-8,1.38539524986241E-7,1.9066638965736E-8,1.00013040809246,10.005763053894,2,20,10,5,2.22136875430232,0.195716090879,0.0404026173055172,172.741912841797,48.9988098144531,49.0005111694336,120.104522705078,120.104522705078,,,47.800968170166,0,1,,,,,,1,1,1,49.0002250671387,0,48.9994886186388,,,,,,,,,,,,,,,,,,,,,,,,,,,,,,,,,
,3754673950.71795,49.0003623962402,120.104522705078,,,5,,,,-2.43999995291233,,,,,0.000679527049169062,3.27626613239235E-8,0.0159133282035455,3.04260790199661E-5,0.000679438361020745,3.27583853208265E-8,0.00067943833481498,2.54149870921029E-8,1.88707189009034E-7,2.066858098506E-8,1.00013053155872,10.005763053894,2,20,10,5,2.22282199275945,0.196009227692428,0.0404026173055172,172.741912841797,48.9999008178711,49.0011291503906,120.104522705078,120.104522705078,,,47.9377746582031,0,1,,,,,,1,1,1,49.0007629394531,0,49.000348259421,,,,,,,,,,,,,,,,,,,,,,,,,,,,,,,,,
,3754674156.89947,49.0000591278076,120.104522705078,,,5,,,,-2.43999995291233,,,,,0.000679538672308125,4.34351321807643E-8,0.0140499727559718,2.93063177384946E-5,0.000679450070019967,4.34294688502512E-8,0.000679450049591618,3.8600968430744E-8,1.66613578840853E-7,1.99018592303244E-8,1.00013040294213,10.005763053894,2,20,10,5,2.22286638665477,0.195940293557764,0.0404026173055172,172.741912841797,48.9994697570801,49.0007629394531,120.104522705078,120.104522705078,,,48.0497093200684,0,1,,,,,,1,1,1,48.9996490478516,0,48.9999716016981,,,,,,,,,,,,,,,,,,,,,,,,,,,,,,,,,
,3754674361.85189,49.0005493164063,120.104522705078,,,5,,,,-2.43999995291233,,,,,0.000679069914547634,4.10529643322518E-8,0.0134895890439859,3.99855212652006E-5,0.00067898135814826,4.1047610682168E-8,0.000678981339329976,3.07904872422386E-8,1.59857837403873E-7,2.71450223448126E-8,1.00013042537665,10.005763053894,2,20,10,5,2.22133492955906,0.195783400568064,0.0404026173055172,172.741912841797,48.9993667602539,49.0007286071777,120.104522705078,120.104522705078,,,48.1740798950195,0,1,,,,,,1,1,1,49.0006713867188,0,49.0001198263729,,,,,,,,,,,,,,,,,,,,,,,,,,,,,,,,,
,3754674566.79605,49.0007190704346,120.104522705078,,,5,,,,-2.43999995291233,,,,,0.000679517890501965,3.51461524928166E-8,0.0133899109569358,3.03679381603219E-5,0.000679429270404875,3.51415688674408E-8,0.000679429251851438,2.8450438892634E-8,1.58781282439316E-7,2.06277092591878E-8,1.0001304331458,10.005763053894,2,20,10,5,2.22280066393728,0.195908689359158,0.0404026173055172,172.741912841797,48.9994850158691,49.000919342041,120.104522705078,120.104522705078,,,48.3233261108398,0,1,,,,,,1,1,1,49.0008277893066,0,49.00033232745,,,,,,,,,,,,,,,,,,,,,,,,,,,,,,,,,
,3754674771.79241,49.0008735656738,120.104522705078,,,5,,,,-2.43999995291233,,,,,0.000679747073228401,2.60983400518721E-8,0.0116807708490834,2.51340671952466E-5,0.000679658418437082,2.60949362227389E-8,0.000679658404313058,1.9728888447775E-8,1.3856054065218E-7,1.70797147834518E-8,1.00013044021661,10.005763053894,2,20,10,5,2.22355619845066,0.195908435996872,0.0404026173055172,172.741912841797,48.9998474121094,49.0012855529785,120.104522705078,120.104522705078,,,48.460132598877,0,1,,,,,,1,1,1,49.0006065368652,0,49.0003177418428,,,,,,,,,,,,,,,,,,,,,,,,,,,,,,,,,
,3754674976.70983,49.0008182525635,120.104522705078,,,5,,,,-2.43999995291233,,,,,0.000679009019157669,3.11919302281803E-8,0.0134669822453883,3.45685587275664E-5,0.000678920462344205,3.1187862155638E-8,0.000678920443590623,2.05419390018121E-8,1.59575623299582E-7,2.34672428692615E-8,1.00013043768508,10.005763053894,2,20,10,5,2.22113580924126,0.195764967585154,0.0404026173055172,172.741912841797,48.9998016357422,49.0012397766113,120.104522705078,120.104522705078,,,48.5845069885254,0,1,,,,,,1,1,1,49.000617980957,0,49.0003509521484,,,,,,,,,,,,,,,,,,,,,,,,,,,,,,,,,
,3754675181.63476,49.0013313293457,120.104522705078,,,5,,,,-2.43999995291233,,,,,0.000679541011049248,4.01123407585719E-8,0.0136676613210707,5.02196606001389E-5,0.00067945236890019,4.01071083384078E-8,0.000679452349568396,2.10797101135586E-8,1.62080433371765E-7,3.41207555718966E-8,1.00013046116713,10.005763053894,2,20,10,5,2.22287534506331,0.195926128098563,0.0404026173055172,172.741912841797,49.0000038146973,49.0015258789063,120.104522705078,120.104522705078,,,48.7213134765625,0,1,,,,,,1,1,1,49.0015258789063,0,49.0005726533778,,,,,,,,,,,,,,,,,,,,,,,,,,,,,,,,,
,3754675386.62111,49.0002269744873,120.104522705078,,,5,,,,-2.43999995291233,,,,,0.000679605581504902,5.50992175967571E-8,0.0131713737991417,2.33048188743899E-5,0.000679516887317979,5.50920266900932E-8,0.000679516869362907,5.27743768589794E-8,1.56209949893775E-7,1.58112792641315E-8,1.00013052536085,10.005763053894,2,20,10,5,2.22308826101173,0.195925493095896,0.0404026173055172,172.741912841797,48.9992942810059,49.0006866455078,120.104522705078,120.104522705078,,,48.8705558776855,0,1,,,,,,1,1,1,49.0005187988281,0,49.0000042634852,,,,,,,,,,,,,,,,,,,,,,,,,,,,,,,,,
,3754675591.64859,49.000638961792,120.104522705078,,,5,,,,-2.43999995291233,,,,,0.000679509570234078,4.02441652383282E-8,0.0136652952177645,3.88745432254242E-5,0.00067942095371275,4.02389168973432E-8,0.000679420934388542,3.03611684662303E-8,1.62044881848169E-7,2.6407761783924E-8,1.00013042947946,10.005763053894,2,20,10,5,2.22277250548352,0.195916974473434,0.0404026173055172,172.741912841797,48.9997444152832,49.0010223388672,120.104522705078,120.104522705078,,,49.0073661804199,0,1,,,,,,1,1,1,49.0007171630859,0,49.0003049513873,,,,,,,,,,,,,,,,,,,,,,,,,,,,,,,,,
,3754675796.67109,49.0016136169434,120.104522705078,,,5,,,,-2.43999995291233,,,,,0.000679570268776904,6.98726243479763E-8,0.0124647397000128,3.232653425468E-5,0.000679481614033934,6.9863508970455E-8,0.00067948159795457,6.63299329176592E-8,1.47821732334322E-7,2.19374083429121E-8,1.00013047408663,10.005763053894,2,20,10,5,2.22297516444811,0.195887891982935,0.0404026173055172,172.741912841797,49.0004348754883,49.0017433166504,120.104522705078,120.104522705078,,,49.1317367553711,0,1,,,,,,1,1,1,49.0016632080078,0,49.0011134428136,,,,,,,,,,,,,,,,,,,,,,,,,,,,,,,,,
,3754676001.58725,49.0006141662598,120.104522705078,,,5,,,,-2.43999995291233,,,,,0.000679559787151536,4.51229145915367E-8,0.0130899133749107,2.64383891171758E-5,0.000679471164852273,4.51170300519919E-8,0.0006794711471198,4.13921579173664E-8,1.55233399159234E-7,1.79509237549533E-8,1.00013042834464,10.005763053894,2,20,10,5,2.22293873967927,0.19590912941955,0.0404026173055172,172.741912841797,49.0000228881836,49.0009002685547,120.104522705078,120.104522705078,,,49.2685432434082,0,1,,,,,,1,1,1,49.0007743835449,0,49.000446768368,,,,,,,,,,,,,,,,,,,,,,,,,,,,,,,,,
,3754676206.57223,49.0001487731934,120.104522705078,,,5,,,,-2.43999995291233,,,,,0.000678953184179859,5.67268904689261E-8,0.0139477582720593,3.20367194324659E-5,0.000678864655446229,5.67194938473431E-8,0.000678864635331381,5.23914819078947E-8,1.65258944036669E-7,2.17309366064497E-8,1.00013040704494,10.005763053894,2,20,10,5,2.22095152222089,0.195767508045152,0.0404026173055172,172.741912841797,48.9990539550781,49.0002975463867,120.104522705078,120.104522705078,,,49.3929176330566,0,1,,,,,,1,1,1,49.000129699707,0,48.9997228734633,,,,,,,,,,,,,,,,,,,,,,,,,,,,,,,,,
,3754676411.49309,49.0000419616699,120.104522705078,,,5,,,,-2.43999995291233,,,,,0.000679475463171059,4.63001924498624E-8,0.00850741717000591,4.62786932576064E-5,0.00067938686965817,4.62941555921407E-8,0.000679386862168937,3.39836316948805E-8,1.00877020050818E-7,3.14366286172046E-8,1.00013040215648,10.005763053894,2,20,10,5,2.22267856308802,0.195707054682195,0.0404026173055172,172.741912841797,48.999267578125,49.0002136230469,120.104522705078,120.104522705078,,,49.5297241210937,0,1,,,,,,1,1,1,48.9999465942383,0,48.9997322559357,,,,,,,,,,,,,,,,,,,,,,,,,,,,,,,,,
,3754676614.90836,49.0000152587891,120.104522705078,,,5,,,,-2.43999995291233,,,,,0.000679565641746219,4.73239332327854E-8,0.013290157703814,3.10318811933483E-5,0.000679477037305673,4.73177629522843E-8,0.000679477019026364,4.23658762348259E-8,1.57609460551497E-7,2.10737567050582E-8,1.00013040093437,10.005763053894,2,20,10,5,2.22295720574487,0.195918591374235,0.0404026173055172,172.741912841797,48.9994201660156,49.0010681152344,120.104522705078,120.104522705078,,,49.6665306091309,0,1,,,,,,1,1,1,48.9995002746582,0,48.9999290915097,,,,,,,,,,,,,,,,,,,,,,,,,,,,,,,,,
,3754676818.99163,49.0005569458008,120.104522705078,,,5,,,,-2.43999995291233,,,,,0.000679535181127484,4.39402029590683E-8,0.0139663404066201,3.34773877404737E-5,0.000679446563816239,4.3934472773568E-8,0.000679446543630471,3.75930320610531E-8,1.65620958210813E-7,2.27376744269951E-8,1.00013042572582,10.005763053894,2,20,10,5,2.22285525284629,0.195936038608066,0.0404026173055172,172.741912841797,48.9999847412109,49.0014343261719,120.104522705078,120.104522705078,,,49.8033409118652,0,1,,,,,,1,1,1,49.0005722045898,0,49.0006359948052,,,,,,,,,,,,,,,,,,,,,,,,,,,,,,,,,
,3754677023.92549,49.0004119873047,120.104522705078,,,5,,,,-2.43999995291233,,,,,0.000679961195630316,3.3368497627112E-8,0.0142402054546702,2.5146775042811E-5,0.000679872527272979,3.33641463054625E-8,0.00067987250627465,2.86547709169884E-8,1.68974476897884E-7,1.70900661902527E-8,1.00013041909149,10.005763053894,2,20,10,5,2.22424786904749,0.196069507168822,0.0404026173055172,172.741912841797,48.9999237060547,49.00048828125,120.104522705078,120.104522705078,,,49.9401512145996,0,1,,,,,,1,1,1,49.0004005432129,0,49.0002293056912,,,,,,,,,,,,,,,,,,,,,,,,,,,,,,,,,
,3754677229.96581,48.999927520752,120.104522705078,,,5,,,,-2.43999995291233,,,,,0.000679447438590751,3.84183865335645E-8,0.0128114521514355,4.33619633687195E-5,0.00067935885228962,3.84133775474897E-8,0.000679358835306374,2.46562486801558E-8,1.51906011772624E-7,2.94560176471345E-8,1.00013039691885,10.005763053894,2,20,10,5,2.22257218282063,0.195865942693378,0.0404026173055172,172.741912841797,48.998893737793,49.0002861022949,120.104522705078,120.104522705078,,,50.0769577026367,0,1,,,,,,1,1,1,48.9997978210449,0,48.9996344622444,,,,,,,,,,,,,,,,,,,,,,,,,,,,,,,,,
,3754677434.03168,49.0010509490967,120.104522705078,,,5,,,,-2.43999995291233,,,,,0.000678987530381136,2.54407224001721E-8,0.012546831178069,2.79320110606037E-5,0.000678898969141022,2.54374041331578E-8,0.000678898952863136,1.69567785747073E-8,1.48667681233902E-7,1.89612549532446E-8,1.00013044833494,10.005763053894,2,20,10,5,2.22106866002253,0.195723101288784,0.0404026173055172,172.741912841797,48.9998512268066,49.0015716552734,120.104522705078,120.104522705078,,,50.176456451416,0,1,,,,,,1,1,1,49.0009384155273,0,49.0006472269694,,,,,,,,,,,,,,,,,,,,,,,,,,,,,,,,,
,3754677637.96521,48.9994373321533,120.104522705078,,,5,,,,-2.43999995291233,,,,,0.000679467841848877,3.86178844027878E-8,0.0112486816388664,3.30994462014285E-5,0.000679379190187457,3.86128458426058E-8,0.000679379177094425,3.13933009310716E-8,1.33380158858848E-7,2.24813816460649E-8,1.00013048922119,10.005763053894,2,20,10,5,2.22264426640175,0.195811202314879,0.0404026173055172,172.741912841797,48.9988212585449,48.9999656677246,120.104522705078,120.104522705078,,,50.3132629394531,0,1,,,,,,1,1,1,48.9994049072266,0,48.9993160472197,,,,,,,,,,,,,,,,,,,,,,,,,,,,,,,,,
,3754677843.96747,48.9997520446777,120.104522705078,,,5,,,,-2.43999995291233,,,,,0.00067947949094241,4.29949359333354E-8,0.0132661113823458,4.52966965718328E-5,0.000679390827976785,4.29893256705129E-8,0.000679390809765873,3.0020819227742E-8,1.57304331874862E-7,3.07706440377945E-8,1.00013050362468,10.005763053894,2,20,10,5,2.22267547637997,0.195892819923329,0.0404026173055172,172.741912841797,48.9995231628418,49.0000610351562,120.104522705078,120.104522705078,,,50.4376335144043,0,1,,,,,,1,1,1,48.9998435974121,0,48.9998639424642,,,,,,,,,,,,,,,,,,,,,,,,,,,,,,,,,
,3754678048.81003,49.0008239746094,120.104522705078,,,5,,,,-2.43999995291233,,,,,0.000679143096669837,3.20536989511962E-8,0.0159119197178219,3.3316517825893E-5,0.000679054522192084,3.20495184778047E-8,0.00067905449600576,2.27038262539113E-8,1.8858388862282E-7,2.26209616968721E-8,1.00013043794697,10.005763053894,2,20,10,5,2.22156603861861,0.195898422574526,0.0404026173055172,172.741912841797,48.9993705749512,49.0009841918945,120.104522705078,120.104522705078,,,50.5620040893555,0,1,,,,,,1,1,1,49.0006637573242,0,49.0000702353085,,,,,,,,,,,,,,,,,,,,,,,,,,,,,,,,,
,3754678253.77481,49.0004291534424,120.104522705078,,,5,,,,-2.43999995291233,,,,,0.000679427504031058,3.53899609495037E-8,0.010829034882625,3.43838374248457E-5,0.000679338904734569,3.53853459970263E-8,0.00067933889260094,2.6583644122864E-8,1.28396623891236E-7,2.3354497992425E-8,1.00013041987714,10.005763053894,2,20,10,5,2.22251374948321,0.195783296181572,0.0404026173055172,172.741912841797,48.9996032714844,49.0007133483887,120.104522705078,120.104522705078,,,50.7236862182617,0,1,,,,,,1,1,1,49.0002288818359,0,49.0000015707577,,,,,,,,,,,,,,,,,,,,,,,,,,,,,,,,,
,3754678458.66636,49.0009098052978,120.104522705078,,,5,,,,-2.43999995291233,,,,,0.000679415865250826,4.4635544524525E-8,0.0185896480837489,3.82902493310201E-5,0.000679327252530139,4.46297229397756E-8,0.000679327216774371,3.62707382204167E-8,2.20408107612698E-7,2.60047249288881E-8,1.00013044187519,10.005763053894,2,20,10,5,2.22244913896166,0.196080968911549,0.0404026173055172,172.741912841797,48.9995422363281,49.0012741088867,120.104522705078,120.104522705078,,,50.8480567932129,0,1,,,,,,1,1,1,49.0007553100586,0,49.0003350201775,,,,,,,,,,,,,,,,,,,,,,,,,,,,,,,,,
,3754678663.78327,49.0006713867188,120.104522705078,,,5,,,,-2.43999995291233,,,,,0.000679439410901447,4.81872402262776E-8,0.0153712871453626,5.02383121159334E-5,0.000679350802521749,4.81809559377743E-8,0.000679350778073977,3.40127385591582E-8,1.82255939642909E-7,3.41253297534852E-8,1.00013043096346,10.005763053894,2,20,10,5,2.22253717054518,0.195962921817154,0.0404026173055172,172.741912841797,49.0002021789551,49.0010108947754,120.104522705078,120.104522705078,,,50.9599914550781,0,1,,,,,,1,1,1,49.0009078979492,0,49.000607883229,,,,,,,,,,,,,,,,,,,,,,,,,,,,,,,,,
,3754678868.71415,49.0002307891846,120.104522705078,,,5,,,,-2.43999995291233,,,,,0.000679452613919684,6.46640013653428E-8,0.0121316669539162,6.86537984282926E-5,0.000679363939577711,6.46555621634721E-8,0.000679363924348823,4.47822010886059E-8,1.43846842889911E-7,4.66357822313968E-8,1.00013052553544,10.005763053894,2,20,10,5,2.22259143603588,0.195841061976753,0.0404026173055172,172.741912841797,48.9995155334473,49.0007781982422,120.104522705078,120.104522705078,,,51.0843620300293,0,1,,,,,,1,1,1,49.0004806518555,0,49.000098957735,,,,,,,,,,,,,,,,,,,,,,,,,,,,,,,,,
,3754679073.6489,48.9999847412109,120.104522705078,,,5,,,,-2.43999995291233,,,,,0.000679412723989065,3.07196693672198E-8,0.0123856002015712,3.1120550837372E-5,0.000679324062501875,3.07156605350683E-8,0.000679324046629722,2.22853033617394E-8,1.46849144063143E-7,2.11380475962375E-8,1.00013051427453,10.005763053894,2,20,10,5,2.22246008196809,0.19583941632281,0.0404026173055172,172.741912841797,48.9987602233887,49.0000648498535,120.104522705078,120.104522705078,,,51.2336082458496,0,1,,,,,,1,1,1,48.9999580383301,0,48.9995334849638,,,,,,,,,,,,,,,,,,,,,,,,,,,,,,,,,
,3754679278.68141,49.0010929107666,120.104522705078,,,5,,,,-2.43999995291233,,,,,0.00067944317367672,5.04917414624653E-8,0.010139228566648,4.5593536475822E-5,0.000679354551701943,5.04851556610154E-8,0.000679354541064652,3.98717509574345E-8,1.20220565983828E-7,3.09676350034237E-8,1.0001304502554,10.005763053894,2,20,10,5,2.22256736472044,0.195761049100884,0.0404026173055172,172.741912841797,48.9999504089355,49.0012550354004,120.104522705078,120.104522705078,,,51.3455429077148,0,1,,,,,,1,1,1,49.0012550354004,0,49.0005854438333,,,,,,,,,,,,,,,,,,,,,,,,,,,,,,,,,
,3754679484.12589,49.0000514984131,120.104522705078,,,5,,,,-2.43999995291233,,,,,0.000679088353373517,4.30702147508233E-8,0.00962284880184505,3.03909683144714E-5,0.000678999810037675,4.30645990154473E-8,0.000678999800461288,3.78036299102849E-8,1.14038285773995E-7,2.062632429609E-8,1.00013040259295,10.005763053894,2,20,10,5,2.22140845363619,0.195638802003946,0.0404026173055172,172.741912841797,48.9994277954102,49.000560760498,120.104522705078,120.104522705078,,,51.482349395752,0,1,,,,,,1,1,1,49.0002098083496,0,49.0000506507026,,,,,,,,,,,,,,,,,,,,,,,,,,,,,,,,,
,3754679690.01842,49.0002250671387,120.104522705078,,,5,,,,-2.43999995291233,,,,,0.000679577863942871,3.47406656852753E-8,0.0135850665548096,3.92115331397662E-5,0.000679489251384921,3.47361357271725E-8,0.000679489232285031,2.2289398232956E-8,1.61109713408178E-7,2.6641731393985E-8,1.00013041053669,10.005763053894,2,20,10,5,2.22299617809953,0.195933554271096,0.0404026173055172,172.741912841797,48.9995307922363,49.0006675720215,120.104522705078,120.104522705078,,,51.6067237854004,0,1,,,,,,1,1,1,49.0002059936523,0,49.000051835004,,,,,,,,,,,,,,,,,,,,,,,,,,,,,,,,,
,3754679893.99555,49.0003051757812,120.104522705078,,,5,,,,-2.43999995291233,,,,,0.000679435512329516,4.47376939847942E-8,0.0141121119921399,3.49301114678153E-5,0.000679346837906938,4.47318551831573E-8,0.000679346817300623,3.79240118735818E-8,1.67325039341283E-7,2.37214711082466E-8,1.0001305289399,10.005763053894,2,20,10,5,2.22252872368027,0.195912955502633,0.0404026173055172,172.741912841797,48.9994430541992,49.0004539489746,120.104522705078,120.104522705078,,,51.7310905456543,0,1,,,,,,1,1,1,49.0004005432129,0,48.9999879201253,,,,,,,,,,,,,,,,,,,,,,,,,,,,,,,,,
,3754679996.43317,48.9995937347412,120.104522705078,,,5,,,,-2.43999995291233,,,,,0.000679436515054165,4.57919863302499E-8,0.0126342125477628,4.08574586917642E-5,0.000679347862617816,4.57860114215373E-8,0.000679347846101496,3.64181763771146E-8,1.49802049881618E-7,2.77502301118121E-8,1.00013049637929,10.005763053894,2,20,10,5,2.22253705615596,0.195855919058831,0.0404026173055172,172.741912841797,48.9993095397949,49.0002288818359,120.104522705078,120.104522705078,,,51.7808418273926,0,1,,,,,,1,1,1,48.9996604919434,0,48.9997376335992,,,,,,,,,,,,,,,,,,,,,,,,,,,,,,,,,