File: Experimental_Data/AC_Suceptibillity_FieldScans/FCd_Down_48K.dat
[Header]
; MPMS3 Data File (default extension .dat)
; Copyright (c) 2007, Quantum Design, Inc. All rights reserved.
TITLE,FCd_Down_48K
FILEOPENTIME,3762229651.69488,03/20/2019,7:47 am
BYAPP,SQUID AC,0.9.1.0
INFO,MPMS3 Measurement Release 1.1.16 Build 347, MultiVu Release 2.3.3.2,APPNAME
INFO,0,MOMENT_UNITS
INFO,SrM,SAMPLE_MATERIAL
INFO,MvsH,SAMPLE_COMMENT
INFO,,SAMPLE_MASS
INFO,,SAMPLE_VOLUME
INFO,,SAMPLE_MOLECULAR_WEIGHT
INFO,,SAMPLE_SIZE
INFO,,SAMPLE_SHAPE
INFO,Quartz,SAMPLE_HOLDER
INFO,Standard,SAMPLE_HOLDER_DETAIL
INFO,65.34,SAMPLE_OFFSET
DATATYPE,COMMENT,1
DATATYPE,TIME,2
STARTUPAXIS,X,2
STARTUPAXIS,Y1,5
FIELDGROUP, VSM,2,3,4,5,6,8,9,10,11,14,15
FIELDGROUP, DC, 2,3,4,14,56,57,58,59,60,61,62,63,64,65,66,67,68,69
FIELDGROUP, AC, 2,3,4,11,16,17,18,19,20,21,22,23,24,25,26,27,28,29,30
STARTUPGROUP, All
[Data]
Comment,Time Stamp (sec),Temperature (K),Magnetic Field (Oe),Moment (emu),M. Std. Err. (emu),Transport Action,Averaging Time (sec),Frequency (Hz),Peak Amplitude (mm),Center Position (mm),Lockin Signal' (V),Lockin Signal (V),Range,M. Quad. Signal (emu),AC Moment (emu),AC M. Std Err. (emu),AC Phase (deg),AC Phase Std. Err. (deg),AC Susceptibility (emu/Oe),AC Suscept. Std Err. (emu/Oe),AC X' (emu/Oe),AC X' Std Err. (emu/Oe),AC X'' (emu/Oe),AC X'' Std Err. (emu/Oe),AC Drive (Oe),AC Frequency (Hz),AC Averaging Time (sec),AC Cycles,AC Range,AC Measure Type,AC Signal' (V),AC Signal'' (V),AC Trim Coil Ratio,AC Trim Coil Phase,Min. Temperature (K),Max. Temperature (K),Min. Field (Oe),Max. Field (Oe),Mass (grams),Motor Lag (deg),Pressure (Torr),Measure Count,Measurement Number,SQUID Status (code),Motor Status (code),Measure Status (code),Motor Current (amps),Motor Temp. (C),Temp. Status (code),Field Status (code),Chamber Status (code),Chamber Temp (K),Redirection State,Average Temp (K),Rotation Angle (deg),Rotator state,DC Moment Fixed Ctr (emu),DC Moment Err Fixed Ctr (emu),DC Moment Free Ctr (emu),DC Moment Err Free Ctr (emu),DC Fixed Fit,DC Free Fit,DC Calculated Center (mm),DC Calculated Center Err (mm),DC Scan Length (mm),DC Scan Time (s),DC Number of Points,DC Squid Drift,DC Min V (V),DC Max V (V),DC Scans per Measure,Map 01,Map 02,Map 03,Map 04,Map 05,Map 06,Map 07,Map 08,Map 09,Map 10,Map 11,Map 12,Map 13,Map 14,Map 15,Map 16
,3762229797.90535,47.9251003265381,220.149124145508,,,5,,,,31.6299982368946,,,,,0.000748315602695791,9.77829668950825E-8,0.012781517887456,0.000114061303372022,0.000748197245509487,9.77675010718545E-8,0.000748197226892658,4.77059164690434E-8,1.66907518822117E-7,8.53383255031625E-8,1.00015818981828,10.005763053894,2,20,10,3,2.44783341981185,0.215984518895222,0.0413267537951469,172.859115600586,47.9064712524414,47.9432067871094,220.149124145508,220.149124145508,,,23.3704853057861,0,1,,,,,,1,1,1,47.9183731079102,0,47.9174407958984,,,,,,,,,,,,,,,,,,,,,,,,,,,,,,,,,
,3762229824.20882,47.9023323059082,200.356353759766,,,5,,,,31.6299982368946,,,,,0.000743738791993303,1.24553870980834E-7,0.0347942237820957,0.000151289861279715,0.0007436205686604,1.24534072129527E-7,0.000743620431543677,5.34004246110481E-8,4.51581235206714E-7,1.1250391003215E-7,1.00015898340886,10.005763053894,2,20,10,3,2.4327826686491,0.215546744725266,0.0413267537951469,172.859115600586,47.8987197875977,47.9032554626465,200.356353759766,200.356353759766,,,23.4190292358398,0,1,,,,,,1,1,1,47.9017601013184,0,47.9009957747026,,,,,,,,,,,,,,,,,,,,,,,,,,,,,,,,,
,3762229847.1239,47.9092502593994,180.308578491211,,,5,,,,31.6299982368946,,,,,0.000741979966915082,1.40744836931289E-7,0.176207122098045,8.37858645694149E-5,0.000741861958498332,1.40722452128312E-7,0.000741858450216978,1.26294860894529E-7,2.28151455046896E-6,6.20678390524157E-8,1.00015907058638,10.005763053894,2,20,10,3,2.42649478189228,0.220974444633864,0.0413267537951469,172.859115600586,47.9072418212891,47.9239654541016,180.308578491211,180.308578491211,,,23.464527130127,0,1,,,,,,1,1,1,47.9099540710449,0,47.9127582203258,,,,,,,,,,,,,,,,,,,,,,,,,,,,,,,,,
,3762229870.22846,47.9480972290039,160.297225952148,,,5,,,,31.6299982368946,,,,,0.000743812637174062,3.33874274830057E-7,0.297526911082449,0.000192342422120187,0.000743694209522218,3.33821116353845E-7,0.00074368418253017,3.01777574049715E-7,3.86185594113977E-6,1.42712415452884E-7,1.00015924240142,10.005763053894,2,20,10,3,2.4320171671498,0.226618085806496,0.0413267537951469,172.859115600586,47.9445610046387,47.9548225402832,160.297225952148,160.297225952148,,,23.4650497436523,0,1,,,,,,1,1,1,47.9493865966797,0,47.9501776261763,,,,,,,,,,,,,,,,,,,,,,,,,,,,,,,,,
,3762229891.81857,47.9602603912354,140.285873413086,,,5,,,,31.6299982368946,,,,,0.000746064206393928,1.74670516187128E-7,0.185070061697009,7.47042672499408E-5,0.000745945518458844,1.74642728655293E-7,0.000745941627077338,1.65579646762661E-7,2.40946094524773E-6,5.55289406536675E-8,1.0001591107288,10.005763053894,2,20,10,3,2.43982389109277,0.222463456150854,0.0413267537951469,172.859115600586,47.9585227966309,47.9603691101074,140.285873413086,140.285873413086,,,23.4640941619873,0,1,,,,,,1,1,1,47.9601745605469,0,47.9596141815186,,,,,,,,,,,,,,,,,,,,,,,,,,,,,,,,,
,3762229913.74974,47.9670810699463,120.323097229004,,,5,,,,31.6299982368946,,,,,0.000742084067904189,7.02207699572326E-8,0.103871493189246,4.93262657263802E-5,0.000741966036895911,7.02096011036773E-8,0.000741964817621677,5.993008586001E-8,1.34510916139187E-6,3.65755778621379E-8,1.00015907872114,10.005763053894,2,20,10,3,2.42712226297643,0.217785301631302,0.0413267537951469,172.859115600586,47.9653511047363,47.9805335998535,120.323097229004,120.323097229004,,,23.4338550567627,0,1,,,,,,1,1,1,47.9680137634277,0,47.971365737915,,,,,,,,,,,,,,,,,,,,,,,,,,,,,,,,,
,3762229934.41757,47.9961986541748,100.336029052734,,,5,,,,31.6299982368946,,,,,0.000733105861884945,7.62101203862234E-8,0.0649123914045857,3.6549732784741E-5,0.000732989291173939,7.61980022619781E-8,0.000732988820762861,7.13482828482294E-8,8.30429012222192E-7,2.67499174452084E-8,1.00015903467132,10.005763053894,2,20,10,3,2.39790637515046,0.213468527002273,0.0413267537951469,172.859115600586,47.9951400756836,47.9988288879395,100.336029052734,100.336029052734,,,23.4321441650391,0,1,,,,,,1,1,1,47.9966201782227,0,47.9969281283292,,,,,,,,,,,,,,,,,,,,,,,,,,,,,,,,,
,3762229957.33153,47.9989547729492,80.2761077880859,,,5,,,,31.6299982368946,,,,,0.00071886941574065,3.31094972782609E-8,0.0417199183069998,2.90438138104279E-5,0.000718755100553135,3.31042321796115E-8,0.000718754910010329,2.56963263243645E-8,5.23361435743436E-7,2.08707690714405E-8,1.00015904608875,10.005763053894,2,20,10,3,2.35142826798177,0.208320804060856,0.0413267537951469,172.859115600586,47.9985427856445,47.9996948242188,80.2761077880859,80.2761077880859,,,23.4011993408203,0,1,,,,,,1,1,1,47.9992637634277,0,47.9990997314453,,,,,,,,,,,,,,,,,,,,,,,,,,,,,,,,,
,3762229980.36379,48.0293216705322,60.2283325195313,,,5,,,,31.6299982368946,,,,,0.000702351111358039,3.60119173625135E-8,0.0361031084958219,2.33447591388416E-5,0.000702239413707028,3.60061902461002E-8,0.000702239274295361,3.20629805951621E-8,4.42493745278163E-7,1.63832539928006E-8,1.0001590592166,10.005763053894,2,20,10,3,2.29741977980019,0.203259323242752,0.0413267537951469,172.859115600586,48.024112701416,48.0297012329102,60.2283325195313,60.2283325195313,,,23.3843612670898,0,1,,,,,,1,1,1,48.0297203063965,0,48.0276885986328,,,,,,,,,,,,,,,,,,,,,,,,,,,,,,,,,
,3762230003.40072,48.0145034790039,40.3991279602051,,,5,,,,31.6299982368946,,,,,0.000688964236003338,1.92154210265668E-8,0.0224361629868257,2.06484492100319E-5,0.000688854739346596,1.92123671316759E-8,0.000688854686532536,1.29165440168322E-8,2.69745118097522E-7,1.4222444988944E-8,1.00015895463947,10.005763053894,2,20,10,3,2.25368121658505,0.198799849497546,0.0413267537951469,172.859115600586,48.0120811462402,48.0154113769531,40.3991279602051,40.3991279602051,,,23.3670673370361,0,1,,,,,,1,1,1,48.014347076416,0,48.013635635376,,,,,,,,,,,,,,,,,,,,,,,,,,,,,,,,,
,3762230023.83764,48.0122966766357,20.2663497924805,,,5,,,,31.6299982368946,,,,,0.000682030831301376,1.47706497840932E-8,0.0185451978799902,1.05077185399765E-5,0.000681922427208262,1.47683020912602E-8,0.00068192239148734,1.2915352290488E-8,2.20721076456874E-7,7.16215204190101E-9,1.00015896836471,10.005763053894,2,20,10,3,2.23101759693221,0.196599652147591,0.0413267537951469,172.859115600586,48.0090827941895,48.0125007629395,20.2663497924805,20.2663497924805,,,23.350456237793,0,1,,,,,,1,1,1,48.0122108459473,0,48.0110983415083,,,,,,,,,,,,,,,,,,,,,,,,,,,,,,,,,
,3762230045.52867,48.0056819915771,0.267141789197922,,,5,,,,31.6299982368946,,,,,0.000680557827558365,4.01285528084327E-8,0.0102900063224185,1.82326306611631E-5,0.000680449629397389,4.01221729896418E-8,0.000680449618423716,3.8161029290512E-8,1.22205003762066E-7,1.23905047879184E-8,1.0001590098022,10.005763053894,2,20,10,3,2.22623038765324,0.195806674610315,0.0413267537951469,172.859115600586,48.0036697387695,48.0059967041016,0.267141789197922,0.267141789197922,,,23.3189430236816,0,1,,,,,,1,1,1,48.0054512023926,0,48.0048793792725,,,,,,,,,,,,,,,,,,,,,,,,,,,,,,,,,
,3762230067.43796,48.0024394989014,-19.8049221038818,,,5,,,,31.6299982368946,,,,,0.000680870599014925,3.94371919331341E-8,0.00597553276109597,1.40828654940764E-5,0.000680762374051837,3.94309233578021E-8,0.00068076237034952,3.82526360927261E-8,7.09985603802625E-8,9.56731669834004E-9,1.00015897612326,10.005763053894,2,20,10,3,2.22726538360147,0.195775533735211,0.0413267537951469,172.859115600586,48.0008811950684,48.0025978088379,-19.8049221038818,-19.8049221038818,,,23.3018970489502,0,1,,,,,,1,1,1,48.0022850036621,0,48.0018497467041,,,,,,,,,,,,,,,,,,,,,,,,,,,,,,,,,
,3762230087.94325,48.0361003875732,-39.8526992797852,,,5,,,,31.6299982368946,,,,,0.000683386098598369,4.6266226646634E-8,0.00471312846466443,3.75813054938531E-5,0.000683277283445508,4.6258859703503E-8,0.000683277281133762,3.8482043382796E-8,5.62061226429156E-8,2.56712765197405E-8,1.00015925474986,10.005763053894,2,20,10,3,2.23549546678444,0.196497390734927,0.0413267537951469,172.859115600586,48.0316429138184,48.0377006530762,-39.8526992797852,-39.8526992797852,,,23.2702693939209,0,1,,,,,,1,1,1,48.0374374389648,0,48.0356105804443,,,,,,,,,,,,,,,,,,,,,,,,,,,,,,,,,
,3762230109.57154,48.0193061828613,-59.8761940002441,,,5,,,,31.6299982368946,,,,,0.000689730222124919,5.26266880568164E-8,0.00961722577956259,3.60492249085187E-5,0.000689620689487053,5.26183306733349E-8,0.000689620679772235,4.63812605793897E-8,1.15754387116717E-7,2.48488911204338E-8,1.00015883026646,10.005763053894,2,20,10,3,2.25622840316836,0.198563102446368,0.0413267537951469,172.859115600586,48.0128860473633,48.0215072631836,-59.8761940002441,-59.8761940002441,,,23.2676334381104,0,1,,,,,,1,1,1,48.0179977416992,0,48.016728591919,,,,,,,,,,,,,,,,,,,,,,,,,,,,,,,,,
,3762230131.55151,48.0069770812988,-79.6568298339844,,,5,,,,31.6299982368946,,,,,0.000700934981230848,1.06132723483136E-7,0.0211920530832463,5.20271439138111E-5,0.000700823582275634,1.06115855906504E-7,0.000700823534337679,9.96699918552465E-8,2.59214384465271E-7,3.6420702880986E-8,1.00015895434747,10.005763053894,2,20,10,3,2.29283729806464,0.202300578342361,0.0413267537951469,172.859115600586,48.0043182373047,48.0074691772461,-79.6568298339844,-79.6568298339844,,,23.2506294250488,0,1,,,,,,1,1,1,48.0067253112793,0,48.0059322357178,,,,,,,,,,,,,,,,,,,,,,,,,,,,,,,,,
,3762230153.13131,48.0139656066895,-99.7410354614258,,,5,,,,31.6299982368946,,,,,0.000719666749663749,9.02394088489063E-8,0.0383090510245188,4.97900704694488E-5,0.000719552308644925,9.0225059026726E-8,0.000719552147806474,8.28214141696584E-8,4.81106362232816E-7,3.57934998472361E-8,1.00015904475248,10.005763053894,2,20,10,3,2.35404570574877,0.208460699136771,0.0413267537951469,172.859115600586,48.0113754272461,48.0141143798828,-99.7410354614258,-99.7410354614258,,,23.2045745849609,0,1,,,,,,1,1,1,48.0139083862305,0,48.0129283905029,,,,,,,,,,,,,,,,,,,,,,,,,,,,,,,,,
,3762230175.08204,48.0066089630127,-119.80094909668,,,5,,,,31.6299982368946,,,,,0.000743134997178705,2.03331008167755E-7,0.05733077832293,7.80171300228437E-5,0.000743016903930644,2.03298696381501E-7,0.000743016531968217,1.94899568889071E-7,7.43470647631428E-7,5.78318078333392E-8,1.00015893749851,10.005763053894,2,20,10,3,2.43073597526044,0.216117799049077,0.0413267537951469,172.859115600586,48.0044174194336,48.0075073242188,-119.80094909668,-119.80094909668,,,23.1726188659668,0,1,,,,,,1,1,1,48.0061988830566,0,48.0058025360107,,,,,,,,,,,,,,,,,,,,,,,,,,,,,,,,,
,3762230196.68054,48.0164680480957,-139.860870361328,,,5,,,,31.6299982368946,,,,,0.000775433512381736,2.41809547282627E-7,0.0801691536534994,8.22548396014131E-5,0.000775310203512506,2.41771094905514E-7,0.000775309444559709,2.33265668298669E-7,1.08482584723002E-6,6.3564064729894E-8,1.00015904455877,10.005763053894,2,20,10,3,2.53628833870789,0.226576220051147,0.0413267537951469,172.859115600586,48.0143814086914,48.0167846679687,-139.860870361328,-139.860870361328,,,23.1703300476074,0,1,,,,,,1,1,1,48.0167846679687,0,48.0158603668213,,,,,,,,,,,,,,,,,,,,,,,,,,,,,,,,,
,3762230218.59508,48.0173759460449,-159.714370727539,,,5,,,,31.6299982368946,,,,,0.000811047734344775,1.91703706262389E-7,0.0646712364278601,0.000102675675481872,0.000810918821459033,1.91673235703216E-7,0.000810918304894717,1.72679836648937E-7,9.15304968994903E-7,8.3188360362715E-8,1.00015897138201,10.005763053894,2,20,10,3,2.65283580522121,0.236321258751803,0.0413267537951469,172.859115600586,48.0126113891602,48.0185089111328,-159.714370727539,-159.714370727539,,,23.1384696960449,0,1,,,,,,1,1,1,48.0166969299316,0,48.0155578613281,,,,,,,,,,,,,,,,,,,,,,,,,,,,,,,,,
,3762230240.27774,48.0112705230713,-179.750015258789,,,5,,,,31.6299982368946,,,,,0.000833543553876039,2.34720794634218E-7,0.0225652976465636,0.000120753270538462,0.000833411011415064,2.34683471483414E-7,0.00083341094678031,2.12042490947449E-7,3.28229534673544E-7,1.00569944915505E-7,1.00015903612883,10.005763053894,2,20,10,3,2.72659092382703,0.240930863870645,0.0413267537951469,172.859115600586,48.0076866149902,48.011962890625,-179.750015258789,-179.750015258789,,,23.1067276000977,0,1,,,,,,1,1,1,48.0109100341797,0,48.0098209381103,,,,,,,,,,,,,,,,,,,,,,,,,,,,,,,,,
,3762230262.12279,48.0169734954834,-199.797775268555,,,5,,,,31.6299982368946,,,,,0.000845237502800784,1.28872181150276E-7,-0.0169808588954536,9.66895464468566E-5,0.000845103171148832,1.28851699790981E-7,0.000845103134033464,9.9639335127591E-8,-2.50464826785688E-7,8.16992254207876E-8,1.00015895296165,10.005763053894,2,20,10,3,2.76500712498249,0.242461842591335,0.0413267537951469,172.859115600586,48.0141448974609,48.0170860290527,-199.797775268555,-199.797775268555,,,23.1046371459961,0,1,,,,,,1,1,1,48.0170097351074,0,48.0161361694336,,,,,,,,,,,,,,,,,,,,,,,,,,,,,,,,,
,3762230284.05827,48.0165214538574,-219.675567626953,,,5,,,,31.6299982368946,,,,,0.000852090175293373,1.75676945163638E-7,-0.0262060824953041,0.000135372271159241,0.000851954772186232,1.75649028864497E-7,0.000851954683072326,1.32495789503731E-7,-3.89669124907193E-7,1.15314557211238E-7,1.00015893227148,10.005763053894,2,20,10,3,2.787459795172,0.244038073365359,0.0413267537951469,172.859115600586,48.0121421813965,48.016902923584,-219.675567626953,-219.675567626953,,,23.0439720153809,0,1,,,,,,1,1,1,48.0162010192871,0,48.0148578990589,,,,,,,,,,,,,,,,,,,,,,,,,,,,,,,,,
,3762230306.55998,48.0083179473877,-239.614059448242,,,5,,,,31.6299982368946,,,,,0.00085722093358916,1.59058901734872E-7,-0.0476505849968598,0.000131813695099977,0.000857084741976911,1.59033631133769E-7,0.000857084445572303,1.11942718534244E-7,-7.12802670392263E-7,1.12962487573331E-7,1.00015890098794,10.005763053894,2,20,10,3,2.80433217589646,0.244517825590209,0.0413267537951469,172.859115600586,48.0054092407227,48.0101623535156,-239.614059448242,-239.614059448242,,,23.0120296478271,0,1,,,,,,1,1,1,48.007625579834,0,48.0072565945712,,,,,,,,,,,,,,,,,,,,,,,,,,,,,,,,,
,3762230328.71309,48.0190868377686,-259.673980712891,,,5,,,,31.6299982368946,,,,,0.000860560507628308,1.65703898440169E-7,-0.0543512386329228,0.00014813722505806,0.000860423657512001,1.65677547477543E-7,0.000860423270382791,1.05859457356934E-7,-8.16204699868308E-7,1.27447342170283E-7,1.00015904969036,10.005763053894,2,20,10,3,2.81528233808613,0.245201556151499,0.0413267537951469,172.859115600586,48.0163116455078,48.0194282531738,-259.673980712891,-259.673980712891,,,23.0087184906006,0,1,,,,,,1,1,1,48.0194282531738,0,48.0182678222656,,,,,,,,,,,,,,,,,,,,,,,,,,,,,,,,,
,3762230350.3497,48.0102081298828,-279.746032714844,,,5,,,,31.6299982368946,,,,,0.000863283965216308,2.35363209287624E-7,-0.0683578827294244,0.000199343521588164,0.000863146834687004,2.35325822422156E-7,0.000863146220378431,1.60559495686922E-7,-1.02979445619942E-6,1.72043282471085E-7,1.00015887277088,10.005763053894,2,20,10,3,2.82424835045366,0.245347868245988,0.0413267537951469,172.859115600586,48.0062980651855,48.0120620727539,-279.746032714844,-279.746032714844,,,22.978099822998,0,1,,,,,,1,1,1,48.0091552734375,0,48.0084587097168,,,,,,,,,,,,,,,,,,,,,,,,,,,,,,,,,
,3762230372.26111,48.0045776367188,-299.587371826172,,,5,,,,31.6299982368946,,,,,0.000865546814397455,1.96473192218953E-7,-0.0904106026696763,0.000143220114056894,0.000865409249587607,1.96441965950335E-7,0.000865408172167911,1.52415153446418E-7,-1.36558294530587E-6,1.23931702910665E-7,1.00015895925531,10.005763053894,2,20,10,3,2.83174213228475,0.244961233434193,0.0413267537951469,172.859115600586,48.0027847290039,48.0053062438965,-299.587371826172,-299.587371826172,,,22.9310665130615,0,1,,,,,,1,1,1,48.0044860839844,0,48.0039451599121,,,,,,,,,,,,,,,,,,,,,,,,,,,,,,,,,
,3762230393.88235,48.0340270996094,-319.647308349609,,,5,,,,31.6299982368946,,,,,0.000867443292600893,2.65734452240293E-7,-0.112174557715178,0.000119195630273256,0.000867305351914768,2.65692195192505E-7,0.000867303689706804,2.447478887445E-7,-1.69802266291433E-6,1.0339639036892E-7,1.00015904512271,10.005763053894,2,20,10,3,2.83803609241799,0.244480708116227,0.0413267537951469,172.859115600586,48.0265045166016,48.0341606140137,-319.647308349609,-319.647308349609,,,22.9141139984131,0,1,,,,,,1,1,1,48.0338935852051,0,48.0315693941983,,,,,,,,,,,,,,,,,,,,,,,,,,,,,,,,,
,3762230416.67455,48.0321388244629,-339.682952880859,,,5,,,,31.6299982368946,,,,,0.000869365309074062,3.69133884398954E-7,-0.121432137240936,0.000243388579461099,0.000869227137862141,3.69075216683971E-7,0.000869225185658442,3.02426343183076E-7,-1.84223045703079E-6,2.11553356199406E-7,1.00015895869549,10.005763053894,2,20,10,3,2.84436029584031,0.244623836335293,0.0413267537951469,172.859115600586,48.026741027832,48.0325698852539,-339.682952880859,-339.682952880859,,,22.8836002349854,0,1,,,,,,1,1,1,48.0316772460937,0,48.0303188670765,,,,,,,,,,,,,,,,,,,,,,,,,,,,,,,,,
,3762230438.92434,48.0175762176514,-359.706420898438,,,5,,,,31.6299982368946,,,,,0.000871101744586844,3.36371157253382E-7,-0.143009804611278,0.000239587473670868,0.000870963378278327,3.36317727862831E-7,0.000870960665239337,2.6375999468634E-7,-2.17391532638636E-6,2.08663075981064E-7,1.00015886581683,10.005763053894,2,20,10,3,2.85012996647929,0.244100251231051,0.0413267537951469,172.859115600586,48.0119857788086,48.0201683044434,-359.706420898438,-359.706420898438,,,22.8663082122803,0,1,,,,,,1,1,1,48.016429901123,0,48.0156555175781,,,,,,,,,,,,,,,,,,,,,,,,,,,,,,,,,
,3762230461.93185,48.013599395752,-379.644927978516,,,5,,,,31.6299982368946,,,,,0.000872971004174028,4.71423844856233E-7,-0.152452329301976,0.000451953632710388,0.000872832199423031,4.71348887189727E-7,0.000872829109672816,2.58091325491825E-7,-2.32242489777423E-6,3.94409230572596E-7,1.00015902799082,10.005763053894,2,20,10,3,2.85628258688972,0.244214300180827,0.0413267537951469,172.859115600586,48.009822845459,48.0145950317383,-379.644927978516,-379.644927978516,,,22.8637790679932,0,1,,,,,,1,1,1,48.0129890441895,0,48.0123085021973,,,,,,,,,,,,,,,,,,,,,,,,,,,,,,,,,
,3762230483.54008,48.0063419342041,-399.619873046875,,,5,,,,31.6299982368946,,,,,0.000874152518829568,4.15610649179133E-7,-0.174916030045888,0.000301918491342512,0.000874013615974015,4.15544608637322E-7,0.000874009543092047,3.21011152478857E-7,-2.66823762134982E-6,2.63873382044763E-7,1.00015892527646,10.005763053894,2,20,10,3,2.86024043728692,0.243484628244527,0.0413267537951469,172.859115600586,48.0040512084961,48.0075225830078,-399.619873046875,-399.619873046875,,,22.8175735473633,0,1,,,,,,1,1,1,48.0057754516602,0,48.0053604125977,,,,,,,,,,,,,,,,,,,,,,,,,,,,,,,,,
,3762230505.4512,48.0028858184814,-419.679748535156,,,5,,,,31.6299982368946,,,,,0.00087560063292965,3.44893830324878E-7,-0.184577814568135,0.000239474074595236,0.000875461437580068,3.44839002112705E-7,0.000875456894813887,2.73786386980731E-7,-2.82028590521685E-6,2.09654362420923E-7,1.00015899655154,10.005763053894,2,20,10,3,2.86501614747262,0.243466381202547,0.0413267537951469,172.859115600586,48.0009231567383,48.0033226013184,-419.679748535156,-419.679748535156,,,22.7862796783447,0,1,,,,,,1,1,1,48.0025482177734,0,48.0021209716797,,,,,,,,,,,,,,,,,,,,,,,,,,,,,,,,,
,3762230527.12193,48.0076217651367,-439.54541015625,,,5,,,,31.6299982368946,,,,,0.00087681216097727,4.74435332909991E-7,-0.192128564712467,0.000379894194987201,0.000876672784158487,4.74359917341683E-7,0.000876667855306986,3.37818947053822E-7,-2.93972033396552E-6,3.33010045181607E-7,1.00015898385498,10.005763053894,2,20,10,3,2.869008856002,0.243486127223302,0.0413267537951469,172.859115600586,48.0068054199219,48.0081253051758,-439.54541015625,-439.54541015625,,,22.7840232849121,0,1,,,,,,1,1,1,48.0078010559082,0,48.0074573516846,,,,,,,,,,,,,,,,,,,,,,,,,,,,,,,,,
,3762230548.96535,48.0403461456299,-459.848205566406,,,5,,,,31.6299982368946,,,,,0.000877365054907231,4.31493702057089E-7,-0.202579779564831,0.000273922940798153,0.000877225484047738,4.31425060222627E-7,0.000877220000928185,3.58288090412092E-7,-3.10158577893036E-6,2.40327332729662E-7,1.0001591048847,10.005763053894,2,20,10,3,2.87085872456522,0.243178193762514,0.0413267537951469,172.859115600586,48.0343742370605,48.0402297973633,-459.848205566406,-459.848205566406,,,22.7522945404053,0,1,,,,,,1,1,1,48.0402297973633,0,48.0384994506836,,,,,,,,,,,,,,,,,,,,,,,,,,,,,,,,,
,3762230570.67156,48.0203914642334,-479.908081054687,,,5,,,,31.6299982368946,,,,,0.000878375060426052,4.72106715993823E-7,-0.2303559019627,0.000398760566533902,0.000878235526418038,4.72031719622386E-7,0.000878228428453204,3.16553000468826E-7,-3.53090914415194E-6,3.50154454810802E-7,1.00015887994031,10.005763053894,2,20,10,3,2.87427768619297,0.242126574062427,0.0413267537951469,172.859115600586,48.0137214660645,48.022289276123,-479.908081054687,-479.908081054687,,,22.7212963104248,0,1,,,,,,1,1,1,48.0196189880371,0,48.0178718566895,,,,,,,,,,,,,,,,,,,,,,,,,,,,,,,,,
,3762230592.64375,48.0080699920654,-499.992309570313,,,5,,,,31.6299982368946,,,,,0.000878439373936368,6.05729414508546E-7,-0.245838026610452,0.000369413941509035,0.000878299821194933,6.05633185670369E-7,0.000878291736474816,5.11327521291732E-7,-3.76849454076493E-6,3.24554651106547E-7,1.0001588896389,10.005763053894,2,20,10,3,2.87454987582338,0.241429418127562,0.0413267537951469,172.859115600586,48.0038909912109,48.0102005004883,-499.992309570313,-499.992309570313,,,22.7046794891357,0,1,,,,,,1,1,1,48.0073089599609,0,48.0062210776589,,,,,,,,,,,,,,,,,,,,,,,,,,,,,,,,,
,3762230615.75558,48.0022411346436,-519.736511230469,,,5,,,,31.6299982368946,,,,,0.000876460874844064,4.2785311163023E-7,-0.248419423009039,0.000346072753378966,0.00087632156859469,4.2778510789615E-7,0.000876313331792097,3.01737694724119E-7,-3.79948781969102E-6,3.03239941498964E-7,1.00015896704402,10.005763053894,2,20,10,3,2.8680828958892,0.240817058411395,0.0413267537951469,172.859115600586,48.0012664794922,48.0025062561035,-519.736511230469,-519.736511230469,,,22.6593132019043,0,1,,,,,,1,1,1,48.0024909973145,0,48.0019031871449,,,,,,,,,,,,,,,,,,,,,,,,,,,,,,,,,
,3762230637.30268,48.0070934295654,-539.796447753906,,,5,,,,31.6299982368946,,,,,0.000873369244157731,4.79849602685677E-7,-0.272262417483241,0.000368483513545864,0.000873230335562158,4.79773283036409E-7,0.000873220476669694,3.55881472120581E-7,-4.14946632132998E-6,3.21761994208177E-7,1.00015907440444,10.005763053894,2,20,10,3,2.85806209574442,0.238839595942652,0.0413267537951469,172.859115600586,48.005973815918,48.0072021484375,-539.796447753906,-539.796447753906,,,22.6423397064209,0,1,,,,,,1,1,1,48.0071830749512,0,48.0065425872803,,,,,,,,,,,,,,,,,,,,,,,,,,,,,,,,,
,3762230659.18791,48.0030670166016,-559.868469238281,,,5,,,,31.6299982368946,,,,,0.000866533056071402,6.79228043017182E-7,-0.293761167097186,0.000544130955842251,0.000866395295021745,6.79120059637313E-7,0.000866383907515105,4.88862550737695E-7,-4.44207549187682E-6,4.71399471667102E-7,1.00015900484507,10.005763053894,2,20,10,3,2.83577620537403,0.235967006738213,0.0413267537951469,172.859115600586,48.0015296936035,48.0033340454102,-559.868469238281,-559.868469238281,,,22.6257820129395,0,1,,,,,,1,1,1,48.0031433105469,0,48.0025764465332,,,,,,,,,,,,,,,,,,,,,,,,,,,,,,,,,
,3762230680.86634,48.0005760192871,-579.904174804687,,,5,,,,31.6299982368946,,,,,0.000850492857654986,7.50205971135832E-7,-0.325295563109913,0.000652933129417918,0.000850357646059196,7.50086703177712E-7,0.0008503439409824,5.04433995862367E-7,-4.82786141670345E-6,5.55136385136422E-7,1.00015900556244,10.005763053894,2,20,10,3,2.78340745339395,0.230126869395326,0.0413267537951469,172.859115600586,48.0004615783691,48.0011901855469,-579.904174804687,-579.904174804687,,,22.5942611694336,0,1,,,,,,1,1,1,48.0006675720215,0,48.0007835388184,,,,,,,,,,,,,,,,,,,,,,,,,,,,,,,,,
,3762230702.74588,48.0315113067627,-599.854797363281,,,5,,,,31.6299982368946,,,,,0.000809097492285273,6.99682971241755E-7,-0.333829300135148,0.000617822229652617,0.000808968830075935,6.9957170806547E-7,0.00080895509901156,4.89547131470447E-7,-4.71336584866846E-6,4.99744115317724E-7,1.0001590447055,10.005763053894,2,20,10,3,2.64796226206054,0.218588068319591,0.0413267537951469,172.859115600586,48.0273513793945,48.0317344665527,-599.854797363281,-599.854797363281,,,22.5779476165771,0,1,,,,,,1,1,1,48.0317459106445,0,48.0302070617676,,,,,,,,,,,,,,,,,,,,,,,,,,,,,,,,,
,3762230724.35499,48.0170421600342,-619.853942871094,,,5,,,,31.6299982368946,,,,,0.000703690676264966,7.80271049014092E-7,-0.407102275787286,0.000649399186352076,0.000703578918823661,7.80147129373114E-7,0.000703561158830627,6.32223796159109E-7,-4.99907971293222E-6,4.57080534522393E-7,1.00015884137275,10.005763053894,2,20,10,3,2.30323212145842,0.187215075278221,0.0413267537951469,172.859115600586,48.0109634399414,48.0186882019043,-619.853942871094,-619.853942871094,,,22.5620098114014,0,1,,,,,,1,1,1,48.0163116455078,0,48.0147285461426,,,,,,,,,,,,,,,,,,,,,,,,,,,,,,,,,
,3762230749.42944,48.0406265258789,-639.804626464844,,,5,,,,31.6299982368946,,,,,0.000486887199745884,6.73663580091584E-7,-0.558515080968129,0.000862097615576606,0.000486809795534781,6.73556482599612E-7,0.000486786666877662,5.26712015097399E-7,-4.7453112387135E-6,4.19824711521367E-7,1.000159002986,10.005763053894,2,20,1,3,1.59395312185256,0.125357202413113,0.0413267537951469,172.859115600586,48.0306739807129,48.0415687561035,-639.804626464844,-639.804626464844,,,22.5298118591309,0,1,,,,,,1,1,1,48.0396842956543,0,48.0379330561711,,,,,,,,,,,,,,,,,,,,,,,,,,,,,,,,,
,3762230771.93498,48.0174007415771,-659.888793945313,,,5,,,,31.6299982368946,,,,,0.000278749834791941,8.66026327431973E-7,-1.04592860951848,0.00192001007205959,0.000278705560243916,8.65888774259062E-7,0.000278659123431866,6.80399148116446E-7,-5.08745899828756E-6,5.3555613023312E-7,1.0001588577852,10.005763053894,2,20,1,3,0.913137432093605,0.0640228071302476,0.0413267537951469,172.859115600586,48.0110549926758,48.0199012756348,-659.888793945313,-659.888793945313,,,22.5418109893799,0,1,,,,,,1,1,1,48.0164527893066,0,48.0152515411377,,,,,,,,,,,,,,,,,,,,,,,,,,,,,,,,,
,3762230792.72073,48.0210781097412,-679.693725585938,,,5,,,,31.6299982368946,,,,,0.000159411817503163,9.91644069292357E-7,-1.87724070330282,0.00364005287626241,0.000159386470894283,9.91486397077298E-7,0.00015930092931427,8.03120888829168E-7,-5.22120903087104E-6,5.81413891746291E-7,1.00015902610013,10.005763053894,2,20,1,3,0.522682138298731,0.0290441642015964,0.0413267537951469,172.859115600586,48.0141754150391,48.0217781066895,-679.693725585938,-679.693725585938,,,22.5253467559814,0,1,,,,,,1,1,1,48.0204391479492,0,48.0184190923517,,,,,,,,,,,,,,,,,,,,,,,,,,,,,,,,,
,3762230815.47203,48.0142459869385,-699.753662109375,,,5,,,,31.6299982368946,,,,,0.000102724569300983,9.75248085182957E-7,-3.04055372432956,0.00566583191395846,0.000102708232777454,9.7509298924633E-7,0.000102563644382775,7.81267111955141E-7,-5.44792907363206E-6,5.83462113126993E-7,1.00015905758562,10.005763053894,2,20,1,3,0.337125526407768,0.0118812575404122,0.0413267537951469,172.859115600586,48.0130958557129,48.0144920349121,-699.753662109375,-699.753662109375,,,22.4801349639893,0,1,,,,,,1,1,1,48.0143966674805,0,48.0138483914462,,,,,,,,,,,,,,,,,,,,,,,,,,,,,,,,,
,3762230838.4762,48.0340709686279,-719.765014648438,,,5,,,,31.6299982368946,,,,,6.67526063518286E-5,8.24211079678971E-7,-4.64277503134531,0.00751700813127086,6.67419912296318E-5,8.24080012117644E-7,6.6522992533107E-5,6.52722887223365E-7,-5.40230115195682E-6,5.03051387898504E-7,1.00015904713062,10.005763053894,2,20,1,3,0.219201636422523,0.00159703102070381,0.0413267537951469,172.859115600586,48.0284461975098,48.0343208312988,-719.765014648438,-719.765014648438,,,22.4353466033936,0,1,,,,,,1,1,1,48.0343360900879,0,48.0322818756103,,,,,,,,,,,,,,,,,,,,,,,,,,,,,,,,,
,3762230860.1158,48.0371932983398,-739.618530273437,,,5,,,,31.6299982368946,,,,,4.87838944572873E-5,8.51876347316197E-7,-6.33005503186491,0.0117164583610665,4.87761409737518E-5,8.51740954082289E-7,4.84787653561507E-5,6.31143294845342E-7,-5.37784695157715E-6,5.71944747534911E-7,1.00015896057746,10.005763053894,2,20,1,3,0.160161205432812,-0.00354684572535172,0.0413267537951469,172.859115600586,48.030216217041,48.037425994873,-739.618530273437,-739.618530273437,,,22.4185676574707,0,1,,,,,,1,1,1,48.036994934082,0,48.0347988128662,,,,,,,,,,,,,,,,,,,,,,,,,,,,,,,,,
,3762230882.02047,48.0234565734863,-759.690551757812,,,5,,,,31.6299982368946,,,,,4.02645059756709E-5,8.39330832031391E-7,-8.42157776056378,0.0135563157727417,4.02581087407686E-5,8.39197478936324E-7,3.9824015518427E-5,6.37142646547594E-7,-5.89602470921172E-6,5.46169988742891E-7,1.00015890550009,10.005763053894,2,20,1,3,0.131996745136414,-0.00774710067486893,0.0413267537951469,172.859115600586,48.0172309875488,48.0254287719727,-759.690551757812,-759.690551757812,,,22.387279510498,0,1,,,,,,1,1,1,48.0226593017578,0,48.0213054656982,,,,,,,,,,,,,,,,,,,,,,,,,,,,,,,,,
,3762230903.69164,48.0072612762451,-779.726196289063,,,5,,,,31.6299982368946,,,,,3.42283143558243E-5,9.13627299701011E-7,-9.29406909973692,0.013835518278642,3.42228740360507E-5,9.1348208586978E-7,3.37736111810159E-5,7.80648199003788E-7,-5.52705121027046E-6,4.7438160862026E-7,1.00015896735522,10.005763053894,2,20,1,3,0.112095603531636,-0.00829117544976221,0.0413267537951469,172.859115600586,48.0048446655273,48.0079231262207,-779.726196289063,-779.726196289063,,,22.3709659576416,0,1,,,,,,1,1,1,48.0067329406738,0,48.0061687469482,,,,,,,,,,,,,,,,,,,,,,,,,,,,,,,,,
,3762230925.67438,48.0034046173096,-799.810424804687,,,5,,,,31.6299982368946,,,,,3.12535589048781E-5,1.05475116741179E-6,-11.0723835313335,0.0198933282258857,3.12485897448487E-5,1.05458346723537E-6,3.06669080357074E-5,8.52742445924425E-7,-6.0012592488017E-6,6.20464834043804E-7,1.00015902029723,10.005763053894,2,20,1,3,0.102069521348638,-0.0107410457725384,0.0413267537951469,172.859115600586,48.0012130737305,48.003963470459,-799.810424804687,-799.810424804687,,,22.368932723999,0,1,,,,,,1,1,1,48.0032386779785,0,48.0026317596436,,,,,,,,,,,,,,,,,,,,,,,,,,,,,,,,,
,3762230947.22555,48.0010414123535,-819.712463378906,,,5,,,,31.6299982368946,,,,,2.97685696505541E-5,9.85856322078022E-7,-12.411960369411,0.0189808464441403,2.97638364009987E-5,9.85699569366926E-7,2.90681790965549E-5,8.10021915486037E-7,-6.39741520584863E-6,5.61665503197834E-7,1.00015902686373,10.005763053894,2,20,1,3,0.0969543418581731,-0.0124986366274067,0.0413267537951469,172.859115600586,48.000358581543,48.0013008117676,-819.712463378906,-819.712463378906,,,22.3372783660889,0,1,,,,,,1,1,1,48.0009651184082,0,48.000821685791,,,,,,,,,,,,,,,,,,,,,,,,,,,,,,,,,
,3762230969.19323,48.0369148254395,-839.687377929688,,,5,,,,31.6299982368946,,,,,2.62756326186316E-5,1.07738717637689E-6,-12.7084648397281,0.0254351189764185,2.62714538138426E-5,1.07721583166533E-6,2.56278571404167E-5,8.47099327772685E-7,-5.7794657091515E-6,6.65444721128273E-7,1.00015906256344,10.005763053894,2,20,1,3,0.0855201223109953,-0.0114729947907802,0.0413267537951469,172.859115600586,48.0313491821289,48.0374526977539,-839.687377929688,-839.687377929688,,,22.3215522766113,0,1,,,,,,1,1,1,48.0373077392578,0,48.035120530562,,,,,,,,,,,,,,,,,,,,,,,,,,,,,,,,,
,3762230992.14967,48.0522537231445,-859.723022460937,,,5,,,,31.6299982368946,,,,,2.50615371430215E-5,1.01737479944263E-6,-13.3181609832643,0.0324791528722764,2.50575539564446E-5,1.01721310171349E-6,2.43836537265523E-5,6.07602738160559E-7,-5.77221285329341E-6,8.15807211832161E-7,1.00015896150852,10.005763053894,2,20,1,3,0.0814478039624423,-0.0118084901696125,0.0413267537951469,172.859115600586,48.040714263916,48.053337097168,-859.723022460937,-859.723022460937,,,22.2767276763916,0,1,,,,,,1,1,1,48.0513153076172,0,48.0484268188477,,,,,,,,,,,,,,,,,,,,,,,,,,,,,,,,,
,3762231013.85421,48.0366973876953,-879.782897949219,,,5,,,,31.6299982368946,,,,,2.54387713298084E-5,9.49436955214632E-7,-14.9339745701645,0.0218841486586984,2.54347287879515E-5,9.49286077698491E-7,2.45756310912748E-5,7.74662168701294E-7,-6.55467657342559E-6,5.48673474568612E-7,1.00015893787941,10.005763053894,2,20,1,3,0.0823032789711317,-0.0143109080341854,0.0413267537951469,172.859115600586,48.0276908874512,48.038703918457,-879.782897949219,-879.782897949219,,,22.2743453979492,0,1,,,,,,1,1,1,48.0354309082031,0,48.0332893371582,,,,,,,,,,,,,,,,,,,,,,,,,,,,,,,,,
,3762231036.97197,48.0155963897705,-899.733581542969,,,5,,,,31.6299982368946,,,,,2.38173969786688E-5,9.90769429168976E-7,-14.3363621254322,0.0254259742797121,2.38136132353087E-5,9.90612030891896E-7,2.30720282930801E-5,7.88224274627898E-7,-5.89658254959434E-6,6.00012240404387E-7,1.00015888993084,10.005763053894,2,20,1,3,0.0771934393156322,-0.0125926940963813,0.0413267537951469,172.859115600586,48.0093154907227,48.0182189941406,-899.733581542969,-899.733581542969,,,22.2434787750244,0,1,,,,,,1,1,1,48.0141944885254,0,48.0131732940674,,,,,,,,,,,,,,,,,,,,,,,,,,,,,,,,,
,3762231058.90989,48.0236740112305,-919.647766113281,,,5,,,,31.6299982368946,,,,,2.28305855781563E-5,9.4310207822537E-7,-14.8205504194918,0.0238721720463868,2.2826955403237E-5,9.42952120376105E-7,2.20675415181458E-5,7.75223281191274E-7,-5.83896431966175E-6,5.36831040105568E-7,1.00015903018406,10.005763053894,2,20,1,3,0.0738907933173504,-0.0126942565283803,0.0413267537951469,172.859115600586,48.0189476013184,48.024356842041,-919.647766113281,-919.647766113281,,,22.2413311004639,0,1,,,,,,1,1,1,48.0230178833008,0,48.021817779541,,,,,,,,,,,,,,,,,,,,,,,,,,,,,,,,,
,3762231081.96407,48.0093326568604,-939.671325683594,,,5,,,,31.6299982368946,,,,,2.35232136666386E-5,1.04147124303832E-6,-15.3935665647506,0.025731243632957,2.35194753064435E-5,1.04130573016689E-6,2.26757192106466E-5,8.5477762414246E-7,-6.24319445238726E-6,5.94703991027282E-7,1.00015894743171,10.005763053894,2,20,1,3,0.075998198217282,-0.0138384874615311,0.0413267537951469,172.859115600586,48.0063209533691,48.0113258361816,-939.671325683594,-939.671325683594,,,22.2106742858887,0,1,,,,,,1,1,1,48.0086441040039,0,48.0082233428955,,,,,,,,,,,,,,,,,,,,,,,,,,,,,,,,,
,3762231105.05534,48.0307846069336,-959.706848144531,,,5,,,,31.6299982368946,,,,,2.28027125193164E-5,1.15414651580146E-6,-15.9204565948034,0.0293903649799664,2.27990872035358E-5,1.15396302247481E-6,2.19245925387787E-5,9.49086502353262E-7,-6.25384836104592E-6,6.56403434093737E-7,1.00015901144411,10.005763053894,2,20,1,3,0.0735442894475578,-0.0140899547689376,0.0413267537951469,172.859115600586,48.0241775512695,48.031063079834,-959.706848144531,-959.706848144531,,,22.1941356658936,0,1,,,,,,1,1,1,48.0305061340332,0,48.0286337534587,,,,,,,,,,,,,,,,,,,,,,,,,,,,,,,,,
,3762231128.14829,48.0456161499023,-979.754638671875,,,5,,,,31.6299982368946,,,,,2.2076556584058E-5,9.5725659214827E-7,-16.3046138595054,0.0237539065942756,2.20730469276667E-5,9.57104410728856E-7,2.11853283038463E-5,8.10876734758565E-7,-6.19687544890375E-6,5.08456265635422E-7,1.00015900189959,10.005763053894,2,20,1,3,0.0711095395339537,-0.0141168329595892,0.0413267537951469,172.859115600586,48.0376739501953,48.0457725524902,-979.754638671875,-979.754638671875,,,22.1631698608398,0,1,,,,,,1,1,1,48.0455780029297,0,48.0430599212647,,,,,,,,,,,,,,,,,,,,,,,,,,,,,,,,,
,3762231151.17068,48.019739151001,-999.656799316406,,,5,,,,31.6299982368946,,,,,2.21006295446757E-5,8.58240763780148E-7,-17.1100453804223,0.0217849368683537,2.20971194154088E-5,8.58104453815905E-7,2.11191328956515E-5,7.21124638192269E-7,-6.50114699069697E-6,4.65104837483725E-7,1.00015885008362,10.005763053894,2,20,1,3,0.0709817511379486,-0.0151300007003261,0.0413267537951469,172.859115600586,48.0126914978027,48.0229568481445,-999.656799316406,-999.656799316406,,,22.1604537963867,0,1,,,,,,1,1,1,48.0183296203613,0,48.0171585083008,,,,,,,,,,,,,,,,,,,,,,,,,,,,,,,,,