File: Experimental_Data/AC_Suceptibillity_FieldScans/FCd_Down_40K.dat
[Header]
; MPMS3 Data File (default extension .dat)
; Copyright (c) 2007, Quantum Design, Inc. All rights reserved.
TITLE,FCd_Down_40K
FILEOPENTIME,3772394707.72278,07/15/2019,11:25 pm
BYAPP,SQUID AC,0.9.1.0
INFO,MPMS3 Measurement Release 1.1.16 Build 347, MultiVu Release 2.3.3.2,APPNAME
INFO,0,MOMENT_UNITS
INFO,Cu2OSeO3,SAMPLE_MATERIAL
INFO,,SAMPLE_COMMENT
INFO,,SAMPLE_MASS
INFO,,SAMPLE_VOLUME
INFO,,SAMPLE_MOLECULAR_WEIGHT
INFO,,SAMPLE_SIZE
INFO,,SAMPLE_SHAPE
INFO,Quartz,SAMPLE_HOLDER
INFO,Standard,SAMPLE_HOLDER_DETAIL
INFO,64.77,SAMPLE_OFFSET
DATATYPE,COMMENT,1
DATATYPE,TIME,2
STARTUPAXIS,X,2
STARTUPAXIS,Y1,5
FIELDGROUP, VSM,2,3,4,5,6,8,9,10,11,14,15
FIELDGROUP, DC, 2,3,4,14,56,57,58,59,60,61,62,63,64,65,66,67,68,69
FIELDGROUP, AC, 2,3,4,11,16,17,18,19,20,21,22,23,24,25,26,27,28,29,30
STARTUPGROUP, All
[Data]
Comment,Time Stamp (sec),Temperature (K),Magnetic Field (Oe),Moment (emu),M. Std. Err. (emu),Transport Action,Averaging Time (sec),Frequency (Hz),Peak Amplitude (mm),Center Position (mm),Lockin Signal' (V),Lockin Signal (V),Range,M. Quad. Signal (emu),AC Moment (emu),AC M. Std Err. (emu),AC Phase (deg),AC Phase Std. Err. (deg),AC Susceptibility (emu/Oe),AC Suscept. Std Err. (emu/Oe),AC X' (emu/Oe),AC X' Std Err. (emu/Oe),AC X'' (emu/Oe),AC X'' Std Err. (emu/Oe),AC Drive (Oe),AC Frequency (Hz),AC Averaging Time (sec),AC Cycles,AC Range,AC Measure Type,AC Signal' (V),AC Signal'' (V),AC Trim Coil Ratio,AC Trim Coil Phase,Min. Temperature (K),Max. Temperature (K),Min. Field (Oe),Max. Field (Oe),Mass (grams),Motor Lag (deg),Pressure (Torr),Measure Count,Measurement Number,SQUID Status (code),Motor Status (code),Measure Status (code),Motor Current (amps),Motor Temp. (C),Temp. Status (code),Field Status (code),Chamber Status (code),Chamber Temp (K),Redirection State,Average Temp (K),Rotation Angle (deg),Rotator state,DC Moment Fixed Ctr (emu),DC Moment Err Fixed Ctr (emu),DC Moment Free Ctr (emu),DC Moment Err Free Ctr (emu),DC Fixed Fit,DC Free Fit,DC Calculated Center (mm),DC Calculated Center Err (mm),DC Scan Length (mm),DC Scan Time (s),DC Number of Points,DC Squid Drift,DC Min V (V),DC Max V (V),DC Scans per Measure,Map 01,Map 02,Map 03,Map 04,Map 05,Map 06,Map 07,Map 08,Map 09,Map 10,Map 11,Map 12,Map 13,Map 14,Map 15,Map 16
,3772394850.47443,39.9375171661377,200.004211425781,,,5,,,,6.47999998182058,,,,,0.000687189085219075,9.183442535751E-8,0.0387131247532704,7.55332684091397E-5,0.000687083288896284,9.18202869715586E-8,0.000687083132058549,7.57588162619399E-8,4.64242554706195E-7,5.18803128183418E-8,1.00015397889092,10.005763053894,2,20,10,3,2.24778938069987,0.199361733110116,0.0403775237500668,172.74836730957,39.909107208252,39.9499359130859,200.004211425781,200.004211425781,,,22.6880588531494,0,1,,,,,,1,1,1,39.9306564331055,0,39.9261573791504,,,,,,,,,,,,,,,,,,,,,,,,,,,,,,,,,
,3772394872.31135,39.8952293395996,180.187149047852,,,5,,,,6.47999998182058,,,,,0.00067956830829465,1.42644062865699E-7,0.145393365849348,0.00014761077414566,0.000679463130671915,1.42621985668681E-7,0.000679460943013137,1.0141306080882E-7,1.72419899606488E-6,1.00281712657213E-7,1.00015479518753,10.005763053894,2,20,10,3,2.22249396763179,0.201242476577324,0.0403775237500668,172.74836730957,39.8945693969727,39.8995246887207,180.187149047852,180.187149047852,,,22.6571216583252,0,1,,,,,,1,1,1,39.8954315185547,0,39.8964649200439,,,,,,,,,,,,,,,,,,,,,,,,,,,,,,,,,
,3772394893.87666,39.9138927459717,160.357940673828,,,5,,,,6.47999998182058,,,,,0.00066944250724887,2.09545361297329E-7,0.178199058810108,0.000256759539695752,0.000669338785439795,2.09512894843942E-7,0.000669335548152874,1.19814504383103E-7,2.08174756169167E-6,1.71872445858317E-7,1.00015496159991,10.005763053894,2,20,10,3,2.18926721749064,0.199450791912957,0.0403775237500668,172.74836730957,39.9111366271973,39.9196739196777,160.357940673828,160.357940673828,,,22.619010925293,0,1,,,,,,1,1,1,39.9150466918945,0,39.9156524658203,,,,,,,,,,,,,,,,,,,,,,,,,,,,,,,,,
,3772394915.85845,39.9230365753174,140.322311401367,,,5,,,,6.47999998182058,,,,,0.000655797790123085,8.64471487657373E-8,0.151127615895899,5.95610882414482E-5,0.000655696283863206,8.64337682285038E-8,0.000655694002917896,7.71317282038027E-8,1.72951135440588E-6,3.90063173662092E-8,1.00015480682501,10.005763053894,2,20,10,3,2.14474017074973,0.194326132210197,0.0403775237500668,172.74836730957,39.9208831787109,39.944953918457,140.322311401367,140.322311401367,,,22.5910911560059,0,1,,,,,,1,1,1,39.924690246582,0,39.9304237365723,,,,,,,,,,,,,,,,,,,,,,,,,,,,,,,,,
,3772394936.42063,39.9661712646484,120.189521789551,,,5,,,,6.47999998182058,,,,,0.000639963227820554,9.43935749744702E-8,0.108633702373536,8.84518632687115E-5,0.000639864156294221,9.43789620793191E-8,0.000639863006178462,7.55413587549339E-8,1.21319181374211E-6,5.65764226566855E-8,1.00015483212391,10.005763053894,2,20,10,3,2.09309733622152,0.188036265643867,0.0403775237500668,172.74836730957,39.9638061523438,39.9687271118164,120.189521789551,120.189521789551,,,22.6045513153076,0,1,,,,,,1,1,1,39.9671440124512,0,39.9670307159424,,,,,,,,,,,,,,,,,,,,,,,,,,,,,,,,,
,3772394957.1098,39.9680118560791,100.348175048828,,,5,,,,6.47999998182058,,,,,0.000624913976564369,7.9600303717383E-8,0.0879728697332647,9.62103006342993E-5,0.000624817325433942,7.95879924879576E-8,0.000624816588929728,5.21634462046489E-8,9.59354284855687E-7,6.01100942298205E-8,1.0001546870205,10.005763053894,2,20,10,3,2.04394529649831,0.182834001969237,0.0403775237500668,172.74836730957,39.9671936035156,39.9693870544434,100.348175048828,100.348175048828,,,22.6047306060791,0,1,,,,,,1,1,1,39.9672546386719,0,39.968166698109,,,,,,,,,,,,,,,,,,,,,,,,,,,,,,,,,
,3772394978.44347,39.9699020385742,80.3003997802734,,,5,,,,6.47999998182058,,,,,0.000612938903895472,6.33711245093664E-8,0.0655523975805652,9.78810777364712E-5,0.000612844051835807,6.33613178522187E-8,0.000612843650736576,2.03913092754571E-8,7.01157895361445E-7,5.99904251193684E-8,1.00015477356659,10.005763053894,2,20,10,3,2.00485040945296,0.178502851729384,0.0403775237500668,172.74836730957,39.9692039489746,39.9800605773926,80.3003997802734,80.3003997802734,,,22.6177711486816,0,1,,,,,,1,1,1,39.9702835083008,0,39.973021697998,,,,,,,,,,,,,,,,,,,,,,,,,,,,,,,,,
,3772395000.38182,39.9942493438721,60.240478515625,,,5,,,,6.47999998182058,,,,,0.000603882034963522,3.04934763394416E-8,0.0527398461553599,3.00146391492357E-5,0.000603788603830557,3.0488758464298E-8,0.000603788348038333,2.45221298581824E-8,5.55777648025505E-7,1.81171062786731E-8,1.00015474146476,10.005763053894,2,20,10,3,1.97526842339548,0.175380960111722,0.0403775237500668,172.74836730957,39.9927978515625,39.9969482421875,60.240478515625,60.240478515625,,,22.6428279876709,0,1,,,,,,1,1,1,39.9950218200684,0,39.9952667236328,,,,,,,,,,,,,,,,,,,,,,,,,,,,,,,,,
,3772395021.16922,40.0095195770264,40.192699432373,,,5,,,,6.47999998182058,,,,,0.000597116133254901,3.3635593035436E-8,0.0494263093825671,2.67397306439485E-5,0.000597023742334263,3.36303886484941E-8,0.000597023520191238,2.96050711840083E-8,5.15023563484466E-7,1.59543975391915E-8,1.00015475250662,10.005763053894,2,20,10,3,1.95315015498283,0.17326101421502,0.0403775237500668,172.74836730957,40.0069770812988,40.0096168518066,40.192699432373,40.192699432373,,,22.6557712554932,0,1,,,,,,1,1,1,40.009635925293,0,40.0087142944336,,,,,,,,,,,,,,,,,,,,,,,,,,,,,,,,,
,3772395043.88787,40.0113143920898,20.2906341552734,,,5,,,,6.47999998182058,,,,,0.000592675545282986,4.16219385860798E-8,0.0505198759316583,1.53537994232577E-5,0.000592583860710259,4.16154998360998E-8,0.000592583630354497,4.06168414311079E-8,5.22503742813521E-7,9.06211999306214E-9,1.00015471999628,10.005763053894,2,20,10,3,1.9386244228914,0.171968216606726,0.0403775237500668,172.74836730957,40.0079689025879,40.0117874145508,20.2906341552734,20.2906341552734,,,22.6688327789307,0,1,,,,,,1,1,1,40.010986328125,0,40.0101570129394,,,,,,,,,,,,,,,,,,,,,,,,,,,,,,,,,
,3772395064.48931,40.0179080963135,0.157856523990631,,,5,,,,6.47999998182058,,,,,0.000590158288555986,1.24318847482753E-7,0.0674433092976816,3.19355330333147E-5,0.000590067018267935,1.24299621086649E-7,0.000590066609474631,1.22891091277945E-7,6.94572332682788E-7,1.86594610533191E-8,1.00015467783358,10.005763053894,2,20,10,3,1.93034251021851,0.171766347752992,0.0403775237500668,172.74836730957,40.0117073059082,40.0186424255371,0.157856523990631,0.157856523990631,,,22.6805477142334,0,1,,,,,,1,1,1,40.0174026489258,0,40.0157741546631,,,,,,,,,,,,,,,,,,,,,,,,,,,,,,,,,
,3772395087.50802,40.0084495544434,-19.8292083740234,,,5,,,,6.47999998182058,,,,,0.000589925227069049,1.77922881185624E-7,0.063831656907241,5.39849379086087E-5,0.000589833977680372,1.77895360148389E-7,0.000589833611641914,1.75061356108118E-7,6.57117725375381E-7,3.16272154941232E-8,1.00015470351341,10.005763053894,2,20,10,3,1.92958844934237,0.171617579731342,0.0403775237500668,172.74836730957,40.0059013366699,40.0095176696777,-19.8292083740234,-19.8292083740234,,,22.6827297210693,0,1,,,,,,1,1,1,40.0080642700195,0,40.0076456936923,,,,,,,,,,,,,,,,,,,,,,,,,,,,,,,,,
,3772395107.99135,40.0044689178467,-39.9255561828613,,,5,,,,6.47999998182058,,,,,0.000592496064468775,1.6390740698357E-7,0.0493524566981964,4.60002576891009E-5,0.000592404457447847,1.63882064926193E-7,0.000592404237681807,1.61632806314679E-7,5.10275136618159E-7,2.70585869423059E-8,1.00015463594133,10.005763053894,2,20,10,3,1.93803829188029,0.171917430576825,0.0403775237500668,172.74836730957,40.0021858215332,40.0051002502441,-39.9255561828613,-39.9255561828613,,,22.7061767578125,0,1,,,,,,1,1,1,40.004207611084,0,40.0036018371582,,,,,,,,,,,,,,,,,,,,,,,,,,,,,,,,,
,3772395129.59008,40.0005359649658,-59.7911911010742,,,5,,,,6.47999998182058,,,,,0.000596754826248348,1.38189474692277E-7,0.0329706712622384,4.35611846383341E-5,0.000596662531360218,1.38168102125946E-7,0.000596662432571109,1.35724905240786E-7,3.43347507572814E-7,2.58684081935002E-8,1.00015468524212,10.005763053894,2,20,10,3,1.95201541892135,0.172636574142272,0.0403775237500668,172.74836730957,39.9992790222168,40.0016403198242,-59.7911911010742,-59.7911911010742,,,22.7073593139648,0,1,,,,,,1,1,1,39.999885559082,0,40.0001331329346,,,,,,,,,,,,,,,,,,,,,,,,,,,,,,,,,
,3772395151.52756,40.0201148986816,-79.8632583618164,,,5,,,,6.47999998182058,,,,,0.000603114059023716,1.4156423221856E-7,0.0349272106847334,9.84915148221589E-5,0.000603020724153489,1.41542324456595E-7,0.000603020612110478,1.28500073601346E-7,3.67598290036535E-7,5.9346109367209E-8,1.00015477887656,10.005763053894,2,20,10,3,1.97280820045303,0.174585851081387,0.0403775237500668,172.74836730957,40.0129737854004,40.0212669372559,-79.8632583618164,-79.8632583618164,,,22.7087478637695,0,1,,,,,,1,1,1,40.0189628601074,0,40.0174236297607,,,,,,,,,,,,,,,,,,,,,,,,,,,,,,,,,
,3772395173.11867,40.0065689086914,-99.9110336303711,,,5,,,,6.47999998182058,,,,,0.000612538979708367,1.37439937680753E-7,0.0274690823092882,6.51110696918321E-5,0.000612444285162814,1.3741869035957E-7,0.000612444214777895,1.31526945206857E-7,2.9362165900334E-7,3.98065213839608E-8,1.00015461740414,10.005763053894,2,20,10,3,2.00365783535419,0.17709640634105,0.0403775237500668,172.74836730957,40.004768371582,40.0084114074707,-99.9110336303711,-99.9110336303711,,,22.708911895752,0,1,,,,,,1,1,1,40.0054779052734,0,40.005802154541,,,,,,,,,,,,,,,,,,,,,,,,,,,,,,,,,
,3772395195.13185,40.0041809082031,-119.825241088867,,,5,,,,6.47999998182058,,,,,0.000624552287070456,2.02123067747391E-7,0.0283158422304535,8.82090893409524E-5,0.00062445573200529,2.02091819753617E-7,0.0006244556557473,1.94472131108247E-7,3.08608931021823E-7,5.49699357244051E-8,1.00015462275421,10.005763053894,2,20,10,3,2.0429488174337,0.180643425179395,0.0403775237500668,172.74836730957,40.0017547607422,40.004997253418,-119.825241088867,-119.825241088867,,,22.7324600219727,0,1,,,,,,1,1,1,40.0038070678711,0,40.0032717386881,,,,,,,,,,,,,,,,,,,,,,,,,,,,,,,,,
,3772395218.16404,40.0007038116455,-139.873016357422,,,5,,,,6.47999998182058,,,,,0.000639699165864756,2.54570624994057E-7,0.0371864023769657,8.57740692250642E-5,0.000639600224233745,2.54531250809771E-7,0.000639600089523179,2.48593268944241E-7,4.15116607734124E-7,5.46584327839951E-8,1.00015469292734,10.005763053894,2,20,10,3,2.09246370470434,0.18539334046344,0.0403775237500668,172.74836730957,39.999584197998,40.0015258789063,-139.873016357422,-139.873016357422,,,22.7453422546387,0,1,,,,,,1,1,1,40.0006256103516,0,40.0003007253011,,,,,,,,,,,,,,,,,,,,,,,,,,,,,,,,,
,3772395241.20149,40.0009822845459,-159.920791625977,,,5,,,,6.47999998182058,,,,,0.000660051667220338,2.30512449040237E-7,0.0577937655998966,8.38818564975694E-5,0.000659949569274909,2.30476792971763E-7,0.000659949233539277,2.23777182954591E-7,6.65685405988919E-7,5.51663347292187E-8,1.0001547056778,10.005763053894,2,20,10,3,2.15896512627463,0.192114609038895,0.0403775237500668,172.74836730957,40.0007133483887,40.0010719299316,-159.920791625977,-159.920791625977,,,22.7455062866211,0,1,,,,,,1,1,1,40.0009269714355,0,40.0009235035289,,,,,,,,,,,,,,,,,,,,,,,,,,,,,,,,,
,3772395262.68104,40.0192165374756,-179.96858215332,,,5,,,,6.47999998182058,,,,,0.000687222551722069,3.94294866744304E-7,0.065977310915784,0.00017231302655603,0.000687116228907461,3.94233863885895E-7,0.000687115773348998,3.76117463238257E-7,7.91228803174171E-7,1.18135486969924E-7,1.00015473774325,10.005763053894,2,20,10,3,2.24780683807337,0.200392099427594,0.0403775237500668,172.74836730957,40.0139083862305,40.0201148986816,-179.96858215332,-179.96858215332,,,22.747142791748,0,1,,,,,,1,1,1,40.0181846618652,0,40.0173468156294,,,,,,,,,,,,,,,,,,,,,,,,,,,,,,,,,
,3772395284.73209,40.0078735351562,-199.858489990234,,,5,,,,6.47999998182058,,,,,0.000720049086889366,3.44878678914155E-7,0.059699151515014,0.000134064672421159,0.000719937728981064,3.44825342316691E-7,0.000719937338179808,3.31112231659974E-7,7.50136644482992E-7,9.62767196625187E-8,1.00015467713917,10.005763053894,2,20,10,3,2.355197570988,0.209756392558028,0.0403775237500668,172.74836730957,40.0044364929199,40.0096588134766,-199.858489990234,-199.858489990234,,,22.7578182220459,0,1,,,,,,1,1,1,40.0071907043457,0,40.0067958831787,,,,,,,,,,,,,,,,,,,,,,,,,,,,,,,,,
,3772395306.24607,40.0016536712646,-219.869857788086,,,5,,,,6.47999998182058,,,,,0.000754989964502538,3.51404247682419E-7,0.0399053696848339,0.000131000915079638,0.000754873244696248,3.51349921350086E-7,0.000754873061607594,3.3720784088052E-7,5.2575414306928E-7,9.86794775087993E-8,1.00015462172903,10.005763053894,2,20,10,3,2.4695576659077,0.219134779167182,0.0403775237500668,172.74836730957,39.9998397827148,40.0028648376465,-219.869857788086,-219.869857788086,,,22.758882522583,0,1,,,,,,1,1,1,40.0011711120605,0,40.0010344765403,,,,,,,,,,,,,,,,,,,,,,,,,,,,,,,,,
,3772395328.41792,40.0165252685547,-239.808349609375,,,5,,,,6.47999998182058,,,,,0.000782698151174772,3.41820588691135E-7,0.00347048629421209,0.000219556573780405,0.000782577063645779,3.41767707244589E-7,0.000782577062210182,2.95474093382996E-7,4.7401798089972E-8,1.71756297860427E-7,1.00015472920766,10.005763053894,2,20,10,3,2.56033118065317,0.225603429047771,0.0403775237500668,172.74836730957,40.012378692627,40.0165939331055,-239.808349609375,-239.808349609375,,,22.7489891052246,0,1,,,,,,1,1,1,40.0164909362793,0,40.0151683807373,,,,,,,,,,,,,,,,,,,,,,,,,,,,,,,,,
,3772395350.0664,40.0256443023682,-259.892547607422,,,5,,,,6.47999998182058,,,,,0.000801060974944142,2.65216877983271E-7,-0.0281603081359432,0.000179965478874639,0.000800937079603238,2.65175858464734E-7,0.000800936982865053,2.22600214510264E-7,-3.93652625773608E-7,1.44108918573742E-7,1.00015468798244,10.005763053894,2,20,10,3,2.62052253296114,0.229505879723229,0.0403775237500668,172.74836730957,40.0189743041992,40.0264434814453,-259.892547607422,-259.892547607422,,,22.7497463226318,0,1,,,,,,1,1,1,40.0248489379883,0,40.0232093811035,,,,,,,,,,,,,,,,,,,,,,,,,,,,,,,,,
,3772395371.97557,40.033088684082,-279.758178710938,,,5,,,,6.47999998182058,,,,,0.000812006915700386,3.85508712340951E-7,-0.054321230546325,0.000170592829204913,0.000811881423124268,3.85449133437751E-7,0.000811881058238847,3.59722348801892E-7,-7.69731937144399E-7,1.38458897295779E-7,1.0001545700795,10.005763053894,2,20,10,3,2.65643265089999,0.231485436064574,0.0403775237500668,172.74836730957,40.0220909118652,40.0355567932129,-279.758178710938,-279.758178710938,,,22.7614727020264,0,1,,,,,,1,1,1,40.0315856933594,0,40.0292446136475,,,,,,,,,,,,,,,,,,,,,,,,,,,,,,,,,
,3772395393.82718,40.0099029541016,-299.793823242188,,,5,,,,6.47999998182058,,,,,0.000818384512758671,3.11615614941069E-7,-0.0806777189656902,0.000227646597148526,0.000818257964769825,3.11567429364791E-7,0.00081825715358068,2.49767340551896E-7,-1.15218197342266E-6,1.86253962735341E-7,1.00015465537067,10.005763053894,2,20,10,3,2.67740011728276,0.23212959380226,0.0403775237500668,172.74836730957,40.006763458252,40.0119171142578,-299.793823242188,-299.793823242188,,,22.7618579864502,0,1,,,,,,1,1,1,40.0093879699707,0,40.0088874816895,,,,,,,,,,,,,,,,,,,,,,,,,,,,,,,,,
,3772395415.49615,39.9987010955811,-319.80517578125,,,5,,,,6.47999998182058,,,,,0.00082163224712268,4.61397914405569E-7,-0.0938239294303615,0.00026997951590509,0.000821505241402903,4.61326592747458E-7,0.000821504139959423,4.04518950582558E-7,-1.34524420478832E-6,2.21780620874694E-7,1.00015460122879,10.005763053894,2,20,10,3,2.68807520956439,0.232491723956955,0.0403775237500668,172.74836730957,39.9969902038574,40.0004196166992,-319.80517578125,-319.80517578125,,,22.7619972229004,0,1,,,,,,1,1,1,39.9980239868164,0,39.9980407714844,,,,,,,,,,,,,,,,,,,,,,,,,,,,,,,,,
,3772395437.16808,40.0020618438721,-339.74365234375,,,5,,,,6.47999998182058,,,,,0.000823510990769188,3.63736570563483E-7,-0.104379295949167,0.000282063750830671,0.000823383567956464,3.63680289181168E-7,0.000823382201626661,2.79883068251647E-7,-1.50000838300721E-6,2.32225797113375E-7,1.00015475510768,10.005763053894,2,20,10,3,2.69426118111208,0.232584435133054,0.0403775237500668,172.74836730957,40.001708984375,40.0031051635742,-339.74365234375,-339.74365234375,,,22.7502117156982,0,1,,,,,,1,1,1,40.0023422241211,0,40.0024215698242,,,,,,,,,,,,,,,,,,,,,,,,,,,,,,,,,
,3772395459.00308,40.003475189209,-359.791412353516,,,5,,,,6.47999998182058,,,,,0.000824453547614338,3.71315147244301E-7,-0.120723333249535,0.000212512595293086,0.000824326020149381,3.71257711771356E-7,0.000824324190339267,3.27322181976819E-7,-1.73686983664184E-6,1.751926874491E-7,1.00015470513103,10.005763053894,2,20,10,3,2.69740776095393,0.23213906052851,0.0403775237500668,172.74836730957,40.0018577575684,40.0041427612305,-359.791412353516,-359.791412353516,,,22.7517337799072,0,1,,,,,,1,1,1,40.0030860900879,0,40.0028217315674,,,,,,,,,,,,,,,,,,,,,,,,,,,,,,,,,
,3772395480.90844,40.0060043334961,-379.875640869141,,,5,,,,6.47999998182058,,,,,0.000824258704829265,3.80338153333433E-7,-0.108401082457367,0.000222133822380175,0.000824131206586113,3.80279321748071E-7,0.000824129731599063,3.33313276516779E-7,-1.55921888738236E-6,1.83069992753653E-7,1.00015470624354,10.005763053894,2,20,10,3,2.69671681769937,0.232722105677903,0.0403775237500668,172.74836730957,40.0033531188965,40.0063323974609,-379.875640869141,-379.875640869141,,,22.7748413085938,0,1,,,,,,1,1,1,40.0059127807617,0,40.0051168961958,,,,,,,,,,,,,,,,,,,,,,,,,,,,,,,,,
,3772395502.69793,40.0024394989014,-399.899139404297,,,5,,,,6.47999998182058,,,,,0.000824896714279415,5.04732815202923E-7,-0.161822136943364,0.000389370415945162,0.000824769157370435,5.04654766452512E-7,0.000824765867848955,3.89298797450421E-7,-2.32941642867444E-6,3.21127513002071E-7,1.00015465770978,10.005763053894,2,20,10,3,2.69901672784378,0.230443722918893,0.0403775237500668,172.74836730957,40.0009880065918,40.0026588439941,-399.899139404297,-399.899139404297,,,22.7753124237061,0,1,,,,,,1,1,1,40.0023651123047,0,40.0019786834717,,,,,,,,,,,,,,,,,,,,,,,,,,,,,,,,,
,3772395523.97222,40.0113410949707,-419.7890625,,,5,,,,6.47999998182058,,,,,0.000824673372366993,4.19225476133522E-7,-0.168285890183853,0.000377169134969125,0.000824545797636119,4.1916062309099E-7,0.000824542241039439,2.81077716435085E-7,-2.42180532708283E-6,3.10951676750046E-7,1.00015472121893,10.005763053894,2,20,10,3,2.69830854298128,0.230134265780486,0.0403775237500668,172.74836730957,40.0083923339844,40.0114250183105,-419.7890625,-419.7890625,,,22.7762336730957,0,1,,,,,,1,1,1,40.0112380981445,0,40.010382565585,,,,,,,,,,,,,,,,,,,,,,,,,,,,,,,,,
,3772395546.10375,40.0056190490723,-439.861114501953,,,5,,,,6.47999998182058,,,,,0.000824371879168338,5.77723394745665E-7,-0.18965899808347,0.000293942856976781,0.000824244377957405,5.77634041343061E-7,0.000824239862234961,5.24303335208605E-7,-2.72838730435758E-6,2.4241926162632E-7,1.00015468860249,10.005763053894,2,20,10,3,2.69740427481272,0.229101937087522,0.0403775237500668,172.74836730957,40.0033073425293,40.0067825317383,-439.861114501953,-439.861114501953,,,22.7649116516113,0,1,,,,,,1,1,1,40.0050964355469,0,40.0047233581543,,,,,,,,,,,,,,,,,,,,,,,,,,,,,,,,,
,3772395567.80286,40.0023422241211,-460.163879394531,,,5,,,,6.47999998182058,,,,,0.000824191467296507,6.7431656805703E-7,-0.207936503265828,0.000378169779966359,0.000824064023112299,6.74212298929863E-7,0.000824058596276391,5.97791426890364E-7,-2.99066731866509E-6,3.11781388098572E-7,1.00015465325586,10.005763053894,2,20,10,3,2.6968834482649,0.228250121424264,0.0403775237500668,172.74836730957,40.0013542175293,40.0025901794434,-460.163879394531,-460.163879394531,,,22.7657985687256,0,1,,,,,,1,1,1,40.0023651123047,0,40.0019443511963,,,,,,,,,,,,,,,,,,,,,,,,,,,,,,,,,
,3772395589.76212,40.0215244293213,-480.235931396484,,,5,,,,6.47999998182058,,,,,0.00082344326908103,5.46287874835804E-7,-0.210568729857093,0.000313378343436985,0.000823315878464805,5.46203361486039E-7,0.000823310318417367,4.81364151329369E-7,-3.02577589510542E-6,2.58121416999064E-7,1.00015472872509,10.005763053894,2,20,10,3,2.69444232707715,0.227976806829204,0.0403775237500668,172.74836730957,40.0154647827148,40.0217018127441,-480.235931396484,-480.235931396484,,,22.7650413513184,0,1,,,,,,1,1,1,40.0213470458984,0,40.0194309234619,,,,,,,,,,,,,,,,,,,,,,,,,,,,,,,,,
,3772395611.31877,40.0076084136963,-500.125915527344,,,5,,,,6.47999998182058,,,,,0.000822927342678466,5.38773956756107E-7,-0.239753077958699,0.000390381522770927,0.000822800084303398,5.38690640168225E-7,0.000822792880749399,4.324246679358E-7,-3.44298094451484E-6,3.21242139772268E-7,1.00015466500004,10.005763053894,2,20,10,3,2.69286648867683,0.226519818865656,0.0403775237500668,172.74836730957,40.0053787231445,40.0084075927734,-500.125915527344,-500.125915527344,,,22.777458190918,0,1,,,,,,1,1,1,40.0071983337402,0,40.0067058563232,,,,,,,,,,,,,,,,,,,,,,,,,,,,,,,,,
,3772395633.32431,40.0060520172119,-520.076538085937,,,5,,,,6.47999998182058,,,,,0.000822426213002169,6.23380946953396E-7,-0.2553597198255,0.000354722789648045,0.000822298996418046,6.23284519585901E-7,0.000822290829493048,5.5072077123651E-7,-3.6648658584321E-6,2.91873644723349E-7,1.00015470842683,10.005763053894,2,20,10,3,2.69128487964442,0.225706291546846,0.0403775237500668,172.74836730957,40.004150390625,40.0071678161621,-520.076538085937,-520.076538085937,,,22.7779445648193,0,1,,,,,,1,1,1,40.0053749084473,0,40.0053393046061,,,,,,,,,,,,,,,,,,,,,,,,,,,,,,,,,
,3772395656.37347,40.0022926330566,-540.197143554687,,,5,,,,6.47999998182058,,,,,0.000821680887196597,5.46320751328288E-7,-0.272571521626166,0.000378390318033759,0.000821553833086894,5.4623627535014E-7,0.000821544536556277,4.49097108128352E-7,-3.90833907188641E-6,3.10943493225288E-7,1.00015465098523,10.005763053894,2,20,10,3,2.68891018043882,0.224751928175517,0.0403775237500668,172.74836730957,40.0011138916016,40.0027809143066,-540.197143554687,-540.197143554687,,,22.7781982421875,0,1,,,,,,1,1,1,40.0022773742676,0,40.0019246881658,,,,,,,,,,,,,,,,,,,,,,,,,,,,,,,,,
,3772395678.09168,40.0019817352295,-560.062805175781,,,5,,,,6.47999998182058,,,,,0.000820531274409961,6.78818895067565E-7,-0.291290561669935,0.000418583150800479,0.000820404409738255,6.78713940949476E-7,0.000820393807327731,5.85314281304546E-7,-4.17090113579816E-6,3.4359832033948E-7,1.00015463675012,10.005763053894,2,20,10,3,2.68521804258307,0.223617296268776,0.0403775237500668,172.74836730957,40.0002822875977,40.0028190612793,-560.062805175781,-560.062805175781,,,22.7887725830078,0,1,,,,,,1,1,1,40.0015754699707,0,40.0012786865234,,,,,,,,,,,,,,,,,,,,,,,,,,,,,,,,,
,3772395699.94185,40.0007381439209,-580.171264648438,,,5,,,,6.47999998182058,,,,,0.000819339511216345,7.48635856093533E-7,-0.322543840119698,0.000597590182264157,0.000819212783504972,7.48520064156984E-7,0.000819199802813796,5.66216805871387E-7,-4.61169467798307E-6,4.89572073544212E-7,1.00015469449931,10.005763053894,2,20,10,3,2.68143608177285,0.221887597063235,0.0403775237500668,172.74836730957,40.0003395080566,40.0009346008301,-580.171264648438,-580.171264648438,,,22.7898750305176,0,1,,,,,,1,1,1,40.0008583068848,0,40.0006374359131,,,,,,,,,,,,,,,,,,,,,,,,,,,,,,,,,
,3772395721.50948,40.0161018371582,-600.255493164062,,,5,,,,6.47999998182058,,,,,0.000817772163127821,7.39739529705124E-7,-0.326485452341216,0.000532180615151852,0.000817645665314131,7.39625102438671E-7,0.000817632390869135,5.98000583779897E-7,-4.65912101247661E-6,4.35247738599888E-7,1.00015470981998,10.005763053894,2,20,10,3,2.67631863472262,0.221336388831318,0.0403775237500668,172.74836730957,40.0107727050781,40.0169982910156,-600.255493164062,-600.255493164062,,,22.7791156768799,0,1,,,,,,1,1,1,40.0156059265137,0,40.0141345977783,,,,,,,,,,,,,,,,,,,,,,,,,,,,,,,,,
,3772395743.6179,40.0051460266113,-620.266845703125,,,5,,,,6.47999998182058,,,,,0.000811441701374312,3.76355002223003E-7,-0.122611948399945,0.000365341154650073,0.000811316217574186,3.76296801546608E-7,0.000811314359853921,2.31876722103268E-7,-1.73620094052976E-6,2.96365430846533E-7,1.00015466694417,10.005763053894,2,20,10,3,2.65479924232363,0.229127889734875,0.0403775237500668,172.74836730957,40.002197265625,40.0066146850586,-620.266845703125,-620.266845703125,,,22.7682781219482,0,1,,,,,,1,1,1,40.0046920776367,0,40.0036493028913,,,,,,,,,,,,,,,,,,,,,,,,,,,,,,,,,
,3772395769.97331,40.0051422119141,-640.132507324219,,,5,,,,6.47999998182058,,,,,0.0008104013154451,6.01506929371852E-7,-0.34717742040855,0.000483487369763636,0.000810275992674906,6.01413910625161E-7,0.000810261117594356,4.56295567549165E-7,-4.90974745284363E-6,3.91781886932556E-7,1.0001546667695,10.005763053894,2,20,10,3,2.65226875289311,0.218496875445463,0.0403775237500668,172.74836730957,40.0008850097656,40.0069847106934,-640.132507324219,-640.132507324219,,,22.7676239013672,0,1,,,,,,1,1,1,40.0040664672852,0,40.0033916126598,,,,,,,,,,,,,,,,,,,,,,,,,,,,,,,,,
,3772395792.14989,40.0056762695313,-660.216674804687,,,5,,,,6.47999998182058,,,,,0.000801959075668345,8.5092238957957E-7,-0.377410996900687,0.000619423605450033,0.000801834946878051,8.50790682152026E-7,0.000801817551364666,6.90640376353787E-7,-5.28170034163586E-6,4.96850737532519E-7,1.00015480591209,10.005763053894,2,20,10,3,2.62474970224612,0.214892119238826,0.0403775237500668,172.74836730957,40.0048942565918,40.006591796875,-660.216674804687,-660.216674804687,,,22.7904777526855,0,1,,,,,,1,1,1,40.0059242248535,0,40.0059577941895,,,,,,,,,,,,,,,,,,,,,,,,,,,,,,,,,
,3772395813.77175,40.0023708343506,-680.167297363281,,,5,,,,6.47999998182058,,,,,0.000784740824116967,8.73565740776779E-7,-0.40799553006669,0.000617427106873136,0.000784619479132076,8.73430660737156E-7,0.000784599586474803,7.26587659892239E-7,-5.58712243088911E-6,4.84717950573388E-7,1.00015465456584,10.005763053894,2,20,10,3,2.56850454679512,0.208962163182126,0.0403775237500668,172.74836730957,40.0008125305176,40.0025367736816,-680.167297363281,-680.167297363281,,,22.7795028686523,0,1,,,,,,1,1,1,40.0023651123047,0,40.0018272399902,,,,,,,,,,,,,,,,,,,,,,,,,,,,,,,,,
,3772395835.66916,40.0012893676758,-700.239379882813,,,5,,,,6.47999998182058,,,,,0.000744720733064579,6.23569940237206E-7,-0.171327243324016,0.000267927687729333,0.000744605527892208,6.23473476584107E-7,0.000744602198970922,5.90620105410194E-7,-2.22653437007127E-6,1.99717468162212E-7,1.00015471973824,10.005763053894,2,20,10,3,2.43667331271784,0.208424678385326,0.0403775237500668,172.74836730957,40.0008163452148,40.001522064209,-700.239379882813,-700.239379882813,,,22.7796306610107,0,1,,,,,,1,1,1,40.0014305114746,0,40.0011772742638,,,,,,,,,,,,,,,,,,,,,,,,,,,,,,,,,
,3772395861.32862,40.0099658966064,-720.129333496094,,,5,,,,6.47999998182058,,,,,0.000657878626014626,8.38460641755839E-7,-0.507815914651641,0.000688566138170451,0.000657776895389369,8.38330986950276E-7,0.000657751060112161,7.05196106448236E-7,-5.82983956947198E-6,4.5331809486416E-7,1.00015465825262,10.005763053894,2,20,10,3,2.15357383859258,0.1715214069597,0.0403775237500668,172.74836730957,40.006778717041,40.0101051330566,-720.129333496094,-720.129333496094,,,22.8133163452148,0,1,,,,,,1,1,1,40.0099563598633,0,40.0088130950928,,,,,,,,,,,,,,,,,,,,,,,,,,,,,,,,,
,3772395886.23112,40.0035190582275,-740.140686035156,,,5,,,,6.47999998182058,,,,,0.000478660648584239,8.90163199697537E-7,-0.631808454915892,0.00106334593248789,0.0004785866626995,8.90025608458135E-7,0.000478557565459449,7.29887340837599E-7,-5.27733411583809E-6,5.09323132594909E-7,1.00015459245003,10.005763053894,2,20,1,3,1.5671662352634,0.121438298831399,0.0403775237500668,172.74836730957,40.0026931762695,40.005012512207,-740.140686035156,-740.140686035156,,,22.8024711608887,0,1,,,,,,1,1,1,40.0032653808594,0,40.0035068805401,,,,,,,,,,,,,,,,,,,,,,,,,,,,,,,,,
,3772395908.56583,40.0013217926025,-760.139831542969,,,5,,,,6.47999998182058,,,,,0.00031685135594101,9.05872828955518E-7,-1.08971090881194,0.00164363628677069,0.000316802339895568,9.05732692885665E-7,0.00031674504411691,7.40558815905987E-7,-6.02491416399311E-6,5.21463662344598E-7,1.00015472122289,10.005763053894,2,20,1,3,1.03800037909198,0.0721155709919354,0.0403775237500668,172.74836730957,40.0002593994141,40.0015754699707,-760.139831542969,-760.139831542969,,,22.8017425537109,0,1,,,,,,1,1,1,40.0013122558594,0,40.0010646473278,,,,,,,,,,,,,,,,,,,,,,,,,,,,,,,,,
,3772395930.47006,40.000602722168,-780.199768066406,,,5,,,,6.47999998182058,,,,,0.000203164846995741,1.16936662769326E-6,-1.73166183878018,0.00343571456969587,0.000203133424631867,1.16918576833584E-6,0.000203040656407558,9.37130563993713E-7,-6.13840763216523E-6,6.99129220464931E-7,1.00015468829874,10.005763053894,2,20,1,3,0.66604088680839,0.0387948979446192,0.0403775237500668,172.74836730957,40.0001678466797,40.000862121582,-780.199768066406,-780.199768066406,,,22.8139972686768,0,1,,,,,,1,1,1,40.0004005432129,0,40.0004737854004,,,,,,,,,,,,,,,,,,,,,,,,,,,,,,,,,
,3772395952.32136,40.0030384063721,-800.150451660156,,,5,,,,6.47999998182058,,,,,0.00013954607807514,9.85481443670593E-7,-2.68667417311916,0.00385222464861671,0.000139524511709641,9.85329140909387E-7,0.000139371146916459,8.24379064507534E-7,-6.54008983153985E-6,5.39696835201868E-7,1.00015457044239,10.005763053894,2,20,1,3,0.457858161914558,0.0190278389151459,0.0403775237500668,172.74836730957,39.9995460510254,40.0046577453613,-800.150451660156,-800.150451660156,,,22.8139724731445,0,1,,,,,,1,1,1,40.0024452209473,0,40.0017105102539,,,,,,,,,,,,,,,,,,,,,,,,,,,,,,,,,
,3772395974.03671,40.009765625,-820.173950195313,,,5,,,,6.47999998182058,,,,,9.65925986663954E-5,1.22594160378681E-6,-3.88136463869389,0.00564059629899738,9.65776519446473E-5,1.22575190179842E-6,9.63561364133221E-5,1.09498937577163E-6,-6.53741773475668E-6,5.50877474316833E-7,1.00015476377244,10.005763053894,2,20,1,3,0.317131246162014,0.00656699391946386,0.0403775237500668,172.74836730957,40.0082664489746,40.0111503601074,-820.173950195313,-820.173950195313,,,22.8148822784424,0,1,,,,,,1,1,1,40.0106391906738,0,40.0102550506592,,,,,,,,,,,,,,,,,,,,,,,,,,,,,,,,,
,3772395995.68958,40.0060253143311,-840.233825683594,,,5,,,,6.47999998182058,,,,,6.69397339681032E-5,1.00062103897099E-6,-5.27587828142425,0.00927435108938404,6.69293871858414E-5,1.00046637435846E-6,6.66458407214227E-5,7.83477089112665E-7,-6.15424923179308E-6,6.2217089055782E-7,1.00015459251454,10.005763053894,2,20,1,3,0.219821245986547,-0.000794190400025318,0.0403775237500668,172.74836730957,40.0033531188965,40.0073699951172,-840.233825683594,-840.233825683594,,,22.8029117584229,0,1,,,,,,1,1,1,40.0052757263184,0,40.0048847198486,,,,,,,,,,,,,,,,,,,,,,,,,,,,,,,,,
,3772396017.59436,40.0245342254639,-860.135864257812,,,5,,,,6.47999998182058,,,,,4.99590172423595E-5,9.68196876655919E-7,-7.5661734526057,0.00908247851565396,4.99512871885048E-5,9.68047069585812E-7,4.9516383791077E-5,8.53334425700309E-7,-6.57714436843603E-6,4.57094614766355E-7,1.00015475184504,10.005763053894,2,20,1,3,0.163904315740824,-0.00714499442921182,0.0403775237500668,172.74836730957,40.0181045532227,40.0247764587402,-860.135864257812,-860.135864257812,,,22.815502166748,0,1,,,,,,1,1,1,40.0243492126465,0,40.0224300384521,,,,,,,,,,,,,,,,,,,,,,,,,,,,,,,,,
,3772396038.36634,40.0122241973877,-880.207946777344,,,5,,,,6.47999998182058,,,,,3.95532428016756E-5,1.03341719898258E-6,-10.0293927040429,0.0137564458331177,3.95471314935058E-5,1.03325752734699E-6,3.89427936649351E-5,8.78444464425311E-7,-6.88726585336481E-6,5.44018787120211E-7,1.00015453227425,10.005763053894,2,20,1,3,0.129402601014831,-0.0112258487664934,0.0403775237500668,172.74836730957,40.0050773620605,40.0145301818848,-880.207946777344,-880.207946777344,,,22.8030776977539,0,1,,,,,,1,1,1,40.0109786987305,0,40.0092995383523,,,,,,,,,,,,,,,,,,,,,,,,,,,,,,,,,
,3772396061.11158,40.0207080841064,-899.903564453125,,,5,,,,6.47999998182058,,,,,3.41682856641209E-5,1.12929461634263E-6,-12.1624222398294,0.0190601166854446,3.41630009434855E-5,1.12911995125639E-6,3.33961878794495E-5,9.24673569179237E-7,-7.19758769207455E-6,6.47989702685592E-7,1.00015469134705,10.005763053894,2,20,1,3,0.111347102929032,-0.0138490813774461,0.0403775237500668,172.74836730957,40.0171241760254,40.0208892822266,-899.903564453125,-899.903564453125,,,22.8030052185059,0,1,,,,,,1,1,1,40.0208892822266,0,40.0196717002175,,,,,,,,,,,,,,,,,,,,,,,,,,,,,,,,,
,3772396082.46847,40.0178260803223,-919.914916992188,,,5,,,,6.47999998182058,,,,,2.87687468372225E-5,1.21957085221386E-6,-14.2810629670274,0.0252404053058826,2.87643010444396E-5,1.21938238521793E-6,2.78754069101639E-5,9.85252396598245E-7,-7.09554114694137E-6,7.18450496817412E-7,1.0001545593886,10.005763053894,2,20,1,3,0.0932563776274984,-0.0151164555592609,0.0403775237500668,172.74836730957,40.0092315673828,40.0204544067383,-919.914916992188,-919.914916992188,,,22.7923641204834,0,1,,,,,,1,1,1,40.0163993835449,0,40.0149213617498,,,,,,,,,,,,,,,,,,,,,,,,,,,,,,,,,
,3772396104.67764,40.0097427368164,-939.816955566406,,,5,,,,6.47999998182058,,,,,2.67458285691119E-5,9.94941930222376E-7,-16.1671493586639,0.0197579307338009,2.67416899523184E-5,9.94787974125246E-7,2.56841493869355E-5,8.53654250500951E-7,-7.44596882719143E-6,5.10761719460133E-7,1.00015476272445,10.005763053894,2,20,1,3,0.086189814058643,-0.0168975563020335,0.0403775237500668,172.74836730957,40.0086708068848,40.0100784301758,-939.816955566406,-939.816955566406,,,22.7927227020264,0,1,,,,,,1,1,1,40.009937286377,0,40.0094295501709,,,,,,,,,,,,,,,,,,,,,,,,,,,,,,,,,
,3772396126.18093,40.0009078979492,-959.840515136719,,,5,,,,6.47999998182058,,,,,2.25355129984846E-5,1.18110819356838E-6,-16.7274460053155,0.0290550036656796,2.25320298264708E-5,1.18092563712933E-6,2.15785809596146E-5,9.96586463666746E-7,-6.48515318788447E-6,6.33561978708888E-7,1.00015458758224,10.005763053894,2,20,1,3,0.0724795154676323,-0.0149454853760558,0.0403775237500668,172.74836730957,39.9985466003418,40.0026779174805,-959.840515136719,-959.840515136719,,,22.7924022674561,0,1,,,,,,1,1,1,40.0001640319824,0,40.0000322515314,,,,,,,,,,,,,,,,,,,,,,,,,,,,,,,,,
,3772396148.34379,40.0090179443359,-979.851867675781,,,5,,,,6.47999998182058,,,,,2.1235151758978E-5,7.65430871720341E-7,-18.3864050328906,0.0261457239646876,2.12318665620671E-5,7.65312455277462E-7,2.01479984829503E-5,5.29119496942766E-7,-6.69703776609148E-6,5.52933732157707E-7,1.00015472953832,10.005763053894,2,20,1,3,0.0678612920345689,-0.0160529705602352,0.0403775237500668,172.74836730957,40.0080642700195,40.0095710754395,-979.851867675781,-979.851867675781,,,22.8133659362793,0,1,,,,,,1,1,1,40.0094223022461,0,40.0088861638849,,,,,,,,,,,,,,,,,,,,,,,,,,,,,,,,,
,3772396171.33928,40.0072174072266,-999.960327148438,,,5,,,,6.47999998182058,,,,,2.03252373739106E-5,1.11048877623228E-6,-20.5235068725666,0.0306387053379416,2.03220946209727E-5,1.11031706892083E-6,1.90322193701915E-5,9.50807411585229E-7,-7.12475653118582E-6,5.73384041992396E-7,1.00015464709699,10.005763053894,2,20,1,3,0.0643357357329502,-0.0177752184158214,0.0403775237500668,172.74836730957,40.0040397644043,40.0081405639648,-999.960327148438,-999.960327148438,,,22.8034286499023,0,1,,,,,,1,1,1,40.0068740844727,0,40.0060585021973,,,,,,,,,,,,,,,,,,,,,,,,,,,,,,,,,