File: Experimental_Data/AC_Suceptibillity_FieldScans/FCd_Up_40K.dat
[Header]
; MPMS3 Data File (default extension .dat)
; Copyright (c) 2007, Quantum Design, Inc. All rights reserved.
TITLE,FCd_Up_40K
FILEOPENTIME,3772396337.73368,07/15/2019,11:52 pm
BYAPP,SQUID AC,0.9.1.0
INFO,MPMS3 Measurement Release 1.1.16 Build 347, MultiVu Release 2.3.3.2,APPNAME
INFO,0,MOMENT_UNITS
INFO,Cu2OSeO3,SAMPLE_MATERIAL
INFO,,SAMPLE_COMMENT
INFO,,SAMPLE_MASS
INFO,,SAMPLE_VOLUME
INFO,,SAMPLE_MOLECULAR_WEIGHT
INFO,,SAMPLE_SIZE
INFO,,SAMPLE_SHAPE
INFO,Quartz,SAMPLE_HOLDER
INFO,Standard,SAMPLE_HOLDER_DETAIL
INFO,64.77,SAMPLE_OFFSET
DATATYPE,COMMENT,1
DATATYPE,TIME,2
STARTUPAXIS,X,2
STARTUPAXIS,Y1,5
FIELDGROUP, VSM,2,3,4,5,6,8,9,10,11,14,15
FIELDGROUP, DC, 2,3,4,14,56,57,58,59,60,61,62,63,64,65,66,67,68,69
FIELDGROUP, AC, 2,3,4,11,16,17,18,19,20,21,22,23,24,25,26,27,28,29,30
STARTUPGROUP, All
[Data]
Comment,Time Stamp (sec),Temperature (K),Magnetic Field (Oe),Moment (emu),M. Std. Err. (emu),Transport Action,Averaging Time (sec),Frequency (Hz),Peak Amplitude (mm),Center Position (mm),Lockin Signal' (V),Lockin Signal (V),Range,M. Quad. Signal (emu),AC Moment (emu),AC M. Std Err. (emu),AC Phase (deg),AC Phase Std. Err. (deg),AC Susceptibility (emu/Oe),AC Suscept. Std Err. (emu/Oe),AC X' (emu/Oe),AC X' Std Err. (emu/Oe),AC X'' (emu/Oe),AC X'' Std Err. (emu/Oe),AC Drive (Oe),AC Frequency (Hz),AC Averaging Time (sec),AC Cycles,AC Range,AC Measure Type,AC Signal' (V),AC Signal'' (V),AC Trim Coil Ratio,AC Trim Coil Phase,Min. Temperature (K),Max. Temperature (K),Min. Field (Oe),Max. Field (Oe),Mass (grams),Motor Lag (deg),Pressure (Torr),Measure Count,Measurement Number,SQUID Status (code),Motor Status (code),Measure Status (code),Motor Current (amps),Motor Temp. (C),Temp. Status (code),Field Status (code),Chamber Status (code),Chamber Temp (K),Redirection State,Average Temp (K),Rotation Angle (deg),Rotator state,DC Moment Fixed Ctr (emu),DC Moment Err Fixed Ctr (emu),DC Moment Free Ctr (emu),DC Moment Err Free Ctr (emu),DC Fixed Fit,DC Free Fit,DC Calculated Center (mm),DC Calculated Center Err (mm),DC Scan Length (mm),DC Scan Time (s),DC Number of Points,DC Squid Drift,DC Min V (V),DC Max V (V),DC Scans per Measure,Map 01,Map 02,Map 03,Map 04,Map 05,Map 06,Map 07,Map 08,Map 09,Map 10,Map 11,Map 12,Map 13,Map 14,Map 15,Map 16
,3772396488.46338,39.915225982666,200.210632324219,,,5,,,,6.47999998182058,,,,,0.000688617286904144,1.25660714805604E-7,0.0354379200117298,0.000101719380922073,0.000688511183797372,1.25641352828359E-7,0.000688511052101497,1.04327493672022E-7,4.258499126859E-7,7.00108820445386E-8,1.00015410513187,10.005763053894,2,20,10,3,2.2524723846557,0.199647987871365,0.0403775237500668,172.74836730957,39.9008560180664,39.9284782409668,200.210632324219,200.210632324219,,,23.0843181610107,0,1,,,,,,1,1,1,39.910961151123,0,39.909854888916,,,,,,,,,,,,,,,,,,,,,,,,,,,,,,,,,
,3772396513.30065,39.9037055969238,200.198501586914,,,5,,,,6.47999998182058,,,,,0.000688462314964109,9.63838584272193E-8,0.0344759539778181,0.000122289051880028,0.00068835573049606,9.63689367357111E-8,0.000688355605881083,4.69146726105476E-8,4.14196634630958E-7,8.41782956670935E-8,1.00015483922531,10.005763053894,2,20,10,3,2.25196881746105,0.199565280060567,0.0403775237500668,172.74836730957,39.9027976989746,39.9091300964355,200.198501586914,200.198501586914,,,23.0426464080811,0,1,,,,,,1,1,1,39.9041557312012,0,39.9054058074951,,,,,,,,,,,,,,,,,,,,,,,,,,,,,,,,,
,3772396535.23787,39.920690536499,220.027694702148,,,5,,,,6.47999998182058,,,,,0.000693123703591285,1.29985910283178E-7,0.0323844299569114,9.57317827466173E-5,0.000693016414881836,1.2996578974699E-7,0.000693016304183584,1.11774516953682E-7,3.91703202966977E-7,6.63141302011095E-8,1.00015481409552,10.005763053894,2,20,10,3,2.26722061453864,0.200881677945679,0.0403775237500668,172.74836730957,39.9180679321289,39.9266395568848,220.027694702148,220.027694702148,,,23.0411205291748,0,1,,,,,,1,1,1,39.9215850830078,0,39.9226020812988,,,,,,,,,,,,,,,,,,,,,,,,,,,,,,,,,
,3772396556.8388,39.9506549835205,240.087615966797,,,5,,,,6.47999998182058,,,,,0.000698114557696505,1.20495392963777E-7,0.0260687409014091,0.000151195170248199,0.000698006339357568,1.20476714351316E-7,0.000698006267109837,5.81132699872748E-8,3.17582655041743E-7,1.0553429088346E-7,1.0001550391921,10.005763053894,2,20,10,3,2.2835650437038,0.202125154530579,0.0403775237500668,172.74836730957,39.9457855224609,39.9629974365234,240.087615966797,240.087615966797,,,23.0398616790771,0,1,,,,,,1,1,1,39.9533309936523,0,39.955358505249,,,,,,,,,,,,,,,,,,,,,,,,,,,,,,,,,
,3772396578.76322,39.9693641662598,260.038269042969,,,5,,,,6.47999998182058,,,,,0.000703436206553063,1.1153676209849E-7,0.0104544226492349,0.000100738434973743,0.000703327367389231,1.11519504573486E-7,0.00070332735568124,8.61305414893563E-8,1.28331992009669E-7,7.08387586217186E-8,1.00015474893894,10.005763053894,2,20,10,3,2.3010247775954,0.203087845987497,0.0403775237500668,172.74836730957,39.9685401916504,39.9695014953613,260.038269042969,260.038269042969,,,23.0279769897461,0,1,,,,,,1,1,1,39.9694213867188,0,39.9691495028409,,,,,,,,,,,,,,,,,,,,,,,,,,,,,,,,,
,3772396601.8216,39.967752456665,279.976776123047,,,5,,,,6.47999998182058,,,,,0.000708155004593793,1.23038413599968E-7,0.00640500842817282,0.000130113455979475,0.000708045487556518,1.23019385558874E-7,0.000708045483132414,8.15358845140166E-8,7.91513326884447E-8,9.21176897224405E-8,1.00015467514334,10.005763053894,2,20,10,3,2.31647190484157,0.204335934060052,0.0403775237500668,172.74836730957,39.9672737121582,39.9722862243652,279.976776123047,279.976776123047,,,23.0527935028076,0,1,,,,,,1,1,1,39.9675102233887,0,39.9685356140137,,,,,,,,,,,,,,,,,,,,,,,,,,,,,,,,,
,3772396623.47228,39.9951248168945,300.012390136719,,,5,,,,6.47999998182058,,,,,0.000711839715057747,1.92269165614169E-7,-0.000688537935236155,0.000218288095162878,0.000711729470839009,1.92239388455769E-7,0.000711729470787617,1.13233011677787E-7,-8.55303382641865E-9,1.55352076073113E-7,1.00015489623973,10.005763053894,2,20,10,3,2.32854743314638,0.205160528513806,0.0403775237500668,172.74836730957,39.9932022094727,39.9984931945801,300.012390136719,300.012390136719,,,23.0781707763672,0,1,,,,,,1,1,1,39.995979309082,0,39.9963340759277,,,,,,,,,,,,,,,,,,,,,,,,,,,,,,,,,
,3772396645.39007,40.0167865753174,320.084442138672,,,5,,,,6.47999998182058,,,,,0.000715122874790168,1.57627841869801E-7,-0.00208930041833977,0.000125347287737003,0.000715012314951012,1.57603472199276E-7,0.000715012314475633,1.29654413559054E-7,-2.60730465857973E-8,8.96023855370256E-8,1.00015462648243,10.005763053894,2,20,10,3,2.33928913696112,0.206099648376549,0.0403775237500668,172.74836730957,40.0106391906738,40.0176124572754,320.084442138672,320.084442138672,,,23.1038055419922,0,1,,,,,,1,1,1,40.0162696838379,0,40.0144823247736,,,,,,,,,,,,,,,,,,,,,,,,,,,,,,,,,
,3772396668.41703,40.006233215332,339.974395751953,,,5,,,,6.47999998182058,,,,,0.000717708116227504,1.33376746568349E-7,-0.00698832646238134,0.000100397304069927,0.000717597091956739,1.33356114147327E-7,0.000717597086619068,1.12233196056933E-7,-8.75248190570538E-8,7.20247379955047E-8,1.00015471672337,10.005763053894,2,20,10,3,2.34776047387732,0.206694048718233,0.0403775237500668,172.74836730957,40.0036506652832,40.0069160461426,339.974395751953,339.974395751953,,,23.1057376861572,0,1,,,,,,1,1,1,40.0061149597168,0,40.0053512573242,,,,,,,,,,,,,,,,,,,,,,,,,,,,,,,,,
,3772396690.2715,40.0094871520996,360.046447753906,,,5,,,,6.47999998182058,,,,,0.000719325223366651,1.37107255354981E-7,-0.00997787542435002,0.000153820962737132,0.000719214006750498,1.37086056869935E-7,0.00071921399584466,8.09647577320978E-8,-1.25248801700886E-7,1.10622307847603E-7,1.00015463633231,10.005763053894,2,20,10,3,2.35305801645539,0.207087506320148,0.0403775237500668,172.74836730957,40.0057563781738,40.0100212097168,360.046447753906,360.046447753906,,,23.1186790466309,0,1,,,,,,1,1,1,40.0091819763184,0,40.0080958279696,,,,,,,,,,,,,,,,,,,,,,,,,,,,,,,,,
,3772396713.07801,40.0032501220703,380.09423828125,,,5,,,,6.47999998182058,,,,,0.00072033052335896,1.97372436708329E-7,-0.0264107482897682,0.000225333680373217,0.000720219191778179,1.97341931565663E-7,0.00072021911526243,1.1229428950056E-7,-3.31988276894948E-7,1.62277017780188E-7,1.00015458013623,10.005763053894,2,20,10,3,2.35640281102926,0.206751715607834,0.0403775237500668,172.74836730957,40.0011444091797,40.0044784545898,380.09423828125,380.09423828125,,,23.1315155029297,0,1,,,,,,1,1,1,40.0027809143066,0,40.0024486541748,,,,,,,,,,,,,,,,,,,,,,,,,,,,,,,,,
,3772396735.11025,40.0018253326416,399.874847412109,,,5,,,,6.47999998182058,,,,,0.000720983070257622,1.5466570051173E-7,-0.0452153506984105,0.000112661234978426,0.000720871602178127,1.54641788315576E-7,0.000720871377710125,1.31608919026455E-7,-5.68880626022962E-7,8.11983689868666E-8,1.0001546295889,10.005763053894,2,20,10,3,2.35860219908805,0.206214864016036,0.0403775237500668,172.74836730957,40.0008392333984,40.0025253295898,399.874847412109,399.874847412109,,,23.1438522338867,0,1,,,,,,1,1,1,40.0018348693848,0,40.0015077590942,,,,,,,,,,,,,,,,,,,,,,,,,,,,,,,,,
,3772396758.06289,39.9972190856934,420.031921386719,,,5,,,,6.47999998182058,,,,,0.000722098186055162,2.23558974254136E-7,-0.0501914736159632,0.000158896185300609,0.00072198653223755,2.23524406637961E-7,0.000721986255215906,1.91852183825315E-7,-6.32464793343101E-7,1.14699171419457E-7,1.00015464806146,10.005763053894,2,20,10,3,2.36226495429977,0.206379652001614,0.0403775237500668,172.74836730957,39.9965476989746,39.9981498718262,420.031921386719,420.031921386719,,,23.1537094116211,0,1,,,,,,1,1,1,39.9971008300781,0,39.9970911199396,,,,,,,,,,,,,,,,,,,,,,,,,,,,,,,,,
,3772396779.90742,40.0088386535645,440.298248291016,,,5,,,,6.47999998182058,,,,,0.000725863227405547,3.19612805168047E-7,-0.0502897626904959,0.000199532131415799,0.000725750938255767,3.19563361899955E-7,0.000725750658698047,2.84886612461691E-7,-6.37007438962524E-7,1.44776932930988E-7,1.00015472132912,10.005763053894,2,20,10,3,2.37457907969155,0.20750304323523,0.0403775237500668,172.74836730957,40.0073432922363,40.0089454650879,440.298248291016,440.298248291016,,,23.1683731079102,0,1,,,,,,1,1,1,40.008716583252,0,40.0081588745117,,,,,,,,,,,,,,,,,,,,,,,,,,,,,,,,,
,3772396801.64116,40.0244731903076,460.321746826172,,,5,,,,6.47999998182058,,,,,0.00073691381221849,2.89009935200105E-7,-0.0482956391055565,0.00014860494398719,0.000736799793150148,2.88965218106997E-7,0.000736799531398127,2.6743296125909E-7,-6.21061673156504E-7,1.09455509262068E-7,1.00015474905042,10.005763053894,2,20,10,3,2.41071931991175,0.210797499084821,0.0403775237500668,172.74836730957,40.0181770324707,40.0246353149414,460.321746826172,460.321746826172,,,23.1704864501953,0,1,,,,,,1,1,1,40.0241928100586,0,40.0227962493897,,,,,,,,,,,,,,,,,,,,,,,,,,,,,,,,,
,3772396823.24882,40.0134887695313,480.272369384766,,,5,,,,6.47999998182058,,,,,0.000755041326637083,2.60556899426981E-7,-0.0425450788149924,0.000205810444257103,0.000754924622707324,2.60516626116082E-7,0.000754924414581019,2.09132565738974E-7,-5.60570514858682E-7,1.55346330598248E-7,1.00015459017529,10.005763053894,2,20,10,3,2.46999622086423,0.216283712806729,0.0403775237500668,172.74836730957,40.0073852539063,40.0148887634277,480.272369384766,480.272369384766,,,23.1711540222168,0,1,,,,,,1,1,1,40.0127372741699,0,40.0111530303955,,,,,,,,,,,,,,,,,,,,,,,,,,,,,,,,,
,3772396845.15043,40.0039958953857,500.320159912109,,,5,,,,6.47999998182058,,,,,0.000775607721821263,3.79431866138513E-7,-0.0333201187473042,0.000303791248917555,0.000775487731401283,3.7937316611827E-7,0.000775487600268059,2.97389926634779E-7,-4.50981591672214E-7,2.35548786256183E-7,1.00015472897265,10.005763053894,2,20,10,3,2.53723670177923,0.222638057682966,0.0403775237500668,172.74836730957,40.0023460388184,40.0043716430664,500.320159912109,500.320159912109,,,23.1721534729004,0,1,,,,,,1,1,1,40.0037574768066,0,40.0032855987549,,,,,,,,,,,,,,,,,,,,,,,,,,,,,,,,,
,3772396866.83261,40.0011978149414,520.367919921875,,,5,,,,6.47999998182058,,,,,0.000793825957475301,3.66659496331735E-7,-0.0631844747680574,0.000223638235808136,0.000793703159257408,3.66602777182785E-7,0.000793702676639355,3.20781288558688E-7,-8.75277507365443E-7,1.77473832292984E-7,1.00015471554631,10.005763053894,2,20,10,3,2.59694881432366,0.226569765111053,0.0403775237500668,172.74836730957,40.0000915527344,40.0017204284668,520.367919921875,520.367919921875,,,23.1843814849854,0,1,,,,,,1,1,1,40.0009918212891,0,40.0007461547852,,,,,,,,,,,,,,,,,,,,,,,,,,,,,,,,,
,3772396888.69396,40.0005855560303,540.415710449219,,,5,,,,6.47999998182058,,,,,0.000803722343823518,4.77774094047744E-7,-0.0739080580400167,0.000287642603731175,0.000803598037241883,4.77700199791996E-7,0.000803597368671507,4.18067564616529E-7,-1.03659212617645E-6,2.31121163671605E-7,1.00015468751275,10.005763053894,2,20,10,3,2.62936362735172,0.228958650721441,0.0403775237500668,172.74836730957,39.9997291564941,40.0010261535645,540.415710449219,540.415710449219,,,23.173490524292,0,1,,,,,,1,1,1,40.0002784729004,0,40.0002876281738,,,,,,,,,,,,,,,,,,,,,,,,,,,,,,,,,
,3772396910.40956,40.0161323547363,560.244934082031,,,5,,,,6.47999998182058,,,,,0.000807442307918353,4.82650252545598E-7,-0.100030315472002,0.000359806659441525,0.000807317406859596,4.82575592688217E-7,0.000807316176499541,3.85377194783236E-7,-1.4094611253404E-6,2.90454162303432E-7,1.00015471121729,10.005763053894,2,20,10,3,2.6416346374249,0.228869910710589,0.0403775237500668,172.74836730957,40.0123100280762,40.0162124633789,560.244934082031,560.244934082031,,,23.1742210388184,0,1,,,,,,1,1,1,40.0161933898926,0,40.0149700164795,,,,,,,,,,,,,,,,,,,,,,,,,,,,,,,,,
,3772396932.26706,40.0204925537109,580.353454589844,,,5,,,,6.47999998182058,,,,,0.000808994754906742,3.06997568356155E-7,-0.0979587806884119,0.000236604765276437,0.000808869730509912,3.06950124061146E-7,0.000808868548312624,2.39995656848057E-7,-1.38292653678301E-6,1.9136473905927E-7,1.00015456678883,10.005763053894,2,20,10,3,2.64670189019358,0.229462572222498,0.0403775237500668,172.74836730957,40.0128364562988,40.023063659668,580.353454589844,580.353454589844,,,23.1973495483398,0,1,,,,,,1,1,1,40.0191535949707,0,40.0174690246582,,,,,,,,,,,,,,,,,,,,,,,,,,,,,,,,,
,3772396955.31521,40.0111103057861,600.4619140625,,,5,,,,6.47999998182058,,,,,0.000808326969960463,4.21362387651414E-7,-0.117016204642513,0.000265209296257895,0.000808201932512723,4.212972084857E-7,0.000808200246982715,3.62694513405457E-7,-1.65060424670557E-6,2.14345580368297E-7,1.00015471065177,10.005763053894,2,20,10,3,2.64458984032086,0.228450542801925,0.0403775237500668,172.74836730957,40.0087661743164,40.0116119384766,600.4619140625,600.4619140625,,,23.1979484558105,0,1,,,,,,1,1,1,40.0109062194824,0,40.0102565765381,,,,,,,,,,,,,,,,,,,,,,,,,,,,,,,,,
,3772396978.36957,40.0008411407471,620.436828613281,,,5,,,,6.47999998182058,,,,,0.000805787232942788,5.28045254810875E-7,-0.145128267564859,0.000323495428223438,0.000805662597571199,5.2796357925949E-7,0.000805660013040282,4.5913096319375E-7,-2.04071387092465E-6,2.60661273804283E-7,1.00015469921524,10.005763053894,2,20,10,3,2.63638866016651,0.226495711624356,0.0403775237500668,172.74836730957,39.9998550415039,40.0020561218262,620.436828613281,620.436828613281,,,23.1988334655762,0,1,,,,,,1,1,1,40.0005722045898,0,40.0005489696156,,,,,,,,,,,,,,,,,,,,,,,,,,,,,,,,,
,3772397000.03668,40.0093326568604,640.375366210937,,,5,,,,6.47999998182058,,,,,0.000801080892024025,5.03338687451826E-7,-0.161756426537555,0.000304176550821259,0.000800956948783519,5.0326081088703E-7,0.000800953756828867,4.40329622495676E-7,-2.26124442044854E-6,2.43682718565527E-7,1.00015474394809,10.005763053894,2,20,10,3,2.6210522848639,0.224467995517907,0.0403775237500668,172.74836730957,40.0077056884766,40.0095863342285,640.375366210937,640.375366210937,,,23.2108039855957,0,1,,,,,,1,1,1,40.0095863342285,0,40.0088111877441,,,,,,,,,,,,,,,,,,,,,,,,,,,,,,,,,
,3772397021.93685,40.0230884552002,660.37451171875,,,5,,,,6.47999998182058,,,,,0.000791705892654088,6.86024001772276E-7,-0.173664697865963,0.000509931688972748,0.00079158344605619,6.85917900117769E-7,0.000791579809886011,5.54559689280846E-7,-2.39930219418915E-6,4.03666838775122E-7,1.00015468564749,10.005763053894,2,20,10,3,2.59042104281016,0.221357984284892,0.0403775237500668,172.74836730957,40.016716003418,40.023551940918,660.37451171875,660.37451171875,,,23.1995868682861,0,1,,,,,,1,1,1,40.0226249694824,0,40.0209167480469,,,,,,,,,,,,,,,,,,,,,,,,,,,,,,,,,
,3772397043.5809,40.008279800415,680.385864257812,,,5,,,,6.47999998182058,,,,,0.00077162678417089,5.2123582397472E-7,-0.192701288964312,0.000301083008617518,0.000771507523726851,5.2115526324628E-7,0.000771503160239363,4.66470817539764E-7,-2.59478473367408E-6,2.3239575037656E-7,1.00015458105122,10.005763053894,2,20,10,3,2.52479156315942,0.214959305937837,0.0403775237500668,172.74836730957,40.005241394043,40.0094184875488,680.385864257812,680.385864257812,,,23.199743270874,0,1,,,,,,1,1,1,40.0077323913574,0,40.0071147918701,,,,,,,,,,,,,,,,,,,,,,,,,,,,,,,,,
,3772397065.54983,40.0030002593994,700.312255859375,,,5,,,,6.47999998182058,,,,,0.000730394819577335,6.57895651435769E-7,-0.224067719629423,0.00060577095942711,0.000730281857107399,6.57793901648183E-7,0.000730276272748964,4.868369647E-7,-2.85592018657734E-6,4.42360245554718E-7,1.00015468338537,10.005763053894,2,20,10,3,2.38998708309825,0.202215576712506,0.0403775237500668,172.74836730957,40.0016174316406,40.0031318664551,700.312255859375,700.312255859375,,,23.2008819580078,0,1,,,,,,1,1,1,40.0030784606934,0,40.0024840615012,,,,,,,,,,,,,,,,,,,,,,,,,,,,,,,,,
,3772397088.60604,40.0013580322266,720.359985351562,,,5,,,,6.47999998182058,,,,,0.000621962264886847,6.16669910046794E-7,-0.252522275366299,0.000470277377649696,0.000621866047979565,6.16574511861231E-7,0.000621860008211372,5.42712293594214E-7,-2.74076943103045E-6,2.92621761081815E-7,1.00015472288219,10.005763053894,2,20,10,3,2.03525841443994,0.171228108922487,0.0403775237500668,172.74836730957,40.0004920959473,40.0021858215332,720.359985351562,720.359985351562,,,23.2009868621826,0,1,,,,,,1,1,1,40.0007476806641,0,40.0009945956143,,,,,,,,,,,,,,,,,,,,,,,,,,,,,,,,,
,3772397113.48497,40.0051612854004,740.347106933594,,,5,,,,6.47999998182058,,,,,0.000435071589099591,6.73369248935557E-7,-0.32888018722182,0.000984553826834243,0.000435004308008653,6.73265116606976E-7,0.00043499714174921,5.19445012557472E-7,-2.49692933513669E-6,4.28325572630182E-7,1.00015466764282,10.005763053894,2,20,1,3,1.42384929592558,0.117909510376597,0.0403775237500668,172.74836730957,40.0031471252441,40.0061912536621,740.347106933594,740.347106933594,,,23.2129535675049,0,1,,,,,,1,1,1,40.0047721862793,0,40.0047349196214,,,,,,,,,,,,,,,,,,,,,,,,,,,,,,,,,
,3772397136.05668,40.0210990905762,760.431335449219,,,5,,,,6.47999998182058,,,,,0.000282333692154742,6.46240732911763E-7,-0.568788322922559,0.00107676638532198,0.000282290019277553,6.46140768957947E-7,0.000282276109568694,5.69883714219077E-7,-2.80231163223243E-6,3.04516741046262E-7,1.00015470925009,10.005763053894,2,20,1,3,0.924298558045258,0.0726659839102368,0.0403775237500668,172.74836730957,40.0149612426758,40.0215225219727,760.431335449219,760.431335449219,,,23.2133979797363,0,1,,,,,,1,1,1,40.020866394043,0,40.019034576416,,,,,,,,,,,,,,,,,,,,,,,,,,,,,,,,,
,3772397157.76688,40.0188503265381,780.30908203125,,,5,,,,6.47999998182058,,,,,0.00017975803155176,8.09712028348577E-7,-0.944929414750657,0.00230022012643394,0.000179730223516246,8.09586768294015E-7,0.000179705781628399,6.95509492042336E-7,-2.96399975136115E-6,4.14363707237687E-7,1.00015472097552,10.005763053894,2,20,1,3,0.588778820105373,0.0424136355435545,0.0403775237500668,172.74836730957,40.012638092041,40.0196151733398,780.30908203125,780.30908203125,,,23.2138614654541,0,1,,,,,,1,1,1,40.0185470581055,0,40.0166458129883,,,,,,,,,,,,,,,,,,,,,,,,,,,,,,,,,
,3772397179.3154,40.006031036377,800.381103515625,,,5,,,,6.47999998182058,,,,,0.000121391939853845,9.17506502514468E-7,-1.35757089725789,0.00417749353698436,0.000121373162519409,9.17364579364829E-7,0.000121339094088789,7.63754233347021E-7,-2.87555658525247E-6,5.08170485681443E-7,1.00015470746618,10.005763053894,2,20,1,3,0.397802363553091,0.0257865424608456,0.0403775237500668,172.74836730957,40.0037651062012,40.0066184997559,800.381103515625,800.381103515625,,,23.2022800445557,0,1,,,,,,1,1,1,40.0057067871094,0,40.0051956176758,,,,,,,,,,,,,,,,,,,,,,,,,,,,,,,,,
,3772397201.28511,40.0022583007812,820.392456054687,,,5,,,,6.47999998182058,,,,,8.02341985172869E-5,6.94852280657066E-7,-2.01421764904404,0.00396116452859848,8.02217922641834E-5,6.9474483877539E-7,8.01722261165006E-5,6.16686366989295E-7,-2.8195945812279E-6,3.19950489567663E-7,1.00015464941325,10.005763053894,2,20,1,3,0.263106019464449,0.0140349107856162,0.0403775237500668,172.74836730957,40.0009117126465,40.0029525756836,820.392456054687,820.392456054687,,,23.2028827667236,0,1,,,,,,1,1,1,40.0020408630371,0,40.0016622543335,,,,,,,,,,,,,,,,,,,,,,,,,,,,,,,,,
,3772397224.27883,40.0012340545654,840.513122558594,,,5,,,,6.47999998182058,,,,,5.34147667896555E-5,7.20546673699729E-7,-3.19242402732316,0.0064951242006471,5.34065038846127E-5,7.20435209977213E-7,5.33236242800119E-5,6.29938920758478E-7,-2.97418069748188E-6,3.49576669542684E-7,1.00015471720562,10.005763053894,2,20,1,3,0.175314123066998,0.00574369190985598,0.0403775237500668,172.74836730957,40.0005416870117,40.0013542175293,840.513122558594,840.513122558594,,,23.2146148681641,0,1,,,,,,1,1,1,40.0013275146484,0,40.0009750366211,,,,,,,,,,,,,,,,,,,,,,,,,,,,,,,,,
,3772397245.8932,40.0114574432373,860.318054199219,,,5,,,,6.47999998182058,,,,,3.80606720486003E-5,7.57843389193138E-7,-4.32149014732663,0.0101835758861336,3.80547839633121E-5,7.5772614884318E-7,3.79465919606327E-5,6.49518503163831E-7,-2.86753222607975E-6,3.90223821272527E-7,1.00015472654618,10.005763053894,2,20,1,3,0.12497643727386,0.00163300536117443,0.0403775237500668,172.74836730957,40.0083999633789,40.0117874145508,860.318054199219,860.318054199219,,,23.2265567779541,0,1,,,,,,1,1,1,40.0111274719238,0,40.0103477478027,,,,,,,,,,,,,,,,,,,,,,,,,,,,,,,,,
,3772397267.87637,40.0133762359619,880.390075683594,,,5,,,,6.47999998182058,,,,,2.84979824264094E-5,7.30731608471701E-7,-5.99625080397409,0.0115539505638588,2.84935744786325E-5,7.30618581987197E-7,2.83376785289858E-5,6.50404685962287E-7,-2.97653526053926E-6,3.3283217516232E-7,1.0001546997124,10.005763053894,2,20,1,3,0.0935721319155513,-0.00151065667502799,0.0403775237500668,172.74836730957,40.0087432861328,40.0145492553711,880.390075683594,880.390075683594,,,23.2153053283691,0,1,,,,,,1,1,1,40.0128746032715,0,40.0118183135986,,,,,,,,,,,,,,,,,,,,,,,,,,,,,,,,,
,3772397289.6904,40.0049057006836,900.243530273437,,,5,,,,6.47999998182058,,,,,2.14180706467244E-5,7.38325725174534E-7,-8.64179781773053,0.0137217423681955,2.14147587270763E-5,7.3821155637211E-7,2.11716376243316E-5,6.76135026777558E-7,-3.21770906746924E-6,2.96306813161365E-7,1.00015465594034,10.005763053894,2,20,1,3,0.0701982617498635,-0.00437867843690462,0.0403775237500668,172.74836730957,40.0033721923828,40.0053787231445,900.243530273437,900.243530273437,,,23.2150363922119,0,1,,,,,,1,1,1,40.0049362182617,0,40.0043510437012,,,,,,,,,,,,,,,,,,,,,,,,,,,,,,,,,
,3772397311.39652,40.0109710693359,920.169921875,,,5,,,,6.47999998182058,,,,,1.74719713092881E-5,8.70750348437763E-7,-9.91881438697942,0.0261028589340816,1.74692687387062E-5,8.70615660471865E-7,1.72081523674902E-5,7.41561402907285E-7,-3.00912651152808E-6,4.56134096485936E-7,1.00015470427654,10.005763053894,2,20,1,3,0.057171128777641,-0.00484606507405355,0.0403775237500668,172.74836730957,40.0077285766602,40.011043548584,920.169921875,920.169921875,,,23.2273197174072,0,1,,,,,,1,1,1,40.010913848877,0,40.0099653764205,,,,,,,,,,,,,,,,,,,,,,,,,,,,,,,,,
,3772397332.9314,40.0040493011475,940.157043457031,,,5,,,,6.47999998182058,,,,,1.45570063943701E-5,6.69372957159414E-7,-12.5696878895103,0.0276425037919271,1.45547559856183E-5,6.69269476902538E-7,1.4205908077325E-5,5.3627321691043E-7,-3.16750651135594E-6,4.00415620996405E-7,1.00015461672831,10.005763053894,2,20,1,3,0.0473953402052784,-0.00623525315630423,0.0403775237500668,172.74836730957,40.0006828308105,40.0063858032227,940.157043457031,940.157043457031,,,23.2273139953613,0,1,,,,,,1,1,1,40.0025482177734,0,40.0027035799893,,,,,,,,,,,,,,,,,,,,,,,,,,,,,,,,,
,3772397355.05198,40.0156784057617,960.216918945313,,,5,,,,6.47999998182058,,,,,1.17122902469501E-5,8.35738049554226E-7,-17.0405034570583,0.0405717453999829,1.17104774050667E-5,8.35608693048556E-7,1.11963620822129E-5,6.97380195752846E-7,-3.43172801640277E-6,4.60328958973948E-7,1.000154805122,10.005763053894,2,20,1,3,0.0376264829158524,-0.00797324820778299,0.0403775237500668,172.74836730957,40.0137825012207,40.0166015625,960.216918945313,960.216918945313,,,23.2164211273193,0,1,,,,,,1,1,1,40.0163421630859,0,40.0155200958252,,,,,,,,,,,,,,,,,,,,,,,,,,,,,,,,,
,3772397376.69972,40.0079307556152,980.264709472656,,,5,,,,6.47999998182058,,,,,1.03449385546958E-5,1.08149240467625E-6,-19.243281849425,0.0499623239120114,1.03433398356555E-5,1.08132526956084E-6,9.76543335352951E-6,9.78703665185408E-7,-3.40895737339607E-6,4.59786335533653E-7,1.00015456506948,10.005763053894,2,20,1,3,0.032938732595101,-0.00831388761587991,0.0403775237500668,172.74836730957,40.003490447998,40.0105133056641,980.264709472656,980.264709472656,,,23.2160377502441,0,1,,,,,,1,1,1,40.0063743591309,0,40.0060764312744,,,,,,,,,,,,,,,,,,,,,,,,,,,,,,,,,
,3772397398.60788,40.022123336792,1000.13031005859,,,5,,,,6.47999998182058,,,,,9.29599483471454E-6,7.75793547148604E-7,-21.4996824381954,0.0496584959955353,9.29455751079358E-6,7.75673595853141E-7,8.64783847486747E-6,6.47529322452921E-7,-3.406418798981E-6,4.27054216543289E-7,1.00015464145757,10.005763053894,2,20,1,3,0.0292819597890743,-0.0086298281153902,0.0403775237500668,172.74836730957,40.0157890319824,40.0228805541992,1000.13031005859,1000.13031005859,,,23.2160415649414,0,1,,,,,,1,1,1,40.021671295166,0,40.0200660705566,,,,,,,,,,,,,,,,,,,,,,,,,,,,,,,,,