File: Experimental_Data/AC_Suceptibillity_FieldScans/FCd_Up_48K.dat
[Header]
; MPMS3 Data File (default extension .dat)
; Copyright (c) 2007, Quantum Design, Inc. All rights reserved.
TITLE,FC_Up_48K
FILEOPENTIME,3762231310.7058,03/20/2019,8:15 am
BYAPP,SQUID AC,0.9.1.0
INFO,MPMS3 Measurement Release 1.1.16 Build 347, MultiVu Release 2.3.3.2,APPNAME
INFO,0,MOMENT_UNITS
INFO,SrM,SAMPLE_MATERIAL
INFO,MvsH,SAMPLE_COMMENT
INFO,,SAMPLE_MASS
INFO,,SAMPLE_VOLUME
INFO,,SAMPLE_MOLECULAR_WEIGHT
INFO,,SAMPLE_SIZE
INFO,,SAMPLE_SHAPE
INFO,Quartz,SAMPLE_HOLDER
INFO,Standard,SAMPLE_HOLDER_DETAIL
INFO,65.34,SAMPLE_OFFSET
DATATYPE,COMMENT,1
DATATYPE,TIME,2
STARTUPAXIS,X,2
STARTUPAXIS,Y1,5
FIELDGROUP, VSM,2,3,4,5,6,8,9,10,11,14,15
FIELDGROUP, DC, 2,3,4,14,56,57,58,59,60,61,62,63,64,65,66,67,68,69
FIELDGROUP, AC, 2,3,4,11,16,17,18,19,20,21,22,23,24,25,26,27,28,29,30
STARTUPGROUP, All
[Data]
Comment,Time Stamp (sec),Temperature (K),Magnetic Field (Oe),Moment (emu),M. Std. Err. (emu),Transport Action,Averaging Time (sec),Frequency (Hz),Peak Amplitude (mm),Center Position (mm),Lockin Signal' (V),Lockin Signal (V),Range,M. Quad. Signal (emu),AC Moment (emu),AC M. Std Err. (emu),AC Phase (deg),AC Phase Std. Err. (deg),AC Susceptibility (emu/Oe),AC Suscept. Std Err. (emu/Oe),AC X' (emu/Oe),AC X' Std Err. (emu/Oe),AC X'' (emu/Oe),AC X'' Std Err. (emu/Oe),AC Drive (Oe),AC Frequency (Hz),AC Averaging Time (sec),AC Cycles,AC Range,AC Measure Type,AC Signal' (V),AC Signal'' (V),AC Trim Coil Ratio,AC Trim Coil Phase,Min. Temperature (K),Max. Temperature (K),Min. Field (Oe),Max. Field (Oe),Mass (grams),Motor Lag (deg),Pressure (Torr),Measure Count,Measurement Number,SQUID Status (code),Motor Status (code),Measure Status (code),Motor Current (amps),Motor Temp. (C),Temp. Status (code),Field Status (code),Chamber Status (code),Chamber Temp (K),Redirection State,Average Temp (K),Rotation Angle (deg),Rotator state,DC Moment Fixed Ctr (emu),DC Moment Err Fixed Ctr (emu),DC Moment Free Ctr (emu),DC Moment Err Free Ctr (emu),DC Fixed Fit,DC Free Fit,DC Calculated Center (mm),DC Calculated Center Err (mm),DC Scan Length (mm),DC Scan Time (s),DC Number of Points,DC Squid Drift,DC Min V (V),DC Max V (V),DC Scans per Measure,Map 01,Map 02,Map 03,Map 04,Map 05,Map 06,Map 07,Map 08,Map 09,Map 10,Map 11,Map 12,Map 13,Map 14,Map 15,Map 16
,3762231455.42328,47.9158916473389,220.513397216797,,,5,,,,31.6299982368946,,,,,0.000748595810046282,9.54206938150057E-8,0.0158178398938578,0.000109314867915423,0.000748477294664272,9.54055871047792E-8,0.000748477266141106,4.90727264832388E-8,2.06634658982035E-7,8.18174404776198E-8,1.00015834198693,10.005763053894,2,20,10,3,2.44873849653662,0.216196154793304,0.0413267537951469,172.859115600586,47.8966064453125,47.9304313659668,220.513397216797,220.513397216797,,,23.6237277984619,0,1,,,,,,1,1,1,47.9105987548828,0,47.9086339314779,,,,,,,,,,,,,,,,,,,,,,,,,,,,,,,,,
,3762231481.63482,47.893533706665,240.330474853516,,,5,,,,31.6299982368946,,,,,0.000753289587338255,7.93511410775531E-8,0.00790370449556477,9.14076583605329E-5,0.000753169803502861,7.93385231094026E-8,0.000753169796336824,3.94359407164584E-8,1.03896510241746E-7,6.88433571885421E-8,1.00015903961475,10.005763053894,2,20,10,3,2.46411912539942,0.217263713122108,0.0413267537951469,172.859115600586,47.8917007446289,47.8947868347168,240.330474853516,240.330474853516,,,23.657787322998,0,1,,,,,,1,1,1,47.8932952880859,0,47.8931324005127,,,,,,,,,,,,,,,,,,,,,,,,,,,,,,,,,
,3762231504.68777,47.9081401824951,260.463256835938,,,5,,,,31.6299982368946,,,,,0.00075783753578397,1.45705821706269E-7,0.00266932141500842,0.000126710395921572,0.000757716956868464,1.45682638571184E-7,0.000757716956046158,1.09582509052967E-7,3.53008566414655E-8,9.59953378592875E-8,1.00015913450849,10.005763053894,2,20,10,3,2.4790127720845,0.218402295950122,0.0413267537951469,172.859115600586,47.9051132202148,47.9205207824707,260.463256835938,260.463256835938,,,23.7186698913574,0,1,,,,,,1,1,1,47.9091262817383,0,47.9114650726318,,,,,,,,,,,,,,,,,,,,,,,,,,,,,,,,,
,3762231527.88639,47.9490947723389,280.304595947266,,,5,,,,31.6299982368946,,,,,0.000761899592302517,1.68184737431324E-7,-0.00189599568154719,0.000204576156196631,0.000761778337509129,1.68157971167377E-7,0.000761778337092041,6.31784511876427E-8,-2.52082867224125E-8,1.55838334733977E-7,1.00015917332827,10.005763053894,2,20,10,3,2.49231465960151,0.219427082433201,0.0413267537951469,172.859115600586,47.9456596374512,47.9557838439941,280.304595947266,280.304595947266,,,23.719144821167,0,1,,,,,,1,1,1,47.9505004882812,0,47.9511299133301,,,,,,,,,,,,,,,,,,,,,,,,,,,,,,,,,
,3762231550.78923,47.9590721130371,300.315948486328,,,5,,,,31.6299982368946,,,,,0.000766578959476124,1.78875961392163E-7,-0.00289611371349441,0.000206569319636536,0.000766457049622607,1.78847514560977E-7,0.00076645704864347,8.31922350336591E-8,-3.87418897191971E-8,1.58320830893295E-7,1.00015905634057,10.005763053894,2,20,10,3,2.50762226311693,0.2207846330158,0.0413267537951469,172.859115600586,47.9586524963379,47.9594078063965,300.315948486328,300.315948486328,,,23.6891632080078,0,1,,,,,,1,1,1,47.9591331481934,0,47.9589899236506,,,,,,,,,,,,,,,,,,,,,,,,,,,,,,,,,
,3762231573.88109,47.9653511047363,320.436584472656,,,5,,,,31.6299982368946,,,,,0.000770500874292484,1.0032986832147E-7,-0.0118452088683316,0.000115242780046499,0.000770378207738949,1.00313895439966E-7,0.000770378191275752,4.67077864465742E-8,-1.59266368148319E-7,8.87764625539995E-8,1.00015922900246,10.005763053894,2,20,10,3,2.52048285104176,0.221574758024561,0.0413267537951469,172.859115600586,47.9618797302246,47.9795227050781,320.436584472656,320.436584472656,,,23.6881790161133,0,1,,,,,,1,1,1,47.9669990539551,0,47.9697513580322,,,,,,,,,,,,,,,,,,,,,,,,,,,,,,,,,
,3762231596.85824,48.0050830841064,340.314361572266,,,5,,,,31.6299982368946,,,,,0.000777004409538714,1.3287684633957E-7,-0.0155359480575079,0.000144281251058967,0.000776880810038061,1.32855709378629E-7,0.000776880781478294,7.13315063543424E-8,-2.1065390620908E-7,1.12082361305065E-7,1.00015909712154,10.005763053894,2,20,10,3,2.54176844968692,0.223335147307317,0.0413267537951469,172.859115600586,48.003360748291,48.0065040588379,340.314361572266,340.314361572266,,,23.6864643096924,0,1,,,,,,1,1,1,48.0059204101562,0,48.0055557250977,,,,,,,,,,,,,,,,,,,,,,,,,,,,,,,,,
,3762231619.91179,48.0035800933838,360.362152099609,,,5,,,,31.6299982368946,,,,,0.000789169162369357,3.85095729560471E-7,-0.033865018862393,0.000249841958118995,0.000789043772585082,3.8503454233629E-7,0.000789043634759935,3.30768006292127E-7,-4.66369092333045E-7,1.9708912909049E-7,1.00015891359723,10.005763053894,2,20,10,3,2.58163130680523,0.226061219613687,0.0413267537951469,172.859115600586,48.0023460388184,48.0044021606445,360.362152099609,360.362152099609,,,23.6550216674805,0,1,,,,,,1,1,1,48.0031661987305,0,48.0031101226807,,,,,,,,,,,,,,,,,,,,,,,,,,,,,,,,,
,3762231642.9922,48.0019302368164,380.422058105469,,,5,,,,31.6299982368946,,,,,0.000808632770440903,1.95095666262608E-7,-0.0285622036288196,0.000203840821584764,0.00080850425641416,1.95064660185946E-7,0.000808504155954787,1.04370203580736E-7,-4.03042989313878E-7,1.64794060141664E-7,1.00015895281407,10.005763053894,2,20,10,3,2.6452782048275,0.23193828771859,0.0413267537951469,172.859115600586,48.0011672973633,48.0024375915527,380.422058105469,380.422058105469,,,23.6677780151367,0,1,,,,,,1,1,1,48.0015678405762,0,48.0017280578613,,,,,,,,,,,,,,,,,,,,,,,,,,,,,,,,,
,3762231666.04801,48.0006446838379,400.445556640625,,,5,,,,31.6299982368946,,,,,0.000834572491474673,1.66976361860035E-7,-0.0282343644081227,0.000174978459342175,0.000834439808281144,1.66949815386048E-7,0.000834439706965671,8.09718164715682E-8,-4.11197419257528E-7,1.45999334911944E-7,1.00015900870526,10.005763053894,2,20,10,3,2.73012976592881,0.23945265365949,0.0413267537951469,172.859115600586,47.9994583129883,48.0011520385742,400.445556640625,400.445556640625,,,23.6208648681641,0,1,,,,,,1,1,1,48.0003433227539,0,48.0001689910889,,,,,,,,,,,,,,,,,,,,,,,,,,,,,,,,,
,3762231689.08421,47.9990158081055,420.335479736328,,,5,,,,31.6299982368946,,,,,0.00085739807498846,1.56791526432255E-7,-0.0374807906752794,0.000143710000927795,0.000857261826808042,1.56766610864091E-7,0.000857261643384237,9.6959390262723E-8,-5.60789102896145E-7,1.23185416838578E-7,1.00015893415075,10.005763053894,2,20,10,3,2.80483488859498,0.245608762419075,0.0413267537951469,172.859115600586,47.9986877441406,47.9997863769531,420.335479736328,420.335479736328,,,23.5890445709229,0,1,,,,,,1,1,1,47.9989356994629,0,47.9990039825439,,,,,,,,,,,,,,,,,,,,,,,,,,,,,,,,,
,3762231712.20498,48.0162696838379,440.480377197266,,,5,,,,31.6299982368946,,,,,0.000867636214479022,2.33665928985488E-7,-0.054880690964815,0.000189802179719569,0.000867498251478595,2.33628773721424E-7,0.000867497853524978,1.65765239813022E-7,-8.30931991440199E-7,1.64633803273531E-7,1.00015903547954,10.005763053894,2,20,10,3,2.8383988635485,0.247740691294756,0.0413267537951469,172.859115600586,48.0142784118652,48.0163841247559,440.480377197266,440.480377197266,,,23.5867977142334,0,1,,,,,,1,1,1,48.0162773132324,0,48.0156154632568,,,,,,,,,,,,,,,,,,,,,,,,,,,,,,,,,
,3762231735.26079,48.0105857849121,460.370361328125,,,5,,,,31.6299982368946,,,,,0.000871749170285869,2.63376700504386E-7,-0.0551437277847189,0.000261448250593017,0.000871610680015814,2.63334859213769E-7,0.000871610276333714,1.32005051446574E-7,-8.38872514892524E-7,2.27859418215975E-7,1.00015889005634,10.005763053894,2,20,10,3,2.85185147270867,0.24896273611309,0.0413267537951469,172.859115600586,48.0072822570801,48.0120010375977,460.370361328125,460.370361328125,,,23.5552711486816,0,1,,,,,,1,1,1,48.0097694396973,0,48.0093158721924,,,,,,,,,,,,,,,,,,,,,,,,,,,,,,,,,
,3762231758.29017,48.0043792724609,480.150939941406,,,5,,,,31.6299982368946,,,,,0.000873389668394985,4.24034254507019E-7,-0.0662981333191146,0.000372828409227916,0.000873250865016237,4.23966864899195E-7,0.000873250280406133,2.7161350505245E-7,-1.01045643924156E-6,3.25536490129103E-7,1.00015895017607,10.005763053894,2,20,10,3,2.85726302679647,0.248935514231533,0.0413267537951469,172.859115600586,48.0027923583984,48.0049819946289,480.150939941406,480.150939941406,,,23.5525875091553,0,1,,,,,,1,1,1,48.0040588378906,0,48.0037318142978,,,,,,,,,,,,,,,,,,,,,,,,,,,,,,,,,
,3762231781.38107,48.0014896392822,500.429473876953,,,5,,,,31.6299982368946,,,,,0.00087402024659037,3.24820923638735E-7,-0.0703590189611543,0.000215821024033596,0.000873881358312328,3.24769307192855E-7,0.000873880699416571,2.64410934594016E-7,-1.07312301409863E-6,1.88578791388761E-7,1.00015893264769,10.005763053894,2,20,10,3,2.85933980056328,0.248974657163804,0.0413267537951469,172.859115600586,48.0003318786621,48.0020523071289,500.429473876953,500.429473876953,,,23.5059471130371,0,1,,,,,,1,1,1,48.0011367797852,0,48.0010425567627,,,,,,,,,,,,,,,,,,,,,,,,,,,,,,,,,
,3762231804.51662,48.0007972717285,520.258666992188,,,5,,,,31.6299982368946,,,,,0.000873184920244803,2.31178135565597E-7,-0.0791862194424722,0.000183456603729247,0.000873046092218672,2.31141380459661E-7,0.000873045258420264,1.66670403299472E-7,-1.20660191764362E-6,1.60147789322205E-7,1.00015901568928,10.005763053894,2,20,10,3,2.85664164192347,0.248357228118744,0.0413267537951469,172.859115600586,47.9998970031738,48.001148223877,520.258666992188,520.258666992188,,,23.4886589050293,0,1,,,,,,1,1,1,48.0006637573242,0,48.0005631880327,,,,,,,,,,,,,,,,,,,,,,,,,,,,,,,,,
,3762231827.50401,48.00075340271,540.27001953125,,,5,,,,31.6299982368946,,,,,0.000871438977524015,4.79763834133832E-7,-0.0854394775979204,0.000503007964104712,0.000871300428835241,4.79687557249443E-7,0.000871299460089614,1.95109208786278E-7,-1.29928288808464E-6,4.38215185983702E-7,1.00015901368138,10.005763053894,2,20,10,3,2.85095307714095,0.247610540297522,0.0413267537951469,172.859115600586,48.0005378723145,48.0011558532715,540.27001953125,540.27001953125,,,23.4426555633545,0,1,,,,,,1,1,1,48.000846862793,0,48.0008014678955,,,,,,,,,,,,,,,,,,,,,,,,,,,,,,,,,
,3762231850.64751,48.0013160705566,560.329895019531,,,5,,,,31.6299982368946,,,,,0.000867019490860105,2.32509316099539E-7,-0.0942972843631775,0.000208219699592493,0.0008668817219396,2.32472370497019E-7,0.000866880547899693,1.46528375125911E-7,-1.42671163626261E-6,1.80479467883368E-7,1.00015892470336,10.005763053894,2,20,10,3,2.83652887794086,0.245977164646916,0.0413267537951469,172.859115600586,47.9996910095215,48.0022850036621,560.329895019531,560.329895019531,,,23.4398880004883,0,1,,,,,,1,1,1,48.0009346008301,0,48.0007110595703,,,,,,,,,,,,,,,,,,,,,,,,,,,,,,,,,
,3762231873.68365,47.9999485015869,580.219848632813,,,5,,,,31.6299982368946,,,,,0.00085836893973553,4.15436242207494E-7,-0.101611518421797,0.000403922895649695,0.000858232500644054,4.15370207964141E-7,0.000858231151011748,2.28893719739699E-7,-1.52203639740572E-6,3.46612283002057E-7,1.00015897684063,10.005763053894,2,20,10,3,2.80825529848078,0.243224255760518,0.0413267537951469,172.859115600586,47.9997291564941,48.000560760498,580.219848632813,580.219848632813,,,23.4082469940186,0,1,,,,,,1,1,1,48.0000762939453,0,48.0000549316406,,,,,,,,,,,,,,,,,,,,,,,,,,,,,,,,,
,3762231896.77703,48.0006656646729,600.304077148438,,,5,,,,31.6299982368946,,,,,0.000838108222650761,5.75219432790374E-7,-0.108308545714108,0.000250125245964857,0.000837974976529996,5.75127981882321E-7,0.000837973479325546,5.35560048691054E-7,-1.58405728608164E-6,2.09636899877065E-7,1.00015900966556,10.005763053894,2,20,10,3,2.74199414629016,0.237221691650636,0.0413267537951469,172.859115600586,48.0001907348633,48.0008430480957,600.304077148438,600.304077148438,,,23.4053287506104,0,1,,,,,,1,1,1,48.0005569458008,0,48.0005672454834,,,,,,,,,,,,,,,,,,,,,,,,,,,,,,,,,
,3762231919.93888,48.0040073394775,620.181823730469,,,5,,,,31.6299982368946,,,,,0.000789731776780766,3.33090936320464E-7,-0.131283570822292,0.000325385228059492,0.000789606191586688,3.3303796733642E-7,0.000789604118794057,2.11947178359142E-7,-1.80924721764775E-6,2.56890407125631E-7,1.00015904788414,10.005763053894,2,20,10,3,2.58380962142449,0.222547903580868,0.0413267537951469,172.859115600586,48.001766204834,48.004264831543,620.181823730469,620.181823730469,,,23.3581523895264,0,1,,,,,,1,1,1,48.0037040710449,0,48.0031800703569,,,,,,,,,,,,,,,,,,,,,,,,,,,,,,,,,
,3762231942.9826,48.0345802307129,640.229614257812,,,5,,,,31.6299982368946,,,,,0.000644219244993231,2.83180175442442E-7,-0.206620214293604,0.000344996502476088,0.000644116785052965,2.83135137011681E-7,0.000644112596784607,1.7550702484916E-7,-2.32281087417506E-6,2.22177384175843E-7,1.00015907043978,10.005763053894,2,20,10,3,2.10796236766753,0.178815744213266,0.0413267537951469,172.859115600586,48.0316162109375,48.035213470459,640.229614257812,640.229614257812,,,23.370475769043,0,1,,,,,,1,1,1,48.035213470459,0,48.0339043357156,,,,,,,,,,,,,,,,,,,,,,,,,,,,,,,,,
,3762231969.15502,48.0188274383545,660.253112792969,,,5,,,,31.6299982368946,,,,,0.000436134312910933,3.49532406925498E-7,-0.257999823222734,0.00054168553249739,0.000436065062136137,3.49476907073093E-7,0.000436060641201291,2.57573020317409E-7,-1.96357095933485E-6,2.36199593102831E-7,1.00015880835409,10.005763053894,2,20,1,3,1.42718980746916,0.119808526318589,0.0413267537951469,172.859115600586,48.0118141174316,48.0234031677246,660.253112792969,660.253112792969,,,23.2949028015137,0,1,,,,,,1,1,1,48.017505645752,0,48.0174155602088,,,,,,,,,,,,,,,,,,,,,,,,,,,,,,,,,
,3762231991.62861,48.0065135955811,680.288696289063,,,5,,,,31.6299982368946,,,,,0.000227800096858317,4.96762410802982E-7,-0.583897127475954,0.00117278708237581,0.000227763871500798,4.96683414366275E-7,0.000227752044394651,4.18558046133438E-7,-2.32108489484841E-6,2.67401526030612E-7,1.00015904786514,10.005763053894,2,20,1,3,0.745787663260942,0.0583528965324348,0.0413267537951469,172.859115600586,48.0039443969727,48.0070533752441,680.288696289063,680.288696289063,,,23.2777080535889,0,1,,,,,,1,1,1,48.0060882568359,0,48.0054761713201,,,,,,,,,,,,,,,,,,,,,,,,,,,,,,,,,
,3762232014.67237,48.0174121856689,700.215087890625,,,5,,,,31.6299982368946,,,,,0.000134946880453355,4.95327509162841E-7,-0.974054802517002,0.00273827737265001,0.000134925415469565,4.95248721147E-7,0.000134905918153695,3.29932108639974E-7,-2.29368409839013E-6,3.69345501510604E-7,1.00015908777242,10.005763053894,2,20,1,3,0.442023119668931,0.0315679625025969,0.0413267537951469,172.859115600586,48.0144500732422,48.0175743103027,700.215087890625,700.215087890625,,,23.260669708252,0,1,,,,,,1,1,1,48.0175743103027,0,48.0162136077881,,,,,,,,,,,,,,,,,,,,,,,,,,,,,,,,,
,3762232037.76031,48.0124130249023,720.153625488281,,,5,,,,31.6299982368946,,,,,8.29789539177473E-5,5.03949801472846E-7,-1.51185930013236,0.00398808867003606,8.29657740613011E-5,5.03869757248065E-7,8.29368924604537E-5,3.7983687170769E-7,-2.1889574216985E-6,3.31072021108006E-7,1.00015885895835,10.005763053894,2,20,1,3,0.271970416588076,0.0168649095919855,0.0413267537951469,172.859115600586,48.0086669921875,48.014720916748,720.153625488281,720.153625488281,,,23.2140846252441,0,1,,,,,,1,1,1,48.0113716125488,0,48.0109474182129,,,,,,,,,,,,,,,,,,,,,,,,,,,,,,,,,
,3762232060.83207,48.0414733886719,740.23779296875,,,5,,,,31.6299982368946,,,,,5.16338779575181E-5,5.42944881738546E-7,-2.55617595832564,0.00575065793438376,5.16256732433489E-5,5.42858606840349E-7,5.15743043837957E-5,4.53719816517788E-7,-2.30244764470849E-6,2.9804998761904E-7,1.00015892701545,10.005763053894,2,20,1,3,0.1693974161448,0.00741169635387519,0.0413267537951469,172.859115600586,48.0344352722168,48.0424308776855,740.23779296875,740.23779296875,,,23.1974906921387,0,1,,,,,,1,1,1,48.0410003662109,0,48.0391704559326,,,,,,,,,,,,,,,,,,,,,,,,,,,,,,,,,
,3762232083.88777,48.0180015563965,760.297729492188,,,5,,,,31.6299982368946,,,,,3.70537995300723E-5,5.37234739197968E-7,-3.51933576906713,0.00932352720138247,3.70479131618387E-5,5.37149394063517E-7,3.69780459606456E-5,4.10930455638988E-7,-2.27420020656186E-6,3.45927206462773E-7,1.00015888528479,10.005763053894,2,20,1,3,0.121636173187974,0.00327725427708273,0.0413267537951469,172.859115600586,48.0114440917969,48.0208015441895,760.297729492188,760.297729492188,,,23.1651020050049,0,1,,,,,,1,1,1,48.0166130065918,0,48.0158073425293,,,,,,,,,,,,,,,,,,,,,,,,,,,,,,,,,
,3762232107.13597,48.007173538208,780.466918945313,,,5,,,,31.6299982368946,,,,,2.85783601571504E-5,5.37799266260447E-7,-4.80491485997517,0.0118306963264081,2.85738179676267E-5,5.37713789480827E-7,2.84734003607172E-5,4.17598815457095E-7,-2.39343793430589E-6,3.38743780351259E-7,1.00015896333941,10.005763053894,2,20,1,3,0.093847063286446,0.000424242460046549,0.0413267537951469,172.859115600586,48.003662109375,48.008487701416,780.466918945313,780.466918945313,,,23.1481494903564,0,1,,,,,,1,1,1,48.0063400268555,0,48.0057629671964,,,,,,,,,,,,,,,,,,,,,,,,,,,,,,,,,
,3762232130.11996,48.01780128479,800.223266601562,,,5,,,,31.6299982368946,,,,,2.32196721466749E-5,7.47755415464202E-7,-6.02392852396781,0.0191166826977442,2.32159810181199E-5,7.47636548093952E-7,2.30877859521738E-5,6.00624802480685E-7,-2.43637321860028E-6,4.45208102678825E-7,1.00015899084997,10.005763053894,2,20,1,3,0.0762400774290037,-0.00127593472506567,0.0413267537951469,172.859115600586,48.0150146484375,48.0180320739746,800.223266601562,800.223266601562,,,23.1314239501953,0,1,,,,,,1,1,1,48.0175704956055,0,48.0168281555176,,,,,,,,,,,,,,,,,,,,,,,,,,,,,,,,,
,3762232153.11635,48.0335521697998,820.453247070312,,,5,,,,31.6299982368946,,,,,2.00147681078592E-5,5.15462008497782E-7,-6.6448089375018,0.0164073581548079,2.00115857977473E-5,5.15380051017529E-7,1.98771594445071E-5,3.96811082167882E-7,-2.31562055575621E-6,3.28873170166837E-7,1.00015902338496,10.005763053894,2,20,1,3,0.0657013113282632,-0.00181046490118889,0.0413267537951469,172.859115600586,48.0270195007324,48.0339317321777,820.453247070312,820.453247070312,,,23.1139755249023,0,1,,,,,,1,1,1,48.0333442687988,0,48.0315036773682,,,,,,,,,,,,,,,,,,,,,,,,,,,,,,,,,
,3762232176.1423,48.0336666107178,840.13671875,,,5,,,,31.6299982368946,,,,,1.83285966572809E-5,7.96357348945705E-7,-7.16760955194058,0.031986916863181,1.83256844514562E-5,7.9623081680833E-7,1.81824764873087E-5,5.39185384924092E-7,-2.28653873853285E-6,5.85886195706571E-7,1.00015891389118,10.005763053894,2,20,1,3,0.06014866134077,-0.00220559221852344,0.0413267537951469,172.859115600586,48.023738861084,48.035285949707,840.13671875,840.13671875,,,23.0676898956299,0,1,,,,,,1,1,1,48.0325660705566,0,48.0302394866943,,,,,,,,,,,,,,,,,,,,,,,,,,,,,,,,,
,3762232199.237,48.0382308959961,860.34228515625,,,5,,,,31.6299982368946,,,,,1.55650459019958E-5,5.27217973126753E-7,-9.9196344582317,0.0192864079153362,1.55625713275839E-5,5.27134154542855E-7,1.53299163429031E-5,4.33309344146293E-7,-2.68091239053538E-6,3.00188989073751E-7,1.00015900806877,10.005763053894,2,20,1,3,0.050930841381282,-0.00432228594951252,0.0413267537951469,172.859115600586,48.0322113037109,48.039176940918,860.34228515625,860.34228515625,,,23.0506229400635,0,1,,,,,,1,1,1,48.0374221801758,0,48.0361888885498,,,,,,,,,,,,,,,,,,,,,,,,,,,,,,,,,
,3762232222.27575,48.0200958251953,880.29296875,,,5,,,,31.6299982368946,,,,,1.42531758647762E-5,5.94047334211669E-7,-11.5826241849496,0.0266836794347645,1.42509118735852E-5,5.93952975035548E-7,1.39607089332749E-5,4.5678405482717E-7,-2.86131006866944E-6,3.79642547416945E-7,1.00015886640877,10.005763053894,2,20,1,3,0.046503865564863,-0.00530880202547343,0.0413267537951469,172.859115600586,48.0133590698242,48.0226821899414,880.29296875,880.29296875,,,23.0042629241943,0,1,,,,,,1,1,1,48.0188903808594,0,48.0175720214844,,,,,,,,,,,,,,,,,,,,,,,,,,,,,,,,,
,3762232245.30234,48.0067958831787,900.450073242188,,,5,,,,31.6299982368946,,,,,1.31438390139668E-5,5.74571185194717E-7,-12.2748494748511,0.0262244622994839,1.3141750184633E-5,5.74479873885694E-7,1.28413165286204E-5,4.60686094842686E-7,-2.79395556999087E-6,3.43213413954523E-7,1.00015894605394,10.005763053894,2,20,1,3,0.042822295252768,-0.00541243675589607,0.0413267537951469,172.859115600586,48.0038833618164,48.0080261230469,900.450073242188,900.450073242188,,,23.0020904541016,0,1,,,,,,1,1,1,48.0062141418457,0,48.0057598114014,,,,,,,,,,,,,,,,,,,,,,,,,,,,,,,,,
,3762232268.3752,48.0437145233154,920.291320800781,,,5,,,,31.6299982368946,,,,,1.28534198167435E-5,7.18776875042851E-7,-11.0831157804035,0.0258453886872613,1.28513760676359E-5,7.18662586424109E-7,1.26116896117879E-5,6.38207590978121E-7,-2.47045582185237E-6,3.304042734949E-7,1.00015902959317,10.005763053894,2,20,1,3,0.0419772567368828,-0.00441987077398916,0.0413267537951469,172.859115600586,48.0350570678711,48.0442047119141,920.291320800781,920.291320800781,,,22.9561614990234,0,1,,,,,,1,1,1,48.0432243347168,0,48.0408954620361,,,,,,,,,,,,,,,,,,,,,,,,,,,,,,,,,
,3762232291.41642,48.0536651611328,940.363403320312,,,5,,,,31.6299982368946,,,,,1.28485115704113E-5,5.36396886651227E-7,-12.1394771517878,0.0268137364192032,1.28464701201326E-5,5.36311660625806E-7,1.25592047570937E-5,4.1172768568188E-7,-2.70151261645287E-6,3.43672096868881E-7,1.00015891137873,10.005763053894,2,20,1,3,0.0418727766333654,-0.00519013288552037,0.0413267537951469,172.859115600586,48.0411376953125,48.0562515258789,940.363403320312,940.363403320312,,,22.9244728088379,0,1,,,,,,1,1,1,48.0524215698242,0,48.049677658081,,,,,,,,,,,,,,,,,,,,,,,,,,,,,,,,,
,3762232314.4911,48.0282611846924,960.471862792969,,,5,,,,31.6299982368946,,,,,1.13343061602669E-5,6.91745848304886E-7,-15.08548510515,0.0335759303770942,1.13325054710906E-5,6.91635950156366E-7,1.09419714014312E-5,5.82657662462865E-7,-2.94939690488769E-6,3.72653104001575E-7,1.0001588959459,10.005763053894,2,20,1,3,0.0366540753923809,-0.00647006268073932,0.0413267537951469,172.859115600586,48.0197906494141,48.0318412780762,960.471862792969,960.471862792969,,,22.9217548370361,0,1,,,,,,1,1,1,48.0264167785645,0,48.0254573822022,,,,,,,,,,,,,,,,,,,,,,,,,,,,,,,,,
,3762232337.58248,48.0499820709229,980.276794433594,,,5,,,,31.6299982368946,,,,,1.09760246794447E-5,6.10068016562832E-7,-16.5319323525104,0.0294269252723992,1.09742800732744E-5,6.09971048083166E-7,1.0520617570912E-5,5.24809574800914E-7,-3.12272782247943E-6,3.10869087715327E-7,1.00015897226593,10.005763053894,2,20,1,3,0.0353261284535422,-0.00715879994139218,0.0413267537951469,172.859115600586,48.0398178100586,48.0508918762207,980.276794433594,980.276794433594,,,22.9050140380859,0,1,,,,,,1,1,1,48.0491561889648,0,48.0464653015137,,,,,,,,,,,,,,,,,,,,,,,,,,,,,,,,,
,3762232360.52687,48.0343952178955,1000.22747802734,,,5,,,,31.6299982368946,,,,,1.11250380010414E-5,6.53319589790058E-7,-15.5650697800265,0.0285846615612194,1.11232712639687E-5,6.53215837880221E-7,1.07153401294009E-5,5.77380556679351E-7,-2.98473608935238E-6,3.05487517954829E-7,1.00015883250806,10.005763053894,2,20,1,3,0.0359232273022989,-0.00665000315446323,0.0413267537951469,172.859115600586,48.0239105224609,48.0376014709473,1000.22747802734,1000.22747802734,,,22.8734397888184,0,1,,,,,,1,1,1,48.0327911376953,0,48.0305854797363,,,,,,,,,,,,,,,,,,,,,,,,,,,,,,,,,