File: Experimental_Data/AC_Suceptibillity_FieldScans/FCd_Down_10K.dat
[Header]
; MPMS3 Data File (default extension .dat)
; Copyright (c) 2007, Quantum Design, Inc. All rights reserved.
TITLE,FCd_Down_10K
FILEOPENTIME,3772403258.8148,07/16/2019,1:47 am
BYAPP,SQUID AC,0.9.1.0
INFO,MPMS3 Measurement Release 1.1.16 Build 347, MultiVu Release 2.3.3.2,APPNAME
INFO,0,MOMENT_UNITS
INFO,Cu2OSeO3,SAMPLE_MATERIAL
INFO,,SAMPLE_COMMENT
INFO,,SAMPLE_MASS
INFO,,SAMPLE_VOLUME
INFO,,SAMPLE_MOLECULAR_WEIGHT
INFO,,SAMPLE_SIZE
INFO,,SAMPLE_SHAPE
INFO,Quartz,SAMPLE_HOLDER
INFO,Standard,SAMPLE_HOLDER_DETAIL
INFO,64.77,SAMPLE_OFFSET
DATATYPE,COMMENT,1
DATATYPE,TIME,2
STARTUPAXIS,X,2
STARTUPAXIS,Y1,5
FIELDGROUP, VSM,2,3,4,5,6,8,9,10,11,14,15
FIELDGROUP, DC, 2,3,4,14,56,57,58,59,60,61,62,63,64,65,66,67,68,69
FIELDGROUP, AC, 2,3,4,11,16,17,18,19,20,21,22,23,24,25,26,27,28,29,30
STARTUPGROUP, All
[Data]
Comment,Time Stamp (sec),Temperature (K),Magnetic Field (Oe),Moment (emu),M. Std. Err. (emu),Transport Action,Averaging Time (sec),Frequency (Hz),Peak Amplitude (mm),Center Position (mm),Lockin Signal' (V),Lockin Signal (V),Range,M. Quad. Signal (emu),AC Moment (emu),AC M. Std Err. (emu),AC Phase (deg),AC Phase Std. Err. (deg),AC Susceptibility (emu/Oe),AC Suscept. Std Err. (emu/Oe),AC X' (emu/Oe),AC X' Std Err. (emu/Oe),AC X'' (emu/Oe),AC X'' Std Err. (emu/Oe),AC Drive (Oe),AC Frequency (Hz),AC Averaging Time (sec),AC Cycles,AC Range,AC Measure Type,AC Signal' (V),AC Signal'' (V),AC Trim Coil Ratio,AC Trim Coil Phase,Min. Temperature (K),Max. Temperature (K),Min. Field (Oe),Max. Field (Oe),Mass (grams),Motor Lag (deg),Pressure (Torr),Measure Count,Measurement Number,SQUID Status (code),Motor Status (code),Measure Status (code),Motor Current (amps),Motor Temp. (C),Temp. Status (code),Field Status (code),Chamber Status (code),Chamber Temp (K),Redirection State,Average Temp (K),Rotation Angle (deg),Rotator state,DC Moment Fixed Ctr (emu),DC Moment Err Fixed Ctr (emu),DC Moment Free Ctr (emu),DC Moment Err Free Ctr (emu),DC Fixed Fit,DC Free Fit,DC Calculated Center (mm),DC Calculated Center Err (mm),DC Scan Length (mm),DC Scan Time (s),DC Number of Points,DC Squid Drift,DC Min V (V),DC Max V (V),DC Scans per Measure,Map 01,Map 02,Map 03,Map 04,Map 05,Map 06,Map 07,Map 08,Map 09,Map 10,Map 11,Map 12,Map 13,Map 14,Map 15,Map 16
,3772403488.62215,9.99997138977051,200.125640869141,,,5,,,,6.47999998182058,,,,,0.000645178948722522,8.067772427917E-8,0.0343748362582437,5.98539164634316E-5,0.000645076023667974,8.06648538047246E-8,0.000645075907572069,7.08356848817681E-8,3.87015964280287E-7,3.85891744750836E-8,1.00015955492186,10.005763053894,2,20,10,3,2.11036803828594,0.18724354541271,0.0403775237500668,172.74836730957,9.99914836883545,10.0010662078857,200.125640869141,200.125640869141,,,17.0851612091064,0,1,,,,,,1,1,1,9.99955463409424,0,9.99996228651567,,,,,,,,,,,,,,,,,,,,,,,,,,,,,,,,,
,3772403510.86,10.000491142273,180.223571777344,,,5,,,,6.46999990567565,,,,,0.000633297543227943,1.65204286553267E-7,0.0642514738832158,7.48425965985473E-5,0.000633196498520522,1.65177927665603E-7,0.000633196100386412,1.58268516725809E-7,7.10066258046882E-7,4.72739294042239E-8,1.00015957875266,10.005763053894,2,20,10,3,2.07141085570664,0.184831355820855,0.0403775237500668,172.74836730957,9.99938011169434,10.0009746551514,180.223571777344,180.223571777344,,,17.1101684570313,0,1,,,,,,1,1,1,10.0004758834839,0,10.0003111839294,,,,,,,,,,,,,,,,,,,,,,,,,,,,,,,,,
,3772403532.46942,10.0002222061157,160.236511230469,,,5,,,,6.46999990567565,,,,,0.000623371820779128,8.50717271952906E-8,0.063984866125999,6.05967299485634E-5,0.000623272367437614,8.50581547698842E-8,0.000623271978789022,7.6228663871949E-8,6.96037143402764E-7,3.77369910983242E-8,1.00015956642186,10.005763053894,2,20,10,3,2.03894907194182,0.18188137545155,0.0403775237500668,172.74836730957,9.99899673461914,10.0009412765503,160.236511230469,160.236511230469,,,17.1301517486572,0,1,,,,,,1,1,1,10.000129699707,0,9.99999980926514,,,,,,,,,,,,,,,,,,,,,,,,,,,,,,,,,
,3772403554.35228,9.99971199035645,140.17658996582,,,5,,,,6.46999990567565,,,,,0.000615102038188552,7.0609475772745E-8,0.0594627596028321,4.54054029304618E-5,0.000615003848174508,7.05982042356872E-8,0.000615003516972734,6.48539550071916E-8,6.38263755635672E-7,2.78939233746163E-8,1.00015965756041,10.005763053894,2,20,10,3,2.01191682492489,0.179266512555456,0.0403775237500668,172.74836730957,9.99891567230225,10.0007352828979,140.17658996582,140.17658996582,,,17.1504669189453,0,1,,,,,,1,1,1,9.99984264373779,0,9.99965944290161,,,,,,,,,,,,,,,,,,,,,,,,,,,,,,,,,
,3772403574.86418,9.99978637695313,120.262382507324,,,5,,,,6.46999990567565,,,,,0.000608471728521766,6.4762049480242E-8,0.0583297970337151,5.97410535598759E-5,0.000608374594843184,6.47517111591605E-8,0.000608374279577499,5.35988857279025E-8,6.19353830412139E-7,3.6331027328808E-8,1.00015966097106,10.005763053894,2,20,10,3,1.99023614559664,0.177252388209097,0.0403775237500668,172.74836730957,9.99898624420166,10.0009183883667,120.262382507324,120.262382507324,,,17.156608581543,0,1,,,,,,1,1,1,9.99976062774658,0,9.99973421096802,,,,,,,,,,,,,,,,,,,,,,,,,,,,,,,,,
,3772403597.86475,10.000011920929,100.251037597656,,,5,,,,6.46999990567565,,,,,0.000603206408442028,3.72269643011675E-8,0.0531579839808236,4.17321990854897E-5,0.000603110178123889,3.72210254341927E-8,0.000603109918551574,2.7424977784556E-8,5.59554593032702E-7,2.51649623065369E-8,1.00015955678022,10.005763053894,2,20,10,3,1.97303244401723,0.17549820751757,0.0403775237500668,172.74836730957,9.99899959564209,10.0007801055908,100.251037597656,100.251037597656,,,17.1757888793945,0,1,,,,,,1,1,1,9.99984073638916,0,9.99982719421387,,,,,,,,,,,,,,,,,,,,,,,,,,,,,,,,,
,3772403618.40427,10.0001382827759,80.1546783447266,,,5,,,,6.46999990567565,,,,,0.000598936949253395,7.50818683909255E-8,0.0514471724959567,4.08311874846435E-5,0.000598841328003158,7.50698814495044E-8,0.000598841086590801,7.09901394828392E-8,5.37713060565957E-7,2.44108008277008E-8,1.00015967710605,10.005763053894,2,20,10,3,1.95907528922806,0.174155406543893,0.0403775237500668,172.74836730957,9.99878120422363,10.0006542205811,80.1546783447266,80.1546783447266,,,17.1963520050049,0,1,,,,,,1,1,1,10.0004281997681,0,9.99985303878784,,,,,,,,,,,,,,,,,,,,,,,,,,,,,,,,,
,3772403640.29319,9.99977922439575,60.2769012451172,,,5,,,,6.46999990567565,,,,,0.000595706857978292,4.71476897565831E-8,0.0449835901819649,6.0258649471428E-5,0.000595611762221289,4.71401633277897E-8,0.000595611578653613,3.05651934342993E-8,4.67621749708313E-7,3.5888214623948E-8,1.00015966064311,10.005763053894,2,20,10,3,1.9485320457325,0.172954912278642,0.0403775237500668,172.74836730957,9.99875164031982,10.0006647109985,60.2769012451172,60.2769012451172,,,17.2101078033447,0,1,,,,,,1,1,1,9.99974346160889,0,9.99968538284302,,,,,,,,,,,,,,,,,,,,,,,,,,,,,,,,,
,3772403661.99942,10.0000524520874,40.2776985168457,,,5,,,,6.46999990567565,,,,,0.00059288121467748,3.16653457457972E-8,0.0463979438000326,1.94316377059491E-5,0.000592786630449753,3.16602940723778E-8,0.000592786436083624,2.94960308860448E-8,4.80036714618314E-7,1.15047113270578E-8,1.00015955863859,10.005763053894,2,20,10,3,1.93928784030556,0.172140888766526,0.0403775237500668,172.74836730957,9.99870777130127,10.0012187957764,40.2776985168457,40.2776985168457,,,17.2309494018555,0,1,,,,,,1,1,1,9.99987506866455,0,9.99986486434937,,,,,,,,,,,,,,,,,,,,,,,,,,,,,,,,,
,3772403683.8329,9.99993991851807,20.1692066192627,,,5,,,,6.46999990567565,,,,,0.00059037328772693,6.08720704157068E-8,0.0529483811035254,2.6634740270581E-5,0.000590279106641949,6.08623596144969E-8,0.00059027885459149,5.88085774222813E-8,5.45490765864097E-7,1.56773096994315E-8,1.00015955347889,10.005763053894,2,20,10,3,1.93106752567991,0.171591935172855,0.0403775237500668,172.74836730957,9.99891376495361,10.0008382797241,20.1692066192627,20.1692066192627,,,17.260217666626,0,1,,,,,,1,1,1,9.99971485137939,0,9.99979782104492,,,,,,,,,,,,,,,,,,,,,,,,,,,,,,,,,
,3772403705.56704,9.99978303909302,0.18214213848114,,,5,,,,6.46999990567565,,,,,0.000588807642199992,9.28614609355753E-8,0.0639149237493752,7.21721192917497E-5,0.000588713715113273,9.28466475977906E-8,0.000588713348816243,8.25707972956889E-8,6.56725237486917E-7,4.245660613029E-8,1.00015954628592,10.005763053894,2,20,10,3,1.92591621918181,0.171464308603004,0.0403775237500668,172.74836730957,9.99877262115479,10.0008497238159,0.18214213848114,0.18214213848114,,,17.2663154602051,0,1,,,,,,1,1,1,9.99984741210937,0,9.999699679288,,,,,,,,,,,,,,,,,,,,,,,,,,,,,,,,,
,3772403728.58785,9.99955892562866,-19.8049221038818,,,5,,,,6.46999990567565,,,,,0.000587067404602679,3.96948616624238E-6,0.0911626349012042,0.00139101971802814,0.0005869737611507,3.96885299127086E-6,0.000586973018170784,3.8849923103119E-6,9.33926592181409E-7,8.1155949574697E-7,1.00015953601026,10.005763053894,2,20,10,3,1.92014004108807,0.171911035686664,0.0403775237500668,172.74836730957,9.99904346466065,10.0015544891357,-19.8049221038818,-19.8049221038818,,,17.2870998382568,0,1,,,,,,1,1,1,9.99957466125488,0,9.99994173916903,,,,,,,,,,,,,,,,,,,,,,,,,,,,,,,,,
,3772403749.97634,9.99989604949951,-39.8648414611816,,,5,,,,6.46999990567565,,,,,0.000588575040222626,2.23655502718843E-7,0.0445473153057456,0.000138606458565062,0.000588481147192006,2.2361982384779E-7,0.000588480969322973,2.08251183658741E-7,4.57542471662637E-7,8.14694428755348E-8,1.00015955146748,10.005763053894,2,20,10,3,1.92520810893375,0.170827573367944,0.0403775237500668,172.74836730957,9.99893379211426,10.000994682312,-39.8648414611816,-39.8648414611816,,,17.317834854126,0,1,,,,,,1,1,1,9.99961853027344,0,9.99981672113592,,,,,,,,,,,,,,,,,,,,,,,,,,,,,,,,,
,3772403772.16373,10.0000643730164,-59.9126205444336,,,5,,,,6.46999990567565,,,,,0.000589389710376889,1.96355782987075E-7,0.0359059306001628,4.13216466561254E-5,0.000589295682837914,1.9632445761659E-7,0.000589295567122728,1.9484345993643E-7,3.69297855545688E-7,2.40690419096606E-8,1.00015955918516,10.005763053894,2,20,10,3,1.92789605640187,0.170814622793722,0.0403775237500668,172.74836730957,9.99892044067383,10.000922203064,-59.9126205444336,-59.9126205444336,,,17.3307647705078,0,1,,,,,,1,1,1,10.0001096725464,0,9.99989093433727,,,,,,,,,,,,,,,,,,,,,,,,,,,,,,,,,
,3772403794.17297,9.9993691444397,-79.7782516479492,,,5,,,,6.46999990567565,,,,,0.000590548516878351,1.47216095860233E-7,0.0192473891277931,4.7294210469677E-5,0.000590454323289227,1.47192614618558E-7,0.000590454289973086,1.44541352819511E-7,1.98351501722584E-7,2.78112049964201E-8,1.00015952730873,10.005763053894,2,20,10,3,1.9317336382244,0.170629898871532,0.0403775237500668,172.74836730957,9.99813842773437,10.0004415512085,-79.7782516479492,-79.7782516479492,,,17.3458881378174,0,1,,,,,,1,1,1,9.99928951263428,0,9.99920988082886,,,,,,,,,,,,,,,,,,,,,,,,,,,,,,,,,
,3772403815.87903,9.99768543243408,-99.8017501831055,,,5,,,,6.46999990567565,,,,,0.000592180994047343,1.47094574025918E-7,0.0125598025809657,6.79658710903832E-5,0.000592086517973987,1.47071106677412E-7,0.000592086503748225,1.414784122284E-7,1.29791230353173E-7,4.0171747443319E-8,1.00015956464214,10.005763053894,2,20,10,3,1.93709098325491,0.170916998490052,0.0403775237500668,172.74836730957,9.99358177185059,9.99966430664062,-99.8017501831055,-99.8017501831055,,,17.3725528717041,0,1,,,,,,1,1,1,9.99704074859619,0,9.99591131210327,,,,,,,,,,,,,,,,,,,,,,,,,,,,,,,,,
,3772403837.58595,9.99848318099976,-119.898101806641,,,5,,,,6.46999990567565,,,,,0.000594456803185079,1.40067622406497E-7,0.00877568105219417,0.000104702441598049,0.000594361874231831,1.40045254973392E-7,0.000594361867260153,1.25475608890495E-7,9.10351558487515E-8,6.21976286856828E-8,1.00015971575123,10.005763053894,2,20,10,3,1.9445441406908,0.17148724095397,0.0403775237500668,172.74836730957,9.99738311767578,10.0001573562622,-119.898101806641,-119.898101806641,,,17.3583145141602,0,1,,,,,,1,1,1,9.99896812438965,0,9.99854459762573,,,,,,,,,,,,,,,,,,,,,,,,,,,,,,,,,
,3772403859.47395,9.99792098999023,-139.727310180664,,,5,,,,6.46999990567565,,,,,0.000597580348438478,1.50880708043298E-7,0.0033869448650492,0.000112873039491213,0.000597485004504484,1.50856635029006E-7,0.000597485003460562,1.34959832380547E-7,3.53193338840906E-8,6.74059936214096E-8,1.00015957544252,10.005763053894,2,20,10,3,1.95477528548522,0.172245951028156,0.0403775237500668,172.74836730957,9.99731826782227,9.99918842315674,-139.727310180664,-139.727310180664,,,17.3641242980957,0,1,,,,,,1,1,1,9.99816989898682,0,9.998047135093,,,,,,,,,,,,,,,,,,,,,,,,,,,,,,,,,
,3772403881.31221,9.99873208999634,-159.860076904297,,,5,,,,6.46999990567565,,,,,0.000601806556293068,1.78631902359481E-7,0.00155463918055787,9.15445965333567E-5,0.00060171051569414,1.78603395001575E-7,0.000601710515472641,1.69918089591396E-7,1.63265558281377E-8,5.50183200006981E-8,1.00015961263169,10.005763053894,2,20,10,3,1.96860276137127,0.173443570076871,0.0403775237500668,172.74836730957,9.99780750274658,9.99944686889648,-159.860076904297,-159.860076904297,,,17.356273651123,0,1,,,,,,1,1,1,9.99882507324219,0,9.99868030548096,,,,,,,,,,,,,,,,,,,,,,,,,,,,,,,,,
,3772403903.10946,9.99940729141235,-179.919998168945,,,5,,,,6.46999990567565,,,,,0.000607512902800086,2.14748951599871E-7,-0.00542402075382586,7.7060086948049E-5,0.000607415932740034,2.14714673778549E-7,0.000607415930018251,2.09574337190507E-7,-5.75022566839007E-8,4.67010527396149E-8,1.00015964358988,10.005763053894,2,20,10,3,1.98728777493617,0.174888779356952,0.0403775237500668,172.74836730957,9.99849700927734,10.0007057189941,-179.919998168945,-179.919998168945,,,17.3483505249023,0,1,,,,,,1,1,1,9.99940299987793,0,9.99962095780806,,,,,,,,,,,,,,,,,,,,,,,,,,,,,,,,,
,3772403926.13885,10.0000457763672,-199.979919433594,,,5,,,,6.46999990567565,,,,,0.000614440090560291,2.48311823928524E-7,-0.00868496276798503,0.000135945012874019,0.000614342067164468,2.48272210028685E-7,0.000614342060106642,2.3382899350228E-7,-9.31227047618713E-8,8.34451440782391E-8,1.0001595583325,10.005763053894,2,20,10,3,2.00995528696833,0.176811711263322,0.0403775237500668,172.74836730957,9.99885654449463,10.0009880065918,-199.979919433594,-199.979919433594,,,17.3553314208984,0,1,,,,,,1,1,1,9.99992275238037,0,9.99989433288574,,,,,,,,,,,,,,,,,,,,,,,,,,,,,,,,,
,3772403947.86442,9.99972295761108,-219.881988525391,,,5,,,,6.46999990567565,,,,,0.000622983141867447,2.81482325853439E-7,-0.00999301827359567,0.00021495031316779,0.000622883764792104,2.81437424332957E-7,0.000622883755318284,2.47576695237957E-7,-1.08637824028818E-7,1.33838723059587E-7,1.00015954353117,10.005763053894,2,20,10,3,2.03790270455115,0.179266949063672,0.0403775237500668,172.74836730957,9.99885082244873,10.0007724761963,-219.881988525391,-219.881988525391,,,17.3499526977539,0,1,,,,,,1,1,1,9.99973678588867,0,9.99968185424805,,,,,,,,,,,,,,,,,,,,,,,,,,,,,,,,,
,3772403970.14678,9.99983406066895,-239.759765625,,,5,,,,6.46999990567565,,,,,0.000633447966797946,3.16905252478853E-7,-0.0106575645828659,0.000199962358050442,0.000633346917167988,3.16854698747255E-7,0.000633346906211223,2.90475429305553E-7,-1.17808601113657E-7,1.26573793053572E-7,1.00015954862528,10.005763053894,2,20,10,3,2.07213462767979,0.182298311498034,0.0403775237500668,172.74836730957,9.99899101257324,10.0007295608521,-239.759765625,-239.759765625,,,17.3601741790771,0,1,,,,,,1,1,1,9.99980545043945,0,9.99985573508523,,,,,,,,,,,,,,,,,,,,,,,,,,,,,,,,,
,3772403992.92236,9.99983072280884,-259.856140136719,,,5,,,,6.46999990567565,,,,,0.000646389285230671,3.59439121432992E-7,0.000407912617351514,0.000236196561120216,0.000646286097250727,3.59381741464448E-7,0.000646286097234348,3.25390577054033E-7,4.60118102459916E-9,1.5256542354827E-7,1.00015966300433,10.005763053894,2,20,10,3,2.11442946874843,0.186476498861343,0.0403775237500668,172.74836730957,9.99891090393066,10.0006103515625,-259.856140136719,-259.856140136719,,,17.3691444396973,0,1,,,,,,1,1,1,9.99984645843506,0,9.99969110488892,,,,,,,,,,,,,,,,,,,,,,,,,,,,,,,,,
,3772404014.68451,9.99968957901001,-279.903900146484,,,5,,,,6.46999990567565,,,,,0.000663341570831371,6.09496805599195E-7,0.0586141509664237,0.000368937321849022,0.000663235680922095,6.09399510986152E-7,0.000663235333867705,5.58228750142289E-7,6.78496564275626E-7,2.44434912614258E-7,1.00015965653285,10.005763053894,2,20,10,3,2.16968428865061,0.193617874273694,0.0403775237500668,172.74836730957,9.99871063232422,10.00062084198,-279.903900146484,-279.903900146484,,,17.3860569000244,0,1,,,,,,1,1,1,9.99960136413574,0,9.99958686828613,,,,,,,,,,,,,,,,,,,,,,,,,,,,,,,,,
,3772404036.55327,9.99962329864502,-299.720947265625,,,5,,,,6.46999990567565,,,,,0.000693872807381963,2.12253745622887E-6,0.167312720022118,0.00179507651991476,0.000693762125292773,2.12219888282242E-6,0.000693759167328414,1.71883126649864E-6,2.0258920333941E-6,1.24472775158241E-6,1.00015953896178,10.005763053894,2,20,10,3,2.26915563842714,0.206882842703787,0.0403775237500668,172.74836730957,9.99869346618652,10.000584602356,-299.720947265625,-299.720947265625,,,17.3800468444824,0,1,,,,,,1,1,1,9.99944305419922,0,9.99963598251343,,,,,,,,,,,,,,,,,,,,,,,,,,,,,,,,,
,3772404058.19325,9.99948310852051,-319.829437255859,,,5,,,,6.46999990567565,,,,,0.000745976876809615,1.87681003861497E-6,0.167278384548299,0.00138940948702741,0.000745857802799659,1.87651045922562E-6,0.000745854624022235,1.56485769198912E-6,2.17757245242845E-6,1.03562150779405E-6,1.00015964706611,10.005763053894,2,20,10,3,2.43954704278356,0.222469066089868,0.0403775237500668,172.74836730957,9.99889183044434,10.0008859634399,-319.829437255859,-319.829437255859,,,17.4155292510986,0,1,,,,,,1,1,1,9.99936866760254,0,9.99961919784546,,,,,,,,,,,,,,,,,,,,,,,,,,,,,,,,,
,3772404080.0373,10.0002770423889,-339.913665771484,,,5,,,,6.46999990567565,,,,,0.00079857403934931,1.60022373109546E-6,0.124224223479185,0.00106690316361655,0.000798446632069685,1.59996842583593E-6,0.000798444755420718,1.3546785614956E-6,1.731128121354E-6,8.51319539712396E-7,1.00015956893612,10.005763053894,2,20,10,3,2.61172865818239,0.236248518751242,0.0403775237500668,172.74836730957,9.99881267547607,10.0012731552124,-339.913665771484,-339.913665771484,,,17.4030647277832,0,1,,,,,,1,1,1,10.000205039978,0,10.0000679016113,,,,,,,,,,,,,,,,,,,,,,,,,,,,,,,,,
,3772404101.74079,10.0000987052917,-359.815734863281,,,5,,,,6.46999990567565,,,,,0.000839817645265673,1.19795342749427E-6,0.033375161472077,0.000836342554732424,0.000839683568547176,1.19776217447003E-6,0.000839683426089081,9.70435130812003E-7,4.89121072075806E-7,7.02061167902813E-7,1.00015967529141,10.005763053894,2,20,10,3,2.74700228798602,0.244153070368664,0.0403775237500668,172.74836730957,9.99941730499268,10.0009145736694,-359.815734863281,-359.815734863281,,,17.4052391052246,0,1,,,,,,1,1,1,10.0003328323364,0,10.0000645637512,,,,,,,,,,,,,,,,,,,,,,,,,,,,,,,,,
,3772404123.66097,10.0002746582031,-379.887786865234,,,5,,,,6.46999990567565,,,,,0.000863742260577959,7.18591840196892E-7,-0.0603911801622532,0.000406338235108935,0.000863604456228059,7.18477193634021E-7,0.000863603976509404,6.269843668707E-7,-9.10260460566027E-7,3.5085621196149E-7,1.0001595688268,10.005763053894,2,20,10,3,2.82566197757562,0.246545213330901,0.0403775237500668,172.74836730957,9.99912929534912,10.0010232925415,-379.887786865234,-379.887786865234,,,17.4167404174805,0,1,,,,,,1,1,1,10.0002775192261,0,10.0002177845348,,,,,,,,,,,,,,,,,,,,,,,,,,,,,,,,,
,3772404145.32921,10.0000758171082,-399.850555419922,,,5,,,,6.46999990567565,,,,,0.000872087660512754,6.93418748423089E-7,-0.128712266588369,0.000303731251696783,0.000871948432807703,6.93308044986549E-7,0.000871946232642789,6.40697683842741E-7,-1.95878938540566E-6,2.64919842898975E-7,1.00015967424198,10.005763053894,2,20,10,3,2.85325440858219,0.24558614020995,0.0403775237500668,172.74836730957,9.9991569519043,10.0008506774902,-399.850555419922,-399.850555419922,,,17.428295135498,0,1,,,,,,1,1,1,10.0000429153442,0,9.99984083175659,,,,,,,,,,,,,,,,,,,,,,,,,,,,,,,,,
,3772404167.24523,10.0001802444458,-419.910491943359,,,5,,,,6.46999990567565,,,,,0.000871473397757254,6.02766356149373E-7,-0.161146467534283,0.000386916630651075,0.000871334363727001,6.02670191382884E-7,0.000871330917444498,4.99538819569768E-7,-2.45065641536439E-6,3.37153269781454E-7,1.0001595644979,10.005763053894,2,20,10,3,2.85137951883806,0.243860291526733,0.0403775237500668,172.74836730957,9.99911880493164,10.0016250610352,-419.910491943359,-419.910491943359,,,17.4297370910645,0,1,,,,,,1,1,1,9.99974822998047,0,10.0001075051048,,,,,,,,,,,,,,,,,,,,,,,,,,,,,,,,,
,3772404189.24678,10.0003442764282,-439.788238525391,,,5,,,,6.46999990567565,,,,,0.000866713937609446,6.24160037091018E-7,-0.183993829320239,0.00028140697037346,0.0008665756563825,6.24060454504429E-7,0.000866571188133495,5.74370714140539E-7,-2.78282799754214E-6,2.44028141028781E-7,1.00015957201882,10.005763053894,2,20,10,3,2.8358999293853,0.241457969963149,0.0403775237500668,172.74836730957,9.99895477294922,10.0010032653809,-439.788238525391,-439.788238525391,,,17.4334182739258,0,1,,,,,,1,1,1,10.0001316070557,0,10.0001584833319,,,,,,,,,,,,,,,,,,,,,,,,,,,,,,,,,
,3772404211.40352,10.0018177032471,-460.163879394531,,,5,,,,6.46999990567565,,,,,0.000859613793295693,5.70558514842272E-7,-0.214493309653047,0.000434536161142629,0.000859476586817911,5.70467445661205E-7,0.00085947056419345,4.31229110134755E-7,-3.21754147754228E-6,3.73462931402311E-7,1.00015963957586,10.005763053894,2,20,10,3,2.81279164605884,0.238044006148045,0.0403775237500668,172.74836730957,9.99982261657715,10.0028400421143,-460.163879394531,-460.163879394531,,,17.4534358978271,0,1,,,,,,1,1,1,10.0014390945435,0,10.0011236884377,,,,,,,,,,,,,,,,,,,,,,,,,,,,,,,,,
,3772404234.44275,10.0000448226929,-480.223815917969,,,5,,,,6.46999990567565,,,,,0.000851645096712497,6.18184338110738E-7,-0.237582895366772,0.000467896296979817,0.000851509231356664,6.18085717411351E-7,0.000851501910804845,4.72537502300924E-7,-3.53086127093814E-6,3.98419707076732E-7,1.00015955828878,10.005763053894,2,20,10,3,2.78680814662375,0.234774110555016,0.0403775237500668,172.74836730957,9.99914169311523,10.0010290145874,-480.223815917969,-480.223815917969,,,17.4736042022705,0,1,,,,,,1,1,1,9.9999532699585,0,10.0000909458507,,,,,,,,,,,,,,,,,,,,,,,,,,,,,,,,,
,3772404257.72307,9.99991607666016,-500.308044433594,,,5,,,,6.46999990567565,,,,,0.000842990610871826,7.2978267870139E-7,-0.253919338531688,0.000490949314630632,0.000842856131165268,7.29666258709024E-7,0.000842847854239977,6.00923347284381E-7,-3.73529730399088E-6,4.13888849556206E-7,1.00015955238573,10.005763053894,2,20,10,3,2.75855108981758,0.23166108444412,0.0403775237500668,172.74836730957,9.99915885925293,10.0007839202881,-500.308044433594,-500.308044433594,,,17.4781742095947,0,1,,,,,,1,1,1,9.99990463256836,0,9.99990110397339,,,,,,,,,,,,,,,,,,,,,,,,,,,,,,,,,
,3772404279.40513,9.99985885620117,-520.100830078125,,,5,,,,6.46999990567565,,,,,0.000834841859889615,7.48171102205166E-7,-0.275389975437151,0.000557070622897113,0.000834708586732205,7.48051665063997E-7,0.000834698945000573,5.85940002097145E-7,-4.0119794873451E-6,4.65032910176705E-7,1.00015966429426,10.005763053894,2,20,10,3,2.7319680607917,0.22845585874788,0.0403775237500668,172.74836730957,9.99894332885742,10.0009708404541,-520.100830078125,-520.100830078125,,,17.4983768463135,0,1,,,,,,1,1,1,9.99987316131592,0,9.99981489181519,,,,,,,,,,,,,,,,,,,,,,,,,,,,,,,,,
,3772404301.35603,10.0000557899475,-540.184997558594,,,5,,,,6.46999990567565,,,,,0.000826461491476035,7.75092329270515E-7,-0.288194689975354,0.000470240501667585,0.000826329643316661,7.7496867620499E-7,0.000826319190120368,6.70384016990415E-7,-4.15637614516871E-6,3.88795214557368E-7,1.00015955879163,10.005763053894,2,20,10,3,2.70459096614977,0.225616256777389,0.0403775237500668,172.74836730957,9.9992151260376,10.0012559890747,-540.184997558594,-540.184997558594,,,17.5030364990234,0,1,,,,,,1,1,1,9.99992656707764,0,10.0000506401062,,,,,,,,,,,,,,,,,,,,,,,,,,,,,,,,,
,3772404323.64262,9.9999942779541,-560.232788085937,,,5,,,,6.46999990567565,,,,,0.000817990772986056,7.03642543934924E-7,-0.294909693645119,0.000408839476827477,0.000817860278494945,7.03530291475939E-7,0.000817849444690484,6.18855404424052E-7,-4.20962697822199E-6,3.34623459188628E-7,1.00015955597129,10.005763053894,2,20,10,3,2.67689344533963,0.223047531146468,0.0403775237500668,172.74836730957,9.99918842315674,10.0011558532715,-560.232788085937,-560.232788085937,,,17.5206451416016,0,1,,,,,,1,1,1,9.99997997283935,0,10.0000532323664,,,,,,,,,,,,,,,,,,,,,,,,,,,,,,,,,
,3772404345.09331,10.0000219345093,-580.280578613281,,,5,,,,6.46999990567565,,,,,0.000810665619838968,9.40443934050792E-7,-0.351507892916333,0.000679941279235069,0.00081053620008808,9.40293795674759E-7,0.000810520946712778,7.61733442039181E-7,-4.97258414174828E-6,5.51284486870061E-7,1.00015967177144,10.005763053894,2,20,10,3,2.65313557285279,0.218486315761433,0.0403775237500668,172.74836730957,9.99899196624756,10.0010528564453,-580.280578613281,-580.280578613281,,,17.5320301055908,0,1,,,,,,1,1,1,10.0002593994141,0,9.99987134933472,,,,,,,,,,,,,,,,,,,,,,,,,,,,,,,,,
,3772404368.08595,10.0000400543213,-600.194763183594,,,5,,,,6.46999990567565,,,,,0.000802222736258269,7.86093168863798E-7,-0.34574429492319,0.000596810257718505,0.000802094663716068,7.85967671360433E-7,0.000802080060144146,6.2329746716107E-7,-4.84011166771733E-6,4.78795831074517E-7,1.00015967260224,10.005763053894,2,20,10,3,2.62547889523203,0.216530892339583,0.0403775237500668,172.74836730957,9.99912357330322,10.000880241394,-600.194763183594,-600.194763183594,,,17.5421028137207,0,1,,,,,,1,1,1,10.0002374649048,0,9.99996871948242,,,,,,,,,,,,,,,,,,,,,,,,,,,,,,,,,
,3772404389.7341,10.0004177093506,-620.206115722656,,,5,,,,6.46999990567565,,,,,0.000794503406928582,7.38128750423921E-7,-0.385527003413901,0.000730413312956503,0.000794376643969201,7.38010982036784E-7,0.000794358661092234,4.56274794587386E-7,-5.34509415473554E-6,5.80063377081451E-7,1.00015957538574,10.005763053894,2,20,10,3,2.60036058377691,0.21269754096267,0.0403775237500668,172.74836730957,9.99921226501465,10.0017671585083,-620.206115722656,-620.206115722656,,,17.5455570220947,0,1,,,,,,1,1,1,10.0000438690186,0,10.0001541137695,,,,,,,,,,,,,,,,,,,,,,,,,,,,,,,,,
,3772404411.7151,9.99986219406128,-640.266052246094,,,5,,,,6.46999990567565,,,,,0.000782407311227005,4.78949339809001E-7,-0.138922325398459,0.000282336122376248,0.000782282408538616,4.78872880835157E-7,0.000782280109045151,4.24877725400607E-7,-1.89676073442717E-6,2.20903043115681E-7,1.0001596644473,10.005763053894,2,20,10,3,2.55984226329223,0.220533981248151,0.0403775237500668,172.74836730957,9.9992036819458,10.0015716552734,-640.266052246094,-640.266052246094,,,17.5653285980225,0,1,,,,,,1,1,1,10,0,9.99988247798039,,,,,,,,,,,,,,,,,,,,,,,,,,,,,,,,,
,3772404438.23937,10.0001082420349,-660.1923828125,,,5,,,,6.46999990567565,,,,,0.000777518771625337,9.72644605423409E-7,-0.402357750460098,0.000594428909265057,0.000777394729592075,9.72489433845692E-7,0.000777375561040862,8.55394970418055E-7,-5.45918436576717E-6,4.62639323366496E-7,1.00015956119657,10.005763053894,2,20,10,3,2.5448259108873,0.20751191117673,0.0403775237500668,172.74836730957,9.99914455413818,10.001124382019,-660.1923828125,-660.1923828125,,,17.5834941864014,0,1,,,,,,1,1,1,10.0000028610229,0,10.0000840967352,,,,,,,,,,,,,,,,,,,,,,,,,,,,,,,,,
,3772404460.52279,10.0001540184021,-680.118774414062,,,5,,,,6.46999990567565,,,,,0.000765124997508633,4.20050650925041E-7,-0.1708018127612,0.000315598814285931,0.000765002931119929,4.19983636951902E-7,0.000764999531953192,3.4364247363051E-7,-2.28051167093514E-6,2.41445864790539E-7,1.00015956329543,10.005763053894,2,20,10,3,2.50341207290394,0.214376582141052,0.0403775237500668,172.74836730957,9.99897861480713,10.0014019012451,-680.118774414062,-680.118774414062,,,17.5787963867187,0,1,,,,,,1,1,1,10.0001029968262,0,9.99996477762858,,,,,,,,,,,,,,,,,,,,,,,,,,,,,,,,,
,3772404486.46529,10.0004377365112,-700.178649902344,,,5,,,,6.46999990567565,,,,,0.000759826709232668,1.05383283190084E-6,-0.472702630059252,0.000744412302034156,0.000759705478240331,1.05366469198365E-6,0.00075967962329811,8.88736694458926E-7,-6.26766415916652E-6,5.66000327787212E-7,1.00015957630399,10.005763053894,2,20,10,3,2.48716095156696,0.19984302840484,0.0403775237500668,172.74836730957,9.99910163879395,10.0010604858398,-700.178649902344,-700.178649902344,,,17.5906867980957,0,1,,,,,,1,1,1,10.0005321502686,0,10.0001974105835,,,,,,,,,,,,,,,,,,,,,,,,,,,,,,,,,
,3772404509.33172,10,-720.214294433594,,,5,,,,6.46999990567565,,,,,0.000749353914204793,1.00441014259728E-6,-0.479460730934217,0.000840857927168885,0.000749234369190729,1.00424990826428E-6,0.000749208136310117,7.81930167958693E-7,-6.26964619018832E-6,6.30161162469498E-7,1.00015955623364,10.005763053894,2,20,10,3,2.4529004504779,0.196851832979406,0.0403775237500668,172.74836730957,9.99910449981689,10.0011043548584,-720.214294433594,-720.214294433594,,,17.6094837188721,0,1,,,,,,1,1,1,9.99989700317383,0,9.99998052914937,,,,,,,,,,,,,,,,,,,,,,,,,,,,,,,,,
,3772404532.36305,10.0001626014709,-740.067810058594,,,5,,,,6.46999990567565,,,,,0.000733225357508209,4.51134215125935E-7,-0.161022841718015,0.000285035504699808,0.000733108380030679,4.51062241970652E-7,0.000733105484903736,3.99712050882124E-7,-2.06030950707251E-6,2.09015364294583E-7,1.00015956368897,10.005763053894,2,20,10,3,2.39899535246508,0.2060021479442,0.0403775237500668,172.74836730957,9.99910163879395,10.0017204284668,-740.067810058594,-740.067810058594,,,17.611421585083,0,1,,,,,,1,1,1,9.99983596801758,0,10.0000751201923,,,,,,,,,,,,,,,,,,,,,,,,,,,,,,,,,
,3772404558.17519,10.0001001358032,-760.103393554687,,,5,,,,6.46999990567565,,,,,0.000719917222313841,4.59384554904972E-7,-0.179516706345819,0.000341203165426398,0.000719802287626598,4.59311214222868E-7,0.000719798754596398,3.88111931243179E-7,-2.25525030953966E-6,2.45633711728614E-7,1.000159675357,10.005763053894,2,20,10,3,2.35551543275913,0.201553386671916,0.0403775237500668,172.74836730957,9.99907302856445,10.0014562606812,-760.103393554687,-760.103393554687,,,17.6229076385498,0,1,,,,,,1,1,1,10.0003480911255,0,9.99987257443942,,,,,,,,,,,,,,,,,,,,,,,,,,,,,,,,,
,3772404583.85288,9.99997472763062,-780.175476074219,,,5,,,,6.46999990567565,,,,,0.000705134054269822,3.49762304486821E-7,-0.210281516302707,0.000395219237962035,0.000705021483766586,3.49706466992673E-7,0.000705016735568778,2.11390518640425E-7,-2.58749693385376E-6,2.78583311929178E-7,1.00015966960699,10.005763053894,2,20,10,3,2.30724875345149,0.196225298493223,0.0403775237500668,172.74836730957,9.99891757965088,10.0015602111816,-780.175476074219,-780.175476074219,,,17.6347370147705,0,1,,,,,,1,1,1,10.0001850128174,0,9.99996355601719,,,,,,,,,,,,,,,,,,,,,,,,,,,,,,,,,
,3772404610.38003,10.0002374649048,-800.24755859375,,,5,,,,6.46999990567565,,,,,0.000686821415506897,4.13920110331142E-7,-0.218043985516434,0.000293365324819719,0.000686711838875483,4.13854072828029E-7,0.000686706866236006,3.61465800287884E-7,-2.61333428228031E-6,2.01538256464094E-7,1.00015956712148,10.005763053894,2,20,10,3,2.24735152757159,0.190873045486239,0.0403775237500668,172.74836730957,9.99922752380371,10.0016431808472,-800.24755859375,-800.24755859375,,,17.6529674530029,0,1,,,,,,1,1,1,10.0000610351562,0,10.0001736958822,,,,,,,,,,,,,,,,,,,,,,,,,,,,,,,,,
,3772404637.80829,9.99978065490723,-820.173950195313,,,5,,,,6.46999990567565,,,,,0.000665760535300201,3.6267572909851E-7,-0.271326403227385,0.000328106907687208,0.000665654256469861,3.6261783327826E-7,0.000665646792725488,2.89443730847225E-7,-3.15221996625863E-6,2.18435390183595E-7,1.0001596607087,10.005763053894,2,20,10,3,2.17860654788542,0.18304059374186,0.0403775237500668,172.74836730957,9.99902057647705,10.0014734268188,-820.173950195313,-820.173950195313,,,17.6471862792969,0,1,,,,,,1,1,1,9.99974918365479,0,9.99990529280442,,,,,,,,,,,,,,,,,,,,,,,,,,,,,,,,,
,3772404663.42442,9.99988842010498,-840.160949707031,,,5,,,,6.46999990567565,,,,,0.000637872534886032,4.71809656983807E-7,-0.249689734191177,0.000351911890799491,0.000637770777845607,4.71734391234441E-7,0.000637764721787374,4.14853089042558E-7,-2.77933755859453E-6,2.24566806062642E-7,1.00015955111767,10.005763053894,2,20,10,3,2.08727805551966,0.176206097730378,0.0403775237500668,172.74836730957,9.99904155731201,10.0015506744385,-840.160949707031,-840.160949707031,,,17.659948348999,0,1,,,,,,1,1,1,9.9998893737793,0,9.99990844726563,,,,,,,,,,,,,,,,,,,,,,,,,,,,,,,,,
,3772404689.07661,9.99998950958252,-860.257263183594,,,5,,,,6.46999990567565,,,,,0.000607476360402847,1.29326821287916E-6,-0.680093492756365,0.00129518328828675,0.000607379449517632,1.29306189741489E-6,0.000607336662011642,1.02589077308582E-6,-7.20934621853284E-6,7.8711955397103E-7,1.00015955575265,10.005763053894,2,20,10,3,1.98901649490822,0.152915237668337,0.0403775237500668,172.74836730957,9.99896144866943,10.0013542175293,-860.257263183594,-860.257263183594,,,17.6786327362061,0,1,,,,,,1,1,1,9.99966716766357,0,9.99999913302335,,,,,,,,,,,,,,,,,,,,,,,,,,,,,,,,,
,3772404710.65773,9.99996948242188,-880.135070800781,,,5,,,,6.46999990567565,,,,,0.000555956629284024,3.71674423771898E-7,-0.3271384924708,0.000411444760195232,0.000555867937867248,3.71615130781245E-7,0.00055585887723548,2.92870916673552E-7,-3.17379068273276E-6,2.28745342230952E-7,1.0001595548344,10.005763053894,2,20,10,3,1.8194302703942,0.151196197674057,0.0403775237500668,172.74836730957,9.99910640716553,10.0015134811401,-880.135070800781,-880.135070800781,,,17.6806812286377,0,1,,,,,,1,1,1,9.99987506866455,0,9.99993999187763,,,,,,,,,,,,,,,,,,,,,,,,,,,,,,,,,
,3772404739.66606,9.99999094009399,-899.830688476563,,,5,,,,6.46999990567565,,,,,0.000483993129338006,4.02984760253493E-7,-0.364301415087969,0.000624805446955144,0.00048391591773779,4.02920471947904E-7,0.000483906136025142,2.66388751326484E-7,-3.07684208647568E-6,3.02294458899661E-7,1.00015955581824,10.005763053894,2,20,1,3,1.58400482177164,0.130631234520189,0.0403775237500668,172.74836730957,9.9990930557251,10.0016431808472,-899.830688476563,-899.830688476563,,,17.6843109130859,0,1,,,,,,1,1,1,9.99988746643066,0,10.0001265020931,,,,,,,,,,,,,,,,,,,,,,,,,,,,,,,,,
,3772404766.81826,9.99986743927002,-919.829956054687,,,5,,,,6.46999990567565,,,,,0.000379483831944965,1.18436328602674E-6,-1.26741113220241,0.00160988049830016,0.000379423294899189,1.1841743508247E-6,0.000379330469664397,1.01339932120101E-6,-8.39234748714329E-6,6.12609752567193E-7,1.0001595501557,10.005763053894,2,20,1,3,1.24342749858432,0.0828623379406877,0.0403775237500668,172.74836730957,9.99926948547363,10.0012245178223,-919.829956054687,-919.829956054687,,,17.6944313049316,0,1,,,,,,1,1,1,9.99991989135742,0,9.99987897005948,,,,,,,,,,,,,,,,,,,,,,,,,,,,,,,,,
,3772404789.00479,9.99981784820557,-939.950622558594,,,5,,,,6.46999990567565,,,,,0.000280305384079022,6.11300613541753E-7,-0.68871623336351,0.000828597812004866,0.000280260669082881,6.11203097382136E-7,0.000280240422007302,5.64937413196413E-7,-3.36875465916353E-6,2.33270112574377E-7,1.00015954788193,10.005763053894,2,20,1,3,0.917790549503112,0.0704992006698886,0.0403775237500668,172.74836730957,9.99904155731201,10.0014343261719,-939.950622558594,-939.950622558594,,,17.7046089172363,0,1,,,,,,1,1,1,9.9998779296875,0,9.99998692103795,,,,,,,,,,,,,,,,,,,,,,,,,,,,,,,,,
,3772404814.94871,9.99989318847656,-959.755554199219,,,5,,,,6.46999990567565,,,,,0.00020315203149341,7.84757496550486E-7,-0.879048744375956,0.000960890062297857,0.000203119600226051,7.84632217566093E-7,0.00020309569493864,7.59125710096183E-7,-3.11619854658756E-6,1.98433548357256E-7,1.0001596658684,10.005763053894,2,20,1,3,0.665336399093122,0.0488986415319126,0.0403775237500668,172.74836730957,9.99931335449219,10.0016307830811,-959.755554199219,-959.755554199219,,,17.723072052002,0,1,,,,,,1,1,1,9.99994564056397,0,10.0000284058707,,,,,,,,,,,,,,,,,,,,,,,,,,,,,,,,,
,3772404841.14577,9.99986839294434,-979.863952636719,,,5,,,,6.46999990567565,,,,,0.000153269166480162,1.32210034593957E-6,-3.60934839864771,0.00507171531433146,0.000153244716255123,1.32188943821608E-6,0.000152940750797058,1.06745039668182E-6,-9.64726934139955E-6,7.79705930137168E-7,1.00015955019942,10.005763053894,2,20,1,3,0.503154215132553,0.0129497550395373,0.0403775237500668,172.74836730957,9.99898624420166,10.000883102417,-979.863952636719,-979.863952636719,,,17.718729019165,0,1,,,,,,1,1,1,9.99985408782959,0,9.99983527443626,,,,,,,,,,,,,,,,,,,,,,,,,,,,,,,,,
,3772404863.2948,10.0001945495605,-999.948181152344,,,5,,,,6.46999990567565,,,,,0.000114319720481597,1.14762965669356E-6,-4.69049874182791,0.00592066712458479,0.000114301481948051,1.14744656420607E-6,0.000113918681808188,9.24946681534569E-7,-9.34680215932671E-6,6.79048786190286E-7,1.0001595651538,10.005763053894,2,20,1,3,0.375406006620318,0.00258406608702467,0.0403775237500668,172.74836730957,9.9990873336792,10.0011539459229,-999.948181152344,-999.948181152344,,,17.7281055450439,0,1,,,,,,1,1,1,9.99999618530273,0,10.0000843048096,,,,,,,,,,,,,,,,,,,,,,,,,,,,,,,,,