File: Experimental_Data/AC_Suceptibillity_FieldScans/FCd_Down_20K.dat
[Header]
; MPMS3 Data File (default extension .dat)
; Copyright (c) 2007, Quantum Design, Inc. All rights reserved.
TITLE,FCd_Down_20K
FILEOPENTIME,3772412585.91814,07/16/2019,4:22 am
BYAPP,SQUID AC,0.9.1.0
INFO,MPMS3 Measurement Release 1.1.16 Build 347, MultiVu Release 2.3.3.2,APPNAME
INFO,0,MOMENT_UNITS
INFO,Cu2OSeO3,SAMPLE_MATERIAL
INFO,,SAMPLE_COMMENT
INFO,,SAMPLE_MASS
INFO,,SAMPLE_VOLUME
INFO,,SAMPLE_MOLECULAR_WEIGHT
INFO,,SAMPLE_SIZE
INFO,,SAMPLE_SHAPE
INFO,Quartz,SAMPLE_HOLDER
INFO,Standard,SAMPLE_HOLDER_DETAIL
INFO,64.77,SAMPLE_OFFSET
DATATYPE,COMMENT,1
DATATYPE,TIME,2
STARTUPAXIS,X,2
STARTUPAXIS,Y1,5
FIELDGROUP, VSM,2,3,4,5,6,8,9,10,11,14,15
FIELDGROUP, DC, 2,3,4,14,56,57,58,59,60,61,62,63,64,65,66,67,68,69
FIELDGROUP, AC, 2,3,4,11,16,17,18,19,20,21,22,23,24,25,26,27,28,29,30
STARTUPGROUP, All
[Data]
Comment,Time Stamp (sec),Temperature (K),Magnetic Field (Oe),Moment (emu),M. Std. Err. (emu),Transport Action,Averaging Time (sec),Frequency (Hz),Peak Amplitude (mm),Center Position (mm),Lockin Signal' (V),Lockin Signal (V),Range,M. Quad. Signal (emu),AC Moment (emu),AC M. Std Err. (emu),AC Phase (deg),AC Phase Std. Err. (deg),AC Susceptibility (emu/Oe),AC Suscept. Std Err. (emu/Oe),AC X' (emu/Oe),AC X' Std Err. (emu/Oe),AC X'' (emu/Oe),AC X'' Std Err. (emu/Oe),AC Drive (Oe),AC Frequency (Hz),AC Averaging Time (sec),AC Cycles,AC Range,AC Measure Type,AC Signal' (V),AC Signal'' (V),AC Trim Coil Ratio,AC Trim Coil Phase,Min. Temperature (K),Max. Temperature (K),Min. Field (Oe),Max. Field (Oe),Mass (grams),Motor Lag (deg),Pressure (Torr),Measure Count,Measurement Number,SQUID Status (code),Motor Status (code),Measure Status (code),Motor Current (amps),Motor Temp. (C),Temp. Status (code),Field Status (code),Chamber Status (code),Chamber Temp (K),Redirection State,Average Temp (K),Rotation Angle (deg),Rotator state,DC Moment Fixed Ctr (emu),DC Moment Err Fixed Ctr (emu),DC Moment Free Ctr (emu),DC Moment Err Free Ctr (emu),DC Fixed Fit,DC Free Fit,DC Calculated Center (mm),DC Calculated Center Err (mm),DC Scan Length (mm),DC Scan Time (s),DC Number of Points,DC Squid Drift,DC Min V (V),DC Max V (V),DC Scans per Measure,Map 01,Map 02,Map 03,Map 04,Map 05,Map 06,Map 07,Map 08,Map 09,Map 10,Map 11,Map 12,Map 13,Map 14,Map 15,Map 16
,3772412744.79037,19.9464082717896,200.028503417969,,,5,,,,6.46999990567565,,,,,0.000660542294492303,9.57615263929833E-8,0.0440347104186678,0.000101065488098904,0.000660438052564611,9.57464140130599E-8,0.000660437857514099,6.86539512848826E-8,5.07580065727417E-7,6.67383755371168E-8,1.00015783755537,10.005763053894,2,20,10,3,2.16059217379866,0.192030198933434,0.0403775237500668,172.74836730957,19.9445495605469,19.9489974975586,200.028503417969,200.028503417969,,,22.8759479522705,0,1,,,,,,1,1,1,19.9451217651367,0,19.9462001800537,,,,,,,,,,,,,,,,,,,,,,,,,,,,,,,,,
,3772412766.69216,19.9534959793091,180.089996337891,,,5,,,,6.46999990567565,,,,,0.000643321481536041,1.43794655589268E-7,0.0885739410860813,0.000119725404707236,0.000643219748369691,1.43771916280793E-7,0.000643218979777512,1.21433715884494E-7,9.94357453363174E-7,7.69689324177968E-8,1.00015816238013,10.005763053894,2,20,10,3,2.10412082229337,0.188614586490168,0.0403775237500668,172.74836730957,19.9506149291992,19.9588031768799,180.089996337891,180.089996337891,,,22.9141330718994,0,1,,,,,,1,1,1,19.9548606872559,0,19.9553536501798,,,,,,,,,,,,,,,,,,,,,,,,,,,,,,,,,
,3772412788.45129,19.9623250961304,160.333648681641,,,5,,,,6.46999990567565,,,,,0.000630502697399718,1.10851192049428E-7,0.0767328399986011,6.73529635907993E-5,0.000630403097435714,1.10833680982808E-7,0.000630402532101125,1.02401581890044E-7,8.44261234620291E-7,4.24030761456699E-8,1.00015799409046,10.005763053894,2,20,10,3,2.06223516783475,0.184386428818195,0.0403775237500668,172.74836730957,19.9620094299316,19.9675426483154,160.333648681641,160.333648681641,,,22.956636428833,0,1,,,,,,1,1,1,19.9625205993652,0,19.9633665084839,,,,,,,,,,,,,,,,,,,,,,,,,,,,,,,,,
,3772412810.33296,19.9760255813599,140.213012695312,,,5,,,,6.46999990567565,,,,,0.000620309761474063,7.84217509514959E-8,0.0652982888588971,7.31610553924053E-5,0.000620211737597184,7.84093584267649E-8,0.000620211334816834,6.3957508072927E-8,7.06836642637807E-7,4.53592840551785E-8,1.00015804905154,10.005763053894,2,20,10,3,2.02893525335135,0.180956894036076,0.0403775237500668,172.74836730957,19.9751396179199,19.9878463745117,140.213012695312,140.213012695312,,,23.0587005615234,0,1,,,,,,1,1,1,19.9769115447998,0,19.9808984236284,,,,,,,,,,,,,,,,,,,,,,,,,,,,,,,,,
,3772412832.01157,19.9899387359619,120.165237426758,,,5,,,,6.46999990567565,,,,,0.000612461783372386,5.28942828143351E-8,0.0622008727068444,4.7747356779054E-5,0.000612365100360035,5.28859329405348E-8,0.000612364739508892,4.40762823751656E-8,6.64789562155433E-7,2.92267554643928E-8,1.00015788458927,10.005763053894,2,20,10,3,2.0032781300631,0.178516135591474,0.0403775237500668,172.74836730957,19.9882526397705,19.9903297424316,120.165237426758,120.165237426758,,,23.1515846252441,0,1,,,,,,1,1,1,19.9897155761719,0,19.9890909194946,,,,,,,,,,,,,,,,,,,,,,,,,,,,,,,,,
,3772412853.93666,19.9873895645142,100.105316162109,,,5,,,,6.46999990567565,,,,,0.000606283736571682,8.46806292282312E-8,0.0556239678532693,5.72534701911969E-5,0.000606187960733797,8.46672520621821E-8,0.000606187675069514,7.72421366244062E-8,5.88500141386555E-7,3.46726967722104E-8,1.00015799693179,10.005763053894,2,20,10,3,1.98309354127553,0.176445199536809,0.0403775237500668,172.74836730957,19.9870471954346,19.9876365661621,100.105316162109,100.105316162109,,,23.282398223877,0,1,,,,,,1,1,1,19.9876327514648,0,19.9872653961182,,,,,,,,,,,,,,,,,,,,,,,,,,,,,,,,,
,3772412874.52318,19.9880380630493,80.2639694213867,,,5,,,,6.46999990567565,,,,,0.000601507849957634,9.90323803688973E-8,0.0532828131492638,0.000110436843421455,0.000601412741802986,9.90167217420846E-8,0.000601412481744143,7.34470074722808E-8,5.59290028000562E-7,6.64066885028621E-8,1.00015814123652,10.005763053894,2,20,10,3,1.9674818731736,0.174933100527435,0.0403775237500668,172.74836730957,19.9856147766113,19.9994812011719,80.2639694213867,80.2639694213867,,,23.4162368774414,0,1,,,,,,1,1,1,19.9899101257324,0,19.9926331259988,,,,,,,,,,,,,,,,,,,,,,,,,,,,,,,,,
,3772412897.44486,20.0032873153687,60.1797637939453,,,5,,,,6.46999990567565,,,,,0.00059790768709342,4.75052866207381E-8,0.0455939767636435,2.62101537826493E-5,0.000597813141396515,4.74977747246257E-8,0.000597812952116343,4.48473309507483E-8,4.75718732388156E-7,1.56446639588504E-8,1.00015815259043,10.005763053894,2,20,10,3,1.95573200226761,0.173581528305258,0.0403775237500668,172.74836730957,20.0002937316895,20.0041408538818,60.1797637939453,60.1797637939453,,,23.5393962860107,0,1,,,,,,1,1,1,20.0041580200195,0,20.002885055542,,,,,,,,,,,,,,,,,,,,,,,,,,,,,,,,,
,3772412917.98333,20.0008602142334,40.1319847106934,,,5,,,,6.46999990567565,,,,,0.000594935987172758,5.50290378878288E-8,0.0431126790858052,3.49307553731863E-5,0.00059484204568762,5.50203487016704E-8,0.000594841877289825,5.09552857324007E-8,4.47593732389868E-7,2.07556649419576E-8,1.0001579267737,10.005763053894,2,20,10,3,1.94602178470836,0.172592785224534,0.0403775237500668,172.74836730957,20.0001354217529,20.001615524292,40.1319847106934,40.1319847106934,,,23.6449394226074,0,1,,,,,,1,1,1,20.0007057189941,0,20.0005897175182,,,,,,,,,,,,,,,,,,,,,,,,,,,,,,,,,
,3772412941.01283,20.0008201599121,20.2906341552734,,,5,,,,6.46999990567565,,,,,0.000592433352603953,6.20194345917895E-8,0.0479980761621768,2.12085792630395E-5,0.000592339807376572,6.20096417229622E-8,0.000592339599529794,6.073571867508E-8,4.96217489395408E-7,1.25047248522978E-8,1.00015792493805,10.005763053894,2,20,10,3,1.93782364545211,0.171990842005936,0.0403775237500668,172.74836730957,20.0002346038818,20.0012035369873,20.2906341552734,20.2906341552734,,,23.7140254974365,0,1,,,,,,1,1,1,20.0009841918945,0,20.0006586074829,,,,,,,,,,,,,,,,,,,,,,,,,,,,,,,,,
,3772412964.06293,19.9996891021729,0.206427752971649,,,5,,,,6.46999990567565,,,,,0.000590438763100113,1.27120324451101E-7,0.0646891314814262,3.28701769757554E-5,0.000590345495780602,1.27100244177485E-7,0.000590345119515805,1.25638539395272E-7,6.66522553792724E-7,1.92205486029617E-8,1.00015798768717,10.005763053894,2,20,10,3,1.9312520286031,0.171932887929163,0.0403775237500668,172.74836730957,19.9985275268555,20.0001811981201,0.206427752971649,0.206427752971649,,,23.8035717010498,0,1,,,,,,1,1,1,19.9994869232178,0,19.999698638916,,,,,,,,,,,,,,,,,,,,,,,,,,,,,,,,,
,3772412985.46477,19.9995822906494,-19.8413505554199,,,5,,,,6.46999990567565,,,,,0.00059019641078677,1.41989826313607E-7,0.0635719898007094,3.96979794693884E-5,0.000590103184638042,1.419673979077E-7,0.000590102821405907,1.40052592647658E-7,6.5474326829745E-7,2.32381875659949E-8,1.00015798279208,10.005763053894,2,20,10,3,1.93046011957377,0.171865244590728,0.0403775237500668,172.74836730957,19.9991645812988,20.0005531311035,-19.8413505554199,-19.8413505554199,,,23.8472385406494,0,1,,,,,,1,1,1,19.9995708465576,0,19.9998351010409,,,,,,,,,,,,,,,,,,,,,,,,,,,,,,,,,
,3772413006.26934,20.0008783340454,-39.9741287231445,,,5,,,,6.46999990567565,,,,,0.000591247465797618,1.28198056347541E-7,0.0492365763981715,5.8684578784781E-5,0.000591153970793054,1.28177784162784E-7,0.000591153752519551,1.23418045952066E-7,5.08002409794286E-7,3.46053505437388E-8,1.00015815677333,10.005763053894,2,20,10,3,1.93393839425622,0.171729106060686,0.0403775237500668,172.74836730957,19.9984741210938,20.0022525787354,-39.9741287231445,-39.9741287231445,,,23.9000358581543,0,1,,,,,,1,1,1,20.0018291473389,0,20.0012849807739,,,,,,,,,,,,,,,,,,,,,,,,,,,,,,,,,
,3772413028.22366,20.0013275146484,-60.0219039916992,,,5,,,,6.46999990567565,,,,,0.000592934422753957,1.63384752062662E-7,0.0386300931711494,6.480112094189E-5,0.00059284078462524,1.63358949812267E-7,0.000592840649879729,1.58806315391822E-7,3.99706456658365E-7,3.82975283202418E-8,1.00015794818971,10.005763053894,2,20,10,3,1.93948558157874,0.171901672925717,0.0403775237500668,172.74836730957,20.0003280639648,20.0017929077148,-60.0219039916992,-60.0219039916992,,,23.9407787322998,0,1,,,,,,1,1,1,20.0011978149414,0,20.0008980144154,,,,,,,,,,,,,,,,,,,,,,,,,,,,,,,,,
,3772413051.25945,20.0009613037109,-79.8389663696289,,,5,,,,6.46999990567565,,,,,0.000594976518683946,1.20205859980237E-7,0.021096826176529,4.07612542734618E-5,0.000594882568043241,1.20186878697436E-7,0.000594882527716769,1.17733586619341E-7,2.19041157246198E-7,2.41596438876527E-8,1.00015793140655,10.005763053894,2,20,10,3,1.94621538965627,0.171939429087962,0.0403775237500668,172.74836730957,20.0002365112305,20.0019683837891,-79.8389663696289,-79.8389663696289,,,23.9817886352539,0,1,,,,,,1,1,1,20.0011596679687,0,20.0007268732244,,,,,,,,,,,,,,,,,,,,,,,,,,,,,,,,,
,3772413074.36573,20.0004110336304,-99.8867492675781,,,5,,,,6.46999990567565,,,,,0.000597525031821942,1.5280262844507E-7,0.0163189068186194,8.22369404888759E-5,0.000597430625372875,1.52778486270615E-7,0.000597430601140591,1.44684148461721E-7,1.70159384462316E-7,4.90689621965556E-8,1.00015802077272,10.005763053894,2,20,10,3,1.95456356028173,0.172554862296943,0.0403775237500668,172.74836730957,19.9999103546143,20.000524520874,-99.8867492675781,-99.8867492675781,,,24.0092830657959,0,1,,,,,,1,1,1,20.0003299713135,0,20.0001928156072,,,,,,,,,,,,,,,,,,,,,,,,,,,,,,,,,
,3772413096.01041,20.0004901885986,-119.995239257813,,,5,,,,6.46999990567565,,,,,0.000601438707761446,1.74293544413519E-7,0.0119463005902212,8.32863423541877E-5,0.000601343680786898,1.74266006132402E-7,0.000601343667715731,1.66937206377992E-7,1.25381526836882E-7,5.0006099828422E-8,1.00015802440033,10.005763053894,2,20,10,3,1.96737619802988,0.173577262617672,0.0403775237500668,172.74836730957,19.9999217987061,20.0010948181152,-119.995239257813,-119.995239257813,,,24.0342750549316,0,1,,,,,,1,1,1,20.0002021789551,0,20.0003377914429,,,,,,,,,,,,,,,,,,,,,,,,,,,,,,,,,
,3772413117.91871,20.000394821167,-139.848739624023,,,5,,,,6.46999990567565,,,,,0.000606863941129235,1.76143026709625E-7,0.0169504719792437,9.07676842972419E-5,0.000606768059622424,1.76115196980965E-7,0.000606768033069581,1.6730666436579E-7,1.79507198085225E-7,5.50003878753319E-8,1.00015802002971,10.005763053894,2,20,10,3,1.98510483751744,0.175358560051027,0.0403775237500668,172.74836730957,20.0000896453857,20.001070022583,-139.848739624023,-139.848739624023,,,24.0633277893066,0,1,,,,,,1,1,1,20.0007190704346,0,20.0005262374878,,,,,,,,,,,,,,,,,,,,,,,,,,,,,,,,,
,3772413139.58395,20.001992225647,-160.017944335938,,,5,,,,6.46999990567565,,,,,0.000613951987931321,3.63798319854664E-7,0.000650246773332697,0.00013463848287902,0.000613854871289044,3.63740773219121E-7,0.000613854871249512,3.54270185221524E-7,6.96660648888721E-9,8.24620274135362E-8,1.00015820782211,10.005763053894,2,20,10,3,2.00833815774365,0.176878701274301,0.0403775237500668,172.74836730957,19.9977436065674,20.0035343170166,-160.017944335938,-160.017944335938,,,24.0901870727539,0,1,,,,,,1,1,1,20.0032444000244,0,20.001913244074,,,,,,,,,,,,,,,,,,,,,,,,,,,,,,,,,
,3772413161.71552,20.0013198852539,-179.956420898438,,,5,,,,6.46999990567565,,,,,0.000622672794473586,2.201344345034E-7,0.00691070832255569,0.000131520045270541,0.000622574460182324,2.20099670235889E-7,0.000622574455653753,2.04328971863311E-7,7.50915779403674E-8,8.18140336081123E-8,1.00015794784006,10.005763053894,2,20,10,3,2.03684303724295,0.179657185839368,0.0403775237500668,172.74836730957,20.0005588531494,20.0014991760254,-179.956420898438,-179.956420898438,,,24.0932502746582,0,1,,,,,,1,1,1,20.0014514923096,0,20.0010299682617,,,,,,,,,,,,,,,,,,,,,,,,,,,,,,,,,
,3772413183.64627,20.000786781311,-200.028503417969,,,5,,,,6.46999990567565,,,,,0.000633501340352347,1.87897656107208E-7,-0.00459139041333234,9.63999164873418E-5,0.0006334013114584,1.87867987354328E-7,0.000633401309424676,1.77688899578711E-7,-5.07575380040979E-8,6.10002921228479E-8,1.00015792340833,10.005763053894,2,20,10,3,2.07229849956701,0.182410012173142,0.0403775237500668,172.74836730957,19.9999179840088,20.001407623291,-200.028503417969,-200.028503417969,,,24.1299266815186,0,1,,,,,,1,1,1,20.0008506774902,0,20.0004562031139,,,,,,,,,,,,,,,,,,,,,,,,,,,,,,,,,
,3772413205.60733,20.0007743835449,-219.857711791992,,,5,,,,6.46999990567565,,,,,0.000645875014785937,3.25288886222217E-7,0.0124605045473576,0.000125725997395674,0.000645772884506659,3.25237449266095E-7,0.000645772869235367,3.14984985609996E-7,1.4044063923921E-7,8.10176353974019E-8,1.00015815200936,10.005763053894,2,20,10,3,2.11271681264166,0.18664648947614,0.0403775237500668,172.74836730957,19.9969043731689,20.003101348877,-219.857711791992,-219.857711791992,,,24.1336402893066,0,1,,,,,,1,1,1,20.0021934509277,0,20.0014908530495,,,,,,,,,,,,,,,,,,,,,,,,,,,,,,,,,
,3772413228.6081,19.9998140335083,-239.844757080078,,,5,,,,6.46999990567565,,,,,0.000661592117050788,2.394519083981E-7,0.00441972160634574,0.000150227539352816,0.000661487606366415,2.39414082550155E-7,0.000661487604398364,2.17844237804781E-7,5.10262900362602E-8,9.93125922458281E-8,1.00015799341268,10.005763053894,2,20,10,3,2.16415283523758,0.190931049806928,0.0403775237500668,172.74836730957,19.9996089935303,20.000280380249,-239.844757080078,-239.844757080078,,,24.1605491638184,0,1,,,,,,1,1,1,19.9998950958252,0,19.9998829581521,,,,,,,,,,,,,,,,,,,,,,,,,,,,,,,,,
,3772413251.64671,20.000337600708,-259.941131591797,,,5,,,,6.46999990567565,,,,,0.000681931322536667,5.24196296673829E-7,0.0627386459126358,0.000335873706513645,0.000681823660656037,5.24113537666794E-7,0.000681823251897302,4.7153079957639E-7,7.46593990621343E-7,2.28809321087344E-7,1.00015790282274,10.005763053894,2,20,10,3,2.23048048625712,0.199119198423014,0.0403775237500668,172.74836730957,19.9999847412109,20.0009365081787,-259.941131591797,-259.941131591797,,,24.1739120483398,0,1,,,,,,1,1,1,20.000207901001,0,20.0003043088046,,,,,,,,,,,,,,,,,,,,,,,,,,,,,,,,,
,3772413274.71942,20.0007066726685,-279.976776123047,,,5,,,,6.46999990567565,,,,,0.000714522896332001,8.49981295722809E-7,0.112975286859563,0.000565698916144578,0.000714410076880539,8.49847088094154E-7,0.00071440868808256,7.47796673821166E-7,1.40866625355112E-6,4.03782376737907E-7,1.00015791973702,10.005763053894,2,20,10,3,2.33689489593954,0.210734883411516,0.0403775237500668,172.74836730957,20.0001277923584,20.0013751983643,-279.976776123047,-279.976776123047,,,24.1751327514648,0,1,,,,,,1,1,1,20.0005626678467,0,20.0004979913885,,,,,,,,,,,,,,,,,,,,,,,,,,,,,,,,,
,3772413300.85938,20.002537727356,-299.793823242188,,,5,,,,6.46999990567565,,,,,0.000762708492002082,7.34466861504638E-7,0.0706425057338036,0.000413512685966522,0.00076258791294542,7.34350747258844E-7,0.000762587333320841,6.63340720857533E-7,9.4022819519829E-7,3.15039851529661E-7,1.00015811823741,10.005763053894,2,20,10,3,2.49465127365385,0.223156096954597,0.0403775237500668,172.74836730957,20.0004215240479,20.0028495788574,-299.793823242188,-299.793823242188,,,24.2136745452881,0,1,,,,,,1,1,1,20.0028457641602,0,20.0020122528076,,,,,,,,,,,,,,,,,,,,,,,,,,,,,,,,,
,3772413325.40086,20.0011024475098,-319.938751220703,,,5,,,,6.46999990567565,,,,,0.000813028041731808,4.20813776175219E-7,0.0443242127813486,0.000240139463391018,0.000812899654087804,4.20747324236891E-7,0.000812899410842918,3.72787909907743E-7,6.2886191531029E-7,1.9508327729234E-7,1.00015793787506,10.005763053894,2,20,10,3,2.65934079901704,0.236714605933457,0.0403775237500668,172.74836730957,20.0003623962402,20.0014266967773,-319.938751220703,-319.938751220703,,,24.2149066925049,0,1,,,,,,1,1,1,20.0012893676758,0,20.0008291244507,,,,,,,,,,,,,,,,,,,,,,,,,,,,,,,,,
,3772413347.07188,20.0007562637329,-339.974395751953,,,5,,,,6.46999990567565,,,,,0.00085283191148875,5.25685293675507E-7,-0.00540388193850383,0.000266436706614737,0.000852697251825047,5.25602289505627E-7,0.000852697248032497,4.740194823541E-7,-8.04225950057213E-8,2.27075531668008E-7,1.00015792200973,10.005763053894,2,20,10,3,2.78974637809003,0.245942215848433,0.0403775237500668,172.74836730957,20.0001392364502,20.0013542175293,-339.974395751953,-339.974395751953,,,24.2653293609619,0,1,,,,,,1,1,1,20.0008983612061,0,20.0006630637429,,,,,,,,,,,,,,,,,,,,,,,,,,,,,,,,,
,3772413368.78368,20.0004873275757,-359.864288330078,,,5,,,,6.46999990567565,,,,,0.000873660488887798,5.14351494134486E-7,-0.0784300726071203,0.000280319733004867,0.000873522451140818,5.14270226957695E-7,0.000873521632743915,4.52246451551085E-7,-1.19573218923807E-6,2.44840791933392E-7,1.00015802426921,10.005763053894,2,20,10,3,2.85819500399204,0.248366959699892,0.0403775237500668,172.74836730957,20.0001640319824,20.000732421875,-359.864288330078,-359.864288330078,,,24.2411403656006,0,1,,,,,,1,1,1,20.0006008148193,0,20.0004076004028,,,,,,,,,,,,,,,,,,,,,,,,,,,,,,,,,
,3772413390.67682,19.9996891021729,-379.984924316406,,,5,,,,6.46999990567565,,,,,0.000880035901654806,4.20237725975399E-7,-0.119377748486933,0.000285976573047035,0.000879896888780397,4.20171344076532E-7,0.000879894978913366,3.36501474879383E-7,-1.83329443071325E-6,2.51616207321943E-7,1.00015798768717,10.005763053894,2,20,10,3,2.87922660457854,0.248183743093536,0.0403775237500668,172.74836730957,19.9990196228027,20.0004806518555,-379.984924316406,-379.984924316406,,,24.2309150695801,0,1,,,,,,1,1,1,20.0002021789551,0,19.9999929428101,,,,,,,,,,,,,,,,,,,,,,,,,,,,,,,,,
,3772413412.29591,20.0004873275757,-399.947692871094,,,5,,,,6.46999990567565,,,,,0.000879869240119029,5.05990518841479E-7,-0.150384878692545,0.000330053267032697,0.000879730221393692,5.05910572692944E-7,0.000879727191116609,4.14288435536182E-7,-2.30903518283745E-6,2.90362875973299E-7,1.00015802426921,10.005763053894,2,20,10,3,2.87881153175698,0.246640330088364,0.0403775237500668,172.74836730957,20.0002403259277,20.0007514953613,-399.947692871094,-399.947692871094,,,24.2558975219727,0,1,,,,,,1,1,1,20.0007514953613,0,20.0005340576172,,,,,,,,,,,,,,,,,,,,,,,,,,,,,,,,,
,3772413435.27623,20.0006284713745,-419.983337402344,,,5,,,,6.46999990567565,,,,,0.000875894944213913,6.99861244797458E-7,-0.172208311331272,0.000424042958769709,0.000875756547760609,6.99750662684015E-7,0.000875752592127331,5.930485709372E-7,-2.63217169649201E-6,3.71408646151463E-7,1.00015803073772,10.005763053894,2,20,10,3,2.86589784826146,0.244496147743098,0.0403775237500668,172.74836730957,20.0001983642578,20.0009651184082,-419.983337402344,-419.983337402344,,,24.2695903778076,0,1,,,,,,1,1,1,20.0008964538574,0,20.0005598935214,,,,,,,,,,,,,,,,,,,,,,,,,,,,,,,,,
,3772413457.38992,20.0005130767822,-439.885406494141,,,5,,,,6.46999990567565,,,,,0.0008704725043021,7.11191455891883E-7,-0.191457216361036,0.000488510257218552,0.000870334969227567,7.11079087299642E-7,0.000870330110145329,5.69956293700168E-7,-2.90827006498264E-6,4.251861847079E-7,1.00015802544928,10.005763053894,2,20,10,3,2.84823370666012,0.242086329102472,0.0403775237500668,172.74836730957,19.9998340606689,20.0007190704346,-439.885406494141,-439.885406494141,,,24.2832889556885,0,1,,,,,,1,1,1,20.0007190704346,0,20.0002555847168,,,,,,,,,,,,,,,,,,,,,,,,,,,,,,,,,
,3772413479.0361,20.000433921814,-460.212493896484,,,5,,,,6.46999990567565,,,,,0.000864391867683173,7.8651802175658E-7,-0.215961452514148,0.000479830706432646,0.000864255395501554,7.86393844477356E-7,0.000864249256202282,6.68097412459868E-7,-3.25757691388449E-6,4.14802514573267E-7,1.00015790723706,10.005763053894,2,20,10,3,2.82843648056866,0.239247137017921,0.0403775237500668,172.74836730957,19.9998340606689,20.0013103485107,-460.212493896484,-460.212493896484,,,24.2838592529297,0,1,,,,,,1,1,1,20.0000534057617,0,20.0003232955933,,,,,,,,,,,,,,,,,,,,,,,,,,,,,,,,,
,3772413500.92447,20.0005493164062,-480.272369384766,,,5,,,,6.46999990567565,,,,,0.000857836452167149,6.18239106649999E-7,-0.230734970516083,0.00049936380782961,0.000857701010434465,6.18141494365505E-7,0.000857694055598074,4.45739336254259E-7,-3.45402548194226E-6,4.28270184780628E-7,1.0001579125255,10.005763053894,2,20,10,3,2.80704366510483,0.236769200792299,0.0403775237500668,172.74836730957,20.0000476837158,20.0012226104736,-480.272369384766,-480.272369384766,,,24.2839603424072,0,1,,,,,,1,1,1,20.000415802002,0,20.0003854751587,,,,,,,,,,,,,,,,,,,,,,,,,,,,,,,,,
,3772413522.6091,19.9999570846558,-500.344451904297,,,5,,,,6.46999990567565,,,,,0.000851320877996678,7.32803970059053E-7,-0.256248744200541,0.000498624913183822,0.000851186390573698,7.32688205345617E-7,0.000851177877778636,5.97186327887135E-7,-3.80681995056547E-6,4.2450028979644E-7,1.0001579999686,10.005763053894,2,20,10,3,2.78582405727651,0.233790194417416,0.0403775237500668,172.74836730957,19.9991455078125,20.0003814697266,-500.344451904297,-500.344451904297,,,24.285758972168,0,1,,,,,,1,1,1,19.9997501373291,0,19.9999628067017,,,,,,,,,,,,,,,,,,,,,,,,,,,,,,,,,
,3772413544.62576,20.0015497207642,-520.210083007812,,,5,,,,6.46999990567565,,,,,0.000844770760499378,5.9390988093954E-7,-0.26308300018082,0.000430630163035695,0.000844637342958709,5.93816082717112E-7,0.000844628439067874,4.69355236060718E-7,-3.87827772512068E-6,3.63762563323775E-7,1.00015795837324,10.005763053894,2,20,10,3,2.76441400463715,0.231720415262681,0.0403775237500668,172.74836730957,20.0006275177002,20.0016212463379,-520.210083007812,-520.210083007812,,,24.323371887207,0,1,,,,,,1,1,1,20.0015659332275,0,20.0011577606201,,,,,,,,,,,,,,,,,,,,,,,,,,,,,,,,,
,3772413566.28321,20.0002527236938,-540.282165527344,,,5,,,,6.46999990567565,,,,,0.000838329034250691,6.06283826344131E-7,-0.288629652618171,0.000438154703439057,0.000838196587859487,6.06188040439595E-7,0.000838185952513986,4.82228442097817E-7,-4.22242910052662E-6,3.67314129872386E-7,1.0001580135175,10.005763053894,2,20,10,3,2.74343308086633,0.228789185578654,0.0403775237500668,172.74836730957,20.0001678466797,20.0005664825439,-540.282165527344,-540.282165527344,,,24.3115825653076,0,1,,,,,,1,1,1,20.0003890991211,0,20.0004035949707,,,,,,,,,,,,,,,,,,,,,,,,,,,,,,,,,
,3772413588.26414,20.0007438659668,-560.354187011719,,,5,,,,6.46999990567565,,,,,0.000832079689401447,6.79596994406454E-7,-0.320729705295612,0.000491617371761475,0.000831948211612113,6.79489610568582E-7,0.000831935176995302,5.42547690328194E-7,-4.65704653061891E-6,4.09082063393381E-7,1.00015803602616,10.005763053894,2,20,10,3,2.7231055627229,0.225616567289149,0.0403775237500668,172.74836730957,20.0002155303955,20.0010185241699,-560.354187011719,-560.354187011719,,,24.3120536804199,0,1,,,,,,1,1,1,20.0009155273438,0,20.0006750280207,,,,,,,,,,,,,,,,,,,,,,,,,,,,,,,,,
,3772413611.27486,20.000997543335,-580.231994628906,,,5,,,,6.46999990567565,,,,,0.000825551169258025,7.11427048075142E-7,-0.328433880763225,0.000506625340108092,0.000825420808017931,7.11314707961437E-7,0.000825407246919538,5.7532850602957E-7,-4.73149465634078E-6,4.18289043499883E-7,1.00015793306739,10.005763053894,2,20,10,3,2.70176681649426,0.223540556993889,0.0403775237500668,172.74836730957,20.0001678466797,20.0018253326416,-580.231994628906,-580.231994628906,,,24.3255672454834,0,1,,,,,,1,1,1,20.0009784698486,0,20.0008190155029,,,,,,,,,,,,,,,,,,,,,,,,,,,,,,,,,
,3772413632.13385,20.0004482269287,-600.304077148438,,,5,,,,6.46999990567565,,,,,0.000819424311202789,7.60705092791675E-7,-0.373405966319431,0.000601026674288825,0.000819294844201903,7.60584903281094E-7,0.000819277445136126,5.79629314818509E-7,-5.33944070502606E-6,4.92462437656048E-7,1.00015802247726,10.005763053894,2,20,10,3,2.68188566345979,0.219834173117279,0.0403775237500668,172.74836730957,20.000072479248,20.0006427764893,-600.304077148438,-600.304077148438,,,24.3256893157959,0,1,,,,,,1,1,1,20.0006103515625,0,20.0003620494496,,,,,,,,,,,,,,,,,,,,,,,,,,,,,,,,,
,3772413654.8711,20.0006513595581,-620.327575683594,,,5,,,,6.46999990567565,,,,,0.000813043768707699,8.87826525665773E-7,-0.377796309730207,0.000658852409627609,0.000812915395382949,8.87686344721908E-7,0.000812897723454786,7.07797520335318E-7,-5.36015416217733E-6,5.35732878226562E-7,1.00015791720206,10.005763053894,2,20,10,3,2.66101636839035,0.217975522774008,0.0403775237500668,172.74836730957,20.0002727508545,20.0011539459229,-620.327575683594,-620.327575683594,,,24.3386688232422,0,1,,,,,,1,1,1,20.0007610321045,0,20.0005970001221,,,,,,,,,,,,,,,,,,,,,,,,,,,,,,,,,
,3772413677.91553,20.0000696182251,-640.351013183594,,,5,,,,6.46999990567565,,,,,0.000805931157157871,7.82038110133014E-7,-0.3764951903082,0.000539000496565973,0.000805803836021293,7.81914563623929E-7,0.000805786439141112,6.50047468518815E-7,-5.29496392035175E-6,4.34544213492112E-7,1.00015800512592,10.005763053894,2,20,10,3,2.63772938514729,0.216185067141992,0.0403775237500668,172.74836730957,19.9998092651367,20.0005435943604,-640.351013183594,-640.351013183594,,,24.3271732330322,0,1,,,,,,1,1,1,20.0001373291016,0,20.000238609314,,,,,,,,,,,,,,,,,,,,,,,,,,,,,,,,,
,3772413699.77473,19.9999542236328,-660.265258789063,,,5,,,,6.46999990567565,,,,,0.000795032678358396,5.14184223443325E-7,-0.127621983955651,0.000303833806959343,0.000794907083168444,5.14102995253627E-7,0.000794905111236555,4.5382640343803E-7,-1.77059350599973E-6,2.41543961363669E-7,1.00015799983748,10.005763053894,2,20,10,3,2.60110556699857,0.224617473589193,0.0403775237500668,172.74836730957,19.9995918273926,20.0005340576172,-660.265258789063,-660.265258789063,,,24.339750289917,0,1,,,,,,1,1,1,20.0002632141113,0,20.0002141680036,,,,,,,,,,,,,,,,,,,,,,,,,,,,,,,,,
,3772413726.66821,20.0033912658691,-680.203735351562,,,5,,,,6.46999990567565,,,,,0.000788120221418493,3.81115484905526E-7,-0.182622541818166,0.000347613583836575,0.000787995594120049,3.81055218220332E-7,0.000787991591384231,2.64933402794079E-7,-2.51162504287974E-6,2.73885690420101E-7,1.0001581573544,10.005763053894,2,20,10,3,2.57869939781085,0.22024422389551,0.0403775237500668,172.74836730957,19.9999351501465,20.0040416717529,-680.203735351562,-680.203735351562,,,24.3405437469482,0,1,,,,,,1,1,1,20.0040416717529,0,20.0025314917931,,,,,,,,,,,,,,,,,,,,,,,,,,,,,,,,,
,3772413752.29863,20.0003366470337,-700.287963867187,,,5,,,,6.46999990567565,,,,,0.000779567313628932,4.31230900321055E-7,-0.16024238646201,0.000244715695781557,0.000779444147919573,4.3116276911698E-7,0.000779441099573532,3.86646954178891E-7,-2.17991322595012E-6,1.90802165335744E-7,1.00015801736364,10.005763053894,2,20,10,3,2.55062603879657,0.218905225504496,0.0403775237500668,172.74836730957,19.9996318817139,20.000846862793,-700.287963867187,-700.287963867187,,,24.3291854858398,0,1,,,,,,1,1,1,20.0007781982422,0,20.0002378736223,,,,,,,,,,,,,,,,,,,,,,,,,,,,,,,,,
,3772413777.91786,20.0005664825439,-720.311462402344,,,5,,,,6.46999990567565,,,,,0.000770454736403314,4.39993694726222E-7,-0.171801632935847,0.000517803331836941,0.00077033300229911,4.39924174434176E-7,0.000770329539259229,1.85741998850729E-7,-2.30984324683894E-6,3.98789655225066E-7,1.00015802789682,10.005763053894,2,20,10,3,2.52085144359856,0.215891830542754,0.0403775237500668,172.74836730957,20.0002136230469,20.0010242462158,-720.311462402344,-720.311462402344,,,24.3416767120361,0,1,,,,,,1,1,1,20.0008659362793,0,20.0004720687866,,,,,,,,,,,,,,,,,,,,,,,,,,,,,,,,,
,3772413804.47261,20.0002517700195,-740.164916992188,,,5,,,,6.46999990567565,,,,,0.00075998783121354,4.81057705642514E-7,-0.173552309686527,0.000349761546117623,0.000759867761868863,4.80981704052625E-7,0.000759864275902257,4.00868152156926E-7,-2.30168093677211E-6,2.65797148629663E-7,1.00015801347379,10.005763053894,2,20,10,3,2.48660812486252,0.212935720806725,0.0403775237500668,172.74836730957,20.0000629425049,20.0005054473877,-740.164916992188,-740.164916992188,,,24.3542194366455,0,1,,,,,,1,1,1,20.0002117156982,0,20.0002655029297,,,,,,,,,,,,,,,,,,,,,,,,,,,,,,,,,
,3772413831.81006,20.0000219345093,-760.200561523437,,,5,,,,6.46999990567565,,,,,0.000747556993825951,5.03418430923098E-7,-0.207489577721407,0.000276488319865438,0.000747438896282409,5.03338901896473E-7,0.00074743399519404,4.5889054362102E-7,-2.70675158458598E-6,2.0680792813031E-7,1.00015800294061,10.005763053894,2,20,10,3,2.44605614088356,0.208056452713051,0.0403775237500668,172.74836730957,19.9998188018799,20.0002288818359,-760.200561523437,-760.200561523437,,,24.3430862426758,0,1,,,,,,1,1,1,20.0001239776611,0,19.9999710963323,,,,,,,,,,,,,,,,,,,,,,,,,,,,,,,,,
,3772413857.5425,20.000542640686,-780.260498046875,,,5,,,,6.46999990567565,,,,,0.00073059687168485,3.19454457454722E-7,-0.220064450366326,0.000307555031612461,0.000730481436038011,3.1940398306404E-7,0.000730476047968721,2.27057993658292E-7,-2.80566215957975E-6,2.24640984490908E-7,1.00015802680417,10.005763053894,2,20,10,3,2.39060304469897,0.202862843767988,0.0403775237500668,172.74836730957,19.9997386932373,20.0007972717285,-780.260498046875,-780.260498046875,,,24.354736328125,0,1,,,,,,1,1,1,20.0004043579102,0,20.0002312293419,,,,,,,,,,,,,,,,,,,,,,,,,,,,,,,,,
,3772413883.18581,20.0004539489746,-800.368957519531,,,5,,,,6.46999990567565,,,,,0.000706248618051815,7.26196327801174E-7,-0.201239724871494,0.000310218597270101,0.000706137113243163,7.26081673583798E-7,0.000706132757715658,6.92131023596038E-7,-2.48015730704306E-6,2.19429357402673E-7,1.00015790815489,10.005763053894,2,20,10,3,2.31086505875986,0.1969111146541,0.0403775237500668,172.74836730957,19.999698638916,20.001148223877,-800.368957519531,-800.368957519531,,,24.3672847747803,0,1,,,,,,1,1,1,20.0002632141113,0,20.0001636232649,,,,,,,,,,,,,,,,,,,,,,,,,,,,,,,,,
,3772413910.0583,20.0004739761353,-820.258911132813,,,5,,,,6.46999990567565,,,,,0.00067348040892572,3.89606958909661E-7,-0.254489532858014,0.000320238837038509,0.000673373999903509,3.89545401520619E-7,0.000673367357577027,3.24377431801103E-7,-2.99090216875672E-6,2.15696317965748E-7,1.00015802365732,10.005763053894,2,20,10,3,2.20381739995913,0.185773712638894,0.0403775237500668,172.74836730957,19.9999771118164,20.0009250640869,-820.258911132813,-820.258911132813,,,24.3678913116455,0,1,,,,,,1,1,1,20.0004558563232,0,20.0003194075364,,,,,,,,,,,,,,,,,,,,,,,,,,,,,,,,,
,3772413935.94501,20.0016803741455,-840.258178710937,,,5,,,,6.46999990567565,,,,,0.000619616097188334,3.29504212295136E-7,-0.274465536404496,0.000282180970323261,0.000619518164410131,3.29452132849353E-7,0.000619511056309092,2.79202599712243E-7,-2.96768342174742E-6,1.74884579517214E-7,1.00015807894559,10.005763053894,2,20,10,3,2.02761516802441,0.170252185017572,0.0403775237500668,172.74836730957,20.0008506774902,20.0022449493408,-840.258178710937,-840.258178710937,,,24.3685455322266,0,1,,,,,,1,1,1,20.0021591186523,0,20.0014190673828,,,,,,,,,,,,,,,,,,,,,,,,,,,,,,,,,
,3772413965.11579,20.0002584457397,-860.330139160156,,,5,,,,6.46999990567565,,,,,0.00052052070172192,3.78244919642743E-7,-0.330847432281307,0.000405218896438221,0.000520438524897722,3.78185204503341E-7,0.000520429848319092,3.13868809801503E-7,-3.00519155529976E-6,2.10974925379822E-7,1.00015789919513,10.005763053894,2,20,1,3,1.70347587464926,0.141384059905566,0.0403775237500668,172.74836730957,19.9998321533203,20.0009689331055,-860.330139160156,-860.330139160156,,,24.3810615539551,0,1,,,,,,1,1,1,20.0001373291016,0,20.0002113791073,,,,,,,,,,,,,,,,,,,,,,,,,,,,,,,,,
,3772413992.20612,19.9998006820679,-880.183654785156,,,5,,,,6.46999990567565,,,,,0.000391941403993297,1.00416962929361E-6,-1.09522335688458,0.00161405545555542,0.000391879489855122,1.00401100278326E-6,0.000391807897039372,7.79350930557711E-7,-7.49041966082353E-6,6.32969367938669E-7,1.00015799280079,10.005763053894,2,20,1,3,1.28398725233006,0.0893654927048659,0.0403775237500668,172.74836730957,19.9989395141602,20.0005855560303,-880.183654785156,-880.183654785156,,,24.3681793212891,0,1,,,,,,1,1,1,19.9997539520264,0,19.9999578475952,,,,,,,,,,,,,,,,,,,,,,,,,,,,,,,,,
,3772414014.47074,20.0007543563843,-899.879272460937,,,5,,,,6.46999990567565,,,,,0.000283768206087756,4.15935969872645E-7,-0.679923598730293,0.000911787052668761,0.000283723367437832,4.15870247191443E-7,0.00028370339022123,3.25518614042093E-7,-3.3668393551845E-6,2.58815946980064E-7,1.00015803650693,10.005763053894,2,20,1,3,0.929120995498094,0.0714572107056121,0.0403775237500668,172.74836730957,19.9999866485596,20.0010509490967,-899.879272460937,-899.879272460937,,,24.3694629669189,0,1,,,,,,1,1,1,20.000883102417,0,20.0004420961652,,,,,,,,,,,,,,,,,,,,,,,,,,,,,,,,,
,3772414041.24681,20.0004510879517,-919.90283203125,,,5,,,,6.46999990567565,,,,,0.000203772682531621,1.32163026671982E-6,-2.49926763950386,0.00428405488631927,0.000203740486928445,1.32142145225517E-6,0.000203546684708447,9.91479126380595E-7,-8.88443346758043E-6,8.73569571603616E-7,1.00015802260838,10.005763053894,2,20,1,3,0.668490130818159,0.0301192179690467,0.0403775237500668,172.74836730957,19.9997997283936,20.0009746551514,-919.90283203125,-919.90283203125,,,24.3697357177734,0,1,,,,,,1,1,1,20.0008010864258,0,20.0002679824829,,,,,,,,,,,,,,,,,,,,,,,,,,,,,,,,,
,3772414064.11244,20.0001840591431,-939.962707519531,,,5,,,,6.46999990567565,,,,,0.000141158280692405,4.69520478783645E-7,-1.40226985215047,0.0014155313253324,0.000141135979743932,4.69446301399557E-7,0.000141093712493414,4.24206368170973E-7,-3.45384902760473E-6,2.01069110260419E-7,1.00015801037066,10.005763053894,2,20,1,3,0.462594627608127,0.0297360935978005,0.0403775237500668,172.74836730957,19.9996509552002,20.0004978179932,-939.962707519531,-939.962707519531,,,24.3821392059326,0,1,,,,,,1,1,1,20.0002384185791,0,20.0001963297526,,,,,,,,,,,,,,,,,,,,,,,,,,,,,,,,,
,3772414091.53099,20.0003108978271,-959.876953125,,,5,,,,6.46999990567565,,,,,0.000111195409653711,1.15042788506668E-6,-4.69284438559126,0.00637008493311554,0.000111177841755459,1.15024612756343E-6,0.00011080513052253,9.04989551237522E-7,-9.09590827169157E-6,7.0997187699625E-7,1.00015801618357,10.005763053894,2,20,1,3,0.365146170132682,0.00247671107754095,0.0403775237500668,172.74836730957,19.9996776580811,20.0007877349854,-959.876953125,-959.876953125,,,24.3949928283691,0,1,,,,,,1,1,1,20.0006809234619,0,20.0003951390584,,,,,,,,,,,,,,,,,,,,,,,,,,,,,,,,,
,3772414114.55518,19.9997310638428,-979.863952636719,,,5,,,,6.46999990567565,,,,,7.68041041317666E-5,3.83442897662986E-7,-2.60377613687368,0.0038090807427042,7.67919717980725E-5,3.83382327238532E-7,7.67126900713653E-5,2.48127920153939E-7,-3.48856914086824E-6,2.92257667271388E-7,1.00015798961024,10.005763053894,2,20,1,3,0.251981089450855,0.0109088077819876,0.0403775237500668,172.74836730957,19.9991817474365,20.0006713867187,-979.863952636719,-979.863952636719,,,24.3820381164551,0,1,,,,,,1,1,1,20.000171661377,0,20.000120980399,,,,,,,,,,,,,,,,,,,,,,,,,,,,,,,,,
,3772414141.6816,19.9997787475586,-999.972534179688,,,5,,,,6.46999990567565,,,,,6.12728750370354E-5,1.37562446725623E-6,-8.10199956607987,0.0107956306113579,6.12631959547054E-5,1.37540716420874E-6,6.0651712055193E-5,1.20381796572737E-6,-8.63417647251799E-6,6.65257222996296E-7,1.00015799179555,10.005763053894,2,20,1,3,0.200935106829223,-0.010594152738201,0.0403775237500668,172.74836730957,19.9997692108154,20.0007171630859,-999.972534179688,-999.972534179688,,,24.3704204559326,0,1,,,,,,1,1,1,19.9998168945313,0,20.0001745223999,,,,,,,,,,,,,,,,,,,,,,,,,,,,,,,,,