File: Experimental_Data/AC_Suceptibillity_FieldScans/FCd_Up_56K.dat
[Header]
; MPMS3 Data File (default extension .dat)
; Copyright (c) 2007, Quantum Design, Inc. All rights reserved.
TITLE,FCd_Up_56K
FILEOPENTIME,3762225691.66964,03/20/2019,6:41 am
BYAPP,SQUID AC,0.9.1.0
INFO,MPMS3 Measurement Release 1.1.16 Build 347, MultiVu Release 2.3.3.2,APPNAME
INFO,0,MOMENT_UNITS
INFO,SrM,SAMPLE_MATERIAL
INFO,MvsH,SAMPLE_COMMENT
INFO,,SAMPLE_MASS
INFO,,SAMPLE_VOLUME
INFO,,SAMPLE_MOLECULAR_WEIGHT
INFO,,SAMPLE_SIZE
INFO,,SAMPLE_SHAPE
INFO,Quartz,SAMPLE_HOLDER
INFO,Standard,SAMPLE_HOLDER_DETAIL
INFO,65.34,SAMPLE_OFFSET
DATATYPE,COMMENT,1
DATATYPE,TIME,2
STARTUPAXIS,X,2
STARTUPAXIS,Y1,5
FIELDGROUP, VSM,2,3,4,5,6,8,9,10,11,14,15
FIELDGROUP, DC, 2,3,4,14,56,57,58,59,60,61,62,63,64,65,66,67,68,69
FIELDGROUP, AC, 2,3,4,11,16,17,18,19,20,21,22,23,24,25,26,27,28,29,30
STARTUPGROUP, All
[Data]
Comment,Time Stamp (sec),Temperature (K),Magnetic Field (Oe),Moment (emu),M. Std. Err. (emu),Transport Action,Averaging Time (sec),Frequency (Hz),Peak Amplitude (mm),Center Position (mm),Lockin Signal' (V),Lockin Signal (V),Range,M. Quad. Signal (emu),AC Moment (emu),AC M. Std Err. (emu),AC Phase (deg),AC Phase Std. Err. (deg),AC Susceptibility (emu/Oe),AC Suscept. Std Err. (emu/Oe),AC X' (emu/Oe),AC X' Std Err. (emu/Oe),AC X'' (emu/Oe),AC X'' Std Err. (emu/Oe),AC Drive (Oe),AC Frequency (Hz),AC Averaging Time (sec),AC Cycles,AC Range,AC Measure Type,AC Signal' (V),AC Signal'' (V),AC Trim Coil Ratio,AC Trim Coil Phase,Min. Temperature (K),Max. Temperature (K),Min. Field (Oe),Max. Field (Oe),Mass (grams),Motor Lag (deg),Pressure (Torr),Measure Count,Measurement Number,SQUID Status (code),Motor Status (code),Measure Status (code),Motor Current (amps),Motor Temp. (C),Temp. Status (code),Field Status (code),Chamber Status (code),Chamber Temp (K),Redirection State,Average Temp (K),Rotation Angle (deg),Rotator state,DC Moment Fixed Ctr (emu),DC Moment Err Fixed Ctr (emu),DC Moment Free Ctr (emu),DC Moment Err Free Ctr (emu),DC Fixed Fit,DC Free Fit,DC Calculated Center (mm),DC Calculated Center Err (mm),DC Scan Length (mm),DC Scan Time (s),DC Number of Points,DC Squid Drift,DC Min V (V),DC Max V (V),DC Scans per Measure,Map 01,Map 02,Map 03,Map 04,Map 05,Map 06,Map 07,Map 08,Map 09,Map 10,Map 11,Map 12,Map 13,Map 14,Map 15,Map 16
,3762225819.54149,55.9830951690674,220.00341796875,,,5,,,,31.6299982368946,,,,,0.000693412681106911,6.30110015095279E-7,1.3271308036484,0.000166028376439946,0.000693303528302448,6.30010827011269E-7,0.000693117552606825,6.21001541176679E-7,1.60574165091644E-5,1.06163684975662E-7,1.00015743869749,10.005763053894,2,20,1,3,2.26305468042959,0.252086647085339,0.0413267537951469,172.859115600586,55.9518432617188,55.9866180419922,220.00341796875,220.00341796875,,,21.4322357177734,0,1,,,,,,1,1,1,55.9812278747559,0,55.9705675565279,,,,,,,,,,,,,,,,,,,,,,,,,,,,,,,,,
,3762225845.10996,55.8980350494385,239.844757080078,,,5,,,,31.6299982368946,,,,,0.000803959305144679,5.04011773598803E-7,2.76287245165513,0.000185666713306082,0.000803833019083331,5.0393260334559E-7,0.000802898629266053,4.84088346927463E-7,3.87467894323532E-5,1.40023359064477E-7,1.00015710484435,10.005763053894,2,20,10,3,2.61568679464077,0.357981811573235,0.0413267537951469,172.859115600586,55.8774604797363,55.9087371826172,239.844757080078,239.844757080078,,,21.5232048034668,0,1,,,,,,1,1,1,55.8939056396484,0,55.8895191192627,,,,,,,,,,,,,,,,,,,,,,,,,,,,,,,,,
,3762225866.99361,55.8926029205322,259.928985595703,,,5,,,,31.6299982368946,,,,,0.000808407236248455,1.08847444048086E-7,0.818398455853123,0.000120545446788823,0.000808279617577158,1.08830260918642E-7,0.00080819716417397,4.82897902655415E-8,1.15448695025214E-5,9.75301073911528E-8,1.00015788926075,10.005763053894,2,20,10,3,2.64085319989628,0.270568078490117,0.0413267537951469,172.859115600586,55.8884544372559,55.9097747802734,259.928985595703,259.928985595703,,,21.5578384399414,0,1,,,,,,1,1,1,55.8949432373047,0,55.8988637057218,,,,,,,,,,,,,,,,,,,,,,,,,,,,,,,,,
,3762225889.89963,55.9328002929687,279.782470703125,,,5,,,,31.6299982368946,,,,,0.000785490460843599,2.13560630370431E-7,0.109867404666574,0.000169507167336459,0.000785366457702291,2.13526916162117E-7,0.000785365013810369,1.66979877117293E-7,1.50597691966714E-6,1.3308442645027E-7,1.00015789207712,10.005763053894,2,20,10,3,2.5690414281711,0.231201639909083,0.0413267537951469,172.859115600586,55.9295959472656,55.942440032959,279.782470703125,279.782470703125,,,21.5879173278809,0,1,,,,,,1,1,1,55.9347152709961,0,55.9356868743896,,,,,,,,,,,,,,,,,,,,,,,,,,,,,,,,,
,3762225912.02367,55.9511890411377,299.866668701172,,,5,,,,31.6299982368946,,,,,0.000756282602087138,3.99590056933832E-7,0.0368290734722709,0.000110049757453964,0.000756163354768272,3.9952705132878E-7,0.000756163198553558,3.90835066512041E-7,4.86053145078393E-7,8.28843503201812E-8,1.0001577004732,10.005763053894,2,20,10,3,2.47379202603923,0.219504401586851,0.0413267537951469,172.859115600586,55.9504623413086,55.9528770446777,299.866668701172,299.866668701172,,,21.5893230438232,0,1,,,,,,1,1,1,55.9513130187988,0,55.9514080394398,,,,,,,,,,,,,,,,,,,,,,,,,,,,,,,,,
,3762225935.00986,55.9530124664307,319.926605224609,,,5,,,,31.6299982368946,,,,,0.00068106682534368,4.032920053381E-7,0.0559346285995801,0.000206216168389952,0.000680959459059223,4.03228428663164E-7,0.000680959134564619,3.78063381369518E-7,6.64782095773561E-7,1.40218562785427E-7,1.0001576691285,10.005763053894,2,20,10,3,2.22769299816675,0.198464351909381,0.0413267537951469,172.859115600586,55.9524955749512,55.9565887451172,319.926605224609,319.926605224609,,,21.6297245025635,0,1,,,,,,1,1,1,55.9532508850098,0,55.953511873881,,,,,,,,,,,,,,,,,,,,,,,,,,,,,,,,,
,3762225958.03919,55.976318359375,339.767944335937,,,5,,,,31.6299982368946,,,,,0.000563549240210486,3.01259785748904E-7,0.101902150532475,0.000169008776289246,0.000563460251779205,3.01212214687089E-7,0.000563459360621412,2.85840675167779E-7,1.00212932983064E-6,9.49942455958718E-8,1.00015793204756,10.005763053894,2,20,10,3,1.84317135269683,0.165737368371778,0.0413267537951469,172.859115600586,55.9720764160156,55.9873657226562,339.767944335937,339.767944335937,,,21.5866603851318,0,1,,,,,,1,1,1,55.9781646728516,0,55.9803040244363,,,,,,,,,,,,,,,,,,,,,,,,,,,,,,,,,
,3762225984.25621,55.9951057434082,359.852142333984,,,5,,,,31.6299982368946,,,,,0.000443979732655204,1.65127772725728E-7,0.0977261179609306,0.000206506440345594,0.000443909702047004,1.65101726495452E-7,0.000443909056332464,1.37343795155873E-7,7.57150897335256E-7,9.16256624748799E-8,1.00015775867902,10.005763053894,2,20,1,3,1.45210907182364,0.130497849232119,0.0413267537951469,172.859115600586,55.9933204650879,55.9980850219727,359.852142333984,359.852142333984,,,21.5842208862305,0,1,,,,,,1,1,1,55.9954605102539,0,55.9958282046848,,,,,,,,,,,,,,,,,,,,,,,,,,,,,,,,,
,3762226012.13889,56.0221691131592,379.936370849609,,,5,,,,31.6299982368946,,,,,0.000302694723971904,1.29354547682233E-7,0.137803520853527,0.000395057248578504,0.000302646986125666,1.29334147235782E-7,0.000302646110776119,4.92699325968012E-8,7.27903179073515E-7,1.19581751881771E-7,1.00015773441807,10.005763053894,2,20,1,3,0.989949260975702,0.0896840274945575,0.0413267537951469,172.859115600586,56.0193862915039,56.0236740112305,379.936370849609,379.936370849609,,,21.5539932250977,0,1,,,,,,1,1,1,56.023021697998,0,56.0224009922573,,,,,,,,,,,,,,,,,,,,,,,,,,,,,,,,,
,3762226037.65615,56.0138111114502,399.971984863281,,,5,,,,31.6299982368946,,,,,0.000206910690311134,1.64738531740696E-7,0.156736056408325,0.000472101100978318,0.000206878090139751,1.64712576076636E-7,0.000206877316075879,1.32665579430217E-7,5.6592677227015E-7,9.76221120046385E-8,1.00015758155618,10.005763053894,2,20,1,3,0.676670719853044,0.0615427344100003,0.0413267537951469,172.859115600586,56.0094871520996,56.0151329040527,399.971984863281,399.971984863281,,,21.5373115539551,0,1,,,,,,1,1,1,56.0132331848145,0,56.0122257579457,,,,,,,,,,,,,,,,,,,,,,,,,,,,,,,,,
,3762226060.6491,56.0067901611328,419.813354492188,,,5,,,,31.6299982368946,,,,,0.000135430315959752,4.06251643013182E-7,0.190522415344344,0.000700922409081242,0.000135408974876635,4.06187625957484E-7,0.000135408226252289,3.9511181408491E-7,4.50266976534467E-7,9.42074405315617E-8,1.0001576046428,10.005763053894,2,20,1,3,0.442880311766857,0.0405524572440966,0.0413267537951469,172.859115600586,56.0043106079102,56.0084266662598,419.813354492188,419.813354492188,,,21.5347518920898,0,1,,,,,,1,1,1,56.0061378479004,0,56.0058773040771,,,,,,,,,,,,,,,,,,,,,,,,,,,,,,,,,
,3762226082.56903,56.0396347045898,440.079711914063,,,5,,,,31.6299982368946,,,,,0.000118024586260601,3.57791198769033E-7,0.0869889573421911,0.000717260643074542,0.000118005959622876,3.57734732169557E-7,0.000118005823617259,3.4766761489454E-7,1.79161738112879E-7,8.42696158408652E-8,1.00015784489008,10.005763053894,2,20,1,3,0.386023294746639,0.0346514587199349,0.0413267537951469,172.859115600586,56.0333023071289,56.041332244873,440.079711914063,440.079711914063,,,21.4909172058105,0,1,,,,,,1,1,1,56.0410957336426,0,56.0381289890834,,,,,,,,,,,,,,,,,,,,,,,,,,,,,,,,,
,3762226109.35872,56.060583114624,460.066772460937,,,5,,,,31.6299982368946,,,,,0.000107011611064437,4.55351723676952E-7,0.0978214019012427,0.000935007767173932,0.00010699474274228,4.55279946236233E-7,0.000106994586803247,4.44276357569587E-7,1.82672628513544E-7,9.94904394882639E-8,1.00015765561675,10.005763053894,2,20,1,3,0.349996706373403,0.0314917531418451,0.0413267537951469,172.859115600586,56.0489463806152,56.0607604980469,460.066772460937,460.066772460937,,,21.4743671417236,0,1,,,,,,1,1,1,56.0603675842285,0,56.0566878685584,,,,,,,,,,,,,,,,,,,,,,,,,,,,,,,,,
,3762226134.99207,56.0453071594238,480.284545898438,,,5,,,,31.6299982368946,,,,,9.66817161620181E-5,4.81510734355743E-7,0.155890274792272,0.00110287217201335,9.6666488236355E-5,4.81434893649146E-7,9.66661304379021E-5,4.69657197464954E-7,2.63009718167651E-7,1.05837959600181E-7,1.00015753055626,10.005763053894,2,20,1,3,0.316181871531726,0.0287791461979053,0.0413267537951469,172.859115600586,56.0374374389648,56.0468139648438,480.284545898438,480.284545898438,,,21.4433002471924,0,1,,,,,,1,1,1,56.0444564819336,0,56.0426254272461,,,,,,,,,,,,,,,,,,,,,,,,,,,,,,,,,
,3762226156.60714,56.0264358520508,500.077301025391,,,5,,,,31.6299982368946,,,,,8.98519122544302E-5,5.23591112519326E-7,0.0977469778314033,0.00114970788637762,8.98377551434173E-5,5.2350861524888E-7,8.98376244089196E-5,5.13362078741887E-7,1.5326372859256E-7,1.02570202055025E-7,1.00015758531578,10.005763053894,2,20,1,3,0.293872697230119,0.0264541507449717,0.0413267537951469,172.859115600586,56.0191764831543,56.0287971496582,500.077301025391,500.077301025391,,,21.4130592346191,0,1,,,,,,1,1,1,56.0253028869629,0,56.0237098693848,,,,,,,,,,,,,,,,,,,,,,,,,,,,,,,,,
,3762226178.59112,56.02707862854,520.112915039063,,,5,,,,31.6299982368946,,,,,8.48969232052718E-5,4.78808130605593E-7,-0.020314364949269,0.00161272342900755,8.48835443087657E-5,4.78732675286556E-7,8.48835389735161E-5,4.587853305448E-7,-3.00956767811246E-8,1.36751580846151E-7,1.00015761472515,10.005763053894,2,20,1,3,0.277717288840988,0.0244290589386505,0.0413267537951469,172.859115600586,56.0222969055176,56.0275955200195,520.112915039063,520.112915039063,,,21.3968868255615,0,1,,,,,,1,1,1,56.0266609191895,0,56.0254570007324,,,,,,,,,,,,,,,,,,,,,,,,,,,,,,,,,
,3762226200.20867,56.0410861968994,540.148620605469,,,5,,,,31.6299982368946,,,,,8.09945829917004E-5,4.95801197521189E-7,-0.0290884966792246,0.00220571456211565,8.09818136373274E-5,4.95723031044421E-7,8.09818032008296E-5,4.6246110520798E-7,-4.11136585607516E-8,1.78524647255447E-7,1.00015768175346,10.005763053894,2,20,1,3,0.264955055061496,0.0232712649825218,0.0413267537951469,172.859115600586,56.036563873291,56.0412292480469,540.148620605469,540.148620605469,,,21.3810539245605,0,1,,,,,,1,1,1,56.0412292480469,0,56.0394248962402,,,,,,,,,,,,,,,,,,,,,,,,,,,,,,,,,
,3762226222.13452,56.0614891052246,560.087036132812,,,5,,,,31.6299982368946,,,,,7.88654473636176E-5,5.52712301872222E-7,-0.177942663298818,0.00148945676540854,7.88530124746626E-5,5.5262515450506E-7,7.88526321952163E-5,5.3991835005083E-7,-2.44892252311294E-7,1.17825025653001E-7,1.00015769706907,10.005763053894,2,20,1,3,0.258047753127405,0.0219946921525716,0.0413267537951469,172.859115600586,56.0477905273438,56.0616149902344,560.087036132812,560.087036132812,,,21.3505096435547,0,1,,,,,,1,1,1,56.0614204406738,0,56.0569918496268,,,,,,,,,,,,,,,,,,,,,,,,,,,,,,,,,
,3762226248.05387,56.051830291748,580.171264648438,,,5,,,,31.6299982368946,,,,,7.27657826938025E-5,5.48637687988747E-7,-0.0974166662872413,0.00191534431602735,7.27543166523953E-5,5.48551236607134E-7,7.27542114925526E-5,5.30542911987344E-7,-1.23699854190662E-7,1.39401139605118E-7,1.00015759946536,10.005763053894,2,20,1,3,0.238060582483008,0.0206332848973145,0.0413267537951469,172.859115600586,56.0444412231445,56.0524520874023,580.171264648438,580.171264648438,,,21.3341293334961,0,1,,,,,,1,1,1,56.0512504577637,0,56.0494129180908,,,,,,,,,,,,,,,,,,,,,,,,,,,,,,,,,
,3762226270.79953,56.0284690856934,600.1826171875,,,5,,,,31.6299982368946,,,,,6.90287122455457E-5,5.58825557555024E-7,-0.143539376003591,0.00182460969266621,6.90178454688663E-5,5.58737584994923E-7,6.90176288840445E-5,5.44307776733699E-7,-1.7290572173178E-7,1.26161535632603E-7,1.00015744879611,10.005763053894,2,20,1,3,0.225849773788984,0.019396651673995,0.0413267537951469,172.859115600586,56.0203475952148,56.0318412780762,600.1826171875,600.1826171875,,,21.3172149658203,0,1,,,,,,1,1,1,56.0272369384766,0,56.0256393432617,,,,,,,,,,,,,,,,,,,,,,,,,,,,,,,,,
,3762226292.70957,56.0464305877686,620.193969726563,,,5,,,,31.6299982368946,,,,,6.78065887739672E-5,4.40856121238842E-7,-0.318374309233277,0.00126844249830042,6.77958898025719E-5,4.40786560048464E-7,6.77948431488587E-5,4.32158752026972E-7,-3.7671812290855E-7,8.67848175999024E-8,1.00015781150489,10.005763053894,2,20,1,3,0.221908038687993,0.0183809353278348,0.0413267537951469,172.859115600586,56.0363349914551,56.0466156005859,620.193969726563,620.193969726563,,,21.3003711700439,0,1,,,,,,1,1,1,56.0466156005859,0,56.0428044455392,,,,,,,,,,,,,,,,,,,,,,,,,,,,,,,,,
,3762226319.54311,56.0383262634277,640.047485351562,,,5,,,,31.6299982368946,,,,,6.25501954993678E-5,5.47910116357144E-7,-0.565780790971727,0.0028191048887659,6.25403347491337E-5,5.478237408508E-7,6.25372856060187E-5,5.18336895159221E-7,-6.17559361474179E-7,1.77306836180851E-7,1.00015767025031,10.005763053894,2,20,1,3,0.204776720708976,0.0160763039473309,0.0413267537951469,172.859115600586,56.0324516296387,56.0388870239258,640.047485351562,640.047485351562,,,21.2701473236084,0,1,,,,,,1,1,1,56.0379600524902,0,56.0363594055176,,,,,,,,,,,,,,,,,,,,,,,,,,,,,,,,,
,3762226341.16585,56.0203266143799,660.168090820312,,,5,,,,31.6299982368946,,,,,5.95417975876682E-5,6.23208099218294E-7,-0.483298536058482,0.00289689813796736,5.95324191275859E-5,6.23109937380421E-7,5.95303012217143E-5,5.98425421026311E-7,-5.02158973356864E-7,1.73646219457019E-7,1.00015753534326,10.005763053894,2,20,1,3,0.194905373983289,0.0155879019191065,0.0413267537951469,172.859115600586,56.0143165588379,56.0213737487793,660.168090820312,660.168090820312,,,21.2535552978516,0,1,,,,,,1,1,1,56.019702911377,0,56.0181461334229,,,,,,,,,,,,,,,,,,,,,,,,,,,,,,,,,
,3762226363.07256,56.0198974609375,680.179443359375,,,5,,,,31.6299982368946,,,,,5.78581521572743E-5,6.76474030955144E-7,-0.530968114155794,0.00223598978219971,5.78490333862793E-5,6.76367414833779E-7,5.78465493689516E-5,6.63437075984608E-7,-5.36087522989561E-7,1.31621145937587E-7,1.00015763048164,10.005763053894,2,20,1,3,0.189406414728715,0.0149936036864295,0.0413267537951469,172.859115600586,56.0190925598145,56.0202903747559,680.179443359375,680.179443359375,,,21.2101669311523,0,1,,,,,,1,1,1,56.0200233459473,0,56.0196703130549,,,,,,,,,,,,,,,,,,,,,,,,,,,,,,,,,
,3762226386.18284,56.0403709411621,700.215087890625,,,5,,,,31.6299982368946,,,,,5.6679083741761E-5,5.83255812878876E-7,-0.554159225659694,0.0032030766724545,5.66701432445172E-5,5.83163810739052E-7,5.66674926408167E-5,5.53834353745452E-7,-5.48099586826932E-7,1.82613084873594E-7,1.00015776380175,10.005763053894,2,20,1,3,0.185552296629835,0.0146169255055182,0.0413267537951469,172.859115600586,56.0374908447266,56.0406379699707,700.215087890625,700.215087890625,,,21.2075252532959,0,1,,,,,,1,1,1,56.040584564209,0,56.0395511627197,,,,,,,,,,,,,,,,,,,,,,,,,,,,,,,,,
,3762226407.82516,56.0551204681396,720.092895507812,,,5,,,,31.6299982368946,,,,,5.61713427891536E-5,5.60550275788991E-7,-0.854552554108493,0.00287661591443952,5.61624896022504E-5,5.60461927244808E-7,5.61562430468932E-5,5.36110675618447E-7,-8.3761875643792E-7,1.63410267054726E-7,1.00015763522888,10.005763053894,2,20,1,3,0.183963321762299,0.0135255908502165,0.0413267537951469,172.859115600586,56.0487251281738,56.0561218261719,720.092895507812,720.092895507812,,,21.1644878387451,0,1,,,,,,1,1,1,56.0541076660156,0,56.0528999328613,,,,,,,,,,,,,,,,,,,,,,,,,,,,,,,,,
,3762226429.75616,56.048454284668,740.128479003906,,,5,,,,31.6299982368946,,,,,5.43827986804417E-5,6.15706103837542E-7,-1.03486651558867,0.00389830819116583,5.43742314887767E-5,6.15609108605062E-7,5.4365362487147E-5,5.77273168906124E-7,-9.82044620259464E-7,2.13846353858558E-7,1.00015755977474,10.005763053894,2,20,1,3,0.17814592956367,0.0125381682407458,0.0413267537951469,172.859115600586,56.0397071838379,56.0503616333008,740.128479003906,740.128479003906,,,21.1470623016357,0,1,,,,,,1,1,1,56.0474815368652,0,56.0455345153809,,,,,,,,,,,,,,,,,,,,,,,,,,,,,,,,,
,3762226451.43749,56.0336570739746,760.1884765625,,,5,,,,31.6299982368946,,,,,5.20825731787172E-5,5.60098151010919E-7,-1.00227879069956,0.00225279746254267,5.2074367748119E-5,5.60009909470116E-7,5.20664003824289E-5,5.46880127120751E-7,-9.10893837362157E-7,1.20553827252057E-7,1.0001575713917,10.005763053894,2,20,1,3,0.170603881272612,0.0121085412563925,0.0413267537951469,172.859115600586,56.0262069702148,56.0349426269531,760.1884765625,760.1884765625,,,21.1173419952393,0,1,,,,,,1,1,1,56.0329055786133,0,56.0307292938232,,,,,,,,,,,,,,,,,,,,,,,,,,,,,,,,,
,3762226473.36983,56.0522441864014,780.11474609375,,,5,,,,31.6299982368946,,,,,5.19657498688605E-5,5.73886911083627E-7,-1.02433500819448,0.00299819082803666,5.19575484763297E-5,5.73796338507691E-7,5.19492452695283E-5,5.51546737887383E-7,-9.28848532612076E-7,1.58235375345144E-7,1.00015784795032,10.005763053894,2,20,1,3,0.170225686363004,0.0120194781895688,0.0413267537951469,172.859115600586,56.0470275878906,56.052791595459,780.11474609375,780.11474609375,,,21.1019515991211,0,1,,,,,,1,1,1,56.0526161193848,0,56.0507228851318,,,,,,,,,,,,,,,,,,,,,,,,,,,,,,,,,
,3762226494.99182,56.0329933166504,800.174682617187,,,5,,,,31.6299982368946,,,,,5.00511098524887E-5,6.09779613233786E-7,-1.40151132880596,0.00351308672310331,5.00432317342492E-5,6.09683633026609E-7,5.00282610497393E-5,5.82811813304611E-7,-1.22398478213902E-6,1.79009839542736E-7,1.0001574262486,10.005763053894,2,20,1,3,0.164026366900834,0.0105006064209634,0.0413267537951469,172.859115600586,56.0227584838867,56.0366706848145,800.174682617187,800.174682617187,,,21.0850944519043,0,1,,,,,,1,1,1,56.0308990478516,0,56.029077911377,,,,,,,,,,,,,,,,,,,,,,,,,,,,,,,,,
,3762226516.89147,56.0538463592529,820.198181152344,,,5,,,,31.6299982368946,,,,,4.84599432843844E-5,6.5971405465662E-7,-1.14698096718327,0.00432082365480534,4.84523027580195E-5,6.59610039623043E-7,4.84425945945387E-5,6.24655535413729E-7,-9.69882211384639E-7,2.11874647960769E-7,1.00015769170772,10.005763053894,2,20,1,3,0.158764955650242,0.0108755819643591,0.0413267537951469,172.859115600586,56.0498085021973,56.0543174743652,820.198181152344,820.198181152344,,,21.0687160491943,0,1,,,,,,1,1,1,56.0542907714844,0,56.0526161193848,,,,,,,,,,,,,,,,,,,,,,,,,,,,,,,,,
,3762226538.55284,56.0328063964844,840.209533691406,,,5,,,,31.6299982368946,,,,,4.78181211980928E-5,6.30196483799417E-7,-1.58737309095607,0.00500614419362706,4.7810594964374E-5,6.30097295334729E-7,4.77922473697414E-5,5.81878734241304E-7,-1.32441768217836E-6,2.41743128601161E-7,1.00015741769632,10.005763053894,2,20,1,3,0.156739951734997,0.00953044337125247,0.0413267537951469,172.859115600586,56.0237121582031,56.0362701416016,840.209533691406,840.209533691406,,,21.0261497497559,0,1,,,,,,1,1,1,56.0309028625488,0,56.0292594909668,,,,,,,,,,,,,,,,,,,,,,,,,,,,,,,,,
,3762226560.47415,56.0152778625488,860.123718261719,,,5,,,,31.6299982368946,,,,,4.53185275997415E-5,5.85653115347876E-7,-1.46624459388979,0.00328212813525998,4.53113895202101E-5,5.85560869665226E-7,4.52965533684754E-5,5.65352579495162E-7,-1.15942795768676E-6,1.52505714454451E-7,1.00015753389174,10.005763053894,2,20,1,3,0.148527150083652,0.00934944616931453,0.0413267537951469,172.859115600586,56.0100555419922,56.0171356201172,860.123718261719,860.123718261719,,,21.009614944458,0,1,,,,,,1,1,1,56.01416015625,0,56.0131114612926,,,,,,,,,,,,,,,,,,,,,,,,,,,,,,,,,
,3762226583.53088,56.0059795379639,880.159423828125,,,5,,,,31.6299982368946,,,,,4.27061985400188E-5,5.34312618091657E-7,-1.73324269211228,0.00590640149406926,4.26994704889058E-5,5.3422844102304E-7,4.26799346140198E-5,4.70213883081944E-7,-1.29149579013297E-6,2.53572339490939E-7,1.00015756755379,10.005763053894,2,20,1,3,0.140004930812599,0.00816117844571727,0.0413267537951469,172.859115600586,56.0043907165527,56.0067520141602,880.159423828125,880.159423828125,,,21.0471515655518,0,1,,,,,,1,1,1,56.0056114196777,0,56.0053310394287,,,,,,,,,,,,,,,,,,,,,,,,,,,,,,,,,
,3762226605.23825,56.0441913604736,900.097900390625,,,5,,,,31.6299982368946,,,,,4.34086462997665E-5,5.38212737259422E-7,-1.51893681055975,0.003834038257251,4.34017914815899E-5,5.38127746116672E-7,4.33865409011129E-5,5.10850999234544E-7,-1.15046618701917E-6,1.69152971365204E-7,1.00015793859983,10.005763053894,2,20,1,3,0.142275652777009,0.00883066523951798,0.0413267537951469,172.859115600586,56.0407409667969,56.0462417602539,900.097900390625,900.097900390625,,,20.9767799377441,0,1,,,,,,1,1,1,56.0454406738281,0,56.0442821502686,,,,,,,,,,,,,,,,,,,,,,,,,,,,,,,,,
,3762226627.17572,56.0676593780518,920.109252929688,,,5,,,,31.6299982368946,,,,,4.48385140811324E-5,5.1640396496048E-7,-1.73422298814329,0.00343189597030033,4.48314470733154E-5,5.16322574420854E-7,4.48109125692931E-5,4.91885444590249E-7,-1.35674662138713E-6,1.56964041285996E-7,1.00015763505928,10.005763053894,2,20,1,3,0.146995304702206,0.00857242060320517,0.0413267537951469,172.859115600586,56.0587310791016,56.0680313110352,920.109252929688,920.109252929688,,,20.9604988098145,0,1,,,,,,1,1,1,56.0672874450684,0,56.0648536682129,,,,,,,,,,,,,,,,,,,,,,,,,,,,,,,,,
,3762226648.97089,56.0391139984131,939.877746582031,,,5,,,,31.6299982368946,,,,,4.27033907818737E-5,5.97592888475434E-7,-1.69504066395934,0.00409406847416911,4.2696671949439E-5,5.97498864876643E-7,4.26779889185601E-5,5.70236162923726E-7,-1.26295582870718E-6,1.78425368215686E-7,1.00015736197057,10.005763053894,2,20,1,3,0.139989958567224,0.00826291820544578,0.0413267537951469,172.859115600586,56.027946472168,56.0422325134277,939.877746582031,939.877746582031,,,20.931058883667,0,1,,,,,,1,1,1,56.0374717712402,0,56.0346561431885,,,,,,,,,,,,,,,,,,,,,,,,,,,,,,,,,
,3762226670.80412,56.017391204834,959.986145019531,,,5,,,,31.6299982368946,,,,,4.0285595312302E-5,6.16831540943811E-7,-1.8797957814613,0.0045548957394844,4.02792506934538E-5,6.16734395525196E-7,4.0257574226056E-5,5.87561284862794E-7,-1.32126979065433E-6,1.87438126202252E-7,1.00015751581122,10.005763053894,2,20,1,3,0.132088322538209,0.00737203750152391,0.0413267537951469,172.859115600586,56.0123405456543,56.0196914672852,959.986145019531,959.986145019531,,,20.9014625549316,0,1,,,,,,1,1,1,56.0162734985352,0,56.015544128418,,,,,,,,,,,,,,,,,,,,,,,,,,,,,,,,,
,3762226692.4353,56.0119514465332,980.021850585938,,,5,,,,31.6299982368946,,,,,3.87497896557198E-5,6.95589967523043E-7,-2.01907861916488,0.00569186033765007,3.87436832156367E-5,6.95480352000048E-7,3.871962922372E-5,6.58133306284911E-7,-1.36502816500548E-6,2.24840990872666E-7,1.00015761124334,10.005763053894,2,20,1,3,0.127069513875854,0.0067848379582482,0.0413267537951469,172.859115600586,56.0094451904297,56.0124015808105,980.021850585938,980.021850585938,,,20.884765625,0,1,,,,,,1,1,1,56.0117378234863,0,56.0109390258789,,,,,,,,,,,,,,,,,,,,,,,,,,,,,,,,,
,3762226714.45428,56.0059547424316,999.923889160156,,,5,,,,31.6299982368946,,,,,3.8402109256939E-5,6.40289692800545E-7,-2.18948056987411,0.0042191407434659,3.83960593273555E-5,6.40188820540415E-7,3.83680281890316E-5,6.1782434527783E-7,-1.46689630017785E-6,1.67734326620846E-7,1.0001575664193,10.005763053894,2,20,1,3,0.125948764391894,0.00635208980929681,0.0413267537951469,172.859115600586,56.0035400390625,56.0073509216309,999.923889160156,999.923889160156,,,20.8691387176514,0,1,,,,,,1,1,1,56.0047721862793,0,56.0047208612615,,,,,,,,,,,,,,,,,,,,,,,,,,,,,,,,,