File: Experimental_Data/AC_Suceptibillity_FieldScans/FCd_Down_52K.dat
[Header]
; MPMS3 Data File (default extension .dat)
; Copyright (c) 2007, Quantum Design, Inc. All rights reserved.
TITLE,FCd_Down_52K
FILEOPENTIME,3772386293.67845,07/15/2019,9:04 pm
BYAPP,SQUID AC,0.9.1.0
INFO,MPMS3 Measurement Release 1.1.16 Build 347, MultiVu Release 2.3.3.2,APPNAME
INFO,0,MOMENT_UNITS
INFO,Cu2OSeO3,SAMPLE_MATERIAL
INFO,,SAMPLE_COMMENT
INFO,,SAMPLE_MASS
INFO,,SAMPLE_VOLUME
INFO,,SAMPLE_MOLECULAR_WEIGHT
INFO,,SAMPLE_SIZE
INFO,,SAMPLE_SHAPE
INFO,Quartz,SAMPLE_HOLDER
INFO,Standard,SAMPLE_HOLDER_DETAIL
INFO,64.77,SAMPLE_OFFSET
DATATYPE,COMMENT,1
DATATYPE,TIME,2
STARTUPAXIS,X,2
STARTUPAXIS,Y1,5
FIELDGROUP, VSM,2,3,4,5,6,8,9,10,11,14,15
FIELDGROUP, DC, 2,3,4,14,56,57,58,59,60,61,62,63,64,65,66,67,68,69
FIELDGROUP, AC, 2,3,4,11,16,17,18,19,20,21,22,23,24,25,26,27,28,29,30
STARTUPGROUP, All
[Data]
Comment,Time Stamp (sec),Temperature (K),Magnetic Field (Oe),Moment (emu),M. Std. Err. (emu),Transport Action,Averaging Time (sec),Frequency (Hz),Peak Amplitude (mm),Center Position (mm),Lockin Signal' (V),Lockin Signal (V),Range,M. Quad. Signal (emu),AC Moment (emu),AC M. Std Err. (emu),AC Phase (deg),AC Phase Std. Err. (deg),AC Susceptibility (emu/Oe),AC Suscept. Std Err. (emu/Oe),AC X' (emu/Oe),AC X' Std Err. (emu/Oe),AC X'' (emu/Oe),AC X'' Std Err. (emu/Oe),AC Drive (Oe),AC Frequency (Hz),AC Averaging Time (sec),AC Cycles,AC Range,AC Measure Type,AC Signal' (V),AC Signal'' (V),AC Trim Coil Ratio,AC Trim Coil Phase,Min. Temperature (K),Max. Temperature (K),Min. Field (Oe),Max. Field (Oe),Mass (grams),Motor Lag (deg),Pressure (Torr),Measure Count,Measurement Number,SQUID Status (code),Motor Status (code),Measure Status (code),Motor Current (amps),Motor Temp. (C),Temp. Status (code),Field Status (code),Chamber Status (code),Chamber Temp (K),Redirection State,Average Temp (K),Rotation Angle (deg),Rotator state,DC Moment Fixed Ctr (emu),DC Moment Err Fixed Ctr (emu),DC Moment Free Ctr (emu),DC Moment Err Free Ctr (emu),DC Fixed Fit,DC Free Fit,DC Calculated Center (mm),DC Calculated Center Err (mm),DC Scan Length (mm),DC Scan Time (s),DC Number of Points,DC Squid Drift,DC Min V (V),DC Max V (V),DC Scans per Measure,Map 01,Map 02,Map 03,Map 04,Map 05,Map 06,Map 07,Map 08,Map 09,Map 10,Map 11,Map 12,Map 13,Map 14,Map 15,Map 16
,3772386436.09476,51.9442272186279,199.894912719727,,,5,,,,6.49000005796552,,,,,0.000660456537719386,2.24014693831267E-7,0.0169024048878033,0.000194746117724515,0.000660355934132623,2.23980570947473E-7,0.000660355905398375,1.83406700713419E-7,1.94806725761222E-7,1.2856624088529E-7,1.00015234751679,10.005763053894,2,20,1,3,2.1604259998585,0.190719979113484,0.0403775237500668,172.74836730957,51.9117546081543,51.9532814025879,199.894912719727,199.894912719727,,,23.9460506439209,0,1,,,,,,1,1,1,51.9393463134766,0,51.9293390909831,,,,,,,,,,,,,,,,,,,,,,,,,,,,,,,,,
,3772386460.37503,51.8960571289063,179.859283447266,,,5,,,,6.47999998182058,,,,,0.000659460642457838,7.88775377610795E-8,0.0187116177389424,5.97606367699821E-5,0.000659359979483358,7.8865497546608E-8,0.000659359944321648,6.83259488466158E-8,2.15333341722344E-7,3.93869447594464E-8,1.00015266770446,10.005763053894,2,20,10,3,2.15716517071841,0.190454390810608,0.0403775237500668,172.74836730957,51.890682220459,51.898551940918,179.859283447266,179.859283447266,,,23.9717407226562,0,1,,,,,,1,1,1,51.8948631286621,0,51.893723227761,,,,,,,,,,,,,,,,,,,,,,,,,,,,,,,,,
,3772386482.09296,51.8870105743408,159.908660888672,,,5,,,,6.47999998182058,,,,,0.000659942160024321,1.34153080176543E-7,0.0452060234893903,0.000172585819112435,0.000659841393848049,1.34132596422446E-7,0.000659841188468647,7.08744310998126E-8,5.2061081476273E-7,1.13878744457886E-7,1.00015271272341,10.005763053894,2,20,10,3,2.15865478959234,0.19154560133096,0.0403775237500668,172.74836730957,51.883228302002,51.8885650634766,159.908660888672,159.908660888672,,,23.9601879119873,0,1,,,,,,1,1,1,51.8860740661621,0,51.8857280731201,,,,,,,,,,,,,,,,,,,,,,,,,,,,,,,,,
,3772386503.90038,51.9309844970703,140.043014526367,,,5,,,,6.47999998182058,,,,,0.000669923988423552,1.34551266286431E-7,0.169364210486415,0.00012892073786079,0.000669821349499035,1.34530651712983E-7,0.00066981842314617,1.03180101852231E-7,1.97996431469123E-6,8.6327068941805E-8,1.00015323328316,10.005763053894,2,20,10,3,2.19088164786334,0.199144081498842,0.0403775237500668,172.74836730957,51.9225997924805,51.9543571472168,140.043014526367,140.043014526367,,,24.0094585418701,0,1,,,,,,1,1,1,51.9345245361328,0,51.9399833679199,,,,,,,,,,,,,,,,,,,,,,,,,,,,,,,,,
,3772386526.92819,51.9615840911865,119.922378540039,,,5,,,,6.47999998182058,,,,,0.000697590271085219,2.54876124328614E-7,0.24917806086858,7.37178374601971E-5,0.000697483697289207,2.54837185832467E-7,0.000697477101333667,2.49727410659255E-7,3.03333140414191E-6,5.0776093276615E-8,1.00015279754412,10.005763053894,2,20,10,3,2.2810720814144,0.210496813931889,0.0403775237500668,172.74836730957,51.9603042602539,51.9617004394531,119.922378540039,119.922378540039,,,23.986608505249,0,1,,,,,,1,1,1,51.9614410400391,0,51.9610346013849,,,,,,,,,,,,,,,,,,,,,,,,,,,,,,,,,
,3772386550.0877,51.9591751098633,99.8746109008789,,,5,,,,6.47999998182058,,,,,0.000705473971931579,8.04723639201796E-8,0.224863525910536,7.24702774731989E-5,0.000705366271456945,8.04600786876494E-8,0.00070536083924253,6.21511121498991E-8,2.76827963659679E-6,5.10985667211264E-8,1.00015268730444,10.005763053894,2,20,10,3,2.30694462610869,0.211847238500363,0.0403775237500668,172.74836730957,51.9590263366699,51.9668884277344,99.8746109008789,99.8746109008789,,,23.999662399292,0,1,,,,,,1,1,1,51.9591217041016,0,51.961275100708,,,,,,,,,,,,,,,,,,,,,,,,,,,,,,,,,
,3772386570.60342,51.979959487915,79.9846878051758,,,5,,,,6.47999998182058,,,,,0.000688712686947585,4.33424949079605E-8,0.15227142141108,5.82319865312242E-5,0.000688607364504204,4.33358666904868E-8,0.000688604932675667,1.64164517845105E-8,1.83006671076985E-6,4.01060775023248E-8,1.000152949923,10.005763053894,2,20,10,3,2.25239748066394,0.203912404300337,0.0403775237500668,172.74836730957,51.9759063720703,51.9877052307129,79.9846878051758,79.9846878051758,,,24.0112380981445,0,1,,,,,,1,1,1,51.9815483093262,0,51.9828651428223,,,,,,,,,,,,,,,,,,,,,,,,,,,,,,,,,
,3772386593.67561,51.9946041107178,59.9490509033203,,,5,,,,6.47999998182058,,,,,0.000669800305239074,3.56428750331442E-8,0.0763541929980223,2.8574322514828E-5,0.00066969796412524,3.56374290345345E-8,0.000669697369464268,3.00697881305337E-8,8.92460717051104E-7,1.91267924644017E-8,1.00015281682089,10.005763053894,2,20,10,3,2.19080937565904,0.195363191468223,0.0403775237500668,172.74836730957,51.9940032958984,51.9977035522461,59.9490509033203,59.9490509033203,,,24.0111808776855,0,1,,,,,,1,1,1,51.9950866699219,0,51.9957660675049,,,,,,,,,,,,,,,,,,,,,,,,,,,,,,,,,
,3772386615.2889,52.0008373260498,39.9255561828613,,,5,,,,6.47999998182058,,,,,0.000651686894855655,4.39960694944551E-8,0.0405188899872408,5.53537191671007E-5,0.000651587359799714,4.3989349777866E-8,0.00065158719686544,2.51843052899161E-8,4.60794749151365E-7,3.60667944367633E-8,1.00015275780668,10.005763053894,2,20,10,3,2.13168463979255,0.188701072311499,0.0403775237500668,172.74836730957,52.0004043579102,52.0018882751465,39.9255561828613,39.9255561828613,,,23.9857177734375,0,1,,,,,,1,1,1,52.0011215209961,0,52.0013694763184,,,,,,,,,,,,,,,,,,,,,,,,,,,,,,,,,
,3772386635.77455,52.0357418060303,19.8170642852783,,,5,,,,6.47999998182058,,,,,0.000635916521818259,2.58952090265685E-8,0.0280225032648138,2.68310673612941E-5,0.000635819182466672,2.58912452628207E-8,0.000635819106421401,1.94787925117642E-8,3.10969578520336E-7,1.70567647443228E-8,1.00015309281989,10.005763053894,2,20,10,3,2.08014225064591,0.183636082272178,0.0403775237500668,172.74836730957,52.0318336486816,52.0382995605469,19.8170642852783,19.8170642852783,,,24.0108127593994,0,1,,,,,,1,1,1,52.0371322631836,0,52.0364139556885,,,,,,,,,,,,,,,,,,,,,,,,,,,,,,,,,
,3772386657.72137,52.0615158081055,-0.0242856182157993,,,5,,,,6.47999998182058,,,,,0.000627114836671122,3.82091459665473E-8,0.0227641834364887,1.92168545898411E-5,0.000627019040390777,3.82033092459904E-8,0.00062701899090167,3.62589301984592E-8,2.49120898596751E-7,1.20325732164004E-8,1.00015278049656,10.005763053894,2,20,10,3,2.05137043592686,0.180862596971188,0.0403775237500668,172.74836730957,52.050838470459,52.0618362426758,-0.0242856182157993,-0.0242856182157993,,,23.9854011535645,0,1,,,,,,1,1,1,52.061206817627,0,52.0580811934038,,,,,,,,,,,,,,,,,,,,,,,,,,,,,,,,,
,3772386680.6991,52.0443458557129,-19.9506359100342,,,5,,,,6.47999998182058,,,,,0.000625227723077718,3.18287995886026E-8,0.0217346217158338,3.21763239988684E-5,0.00062513234755193,3.18239442560831E-8,0.000625132302573853,2.46644201541149E-8,2.37138143262534E-7,2.01104402357475E-8,1.00015256853395,10.005763053894,2,20,10,3,2.04519797830073,0.180325265187666,0.0403775237500668,172.74836730957,52.032356262207,52.0471076965332,-19.9506359100342,-19.9506359100342,,,23.9844245910645,0,1,,,,,,1,1,1,52.0426406860352,0,52.0400234222412,,,,,,,,,,,,,,,,,,,,,,,,,,,,,,,,,
,3772386702.38808,52.0490684509277,-40.0469856262207,,,5,,,,6.47999998182058,,,,,0.000626840726291482,5.46391102066625E-8,0.0225785621144405,7.44971549435124E-5,0.000626744969281816,5.46307634646837E-8,0.000626744920617777,2.8365368124984E-8,2.46981539876892E-7,4.668967988612E-8,1.00015278464824,10.005763053894,2,20,10,3,2.05046890999255,0.18086476702618,0.0403775237500668,172.74836730957,52.0425453186035,52.049373626709,-40.0469856262207,-40.0469856262207,,,23.9705123901367,0,1,,,,,,1,1,1,52.0487937927246,0,52.0470672607422,,,,,,,,,,,,,,,,,,,,,,,,,,,,,,,,,
,3772386724.29094,52.0582237243652,-59.9126205444336,,,5,,,,6.47999998182058,,,,,0.000631796485212647,3.94148829601061E-8,0.0341413828114625,2.90908982979217E-5,0.000631699996450626,3.94088634690975E-8,0.000631699884301004,3.48675764024231E-8,3.76417081812832E-7,1.83660185055757E-8,1.00015274459801,10.005763053894,2,20,10,3,2.06664020371662,0.182755657053756,0.0403775237500668,172.74836730957,52.0496635437012,52.058910369873,-59.9126205444336,-59.9126205444336,,,23.9698486328125,0,1,,,,,,1,1,1,52.0575866699219,0,52.0556928461248,,,,,,,,,,,,,,,,,,,,,,,,,,,,,,,,,
,3772386745.91381,52.0411472320557,-79.9118270874023,,,5,,,,6.47999998182058,,,,,0.000642428881685801,8.66108095153401E-8,0.0672086933205795,3.84884897035301E-5,0.000642330828815333,8.65975902490079E-8,0.000642330386904793,8.30121279006816E-8,7.53462229696504E-7,2.46602769314526E-8,1.00015265166495,10.005763053894,2,20,10,3,2.10130890574818,0.187089019434974,0.0403775237500668,172.74836730957,52.030445098877,52.0429000854492,-79.9118270874023,-79.9118270874023,,,23.9564990997314,0,1,,,,,,1,1,1,52.0402336120605,0,52.0372520446777,,,,,,,,,,,,,,,,,,,,,,,,,,,,,,,,,
,3772386767.96641,52.0277099609375,-100.03246307373,,,5,,,,6.47999998182058,,,,,0.000660878454259353,9.24850281992834E-8,0.11818038275314,7.28450440103069E-5,0.000660777612647329,9.2470916165109E-8,0.000660776207018388,7.89749986556073E-8,1.36294324762508E-6,4.81021821101854E-8,1.00015261051539,10.005763053894,2,20,10,3,2.16148022340587,0.194431502029487,0.0403775237500668,172.74836730957,52.022762298584,52.0294952392578,-100.03246307373,-100.03246307373,,,23.9304122924805,0,1,,,,,,1,1,1,52.0268669128418,0,52.0261299826882,,,,,,,,,,,,,,,,,,,,,,,,,,,,,,,,,
,3772386789.59671,52.0164737701416,-119.934532165527,,,5,,,,6.47999998182058,,,,,0.000682480876297467,1.71040097241559E-7,0.189572067916798,9.81604718420937E-5,0.000682376697785208,1.71013988520441E-7,0.000682372962728273,1.57410946354217E-7,2.25774615121403E-6,6.68399449247184E-8,1.00015267009058,10.005763053894,2,20,10,3,2.23187844992738,0.203615675204988,0.0403775237500668,172.74836730957,52.0114479064941,52.0179061889648,-119.934532165527,-119.934532165527,,,23.9415550231934,0,1,,,,,,1,1,1,52.0155296325684,0,52.0145923614502,,,,,,,,,,,,,,,,,,,,,,,,,,,,,,,,,
,3772386811.55274,52.0421924591064,-139.933731079102,,,5,,,,6.47999998182058,,,,,0.000705301152889095,2.03223426173999E-7,0.167331289057941,7.60437850438913E-5,0.000705193308380174,2.03192352170352E-7,0.000705190301009732,1.96063138002294E-7,2.05950139062E-6,5.33514563738787E-8,1.00015292900208,10.005763053894,2,20,10,3,2.30658462021421,0.209577963153819,0.0403775237500668,172.74836730957,52.0362167358398,52.0427284240723,-139.933731079102,-139.933731079102,,,23.9162673950195,0,1,,,,,,1,1,1,52.0428085327148,0,52.040563583374,,,,,,,,,,,,,,,,,,,,,,,,,,,,,,,,,
,3772386833.417,52.0419120788574,-160.066513061523,,,5,,,,6.47999998182058,,,,,0.000717292106355366,8.39376483170777E-8,0.0860247172491944,9.1013027539807E-5,0.000717182602135149,8.39248341139875E-8,0.000717181793782415,5.27554238900652E-8,1.07678799223232E-6,6.52705372372547E-8,1.0001526866657,10.005763053894,2,20,10,3,2.34609617930294,0.209862534396229,0.0403775237500668,172.74836730957,52.0326194763184,52.0427589416504,-160.066513061523,-160.066513061523,,,23.9026489257813,0,1,,,,,,1,1,1,52.0413208007812,0,52.0384767705744,,,,,,,,,,,,,,,,,,,,,,,,,,,,,,,,,
,3772386855.97181,52.0223903656006,-180.089996337891,,,5,,,,6.47999998182058,,,,,0.000723893373754157,9.72809322719774E-8,0.0326618504726612,6.05774406298199E-5,0.000723782926950069,9.72660897986828E-8,0.000723782809348089,8.68375305619609E-8,4.12597378990968E-7,4.38170687132986E-8,1.00015259658659,10.005763053894,2,20,10,3,2.36788044588802,0.209639466893858,0.0403775237500668,172.74836730957,52.015941619873,52.0257873535156,-180.089996337891,-180.089996337891,,,23.8900737762451,0,1,,,,,,1,1,1,52.0205345153809,0,52.0202123468572,,,,,,,,,,,,,,,,,,,,,,,,,,,,,,,,,
,3772386878.16955,52.008810043335,-199.931350708008,,,5,,,,6.47999998182058,,,,,0.000729235356846508,7.50595891572716E-8,0.0195406867978054,5.7157044376869E-5,0.000729124046113848,7.50481320360777E-8,0.000729124003709947,6.24222657422166E-8,2.48667257287349E-7,4.1661527356935E-8,1.00015266364243,10.005763053894,2,20,10,3,2.38539940056846,0.210690932404967,0.0403775237500668,172.74836730957,52.0058441162109,52.0097274780273,-199.931350708008,-199.931350708008,,,23.8878841400146,0,1,,,,,,1,1,1,52.0081558227539,0,52.0076030731201,,,,,,,,,,,,,,,,,,,,,,,,,,,,,,,,,
,3772386899.77171,52.0352325439453,-220.06413269043,,,5,,,,6.47999998182058,,,,,0.000733124910132059,8.63184744040522E-8,0.0142284246333144,7.18766522471981E-5,0.000733012792334617,8.630527360144E-8,0.000733012769732458,6.83663541243413E-8,1.82031159230661E-7,5.26748694840772E-8,1.00015295476234,10.005763053894,2,20,10,3,2.39813892768202,0.211643936807702,0.0403775237500668,172.74836730957,52.0318336486816,52.0358047485352,-220.06413269043,-220.06413269043,,,23.8742961883545,0,1,,,,,,1,1,1,52.0358085632324,0,52.0342784881592,,,,,,,,,,,,,,,,,,,,,,,,,,,,,,,,,
,3772386921.73727,52.0301303863525,-239.966186523438,,,5,,,,6.47999998182058,,,,,0.000736528406192073,1.8881129751197E-7,0.00936429669587557,7.40866327766108E-5,0.0007364159398083,1.88782466412357E-7,0.000736415929972759,1.80751308204599E-7,1.20358207530128E-7,5.44773733494806E-8,1.00015272127842,10.005763053894,2,20,10,3,2.40928701963395,0.212473287610774,0.0403775237500668,172.74836730957,52.0246658325195,52.0313034057617,-239.966186523438,-239.966186523438,,,23.8727130889893,0,1,,,,,,1,1,1,52.0295181274414,0,52.0282196044922,,,,,,,,,,,,,,,,,,,,,,,,,,,,,,,,,
,3772386943.34171,52.0350360870361,-259.856140136719,,,5,,,,6.47999998182058,,,,,0.000739184550380873,1.1768729561802E-7,-0.00388361599640863,0.000108201372207319,0.000739071597315309,1.1766931209711E-7,0.000739071595617519,8.63300552844141E-8,-5.0095666731819E-8,7.99574171918849E-8,1.00015283101931,10.005763053894,2,20,10,3,2.41802169114372,0.212731897387548,0.0403775237500668,172.74836730957,52.0293159484863,52.035530090332,-259.856140136719,-259.856140136719,,,23.860179901123,0,1,,,,,,1,1,1,52.0345420837402,0,52.0331745147705,,,,,,,,,,,,,,,,,,,,,,,,,,,,,,,,,
,3772386965.24772,52.0184383392334,-279.928192138672,,,5,,,,6.47999998182058,,,,,0.000742077012738613,1.25503036831226E-7,-0.00933937294993203,7.87884899550861E-5,0.000741963755502982,1.25483882313877E-7,0.000741963745646025,1.1104755114607E-7,-1.20942175081262E-7,5.84349733038686E-8,1.00015264524014,10.005763053894,2,20,10,3,2.42750061209242,0.213385384752612,0.0403775237500668,172.74836730957,52.0142288208008,52.0211029052734,-279.928192138672,-279.928192138672,,,23.8341655731201,0,1,,,,,,1,1,1,52.0177001953125,0,52.0170024525036,,,,,,,,,,,,,,,,,,,,,,,,,,,,,,,,,
,3772386988.26229,52.0093116760254,-300.024505615234,,,5,,,,6.47999998182058,,,,,0.000744698638889499,1.37247101390582E-7,-0.0174135708219669,0.000156977915465256,0.000744584950746401,1.37226148796757E-7,0.000744584916357788,7.19094062956632E-8,-2.2629734132901E-7,1.16876230260027E-7,1.00015268659806,10.005763053894,2,20,10,3,2.43610345448081,0.21384837034621,0.0403775237500668,172.74836730957,52.0041122436523,52.0120086669922,-300.024505615234,-300.024505615234,,,23.8205509185791,0,1,,,,,,1,1,1,52.0077972412109,0,52.0069937272505,,,,,,,,,,,,,,,,,,,,,,,,,,,,,,,,,
,3772387009.93233,52.0380344390869,-320.060180664063,,,5,,,,6.47999998182058,,,,,0.000746726153012019,1.18979514865872E-7,-0.0180366676939121,0.000128444497813599,0.00074661194510481,1.18961317563771E-7,0.000746611908110726,7.04041341647379E-8,-2.35032867031146E-7,9.58908388169689E-8,1.00015296822929,10.005763053894,2,20,10,3,2.44273508857977,0.214456300637504,0.0403775237500668,172.74836730957,52.0350875854492,52.0392074584961,-320.060180664063,-320.060180664063,,,23.8064155578613,0,1,,,,,,1,1,1,52.0389060974121,0,52.0377178192139,,,,,,,,,,,,,,,,,,,,,,,,,,,,,,,,,
,3772387031.90919,52.0256175994873,-339.962219238281,,,5,,,,6.47999998182058,,,,,0.000749104794347951,1.56432890465748E-7,-0.0212042478618031,0.000106394479792998,0.000748990476292634,1.56409017832759E-7,0.000748990425000972,1.34599763765536E-7,-2.77189340608918E-7,7.9666080948358E-8,1.00015262951791,10.005763053894,2,20,10,3,2.45052490595811,0.215056204797975,0.0403775237500668,172.74836730957,52.0190162658691,52.0276947021484,-339.962219238281,-339.962219238281,,,23.7940788269043,0,1,,,,,,1,1,1,52.0247650146484,0,52.0233837127686,,,,,,,,,,,,,,,,,,,,,,,,,,,,,,,,,
,3772387053.48949,52.0545787811279,-359.937164306641,,,5,,,,6.47999998182058,,,,,0.000750786348790493,1.76206813410724E-7,-0.0301579810666803,0.000116160382793008,0.000750671554551665,1.76179871622219E-7,0.000750671450564624,1.53100963918011E-7,-3.9512050759252E-7,8.71747785325386E-8,1.00015292205777,10.005763053894,2,20,10,3,2.45605615506816,0.215207541408423,0.0403775237500668,172.74836730957,52.0500946044922,52.0552635192871,-359.937164306641,-359.937164306641,,,23.7806034088135,0,1,,,,,,1,1,1,52.0552864074707,0,52.0534069061279,,,,,,,,,,,,,,,,,,,,,,,,,,,,,,,,,
,3772387075.4568,52.0629634857178,-380.057800292969,,,5,,,,6.47999998182058,,,,,0.000752025377088817,2.02295985022526E-7,-0.0411102935615171,0.000159748709429804,0.00075191053629491,2.02265092672039E-7,0.000751910342745413,1.62750876838931E-7,-5.39503266898241E-7,1.20097126534266E-7,1.00015273199186,10.005763053894,2,20,10,3,2.46014731198287,0.215145389904261,0.0403775237500668,172.74836730957,52.0492134094238,52.0641403198242,-380.057800292969,-380.057800292969,,,23.7668952941895,0,1,,,,,,1,1,1,52.0620079040527,0,52.0585514704386,,,,,,,,,,,,,,,,,,,,,,,,,,,,,,,,,
,3772387098.51892,52.0297451019287,-400.020568847656,,,5,,,,6.47999998182058,,,,,0.000753218521855093,2.27969305256731E-7,-0.0486005930683042,0.000198987412026021,0.000753103606608442,2.27934524979584E-7,0.000753103335675023,1.71763020174404E-7,-6.38812803402334E-7,1.49838621784357E-7,1.00015258889433,10.005763053894,2,20,10,3,2.46407543209087,0.215217369921096,0.0403775237500668,172.74836730957,52.0203552246094,52.0337371826172,-400.020568847656,-400.020568847656,,,23.7412719726562,0,1,,,,,,1,1,1,52.0279083251953,0,52.0264720916748,,,,,,,,,,,,,,,,,,,,,,,,,,,,,,,,,
,3772387120.13791,52.0115203857422,-419.983337402344,,,5,,,,6.47999998182058,,,,,0.000754023186542987,2.00286885382836E-7,-0.0586096338842701,0.000200716438505956,0.000753908085194199,2.00256311666983E-7,0.000753907690754045,1.31184336816828E-7,-7.71195880833354E-7,1.51305188729247E-7,1.00015267292001,10.005763053894,2,20,10,3,2.46674217896784,0.215069135815878,0.0403775237500668,172.74836730957,52.0074462890625,52.0135536193848,-419.983337402344,-419.983337402344,,,23.7402591705322,0,1,,,,,,1,1,1,52.0103569030762,0,52.009785045277,,,,,,,,,,,,,,,,,,,,,,,,,,,,,,,,,
,3772387142.6885,52.0322914123535,-440.067535400391,,,5,,,,6.47999998182058,,,,,0.00075348471539298,2.03514507513233E-7,-0.0649890267320874,0.000158599052774526,0.000753369585324231,2.03483411143575E-7,0.000753369100691388,1.64720545567812E-7,-8.54526215320848E-7,1.19468156755126E-7,1.00015282017086,10.005763053894,2,20,10,3,2.46500128784937,0.214693998584306,0.0403775237500668,172.74836730957,52.0291786193848,52.0328941345215,-440.067535400391,-440.067535400391,,,23.7144927978516,0,1,,,,,,1,1,1,52.0328598022461,0,52.0315032958984,,,,,,,,,,,,,,,,,,,,,,,,,,,,,,,,,
,3772387164.42924,52.0191535949707,-460.346008300781,,,5,,,,6.47999998182058,,,,,0.000751788442560178,3.18134597722155E-7,-0.0699167871683182,0.00018178163200195,0.000751673678547676,3.18086032991862E-7,0.0007516731188971,2.87251570853828E-7,-9.17250729576935E-7,1.36620860144079E-7,1.00015267797154,10.005763053894,2,20,10,3,2.45946713910347,0.214052571328359,0.0403775237500668,172.74836730957,52.0131988525391,52.02099609375,-460.346008300781,-460.346008300781,,,23.688512802124,0,1,,,,,,1,1,1,52.0183982849121,0,52.0170497894287,,,,,,,,,,,,,,,,,,,,,,,,,,,,,,,,,
,3772387186.22415,52.0073146820068,-480.199554443359,,,5,,,,6.47999998182058,,,,,0.000746656174054771,3.20347486500957E-7,-0.0825363990146082,0.000259569748348745,0.000746542169626481,3.20298573717106E-7,0.000746541395039768,2.55046040204398E-7,-1.07541744970796E-6,1.93759370615381E-7,1.00015270996459,10.005763053894,2,20,10,3,2.44272058812574,0.212105217059943,0.0403775237500668,172.74836730957,52.0048484802246,52.0087890625,-480.199554443359,-480.199554443359,,,23.7111186981201,0,1,,,,,,1,1,1,52.0069198608398,0,52.0065418243408,,,,,,,,,,,,,,,,,,,,,,,,,,,,,,,,,
,3772387207.89326,52.0409679412842,-500.271606445313,,,5,,,,6.47999998182058,,,,,0.000730926969332433,3.46589433113235E-7,-0.107978172478789,0.000339195195523112,0.000730815163587701,3.46536417297277E-7,0.000730813865798648,2.42182949462036E-7,-1.37727490128658E-6,2.47860661467488E-7,1.00015298771879,10.005763053894,2,20,10,3,2.39135063234895,0.206626375512505,0.0403775237500668,172.74836730957,52.0381088256836,52.0419998168945,-500.271606445313,-500.271606445313,,,23.685510635376,0,1,,,,,,1,1,1,52.0418395996094,0,52.0403262051669,,,,,,,,,,,,,,,,,,,,,,,,,,,,,,,,,
,3772387229.8839,52.0651302337646,-520.307250976562,,,5,,,,6.47999998182058,,,,,0.00068505761645764,3.37786125792776E-7,-0.103609723771881,0.000264373485444341,0.00068495293431573,3.37734509440653E-7,0.000684951814397321,2.85090001617049E-7,-1.23862082418895E-6,1.81075370619833E-7,1.000152831146,10.005763053894,2,20,10,3,2.24126365061395,0.193878398001673,0.0403775237500668,172.74836730957,52.0534362792969,52.0656776428223,-520.307250976562,-520.307250976562,,,23.6728096008301,0,1,,,,,,1,1,1,52.064582824707,0,52.0611912120472,,,,,,,,,,,,,,,,,,,,,,,,,,,,,,,,,
,3772387252.91962,52.0320110321045,-540.3671875,,,5,,,,6.47999998182058,,,,,0.000577573164421913,4.72061341428238E-7,-0.121367174718309,0.000370098470254832,0.000577485053003022,4.71989326318883E-7,0.00057748375741236,4.20815291345427E-7,-1.22326072717031E-6,2.13748484740397E-7,1.00015257783458,10.005763053894,2,20,10,3,1.88966106327214,0.162914197216835,0.0403775237500668,172.74836730957,52.0210571289063,52.036304473877,-540.3671875,-540.3671875,,,23.6456966400146,0,1,,,,,,1,1,1,52.0301513671875,0,52.028297106425,,,,,,,,,,,,,,,,,,,,,,,,,,,,,,,,,
,3772387279.09191,52.0395469665527,-560.281372070313,,,5,,,,6.47999998182058,,,,,0.000384352468341206,4.08498255945431E-7,-0.186871313385608,0.00056380269754781,0.000384293789297855,4.08435890567702E-7,0.000384291745335014,3.46207359836654E-7,-1.25337954074331E-6,2.16703347225568E-7,1.00015269318679,10.005763053894,2,20,1,3,1.2576174547574,0.107002127457226,0.0403775237500668,172.74836730957,52.0308227539063,52.0417060852051,-560.281372070313,-560.281372070313,,,23.6444606781006,0,1,,,,,,1,1,1,52.0386009216309,0,52.0375823974609,,,,,,,,,,,,,,,,,,,,,,,,,,,,,,,,,
,3772387301.69488,52.0450878143311,-580.365539550781,,,5,,,,6.47999998182058,,,,,0.000182562175486809,3.76411661266024E-7,-0.463244694229399,0.000964640090927882,0.000182534299352382,3.76354185493501E-7,0.000182528333290351,3.32486968675384E-7,-1.47580022747918E-6,1.76337428243499E-7,1.00015271724014,10.005763053894,2,20,1,3,0.597588634809867,0.0479554090664384,0.0403775237500668,172.74836730957,52.0364151000977,52.0453147888184,-580.365539550781,-580.365539550781,,,23.6314182281494,0,1,,,,,,1,1,1,52.0448608398438,0,52.0422127463601,,,,,,,,,,,,,,,,,,,,,,,,,,,,,,,,,
,3772387324.67045,52.0420322418213,-600.425476074219,,,5,,,,6.47999998182058,,,,,0.000102440748873797,3.95979494173044E-7,-0.833593140923346,0.00281426161293683,0.000102425109362143,3.95919040437766E-7,0.000102414269299795,2.71466855443876E-7,-1.49012470481621E-6,2.88197211951426E-7,1.00015269216457,10.005763053894,2,20,1,3,0.335490301823489,0.0247483122722959,0.0403775237500668,172.74836730957,52.0325088500977,52.0431098937988,-600.425476074219,-600.425476074219,,,23.6056098937988,0,1,,,,,,1,1,1,52.0413131713867,0,52.0390071868897,,,,,,,,,,,,,,,,,,,,,,,,,,,,,,,,,
,3772387347.70295,52.0480709075928,-620.436828613281,,,5,,,,6.47999998182058,,,,,6.45640273303626E-5,3.82866304748153E-7,-1.4554043605777,0.00335810396728553,6.45541673914609E-5,3.82807835062656E-7,6.45333420076129E-5,3.15201913479305E-7,-1.63960267541325E-6,2.17231655898359E-7,1.00015273899889,10.005763053894,2,20,1,3,0.211601858930892,0.0133067161936834,0.0403775237500668,172.74836730957,52.0389595031738,52.0490036010742,-620.436828613281,-620.436828613281,,,23.6042289733887,0,1,,,,,,1,1,1,52.0471153259277,0,52.0451796849569,,,,,,,,,,,,,,,,,,,,,,,,,,,,,,,,,
,3772387370.71122,52.0617141723633,-640.326721191406,,,5,,,,6.47999998182058,,,,,4.85358144664672E-5,3.99070780034848E-7,-1.89871520970578,0.00512849574819086,4.85283998329272E-5,3.99009815495095E-7,4.85017557593376E-5,3.11615309619708E-7,-1.60788015909359E-6,2.4920820947963E-7,1.00015278957406,10.005763053894,2,20,1,3,0.159143601603196,0.00877560865271032,0.0403775237500668,172.74836730957,52.0518989562988,52.0623931884766,-640.326721191406,-640.326721191406,,,23.5910320281982,0,1,,,,,,1,1,1,52.0610542297363,0,52.0586048126221,,,,,,,,,,,,,,,,,,,,,,,,,,,,,,,,,
,3772387392.42958,52.0336971282959,-660.398803710937,,,5,,,,6.47999998182058,,,,,4.07066920349067E-5,5.77401067204341E-7,-2.44384173952313,0.0063783451891743,4.07004835733512E-5,5.77313003739868E-7,4.06634662833166E-5,5.14555743226439E-7,-1.73547484286072E-6,2.61768392667709E-7,1.00015254024057,10.005763053894,2,20,1,3,0.133536696151252,0.00609271293402,0.0403775237500668,172.74836730957,52.0229911804199,52.0373306274414,-660.398803710937,-660.398803710937,,,23.5775489807129,0,1,,,,,,1,1,1,52.0320243835449,0,52.0296829223633,,,,,,,,,,,,,,,,,,,,,,,,,,,,,,,,,
,3772387414.25724,52.0133476257324,-680.373779296875,,,5,,,,6.47999998182058,,,,,3.65338136475396E-5,3.98856068981294E-7,-2.99298353875639,0.00539909783825432,3.6528237912095E-5,3.98795196170627E-7,3.64784110704186E-5,3.45854816266956E-7,-1.90727311630485E-6,1.98549879258888E-7,1.00015264178519,10.005763053894,2,20,1,3,0.119894610437859,0.00432181252052656,0.0403775237500668,172.74836730957,52.0093116760254,52.0150299072266,-680.373779296875,-680.373779296875,,,23.5638275146484,0,1,,,,,,1,1,1,52.0128707885742,0,52.0119167327881,,,,,,,,,,,,,,,,,,,,,,,,,,,,,,,,,
,3772387435.74261,52.0171127319336,-700.421508789063,,,5,,,,6.47999998182058,,,,,3.32918039126025E-5,3.20800737906385E-7,-3.4593801958586,0.00519138359430783,3.32867210525786E-5,3.20751759327434E-7,3.32260669182838E-5,2.69663094107889E-7,-2.00855061522156E-6,1.73676442811925E-7,1.00015269933064,10.005763053894,2,20,1,3,0.109283599169663,0.00305116075939455,0.0403775237500668,172.74836730957,52.0142250061035,52.0181312561035,-700.421508789063,-700.421508789063,,,23.5262813568115,0,1,,,,,,1,1,1,52.0161552429199,0,52.0161815990101,,,,,,,,,,,,,,,,,,,,,,,,,,,,,,,,,
,3772387457.88552,52.0402069091797,-720.347839355469,,,5,,,,6.47999998182058,,,,,3.08767663707679E-5,3.66867959844085E-7,-3.69725325326627,0.00661594099763997,3.08720479443894E-5,3.66811896996104E-7,3.08077942841044E-5,3.04080340381481E-7,-1.99076759793335E-6,2.05149005289724E-7,1.00015283813977,10.005763053894,2,20,1,3,0.101366882072661,0.00241115998206707,0.0403775237500668,172.74836730957,52.0353775024414,52.0406723022461,-720.347839355469,-720.347839355469,,,23.5369071960449,0,1,,,,,,1,1,1,52.0406875610352,0,52.0386068170721,,,,,,,,,,,,,,,,,,,,,,,,,,,,,,,,,
,3772387480.93573,52.0532112121582,-740.383544921875,,,5,,,,6.47999998182058,,,,,2.89142573751336E-5,3.98657416123471E-7,-4.26098106984476,0.00776706514638978,2.89098415494085E-5,3.98596532606705E-7,2.88299336910099E-5,3.28661515011434E-7,-2.14799017313367E-6,2.25523400906596E-7,1.00015274472251,10.005763053894,2,20,1,3,0.094941707810211,0.00132589530744236,0.0403775237500668,172.74836730957,52.0418853759766,52.0541839599609,-740.383544921875,-740.383544921875,,,23.5250072479248,0,1,,,,,,1,1,1,52.0522384643555,0,52.0494190562855,,,,,,,,,,,,,,,,,,,,,,,,,,,,,,,,,
,3772387503.98593,52.0249919891357,-760.394897460937,,,5,,,,6.47999998182058,,,,,2.76748485297937E-5,5.12171032002554E-7,-4.4274427124349,0.0090241926836081,2.7670625967676E-5,5.1209288617295E-7,2.75880538335817E-5,4.45906141953367E-7,-2.13607750758815E-6,2.51807141751789E-7,1.00015260088885,10.005763053894,2,20,1,3,0.0908753663316568,0.00100699112514222,0.0403775237500668,172.74836730957,52.0170059204102,52.0284843444824,-760.394897460937,-760.394897460937,,,23.5106658935547,0,1,,,,,,1,1,1,52.0235710144043,0,52.022159576416,,,,,,,,,,,,,,,,,,,,,,,,,,,,,,,,,
,3772387525.67721,52.048225402832,-780.272644042969,,,5,,,,6.47999998182058,,,,,2.74683316047645E-5,4.80112377459273E-7,-4.82553349405318,0.0111284193431933,2.74641334147624E-5,4.80038998303525E-7,2.73667859647186E-5,3.6971240851413E-7,-2.31033551354552E-6,3.06186503430397E-7,1.00015286082174,10.005763053894,2,20,1,3,0.0902020395289231,0.000374679352605369,0.0403775237500668,172.74836730957,52.0431900024414,52.048698425293,-780.272644042969,-780.272644042969,,,23.4978923797607,0,1,,,,,,1,1,1,52.0485725402832,0,52.0468433380127,,,,,,,,,,,,,,,,,,,,,,,,,,,,,,,,,
,3772387547.60119,52.0578937530518,-800.356872558594,,,5,,,,6.47999998182058,,,,,2.55145607915507E-5,4.53007894465894E-7,-4.78348942636732,0.010036730624662,2.551066456056E-5,4.5293871736299E-7,2.54218091507324E-5,3.7285367498185E-7,-2.12735183388924E-6,2.57164575202261E-7,1.00015272949795,10.005763053894,2,20,1,3,0.083785897724483,0.000411308045819915,0.0403775237500668,172.74836730957,52.0482711791992,52.0588150024414,-800.356872558594,-800.356872558594,,,23.4488697052002,0,1,,,,,,1,1,1,52.0569725036621,0,52.0545097351074,,,,,,,,,,,,,,,,,,,,,,,,,,,,,,,,,
,3772387569.23312,52.0392646789551,-820.453247070312,,,5,,,,6.47999998182058,,,,,2.52359086733667E-5,5.96154257310474E-7,-4.82924472751284,0.013346519446636,2.52320562362381E-5,5.96063250213208E-7,2.51424829127254E-5,4.90799743067744E-7,-2.12419747010323E-6,3.38241053775809E-7,1.0001526802688,10.005763053894,2,20,1,3,0.0828711841224192,0.000342417633822609,0.0403775237500668,172.74836730957,52.0291900634766,52.0416564941406,-820.453247070312,-820.453247070312,,,23.4470291137695,0,1,,,,,,1,1,1,52.0379905700684,0,52.0354625701904,,,,,,,,,,,,,,,,,,,,,,,,,,,,,,,,,
,3772387591.18137,52.0464611053467,-840.452331542969,,,5,,,,6.47999998182058,,,,,2.51060812877177E-5,4.47696219524939E-7,-5.52953064742665,0.00993943075662534,2.51022461644309E-5,4.4762783090717E-7,2.49854370435428E-5,3.70853628248968E-7,-2.41882166412677E-6,2.50675609936894E-7,1.00015278008436,10.005763053894,2,20,1,3,0.0824429145746586,-0.00066525028516333,0.0403775237500668,172.74836730957,52.0382308959961,52.0467681884766,-840.452331542969,-840.452331542969,,,23.410120010376,0,1,,,,,,1,1,1,52.0461540222168,0,52.0439170837402,,,,,,,,,,,,,,,,,,,,,,,,,,,,,,,,,
,3772387611.9108,52.0250682830811,-860.330139160156,,,5,,,,6.47999998182058,,,,,2.36267776924578E-5,3.87999245030764E-7,-5.59336902534809,0.00855530383735906,2.36231726928307E-5,3.87940043680844E-7,2.35106953691965E-5,3.30333696017667E-7,-2.30249676050647E-6,2.034136838229E-7,1.0001526043802,10.005763053894,2,20,1,3,0.0775845151240188,-0.000710847636428513,0.0403775237500668,172.74836730957,52.0153999328613,52.0284538269043,-860.330139160156,-860.330139160156,,,23.4200019836426,0,1,,,,,,1,1,1,52.0233001708984,0,52.0215315385298,,,,,,,,,,,,,,,,,,,,,,,,,,,,,,,,,
,3772387634.86021,52.017951965332,-880.426513671875,,,5,,,,6.47999998182058,,,,,2.38433973531175E-5,5.31527011675261E-7,-5.76453566783746,0.0154297782352983,2.38397561227527E-5,5.31445839841147E-7,2.3719200120884E-5,3.83453082792418E-7,-2.39447648094111E-6,3.67965234745693E-7,1.00015273773549,10.005763053894,2,20,1,3,0.078293412146366,-0.000949583880561328,0.0403775237500668,172.74836730957,52.0142707824707,52.0182685852051,-880.426513671875,-880.426513671875,,,23.3958396911621,0,1,,,,,,1,1,1,52.0177764892578,0,52.0168259938558,,,,,,,,,,,,,,,,,,,,,,,,,,,,,,,,,
,3772387657.83944,52.0233592987061,-900.109985351562,,,5,,,,6.47999998182058,,,,,2.35522547461664E-5,4.07281995481201E-7,-6.33181227314024,0.0101816326144944,2.3548657554981E-5,4.07219790345433E-7,2.34050077906064E-5,3.28585388599646E-7,-2.5970912504986E-6,2.405402254256E-7,1.00015275567947,10.005763053894,2,20,1,3,0.0773244018165544,-0.00170201221407837,0.0403775237500668,172.74836730957,52.0191307067871,52.023868560791,-900.109985351562,-900.109985351562,,,23.3822612762451,0,1,,,,,,1,1,1,52.022819519043,0,52.0221092917702,,,,,,,,,,,,,,,,,,,,,,,,,,,,,,,,,
,3772387679.43993,52.0123500823975,-920.121337890625,,,5,,,,6.47999998182058,,,,,2.27227533269283E-5,4.02407033696452E-7,-6.55967883507527,0.00946804812274142,2.27192838449072E-5,4.02345591143762E-7,2.25705498982294E-5,3.39286216225686E-7,-2.59540665734675E-6,2.16256417689927E-7,1.00015271088846,10.005763053894,2,20,1,3,0.0745940281170229,-0.00193715020534489,0.0403775237500668,172.74836730957,52.0080947875977,52.0136451721191,-920.121337890625,-920.121337890625,,,23.3794460296631,0,1,,,,,,1,1,1,52.0116386413574,0,52.0106948852539,,,,,,,,,,,,,,,,,,,,,,,,,,,,,,,,,
,3772387701.39292,52.0045795440674,-940.059814453125,,,5,,,,6.47999998182058,,,,,2.29971495457602E-5,4.78082977794651E-7,-6.98008140271701,0.0113785794742332,2.29936384274673E-5,4.78009985883828E-7,2.28232201322127E-5,3.99280986294317E-7,-2.79428540590673E-6,2.62808372371383E-7,1.00015269955227,10.005763053894,2,20,1,3,0.0754784910366418,-0.00251281499446145,0.0403775237500668,172.74836730957,52.0024147033691,52.0065155029297,-940.059814453125,-940.059814453125,,,23.3550930023193,0,1,,,,,,1,1,1,52.00341796875,0,52.0036228179932,,,,,,,,,,,,,,,,,,,,,,,,,,,,,,,,,
,3772387722.99265,52.0408401489258,-960.022583007812,,,5,,,,6.47999998182058,,,,,2.28686384417251E-5,4.50935144647266E-7,-7.37557180214152,0.0125067737583426,2.28651404897574E-5,4.50866170297063E-7,2.26759539645954E-5,3.48217836589801E-7,-2.93526172800543E-6,2.86399444481058E-7,1.00015298187078,10.005763053894,2,20,1,3,0.0750377768314229,-0.00301520268162777,0.0403775237500668,172.74836730957,52.0385513305664,52.0419082641602,-960.022583007812,-960.022583007812,,,23.3545780181885,0,1,,,,,,1,1,1,52.0411605834961,0,52.0405578613281,,,,,,,,,,,,,,,,,,,,,,,,,,,,,,,,,
,3772387745.10848,52.0254974365234,-980.106811523437,,,5,,,,6.47999998182058,,,,,2.14257585978885E-5,5.12677770801587E-7,-7.69158346912229,0.0106645052671593,2.14224890115178E-5,5.12599535800277E-7,2.12297481161154E-5,4.57880192058713E-7,-2.86719904696146E-6,2.30443081525429E-7,1.00015262401904,10.005763053894,2,20,1,3,0.0702867815804926,-0.00321116251521642,0.0403775237500668,172.74836730957,52.0176811218262,52.0287895202637,-980.106811523437,-980.106811523437,,,23.3290901184082,0,1,,,,,,1,1,1,52.024299621582,0,52.0228481292725,,,,,,,,,,,,,,,,,,,,,,,,,,,,,,,,,
,3772387766.79667,52.0322875976562,-1000.23962402344,,,5,,,,6.47999998182058,,,,,2.20969756546447E-5,5.3813599430805E-7,-8.06268341907417,0.0141851718369052,2.20935993108799E-5,5.38053768933078E-7,2.18752088607628E-5,4.36815834151023E-7,-3.09876875673544E-6,3.14155670485248E-7,1.00015281999629,10.005763053894,2,20,1,3,0.0724658472478958,-0.003779635899573,0.0403775237500668,172.74836730957,52.0273323059082,52.0325508117676,-1000.23962402344,-1000.23962402344,,,23.3389377593994,0,1,,,,,,1,1,1,52.0320243835449,0,52.0305500030518,,,,,,,,,,,,,,,,,,,,,,,,,,,,,,,,,