File: Experimental_Data/AC_Suceptibillity_FieldScans/FCd_Down_56K.dat
[Header]
; MPMS3 Data File (default extension .dat)
; Copyright (c) 2007, Quantum Design, Inc. All rights reserved.
TITLE,FCd_Down_56K
FILEOPENTIME,3762224037.94549,03/20/2019,6:13 am
BYAPP,SQUID AC,0.9.1.0
INFO,MPMS3 Measurement Release 1.1.16 Build 347, MultiVu Release 2.3.3.2,APPNAME
INFO,0,MOMENT_UNITS
INFO,SrM,SAMPLE_MATERIAL
INFO,MvsH,SAMPLE_COMMENT
INFO,,SAMPLE_MASS
INFO,,SAMPLE_VOLUME
INFO,,SAMPLE_MOLECULAR_WEIGHT
INFO,,SAMPLE_SIZE
INFO,,SAMPLE_SHAPE
INFO,Quartz,SAMPLE_HOLDER
INFO,Standard,SAMPLE_HOLDER_DETAIL
INFO,65.34,SAMPLE_OFFSET
DATATYPE,COMMENT,1
DATATYPE,TIME,2
STARTUPAXIS,X,2
STARTUPAXIS,Y1,5
FIELDGROUP, VSM,2,3,4,5,6,8,9,10,11,14,15
FIELDGROUP, DC, 2,3,4,14,56,57,58,59,60,61,62,63,64,65,66,67,68,69
FIELDGROUP, AC, 2,3,4,11,16,17,18,19,20,21,22,23,24,25,26,27,28,29,30
STARTUPGROUP, All
[Data]
Comment,Time Stamp (sec),Temperature (K),Magnetic Field (Oe),Moment (emu),M. Std. Err. (emu),Transport Action,Averaging Time (sec),Frequency (Hz),Peak Amplitude (mm),Center Position (mm),Lockin Signal' (V),Lockin Signal (V),Range,M. Quad. Signal (emu),AC Moment (emu),AC M. Std Err. (emu),AC Phase (deg),AC Phase Std. Err. (deg),AC Susceptibility (emu/Oe),AC Suscept. Std Err. (emu/Oe),AC X' (emu/Oe),AC X' Std Err. (emu/Oe),AC X'' (emu/Oe),AC X'' Std Err. (emu/Oe),AC Drive (Oe),AC Frequency (Hz),AC Averaging Time (sec),AC Cycles,AC Range,AC Measure Type,AC Signal' (V),AC Signal'' (V),AC Trim Coil Ratio,AC Trim Coil Phase,Min. Temperature (K),Max. Temperature (K),Min. Field (Oe),Max. Field (Oe),Mass (grams),Motor Lag (deg),Pressure (Torr),Measure Count,Measurement Number,SQUID Status (code),Motor Status (code),Measure Status (code),Motor Current (amps),Motor Temp. (C),Temp. Status (code),Field Status (code),Chamber Status (code),Chamber Temp (K),Redirection State,Average Temp (K),Rotation Angle (deg),Rotator state,DC Moment Fixed Ctr (emu),DC Moment Err Fixed Ctr (emu),DC Moment Free Ctr (emu),DC Moment Err Free Ctr (emu),DC Fixed Fit,DC Free Fit,DC Calculated Center (mm),DC Calculated Center Err (mm),DC Scan Length (mm),DC Scan Time (s),DC Number of Points,DC Squid Drift,DC Min V (V),DC Max V (V),DC Scans per Measure,Map 01,Map 02,Map 03,Map 04,Map 05,Map 06,Map 07,Map 08,Map 09,Map 10,Map 11,Map 12,Map 13,Map 14,Map 15,Map 16
,3762224169.71342,55.9689674377441,219.72412109375,,,5,,,,31.6299982368946,,,,,0.000690845336106947,5.46167826839551E-7,1.14073532502333,0.000123054322874197,0.000690736796060613,5.46082017356396E-7,0.00069059989942771,5.40617272243068E-7,1.375137602268E-5,7.70618883268229E-8,1.00015713662129,10.005763053894,2,20,1,3,2.25548094390954,0.243816416196728,0.0413267537951469,172.859115600586,55.9366455078125,55.9801216125488,219.72412109375,219.72412109375,,,20.7222633361816,0,1,,,,,,1,1,1,55.9608535766602,0,55.957034556071,,,,,,,,,,,,,,,,,,,,,,,,,,,,,,,,,
,3762224197.46928,55.9043369293213,199.822067260742,,,5,,,,31.6299982368946,,,,,0.00063268547104532,4.51066078477313E-7,0.162610464119733,0.000100519125258809,0.000632585906337921,4.50995094925175E-7,0.000632583358681029,4.46663490108093E-7,1.79533205774427E-6,6.23562527019128E-8,1.00015739317996,10.005763053894,2,20,10,3,2.06911342372837,0.187952705987976,0.0413267537951469,172.859115600586,55.8924751281738,55.9092864990234,199.822067260742,199.822067260742,,,20.8135566711426,0,1,,,,,,1,1,1,55.9019355773926,0,55.8996384360574,,,,,,,,,,,,,,,,,,,,,,,,,,,,,,,,,
,3762224220.92219,55.9008445739746,179.750015258789,,,5,,,,31.6299982368946,,,,,0.000619366606685789,1.37668635409375E-6,0.0729016886443254,0.00121419416246693,0.000619268881562513,1.37646913727545E-6,0.000619268380283971,1.15317327825097E-6,7.87941719147577E-7,7.5157080584582E-7,1.00015780725657,10.005763053894,2,20,10,3,2.02584420811762,0.180780868699731,0.0413267537951469,172.859115600586,55.8990936279297,55.9111213684082,179.750015258789,179.750015258789,,,20.8601341247559,0,1,,,,,,1,1,1,55.9015808105469,0,55.9031063426625,,,,,,,,,,,,,,,,,,,,,,,,,,,,,,,,,
,3762224243.65949,55.9213390350342,159.93293762207,,,5,,,,31.6299982368946,,,,,0.000622843910779184,1.52513305015635E-7,0.321794968898671,7.70316164935805E-5,0.000622745624846773,1.52489238131253E-7,0.000622735803008412,1.44835976218601E-7,3.49755875811231E-6,4.77022823212372E-8,1.00015782677307,10.005763053894,2,20,10,3,2.0364118672114,0.190600529409695,0.0413267537951469,172.859115600586,55.9180641174316,55.9230308532715,159.93293762207,159.93293762207,,,20.8764019012451,0,1,,,,,,1,1,1,55.9217414855957,0,55.9208322004838,,,,,,,,,,,,,,,,,,,,,,,,,,,,,,,,,
,3762224266.17531,55.9409599304199,139.860870361328,,,5,,,,31.6299982368946,,,,,0.00066430565480045,1.91618011147709E-7,1.58783798151216,0.000178212025376776,0.000664200763490462,1.91587755400131E-7,0.000663945723263063,1.50868794660976E-7,1.84046402301407E-5,1.18086725828116E-7,1.00015792109217,10.005763053894,2,20,10,3,2.16695495888668,0.251181592631261,0.0413267537951469,172.859115600586,55.9364128112793,55.9560546875,139.860870361328,139.860870361328,,,20.892126083374,0,1,,,,,,1,1,1,55.9431304931641,0,55.9458309520375,,,,,,,,,,,,,,,,,,,,,,,,,,,,,,,,,
,3762224289.28081,55.9651317596436,119.813102722168,,,5,,,,31.6299982368946,,,,,0.000740671245983003,1.87779774196395E-7,2.33977937202287,0.000171124244237126,0.000740554412757721,1.87750153879985E-7,0.00073993700629063,1.38711346915774E-7,3.02335075138958E-5,1.2652779346361E-7,1.00015776453866,10.005763053894,2,20,10,3,2.41218032709621,0.31168739497931,0.0413267537951469,172.859115600586,55.9632186889648,55.9764709472656,119.813102722168,119.813102722168,,,20.8906345367432,0,1,,,,,,1,1,1,55.9661102294922,0,55.9688911437988,,,,,,,,,,,,,,,,,,,,,,,,,,,,,,,,,
,3762224310.96675,55.9908504486084,99.9231796264648,,,5,,,,31.6299982368946,,,,,0.000816136737585039,2.5356135068406E-7,1.30135533565453,0.00018377048412023,0.000816007976805422,2.53521346655702E-7,0.00081579750580397,2.04694219354181E-7,1.85323429198311E-5,1.4957723681464E-7,1.00015779353055,10.005763053894,2,20,10,3,2.66374499905554,0.295161497956473,0.0413267537951469,172.859115600586,55.9889335632324,55.9955139160156,99.9231796264648,99.9231796264648,,,20.8753681182861,0,1,,,,,,1,1,1,55.9919319152832,0,55.9925788879394,,,,,,,,,,,,,,,,,,,,,,,,,,,,,,,,,
,3762224332.90616,56.0246810913086,79.8632583618164,,,5,,,,31.6299982368946,,,,,0.000781980546433204,1.6629387817665E-7,0.658496327387215,0.000179933793240555,0.00078185713079308,1.66267632938814E-7,0.000781805494616797,8.84897067924616E-8,8.98563069420867E-6,1.40763978186397E-7,1.0001578493503,10.005763053894,2,20,10,3,2.55528087141987,0.254100082640692,0.0413267537951469,172.859115600586,56.0217475891113,56.0264320373535,79.8632583618164,79.8632583618164,,,20.8733425140381,0,1,,,,,,1,1,1,56.0257339477539,0,56.0252788543701,,,,,,,,,,,,,,,,,,,,,,,,,,,,,,,,,
,3762224353.44185,56.0315990447998,59.766902923584,,,5,,,,31.6299982368946,,,,,0.000726396533646413,2.00592579759713E-7,0.741882732068138,0.00019357764056455,0.000726281994053978,2.00560949938717E-7,0.000726221111274041,1.43069491200871E-7,9.40385170660703E-6,1.40555381710714E-7,1.00015770677694,10.005763053894,2,20,10,3,2.37330656250027,0.239441579233573,0.0413267537951469,172.859115600586,56.0266571044922,56.0317802429199,59.766902923584,59.766902923584,,,20.871789932251,0,1,,,,,,1,1,1,56.0315971374512,0,56.0300986550071,,,,,,,,,,,,,,,,,,,,,,,,,,,,,,,,,
,3762224376.60626,56.023416519165,39.7919845581055,,,5,,,,31.6299982368946,,,,,0.000649821307551072,1.19083087727196E-7,0.397218668612626,0.000107629278399366,0.000649718936572375,1.1906432772026E-7,0.000649703322800577,9.64102369259185E-8,4.50431822006894E-6,6.98668759239014E-8,1.000157561944,10.005763053894,2,20,10,3,2.12437069905195,0.201379277697404,0.0413267537951469,172.859115600586,56.0195655822754,56.0244178771973,39.7919845581055,39.7919845581055,,,20.8417072296143,0,1,,,,,,1,1,1,56.0229148864746,0,56.0220890045166,,,,,,,,,,,,,,,,,,,,,,,,,,,,,,,,,
,3762224399.66183,56.0138759613037,19.9263496398926,,,5,,,,31.6299982368946,,,,,0.000600620632556466,1.21486219798741E-7,0.0339630358285818,4.48123725505616E-5,0.000600525998953195,1.21467078467084E-7,0.000600525893449044,1.18469045502803E-7,3.55971853378337E-7,2.68204475910365E-8,1.0001575845233,10.005763053894,2,20,10,3,1.9646689652889,0.173637838473796,0.0413267537951469,172.859115600586,56.0105438232422,56.0149574279785,19.9263496398926,19.9263496398926,,,20.8261871337891,0,1,,,,,,1,1,1,56.0135307312012,0,56.0125513943759,,,,,,,,,,,,,,,,,,,,,,,,,,,,,,,,,
,3762224421.36437,56.0379581451416,-0.218570560216904,,,5,,,,31.6299982368946,,,,,0.000603726051891648,1.18737233798561E-7,0.0288087906296077,3.50585248978342E-5,0.000603630679615106,1.18718476548874E-7,0.00060363060331132,1.16836467301951E-7,3.0351047287748E-7,2.10550844806106E-8,1.00015799772901,10.005763053894,2,20,10,3,1.97484528385144,0.174316244253908,0.0413267537951469,172.859115600586,56.0317001342773,56.039623260498,-0.218570560216904,-0.218570560216904,,,20.8100700378418,0,1,,,,,,1,1,1,56.039421081543,0,56.0374627546831,,,,,,,,,,,,,,,,,,,,,,,,,,,,,,,,,
,3762224444.31663,56.0642623901367,-19.9142074584961,,,5,,,,31.6299982368946,,,,,0.000644625525634501,1.34825994338033E-7,0.34025928049332,5.86083846020343E-5,0.000644523804337439,1.34804718923895E-7,0.000644512438998715,1.29488717144855E-7,3.82757541188689E-6,3.74831212191585E-8,1.00015782395681,10.005763053894,2,20,10,3,2.10758545076662,0.197629059007532,0.0413267537951469,172.859115600586,56.0570907592773,56.0644607543945,-19.9142074584961,-19.9142074584961,,,20.7802276611328,0,1,,,,,,1,1,1,56.064453125,0,56.0620491721413,,,,,,,,,,,,,,,,,,,,,,,,,,,,,,,,,
,3762224466.602,56.049898147583,-39.8284149169922,,,5,,,,31.6299982368946,,,,,0.000716174149127138,2.20729759006683E-7,0.719608110720289,0.000158176037042024,0.000716061361541052,2.20694997103134E-7,0.000716004885873911,1.8959852860814E-7,8.99315832794912E-6,1.12954325707256E-7,1.0001575110628,10.005763053894,2,20,10,3,2.34000297344983,0.235112296419223,0.0413267537951469,172.859115600586,56.0390090942383,56.0526809692383,-39.8284149169922,-39.8284149169922,,,20.7646293640137,0,1,,,,,,1,1,1,56.0483474731445,0,56.0460662841797,,,,,,,,,,,,,,,,,,,,,,,,,,,,,,,,,
,3762224489.75148,56.0561847686768,-59.8640480041504,,,5,,,,31.6299982368946,,,,,0.00077718981474375,1.8186937074566E-7,0.675935918221494,0.000210005335322138,0.000777067283724877,1.81840697390868E-7,0.000777013209615302,7.99558336945024E-8,9.16708889916935E-6,1.63319024874061E-7,1.00015768392447,10.005763053894,2,20,10,3,2.5395532058675,0.253261903107814,0.0413267537951469,172.859115600586,56.0456771850586,56.0571517944336,-59.8640480041504,-59.8640480041504,,,20.747974395752,0,1,,,,,,1,1,1,56.0551872253418,0,56.0524617975408,,,,,,,,,,,,,,,,,,,,,,,,,,,,,,,,,
,3762224512.73974,56.0627994537354,-79.9118270874023,,,5,,,,31.6299982368946,,,,,0.000801760697588344,2.80501556573635E-7,1.00314238102192,0.000130245556155509,0.000801634234158651,2.8045731246316E-7,0.000801511372871958,2.60738043176173E-7,1.40344052968972E-5,1.03305261021494E-7,1.00015775702222,10.005763053894,2,20,10,3,2.61830203283686,0.276282097532768,0.0413267537951469,172.859115600586,56.0552978515625,56.0630989074707,-79.9118270874023,-79.9118270874023,,,20.7059154510498,0,1,,,,,,1,1,1,56.0625,0,56.0600655295632,,,,,,,,,,,,,,,,,,,,,,,,,,,,,,,,,
,3762224534.4161,56.0631809234619,-99.9960327148438,,,5,,,,31.6299982368946,,,,,0.000733633775650343,1.58302034441071E-7,2.07945364992518,7.78375162961303E-5,0.000733518129400738,1.58277080523741E-7,0.000733035085715365,1.48186498428273E-7,2.66159589311561E-5,5.56093148913579E-8,1.00015765970188,10.005763053894,2,20,10,3,2.39064411942882,0.297816050262425,0.0413267537951469,172.859115600586,56.052848815918,56.0642318725586,-99.9960327148438,-99.9960327148438,,,20.6895217895508,0,1,,,,,,1,1,1,56.0623970031738,0,56.0595603942871,,,,,,,,,,,,,,,,,,,,,,,,,,,,,,,,,
,3762224556.32392,56.054615020752,-119.861663818359,,,5,,,,31.6299982368946,,,,,0.000656985972431469,1.38806788555384E-7,0.918975955070689,4.42182416254549E-5,0.000656882439808807,1.38784914373186E-7,0.000656797948628349,1.35945567569886E-7,1.05353883063052E-5,2.79294667989566E-8,1.00015761210285,10.005763053894,2,20,10,3,2.14583573035391,0.223333411227444,0.0413267537951469,172.859115600586,56.0440483093262,56.0556335449219,-119.861663818359,-119.861663818359,,,20.6999664306641,0,1,,,,,,1,1,1,56.0536346435547,0,56.0510837554932,,,,,,,,,,,,,,,,,,,,,,,,,,,,,,,,,
,3762224577.9908,56.0662879943848,-139.970169067383,,,5,,,,31.6299982368946,,,,,0.000638792939079579,9.95706897954563E-8,0.0943701860526867,8.79698428623939E-5,0.000638692152269018,9.95549798343157E-8,0.000638691285934051,8.22020829904575E-8,1.05197050289174E-6,5.61605872640319E-8,1.00015780186151,10.005763053894,2,20,10,3,2.08932015932882,0.187144574850337,0.0413267537951469,172.859115600586,56.060676574707,56.0664978027344,-139.970169067383,-139.970169067383,,,20.6573753356934,0,1,,,,,,1,1,1,56.0664978027344,0,56.0645130157471,,,,,,,,,,,,,,,,,,,,,,,,,,,,,,,,,
,3762224599.90537,56.0650901794434,-160.005798339844,,,5,,,,31.6299982368946,,,,,0.000651511801568232,6.46714091163407E-8,-0.0133689270895232,8.15278128850906E-5,0.000651409193214607,6.46612238414154E-8,0.000651409175482035,3.6891713951804E-8,-1.51994475064624E-7,5.31043812728093E-8,1.00015751750926,10.005763053894,2,20,10,3,2.13127247065516,0.186909153481744,0.0413267537951469,172.859115600586,56.0558700561523,56.0670318603516,-160.005798339844,-160.005798339844,,,20.6545925140381,0,1,,,,,,1,1,1,56.063835144043,0,56.0617614746094,,,,,,,,,,,,,,,,,,,,,,,,,,,,,,,,,
,3762224623.12383,56.034309387207,-180.029296875,,,5,,,,31.6299982368946,,,,,0.000675275730839496,1.1846384856017E-7,0.0101275179224052,9.83138337908722E-5,0.000675169478277791,1.18445208637537E-7,0.000675169467730436,9.81104885527644E-8,1.19341965750756E-7,6.63596224004289E-8,1.00015737168981,10.005763053894,2,20,10,3,2.20892817543295,0.194679966371184,0.0413267537951469,172.859115600586,56.0228157043457,56.0388145446777,-180.029296875,-180.029296875,,,20.6238994598389,0,1,,,,,,1,1,1,56.0320854187012,0,56.0297470092773,,,,,,,,,,,,,,,,,,,,,,,,,,,,,,,,,
,3762224646.38301,56.0247211456299,-199.955627441406,,,5,,,,31.6299982368946,,,,,0.0007223913034041,1.59484907885924E-7,0.327419599186985,0.000145764780081013,0.000722277456850113,1.59459773575627E-7,0.000722265663506215,1.1979513731085E-7,4.12746820634989E-6,1.05245163620306E-7,1.00015762163543,10.005763053894,2,20,10,3,2.36185732081822,0.221396460153219,0.0413267537951469,172.859115600586,56.020378112793,56.0248260498047,-199.955627441406,-199.955627441406,,,20.5821475982666,0,1,,,,,,1,1,1,56.0246162414551,0,56.023118799383,,,,,,,,,,,,,,,,,,,,,,,,,,,,,,,,,
,3762224669.47994,56.0156402587891,-220.00341796875,,,5,,,,31.6299982368946,,,,,0.00082919432088193,2.48747941825358E-7,1.8435165854775,0.000127033796413445,0.000829063701503857,2.48708757643026E-7,0.000828634590875612,2.26007046044948E-7,2.66708821692089E-5,1.03811662477654E-7,1.0001575504727,10.005763053894,2,20,10,3,2.70337140103993,0.325826666110404,0.0413267537951469,172.859115600586,56.0114784240723,56.0165672302246,-220.00341796875,-220.00341796875,,,20.5791893005371,0,1,,,,,,1,1,1,56.0152931213379,0,56.014309276234,,,,,,,,,,,,,,,,,,,,,,,,,,,,,,,,,
,3762224691.32288,56.0190811157227,-239.929779052734,,,5,,,,31.6299982368946,,,,,0.00079565031834863,3.11721310065303E-7,0.285294004015072,0.000156382400884856,0.000795524857790278,3.11672156902527E-7,0.000795514995838257,2.85915524438658E-7,3.96115623259802E-6,1.24063879808913E-7,1.00015770790457,10.005763053894,2,20,10,3,2.60154868963418,0.242047331194674,0.0413267537951469,172.859115600586,56.0160293579102,56.0191268920898,-239.929779052734,-239.929779052734,,,20.5499000549316,0,1,,,,,,1,1,1,56.0191307067871,0,56.0180812835693,,,,,,,,,,,,,,,,,,,,,,,,,,,,,,,,,
,3762224713.22788,56.0114688873291,-259.843963623047,,,5,,,,31.6299982368946,,,,,0.000768003753872409,5.26095882205454E-7,-0.0474052102756559,0.000165177915376923,0.000767882743872388,5.26012988258133E-7,0.000767882481044299,5.10516602008327E-7,-6.35328449957929E-7,1.26737772152275E-7,1.00015758916447,10.005763053894,2,20,10,3,2.51246337922617,0.219105094138528,0.0413267537951469,172.859115600586,56.0081634521484,56.0127029418945,-259.843963623047,-259.843963623047,,,20.5341548919678,0,1,,,,,,1,1,1,56.0110130310059,0,56.0099098899148,,,,,,,,,,,,,,,,,,,,,,,,,,,,,,,,,
,3762224736.28455,56.0064792633057,-279.879608154297,,,5,,,,31.6299982368946,,,,,0.000726087950370674,5.09968912177485E-7,-0.114750628437525,0.000152802099621412,0.000725973543896381,5.09888558626361E-7,0.000725972087915963,4.97647476390897E-7,-1.4539616252283E-6,1.11055533224775E-7,1.00015759041807,10.005763053894,2,20,10,3,2.37557793326792,0.204405699018864,0.0413267537951469,172.859115600586,56.0048980712891,56.0068473815918,-279.879608154297,-279.879608154297,,,20.5306758880615,0,1,,,,,,1,1,1,56.0062103271484,0,56.0058302445845,,,,,,,,,,,,,,,,,,,,,,,,,,,,,,,,,
,3762224759.45408,56.0046157836914,-299.866668701172,,,5,,,,31.6299982368946,,,,,0.000654763249847101,5.95217032412722E-7,-0.139460994665117,0.00028514681757035,0.000654660062373483,5.95123229130631E-7,0.0006546581230695,5.65042106812345E-7,-1.59347606559482E-6,1.86812942217436E-7,1.00015761993063,10.005763053894,2,20,10,3,2.14229794066066,0.183448542528962,0.0413267537951469,172.859115600586,56.0033264160156,56.0052833557129,-299.866668701172,-299.866668701172,,,20.5016212463379,0,1,,,,,,1,1,1,56.0043144226074,0,56.0040893554687,,,,,,,,,,,,,,,,,,,,,,,,,,,,,,,,,
,3762224782.56431,56.020637512207,-320.072296142578,,,5,,,,31.6299982368946,,,,,0.000556520223002583,7.36974424477323E-7,-0.16667725689972,0.000385173376597609,0.000556432429586045,7.36858163648065E-7,0.000556430075135593,7.04912946530147E-7,-1.61869689164664E-6,2.14610556937408E-7,1.00015777911543,10.005763053894,2,20,10,3,1.82093140668066,0.155097657077785,0.0413267537951469,172.859115600586,56.0190048217773,56.0213584899902,-320.072296142578,-320.072296142578,,,20.4455242156982,0,1,,,,,,1,1,1,56.0210990905762,0,56.0205230712891,,,,,,,,,,,,,,,,,,,,,,,,,,,,,,,,,
,3762224809.21659,56.0292797088623,-339.889373779297,,,5,,,,31.6299982368946,,,,,0.000452787695169159,5.34704800859022E-7,-0.160286466313512,0.000239997958446581,0.000452716346774633,5.34620544309002E-7,0.000452714575261641,5.23397163643348E-7,-1.26648436296119E-6,1.08970342237472E-7,1.00015760065885,10.005763053894,2,20,1,3,1.48150314477722,0.126384901817816,0.0413267537951469,172.859115600586,56.0224189758301,56.0303039550781,-339.889373779297,-339.889373779297,,,20.4546966552734,0,1,,,,,,1,1,1,56.0285720825195,0,56.0273993355887,,,,,,,,,,,,,,,,,,,,,,,,,,,,,,,,,
,3762224832.79035,56.0199527740479,-359.973602294922,,,5,,,,31.6299982368946,,,,,0.000336952886301688,8.98753333591721E-7,-0.338624914087905,0.000732815964099107,0.00033689977977452,8.9861168272518E-7,0.000336893895918753,8.63709029493444E-7,-1.99110642722835E-6,2.48011428570685E-7,1.00015763301242,10.005763053894,2,20,1,3,1.10278237785955,0.0906440132490671,0.0413267537951469,172.859115600586,56.0153732299805,56.0213165283203,-359.973602294922,-359.973602294922,,,20.4252471923828,0,1,,,,,,1,1,1,56.0192680358887,0,56.0182456970215,,,,,,,,,,,,,,,,,,,,,,,,,,,,,,,,,
,3762224854.7523,56.0289363861084,-380.021362304687,,,5,,,,31.6299982368946,,,,,0.000225433075114587,7.80377512512899E-7,-0.592654581948516,0.000890686883103849,0.000225397529986238,7.80254466598589E-7,0.000225385472040849,7.53435684109873E-7,-2.33141948617172E-6,2.02809522845786E-7,1.00015769972436,10.005763053894,2,20,1,3,0.738060159500196,0.0573880553520352,0.0413267537951469,172.859115600586,56.0252494812012,56.0292358398438,-380.021362304687,-380.021362304687,,,20.3969707489014,0,1,,,,,,1,1,1,56.0291442871094,0,56.0276641845703,,,,,,,,,,,,,,,,,,,,,,,,,,,,,,,,,
,3762224877.77808,56.0524940490723,-400.044860839844,,,5,,,,31.6299982368946,,,,,0.000150592912492052,6.45601409550219E-7,-0.932445229535092,0.00156872132575638,0.000150569161018688,6.45499585470791E-7,0.000150549222272384,6.00099790601864E-7,-2.45029040153387E-6,2.37802346839895E-7,1.00015774460855,10.005763053894,2,20,1,3,0.493254229153848,0.035422105710595,0.0413267537951469,172.859115600586,56.0467300415039,56.052734375,-400.044860839844,-400.044860839844,,,20.3929500579834,0,1,,,,,,1,1,1,56.0524063110352,0,56.0506435394287,,,,,,,,,,,,,,,,,,,,,,,,,,,,,,,,,
,3762224899.98718,56.0302314758301,-419.922607421875,,,5,,,,31.6299982368946,,,,,0.000129217232913763,2.6415504506075E-6,-1.2746269109583,0.0159813722979419,0.00012919689542864,2.6411346972921E-6,0.000129164926721518,1.64862254756325E-6,-2.87393344110337E-6,2.06340402851847E-6,1.00015741465811,10.005763053894,2,20,1,3,0.423413626848892,0.0278749831435234,0.0413267537951469,172.859115600586,56.0210113525391,56.0335273742676,-419.922607421875,-419.922607421875,,,20.3769035339355,0,1,,,,,,1,1,1,56.028491973877,0,56.0265984968706,,,,,,,,,,,,,,,,,,,,,,,,,,,,,,,,,
,3762224923.01013,56.0266189575195,-439.982543945313,,,5,,,,31.6299982368946,,,,,0.000120081844816049,6.23683359438585E-7,-1.14686647197448,0.00177214367519838,0.000120062923656455,6.23585086361601E-7,0.000120038872006933,5.85389665136723E-7,-2.40309055988618E-6,2.14889040864629E-7,1.00015759369352,10.005763053894,2,20,1,3,0.393420072765929,0.0267900538401982,0.0413267537951469,172.859115600586,56.023063659668,56.0271797180176,-439.982543945313,-439.982543945313,,,20.3482894897461,0,1,,,,,,1,1,1,56.0261268615723,0,56.0253805680708,,,,,,,,,,,,,,,,,,,,,,,,,,,,,,,,,
,3762224945.87307,56.0297145843506,-460.297485351562,,,5,,,,31.6299982368946,,,,,0.000110780358109002,7.39065622027738E-7,-1.43676606369836,0.00181330072757032,0.000110762899599183,7.38949148452107E-7,0.000110728076419731,7.09908016929732E-7,-2.77723243624833E-6,2.05125453069551E-7,1.000157620556,10.005763053894,2,20,1,3,0.363066038843082,0.022886089112332,0.0413267537951469,172.859115600586,56.0243721008301,56.0312614440918,-460.297485351562,-460.297485351562,,,20.3318958282471,0,1,,,,,,1,1,1,56.0283355712891,0,56.0279898210005,,,,,,,,,,,,,,,,,,,,,,,,,,,,,,,,,
,3762224967.88449,56.0475654602051,-480.223815917969,,,5,,,,31.6299982368946,,,,,0.000104646214131841,7.11933018058111E-7,-1.58406813547592,0.00232372842218555,0.000104629708935926,7.11820729295071E-7,0.000104589723686541,6.67832274505516E-7,-2.89235046106518E-6,2.46350976825659E-7,1.00015774865555,10.005763053894,2,20,1,3,0.343016494886199,0.0207443462377947,0.0413267537951469,172.859115600586,56.0420188903809,56.0479393005371,-480.223815917969,-480.223815917969,,,20.3163890838623,0,1,,,,,,1,1,1,56.0478134155273,0,56.0458041104403,,,,,,,,,,,,,,,,,,,,,,,,,,,,,,,,,
,3762224990.96721,56.0270042419434,-500.223022460937,,,5,,,,31.6299982368946,,,,,9.73790865835365E-5,8.1205004822258E-7,-1.67511223872332,0.00295343430244805,9.73637521286826E-5,8.119221732831E-7,9.73221439285175E-5,7.57910390868106E-7,-2.84614295714055E-6,2.91186288967915E-7,1.00015749654793,10.005763053894,2,20,1,3,0.319225854359632,0.0188033636150519,0.0413267537951469,172.859115600586,56.0173835754395,56.0302467346191,-500.223022460937,-500.223022460937,,,20.2737655639648,0,1,,,,,,1,1,1,56.0256538391113,0,56.0230277379354,,,,,,,,,,,,,,,,,,,,,,,,,,,,,,,,,
,3762225015.51503,56.0113124847412,-520.282958984375,,,5,,,,31.6299982368946,,,,,9.26169363677941E-5,6.18698809698943E-7,-1.59738141592632,0.00213274003515627,9.26023439044519E-5,6.18601329259031E-7,9.25663577165355E-5,5.85163821881525E-7,-2.58137864188329E-6,2.00626284723732E-7,1.00015758200848,10.005763053894,2,20,1,3,0.303589918829128,0.0183022217068945,0.0413267537951469,172.859115600586,56.0076141357422,56.0125312805176,-520.282958984375,-520.282958984375,,,20.2576370239258,0,1,,,,,,1,1,1,56.0108222961426,0,56.009801344438,,,,,,,,,,,,,,,,,,,,,,,,,,,,,,,,,
,3762225038.5012,56.0053100585937,-540.342834472656,,,5,,,,31.6299982368946,,,,,8.94383010264467E-5,6.88324599676516E-7,-2.03725999162941,0.00300394095136121,8.94242031491318E-5,6.88216101240749E-7,8.93676799187343E-5,6.32331924967187E-7,-3.17897700524024E-6,2.71657392084788E-7,1.00015765169628,10.005763053894,2,20,1,3,0.293297521065424,0.015429111676076,0.0413267537951469,172.859115600586,56.0039329528809,56.0057983398438,-540.342834472656,-540.342834472656,,,20.2421455383301,0,1,,,,,,1,1,1,56.0050849914551,0,56.00475730896,,,,,,,,,,,,,,,,,,,,,,,,,,,,,,,,,
,3762225061.93235,56.0315475463867,-560.220642089844,,,5,,,,31.6299982368946,,,,,8.60593558681183E-5,5.4134211795841E-7,-1.75753600906927,0.00300488789030994,8.60457761930303E-5,5.41256697262436E-7,8.60052972927194E-5,4.74766405134548E-7,-2.63902221513982E-6,2.5991474157319E-7,1.00015781919449,10.005763053894,2,20,1,3,0.282140819082214,0.0162298247276552,0.0413267537951469,172.859115600586,56.0289764404297,56.0333557128906,-560.220642089844,-560.220642089844,,,20.2121963500977,0,1,,,,,,1,1,1,56.0326194763184,0,56.0318003567782,,,,,,,,,,,,,,,,,,,,,,,,,,,,,,,,,
,3762225083.69955,56.0210437774658,-580.317016601562,,,5,,,,31.6299982368946,,,,,8.09854451517074E-5,8.37238794813439E-7,-2.27728198060456,0.00396033753946601,8.09726864348113E-5,8.37106893423783E-7,8.0908736554898E-5,7.71514777545755E-7,-3.21749864963314E-6,3.24827491210553E-7,1.0001575681561,10.005763053894,2,20,1,3,0.265633775122079,0.0128695766090122,0.0413267537951469,172.859115600586,56.0148963928223,56.0231742858887,-580.317016601562,-580.317016601562,,,20.2094440460205,0,1,,,,,,1,1,1,56.0201187133789,0,56.0185533003374,,,,,,,,,,,,,,,,,,,,,,,,,,,,,,,,,
,3762225106.69708,56.0332698822022,-600.401184082031,,,5,,,,31.6299982368946,,,,,8.02358124183721E-5,8.13494553927165E-7,-2.29100686160815,0.00433928207306055,8.02231637564834E-5,8.13366311721461E-7,8.01590399286334E-5,7.33557320197902E-7,-3.20691765084653E-6,3.51366496734459E-7,1.00015766845006,10.005763053894,2,20,1,3,0.263177886614971,0.0126930558695034,0.0413267537951469,172.859115600586,56.0292091369629,56.0333862304687,-600.401184082031,-600.401184082031,,,20.1672782897949,0,1,,,,,,1,1,1,56.0333976745605,0,56.0320247303356,,,,,,,,,,,,,,,,,,,,,,,,,,,,,,,,,
,3762225129.78569,56.0187225341797,-620.363952636719,,,5,,,,31.6299982368946,,,,,7.63583161087349E-5,8.15463632504904E-7,-2.45691357664808,0.00381349193338779,7.63462857111106E-5,8.15335154661925E-7,7.62761036911634E-5,7.5972190052587E-7,-3.27281951494744E-6,2.95962917084124E-7,1.00015757672442,10.005763053894,2,20,1,3,0.250493308959701,0.0113597134617789,0.0413267537951469,172.859115600586,56.013858795166,56.0209922790527,-620.363952636719,-620.363952636719,,,20.164457321167,0,1,,,,,,1,1,1,56.0177993774414,0,56.0169143676758,,,,,,,,,,,,,,,,,,,,,,,,,,,,,,,,,
,3762225151.41787,56.0299758911133,-640.278198242188,,,5,,,,31.6299982368946,,,,,7.51839845784439E-5,6.86751295005048E-7,-2.53565015982023,0.00421449479011038,7.51721263795614E-5,6.86642978939004E-7,7.5098524422862E-5,6.07889053144629E-7,-3.32568999360249E-6,3.19295285892473E-7,1.00015774728551,10.005763053894,2,20,1,3,0.246655959553264,0.0108513102487655,0.0413267537951469,172.859115600586,56.0276107788086,56.0300483703613,-640.278198242188,-640.278198242188,,,20.1356735229492,0,1,,,,,,1,1,1,56.0299987792969,0,56.0291758450595,,,,,,,,,,,,,,,,,,,,,,,,,,,,,,,,,
,3762225173.39894,56.0369205474854,-660.313842773437,,,5,,,,31.6299982368946,,,,,7.18730525409768E-5,6.88100823304337E-7,-2.65759385770064,0.00422869792205983,7.18617267064427E-5,6.87992391621085E-7,7.17844369844018E-5,6.15834206060897E-7,-3.33202221839817E-6,3.06727503777938E-7,1.00015760593369,10.005763053894,2,20,1,3,0.235815254281732,0.00987662460224678,0.0413267537951469,172.859115600586,56.0321769714355,56.037181854248,-660.313842773437,-660.313842773437,,,20.1071510314941,0,1,,,,,,1,1,1,56.0366287231445,0,56.0352771759033,,,,,,,,,,,,,,,,,,,,,,,,,,,,,,,,,
,3762225195.26651,56.0212383270264,-680.288696289063,,,5,,,,31.6299982368946,,,,,7.00172106167548E-5,9.09053183959353E-7,-2.93700326670919,0.00438593505397464,7.00061792490249E-5,9.08909960602268E-7,6.99142243492713E-5,8.53085546879997E-7,-3.58697179893651E-6,3.13627750982712E-7,1.00015757705746,10.005763053894,2,20,1,3,0.229770377270239,0.00850611264070237,0.0413267537951469,172.859115600586,56.0154075622559,56.0232124328613,-680.288696289063,-680.288696289063,,,20.0907001495361,0,1,,,,,,1,1,1,56.0202980041504,0,56.0190441131592,,,,,,,,,,,,,,,,,,,,,,,,,,,,,,,,,
,3762225217.00438,56.0096702575684,-700.190795898438,,,5,,,,31.6299982368946,,,,,6.8107988800092E-5,8.24314557856621E-7,-2.95716494874905,0.00536726730082469,6.80972551987623E-5,8.241846485172E-7,6.8006575715389E-5,7.36912433699264E-7,-3.51309337656022E-6,3.69107572275141E-7,1.0001576216442,10.005763053894,2,20,1,3,0.223507869551065,0.00820027689462719,0.0413267537951469,172.859115600586,56.0060386657715,56.0111083984375,-700.190795898438,-700.190795898438,,,20.0875968933105,0,1,,,,,,1,1,1,56.0089912414551,0,56.0082324981689,,,,,,,,,,,,,,,,,,,,,,,,,,,,,,,,,
,3762225238.83046,56.0059242248535,-720.238586425781,,,5,,,,31.6299982368946,,,,,6.72461542962329E-5,8.63400173408795E-7,-3.14071278264817,0.00647536799848047,6.72355526079693E-5,8.63264054108278E-7,6.71345642261329E-5,7.43796788951746E-7,-3.68372374999043E-6,4.38167963069565E-7,1.00015767979666,10.005763053894,2,20,1,3,0.220704382968094,0.00739425010950549,0.0413267537951469,172.859115600586,56.0049858093262,56.0061950683594,-720.238586425781,-720.238586425781,,,20.060001373291,0,1,,,,,,1,1,1,56.0057029724121,0,56.0056480407715,,,,,,,,,,,,,,,,,,,,,,,,,,,,,,,,,
,3762225260.4961,56.0201587677002,-740.262084960937,,,5,,,,31.6299982368946,,,,,6.58104546736452E-5,8.70508918253894E-7,-3.25837851921882,0.00575921932874214,6.58000742374427E-5,8.70371610855938E-7,6.56936998331942E-5,7.81498404907386E-7,-3.73999624052637E-6,3.83153995295848E-7,1.00015775721111,10.005763053894,2,20,1,3,0.216006743263681,0.00679741369916309,0.0413267537951469,172.859115600586,56.0182418823242,56.0209693908691,-740.262084960937,-740.262084960937,,,20.0307312011719,0,1,,,,,,1,1,1,56.0207443237305,0,56.0202285766602,,,,,,,,,,,,,,,,,,,,,,,,,,,,,,,,,
,3762225282.15345,56.0143547058105,-760.285583496094,,,5,,,,31.6299982368946,,,,,6.3663517413404E-5,7.8650170707304E-7,-3.59854199421067,0.0060187597922885,6.36534852149937E-5,7.86377768882127E-7,6.35279812890855E-5,6.85050060600903E-7,-3.99521881115715E-6,3.86130042683461E-7,1.00015760642762,10.005763053894,2,20,1,3,0.208995304241739,0.00533943648269331,0.0413267537951469,172.859115600586,56.010498046875,56.0155258178711,-760.285583496094,-760.285583496094,,,20.026762008667,0,1,,,,,,1,1,1,56.0137481689453,0,56.0127620697022,,,,,,,,,,,,,,,,,,,,,,,,,,,,,,,,,
,3762225304.17576,56.0049648284912,-780.199768066406,,,5,,,,31.6299982368946,,,,,6.23027236133101E-5,7.97521923105872E-7,-3.85086697439872,0.00467975329491186,6.2292904015277E-5,7.97396224833737E-7,6.21522614238128E-5,7.39889659843639E-7,-4.18357389830132E-6,2.97328153116317E-7,1.00015763590072,10.005763053894,2,20,1,3,0.20454912406144,0.0043288920045285,0.0413267537951469,172.859115600586,56.0037460327148,56.0053329467773,-780.199768066406,-780.199768066406,,,20.0122966766357,0,1,,,,,,1,1,1,56.0045967102051,0,56.0043834339489,,,,,,,,,,,,,,,,,,,,,,,,,,,,,,,,,
,3762225327.24346,56.0034694671631,-800.320434570312,,,5,,,,31.6299982368946,,,,,6.09622140261818E-5,8.77330347629627E-7,-3.76321138014981,0.0055459474952699,6.09526028822478E-5,8.77192030011355E-7,6.0821177850393E-5,8.07003810486109E-7,-4.0005153432864E-6,3.43817840398577E-7,1.00015768225604,10.005763053894,2,20,1,3,0.200141330630531,0.0045462513087085,0.0413267537951469,172.859115600586,56.0020179748535,56.0036430358887,-800.320434570312,-800.320434570312,,,19.9843406677246,0,1,,,,,,1,1,1,56.0033874511719,0,56.002876663208,,,,,,,,,,,,,,,,,,,,,,,,,,,,,,,,,
,3762225350.4695,56.0442390441895,-820.319580078125,,,5,,,,31.6299982368946,,,,,6.07042800694763E-5,6.44939034297815E-7,-3.79237442652928,0.00576053643045857,6.06947008671512E-5,6.44837262207119E-7,6.0561796463046E-5,5.40665357510878E-7,-4.01441434353267E-6,3.51420070454731E-7,1.00015782600768,10.005763053894,2,20,1,3,0.199296817594909,0.00442982586190169,0.0413267537951469,172.859115600586,56.0404586791992,56.0451278686523,-820.319580078125,-820.319580078125,,,19.9674797058105,0,1,,,,,,1,1,1,56.0447387695313,0,56.0433890602805,,,,,,,,,,,,,,,,,,,,,,,,,,,,,,,,,
,3762225373.45534,56.0420913696289,-840.40380859375,,,5,,,,31.6299982368946,,,,,5.87900701695881E-5,6.20130128519224E-7,-4.27901959104344,0.00511880069772799,5.87808055522503E-5,6.20032403370678E-7,5.86169553600435E-5,5.40701944674687E-7,-4.38584606320473E-6,3.03449482211834E-7,1.00015761296993,10.005763053894,2,20,1,3,0.193041845766543,0.00265478406963934,0.0413267537951469,172.859115600586,56.0329055786133,56.0439491271973,-840.40380859375,-840.40380859375,,,19.9515380859375,0,1,,,,,,1,1,1,56.0409049987793,0,56.0388282140096,,,,,,,,,,,,,,,,,,,,,,,,,,,,,,,,,
,3762225396.55685,56.0195217132568,-860.330139160156,,,5,,,,31.6299982368946,,,,,5.80781770278949E-5,7.17681791433418E-7,-4.41770605033875,0.00553430318212064,5.80690312416442E-5,7.17568775416105E-7,5.78965079305322E-5,6.3973278668068E-7,-4.47289154718436E-6,3.25033704556835E-7,1.00015749851608,10.005763053894,2,20,1,3,0.190710136794907,0.00216508708925916,0.0413267537951469,172.859115600586,56.0145454406738,56.0219650268555,-860.330139160156,-860.330139160156,,,19.923490524292,0,1,,,,,,1,1,1,56.0184631347656,0,56.017706784335,,,,,,,,,,,,,,,,,,,,,,,,,,,,,,,,,
,3762225419.63391,56.0335083007812,-880.353637695313,,,5,,,,31.6299982368946,,,,,5.76277262136406E-5,7.65664508087664E-7,-4.23203434266729,0.0073430875180739,5.76186343312274E-5,7.6554370978218E-7,5.74615298372996E-5,6.36641409937078E-7,-4.25201257674853E-6,4.25141019828E-7,1.00015779413238,10.005763053894,2,20,1,3,0.189223090940954,0.00276554547141947,0.0413267537951469,172.859115600586,56.0320930480957,56.033863067627,-880.353637695313,-880.353637695313,,,19.9062118530273,0,1,,,,,,1,1,1,56.0336799621582,0,56.0331520080566,,,,,,,,,,,,,,,,,,,,,,,,,,,,,,,,,
,3762225441.29985,56.0253028869629,-900.085754394531,,,5,,,,31.6299982368946,,,,,5.49802914694946E-5,7.26373523950952E-7,-4.37991710956071,0.00518860073143696,5.49716315971514E-5,7.26259113826474E-7,5.48110914525993E-5,6.65808928266424E-7,-4.19815843290053E-6,2.90087523786754E-7,1.00015753347848,10.005763053894,2,20,1,3,0.180536387678161,0.00217633852020419,0.0413267537951469,172.859115600586,56.0186347961426,56.0270233154297,-900.085754394531,-900.085754394531,,,19.8914833068848,0,1,,,,,,1,1,1,56.0243148803711,0,56.022741317749,,,,,,,,,,,,,,,,,,,,,,,,,,,,,,,,,
,3762225463.28347,56.0159759521484,-920.072814941406,,,5,,,,31.6299982368946,,,,,5.42813862200191E-5,8.70160393583579E-7,-4.25124991400204,0.00775932034148855,5.42728284475611E-5,8.70023207797276E-7,5.4123500460245E-5,7.5929948290182E-7,-4.02325808621055E-6,4.24740717816048E-7,1.00015768060561,10.005763053894,2,20,1,3,0.178236192328774,0.00255274512975286,0.0413267537951469,172.859115600586,56.0125160217285,56.0162620544434,-920.072814941406,-920.072814941406,,,19.8762550354004,0,1,,,,,,1,1,1,56.0158424377441,0,56.0148051868786,,,,,,,,,,,,,,,,,,,,,,,,,,,,,,,,,
,3762225486.22346,56.008020401001,-939.962707519531,,,5,,,,31.6299982368946,,,,,5.3422378998507E-5,7.65978029634956E-7,-4.48712528200433,0.00694467106924806,5.34139638337661E-5,7.65857371749102E-7,5.32502467662757E-5,6.68234191202714E-7,-4.17884574561167E-6,3.74166513159712E-7,1.00015754615716,10.005763053894,2,20,1,3,0.17542450521706,0.00179390566395866,0.0413267537951469,172.859115600586,56.0050659179687,56.0093154907227,-939.962707519531,-939.962707519531,,,19.8482894897461,0,1,,,,,,1,1,1,56.0074653625488,0,56.006950378418,,,,,,,,,,,,,,,,,,,,,,,,,,,,,,,,,
,3762225507.89994,56.0040321350098,-960.034790039063,,,5,,,,31.6299982368946,,,,,5.32701480096001E-5,8.65508866883958E-7,-5.06652105937329,0.00640445744842433,5.32617543178859E-5,8.65372490041093E-7,5.30536520092394E-5,7.92763494719693E-7,-4.70366681445177E-6,3.46980673755387E-7,1.00015759322654,10.005763053894,2,20,1,3,0.174933861622846,2.35812001435927E-5,0.0413267537951469,172.859115600586,56.0017585754395,56.0044441223145,-960.034790039063,-960.034790039063,,,19.8325023651123,0,1,,,,,,1,1,1,56.003791809082,0,56.0031951904297,,,,,,,,,,,,,,,,,,,,,,,,,,,,,,,,,
,3762225529.97212,56.0107593536377,-980.082580566406,,,5,,,,31.6299982368946,,,,,5.23644131658947E-5,1.04441070391004E-6,-5.06015245107886,0.00731774503484438,5.2356158093256E-5,1.04424605609478E-6,5.21521077117367E-5,9.68207236534942E-7,-4.6178947053207E-6,3.91183553834863E-7,1.00015767147437,10.005763053894,2,20,1,3,0.171959609296136,4.59740937697346E-5,0.0413267537951469,172.859115600586,56.009937286377,56.0110397338867,-980.082580566406,-980.082580566406,,,19.8164901733398,0,1,,,,,,1,1,1,56.0106353759766,0,56.0106586109508,,,,,,,,,,,,,,,,,,,,,,,,,,,,,,,,,
,3762225552.89822,56.0429992675781,-999.996765136719,,,5,,,,31.6299982368946,,,,,5.25502563191002E-5,9.65766760228127E-7,-5.30910056664444,0.00680069393140749,5.25419668106483E-5,9.65614415933689E-7,5.23165625062935E-5,8.94115059007025E-7,-4.86164209463775E-6,3.64649779261998E-7,1.0001577692834,10.005763053894,2,20,1,3,0.172568581445923,-0.000700007789523076,0.0413267537951469,172.859115600586,56.0393333435059,56.0444068908691,-999.996765136719,-999.996765136719,,,19.8011455535889,0,1,,,,,,1,1,1,56.0439529418945,0,56.0425827026367,,,,,,,,,,,,,,,,,,,,,,,,,,,,,,,,,