File: Experimental_Data/AC_Suceptibillity_FieldScans/FCd_Up_20K.dat
[Header]
; MPMS3 Data File (default extension .dat)
; Copyright (c) 2007, Quantum Design, Inc. All rights reserved.
TITLE,FCd_Up_20K
FILEOPENTIME,3772414334.9537,07/16/2019,4:52 am
BYAPP,SQUID AC,0.9.1.0
INFO,MPMS3 Measurement Release 1.1.16 Build 347, MultiVu Release 2.3.3.2,APPNAME
INFO,0,MOMENT_UNITS
INFO,Cu2OSeO3,SAMPLE_MATERIAL
INFO,,SAMPLE_COMMENT
INFO,,SAMPLE_MASS
INFO,,SAMPLE_VOLUME
INFO,,SAMPLE_MOLECULAR_WEIGHT
INFO,,SAMPLE_SIZE
INFO,,SAMPLE_SHAPE
INFO,Quartz,SAMPLE_HOLDER
INFO,Standard,SAMPLE_HOLDER_DETAIL
INFO,64.77,SAMPLE_OFFSET
DATATYPE,COMMENT,1
DATATYPE,TIME,2
STARTUPAXIS,X,2
STARTUPAXIS,Y1,5
FIELDGROUP, VSM,2,3,4,5,6,8,9,10,11,14,15
FIELDGROUP, DC, 2,3,4,14,56,57,58,59,60,61,62,63,64,65,66,67,68,69
FIELDGROUP, AC, 2,3,4,11,16,17,18,19,20,21,22,23,24,25,26,27,28,29,30
STARTUPGROUP, All
[Data]
Comment,Time Stamp (sec),Temperature (K),Magnetic Field (Oe),Moment (emu),M. Std. Err. (emu),Transport Action,Averaging Time (sec),Frequency (Hz),Peak Amplitude (mm),Center Position (mm),Lockin Signal' (V),Lockin Signal (V),Range,M. Quad. Signal (emu),AC Moment (emu),AC M. Std Err. (emu),AC Phase (deg),AC Phase Std. Err. (deg),AC Susceptibility (emu/Oe),AC Suscept. Std Err. (emu/Oe),AC X' (emu/Oe),AC X' Std Err. (emu/Oe),AC X'' (emu/Oe),AC X'' Std Err. (emu/Oe),AC Drive (Oe),AC Frequency (Hz),AC Averaging Time (sec),AC Cycles,AC Range,AC Measure Type,AC Signal' (V),AC Signal'' (V),AC Trim Coil Ratio,AC Trim Coil Phase,Min. Temperature (K),Max. Temperature (K),Min. Field (Oe),Max. Field (Oe),Mass (grams),Motor Lag (deg),Pressure (Torr),Measure Count,Measurement Number,SQUID Status (code),Motor Status (code),Measure Status (code),Motor Current (amps),Motor Temp. (C),Temp. Status (code),Field Status (code),Chamber Status (code),Chamber Temp (K),Redirection State,Average Temp (K),Rotation Angle (deg),Rotator state,DC Moment Fixed Ctr (emu),DC Moment Err Fixed Ctr (emu),DC Moment Free Ctr (emu),DC Moment Err Free Ctr (emu),DC Fixed Fit,DC Free Fit,DC Calculated Center (mm),DC Calculated Center Err (mm),DC Scan Length (mm),DC Scan Time (s),DC Number of Points,DC Squid Drift,DC Min V (V),DC Max V (V),DC Scans per Measure,Map 01,Map 02,Map 03,Map 04,Map 05,Map 06,Map 07,Map 08,Map 09,Map 10,Map 11,Map 12,Map 13,Map 14,Map 15,Map 16
,3772414499.02021,19.9450712203979,200.368499755859,,,5,,,,6.46999990567565,,,,,0.000663850268700577,8.56411712567239E-8,0.042168172610701,0.000115465934345081,0.000663745393312446,8.56276416228607E-8,0.000663745213551311,3.8186160818067E-8,4.88498944003952E-7,7.66414387382556E-8,1.00015800544785,10.005763053894,2,20,10,3,2.1714185854176,0.192921927825024,0.0403775237500668,172.74836730957,19.9443626403809,19.9500064849854,200.368499755859,200.368499755859,,,23.2063255310059,0,1,,,,,,1,1,1,19.945779800415,0,19.9462643941243,,,,,,,,,,,,,,,,,,,,,,,,,,,,,,,,,
,3772414522.77272,19.9576473236084,200.392776489258,,,5,,,,6.46999990567565,,,,,0.000663742766431947,8.49542116322346E-8,0.0399568176388323,6.93872522400306E-5,0.00066363790574957,8.49407902330826E-8,0.000663637744374037,7.13874465254494E-8,4.6280645545361E-7,4.60301023678705E-8,1.00015800888025,10.005763053894,2,20,10,3,2.17107439691345,0.192806881960445,0.0403775237500668,172.74836730957,19.9565277099609,19.9623184204102,200.392776489258,200.392776489258,,,23.2697830200195,0,1,,,,,,1,1,1,19.9583969116211,0,19.9594234119762,,,,,,,,,,,,,,,,,,,,,,,,,,,,,,,,,
,3772414545.8399,19.9678325653076,220.039855957031,,,5,,,,6.46999990567565,,,,,0.000676238067996566,1.1041448819485E-7,0.0494634824828237,9.18930651973938E-5,0.000676131150086792,1.10397030901561E-7,0.0006761308981306,9.1268531332535E-8,5.83704374535352E-7,6.21092555122204E-8,1.00015813190941,10.005763053894,2,20,10,3,2.21191045103265,0.196850034672282,0.0403775237500668,172.74836730957,19.9644832611084,19.9720554351807,220.039855957031,220.039855957031,,,23.3131275177002,0,1,,,,,,1,1,1,19.9690017700195,0,19.9693095467307,,,,,,,,,,,,,,,,,,,,,,,,,,,,,,,,,
,3772414568.84716,19.9892749786377,239.990478515625,,,5,,,,6.46999990567565,,,,,0.00069185137196546,7.02474071784948E-8,0.0619118385925139,7.27311682489203E-5,0.000691741939827035,7.02362959423279E-8,0.000691741535980643,4.90153781639064E-8,7.47472280784207E-7,5.03053672200841E-8,1.00015819792342,10.005763053894,2,20,10,3,2.2629332323651,0.201934862817806,0.0403775237500668,172.74836730957,19.9864540100098,19.9914264678955,239.990478515625,239.990478515625,,,23.4191055297852,0,1,,,,,,1,1,1,19.9904479980469,0,19.9898809432983,,,,,,,,,,,,,,,,,,,,,,,,,,,,,,,,,
,3772414590.7443,19.9879274368286,260.038269042969,,,5,,,,6.46999990567565,,,,,0.000710728707952503,2.08659731840091E-7,0.0862877708556189,0.000141392412528487,0.000710616415222326,2.08626764308733E-7,0.000710615609364566,1.82879170765157E-7,1.07019197130194E-6,1.00400874927363E-7,1.00015802158207,10.005763053894,2,20,10,3,2.32458628450618,0.20848359195072,0.0403775237500668,172.74836730957,19.9869918823242,19.9883918762207,260.038269042969,260.038269042969,,,23.5267868041992,0,1,,,,,,1,1,1,19.9879531860352,0,19.9875939109109,,,,,,,,,,,,,,,,,,,,,,,,,,,,,,,,,
,3772414613.31884,19.9881381988525,279.988891601562,,,5,,,,6.46999990567565,,,,,0.000730989565593497,8.61981871809967E-7,0.175115877262233,0.000750459307014569,0.000730874064657949,8.61845673268558E-7,0.000730870651015733,6.64933883406519E-7,2.23380246900248E-6,5.48307299996689E-7,1.00015803124113,10.005763053894,2,20,10,3,2.39051500232266,0.218184296584348,0.0403775237500668,172.74836730957,19.9866714477539,19.9883346557617,279.988891601562,279.988891601562,,,23.6731281280518,0,1,,,,,,1,1,1,19.9882698059082,0,19.987512588501,,,,,,,,,,,,,,,,,,,,,,,,,,,,,,,,,
,3772414635.48783,19.998682975769,300.036682128906,,,5,,,,6.46999990567565,,,,,0.000750185809726129,7.51895622052065E-7,0.146175606610073,0.000674761960995034,0.000750067256974406,7.51776799096675E-7,0.000750064815936514,5.55988272133243E-7,1.91360372924959E-6,5.06009285399323E-7,1.00015805616179,10.005763053894,2,20,10,3,2.45340080959418,0.222727335775089,0.0403775237500668,172.74836730957,19.9970092773438,20.0004177093506,300.036682128906,300.036682128906,,,23.833215713501,0,1,,,,,,1,1,1,19.999547958374,0,19.9992565155029,,,,,,,,,,,,,,,,,,,,,,,,,,,,,,,,,
,3772414657.11394,20.0008487701416,320.011596679687,,,5,,,,6.46999990567565,,,,,0.000775253186569429,3.93446083040974E-7,0.10550875080118,0.000317720676908926,0.000775130773073775,3.93383957388077E-7,0.000775129458828096,3.06815240081268E-7,1.42738320427973E-6,2.4620184074084E-7,1.00015792624923,10.005763053894,2,20,10,3,2.53554018747205,0.228424351293147,0.0403775237500668,172.74836730957,20.0001125335693,20.0018692016602,320.011596679687,320.011596679687,,,23.9418563842773,0,1,,,,,,1,1,1,20.0005168914795,0,20.0006256103516,,,,,,,,,,,,,,,,,,,,,,,,,,,,,,,,,
,3772414679.05072,20.0020866394043,339.986511230469,,,5,,,,6.46999990567565,,,,,0.000796423402816951,3.10416620802212E-7,0.0566801900548279,0.000237564087066473,0.00079629760134909,3.10367588005829E-7,0.000796297211709833,2.46093424762613E-7,7.87742001359022E-7,1.89119184571963E-7,1.00015798297979,10.005763053894,2,20,10,3,2.60497493635309,0.232497799089061,0.0403775237500668,172.74836730957,20.0010147094727,20.0026721954346,339.986511230469,339.986511230469,,,24.0486297607422,0,1,,,,,,1,1,1,20.0022392272949,0,20.0016428629557,,,,,,,,,,,,,,,,,,,,,,,,,,,,,,,,,
,3772414700.44239,19.9998960494995,360.095031738281,,,5,,,,6.46999990567565,,,,,0.000807561903722108,3.23791151754452E-7,0.0235472912654542,0.000236947590099956,0.000807434423886591,3.23740038839669E-7,0.000807434355697657,2.6119674667709E-7,3.31837583559693E-7,1.912691095635E-7,1.0001578825868,10.005763053894,2,20,10,3,2.64153953443286,0.234278791431512,0.0403775237500668,172.74836730957,19.9991645812988,20.0009269714355,360.095031738281,360.095031738281,,,24.0928802490234,0,1,,,,,,1,1,1,19.9997959136963,0,20.0002496892756,,,,,,,,,,,,,,,,,,,,,,,,,,,,,,,,,
,3772414722.62049,20.0018873214722,379.948486328125,,,5,,,,6.46999990567565,,,,,0.00081088162066805,1.75996824396645E-7,-0.000809964354364645,0.000139203310087929,0.000810753449928179,1.75969005732831E-7,0.000810753449847168,1.35026864002403E-7,-1.14612524723252E-8,1.12839873166704E-7,1.00015808842982,10.005763053894,2,20,10,3,2.65249460578634,0.234170611182697,0.0403775237500668,172.74836730957,19.9991836547852,20.0027904510498,379.948486328125,379.948486328125,,,24.172492980957,0,1,,,,,,1,1,1,20.0026569366455,0,20.0017670718106,,,,,,,,,,,,,,,,,,,,,,,,,,,,,,,,,
,3772414745.76445,20.0030355453491,399.971984863281,,,5,,,,6.46999990567565,,,,,0.000809770433922476,2.0354396853741E-7,-0.0284351803171079,0.000169725698016216,0.000809642396222185,2.03511784969639E-7,0.000809642296514199,1.50128774321926E-7,-4.01815400358153E-7,1.37398681733576E-7,1.00015814105201,10.005763053894,2,20,10,3,2.64896871238855,0.232629298022276,0.0403775237500668,172.74836730957,19.9988498687744,20.0042362213135,399.971984863281,399.971984863281,,,24.2141723632813,0,1,,,,,,1,1,1,20.0040874481201,0,20.0026907487349,,,,,,,,,,,,,,,,,,,,,,,,,,,,,,,,,
,3772414767.35867,19.9998235702515,420.068359375,,,5,,,,6.46999990567565,,,,,0.000806701241935287,2.23625689654373E-7,-0.0422329703686222,0.000142533051181637,0.000806573808234226,2.2359036375204E-7,0.000806573589119235,1.91785611293958E-7,-5.94529037707905E-7,1.14938810083332E-7,1.00015799384974,10.005763053894,2,20,10,3,2.63898082623562,0.231168870726853,0.0403775237500668,172.74836730957,19.9992084503174,20.0004825592041,420.068359375,420.068359375,,,24.2683486938477,0,1,,,,,,1,1,1,19.9994869232178,0,19.9998542785645,,,,,,,,,,,,,,,,,,,,,,,,,,,,,,,,,
,3772414789.22328,20.0014228820801,440.322570800781,,,5,,,,6.46999990567565,,,,,0.000802272451858312,1.98689817279561E-7,-0.0490270681998766,0.000114741466057454,0.000802145658984178,1.98658415910941E-7,0.000802145365320795,1.76062038318201E-7,-6.86382931942152E-7,9.20180682012226E-8,1.00015806714493,10.005763053894,2,20,10,3,2.62451656829458,0.229645415995782,0.0403775237500668,172.74836730957,19.9993724822998,20.0023403167725,440.322570800781,440.322570800781,,,24.3228340148926,0,1,,,,,,1,1,1,20.0020637512207,0,20.0015239715576,,,,,,,,,,,,,,,,,,,,,,,,,,,,,,,,,
,3772414810.89257,20.002459526062,460.176055908203,,,5,,,,6.46999990567565,,,,,0.000797272874462777,2.544205636294E-7,-0.0640753504113762,0.000125376958926464,0.000797146833867349,2.54380342369708E-7,0.000797146335390493,2.3393278582201E-7,-8.91469712023265E-7,9.99240226456259E-8,1.0001581146535,10.005763053894,2,20,10,3,2.60821764144815,0.227584707032963,0.0403775237500668,172.74836730957,20.0000915527344,20.0036449432373,460.176055908203,460.176055908203,,,24.3508224487305,0,1,,,,,,1,1,1,20.0036277770996,0,20.0020746231079,,,,,,,,,,,,,,,,,,,,,,,,,,,,,,,,,
,3772414832.75738,20.002082824707,480.320983886719,,,5,,,,6.46999990567565,,,,,0.00079216840774233,2.33062240267322E-7,-0.0663734047792985,0.000173896723484169,0.000792043187781908,2.33025399559946E-7,0.000792042656332721,1.87976463880675E-7,-9.17529908730885E-7,1.37715960828765E-7,1.00015809738958,10.005763053894,2,20,10,3,2.59152441390694,0.226079552230384,0.0403775237500668,172.74836730957,20.0001640319824,20.0028476715088,480.320983886719,480.320983886719,,,24.3654537200928,0,1,,,,,,1,1,1,20.0028476715088,0,20.0018346959894,,,,,,,,,,,,,,,,,,,,,,,,,,,,,,,,,
,3772414854.65148,20.0017490386963,500.332336425781,,,5,,,,6.46999990567565,,,,,0.000786397883502941,2.34621153074616E-7,-0.0847695415358816,0.000165974390417873,0.000786273587728971,2.34584069534053E-7,0.000786272727175191,1.94941966099208E-7,-1.16329732841993E-6,1.3048875634526E-7,1.00015808209243,10.005763053894,2,20,10,3,2.57271511192733,0.223661765615137,0.0403775237500668,172.74836730957,20.000280380249,20.002534866333,500.332336425781,500.332336425781,,,24.4059162139893,0,1,,,,,,1,1,1,20.0024604797363,0,20.0016342163086,,,,,,,,,,,,,,,,,,,,,,,,,,,,,,,,,
,3772414876.29928,20.0004863739014,520.404357910156,,,5,,,,6.46999990567565,,,,,0.000780624326203876,3.72372112456362E-7,-0.0868096437063679,0.000187066486813542,0.000780500988139721,3.72313277938971E-7,0.000780500092292272,3.42492188876684E-7,-1.18254760378419E-6,1.46000950298684E-7,1.0001580242255,10.005763053894,2,20,10,3,2.55383137566183,0.221983629391614,0.0403775237500668,172.74836730957,20.0002326965332,20.0007934570313,520.404357910156,520.404357910156,,,24.4333724975586,0,1,,,,,,1,1,1,20.0007419586182,0,20.0005434036255,,,,,,,,,,,,,,,,,,,,,,,,,,,,,,,,,
,3772414897.93695,20.0008726119995,540.282165527344,,,5,,,,6.46999990567565,,,,,0.00077525585460406,2.31524211526449E-7,-0.0885628395548652,0.000163350769381319,0.000775133351035976,2.31487626775955E-7,0.000775132425050571,1.93796297085081E-7,-1.19813333283618E-6,1.26607727198914E-7,1.00015804192649,10.005763053894,2,20,10,3,2.53627175096776,0.220433360125221,0.0403775237500668,172.74836730957,20.0001792907715,20.0013236999512,540.282165527344,540.282165527344,,,24.4474773406982,0,1,,,,,,1,1,1,20.0012035369873,0,20.0006050109863,,,,,,,,,,,,,,,,,,,,,,,,,,,,,,,,,
,3772414919.86024,20.0008983612061,560.3056640625,,,5,,,,6.46999990567565,,,,,0.000771034329079646,3.10018552078024E-7,-0.100399779637208,0.00021731837800476,0.000770912491674579,3.09969563525267E-7,0.000770911308101085,2.6080036076515E-7,-1.35087445063645E-6,1.67524034504939E-7,1.00015804310656,10.005763053894,2,20,10,3,2.52250286691897,0.218765952109997,0.0403775237500668,172.74836730957,19.999439239502,20.0017127990723,560.3056640625,560.3056640625,,,24.4749565124512,0,1,,,,,,1,1,1,20.0016098022461,0,20.0008634567261,,,,,,,,,,,,,,,,,,,,,,,,,,,,,,,,,
,3772414941.48699,20.0007286071777,580.414123535156,,,5,,,,6.46999990567565,,,,,0.000768753046956124,3.32724355908636E-7,-0.10479883592967,0.000213624767200964,0.000768631576013772,3.32671782014828E-7,0.000768630290266068,2.8932684617435E-7,-1.40589150186323E-6,1.64196500059303E-7,1.00015803532686,10.005763053894,2,20,10,3,2.51505291995999,0.217979710701689,0.0403775237500668,172.74836730957,20.0001583099365,20.0011177062988,580.414123535156,580.414123535156,,,24.4895515441895,0,1,,,,,,1,1,1,20.0011177062988,0,20.0005977630615,,,,,,,,,,,,,,,,,,,,,,,,,,,,,,,,,
,3772414963.3824,20.0003662109375,600.413330078125,,,5,,,,6.46999990567565,,,,,0.000768434308441705,3.90903430697926E-7,-0.124125661414357,0.000254928430640026,0.000768312900621719,3.90841670398022E-7,0.000768311097662737,3.38217126429764E-7,-1.66447290141575E-6,1.95873394592295E-7,1.00015801871853,10.005763053894,2,20,10,3,2.51408024328243,0.217095117360871,0.0403775237500668,172.74836730957,20.0001487731934,20.0005760192871,600.413330078125,600.413330078125,,,24.5151786804199,0,1,,,,,,1,1,1,20.0003032684326,0,20.0003578186035,,,,,,,,,,,,,,,,,,,,,,,,,,,,,,,,,
,3772414985.07735,20.0004386901855,620.291137695313,,,5,,,,6.46999990567565,,,,,0.000768018631061064,5.36966927464824E-7,-0.156752363602243,0.000336332427442279,0.000767897286365212,5.36882088261892E-7,0.000767894412570127,4.70652368068648E-7,-2.10084521942697E-6,2.58319037486253E-7,1.0001580220402,10.005763053894,2,20,10,3,2.51284022921417,0.215600248771161,0.0403775237500668,172.74836730957,19.9998874664307,20.0007934570313,620.291137695313,620.291137695313,,,24.5300922393799,0,1,,,,,,1,1,1,20.000638961792,0,20.0003456115723,,,,,,,,,,,,,,,,,,,,,,,,,,,,,,,,,
,3772415006.94118,20.0000667572021,640.338928222656,,,5,,,,6.46999990567565,,,,,0.000766370985818361,5.38058799116296E-7,-0.174556723852808,0.000309553650985491,0.000766249914504602,5.37973796569365E-7,0.000766246358453386,4.82814575407738E-7,-2.33444538069213E-6,2.37288625030999E-7,1.0001580049948,10.005763053894,2,20,10,3,2.50751291624897,0.214412329984315,0.0403775237500668,172.74836730957,19.9996681213379,20.0005397796631,640.338928222656,640.338928222656,,,24.5188941955566,0,1,,,,,,1,1,1,20.0004653930664,0,20.0002450942993,,,,,,,,,,,,,,,,,,,,,,,,,,,,,,,,,
,3772415028.68518,20.0009393692017,660.423095703125,,,5,,,,6.46999990567565,,,,,0.000762440631337015,5.06437903380826E-7,-0.182512698735098,0.000313577551897176,0.000762320237795932,5.06357934069091E-7,0.000762316370138546,4.46339013819992E-7,-2.42832700390798E-6,2.39123069018685E-7,1.00015793040131,10.005763053894,2,20,10,3,2.49467948124403,0.213019924229096,0.0403775237500668,172.74836730957,19.9999313354492,20.0018329620361,660.423095703125,660.423095703125,,,24.5442733764648,0,1,,,,,,1,1,1,20.0007781982422,0,20.0005596160889,,,,,,,,,,,,,,,,,,,,,,,,,,,,,,,,,
,3772415050.57779,20.0001792907715,680.313049316406,,,5,,,,6.46999990567565,,,,,0.000756532363371998,5.43857014956313E-7,-0.188290243162712,0.000325601589956315,0.000756412842463689,5.4377109360309E-7,0.000756408757963928,4.84745759992103E-7,-2.48578347117388E-6,2.46391051801763E-7,1.00015801015213,10.005763053894,2,20,10,3,2.4753660096354,0.211172283471093,0.0403775237500668,172.74836730957,19.9996662139893,20.0006618499756,680.313049316406,680.313049316406,,,24.5713958740234,0,1,,,,,,1,1,1,20.0006732940674,0,20.0002531571822,,,,,,,,,,,,,,,,,,,,,,,,,,,,,,,,,
,3772415073.65234,20.000394821167,700.263671875,,,5,,,,6.46999990567565,,,,,0.000748636830845381,5.56374738570868E-7,-0.217473674908302,0.000361298596099223,0.000748518549921881,5.56286834108812E-7,0.00074851315804245,4.86064873831745E-7,-2.8410938869807E-6,2.70547556318173E-7,1.00015802002971,10.005763053894,2,20,10,3,2.44963495409295,0.207773003081091,0.0403775237500668,172.74836730957,20.0000038146973,20.0004348754883,700.263671875,700.263671875,,,24.5725708007813,0,1,,,,,,1,1,1,20.0003623962402,0,20.0002505562522,,,,,,,,,,,,,,,,,,,,,,,,,,,,,,,,,
,3772415095.26677,20.0005807876587,720.347839355469,,,5,,,,6.46999990567565,,,,,0.000739502465755312,6.77587466139957E-7,-0.219387393867874,0.00042914582864354,0.000739385621715839,6.77480404892285E-7,0.000739380201475449,5.98498218098627E-7,-2.83112455424248E-6,3.1745800028631E-7,1.00015802855241,10.005763053894,2,20,10,3,2.41974994635528,0.205209080373068,0.0403775237500668,172.74836730957,19.9998378753662,20.0009002685547,720.347839355469,720.347839355469,,,24.5738201141357,0,1,,,,,,1,1,1,20.0009002685547,0,20.0002698898315,,,,,,,,,,,,,,,,,,,,,,,,,,,,,,,,,
,3772415117.23094,20.0015592575073,740.407775878906,,,5,,,,6.46999990567565,,,,,0.000728198798148751,6.59506540463025E-7,-0.24336014213707,0.000387019614085382,0.000728083707485332,6.59402306501825E-7,0.000728077139921535,5.96052307245044E-7,-3.09247946856979E-6,2.82016043599981E-7,1.00015807339491,10.005763053894,2,20,10,3,2.38284420313473,0.201126529581117,0.0403775237500668,172.74836730957,20.000804901123,20.0019512176514,740.407775878906,740.407775878906,,,24.6004390716553,0,1,,,,,,1,1,1,20.0019550323486,0,20.0013035860929,,,,,,,,,,,,,,,,,,,,,,,,,,,,,,,,,
,3772415140.19007,20.0008640289307,760.322021484375,,,5,,,,6.46999990567565,,,,,0.000713685900545733,7.87708656005391E-7,-0.265112621614033,0.000506863081164765,0.000713573126354841,7.87584184993322E-7,0.000713565487587912,6.99487969311794E-7,-3.30175396519509E-6,3.61946721548431E-7,1.00015804153313,10.005763053894,2,20,10,3,2.33542623979944,0.196281244776057,0.0403775237500668,172.74836730957,20.0003032684326,20.0012359619141,760.322021484375,760.322021484375,,,24.6130695343018,0,1,,,,,,1,1,1,20.0011940002441,0,20.0006315057928,,,,,,,,,,,,,,,,,,,,,,,,,,,,,,,,,
,3772415161.81538,20.0020523071289,780.296875,,,5,,,,6.46999990567565,,,,,0.000694702336428493,9.14293406175609E-7,-0.271654208439698,0.000687281721665268,0.000694592444558035,9.14148778171235E-7,0.000694584637509922,7.79476822744035E-7,-3.29323128821097E-6,4.77581272075054E-7,1.00015821057559,10.005763053894,2,20,10,3,2.27332446017474,0.190849329630246,0.0403775237500668,172.74836730957,19.99973487854,20.0032119750977,780.296875,780.296875,,,24.6147232055664,0,1,,,,,,1,1,1,20.0032005310059,0,20.0021825790405,,,,,,,,,,,,,,,,,,,,,,,,,,,,,,,,,
,3772415183.76926,20.0027265548706,800.393310546875,,,5,,,,6.46999990567565,,,,,0.000667801338219285,7.35603935631726E-7,-0.273793222247992,0.000471456281322365,0.00066769575756486,7.35487635258431E-7,0.000667688134178762,6.64570073466526E-7,-3.1906342623179E-6,3.15101061678209E-7,1.00015812689122,10.005763053894,2,20,10,3,2.18529851336551,0.183424471756847,0.0403775237500668,172.74836730957,19.9998474121094,20.00368309021,800.393310546875,800.393310546875,,,24.6270503997803,0,1,,,,,,1,1,1,20.0036296844482,0,20.0022530989213,,,,,,,,,,,,,,,,,,,,,,,,,,,,,,,,,
,3772415206.86916,20.0017118453979,820.441040039063,,,5,,,,6.46999990567565,,,,,0.000628681917675059,6.53703687995076E-7,-0.300522886494861,0.000499553314110187,0.000628582623116071,6.53600441476314E-7,0.000628573976598708,5.73102129825994E-7,-3.29697230311076E-6,3.14241126982039E-7,1.00015796580328,10.005763053894,2,20,10,3,2.05736277344164,0.171763934029696,0.0403775237500668,172.74836730957,20.0006942749023,20.0016651153564,820.441040039063,820.441040039063,,,24.6417045593262,0,1,,,,,,1,1,1,20.0017700195313,0,20.0012239976363,,,,,,,,,,,,,,,,,,,,,,,,,,,,,,,,,
,3772415229.86623,20.0001020431519,840.343139648438,,,5,,,,6.46999990567565,,,,,0.000566538668842155,7.35754634271125E-7,-0.377129191447816,0.000547537150074458,0.000566449166128584,7.35638398540166E-7,0.000566436895567737,6.668255859667E-7,-3.72842424525285E-6,3.10656548791278E-7,1.00015800661193,10.005763053894,2,20,10,3,1.85420195158953,0.152346106635682,0.0403775237500668,172.74836730957,19.9998149871826,20.0004539489746,840.343139648438,840.343139648438,,,24.6546516418457,0,1,,,,,,1,1,1,20.0002536773682,0,20.0002046064897,,,,,,,,,,,,,,,,,,,,,,,,,,,,,,,,,
,3772415254.61613,20.0018949508667,860.403015136719,,,5,,,,6.46999990567565,,,,,0.000455334991700146,7.6734045781956E-7,-0.402712425800789,0.000820453533457583,0.00045526301972502,7.67219169077535E-7,0.000455251774312629,6.69935600960968E-7,-3.19986161372916E-6,3.73913818900946E-7,1.00015808877947,10.005763053894,2,20,1,3,1.49030058630848,0.121809239748552,0.0403775237500668,172.74836730957,19.9991474151611,20.0020217895508,860.403015136719,860.403015136719,,,24.6556339263916,0,1,,,,,,1,1,1,20.001859664917,0,20.0011667524065,,,,,,,,,,,,,,,,,,,,,,,,,,,,,,,,,
,3772415277.13155,20.0017738342285,880.402282714844,,,5,,,,6.46999990567565,,,,,0.000343648285680761,8.91164328535001E-7,-0.653740956000616,0.00147339195165819,0.000343593969236711,8.91023472667514E-7,0.000343571603822388,7.32923046446355E-7,-3.92029880880324E-6,5.06701723731301E-7,1.00015808322879,10.005763053894,2,20,1,3,1.1251434005858,0.0870266537584395,0.0403775237500668,172.74836730957,19.9994869232178,20.0030059814453,880.402282714844,880.402282714844,,,24.6691875457764,0,1,,,,,,1,1,1,20.0030059814453,0,20.0017448425293,,,,,,,,,,,,,,,,,,,,,,,,,,,,,,,,,
,3772415299.09165,20.0010957717896,900.109985351562,,,5,,,,6.46999990567565,,,,,0.00024862318038461,7.05792214054426E-7,-0.834398844359597,0.00132611220626113,0.00024858391964462,7.05680760550531E-7,0.000248557560125475,6.23453376626187E-7,-3.62000143008599E-6,3.30592230677889E-7,1.00015793756912,10.005763053894,2,20,1,3,0.814214095380601,0.060412370062763,0.0403775237500668,172.74836730957,20.0002269744873,20.0014381408691,900.109985351562,900.109985351562,,,24.6700496673584,0,1,,,,,,1,1,1,20.0010604858398,0,20.000691986084,,,,,,,,,,,,,,,,,,,,,,,,,,,,,,,,,
,3772415322.0974,20.0005121231079,920.194213867187,,,5,,,,6.46999990567565,,,,,0.000175250092358145,7.59083992738694E-7,-1.17950055266987,0.0019624205685059,0.000175222402766883,7.58964057135753E-7,0.000175185275299025,6.75814485977611E-7,-3.60690307670333E-6,3.45400087676276E-7,1.00015802540557,10.005763053894,2,20,1,3,0.574170702616605,0.0391383545856949,0.0403775237500668,172.74836730957,20.0004329681396,20.000940322876,920.194213867187,920.194213867187,,,24.6703948974609,0,1,,,,,,1,1,1,20.0006999969482,0,20.0006404876709,,,,,,,,,,,,,,,,,,,,,,,,,,,,,,,,,
,3772415343.88239,20.001091003418,940.157043457031,,,5,,,,6.46999990567565,,,,,0.000127469860722395,8.31740860552906E-7,-1.78331567566127,0.00234567944956063,0.000127449731649445,8.31609518348855E-7,0.00012738800324398,7.74522719632793E-7,-3.96619805701539E-6,3.028018292234E-7,1.00015793735059,10.005763053894,2,20,1,3,0.417905179319041,0.0240738794812856,0.0403775237500668,172.74836730957,20.0003471374512,20.0014705657959,940.157043457031,940.157043457031,,,24.6840362548828,0,1,,,,,,1,1,1,20.001350402832,0,20.0008209228516,,,,,,,,,,,,,,,,,,,,,,,,,,,,,,,,,
,3772415365.85695,20.0004987716675,960.216918945313,,,5,,,,6.46999990567565,,,,,9.3431559257877E-5,7.24536367891677E-7,-2.44805288901934,0.00335687086467494,9.34167970877907E-5,7.24421891271769E-7,9.33315410324378E-5,6.51588630434324E-7,-3.99016624363259E-6,3.16574372371625E-7,1.00015802479368,10.005763053894,2,20,1,3,0.306495846849513,0.0140971071316742,0.0403775237500668,172.74836730957,20.0001163482666,20.0007476806641,960.216918945313,960.216918945313,,,24.6719360351562,0,1,,,,,,1,1,1,20.0007476806641,0,20.0003348263827,,,,,,,,,,,,,,,,,,,,,,,,,,,,,,,,,
,3772415388.88289,20.0014505386353,980.143249511719,,,5,,,,6.46999990567565,,,,,6.7177314718135E-5,8.26136371489491E-7,-3.35784276266904,0.00474573299412076,6.71667054799038E-5,8.26005900695691E-7,6.70513932974707E-5,7.59835869137503E-7,-3.93407954826062E-6,3.23937030850372E-7,1.0001579538278,10.005763053894,2,20,1,3,0.22050372858281,0.00664016108790546,0.0403775237500668,172.74836730957,20.0006275177002,20.0017032623291,980.143249511719,980.143249511719,,,24.7107715606689,0,1,,,,,,1,1,1,20.0014324188232,0,20.0010900497437,,,,,,,,,,,,,,,,,,,,,,,,,,,,,,,,,
,3772415410.52485,20.000732421875,1000.16674804688,,,5,,,,6.46999990567565,,,,,4.87815942448151E-5,9.18608954187846E-7,-4.85927094713555,0.00966038370351943,4.87738918270881E-5,9.18463909524948E-7,4.85985869292075E-5,7.86408898649181E-7,-4.13157021539708E-6,4.74486034805276E-7,1.00015792091708,10.005763053894,2,20,1,3,0.160192808414212,0.000628122467923208,0.0403775237500668,172.74836730957,20.0001811981201,20.0009346008301,1000.16674804688,1000.16674804688,,,24.7242336273193,0,1,,,,,,1,1,1,20.0007801055908,0,20.0005016326904,,,,,,,,,,,,,,,,,,,,,,,,,,,,,,,,,