File: Experimental_Data/AC_Suceptibillity_FieldScans/FCd_Down_30K.dat
[Header]
; MPMS3 Data File (default extension .dat)
; Copyright (c) 2007, Quantum Design, Inc. All rights reserved.
TITLE,FCd_Down_30K
FILEOPENTIME,3772421499.98848,07/16/2019,6:51 am
BYAPP,SQUID AC,0.9.1.0
INFO,MPMS3 Measurement Release 1.1.16 Build 347, MultiVu Release 2.3.3.2,APPNAME
INFO,0,MOMENT_UNITS
INFO,Cu2OSeO3,SAMPLE_MATERIAL
INFO,,SAMPLE_COMMENT
INFO,,SAMPLE_MASS
INFO,,SAMPLE_VOLUME
INFO,,SAMPLE_MOLECULAR_WEIGHT
INFO,,SAMPLE_SIZE
INFO,,SAMPLE_SHAPE
INFO,Quartz,SAMPLE_HOLDER
INFO,Standard,SAMPLE_HOLDER_DETAIL
INFO,64.77,SAMPLE_OFFSET
DATATYPE,COMMENT,1
DATATYPE,TIME,2
STARTUPAXIS,X,2
STARTUPAXIS,Y1,5
FIELDGROUP, VSM,2,3,4,5,6,8,9,10,11,14,15
FIELDGROUP, DC, 2,3,4,14,56,57,58,59,60,61,62,63,64,65,66,67,68,69
FIELDGROUP, AC, 2,3,4,11,16,17,18,19,20,21,22,23,24,25,26,27,28,29,30
STARTUPGROUP, All
[Data]
Comment,Time Stamp (sec),Temperature (K),Magnetic Field (Oe),Moment (emu),M. Std. Err. (emu),Transport Action,Averaging Time (sec),Frequency (Hz),Peak Amplitude (mm),Center Position (mm),Lockin Signal' (V),Lockin Signal (V),Range,M. Quad. Signal (emu),AC Moment (emu),AC M. Std Err. (emu),AC Phase (deg),AC Phase Std. Err. (deg),AC Susceptibility (emu/Oe),AC Suscept. Std Err. (emu/Oe),AC X' (emu/Oe),AC X' Std Err. (emu/Oe),AC X'' (emu/Oe),AC X'' Std Err. (emu/Oe),AC Drive (Oe),AC Frequency (Hz),AC Averaging Time (sec),AC Cycles,AC Range,AC Measure Type,AC Signal' (V),AC Signal'' (V),AC Trim Coil Ratio,AC Trim Coil Phase,Min. Temperature (K),Max. Temperature (K),Min. Field (Oe),Max. Field (Oe),Mass (grams),Motor Lag (deg),Pressure (Torr),Measure Count,Measurement Number,SQUID Status (code),Motor Status (code),Measure Status (code),Motor Current (amps),Motor Temp. (C),Temp. Status (code),Field Status (code),Chamber Status (code),Chamber Temp (K),Redirection State,Average Temp (K),Rotation Angle (deg),Rotator state,DC Moment Fixed Ctr (emu),DC Moment Err Fixed Ctr (emu),DC Moment Free Ctr (emu),DC Moment Err Free Ctr (emu),DC Fixed Fit,DC Free Fit,DC Calculated Center (mm),DC Calculated Center Err (mm),DC Scan Length (mm),DC Scan Time (s),DC Number of Points,DC Squid Drift,DC Min V (V),DC Max V (V),DC Scans per Measure,Map 01,Map 02,Map 03,Map 04,Map 05,Map 06,Map 07,Map 08,Map 09,Map 10,Map 11,Map 12,Map 13,Map 14,Map 15,Map 16
,3772421651.76189,29.9067106246948,200.016342163086,,,5,,,,6.46999990567565,,,,,0.000701146765533259,1.41446886450409E-7,0.0752312217470994,0.000154652783031477,0.000701037166731554,1.41424776373001E-7,0.000701036562418536,9.0818118406471E-8,9.20484333002131E-7,1.08411423481391E-7,1.00015633807579,10.005763053894,2,20,10,3,2.29330364998978,0.204993938585672,0.0403775237500668,172.74836730957,29.9063148498535,29.9100208282471,200.016342163086,200.016342163086,,,29.5557327270508,0,1,,,,,,1,1,1,29.9063682556152,0,29.9076031771573,,,,,,,,,,,,,,,,,,,,,,,,,,,,,,,,,
,3772421674.7913,29.9220972061157,180.247863769531,,,5,,,,6.46999990567565,,,,,0.000672226887498792,2.62864932772122E-7,0.139241560430954,0.000192517591587543,0.0006721217207973,2.62823808802772E-7,0.000672119736027151,2.28829601090429E-7,1.63340451736304E-6,1.29280192366778E-7,1.000156469726,10.005763053894,2,20,10,3,2.19849488405753,0.198948183361756,0.0403775237500668,172.74836730957,29.919282913208,29.9303817749023,180.247863769531,180.247863769531,,,29.4064865112305,0,1,,,,,,1,1,1,29.9235229492188,0,29.9246517528187,,,,,,,,,,,,,,,,,,,,,,,,,,,,,,,,,
,3772421696.4888,29.9364948272705,160.236511230469,,,5,,,,6.46999990567565,,,,,0.000649628702892243,1.69553420836566E-7,0.115729685293622,0.00012006718212841,0.000649527089941536,1.6952689980491E-7,0.000649525764955183,1.5056378950173E-7,1.31195552681202E-6,7.79096595316838E-8,1.00015644143606,10.005763053894,2,20,10,3,2.12466994556155,0.191342629023811,0.0403775237500668,172.74836730957,29.9349422454834,29.9459762573242,160.236511230469,160.236511230469,,,29.3318634033203,0,1,,,,,,1,1,1,29.9376430511475,0,29.9393356323242,,,,,,,,,,,,,,,,,,,,,,,,,,,,,,,,,
,3772421718.38153,29.9565296173096,140.261596679688,,,5,,,,6.46999990567565,,,,,0.000633504812802606,1.11922068577324E-7,0.0897846477701778,4.12302943235863E-5,0.000633405576280652,1.11904536339856E-7,0.000633404798583158,1.0884311964168E-7,9.92570024707305E-7,2.59961643344736E-8,1.00015667137403,10.005763053894,2,20,10,3,2.07202241212002,0.185610680220946,0.0403775237500668,172.74836730957,29.9512157440186,29.9733600616455,140.261596679688,140.261596679688,,,29.3194274902344,0,1,,,,,,1,1,1,29.9595985412598,0,29.9618147069758,,,,,,,,,,,,,,,,,,,,,,,,,,,,,,,,,
,3772421738.8956,29.9738721847534,120.298812866211,,,5,,,,6.46999990567565,,,,,0.000621451726925999,8.32668945041535E-8,0.0790796933873716,9.78522162577518E-5,0.000621354454687113,8.32538612195031E-8,0.000621353862861114,5.68785453149279E-8,8.57593780530401E-7,6.07950367284532E-8,1.00015654871089,10.005763053894,2,20,10,3,2.03263678883766,0.181655865509635,0.0403775237500668,172.74836730957,29.9699535369873,29.9834804534912,120.298812866211,120.298812866211,,,29.3691749572754,0,1,,,,,,1,1,1,29.9759216308594,0,29.9775260925293,,,,,,,,,,,,,,,,,,,,,,,,,,,,,,,,,
,3772421760.75853,29.9804601669312,100.287460327148,,,5,,,,6.46999990567565,,,,,0.000612668965332815,6.43355398656017E-8,0.0622960522272251,5.26276559390607E-5,0.000612573234035925,6.43254872515214E-8,0.000612572871956568,5.5674477968081E-8,6.66033117728746E-7,3.22198822643303E-8,1.00015627730951,10.005763053894,2,20,10,3,2.00396532244905,0.178458606770659,0.0403775237500668,172.74836730957,29.9793243408203,29.9811153411865,100.287460327148,100.287460327148,,,29.4313621520996,0,1,,,,,,1,1,1,29.9801044464111,0,29.9799650192261,,,,,,,,,,,,,,,,,,,,,,,,,,,,,,,,,
,3772421782.38646,29.9830598831177,80.2396850585938,,,5,,,,6.46999990567565,,,,,0.000605893508640238,9.33258143503439E-8,0.0572159693043792,3.34074592089115E-5,0.000605798694459695,9.33112101162913E-8,0.000605798392403633,9.11092979269954E-8,6.0495474606667E-7,2.01513712837775E-8,1.00015651103479,10.005763053894,2,20,10,3,1.98182195178745,0.176266758307362,0.0403775237500668,172.74836730957,29.9799346923828,29.9942646026611,80.2396850585938,80.2396850585938,,,29.5059814453125,0,1,,,,,,1,1,1,29.9846858978271,0,29.9868654251099,,,,,,,,,,,,,,,,,,,,,,,,,,,,,,,,,
,3772421805.44042,29.9981336593628,60.1676177978516,,,5,,,,6.46999990567565,,,,,0.000600779849321159,4.40714153843196E-8,0.0450372725904122,2.74122268870889E-5,0.000600685971450297,4.40645287841002E-8,0.000600685785876621,4.08798621238716E-8,4.72168374031036E-7,1.64474791289743E-8,1.00015628444033,10.005763053894,2,20,10,3,1.96513540863739,0.174319023732272,0.0403775237500668,172.74836730957,29.9977550506592,30.0052299499512,60.1676177978516,60.1676177978516,,,29.5557327270508,0,1,,,,,,1,1,1,29.9984970092773,0,30.0003816604614,,,,,,,,,,,,,,,,,,,,,,,,,,,,,,,,,
,3772421825.94872,30.006519317627,40.2534141540527,,,5,,,,6.46999990567565,,,,,0.000596936874461655,2.5736461627119E-8,0.0435746759711222,2.38472622313288E-5,0.00059684357309282,2.57324390123309E-8,0.00059684340048774,2.14412472012902E-8,4.53912365219815E-7,1.42278366583431E-8,1.00015632466033,10.005763053894,2,20,10,3,1.95257217195691,0.173112424287887,0.0403775237500668,172.74836730957,30.0030326843262,30.0072555541992,40.2534141540527,40.2534141540527,,,29.6179161071777,0,1,,,,,,1,1,1,30.0062046051025,0,30.0052530288696,,,,,,,,,,,,,,,,,,,,,,,,,,,,,,,,,
,3772421847.8037,30.000316619873,20.2056350708008,,,5,,,,6.46999990567565,,,,,0.000594009494684295,6.22263384640263E-8,0.0523754212698879,2.75541470140296E-5,0.000593916683442609,6.22166158858687E-8,0.000593916435297744,6.00378870724802E-8,5.42913150438734E-7,1.63205210750712E-8,1.00015626980059,10.005763053894,2,20,10,3,1.94297288176203,0.172520301728652,0.0403775237500668,172.74836730957,29.9997577667236,30.0009078979492,20.2056350708008,20.2056350708008,,,29.680103302002,0,1,,,,,,1,1,1,30.0001316070557,0,30.0002006530762,,,,,,,,,,,,,,,,,,,,,,,,,,,,,,,,,
,3772421869.50719,29.9963235855103,0.145713716745377,,,5,,,,6.46999990567565,,,,,0.000591900182475834,1.23721816755003E-7,0.070055785593266,2.96173024465347E-5,0.000591807673372107,1.23702480058177E-7,0.00059180723099434,1.22483098641988E-7,7.23605499395727E-7,1.73261109196711E-8,1.0001563161613,10.005763053894,2,20,10,3,1.93602291350972,0.172463589738424,0.0403775237500668,172.74836730957,29.9959449768066,30.0038948059082,0.145713716745377,0.145713716745377,,,29.717414855957,0,1,,,,,,1,1,1,29.9961071014404,0,29.9987099387429,,,,,,,,,,,,,,,,,,,,,,,,,,,,,,,,,
,3772421890.17117,30.0060930252075,-19.8777770996094,,,5,,,,6.46999990567565,,,,,0.000591897924651682,1.96160140026815E-7,0.0716928960863772,4.23747796174297E-5,0.000591805422426612,1.961294839818E-7,0.00059180495913347,1.94565844988956E-7,7.40512371807219E-7,2.47165218163993E-8,1.00015630513267,10.005763053894,2,20,10,3,1.9360080293191,0.172559038401469,0.0403775237500668,172.74836730957,30.0025005340576,30.0076351165771,-19.8777770996094,-19.8777770996094,,,29.7422866821289,0,1,,,,,,1,1,1,30.0052871704102,0,30.0044647563588,,,,,,,,,,,,,,,,,,,,,,,,,,,,,,,,,
,3772421911.34066,29.9924898147583,-39.779842376709,,,5,,,,6.46999990567565,,,,,0.000594042019673578,1.91539045289663E-7,0.0550320635280723,6.09240638284937E-5,0.000593949212032287,1.91509120997408E-7,0.000593948938060645,1.8809861230085E-7,5.70482608336E-7,3.59813212055167E-8,1.00015625518043,10.005763053894,2,20,10,3,1.94306870261894,0.1726606346527,0.0403775237500668,172.74836730957,29.992244720459,29.9997177124023,-39.779842376709,-39.779842376709,,,29.767162322998,0,1,,,,,,1,1,1,29.9922142028809,0,29.9945734197443,,,,,,,,,,,,,,,,,,,,,,,,,,,,,,,,,
,3772421933.50349,30.0020656585693,-59.8640480041504,,,5,,,,6.46999990567565,,,,,0.000596840679332109,1.37015550071008E-7,0.031257555875337,3.97372529978171E-5,0.000596747446325551,1.36994146751628E-7,0.000596747357523023,1.34949284892856E-7,3.25553921776674E-7,2.35814917067043E-8,1.00015623528367,10.005763053894,2,20,10,3,1.95229212066434,0.172705860179768,0.0403775237500668,172.74836730957,30.0016555786133,30.0071315765381,-59.8640480041504,-59.8640480041504,,,29.8293495178223,0,1,,,,,,1,1,1,30.0019454956055,0,30.0037536621094,,,,,,,,,,,,,,,,,,,,,,,,,,,,,,,,,
,3772421956.62194,30.0126810073853,-79.8632583618164,,,5,,,,6.46999990567565,,,,,0.000600321810716956,1.55473189323985E-7,0.0235888203260215,7.19366032455955E-5,0.000600228017283726,1.55448898412108E-7,0.000600227966414698,1.49355218890864E-7,2.47115417133595E-7,4.30973155498136E-8,1.00015626300427,10.005763053894,2,20,10,3,1.96369967798519,0.173492281902981,0.0403775237500668,172.74836730957,30.0061340332031,30.0150966644287,-79.8632583618164,-79.8632583618164,,,29.8293495178223,0,1,,,,,,1,1,1,30.0116233825684,0,30.0104349454244,,,,,,,,,,,,,,,,,,,,,,,,,,,,,,,,,
,3772421979.71056,30.0010099411011,-99.9231796264648,,,5,,,,6.46999990567565,,,,,0.00060549348929656,2.05094460609895E-7,0.02697862543996,7.02167990482594E-5,0.000605398864509409,2.05062409035396E-7,0.000605398797396515,2.00640825999343E-7,2.85061635300891E-7,4.23538728064093E-8,1.00015630156034,10.005763053894,2,20,10,3,1.98060362381893,0.175146711574307,0.0403775237500668,172.74836730957,30.000301361084,30.0021362304687,-99.9231796264648,-99.9231796264648,,,29.8666572570801,0,1,,,,,,1,1,1,30.0007247924805,0,30.0008455912272,,,,,,,,,,,,,,,,,,,,,,,,,,,,,,,,,
,3772422002.68721,30.008246421814,-119.813102722168,,,5,,,,6.46999990567565,,,,,0.000613385835811242,2.13753081016995E-7,0.0170879841814529,8.58283602916809E-5,0.000613289985247743,2.13719678952472E-7,0.000613289957972271,2.07166713767702E-7,1.82908575470259E-7,5.25171769827631E-8,1.00015628913859,10.005763053894,2,20,10,3,2.00644788515791,0.177125950459906,0.0403775237500668,172.74836730957,30.0046138763428,30.0094203948975,-119.813102722168,-119.813102722168,,,29.9164085388184,0,1,,,,,,1,1,1,30.0076007843018,0,30.0069610595703,,,,,,,,,,,,,,,,,,,,,,,,,,,,,,,,,
,3772422024.31515,30.0000925064087,-139.909454345703,,,5,,,,6.46999990567565,,,,,0.000622470732248384,2.04907015612556E-7,0.012562298372675,0.000103369210888024,0.000622373409122185,2.04874978457544E-7,0.000622373394162792,1.94539054534519E-7,1.36457527385332E-7,6.42519498443008E-8,1.00015637417147,10.005763053894,2,20,10,3,2.03617697284099,0.17963241812555,0.0403775237500668,172.74836730957,29.9999504089355,30.0005435943604,-139.909454345703,-139.909454345703,,,29.8915328979492,0,1,,,,,,1,1,1,30.0002307891846,0,30.0001454786821,,,,,,,,,,,,,,,,,,,,,,,,,,,,,,,,,
,3772422046.25623,30.0016145706177,-159.99365234375,,,5,,,,6.46999990567565,,,,,0.000633695936639403,1.98126715766684E-7,0.0174337770448219,8.54269988096221E-5,0.00063359688690865,1.98095747605588E-7,0.000633596857578064,1.90585989760049E-7,1.92788836910559E-7,5.40268981767354E-8,1.00015632925729,10.005763053894,2,20,10,3,2.07287764283636,0.183092569500201,0.0403775237500668,172.74836730957,30.0007438659668,30.0017604827881,-159.99365234375,-159.99365234375,,,29.9164085388184,0,1,,,,,,1,1,1,30.0016441345215,0,30.00126953125,,,,,,,,,,,,,,,,,,,,,,,,,,,,,,,,,
,3772422068.13229,30.000412940979,-179.895706176758,,,5,,,,6.46999990567565,,,,,0.000647308670340578,2.26636510543934E-7,0.0229700154916115,0.000157308171258015,0.000647207454311097,2.26601072662775E-7,0.000647207402300622,2.02471924746765E-7,2.59467014497826E-7,1.01750507719915E-7,1.00015638884999,10.005763053894,2,20,10,3,2.11738524822287,0.187275384088466,0.0403775237500668,172.74836730957,29.999683380127,30.0010795593262,-179.895706176758,-179.895706176758,,,29.9288444519043,0,1,,,,,,1,1,1,30.0001945495605,0,30.0001440048218,,,,,,,,,,,,,,,,,,,,,,,,,,,,,,,,,
,3772422089.79864,29.9943199157715,-199.919204711914,,,5,,,,6.46999990567565,,,,,0.000664030448685937,2.46712687508937E-7,0.0247392318265405,0.000188060197858048,0.000663926651047961,2.46674122719818E-7,0.000663926589158421,2.12772294310389E-7,2.86670937463679E-7,1.24804140930841E-7,1.00015633901397,10.005763053894,2,20,10,3,2.1720743354945,0.192226911684176,0.0403775237500668,172.74836730957,29.9939098358154,30.0035743713379,-199.919204711914,-199.919204711914,,,29.9288444519043,0,1,,,,,,1,1,1,29.9947299957275,0,29.9970096588135,,,,,,,,,,,,,,,,,,,,,,,,,,,,,,,,,
,3772422111.43839,30.0014247894287,-219.979141235352,,,5,,,,6.46999990567565,,,,,0.000686868053375738,3.27274475740931E-7,0.0634607898948323,0.000205693745748955,0.000686760777272134,3.27223361512523E-7,0.000686760356020959,2.95221379723334E-7,7.60655895667667E-7,1.41136335767252E-7,1.00015620592665,10.005763053894,2,20,10,3,2.24663926568734,0.200404593919352,0.0403775237500668,172.74836730957,29.999792098999,30.0057239532471,-219.979141235352,-219.979141235352,,,29.9537200927734,0,1,,,,,,1,1,1,30.0001964569092,0,30.002435874939,,,,,,,,,,,,,,,,,,,,,,,,,,,,,,,,,
,3772422133.3128,30.0071697235107,-239.905471801758,,,5,,,,6.46999990567565,,,,,0.000716985340937746,5.42711585248301E-7,0.080306813814083,0.000196831233865702,0.000716873254611286,5.4262674314004E-7,0.000716872550450498,5.24088749837531E-7,1.00478235266145E-6,1.40622774345056E-7,1.00015635445421,10.005763053894,2,20,10,3,2.34508348510795,0.209931223212033,0.0403775237500668,172.74836730957,30.0031890869141,30.0080795288086,-239.905471801758,-239.905471801758,,,29.9785919189453,0,1,,,,,,1,1,1,30.0069217681885,0,30.0056879043579,,,,,,,,,,,,,,,,,,,,,,,,,,,,,,,,,
,3772422155.0521,29.9961004257202,-259.843963623047,,,5,,,,6.46999990567565,,,,,0.000754630049588493,3.77403924229332E-7,0.0635230632008126,0.000223601858284417,0.000754512201345636,3.77344986224753E-7,0.000754511737627772,3.37597727317792E-7,8.36517398667954E-7,1.68573465108899E-7,1.00015619130167,10.005763053894,2,20,10,3,2.46827138432219,0.220283286714786,0.0403775237500668,172.74836730957,29.9943904876709,30.0030059814453,-259.843963623047,-259.843963623047,,,29.9910316467285,0,1,,,,,,1,1,1,29.9954433441162,0,29.9981273304332,,,,,,,,,,,,,,,,,,,,,,,,,,,,,,,,,
,3772422176.99558,30.0057563781738,-279.867462158203,,,5,,,,6.46999990567565,,,,,0.000795623978191825,4.71152153789914E-7,0.0323121184454465,0.000243843535924837,0.000795499649781059,4.71078529062511E-7,0.000795499523279585,4.29358399784759E-7,4.48624274998431E-7,1.93820393864965E-7,1.0001562897115,10.005763053894,2,20,10,3,2.60247846044709,0.230887791691683,0.0403775237500668,172.74836730957,30.0028781890869,30.0069808959961,-279.867462158203,-279.867462158203,,,30.0034675598145,0,1,,,,,,1,1,1,30.0051155090332,0,30.0045967102051,,,,,,,,,,,,,,,,,,,,,,,,,,,,,,,,,
,3772422198.63081,30.0013332366943,-299.890960693359,,,5,,,,6.46999990567565,,,,,0.000829696062210622,5.10704859787437E-7,-0.00570815487593634,0.000231349113776241,0.000829566387404345,5.10625040734685E-7,0.000829566383287473,4.73239903752178E-7,-8.2646461075908E-8,1.91786145802893E-7,1.00015631636991,10.005763053894,2,20,10,3,2.71408348490755,0.239032684683141,0.0403775237500668,172.74836730957,30.0006313323975,30.0060501098633,-299.890960693359,-299.890960693359,,,30.0034675598145,0,1,,,,,,1,1,1,30.0006465911865,0,30.0025260925293,,,,,,,,,,,,,,,,,,,,,,,,,,,,,,,,,
,3772422220.4721,30.0066003799438,-319.999450683594,,,5,,,,6.46999990567565,,,,,0.00085238135127687,4.70760260431883E-7,-0.0468720293575062,0.000239562470914622,0.000852248120714217,4.70686678748898E-7,0.000852247835534731,4.24127638462323E-7,-6.97199598606179E-7,2.04111968889728E-7,1.00015632837364,10.005763053894,2,20,10,3,2.78846313780099,0.243624865996057,0.0403775237500668,172.74836730957,30.003023147583,30.0075435638428,-319.999450683594,-319.999450683594,,,30.0159034729004,0,1,,,,,,1,1,1,30.0063972473145,0,30.0052213668823,,,,,,,,,,,,,,,,,,,,,,,,,,,,,,,,,
,3772422241.93792,29.9971551895142,-339.889373779297,,,5,,,,6.46999990567565,,,,,0.000862456271594522,4.06821978096334E-7,-0.087937352030103,0.000221836064647171,0.000862321443967119,4.06758379692695E-7,0.000862320428325221,3.58975456011313E-7,-1.32348726650928E-6,1.91282517318483E-7,1.00015635425553,10.005763053894,2,20,10,3,2.82159432506231,0.244542408338176,0.0403775237500668,172.74836730957,29.9965667724609,30.001012802124,-339.889373779297,-339.889373779297,,,30.0283432006836,0,1,,,,,,1,1,1,29.9969692230225,0,29.9983173717152,,,,,,,,,,,,,,,,,,,,,,,,,,,,,,,,,
,3772422264.0867,30.0104646682739,-359.937164306641,,,5,,,,6.46999990567565,,,,,0.000865607636874624,3.74214233413902E-7,-0.113668048915495,0.000274374453056245,0.000865472384212668,3.74155761804994E-7,0.000865470681055907,2.89158653421082E-7,-1.71699370543904E-6,2.3744432451331E-7,1.00015627611513,10.005763053894,2,20,10,3,2.83201056262525,0.244224725346819,0.0403775237500668,172.74836730957,30.0052547454834,30.0118522644043,-359.937164306641,-359.937164306641,,,30.0407791137695,0,1,,,,,,1,1,1,30.0096225738525,0,30.0084604263306,,,,,,,,,,,,,,,,,,,,,,,,,,,,,,,,,
,3772422284.90702,30.0020341873169,-380.009216308594,,,5,,,,6.46999990567565,,,,,0.000865846634691708,4.10117645323656E-7,-0.145178896185414,0.00028660032455394,0.000865711282049376,4.10053534077233E-7,0.000865708502946878,3.26476536436891E-7,-2.19357996212359E-6,2.48106775331508E-7,1.00015634847915,10.005763053894,2,20,10,3,2.83292277448754,0.242795152456224,0.0403775237500668,172.74836730957,30.0007228851318,30.0029907226562,-380.009216308594,-380.009216308594,,,30.0407791137695,0,1,,,,,,1,1,1,30.0016746520996,0,30.001426523382,,,,,,,,,,,,,,,,,,,,,,,,,,,,,,,,,
,3772422307.61158,29.9929056167603,-399.862701416016,,,5,,,,6.46999990567565,,,,,0.000864224792199736,5.10683797054346E-7,-0.155307669671362,0.000443108377142731,0.000864089757240391,5.10604002808224E-7,0.000864086582785666,3.37868458654118E-7,-2.34222491403857E-6,3.82833321865366E-7,1.00015627422755,10.005763053894,2,20,10,3,2.82765555401815,0.241900705275802,0.0403775237500668,172.74836730957,29.9924449920654,30.0013256072998,-399.862701416016,-399.862701416016,,,30.0532150268555,0,1,,,,,,1,1,1,29.9932270050049,0,29.9957607269287,,,,,,,,,,,,,,,,,,,,,,,,,,,,,,,,,
,3772422329.05742,30.011664390564,-419.910491943359,,,5,,,,6.46999990567565,,,,,0.000861717394809546,5.3810193857849E-7,-0.175178896490299,0.000336490450597518,0.00086158280141587,5.3801789134155E-7,0.000861578774384665,4.53201618043685E-7,-2.63424096014302E-6,2.89950935170407E-7,1.00015621643498,10.005763053894,2,20,10,3,2.8195315305464,0.240281241236087,0.0403775237500668,172.74836730957,30.0061569213867,30.0143013000488,-419.910491943359,-419.910491943359,,,30.0532150268555,0,1,,,,,,1,1,1,30.0107593536377,0,30.0099249753085,,,,,,,,,,,,,,,,,,,,,,,,,,,,,,,,,
,3772422351.27432,30.002498626709,-439.958282470703,,,5,,,,6.46999990567565,,,,,0.000858802690580559,5.64995198944016E-7,-0.199259587663115,0.00038977245869691,0.000858668519230508,5.64906929345602E-7,0.000858663326589518,4.55072563272923E-7,-2.98621629098287E-6,3.34707037540128E-7,1.00015625511713,10.005763053894,2,20,10,3,2.81009148556674,0.238347905762448,0.0403775237500668,172.74836730957,30.001838684082,30.0069446563721,-439.958282470703,-439.958282470703,,,30.0780906677246,0,1,,,,,,1,1,1,30.0018558502197,0,30.0038134834983,,,,,,,,,,,,,,,,,,,,,,,,,,,,,,,,,
,3772422374.29317,30.003381729126,-460.200317382812,,,5,,,,6.46999990567565,,,,,0.000855520431739061,6.51879544508415E-7,-0.205220943987085,0.000466884731538978,0.000855386738580837,6.51777674544994E-7,0.000855381251641609,5.15081627868769E-7,-3.06380155942204E-6,3.99380837882014E-7,1.00015629557041,10.005763053894,2,20,10,3,2.79937272486171,0.237206322636124,0.0403775237500668,172.74836730957,30.0031623840332,30.0073890686035,-460.200317382812,-460.200317382812,,,30.0780906677246,0,1,,,,,,1,1,1,30.0032501220703,0,30.0045932422985,,,,,,,,,,,,,,,,,,,,,,,,,,,,,,,,,
,3772422395.87582,29.9979982376099,-480.163116455078,,,5,,,,6.46999990567565,,,,,0.000852263534204791,6.44671215996658E-7,-0.22877394372454,0.000385156124132172,0.000852130364773766,6.44570483657908E-7,0.000852123572059892,5.54686938460367E-7,-3.40242698108839E-6,3.28319217689817E-7,1.00015627823691,10.005763053894,2,20,10,3,2.78880915986972,0.235216556135071,0.0403775237500668,172.74836730957,29.99778175354,30.0038738250732,-480.163116455078,-480.163116455078,,,30.0656509399414,0,1,,,,,,1,1,1,29.9981250762939,0,29.9999082565308,,,,,,,,,,,,,,,,,,,,,,,,,,,,,,,,,
,3772422417.76105,29.9987707138062,-500.223022460937,,,5,,,,6.46999990567565,,,,,0.000848567490214678,7.28188735645143E-7,-0.242136948236583,0.000490648198607441,0.000848434868286868,7.28074927615676E-7,0.000848427291854851,5.97276115481478E-7,-3.58554888368073E-6,4.16358429838917E-7,1.00015631362261,10.005763053894,2,20,10,3,2.77676590665382,0.233608472270151,0.0403775237500668,172.74836730957,29.9982147216797,30.004093170166,-500.223022460937,-500.223022460937,,,30.0905265808105,0,1,,,,,,1,1,1,29.9984664916992,0,30.000431580977,,,,,,,,,,,,,,,,,,,,,,,,,,,,,,,,,
,3772422439.20829,30.0127935409546,-520.258666992188,,,5,,,,6.46999990567565,,,,,0.00084468496687214,4.98090275228596E-7,-0.243290899165316,0.000332554758143766,0.000844552990131004,4.98012451739492E-7,0.000844545376309032,4.11219562714092E-7,-3.58615312767631E-6,2.80917912082534E-7,1.00015626815922,10.005763053894,2,20,10,3,2.76406238867243,0.232543019122427,0.0403775237500668,172.74836730957,30.0064716339111,30.015115737915,-520.258666992188,-520.258666992188,,,30.0780906677246,0,1,,,,,,1,1,1,30.0116367340088,0,30.0105393149636,,,,,,,,,,,,,,,,,,,,,,,,,,,,,,,,,
,3772422461.41476,30.0079288482666,-540.318603515625,,,5,,,,6.46999990567565,,,,,0.000841464772657601,6.42903687678545E-7,-0.271026618346527,0.000441281788788324,0.000841333293641124,6.42803233865988E-7,0.000841323880904699,5.24690221963699E-7,-3.97974980090508E-6,3.71343733546503E-7,1.00015627459114,10.005763053894,2,20,10,3,2.75363335303266,0.230382714608827,0.0403775237500668,172.74836730957,30.0041751861572,30.0086250305176,-540.318603515625,-540.318603515625,,,30.0905265808105,0,1,,,,,,1,1,1,30.0076675415039,0,30.0064455032349,,,,,,,,,,,,,,,,,,,,,,,,,,,,,,,,,
,3772422482.18859,29.9991025924683,-560.172058105469,,,5,,,,6.46999990567565,,,,,0.000837906343714891,6.86071816775623E-7,-0.308533959022849,0.000522039842655994,0.000837775375274564,6.85964580738481E-7,0.000837763228604782,5.28433573400479E-7,-4.51134282979865E-6,4.37384687124412E-7,1.00015632882535,10.005763053894,2,20,10,3,2.74213490538018,0.227671824514044,0.0403775237500668,172.74836730957,29.9987640380859,30.0044136047363,-560.172058105469,-560.172058105469,,,30.0905265808105,0,1,,,,,,1,1,1,29.9988174438477,0,30.0005489696156,,,,,,,,,,,,,,,,,,,,,,,,,,,,,,,,,
,3772422504.97807,30.0000915527344,-580.256286621094,,,5,,,,6.46999990567565,,,,,0.000834081161700036,7.53548691865176E-7,-0.311915906808982,0.000549910379037804,0.000833950753378359,7.53430874769286E-7,0.000833938395636515,5.97725505199518E-7,-4.53997175402126E-6,4.58674507128522E-7,1.00015637412779,10.005763053894,2,20,10,3,2.72962663476901,0.226529992153703,0.0403775237500668,172.74836730957,29.9999122619629,30.0037784576416,-580.256286621094,-580.256286621094,,,30.1029624938965,0,1,,,,,,1,1,1,30.0001544952393,0,30.0011513449929,,,,,,,,,,,,,,,,,,,,,,,,,,,,,,,,,
,3772422526.7939,30.0045375823975,-600.352600097656,,,5,,,,6.46999990567565,,,,,0.000826547786821878,6.05229885262475E-7,-0.117478834052706,0.000268427656588721,0.000826418577502134,6.05135273259381E-7,0.000826416840325761,5.62986003549551E-7,-1.69448122919975E-6,2.21890645927246E-7,1.00015634851788,10.005763053894,2,20,10,3,2.7041919152633,0.233720280452406,0.0403775237500668,172.74836730957,30.0011501312256,30.0054378509521,-600.352600097656,-600.352600097656,,,30.1029624938965,0,1,,,,,,1,1,1,30.0043182373047,0,30.0028350012643,,,,,,,,,,,,,,,,,,,,,,,,,,,,,,,,,
,3772422553.70487,30.0000734329224,-620.169677734375,,,5,,,,6.46999990567565,,,,,0.000826446517833048,8.59386944113598E-7,-0.361081676286466,0.000734790021652053,0.000826317303871252,8.59252579954069E-7,0.000826300894911512,6.08051273980349E-7,-5.20747016216162E-6,6.07115017413174E-7,1.00015637329775,10.005763053894,2,20,10,3,2.70482650904442,0.222251062873335,0.0403775237500668,172.74836730957,29.9998016357422,30.0004768371582,-620.169677734375,-620.169677734375,,,30.1029624938965,0,1,,,,,,1,1,1,30.0000228881836,0,29.9999912261963,,,,,,,,,,,,,,,,,,,,,,,,,,,,,,,,,
,3772422575.03341,30.0004177093506,-640.217468261719,,,5,,,,6.46999990567565,,,,,0.000821797809284268,8.61819464664468E-7,-0.347852307100671,0.000717039927918405,0.000821669403365535,8.61684805361545E-7,0.000821654260422202,6.2881033771645E-7,-4.98846240029582E-6,5.89150458687666E-7,1.00015627443131,10.005763053894,2,20,10,3,2.68955767932672,0.221679628859927,0.0403775237500668,172.74836730957,29.9996547698975,30.0016670227051,-640.217468261719,-640.217468261719,,,30.1154022216797,0,1,,,,,,1,1,1,30.0000667572022,0,30.0002193450928,,,,,,,,,,,,,,,,,,,,,,,,,,,,,,,,,
,3772422597.22351,30.0005283355713,-660.313842773437,,,5,,,,6.46999990567565,,,,,0.000817161857020476,8.27436664154757E-7,-0.394032663318283,0.000562478777086363,0.000817034171329607,8.27307372973083E-7,0.0008170148504143,6.8776010759356E-7,-5.61883642377134E-6,4.59808138008146E-7,1.00015627949889,10.005763053894,2,20,10,3,2.67455885814588,0.218330972639596,0.0403775237500668,172.74836730957,29.999942779541,30.0012321472168,-660.313842773437,-660.313842773437,,,30.1029624938965,0,1,,,,,,1,1,1,30.0001907348633,0,30.0002897262573,,,,,,,,,,,,,,,,,,,,,,,,,,,,,,,,,
,3772422618.87214,30.0008602142334,-680.252319335938,,,5,,,,6.46999990567565,,,,,0.00081138364857585,9.05380892925028E-7,-0.406019022741391,0.000625214814962592,0.000811256853427997,9.05239408801725E-7,0.000811236484223705,7.49617488220911E-7,-5.74881711801818E-6,5.07476116286343E-7,1.00015629470163,10.005763053894,2,20,10,3,2.65568902008523,0.216288222186648,0.0403775237500668,172.74836730957,29.9999389648438,30.0013446807861,-680.252319335938,-680.252319335938,,,30.0905265808105,0,1,,,,,,1,1,1,30.0007419586182,0,30.0004968643188,,,,,,,,,,,,,,,,,,,,,,,,,,,,,,,,,
,3772422640.78185,30.0018749237061,-700.178649902344,,,5,,,,6.46999990567565,,,,,0.000799650999841847,2.98183800460642E-7,-0.144720386210523,0.000221676401852163,0.000799526001000547,2.98137189339591E-7,0.000799523450552237,2.39737934751362E-7,-2.01947839089533E-6,1.77232915420535E-7,1.00015634118358,10.005763053894,2,20,10,3,2.61628493650598,0.225150396685009,0.0403775237500668,172.74836730957,30.0009536743164,30.0020408630371,-700.178649902344,-700.178649902344,,,30.0780906677246,0,1,,,,,,1,1,1,30.0020122528076,0,30.0015081258921,,,,,,,,,,,,,,,,,,,,,,,,,,,,,,,,,
,3772422666.43478,30.0101833343506,-720.226440429688,,,5,,,,6.46999990567565,,,,,0.000789954234467402,6.76562105449524E-7,-0.175317126483508,0.00022379030659545,0.000789830812955191,6.76456400188997E-7,0.000789827115463892,6.52863344389219E-7,-2.4167688027685E-6,1.77095214248098E-7,1.00015626322775,10.005763053894,2,20,10,3,2.58467433578546,0.221095292005679,0.0403775237500668,172.74836730957,30.0034618377686,30.0110054016113,-720.226440429688,-720.226440429688,,,30.1029624938965,0,1,,,,,,1,1,1,30.0095672607422,0,30.0071014991173,,,,,,,,,,,,,,,,,,,,,,,,,,,,,,,,,
,3772422692.04484,30.0063133239746,-740.262084960937,,,5,,,,6.46999990567565,,,,,0.000774262920976177,5.0281507844569E-7,-0.159702701664772,0.000394542560382461,0.000774141910809866,5.02736493078087E-7,0.000774138903559651,3.99321600630805E-7,-2.15779234684001E-6,3.0542796326156E-7,1.00015631522415,10.005763053894,2,20,10,3,2.53327106457921,0.217448306521356,0.0403775237500668,172.74836730957,30.0025863647461,30.0074577331543,-740.262084960937,-740.262084960937,,,30.1154022216797,0,1,,,,,,1,1,1,30.0056648254395,0,30.004311970302,,,,,,,,,,,,,,,,,,,,,,,,,,,,,,,,,
,3772422717.96785,30.000979423523,-760.309875488281,,,5,,,,6.46999990567565,,,,,0.000747210103145412,5.64494425168616E-7,-0.17505990522651,0.000344340275965078,0.00074709333233625,5.64406208386594E-7,0.000747089845170102,5.02323962441139E-7,-2.28264429907193E-6,2.5734219401949E-7,1.00015630016239,10.005763053894,2,20,10,3,2.44481136914311,0.209247879881276,0.0403775237500668,172.74836730957,29.9995670318604,30.002082824707,-760.309875488281,-760.309875488281,,,30.1154022216797,0,1,,,,,,1,1,1,30.0005187988281,0,30.0003886904035,,,,,,,,,,,,,,,,,,,,,,,,,,,,,,,,,
,3772422744.12862,30.000599861145,-780.248352050781,,,5,,,,6.46999990567565,,,,,0.000702318780469922,1.14595933553446E-6,-0.532176257140417,0.000953650833935535,0.000702209037292705,1.14578026981396E-6,0.000702178747310289,9.29435117223888E-7,-6.52218378305985E-6,6.70046856246613E-7,1.00015628277534,10.005763053894,2,20,10,3,2.29910916835398,0.182399223737906,0.0403775237500668,172.74836730957,29.9998741149902,30.0051326751709,-780.248352050781,-780.248352050781,,,30.1154022216797,0,1,,,,,,1,1,1,29.9999370574951,0,30.0018555034291,,,,,,,,,,,,,,,,,,,,,,,,,,,,,,,,,
,3772422766.30353,30.0067663192749,-800.320434570312,,,5,,,,6.46999990567565,,,,,0.000585277287480534,9.61004589244827E-7,-0.246384002820978,0.00090263306972424,0.000585185801887631,9.60854373139555E-7,0.000585180391319577,8.02555377026605E-7,-2.51641529496506E-6,5.28342685372941E-7,1.00015633597501,10.005763053894,2,20,10,3,1.91517798554483,0.16159836530062,0.0403775237500668,172.74836730957,30.0019912719727,30.0077152252197,-800.320434570312,-800.320434570312,,,30.1278381347656,0,1,,,,,,1,1,1,30.0064792633057,0,30.0044860839844,,,,,,,,,,,,,,,,,,,,,,,,,,,,,,,,,
,3772422796.23859,30.0000762939453,-820.453247070312,,,5,,,,6.46999990567565,,,,,0.000429836533596191,1.02064460786882E-6,-0.908804140554448,0.00140034579790953,0.000429769378352419,1.02048514809263E-6,0.000429715316403682,8.23684773687529E-7,-6.81655466547433E-6,6.02439483328378E-7,1.0001562587917,10.005763053894,2,20,1,3,1.40781247185878,0.102441557141249,0.0403775237500668,172.74836730957,30.0000610351562,30.0008277893066,-820.453247070312,-820.453247070312,,,30.1154022216797,0,1,,,,,,1,1,1,30.0000820159912,0,30.000266620091,,,,,,,,,,,,,,,,,,,,,,,,,,,,,,,,,
,3772422818.69567,29.9995222091675,-840.221740722656,,,5,,,,6.46999990567565,,,,,0.000303573035054626,1.25135480884546E-6,-1.41944822217062,0.00246845362000518,0.000303525579423003,1.25115919254895E-6,0.000303432439272755,1.00121428021029E-6,-7.51878720645427E-6,7.50312794908048E-7,1.00015634804722,10.005763053894,2,20,1,3,0.994875295049287,0.0635065083643835,0.0403775237500668,172.74836730957,29.9989929199219,29.9999561309814,-840.221740722656,-840.221740722656,,,30.1154022216797,0,1,,,,,,1,1,1,29.9993762969971,0,29.9994705200195,,,,,,,,,,,,,,,,,,,,,,,,,,,,,,,,,
,3772422840.54224,30.0010871887207,-860.293701171875,,,5,,,,6.46999990567565,,,,,0.000205004655195167,1.31918772779998E-6,-2.15995244235709,0.00383726482518216,0.000204972616930004,1.31898156425612E-6,0.000204826984690092,1.05757339394307E-6,-7.72528536036028E-6,7.8819469883478E-7,1.00015630509891,10.005763053894,2,20,1,3,0.67234292267979,0.0342143163395012,0.0403775237500668,172.74836730957,30.0002956390381,30.0013275146484,-860.293701171875,-860.293701171875,,,30.1154022216797,0,1,,,,,,1,1,1,30.0010108947754,0,30.0007286071777,,,,,,,,,,,,,,,,,,,,,,,,,,,,,,,,,
,3772422862.18396,30.0032730102539,-880.3779296875,,,5,,,,6.46999990567565,,,,,0.000145257301926708,1.06469094946911E-6,-2.88755592321085,0.00448360614957895,0.000145234603124868,1.06452457429511E-6,0.000145050201932078,8.41052342873313E-7,-7.31634227611813E-6,6.52566874600221E-7,1.0001562905902,10.005763053894,2,20,1,3,0.476662003316775,0.0182014506891034,0.0403775237500668,172.74836730957,30.0023384094238,30.0032997131348,-880.3779296875,-880.3779296875,,,30.1402740478516,0,1,,,,,,1,1,1,30.0032520294189,0,30.0028180209073,,,,,,,,,,,,,,,,,,,,,,,,,,,,,,,,,
,3772422884.15619,30.0012264251709,-900.097900390625,,,5,,,,6.46999990567565,,,,,0.000108401792701101,1.29123848896146E-6,-4.15231734790782,0.00674894755372506,0.000108384850904963,1.29103668511025E-6,0.000108100349568898,1.0616922472787E-6,-7.84795060975758E-6,7.34564697197441E-7,1.00015631147707,10.005763053894,2,20,1,3,0.355933834000254,0.00573583956762887,0.0403775237500668,172.74836730957,30.0005187988281,30.0013027191162,-900.097900390625,-900.097900390625,,,30.1154022216797,0,1,,,,,,1,1,1,30.0012588500977,0,30.0009843652899,,,,,,,,,,,,,,,,,,,,,,,,,,,,,,,,,
,3772422905.7488,30.0080986022949,-919.927062988281,,,5,,,,6.46999990567565,,,,,7.7912404527748E-5,1.15659269742264E-6,-5.99004132721857,0.00929164705039266,7.79002300953791E-5,1.15641197062235E-6,7.7474898625647E-5,9.00653769605248E-7,-8.12932542458031E-6,7.25335393521182E-7,1.00015628236725,10.005763053894,2,20,1,3,0.255823751919926,-0.00407809525733355,0.0403775237500668,172.74836730957,30.0045680999756,30.0095558166504,-919.927062988281,-919.927062988281,,,30.1154022216797,0,1,,,,,,1,1,1,30.0073661804199,0,30.006721496582,,,,,,,,,,,,,,,,,,,,,,,,,,,,,,,,,
,3772422927.66947,30.0013999938965,-939.987060546875,,,5,,,,6.46999990567565,,,,,5.83945180147497E-5,1.31058112053844E-6,-8.12173873388092,0.0110449973999891,5.83853912437909E-5,1.31037628326746E-6,5.77997931713037E-5,1.13877533983013E-6,-8.24850410953728E-6,6.48287535854735E-7,1.00015631942793,10.005763053894,2,20,1,3,0.191491125127668,-0.0101822340424012,0.0403775237500668,172.74836730957,30.0006370544434,30.0017738342285,-939.987060546875,-939.987060546875,,,30.1154022216797,0,1,,,,,,1,1,1,30.0014514923096,0,30.0011001586914,,,,,,,,,,,,,,,,,,,,,,,,,,,,,,,,,
,3772422949.14653,29.993088722229,-959.986145019531,,,5,,,,6.46999990567565,,,,,4.57205244751382E-5,2.04086004564952E-6,-10.2956875143435,0.0252083409426387,4.57133802685169E-5,2.04054114454288E-6,4.49773259591515E-5,1.68443771128187E-6,-8.1702683639073E-6,1.15172816210418E-6,1.00015628261527,10.005763053894,2,20,1,3,0.149519785645468,-0.0136506967676163,0.0403775237500668,172.74836730957,29.9915409088135,30.0014762878418,-959.986145019531,-959.986145019531,,,30.1154022216797,0,1,,,,,,1,1,1,29.9926147460937,0,29.9955163435503,,,,,,,,,,,,,,,,,,,,,,,,,,,,,,,,,
,3772422971.2619,30.0057554244995,-980.070373535156,,,5,,,,6.46999990567565,,,,,3.75278665443386E-5,1.32426136902206E-6,-12.5733242163735,0.0216219166173995,3.75220022430721E-5,1.32405443299456E-6,3.66221578156817E-5,1.04900775846874E-6,-8.16812152532105E-6,8.07900281102149E-7,1.00015628966782,10.005763053894,2,20,1,3,0.122185507271101,-0.0160705788112792,0.0403775237500668,172.74836730957,30.0026321411133,30.0069217681885,-980.070373535156,-980.070373535156,,,30.1154022216797,0,1,,,,,,1,1,1,30.0052146911621,0,30.0046241760254,,,,,,,,,,,,,,,,,,,,,,,,,,,,,,,,,
,3772422992.7848,29.9953384399414,-999.911743164062,,,5,,,,6.46999990567565,,,,,3.19155793207345E-5,1.3559188645866E-6,-14.812344103186,0.0302935002442599,3.1910592619443E-5,1.35570700685138E-6,3.08501503868408E-5,9.51894758598289E-7,-8.15807222530905E-6,9.65317490248169E-7,1.0001562710336,10.005763053894,2,20,1,3,0.103299825985773,-0.0177143013267342,0.0403775237500668,172.74836730957,29.9949378967285,30.0009460449219,-999.911743164062,-999.911743164062,,,30.1154022216797,0,1,,,,,,1,1,1,29.9952297210693,0,29.9968910217285,,,,,,,,,,,,,,,,,,,,,,,,,,,,,,,,,