File: Experimental_Data/AC_Suceptibillity_FieldScans/HFCd_Up_56K.dat
[Header]
; MPMS3 Data File (default extension .dat)
; Copyright (c) 2007, Quantum Design, Inc. All rights reserved.
TITLE,HFCd_Up_56K
FILEOPENTIME,3762242357.63767,03/20/2019,11:19 am
BYAPP,SQUID AC,0.9.1.0
INFO,MPMS3 Measurement Release 1.1.16 Build 347, MultiVu Release 2.3.3.2,APPNAME
INFO,0,MOMENT_UNITS
INFO,SrM,SAMPLE_MATERIAL
INFO,MvsH,SAMPLE_COMMENT
INFO,,SAMPLE_MASS
INFO,,SAMPLE_VOLUME
INFO,,SAMPLE_MOLECULAR_WEIGHT
INFO,,SAMPLE_SIZE
INFO,,SAMPLE_SHAPE
INFO,Quartz,SAMPLE_HOLDER
INFO,Standard,SAMPLE_HOLDER_DETAIL
INFO,65.34,SAMPLE_OFFSET
DATATYPE,COMMENT,1
DATATYPE,TIME,2
STARTUPAXIS,X,2
STARTUPAXIS,Y1,5
FIELDGROUP, VSM,2,3,4,5,6,8,9,10,11,14,15
FIELDGROUP, DC, 2,3,4,14,56,57,58,59,60,61,62,63,64,65,66,67,68,69
FIELDGROUP, AC, 2,3,4,11,16,17,18,19,20,21,22,23,24,25,26,27,28,29,30
STARTUPGROUP, All
[Data]
Comment,Time Stamp (sec),Temperature (K),Magnetic Field (Oe),Moment (emu),M. Std. Err. (emu),Transport Action,Averaging Time (sec),Frequency (Hz),Peak Amplitude (mm),Center Position (mm),Lockin Signal' (V),Lockin Signal (V),Range,M. Quad. Signal (emu),AC Moment (emu),AC M. Std Err. (emu),AC Phase (deg),AC Phase Std. Err. (deg),AC Susceptibility (emu/Oe),AC Suscept. Std Err. (emu/Oe),AC X' (emu/Oe),AC X' Std Err. (emu/Oe),AC X'' (emu/Oe),AC X'' Std Err. (emu/Oe),AC Drive (Oe),AC Frequency (Hz),AC Averaging Time (sec),AC Cycles,AC Range,AC Measure Type,AC Signal' (V),AC Signal'' (V),AC Trim Coil Ratio,AC Trim Coil Phase,Min. Temperature (K),Max. Temperature (K),Min. Field (Oe),Max. Field (Oe),Mass (grams),Motor Lag (deg),Pressure (Torr),Measure Count,Measurement Number,SQUID Status (code),Motor Status (code),Measure Status (code),Motor Current (amps),Motor Temp. (C),Temp. Status (code),Field Status (code),Chamber Status (code),Chamber Temp (K),Redirection State,Average Temp (K),Rotation Angle (deg),Rotator state,DC Moment Fixed Ctr (emu),DC Moment Err Fixed Ctr (emu),DC Moment Free Ctr (emu),DC Moment Err Free Ctr (emu),DC Fixed Fit,DC Free Fit,DC Calculated Center (mm),DC Calculated Center Err (mm),DC Scan Length (mm),DC Scan Time (s),DC Number of Points,DC Squid Drift,DC Min V (V),DC Max V (V),DC Scans per Measure,Map 01,Map 02,Map 03,Map 04,Map 05,Map 06,Map 07,Map 08,Map 09,Map 10,Map 11,Map 12,Map 13,Map 14,Map 15,Map 16
,3762242516.04309,55.905725479126,1000.37322998047,,,5,,,,31.6299982368946,,,,,2.58532488092397E-5,4.34305482028657E-7,3.44200384953779,0.0107820066379726,2.58491846152177E-5,4.34237208143358E-7,2.58025548019741E-5,3.3408026644228E-7,1.55193780891058E-6,2.77402827148522E-7,1.00015722716529,10.005763053894,2,20,1,3,0.0839629363194946,0.0125763957847056,0.0413267537951469,172.859115600586,55.8920555114746,55.9155616760254,1000.37322998047,1000.37322998047,,,25.7633285522461,0,1,,,,,,1,1,1,55.903205871582,0,55.8992687722911,,,,,,,,,,,,,,,,,,,,,,,,,,,,,,,,,
,3762242554.13296,55.9041175842285,980.398254394531,,,5,,,,31.6299982368946,,,,,2.87008338202042E-5,4.09381128304249E-7,3.13954533206584,0.00999356411725938,2.86962977452608E-5,4.09316426926929E-7,2.8653227687153E-5,2.92390831064374E-7,1.57163844214521E-6,2.86439416389771E-7,1.00015807178277,10.005763053894,2,20,1,3,0.0932836041458394,0.0134673717523259,0.0413267537951469,172.859115600586,55.8945808410645,55.9391593933105,980.398254394531,980.398254394531,,,25.7975959777832,0,1,,,,,,1,1,1,55.9072418212891,0,55.9169206165132,,,,,,,,,,,,,,,,,,,,,,,,,,,,,,,,,
,3762242586.94064,55.9506797790527,960.253356933594,,,5,,,,31.6299982368946,,,,,3.03194281623281E-5,4.85556039935081E-7,2.96371477973136,0.00752299029718611,3.03146482343087E-5,4.8547949090164E-7,3.02741017458704E-5,4.30807375071614E-7,1.56737393450294E-6,2.23819886672345E-7,1.00015767717252,10.005763053894,2,20,1,3,0.0985878090754678,0.0139222544442302,0.0413267537951469,172.859115600586,55.9497756958008,55.951602935791,960.253356933594,960.253356933594,,,25.8133029937744,0,1,,,,,,1,1,1,55.951042175293,0,55.9506443023682,,,,,,,,,,,,,,,,,,,,,,,,,,,,,,,,,
,3762242608.2235,55.9712543487549,940.326965332031,,,5,,,,31.6299982368946,,,,,3.37171063280927E-5,4.57291156228282E-7,2.62895540652338,0.00689111245671776,3.37117860984093E-5,4.57219000155348E-7,3.36763050253982E-5,3.95425053712543E-7,1.54628644863775E-6,2.2953919273076E-7,1.00015781512341,10.005763053894,2,20,1,3,0.109724671283238,0.0148392502758826,0.0413267537951469,172.859115600586,55.9683456420898,55.9819259643555,940.326965332031,940.326965332031,,,25.812370300293,0,1,,,,,,1,1,1,55.9721908569336,0,55.9745483398438,,,,,,,,,,,,,,,,,,,,,,,,,,,,,,,,,
,3762242630.58747,56.0205554962158,920.400634765625,,,5,,,,31.6299982368946,,,,,4.0829701841799E-5,3.76513860329453E-7,1.45609883008404,0.00351294606998142,4.08232562522919E-5,3.76454421889348E-7,4.081007396677E-5,3.48947869069499E-7,1.03735908298484E-6,1.41256208472048E-7,1.00015789013663,10.005763053894,2,20,1,3,0.133211229043124,0.0152432559070906,0.0413267537951469,172.859115600586,56.0151100158691,56.022632598877,920.400634765625,920.400634765625,,,25.7793846130371,0,1,,,,,,1,1,1,56.0216484069824,0,56.0207042694092,,,,,,,,,,,,,,,,,,,,,,,,,,,,,,,,,
,3762242653.4428,56.017993927002,900.304321289063,,,5,,,,31.6299982368946,,,,,4.23694158127503E-5,4.19467226573919E-7,1.27693545879293,0.00404935655443258,4.23627418428768E-5,4.19401152695406E-7,4.23522215284909E-5,3.83525860767728E-7,9.44048752902364E-7,1.6972106824024E-7,1.00015754338797,10.005763053894,2,20,1,3,0.13828374939442,0.0153827780560116,0.0413267537951469,172.859115600586,56.0155563354492,56.0190505981445,900.304321289063,900.304321289063,,,25.7618064880371,0,1,,,,,,1,1,1,56.0176048278809,0,56.017041015625,,,,,,,,,,,,,,,,,,,,,,,,,,,,,,,,,
,3762242676.50817,56.0307464599609,880.438720703125,,,5,,,,31.6299982368946,,,,,4.4444528911555E-5,4.09217664280396E-7,1.62951957038738,0.00373815070779758,4.44375225465563E-5,4.09153154015802E-7,4.44195518684365E-5,3.74954926295148E-7,1.26365417855708E-6,1.63753188329507E-7,1.00015766776807,10.005763053894,2,20,1,3,0.144954665494225,0.0170254194183674,0.0413267537951469,172.859115600586,56.0261459350586,56.0308151245117,880.438720703125,880.438720703125,,,25.744026184082,0,1,,,,,,1,1,1,56.0307273864746,0,56.0291797637939,,,,,,,,,,,,,,,,,,,,,,,,,,,,,,,,,
,3762242697.09302,56.0190734863281,860.378723144531,,,5,,,,31.6299982368946,,,,,4.62965725056061E-5,3.27010331478908E-7,1.29963706474059,0.00294537733572881,4.6289277649575E-5,3.26958805131281E-7,4.62773698723985E-5,2.97810898685019E-7,1.04988714282269E-6,1.34947133638684E-7,1.00015759278177,10.005763053894,2,20,1,3,0.151094940309312,0.0168619915775021,0.0413267537951469,172.859115600586,56.0142669677734,56.0209770202637,860.378723144531,860.378723144531,,,25.7111377716064,0,1,,,,,,1,1,1,56.0179748535156,0,56.017134475708,,,,,,,,,,,,,,,,,,,,,,,,,,,,,,,,,
,3762242720.03271,56.0376625061035,840.100280761719,,,5,,,,31.6299982368946,,,,,4.65714424974886E-5,3.9343132903015E-7,1.55989891751746,0.00359942785306441,4.65640967944721E-5,3.93369273196243E-7,4.654684071984E-5,3.5679398731142E-7,1.26756825726087E-6,1.65642493682505E-7,1.00015775465481,10.005763053894,2,20,1,3,0.151913695122201,0.0176490363767784,0.0413267537951469,172.859115600586,56.0337409973145,56.0377922058105,840.100280761719,840.100280761719,,,25.6935081481934,0,1,,,,,,1,1,1,56.037727355957,0,56.0365207672119,,,,,,,,,,,,,,,,,,,,,,,,,,,,,,,,,
,3762242743.06797,56.0542964935303,820.441040039063,,,5,,,,31.6299982368946,,,,,4.8760128988933E-5,4.47542765095854E-7,1.45263960071474,0.00628574525570161,4.8752440129324E-5,4.47472193225738E-7,4.87367721282599E-5,3.26284121776966E-7,1.23590496454747E-6,3.06218934075746E-7,1.00015771230299,10.005763053894,2,20,1,3,0.159087689012857,0.0181773397350617,0.0413267537951469,172.859115600586,56.0473213195801,56.0543556213379,820.441040039063,820.441040039063,,,25.6596069335938,0,1,,,,,,1,1,1,56.054271697998,0,56.0520454406738,,,,,,,,,,,,,,,,,,,,,,,,,,,,,,,,,
,3762242763.65886,56.0349273681641,800.417541503906,,,5,,,,31.6299982368946,,,,,5.12077119625991E-5,3.3654958488143E-7,1.2808919914158,0.0043931323486934,5.11996472635498E-5,3.36496581710361E-7,5.11868534905337E-5,2.50462564748803E-7,1.14451284420964E-6,2.24718608847173E-7,1.00015751473849,10.005763053894,2,20,1,3,0.167130094971082,0.0185852992511174,0.0413267537951469,172.859115600586,56.0238265991211,56.038257598877,800.417541503906,800.417541503906,,,25.674654006958,0,1,,,,,,1,1,1,56.0330810546875,0,56.0303951263428,,,,,,,,,,,,,,,,,,,,,,,,,,,,,,,,,
,3762242786.65401,56.0131874084473,780.381958007812,,,5,,,,31.6299982368946,,,,,5.05084169805032E-5,3.58440318371611E-7,1.47289188871111,0.00414603598995666,5.05004604804701E-5,3.58383853913299E-7,5.04837750313133E-5,2.91335534218097E-7,1.29806291345039E-6,2.08716538030902E-7,1.00015755301947,10.005763053894,2,20,1,3,0.164785715762857,0.0188802711209832,0.0413267537951469,172.859115600586,56.0088691711426,56.0153770446777,780.381958007812,780.381958007812,,,25.5924453735352,0,1,,,,,,1,1,1,56.0122528076172,0,56.0116172790527,,,,,,,,,,,,,,,,,,,,,,,,,,,,,,,,,
,3762242809.69369,56.0256633758545,760.479858398438,,,5,,,,31.6299982368946,,,,,5.12771353799094E-5,4.41140622974043E-7,2.27912628085547,0.00586942849860194,5.12690520578432E-5,4.41071081614028E-7,5.12284956446763E-5,3.22842816172762E-7,2.03885578038704E-6,3.00526563021988E-7,1.00015766474592,10.005763053894,2,20,1,3,0.16700778630025,0.0215161466516566,0.0413267537951469,172.859115600586,56.022346496582,56.0259590148926,760.479858398438,760.479858398438,,,25.5906829833984,0,1,,,,,,1,1,1,56.0253677368164,0,56.0245491027832,,,,,,,,,,,,,,,,,,,,,,,,,,,,,,,,,
,3762242830.20084,56.0163822174072,740.432067871094,,,5,,,,31.6299982368946,,,,,5.36292730731229E-5,4.22910853013626E-7,1.93542957039139,0.00416136263508078,5.36208232667863E-5,4.22844219352553E-7,5.35902338170579E-5,3.6014515029247E-7,1.81094650417928E-6,2.21568735521696E-7,1.00015758442004,10.005763053894,2,20,1,3,0.174800821020009,0.0214511909138773,0.0413267537951469,172.859115600586,56.0118293762207,56.0180320739746,740.432067871094,740.432067871094,,,25.5412254333496,0,1,,,,,,1,1,1,56.0154800415039,0,56.0146743774414,,,,,,,,,,,,,,,,,,,,,,,,,,,,,,,,,
,3762242851.88222,56.0434379577637,720.408569335938,,,5,,,,31.6299982368946,,,,,5.48544099945026E-5,4.63686983915748E-7,2.18217764807305,0.00475175923711847,5.48457496241837E-5,4.63613777386078E-7,5.48059759763366E-5,3.84499227916573E-7,2.08836039032046E-6,2.59032967619465E-7,1.00015790412891,10.005763053894,2,20,1,3,0.178698306406877,0.0227071775365093,0.0413267537951469,172.859115600586,56.0401725769043,56.0451965332031,720.408569335938,720.408569335938,,,25.5077705383301,0,1,,,,,,1,1,1,56.0444374084473,0,56.0428958892822,,,,,,,,,,,,,,,,,,,,,,,,,,,,,,,,,
,3762242873.74237,56.0543975830078,700.324401855469,,,5,,,,31.6299982368946,,,,,5.77753701213638E-5,4.11670178692352E-7,1.94839635187092,0.00315207206380561,5.77662660333917E-5,4.11605308808967E-7,5.77328686994639E-5,3.70335730835906E-7,1.96401710049712E-6,1.79639574442717E-7,1.00015760215429,10.005763053894,2,20,1,3,0.188310279756522,0.0231441087539929,0.0413267537951469,172.859115600586,56.0468940734863,56.0547714233398,700.324401855469,700.324401855469,,,25.5058650970459,0,1,,,,,,1,1,1,56.0540237426758,0,56.051957321167,,,,,,,,,,,,,,,,,,,,,,,,,,,,,,,,,
,3762242896.7685,56.0283088684082,680.446594238281,,,5,,,,31.6299982368946,,,,,5.81751882722089E-5,3.80904722027886E-7,1.98932000780074,0.00344679016203938,5.81660238522324E-5,3.80844717566407E-7,5.8130968059764E-5,3.24706675810983E-7,2.01912932056609E-6,1.99018274492614E-7,1.00015755623936,10.005763053894,2,20,1,3,0.189597127054498,0.0234356651570412,0.0413267537951469,172.859115600586,56.0195655822754,56.0312881469727,680.446594238281,680.446594238281,,,25.4243392944336,0,1,,,,,,1,1,1,56.0271110534668,0,56.0253414154053,,,,,,,,,,,,,,,,,,,,,,,,,,,,,,,,,
,3762242919.79453,56.011682510376,660.483825683594,,,5,,,,31.6299982368946,,,,,5.84455102380126E-5,4.35602417113712E-7,2.20852053975081,0.00456393962562314,5.84363007390454E-5,4.35533777452697E-7,5.83928940593063E-5,3.45098842908261E-7,2.25192527469085E-6,2.65699943405329E-7,1.00015759893852,10.005763053894,2,20,1,3,0.190387067855985,0.0242690463991567,0.0413267537951469,172.859115600586,56.0094604492188,56.0130882263184,660.483825683594,660.483825683594,,,25.4382438659668,0,1,,,,,,1,1,1,56.0113525390625,0,56.0109214782715,,,,,,,,,,,,,,,,,,,,,,,,,,,,,,,,,
,3762242942.8994,56.0194835662842,640.411743164062,,,5,,,,31.6299982368946,,,,,6.14587184967803E-5,4.27722548840845E-7,2.00222340368677,0.00466295805500487,6.14490263680968E-5,4.27655096377051E-7,6.14115100148796E-5,3.1784506225077E-7,2.14692321227257E-6,2.86117804164768E-7,1.00015772631816,10.005763053894,2,20,1,3,0.200293645937231,0.0247949430074232,0.0413267537951469,172.859115600586,56.0166549682617,56.0196266174316,640.411743164062,640.411743164062,,,25.4049491882324,0,1,,,,,,1,1,1,56.0195541381836,0,56.0184509970925,,,,,,,,,,,,,,,,,,,,,,,,,,,,,,,,,
,3762242965.9558,56.0393390655518,620.376098632813,,,5,,,,31.6299982368946,,,,,6.57857055804074E-5,4.8327549258154E-7,1.80250329144342,0.00375874413404473,6.57753241713079E-5,4.83199228588443E-7,6.57427776894076E-5,4.16232305299628E-7,2.06892520932382E-6,2.45422416525924E-7,1.00015783136351,10.005763053894,2,20,1,3,0.214486919946813,0.0257885244440312,0.0413267537951469,172.859115600586,56.0358276367188,56.0400505065918,620.376098632813,620.376098632813,,,25.3713111877441,0,1,,,,,,1,1,1,56.0396957397461,0,56.0382700833407,,,,,,,,,,,,,,,,,,,,,,,,,,,,,,,,,
,3762242988.98297,56.0482292175293,600.498352050781,,,5,,,,31.6299982368946,,,,,6.96532501632399E-5,4.57592318082014E-7,1.58361992800626,0.00284228425023052,6.96422700668934E-5,4.57520183504974E-7,6.96156706615903E-5,4.13551647620349E-7,1.92462422490795E-6,1.95703227017133E-7,1.00015766425098,10.005763053894,2,20,1,3,0.227199704808205,0.0264320343160394,0.0413267537951469,172.859115600586,56.0410232543945,56.0487327575684,600.498352050781,600.498352050781,,,25.3692283630371,0,1,,,,,,1,1,1,56.0475959777832,0,56.0458202362061,,,,,,,,,,,,,,,,,,,,,,,,,,,,,,,,,
,3762243009.48181,56.0296401977539,580.401977539063,,,5,,,,31.6299982368946,,,,,7.12130570938745E-5,4.88852257355302E-7,1.7265534100956,0.00286704275631596,7.1201834463471E-5,4.8877521799721E-7,7.1169509124053E-5,4.45397947257892E-7,2.14527434256195E-6,2.0130047766132E-7,1.00015761715254,10.005763053894,2,20,1,3,0.232219913500842,0.027598350118139,0.0413267537951469,172.859115600586,56.0236396789551,56.0308685302734,580.401977539063,580.401977539063,,,25.3200664520264,0,1,,,,,,1,1,1,56.028995513916,0,56.0275009155273,,,,,,,,,,,,,,,,,,,,,,,,,,,,,,,,,
,3762243032.48625,56.0208015441895,560.366333007812,,,5,,,,31.6299982368946,,,,,7.44135155119023E-5,4.71953999626099E-7,1.63570296935702,0.00321120301745847,7.44017929831709E-5,4.71879651649358E-7,7.43714758920676E-5,4.07877637380509E-7,2.12376381601627E-6,2.37289356199585E-7,1.00015755707304,10.005763053894,2,20,1,3,0.242702241469242,0.0284486681593837,0.0413267537951469,172.859115600586,56.0163230895996,56.0219535827637,560.366333007812,560.366333007812,,,25.2707710266113,0,1,,,,,,1,1,1,56.0201072692871,0,56.0192687988281,,,,,,,,,,,,,,,,,,,,,,,,,,,,,,,,,
,3762243054.1493,56.0343494415283,540.1728515625,,,5,,,,31.6299982368946,,,,,7.93050373346927E-5,4.28987774876099E-7,1.53755520361208,0.00220830162130947,7.92925314875937E-5,4.28920126518565E-7,7.92639823893677E-5,3.92562951981767E-7,2.12759147607145E-6,1.72820148316284E-7,1.00015771784384,10.005763053894,2,20,1,3,0.258708164903887,0.0298700003632323,0.0413267537951469,172.859115600586,56.0303611755371,56.0348472595215,540.1728515625,540.1728515625,,,25.2529354095459,0,1,,,,,,1,1,1,56.0338172912598,0,56.0329166412354,,,,,,,,,,,,,,,,,,,,,,,,,,,,,,,,,
,3762243076.01016,56.0197505950928,520.513671875,,,5,,,,31.6299982368946,,,,,8.41118222173556E-5,6.09146612042241E-7,1.18982531686123,0.00284597694940194,8.40985759357455E-5,6.09050681085662E-7,8.40804431643988E-5,5.61166855875484E-7,1.74629656664266E-6,2.36716057752179E-7,1.00015750898826,10.005763053894,2,20,1,3,0.274576510005083,0.0300088376926995,0.0413267537951469,172.859115600586,56.0136108398438,56.0218658447266,520.513671875,520.513671875,,,25.2190055847168,0,1,,,,,,1,1,1,56.0189094543457,0,56.0176616668701,,,,,,,,,,,,,,,,,,,,,,,,,,,,,,,,,
,3762243097.68542,56.0326919555664,500.429473876953,,,5,,,,31.6299982368946,,,,,8.82779093912422E-5,5.06014883207219E-7,1.76196681953477,0.00233089648109123,8.82639851490135E-5,5.05935068519109E-7,8.82222531203452E-5,4.63612365403247E-7,2.71387707072497E-6,2.02568181614589E-7,1.0001577567816,10.005763053894,2,20,1,3,0.287848090168226,0.0343650290233829,0.0413267537951469,172.859115600586,56.0305137634277,56.0327568054199,500.429473876953,500.429473876953,,,25.2018184661865,0,1,,,,,,1,1,1,56.0327224731445,0,56.0319957733154,,,,,,,,,,,,,,,,,,,,,,,,,,,,,,,,,
,3762243119.62189,56.0211448669434,480.369537353516,,,5,,,,31.6299982368946,,,,,9.59354686222249E-5,5.31721647523186E-7,1.84955371446781,0.00276665455043267,9.59203541852312E-5,5.31637875864434E-7,9.58703816138555E-5,4.61925540161623E-7,3.0958482252723E-6,2.63179836613749E-7,1.00015757278132,10.005763053894,2,20,1,3,0.312760301184687,0.0378174187078144,0.0413267537951469,172.859115600586,56.0149116516113,56.0240058898926,480.369537353516,480.369537353516,,,25.1523284912109,0,1,,,,,,1,1,1,56.0196838378906,0,56.0188861846924,,,,,,,,,,,,,,,,,,,,,,,,,,,,,,,,,
,3762243142.60189,56.0082359313965,460.188201904297,,,5,,,,31.6299982368946,,,,,0.000102709962436068,5.15477231865928E-7,1.45586703375195,0.00260999027026193,0.000102693782412589,5.153960281198E-7,0.000102660631999331,4.41093467761081E-7,2.60913466539257E-6,2.6658885666916E-7,1.00015755601847,10.005763053894,2,20,1,3,0.335116831089243,0.0381789542417399,0.0413267537951469,172.859115600586,56.0050315856934,56.0096397399902,460.188201904297,460.188201904297,,,25.134635925293,0,1,,,,,,1,1,1,56.0074729919434,0,56.0069337324663,,,,,,,,,,,,,,,,,,,,,,,,,,,,,,,,,
,3762243165.69552,56.0200824737549,440.237518310547,,,5,,,,31.6299982368946,,,,,0.00011499978374288,5.11900314386008E-7,1.33581015991334,0.00207413588517919,0.000114981644960612,5.11819572944213E-7,0.000114950396899911,4.53779460288236E-7,2.68047204819178E-6,2.36735034731478E-7,1.00015775372038,10.005763053894,2,20,1,3,0.37530486953804,0.0419529406935582,0.0413267537951469,172.859115600586,56.0184478759766,56.0207176208496,440.237518310547,440.237518310547,,,25.0856418609619,0,1,,,,,,1,1,1,56.0204620361328,0,56.0198932647705,,,,,,,,,,,,,,,,,,,,,,,,,,,,,,,,,
,3762243187.3604,56.0130920410156,420.177642822266,,,5,,,,31.6299982368946,,,,,0.000134957582311912,5.11152049100635E-7,1.13467913349954,0.00156729632153664,0.000134936323275528,5.11071530467862E-7,0.000134909863536611,4.66119009465007E-7,2.67208900500059E-6,2.0958811576548E-7,1.00015754865605,10.005763053894,2,20,1,3,0.440608571432691,0.0476778498692264,0.0413267537951469,172.859115600586,56.0104789733887,56.0140533447266,420.177642822266,420.177642822266,,,25.0521411895752,0,1,,,,,,1,1,1,56.0124855041504,0,56.012024307251,,,,,,,,,,,,,,,,,,,,,,,,,,,,,,,,,
,3762243209.19437,56.0501441955566,400.093414306641,,,5,,,,31.6299982368946,,,,,0.000192592308867817,4.31349690255065E-7,0.777967169211117,0.00128839013483135,0.000192561909765739,4.3128160527627E-7,0.000192544159249373,3.53088590717213E-7,2.6145423271451E-6,2.47653528452571E-7,1.00015786664203,10.005763053894,2,20,1,3,0.629186461267626,0.0641095920332394,0.0413267537951469,172.859115600586,56.0420913696289,56.0514068603516,400.093414306641,400.093414306641,,,25.0346336364746,0,1,,,,,,1,1,1,56.0511169433594,0,56.0483591897147,,,,,,,,,,,,,,,,,,,,,,,,,,,,,,,,,
,3762243237.42079,56.026782989502,380.239929199219,,,5,,,,31.6299982368946,,,,,0.000312785891906257,2.60592218623671E-7,0.485842226886989,0.000649573585104727,0.000312736640130891,2.60551185349007E-7,0.000312725396892458,1.63110352385878E-7,2.65183310435559E-6,2.03179558842241E-7,1.00015748642482,10.005763053894,2,20,1,3,1.02237013182028,0.0988863159005441,0.0413267537951469,172.859115600586,56.0178375244141,56.0301132202148,380.239929199219,380.239929199219,,,24.9850482940674,0,1,,,,,,1,1,1,56.0255928039551,0,56.0227948702299,,,,,,,,,,,,,,,,,,,,,,,,,,,,,,,,,
,3762243263.04849,56.0113716125488,360.167877197266,,,5,,,,31.6299982368946,,,,,0.000439782729322548,1.88061239161132E-7,0.342941397230847,0.00040259733830423,0.000439713437206395,1.88031608253961E-7,0.000439705560711311,6.31526695924451E-8,2.63186994618263E-6,1.77109079456471E-7,1.00015758471379,10.005763053894,2,20,1,3,1.43781564969464,0.135419501794609,0.0413267537951469,172.859115600586,56.0071029663086,56.0122718811035,360.167877197266,360.167877197266,,,24.9350204467773,0,1,,,,,,1,1,1,56.010856628418,0,56.0095667521159,,,,,,,,,,,,,,,,,,,,,,,,,,,,,,,,,
,3762243291.51025,56.0404739379883,340.083648681641,,,5,,,,31.6299982368946,,,,,0.000525276755028099,2.42027899763805E-7,0.287092876423236,0.00038431813466652,0.000525193895967451,2.41989721405E-7,0.000525187302887627,1.33429197842326E-7,2.63158642070979E-6,2.01880346811727E-7,1.00015776851423,10.005763053894,2,20,1,3,1.71748720029668,0.160034129515426,0.0413267537951469,172.859115600586,56.0326728820801,56.0415077209473,340.083648681641,340.083648681641,,,24.9174823760986,0,1,,,,,,1,1,1,56.0411338806152,0,56.0385526021322,,,,,,,,,,,,,,,,,,,,,,,,,,,,,,,,,
,3762243321.29656,56.0188102722168,320.327301025391,,,5,,,,31.6299982368946,,,,,0.000634846860679255,2.32367698047065E-7,0.119686228410528,0.000314076473435892,0.00063474690964457,2.32331113804021E-7,0.000634745524760117,1.19280591569062E-7,1.32593375996761E-6,1.99373736776816E-7,1.00015746596504,10.005763053894,2,20,10,3,2.0763055216846,0.18730687075156,0.0413267537951469,172.859115600586,56.0105743408203,56.0225639343262,320.327301025391,320.327301025391,,,24.8677635192871,0,1,,,,,,1,1,1,56.0171508789063,0,56.0153196122911,,,,,,,,,,,,,,,,,,,,,,,,,,,,,,,,,
,3762243350.18003,56.0405673980713,300.158111572266,,,5,,,,31.6299982368946,,,,,0.000690864599514101,2.62031329282236E-7,0.177611082446147,0.000325518955268437,0.00069075553780478,2.61989964324924E-7,0.000690752218945113,1.34410413420254E-7,2.14126840282099E-6,2.24883485768011E-7,1.0001578875642,10.005763053894,2,20,10,3,2.25931092346706,0.206069873267845,0.0413267537951469,172.859115600586,56.0352325439453,56.0437278747559,300.158111572266,300.158111572266,,,24.8339824676514,0,1,,,,,,1,1,1,56.0424995422363,0,56.0413528442383,,,,,,,,,,,,,,,,,,,,,,,,,,,,,,,,,
,3762243371.78763,56.0451316833496,280.110321044922,,,5,,,,31.6299982368946,,,,,0.000749824365538966,2.45435835481188E-7,0.160014568008204,0.000258845047618243,0.000749706183879261,2.45397151736405E-7,0.000749703260167215,1.50199545852166E-7,2.09376251131344E-6,1.9406148125309E-7,1.00015763730145,10.005763053894,2,20,10,3,2.45219701984183,0.222850566592482,0.0413267537951469,172.859115600586,56.0367698669434,56.0474739074707,280.110321044922,280.110321044922,,,24.7850227355957,0,1,,,,,,1,1,1,56.0434608459473,0,56.0421054840088,,,,,,,,,,,,,,,,,,,,,,,,,,,,,,,,,
,3762243393.68076,56.024881362915,260.135406494141,,,5,,,,31.6299982368946,,,,,0.000788883740795766,2.20086198305119E-7,0.422066269871199,0.000242819414696805,0.000788759499980277,2.20051537065013E-7,0.000788738099246179,1.0821381102831E-7,5.81030177027294E-6,1.91604932262726E-7,1.00015751419221,10.005763053894,2,20,10,3,2.57883981652688,0.246201335938689,0.0413267537951469,172.859115600586,56.0187835693359,56.0271148681641,260.135406494141,260.135406494141,,,24.7520980834961,0,1,,,,,,1,1,1,56.0238380432129,0,56.0227481842041,,,,,,,,,,,,,,,,,,,,,,,,,,,,,,,,,
,3762243414.31845,56.0237503051758,240.196899414062,,,5,,,,31.6299982368946,,,,,0.000829016429623173,2.64273821001828E-7,2.04171728230287,0.000199763400534948,0.00082888572098462,2.64232153707774E-7,0.000828359504255972,2.06296771345858E-7,2.95308340721016E-5,1.65106853841153E-7,1.00015769198967,10.005763053894,2,20,10,3,2.70164267269484,0.335162861250063,0.0413267537951469,172.859115600586,56.0206298828125,56.0243148803711,240.196899414062,240.196899414062,,,24.7338256835938,0,1,,,,,,1,1,1,56.0231857299805,0,56.0225036621094,,,,,,,,,,,,,,,,,,,,,,,,,,,,,,,,,
,3762243437.25352,56.0127334594727,220.161285400391,,,5,,,,31.6299982368946,,,,,0.000727650558282647,2.01500722104746E-7,0.576346201670227,0.000153617786828971,0.000727535947908088,2.01468984242428E-7,0.000727499139892427,1.67746891912823E-7,7.31826169934754E-6,1.11582847540577E-7,1.00015753224963,10.005763053894,2,20,10,3,2.37805740777285,0.233393640627763,0.0413267537951469,172.859115600586,56.009204864502,56.01416015625,220.161285400391,220.161285400391,,,24.7165851593018,0,1,,,,,,1,1,1,56.01220703125,0,56.01145362854,,,,,,,,,,,,,,,,,,,,,,,,,,,,,,,,,
,3762243457.79104,56.0058517456055,200.18635559082,,,5,,,,31.6299982368946,,,,,0.000675578403953178,2.40901752896635E-7,0.183408316415741,0.000125133371164104,0.000675471897921659,2.40863774344424E-7,0.000675468437175841,2.25633767543492E-7,2.16223521278868E-6,8.42897427660745E-8,1.00015767648047,10.005763053894,2,20,10,3,2.20931600904338,0.20149755531074,0.0413267537951469,172.859115600586,56.0040969848633,56.0061225891113,200.18635559082,200.18635559082,,,24.6841659545898,0,1,,,,,,1,1,1,56.0055809020996,0,56.0051383972168,,,,,,,,,,,,,,,,,,,,,,,,,,,,,,,,,
,3762243480.82543,56.0143852233887,180.126434326172,,,5,,,,31.6299982368946,,,,,0.000645220471048045,2.17379995102912E-7,0.110105564800484,0.000155551953505526,0.000645118721247565,2.17345714772199E-7,0.000645117530052764,1.92842670663398E-7,1.23972687082556E-6,1.00253997931486E-7,1.00015772259761,10.005763053894,2,20,10,3,2.11028509671015,0.189698004787552,0.0413267537951469,172.859115600586,56.0132217407227,56.014705657959,180.126434326172,180.126434326172,,,24.6508769989014,0,1,,,,,,1,1,1,56.0146751403809,0,56.0140106201172,,,,,,,,,,,,,,,,,,,,,,,,,,,,,,,,,
,3762243501.34003,56.0544662475586,160.248657226562,,,5,,,,31.6299982368946,,,,,0.000635777127004997,2.00683364598629E-7,0.184547580337648,0.000151839892422751,0.000635676722109787,2.00651671743795E-7,0.000635673424666133,1.75971628552186E-7,2.04748760020605E-6,9.64109916880382E-8,1.00015794961766,10.005763053894,2,20,10,3,2.07915757632789,0.1895788041921,0.0413267537951469,172.859115600586,56.0484313964844,56.0580978393555,160.248657226562,160.248657226562,,,24.6180591583252,0,1,,,,,,1,1,1,56.0561752319336,0,56.0555225372314,,,,,,,,,,,,,,,,,,,,,,,,,,,,,,,,,
,3762243523.27463,56.0629940032959,140.164443969727,,,5,,,,31.6299982368946,,,,,0.000649227809656738,2.38345101405226E-7,0.83946050230495,0.000180728651509456,0.000649125548770436,2.38307559296042E-7,0.000649055878706824,2.07677058609519E-7,9.5102251619952E-6,1.16879134771502E-7,1.00015753637566,10.005763053894,2,20,10,3,2.12079687128744,0.217799161646554,0.0413267537951469,172.859115600586,56.0514640808105,56.0644760131836,140.164443969727,140.164443969727,,,24.6310443878174,0,1,,,,,,1,1,1,56.0619812011719,0,56.0589393615723,,,,,,,,,,,,,,,,,,,,,,,,,,,,,,,,,
,3762243545.14884,56.0473499298096,120.128807067871,,,5,,,,31.6299982368946,,,,,0.000725922432580372,2.1131159827713E-7,2.24985033713813,0.000167063156859595,0.000725808111091677,2.11278319988143E-7,0.00072524861377167,1.73493546705545E-7,2.84931982890496E-5,1.20575775960774E-7,1.00015750924652,10.005763053894,2,20,10,3,2.36462364678961,0.301770392872588,0.0413267537951469,172.859115600586,56.0388336181641,56.0492095947266,120.128807067871,120.128807067871,,,24.5520439147949,0,1,,,,,,1,1,1,56.0460472106934,0,56.0444065440785,,,,,,,,,,,,,,,,,,,,,,,,,,,,,,,,,
,3762243567.99386,56.0259437561035,100.275314331055,,,5,,,,31.6299982368946,,,,,0.000806693341960301,2.82997318923217E-7,1.26989884116333,0.000110795042626872,0.000806566349680036,2.8295276856812E-7,0.000806368249297691,2.6908300339125E-7,1.7875205194786E-5,8.75020372694748E-8,1.00015744802683,10.005763053894,2,20,10,3,2.63308291009532,0.29030155868338,0.0413267537951469,172.859115600586,56.0190849304199,56.0290870666504,100.275314331055,100.275314331055,,,24.5495777130127,0,1,,,,,,1,1,1,56.0247573852539,0,56.0237464904785,,,,,,,,,,,,,,,,,,,,,,,,,,,,,,,,,
,3762243588.45671,56.0262641906738,80.2518310546875,,,5,,,,31.6299982368946,,,,,0.000783512871888271,2.85764434587208E-7,0.688573151325182,0.000221582525561396,0.000783389337472458,2.85719378859659E-7,0.000783332766018838,2.27097621373487E-7,9.41444352117159E-6,1.73384641253064E-7,1.0001576922354,10.005763053894,2,20,10,3,2.56015397743957,0.25594302750638,0.0413267537951469,172.859115600586,56.0224914550781,56.0264549255371,80.2518310546875,80.2518310546875,,,24.5015869140625,0,1,,,,,,1,1,1,56.0264511108398,0,56.0250015258789,,,,,,,,,,,,,,,,,,,,,,,,,,,,,,,,,
,3762243610.26974,56.0146350860596,60.1919059753418,,,5,,,,31.6299982368946,,,,,0.000725939027335833,2.69430293251515E-7,0.810132281333591,0.000234683895348559,0.000725824623398671,2.69387832541761E-7,0.000725752069446044,2.08837307370648E-7,1.02624376542577E-5,1.70166927961121E-7,1.00015761925605,10.005763053894,2,20,10,3,2.37152497539991,0.242116978221746,0.0413267537951469,172.859115600586,56.0106239318848,56.0158996582031,60.1919059753418,60.1919059753418,,,24.4686088562012,0,1,,,,,,1,1,1,56.0141105651855,0,56.0130622170188,,,,,,,,,,,,,,,,,,,,,,,,,,,,,,,,,
,3762243631.99649,56.0523567199707,40.1198425292969,,,5,,,,31.6299982368946,,,,,0.000659558196658924,1.69579416577388E-7,0.393915499184884,7.43632726580435E-5,0.000659454024109371,1.69552632708631E-7,0.00065943843886236,1.62426016445149E-7,4.5337914393945E-6,4.86403581420643E-8,1.00015796787304,10.005763053894,2,20,10,3,2.15621389575594,0.204273109826304,0.0413267537951469,172.859115600586,56.0453834533691,56.0561790466309,40.1198425292969,40.1198425292969,,,24.4667110443115,0,1,,,,,,1,1,1,56.0546188354492,0,56.0534511912953,,,,,,,,,,,,,,,,,,,,,,,,,,,,,,,,,
,3762243653.61004,56.0381832122803,20.1934909820557,,,5,,,,31.6299982368946,,,,,0.000604757804560909,1.04251545591686E-7,0.0503445777531093,2.57854811648531E-5,0.000604662610012297,1.04235135420953E-7,0.00060466237658952,1.03083212606073E-7,5.3130405285822E-7,1.54536317749444E-8,1.00015743415756,10.005763053894,2,20,10,3,1.97815182370416,0.175399985391829,0.0413267537951469,172.859115600586,56.0277481079102,56.0414047241211,20.1934909820557,20.1934909820557,,,24.4182548522949,0,1,,,,,,1,1,1,56.0362777709961,0,56.034349822998,,,,,,,,,,,,,,,,,,,,,,,,,,,,,,,,,
,3762243675.52814,56.0151863098145,0.206427752971649,,,5,,,,31.6299982368946,,,,,0.000598593834985991,1.13496487208492E-7,0.0324545211793588,3.59515170666918E-5,0.000598499553529157,1.13478610956626E-7,0.000598499457514183,1.11439114623324E-7,3.39013022638204E-7,2.14177234227844E-8,1.00015752970287,10.005763053894,2,20,10,3,1.95804631010735,0.172959016756781,0.0413267537951469,172.859115600586,56.0099868774414,56.0168724060059,0.206427752971649,0.206427752971649,,,24.3854904174805,0,1,,,,,,1,1,1,56.0143890380859,0,56.0128635059703,,,,,,,,,,,,,,,,,,,,,,,,,,,,,,,,,