File: Experimental_Data/AC_Suceptibillity_FieldScans/HFCd_Up_5K.dat
[Header]
; MPMS3 Data File (default extension .dat)
; Copyright (c) 2007, Quantum Design, Inc. All rights reserved.
TITLE,HFCd_Up_5K
FILEOPENTIME,3772375655.64454,07/15/2019,6:07 pm
BYAPP,SQUID AC,0.9.1.0
INFO,MPMS3 Measurement Release 1.1.16 Build 347, MultiVu Release 2.3.3.2,APPNAME
INFO,0,MOMENT_UNITS
INFO,Cu2OSeO3,SAMPLE_MATERIAL
INFO,,SAMPLE_COMMENT
INFO,,SAMPLE_MASS
INFO,,SAMPLE_VOLUME
INFO,,SAMPLE_MOLECULAR_WEIGHT
INFO,,SAMPLE_SIZE
INFO,,SAMPLE_SHAPE
INFO,Quartz,SAMPLE_HOLDER
INFO,Standard,SAMPLE_HOLDER_DETAIL
INFO,64.77,SAMPLE_OFFSET
DATATYPE,COMMENT,1
DATATYPE,TIME,2
STARTUPAXIS,X,2
STARTUPAXIS,Y1,5
FIELDGROUP, VSM,2,3,4,5,6,8,9,10,11,14,15
FIELDGROUP, DC, 2,3,4,14,56,57,58,59,60,61,62,63,64,65,66,67,68,69
FIELDGROUP, AC, 2,3,4,11,16,17,18,19,20,21,22,23,24,25,26,27,28,29,30
STARTUPGROUP, All
[Data]
Comment,Time Stamp (sec),Temperature (K),Magnetic Field (Oe),Moment (emu),M. Std. Err. (emu),Transport Action,Averaging Time (sec),Frequency (Hz),Peak Amplitude (mm),Center Position (mm),Lockin Signal' (V),Lockin Signal (V),Range,M. Quad. Signal (emu),AC Moment (emu),AC M. Std Err. (emu),AC Phase (deg),AC Phase Std. Err. (deg),AC Susceptibility (emu/Oe),AC Suscept. Std Err. (emu/Oe),AC X' (emu/Oe),AC X' Std Err. (emu/Oe),AC X'' (emu/Oe),AC X'' Std Err. (emu/Oe),AC Drive (Oe),AC Frequency (Hz),AC Averaging Time (sec),AC Cycles,AC Range,AC Measure Type,AC Signal' (V),AC Signal'' (V),AC Trim Coil Ratio,AC Trim Coil Phase,Min. Temperature (K),Max. Temperature (K),Min. Field (Oe),Max. Field (Oe),Mass (grams),Motor Lag (deg),Pressure (Torr),Measure Count,Measurement Number,SQUID Status (code),Motor Status (code),Measure Status (code),Motor Current (amps),Motor Temp. (C),Temp. Status (code),Field Status (code),Chamber Status (code),Chamber Temp (K),Redirection State,Average Temp (K),Rotation Angle (deg),Rotator state,DC Moment Fixed Ctr (emu),DC Moment Err Fixed Ctr (emu),DC Moment Free Ctr (emu),DC Moment Err Free Ctr (emu),DC Fixed Fit,DC Free Fit,DC Calculated Center (mm),DC Calculated Center Err (mm),DC Scan Length (mm),DC Scan Time (s),DC Number of Points,DC Squid Drift,DC Min V (V),DC Max V (V),DC Scans per Measure,Map 01,Map 02,Map 03,Map 04,Map 05,Map 06,Map 07,Map 08,Map 09,Map 10,Map 11,Map 12,Map 13,Map 14,Map 15,Map 16
,3772375874.00168,4.99987363815308,1000.25183105469,,,5,,,,6.47999998182058,,,,,0.000122598869228192,5.21197739991323E-7,0.193388767218818,0.00308242870453908,0.000122579214724776,5.21114183896349E-7,0.000122578516486501,3.5892163939734E-7,4.1373724929191E-7,3.77803188750815E-7,1.00016034124105,10.005763053894,2,20,1,3,0.400895459118094,0.0370387014728711,0.0403775237500668,172.74836730957,4.99931716918945,5.00068378448486,1000.25183105469,1000.25183105469,,,12.2643480300903,0,1,,,,,,1,1,1,4.99977731704712,0,4.99999109903971,,,,,,,,,,,,,,,,,,,,,,,,,,,,,,,,,
,3772375898.83485,4.99996495246887,980.434692382813,,,5,,,,6.47999998182058,,,,,0.000169020406021079,5.97375185048351E-7,-0.059411685403993,0.00196377211059002,0.000168993289368912,5.97279345643585E-7,0.000168993198516198,4.96631546092622E-7,-1.75234099779401E-7,3.31812784802034E-7,1.00016045993464,10.005763053894,2,20,1,3,0.552913454583616,0.0486124395515076,0.0403775237500668,172.74836730957,4.99911403656006,5.00185108184814,980.434692382813,980.434692382813,,,12.2841825485229,0,1,,,,,,1,1,1,5.00017261505127,0,5.00020027160645,,,,,,,,,,,,,,,,,,,,,,,,,,,,,,,,,
,3772375923.34804,4.99979043006897,960.289794921875,,,5,,,,6.47999998182058,,,,,0.000235580655685848,4.16128345201833E-7,0.0643870283517431,0.00140365210750071,0.000235542862378769,4.16061587316775E-7,0.000235542713651226,2.52596623871028E-7,2.64694919850564E-7,3.30608817259178E-7,1.0001604519309,10.005763053894,2,20,1,3,0.770503683213944,0.0694043913883964,0.0403775237500668,172.74836730957,4.99863052368164,5.00085973739624,960.289794921875,960.289794921875,,,12.2860774993896,0,1,,,,,,1,1,1,4.99975633621216,0,5.00000961621602,,,,,,,,,,,,,,,,,,,,,,,,,,,,,,,,,
,3772375946.6925,4.99988174438477,940.448425292969,,,5,,,,6.47999998182058,,,,,0.000315145297055057,2.46685417789872E-7,0.0232018505131411,0.000667457562075463,0.000315094738176362,2.4664584195539E-7,0.000315094712341204,1.28860625030779E-7,1.27597196075641E-7,2.10307181690403E-7,1.00016045611865,10.005763053894,2,20,1,3,1.03080024745391,0.0920820996165705,0.0403775237500668,172.74836730957,4.99934101104736,5.0008864402771,940.448425292969,940.448425292969,,,12.2854785919189,0,1,,,,,,1,1,1,4.99987459182739,0,5.00004801383385,,,,,,,,,,,,,,,,,,,,,,,,,,,,,,,,,
,3772375972.13005,4.99988508224487,920.44921875,,,5,,,,6.47999998182058,,,,,0.000413483668042197,3.25759803567018E-7,0.020016088779311,0.000656758730328686,0.000413417332638335,3.25707541749195E-7,0.000413417307410972,1.79917590711165E-7,1.44425958334117E-7,2.7150518099107E-7,1.00016045627173,10.005763053894,2,20,1,3,1.35246111732561,0.120711375656602,0.0403775237500668,172.74836730957,4.99936532974243,5.00093364715576,920.44921875,920.44921875,,,12.297550201416,0,1,,,,,,1,1,1,4.99985313415527,0,5.00001307328542,,,,,,,,,,,,,,,,,,,,,,,,,,,,,,,,,
,3772375995.38949,4.99988627433777,900.352844238281,,,5,,,,6.47999998182058,,,,,0.000498122366151466,4.15535949009897E-7,0.0200734308532082,0.000521932034272754,0.000498042452089214,4.15469284334801E-7,0.000498042421523516,3.2414945945292E-7,1.74487904770943E-7,2.59888157025386E-7,1.0001604563264,10.005763053894,2,20,1,3,1.62930736987995,0.145387169040119,0.0403775237500668,172.74836730957,4.99941158294678,5.00129079818726,900.352844238281,900.352844238281,,,12.3024101257324,0,1,,,,,,1,1,1,4.99972915649414,0,5.00006396953876,,,,,,,,,,,,,,,,,,,,,,,,,,,,,,,,,
,3772376020.86148,5.00016832351685,880.402282714844,,,5,,,,6.47999998182058,,,,,0.000551373472974383,5.46399198831682E-7,0.111172153132381,0.000559594838205263,0.000551285008676214,5.46311532623542E-7,0.000551283970926028,4.50976946121348E-7,1.06966871676529E-6,3.0834410119953E-7,1.00016046926141,10.005763053894,2,20,1,3,1.80323064154372,0.163758373172624,0.0403775237500668,172.74836730957,4.99930381774902,5.00106000900269,880.402282714844,880.402282714844,,,12.3185214996338,0,1,,,,,,1,1,1,5.00013732910156,0,5.00009087721507,,,,,,,,,,,,,,,,,,,,,,,,,,,,,,,,,
,3772376045.06821,5.0001392364502,860.330139160156,,,5,,,,6.47999998182058,,,,,0.000590857703097535,3.31129643797751E-7,0.0800655998724311,0.000409317433748805,0.000590762904598618,3.31076516635298E-7,0.000590762327792564,2.26167120396999E-7,8.25536738428694E-7,2.41785221878203E-7,1.00016046792745,10.005763053894,2,20,1,3,1.93245887094599,0.174394578001704,0.0403775237500668,172.74836730957,4.99896860122681,5.00080156326294,860.330139160156,860.330139160156,,,12.3307332992554,0,1,,,,,,1,1,1,5.00026750564575,0,4.99998100598653,,,,,,,,,,,,,,,,,,,,,,,,,,,,,,,,,
,3772376069.59629,4.99979877471924,840.221740722656,,,5,,,,6.47999998182058,,,,,0.000622179104262498,4.04390898600878E-7,0.088812018909918,0.000372696226452817,0.000622079290201148,4.04326023554954E-7,0.000622078542868627,3.31318448090584E-7,9.64261172991973E-7,2.31749043749069E-7,1.00016045231359,10.005763053894,2,20,1,3,2.03487338922499,0.183906083129554,0.0403775237500668,172.74836730957,4.99929809570313,5.00122833251953,840.221740722656,840.221740722656,,,12.348427772522,0,1,,,,,,1,1,1,4.99964237213135,0,5.00000520547231,,,,,,,,,,,,,,,,,,,,,,,,,,,,,,,,,
,3772376095.18417,4.99985337257385,820.343933105469,,,5,,,,6.47999998182058,,,,,0.000648413096166645,4.15519899130703E-7,0.0955280432344425,0.000338833805761325,0.00064830907185284,4.15453237657277E-7,0.000648308170762152,3.52708812743611E-7,1.0809115239972E-6,2.19540169656731E-7,1.0001604548175,10.005763053894,2,20,1,3,2.12065363161983,0.191863885260254,0.0403775237500668,172.74836730957,4.99925947189331,5.00066232681274,820.343933105469,820.343933105469,,,12.3656740188599,0,1,,,,,,1,1,1,4.99981927871704,0,4.99995942910512,,,,,,,,,,,,,,,,,,,,,,,,,,,,,,,,,
,3772376118.35888,4.99998593330383,800.453979492188,,,5,,,,6.47999998182058,,,,,0.00066989216010579,3.21095681009834E-7,0.103829663298677,0.000311073049803255,0.000669784685854407,3.21044165975036E-7,0.000669783586082237,2.4429559315105E-7,1.21376270543625E-6,2.08300311266169E-7,1.00016046089684,10.005763053894,2,20,1,3,2.19087579498328,0.198490286486948,0.0403775237500668,172.74836730957,4.99910974502563,5.00048685073853,800.453979492188,800.453979492188,,,12.3862771987915,0,1,,,,,,1,1,1,4.99998092651367,0,4.99983330567678,,,,,,,,,,,,,,,,,,,,,,,,,,,,,,,,,
,3772376143.96338,4.9999623298645,780.224060058594,,,5,,,,6.47999998182058,,,,,0.00068916921757233,3.34498210171163E-7,0.0984131971349624,0.000361867654029694,0.000689058730237639,3.34444583551229E-7,0.000689057713784049,2.22908501896703E-7,1.18355033980832E-6,2.49329058171972E-7,1.00016034530852,10.005763053894,2,20,1,3,2.25394366379841,0.203940235217537,0.0403775237500668,172.74836730957,4.99855279922485,5.00122737884521,780.224060058594,780.224060058594,,,12.3954830169678,0,1,,,,,,1,1,1,4.99974966049194,0,4.9999976839338,,,,,,,,,,,,,,,,,,,,,,,,,,,,,,,,,
,3772376170.8942,4.99982213973999,760.212707519531,,,5,,,,6.47999998182058,,,,,0.00070464762012532,5.85518613350772E-7,0.146008418924181,0.000716052428522154,0.000704534575167793,5.8542467997913E-7,0.000704532287554498,2.96926880929585E-7,1.79538299216653E-6,5.04535908841081E-7,1.00016045338513,10.005763053894,2,20,10,3,2.30439534251915,0.210385590123322,0.0403775237500668,172.74836730957,4.99877405166626,5.00080585479736,760.212707519531,760.212707519531,,,12.4192228317261,0,1,,,,,,1,1,1,4.99982786178589,0,4.99995744228363,,,,,,,,,,,,,,,,,,,,,,,,,,,,,,,,,
,3772376195.20283,4.9998414516449,740.492797851562,,,5,,,,6.47999998182058,,,,,0.000719273671179453,8.01501492349584E-7,0.144017368489942,0.00060464581813513,0.000719158279162186,8.01372908643895E-7,0.000719156007316976,6.73322743230424E-7,1.80765799350541E-6,4.3455151841529E-7,1.00016045427079,10.005763053894,2,20,10,3,2.35223733045733,0.214621078785421,0.0403775237500668,172.74836730957,4.99909782409668,5.00089645385742,740.492797851562,740.492797851562,,,12.4336290359497,0,1,,,,,,1,1,1,4.99966335296631,0,4.99995978673299,,,,,,,,,,,,,,,,,,,,,,,,,,,,,,,,,
,3772376220.7911,5.00010871887207,720.275024414062,,,5,,,,6.47999998182058,,,,,0.00073291926398111,2.50112512411773E-7,0.154485728056419,0.00027100259474842,0.000732801757737497,2.50072412794724E-7,0.000732799094022802,1.5197433329174E-7,1.97583970160637E-6,1.9859509979228E-7,1.00016035202205,10.005763053894,2,20,10,3,2.39682584299625,0.219078782903832,0.0403775237500668,172.74836730957,4.99944162368774,5.00063943862915,720.275024414062,720.275024414062,,,12.4529428482056,0,1,,,,,,1,1,1,4.99999189376831,0,5.00015219052633,,,,,,,,,,,,,,,,,,,,,,,,,,,,,,,,,
,3772376244.98971,4.99955749511719,700.263671875,,,5,,,,6.47999998182058,,,,,0.000744763468083114,4.19631789384682E-7,0.168831889754272,0.000332245401986475,0.000744643996470776,4.19564473936738E-7,0.000744640763646632,3.38949506772439E-7,2.19421870602133E-6,2.47280366484143E-7,1.00016044124831,10.005763053894,2,20,10,3,2.43550690161962,0.223176825896548,0.0403775237500668,172.74836730957,4.99816989898682,5.00064611434937,700.263671875,700.263671875,,,12.4687843322754,0,1,,,,,,1,1,1,4.99944829940796,0,4.99943741162618,,,,,,,,,,,,,,,,,,,,,,,,,,,,,,,,,
,3772376269.5221,4.99944233894348,680.361572265625,,,5,,,,6.47999998182058,,,,,0.00075564026494326,3.4561314847632E-7,0.152756122634782,0.000303500231591764,0.000755519052513372,3.45557708591137E-7,0.000755516367372003,2.5856754938603E-7,2.01428491409798E-6,2.29244307173068E-7,1.00016043596715,10.005763053894,2,20,10,3,2.471142803705,0.225690209988519,0.0403775237500668,172.74836730957,4.99435615539551,4.99970436096191,680.361572265625,680.361572265625,,,12.4777793884277,0,1,,,,,,1,1,1,4.99923038482666,0,4.99776570002238,,,,,,,,,,,,,,,,,,,,,,,,,,,,,,,,,
,3772376295.16454,4.99964308738708,660.459533691406,,,5,,,,6.47999998182058,,,,,0.000765561914020514,4.45813584462544E-7,0.152161922858101,0.000443473145819092,0.00076543910301072,4.45742067299158E-7,0.000765436403735894,2.88905656186925E-7,2.03279455879148E-6,3.39439998207826E-7,1.00016044517364,10.005763053894,2,20,10,3,2.50359506306961,0.22857425294255,0.0403775237500668,172.74836730957,4.99913930892944,5.00091218948364,660.459533691406,660.459533691406,,,12.4545679092407,0,1,,,,,,1,1,1,4.99976825714111,0,4.99983064944927,,,,,,,,,,,,,,,,,,,,,,,,,,,,,,,,,
,3772376319.44688,4.99928259849548,640.25390625,,,5,,,,6.47999998182058,,,,,0.000775230747697057,3.86038084469615E-7,0.148909532646211,0.000218912822070812,0.000775106398430682,3.8597616283823E-7,0.000775103780664709,3.46789287120318E-7,2.01446952263296E-6,1.69454385065438E-7,1.00016042864132,10.005763053894,2,20,10,3,2.53523148021021,0.231262342026621,0.0403775237500668,172.74836730957,4.99799013137817,5.00034475326538,640.25390625,640.25390625,,,12.4454784393311,0,1,,,,,,1,1,1,4.99925231933594,0,4.99921631813049,,,,,,,,,,,,,,,,,,,,,,,,,,,,,,,,,
,3772376343.92978,4.99944472312927,620.242553710937,,,5,,,,6.47999998182058,,,,,0.000784122114724062,3.89692937796276E-7,0.142874250865826,0.000439515139864824,0.000783996333428346,3.89630427019285E-7,0.000783993895917939,1.8179094505687E-7,1.95499168850133E-6,3.44621418305016E-7,1.00016043607649,10.005763053894,2,20,10,3,2.56433705215253,0.233589722903274,0.0403775237500668,172.74836730957,4.9988374710083,5.00050973892212,620.242553710937,620.242553710937,,,12.4242830276489,0,1,,,,,,1,1,1,4.99947261810303,0,4.99952614307404,,,,,,,,,,,,,,,,,,,,,,,,,,,,,,,,,
,3772376369.54146,4.9996554851532,600.474060058594,,,5,,,,6.47999998182058,,,,,0.000793013255972886,2.73984159083691E-7,0.131992516079985,0.000290215280983774,0.000792886040783582,2.7394020654393E-7,0.000792883936840753,1.48616399678488E-7,1.82657312299198E-6,2.3012258148199E-7,1.00016044574221,10.005763053894,2,20,10,3,2.59346238534985,0.235690964769991,0.0403775237500668,172.74836730957,4.99900770187378,5.00118637084961,600.474060058594,600.474060058594,,,12.4240064620972,0,1,,,,,,1,1,1,4.99964809417725,0,4.99975256125132,,,,,,,,,,,,,,,,,,,,,,,,,,,,,,,,,
,3772376392.71179,4.99976682662964,580.42626953125,,,5,,,,6.47999998182058,,,,,0.000801334858276545,2.80392725463977E-7,0.151024773433603,0.000248966678723578,0.000801206304045296,2.80347743430689E-7,0.000801203520711894,1.9701632232851E-7,2.11188086544703E-6,1.99447802652294E-7,1.00016045084843,10.005763053894,2,20,10,3,2.62060167522274,0.238978501639056,0.0403775237500668,172.74836730957,4.99911117553711,5.00082206726074,580.42626953125,580.42626953125,,,12.416054725647,0,1,,,,,,1,1,1,4.99963665008545,0,4.99979003270467,,,,,,,,,,,,,,,,,,,,,,,,,,,,,,,,,
,3772376418.28478,4.99982357025146,560.20849609375,,,5,,,,6.47999998182058,,,,,0.000810155049900194,2.43682974612601E-7,0.141316868846952,0.000212750894071152,0.000810025078581153,2.43643881111126E-7,0.000810022614749691,1.72254605856618E-7,1.9978799957878E-6,1.72309870767968E-7,1.00016045345074,10.005763053894,2,20,10,3,2.64949093121517,0.241102659692792,0.0403775237500668,172.74836730957,4.99924802780151,5.00111675262451,560.20849609375,560.20849609375,,,12.4218492507935,0,1,,,,,,1,1,1,5.00022125244141,0,4.99990157286326,,,,,,,,,,,,,,,,,,,,,,,,,,,,,,,,,
,3772376443.85263,5.00001168251038,540.1728515625,,,5,,,,6.47999998182058,,,,,0.000818406430541449,3.45509840796587E-7,0.126626483571409,0.000312373664507733,0.000818275128414195,3.45454408464447E-7,0.000818273130057513,2.32408388287729E-7,1.80842670502575E-6,2.55587733236595E-7,1.00016046207772,10.005763053894,2,20,10,3,2.67654191006302,0.242814633648016,0.0403775237500668,172.74836730957,4.99930191040039,5.0006742477417,540.1728515625,540.1728515625,,,12.4248514175415,0,1,,,,,,1,1,1,5.00007104873657,0,5.00000158945719,,,,,,,,,,,,,,,,,,,,,,,,,,,,,,,,,
,3772376466.91042,5.00001215934753,520.41650390625,,,5,,,,6.47999998182058,,,,,0.000825837001002087,3.00150413284978E-7,0.155525088801065,0.000213704597991817,0.000825704506723297,3.00102258246528E-7,0.000825701464787498,2.42805435390607E-7,2.24131009515471E-6,1.76371443123436E-7,1.00016046209959,10.005763053894,2,20,10,3,2.70072287636176,0.246324323268922,0.0403775237500668,172.74836730957,4.9989218711853,5.00165891647339,520.41650390625,520.41650390625,,,12.4275560379028,0,1,,,,,,1,1,1,5.00006246566772,0,5.00011984507243,,,,,,,,,,,,,,,,,,,,,,,,,,,,,,,,,
,3772376495.38254,4.99995851516724,500.186614990234,,,5,,,,6.47999998182058,,,,,0.000834252012705824,4.52742563097253E-7,0.170286644325212,0.000468845011977988,0.000834118170404965,4.52669927843853E-7,0.000834114486459636,2.27887186362027E-7,2.47904778165305E-6,3.91123374226289E-7,1.00016045963942,10.005763053894,2,20,10,3,2.72818203282133,0.249478104862445,0.0403775237500668,172.74836730957,4.99890661239624,5.0007209777832,500.186614990234,500.186614990234,,,12.4337940216064,0,1,,,,,,1,1,1,4.99998664855957,0,4.99994831818801,,,,,,,,,,,,,,,,,,,,,,,,,,,,,,,,,
,3772376518.67008,4.9998836517334,480.248107910156,,,5,,,,6.47999998182058,,,,,0.000843053266695124,3.95249360800799E-7,0.15702403722142,0.000373483911482909,0.000842918015268321,3.95185950762426E-7,0.00084291484977004,2.38867153972216E-7,2.31008680294497E-6,3.14824424772311E-7,1.00016045620612,10.005763053894,2,20,10,3,2.75702612822353,0.251413051783701,0.0403775237500668,172.74836730957,4.99923324584961,5.0014796257019,480.248107910156,480.248107910156,,,12.4463329315186,0,1,,,,,,1,1,1,4.99981737136841,0,4.9999917103694,,,,,,,,,,,,,,,,,,,,,,,,,,,,,,,,,
,3772376544.10732,4.9997980594635,460.479614257812,,,5,,,,6.47999998182058,,,,,0.000851550730059982,3.72835474175138E-7,0.162961470799188,0.000287642429686598,0.000851414118722736,3.72775661470032E-7,0.000851410674944589,2.81098184790058E-7,2.42160087806823E-6,2.44837710110502E-7,1.00016045228079,10.005763053894,2,20,10,3,2.78479278556908,0.254176801076045,0.0403775237500668,172.74836730957,4.99856805801392,5.00058746337891,460.479614257812,460.479614257812,,,12.4499034881592,0,1,,,,,,1,1,1,4.99983358383179,0,4.99983982245127,,,,,,,,,,,,,,,,,,,,,,,,,,,,,,,,,
,3772376567.31743,4.99994277954102,440.201141357422,,,5,,,,6.47999998182058,,,,,0.000860896116416915,2.72149134895833E-7,0.145941513416576,0.000231667398740384,0.00086075800011975,2.72105473146091E-7,0.000860755207812116,1.8515967551207E-7,2.19248591174717E-6,1.99392284405197E-7,1.00016045891777,10.005763053894,2,20,10,3,2.81543481032151,0.256068843858802,0.0403775237500668,172.74836730957,4.99911832809448,5.00101137161255,440.201141357422,440.201141357422,,,12.4629764556885,0,1,,,,,,1,1,1,4.99993419647217,0,5.00004350222074,,,,,,,,,,,,,,,,,,,,,,,,,,,,,,,,,
,3772376592.81128,5.00000715255737,420.286895751953,,,5,,,,6.47999998182058,,,,,0.000869797346933078,2.63986648037635E-7,0.148137900990723,0.00023795239378655,0.000869657800016249,2.63944295042484E-7,0.000869654893282403,1.63839824760128E-7,2.24849262261431E-6,2.06937436700188E-7,1.00016046186998,10.005763053894,2,20,10,3,2.84453900025813,0.25876487783103,0.0403775237500668,172.74836730957,4.99930143356323,5.00176048278809,420.286895751953,420.286895751953,,,12.4679756164551,0,1,,,,,,1,1,1,5.00000762939453,0,5.00022770808293,,,,,,,,,,,,,,,,,,,,,,,,,,,,,,,,,
,3772376616.19328,4.99997520446777,400.21484375,,,5,,,,6.47999998182058,,,,,0.000879371642828105,2.38032881450723E-7,0.142778583407274,0.000139444028816228,0.000879230561136345,2.37994692725986E-7,0.000879227831194298,2.04042393824825E-7,2.19100194025613E-6,1.22507858066212E-7,1.00016046040481,10.005763053894,2,20,10,3,2.87587873188396,0.261282446043914,0.0403775237500668,172.74836730957,4.99914407730103,5.00104665756226,400.21484375,400.21484375,,,12.4761753082275,0,1,,,,,,1,1,1,5.00002574920654,0,5.00003279172457,,,,,,,,,,,,,,,,,,,,,,,,,,,,,,,,,
,3772376641.5771,5.00004577636719,380.239929199219,,,5,,,,6.47999998182058,,,,,0.000888688178020552,2.3146732370435E-7,0.142981584858648,0.000156921102852422,0.000888545598758318,2.31430187573746E-7,0.000888542832043174,1.84755961968531E-7,2.21736272978885E-6,1.39374195020105E-7,1.0001604636413,10.005763053894,2,20,10,3,2.90635042619273,0.263998772608701,0.0403775237500668,172.74836730957,4.9994912147522,5.00102663040161,380.239929199219,380.239929199219,,,12.4848108291626,0,1,,,,,,1,1,1,4.99995946884155,0,5.00010784467061,,,,,,,,,,,,,,,,,,,,,,,,,,,,,,,,,
,3772376664.66852,5.0000171661377,360.155731201172,,,5,,,,6.47999998182058,,,,,0.00089661184646708,5.17264488810632E-7,0.166893395114346,0.000433058200296,0.000896467997124203,5.17181500662413E-7,0.000896464194026156,3.41722541284344E-7,2.6112634709254E-6,3.88204082159881E-7,1.00016046232921,10.005763053894,2,20,10,3,2.93215654939797,0.267513316979607,0.0403775237500668,172.74836730957,4.9992618560791,5.00186157226562,360.155731201172,360.155731201172,,,12.4909858703613,0,1,,,,,,1,1,1,5.00004386901855,0,5.0000528494517,,,,,,,,,,,,,,,,,,,,,,,,,,,,,,,,,
,3772376688.84668,5.00012683868408,340.277954101562,,,5,,,,6.47999998182058,,,,,0.000897892279155117,1.10179876374941E-6,0.218512828357774,0.000807978875218648,0.000897748219869334,1.10162198937829E-6,0.000897741691080191,8.29296758310891E-7,3.423795413943E-6,7.25146808678642E-7,1.00016046735888,10.005763053894,2,20,10,3,2.93610548326351,0.2704782051812,0.0403775237500668,172.74836730957,4.99886846542358,5.0011739730835,340.277954101562,340.277954101562,,,12.5048999786377,0,1,,,,,,1,1,1,5.00009632110596,0,5.00013864040375,,,,,,,,,,,,,,,,,,,,,,,,,,,,,,,,,
,3772376713.38278,5.00019407272339,320.242309570313,,,5,,,,6.47999998182058,,,,,0.000876010551009974,2.56187055411855E-6,0.440596928863806,0.00193246283040939,0.000875870100039877,2.56145980883224E-6,0.000875844203291829,1.9231968843105E-6,6.73525827016703E-6,1.69185995178126E-6,1.00016035593645,10.005763053894,2,20,10,3,2.86351221753779,0.274926484395222,0.0403775237500668,172.74836730957,4.99938583374023,5.00120401382446,320.242309570313,320.242309570313,,,12.5137329101562,0,1,,,,,,1,1,1,5.00027751922607,0,5.00020237763723,,,,,,,,,,,,,,,,,,,,,,,,,,,,,,,,,
,3772376739.01408,5.00008058547974,300.206665039063,,,5,,,,6.47999998182058,,,,,0.000831804319033407,3.48730481987981E-6,0.575975692249204,0.00269410286444158,0.000831670959986335,3.48674571765229E-6,0.00083162893757881,2.67278777411217E-6,8.36037476029773E-6,2.23910723595881E-6,1.00016035073183,10.005763053894,2,20,10,3,2.71839024596353,0.267418284789483,0.0403775237500668,172.74836730957,4.99949932098389,5.00156450271606,300.206665039063,300.206665039063,,,12.514853477478,0,1,,,,,,1,1,1,5.0001654624939,0,5.00018534293542,,,,,,,,,,,,,,,,,,,,,,,,,,,,,,,,,
,3772376762.23696,5.00000500679016,280.280334472656,,,5,,,,6.47999998182058,,,,,0.000779662185091643,3.36703560193637E-6,0.621581029624474,0.00275621413407971,0.000779537188434947,3.36649579354081E-6,0.000779491315891414,2.59304479682649E-6,8.45674895773247E-6,2.14695426350424E-6,1.00016034726572,10.005763053894,2,20,10,3,2.54779003732978,0.252628689137188,0.0403775237500668,172.74836730957,4.99878597259521,5.00127840042114,280.280334472656,280.280334472656,,,12.5319595336914,0,1,,,,,,1,1,1,4.99993419647217,0,5.0000534424415,,,,,,,,,,,,,,,,,,,,,,,,,,,,,,,,,
,3772376785.58608,5.00007176399231,260.232543945313,,,5,,,,6.47999998182058,,,,,0.000739208046528684,1.33676417443854E-6,0.296829493738023,0.00107802223010235,0.000739089448663651,1.33654970521315E-6,0.000739079530417711,1.07349519518462E-6,3.82894808997818E-6,7.96224327950922E-7,1.00016046483311,10.005763053894,2,20,10,3,2.41691577155677,0.225773423153486,0.0403775237500668,172.74836730957,4.99923467636108,5.00179433822632,260.232543945313,260.232543945313,,,12.5369272232056,0,1,,,,,,1,1,1,5.00004720687866,0,5.00011627490704,,,,,,,,,,,,,,,,,,,,,,,,,,,,,,,,,
,3772376810.92952,5.00003051757812,240.196899414062,,,5,,,,6.47999998182058,,,,,0.000712724153412905,3.85087021981907E-7,0.212507788143815,0.000181301157479895,0.000712609805947291,3.85025239699387E-7,0.000712604904484185,3.62860880614798E-7,2.64303562598395E-6,1.28749433105642E-7,1.00016046294151,10.005763053894,2,20,10,3,2.33064512704966,0.2142048170831,0.0403775237500668,172.74836730957,4.99938344955444,5.00071573257446,240.196899414062,240.196899414062,,,12.5427207946777,0,1,,,,,,1,1,1,5.0001106262207,0,5.00005241235097,,,,,,,,,,,,,,,,,,,,,,,,,,,,,,,,,
,3772376834.14482,5.00014734268188,220.136978149414,,,5,,,,6.47999998182058,,,,,0.00069279062132153,3.33650540434776E-7,0.17428865037423,0.00019030696263905,0.000692679468225365,3.33597008690169E-7,0.000692676263469631,3.06559034026839E-7,2.10706590434172E-6,1.3156185945615E-7,1.00016046829921,10.005763053894,2,20,10,3,2.26560299413523,0.206654051086616,0.0403775237500668,172.74836730957,4.99916458129883,5.0010142326355,220.136978149414,220.136978149414,,,12.5552587509155,0,1,,,,,,1,1,1,5.00013732910156,0,5.00002380212148,,,,,,,,,,,,,,,,,,,,,,,,,,,,,,,,,
,3772376857.19686,5.00009846687317,200.271347045898,,,5,,,,6.47999998182058,,,,,0.000677380404890615,2.85625759435972E-7,0.149558907449051,0.000183635516479131,0.000677271725766771,2.8557993354987E-7,0.000677269418424588,2.57156958761979E-7,1.7678772360676E-6,1.24202242357528E-7,1.00016046605773,10.005763053894,2,20,10,3,2.21529768824977,0.201054063105646,0.0403775237500668,172.74836730957,4.99925374984741,5.00085639953613,200.271347045898,200.271347045898,,,12.5645217895508,0,1,,,,,,1,1,1,5.00023651123047,0,5.00007406870524,,,,,,,,,,,,,,,,,,,,,,,,,,,,,,,,,
,3772376880.22186,5.00011730194092,180.187149047852,,,5,,,,6.47999998182058,,,,,0.000665133625076158,1.83763139929672E-7,0.119531426303205,0.000149283716352406,0.000665026986392402,1.83733677790598E-7,0.000665025539194066,1.5464043922402E-7,1.38738956389543E-6,9.92189443153951E-8,1.00016035241567,10.005763053894,2,20,10,3,2.17535211509597,0.196232293738235,0.0403775237500668,172.74836730957,4.99932765960693,5.00096082687378,180.187149047852,180.187149047852,,,12.5696239471436,0,1,,,,,,1,1,1,4.99997186660767,0,5.00008924802144,,,,,,,,,,,,,,,,,,,,,,,,,,,,,,,,,
,3772376905.89104,4.99998307228088,160.151504516602,,,5,,,,6.47999998182058,,,,,0.000655261525033046,1.96230124824941E-7,0.106533922949563,9.35137724251678E-5,0.000655156398135791,1.96198642640526E-7,0.000655155265616939,1.86440129827836E-7,1.21817595667312E-6,6.11063447095678E-8,1.00016046076563,10.005763053894,2,20,10,3,2.14311166560258,0.192787643733022,0.0403775237500668,172.74836730957,4.9993462562561,5.00113677978516,160.151504516602,160.151504516602,,,12.5728073120117,0,1,,,,,,1,1,1,4.99991226196289,0,5.00008612412673,,,,,,,,,,,,,,,,,,,,,,,,,,,,,,,,,
,3772376928.97324,4.99991297721863,140.17658996582,,,5,,,,6.47999998182058,,,,,0.000647021222348488,1.84435088057686E-7,0.0968303046997541,7.56225501355559E-5,0.000646917419563636,1.84405498802955E-7,0.00064691649572509,1.77846103166174E-7,1.09329485637066E-6,4.87457852267592E-8,1.00016045755101,10.005763053894,2,20,10,3,2.11619585753116,0.18995958575026,0.0403775237500668,172.74836730957,4.99953508377075,5.00171804428101,140.17658996582,140.17658996582,,,12.5905542373657,0,1,,,,,,1,1,1,5.00006580352783,0,5.00012900279118,,,,,,,,,,,,,,,,,,,,,,,,,,,,,,,,,
,3772376954.64781,5.00003480911255,120.238098144531,,,5,,,,6.47999998182058,,,,,0.000640431628073256,1.36255385175201E-7,0.0811360686502027,8.90580144421033E-5,0.000640328952201431,1.36233540313314E-7,0.000640328310170832,1.23752116948701E-7,9.06764109016402E-7,5.69648229788729E-8,1.00016034863248,10.005763053894,2,20,10,3,2.09469769960766,0.187406475904168,0.0403775237500668,172.74836730957,4.99946689605713,5.00098848342895,120.238098144531,120.238098144531,,,12.5914001464844,0,1,,,,,,1,1,1,4.99994134902954,0,5.00013852119446,,,,,,,,,,,,,,,,,,,,,,,,,,,,,,,,,
,3772376977.77564,5.00002384185791,100.251037597656,,,5,,,,6.47999998182058,,,,,0.0006349670761277,1.60657003881212E-7,0.0734364955672486,0.000102656369161498,0.000634865276668092,1.6063124696122E-7,0.000634864755197115,1.46848203852857E-7,8.13712086772291E-7,6.50999425921883E-8,1.00016034812952,10.005763053894,2,20,10,3,2.07685222791298,0.185483890323542,0.0403775237500668,172.74836730957,4.99932956695557,5.0007791519165,100.251037597656,100.251037597656,,,12.6045036315918,0,1,,,,,,1,1,1,5.00003290176392,0,5.00002988179525,,,,,,,,,,,,,,,,,,,,,,,,,,,,,,,,,
,3772377001.97633,5.00010418891907,80.1668243408203,,,5,,,,6.47999998182058,,,,,0.000630795908326873,1.19144366456214E-7,0.0620517606054731,4.30042216411528E-5,0.000630694703068737,1.19125250865572E-7,0.000630694333196191,1.1602191351774E-7,6.83046978540729E-7,2.70137183199098E-8,1.00016046632014,10.005763053894,2,20,10,3,2.06324852983596,0.183811109278386,0.0403775237500668,172.74836730957,4.99892711639404,5.00169992446899,80.1668243408203,80.1668243408203,,,12.6038370132446,0,1,,,,,,1,1,1,5.00017976760864,0,5.00007919164804,,,,,,,,,,,,,,,,,,,,,,,,,,,,,,,,,
,3772377026.5055,5.00000429153442,60.1676177978516,,,5,,,,6.47999998182058,,,,,0.0006275994089247,8.01966035167605E-8,0.0564514762940629,2.89286948967177E-5,0.000627498719389113,8.01837370948855E-8,0.000627498414818389,7.81183199230967E-8,6.18251879144175E-7,1.80820293909288E-8,1.00016046173877,10.005763053894,2,20,10,3,2.05281384180389,0.182635076020565,0.0403775237500668,172.74836730957,4.9993052482605,5.00102758407593,60.1676177978516,60.1676177978516,,,12.6170530319214,0,1,,,,,,1,1,1,4.99994993209839,0,5.00012691815694,,,,,,,,,,,,,,,,,,,,,,,,,,,,,,,,,
,3772377049.6687,4.99996089935303,40.2898406982422,,,5,,,,6.47999998182058,,,,,0.000625418782989918,1.27662869286085E-7,0.0512592674657961,6.0511644682079E-5,0.000625318444549408,1.27642387820604E-7,0.000625318194301336,1.21928979344008E-7,5.59436687955185E-7,3.77611329898069E-8,1.00016045974876,10.005763053894,2,20,10,3,2.04570045553527,0.181771596518434,0.0403775237500668,172.74836730957,4.99923038482666,5.0012640953064,40.2898406982422,40.2898406982422,,,12.6214828491211,0,1,,,,,,1,1,1,4.99999475479126,0,5.00005129973094,,,,,,,,,,,,,,,,,,,,,,,,,,,,,,,,,
,3772377072.70895,5.00003409385681,20.2056350708008,,,5,,,,6.47999998182058,,,,,0.000624056017444609,1.02378850411143E-7,0.0441733108407805,2.61725957210403E-5,0.000623955895543899,1.02362425018535E-7,0.000623955710105993,1.01070791517164E-7,4.81051051727748E-7,1.62099092461765E-8,1.00016046310553,10.005763053894,2,20,10,3,2.04126811256849,0.181079195463615,0.0403775237500668,172.74836730957,4.99927377700806,5.00096559524536,20.2056350708008,20.2056350708008,,,12.6339416503906,0,1,,,,,,1,1,1,5.00007200241089,0,5.00006810824076,,,,,,,,,,,,,,,,,,,,,,,,,,,,,,,,,
,3772377095.78629,5.0000102519989,0.218570560216904,,,5,,,,6.47999998182058,,,,,0.000623704700134159,1.21971507640376E-7,0.0415813493033106,2.64807101512236E-5,0.000623604635279615,1.21951938986864E-7,0.000623604471057663,1.2085147922747E-7,4.52569458185214E-7,1.6346112418197E-8,1.00016046201212,10.005763053894,2,20,10,3,2.04012988236081,0.180841322301268,0.0403775237500668,172.74836730957,4.99939632415771,5.0009880065918,0.218570560216904,0.218570560216904,,,12.6379814147949,0,1,,,,,,1,1,1,4.99995088577271,0,5.00006560484568,,,,,,,,,,,,,,,,,,,,,,,,,,,,,,,,,