File: Experimental_Data/AC_Suceptibillity_FieldScans/HFCd_Up_40K.dat
[Header]
; MPMS3 Data File (default extension .dat)
; Copyright (c) 2007, Quantum Design, Inc. All rights reserved.
TITLE,HFCd_Up_40K
FILEOPENTIME,3772401824.80898,07/16/2019,1:23 am
BYAPP,SQUID AC,0.9.1.0
INFO,MPMS3 Measurement Release 1.1.16 Build 347, MultiVu Release 2.3.3.2,APPNAME
INFO,0,MOMENT_UNITS
INFO,Cu2OSeO3,SAMPLE_MATERIAL
INFO,,SAMPLE_COMMENT
INFO,,SAMPLE_MASS
INFO,,SAMPLE_VOLUME
INFO,,SAMPLE_MOLECULAR_WEIGHT
INFO,,SAMPLE_SIZE
INFO,,SAMPLE_SHAPE
INFO,Quartz,SAMPLE_HOLDER
INFO,Standard,SAMPLE_HOLDER_DETAIL
INFO,64.77,SAMPLE_OFFSET
DATATYPE,COMMENT,1
DATATYPE,TIME,2
STARTUPAXIS,X,2
STARTUPAXIS,Y1,5
FIELDGROUP, VSM,2,3,4,5,6,8,9,10,11,14,15
FIELDGROUP, DC, 2,3,4,14,56,57,58,59,60,61,62,63,64,65,66,67,68,69
FIELDGROUP, AC, 2,3,4,11,16,17,18,19,20,21,22,23,24,25,26,27,28,29,30
STARTUPGROUP, All
[Data]
Comment,Time Stamp (sec),Temperature (K),Magnetic Field (Oe),Moment (emu),M. Std. Err. (emu),Transport Action,Averaging Time (sec),Frequency (Hz),Peak Amplitude (mm),Center Position (mm),Lockin Signal' (V),Lockin Signal (V),Range,M. Quad. Signal (emu),AC Moment (emu),AC M. Std Err. (emu),AC Phase (deg),AC Phase Std. Err. (deg),AC Susceptibility (emu/Oe),AC Suscept. Std Err. (emu/Oe),AC X' (emu/Oe),AC X' Std Err. (emu/Oe),AC X'' (emu/Oe),AC X'' Std Err. (emu/Oe),AC Drive (Oe),AC Frequency (Hz),AC Averaging Time (sec),AC Cycles,AC Range,AC Measure Type,AC Signal' (V),AC Signal'' (V),AC Trim Coil Ratio,AC Trim Coil Phase,Min. Temperature (K),Max. Temperature (K),Min. Field (Oe),Max. Field (Oe),Mass (grams),Motor Lag (deg),Pressure (Torr),Measure Count,Measurement Number,SQUID Status (code),Motor Status (code),Measure Status (code),Motor Current (amps),Motor Temp. (C),Temp. Status (code),Field Status (code),Chamber Status (code),Chamber Temp (K),Redirection State,Average Temp (K),Rotation Angle (deg),Rotator state,DC Moment Fixed Ctr (emu),DC Moment Err Fixed Ctr (emu),DC Moment Free Ctr (emu),DC Moment Err Free Ctr (emu),DC Fixed Fit,DC Free Fit,DC Calculated Center (mm),DC Calculated Center Err (mm),DC Scan Length (mm),DC Scan Time (s),DC Number of Points,DC Squid Drift,DC Min V (V),DC Max V (V),DC Scans per Measure,Map 01,Map 02,Map 03,Map 04,Map 05,Map 06,Map 07,Map 08,Map 09,Map 10,Map 11,Map 12,Map 13,Map 14,Map 15,Map 16
,3772401976.24457,39.9055328369141,1000.26391601562,,,5,,,,6.47999998182058,,,,,1.081370152407E-5,2.43385260013112E-7,1.82354101281653,0.0142030359204363,1.08120351724968E-5,2.4334775524104E-7,1.08065596369833E-5,1.89076044896336E-7,3.44054332384463E-7,1.53193926861387E-7,1.00015412006589,10.005763053894,2,20,1,3,0.035253795186025,0.00426757095030686,0.0403775237500668,172.74836730957,39.8957443237305,39.9193649291992,1000.26391601562,1000.26391601562,,,24.6787090301514,0,1,,,,,,1,1,1,39.9019088745117,0,39.9043294466459,,,,,,,,,,,,,,,,,,,,,,,,,,,,,,,,,
,3772401998.72286,39.9021072387695,980.434692382813,,,5,,,,6.47999998182058,,,,,1.23784947893733E-5,2.74842988327349E-7,1.3783547002059,0.0133992473479348,1.23765778959551E-5,2.74800427036632E-7,1.2372996714251E-5,2.19423859314108E-7,2.97712485091035E-7,1.65434109733205E-7,1.0001548807299,10.005763053894,2,20,1,3,0.0403919977395322,0.00457054778324256,0.0403775237500668,172.74836730957,39.900276184082,39.9078369140625,980.434692382813,980.434692382813,,,24.6370468139648,0,1,,,,,,1,1,1,39.9028205871582,0,39.9038366837935,,,,,,,,,,,,,,,,,,,,,,,,,,,,,,,,,
,3772402021.65479,39.9162063598633,960.362670898438,,,5,,,,6.47999998182058,,,,,1.43083957737129E-5,4.1156417421874E-7,1.11304855636423,0.0153830202791441,1.43061789905795E-5,4.11500411059392E-7,1.4303479617221E-5,3.48210682175876E-7,2.77899532636815E-7,2.19275874461054E-7,1.00015495284484,10.005763053894,2,20,1,3,0.0467134614760482,0.0050658743118331,0.0403775237500668,172.74836730957,39.9123802185059,39.9263076782227,960.362670898438,960.362670898438,,,24.6088924407959,0,1,,,,,,1,1,1,39.9178657531738,0,39.9196773529053,,,,,,,,,,,,,,,,,,,,,,,,,,,,,,,,,
,3772402042.17157,39.9507007598877,940.266357421875,,,5,,,,6.47999998182058,,,,,1.67200713592874E-5,2.4705708451999E-7,1.41326928919614,0.00953770279536703,1.67174794597386E-5,2.47018786409166E-7,1.67123940803139E-5,1.88867876470741E-7,4.12314917350004E-7,1.59208059081474E-7,1.00015504128808,10.005763053894,2,20,1,3,0.0545553367293578,0.00620448868450121,0.0403775237500668,172.74836730957,39.9443702697754,39.962158203125,940.266357421875,940.266357421875,,,24.6075286865234,0,1,,,,,,1,1,1,39.952693939209,0,39.9546955108643,,,,,,,,,,,,,,,,,,,,,,,,,,,,,,,,,
,3772402064.01191,39.9691104888916,920.412780761719,,,5,,,,6.47999998182058,,,,,2.08796856000386E-5,3.45728057399458E-7,0.93572495758867,0.0143826451771541,2.08764552332258E-5,3.45674568641809E-7,2.08736712393767E-5,1.70747448704979E-7,3.40928284686127E-7,3.00559837913254E-7,1.00015473732378,10.005763053894,2,20,1,3,0.068189922659864,0.00717849842044402,0.0403775237500668,172.74836730957,39.9685859680176,39.9691696166992,920.412780761719,920.412780761719,,,24.6202945709229,0,1,,,,,,1,1,1,39.9690818786621,0,39.9688529968262,,,,,,,,,,,,,,,,,,,,,,,,,,,,,,,,,
,3772402085.7564,39.9688568115234,900.377197265625,,,5,,,,6.47999998182058,,,,,2.5715200137089E-5,2.90910990160525E-7,0.529142981854164,0.00607353124282543,2.57112219500536E-5,2.90865985714775E-7,2.57101254959663E-5,2.45566344433359E-7,2.3744714481889E-7,1.5588518892911E-7,1.00015472570861,10.005763053894,2,20,1,3,0.0840427401350199,0.00824299022183967,0.0403775237500668,172.74836730957,39.9679946899414,39.9690818786621,900.377197265625,900.377197265625,,,24.6217479705811,0,1,,,,,,1,1,1,39.9686851501465,0,39.9685470581055,,,,,,,,,,,,,,,,,,,,,,,,,,,,,,,,,
,3772402107.47621,39.9869041442871,880.29296875,,,5,,,,6.47999998182058,,,,,3.16582882934339E-5,3.33692080078749E-7,1.52854296015658,0.00705408258056644,3.16533863263422E-5,3.33640411220972E-7,3.16421227979522E-5,2.48130551786629E-7,8.443522748135E-7,2.23040698684707E-7,1.00015486390749,10.005763053894,2,20,1,3,0.103273474422872,0.0119489174583708,0.0403775237500668,172.74836730957,39.9838943481445,39.993293762207,880.29296875,880.29296875,,,24.6483383178711,0,1,,,,,,1,1,1,39.9883766174316,0,39.9893642425537,,,,,,,,,,,,,,,,,,,,,,,,,,,,,,,,,
,3772402129.33114,40.0050621032715,860.42724609375,,,5,,,,6.47999998182058,,,,,4.18078986156957E-5,4.2914696991793E-7,1.15391945357895,0.00828494783331795,4.18014286828951E-5,4.2908055777695E-7,4.17929514878534E-5,2.52946549748444E-7,8.41811062588482E-7,3.46595106763693E-7,1.0001547777912,10.005763053894,2,20,1,3,0.136483330203433,0.0148847555936299,0.0403775237500668,172.74836730957,40.0040969848633,40.0053863525391,860.42724609375,860.42724609375,,,24.6742210388184,0,1,,,,,,1,1,1,40.0053329467773,0,40.0048162286932,,,,,,,,,,,,,,,,,,,,,,,,,,,,,,,,,
,3772402152.41944,40.0012588500977,840.221740722656,,,5,,,,6.47999998182058,,,,,5.86819764579651E-5,2.91973867095761E-7,0.957483130386108,0.00336846149786275,5.8672898684423E-5,2.91928700371568E-7,5.86647062223547E-5,2.14961491438943E-7,9.8045085413803E-7,1.97519425118083E-7,1.00015471834093,10.005763053894,2,20,1,3,0.19164017247905,0.0202313366533273,0.0403775237500668,172.74836730957,40.0003662109375,40.0017204284668,840.221740722656,840.221740722656,,,24.6760025024414,0,1,,,,,,1,1,1,40.0009803771973,0,40.0009227752686,,,,,,,,,,,,,,,,,,,,,,,,,,,,,,,,,
,3772402173.81593,40.0021419525146,820.198181152344,,,5,,,,6.47999998182058,,,,,8.64870036253484E-5,3.93460319121374E-7,0.515486863029208,0.00243875391655189,8.64736309897207E-5,3.93399482218012E-7,8.64701312100099E-5,3.32327938846983E-7,7.77987834136157E-7,2.1052623036362E-7,1.000154644086,10.005763053894,2,20,1,3,0.282666255404565,0.0276316815047329,0.0403775237500668,172.74836730957,39.9996795654297,40.0036735534668,820.198181152344,820.198181152344,,,24.6894416809082,0,1,,,,,,1,1,1,40.0014991760254,0,40.001256422563,,,,,,,,,,,,,,,,,,,,,,,,,,,,,,,,,
,3772402195.9568,40.0002326965332,800.453979492188,,,5,,,,6.47999998182058,,,,,0.000128352324312282,2.84084731296758E-7,0.46487089548224,0.00107601266044443,0.000128332474954318,2.84040798321224E-7,0.000128328250956933,2.48390279731528E-7,1.04121766942001E-6,1.37773161558599E-7,1.00015467135634,10.005763053894,2,20,1,3,0.419531751507342,0.0406277380911262,0.0403775237500668,172.74836730957,39.9999580383301,40.0009346008301,800.453979492188,800.453979492188,,,24.7156925201416,0,1,,,,,,1,1,1,40.0004653930664,0,40.0004810333252,,,,,,,,,,,,,,,,,,,,,,,,,,,,,,,,,
,3772402218.97229,40.0009479522705,780.224060058594,,,5,,,,6.47999998182058,,,,,0.000189882930466269,4.04376668894069E-7,0.292555506061786,0.0016496800797721,0.000189853559341134,4.04314119839686E-7,0.000189851084432949,2.55669055388604E-7,9.69398850197094E-7,3.13214370070147E-7,1.00015470410583,10.005763053894,2,20,1,3,0.620829241633885,0.0582239013280741,0.0403775237500668,172.74836730957,39.999397277832,40.0022315979004,780.224060058594,780.224060058594,,,24.7165622711182,0,1,,,,,,1,1,1,40.0002746582031,0,40.0003547668457,,,,,,,,,,,,,,,,,,,,,,,,,,,,,,,,,
,3772402242.08908,40.0004367828369,760.212707519531,,,5,,,,6.47999998182058,,,,,0.000299167031060312,3.71313676749947E-7,0.384459510594191,0.000896319549111879,0.000299120762851072,3.71256250572908E-7,0.000299114028885569,2.56834575850526E-7,2.00711047290497E-6,2.68080592802116E-7,1.00015468070086,10.005763053894,2,20,1,3,0.977990688487015,0.0932816316880482,0.0403775237500668,172.74836730957,40.0000038146973,40.000789642334,760.212707519531,760.212707519531,,,24.7171649932861,0,1,,,,,,1,1,1,40.0005493164063,0,40.0004192988078,,,,,,,,,,,,,,,,,,,,,,,,,,,,,,,,,
,3772402265.06404,40.0190010070801,740.480651855469,,,5,,,,6.47999998182058,,,,,0.000452103519992288,3.21386775577891E-7,0.232502487851592,0.000392389555853178,0.000452033577797483,3.21337055778174E-7,0.000452029856023048,2.68044020037227E-7,1.83431735954671E-6,1.77228402741964E-7,1.00015472787474,10.005763053894,2,20,1,3,1.47831781674308,0.137016361747206,0.0403775237500668,172.74836730957,40.0138168334961,40.0195198059082,740.480651855469,740.480651855469,,,24.7427253723145,0,1,,,,,,1,1,1,40.0186042785645,0,40.0171276092529,,,,,,,,,,,,,,,,,,,,,,,,,,,,,,,,,
,3772402288.1912,40.0272941589355,720.469299316406,,,5,,,,6.47999998182058,,,,,0.000637346425195226,3.07619264823905E-7,0.157730789454926,0.000245633016127153,0.000637247948628347,3.07571734488897E-7,0.000637245533913428,2.64842441676559E-7,1.75429143143785E-6,1.56393263740186E-7,1.00015453414498,10.005763053894,2,20,1,3,2.08429046760271,0.190392278138067,0.0403775237500668,172.74836730957,40.0182266235352,40.0296669006348,720.469299316406,720.469299316406,,,24.7314720153809,0,1,,,,,,1,1,1,40.026195526123,0,40.024636702104,,,,,,,,,,,,,,,,,,,,,,,,,,,,,,,,,
,3772402313.12065,40.0075607299805,700.215087890625,,,5,,,,6.47999998182058,,,,,0.000738403609874425,3.66186262084484E-7,0.0703950320665578,0.000457162723651948,0.000738289423952548,3.66129635443775E-7,0.000738288866721439,1.41832922569064E-7,9.07080679236397E-7,3.37541600437204E-7,1.00015466281674,10.005763053894,2,20,10,3,2.41511079158858,0.216847481353048,0.0403775237500668,172.74836730957,40.0032081604004,40.0093383789063,700.215087890625,700.215087890625,,,24.7438125610352,0,1,,,,,,1,1,1,40.0069046020508,0,40.0059104919434,,,,,,,,,,,,,,,,,,,,,,,,,,,,,,,,,
,3772402339.39975,40.0194339752197,680.50732421875,,,5,,,,6.47999998182058,,,,,0.0007749958105535,3.45981915182636E-7,0.136749266571519,0.000300534849424711,0.000774875900290858,3.45928383561234E-7,0.000774873693268672,2.55846649014488E-7,1.84941388958009E-6,2.32828131335853E-7,1.00015474769908,10.005763053894,2,20,10,3,2.53453180693219,0.23047534293268,0.0403775237500668,172.74836730957,40.0138092041016,40.0197982788086,680.50732421875,680.50732421875,,,24.7449359893799,0,1,,,,,,1,1,1,40.0190696716309,0,40.0176040649414,,,,,,,,,,,,,,,,,,,,,,,,,,,,,,,,,
,3772402362.46707,40.0059566497803,660.180236816406,,,5,,,,6.47999998182058,,,,,0.000794018803598385,4.53495644873072E-7,0.137065439029419,0.000505954767895966,0.000793896075703725,4.53425550102671E-7,0.000793893804039647,2.10268210599853E-7,1.89919067854413E-6,4.01723797026073E-7,1.00015458937059,10.005763053894,2,20,10,3,2.59674659747845,0.236090549081488,0.0403775237500668,172.74836730957,40.0030670166016,40.0075187683105,660.180236816406,660.180236816406,,,24.7453765869141,0,1,,,,,,1,1,1,40.0052375793457,0,40.0048446655273,,,,,,,,,,,,,,,,,,,,,,,,,,,,,,,,,
,3772402384.08558,40.0023307800293,640.423889160156,,,5,,,,6.47999998182058,,,,,0.000802713940914874,4.12337778106961E-7,0.139998163465326,0.000318759821655206,0.000802589818206922,4.12274018803676E-7,0.000802587422339146,3.23365531111575E-7,1.96106920464474E-6,2.55743230349237E-7,1.00015465273186,10.005763053894,2,20,10,3,2.62517441784564,0.23875482499352,0.0403775237500668,172.74836730957,40.0009803771973,40.0032539367676,640.423889160156,640.423889160156,,,24.733081817627,0,1,,,,,,1,1,1,40.0016708374023,0,40.001685333252,,,,,,,,,,,,,,,,,,,,,,,,,,,,,,,,,
,3772402406.91902,40.0005855560303,620.169677734375,,,5,,,,6.47999998182058,,,,,0.000807518574461124,2.65787690945115E-7,0.136662246529649,0.000284024165607934,0.000807393680740836,2.65746583267127E-7,0.000807391384026449,1.34252957738341E-7,1.92579855893147E-6,2.29341208370103E-7,1.00015468751275,10.005763053894,2,20,10,3,2.64090505433604,0.239972895570744,0.0403775237500668,172.74836730957,39.9997444152832,40.0020523071289,620.169677734375,620.169677734375,,,24.7585983276367,0,1,,,,,,1,1,1,39.9998931884766,0,40.0003589283336,,,,,,,,,,,,,,,,,,,,,,,,,,,,,,,,,
,3772402429.05018,39.9958724975586,600.206909179688,,,5,,,,6.47999998182058,,,,,0.000810466946692742,3.38562618962518E-7,0.146253226192166,0.000252997561409593,0.000810341678885701,3.38510289873718E-7,0.000810339038887746,2.69429919426165E-7,2.06847619771335E-6,2.04931049058943E-7,1.0001545864051,10.005763053894,2,20,10,3,2.65051071966512,0.241236168241561,0.0403775237500668,172.74836730957,39.9945068359375,39.9973487854004,600.206909179688,600.206909179688,,,24.7451839447021,0,1,,,,,,1,1,1,39.9955139160156,0,39.9954349517822,,,,,,,,,,,,,,,,,,,,,,,,,,,,,,,,,
,3772402452.16812,40.0171909332275,580.486999511719,,,5,,,,6.47999998182058,,,,,0.000812376336162438,3.40423333024083E-7,0.135748305175442,0.000200198230065595,0.000812250632509198,3.40370657367858E-7,0.000812248352779133,2.99100919356624E-7,1.92442697387704E-6,1.62452529795784E-7,1.00015475968649,10.005763053894,2,20,10,3,2.65680303527864,0.241261081942138,0.0403775237500668,172.74836730957,40.013988494873,40.0176544189453,580.486999511719,580.486999511719,,,24.7595233917236,0,1,,,,,,1,1,1,40.0176544189453,0,40.0162436167399,,,,,,,,,,,,,,,,,,,,,,,,,,,,,,,,,
,3772402475.20212,40.0060958862305,560.329895019531,,,5,,,,6.47999998182058,,,,,0.000813765393418571,3.06174983204299E-7,0.142635139189593,0.000261168395011136,0.00081363960819651,3.06127657170821E-7,0.000813637086982814,2.20395249522629E-7,2.02551531509453E-6,2.12461941233609E-7,1.00015459574582,10.005763053894,2,20,10,3,2.66132046673319,0.241936199878845,0.0403775237500668,172.74836730957,40.0030975341797,40.0071907043457,560.329895019531,560.329895019531,,,24.7589817047119,0,1,,,,,,1,1,1,40.0058441162109,0,40.0048398104581,,,,,,,,,,,,,,,,,,,,,,,,,,,,,,,,,
,3772402498.27639,40.0023975372314,540.160705566406,,,5,,,,6.47999998182058,,,,,0.000815051423182134,2.8658013777433E-7,0.135941629898437,0.000240901843871095,0.00081492539025335,2.86535823350641E-7,0.000814923096496755,2.0874974760284E-7,1.9335138259589E-6,1.96281229206922E-7,1.00015465578848,10.005763053894,2,20,10,3,2.66555828269497,0.24194963658975,0.0403775237500668,172.74836730957,40.0016212463379,40.0026397705078,540.160705566406,540.160705566406,,,24.7589893341064,0,1,,,,,,1,1,1,40.0024223327637,0,40.0021310286088,,,,,,,,,,,,,,,,,,,,,,,,,,,,,,,,,
,3772402521.2834,40.0019035339355,520.465087890625,,,5,,,,6.47999998182058,,,,,0.00081546730461755,2.68075929304322E-7,0.1734492803354,0.000224257885273233,0.000815341132322861,2.68034451546772E-7,0.000815337396306543,1.96018083366429E-7,2.4682466636793E-6,1.82809677559286E-7,1.00015474785913,10.005763053894,2,20,10,3,2.66676302312736,0.243762677909244,0.0403775237500668,172.74836730957,40.0010223388672,40.0024147033691,520.465087890625,520.465087890625,,,24.7721271514893,0,1,,,,,,1,1,1,40.0017929077148,0,40.0015296936035,,,,,,,,,,,,,,,,,,,,,,,,,,,,,,,,,
,3772402541.78372,40.0210361480713,500.393035888672,,,5,,,,6.47999998182058,,,,,0.000815727024499218,4.33924245414503E-7,0.201097191678984,0.000265974561414209,0.000815600845854508,4.33857124954412E-7,0.00081559582226699,3.75865039817296E-7,2.86259658709493E-6,2.16696739054492E-7,1.00015470636814,10.005763053894,2,20,10,3,2.66749818315545,0.245070024521625,0.0403775237500668,172.74836730957,40.0160179138184,40.0212860107422,500.393035888672,500.393035888672,,,24.7603073120117,0,1,,,,,,1,1,1,40.0207862854004,0,40.0192886352539,,,,,,,,,,,,,,,,,,,,,,,,,,,,,,,,,
,3772402564.87536,40.007381439209,480.248107910156,,,5,,,,6.47999998182058,,,,,0.00081666104054082,3.58395514722141E-7,0.190665480548289,0.000272310052986865,0.000816534759678021,3.58340095775264E-7,0.000816530238587935,2.81083914709928E-7,2.71721069724051E-6,2.22259886465299E-7,1.00015465460754,10.005763053894,2,20,10,3,2.67060088855088,0.244806971145239,0.0403775237500668,172.74836730957,40.0046501159668,40.0088653564453,480.248107910156,480.248107910156,,,24.7852077484131,0,1,,,,,,1,1,1,40.0067138671875,0,40.0063331604004,,,,,,,,,,,,,,,,,,,,,,,,,,,,,,,,,
,3772402586.41285,40.0025978088379,460.163879394531,,,5,,,,6.47999998182058,,,,,0.00081744848611253,3.87137532494222E-7,0.186497197542402,0.000277159790893091,0.000817322075027848,3.8707766514327E-7,0.000817317745283986,3.13958068160037E-7,2.66037059999571E-6,2.2640549969023E-7,1.00015466495834,10.005763053894,2,20,10,3,2.6731975320253,0.244791131081512,0.0403775237500668,172.74836730957,40.0010833740234,40.0038719177246,460.163879394531,460.163879394531,,,24.7731075286865,0,1,,,,,,1,1,1,40.0017852783203,0,40.001916885376,,,,,,,,,,,,,,,,,,,,,,,,,,,,,,,,,
,3772402608.48653,40.000825881958,440.456115722656,,,5,,,,6.47999998182058,,,,,0.000818291982599417,4.73794499727401E-7,0.180308532820995,0.000195759380220953,0.000818165413623612,4.7372121575805E-7,0.000818161362289537,4.45998309398817E-7,2.57474395308455E-6,1.59678734566259E-7,1.00015469851658,10.005763053894,2,20,10,3,2.67598605447295,0.244698247942988,0.0403775237500668,172.74836730957,40.0002593994141,40.0012474060059,440.456115722656,440.456115722656,,,24.7728900909424,0,1,,,,,,1,1,1,40.0006790161133,0,40.0006329218546,,,,,,,,,,,,,,,,,,,,,,,,,,,,,,,,,
,3772402629.08764,40.0028438568115,420.141204833984,,,5,,,,6.47999998182058,,,,,0.000818856354657137,3.94057200155375E-7,0.178313068438158,0.000305410847911904,0.00081872962275069,3.93996213121519E-7,0.000818725657859805,3.04551573299654E-7,2.54800539988338E-6,2.49962707528148E-7,1.00015479091378,10.005763053894,2,20,10,3,2.67784400339435,0.244715501776551,0.0403775237500668,172.74836730957,40.002254486084,40.0030364990234,420.141204833984,420.141204833984,,,24.7736968994141,0,1,,,,,,1,1,1,40.0029411315918,0,40.0026758367365,,,,,,,,,,,,,,,,,,,,,,,,,,,,,,,,,
,3772402651.98724,40.0097484588623,400.251281738281,,,5,,,,6.47999998182058,,,,,0.000819747384369227,3.37054925086304E-7,0.16313364583158,0.000223295352093345,0.000819620725422054,3.37002846820774E-7,0.000819617403232088,2.83057925457993E-7,2.3336367463679E-6,1.82891032040183E-7,1.00015453360712,10.005763053894,2,20,10,3,2.68082639866334,0.244214431179347,0.0403775237500668,172.74836730957,40.0044975280762,40.0124015808105,400.251281738281,400.251281738281,,,24.7604541778564,0,1,,,,,,1,1,1,40.0084762573242,0,40.0077387491862,,,,,,,,,,,,,,,,,,,,,,,,,,,,,,,,,
,3772402672.57607,40.0198001861572,380.252075195313,,,5,,,,6.47999998182058,,,,,0.000820203344702636,3.51063226130233E-7,0.163825816889192,0.00021857813317056,0.000820076426011829,3.51008902424607E-7,0.000820073073707362,3.01881170972291E-7,2.34484125148447E-6,1.7909496976109E-7,1.0001547644668,10.005763053894,2,20,10,3,2.68231832449688,0.244325128755829,0.0403775237500668,172.74836730957,40.0180931091309,40.0204048156738,380.252075195313,380.252075195313,,,24.7610054016113,0,1,,,,,,1,1,1,40.0203514099121,0,40.019388961792,,,,,,,,,,,,,,,,,,,,,,,,,,,,,,,,,
,3772402694.27623,40.0116767883301,360.204284667969,,,5,,,,6.47999998182058,,,,,0.000820865369128508,3.2889775219313E-7,0.155744033302454,0.000257102236778163,0.000820738464987916,3.28846905259937E-7,0.000820735432828054,2.52270506856133E-7,2.23096644283993E-6,2.10949943042391E-7,1.00015462189967,10.005763053894,2,20,10,3,2.68452154157448,0.244086175626924,0.0403775237500668,172.74836730957,40.0050849914551,40.0139236450195,360.204284667969,360.204284667969,,,24.7615375518799,0,1,,,,,,1,1,1,40.0105781555176,0,40.0092700958252,,,,,,,,,,,,,,,,,,,,,,,,,,,,,,,,,
,3772402716.29666,40.0030212402344,340.107940673828,,,5,,,,6.47999998182058,,,,,0.000821504494243837,2.36836948723535E-7,0.148570580960339,0.000170624672728353,0.000821377440011688,2.36800319420986E-7,0.000821374678588866,1.90921403279505E-7,2.1298669418916E-6,1.40083578793753E-7,1.00015468434603,10.005763053894,2,20,10,3,2.68664600452816,0.243882145954621,0.0403775237500668,172.74836730957,40.0019950866699,40.0038528442383,340.107940673828,340.107940673828,,,24.7740650177002,0,1,,,,,,1,1,1,40.0029640197754,0,40.0026958465576,,,,,,,,,,,,,,,,,,,,,,,,,,,,,,,,,
,3772402737.95686,40.022777557373,320.193725585937,,,5,,,,6.47999998182058,,,,,0.000821972320113444,2.37633864895774E-7,0.137861261681883,0.000135463039638619,0.000821845204154943,2.37597115414351E-7,0.000821842825129686,2.09961469366526E-7,1.9774668987787E-6,1.11214075703886E-7,1.0001546714124,10.005763053894,2,20,10,3,2.68822526169875,0.243461067235994,0.0403775237500668,172.74836730957,40.0162162780762,40.023193359375,320.193725585937,320.193725585937,,,24.7863864898682,0,1,,,,,,1,1,1,40.0223007202148,0,40.020656932484,,,,,,,,,,,,,,,,,,,,,,,,,,,,,,,,,
,3772402759.79879,40.0140361785889,300.145935058594,,,5,,,,6.47999998182058,,,,,0.000822385664668702,2.48345639464833E-7,0.133698109989385,0.000142952503249196,0.000822258530968967,2.48307247380298E-7,0.000822256292333055,2.1878569096299E-7,1.91871570088247E-6,1.17427895031067E-7,1.00015461523955,10.005763053894,2,20,10,3,2.6895984897597,0.243330450628857,0.0403775237500668,172.74836730957,40.0090217590332,40.0154037475586,300.145935058594,300.145935058594,,,24.7606983184814,0,1,,,,,,1,1,1,40.0134544372559,0,40.0122039101341,,,,,,,,,,,,,,,,,,,,,,,,,,,,,,,,,
,3772402782.90011,40.0254058837891,280.110321044922,,,5,,,,6.47999998182058,,,,,0.000822903202723251,2.4448839391336E-7,0.12247814816129,0.000133624442628179,0.000822775938155197,2.44450583014408E-7,0.000822774058304407,2.18392084687823E-7,1.75880313290816E-6,1.09822515368164E-7,1.00015467706596,10.005763053894,2,20,10,3,2.69134243559359,0.242898721532446,0.0403775237500668,172.74836730957,40.0169448852539,40.0263175964355,280.110321044922,280.110321044922,,,24.785228729248,0,1,,,,,,1,1,1,40.0245590209961,0,40.0227310874245,,,,,,,,,,,,,,,,,,,,,,,,,,,,,,,,,
,3772402805.8702,40.0220699310303,260.208251953125,,,5,,,,6.47999998182058,,,,,0.000823293259537074,2.57282428391326E-7,0.113942311205887,0.000154629294238596,0.000823166060359249,2.57242678140755E-7,0.000823164432630248,2.23601299250803E-7,1.63700332551984E-6,1.27185904998867E-7,1.00015452432255,10.005763053894,2,20,10,3,2.69265797792772,0.242555399590026,0.0403775237500668,172.74836730957,40.0129661560059,40.0255737304687,260.208251953125,260.208251953125,,,24.7855682373047,0,1,,,,,,1,1,1,40.0202102661133,0,40.0187705993652,,,,,,,,,,,,,,,,,,,,,,,,,,,,,,,,,
,3772402826.40042,40.0276489257812,240.184768676758,,,5,,,,6.47999998182058,,,,,0.000823450237919213,2.42665547365154E-7,0.110794709279836,0.000186600200449253,0.000823322804206414,2.42627993460565E-7,0.000823321264872658,1.87826695831735E-7,1.59208504816069E-6,1.53588656949766E-7,1.00015477976821,10.005763053894,2,20,10,3,2.69318841394171,0.242395898596351,0.0403775237500668,172.74836730957,40.0225219726562,40.0277938842773,240.184768676758,240.184768676758,,,24.7734699249268,0,1,,,,,,1,1,1,40.0275497436523,0,40.0261173248291,,,,,,,,,,,,,,,,,,,,,,,,,,,,,,,,,
,3772402848.34664,40.0126762390137,220.112701416016,,,5,,,,6.47999998182058,,,,,0.000823975817898832,2.35051438686475E-7,0.107702355875138,0.000119952236495481,0.00082384848966635,2.35015116401791E-7,0.000823847034132306,2.13284543401907E-7,1.54863711987999E-6,9.8700600216957E-8,1.00015455297191,10.005763053894,2,20,10,3,2.69492415457949,0.242347436293652,0.0403775237500668,172.74836730957,40.0059432983398,40.0151214599609,220.112701416016,220.112701416016,,,24.7734909057617,0,1,,,,,,1,1,1,40.0115928649902,0,40.0102600097656,,,,,,,,,,,,,,,,,,,,,,,,,,,,,,,,,
,3772402870.08826,40.0040512084961,200.113494873047,,,5,,,,6.47999998182058,,,,,0.000824648807044782,2.28169974025942E-7,0.10153609523659,0.000123667844296155,0.000824521322183519,2.28134700565004E-7,0.000824520027488633,2.04130104674653E-7,1.46116576798267E-6,1.01864331183192E-7,1.00015461681564,10.005763053894,2,20,10,3,2.69715501804834,0.242197456280367,0.0403775237500668,172.74836730957,40.0024299621582,40.0052185058594,200.113494873047,200.113494873047,,,24.7613525390625,0,1,,,,,,1,1,1,40.0036926269531,0,40.0034603118896,,,,,,,,,,,,,,,,,,,,,,,,,,,,,,,,,
,3772402891.55407,40.0016708374023,180.247863769531,,,5,,,,6.47999998182058,,,,,0.00082606467624564,1.91640527891988E-7,0.103677421447912,9.13054268337431E-5,0.000825936873082695,1.91610878560262E-7,0.00082593552088606,1.76193278226986E-7,1.49454216832245E-6,7.53037681013597E-8,1.00015473720463,10.005763053894,2,20,10,3,2.70178045358903,0.242656846672905,0.0403775237500668,172.74836730957,40.0011558532715,40.002197265625,180.247863769531,180.247863769531,,,24.7487087249756,0,1,,,,,,1,1,1,40.0013694763184,0,40.0015619451349,,,,,,,,,,,,,,,,,,,,,,,,,,,,,,,,,
,3772402913.64952,40.0139961242676,160.200088500977,,,5,,,,6.47999998182058,,,,,0.000829717704482771,2.2223866568093E-7,0.124217912408636,7.57957452854225E-5,0.000829589438834402,2.2220430991584E-7,0.000829587489186277,2.13188283512336E-7,1.79855808572508E-6,6.26538994655438E-8,1.00015461340558,10.005763053894,2,20,10,3,2.71364447793071,0.244644424150168,0.0403775237500668,172.74836730957,40.0083961486816,40.0151672363281,160.200088500977,160.200088500977,,,24.7480812072754,0,1,,,,,,1,1,1,40.0131874084473,0,40.0118990811435,,,,,,,,,,,,,,,,,,,,,,,,,,,,,,,,,
,3772402934.15424,40.0231380462646,140.200881958008,,,5,,,,6.47999998182058,,,,,0.000821794711450321,1.89353584321142E-7,0.144220149620867,7.84231278249278E-5,0.000821667515176182,1.8932427642942E-7,0.000821664912186113,1.78080142546908E-7,2.0682306419392E-6,6.4273979774063E-8,1.00015480260786,10.005763053894,2,20,10,3,2.68765078910816,0.243188956840078,0.0403775237500668,172.74836730957,40.0199432373047,40.0232849121094,140.200881958008,140.200881958008,,,24.761402130127,0,1,,,,,,1,1,1,40.0232391357422,0,40.0221547213468,,,,,,,,,,,,,,,,,,,,,,,,,,,,,,,,,
,3772402957.16012,40.0105381011963,120.08024597168,,,5,,,,6.47999998182058,,,,,0.000791402487294566,1.58181511355427E-7,0.11811871826654,0.000116867483112014,0.000791280179305156,1.58157065055439E-7,0.000791278497822762,1.2833289377188E-7,1.63127083981891E-6,9.24355213274951E-8,1.00015456976253,10.005763053894,2,20,10,3,2.58836405953914,0.232960440292967,0.0403775237500668,172.74836730957,40.0055351257324,40.0127906799316,120.08024597168,120.08024597168,,,24.7359275817871,0,1,,,,,,1,1,1,40.0096817016602,0,40.0087898254394,,,,,,,,,,,,,,,,,,,,,,,,,,,,,,,,,
,3772402977.65845,40.0029182434082,100.238891601562,,,5,,,,6.47999998182058,,,,,0.000759816448815816,1.04981122725623E-7,0.0975613743844095,6.53231159551854E-5,0.000759698938864963,1.04964886795759E-7,0.000759697837523541,9.25147836213263E-8,1.2935898142548E-6,4.95846979575934E-8,1.0001546796301,10.005763053894,2,20,10,3,2.48514207746214,0.222718305590875,0.0403775237500668,172.74836730957,40.0016479492188,40.00390625,100.238891601562,100.238891601562,,,24.7604999542236,0,1,,,,,,1,1,1,40.0024185180664,0,40.0024105072022,,,,,,,,,,,,,,,,,,,,,,,,,,,,,,,,,
,3772402999.29708,40.0064697265625,80.1304016113281,,,5,,,,6.47999998182058,,,,,0.000735288114892709,8.93864198975776E-8,0.0764908688286852,4.88941157133742E-5,0.000735174363162816,8.93725914952326E-8,0.000735173708022665,8.18435789172895E-8,9.81470355281202E-7,3.59038814138964E-8,1.00015472755253,10.005763053894,2,20,10,3,2.40499929190126,0.214592315457095,0.0403775237500668,172.74836730957,40.0040893554687,40.0073165893555,80.1304016113281,80.1304016113281,,,24.7612972259521,0,1,,,,,,1,1,1,40.005916595459,0,40.0055366516113,,,,,,,,,,,,,,,,,,,,,,,,,,,,,,,,,
,3772403021.25598,40.0028743743897,60.0826187133789,,,5,,,,6.47999998182058,,,,,0.000717715109980117,9.92164769199469E-8,0.0692817801063104,5.65176321866089E-5,0.000717604112682812,9.92011327246903E-8,0.000717603588059384,9.05509334435689E-8,8.67723218798466E-7,4.05141109535922E-8,1.00015467762147,10.005763053894,2,20,10,3,2.3475505651198,0.209117959130021,0.0403775237500668,172.74836730957,40.0014152526855,40.0041313171387,60.0826187133789,60.0826187133789,,,24.7601585388184,0,1,,,,,,1,1,1,40.0024528503418,0,40.0022759871049,,,,,,,,,,,,,,,,,,,,,,,,,,,,,,,,,
,3772403044.26886,40.0010395050049,40.2291259765625,,,5,,,,6.47999998182058,,,,,0.000706181170182416,9.48190174543411E-8,0.0487466111185082,5.07144372942172E-5,0.000706071934995258,9.48043504346653E-8,0.000706071679453122,8.77983513286302E-8,6.00718066446351E-7,3.57675043204475E-8,1.00015470829776,10.005763053894,2,20,10,3,2.30990125518506,0.204880420754406,0.0403775237500668,172.74836730957,40.0004653930664,40.0014877319336,40.2291259765625,40.2291259765625,,,24.7481250762939,0,1,,,,,,1,1,1,40.0009460449219,0,40.000793838501,,,,,,,,,,,,,,,,,,,,,,,,,,,,,,,,,
,3772403064.86388,40.0007400512695,20.1813488006592,,,5,,,,6.47999998182058,,,,,0.000699253282304073,7.55981343753844E-8,0.0481307097982135,3.45933015824989E-5,0.000699145128337442,7.55864415620512E-8,0.00069914488165594,7.16262631686721E-8,5.87309355194457E-7,2.41451562949073E-8,1.00015469458664,10.005763053894,2,20,10,3,2.28724555917182,0.20279680791002,0.0403775237500668,172.74836730957,40.0004081726074,40.0010299682617,20.1813488006592,20.1813488006592,,,24.7481536865234,0,1,,,,,,1,1,1,40.0009307861328,0,40.0007823944092,,,,,,,,,,,,,,,,,,,,,,,,,,,,,,,,,
,3772403086.66074,40.014289855957,0.133570894598961,,,5,,,,6.47999998182058,,,,,0.000696564932250177,6.59998540412029E-8,0.0393691957665627,2.59739636876175E-5,0.000696457241257536,6.59896502691398E-8,0.000696457076846007,6.3473189281188E-8,4.78551117543733E-7,1.80496034615127E-8,1.00015462685469,10.005763053894,2,20,10,3,2.27848594185351,0.20161971313652,0.0403775237500668,172.74836730957,40.0095863342285,40.0148887634277,0.133570894598961,0.133570894598961,,,24.7473335266113,0,1,,,,,,1,1,1,40.0138473510742,0,40.0127086639404,,,,,,,,,,,,,,,,,,,,,,,,,,,,,,,,,