File: Experimental_Data/AC_Suceptibillity_FieldScans/HFCd_Down_5K.dat
[Header]
; MPMS3 Data File (default extension .dat)
; Copyright (c) 2007, Quantum Design, Inc. All rights reserved.
TITLE,HFCd_Down_5K
FILEOPENTIME,3772374008.94082,07/15/2019,5:40 pm
BYAPP,SQUID AC,0.9.1.0
INFO,MPMS3 Measurement Release 1.1.16 Build 347, MultiVu Release 2.3.3.2,APPNAME
INFO,0,MOMENT_UNITS
INFO,Cu2OSeO3,SAMPLE_MATERIAL
INFO,,SAMPLE_COMMENT
INFO,,SAMPLE_MASS
INFO,,SAMPLE_VOLUME
INFO,,SAMPLE_MOLECULAR_WEIGHT
INFO,,SAMPLE_SIZE
INFO,,SAMPLE_SHAPE
INFO,Quartz,SAMPLE_HOLDER
INFO,Standard,SAMPLE_HOLDER_DETAIL
INFO,64.77,SAMPLE_OFFSET
DATATYPE,COMMENT,1
DATATYPE,TIME,2
STARTUPAXIS,X,2
STARTUPAXIS,Y1,5
FIELDGROUP, VSM,2,3,4,5,6,8,9,10,11,14,15
FIELDGROUP, DC, 2,3,4,14,56,57,58,59,60,61,62,63,64,65,66,67,68,69
FIELDGROUP, AC, 2,3,4,11,16,17,18,19,20,21,22,23,24,25,26,27,28,29,30
STARTUPGROUP, All
[Data]
Comment,Time Stamp (sec),Temperature (K),Magnetic Field (Oe),Moment (emu),M. Std. Err. (emu),Transport Action,Averaging Time (sec),Frequency (Hz),Peak Amplitude (mm),Center Position (mm),Lockin Signal' (V),Lockin Signal (V),Range,M. Quad. Signal (emu),AC Moment (emu),AC M. Std Err. (emu),AC Phase (deg),AC Phase Std. Err. (deg),AC Susceptibility (emu/Oe),AC Suscept. Std Err. (emu/Oe),AC X' (emu/Oe),AC X' Std Err. (emu/Oe),AC X'' (emu/Oe),AC X'' Std Err. (emu/Oe),AC Drive (Oe),AC Frequency (Hz),AC Averaging Time (sec),AC Cycles,AC Range,AC Measure Type,AC Signal' (V),AC Signal'' (V),AC Trim Coil Ratio,AC Trim Coil Phase,Min. Temperature (K),Max. Temperature (K),Min. Field (Oe),Max. Field (Oe),Mass (grams),Motor Lag (deg),Pressure (Torr),Measure Count,Measurement Number,SQUID Status (code),Motor Status (code),Measure Status (code),Motor Current (amps),Motor Temp. (C),Temp. Status (code),Field Status (code),Chamber Status (code),Chamber Temp (K),Redirection State,Average Temp (K),Rotation Angle (deg),Rotator state,DC Moment Fixed Ctr (emu),DC Moment Err Fixed Ctr (emu),DC Moment Free Ctr (emu),DC Moment Err Free Ctr (emu),DC Fixed Fit,DC Free Fit,DC Calculated Center (mm),DC Calculated Center Err (mm),DC Scan Length (mm),DC Scan Time (s),DC Number of Points,DC Squid Drift,DC Min V (V),DC Max V (V),DC Scans per Measure,Map 01,Map 02,Map 03,Map 04,Map 05,Map 06,Map 07,Map 08,Map 09,Map 10,Map 11,Map 12,Map 13,Map 14,Map 15,Map 16
,3772374221.54797,4.99998807907105,-1000.05749511719,,,5,,,,6.47999998182058,,,,,0.000137791292603888,4.25575954071691E-7,0.00837450144239593,0.00229401452558146,0.000137769186023185,4.25507676686404E-7,0.000137769184551568,2.84943331764414E-7,2.01367055787664E-8,3.16012785504094E-7,1.00016046099525,10.005763053894,2,20,1,3,0.450706410832614,0.0401732671760171,0.0403775237500668,172.74836730957,4.9990816116333,5.00143194198608,-1000.05749511719,-1000.05749511719,,,11.7382316589355,0,1,,,,,,1,1,1,5.00004529953003,0,5.00005945792565,,,,,,,,,,,,,,,,,,,,,,,,,,,,,,,,,
,3772374246.05457,5.00019836425781,-980.009704589844,,,5,,,,6.47999998182058,,,,,0.000192373379521419,2.16635679085747E-7,0.0661415981962712,0.000739842834810535,0.000192342514195239,2.16600920997523E-7,0.000192342386036169,1.63322297023213E-7,2.22037968110873E-7,1.42273631682181E-7,1.0001604706391,10.005763053894,2,20,1,3,0.62918488628823,0.0567076478302624,0.0403775237500668,172.74836730957,4.99934101104736,5.00090551376343,-980.009704589844,-980.009704589844,,,11.758376121521,0,1,,,,,,1,1,1,5.00002574920654,0,5.00005789597829,,,,,,,,,,,,,,,,,,,,,,,,,,,,,,,,,
,3772374270.45671,4.99995374679565,-959.9619140625,,,5,,,,6.47999998182058,,,,,0.000264248967382811,5.08554174375069E-7,0.00695743384089464,0.00157435696774001,0.000264206603197506,5.0847264337234E-7,0.000264206601249607,2.92480739101538E-7,3.20826415693843E-8,4.159320212639E-7,1.0001603449149,10.005763053894,2,20,1,3,0.86434553448184,0.0769837307063602,0.0403775237500668,172.74836730957,4.99871492385864,5.00121593475342,-959.9619140625,-959.9619140625,,,11.7702522277832,0,1,,,,,,1,1,1,4.99998903274536,0,5.00009932884803,,,,,,,,,,,,,,,,,,,,,,,,,,,,,,,,,
,3772374294.75346,5.00000596046448,-939.938415527344,,,5,,,,6.47999998182058,,,,,0.000351491377480306,2.8580262684133E-7,0.0540316355412855,0.000522038638196202,0.000351435025819466,2.85756806506247E-7,0.000351434869552932,2.19119730862002E-7,3.31413702343267E-7,1.83421634524427E-7,1.00016034730946,10.005763053894,2,20,1,3,1.14962827268529,0.103320017639215,0.0403775237500668,172.74836730957,4.99937009811401,5.00071477890015,-939.938415527344,-939.938415527344,,,11.787091255188,0,1,,,,,,1,1,1,5.00028133392334,0,4.99997953573863,,,,,,,,,,,,,,,,,,,,,,,,,,,,,,,,,
,3772374318.95768,4.99972939491272,-919.975708007812,,,5,,,,6.47999998182058,,,,,0.000451132617769504,3.49144135683883E-7,0.0108326011346866,0.000544995515766242,0.000451060245544727,3.49088124797346E-7,0.000451060237483061,2.47886613580163E-7,8.52795047054835E-8,2.45794112383284E-7,1.00016044913178,10.005763053894,2,20,1,3,1.47562796685043,0.131465252143042,0.0403775237500668,172.74836730957,4.99860763549805,5.00145196914673,-919.975708007812,-919.975708007812,,,11.7983865737915,0,1,,,,,,1,1,1,4.99963855743408,0,4.99998466173808,,,,,,,,,,,,,,,,,,,,,,,,,,,,,,,,,
,3772374343.46182,4.99988913536072,-899.903564453125,,,5,,,,6.47999998182058,,,,,0.000521233382375381,6.53609013171185E-7,0.0351324909417929,0.00118145542309365,0.000521149760530923,6.53504154209569E-7,0.000521149662558206,2.18946614006968E-7,3.19557360933501E-7,6.15735381299505E-7,1.00016045645761,10.005763053894,2,20,1,3,1.7048611509538,0.152579864796858,0.0403775237500668,172.74836730957,4.99928426742554,5.0006685256958,-899.903564453125,-899.903564453125,,,11.8143424987793,0,1,,,,,,1,1,1,4.99970149993897,0,5.00009588400523,,,,,,,,,,,,,,,,,,,,,,,,,,,,,,,,,
,3772374366.55714,4.99997639656067,-880.329406738281,,,5,,,,6.47999998182058,,,,,0.000568012376442815,4.64915727994325E-7,0.056762341008354,0.000756264955987452,0.000567921247538487,4.64841139371516E-7,0.000567920968840766,1.77731865313969E-7,5.62633662015722E-7,4.29521441728148E-7,1.00016046045948,10.005763053894,2,20,1,3,1.85780645420971,0.166935842684388,0.0403775237500668,172.74836730957,4.99953031539917,5.00081348419189,-880.329406738281,-880.329406738281,,,11.8301000595093,0,1,,,,,,1,1,1,4.99991893768311,0,5.00003631909688,,,,,,,,,,,,,,,,,,,,,,,,,,,,,,,,,
,3772374389.58428,5.00000023841858,-860.220825195313,,,5,,,,6.47999998182058,,,,,0.000604269541395865,3.88069797740033E-7,0.0727979869808237,0.000485632282434415,0.000604172594923072,3.88007537448042E-7,0.000604172107254864,2.5391931421939E-7,7.67640081684944E-7,2.93385123997194E-7,1.00016046155289,10.005763053894,2,20,1,3,1.97634624360925,0.178102231787838,0.0403775237500668,172.74836730957,4.99916982650757,5.00091600418091,-860.220825195313,-860.220825195313,,,11.8489856719971,0,1,,,,,,1,1,1,5.00009298324585,0,5.00005269050598,,,,,,,,,,,,,,,,,,,,,,,,,,,,,,,,,
,3772374415.75994,5.00006771087646,-840.270263671875,,,5,,,,6.47999998182058,,,,,0.000633226967034655,5.27340132481569E-7,0.0548221908980038,0.00074883819455976,0.000633125372795057,5.27255526609491E-7,0.000633125082975826,2.30658906396953E-7,6.05791823560757E-7,4.74125362367394E-7,1.00016046464723,10.005763053894,2,20,10,3,2.07111674029111,0.185943134446805,0.0403775237500668,172.74836730957,4.99938249588013,5.00052738189697,-840.270263671875,-840.270263671875,,,11.8785390853882,0,1,,,,,,1,1,1,5.00017070770264,0,4.99992931590361,,,,,,,,,,,,,,,,,,,,,,,,,,,,,,,,,
,3772374445.93896,4.99989461898804,-820.307495117187,,,5,,,,6.47999998182058,,,,,0.000658379328677281,5.79695188372104E-7,0.0683671387023317,0.000382863932299171,0.000658273704245016,5.79602187312546E-7,0.000658273235619423,5.22050913229076E-7,7.85472845384887E-7,2.51796623357373E-7,1.00016045670909,10.005763053894,2,20,10,3,2.15334059484807,0.19379202257173,0.0403775237500668,172.74836730957,4.99905872344971,5.00091600418091,-820.307495117187,-820.307495117187,,,11.9060049057007,0,1,,,,,,1,1,1,4.99970579147339,0,4.99991122881571,,,,,,,,,,,,,,,,,,,,,,,,,,,,,,,,,
,3772374469.06838,5.0001323223114,-800.235412597656,,,5,,,,6.47999998182058,,,,,0.000679319531129117,4.47205347791825E-7,0.0725772982453865,0.000505717370346818,0.000679210539836855,4.47133597331947E-7,0.000679209994919434,2.86282035430971E-7,8.60364465885573E-7,3.43469139883786E-7,1.00016046761037,10.005763053894,2,20,10,3,2.22181741452191,0.200071238642651,0.0403775237500668,172.74836730957,4.99914932250977,5.00110960006714,-800.235412597656,-800.235412597656,,,11.9197864532471,0,1,,,,,,1,1,1,5.00012874603271,0,5.00009743372599,,,,,,,,,,,,,,,,,,,,,,,,,,,,,,,,,
,3772374493.38741,4.99956488609314,-780.381958007812,,,5,,,,6.47999998182058,,,,,0.000697122530148852,4.01889679519289E-7,0.0782804486632784,0.000517503573619148,0.000697010700645701,4.01825210044788E-7,0.000697010050110608,1.7702764549326E-7,9.52291667180582E-7,3.60728030735969E-7,1.00016044158726,10.005763053894,2,20,10,3,2.28002747673938,0.205493030944736,0.0403775237500668,172.74836730957,4.99844646453857,5.00137805938721,-780.381958007812,-780.381958007812,,,11.9380588531494,0,1,,,,,,1,1,1,4.99922752380371,0,4.99993507067362,,,,,,,,,,,,,,,,,,,,,,,,,,,,,,,,,
,3772374517.75418,4.99988913536072,-760.261291503906,,,5,,,,6.47999998182058,,,,,0.000714233126912369,3.64111735700658E-7,0.0997540202222753,0.000294844367924388,0.000714118541980811,3.64053320994392E-7,0.000714117459660636,2.9705146686468E-7,1.24330552956331E-6,2.10464359359459E-7,1.00016045645761,10.005763053894,2,20,10,3,2.33591402200213,0.211361947509063,0.0403775237500668,172.74836730957,4.99909591674805,5.00084781646729,-760.261291503906,-760.261291503906,,,11.9570932388306,0,1,,,,,,1,1,1,4.99981927871704,0,4.99998104572296,,,,,,,,,,,,,,,,,,,,,,,,,,,,,,,,,
,3772374542.01503,4.99997568130493,-740.23779296875,,,5,,,,6.47999998182058,,,,,0.000728428365788067,3.25891156293441E-7,0.12135636274964,0.000259846965803452,0.000728311500613925,3.25838872049004E-7,0.000728309866934468,2.65307699632303E-7,1.54261220160637E-6,1.89163408337825E-7,1.00016046042668,10.005763053894,2,20,10,3,2.38226170640703,0.216409869503388,0.0403775237500668,172.74836730957,4.99932956695557,5.00130176544189,-740.23779296875,-740.23779296875,,,11.976149559021,0,1,,,,,,1,1,1,5.00013828277588,0,5.00003579946665,,,,,,,,,,,,,,,,,,,,,,,,,,,,,,,,,
,3772374566.58451,5.00015640258789,-720.190063476563,,,5,,,,6.47999998182058,,,,,0.000741093159455487,4.54190410222126E-7,0.100355953072981,0.000413217294613233,0.000740974256268952,4.54117538564387E-7,0.000740973119652266,3.35426162301228E-7,1.29784672274766E-6,3.06124204328321E-7,1.00016046871471,10.005763053894,2,20,10,3,2.42376470099329,0.219232106161325,0.0403775237500668,172.74836730957,4.99928140640259,5.00077342987061,-720.190063476563,-720.190063476563,,,11.9919242858887,0,1,,,,,,1,1,1,5.00019454956055,0,4.99999141693115,,,,,,,,,,,,,,,,,,,,,,,,,,,,,,,,,
,3772374589.63834,4.99985980987549,-700.312255859375,,,5,,,,6.47999998182058,,,,,0.000753031356546448,3.20709961343917E-7,0.116479232563473,0.000316529021737224,0.000752910548199571,3.20658510046544E-7,0.000752908992359428,2.14557541445695E-7,1.53062552217322E-6,2.38300108002594E-7,1.00016045511272,10.005763053894,2,20,10,3,2.46274949420461,0.223404334423119,0.0403775237500668,172.74836730957,4.99843072891235,5.00023698806763,-700.312255859375,-700.312255859375,,,12.0155019760132,0,1,,,,,,1,1,1,4.99987745285034,0,4.99952693780263,,,,,,,,,,,,,,,,,,,,,,,,,,,,,,,,,
,3772374614.38228,4.99974226951599,-680.252319335938,,,5,,,,6.47999998182058,,,,,0.000763294916015942,5.39463276747204E-7,0.100896192863063,0.000659499775953937,0.000763172465205897,5.3937673390008E-7,0.000763171281900409,1.9376598196861E-7,1.34392370772443E-6,5.03370644063059E-7,1.00016044972222,10.005763053894,2,20,10,3,2.49638087391212,0.225716715233984,0.0403775237500668,172.74836730957,4.99692106246948,5.00016403198242,-680.252319335938,-680.252319335938,,,12.0244169235229,0,1,,,,,,1,1,1,4.99992227554321,0,4.99920570850372,,,,,,,,,,,,,,,,,,,,,,,,,,,,,,,,,
,3772374638.42577,4.99639058113098,-660.277404785156,,,5,,,,6.47999998182058,,,,,0.000773443016024639,2.7975219014109E-7,0.0989911829717096,0.000288079812614434,0.000773318967529413,2.79707322144994E-7,0.00077331781334203,1.69137221720158E-7,1.33607958519743E-6,2.22775192268595E-7,1.00016041051679,10.005763053894,2,20,10,3,2.52958164753368,0.228579465160411,0.0403775237500668,172.74836730957,4.99516773223877,5.00115394592285,-660.277404785156,-660.277404785156,,,12.0107946395874,0,1,,,,,,1,1,1,4.99761343002319,0,4.99854358037313,,,,,,,,,,,,,,,,,,,,,,,,,,,,,,,,,
,3772374662.67098,4.99907088279724,-640.25390625,,,5,,,,6.47999998182058,,,,,0.000782881463739533,2.90488217772867E-7,0.10397685675268,0.000326335947411004,0.000782755805259238,2.90441592185624E-7,0.000782754516344213,1.38188087741275E-7,1.4204963132535E-6,2.55461094645994E-7,1.0001605334377,10.005763053894,2,20,10,3,2.56043392513485,0.231536778821183,0.0403775237500668,172.74836730957,4.99749183654785,5.00009441375732,-640.25390625,-640.25390625,,,11.9888210296631,0,1,,,,,,1,1,1,4.99941110610962,0,4.99904445807139,,,,,,,,,,,,,,,,,,,,,,,,,,,,,,,,,
,3772374687.09796,4.99946856498718,-620.327575683594,,,5,,,,6.47999998182058,,,,,0.000791677117144056,4.8910751934361E-7,0.100655676822439,0.000359862878024125,0.000791550123082478,4.89029060905082E-7,0.000791548901621504,3.97589038380703E-7,1.39057314644316E-6,2.84732117909474E-7,1.0001604371699,10.005763053894,2,20,10,3,2.58921745503081,0.233932781944377,0.0403775237500668,172.74836730957,4.99864482879639,5.00032424926758,-620.327575683594,-620.327575683594,,,11.9756212234497,0,1,,,,,,1,1,1,4.99949359893799,0,4.99955224990845,,,,,,,,,,,,,,,,,,,,,,,,,,,,,,,,,
,3772374710.26329,4.99964427947998,-600.316223144531,,,5,,,,6.47999998182058,,,,,0.000800677895156879,2.70465407723791E-7,0.110733822284068,0.000244033970600223,0.000800549450817469,2.70422019801084E-7,0.000800547955706767,1.87003615008292E-7,1.5471967775522E-6,1.95340002987428E-7,1.00016044522831,10.005763053894,2,20,10,3,2.61861688530393,0.23699694482877,0.0403775237500668,172.74836730957,4.99876499176025,5.00066375732422,-600.316223144531,-600.316223144531,,,11.9771299362183,0,1,,,,,,1,1,1,4.99965333938599,0,4.99960557619731,,,,,,,,,,,,,,,,,,,,,,,,,,,,,,,,,
,3772374734.62752,4.99963974952698,-580.244140625,,,5,,,,6.47999998182058,,,,,0.000809113971047766,3.16000148439666E-7,0.0939437849852975,0.000201595568653837,0.000808984173565403,3.15949455922714E-7,0.000808983086136742,2.70665549596078E-7,1.32643279926391E-6,1.62985333572416E-7,1.00016044502056,10.005763053894,2,20,10,3,2.64628078547597,0.23866167414805,0.0403775237500668,172.74836730957,4.99890041351318,5.00135183334351,-580.244140625,-580.244140625,,,11.9724922180176,0,1,,,,,,1,1,1,4.99967527389526,0,4.99981168600229,,,,,,,,,,,,,,,,,,,,,,,,,,,,,,,,,
,3772374758.94266,4.99969387054443,-560.196350097656,,,5,,,,6.47999998182058,,,,,0.000817331959698278,3.0074011703454E-7,0.0779544012182418,0.000310395170812487,0.00081720084186408,3.00691871774662E-7,0.000817200085493274,1.61468381297972E-7,1.11185122516513E-6,2.53660331136665E-7,1.0001604475026,10.005763053894,2,20,10,3,2.67322930251918,0.240282345353616,0.0403775237500668,172.74836730957,4.99931335449219,5.0007791519165,-560.196350097656,-560.196350097656,,,11.970211982727,0,1,,,,,,1,1,1,4.99994897842407,0,4.99988249937693,,,,,,,,,,,,,,,,,,,,,,,,,,,,,,,,,
,3772374782.28425,5.00013470649719,-540.318603515625,,,5,,,,6.47999998182058,,,,,0.000826010240804482,2.25147098257916E-7,0.0857994105658211,0.000160039576402155,0.000825877714090945,2.25110975213043E-7,0.000825876788095151,1.82258744400362E-7,1.23673672279774E-6,1.32123810310521E-7,1.00016046771971,10.005763053894,2,20,10,3,2.70158356465602,0.243146047691257,0.0403775237500668,172.74836730957,4.99955034255981,5.00087690353394,-540.318603515625,-540.318603515625,,,11.9797782897949,0,1,,,,,,1,1,1,5.00007152557373,0,5.00017485251793,,,,,,,,,,,,,,,,,,,,,,,,,,,,,,,,,
,3772374807.61359,5.00007510185242,-520.210083007812,,,5,,,,6.47999998182058,,,,,0.000835859077455041,3.94393543697016E-7,0.11690425717391,0.00029662401815648,0.000835724972858815,3.94330267496089E-7,0.000835723233261927,3.0672683939558E-7,1.70518213025914E-6,2.47820511374533E-7,1.00016046498619,10.005763053894,2,20,10,3,2.73366539943221,0.247470427245809,0.0403775237500668,172.74836730957,4.99925661087036,5.00064277648926,-520.210083007812,-520.210083007812,,,11.9853897094727,0,1,,,,,,1,1,1,5.00013208389282,0,5.00003707408905,,,,,,,,,,,,,,,,,,,,,,,,,,,,,,,,,
,3772374830.78423,4.99987721443176,-500.210906982422,,,5,,,,6.47999998182058,,,,,0.000844357490423189,5.91119719143651E-7,0.112203134502852,0.000565850786427712,0.000844222030008359,5.91024885707249E-7,0.000844220411215572,3.4800010900556E-7,1.65325087194461E-6,4.77709472019746E-7,1.0001604559109,10.005763053894,2,20,10,3,2.76148364856185,0.249700838995305,0.0403775237500668,172.74836730957,4.99916791915894,5.00089550018311,-500.210906982422,-500.210906982422,,,11.9941101074219,0,1,,,,,,1,1,1,4.99981832504272,0,5.00002769629161,,,,,,,,,,,,,,,,,,,,,,,,,,,,,,,,,
,3772374855.26086,4.99982070922852,-480.320983886719,,,5,,,,6.47999998182058,,,,,0.000852718044064252,4.3835656897827E-7,0.111736150274174,0.000261564132104836,0.000852581244573393,4.38286244495438E-7,0.000852579623331621,3.77405274127566E-7,1.66267195403222E-6,2.2284544234651E-7,1.00016045331953,10.005763053894,2,20,10,3,2.78883283952715,0.252091194739188,0.0403775237500668,172.74836730957,4.99882173538208,5.00144863128662,-480.320983886719,-480.320983886719,,,12.0028162002563,0,1,,,,,,1,1,1,4.99993276596069,0,4.99993199568528,,,,,,,,,,,,,,,,,,,,,,,,,,,,,,,,,
,3772374879.44746,5.00012993812561,-460.236755371094,,,5,,,,6.47999998182058,,,,,0.00086147621755847,3.75332249744189E-7,0.105079252244708,0.000226137379061653,0.000861338099414367,3.75272073743157E-7,0.000861336650868595,3.20840522874846E-7,1.57967503798947E-6,1.94654792422085E-7,1.00016035299518,10.005763053894,2,20,10,3,2.81751009687626,0.254292478674126,0.0403775237500668,172.74836730957,4.99928712844849,5.00077247619629,-460.236755371094,-460.236755371094,,,12.0088987350464,0,1,,,,,,1,1,1,5.00022459030151,0,5.00005288918813,,,,,,,,,,,,,,,,,,,,,,,,,,,,,,,,,
,3772374903.44114,5.00007295608521,-439.921844482422,,,5,,,,6.47999998182058,,,,,0.00087032889968875,2.27395273177398E-7,0.0909619251798546,0.000194691955931961,0.000870189264866016,2.27358790074663E-7,0.000870188168242243,1.51636696629933E-7,1.38149892060798E-6,1.69405819437752E-7,1.00016046488778,10.005763053894,2,20,10,3,2.84653050163911,0.256142381807709,0.0403775237500668,172.74836730957,4.99907922744751,5.0012526512146,-439.921844482422,-439.921844482422,,,12.0205726623535,0,1,,,,,,1,1,1,5.00006151199341,0,5.00005417603713,,,,,,,,,,,,,,,,,,,,,,,,,,,,,,,,,
,3772374928.18035,4.99992728233337,-419.861907958984,,,5,,,,6.47999998182058,,,,,0.000879414677980975,2.89538948015771E-7,0.0913438993260547,0.000261297006747404,0.000879273591316998,2.89492496568814E-7,0.000879272473919304,1.76130664419152E-7,1.40178290731675E-6,2.29747458355719E-7,1.00016045820706,10.005763053894,2,20,10,3,2.87624901385428,0.258773795691472,0.0403775237500668,172.74836730957,4.9987301826477,5.00083112716675,-419.861907958984,-419.861907958984,,,12.0300855636597,0,1,,,,,,1,1,1,4.99983215332031,0,4.99986716111501,,,,,,,,,,,,,,,,,,,,,,,,,,,,,,,,,
,3772374951.61016,5.00006794929504,-399.971984863281,,,5,,,,6.47999998182058,,,,,0.000888796930765242,4.10976127748267E-7,0.0872153609097479,0.000228057097115983,0.000888654333151446,4.10910191184902E-7,0.000888653303610833,3.5753591216387E-7,1.35270484349603E-6,2.02522237625308E-7,1.00016046465816,10.005763053894,2,20,10,3,2.9069577763536,0.261263238053495,0.0403775237500668,172.74836730957,4.99892377853394,5.00094890594482,-399.971984863281,-399.971984863281,,,12.0392398834229,0,1,,,,,,1,1,1,5.00021266937256,0,5.00003888056828,,,,,,,,,,,,,,,,,,,,,,,,,,,,,,,,,
,3772374975.73077,5.00012516975403,-380.009216308594,,,5,,,,6.47999998182058,,,,,0.0008982915508964,4.85270120447194E-7,0.0950497051296884,0.000280903006735797,0.000898147530446188,4.85192318511785E-7,0.000898146294573122,4.14533376993775E-7,1.48996347551071E-6,2.52138186915386E-7,1.0001603527765,10.005763053894,2,20,10,3,2.93797938876805,0.264393149250431,0.0403775237500668,172.74836730957,4.99915742874146,5.00134801864624,-380.009216308594,-380.009216308594,,,12.0488376617432,0,1,,,,,,1,1,1,5.00017881393433,0,5.00021223227183,,,,,,,,,,,,,,,,,,,,,,,,,,,,,,,,,
,3772375000.00121,4.99997425079346,-359.912841796875,,,5,,,,6.47999998182058,,,,,0.000905445507506766,8.11289284848016E-7,0.115681986405694,0.000340788402634321,0.000905300242702943,8.11159125961777E-7,0.000905298397480604,7.50412471585955E-7,1.82782850859925E-6,3.07993912471225E-7,1.00016046036107,10.005763053894,2,20,10,3,2.9612852721332,0.267501448217217,0.0403775237500668,172.74836730957,4.99947357177734,5.00067186355591,-359.912841796875,-359.912841796875,,,12.0572338104248,0,1,,,,,,1,1,1,4.99993896484375,0,4.99997043609619,,,,,,,,,,,,,,,,,,,,,,,,,,,,,,,,,
,3772375023.28359,5.0000262260437,-339.901519775391,,,5,,,,6.47999998182058,,,,,0.00090459957985903,1.83564938777374E-6,0.216089664810865,0.00115059851837675,0.000904454448615748,1.83535488169192E-6,0.000904448016128771,1.5122947487036E-6,3.41112027740036E-6,1.03994814043483E-6,1.0001604627447,10.005763053894,2,20,10,3,2.95804994024543,0.272372396925007,0.0403775237500668,172.74836730957,4.99914216995239,5.00077056884766,-339.901519775391,-339.901519775391,,,12.0707626342773,0,1,,,,,,1,1,1,5.00014019012451,0,5.00013311704,,,,,,,,,,,,,,,,,,,,,,,,,,,,,,,,,
,3772375046.43734,5.00005674362183,-319.938751220703,,,5,,,,6.47999998182058,,,,,0.000879156507024613,4.47832750002145E-6,0.417938548111015,0.00214216810316599,0.000879015456561582,4.47760900432423E-6,0.000878992071194851,4.06527333108638E-6,6.41183676907224E-6,1.87684179918374E-6,1.00016046414426,10.005763053894,2,20,10,3,2.87390470458759,0.274776373206528,0.0403775237500668,172.74836730957,4.99939823150635,5.00111722946167,-319.938751220703,-319.938751220703,,,12.0793266296387,0,1,,,,,,1,1,1,4.99999523162842,0,5.00015735626221,,,,,,,,,,,,,,,,,,,,,,,,,,,,,,,,,
,3772375071.79887,5.0000958442688,-299.878814697266,,,5,,,,6.47999998182058,,,,,0.000829472218631781,3.80323998979652E-6,0.458523123761446,0.0027070363365788,0.000829339232898499,3.80263023259485E-6,0.000829312676014457,3.07075803265102E-6,6.63691392224169E-6,2.24286463941844E-6,1.00016035143161,10.005763053894,2,20,10,3,2.71130981491299,0.261110128609875,0.0403775237500668,172.74836730957,4.99934577941895,5.00138711929321,-299.878814697266,-299.878814697266,,,12.0855808258057,0,1,,,,,,1,1,1,5.00007724761963,0,5.0001882314682,,,,,,,,,,,,,,,,,,,,,,,,,,,,,,,,,
,3772375096.07871,5.00000166893005,-279.867462158203,,,5,,,,6.47999998182058,,,,,0.000774547259939233,2.85930752019141E-6,0.406502355367469,0.00213922153372127,0.000774422994772095,2.85884878468839E-6,0.000774403504078671,2.33105859364351E-6,5.49433366806738E-6,1.65504749379438E-6,1.00016046161849,10.005763053894,2,20,10,3,2.53199976599565,0.241467239922643,0.0403775237500668,172.74836730957,4.99910020828247,5.00172424316406,-279.867462158203,-279.867462158203,,,12.0918960571289,0,1,,,,,,1,1,1,4.99995756149292,0,5.00011253356934,,,,,,,,,,,,,,,,,,,,,,,,,,,,,,,,,
,3772375120.56699,4.99996733665466,-259.953247070313,,,5,,,,6.47999998182058,,,,,0.000733500964236681,1.02303155995124E-6,0.200778546648185,0.000736851734360135,0.000733383285522428,1.02286743059833E-6,0.000733378782647177,8.68758401133791E-7,2.56995070307526E-6,5.39922791738126E-7,1.00016046004398,10.005763053894,2,20,10,3,2.39862812905452,0.220008852731128,0.0403775237500668,172.74836730957,4.99928522109985,5.00087404251099,-259.953247070313,-259.953247070313,,,12.1054811477661,0,1,,,,,,1,1,1,4.9999418258667,0,5.00002392133077,,,,,,,,,,,,,,,,,,,,,,,,,,,,,,,,,
,3772375146.20868,4.99999022483826,-239.905471801758,,,5,,,,6.47999998182058,,,,,0.000708632133316819,4.42280752099429E-7,0.143979386753206,0.000234960450946833,0.000708518524788968,4.42209845259646E-7,0.000708516287735524,4.09811573116771E-7,1.78044449706619E-6,1.66144580965247E-7,1.00016034658781,10.005763053894,2,20,10,3,2.31751712519955,0.21020255673791,0.0403775237500668,172.74836730957,4.99960565567017,5.00084066390991,-239.905471801758,-239.905471801758,,,12.1106052398682,0,1,,,,,,1,1,1,4.99993896484375,0,5.00014177958171,,,,,,,,,,,,,,,,,,,,,,,,,,,,,,,,,
,3772375169.29191,5.00009989738464,-220.015548706055,,,5,,,,6.47999998182058,,,,,0.000690200564468212,2.79863574980472E-7,0.117926696192639,0.000192496572782347,0.000690089828428694,2.79818673562689E-7,0.000690088366741387,2.46341665014527E-7,1.42034817881888E-6,1.32718778446208E-7,1.00016046612333,10.005763053894,2,20,10,3,2.25733429667634,0.203660719247872,0.0403775237500668,172.74836730957,4.9994068145752,5.00073051452637,-220.015548706055,-220.015548706055,,,12.1208553314209,0,1,,,,,,1,1,1,5.00016021728516,0,5.00005253156026,,,,,,,,,,,,,,,,,,,,,,,,,,,,,,,,,
,3772375193.50896,4.99994707107544,-199.919204711914,,,5,,,,6.47999998182058,,,,,0.00067579993117841,2.98719798760258E-7,0.0968890703429963,9.80477063132761E-5,0.00067569151031693,2.98671874135782E-7,0.000675690544215609,2.91311861477206E-7,1.14261629090426E-6,6.58960375323555E-8,1.00016045911459,10.005763053894,2,20,10,3,2.21031243320541,0.198552355940789,0.0403775237500668,172.74836730957,4.99898099899292,5.00186395645142,-199.919204711914,-199.919204711914,,,12.1301326751709,0,1,,,,,,1,1,1,5.00007295608521,0,5.00009965896606,,,,,,,,,,,,,,,,,,,,,,,,,,,,,,,,,
,3772375218.05458,5.0001494884491,-180.005004882813,,,5,,,,6.47999998182058,,,,,0.000664195338657043,2.70141724985562E-7,0.0759027508547217,8.50206512778042E-5,0.0006640887733957,2.70098382730886E-7,0.000664088190667754,2.6419525003567E-7,8.79753280211678E-7,5.61605396379872E-8,1.00016046839762,10.005763053894,2,20,10,3,2.17243201349146,0.194300878192242,0.0403775237500668,172.74836730957,4.99923992156982,5.00126838684082,-180.005004882813,-180.005004882813,,,12.1384353637695,0,1,,,,,,1,1,1,4.99996614456177,0,5.00013344104473,,,,,,,,,,,,,,,,,,,,,,,,,,,,,,,,,
,3772375243.64888,5.00002479553223,-160.017944335938,,,5,,,,6.47999998182058,,,,,0.000654824257374865,2.01447273903489E-7,0.0640389928496479,6.88542499399585E-5,0.000654719199378077,2.01414954320308E-7,0.000654718790429447,1.96349011385662E-7,7.31773784286736E-7,4.48893033107575E-8,1.0001604626791,10.005763053894,2,20,10,3,2.14182385003316,0.191070199259406,0.0403775237500668,172.74836730957,4.99934005737305,5.00099182128906,-160.017944335938,-160.017944335938,,,12.1482210159302,0,1,,,,,,1,1,1,4.99996566772461,0,5.00006650044368,,,,,,,,,,,,,,,,,,,,,,,,,,,,,,,,,
,3772375269.26876,5.00000166893005,-139.958023071289,,,5,,,,6.47999998182058,,,,,0.000647065463117155,2.27957584003293E-7,0.057187022933606,9.76279593717125E-5,0.000646961650603598,2.27921011428911E-7,0.00064696132834967,2.1904031557251E-7,6.45733506407211E-7,6.30025999834397E-8,1.00016046161849,10.005763053894,2,20,10,3,2.11647152240302,0.188507725987463,0.0403775237500668,172.74836730957,4.99934911727905,5.00072574615479,-139.958023071289,-139.958023071289,,,12.157187461853,0,1,,,,,,1,1,1,4.99989700317383,0,5.00015735626221,,,,,,,,,,,,,,,,,,,,,,,,,,,,,,,,,
,3772375293.50803,5.00007629394531,-119.873817443848,,,5,,,,6.47999998182058,,,,,0.000640701392333957,2.59053263257876E-7,0.0451423444459929,7.67423486636489E-5,0.000640598598653651,2.59011700934703E-7,0.00064059839982502,2.54352715601323E-7,5.04716400508645E-7,4.89055956647112E-8,1.00016046504086,10.005763053894,2,20,10,3,2.09569745141302,0.186168099334131,0.0403775237500668,172.74836730957,4.998619556427,5.00137186050415,-119.873817443848,-119.873817443848,,,12.1632747650146,0,1,,,,,,1,1,1,5.00005102157593,0,5.00005567990817,,,,,,,,,,,,,,,,,,,,,,,,,,,,,,,,,
,3772375318.04199,5.00008749961853,-99.9474563598633,,,5,,,,6.47999998182058,,,,,0.000635684737650788,2.14499467085195E-7,0.0366389479322464,6.10239381580232E-5,0.000635582748512453,2.14465052831516E-7,0.000635582618560498,2.10966703122304E-7,4.06436247838529E-7,3.85786088361235E-8,1.00016046555476,10.005763053894,2,20,10,3,2.07931843039908,0.184357475037965,0.0403775237500668,172.74836730957,4.99910688400269,5.00105333328247,-99.9474563598633,-99.9474563598633,,,12.1685304641724,0,1,,,,,,1,1,1,5.00003242492676,0,5.00005223200871,,,,,,,,,,,,,,,,,,,,,,,,,,,,,,,,,
,3772375341.29804,5.00003266334534,-79.8511123657227,,,5,,,,6.47999998182058,,,,,0.000631707681469111,2.0995811092318E-7,0.0285599350815655,4.75660467480127E-5,0.000631606331997045,2.09924425811661E-7,0.0006316062535303,2.07798337807463E-7,3.14833574920136E-7,2.98012643492009E-8,1.00016046303992,10.005763053894,2,20,10,3,2.06633810840337,0.182868266570322,0.0403775237500668,172.74836730957,4.99915266036987,5.00180339813232,-79.8511123657227,-79.8511123657227,,,12.1845541000366,0,1,,,,,,1,1,1,5.00003242492676,0,5.00017809867859,,,,,,,,,,,,,,,,,,,,,,,,,,,,,,,,,
,3772375366.74458,5.00014543533325,-59.8640480041504,,,5,,,,6.47999998182058,,,,,0.000628541138765588,1.62197230442869E-7,0.0194348367141579,3.34420803510877E-5,0.000628440366023962,1.6217122568584E-7,0.000628440329870441,1.60828230004605E-7,2.13168155976655E-7,2.08275508409778E-8,1.00016035370589,10.005763053894,2,20,10,3,2.05601192758216,0.181580182976665,0.0403775237500668,172.74836730957,4.9993314743042,5.00180339813232,-59.8640480041504,-59.8640480041504,,,12.187596321106,0,1,,,,,,1,1,1,5.00009441375732,0,5.00023833910624,,,,,,,,,,,,,,,,,,,,,,,,,,,,,,,,,
,3772375389.9005,4.99998950958252,-40.0591278076172,,,5,,,,6.47999998182058,,,,,0.000626617399847948,1.74567325323054E-7,0.0167918276386132,4.21265727285922E-5,0.00062651686828662,1.74539318558837E-7,0.000626516841380353,1.7255782805742E-7,1.83614974850787E-7,2.6225363659805E-8,1.00016046106085,10.005763053894,2,20,10,3,2.04973026479384,0.180886432168153,0.0403775237500668,172.74836730957,4.9994592666626,5.00110292434692,-40.0591278076172,-40.0591278076172,,,12.1971960067749,0,1,,,,,,1,1,1,4.99996709823608,0,5.00009846687317,,,,,,,,,,,,,,,,,,,,,,,,,,,,,,,,,
,3772375414.16207,5.00009107589722,-19.9142074584961,,,5,,,,6.47999998182058,,,,,0.000625398435234419,1.80344297366987E-7,0.0123612707740355,4.64988464372456E-5,0.000625298096325946,1.80315362932669E-7,0.000625298081773431,1.77980775736399E-7,1.34904858418874E-7,2.89218529456494E-8,1.00016046571877,10.005763053894,2,20,10,3,2.04575960028839,0.180332251339735,0.0403775237500668,172.74836730957,4.99891376495361,5.00131225585937,-19.9142074584961,-19.9142074584961,,,12.2060384750366,0,1,,,,,,1,1,1,5.00006532669067,0,5.00006385949942,,,,,,,,,,,,,,,,,,,,,,,,,,,,,,,,,
,3772375438.70506,5.00009322166443,0.0971424728631973,,,5,,,,6.47999998182058,,,,,0.00062517828446961,2.32721697771264E-7,0.0102999880673647,7.05010595428184E-5,0.000625077980820618,2.3268435988531E-7,0.000625077970720362,2.28504462126905E-7,1.12369458338152E-7,4.39058324523133E-8,1.00016046581718,10.005763053894,2,20,10,3,2.04504863499833,0.180151824228222,0.0403775237500668,172.74836730957,4.99937438964844,5.00079250335693,0.0971424728631973,0.0971424728631973,,,12.2180089950562,0,1,,,,,,1,1,1,5.00008821487427,0,5.0000817378362,,,,,,,,,,,,,,,,,,,,,,,,,,,,,,,,,