File: Experimental_Data/AC_Suceptibillity_FieldScans/HFCd_Down_40K.dat
[Header]
; MPMS3 Data File (default extension .dat)
; Copyright (c) 2007, Quantum Design, Inc. All rights reserved.
TITLE,HFCd_Down_40K
FILEOPENTIME,3772400407.94307,07/16/2019,1:00 am
BYAPP,SQUID AC,0.9.1.0
INFO,MPMS3 Measurement Release 1.1.16 Build 347, MultiVu Release 2.3.3.2,APPNAME
INFO,0,MOMENT_UNITS
INFO,Cu2OSeO3,SAMPLE_MATERIAL
INFO,,SAMPLE_COMMENT
INFO,,SAMPLE_MASS
INFO,,SAMPLE_VOLUME
INFO,,SAMPLE_MOLECULAR_WEIGHT
INFO,,SAMPLE_SIZE
INFO,,SAMPLE_SHAPE
INFO,Quartz,SAMPLE_HOLDER
INFO,Standard,SAMPLE_HOLDER_DETAIL
INFO,64.77,SAMPLE_OFFSET
DATATYPE,COMMENT,1
DATATYPE,TIME,2
STARTUPAXIS,X,2
STARTUPAXIS,Y1,5
FIELDGROUP, VSM,2,3,4,5,6,8,9,10,11,14,15
FIELDGROUP, DC, 2,3,4,14,56,57,58,59,60,61,62,63,64,65,66,67,68,69
FIELDGROUP, AC, 2,3,4,11,16,17,18,19,20,21,22,23,24,25,26,27,28,29,30
STARTUPGROUP, All
[Data]
Comment,Time Stamp (sec),Temperature (K),Magnetic Field (Oe),Moment (emu),M. Std. Err. (emu),Transport Action,Averaging Time (sec),Frequency (Hz),Peak Amplitude (mm),Center Position (mm),Lockin Signal' (V),Lockin Signal (V),Range,M. Quad. Signal (emu),AC Moment (emu),AC M. Std Err. (emu),AC Phase (deg),AC Phase Std. Err. (deg),AC Susceptibility (emu/Oe),AC Suscept. Std Err. (emu/Oe),AC X' (emu/Oe),AC X' Std Err. (emu/Oe),AC X'' (emu/Oe),AC X'' Std Err. (emu/Oe),AC Drive (Oe),AC Frequency (Hz),AC Averaging Time (sec),AC Cycles,AC Range,AC Measure Type,AC Signal' (V),AC Signal'' (V),AC Trim Coil Ratio,AC Trim Coil Phase,Min. Temperature (K),Max. Temperature (K),Min. Field (Oe),Max. Field (Oe),Mass (grams),Motor Lag (deg),Pressure (Torr),Measure Count,Measurement Number,SQUID Status (code),Motor Status (code),Measure Status (code),Motor Current (amps),Motor Temp. (C),Temp. Status (code),Field Status (code),Chamber Status (code),Chamber Temp (K),Redirection State,Average Temp (K),Rotation Angle (deg),Rotator state,DC Moment Fixed Ctr (emu),DC Moment Err Fixed Ctr (emu),DC Moment Free Ctr (emu),DC Moment Err Free Ctr (emu),DC Fixed Fit,DC Free Fit,DC Calculated Center (mm),DC Calculated Center Err (mm),DC Scan Length (mm),DC Scan Time (s),DC Number of Points,DC Squid Drift,DC Min V (V),DC Max V (V),DC Scans per Measure,Map 01,Map 02,Map 03,Map 04,Map 05,Map 06,Map 07,Map 08,Map 09,Map 10,Map 11,Map 12,Map 13,Map 14,Map 15,Map 16
,3772400555.39329,39.9149780273438,-1000.17895507813,,,5,,,,6.47999998182058,,,,,1.69344352721773E-5,3.40667542943217E-7,-0.659257134170973,0.00898892935134554,1.69318222999061E-5,3.40614978164462E-7,1.69307014864756E-5,3.04521653505408E-7,-1.94816763784075E-7,1.52594645700003E-7,1.00015432315701,10.005763053894,2,20,1,3,0.0554457085136574,0.00428522489173969,0.0403775237500668,172.74836730957,39.9004173278809,39.9225921630859,-1000.17895507813,-1000.17895507813,,,24.3893508911133,0,1,,,,,,1,1,1,39.9119148254395,0,39.9095706939697,,,,,,,,,,,,,,,,,,,,,,,,,,,,,,,,,
,3772400575.81831,39.899507522583,-980.070373535156,,,5,,,,6.47999998182058,,,,,1.81018868358989E-5,3.74789066167896E-7,-1.08616963153106,0.0132460322720652,1.80990857906878E-5,3.74731072151665E-7,1.8095833692241E-5,2.87886420617639E-7,-3.43088095733178E-7,2.39884941711439E-7,1.00015476169589,10.005763053894,2,20,1,3,0.0593006488348832,0.00413764195751302,0.0403775237500668,172.74836730957,39.8988151550293,39.9030723571777,-980.070373535156,-980.070373535156,,,24.3604679107666,0,1,,,,,,1,1,1,39.899829864502,0,39.9003665924072,,,,,,,,,,,,,,,,,,,,,,,,,,,,,,,,,
,3772400598.86651,39.902868270874,-960.107604980469,,,5,,,,6.47999998182058,,,,,2.01476301659893E-5,3.50315413673257E-7,-0.896591858641401,0.0143604198094809,2.01445094677117E-5,3.50261152765197E-7,2.01420430754127E-5,1.97777543543796E-7,-3.15218087907898E-7,2.89079432693138E-7,1.00015491557551,10.005763053894,2,20,1,3,0.0659868436047101,0.00482219749470984,0.0403775237500668,172.74836730957,39.8983345031738,39.924186706543,-960.107604980469,-960.107604980469,,,24.319164276123,0,1,,,,,,1,1,1,39.9054832458496,0,39.9099918712269,,,,,,,,,,,,,,,,,,,,,,,,,,,,,,,,,
,3772400621.90458,39.9468517303467,-940.059814453125,,,5,,,,6.47999998182058,,,,,2.27174562681456E-5,3.305710844522E-7,-0.329406606934682,0.0088021329398032,2.2713936068215E-5,3.3051986056979E-7,2.27135606800697E-5,2.63163506857934E-7,-1.30586920283773E-7,1.99970865101163E-7,1.00015497974107,10.005763053894,2,20,1,3,0.0743460744895467,0.00617191976082644,0.0403775237500668,172.74836730957,39.9405899047852,39.9593849182129,-940.059814453125,-940.059814453125,,,24.3051834106445,0,1,,,,,,1,1,1,39.949348449707,0,39.9506065368652,,,,,,,,,,,,,,,,,,,,,,,,,,,,,,,,,
,3772400643.78937,39.9624805450439,-920.206359863281,,,5,,,,6.47999998182058,,,,,2.53874032882008E-5,3.06152643336326E-7,0.207620650329157,0.00532849016496817,2.53834744892103E-5,3.06105265028966E-7,2.53833078349477E-5,2.7471166465507E-7,9.19809799643779E-8,1.35033086985723E-7,1.00015477782571,10.005763053894,2,20,1,3,0.0830156734893975,0.00767394892757292,0.0403775237500668,172.74836730957,39.9617347717285,39.9688835144043,-920.206359863281,-920.206359863281,,,24.3180446624756,0,1,,,,,,1,1,1,39.9629821777344,0,39.9645473480225,,,,,,,,,,,,,,,,,,,,,,,,,,,,,,,,,
,3772400665.50349,39.9726467132568,-900.097900390625,,,5,,,,6.47999998182058,,,,,3.02668137770357E-5,3.71013362085979E-7,0.246948089789067,0.00858845171129243,3.02621296669742E-5,3.7095594383789E-7,3.02618485837689E-5,2.64728108219595E-7,1.30431107492553E-7,2.59860233562457E-7,1.00015478454798,10.005763053894,2,20,1,3,0.0989649677806102,0.00921466444928586,0.0403775237500668,172.74836730957,39.9703102111816,39.9730072021484,-900.097900390625,-900.097900390625,,,24.3310546875,0,1,,,,,,1,1,1,39.9722862243652,0,39.9717365264893,,,,,,,,,,,,,,,,,,,,,,,,,,,,,,,,,
,3772400686.06864,39.9797554016113,-880.475036621094,,,5,,,,6.47999998182058,,,,,3.85410015987241E-5,3.7323146612094E-7,0.49587512044897,0.00569508478147338,3.85350332675083E-5,3.73173668738475E-7,3.85335900811838E-5,3.0199172814385E-7,3.33503198282542E-7,2.1922496019483E-7,1.00015488065559,10.005763053894,2,20,1,3,0.125967530009273,0.0122784630975566,0.0403775237500668,172.74836730957,39.9763565063477,39.9917030334473,-880.475036621094,-880.475036621094,,,24.3324203491211,0,1,,,,,,1,1,1,39.981861114502,0,39.9841121673584,,,,,,,,,,,,,,,,,,,,,,,,,,,,,,,,,
,3772400709.0182,39.9976940155029,-860.269470214844,,,5,,,,6.47999998182058,,,,,4.97460010512831E-5,2.75250538935027E-7,0.435644025286804,0.00293528289477765,4.97383080367726E-5,2.75207972570992E-7,4.97368703072878E-5,2.33432463779066E-7,3.78177731909989E-7,1.45769383001614E-7,1.00015466980712,10.005763053894,2,20,1,3,0.162606803876522,0.0156737166089099,0.0403775237500668,172.74836730957,39.9970016479492,39.9984817504883,-860.269470214844,-860.269470214844,,,24.3588600158691,0,1,,,,,,1,1,1,39.9978408813477,0,39.9979400634766,,,,,,,,,,,,,,,,,,,,,,,,,,,,,,,,,
,3772400732.0369,39.9983024597168,-840.197387695313,,,5,,,,6.47999998182058,,,,,7.03199949962964E-5,4.52740605914876E-7,0.376825656255036,0.00363948708639627,7.03091183397897E-5,4.52670578832857E-7,7.03075977370998E-5,3.73588574293074E-7,4.62409079399597E-7,2.55621263001617E-7,1.00015469766601,10.005763053894,2,20,1,3,0.22988083183018,0.0219151481616262,0.0403775237500668,172.74836730957,39.9980926513672,39.9990234375,-840.197387695313,-840.197387695313,,,24.3970699310303,0,1,,,,,,1,1,1,39.998462677002,0,39.9984504699707,,,,,,,,,,,,,,,,,,,,,,,,,,,,,,,,,
,3772400752.58706,40.0050468444824,-820.404602050781,,,5,,,,6.47999998182058,,,,,0.000102910360675906,3.20090026818058E-7,0.266648574845117,0.00132953683934572,0.000102894434974422,3.20040491881228E-7,0.000102893320694318,2.89469358253837E-7,4.78858227222242E-7,1.36504238306693E-7,1.00015477709255,10.005763053894,2,20,1,3,0.336482478646983,0.0314177812381211,0.0403775237500668,172.74836730957,40.0025634765625,40.0050506591797,-820.404602050781,-820.404602050781,,,24.3982257843018,0,1,,,,,,1,1,1,40.0050506591797,0,40.0040832519531,,,,,,,,,,,,,,,,,,,,,,,,,,,,,,,,,
,3772400775.59951,40.0203552246094,-800.368957519531,,,5,,,,6.47999998182058,,,,,0.000150049516938283,3.88594583578851E-7,0.20330021727065,0.00142296754904497,0.000150026294386122,3.88534442378992E-7,0.000150025349961389,3.24736480042885E-7,5.32330906457667E-7,2.13319552418694E-7,1.00015478988038,10.005763053894,2,20,1,3,0.490662809689712,0.0452560023939945,0.0403775237500668,172.74836730957,40.0165748596191,40.0203819274902,-800.368957519531,-800.368957519531,,,24.3994922637939,0,1,,,,,,1,1,1,40.020336151123,0,40.019213104248,,,,,,,,,,,,,,,,,,,,,,,,,,,,,,,,,
,3772400797.2576,40.0092830657959,-780.4912109375,,,5,,,,6.47999998182058,,,,,0.000226207118790787,4.81897249279828E-7,0.157496072262238,0.00164926019328581,0.000226172146473053,4.81822746479886E-7,0.000226171291990813,3.04983057601465E-7,6.21706872096607E-7,3.73012725790263E-7,1.0001546269878,10.005763053894,2,20,1,3,0.739753950428005,0.0676186105025692,0.0403775237500668,172.74836730957,40.0054550170898,40.0105895996094,-780.4912109375,-780.4912109375,,,24.4253692626953,0,1,,,,,,1,1,1,40.0087966918945,0,40.0078895568848,,,,,,,,,,,,,,,,,,,,,,,,,,,,,,,,,
,3772400819.15014,40.0030193328857,-760.406982421875,,,5,,,,6.47999998182058,,,,,0.000354246676316396,4.69679357677745E-7,0.195045570582928,0.000706924820017919,0.000354191888406702,4.69606716910862E-7,0.00035418983613378,3.97418733678188E-7,1.20573323424966E-6,2.50177574313574E-7,1.00015468425869,10.005763053894,2,20,1,3,1.15840737585562,0.106626960045701,0.0403775237500668,172.74836730957,40.0010299682617,40.0041618347168,-760.406982421875,-760.406982421875,,,24.4253978729248,0,1,,,,,,1,1,1,40.0025024414063,0,40.0022903442383,,,,,,,,,,,,,,,,,,,,,,,,,,,,,,,,,
,3772400840.79964,40.0008354187012,-740.371337890625,,,5,,,,6.47999998182058,,,,,0.000532116447352212,3.65843692658638E-7,0.123377543217452,0.000422826803562858,0.000532034142227322,3.65787105776266E-7,0.000532032908735396,2.88495129927297E-7,1.145651829947E-6,2.24879449395469E-7,1.00015469895324,10.005763053894,2,20,1,3,1.74025333776005,0.15795115129913,0.0403775237500668,172.74836730957,40.000186920166,40.0014343261719,-740.371337890625,-740.371337890625,,,24.4266109466553,0,1,,,,,,1,1,1,40.0005149841309,0,40.0005508422852,,,,,,,,,,,,,,,,,,,,,,,,,,,,,,,,,
,3772400862.68288,40.0006561279297,-720.359985351562,,,5,,,,6.47999998182058,,,,,0.000693279284508223,3.19024745132792E-7,0.0991646298371567,0.000244453479936726,0.000693172057206948,3.18975402590436E-7,0.000693171019011146,2.70307311157063E-7,1.19970644841746E-6,1.69349534964728E-7,1.00015469074404,10.005763053894,2,20,1,3,2.26741613509985,0.204783288960316,0.0403775237500668,172.74836730957,40.0000610351562,40.0013771057129,-720.359985351562,-720.359985351562,,,24.4398040771484,0,1,,,,,,1,1,1,40.0004920959473,0,40.0004853468675,,,,,,,,,,,,,,,,,,,,,,,,,,,,,,,,,
,3772400888.38437,40.0015926361084,-700.457946777344,,,5,,,,6.47999998182058,,,,,0.000759827475783253,4.19114860754456E-7,0.0966416681802222,0.000303821495046191,0.000759709923113642,4.19050019626272E-7,0.000759708842423297,3.49829346960101E-7,1.28141374658782E-6,2.30699689974322E-7,1.00015473362402,10.005763053894,2,20,10,3,2.48507971430974,0.224278153455221,0.0403775237500668,172.74836730957,40.000862121582,40.0017738342285,-700.457946777344,-700.457946777344,,,24.4647922515869,0,1,,,,,,1,1,1,40.0017280578613,0,40.0013139898127,,,,,,,,,,,,,,,,,,,,,,,,,,,,,,,,,
,3772400911.49325,40.0115985870361,-680.361572265625,,,5,,,,6.47999998182058,,,,,0.000788665995703834,3.84613715404887E-7,0.0839839101872446,0.000291999027955961,0.000788543981920989,3.84554212174614E-7,0.000788543134805221,3.08060317035258E-7,1.15584400464477E-6,2.30175548591449E-7,1.00015473300874,10.005763053894,2,20,10,3,2.57945344473196,0.232164990998152,0.0403775237500668,172.74836730957,40.0076446533203,40.0122451782227,-680.361572265625,-680.361572265625,,,24.4405841827393,0,1,,,,,,1,1,1,40.0111312866211,0,40.0103582902388,,,,,,,,,,,,,,,,,,,,,,,,,,,,,,,,,
,3772400932.01045,40.0031204223633,-660.410949707031,,,5,,,,6.47999998182058,,,,,0.000803066660935769,4.23063885135212E-7,0.094091746141558,0.000244439323267113,0.000802942546735841,4.22998500481389E-7,0.000802941464025787,3.74797537220431E-7,1.3186003045555E-6,1.96098285313777E-7,1.00015457419766,10.005763053894,2,20,10,3,2.62651487770917,0.236811581444991,0.0403775237500668,172.74836730957,39.9980316162109,40.0064315795898,-660.410949707031,-660.410949707031,,,24.4405574798584,0,1,,,,,,1,1,1,40.0020942687988,0,40.0011021007191,,,,,,,,,,,,,,,,,,,,,,,,,,,,,,,,,
,3772400953.70749,40.0007209777832,-640.338928222656,,,5,,,,6.47999998182058,,,,,0.000810125757009836,2.72929936529995E-7,0.0891860472286377,0.000182985052310592,0.000810000362147391,2.72887691222335E-7,0.000809999380843102,2.29175978291511E-7,1.26083809304506E-6,1.48142036555413E-7,1.00015480840294,10.005763053894,2,20,10,3,2.64962649015557,0.238609421239945,0.0403775237500668,172.74836730957,39.9999923706055,40.0027122497559,-640.338928222656,-640.338928222656,,,24.453706741333,0,1,,,,,,1,1,1,40.0012359619141,0,40.0014942169189,,,,,,,,,,,,,,,,,,,,,,,,,,,,,,,,,
,3772400975.61829,40.0029430389404,-620.49755859375,,,5,,,,6.47999998182058,,,,,0.000814198796117963,3.88085403811942E-7,0.0893612392225505,0.00018728445323222,0.000814072874702599,3.88025383748583E-7,0.000814071884586092,3.56905790868294E-7,1.26966649247867E-6,1.52256214578954E-7,1.00015468076542,10.005763053894,2,20,10,3,2.66295080670883,0.239760644165882,0.0403775237500668,172.74836730957,40.0014839172363,40.0034675598145,-620.49755859375,-620.49755859375,,,24.4786319732666,0,1,,,,,,1,1,1,40.0027046203613,0,40.0023551940918,,,,,,,,,,,,,,,,,,,,,,,,,,,,,,,,,
,3772400998.70635,40.01051902771,-600.170471191406,,,5,,,,6.47999998182058,,,,,0.000816299073747741,3.74093910396237E-7,0.0844145215266199,0.000261351487511024,0.000816172825214154,3.74036053160905E-7,0.000816171939403054,3.07311814364496E-7,1.20247624142443E-6,2.13219177880859E-7,1.00015468357888,10.005763053894,2,20,10,3,2.66984452064585,0.24009045179893,0.0403775237500668,172.74836730957,40.0067596435547,40.0115051269531,-600.170471191406,-600.170471191406,,,24.4547176361084,0,1,,,,,,1,1,1,40.0103187561035,0,40.0092128753662,,,,,,,,,,,,,,,,,,,,,,,,,,,,,,,,,
,3772401019.1837,40.0172996520996,-580.438415527344,,,5,,,,6.47999998182058,,,,,0.000818435923888788,4.47748632917957E-7,0.0855044151153779,0.000275066261984595,0.000818309278527914,4.47679347973905E-7,0.000818308367316365,3.87063018824374E-7,1.22118995269395E-6,2.24942254947582E-7,1.00015476466441,10.005763053894,2,20,10,3,2.67683249077305,0.240713259641162,0.0403775237500668,172.74836730957,40.0134239196777,40.0176429748535,-580.438415527344,-580.438415527344,,,24.4668827056885,0,1,,,,,,1,1,1,40.0169448852539,0,40.0158996582031,,,,,,,,,,,,,,,,,,,,,,,,,,,,,,,,,
,3772401042.17008,40.0067577362061,-560.244934082031,,,5,,,,6.47999998182058,,,,,0.000819631041792501,3.01689500684409E-7,0.0929958685132179,0.000154459737571812,0.000819504325075756,3.01642858840636E-7,0.000819503245624084,2.7386666933371E-7,1.33012385287191E-6,1.26433625739404E-7,1.00015462605,10.005763053894,2,20,10,3,2.6807134811356,0.241357440417202,0.0403775237500668,172.74836730957,40.0033149719238,40.0081977844238,-560.244934082031,-560.244934082031,,,24.4549980163574,0,1,,,,,,1,1,1,40.006275177002,0,40.0054950714111,,,,,,,,,,,,,,,,,,,,,,,,,,,,,,,,,
,3772401062.84303,40.0110130310059,-540.440002441406,,,5,,,,6.47999998182058,,,,,0.000820918426041122,3.65427909545586E-7,0.0980396637855288,0.000189468394082356,0.00082079144451752,3.65371384327917E-7,0.000820790242914307,3.30706809291046E-7,1.4044678102669E-6,1.55335941669126E-7,1.00015470619784,10.005763053894,2,20,10,3,2.6849064050875,0.241915929815746,0.0403775237500668,172.74836730957,40.0079154968262,40.0112342834473,-540.440002441406,-540.440002441406,,,24.4550838470459,0,1,,,,,,1,1,1,40.0109367370605,0,40.0099674571644,,,,,,,,,,,,,,,,,,,,,,,,,,,,,,,,,
,3772401085.74311,40.0047626495361,-520.428649902344,,,5,,,,6.47999998182058,,,,,0.000823393671075479,3.7806162077853E-7,0.136837597964239,0.000232352672238626,0.000823266353435742,3.78003162819812E-7,0.000823264005556353,3.26120342249218E-7,1.96617768627194E-6,1.91133234873044E-7,1.00015464939045,10.005763053894,2,20,10,3,2.69284077581841,0.244411263935965,0.0403775237500668,172.74836730957,40.0025253295898,40.0053596496582,-520.428649902344,-520.428649902344,,,24.4680004119873,0,1,,,,,,1,1,1,40.0045394897461,0,40.0038282221014,,,,,,,,,,,,,,,,,,,,,,,,,,,,,,,,,
,3772401106.33413,40.0115814208984,-500.441589355469,,,5,,,,6.47999998182058,,,,,0.000824066669959668,4.67776566670017E-7,0.130753425162691,0.000331351134733584,0.000823939180018932,4.67704197759907E-7,0.000823937034532094,3.79840760956605E-7,1.8802916605521E-6,2.72888645638007E-7,1.00015473222275,10.005763053894,2,20,10,3,2.69507145481043,0.244267115705937,0.0403775237500668,172.74836730957,40.008617401123,40.0118026733398,-500.441589355469,-500.441589355469,,,24.4679412841797,0,1,,,,,,1,1,1,40.0118026733398,0,40.0106423117898,,,,,,,,,,,,,,,,,,,,,,,,,,,,,,,,,
,3772401129.34963,40.0057067871094,-480.503112792969,,,5,,,,6.47999998182058,,,,,0.000824393263341953,4.25933266900588E-7,0.116612504734764,0.000250269266948683,0.000824265850032992,4.25867437193644E-7,0.000824264142841868,3.72667262386534E-7,1.67760417602445E-6,2.06112070503425E-7,1.00015457793011,10.005763053894,2,20,10,3,2.69620348670854,0.243641027360985,0.0403775237500668,172.74836730957,40.0024681091309,40.0074882507324,-480.503112792969,-480.503112792969,,,24.4677047729492,0,1,,,,,,1,1,1,40.0050163269043,0,40.0045984441584,,,,,,,,,,,,,,,,,,,,,,,,,,,,,,,,,
,3772401149.92034,40.0021953582764,-460.443176269531,,,5,,,,6.47999998182058,,,,,0.000825399345951244,4.69235469483326E-7,0.12400649702318,0.000340550531887798,0.000825271625906828,4.69162861266106E-7,0.000825269693002481,3.75751179707703E-7,1.78615186656785E-6,2.80935653379326E-7,1.00015476122092,10.005763053894,2,20,10,3,2.69946614075879,0.244228801032482,0.0403775237500668,172.74836730957,40.0018272399902,40.0023918151855,-460.443176269531,-460.443176269531,,,24.4684295654297,0,1,,,,,,1,1,1,40.0022811889648,0,40.002087020874,,,,,,,,,,,,,,,,,,,,,,,,,,,,,,,,,
,3772401171.66095,40.005500793457,-440.128265380859,,,5,,,,6.47999998182058,,,,,0.000825853189855096,3.93400145140541E-7,0.113043019437268,0.000228475492911761,0.000825725464007988,3.93339302163354E-7,0.000825723856889953,3.45232660871256E-7,1.62913289448408E-6,1.88494606007988E-7,1.00015468318791,10.005763053894,2,20,10,3,2.70100092049265,0.243787498854406,0.0403775237500668,172.74836730957,40.0034332275391,40.0056343078613,-440.128265380859,-440.128265380859,,,24.4679927825928,0,1,,,,,,1,1,1,40.0054321289063,0,40.0047412872314,,,,,,,,,,,,,,,,,,,,,,,,,,,,,,,,,
,3772401193.41237,40.0144386291504,-420.068359375,,,5,,,,6.47999998182058,,,,,0.000826380367112762,4.0952686743097E-7,0.109451765923597,0.000173058158215495,0.000826252600643607,4.09463550580815E-7,0.000826251093054493,3.83793310764275E-7,1.57838416730132E-6,1.42699312776355E-7,1.00015463366658,10.005763053894,2,20,10,3,2.70274410047472,0.243715589471963,0.0403775237500668,172.74836730957,40.0099334716797,40.015079498291,-420.068359375,-420.068359375,,,24.456657409668,0,1,,,,,,1,1,1,40.0143203735352,0,40.0130302429199,,,,,,,,,,,,,,,,,,,,,,,,,,,,,,,,,
,3772401215.01198,40.0054550170898,-400.166290283203,,,5,,,,6.47999998182058,,,,,0.000826887426594361,3.62755548769491E-7,0.0998855408754116,0.000163910091269693,0.000826759542525551,3.62699446023134E-7,0.000826758286180026,3.36521203786335E-7,1.44131527576061E-6,1.35293634542369E-7,1.00015468109194,10.005763053894,2,20,10,3,2.70444683342258,0.243356088596385,0.0403775237500668,172.74836730957,40.0036277770996,40.0069007873535,-400.166290283203,-400.166290283203,,,24.4564590454102,0,1,,,,,,1,1,1,40.0047645568848,0,40.0046188354492,,,,,,,,,,,,,,,,,,,,,,,,,,,,,,,,,
,3772401236.99436,40.0024738311768,-380.142791748047,,,5,,,,6.47999998182058,,,,,0.000827087702062821,3.75796638698476E-7,0.097897145359406,0.000231982431221961,0.000826959805053327,3.75738527247722E-7,0.000826958597937092,3.23148760384939E-7,1.41296558906446E-6,1.91714160979215E-7,1.00015465928176,10.005763053894,2,20,10,3,2.70511400960391,0.243263203317769,0.0403775237500668,172.74836730957,40.0011863708496,40.0030174255371,-380.142791748047,-380.142791748047,,,24.4811229705811,0,1,,,,,,1,1,1,40.0023994445801,0,40.0020162409002,,,,,,,,,,,,,,,,,,,,,,,,,,,,,,,,,
,3772401260.02187,39.9950580596924,-360.095031738281,,,5,,,,6.47999998182058,,,,,0.000827376164396142,3.49171093011945E-7,0.0846728485991006,0.000216778895935726,0.000827248219039784,3.49117097233667E-7,0.000827247315704773,2.9960342102863E-7,1.22252351401647E-6,1.79222034607363E-7,1.00015466380394,10.005763053894,2,20,10,3,2.70611725118881,0.242665482076198,0.0403775237500668,172.74836730957,39.993278503418,39.9965438842773,-360.095031738281,-360.095031738281,,,24.4674587249756,0,1,,,,,,1,1,1,39.9943046569824,0,39.9944891496138,,,,,,,,,,,,,,,,,,,,,,,,,,,,,,,,,
,3772401283.07492,40.0035095214844,-340.180786132812,,,5,,,,6.47999998182058,,,,,0.000827813073097312,3.81815453027615E-7,0.0851653659775762,0.000138242931782006,0.000827684929763824,3.81756348978019E-7,0.000827684015406935,3.64296824632009E-7,1.23028370674639E-6,1.14130335792298E-7,1.00015482139263,10.005763053894,2,20,10,3,2.7075478527893,0.242759086363551,0.0403775237500668,172.74836730957,40.0023002624512,40.0048637390137,-340.180786132812,-340.180786132812,,,24.4688701629639,0,1,,,,,,1,1,1,40.003978729248,0,40.0039322592995,,,,,,,,,,,,,,,,,,,,,,,,,,,,,,,,,
,3772401303.60401,40.0161781311035,-320.120880126953,,,5,,,,6.47999998182058,,,,,0.000827917368521357,4.66819763861313E-7,0.0858285051604168,0.000254332279557658,0.000827789298496307,4.66747551801119E-7,0.000827788369727623,4.1666404527314E-7,1.24001963338145E-6,2.10343410852254E-7,1.00015471331326,10.005763053894,2,20,10,3,2.70788987440007,0.242762752280669,0.0403775237500668,172.74836730957,40.0089225769043,40.017147064209,-320.120880126953,-320.120880126953,,,24.4562435150146,0,1,,,,,,1,1,1,40.0152931213379,0,40.013480758667,,,,,,,,,,,,,,,,,,,,,,,,,,,,,,,,,
,3772401326.60083,40.0087032318115,-300.085235595703,,,5,,,,6.47999998182058,,,,,0.000828100785736083,3.34979158566659E-7,0.0789101022357048,0.000147733606263168,0.000827972685835552,3.34927340240156E-7,0.000827971900589262,3.1186507650774E-7,1.14031764971648E-6,1.22133113016769E-7,1.00015471512856,10.005763053894,2,20,10,3,2.70852276296749,0.242431469160921,0.0403775237500668,172.74836730957,40.0081100463867,40.0093231201172,-300.085235595703,-300.085235595703,,,24.4564533233643,0,1,,,,,,1,1,1,40.0091323852539,0,40.0085878372192,,,,,,,,,,,,,,,,,,,,,,,,,,,,,,,,,
,3772401349.69783,40.0053768157959,-280.086029052734,,,5,,,,6.47999998182058,,,,,0.000828194074936946,3.58406342768773E-7,0.0737998224572731,0.000214781557630808,0.000828065991750125,3.58350913941221E-7,0.000828065304839455,3.1116486487729E-7,1.06659001405415E-6,1.77740834892846E-7,1.00015467751133,10.005763053894,2,20,10,3,2.70885317488267,0.242159237226046,0.0403775237500668,172.74836730957,40.0025024414063,40.0065803527832,-280.086029052734,-280.086029052734,,,24.4687213897705,0,1,,,,,,1,1,1,40.0049438476562,0,40.0043712615967,,,,,,,,,,,,,,,,,,,,,,,,,,,,,,,,,
,3772401371.29126,40.0208053588867,-260.159698486328,,,5,,,,6.47999998182058,,,,,0.000828145591794679,2.82969912625145E-7,0.0700607367696513,0.000133477761010826,0.000828017500964143,2.82926145138505E-7,0.000828016881931427,2.60502834411644E-7,1.01249170902435E-6,1.10387847458105E-7,1.00015469580098,10.005763053894,2,20,10,3,2.70871406441356,0.241910354100442,0.0403775237500668,172.74836730957,40.0154914855957,40.0208358764648,-260.159698486328,-260.159698486328,,,24.4441890716553,0,1,,,,,,1,1,1,40.020809173584,0,40.0189636230469,,,,,,,,,,,,,,,,,,,,,,,,,,,,,,,,,
,3772401393.24575,40.0239067077637,-240.002624511719,,,5,,,,6.47999998182058,,,,,0.000828041034103052,2.58178697460509E-7,0.0628749531762125,0.000120574287091175,0.000827913031774726,2.58138787029699E-7,0.000827912533275183,2.3810552598376E-7,9.08530839469845E-7,9.97065286987823E-8,1.00015460842312,10.005763053894,2,20,10,3,2.70840607999332,0.241481691729852,0.0403775237500668,172.74836730957,40.0143280029297,40.0265884399414,-240.002624511719,-240.002624511719,,,24.468635559082,0,1,,,,,,1,1,1,40.022216796875,0,40.020426940918,,,,,,,,,,,,,,,,,,,,,,,,,,,,,,,,,
,3772401414.06843,40.0118503570557,-220.136978149414,,,5,,,,6.47999998182058,,,,,0.000828534698515262,2.14401234470518E-7,0.0614060094672562,9.30627170608772E-5,0.00082840650713424,2.14368062184085E-7,0.000828406031372022,2.00067355237124E-7,8.87833772642655E-7,7.69851898288376E-8,1.00015474453655,10.005763053894,2,20,10,3,2.71003060608152,0.241498671386085,0.0403775237500668,172.74836730957,40.0096740722656,40.0120010375977,-220.136978149414,-220.136978149414,,,24.4681930541992,0,1,,,,,,1,1,1,40.0117454528809,0,40.0111642317338,,,,,,,,,,,,,,,,,,,,,,,,,,,,,,,,,
,3772401436.79433,40.0134449005127,-200.040634155273,,,5,,,,6.47999998182058,,,,,0.000828932424198241,2.32627495188144E-7,0.0601759569404896,9.8866686327804E-5,0.00082880430086085,2.32591539288504E-7,0.000828803843748761,2.17724979040484E-7,8.70466955428272E-7,8.18208876168949E-8,1.00015458816666,10.005763053894,2,20,10,3,2.71134037988867,0.241498063985177,0.0403775237500668,172.74836730957,40.0075950622559,40.0152893066406,-200.040634155273,-200.040634155273,,,24.4810791015625,0,1,,,,,,1,1,1,40.0126037597656,0,40.0114242553711,,,,,,,,,,,,,,,,,,,,,,,,,,,,,,,,,
,3772401457.32598,40.0124588012695,-180.15071105957,,,5,,,,6.47999998182058,,,,,0.000831203159442375,2.64669545022164E-7,0.0673583792886605,0.000102829992152095,0.000831074627347201,2.64628618167202E-7,0.000831074053035095,2.50504864292206E-7,9.77032297088158E-7,8.52972362918411E-8,1.00015465770575,10.005763053894,2,20,10,3,2.71874096458536,0.242442552876724,0.0403775237500668,172.74836730957,40.009334564209,40.0126571655273,-180.15071105957,-180.15071105957,,,24.455961227417,0,1,,,,,,1,1,1,40.012279510498,0,40.0113636363636,,,,,,,,,,,,,,,,,,,,,,,,,,,,,,,,,
,3772401480.32874,40.0056343078613,-160.163650512695,,,5,,,,6.47999998182058,,,,,0.000834107998744061,2.58321227434624E-7,0.0863368342212265,9.15098273240795E-5,0.000833978991116758,2.58281274084838E-7,0.000833978044286763,2.46810741092042E-7,1.25669079403698E-6,7.61161916052323E-8,1.00015468930114,10.005763053894,2,20,10,3,2.72816521979002,0.244135216806039,0.0403775237500668,172.74836730957,40.0034828186035,40.0060386657715,-160.163650512695,-160.163650512695,,,24.4563446044922,0,1,,,,,,1,1,1,40.0056762695313,0,40.0049247741699,,,,,,,,,,,,,,,,,,,,,,,,,,,,,,,,,
,3772401502.22034,40.0065212249756,-140.067306518555,,,5,,,,6.47999998182058,,,,,0.00081681437730998,2.89681102969253E-7,0.0850999809223198,9.39522971304855E-5,0.000816688011247102,2.89636287572402E-7,0.000816687110423481,2.79358373961813E-7,1.21300572596952E-6,7.64727270086227E-8,1.00015472991049,10.005763053894,2,20,10,3,2.6716107785183,0.238958399550597,0.0403775237500668,172.74836730957,40.0039978027344,40.0066871643066,-140.067306518555,-140.067306518555,,,24.4682712554932,0,1,,,,,,1,1,1,40.0064277648926,0,40.0056492198597,,,,,,,,,,,,,,,,,,,,,,,,,,,,,,,,,
,3772401525.28842,40.0123882293701,-120.165237426758,,,5,,,,6.47999998182058,,,,,0.000783452908299101,3.33159761212594E-7,0.0606827669557042,0.000118781200258636,0.000783331762537029,3.33108244532094E-7,0.000783331323196584,3.1991776577307E-7,8.29637545944962E-7,9.28101595625211E-8,1.00015465447447,10.005763053894,2,20,10,3,2.56259402025283,0.228051828899237,0.0403775237500668,172.74836730957,40.0082664489746,40.0126419067383,-120.165237426758,-120.165237426758,,,24.455696105957,0,1,,,,,,1,1,1,40.0122413635254,0,40.0107969804244,,,,,,,,,,,,,,,,,,,,,,,,,,,,,,,,,
,3772401549.78016,40.0145320892334,-100.068893432617,,,5,,,,6.47999998182058,,,,,0.000753509435054466,2.54535944637039E-7,0.0474334624944444,8.02695539609065E-5,0.000753392845526034,2.5449656062355E-7,0.000753392587350037,2.47255215754973E-7,6.23711336218432E-7,6.02773394500609E-8,1.00015475263553,10.005763053894,2,20,10,3,2.46470597450083,0.218712743101529,0.0403775237500668,172.74836730957,40.010326385498,40.0149269104004,-100.068893432617,-100.068893432617,,,24.4431533813477,0,1,,,,,,1,1,1,40.0141639709473,0,40.0130153656006,,,,,,,,,,,,,,,,,,,,,,,,,,,,,,,,,
,3772401570.27359,40.0239791870117,-80.021110534668,,,5,,,,6.47999998182058,,,,,0.000731487980827503,2.80532234366184E-7,0.0377486514317216,5.80591175944485E-5,0.000731374817811875,2.80488835329626E-7,0.000731374659078734,2.77306345711567E-7,4.81857674349204E-7,4.21328538395738E-8,1.00015472643147,10.005763053894,2,20,10,3,2.39271355436028,0.211864950670376,0.0403775237500668,172.74836730957,40.0174827575684,40.0241813659668,-80.021110534668,-80.021110534668,,,24.4433345794678,0,1,,,,,,1,1,1,40.0237770080566,0,40.0217292092063,,,,,,,,,,,,,,,,,,,,,,,,,,,,,,,,,
,3772401591.9076,40.0260143280029,-60.0704803466797,,,5,,,,6.47999998182058,,,,,0.000715641962656572,2.14266395426805E-7,0.0292919174113928,3.79443617315512E-5,0.000715531348497209,2.14233277054146E-7,0.00071553125498916,2.12541620523835E-7,3.6580851906635E-7,2.68692490118489E-8,1.00015459023507,10.005763053894,2,20,10,3,2.34091456039696,0.206879870078765,0.0403775237500668,172.74836730957,40.0177192687988,40.0270957946777,-60.0704803466797,-60.0704803466797,,,24.4429683685303,0,1,,,,,,1,1,1,40.0253067016602,0,40.0228199005127,,,,,,,,,,,,,,,,,,,,,,,,,,,,,,,,,
,3772401615.35564,40.0069198608398,-40.1198425292969,,,5,,,,6.47999998182058,,,,,0.000705058386989745,2.21927728005623E-7,0.0153481920365168,3.1862203185032E-5,0.000704949378218952,2.21893415856046E-7,0.00070494935292614,2.20785780207247E-7,1.88839359469008E-7,2.21433344043177E-8,1.00015463347321,10.005763053894,2,20,10,3,2.30634752600193,0.203209988397473,0.0403775237500668,172.74836730957,40.0036010742188,40.0079917907715,-40.1198425292969,-40.1198425292969,,,24.4434013366699,0,1,,,,,,1,1,1,40.0066261291504,0,40.0056381225586,,,,,,,,,,,,,,,,,,,,,,,,,,,,,,,,,
,3772401637.48693,40.0027027130127,-20.047779083252,,,5,,,,6.47999998182058,,,,,0.000699689956580111,1.91760301603565E-7,0.01924345745641,3.51341857490979E-5,0.000699581752437248,1.91730646670154E-7,0.000699581712979761,1.90177442382485E-7,2.34962706705711E-7,2.43553132070234E-8,1.00015466976159,10.005763053894,2,20,10,3,2.2887759535247,0.201769185796621,0.0403775237500668,172.74836730957,40.0012092590332,40.0032348632812,-20.047779083252,-20.047779083252,,,24.4428005218506,0,1,,,,,,1,1,1,40.0025634765625,0,40.0021344965154,,,,,,,,,,,,,,,,,,,,,,,,,,,,,,,,,
,3772401660.29662,40.0085773468018,0.0728568583726883,,,5,,,,6.47999998182058,,,,,0.000697782559472371,1.72691405283604E-7,0.0158555226728962,6.29436936427755E-5,0.000697674622674764,1.72664692438739E-7,0.000697674595960772,1.6701107734584E-7,1.93068246054845E-7,4.3822323748818E-8,1.00015470936465,10.005763053894,2,20,10,3,2.28255153920505,0.20103533223012,0.0403775237500668,172.74836730957,40.0060348510742,40.0086784362793,0.0728568583726883,0.0728568583726883,,,24.4435577392578,0,1,,,,,,1,1,1,40.0084571838379,0,40.007792039351,,,,,,,,,,,,,,,,,,,,,,,,,,,,,,,,,