File: Experimental_Data/AC_Suceptibillity_FieldScans/HFCd_Up_20K.dat
[Header]
; MPMS3 Data File (default extension .dat)
; Copyright (c) 2007, Quantum Design, Inc. All rights reserved.
TITLE,HFCd_Up_20K
FILEOPENTIME,3772420024.98525,07/16/2019,6:26 am
BYAPP,SQUID AC,0.9.1.0
INFO,MPMS3 Measurement Release 1.1.16 Build 347, MultiVu Release 2.3.3.2,APPNAME
INFO,0,MOMENT_UNITS
INFO,Cu2OSeO3,SAMPLE_MATERIAL
INFO,,SAMPLE_COMMENT
INFO,,SAMPLE_MASS
INFO,,SAMPLE_VOLUME
INFO,,SAMPLE_MOLECULAR_WEIGHT
INFO,,SAMPLE_SIZE
INFO,,SAMPLE_SHAPE
INFO,Quartz,SAMPLE_HOLDER
INFO,Standard,SAMPLE_HOLDER_DETAIL
INFO,64.77,SAMPLE_OFFSET
DATATYPE,COMMENT,1
DATATYPE,TIME,2
STARTUPAXIS,X,2
STARTUPAXIS,Y1,5
FIELDGROUP, VSM,2,3,4,5,6,8,9,10,11,14,15
FIELDGROUP, DC, 2,3,4,14,56,57,58,59,60,61,62,63,64,65,66,67,68,69
FIELDGROUP, AC, 2,3,4,11,16,17,18,19,20,21,22,23,24,25,26,27,28,29,30
STARTUPGROUP, All
[Data]
Comment,Time Stamp (sec),Temperature (K),Magnetic Field (Oe),Moment (emu),M. Std. Err. (emu),Transport Action,Averaging Time (sec),Frequency (Hz),Peak Amplitude (mm),Center Position (mm),Lockin Signal' (V),Lockin Signal (V),Range,M. Quad. Signal (emu),AC Moment (emu),AC M. Std Err. (emu),AC Phase (deg),AC Phase Std. Err. (deg),AC Susceptibility (emu/Oe),AC Suscept. Std Err. (emu/Oe),AC X' (emu/Oe),AC X' Std Err. (emu/Oe),AC X'' (emu/Oe),AC X'' Std Err. (emu/Oe),AC Drive (Oe),AC Frequency (Hz),AC Averaging Time (sec),AC Cycles,AC Range,AC Measure Type,AC Signal' (V),AC Signal'' (V),AC Trim Coil Ratio,AC Trim Coil Phase,Min. Temperature (K),Max. Temperature (K),Min. Field (Oe),Max. Field (Oe),Mass (grams),Motor Lag (deg),Pressure (Torr),Measure Count,Measurement Number,SQUID Status (code),Motor Status (code),Measure Status (code),Motor Current (amps),Motor Temp. (C),Temp. Status (code),Field Status (code),Chamber Status (code),Chamber Temp (K),Redirection State,Average Temp (K),Rotation Angle (deg),Rotator state,DC Moment Fixed Ctr (emu),DC Moment Err Fixed Ctr (emu),DC Moment Free Ctr (emu),DC Moment Err Free Ctr (emu),DC Fixed Fit,DC Free Fit,DC Calculated Center (mm),DC Calculated Center Err (mm),DC Scan Length (mm),DC Scan Time (s),DC Number of Points,DC Squid Drift,DC Min V (V),DC Max V (V),DC Scans per Measure,Map 01,Map 02,Map 03,Map 04,Map 05,Map 06,Map 07,Map 08,Map 09,Map 10,Map 11,Map 12,Map 13,Map 14,Map 15,Map 16
,3772420194.56678,19.9470310211182,1000.19104003906,,,5,,,,6.46999990567565,,,,,5.12870797839283E-5,3.90866734197941E-7,0.0991186957633286,0.00702668804046432,5.12789786960109E-5,3.90804994559204E-7,5.12789019642516E-5,1.51226696948077E-7,8.87099014348755E-8,3.60359584169194E-7,1.00015798067987,10.005763053894,2,20,1,3,0.167733161841953,0.0152149025028815,0.0403775237500668,172.74836730957,19.9466533660889,19.9480876922607,1000.19104003906,1000.19104003906,,,24.752649307251,0,1,,,,,,1,1,1,19.947021484375,0,19.9472471383902,,,,,,,,,,,,,,,,,,,,,,,,,,,,,,,,,
,3772420218.0832,19.957314491272,980.228271484375,,,5,,,,6.46999990567565,,,,,7.20082890516595E-5,2.76278714884283E-7,-0.109405416720271,0.00314602672017654,7.19969057496828E-5,2.76235039856273E-7,7.19967744946125E-5,1.58165295154722E-7,-1.37476909405573E-7,2.26471933477454E-7,1.00015810821115,10.005763053894,2,20,1,3,0.235577872408881,0.0204998173908832,0.0403775237500668,172.74836730957,19.9566097259521,19.9624156951904,980.228271484375,980.228271484375,,,24.7832832336426,0,1,,,,,,1,1,1,19.9579467773438,0,19.9590368270874,,,,,,,,,,,,,,,,,,,,,,,,,,,,,,,,,
,3772420240.04881,19.9665412902832,960.435546875,,,5,,,,6.46999990567565,,,,,9.84780179847787E-5,5.03623749847256E-7,-0.015018958141976,0.00359976646440957,9.84624424753132E-5,5.03544095558479E-7,9.84624390925239E-5,3.57714005698136E-7,-2.58099863153178E-8,3.54397158988613E-7,1.00015818731563,10.005763053894,2,20,1,3,0.322128410049744,0.028559268188287,0.0403775237500668,172.74836730957,19.9632549285889,19.9723644256592,960.435546875,960.435546875,,,24.8645858764648,0,1,,,,,,1,1,1,19.9682579040527,0,19.9687751423229,,,,,,,,,,,,,,,,,,,,,,,,,,,,,,,,,
,3772420263.06632,19.9861860275269,940.411987304687,,,5,,,,6.46999990567565,,,,,0.000133449959268866,3.0571999499598E-7,0.0409080468737377,0.00180532435806522,0.000133428854701005,3.05671646623179E-7,0.000133428820692153,1.88194232968438E-7,9.52655400634929E-8,2.40869438133498E-7,1.00015817094367,10.005763053894,2,20,1,3,0.436486661593748,0.0391180614331186,0.0403775237500668,172.74836730957,19.9829139709473,19.9904537200928,940.411987304687,940.411987304687,,,24.9628372192383,0,1,,,,,,1,1,1,19.9874858856201,0,19.9878196716309,,,,,,,,,,,,,,,,,,,,,,,,,,,,,,,,,
,3772420283.64648,19.9887866973877,920.255004882813,,,5,,,,6.46999990567565,,,,,0.000187037460140203,3.90494991499203E-7,0.0546966770087014,0.00137074379573613,0.00018700792291635,3.90433323970309E-7,0.000187007837703204,2.94540959945887E-7,1.78524674786261E-7,2.56288515896946E-7,1.00015794637678,10.005763053894,2,20,1,3,0.611747701511866,0.0549601383685034,0.0403775237500668,172.74836730957,19.9875965118408,19.9890823364258,920.255004882813,920.255004882813,,,25.0992698669434,0,1,,,,,,1,1,1,19.9886360168457,0,19.9882151863792,,,,,,,,,,,,,,,,,,,,,,,,,,,,,,,,,
,3772420306.63298,19.9876699447632,900.146423339844,,,5,,,,6.46999990567565,,,,,0.000269844232299532,3.43408463263287E-7,0.0414677967648149,0.000934504362311575,0.000269801601007534,3.43354209939631E-7,0.000269801530344681,2.3309874209976E-7,1.95268780279065E-7,2.52105315125996E-7,1.0001580097814,10.005763053894,2,20,1,3,0.882605197758882,0.0790697719498309,0.0403775237500668,172.74836730957,19.986946105957,19.9883460998535,900.146423339844,900.146423339844,,,25.2394313812256,0,1,,,,,,1,1,1,19.9876823425293,0,19.9875975522128,,,,,,,,,,,,,,,,,,,,,,,,,,,,,,,,,
,3772420329.68023,20.0002069473267,880.268615722656,,,5,,,,6.46999990567565,,,,,0.000371507718861762,2.9274385767073E-7,0.122461104928246,0.000535038503171663,0.000371449025673905,2.92697608106158E-7,0.000371448177235839,2.1491816810979E-7,7.93915779862999E-7,1.98700958244791E-7,1.00015801141961,10.005763053894,2,20,1,3,1.21497221866538,0.1105509173933,0.0403775237500668,172.74836730957,19.9998531341553,20.00048828125,880.268615722656,880.268615722656,,,25.4087867736816,0,1,,,,,,1,1,1,20.0001163482666,0,20.0002254486084,,,,,,,,,,,,,,,,,,,,,,,,,,,,,,,,,
,3772420351.32278,20.0002336502075,860.366577148438,,,5,,,,6.46999990567565,,,,,0.000501577179900946,3.45103393011828E-7,0.0820293653858926,0.000448083600861386,0.00050149793688629,3.45048870927638E-7,0.000501497422922504,2.61888888827616E-7,7.17985579415121E-7,2.24661819713708E-7,1.00015801264338,10.005763053894,2,20,1,3,1.64045622593082,0.148063641942673,0.0403775237500668,172.74836730957,19.9997997283936,20.0004997253418,860.366577148438,860.366577148438,,,25.5483589172363,0,1,,,,,,1,1,1,20.0004997253418,0,20.000079536438,,,,,,,,,,,,,,,,,,,,,,,,,,,,,,,,,
,3772420373.18057,19.9998016357422,840.31884765625,,,5,,,,6.46999990567565,,,,,0.000608325981318439,3.29858467836333E-7,0.0629978017815622,0.000388981432980015,0.000608229885348745,3.29806360791258E-7,0.000608229517691403,2.2980550333564E-7,6.68760218639464E-7,2.3656218263921E-7,1.0001579928445,10.005763053894,2,20,1,3,1.98965067476777,0.178871905758916,0.0403775237500668,172.74836730957,19.9990386962891,20.0004024505615,840.31884765625,840.31884765625,,,25.647331237793,0,1,,,,,,1,1,1,20.0001354217529,0,20.0000051498413,,,,,,,,,,,,,,,,,,,,,,,,,,,,,,,,,
,3772420398.20358,20.0002317428589,820.307495117187,,,5,,,,6.46999990567565,,,,,0.000665533337766974,3.5347984507794E-7,0.0236980018913071,0.000426666034007708,0.000665428191757583,3.53423999648416E-7,0.000665428134839615,2.10496900880895E-7,2.75226521590227E-7,2.83900648549844E-7,1.00015801255596,10.005763053894,2,20,10,3,2.17689533206901,0.194153398418346,0.0403775237500668,172.74836730957,19.9997310638428,20.0002613067627,820.307495117187,820.307495117187,,,25.7196273803711,0,1,,,,,,1,1,1,20.0002021789551,0,20.0000312328339,,,,,,,,,,,,,,,,,,,,,,,,,,,,,,,,,
,3772420424.44044,20.0020046234131,800.271850585938,,,5,,,,6.46999990567565,,,,,0.00070029572139407,4.05379678836394E-7,0.065184767459523,0.000458839039452219,0.000700185026478557,4.05315600950541E-7,0.00070018457334132,2.47127890378615E-7,7.96592500732819E-7,3.21260863117363E-7,1.00015809380567,10.005763053894,2,20,10,3,2.29045434701376,0.205903886122145,0.0403775237500668,172.74836730957,20.0006275177002,20.0023899078369,800.271850585938,800.271850585938,,,25.8176326751709,0,1,,,,,,1,1,1,20.0023899078369,0,20.0016455216841,,,,,,,,,,,,,,,,,,,,,,,,,,,,,,,,,
,3772420446.0678,19.9999341964722,780.357604980469,,,5,,,,6.46999990567565,,,,,0.000724758234834168,4.1333107873632E-7,0.0801274879385501,0.000356071750525935,0.000724643824925723,4.13265830535468E-7,0.000724643116307496,3.22875937398997E-7,1.01340571519098E-6,2.57953049481663E-7,1.00015788433505,10.005763053894,2,20,10,3,2.37041137106424,0.213664159178174,0.0403775237500668,172.74836730957,19.9990768432617,20.0015563964844,780.357604980469,780.357604980469,,,25.8607940673828,0,1,,,,,,1,1,1,19.9994029998779,0,20.0000225413929,,,,,,,,,,,,,,,,,,,,,,,,,,,,,,,,,
,3772420468.09741,20.0003871917725,760.334167480469,,,5,,,,6.46999990567565,,,,,0.000741503593315375,3.98885479449909E-7,0.154753991534327,0.00043293959614943,0.000741386439667374,3.98822457652748E-7,0.000741383735380048,2.36699445012969E-7,2.00245763794812E-6,3.20987111047671E-7,1.00015801968007,10.005763053894,2,20,10,3,2.42489575510599,0.221707394528954,0.0403775237500668,172.74836730957,19.9999523162842,20.0007209777832,760.334167480469,760.334167480469,,,25.9036083221436,0,1,,,,,,1,1,1,20.000696182251,0,20.0002456665039,,,,,,,,,,,,,,,,,,,,,,,,,,,,,,,,,
,3772420491.04024,20.0012893676758,740.286376953125,,,5,,,,6.46999990567565,,,,,0.000755233820529516,4.16335994967088E-7,0.129192585624438,0.000342088318473908,0.000755114552872993,4.16270246562956E-7,0.000755112633264882,3.26495819846155E-7,1.70265802631476E-6,2.58227414881866E-7,1.00015794644146,10.005763053894,2,20,10,3,2.46990085032837,0.22465781600169,0.0403775237500668,172.74836730957,20.0003051757813,20.0022830963135,740.286376953125,740.286376953125,,,25.9455299377441,0,1,,,,,,1,1,1,20.0011005401611,0,20.0009176254272,,,,,,,,,,,,,,,,,,,,,,,,,,,,,,,,,
,3772420512.75809,20.001012802124,720.335754394531,,,5,,,,6.46999990567565,,,,,0.000766342102052597,4.43695824682497E-7,0.143446425963733,0.000294573771995444,0.000766221089869761,4.43625761195033E-7,0.000766218688505303,3.82025277063078E-7,1.91831864321438E-6,2.25522734288034E-7,1.00015793376668,10.005763053894,2,20,10,3,2.50617583904685,0.228532141588568,0.0403775237500668,172.74836730957,20.0003986358643,20.0017681121826,720.335754394531,720.335754394531,,,26.657886505127,0,1,,,,,,1,1,1,20.0008163452148,0,20.0008283615112,,,,,,,,,,,,,,,,,,,,,,,,,,,,,,,,,
,3772420534.87812,20.0017728805542,700.215087890625,,,5,,,,6.46999990567565,,,,,0.000775957996170836,4.79265702218293E-7,0.156795513932171,0.000403210644917502,0.000775835438532415,4.79190005243805E-7,0.000775832533430666,3.63066700299333E-7,2.12314703647635E-6,3.12738920282257E-7,1.00015796860047,10.005763053894,2,20,10,3,2.5375723803035,0.231936278635274,0.0403775237500668,172.74836730957,20.0008239746094,20.0021018981934,700.215087890625,700.215087890625,,,26.6703224182129,0,1,,,,,,1,1,1,20.0021018981934,0,20.0013786662709,,,,,,,,,,,,,,,,,,,,,,,,,,,,,,,,,
,3772420559.19622,19.9999074935913,680.313049316406,,,5,,,,6.46999990567565,,,,,0.000784773702020341,3.53771455446193E-7,0.133871371191406,0.000298041747949173,0.000784649729171061,3.53715569201263E-7,0.000784647587386446,2.65426182989015E-7,1.83332944358573E-6,2.33802577571881E-7,1.00015799769588,10.005763053894,2,20,10,3,2.56649909066312,0.233489820533001,0.0403775237500668,172.74836730957,19.9995365142822,20.0010147094727,680.313049316406,680.313049316406,,,26.707633972168,0,1,,,,,,1,1,1,20.0002346038818,0,20.000274848938,,,,,,,,,,,,,,,,,,,,,,,,,,,,,,,,,
,3772420581.0949,20.000340461731,660.28955078125,,,5,,,,6.46999990567565,,,,,0.000792230015509288,3.26097368084576E-7,0.163791594656728,0.000306150440046303,0.000792104849050835,3.26045847122388E-7,0.000792101612441086,2.17957678372575E-7,2.26438911825726E-6,2.4248782415658E-7,1.00015801753846,10.005763053894,2,20,10,3,2.59076417501823,0.237005678588656,0.0403775237500668,172.74836730957,20,20.0006084442139,660.28955078125,660.28955078125,,,26.757381439209,0,1,,,,,,1,1,1,20.0002403259277,0,20.00026252053,,,,,,,,,,,,,,,,,,,,,,,,,,,,,,,,,
,3772420604.31864,20.0004825592041,640.411743164062,,,5,,,,6.46999990567565,,,,,0.000799410078359853,3.97890857235906E-7,0.159174966900071,0.000412561039673386,0.000799283863871667,3.97828036423085E-7,0.000799280779440789,2.22516845427685E-7,2.22050943371343E-6,3.29777804082019E-7,1.00015790946607,10.005763053894,2,20,10,3,2.61426743597132,0.238887417723786,0.0403775237500668,172.74836730957,19.9998722076416,20.0007495880127,640.411743164062,640.411743164062,,,26.7698211669922,0,1,,,,,,1,1,1,20.0005054473877,0,20.000257174174,,,,,,,,,,,,,,,,,,,,,,,,,,,,,,,,,
,3772420627.09434,20.0014238357544,620.3154296875,,,5,,,,6.46999990567565,,,,,0.000806457292536857,4.81616787555501E-7,0.148388053289422,0.000330740613095627,0.00080632993062461,4.81540726943735E-7,0.000806327226447375,4.01057317467649E-7,2.08827938070317E-6,2.66522981769217E-7,1.00015795260403,10.005763053894,2,20,10,3,2.63736257869204,0.240440073645183,0.0403775237500668,172.74836730957,20.0005111694336,20.0016479492187,620.3154296875,620.3154296875,,,26.7822570800781,0,1,,,,,,1,1,1,20.0015830993652,0,20.0010185241699,,,,,,,,,,,,,,,,,,,,,,,,,,,,,,,,,
,3772420650.14062,19.9999685287476,600.304077148438,,,5,,,,6.46999990567565,,,,,0.000813098865932829,4.21500229036056E-7,0.14575463916881,0.00032037083504031,0.000812970416206216,4.21433642312774E-7,0.000812967785671604,3.31392357495212E-7,2.0681118726688E-6,2.60356333256514E-7,1.00015800049307,10.005763053894,2,20,10,3,2.65909740419762,0.242241054474739,0.0403775237500668,172.74836730957,19.9996318817139,20.0002670288086,600.304077148438,600.304077148438,,,26.8195686340332,0,1,,,,,,1,1,1,20.0000858306885,0,19.99992387945,,,,,,,,,,,,,,,,,,,,,,,,,,,,,,,,,
,3772420670.63133,19.9998531341553,580.231994628906,,,5,,,,6.46999990567565,,,,,0.000819363630440782,5.78532005701553E-7,0.147437615480047,0.000301885239329652,0.000819234195366446,5.78440614858243E-7,0.000819231482994972,5.23071876290008E-7,2.1081099517125E-6,2.46960233948774E-7,1.00015799520463,10.005763053894,2,20,10,3,2.67958179405456,0.244128614014936,0.0403775237500668,172.74836730957,19.9996528625488,20.0003719329834,580.231994628906,580.231994628906,,,26.8568801879883,0,1,,,,,,1,1,1,20.0000686645508,0,20.0000995635986,,,,,,,,,,,,,,,,,,,,,,,,,,,,,,,,,
,3772420693.61821,20.0006551742554,560.329895019531,,,5,,,,6.46999990567565,,,,,0.000825785901607941,3.36945469110946E-7,0.148493524116998,0.000273367669272161,0.000825655421662141,3.36892229371128E-7,0.000825652648735617,2.50150567151603E-7,2.1398495152163E-6,2.25656969678271E-7,1.00015803196149,10.005763053894,2,20,10,3,2.70058388949582,0.246034358203123,0.0403775237500668,172.74836730957,20.0001945495605,20.001091003418,560.329895019531,560.329895019531,,,26.8817520141602,0,1,,,,,,1,1,1,20.0010547637939,0,20.0005616274747,,,,,,,,,,,,,,,,,,,,,,,,,,,,,,,,,
,3772420716.69459,20.000659942627,540.306396484375,,,5,,,,6.46999990567565,,,,,0.000832134462441568,3.51209351897585E-7,0.152581919962079,0.00026297274737863,0.000832002979196982,3.51153858287837E-7,0.000832000028969426,2.74722553703417E-7,2.21566864101328E-6,2.1871568457042E-7,1.00015803218002,10.005763053894,2,20,10,3,2.72133181321305,0.248061708128115,0.0403775237500668,172.74836730957,20.0003490447998,20.0009613037109,540.306396484375,540.306396484375,,,26.8817520141602,0,1,,,,,,1,1,1,20.0007514953613,0,20.0006097793579,,,,,,,,,,,,,,,,,,,,,,,,,,,,,,,,,
,3772420738.41313,20.0015993118286,520.234375,,,5,,,,6.46999990567565,,,,,0.000838059366334616,3.9993149655528E-7,0.17849914461386,0.000390982389092254,0.000837926910844987,3.99868287283572E-7,0.000837922844513258,2.29231408000155E-7,2.6104714197135E-6,3.27639449336254E-7,1.00015807523057,10.005763053894,2,20,10,3,2.74059861724951,0.251008758583678,0.0403775237500668,172.74836730957,19.9998054504395,20.0022621154785,520.234375,520.234375,,,26.8941917419434,0,1,,,,,,1,1,1,20.0021915435791,0,20.0014781951904,,,,,,,,,,,,,,,,,,,,,,,,,,,,,,,,,
,3772420760.21024,20.0009002685547,500.332336425781,,,5,,,,6.46999990567565,,,,,0.000843486417164946,4.26388717841563E-7,0.198678275250971,0.000368627643245584,0.000843353227562517,4.26321389497379E-7,0.000843348157251758,2.91750965503506E-7,2.92439740442318E-6,3.10855756373833E-7,1.00015792860936,10.005763053894,2,20,10,3,2.7582607330203,0.253546928244789,0.0403775237500668,172.74836730957,20.0001735687256,20.00119972229,500.332336425781,500.332336425781,,,26.9190635681152,0,1,,,,,,1,1,1,20.0009307861328,0,20.0006126403809,,,,,,,,,,,,,,,,,,,,,,,,,,,,,,,,,
,3772420783.24837,20.001389503479,480.369537353516,,,5,,,,6.46999990567565,,,,,0.000850062784901562,4.08561095089219E-7,0.198288213111408,0.000236354736469337,0.000849928440439735,4.08496525834549E-7,0.000849923350642679,3.55816706668199E-7,2.94141133507327E-6,2.00658622726993E-7,1.00015806561522,10.005763053894,2,20,10,3,2.77977157657513,0.25544541743111,0.0403775237500668,172.74836730957,20.0007228851318,20.0018405914307,480.369537353516,480.369537353516,,,26.9439392089844,0,1,,,,,,1,1,1,20.0018405914307,0,20.0011556625366,,,,,,,,,,,,,,,,,,,,,,,,,,,,,,,,,
,3772420804.89186,20.0004272460938,460.261047363281,,,5,,,,6.46999990567565,,,,,0.00085639233925118,3.56553861991865E-7,0.188109608990897,0.000261729336515542,0.000856257130315484,3.56497568554863E-7,0.00085625251554069,2.77315899451716E-7,2.81120016145816E-6,2.24023231600687E-7,1.00015790693112,10.005763053894,2,20,10,3,2.80051934322599,0.256789686778296,0.0403775237500668,172.74836730957,19.999979019165,20.0010623931885,460.261047363281,460.261047363281,,,26.9563751220703,0,1,,,,,,1,1,1,20.0002384185791,0,20.000329208374,,,,,,,,,,,,,,,,,,,,,,,,,,,,,,,,,
,3772420826.80877,20.0004663467407,440.225402832031,,,5,,,,6.46999990567565,,,,,0.000862709149278675,3.2045712049726E-7,0.188497197103526,0.000226547483781545,0.000862572842664967,3.20406488804098E-7,0.000862568174674914,2.53984044044416E-7,2.83777044697896E-6,1.95326453504421E-7,1.00015802330767,10.005763053894,2,20,10,3,2.8211783927341,0.258642364338665,0.0403775237500668,172.74836730957,20.000057220459,20.0008754730225,440.225402832031,440.225402832031,,,26.9563751220703,0,1,,,,,,1,1,1,20.0008754730225,0,20.0004627227783,,,,,,,,,,,,,,,,,,,,,,,,,,,,,,,,,
,3772420849.83286,20.0029125213623,420.250518798828,,,5,,,,6.46999990567565,,,,,0.000869320346160933,3.59001482239094E-7,0.176351220372541,0.000252903535754133,0.000869182897563656,3.58944720367164E-7,0.000869178780453303,2.83833451969227E-7,2.67526201747673E-6,2.19726839104135E-7,1.00015813541392,10.005763053894,2,20,10,3,2.84285708482975,0.259960976153581,0.0403775237500668,172.74836730957,20.0013771057129,20.0035438537598,420.250518798828,420.250518798828,,,26.9688148498535,0,1,,,,,,1,1,1,20.0034217834473,0,20.0022674560547,,,,,,,,,,,,,,,,,,,,,,,,,,,,,,,,,
,3772420871.49546,20.0001487731934,400.336273193359,,,5,,,,6.46999990567565,,,,,0.000875651500806384,3.67774778701522E-7,0.172905777052784,0.00023800748696594,0.000875513162062947,3.67716676247856E-7,0.000875509175431416,3.0306133431332E-7,2.64209781457391E-6,2.08253167166794E-7,1.00015800875353,10.005763053894,2,20,10,3,2.86358099498303,0.2616210268014,0.0403775237500668,172.74836730957,20.0000038146973,20.0002384185791,400.336273193359,400.336273193359,,,26.9812507629395,0,1,,,,,,1,1,1,20.000171661377,0,20.0001214981079,,,,,,,,,,,,,,,,,,,,,,,,,,,,,,,,,
,3772420891.75217,20.0005226135254,380.349212646484,,,5,,,,6.46999990567565,,,,,0.000882300505862616,3.1133440137971E-7,0.159972545675163,0.000146793176944356,0.00088216120263877,3.11285245921316E-7,0.000882157764183946,2.8316753767522E-7,2.46303289925441E-6,1.29285149708878E-7,1.00015791130173,10.005763053894,2,20,10,3,2.88538821216309,0.262894537199217,0.0403775237500668,172.74836730957,20.0000171661377,20.0010833740234,380.349212646484,380.349212646484,,,26.9936866760254,0,1,,,,,,1,1,1,20.000431060791,0,20.0004019303755,,,,,,,,,,,,,,,,,,,,,,,,,,,,,,,,,
,3772420913.92571,20.0006246566772,360.252868652344,,,5,,,,6.46999990567565,,,,,0.000889164944439382,3.2701069555386E-7,0.163711685324917,0.00021528169727051,0.000889024553257332,3.26959063493488E-7,0.000889020924168839,2.65158092475198E-7,2.54021345209738E-6,1.9129405426059E-7,1.00015791597829,10.005763053894,2,20,10,3,2.90782376997072,0.265067113960587,0.0403775237500668,172.74836730957,20.000337600708,20.0010757446289,360.252868652344,360.252868652344,,,27.0061264038086,0,1,,,,,,1,1,1,20.0008544921875,0,20.0006345748901,,,,,,,,,,,,,,,,,,,,,,,,,,,,,,,,,
,3772420934.54224,20.0002527236938,340.192932128906,,,5,,,,6.46999990567565,,,,,0.00089609566497315,4.39697022405796E-7,0.156774903416001,0.000225274445325521,0.000895954092115537,4.39627555309392E-7,0.000895950738113595,3.90682036429188E-7,2.45154079717207E-6,2.0159348649908E-7,1.0001580135175,10.005763053894,2,20,10,3,2.93052561791405,0.266715503495791,0.0403775237500668,172.74836730957,20.0000762939453,20.0005283355713,340.192932128906,340.192932128906,,,27.0061264038086,0,1,,,,,,1,1,1,20.0003833770752,0,20.0002498626709,,,,,,,,,,,,,,,,,,,,,,,,,,,,,,,,,
,3772420957.50968,20.000262260437,320.278747558594,,,5,,,,6.46999990567565,,,,,0.000903414007942595,3.0394372044546E-7,0.149585271201034,0.000204851897583049,0.000903271278475841,3.0389570068402E-7,0.000903268200109086,2.41124888246376E-7,2.35821777475342E-6,1.84963199481422E-7,1.00015801395456,10.005763053894,2,20,10,3,2.95449679203014,0.268460037169121,0.0403775237500668,172.74836730957,20,20.0004367828369,320.278747558594,320.278747558594,,,27.0185623168945,0,1,,,,,,1,1,1,20.0004367828369,0,20.0001841458407,,,,,,,,,,,,,,,,,,,,,,,,,,,,,,,,,
,3772420979.13753,20.0003547668457,300.267364501953,,,5,,,,6.46999990567565,,,,,0.000908347484820308,9.45902115301407E-7,0.197887099188899,0.000541085211228128,0.000908203972068807,9.45752669172601E-7,0.000908198555270446,8.08333648720296E-7,3.13673177547948E-6,4.90963159100184E-7,1.00015801819406,10.005763053894,2,20,10,3,2.97040664732976,0.272366675423328,0.0403775237500668,172.74836730957,19.9997539520264,20.000545501709,300.267364501953,300.267364501953,,,27.0309982299805,0,1,,,,,,1,1,1,20.0005264282227,0,20.0001377105713,,,,,,,,,,,,,,,,,,,,,,,,,,,,,,,,,
,3772421001.03415,20.002589225769,280.171051025391,,,5,,,,6.46999990567565,,,,,0.0009030156683418,1.20436403154048E-6,0.321281683040044,0.000798912246826499,0.000902872905538476,1.20417362688705E-6,0.000902858710971303,9.64598585033742E-7,5.06276394133626E-6,7.20821540633479E-7,1.00015812059754,10.005763053894,2,20,10,3,2.95238528355451,0.277063409006486,0.0403775237500668,172.74836730957,19.9990615844727,20.004301071167,280.171051025391,280.171051025391,,,27.0434379577637,0,1,,,,,,1,1,1,20.0042934417725,0,20.0027555465698,,,,,,,,,,,,,,,,,,,,,,,,,,,,,,,,,
,3772421024.0804,20.0013494491577,260.159698486328,,,5,,,,6.46999990567565,,,,,0.000869903920341752,2.63765376196279E-6,0.572983564291844,0.00205604089397888,0.000869766541416741,2.63723721246819E-6,0.000869723049540216,1.93895837654296E-6,8.69791161757614E-6,1.78758511094182E-6,1.00015794919495,10.005763053894,2,20,10,3,2.84293175792669,0.279334886281203,0.0403775237500668,172.74836730957,20.0006732940674,20.0016860961914,260.159698486328,260.159698486328,,,27.0683097839355,0,1,,,,,,1,1,1,20.0011978149414,0,20.0010990142822,,,,,,,,,,,,,,,,,,,,,,,,,,,,,,,,,
,3772421044.59683,20.0009679794312,240.269760131836,,,5,,,,6.46999990567565,,,,,0.000822123502163572,1.44439063610557E-6,0.413234036248501,0.00112001274366167,0.000821993683293509,1.44416255703981E-6,0.000821972304484494,1.11308494206296E-6,5.92840913558573E-6,9.20134448278328E-7,1.0001579317125,10.005763053894,2,20,10,3,2.68751021793591,0.25644271588844,0.0403775237500668,172.74836730957,20.0001068115234,20.0015068054199,240.269760131836,240.269760131836,,,27.0558738708496,0,1,,,,,,1,1,1,20.0010948181152,0,20.0006217956543,,,,,,,,,,,,,,,,,,,,,,,,,,,,,,,,,
,3772421066.32784,20.0009212493896,220.22200012207,,,5,,,,6.46999990567565,,,,,0.000776398810735742,5.04711717837018E-7,0.224154426055925,0.000369249600510472,0.000776276213766405,5.04632021518399E-7,0.00077627027310087,4.15458198069701E-7,3.03696549310804E-6,2.86440155701716E-7,1.0001579295709,10.005763053894,2,20,10,3,2.5388258265744,0.233748478864887,0.0403775237500668,172.74836730957,20.0001983642578,20.0014476776123,220.22200012207,220.22200012207,,,27.0558738708496,0,1,,,,,,1,1,1,20.0009231567383,0,20.0007368087769,,,,,,,,,,,,,,,,,,,,,,,,,,,,,,,,,
,3772421088.13245,20.0002393722534,200.18635559082,,,5,,,,6.46999990567565,,,,,0.000742379481420905,3.37304407222643E-7,0.167783080293525,0.000169398564054726,0.000742262194414838,3.37251117193693E-7,0.000742259011843869,3.13047846912769E-7,2.17361314269252E-6,1.25456612387206E-7,1.00015801290561,10.005763053894,2,20,10,3,2.42780465525073,0.221065777465778,0.0403775237500668,172.74836730957,19.9997653961182,20.0007266998291,200.18635559082,200.18635559082,,,27.0807456970215,0,1,,,,,,1,1,1,20.0007057189941,0,20.0003342628479,,,,,,,,,,,,,,,,,,,,,,,,,,,,,,,,,
,3772421108.72209,20.0003690719604,180.332855224609,,,5,,,,6.46999990567565,,,,,0.000717896233547112,2.31367170469802E-7,0.133643371034327,0.000107518663069625,0.000717782810333126,2.31330615871994E-7,0.000717780857736926,2.18147237627524E-7,1.67423898016165E-6,7.69781563509827E-8,1.00015801884965,10.005763053894,2,20,10,3,2.34786723003808,0.212326327014954,0.0403775237500668,172.74836730957,19.9999408721924,20.0005340576172,180.332855224609,180.332855224609,,,27.0807456970215,0,1,,,,,,1,1,1,20.000560760498,0,20.0003211975098,,,,,,,,,,,,,,,,,,,,,,,,,,,,,,,,,
,3772421131.71206,19.9998445510864,160.321517944336,,,5,,,,6.46999990567565,,,,,0.00069955033156196,1.11013193222922E-7,0.111918673569009,8.89961094344406E-5,0.000699439823699018,1.10995656485123E-7,0.000699438489317352,9.19191913944535E-8,1.36624945492038E-6,6.22165413049722E-8,1.00015799481127,10.005763053894,2,20,10,3,2.28794869610747,0.205983808666592,0.0403775237500668,172.74836730957,19.999698638916,20.0000972747803,160.321517944336,160.321517944336,,,27.0807456970215,0,1,,,,,,1,1,1,19.9998950958252,0,19.9998538277366,,,,,,,,,,,,,,,,,,,,,,,,,,,,,,,,,
,3772421152.25438,20.0002307891846,140.249450683594,,,5,,,,6.46999990567565,,,,,0.000685315408936554,1.89826822285862E-7,0.100343435570896,0.000137483751012398,0.000685207137635319,1.89796832011617E-7,0.000685206086824732,1.64806431690713E-7,1.20001863496788E-6,9.4136483443033E-8,1.00015801251226,10.005763053894,2,20,10,3,2.2414357638172,0.201291331240247,0.0403775237500668,172.74836730957,20.0000972747803,20.0004100799561,140.249450683594,140.249450683594,,,27.0931854248047,0,1,,,,,,1,1,1,20.0003929138184,0,20.0002021789551,,,,,,,,,,,,,,,,,,,,,,,,,,,,,,,,,
,3772421175.20964,19.999529838562,120.153099060059,,,5,,,,6.46999990567565,,,,,0.000674272074311064,1.88783194022743E-7,0.0856025182502833,6.70324465033084E-5,0.00067416564660947,1.88753396316142E-7,0.000674164894182492,1.83310646219554E-7,1.00723397234767E-6,4.50005733679933E-8,1.00015786580365,10.005763053894,2,20,10,3,2.20537062953263,0.197432860651142,0.0403775237500668,172.74836730957,19.9992599487305,20.0013427734375,120.153099060059,120.153099060059,,,27.0931854248047,0,1,,,,,,1,1,1,19.9992694854736,0,20.0001581365412,,,,,,,,,,,,,,,,,,,,,,,,,,,,,,,,,
,3772421198.28434,20.0001277923584,100.360321044922,,,5,,,,6.46999990567565,,,,,0.000665470917817589,1.02788039241009E-7,0.0711767088822706,8.09125356142689E-5,0.000665365784839057,1.02771800495733E-7,0.00066536527143304,8.75597118627638E-8,8.26562357460358E-7,5.38083621349372E-8,1.000158007792,10.005763053894,2,20,10,3,2.1766362163212,0.194261666107655,0.0403775237500668,172.74836730957,19.9999866485596,20.0003566741943,100.360321044922,100.360321044922,,,27.1056213378906,0,1,,,,,,1,1,1,20.0003318786621,0,20.0001407623291,,,,,,,,,,,,,,,,,,,,,,,,,,,,,,,,,
,3772421220.14388,20.0006990432739,80.2639694213867,,,5,,,,6.46999990567565,,,,,0.000658690393483709,1.45658557340073E-7,0.0690682764691601,8.94226597925146E-5,0.000658586314472547,1.45635541976914E-7,0.000658585835958571,1.33225349333446E-7,7.93905083701612E-7,5.88278622923771E-8,1.00015803397197,10.005763053894,2,20,10,3,2.15446833722033,0.192156695980033,0.0403775237500668,172.74836730957,20.0004730224609,20.0010948181152,80.2639694213867,80.2639694213867,,,27.1180572509766,0,1,,,,,,1,1,1,20.0009784698486,0,20.0006544113159,,,,,,,,,,,,,,,,,,,,,,,,,,,,,,,,,
,3772421241.83238,20.0005254745483,60.1919059753418,,,5,,,,6.46999990567565,,,,,0.000653593311228521,1.18918812484545E-7,0.0603457262242015,4.20628592451032E-5,0.00065349004279961,1.18900023187406E-7,0.000653489680342428,1.15704010538905E-7,6.88276244031352E-7,2.73824297530088E-8,1.00015802601746,10.005763053894,2,20,10,3,2.13782851174131,0.190298367205842,0.0403775237500668,172.74836730957,19.999963760376,20.0008907318115,60.1919059753418,60.1919059753418,,,27.1180572509766,0,1,,,,,,1,1,1,20.0008907318115,0,20.0006013870239,,,,,,,,,,,,,,,,,,,,,,,,,,,,,,,,,
,3772421263.46278,20.0001859664917,40.1319847106934,,,5,,,,6.46999990567565,,,,,0.000650191877940198,1.17657199860772E-7,0.0491845722051512,3.96667147249836E-5,0.000650089157054705,1.17638611729846E-7,0.000650088917527177,1.14800293971124E-7,5.58057738801207E-7,2.56853163085226E-8,1.00015801045807,10.005763053894,2,20,10,3,2.12674251793998,0.188848071921338,0.0403775237500668,172.74836730957,19.9994525909424,20.000919342041,40.1319847106934,40.1319847106934,,,27.1304969787598,0,1,,,,,,1,1,1,20.000919342041,0,20.0003684997559,,,,,,,,,,,,,,,,,,,,,,,,,,,,,,,,,
,3772421285.41141,20.0003538131714,20.1934909820557,,,5,,,,6.46999990567565,,,,,0.000648021435017282,8.38997910642262E-8,0.0440575512448476,2.78136140827838E-5,0.000647919052047101,8.38865354690521E-8,0.000647918860495326,8.19435821377578E-8,4.98216871601504E-7,1.79499353601363E-8,1.00015801815035,10.005763053894,2,20,10,3,2.11966278450049,0.187982763780438,0.0403775237500668,172.74836730957,19.9999694824219,20.0004940032959,20.1934909820557,20.1934909820557,,,27.1304969787598,0,1,,,,,,1,1,1,20.0003356933594,0,20.0002779527144,,,,,,,,,,,,,,,,,,,,,,,,,,,,,,,,,
,3772421305.93742,20.0004081726074,0.121428087353706,,,5,,,,6.46999990567565,,,,,0.00064734373247614,1.6063809968339E-7,0.0348938954391995,4.32396027362105E-5,0.000647241454966156,1.60612719558397E-7,0.000647241334936113,1.58183563349554E-7,3.94178671611272E-7,2.78281506748445E-8,1.0001580206416,10.005763053894,2,20,10,3,2.11747888470549,0.187402021649293,0.0403775237500668,172.74836730957,19.9997501373291,20.0007610321045,0.121428087353706,0.121428087353706,,,27.1304969787598,0,1,,,,,,1,1,1,20.0007591247559,0,20.0004388635809,,,,,,,,,,,,,,,,,,,,,,,,,,,,,,,,,