File: Experimental_Data/AC_Suceptibillity_FieldScans/HFCd_Up_52K.dat
[Header]
; MPMS3 Data File (default extension .dat)
; Copyright (c) 2007, Quantum Design, Inc. All rights reserved.
TITLE,HFCd_Up_52K
FILEOPENTIME,3772393310.72119,07/15/2019,11:01 pm
BYAPP,SQUID AC,0.9.1.0
INFO,MPMS3 Measurement Release 1.1.16 Build 347, MultiVu Release 2.3.3.2,APPNAME
INFO,0,MOMENT_UNITS
INFO,Cu2OSeO3,SAMPLE_MATERIAL
INFO,,SAMPLE_COMMENT
INFO,,SAMPLE_MASS
INFO,,SAMPLE_VOLUME
INFO,,SAMPLE_MOLECULAR_WEIGHT
INFO,,SAMPLE_SIZE
INFO,,SAMPLE_SHAPE
INFO,Quartz,SAMPLE_HOLDER
INFO,Standard,SAMPLE_HOLDER_DETAIL
INFO,64.77,SAMPLE_OFFSET
DATATYPE,COMMENT,1
DATATYPE,TIME,2
STARTUPAXIS,X,2
STARTUPAXIS,Y1,5
FIELDGROUP, VSM,2,3,4,5,6,8,9,10,11,14,15
FIELDGROUP, DC, 2,3,4,14,56,57,58,59,60,61,62,63,64,65,66,67,68,69
FIELDGROUP, AC, 2,3,4,11,16,17,18,19,20,21,22,23,24,25,26,27,28,29,30
STARTUPGROUP, All
[Data]
Comment,Time Stamp (sec),Temperature (K),Magnetic Field (Oe),Moment (emu),M. Std. Err. (emu),Transport Action,Averaging Time (sec),Frequency (Hz),Peak Amplitude (mm),Center Position (mm),Lockin Signal' (V),Lockin Signal (V),Range,M. Quad. Signal (emu),AC Moment (emu),AC M. Std Err. (emu),AC Phase (deg),AC Phase Std. Err. (deg),AC Susceptibility (emu/Oe),AC Suscept. Std Err. (emu/Oe),AC X' (emu/Oe),AC X' Std Err. (emu/Oe),AC X'' (emu/Oe),AC X'' Std Err. (emu/Oe),AC Drive (Oe),AC Frequency (Hz),AC Averaging Time (sec),AC Cycles,AC Range,AC Measure Type,AC Signal' (V),AC Signal'' (V),AC Trim Coil Ratio,AC Trim Coil Phase,Min. Temperature (K),Max. Temperature (K),Min. Field (Oe),Max. Field (Oe),Mass (grams),Motor Lag (deg),Pressure (Torr),Measure Count,Measurement Number,SQUID Status (code),Motor Status (code),Measure Status (code),Motor Current (amps),Motor Temp. (C),Temp. Status (code),Field Status (code),Chamber Status (code),Chamber Temp (K),Redirection State,Average Temp (K),Rotation Angle (deg),Rotator state,DC Moment Fixed Ctr (emu),DC Moment Err Fixed Ctr (emu),DC Moment Free Ctr (emu),DC Moment Err Free Ctr (emu),DC Fixed Fit,DC Free Fit,DC Calculated Center (mm),DC Calculated Center Err (mm),DC Scan Length (mm),DC Scan Time (s),DC Number of Points,DC Squid Drift,DC Min V (V),DC Max V (V),DC Scans per Measure,Map 01,Map 02,Map 03,Map 04,Map 05,Map 06,Map 07,Map 08,Map 09,Map 10,Map 11,Map 12,Map 13,Map 14,Map 15,Map 16
,3772393447.93468,51.9535541534424,1000.20318603516,,,5,,,,6.47999998182058,,,,,6.313107807642E-6,2.92598771016475E-7,10.8174481899938,0.0280159372224361,6.31214999212821E-6,2.92554378357465E-7,6.19998398471542E-6,2.40805373288744E-7,1.18466708926873E-6,1.66134994782531E-7,1.00015174156428,10.005763053894,2,20,1,3,0.0199390262509,0.00567768858162134,0.0403775237500668,172.74836730957,51.9208679199219,51.9760208129883,1000.20318603516,1000.20318603516,,,23.4800033569336,0,1,,,,,,1,1,1,51.9471855163574,0,51.946951352633,,,,,,,,,,,,,,,,,,,,,,,,,,,,,,,,,
,3772393470.4137,51.8995628356934,980.325439453125,,,5,,,,6.47999998182058,,,,,9.86017188116781E-6,3.06854067475479E-7,4.67097346100767,0.0179981510028117,9.85866746203218E-6,3.06807249109986E-7,9.82592455675195E-6,2.52132581505585E-7,8.02826713526097E-7,1.74813756466037E-7,1.00015259862871,10.005763053894,2,20,1,3,0.0319124591495705,0.0054817006197842,0.0403775237500668,172.74836730957,51.8937149047852,51.9027862548828,980.325439453125,980.325439453125,,,23.5067386627197,0,1,,,,,,1,1,1,51.898380279541,0,51.8971613103693,,,,,,,,,,,,,,,,,,,,,,,,,,,,,,,,,
,3772393492.24506,51.8967266082764,960.301879882813,,,5,,,,6.47999998182058,,,,,1.08327349428587E-5,2.63204218357667E-7,4.01950553143844,0.0123354401734844,1.08310798120488E-5,2.63164003452254E-7,1.08044380077663E-5,2.2837517042815E-7,7.59216195366676E-7,1.30767252188501E-7,1.0001528130933,10.005763053894,2,20,1,3,0.0351264699108043,0.00562261295483452,0.0403775237500668,172.74836730957,51.8955497741699,51.9018363952637,960.301879882813,960.301879882813,,,23.5204467773438,0,1,,,,,,1,1,1,51.8975563049316,0,51.89814453125,,,,,,,,,,,,,,,,,,,,,,,,,,,,,,,,,
,3772393513.99255,51.9265766143799,940.302673339844,,,5,,,,6.47999998182058,,,,,1.15511105571786E-5,2.74100201081241E-7,4.54691471599984,0.0136388961330716,1.15493431430708E-5,2.74058261515349E-7,1.15129945417004E-5,2.25869374769182E-7,9.15578352285026E-7,1.55212616259742E-7,1.00015303156949,10.005763053894,2,20,1,3,0.0373992312209565,0.00633919771442357,0.0403775237500668,172.74836730957,51.9201278686523,51.9401168823242,940.302673339844,940.302673339844,,,23.5339984893799,0,1,,,,,,1,1,1,51.9291000366211,0,51.930842590332,,,,,,,,,,,,,,,,,,,,,,,,,,,,,,,,,
,3772393535.61815,51.9454956054687,920.352111816406,,,5,,,,6.47999998182058,,,,,1.4754040161495E-5,3.05702377032341E-7,2.56093625346914,0.0103538948621117,1.47517868287468E-5,3.05655688181704E-7,1.47370537130322E-5,2.65832944198607E-7,6.59137694256313E-7,1.50858362368586E-7,1.00015274981766,10.005763053894,2,20,1,3,0.0480214287313485,0.00643561462362332,0.0403775237500668,172.74836730957,51.9442100524902,51.9457168579102,920.352111816406,920.352111816406,,,23.5572662353516,0,1,,,,,,1,1,1,51.945255279541,0,51.9450244903564,,,,,,,,,,,,,,,,,,,,,,,,,,,,,,,,,
,3772393557.56971,51.9567012786865,900.352844238281,,,5,,,,6.47999998182058,,,,,1.5407024466256E-5,3.21351715952732E-7,2.25089025026774,0.0139174598803709,1.54046688096534E-5,3.2130258289053E-7,1.53927829694004E-5,2.39652798018655E-7,6.05023629327139E-7,2.14013752301004E-7,1.00015291835428,10.005763053894,2,20,1,3,0.0501825032971371,0.00644790848632766,0.0403775237500668,172.74836730957,51.9541320800781,51.9644966125488,900.352844238281,900.352844238281,,,23.5600070953369,0,1,,,,,,1,1,1,51.9578056335449,0,51.9588588367809,,,,,,,,,,,,,,,,,,,,,,,,,,,,,,,,,
,3772393580.67763,52.0046443939209,880.487243652344,,,5,,,,6.47999998182058,,,,,1.6556885579624E-5,3.03844365963407E-7,3.14467353969853,0.0118493150234699,1.6554353888758E-5,3.03797905534462E-7,1.65294263681532E-5,2.32625419622354E-7,9.08128082396448E-7,1.95393402019234E-7,1.0001529320252,10.005763053894,2,20,1,3,0.0538132252496279,0.00776834746834276,0.0403775237500668,172.74836730957,52.0012092590332,52.0113296508789,880.487243652344,880.487243652344,,,23.5730857849121,0,1,,,,,,1,1,1,52.0059432983398,0,52.0074660561302,,,,,,,,,,,,,,,,,,,,,,,,,,,,,,,,,
,3772393603.58577,52.0088806152344,860.269470214844,,,5,,,,6.47999998182058,,,,,1.88319238644724E-5,2.52977992314714E-7,2.25553634833599,0.0102187033749079,1.8829047132062E-5,2.52939347830229E-7,1.88144591018059E-5,1.64010622496494E-7,7.41042919058826E-7,1.92558638832679E-7,1.00015278162459,10.005763053894,2,20,1,3,0.0613374370551122,0.00788357948391687,0.0403775237500668,172.74836730957,52.0050315856934,52.0092964172363,860.269470214844,860.269470214844,,,23.5729999542236,0,1,,,,,,1,1,1,52.0085182189941,0,52.007462310791,,,,,,,,,,,,,,,,,,,,,,,,,,,,,,,,,
,3772393626.69459,52.0229301452637,840.501037597656,,,5,,,,6.47999998182058,,,,,1.96879138668859E-5,3.07719282392812E-7,2.21913893212137,0.0091021611945901,1.9684907272089E-5,3.07672289745465E-7,1.96701443337224E-5,2.50775574472082E-7,7.62231068163393E-7,1.78252206509246E-7,1.00015273604063,10.005763053894,2,20,1,3,0.0641308420986012,0.00819982404529996,0.0403775237500668,172.74836730957,52.021240234375,52.023078918457,840.501037597656,840.501037597656,,,23.5846881866455,0,1,,,,,,1,1,1,52.0229682922363,0,52.0224314602939,,,,,,,,,,,,,,,,,,,,,,,,,,,,,,,,,
,3772393648.29689,52.0181312561035,820.331787109375,,,5,,,,6.47999998182058,,,,,2.00170366864928E-5,2.76696129218563E-7,2.41290617520764,0.00995295445157859,2.00139796323574E-5,2.76653871462866E-7,1.99962346784311E-5,1.92030512727048E-7,8.42602759032359E-7,1.99152320541788E-7,1.00015274594017,10.005763053894,2,20,1,3,0.0651744979769734,0.00855595262407084,0.0403775237500668,172.74836730957,52.0128707885742,52.0187034606934,820.331787109375,820.331787109375,,,23.5966625213623,0,1,,,,,,1,1,1,52.0178527832031,0,52.0161288868297,,,,,,,,,,,,,,,,,,,,,,,,,,,,,,,,,
,3772393670.24509,52.0094146728516,800.441833496094,,,5,,,,6.47999998182058,,,,,2.07852017896726E-5,2.5393062401164E-7,2.72678359292918,0.00699804440068209,2.07820285544793E-5,2.53891856931054E-7,2.0758498006088E-5,2.08846912335159E-7,9.88671517965181E-7,1.44374659216808E-7,1.00015269131139,10.005763053894,2,20,1,3,0.067626080320694,0.00925345655456524,0.0403775237500668,172.74836730957,52.0075950622559,52.0104103088379,800.441833496094,800.441833496094,,,23.5851726531982,0,1,,,,,,1,1,1,52.0090370178223,0,52.0086570739746,,,,,,,,,,,,,,,,,,,,,,,,,,,,,,,,,
,3772393693.25807,52.0123100280762,780.248352050781,,,5,,,,6.47999998182058,,,,,2.12748965223314E-5,2.68843532369849E-7,2.69594027936456,0.00566570462338613,2.12716481490337E-5,2.68802483796433E-7,2.12481049059446E-5,2.41415514542908E-7,1.00052630263523E-6,1.18208817916069E-7,1.0001527090555,10.005763053894,2,20,1,3,0.0692245891782458,0.00943270432763641,0.0403775237500668,172.74836730957,52.0100479125977,52.0125389099121,780.248352050781,780.248352050781,,,23.5728988647461,0,1,,,,,,1,1,1,52.0121192932129,0,52.0115978240967,,,,,,,,,,,,,,,,,,,,,,,,,,,,,,,,,
,3772393713.85284,52.0247077941895,760.443420410156,,,5,,,,6.47999998182058,,,,,2.15472214674568E-5,3.57806947814295E-7,5.31493482124728,0.00518891961716861,2.15439291804491E-5,3.57752277045382E-7,2.14513029285419E-5,3.44647980011162E-7,1.99561699735625E-6,9.59398853729838E-8,1.00015281738907,10.005763053894,2,20,1,3,0.0696011470490052,0.0127456356817078,0.0403775237500668,172.74836730957,52.0232276916504,52.0251083374023,760.443420410156,760.443420410156,,,23.5728206634521,0,1,,,,,,1,1,1,52.0249671936035,0,52.0244094848633,,,,,,,,,,,,,,,,,,,,,,,,,,,,,,,,,
,3772393737.05111,52.0403060913086,740.395629882813,,,5,,,,6.47999998182058,,,,,2.35491081928856E-5,4.06271437713754E-7,3.88082622762966,0.0055062760745117,2.35455121356578E-5,4.06209398194973E-7,2.34915218991115E-5,3.8839240238564E-7,1.5935936100445E-6,1.18984944219986E-7,1.00015272792569,10.005763053894,2,20,1,3,0.0763925912842533,0.0120200206680531,0.0403775237500668,172.74836730957,52.032657623291,52.0416526794434,740.395629882813,740.395629882813,,,23.5605144500732,0,1,,,,,,1,1,1,52.0395088195801,0,52.038308577104,,,,,,,,,,,,,,,,,,,,,,,,,,,,,,,,,
,3772393757.50362,52.017915725708,720.347839355469,,,5,,,,6.47999998182058,,,,,2.48486709391572E-5,2.98155098554078E-7,4.1019721753709,0.00431018833168664,2.48448790808076E-5,2.9810960067201E-7,2.47812344840037E-5,2.80799369641665E-7,1.77719835380854E-6,1.00105184789147E-7,1.00015262132439,10.005763053894,2,20,1,3,0.0805590118856814,0.0129926497565749,0.0403775237500668,172.74836730957,52.0098266601562,52.0207672119141,720.347839355469,720.347839355469,,,23.5715045928955,0,1,,,,,,1,1,1,52.0166358947754,0,52.0153076171875,,,,,,,,,,,,,,,,,,,,,,,,,,,,,,,,,
,3772393780.62432,52.0123233795166,700.16650390625,,,5,,,,6.47999998182058,,,,,2.66258480630939E-5,2.35636456986664E-7,3.56215981800137,0.00389009321151633,2.66217826595428E-5,2.35600478516166E-7,2.65703488396209E-5,2.13089915658022E-7,1.65404791731868E-6,1.00500116029305E-7,1.00015270966648,10.005763053894,2,20,1,3,0.0864481591937494,0.0131061388557091,0.0403775237500668,172.74836730957,52.0110092163086,52.0129699707031,700.16650390625,700.16650390625,,,23.5597515106201,0,1,,,,,,1,1,1,52.0121612548828,0,52.0119001215154,,,,,,,,,,,,,,,,,,,,,,,,,,,,,,,,,
,3772393803.66676,52.0068359375,680.446594238281,,,5,,,,6.47999998182058,,,,,2.90346485647942E-5,3.35660013411859E-7,3.75780076213519,0.00869188022512605,2.90302159975378E-5,3.35608769961077E-7,2.89678013066265E-5,2.2099698064679E-7,1.90261092278759E-6,2.52573911993677E-7,1.00015268805636,10.005763053894,2,20,1,3,0.0942199005529258,0.014611645303059,0.0403775237500668,172.74836730957,52.0036964416504,52.0078544616699,680.446594238281,680.446594238281,,,23.5584030151367,0,1,,,,,,1,1,1,52.0063247680664,0,52.0055455294522,,,,,,,,,,,,,,,,,,,,,,,,,,,,,,,,,
,3772393826.70435,52.0026988983154,660.362365722656,,,5,,,,6.47999998182058,,,,,3.37080034751436E-5,2.71239025636797E-7,3.02741254455858,0.00358339901471134,3.37028560971457E-5,2.71197606102894E-7,3.36558197470976E-5,2.44168765184158E-7,1.77997366716149E-6,1.18024385888614E-7,1.00015272824306,10.005763053894,2,20,1,3,0.109592958917853,0.0155653963074616,0.0403775237500668,172.74836730957,52.0025672912598,52.0033874511719,660.362365722656,660.362365722656,,,23.5347843170166,0,1,,,,,,1,1,1,52.0028686523438,0,52.0030256907145,,,,,,,,,,,,,,,,,,,,,,,,,,,,,,,,,
,3772393848.39582,52.0044345855713,640.290283203125,,,5,,,,6.47999998182058,,,,,4.12880603065715E-5,2.35770208042492E-7,2.63791054584312,0.00397298039329725,4.12817568746254E-5,2.35734213097458E-7,4.1238012085879E-5,1.69496055031341E-7,1.89994996265156E-6,1.63834387579318E-7,1.0001526929187,10.005763053894,2,20,1,3,0.134364398317965,0.0181497675733172,0.0403775237500668,172.74836730957,52.0028839111328,52.0049591064453,640.290283203125,640.290283203125,,,23.5342655181885,0,1,,,,,,1,1,1,52.0041542053223,0,52.0037456512451,,,,,,,,,,,,,,,,,,,,,,,,,,,,,,,,,
,3772393870.22656,51.9997634887695,620.509704589844,,,5,,,,6.47999998182058,,,,,5.39296131825538E-5,2.66789419085871E-7,2.16890657573789,0.00226136763352984,5.39213789207164E-5,2.66748684250174E-7,5.38827497345333E-5,2.38098578769391E-7,2.04068266938589E-6,1.20266068935487E-7,1.00015270866588,10.005763053894,2,20,1,3,0.175692555527829,0.0222657352097823,0.0403775237500668,172.74836730957,51.9984741210937,51.9999008178711,620.509704589844,620.509704589844,,,23.5215282440186,0,1,,,,,,1,1,1,51.9997520446777,0,51.9993041992187,,,,,,,,,,,,,,,,,,,,,,,,,,,,,,,,,
,3772393893.32294,51.9994621276855,600.510498046875,,,5,,,,6.47999998182058,,,,,8.58435244228066E-5,2.4139631446192E-7,1.29056046565657,0.0013938523275271,8.58304087100107E-5,2.41359432416923E-7,8.58086364118918E-5,2.10010751368516E-7,1.93312608466844E-6,1.1895318375836E-7,1.00015280962765,10.005763053894,2,20,1,3,0.280173040903884,0.0311446971710071,0.0403775237500668,172.74836730957,51.9993743896484,52.0006332397461,600.510498046875,600.510498046875,,,23.5215015411377,0,1,,,,,,1,1,1,51.9993858337402,0,51.9998157501221,,,,,,,,,,,,,,,,,,,,,,,,,,,,,,,,,
,3772393916.34827,52.0350646972656,580.377685546875,,,5,,,,6.47999998182058,,,,,0.000146098350981122,2.47315383160097E-7,0.785671466124313,0.00110541190194091,0.000146076025841944,2.47277591150038E-7,0.000146062292417554,1.87380974145169E-7,2.0030126073576E-6,1.61352339968694E-7,1.00015283232857,10.005763053894,2,20,1,3,0.477279951182104,0.0487914806018926,0.0403775237500668,172.74836730957,52.0318183898926,52.0358009338379,580.377685546875,580.377685546875,,,23.5201683044434,0,1,,,,,,1,1,1,52.0355987548828,0,52.0342917008833,,,,,,,,,,,,,,,,,,,,,,,,,,,,,,,,,
,3772393937.95251,52.0312557220459,560.196350097656,,,5,,,,6.47999998182058,,,,,0.000306738743468826,3.06080533581226E-7,0.352798225683066,0.000899705493401092,0.000306691924485957,3.06033815064041E-7,0.000306686110439567,1.32124215993991E-7,1.88844071902337E-6,2.76043271083765E-7,1.00015265802302,10.005763053894,2,20,1,3,1.00281324163945,0.0948442856919989,0.0403775237500668,172.74836730957,52.0230102539063,52.0325469970703,560.196350097656,560.196350097656,,,23.5313301086426,0,1,,,,,,1,1,1,52.0303382873535,0,52.0283702850342,,,,,,,,,,,,,,,,,,,,,,,,,,,,,,,,,
,3772393959.85097,52.0137176513672,540.427917480469,,,5,,,,6.47999998182058,,,,,0.000519237521451327,2.01054629946994E-7,0.211180325218808,0.00025396592131826,0.000519158267415662,2.0102394188969E-7,0.000519154741020874,1.51779614773298E-7,1.91350505132164E-6,1.31808853087109E-7,1.00015265871824,10.005763053894,2,20,1,3,1.69792415203852,0.156317214807769,0.0403775237500668,172.74836730957,52.0105819702148,52.015796661377,540.427917480469,540.427917480469,,,23.5186500549316,0,1,,,,,,1,1,1,52.0129737854004,0,52.0124877929687,,,,,,,,,,,,,,,,,,,,,,,,,,,,,,,,,
,3772393983.04285,52.0145969390869,520.404357910156,,,5,,,,6.47999998182058,,,,,0.000662229892880913,1.68526994144147E-7,0.159430696398212,0.000171484459800529,0.00066212878650644,1.68501264177013E-7,0.000662126223139287,1.24522585654672E-7,1.84243094707205E-6,1.13520049731872E-7,1.00015269895605,10.005763053894,2,20,1,3,2.16569621968453,0.197362883459024,0.0403775237500668,172.74836730957,52.0094299316406,52.015567779541,520.404357910156,520.404357910156,,,23.5049533843994,0,1,,,,,,1,1,1,52.0136260986328,0,52.01299902109,,,,,,,,,,,,,,,,,,,,,,,,,,,,,,,,,
,3772394010.5196,52.0069427490234,500.320159912109,,,5,,,,6.47999998182058,,,,,0.000721009671306538,2.16974850182237E-7,0.0912528408190392,0.000228462882937683,0.000720899595024865,2.1694172471156E-7,0.000720898680717504,1.41213250525271E-7,1.14814928323373E-6,1.64689191499969E-7,1.00015269294425,10.005763053894,2,20,10,3,2.35818150385739,0.212024306863925,0.0403775237500668,172.74836730957,52.0062675476074,52.008056640625,500.320159912109,500.320159912109,,,23.5048046112061,0,1,,,,,,1,1,1,52.006950378418,0,52.0069167613983,,,,,,,,,,,,,,,,,,,,,,,,,,,,,,,,,
,3772394038.20639,52.0050964355469,480.539520263672,,,5,,,,6.47999998182058,,,,,0.000739940001084367,3.38168788147017E-7,0.189029033256102,0.000257092293594177,0.000739827012331027,3.38117149811834E-7,0.000739822985980732,2.79630257255341E-7,2.4408173238419E-6,1.90079263004121E-7,1.00015272320618,10.005763053894,2,20,10,3,2.41972479416652,0.221669460709375,0.0403775237500668,172.74836730957,52.0038986206055,52.0055389404297,480.539520263672,480.539520263672,,,23.4804191589355,0,1,,,,,,1,1,1,52.0050239562988,0,52.0048037442294,,,,,,,,,,,,,,,,,,,,,,,,,,,,,,,,,
,3772394059.92721,52.0006332397461,460.467437744141,,,5,,,,6.47999998182058,,,,,0.000746909915995496,3.6124885473711E-7,0.186265193563081,0.000266192930010269,0.000746795844074923,3.61193682955638E-7,0.000746791897778848,3.01660138437726E-7,2.42778488418456E-6,1.98650541113761E-7,1.00015274846731,10.005763053894,2,20,10,3,2.44253178250583,0.223587208793586,0.0403775237500668,172.74836730957,51.9987106323242,52.0014419555664,460.467437744141,460.467437744141,,,23.4680290222168,0,1,,,,,,1,1,1,52.0003356933594,0,51.9999628933993,,,,,,,,,,,,,,,,,,,,,,,,,,,,,,,,,
,3772394080.48955,52.000093460083,440.358947753906,,,5,,,,6.47999998182058,,,,,0.000749981065425089,3.48400652104629E-7,0.181567039070202,0.000237279491767409,0.000749866542982661,3.48347451170016E-7,0.000749862777831855,2.99576823923438E-7,2.37628008883701E-6,1.7776296944131E-7,1.00015272376598,10.005763053894,2,20,10,3,2.45259685519079,0.224252661811744,0.0403775237500668,172.74836730957,52.0000267028809,52.0007591247559,440.358947753906,440.358947753906,,,23.478874206543,0,1,,,,,,1,1,1,52.0000839233398,0,52.0002532958984,,,,,,,,,,,,,,,,,,,,,,,,,,,,,,,,,
,3772394103.50087,52.0019207000732,420.262603759766,,,5,,,,6.47999998182058,,,,,0.000750989377051738,3.18279120116474E-7,0.173430644599622,0.000277952867711177,0.00075087472401438,3.18230528659705E-7,0.000750871284132183,2.40282392845939E-7,2.27284609173096E-6,2.08650523745485E-7,1.00015269263126,10.005763053894,2,20,10,3,2.45592955822548,0.224152568200199,0.0403775237500668,172.74836730957,52.001823425293,52.0022964477539,420.262603759766,420.262603759766,,,23.4655570983887,0,1,,,,,,1,1,1,52.0019798278809,0,52.0019798278809,,,,,,,,,,,,,,,,,,,,,,,,,,,,,,,,,
,3772394124.01338,52.0021343231201,400.190551757812,,,5,,,,6.47999998182058,,,,,0.000750802328473543,2.89659981944233E-7,0.172225373262224,0.000182176035456247,0.000750687696655321,2.89615756921031E-7,0.000750684305263411,2.55378683702749E-7,2.25648861336573E-6,1.36598003525648E-7,1.00015270240705,10.005763053894,2,20,10,3,2.45532601372094,0.223992338355959,0.0403775237500668,172.74836730957,52.000919342041,52.002685546875,400.190551757812,400.190551757812,,,23.4651508331299,0,1,,,,,,1,1,1,52.001953125,0,52.0017154693603,,,,,,,,,,,,,,,,,,,,,,,,,,,,,,,,,
,3772394146.99564,52.0033473968506,380.203491210937,,,5,,,,6.47999998182058,,,,,0.000750364496777003,2.59705317655025E-7,0.160841592254705,0.000206680994019829,0.000750249890164632,2.59665651670294E-7,0.000750246934010172,2.08335612663391E-7,2.1061102485662E-6,1.54992009966735E-7,1.00015275791956,10.005763053894,2,20,10,3,2.45394202689532,0.223321660856473,0.0403775237500668,172.74836730957,52.0021781921387,52.0038948059082,380.203491210937,380.203491210937,,,23.4650382995605,0,1,,,,,,1,1,1,52.0030517578125,0,52.0028907775879,,,,,,,,,,,,,,,,,,,,,,,,,,,,,,,,,
,3772394167.49629,52.002498626709,360.107147216797,,,5,,,,6.47999998182058,,,,,0.000749252256290936,3.03219639817845E-7,0.154082055478785,0.00027213035486811,0.000749137848649201,3.03173339464889E-7,0.000749135139765601,2.24437039534548E-7,2.01460843028267E-6,2.03818765199038E-7,1.00015271907826,10.005763053894,2,20,10,3,2.45033433722176,0.222648857101688,0.0403775237500668,172.74836730957,52.0016059875488,52.0032806396484,360.107147216797,360.107147216797,,,23.4406661987305,0,1,,,,,,1,1,1,52.0018997192383,0,52.0020725250244,,,,,,,,,,,,,,,,,,,,,,,,,,,,,,,,,
,3772394189.07722,52.0016937255859,340.253662109375,,,5,,,,6.47999998182058,,,,,0.000748076709839897,2.87934433676371E-7,0.146344068960004,0.000249369997517472,0.000747962509245193,2.87890477912037E-7,0.00074796006944318,2.19341486062806E-7,1.91043317580846E-6,1.86467798196313E-7,1.00015268224449,10.005763053894,2,20,10,3,2.44652322419841,0.22191713569662,0.0403775237500668,172.74836730957,52.0009269714355,52.0022964477539,340.253662109375,340.253662109375,,,23.4500617980957,0,1,,,,,,1,1,1,52.0011825561523,0,52.0013542175293,,,,,,,,,,,,,,,,,,,,,,,,,,,,,,,,,
,3772394211.03084,52.0127010345459,320.193725585937,,,5,,,,6.47999998182058,,,,,0.000746343890904002,2.32295155757533E-7,0.139726228249604,0.000178206928821438,0.000746229835866285,2.32259656796431E-7,0.00074622761688824,1.90467839703822E-7,1.81981601278813E-6,1.3291557551226E-7,1.00015284170136,10.005763053894,2,20,10,3,2.44088512547027,0.221068717647279,0.0403775237500668,172.74836730957,52.0115242004395,52.0133514404297,320.193725585937,320.193725585937,,,23.4158267974854,0,1,,,,,,1,1,1,52.0131225585937,0,52.0124567205256,,,,,,,,,,,,,,,,,,,,,,,,,,,,,,,,,
,3772394231.62182,52.0077533721924,300.109527587891,,,5,,,,6.47999998182058,,,,,0.00074467541517188,2.46612492020008E-7,0.133023625669049,0.000138570768566707,0.000744561698234026,2.4657483263599E-7,0.000744559691532424,2.2401843769483E-7,1.72864752858785E-6,1.03028576920356E-7,1.00015273003987,10.005763053894,2,20,10,3,2.43545760505121,0.220237273010839,0.0403775237500668,172.74836730957,52.0054397583008,52.0084419250488,300.109527587891,300.109527587891,,,23.4383010864258,0,1,,,,,,1,1,1,52.007438659668,0,52.0069141387939,,,,,,,,,,,,,,,,,,,,,,,,,,,,,,,,,
,3772394253.17196,52.035213470459,280.01318359375,,,5,,,,6.47999998182058,,,,,0.000742246783116964,2.12771974734392E-7,0.129259435605691,0.000175163283054916,0.000742133270946644,2.12739435410296E-7,0.000742131382385857,1.68439217520105E-7,1.67425327293816E-6,1.2994728692784E-7,1.0001529538895,10.005763053894,2,20,10,3,2.42753255874837,0.21930721081858,0.0403775237500668,172.74836730957,52.0329208374023,52.0364685058594,280.01318359375,280.01318359375,,,23.4145393371582,0,1,,,,,,1,1,1,52.0360565185547,0,52.0348964691162,,,,,,,,,,,,,,,,,,,,,,,,,,,,,,,,,
,3772394275.15494,52.0205554962158,260.183959960938,,,5,,,,6.47999998182058,,,,,0.000740093560614787,2.02002475519796E-7,0.122935173821396,0.000173129834259102,0.000739980619317255,2.01971649117697E-7,0.000739978915993365,1.56170607509381E-7,1.58771862489412E-6,1.28075323140226E-7,1.00015262737237,10.005763053894,2,20,10,3,2.42051781655095,0.218352523450166,0.0403775237500668,172.74836730957,52.014102935791,52.0233421325684,260.183959960938,260.183959960938,,,23.4002017974854,0,1,,,,,,1,1,1,52.0192794799805,0,52.0181987762451,,,,,,,,,,,,,,,,,,,,,,,,,,,,,,,,,
,3772394296.83555,52.0085830688477,240.136184692383,,,5,,,,6.47999998182058,,,,,0.000737771656386186,2.79213059855529E-7,0.113349691996287,0.000120030440918246,0.00073765905033059,2.79170443578434E-7,0.000737657606816718,2.6483444414451E-7,1.4593286333338E-6,8.83111191325771E-8,1.00015265325566,10.005763053894,2,20,10,3,2.41296358902035,0.217212064767292,0.0403775237500668,172.74836730957,52.0058364868164,52.0094833374023,240.136184692383,240.136184692383,,,23.4006404876709,0,1,,,,,,1,1,1,52.0081520080566,0,52.0076328277588,,,,,,,,,,,,,,,,,,,,,,,,,,,,,,,,,
,3772394318.60017,52.0035858154297,220.100570678711,,,5,,,,6.47999998182058,,,,,0.000735333554399685,2.40774988092542E-7,0.111480542327186,0.000172851487221994,0.000735221235511717,2.40738210797734E-7,0.000735219843827217,2.04510496834505E-7,1.43052090479616E-6,1.2700528659311E-7,1.00015276883004,10.005763053894,2,20,10,3,2.40499986506303,0.216364231944728,0.0403775237500668,172.74836730957,52.002269744873,52.0037803649902,220.100570678711,220.100570678711,,,23.3998222351074,0,1,,,,,,1,1,1,52.0035629272461,0,52.0030960083008,,,,,,,,,,,,,,,,,,,,,,,,,,,,,,,,,
,3772394340.16963,52.0289039611816,200.271347045898,,,5,,,,6.47999998182058,,,,,0.000732521479894177,1.83021632642541E-7,0.109199376516851,0.000134582519354089,0.000732409498392552,1.8299365388995E-7,0.000732408168186579,1.54213505850726E-7,1.3958901133721E-6,9.85133086299663E-8,1.00015289466053,10.005763053894,2,20,10,3,2.3958144611075,0.215390487001161,0.0403775237500668,172.74836730957,52.0265350341797,52.0295867919922,200.271347045898,200.271347045898,,,23.3875904083252,0,1,,,,,,1,1,1,52.029354095459,0,52.028358112682,,,,,,,,,,,,,,,,,,,,,,,,,,,,,,,,,
,3772394362.38217,52.0186729431152,180.187149047852,,,5,,,,6.47999998182058,,,,,0.000730640381493612,1.23629918398005E-7,0.103644723415857,9.98503237592527E-5,0.000730528861897175,1.23611048432757E-7,0.000730527666653666,9.98150576680618E-8,1.3214833830436E-6,7.29153314287669E-8,1.00015265597604,10.005763053894,2,20,10,3,2.38968615275675,0.214554366843293,0.0403775237500668,172.74836730957,52.0118522644043,52.0202865600586,180.187149047852,180.187149047852,,,23.3743171691895,0,1,,,,,,1,1,1,52.0179824829102,0,52.0164405822754,,,,,,,,,,,,,,,,,,,,,,,,,,,,,,,,,
,3772394383.1715,52.0073928833008,160.139373779297,,,5,,,,6.47999998182058,,,,,0.000729368292325622,1.81981068601195E-7,0.11485930031709,0.000133479520169526,0.000729256924916695,1.81953281870819E-7,0.000729255459579787,1.5376311675092E-7,1.46192066425534E-6,9.72825817431087E-8,1.00015271354323,10.005763053894,2,20,10,3,2.38548686602025,0.214596583051754,0.0403775237500668,172.74836730957,52.0063285827637,52.007884979248,160.139373779297,160.139373779297,,,23.3741722106934,0,1,,,,,,1,1,1,52.0071296691895,0,52.0069243691184,,,,,,,,,,,,,,,,,,,,,,,,,,,,,,,,,
,3772394405.9037,52.0063781738281,140.103729248047,,,5,,,,6.47999998182058,,,,,0.000727900214823768,1.96152274635776E-7,0.130818605103013,9.98234781382728E-5,0.000727789021862667,1.96122310704183E-7,0.000727787124855031,1.82225746333968E-7,1.6616976457456E-6,7.25102622321572E-8,1.0001527818609,10.005763053894,2,20,10,3,2.38062887234594,0.21477670580716,0.0403775237500668,172.74836730957,52.0057525634766,52.0065765380859,140.103729248047,140.103729248047,,,23.3613185882568,0,1,,,,,,1,1,1,52.0064888000488,0,52.0062347412109,,,,,,,,,,,,,,,,,,,,,,,,,,,,,,,,,
,3772394426.36557,52.0389766693115,120.177383422852,,,5,,,,6.47999998182058,,,,,0.000723980639793818,1.70047080022317E-7,0.144714471400724,6.87003249344498E-5,0.000723869879488189,1.70021064870088E-7,0.000723867570567902,1.62641106650225E-7,1.82830806187107E-6,4.9548288841785E-8,1.00015301134744,10.005763053894,2,20,10,3,2.36776111882361,0.214143825424908,0.0403775237500668,172.74836730957,52.0342903137207,52.0410652160645,120.177383422852,120.177383422852,,,23.3488578796387,0,1,,,,,,1,1,1,52.0403861999512,0,52.0388547723943,,,,,,,,,,,,,,,,,,,,,,,,,,,,,,,,,
,3772394448.27403,52.0255470275879,100.190322875977,,,5,,,,6.47999998182058,,,,,0.000716777929679508,1.92432124148874E-7,0.125300996709634,0.000124844915951662,0.000716668547219122,1.92402758429974E-7,0.000716666833451386,1.70380387878781E-7,1.56729190982647E-6,8.9383135309404E-8,1.00015262628841,10.005763053894,2,20,10,3,2.34427973908823,0.211168967802678,0.0403775237500668,172.74836730957,52.0167007446289,52.0288124084473,100.190322875977,100.190322875977,,,23.3361110687256,0,1,,,,,,1,1,1,52.0238914489746,0,52.0220080288974,,,,,,,,,,,,,,,,,,,,,,,,,,,,,,,,,
,3772394470.00695,52.040491104126,80.0939712524414,,,5,,,,6.47999998182058,,,,,0.000703699257209976,1.72058337533437E-7,0.112246905029823,0.000100020234444197,0.000703591712411097,1.72032042238799E-7,0.00070359036222365,1.57022322537438E-7,1.37839021086395E-6,7.02781173751867E-8,1.00015285114503,10.005763053894,2,20,10,3,2.30155522924175,0.206741945691866,0.0403775237500668,172.74836730957,52.034351348877,52.0407333374023,80.0939712524414,80.0939712524414,,,23.3349838256836,0,1,,,,,,1,1,1,52.0405654907227,0,52.0386981964111,,,,,,,,,,,,,,,,,,,,,,,,,,,,,,,,,
,3772394491.61137,52.0472049713135,60.0704803466797,,,5,,,,6.47999998182058,,,,,0.000684246796109063,9.24461635010454E-8,0.0934862184383043,7.07195962595519E-5,0.000684142249509837,9.2432038579949E-8,0.000684141338828913,7.87754455508669E-8,1.11627494983707E-6,4.83540167339547E-8,1.00015281412499,10.005763053894,2,20,10,3,2.23800175134607,0.200246174845958,0.0403775237500668,172.74836730957,52.0403671264648,52.0474739074707,60.0704803466797,60.0704803466797,,,23.334508895874,0,1,,,,,,1,1,1,52.046947479248,0,52.0449100494385,,,,,,,,,,,,,,,,,,,,,,,,,,,,,,,,,
,3772394513.54854,52.0573539733887,40.1805572509766,,,5,,,,6.47999998182058,,,,,0.000660669831580491,6.63501432892074E-8,0.068727331672318,4.86568273872233E-5,0.000660568959531826,6.63400128510326E-8,0.000660568484304051,5.80456294072658E-8,7.9236431501503E-7,3.21201216029692E-8,1.00015270479669,10.005763053894,2,20,10,3,2.1609735900984,0.192366507250613,0.0403775237500668,172.74836730957,52.0454940795898,52.0578193664551,40.1805572509766,40.1805572509766,,,23.3214111328125,0,1,,,,,,1,1,1,52.0568618774414,0,52.053871790568,,,,,,,,,,,,,,,,,,,,,,,,,,,,,,,,,
,3772394536.52692,52.0255584716797,20.1449203491211,,,5,,,,6.47999998182058,,,,,0.000644188616479197,9.30718726668943E-8,0.0468626390109215,6.05481840041432E-5,0.000644090384928175,9.30576802484399E-8,0.000644090169488833,8.45070718332095E-8,5.26806199173022E-7,3.89651981054587E-8,1.00015251205936,10.005763053894,2,20,10,3,2.10713971081831,0.186718511451798,0.0403775237500668,172.74836730957,52.0151138305664,52.0291175842285,20.1449203491211,20.1449203491211,,,23.3096237182617,0,1,,,,,,1,1,1,52.0237121582031,0,52.0216194152832,,,,,,,,,,,,,,,,,,,,,,,,,,,,,,,,,
,3772394558.21803,52.041145324707,0.121428087353706,,,5,,,,6.47999998182058,,,,,0.000636924107291366,7.62552568749019E-8,0.039101908080216,2.57277113183905E-5,0.000636826748528154,7.6243600670634E-8,0.000636826600227892,7.44759130797777E-8,4.34606863937403E-7,1.63225308747293E-8,1.00015288108334,10.005763053894,2,20,10,3,2.08340529454736,0.184285991696743,0.0403775237500668,172.74836730957,52.0374641418457,52.0415000915527,0.121428087353706,0.121428087353706,,,23.3094463348389,0,1,,,,,,1,1,1,52.0414848327637,0,52.0401233673096,,,,,,,,,,,,,,,,,,,,,,,,,,,,,,,,,