File: Experimental_Data/AC_Suceptibillity_FieldScans/HFCd_Up_10K.dat
[Header]
; MPMS3 Data File (default extension .dat)
; Copyright (c) 2007, Quantum Design, Inc. All rights reserved.
TITLE,HFCd_Up_10K
FILEOPENTIME,3772411060.89243,07/16/2019,3:57 am
BYAPP,SQUID AC,0.9.1.0
INFO,MPMS3 Measurement Release 1.1.16 Build 347, MultiVu Release 2.3.3.2,APPNAME
INFO,0,MOMENT_UNITS
INFO,Cu2OSeO3,SAMPLE_MATERIAL
INFO,,SAMPLE_COMMENT
INFO,,SAMPLE_MASS
INFO,,SAMPLE_VOLUME
INFO,,SAMPLE_MOLECULAR_WEIGHT
INFO,,SAMPLE_SIZE
INFO,,SAMPLE_SHAPE
INFO,Quartz,SAMPLE_HOLDER
INFO,Standard,SAMPLE_HOLDER_DETAIL
INFO,64.77,SAMPLE_OFFSET
DATATYPE,COMMENT,1
DATATYPE,TIME,2
STARTUPAXIS,X,2
STARTUPAXIS,Y1,5
FIELDGROUP, VSM,2,3,4,5,6,8,9,10,11,14,15
FIELDGROUP, DC, 2,3,4,14,56,57,58,59,60,61,62,63,64,65,66,67,68,69
FIELDGROUP, AC, 2,3,4,11,16,17,18,19,20,21,22,23,24,25,26,27,28,29,30
STARTUPGROUP, All
[Data]
Comment,Time Stamp (sec),Temperature (K),Magnetic Field (Oe),Moment (emu),M. Std. Err. (emu),Transport Action,Averaging Time (sec),Frequency (Hz),Peak Amplitude (mm),Center Position (mm),Lockin Signal' (V),Lockin Signal (V),Range,M. Quad. Signal (emu),AC Moment (emu),AC M. Std Err. (emu),AC Phase (deg),AC Phase Std. Err. (deg),AC Susceptibility (emu/Oe),AC Suscept. Std Err. (emu/Oe),AC X' (emu/Oe),AC X' Std Err. (emu/Oe),AC X'' (emu/Oe),AC X'' Std Err. (emu/Oe),AC Drive (Oe),AC Frequency (Hz),AC Averaging Time (sec),AC Cycles,AC Range,AC Measure Type,AC Signal' (V),AC Signal'' (V),AC Trim Coil Ratio,AC Trim Coil Phase,Min. Temperature (K),Max. Temperature (K),Min. Field (Oe),Max. Field (Oe),Mass (grams),Motor Lag (deg),Pressure (Torr),Measure Count,Measurement Number,SQUID Status (code),Motor Status (code),Measure Status (code),Motor Current (amps),Motor Temp. (C),Temp. Status (code),Field Status (code),Chamber Status (code),Chamber Temp (K),Redirection State,Average Temp (K),Rotation Angle (deg),Rotator state,DC Moment Fixed Ctr (emu),DC Moment Err Fixed Ctr (emu),DC Moment Free Ctr (emu),DC Moment Err Free Ctr (emu),DC Fixed Fit,DC Free Fit,DC Calculated Center (mm),DC Calculated Center Err (mm),DC Scan Length (mm),DC Scan Time (s),DC Number of Points,DC Squid Drift,DC Min V (V),DC Max V (V),DC Scans per Measure,Map 01,Map 02,Map 03,Map 04,Map 05,Map 06,Map 07,Map 08,Map 09,Map 10,Map 11,Map 12,Map 13,Map 14,Map 15,Map 16
,3772411265.85924,10.0001835823059,1000.21539306641,,,5,,,,6.46999990567565,,,,,0.000101331608874507,2.79007072820448E-7,-0.000459765165995663,0.00137252668111714,0.000101315442511288,2.78962560256894E-7,0.000101315442508026,2.41862949103312E-7,-8.12997251097534E-10,1.39005121762222E-7,1.00015956465094,10.005763053894,2,20,1,3,0.331453835033642,0.0294907281532968,0.0403775237500668,172.74836730957,9.99930191040039,10.0008907318115,1000.21539306641,1000.21539306641,,,18.814868927002,0,1,,,,,,1,1,1,9.99984836578369,0,10.0001046840961,,,,,,,,,,,,,,,,,,,,,,,,,,,,,,,,,
,3772411288.24802,10.0001535415649,980.458984375,,,5,,,,6.46999990567565,,,,,0.00013652732833869,3.87623276650094E-7,-0.0263518351444842,0.00141985639868189,0.00013650553143497,3.87561391697507E-7,0.000136505516997313,3.35648677486417E-7,-6.27824800436411E-8,1.93762219320814E-7,1.00015967780567,10.005763053894,2,20,1,3,0.446596888401954,0.0395225472892086,0.0403775237500668,172.74836730957,9.99899959564209,10.0009756088257,980.458984375,980.458984375,,,18.8493576049805,0,1,,,,,,1,1,1,10.000394821167,0,10.0000117041848,,,,,,,,,,,,,,,,,,,,,,,,,,,,,,,,,
,3772411310.22349,10.000096321106,960.399108886719,,,5,,,,6.46999990567565,,,,,0.000191054721808749,3.66301038995434E-7,0.0264254298813071,0.000784274141395151,0.000191024219981639,3.66242559148113E-7,0.000191024199664747,3.34253236331121E-7,8.8102422110214E-8,1.49694308955053E-7,1.00015967518209,10.005763053894,2,20,1,3,0.624912021186246,0.0558696189922761,0.0403775237500668,172.74836730957,9.99904537200928,10.0014657974243,960.399108886719,960.399108886719,,,18.8608226776123,0,1,,,,,,1,1,1,10.0002288818359,0,9.99996671676636,,,,,,,,,,,,,,,,,,,,,,,,,,,,,,,,,
,3772411331.97407,10.0022420883179,940.326965332031,,,5,,,,6.46999990567565,,,,,0.000265696049828712,2.64793751413751E-7,0.0340493421809862,0.000707203967854808,0.000265653666246845,2.64751511765671E-7,0.000265653619337648,1.86565407512303E-7,1.57870826230716E-7,1.87847575714931E-7,1.00015954450193,10.005763053894,2,20,1,3,0.869043715682743,0.0777937479459458,0.0403775237500668,172.74836730957,9.99974346160889,10.003381729126,940.326965332031,940.326965332031,,,18.9023685455322,0,1,,,,,,1,1,1,10.0020217895508,0,10.0013221740723,,,,,,,,,,,,,,,,,,,,,,,,,,,,,,,,,
,3772411353.79128,10.0000114440918,920.206359863281,,,5,,,,6.46999990567565,,,,,0.000356907905379149,3.48790111084546E-7,0.0457820702730354,0.000502186867600671,0.00035685092653121,3.48734428208368E-7,0.000356850812610574,2.99220032487448E-7,2.85140940498275E-7,1.79117485400025E-7,1.00015967129046,10.005763053894,2,20,1,3,1.16736137255302,0.104713784619032,0.0403775237500668,172.74836730957,9.99899864196777,10.0008716583252,920.206359863281,920.206359863281,,,18.9097595214844,0,1,,,,,,1,1,1,10.0002546310425,0,9.99985027313232,,,,,,,,,,,,,,,,,,,,,,,,,,,,,,,,,
,3772411376.87404,10.0001540184021,900.364990234375,,,5,,,,6.46999990567565,,,,,0.000464725790931842,3.54151577421312E-7,0.0498864842852083,0.000280609012824389,0.000464651649583407,3.54095076843955E-7,0.000464651473459629,3.29280648275578E-7,4.0456442836272E-7,1.30221265991162E-7,1.00015956329543,10.005763053894,2,20,1,3,1.52000047010617,0.136423254479326,0.0403775237500668,172.74836730957,9.99904155731201,10.0009813308716,900.364990234375,900.364990234375,,,18.9328804016113,0,1,,,,,,1,1,1,10.0002975463867,0,10.0000547929244,,,,,,,,,,,,,,,,,,,,,,,,,,,,,,,,,
,3772411399.87689,10.0000348091125,880.256530761719,,,5,,,,6.46999990567565,,,,,0.000544126188225578,4.01090657429774E-7,0.084218420999127,0.000548229536227826,0.000544039382482464,4.01026670484599E-7,0.000544038794764197,2.68102482518761E-7,7.99677072979677E-7,2.98233883566641E-7,1.00015955782965,10.005763053894,2,20,1,3,1.77960550997346,0.160759829418054,0.0403775237500668,172.74836730957,9.99912643432617,10.0008277893066,880.256530761719,880.256530761719,,,18.9567165374756,0,1,,,,,,1,1,1,9.99972057342529,0,9.99986028671265,,,,,,,,,,,,,,,,,,,,,,,,,,,,,,,,,
,3772411423.0456,9.99987316131592,860.305847167969,,,5,,,,6.46999990567565,,,,,0.000593119083680065,5.62392302107753E-7,0.0674066188946503,0.000729628351065922,0.000593024398469046,5.62302522103593E-7,0.000593023988073784,3.59147988733013E-7,6.97673733413219E-7,4.32662511148231E-7,1.00015966495015,10.005763053894,2,20,1,3,1.93989443407073,0.174623955863753,0.0403775237500668,172.74836730957,9.99899768829346,10.0010852813721,860.305847167969,860.305847167969,,,18.979284286499,0,1,,,,,,1,1,1,9.99977779388428,0,9.99978897788308,,,,,,,,,,,,,,,,,,,,,,,,,,,,,,,,,
,3772411447.95988,9.99981355667114,840.258178710937,,,5,,,,6.46999990567565,,,,,0.000629731629372248,2.70002150884156E-7,0.0406098925360974,0.000304660279039141,0.000629631173176062,2.69959079537927E-7,0.000629631015024085,1.89975861588217E-7,4.4626763710185E-7,1.91799574136075E-7,1.00015954768516,10.005763053894,2,20,10,3,2.05973113599025,0.184395795590855,0.0403775237500668,172.74836730957,9.99879169464111,10.0014200210571,840.258178710937,840.258178710937,,,19.0109004974365,0,1,,,,,,1,1,1,9.99989032745361,0,9.9997763633728,,,,,,,,,,,,,,,,,,,,,,,,,,,,,,,,,
,3772411474.35616,9.99998235702515,820.271057128906,,,5,,,,6.46999990567565,,,,,0.000657646596444725,2.65715853624445E-7,0.0840715584178593,0.000310423924495315,0.000657541606804769,2.65673433558785E-7,0.000657540898946848,1.70067873076287E-7,9.64827221857247E-7,2.04106079885491E-7,1.0001596699568,10.005763053894,2,20,10,3,2.15089189210303,0.194155354462779,0.0403775237500668,172.74836730957,9.99902725219727,10.0007238388062,820.271057128906,820.271057128906,,,19.0269050598145,0,1,,,,,,1,1,1,10.0002546310425,0,9.99983701705933,,,,,,,,,,,,,,,,,,,,,,,,,,,,,,,,,
,3772411497.34188,9.99991893768311,800.320434570312,,,5,,,,6.46999990567565,,,,,0.000680621438151011,3.30758115729571E-7,0.0945266316206492,0.000370306151946471,0.000680512782683187,3.30705312988154E-7,0.000680511856558858,2.14172846106984E-7,1.1227101278203E-6,2.51984118604779E-7,1.00015966704901,10.005763053894,2,20,10,3,2.2259995204394,0.20129681995485,0.0403775237500668,172.74836730957,9.99882888793945,10.0005674362183,800.320434570312,800.320434570312,,,19.0516662597656,0,1,,,,,,1,1,1,9.99995040893555,0,9.99968490600586,,,,,,,,,,,,,,,,,,,,,,,,,,,,,,,,,
,3772411520.37795,10.0000967979431,780.442626953125,,,5,,,,6.46999990567565,,,,,0.000699416698646586,3.46970364735615E-7,0.100746375565349,0.000315588914301901,0.000699305117052277,3.46915010743424E-7,0.000699304035991288,2.67715013455012E-7,1.22962668894144E-6,2.20632491373988E-7,1.00015956067186,10.005763053894,2,20,10,3,2.28745083841886,0.207055249356196,0.0403775237500668,172.74836730957,9.99905490875244,10.0011205673218,780.442626953125,780.442626953125,,,19.0738372802734,0,1,,,,,,1,1,1,10.0001182556152,0,10.0000247088346,,,,,,,,,,,,,,,,,,,,,,,,,,,,,,,,,
,3772411543.40437,9.99994945526123,760.261291503906,,,5,,,,6.46999990567565,,,,,0.00071446365758963,3.95696628763742E-7,0.169233935873261,0.000377117326616687,0.000714349680300636,3.95633503888836E-7,0.000714346564209232,2.89798136801845E-7,2.10996400139078E-6,2.69337909150451E-7,1.00015955391615,10.005763053894,2,20,10,3,2.33641092141802,0.214252219055034,0.0403775237500668,172.74836730957,9.99899005889893,10.0008182525635,760.261291503906,760.261291503906,,,19.0991363525391,0,1,,,,,,1,1,1,9.99995517730713,0,9.99983730316162,,,,,,,,,,,,,,,,,,,,,,,,,,,,,,,,,
,3772411566.53127,10.0002579689026,740.213500976563,,,5,,,,6.46999990567565,,,,,0.000728599235180546,3.85179656032948E-7,0.163539857756911,0.000412045039423916,0.000728482992561521,3.85118203467737E-7,0.000728480025059024,2.4127818765262E-7,2.07931272121504E-6,3.00168064266145E-7,1.00015956806159,10.005763053894,2,20,10,3,2.38266158408042,0.21820325661161,0.0403775237500668,172.74836730957,9.99893283843994,10.0010099411011,740.213500976563,740.213500976563,,,19.1400699615479,0,1,,,,,,1,1,1,10.0001573562622,0,9.99998588562012,,,,,,,,,,,,,,,,,,,,,,,,,,,,,,,,,
,3772411589.57559,9.99989938735962,720.505737304687,,,5,,,,6.46999990567565,,,,,0.00074139965191222,4.44660880556309E-7,0.171226836020261,0.000416275037846914,0.000741281379266894,4.44589945510034E-7,0.000741278069090245,3.20114929373366E-7,2.2152953903561E-6,3.08523340512351E-7,1.00015955162052,10.005763053894,2,20,10,3,2.42449499017666,0.222310903649905,0.0403775237500668,172.74836730957,9.99891376495361,10.0008096694946,720.505737304687,720.505737304687,,,19.1464920043945,0,1,,,,,,1,1,1,9.99986553192139,0,9.9997594833374,,,,,,,,,,,,,,,,,,,,,,,,,,,,,,,,,
,3772411610.20123,9.9990439414978,700.178649902344,,,5,,,,6.46999990567565,,,,,0.000752435515352624,3.60655870345328E-7,0.169885609933031,0.000329286339013053,0.000752315425550718,3.60598309144212E-7,0.000752312118524976,2.62079787159153E-7,2.23065954850036E-6,2.476798855787E-7,1.00015962693018,10.005763053894,2,20,10,3,2.46059281548209,0.225508907394376,0.0403775237500668,172.74836730957,9.99795722961426,10.0001630783081,700.178649902344,700.178649902344,,,19.1696643829346,0,1,,,,,,1,1,1,9.99905490875244,0,9.99893636703491,,,,,,,,,,,,,,,,,,,,,,,,,,,,,,,,,
,3772411633.12942,9.99803066253662,680.22802734375,,,5,,,,6.46999990567565,,,,,0.000762689865538246,3.32591434766113E-7,0.162493124500483,0.000159803127451843,0.000762568174549751,3.32538368136687E-7,0.000762565107836965,3.09516678741154E-7,2.1626709728646E-6,1.21577925068888E-7,1.00015958047104,10.005763053894,2,20,10,3,2.49415925218143,0.228207133170226,0.0403775237500668,172.74836730957,9.99409198760986,9.99999904632568,680.22802734375,680.22802734375,,,19.1918277740479,0,1,,,,,,1,1,1,9.99704647064209,0,9.99629068374634,,,,,,,,,,,,,,,,,,,,,,,,,,,,,,,,,
,3772411654.95415,9.99796867370605,660.1923828125,,,5,,,,6.46999990567565,,,,,0.000772033964664006,4.04836786943672E-7,0.165891403830418,0.000327331237784402,0.000771910784971269,4.04772194356679E-7,0.000771907549486873,3.16299679341086E-7,2.23494969308201E-6,2.52576804503199E-7,1.00015957762883,10.005763053894,2,20,10,3,2.52470629951177,0.231098611487739,0.0403775237500668,172.74836730957,9.99783325195313,10.0002365112305,660.1923828125,660.1923828125,,,19.1827201843262,0,1,,,,,,1,1,1,9.99814128875732,0,9.99849729537964,,,,,,,,,,,,,,,,,,,,,,,,,,,,,,,,,
,3772411676.66772,9.99751043319702,640.43603515625,,,5,,,,6.46999990567565,,,,,0.000780707303051687,3.49954661422904E-7,0.169475582514549,0.000352743879889188,0.000780582666519297,3.49898792680133E-7,0.000780579251779652,2.15896496693578E-7,2.30888750145827E-6,2.7535044549529E-7,1.00015967115046,10.005763053894,2,20,10,3,2.55305877462661,0.233800587827643,0.0403775237500668,172.74836730957,9.99715900421143,9.99914264678955,640.43603515625,640.43603515625,,,19.1824588775635,0,1,,,,,,1,1,1,9.99770545959473,0,9.99777460098267,,,,,,,,,,,,,,,,,,,,,,,,,,,,,,,,,
,3772411699.78395,9.99888563156128,620.242553710937,,,5,,,,6.46999990567565,,,,,0.000789473600138589,4.35106229291655E-7,0.162669993743107,0.000361197455794894,0.000789347604733127,4.35036788862274E-7,0.000789344423411022,3.28653722157653E-7,2.24105507442877E-6,2.85032872798068E-7,1.00015961967162,10.005763053894,2,20,10,3,2.58175791881965,0.236063390257968,0.0403775237500668,172.74836730957,9.99789524078369,9.99984836578369,620.242553710937,620.242553710937,,,19.1818408966064,0,1,,,,,,1,1,1,9.9989128112793,0,9.99879602952437,,,,,,,,,,,,,,,,,,,,,,,,,,,,,,,,,
,3772411722.81098,9.99933528900146,600.194763183594,,,5,,,,6.46999990567565,,,,,0.000797574270591269,4.21773814456315E-7,0.153195396251635,0.000480597142380028,0.000797446965927528,4.21706493110073E-7,0.000797444115449358,1.75804976099855E-7,2.13218249953226E-6,3.83313157496225E-7,1.00015964028855,10.005763053894,2,20,10,3,2.60829200171376,0.237998320109272,0.0403775237500668,172.74836730957,9.99840927124023,10.0000858306885,600.194763183594,600.194763183594,,,19.1798839569092,0,1,,,,,,1,1,1,9.99937152862549,0,9.99920701980591,,,,,,,,,,,,,,,,,,,,,,,,,,,,,,,,,
,3772411745.90497,9.99950981140137,580.474853515625,,,5,,,,6.46999990567565,,,,,0.000805564005676224,4.30699828855852E-7,0.160049831056405,0.000444809446897235,0.000805435419288467,4.30631079340221E-7,0.000805432276858403,2.38890798473497E-7,2.24989757065823E-6,3.58293612695537E-7,1.00015964829045,10.005763053894,2,20,10,3,2.63439553622298,0.240642034588887,0.0403775237500668,172.74836730957,9.99740505218506,10.0001964569092,580.474853515625,580.474853515625,,,19.1713104248047,0,1,,,,,,1,1,1,9.99932193756104,0,9.99900618466464,,,,,,,,,,,,,,,,,,,,,,,,,,,,,,,,,
,3772411767.51153,10.0002813339233,560.475646972656,,,5,,,,6.46999990567565,,,,,0.000813382758837088,3.75763367901897E-7,0.155558526731458,0.000385246728278375,0.000813252988762855,3.75703417233387E-7,0.000813249991410612,2.07313668204795E-7,2.20798604095695E-6,3.13327465595209E-7,1.00015956913288,10.005763053894,2,20,10,3,2.65998756427135,0.242712238285454,0.0403775237500668,172.74836730957,9.99908638000488,10.0019254684448,560.475646972656,560.475646972656,,,19.1808757781982,0,1,,,,,,1,1,1,10.000147819519,0,10.0003556338224,,,,,,,,,,,,,,,,,,,,,,,,,,,,,,,,,
,3772411789.42817,10.0003223419189,540.209289550781,,,5,,,,6.46999990567565,,,,,0.000821488742833555,2.42145336438777E-7,0.158852210858961,0.000168218691483193,0.000821357677956755,2.42106703226862E-7,0.000821354521184073,1.98863512658016E-7,2.27720640167116E-6,1.38090401841311E-7,1.00015957101311,10.005763053894,2,20,10,3,2.686486090299,0.245227211193102,0.0403775237500668,172.74836730957,9.99876689910889,10.0008039474487,540.209289550781,540.209289550781,,,19.1807708740234,0,1,,,,,,1,1,1,10.0001840591431,0,9.99994697570801,,,,,,,,,,,,,,,,,,,,,,,,,,,,,,,,,
,3772411812.50319,9.99989652633667,520.173645019531,,,5,,,,6.46999990567565,,,,,0.000829080886855018,4.31665402209245E-7,0.181044210374818,0.00028956561231239,0.000828948531940943,4.31596490914672E-7,0.000828944393648032,3.58798285635118E-7,2.6193217710612E-6,2.398735525129E-7,1.00015966602144,10.005763053894,2,20,10,3,2.71122216685195,0.248485579920745,0.0403775237500668,172.74836730957,9.99910449981689,10.0009260177612,520.173645019531,520.173645019531,,,19.182788848877,0,1,,,,,,1,1,1,9.99979877471924,0,9.99976758956909,,,,,,,,,,,,,,,,,,,,,,,,,,,,,,,,,
,3772411833.11497,9.99961805343628,500.417327880859,,,5,,,,6.46999990567565,,,,,0.000836105149453908,5.32932717854119E-7,0.231566468130334,0.000535122455633216,0.000835971683854848,5.32847646993721E-7,0.000835964856270735,2.89388425522422E-7,3.37865170731411E-6,4.47415862571276E-7,1.00015965325338,10.005763053894,2,20,10,3,2.73397440202498,0.252943880199589,0.0403775237500668,172.74836730957,9.99884223937988,10.0009155273438,500.417327880859,500.417327880859,,,19.2029914855957,0,1,,,,,,1,1,1,9.99958038330078,0,9.99970655441284,,,,,,,,,,,,,,,,,,,,,,,,,,,,,,,,,
,3772411856.02944,10.0001940727234,480.454528808594,,,5,,,,6.46999990567565,,,,,0.000844403707659758,4.83071157829505E-7,0.20913504409641,0.000291633371889138,0.0008442689917667,4.82994088814E-7,0.000844263367593058,4.15674419053305E-7,3.08165526766714E-6,2.45963548465954E-7,1.00015956513193,10.005763053894,2,20,10,3,2.76121349733083,0.254314410739472,0.0403775237500668,172.74836730957,9.99876022338867,10.0009832382202,480.454528808594,480.454528808594,,,19.2144832611084,0,1,,,,,,1,1,1,10.0001440048218,0,9.9999363899231,,,,,,,,,,,,,,,,,,,,,,,,,,,,,,,,,
,3772411877.41401,9.99940061569214,460.188201904297,,,5,,,,6.46999990567565,,,,,0.000852903648818589,3.69068213523458E-7,0.198824918471484,0.000317035808034134,0.000852767510212946,3.6900930366647E-7,0.000852762375731657,2.51169779333603E-7,2.9592247779221E-6,2.70336102180086E-7,1.00015964328379,10.005763053894,2,20,10,3,2.78905860267614,0.256312018409534,0.0403775237500668,172.74836730957,9.99893474578857,10.0008907318115,460.188201904297,460.188201904297,,,19.2171211242676,0,1,,,,,,1,1,1,9.99953174591064,0,9.99951067837802,,,,,,,,,,,,,,,,,,,,,,,,,,,,,,,,,
,3772411899.60067,9.99957323074341,440.431823730469,,,5,,,,6.46999990567565,,,,,0.000861303648285671,4.25265057138777E-7,0.183430320156554,0.000344796498025675,0.000861166162076007,4.25197173900474E-7,0.000861161748876374,3.04394139422788E-7,2.75698692507056E-6,2.96878501373896E-7,1.00015965119824,10.005763053894,2,20,10,3,2.81660057791904,0.258020027857985,0.0403775237500668,172.74836730957,9.9987211227417,10.000804901123,440.431823730469,440.431823730469,,,19.219841003418,0,1,,,,,,1,1,1,9.99954319000244,0,9.99959774017334,,,,,,,,,,,,,,,,,,,,,,,,,,,,,,,,,
,3772411920.13143,9.99968433380127,420.189788818359,,,5,,,,6.46999990567565,,,,,0.000869987106131753,3.52636270870103E-7,0.188243775219274,0.000277242622232711,0.000869848229388539,3.52579979257857E-7,0.000869843534675185,2.57251940663037E-7,2.85785831654291E-6,2.41110100988267E-7,1.00015965629235,10.005763053894,2,20,10,3,2.84497901381294,0.26079869289799,0.0403775237500668,172.74836730957,9.99880409240723,10.00071144104,420.189788818359,420.189788818359,,,19.2396945953369,0,1,,,,,,1,1,1,9.99966335296631,0,9.99964923858643,,,,,,,,,,,,,,,,,,,,,,,,,,,,,,,,,
,3772411941.50178,9.99977684020996,400.287719726562,,,5,,,,6.46999990567565,,,,,0.000878903089182012,3.11149722156887E-7,0.177714460937797,0.000261754279546804,0.000878762886077094,3.11100087381816E-7,0.000878758658985727,2.09478722904805E-7,2.72565664545165E-6,2.30004193481652E-7,1.0001595460017,10.005763053894,2,20,10,3,2.87418789645075,0.262882049508124,0.0403775237500668,172.74836730957,9.99903678894043,10.0008611679077,400.287719726562,400.287719726562,,,19.2314643859863,0,1,,,,,,1,1,1,9.99979591369629,0,9.99976947090843,,,,,,,,,,,,,,,,,,,,,,,,,,,,,,,,,
,3772411963.65157,10.0004096031189,380.2763671875,,,5,,,,6.46999990567565,,,,,0.000887829879604636,2.79292669339593E-7,0.179349470387592,0.000246220746693168,0.000887688226743369,2.79248108318781E-7,0.000887683877787086,1.73799752074744E-7,2.77867156524072E-6,2.18570702927851E-7,1.00015957501406,10.005763053894,2,20,10,3,2.90337676717339,0.265572735900865,0.0403775237500668,172.74836730957,9.99913787841797,10.0008945465088,380.2763671875,380.2763671875,,,19.2444171905518,0,1,,,,,,1,1,1,10.0003623962402,0,10.0001096725464,,,,,,,,,,,,,,,,,,,,,,,,,,,,,,,,,
,3772411985.48461,9.99996185302734,360.228576660156,,,5,,,,6.46999990567565,,,,,0.000896764771287565,4.03215139001893E-7,0.178187702931067,0.00030400274422997,0.000896621608596977,4.03150768315139E-7,0.000896617272599217,2.97095720723218E-7,2.78845472827884E-6,2.72515457765313E-7,1.00015966901669,10.005763053894,2,20,10,3,2.93260515845635,0.268123000686273,0.0403775237500668,172.74836730957,9.99908828735352,10.0010013580322,360.228576660156,360.228576660156,,,19.2648868560791,0,1,,,,,,1,1,1,10.0001268386841,0,9.99995260238648,,,,,,,,,,,,,,,,,,,,,,,,,,,,,,,,,
,3772412007.32853,10.0004148483276,340.180786132812,,,5,,,,6.46999990567565,,,,,0.000902078425337688,7.76399357756209E-7,0.211626178489606,0.00048048081486792,0.000901934498910429,7.76275483398338E-7,0.000901928346603071,6.44261897202773E-7,3.33135387768206E-6,4.33047611629491E-7,1.00015957525456,10.005763053894,2,20,10,3,2.94982816576665,0.271370023649204,0.0403775237500668,172.74836730957,9.99910163879395,10.0013723373413,340.180786132812,340.180786132812,,,19.2678241729736,0,1,,,,,,1,1,1,10.0003414154053,0,10.0001507759094,,,,,,,,,,,,,,,,,,,,,,,,,,,,,,,,,
,3772412028.74458,10.0000329017639,320.278747558594,,,5,,,,6.46999990567565,,,,,0.000895080187396676,2.83423880031707E-6,0.349787377991181,0.00192375944843101,0.000894937290724114,2.83378632320998E-6,0.000894920613480856,2.25172831144729E-6,5.46350580357547E-6,1.72048380900218E-6,1.0001596722743,10.005763053894,2,20,10,3,2.92629013805092,0.276259568741309,0.0403775237500668,172.74836730957,9.99918842315674,10.0010137557983,320.278747558594,320.278747558594,,,19.2875957489014,0,1,,,,,,1,1,1,10.0001125335693,0,9.99986336447976,,,,,,,,,,,,,,,,,,,,,,,,,,,,,,,,,
,3772412051.00926,10.0000495910645,300.170257568359,,,5,,,,6.46999990567565,,,,,0.000859297719536114,4.05747055582175E-6,0.552823586099289,0.00307743338665709,0.000859160633147866,4.05682325515834E-6,0.000859120641539814,3.07815703541001E-6,8.28956158430654E-6,2.64249204141647E-6,1.00015955850741,10.005763053894,2,20,10,3,2.80835321532281,0.275108646510148,0.0403775237500668,172.74836730957,9.99899387359619,10.0008220672607,300.170257568359,300.170257568359,,,19.2824935913086,0,1,,,,,,1,1,1,9.99981117248535,0,9.99991321563721,,,,,,,,,,,,,,,,,,,,,,,,,,,,,,,,,
,3772412071.65782,10.0000123977661,280.158905029297,,,5,,,,6.46999990567565,,,,,0.000808080026782583,3.3302535260157E-6,0.576299115475724,0.00273048835601771,0.000807951112686802,3.32972224618227E-6,0.000807910242928679,2.49501282962241E-6,8.12649141788455E-6,2.20498553662846E-6,1.00015955680208,10.005763053894,2,20,10,3,2.6408616339262,0.25973650673748,0.0403775237500668,172.74836730957,9.99903869628906,10.0007905960083,280.158905029297,280.158905029297,,,19.302303314209,0,1,,,,,,1,1,1,10.0001268386841,0,9.99994697570801,,,,,,,,,,,,,,,,,,,,,,,,,,,,,,,,,
,3772412093.56731,9.99974298477173,260.171844482422,,,5,,,,6.46999990567565,,,,,0.000760253672539815,2.228916230422E-6,0.392237746901687,0.00200701547657909,0.000760132310589288,2.22856042073498E-6,0.000760114498658136,1.62489985174897E-6,5.20370363307045E-6,1.52518261878788E-6,1.00015965898152,10.005763053894,2,20,10,3,2.48533765070541,0.236327939455662,0.0403775237500668,172.74836730957,9.99889373779297,10.0010290145874,260.171844482422,260.171844482422,,,19.3058032989502,0,1,,,,,,1,1,1,9.9997444152832,0,9.99973999370228,,,,,,,,,,,,,,,,,,,,,,,,,,,,,,,,,
,3772412115.16807,10.0000500679016,240.221206665039,,,5,,,,6.46999990567565,,,,,0.000728621867701044,5.3693740923465E-7,0.235834214823385,0.00042370781906359,0.000728505628414409,5.3685174995899E-7,0.000728499457199605,4.39386248091756E-7,2.99858155702656E-6,3.08463168663425E-7,1.00015955852927,10.005763053894,2,20,10,3,2.38254320837145,0.219941258707007,0.0403775237500668,172.74836730957,9.99896335601807,10.0009117126465,240.221206665039,240.221206665039,,,19.3256378173828,0,1,,,,,,1,1,1,10.0002021789551,0,9.99998273849487,,,,,,,,,,,,,,,,,,,,,,,,,,,,,,,,,
,3772412136.88134,10.0001840591431,220.149124145508,,,5,,,,6.46999990567565,,,,,0.000705233704322594,2.25947196659211E-7,0.188728992315467,0.00014370513660898,0.000705121191890321,2.25911149220602E-7,0.000705117366591591,2.0198495917733E-7,2.32262432745174E-6,1.01182625031699E-7,1.00015956467281,10.005763053894,2,20,10,3,2.30624300983576,0.210935794116694,0.0403775237500668,172.74836730957,9.99901008605957,10.0011024475098,220.149124145508,220.149124145508,,,19.3194198608398,0,1,,,,,,1,1,1,10.0001125335693,0,10.0000312805176,,,,,,,,,,,,,,,,,,,,,,,,,,,,,,,,,
,3772412158.78279,9.99973821640015,200.174209594727,,,5,,,,6.46999990567565,,,,,0.000687678450582424,2.3138601062489E-7,0.155693319041287,0.000115228294080174,0.000687568752954619,2.31349100210653E-7,0.000687566214434804,2.17436355153194E-7,1.86837024267351E-6,7.90179576170675E-8,1.00015954423079,10.005763053894,2,20,10,3,2.24895546151539,0.204340256446192,0.0403775237500668,172.74836730957,9.99910354614258,10.0009870529175,200.174209594727,200.174209594727,,,19.3392734527588,0,1,,,,,,1,1,1,9.99985218048096,0,9.99978294372559,,,,,,,,,,,,,,,,,,,,,,,,,,,,,,,,,
,3772412179.34802,10.0000200271606,180.308578491211,,,5,,,,6.46999990567565,,,,,0.000673902527890604,1.7393180267677E-7,0.134794230684959,0.000102780797280778,0.000673795019076399,1.73904055041045E-7,0.000673793154436623,1.5956900013098E-7,1.58517081409309E-6,6.91401081639166E-8,1.00015955715189,10.005763053894,2,20,10,3,2.20397916272882,0.199396042167543,0.0403775237500668,172.74836730957,9.99899005889893,10.0008115768433,180.308578491211,180.308578491211,,,19.3427314758301,0,1,,,,,,1,1,1,9.9998083114624,0,9.9998664855957,,,,,,,,,,,,,,,,,,,,,,,,,,,,,,,,,
,3772412202.33061,10.0001182556152,160.212219238281,,,5,,,,6.46999990567565,,,,,0.000662910015094805,1.69814439584204E-7,0.110681036755939,0.000127362461960921,0.000662804181049921,1.69787328590839E-7,0.000662802944372929,1.47351387946902E-7,1.28037019345302E-6,8.43522697983577E-8,1.00015967618779,10.005763053894,2,20,10,3,2.16811380110937,0.195184470609339,0.0403775237500668,172.74836730957,9.99929332733154,10.0010118484497,160.212219238281,160.212219238281,,,19.3715648651123,0,1,,,,,,1,1,1,10.0002708435059,0,10.0000264167786,,,,,,,,,,,,,,,,,,,,,,,,,,,,,,,,,
,3772412222.82907,9.99977254867554,140.261596679688,,,5,,,,6.46999990567565,,,,,0.000653769517849147,1.94850411190461E-7,0.103598940928266,0.00012162767818772,0.000653665153450442,1.94819306274361E-7,0.000653664084910929,1.77905244843649E-7,1.1819191796467E-6,7.93995337161652E-8,1.00015966033703,10.005763053894,2,20,10,3,2.13824557896794,0.192183225185425,0.0403775237500668,172.74836730957,9.99900722503662,10.0010356903076,140.261596679688,140.261596679688,,,19.3559856414795,0,1,,,,,,1,1,1,9.99977016448975,0,9.99993162155151,,,,,,,,,,,,,,,,,,,,,,,,,,,,,,,,,
,3772412244.78497,9.99988889694214,120.201675415039,,,5,,,,6.46999990567565,,,,,0.000646287517062476,4.12897723612249E-7,0.0998566305502608,0.000191021474109128,0.000646184343605255,4.12831808544266E-7,0.000646183362230514,3.94053888547147E-7,1.12618693993725E-6,1.23091978076569E-7,1.00015966567163,10.005763053894,2,20,10,3,2.11378993672367,0.189800356112586,0.0403775237500668,172.74836730957,9.99895000457764,10.0009412765503,120.201675415039,120.201675415039,,,19.3772506713867,0,1,,,,,,1,1,1,9.99998092651367,0,9.99969148635864,,,,,,,,,,,,,,,,,,,,,,,,,,,,,,,,,
,3772412266.446,10.0002670288086,100.275314331055,,,5,,,,6.46999990567565,,,,,0.000640628652275555,1.5388629353909E-7,0.0751281476568186,5.17617310769319E-5,0.000640526444446343,1.53861742055243E-7,0.00064052589380717,1.50283249718971E-7,8.39879514964504E-7,3.29906126372241E-8,1.00015956847699,10.005763053894,2,20,10,3,2.0953655195444,0.187189456266855,0.0403775237500668,172.74836730957,9.99925327301025,10.0012826919556,100.275314331055,100.275314331055,,,19.3878192901611,0,1,,,,,,1,1,1,10.0004053115845,0,10.0001859664917,,,,,,,,,,,,,,,,,,,,,,,,,,,,,,,,,
,3772412288.07508,10.0002069473267,80.2396850585938,,,5,,,,6.46999990567565,,,,,0.000635987134120856,1.37942609495153E-7,0.0687334125645327,6.97064099003242E-5,0.000635885668564891,1.37920602094668E-7,0.00063588521101386,1.30632938533234E-7,7.62823752286148E-7,4.4239437748779E-8,1.00015956572224,10.005763053894,2,20,10,3,2.08020760728689,0.185556445312847,0.0403775237500668,172.74836730957,9.99911975860596,10.0013027191162,80.2396850585938,80.2396850585938,,,19.4189910888672,0,1,,,,,,1,1,1,9.99993228912354,0,10.0000816345215,,,,,,,,,,,,,,,,,,,,,,,,,,,,,,,,,
,3772412310.0877,9.99988269805908,60.1797637939453,,,5,,,,6.46999990567565,,,,,0.000632485093981599,1.3834470301155E-7,0.0593615345087004,4.02828205352776E-5,0.000632384196542153,1.38322633517063E-7,0.000632383857138942,1.35986070168214E-7,6.55184202204464E-7,2.53167861961434E-8,1.00015955085532,10.005763053894,2,20,10,3,2.06878597397887,0.184151880722114,0.0403775237500668,172.74836730957,9.99903297424316,10.001072883606,60.1797637939453,60.1797637939453,,,19.4112949371338,0,1,,,,,,1,1,1,9.9997444152832,0,9.99990645321933,,,,,,,,,,,,,,,,,,,,,,,,,,,,,,,,,
,3772412333.06043,9.99991989135742,40.1684112548828,,,5,,,,6.46999990567565,,,,,0.000630011742900663,8.51178812833078E-8,0.0517137345513303,2.77011562827438E-5,0.000629911238949514,8.51043026738948E-8,0.000629910982373608,8.33131670753197E-8,5.68542019254037E-7,1.73683195931489E-8,1.00015955256064,10.005763053894,2,20,10,3,2.06072316660405,0.18311255114341,0.0403775237500668,172.74836730957,9.99906253814697,10.0013513565063,40.1684112548828,40.1684112548828,,,19.4220085144043,0,1,,,,,,1,1,1,9.99991703033447,0,9.99999566511674,,,,,,,,,,,,,,,,,,,,,,,,,,,,,,,,,
,3772412356.07056,10.0003118515015,20.2420616149902,,,5,,,,6.46999990567565,,,,,0.000628717147851617,1.05489849450428E-7,0.0416445011115405,2.35172002007817E-5,0.000628616839128095,1.05473019064651E-7,0.000628616673082997,1.04451533185414E-7,4.56899837532895E-7,1.46435981175614E-8,1.00015957053212,10.005763053894,2,20,10,3,2.05652346907593,0.18233100592956,0.0403775237500668,172.74836730957,9.99927711486816,10.0015201568604,20.2420616149902,20.2420616149902,,,19.4424991607666,0,1,,,,,,1,1,1,10.0000495910645,0,10.0001343727112,,,,,,,,,,,,,,,,,,,,,,,,,,,,,,,,,
,3772412376.62216,10.0006923675537,0.18214213848114,,,5,,,,6.46999990567565,,,,,0.000628264779283497,1.51560993586255E-7,0.0389845060509,3.45643886976868E-5,0.000628164531775457,1.51536810132997E-7,0.000628164386369498,1.50000878984925E-7,4.27408132126784E-7,2.15207139527021E-8,1.00015958797889,10.005763053894,2,20,10,3,2.05505499634733,0.182060287147558,0.0403775237500668,172.74836730957,9.99928855895996,10.0008506774902,0.18214213848114,0.18214213848114,,,19.4360847473145,0,1,,,,,,1,1,1,10.0006952285767,0,10.0003511255438,,,,,,,,,,,,,,,,,,,,,,,,,,,,,,,,,