File: Experimental_Data/AC_Suceptibillity_FieldScans/HFCd_Up_48K.dat
[Header]
; MPMS3 Data File (default extension .dat)
; Copyright (c) 2007, Quantum Design, Inc. All rights reserved.
TITLE,HFCd_Up_48K
FILEOPENTIME,3762248006.63907,03/20/2019,12:53 pm
BYAPP,SQUID AC,0.9.1.0
INFO,MPMS3 Measurement Release 1.1.16 Build 347, MultiVu Release 2.3.3.2,APPNAME
INFO,0,MOMENT_UNITS
INFO,SrM,SAMPLE_MATERIAL
INFO,MvsH,SAMPLE_COMMENT
INFO,,SAMPLE_MASS
INFO,,SAMPLE_VOLUME
INFO,,SAMPLE_MOLECULAR_WEIGHT
INFO,,SAMPLE_SIZE
INFO,,SAMPLE_SHAPE
INFO,Quartz,SAMPLE_HOLDER
INFO,Standard,SAMPLE_HOLDER_DETAIL
INFO,65.34,SAMPLE_OFFSET
DATATYPE,COMMENT,1
DATATYPE,TIME,2
STARTUPAXIS,X,2
STARTUPAXIS,Y1,5
FIELDGROUP, VSM,2,3,4,5,6,8,9,10,11,14,15
FIELDGROUP, DC, 2,3,4,14,56,57,58,59,60,61,62,63,64,65,66,67,68,69
FIELDGROUP, AC, 2,3,4,11,16,17,18,19,20,21,22,23,24,25,26,27,28,29,30
STARTUPGROUP, All
[Data]
Comment,Time Stamp (sec),Temperature (K),Magnetic Field (Oe),Moment (emu),M. Std. Err. (emu),Transport Action,Averaging Time (sec),Frequency (Hz),Peak Amplitude (mm),Center Position (mm),Lockin Signal' (V),Lockin Signal (V),Range,M. Quad. Signal (emu),AC Moment (emu),AC M. Std Err. (emu),AC Phase (deg),AC Phase Std. Err. (deg),AC Susceptibility (emu/Oe),AC Suscept. Std Err. (emu/Oe),AC X' (emu/Oe),AC X' Std Err. (emu/Oe),AC X'' (emu/Oe),AC X'' Std Err. (emu/Oe),AC Drive (Oe),AC Frequency (Hz),AC Averaging Time (sec),AC Cycles,AC Range,AC Measure Type,AC Signal' (V),AC Signal'' (V),AC Trim Coil Ratio,AC Trim Coil Phase,Min. Temperature (K),Max. Temperature (K),Min. Field (Oe),Max. Field (Oe),Mass (grams),Motor Lag (deg),Pressure (Torr),Measure Count,Measurement Number,SQUID Status (code),Motor Status (code),Measure Status (code),Motor Current (amps),Motor Temp. (C),Temp. Status (code),Field Status (code),Chamber Status (code),Chamber Temp (K),Redirection State,Average Temp (K),Rotation Angle (deg),Rotator state,DC Moment Fixed Ctr (emu),DC Moment Err Fixed Ctr (emu),DC Moment Free Ctr (emu),DC Moment Err Free Ctr (emu),DC Fixed Fit,DC Free Fit,DC Calculated Center (mm),DC Calculated Center Err (mm),DC Scan Length (mm),DC Scan Time (s),DC Number of Points,DC Squid Drift,DC Min V (V),DC Max V (V),DC Scans per Measure,Map 01,Map 02,Map 03,Map 04,Map 05,Map 06,Map 07,Map 08,Map 09,Map 10,Map 11,Map 12,Map 13,Map 14,Map 15,Map 16
,3762248149.48156,47.9149799346924,1000.44604492187,,,5,,,,31.6299982368946,,,,,6.49477530244299E-6,5.63655238830553E-7,9.05384863233025,0.0708494531702623,6.49374957532129E-6,5.63566220128776E-7,6.41284318100368E-6,3.18728914534132E-7,1.02187371178642E-6,4.6477818742937E-7,1.00015795606372,10.005763053894,2,20,1,3,0.0206828065231219,0.00520715258416894,0.0413267537951469,172.859115600586,47.8982009887695,47.9380683898926,1000.44604492187,1000.44604492187,,,25.6555767059326,0,1,,,,,,1,1,1,47.9092025756836,0,47.9129128089318,,,,,,,,,,,,,,,,,,,,,,,,,,,,,,,,,
,3762248172.93349,47.8939895629883,980.240356445313,,,5,,,,31.6299982368946,,,,,8.46329516850583E-6,6.41736027119873E-7,5.29307827291723,0.0634624969205082,8.46194920680629E-6,6.41633968513086E-7,8.42586618546531E-6,3.45742941572204E-7,7.80617321868875E-7,5.4051453995508E-7,1.00015906047964,10.005763053894,2,20,1,3,0.0273387315908594,0.00500242426446276,0.0413267537951469,172.859115600586,47.8923645019531,47.8943061828613,980.240356445313,980.240356445313,,,25.7056732177734,0,1,,,,,,1,1,1,47.8936729431152,0,47.8933559417725,,,,,,,,,,,,,,,,,,,,,,,,,,,,,,,,,
,3762248194.87192,47.8822174072266,960.301879882813,,,5,,,,31.6299982368946,,,,,1.0588485873919E-5,3.89185890588485E-7,2.92737515931989,0.0285310885732356,1.05868027778392E-5,3.89124027423671E-7,1.05729877472105E-5,2.44754111065819E-7,5.40669172600812E-7,3.02511047459094E-7,1.00015898058319,10.005763053894,2,20,1,3,0.0344329434184324,0.00484065310435797,0.0413267537951469,172.859115600586,47.8815002441406,47.8938064575195,960.301879882813,960.301879882813,,,25.7221431732178,0,1,,,,,,1,1,1,47.8815498352051,0,47.8843668157404,,,,,,,,,,,,,,,,,,,,,,,,,,,,,,,,,
,3762248217.864,47.9447574615479,940.314880371094,,,5,,,,31.6299982368946,,,,,9.94288698843651E-6,5.19349037123172E-7,6.04224265801382,0.0470263993614877,9.94130086915866E-6,5.19266189000622E-7,9.88607255887118E-6,2.14607358000634E-7,1.0464379254733E-6,4.72843586116189E-7,1.0001595484634,10.005763053894,2,20,1,3,0.0320388599581055,0.00629503818344911,0.0413267537951469,172.859115600586,47.9330062866211,47.961109161377,940.314880371094,940.314880371094,,,25.7393798828125,0,1,,,,,,1,1,1,47.9491119384766,0,47.9498310089111,,,,,,,,,,,,,,,,,,,,,,,,,,,,,,,,,
,3762248240.94811,47.9603538513184,920.279235839844,,,5,,,,31.6299982368946,,,,,1.4103501888374E-5,6.76245222176214E-7,2.50607419296629,0.0287778819898026,1.41012597841889E-5,6.7613771609334E-7,1.4087773221908E-5,5.42341006830551E-7,6.16581826910036E-7,4.03767808813361E-7,1.00015900027511,10.005763053894,2,20,1,3,0.0459098863510226,0.00610819918900071,0.0413267537951469,172.859115600586,47.9590492248535,47.9612426757812,920.279235839844,920.279235839844,,,25.7225875854492,0,1,,,,,,1,1,1,47.9599800109863,0,47.9600765228271,,,,,,,,,,,,,,,,,,,,,,,,,,,,,,,,,
,3762248261.4662,47.9638690948486,900.182861328125,,,5,,,,31.6299982368946,,,,,1.52915080537683E-5,3.60677472898106E-7,1.70858386645884,0.0210833745144206,1.52890763806215E-5,3.60620117552745E-7,1.52822789245662E-5,1.60221520159218E-7,4.55859017940681E-7,3.23072644557884E-7,1.00015904643853,10.005763053894,2,20,1,3,0.0498645535691097,0.00592819038680547,0.0413267537951469,172.859115600586,47.9634895324707,47.9661102294922,900.182861328125,900.182861328125,,,25.7380714416504,0,1,,,,,,1,1,1,47.9640464782715,0,47.9642208099365,,,,,,,,,,,,,,,,,,,,,,,,,,,,,,,,,
,3762248284.53158,47.9978713989258,880.183654785156,,,5,,,,31.6299982368946,,,,,1.63271418877449E-5,6.32456933406837E-7,3.77177029041183,0.037004501443701,1.63245444693339E-5,6.32356318412843E-7,1.62891855129087E-5,1.71896225555645E-7,1.07386566073548E-6,6.08544329590185E-7,1.00015911123375,10.005763053894,2,20,1,3,0.0529794376693007,0.00824122719275188,0.0413267537951469,172.859115600586,47.9954376220703,48.0006942749023,880.183654785156,880.183654785156,,,25.704906463623,0,1,,,,,,1,1,1,47.9984931945801,0,47.9989187067205,,,,,,,,,,,,,,,,,,,,,,,,,,,,,,,,,
,3762248307.58534,48.003396987915,860.403015136719,,,5,,,,31.6299982368946,,,,,1.7785743138714E-5,4.32475101617993E-7,2.95163481575973,0.0210753221569482,1.7782915300447E-5,4.32406340384216E-7,1.77593237274323E-5,2.13184554319735E-7,9.15694996782802E-7,3.7620152711541E-7,1.00015901994803,10.005763053894,2,20,1,3,0.0578351356629656,0.00814924808642778,0.0413267537951469,172.859115600586,48.0032119750977,48.0048980712891,860.403015136719,860.403015136719,,,25.7036743164062,0,1,,,,,,1,1,1,48.0035133361816,0,48.0038471221924,,,,,,,,,,,,,,,,,,,,,,,,,,,,,,,,,
,3762248328.93408,48.0369968414307,840.367370605469,,,5,,,,31.6299982368946,,,,,2.01421038274706E-5,5.07315615741898E-7,2.37311289249648,0.0236959915493422,2.01388980965427E-5,5.07234873562554E-7,2.01216263938219E-5,1.66580633974603E-7,8.33887168854172E-7,4.79101356022543E-7,1.00015918104916,10.005763053894,2,20,1,3,0.0655874698047069,0.00856570189782721,0.0413267537951469,172.859115600586,48.032054901123,48.0374908447266,840.367370605469,840.367370605469,,,25.7021942138672,0,1,,,,,,1,1,1,48.0374755859375,0,48.0354981855913,,,,,,,,,,,,,,,,,,,,,,,,,,,,,,,,,
,3762248351.2123,48.038257598877,820.416809082031,,,5,,,,31.6299982368946,,,,,2.23779598684886E-5,6.37036284519352E-7,2.93106095302174,0.0227762242220608,2.23744046973178E-5,6.36935079000763E-7,2.23451341250171E-5,3.80597480643111E-7,1.14410073610514E-6,5.10716998532283E-7,1.00015889455916,10.005763053894,2,20,1,3,0.0727719995661877,0.010224101834767,0.0413267537951469,172.859115600586,48.0281028747559,48.0400123596191,820.416809082031,820.416809082031,,,25.6529006958008,0,1,,,,,,1,1,1,48.0374183654785,0,48.0343797857111,,,,,,,,,,,,,,,,,,,,,,,,,,,,,,,,,
,3762248374.12963,48.0163879394531,800.490417480469,,,5,,,,31.6299982368946,,,,,2.57433684048271E-5,6.18242116108268E-7,2.79110619453497,0.0159945518082314,2.57392777602396E-5,6.18143876875304E-7,2.57087434627942E-5,4.61976805041867E-7,1.25336713815293E-6,4.10705836483657E-7,1.00015892616046,10.005763053894,2,20,1,3,0.0837448182480847,0.0115553880477017,0.0413267537951469,172.859115600586,48.0100440979004,48.0188369750977,800.490417480469,800.490417480469,,,25.6192722320557,0,1,,,,,,1,1,1,48.0153884887695,0,48.0141765594482,,,,,,,,,,,,,,,,,,,,,,,,,,,,,,,,,
,3762248394.64709,48.0443325042725,780.418334960937,,,5,,,,31.6299982368946,,,,,3.093887177601E-5,7.12226810599413E-7,2.10882995252823,0.0219911080503146,3.09339479387706E-5,7.12113461640913E-7,3.09129974487932E-5,2.024994750233E-7,1.13829864687262E-6,6.82714834221062E-7,1.00015917261027,10.005763053894,2,20,1,3,0.100804570701826,0.0126858656832683,0.0413267537951469,172.859115600586,48.0384635925293,48.0447731018066,780.418334960937,780.418334960937,,,25.5860233306885,0,1,,,,,,1,1,1,48.0447731018066,0,48.0424686778675,,,,,,,,,,,,,,,,,,,,,,,,,,,,,,,,,
,3762248416.26096,48.0247974395752,760.394897460937,,,5,,,,31.6299982368946,,,,,3.88009027618712E-5,5.12612477339043E-7,3.48782103034837,0.0106399563747296,3.87947401343636E-5,5.12531060683019E-7,3.87228826755038E-5,3.0220670780583E-7,2.36013122346432E-6,4.1395554582832E-7,1.00015885214042,10.005763053894,2,20,1,3,0.126001370980543,0.0189446142880229,0.0413267537951469,172.859115600586,48.0163612365723,48.0272560119629,760.394897460937,760.394897460937,,,25.5678653717041,0,1,,,,,,1,1,1,48.0236663818359,0,48.0215278625488,,,,,,,,,,,,,,,,,,,,,,,,,,,,,,,,,
,3762248438.16906,48.0215702056885,740.492797851562,,,5,,,,31.6299982368946,,,,,5.4623570503624E-5,5.15660954080098E-7,2.12375220928724,0.00906351153894882,5.46148903465471E-5,5.15579011101296E-7,5.45773763124881E-5,1.37812413925231E-7,2.0239175898308E-6,4.96819338649666E-7,1.00015893389187,10.005763053894,2,20,1,3,0.177968622927075,0.0224360499654379,0.0413267537951469,172.859115600586,48.0171852111816,48.0223617553711,740.492797851562,740.492797851562,,,25.5665550231934,0,1,,,,,,1,1,1,48.0210113525391,0,48.0199657440186,,,,,,,,,,,,,,,,,,,,,,,,,,,,,,,,,
,3762248459.78148,48.0071029663086,720.420715332031,,,5,,,,31.6299982368946,,,,,8.70774779142283E-5,5.31266525779748E-7,1.37722265005761,0.0056553601980458,8.70636382687736E-5,5.31182089016823E-7,8.7038487633819E-5,1.96845892728502E-7,2.09255322832964E-6,4.93362043744951E-7,1.00015896010929,10.005763053894,2,20,1,3,0.284148887360049,0.0320605913153227,0.0413267537951469,172.859115600586,48.0023727416992,48.0085716247559,720.420715332031,720.420715332031,,,25.5331325531006,0,1,,,,,,1,1,1,48.0062026977539,0,48.0052043914795,,,,,,,,,,,,,,,,,,,,,,,,,,,,,,,,,
,3762248481.69985,48.0093669891357,700.409362792969,,,5,,,,31.6299982368946,,,,,0.000141188603118484,5.12110450051167E-7,0.894644996527406,0.00323300513906981,0.000141166148703647,5.12029004805349E-7,0.000141148940007875,2.31160908369918E-7,2.20414937639567E-6,4.56878907593194E-7,1.00015906373478,10.005763053894,2,20,1,3,0.461145118465253,0.0480913258389664,0.0413267537951469,172.859115600586,48.0087356567383,48.0102119445801,700.409362792969,700.409362792969,,,25.5154495239258,0,1,,,,,,1,1,1,48.0094413757324,0,48.0095230102539,,,,,,,,,,,,,,,,,,,,,,,,,,,,,,,,,
,3762248502.51335,48.0365447998047,680.313049316406,,,5,,,,31.6299982368946,,,,,0.000235814883446289,4.80389646538535E-7,0.522750275460418,0.00184686681989524,0.000235777384084358,4.80313254815671E-7,0.000235767570844536,2.02099495754942E-7,2.15113545120035E-6,4.35725391235376E-7,1.0001590456272,10.005763053894,2,20,1,3,0.770716380665928,0.0753051559406341,0.0413267537951469,172.859115600586,48.0284652709961,48.036865234375,680.313049316406,680.313049316406,,,25.4660415649414,0,1,,,,,,1,1,1,48.0366096496582,0,48.033821105957,,,,,,,,,,,,,,,,,,,,,,,,,,,,,,,,,
,3762248525.26237,48.0205383300781,660.520263671875,,,5,,,,31.6299982368946,,,,,0.000454427774417711,3.52902895937739E-7,0.257790486367584,0.000706670993583181,0.000454355583375513,3.5284683328205E-7,0.000454350984478883,1.46107835633898E-7,2.0442718928583E-6,3.21175011673618E-7,1.00015888666243,10.005763053894,2,20,1,3,1.48586860285845,0.138215825313258,0.0413267537951469,172.859115600586,48.0154418945313,48.0226669311523,660.520263671875,660.520263671875,,,25.4165420532227,0,1,,,,,,1,1,1,48.0196838378906,0,48.0187641143799,,,,,,,,,,,,,,,,,,,,,,,,,,,,,,,,,
,3762248548.86348,48.0511684417725,640.423889160156,,,5,,,,31.6299982368946,,,,,0.000659442937706629,4.65994429889754E-7,0.0733753480507247,0.000490514690209343,0.000659338009799591,4.65920282730957E-7,0.000659337469128509,3.35433495525559E-7,8.44375329898317E-7,3.23366788553803E-7,1.00015914129851,10.005763053894,2,20,10,3,2.15685583072208,0.193584253333356,0.0413267537951469,172.859115600586,48.0331192016602,48.0519218444824,640.423889160156,640.423889160156,,,25.4143333435059,0,1,,,,,,1,1,1,48.0504684448242,0,48.045442199707,,,,,,,,,,,,,,,,,,,,,,,,,,,,,,,,,
,3762248574.8494,48.0206737518311,620.412536621094,,,5,,,,31.6299982368946,,,,,0.000794599777399333,3.72248125225447E-7,0.132500161489355,0.00041583535976593,0.000794473541225579,3.72188987052555E-7,0.000794471416823101,1.71332074145968E-7,1.8372693342878E-6,3.30408780833754E-7,1.00015889286075,10.005763053894,2,20,10,3,2.59867804622378,0.235886775360289,0.0413267537951469,172.859115600586,48.0128746032715,48.023796081543,620.412536621094,620.412536621094,,,25.3809585571289,0,1,,,,,,1,1,1,48.0194129943848,0,48.017879486084,,,,,,,,,,,,,,,,,,,,,,,,,,,,,,,,,
,3762248597.05394,48.0060539245605,600.36474609375,,,5,,,,31.6299982368946,,,,,0.000839900998447968,4.96166693837398E-7,0.14430629627694,0.000447155223624844,0.00083976754922815,4.96087859476783E-7,0.000839764885719208,3.24207586534002E-7,2.11505310988238E-6,3.75489820306828E-7,1.00015891209412,10.005763053894,2,20,10,3,2.7467846237216,0.249842134173425,0.0413267537951469,172.859115600586,48.0039138793945,48.0074195861816,600.36474609375,600.36474609375,,,25.3790435791016,0,1,,,,,,1,1,1,48.005298614502,0,48.0051803588867,,,,,,,,,,,,,,,,,,,,,,,,,,,,,,,,,
,3762248620.11251,48.046703338623,580.474853515625,,,5,,,,31.6299982368946,,,,,0.000858148513140974,3.80163296685117E-7,0.127388342029569,0.000397769006983269,0.00085801204490034,3.80102840697071E-7,0.000858009924209719,1.67244661123028E-7,1.9076560737927E-6,3.41331792881687E-7,1.00015905166069,10.005763053894,2,20,10,3,2.80653982982892,0.254381491654263,0.0413267537951469,172.859115600586,48.0380630493164,48.0469703674316,580.474853515625,580.474853515625,,,25.313648223877,0,1,,,,,,1,1,1,48.0469436645508,0,48.0441158294678,,,,,,,,,,,,,,,,,,,,,,,,,,,,,,,,,
,3762248641.79463,48.0285625457764,560.402770996094,,,5,,,,31.6299982368946,,,,,0.000866500405462402,4.92148129673346E-7,0.125871140854372,0.000461298049839443,0.000866362831370033,4.92069991415333E-7,0.000866360740742268,2.8705932852343E-7,1.90328137933596E-6,3.99662130253998E-7,1.00015879500757,10.005763053894,2,20,10,3,2.83386507569642,0.256721432047875,0.0413267537951469,172.859115600586,48.0205345153809,48.0313568115234,560.402770996094,560.402770996094,,,25.279899597168,0,1,,,,,,1,1,1,48.0275268554687,0,48.0257270812988,,,,,,,,,,,,,,,,,,,,,,,,,,,,,,,,,
,3762248663.62041,48.0244140625,540.440002441406,,,5,,,,31.6299982368946,,,,,0.000870769195101777,5.31567483896926E-7,0.126975324155339,0.000529098971239609,0.000870630808922531,5.31483005032123E-7,0.000870628670973962,2.65024224046556E-7,1.92943598347244E-6,4.60691160438852E-7,1.00015894932482,10.005763053894,2,20,10,3,2.84782498557708,0.257980218959763,0.0413267537951469,172.859115600586,48.0174217224121,48.0253791809082,540.440002441406,540.440002441406,,,25.2465896606445,0,1,,,,,,1,1,1,48.0234489440918,0,48.0217666625977,,,,,,,,,,,,,,,,,,,,,,,,,,,,,,,,,
,3762248686.73442,48.0240116119385,520.477233886719,,,5,,,,31.6299982368946,,,,,0.000872228714901006,4.03676988379684E-7,0.144820774096914,0.000401607175773164,0.000872090112830598,4.03612841825679E-7,0.000872087327045568,2.00524581946637E-7,2.20429204063238E-6,3.50275917130662E-7,1.00015893090447,10.005763053894,2,20,10,3,2.85252163081834,0.259240139696321,0.0413267537951469,172.859115600586,48.0197296142578,48.024974822998,520.477233886719,520.477233886719,,,25.2282619476318,0,1,,,,,,1,1,1,48.0235176086426,0,48.0225077542392,,,,,,,,,,,,,,,,,,,,,,,,,,,,,,,,,
,3762248709.73962,48.0320129394531,500.417327880859,,,5,,,,31.6299982368946,,,,,0.000872821977418148,4.06182009860199E-7,0.178006203769417,0.000433630509174762,0.000872683161744922,4.06117409711933E-7,0.000872678950104713,1.47192051994787E-7,2.71124275010159E-6,3.78504755981605E-7,1.00015906766546,10.005763053894,2,20,10,3,2.85431510791038,0.261008381681395,0.0413267537951469,172.859115600586,48.026309967041,48.0322456359863,500.417327880859,500.417327880859,,,25.2430591583252,0,1,,,,,,1,1,1,48.0318031311035,0,48.0301239013672,,,,,,,,,,,,,,,,,,,,,,,,,,,,,,,,,
,3762248732.79694,48.0273838043213,480.405975341797,,,5,,,,31.6299982368946,,,,,0.000872405293623308,4.70712298480679E-7,0.167950767375206,0.000408202367069341,0.000872266628944114,4.70637480995803E-7,0.000872262881478374,3.07781257296423E-7,2.55686616248682E-6,3.56048221699123E-7,1.00015897051955,10.005763053894,2,20,10,3,2.85300218631894,0.260321998631647,0.0413267537951469,172.859115600586,48.0206527709961,48.0291061401367,480.405975341797,480.405975341797,,,25.209508895874,0,1,,,,,,1,1,1,48.026538848877,0,48.0250511169434,,,,,,,,,,,,,,,,,,,,,,,,,,,,,,,,,
,3762248753.2494,48.0418434143066,460.321746826172,,,5,,,,31.6299982368946,,,,,0.000871506815344202,4.80198800379828E-7,0.171736793758348,0.000476189379677584,0.000871368116705033,4.80122377661187E-7,0.000871364202416996,2.4145320622028E-7,2.61181091769905E-6,4.14991381521325E-7,1.00015917341536,10.005763053894,2,20,10,3,2.85005073460612,0.260180869694458,0.0413267537951469,172.859115600586,48.0354919433594,48.0422096252441,460.321746826172,460.321746826172,,,25.1761741638184,0,1,,,,,,1,1,1,48.0422096252441,0,48.0399150848389,,,,,,,,,,,,,,,,,,,,,,,,,,,,,,,,,
,3762248776.33918,48.0454940795898,440.225402832031,,,5,,,,31.6299982368946,,,,,0.000870704050475857,3.80722209943164E-7,0.150698626047725,0.000309673959549909,0.000870565733616148,3.80661729805887E-7,0.00087056272238119,2.68781261341651E-7,2.28974821168465E-6,2.69555163353257E-7,1.00015888158053,10.005763053894,2,20,10,3,2.84752471680132,0.258834397806917,0.0413267537951469,172.859115600586,48.034839630127,48.0471992492676,440.225402832031,440.225402832031,,,25.1580581665039,0,1,,,,,,1,1,1,48.0445938110352,0,48.0420280456543,,,,,,,,,,,,,,,,,,,,,,,,,,,,,,,,,
,3762248797.94995,48.0194911956787,420.177642822266,,,5,,,,31.6299982368946,,,,,0.000869775128553272,4.48277103877033E-7,0.159753610829893,0.00035571684296862,0.000869636996513198,4.4820591141723E-7,0.000869633616146367,3.24389229950584E-7,2.42474177812479E-6,3.09289777589588E-7,1.00015883873458,10.005763053894,2,20,10,3,2.8444498540511,0.258946908217276,0.0413267537951469,172.859115600586,48.0128707885742,48.0236206054687,420.177642822266,420.177642822266,,,25.1088008880615,0,1,,,,,,1,1,1,48.0174713134766,0,48.0170738220215,,,,,,,,,,,,,,,,,,,,,,,,,,,,,,,,,
,3762248818.4311,48.029468536377,400.093414306641,,,5,,,,31.6299982368946,,,,,0.000868506434747213,2.7686332524504E-7,0.141312240575025,0.000266486165544322,0.000868368306927317,2.76819292724387E-7,0.000868365665807835,1.51894186893734E-7,2.14171004795724E-6,2.31424019523301E-7,1.00015906593872,10.005763053894,2,20,10,3,2.84038784022285,0.257593872073546,0.0413267537951469,172.859115600586,48.0245590209961,48.0296897888184,400.093414306641,400.093414306641,,,25.0756645202637,0,1,,,,,,1,1,1,48.0292549133301,0,48.0276321411133,,,,,,,,,,,,,,,,,,,,,,,,,,,,,,,,,
,3762248840.35133,48.0138988494873,380.09423828125,,,5,,,,31.6299982368946,,,,,0.000867470035240283,2.84558220720814E-7,0.13450718630411,0.000238016562041917,0.000867332192766998,2.84513003932516E-7,0.00086732980275004,1.9580334543622E-7,2.03614134711709E-6,2.06418747507798E-7,1.00015892696528,10.005763053894,2,20,10,3,2.83703281835844,0.256888888138994,0.0413267537951469,172.859115600586,48.0085182189941,48.0160255432129,380.09423828125,380.09423828125,,,25.0584335327148,0,1,,,,,,1,1,1,48.0132141113281,0,48.0121291478475,,,,,,,,,,,,,,,,,,,,,,,,,,,,,,,,,
,3762248863.37602,48.0132522583008,360.192138671875,,,5,,,,31.6299982368946,,,,,0.000866961618234735,3.13021760842941E-7,0.122873587610479,0.000298616488084584,0.000866823782762831,3.12971994508176E-7,0.000866821789463738,1.75907743002109E-7,1.85894436340731E-6,2.58858910023066E-7,1.00015901210217,10.005763053894,2,20,10,3,2.8354260111558,0.256102217597668,0.0413267537951469,172.859115600586,48.0104827880859,48.0134963989258,360.192138671875,360.192138671875,,,25.0250682830811,0,1,,,,,,1,1,1,48.0130271911621,0,48.0121807098389,,,,,,,,,,,,,,,,,,,,,,,,,,,,,,,,,
,3762248886.43605,48.0140342712402,340.107940673828,,,5,,,,31.6299982368946,,,,,0.000865318246033217,2.53707495404138E-7,0.128383350923828,0.000183758354120127,0.000865180740121104,2.53667179276835E-7,0.000865178568176147,1.97704708818686E-7,1.93861939864065E-6,1.58933589757434E-7,1.0001589331636,10.005763053894,2,20,10,3,2.8300306315713,0.255828068974213,0.0413267537951469,172.859115600586,48.0107078552246,48.0147399902344,340.107940673828,340.107940673828,,,24.9912948608398,0,1,,,,,,1,1,1,48.0136833190918,0,48.0128528594971,,,,,,,,,,,,,,,,,,,,,,,,,,,,,,,,,
,3762248907.24218,48.0061836242676,320.120880126953,,,5,,,,31.6299982368946,,,,,0.000864084597148479,2.83020775189149E-7,0.122075177338838,0.000252632643980152,0.00086394730034502,2.82975805231492E-7,0.000863945339394864,1.80111393690102E-7,1.84073663021705E-6,2.18254879004846E-7,1.00015891803054,10.005763053894,2,20,10,3,2.82602796097988,0.255091795034878,0.0413267537951469,172.859115600586,48.0037574768066,48.0076751708984,320.120880126953,320.120880126953,,,24.9737720489502,0,1,,,,,,1,1,1,48.0055313110352,0,48.0052705244585,,,,,,,,,,,,,,,,,,,,,,,,,,,,,,,,,
,3762248928.81654,48.0024299621582,300.194519042969,,,5,,,,31.6299982368946,,,,,0.000863661006934628,3.08074732279679E-7,0.111011736981228,0.00032008127740541,0.000863523727656992,3.0802576367236E-7,0.000863522106829945,1.35899760325746E-7,1.67309372120281E-6,2.76425625131509E-7,1.00015897568676,10.005763053894,2,20,10,3,2.82469562484771,0.254361096395353,0.0413267537951469,172.859115600586,48.0006141662598,48.0035934448242,300.194519042969,300.194519042969,,,24.9404811859131,0,1,,,,,,1,1,1,48.0018157958984,0,48.0017176541415,,,,,,,,,,,,,,,,,,,,,,,,,,,,,,,,,
,3762248950.48409,48.0271301269531,280.171051025391,,,5,,,,31.6299982368946,,,,,0.000861922886708308,2.3306608654975E-7,0.10412015354317,0.000225284220431072,0.000861785799303985,2.33029017775578E-7,0.000861784376341163,1.28868178316651E-7,1.566070330503E-6,1.94153330496282E-7,1.00015907364038,10.005763053894,2,20,10,3,2.81904530215601,0.253449561865718,0.0413267537951469,172.859115600586,48.02490234375,48.0278244018555,280.171051025391,280.171051025391,,,24.8918609619141,0,1,,,,,,1,1,1,48.0276145935059,0,48.0265464782715,,,,,,,,,,,,,,,,,,,,,,,,,,,,,,,,,
,3762248972.13182,48.0158939361572,260.147521972656,,,5,,,,31.6299982368946,,,,,0.000861060327745623,3.05340885432139E-7,0.0979629031824967,0.000189048378409415,0.00086092352394166,3.05292373390315E-7,0.000860922265559645,2.58348004148755E-7,1.47198497775189E-6,1.62664507507466E-7,1.00015890354969,10.005763053894,2,20,10,3,2.81625521111554,0.252832994795446,0.0413267537951469,172.859115600586,48.0095291137695,48.0180015563965,260.147521972656,260.147521972656,,,24.8744735717773,0,1,,,,,,1,1,1,48.014720916748,0,48.0134536743164,,,,,,,,,,,,,,,,,,,,,,,,,,,,,,,,,
,3762248994.03799,48.0058078765869,240.09977722168,,,5,,,,31.6299982368946,,,,,0.000860058078050104,1.68167868525346E-7,0.0917049406261317,0.000149662777961374,0.000859921435818176,1.68141150756534E-7,0.000859920334357771,1.08212055367389E-7,1.37634937887612E-6,1.28691870958878E-7,1.00015890083237,10.005763053894,2,20,10,3,2.81300857159774,0.252171157246378,0.0413267537951469,172.859115600586,48.004337310791,48.0073852539063,240.09977722168,240.09977722168,,,24.8567867279053,0,1,,,,,,1,1,1,48.0050964355469,0,48.0052169799805,,,,,,,,,,,,,,,,,,,,,,,,,,,,,,,,,
,3762249015.64111,48.0077419281006,220.161285400391,,,5,,,,31.6299982368946,,,,,0.000858858021926902,2.18880489116615E-7,0.0868086063659312,0.000164738628339317,0.000858721494350475,2.18845694980747E-7,0.000858720508746246,1.67004664373896E-7,1.30104500357428E-6,1.41431539230005E-7,1.0001589893549,10.005763053894,2,20,10,3,2.80910884332055,0.251519277452772,0.0413267537951469,172.859115600586,48.0065689086914,48.0081405639648,220.161285400391,220.161285400391,,,24.8232498168945,0,1,,,,,,1,1,1,48.0080795288086,0,48.0073810577393,,,,,,,,,,,,,,,,,,,,,,,,,,,,,,,,,
,3762249037.57185,48.0176677703857,200.149917602539,,,5,,,,31.6299982368946,,,,,0.00085749548369678,2.28624435739314E-7,0.0831007721081969,0.000187450601072704,0.00085735917667189,2.28588093720907E-7,0.000857358274898156,1.62576032504765E-7,1.24349795362934E-6,1.60690853025204E-7,1.00015898473895,10.005763053894,2,20,10,3,2.8046723831,0.250878629921576,0.0413267537951469,172.859115600586,48.0154609680176,48.0177116394043,200.149917602539,200.149917602539,,,24.7904739379883,0,1,,,,,,1,1,1,48.0177116394043,0,48.0167903900146,,,,,,,,,,,,,,,,,,,,,,,,,,,,,,,,,
,3762249058.16092,48.0160865783691,180.041427612305,,,5,,,,31.6299982368946,,,,,0.000856000679687638,1.97829114833341E-7,0.0762923203506372,0.000168162122568133,0.000855864574027537,1.97797659645394E-7,0.000855863815290344,1.3569800785055E-7,1.1396280060783E-6,1.43909571698992E-7,1.00015902709872,10.005763053894,2,20,10,3,2.79981677232146,0.250048347313402,0.0413267537951469,172.859115600586,48.0115776062012,48.0168418884277,180.041427612305,180.041427612305,,,24.788179397583,0,1,,,,,,1,1,1,48.0155792236328,0,48.014403256503,,,,,,,,,,,,,,,,,,,,,,,,,,,,,,,,,
,3762249081.19586,48.0060253143311,160.102935791016,,,5,,,,31.6299982368946,,,,,0.000854392357464339,1.79648586860825E-7,0.0702974328324544,0.000159215390937385,0.000854256606876681,1.79620043298813E-7,0.000854255963904827,1.17332325413427E-7,1.04810567004255E-6,1.36001784428533E-7,1.00015891078461,10.005763053894,2,20,10,3,2.79458611372779,0.249226556103418,0.0413267537951469,172.859115600586,48.0044860839844,48.0070991516113,160.102935791016,160.102935791016,,,24.7396907806396,0,1,,,,,,1,1,1,48.0057983398438,0,48.0055174394087,,,,,,,,,,,,,,,,,,,,,,,,,,,,,,,,,
,3762249101.59076,48.0031223297119,140.213012695312,,,5,,,,31.6299982368946,,,,,0.000851064294208084,1.75565131197046E-7,0.0658648878813555,0.000113174390733271,0.00085092899022152,1.75537219484248E-7,0.000850928427976102,1.46788855245914E-7,9.78192995507823E-7,9.6261868877844E-8,1.00015900737678,10.005763053894,2,20,10,3,2.78372346315765,0.247981159874136,0.0413267537951469,172.859115600586,48.0014190673828,48.0038871765137,140.213012695312,140.213012695312,,,24.6906909942627,0,1,,,,,,1,1,1,48.0029335021973,0,48.0024410247803,,,,,,,,,,,,,,,,,,,,,,,,,,,,,,,,,
,3762249123.18845,48.0245475769043,120.116668701172,,,5,,,,31.6299982368946,,,,,0.000846714022582399,1.8390504473776E-7,0.0699905055623233,0.00011832690823256,0.000846579357062199,1.83875795584142E-7,0.00084657872542075,1.54222920995662E-7,1.03415125802728E-6,1.00127912398427E-7,1.00015907016758,10.005763053894,2,20,10,3,2.76948027426963,0.246853319124566,0.0413267537951469,172.859115600586,48.0211601257324,48.0249900817871,120.116668701172,120.116668701172,,,24.7049045562744,0,1,,,,,,1,1,1,48.0249557495117,0,48.0234188079834,,,,,,,,,,,,,,,,,,,,,,,,,,,,,,,,,
,3762249145.15136,48.0103893280029,100.068893432617,,,5,,,,31.6299982368946,,,,,0.000838994241926082,1.29496432147022E-7,0.0714965971009605,6.14077559062512E-5,0.00083886096280342,1.29475860884429E-7,0.000838860309694806,1.18813334689385E-7,1.04677323925003E-6,5.14527944017846E-8,1.00015888106441,10.005763053894,2,20,10,3,2.74422725584078,0.24461600991031,0.0413267537951469,172.859115600586,48.0074157714844,48.0123062133789,100.068893432617,100.068893432617,,,24.6561260223389,0,1,,,,,,1,1,1,48.0092277526855,0,48.0091121673584,,,,,,,,,,,,,,,,,,,,,,,,,,,,,,,,,
,3762249168.14811,48.0116920471191,80.021110534668,,,5,,,,31.6299982368946,,,,,0.000822252141151885,9.66384744536944E-8,0.0608370316717659,5.00100751832345E-5,0.000822121472597342,9.66231171087412E-8,0.00082212100915392,8.7456828444327E-8,8.72933767431315E-7,4.1077121591819E-8,1.00015894069052,10.005763053894,2,20,10,3,2.68951448311882,0.239176620779599,0.0413267537951469,172.859115600586,48.0088882446289,48.0119667053223,80.021110534668,80.021110534668,,,24.6231861114502,0,1,,,,,,1,1,1,48.0115623474121,0,48.0107070922852,,,,,,,,,,,,,,,,,,,,,,,,,,,,,,,,,
,3762249188.71592,48.0077056884766,60.1311912536621,,,5,,,,31.6299982368946,,,,,0.000802099403978111,1.20318594313057E-7,0.0483856315025344,8.52164177718494E-5,0.000801971900313267,1.20299468177758E-7,0.000801971614345758,9.90185028851608E-8,6.77256031098159E-7,6.83176267901106E-8,1.0001589876962,10.005763053894,2,20,10,3,2.62365079091798,0.232688603517618,0.0413267537951469,172.859115600586,48.0050621032715,48.0082511901855,60.1311912536621,60.1311912536621,,,24.6524505615234,0,1,,,,,,1,1,1,48.0075378417969,0,48.0066725990989,,,,,,,,,,,,,,,,,,,,,,,,,,,,,,,,,
,3762249210.67787,48.0089092254639,40.1076965332031,,,5,,,,31.6299982368946,,,,,0.000786720929138095,4.26676837732843E-8,0.0295428744326047,3.56201300902216E-5,0.000786595826748949,4.26608988652163E-8,0.000786595722185026,3.21742801770658E-8,4.0558485994318E-7,2.80137106980829E-8,1.0001590427827,10.005763053894,2,20,10,3,2.57342646815737,0.227325856997376,0.0413267537951469,172.859115600586,48.0064544677734,48.0096397399902,40.1076965332031,40.1076965332031,,,24.5729103088379,0,1,,,,,,1,1,1,48.0085258483887,0,48.0079723358154,,,,,,,,,,,,,,,,,,,,,,,,,,,,,,,,,
,3762249232.38161,48.003791809082,20.0963497161865,,,5,,,,31.6299982368946,,,,,0.000778183129782183,6.89975747059341E-8,0.0223430472188646,2.14621796404633E-5,0.000778059478012014,6.89866111268957E-8,0.000778059418852808,6.69454108873235E-8,3.03411863202581E-7,1.66572649585985E-8,1.00015892328757,10.005763053894,2,20,10,3,2.54553027329098,0.224484464060731,0.0413267537951469,172.859115600586,48.0025024414063,48.0042533874512,20.0963497161865,20.0963497161865,,,24.5391674041748,0,1,,,,,,1,1,1,48.0035629272461,0,48.0032563643022,,,,,,,,,,,,,,,,,,,,,,,,,,,,,,,,,
,3762249253.05824,48.0271224975586,0.218570560216904,,,5,,,,31.6299982368946,,,,,0.000776060184977276,1.09499385759139E-7,0.0157174475516992,2.26541520998451E-5,0.000775936754164044,1.0948197010183E-7,0.000775936724968599,1.08077298726743E-7,2.12855906450582E-7,1.74813980364358E-8,1.00015907329118,10.005763053894,2,20,10,3,2.53861509858348,0.223524366766611,0.0413267537951469,172.859115600586,48.0249290466309,48.0276527404785,0.218570560216904,0.218570560216904,,,24.5223846435547,0,1,,,,,,1,1,1,48.0276145935059,0,48.0264453887939,,,,,,,,,,,,,,,,,,,,,,,,,,,,,,,,,