File: Experimental_Data/AC_Suceptibillity_FieldScans/HFCd_Down_10K.dat
[Header]
; MPMS3 Data File (default extension .dat)
; Copyright (c) 2007, Quantum Design, Inc. All rights reserved.
TITLE,HFCd_Down_10K
FILEOPENTIME,3772409523.87553,07/16/2019,3:31 am
BYAPP,SQUID AC,0.9.1.0
INFO,MPMS3 Measurement Release 1.1.16 Build 347, MultiVu Release 2.3.3.2,APPNAME
INFO,0,MOMENT_UNITS
INFO,Cu2OSeO3,SAMPLE_MATERIAL
INFO,,SAMPLE_COMMENT
INFO,,SAMPLE_MASS
INFO,,SAMPLE_VOLUME
INFO,,SAMPLE_MOLECULAR_WEIGHT
INFO,,SAMPLE_SIZE
INFO,,SAMPLE_SHAPE
INFO,Quartz,SAMPLE_HOLDER
INFO,Standard,SAMPLE_HOLDER_DETAIL
INFO,64.77,SAMPLE_OFFSET
DATATYPE,COMMENT,1
DATATYPE,TIME,2
STARTUPAXIS,X,2
STARTUPAXIS,Y1,5
FIELDGROUP, VSM,2,3,4,5,6,8,9,10,11,14,15
FIELDGROUP, DC, 2,3,4,14,56,57,58,59,60,61,62,63,64,65,66,67,68,69
FIELDGROUP, AC, 2,3,4,11,16,17,18,19,20,21,22,23,24,25,26,27,28,29,30
STARTUPGROUP, All
[Data]
Comment,Time Stamp (sec),Temperature (K),Magnetic Field (Oe),Moment (emu),M. Std. Err. (emu),Transport Action,Averaging Time (sec),Frequency (Hz),Peak Amplitude (mm),Center Position (mm),Lockin Signal' (V),Lockin Signal (V),Range,M. Quad. Signal (emu),AC Moment (emu),AC M. Std Err. (emu),AC Phase (deg),AC Phase Std. Err. (deg),AC Susceptibility (emu/Oe),AC Suscept. Std Err. (emu/Oe),AC X' (emu/Oe),AC X' Std Err. (emu/Oe),AC X'' (emu/Oe),AC X'' Std Err. (emu/Oe),AC Drive (Oe),AC Frequency (Hz),AC Averaging Time (sec),AC Cycles,AC Range,AC Measure Type,AC Signal' (V),AC Signal'' (V),AC Trim Coil Ratio,AC Trim Coil Phase,Min. Temperature (K),Max. Temperature (K),Min. Field (Oe),Max. Field (Oe),Mass (grams),Motor Lag (deg),Pressure (Torr),Measure Count,Measurement Number,SQUID Status (code),Motor Status (code),Measure Status (code),Motor Current (amps),Motor Temp. (C),Temp. Status (code),Field Status (code),Chamber Status (code),Chamber Temp (K),Redirection State,Average Temp (K),Rotation Angle (deg),Rotator state,DC Moment Fixed Ctr (emu),DC Moment Err Fixed Ctr (emu),DC Moment Free Ctr (emu),DC Moment Err Free Ctr (emu),DC Fixed Fit,DC Free Fit,DC Calculated Center (mm),DC Calculated Center Err (mm),DC Scan Length (mm),DC Scan Time (s),DC Number of Points,DC Squid Drift,DC Min V (V),DC Max V (V),DC Scans per Measure,Map 01,Map 02,Map 03,Map 04,Map 05,Map 06,Map 07,Map 08,Map 09,Map 10,Map 11,Map 12,Map 13,Map 14,Map 15,Map 16
,3772409748.29072,10.0001940727234,-1000.08172607422,,,5,,,,6.46999990567565,,,,,0.000113475955109475,2.98670792276416E-7,-0.0312980143558281,0.00145571012264793,0.000113457851192481,2.98623142435295E-7,0.000113457834264979,2.48815729521063E-7,-6.19767338708396E-8,1.65125751900882E-7,1.00015956513193,10.005763053894,2,20,1,3,0.371195493587447,0.0328252832662448,0.0403775237500668,172.74836730957,9.99933242797852,10.0008974075317,-1000.08172607422,-1000.08172607422,,,18.3566036224365,0,1,,,,,,1,1,1,10.0004072189331,0,10.0001173019409,,,,,,,,,,,,,,,,,,,,,,,,,,,,,,,,,
,3772409771.32677,10.0002379417419,-980.155395507812,,,5,,,,6.46999990567565,,,,,0.00015467303572911,3.71098216423343E-7,0.0299397486333897,0.0020441767482456,0.000154648358932253,3.71039010788323E-7,0.000154648337818456,1.94258626689578E-7,8.08110618553807E-8,3.16122655757946E-7,1.00015956714334,10.005763053894,2,20,1,3,0.505909399021581,0.0452723486667886,0.0403775237500668,172.74836730957,9.99917888641357,10.0011425018311,-980.155395507812,-980.155395507812,,,18.3929958343506,0,1,,,,,,1,1,1,10.000129699707,0,10.0000888824463,,,,,,,,,,,,,,,,,,,,,,,,,,,,,,,,,
,3772409791.92089,9.99990606307983,-960.131896972656,,,5,,,,6.46999990567565,,,,,0.00021804247281465,3.25810530600601E-7,0.0199711458838312,0.00110539061157291,0.00021800766430292,3.25758517891657E-7,0.00021800765105943,2.19219354665841E-7,7.59892406809867E-8,2.40959512198337E-7,1.0001596664587,10.005763053894,2,20,1,3,0.713192194285547,0.0636810306054892,0.0403775237500668,172.74836730957,9.99910736083984,10.0070238113403,-960.131896972656,-960.131896972656,,,18.4158000946045,0,1,,,,,,1,1,1,10.0006074905396,0,10.0031081199646,,,,,,,,,,,,,,,,,,,,,,,,,,,,,,,,,
,3772409813.65347,10.0005922317505,-940.084167480469,,,5,,,,6.46999990567565,,,,,0.000298459564532095,3.67111781807799E-7,0.012752282780089,0.000925092733821094,0.000298411942943328,3.67053206213708E-7,0.000298411935552096,2.41937473622398E-7,6.64173431671673E-8,2.76033177442448E-7,1.00015958338764,10.005763053894,2,20,1,3,0.976239675856224,0.0870235337022543,0.0403775237500668,172.74836730957,9.99924755096436,10.0011968612671,-940.084167480469,-940.084167480469,,,18.4708976745605,0,1,,,,,,1,1,1,10.000412940979,0,10.0002909573642,,,,,,,,,,,,,,,,,,,,,,,,,,,,,,,,,
,3772409835.54065,9.99991130828857,-920.024230957031,,,5,,,,6.46999990567565,,,,,0.000397618402961632,2.16574212447758E-7,0.0223940751622305,0.000360748206695664,0.000397554972204274,2.16539663075251E-7,0.000397554941838232,1.62259228952517E-7,1.55384493895489E-7,1.43392357901242E-7,1.0001595521671,10.005763053894,2,20,1,3,1.30056331182384,0.11612677290702,0.0403775237500668,172.74836730957,9.99910736083984,10.0008220672607,-920.024230957031,-920.024230957031,,,18.5061225891113,0,1,,,,,,1,1,1,9.99995422363281,0,9.99984111785889,,,,,,,,,,,,,,,,,,,,,,,,,,,,,,,,,
,3772409857.07137,9.99964952468872,-900.134338378906,,,5,,,,6.46999990567565,,,,,0.000501235497366811,4.50500108248435E-7,0.0152641296179308,0.000448165273831234,0.000501155542929177,4.5042824685195E-7,0.000501155525144689,3.90491960094205E-7,1.33512505467886E-7,2.24503083862798E-7,1.00015954016425,10.005763053894,2,20,1,3,1.6395031211416,0.146149828637704,0.0403775237500668,172.74836730957,9.99884986877441,10.0009517669678,-900.134338378906,-900.134338378906,,,18.540641784668,0,1,,,,,,1,1,1,9.99949836730957,0,9.9996337890625,,,,,,,,,,,,,,,,,,,,,,,,,,,,,,,,,
,3772409879.14481,10.000048160553,-880.499389648438,,,5,,,,6.46999990567565,,,,,0.000566323186000692,4.628014224083E-7,0.0471157985460815,0.000394761022466963,0.000566232838771231,4.62727590315003E-7,0.000566232647322329,4.05231379009589E-7,4.6562782776825E-7,2.2339282062035E-7,1.00015955844182,10.005763053894,2,20,1,3,1.85231038591894,0.166118868898766,0.0403775237500668,172.74836730957,9.99900627136231,10.000825881958,-880.499389648438,-880.499389648438,,,18.5671691894531,0,1,,,,,,1,1,1,9.99993515014648,0,9.99986631220037,,,,,,,,,,,,,,,,,,,,,,,,,,,,,,,,,
,3772409900.84082,9.99985551834106,-860.415161132813,,,5,,,,6.46999990567565,,,,,0.000609288265217555,3.41122196109883E-7,0.0478886217215981,0.000323299136247103,0.000609190999259823,3.41067739822109E-7,0.000609190786473912,2.785024148494E-7,5.09170381675672E-7,1.96884758349686E-7,1.00015966414121,10.005763053894,2,20,1,3,1.99283940420539,0.178705803028863,0.0403775237500668,172.74836730957,9.99897193908691,10.000901222229,-860.415161132813,-860.415161132813,,,18.6107234954834,0,1,,,,,,1,1,1,9.99997234344482,0,9.999755859375,,,,,,,,,,,,,,,,,,,,,,,,,,,,,,,,,
,3772409922.84079,9.99981021881103,-840.379577636719,,,5,,,,6.46999990567565,,,,,0.000642154648803557,3.28254744915115E-7,0.0595741726447798,0.000293329535190257,0.000642052210957806,3.28202381035185E-7,0.000642051863892593,2.68837176850575E-7,6.67583593339334E-7,1.8826411038798E-7,1.00015954753212,10.005763053894,2,20,1,3,2.10030207552875,0.18872892105561,0.0403775237500668,172.74836730957,9.99866962432861,10.0013103485107,-840.379577636719,-840.379577636719,,,18.6450424194336,0,1,,,,,,1,1,1,9.99975299835205,0,9.99982731682914,,,,,,,,,,,,,,,,,,,,,,,,,,,,,,,,,
,3772409950.91659,10.0001964569092,-820.18603515625,,,5,,,,6.46999990567565,,,,,0.000668775642800542,3.580556725393E-7,0.0477694145614676,0.000342006437207554,0.000668668946478781,3.57998548414555E-7,0.000668668714079004,2.75476896673398E-7,5.57491680532901E-7,2.28638229668886E-7,1.00015956524125,10.005763053894,2,20,10,3,2.1874151021136,0.196054867141816,0.0403775237500668,172.74836730957,9.99930286407471,10.0006647109985,-820.18603515625,-820.18603515625,,,18.6704330444336,0,1,,,,,,1,1,1,10.0000858306885,0,9.99991445541382,,,,,,,,,,,,,,,,,,,,,,,,,,,,,,,,,
,3772409972.62558,10.0003838539124,-800.4296875,,,5,,,,6.46999990567565,,,,,0.000689961973762219,3.37476112850003E-7,0.0883526153973575,0.000204015895389107,0.000689851891451383,3.37422269085032E-7,0.0006898510712522,3.06743907282317E-7,1.06378157708883E-6,1.40577249296141E-7,1.00015957383346,10.005763053894,2,20,10,3,2.25657007298275,0.20381642804469,0.0403775237500668,172.74836730957,9.99918842315674,10.0013399124146,-800.4296875,-800.4296875,,,18.7057113647461,0,1,,,,,,1,1,1,10.0003137588501,0,10.0002354621887,,,,,,,,,,,,,,,,,,,,,,,,,,,,,,,,,
,3772409994.55893,10.0002303123474,-780.418334960937,,,5,,,,6.46999990567565,,,,,0.000707946769746142,3.64823675770383E-7,0.0679712425635781,0.000281352498721143,0.000707833822972658,3.64765471313735E-7,0.000707833324884269,3.05661518948524E-7,8.39718624995135E-7,1.99060003257341E-7,1.00015956679353,10.005763053894,2,20,10,3,2.31546805214104,0.208255937973047,0.0403775237500668,172.74836730957,9.99881172180176,10.0010204315186,-780.418334960937,-780.418334960937,,,18.7297515869141,0,1,,,,,,1,1,1,10.0002355575562,0,9.99995222958651,,,,,,,,,,,,,,,,,,,,,,,,,,,,,,,,,
,3772410016.14486,10.0000548362732,-760.334167480469,,,5,,,,6.46999990567565,,,,,0.000724578532450551,4.27566530186044E-7,0.122928969015287,0.000275012871323485,0.000724462938051255,4.27498319089519E-7,0.00072446127061506,3.78337461548956E-7,1.55434509305659E-6,1.99036624803217E-7,1.0001595587479,10.005763053894,2,20,10,3,2.36966300564496,0.215370605938736,0.0403775237500668,172.74836730957,9.99881553649902,10.0009412765503,-760.334167480469,-760.334167480469,,,18.7552032470703,0,1,,,,,,1,1,1,10.0001945495605,0,9.99981542067094,,,,,,,,,,,,,,,,,,,,,,,,,,,,,,,,,
,3772410038.16346,10.0001692771912,-740.468505859375,,,5,,,,6.46999990567565,,,,,0.000738062649230033,4.01123029996167E-7,0.110020739982287,0.000422318993187104,0.000737944899793694,4.01059035414225E-7,0.000737943539296455,2.524468232916E-7,1.41701875316329E-6,3.11639136337798E-7,1.00015956399505,10.005763053894,2,20,10,3,2.41381416556653,0.218783438454377,0.0403775237500668,172.74836730957,9.9989070892334,10.0011758804321,-740.468505859375,-740.468505859375,,,18.7870025634766,0,1,,,,,,1,1,1,9.99994277954102,0,9.99987258911133,,,,,,,,,,,,,,,,,,,,,,,,,,,,,,,,,
,3772410059.02352,9.9996771812439,-720.445007324219,,,5,,,,6.46999990567565,,,,,0.000750232458363691,4.11993408332248E-7,0.110566921494057,0.000300665997479302,0.000750112784295691,4.11927688798769E-7,0.000750111387600597,3.44782817066844E-7,1.44753436573587E-6,2.25409027890515E-7,1.00015954143231,10.005763053894,2,20,10,3,2.4536164778131,0.22236173251413,0.0403775237500668,172.74836730957,9.99853134155273,10.0001792907715,-720.445007324219,-720.445007324219,,,18.8125762939453,0,1,,,,,,1,1,1,9.9995288848877,0,9.99950183521618,,,,,,,,,,,,,,,,,,,,,,,,,,,,,,,,,
,3772410081.75368,9.99960613250732,-700.385131835938,,,5,,,,6.46999990567565,,,,,0.000761075799072045,4.79268014596012E-7,0.106905720312076,0.000252588091584455,0.000760954310656598,4.79191510374305E-7,0.000760952986055583,4.39073460572798E-7,1.41983095778054E-6,1.91934884362993E-7,1.0001596527068,10.005763053894,2,20,10,3,2.48909720922698,0.225363099402038,0.0403775237500668,172.74836730957,9.99828910827637,10.0000514984131,-700.385131835938,-700.385131835938,,,18.8346786499023,0,1,,,,,,1,1,1,9.99971103668213,0,9.99940557479858,,,,,,,,,,,,,,,,,,,,,,,,,,,,,,,,,
,3772410102.38209,9.99351453781128,-680.495178222656,,,5,,,,6.46999990567565,,,,,0.000771165560275999,4.44890181628493E-7,0.109678480729374,0.000283933996720922,0.000771042499988893,4.44819187387694E-7,0.000771041087302455,3.87313760928746E-7,1.4759676724556E-6,2.18751365855116E-7,1.00015960246952,10.005763053894,2,20,10,3,2.52208816733332,0.228419171373017,0.0403775237500668,172.74836730957,9.99174118041992,9.99654483795166,-680.495178222656,-680.495178222656,,,18.8461418151855,0,1,,,,,,1,1,1,9.99308967590332,0,9.99354400634766,,,,,,,,,,,,,,,,,,,,,,,,,,,,,,,,,
,3772410125.40074,9.999596118927,-660.204528808594,,,5,,,,6.46999990567565,,,,,0.00078026039993531,2.68669495054961E-7,0.112828185697516,0.000145979340831348,0.000780135849493447,2.68626608213174E-7,0.000780134336872731,2.43358464991382E-7,1.53626072208478E-6,1.13740547550785E-7,1.00015965224767,10.005763053894,2,20,10,3,2.5518236084009,0.231197903726437,0.0403775237500668,172.74836730957,9.99633693695068,10.0003261566162,-660.204528808594,-660.204528808594,,,18.8555545806885,0,1,,,,,,1,1,1,9.99983882904053,0,9.9985127882524,,,,,,,,,,,,,,,,,,,,,,,,,,,,,,,,,
,3772410148.4646,9.99852418899536,-640.43603515625,,,5,,,,6.46999990567565,,,,,0.000789247478589809,4.83515668593554E-7,0.109824746326241,0.000187531324293615,0.000789121532347465,4.83438510308952E-7,0.000789120082678244,4.60365726347929E-7,1.51258992856514E-6,1.4756758198833E-7,1.00015960309937,10.005763053894,2,20,10,3,2.58123141925697,0.233670933747647,0.0403775237500668,172.74836730957,9.9977560043335,9.99963665008545,-640.43603515625,-640.43603515625,,,18.8461380004883,0,1,,,,,,1,1,1,9.99848556518555,0,9.99855527877808,,,,,,,,,,,,,,,,,,,,,,,,,,,,,,,,,
,3772410171.52354,9.99913597106934,-620.424682617187,,,5,,,,6.46999990567565,,,,,0.000797506769953262,4.32367035684679E-7,0.101647052011501,0.000321339137093775,0.00079737948334954,4.32298027453518E-7,0.000797378228535822,3.48250726014673E-7,1.41461084899604E-6,2.56130857903642E-7,1.00015963114976,10.005763053894,2,20,10,3,2.60828067400244,0.235688107295508,0.0403775237500668,172.74836730957,9.99828624725342,10.0003261566162,-620.424682617187,-620.424682617187,,,18.8446617126465,0,1,,,,,,1,1,1,9.9990758895874,0,9.99907426834106,,,,,,,,,,,,,,,,,,,,,,,,,,,,,,,,,
,3772410194.61742,9.99963712692261,-600.243347167969,,,5,,,,6.46999990567565,,,,,0.000805744413769869,3.3083111517218E-7,0.112715351159519,0.000282707381150969,0.000805615793882872,3.30778305050358E-7,0.000805614234981253,2.39917040130786E-7,1.58484986692095E-6,2.27714955474757E-7,1.0001596541279,10.005763053894,2,20,10,3,2.63517987017843,0.238574727585195,0.0403775237500668,172.74836730957,9.99827861785889,10.0001564025879,-600.243347167969,-600.243347167969,,,18.8362560272217,0,1,,,,,,1,1,1,9.99969482421875,0,9.99935661662709,,,,,,,,,,,,,,,,,,,,,,,,,,,,,,,,,
,3772410217.64695,9.99903297424316,-580.474853515625,,,5,,,,6.46999990567565,,,,,0.00081406705125501,3.58889302290301E-7,0.110847082506202,0.000253201362054808,0.000813937125379618,3.58832023216425E-7,0.000813935602154838,2.93812843899383E-7,1.57467967408548E-6,2.05996198133241E-7,1.00015962642733,10.005763053894,2,20,10,3,2.66241047027519,0.240895851517775,0.0403775237500668,172.74836730957,9.99837493896484,10.0004606246948,-580.474853515625,-580.474853515625,,,18.8372898101807,0,1,,,,,,1,1,1,9.99892520904541,0,9.99915065765381,,,,,,,,,,,,,,,,,,,,,,,,,,,,,,,,,
,3772410239.80651,10.0000619888306,-560.414916992188,,,5,,,,6.46999990567565,,,,,0.000821617882013656,3.25512905319309E-7,0.0982105723778091,0.000270179157105665,0.000821486806338015,3.25460975066903E-7,0.000821485599520206,2.38077855899944E-7,1.40810807758409E-6,2.21909397776626E-7,1.00015955907585,10.005763053894,2,20,10,3,2.68716276271932,0.242479924799562,0.0403775237500668,172.74836730957,9.99899482727051,10.0014600753784,-560.414916992188,-560.414916992188,,,18.8465366363525,0,1,,,,,,1,1,1,10.0000905990601,0,10.0000344189731,,,,,,,,,,,,,,,,,,,,,,,,,,,,,,,,,
,3772410262.33373,10.0002784729004,-540.391479492188,,,5,,,,6.46999990567565,,,,,0.000830071458676612,4.70659426973974E-7,0.109046277269513,0.000451043271835855,0.000829939026134736,4.70584336301212E-7,0.000829937523018787,2.85169927697307E-7,1.57955275752218E-6,3.74336386034226E-7,1.00015956900171,10.005763053894,2,20,10,3,2.71476818562495,0.245430021208671,0.0403775237500668,172.74836730957,9.99889469146729,10.0007905960083,-540.391479492188,-540.391479492188,,,18.8388900756836,0,1,,,,,,1,1,1,10.0001916885376,0,9.99982504411177,,,,,,,,,,,,,,,,,,,,,,,,,,,,,,,,,
,3772410284.33587,10.0001311302185,-520.465087890625,,,5,,,,6.46999990567565,,,,,0.000839850091793935,3.82546536272847E-7,0.150430492895504,0.000172738807171898,0.000839716104806249,3.82485506026442E-7,0.00083971321060498,3.54033505276415E-7,2.20467831114937E-6,1.44759937351458E-7,1.000159562246,10.005763053894,2,20,10,3,2.74657317057549,0.250246610312128,0.0403775237500668,172.74836730957,9.99903106689453,10.0008506774902,-520.465087890625,-520.465087890625,,,18.8513259887695,0,1,,,,,,1,1,1,10.0002126693726,0,9.99997373060747,,,,,,,,,,,,,,,,,,,,,,,,,,,,,,,,,
,3772410307.39255,9.99976873397827,-500.453765869141,,,5,,,,6.46999990567565,,,,,0.000847716870074904,4.40384724108048E-7,0.142119495360766,0.000182519839939313,0.000847581545068004,4.40314423435816E-7,0.000847578937634016,4.12379892375776E-7,2.1023841365529E-6,1.54336048445459E-7,1.00015966016213,10.005763053894,2,20,10,3,2.77234046732508,0.252129125612261,0.0403775237500668,172.74836730957,9.99893856048584,10.0010175704956,-500.453765869141,-500.453765869141,,,18.8798027038574,0,1,,,,,,1,1,1,9.99975204467773,0,9.99960250854492,,,,,,,,,,,,,,,,,,,,,,,,,,,,,,,,,
,3772410329.08002,10.0000357627869,-480.454528808594,,,5,,,,6.46999990567565,,,,,0.000855756919634132,4.84165392146153E-7,0.136939959635376,0.000248207962425996,0.000855620398662904,4.84088152070082E-7,0.000855617954860691,4.35148211858992E-7,2.04497630192703E-6,2.12102269413952E-7,1.00015955787338,10.005763053894,2,20,10,3,2.7986612139887,0.254207502343082,0.0403775237500668,172.74836730957,9.9989013671875,10.0007152557373,-480.454528808594,-480.454528808594,,,18.8739414215088,0,1,,,,,,1,1,1,9.99995231628418,0,9.99982442855835,,,,,,,,,,,,,,,,,,,,,,,,,,,,,,,,,
,3772410350.96828,9.99974203109741,-460.200317382812,,,5,,,,6.46999990567565,,,,,0.000863799877637837,4.68007955318719E-7,0.131823827482473,0.000268715706344348,0.000863661986282497,4.67933245593771E-7,0.000863659700387975,4.06438262812851E-7,1.98707704485876E-6,2.31882428945342E-7,1.00015965893779,10.005763053894,2,20,10,3,2.82499170841132,0.256283215938357,0.0403775237500668,172.74836730957,9.99842166900635,10.0004272460938,-460.200317382812,-460.200317382812,,,18.9035530090332,0,1,,,,,,1,1,1,9.99974822998047,0,9.99941938573664,,,,,,,,,,,,,,,,,,,,,,,,,,,,,,,,,
,3772410371.62652,9.9997353553772,-440.201141357422,,,5,,,,6.46999990567565,,,,,0.000872548736882509,4.27336254190129E-7,0.123885705940101,0.000219272671449784,0.000872409449183564,4.27268037159944E-7,0.000872407409854396,3.82160145793443E-7,1.88633398803225E-6,1.91080084115656E-7,1.00015965863171,10.005763053894,2,20,10,3,2.85364396753621,0.258422495483284,0.0403775237500668,172.74836730957,9.99886131286621,10.0006942749023,-440.201141357422,-440.201141357422,,,18.8968696594238,0,1,,,,,,1,1,1,10.0000486373901,0,9.99969707835804,,,,,,,,,,,,,,,,,,,,,,,,,,,,,,,,,
,3772410394.5783,9.99976682662964,-420.129089355469,,,5,,,,6.46999990567565,,,,,0.00088083295700543,4.09653945468523E-7,0.121222603809477,0.000220912540274968,0.000880692345599768,4.09588550529961E-7,0.000880690374466373,3.60528926255731E-7,1.86330896529038E-6,1.94375086001585E-7,1.00015966007467,10.005763053894,2,20,10,3,2.88075336812014,0.260680245184585,0.0403775237500668,172.74836730957,9.99888134002686,10.0006427764893,-420.129089355469,-420.129089355469,,,18.8981781005859,0,1,,,,,,1,1,1,9.99990081787109,0,9.99960587241433,,,,,,,,,,,,,,,,,,,,,,,,,,,,,,,,,
,3772410415.10292,9.99996137619018,-400.105560302734,,,5,,,,6.46999990567565,,,,,0.000889790628630373,3.99497616265851E-7,0.113512471339557,0.000181384768249661,0.000889648579335961,3.99433839066268E-7,0.000889646833392222,3.65488538643174E-7,1.76254069078429E-6,1.61138201279815E-7,1.00015966899483,10.005763053894,2,20,10,3,2.91008874329435,0.26287727722591,0.0403775237500668,172.74836730957,9.99893665313721,10.0008058547974,-400.105560302734,-400.105560302734,,,18.9098854064941,0,1,,,,,,1,1,1,9.99999618530273,0,9.99978876113892,,,,,,,,,,,,,,,,,,,,,,,,,,,,,,,,,
,3772410438.07816,10.0001792907715,-380.227783203125,,,5,,,,6.46999990567565,,,,,0.000898438423099864,3.81162885442384E-7,0.104287419428329,0.000215593599896475,0.000898295087134596,3.81102075097786E-7,0.000898293599118989,3.2830438801375E-7,1.63503883866201E-6,1.93532995777866E-7,1.00015956445418,10.005763053894,2,20,10,3,2.93841833943784,0.264896536594287,0.0403775237500668,172.74836730957,9.99923992156982,10.0008811950684,-380.227783203125,-380.227783203125,,,18.9211502075195,0,1,,,,,,1,1,1,10.0003814697266,0,10.0000547409058,,,,,,,,,,,,,,,,,,,,,,,,,,,,,,,,,
,3772410458.6156,9.99994230270386,-360.179992675781,,,5,,,,6.46999990567565,,,,,0.000907268553298989,4.64891893924632E-7,0.123823129077305,0.000222567728530416,0.00090712381843881,4.64817730587855E-7,0.000907121700103574,4.18799787277546E-7,1.96040307298761E-6,2.01648855303287E-7,1.00015955358821,10.005763053894,2,20,10,3,2.96721074517821,0.268448075094677,0.0403775237500668,172.74836730957,9.99900913238525,10.0008392333984,-360.179992675781,-360.179992675781,,,18.9244346618652,0,1,,,,,,1,1,1,9.99998569488525,0,9.9998459815979,,,,,,,,,,,,,,,,,,,,,,,,,,,,,,,,,
,3772410480.44894,10.000063419342,-340.095825195313,,,5,,,,6.46999990567565,,,,,0.000910988923187649,1.14476108500345E-6,0.169160923458896,0.000685165551006486,0.000910843589766481,1.14457845704753E-6,0.000910839619969246,9.59753904689673E-7,2.68918444318246E-6,6.23644359206617E-7,1.00015955914144,10.005763053894,2,20,10,3,2.97916812129535,0.271842315480407,0.0403775237500668,172.74836730957,9.99902629852295,10.0010375976562,-340.095825195313,-340.095825195313,,,18.9520931243896,0,1,,,,,,1,1,1,10.0001487731934,0,9.99999265670776,,,,,,,,,,,,,,,,,,,,,,,,,,,,,,,,,
,3772410502.19554,9.99994945526123,-320.157318115234,,,5,,,,6.46999990567565,,,,,0.000900131275069463,3.75383969459749E-6,0.354642262848452,0.00236945252269908,0.000899987678510868,3.75324085032156E-6,0.000899970438366614,3.09000527886649E-6,5.57059580172771E-6,2.13041879852289E-6,1.00015955391615,10.005763053894,2,20,10,3,2.942780159293,0.27806751893552,0.0403775237500668,172.74836730957,9.99917411804199,10.0010452270508,-320.157318115234,-320.157318115234,,,18.9640007019043,0,1,,,,,,1,1,1,10.0001468658447,0,10.0000067710876,,,,,,,,,,,,,,,,,,,,,,,,,,,,,,,,,
,3772410523.79163,10.0002074241638,-300.121673583984,,,5,,,,6.46999990567565,,,,,0.000860357361674083,4.38484614292925E-6,0.54834834270624,0.0030974776450027,0.000860220100013734,4.38414658331743E-6,0.000860180704743746,3.4834839778828E-6,8.2325970501621E-6,2.66196931609809E-6,1.0001595657441,10.005763053894,2,20,10,3,2.81183784998394,0.275228123581345,0.0403775237500668,172.74836730957,9.9990758895874,10.0015106201172,-300.121673583984,-300.121673583984,,,18.9573287963867,0,1,,,,,,1,1,1,10.0001888275146,0,10.0001577030529,,,,,,,,,,,,,,,,,,,,,,,,,,,,,,,,,
,3772410545.85779,9.99981737136841,-280.134613037109,,,5,,,,6.46999990567565,,,,,0.000802324003251041,4.1784838948499E-6,0.426587341806942,0.00319106279310392,0.000802195922731033,4.17781685461687E-6,0.00080217368865367,3.30318004887641E-6,5.97257717054421E-6,2.55795919346372E-6,1.00015966239216,10.005763053894,2,20,10,3,2.62271544984696,0.251034119040358,0.0403775237500668,172.74836730957,9.99903011322022,10.0007209777832,-280.134613037109,-280.134613037109,,,18.9761066436768,0,1,,,,,,1,1,1,9.99991893768311,0,9.99975811351429,,,,,,,,,,,,,,,,,,,,,,,,,,,,,,,,,
,3772410568.89484,10.0000214576721,-260.074676513672,,,5,,,,6.46999990567565,,,,,0.000753764329210074,1.44056720983978E-6,0.229124893529375,0.000867912223288458,0.00075364407985772,1.44033739361301E-6,0.000753638053776164,1.28378288998207E-6,3.01380242632018E-6,6.53049231550885E-7,1.00015955721748,10.005763053894,2,20,10,3,2.46478048317224,0.22729449904396,0.0403775237500668,172.74836730957,9.99882030487061,10.0010805130005,-260.074676513672,-260.074676513672,,,18.9797954559326,0,1,,,,,,1,1,1,9.99973964691162,0,9.9998330116272,,,,,,,,,,,,,,,,,,,,,,,,,,,,,,,,,
,3772410591.93896,10.0001420974731,-240.148330688477,,,5,,,,6.46999990567565,,,,,0.00072407991571037,5.81774784997602E-7,0.160907183890724,0.000288677276083236,0.00072396439796096,5.81681970223475E-7,0.000723961543050236,5.43033548670845E-7,2.03315009199217E-6,2.08490957839931E-7,1.00015956274885,10.005763053894,2,20,10,3,2.36797515570205,0.215473572146031,0.0403775237500668,172.74836730957,9.99905490875244,10.0010633468628,-240.148330688477,-240.148330688477,,,18.9920978546143,0,1,,,,,,1,1,1,10.0002880096436,0,10.0000768661499,,,,,,,,,,,,,,,,,,,,,,,,,,,,,,,,,
,3772410612.45875,10.0001797676086,-220.173416137695,,,5,,,,6.46999990567565,,,,,0.000702467400759181,5.52451527556713E-7,0.127153429790006,0.000167767714524968,0.000702355329798988,5.52363389981807E-7,0.000702353600231146,5.3982436903383E-7,1.55869798032857E-6,1.17025489485927E-7,1.00015956447604,10.005763053894,2,20,10,3,2.29742116418716,0.207639541393146,0.0403775237500668,172.74836730957,9.99923515319824,10.0008249282837,-220.173416137695,-220.173416137695,,,18.9946441650391,0,1,,,,,,1,1,1,10.0000600814819,0,10.0001101927324,,,,,,,,,,,,,,,,,,,,,,,,,,,,,,,,,
,3772410634.21144,10.0003066062927,-200.162063598633,,,5,,,,6.46999990567565,,,,,0.000685729029791955,2.49901078151802E-7,0.0992213230157706,0.000102734800705611,0.000685619625268404,2.49861207726018E-7,0.000685618597209737,2.39793141644285E-7,1.18731349640494E-6,7.02130496892731E-8,1.00015957029163,10.005763053894,2,20,10,3,2.24277989964333,0.201550529036769,0.0403775237500668,172.74836730957,9.99906921386719,10.0011167526245,-200.162063598633,-200.162063598633,,,19.0143070220947,0,1,,,,,,1,1,1,10.0006160736084,0,10.000127696991,,,,,,,,,,,,,,,,,,,,,,,,,,,,,,,,,
,3772410656.07778,9.99982500076294,-180.102142333984,,,5,,,,6.46999990567565,,,,,0.000672756656733641,2.08489454922161E-7,0.0805613451188378,8.14024864532158E-5,0.000672649259708449,2.0845617223812E-7,0.000672648594792494,2.01185935774511E-7,9.45785392228078E-7,5.45728411455998E-8,1.00015966274197,10.005763053894,2,20,10,3,2.20041908461468,0.196973811030746,0.0403775237500668,172.74836730957,9.99900150299072,10.0007028579712,-180.102142333984,-180.102142333984,,,19.0150508880615,0,1,,,,,,1,1,1,9.99988269805908,0,9.99975700378418,,,,,,,,,,,,,,,,,,,,,,,,,,,,,,,,,
,3772410676.9094,10.0000028610229,-160.260803222656,,,5,,,,6.46999990567565,,,,,0.000662409972664012,2.7146667588135E-7,0.0672322954120643,0.000104792436046323,0.00066230429779785,2.71423368555336E-7,0.000662303841825886,2.62459127987592E-7,7.77164188391515E-7,6.91798462987458E-8,1.00015955636482,10.005763053894,2,20,10,3,2.16662563329251,0.193394406313597,0.0403775237500668,172.74836730957,9.99900817871094,10.0008678436279,-160.260803222656,-160.260803222656,,,19.0366134643555,0,1,,,,,,1,1,1,9.99985027313232,0,9.99988824670965,,,,,,,,,,,,,,,,,,,,,,,,,,,,,,,,,
,3772410699.6437,10.0001578330994,-140.152297973633,,,5,,,,6.46999990567565,,,,,0.000653914019584765,5.14209167585182E-7,0.0567378875854665,0.00014526941241948,0.000653809695440821,5.14127131675858E-7,0.000653809374871184,5.05385348873522E-7,6.47443411271234E-7,9.44052788208045E-8,1.00015956347034,10.005763053894,2,20,10,3,2.13887471029221,0.190476174081461,0.0403775237500668,172.74836730957,9.99915790557861,10.0010499954224,-140.152297973633,-140.152297973633,,,19.0390205383301,0,1,,,,,,1,1,1,10.0000371932983,0,10.0000284194946,,,,,,,,,,,,,,,,,,,,,,,,,,,,,,,,,
,3772410720.18555,10.0005598068237,-120.068092346191,,,5,,,,6.46999990567565,,,,,0.000646820977924203,2.11910437324864E-7,0.046630306677784,6.86498836380495E-5,0.000646717773472536,2.11876625650176E-7,0.000646717559293946,2.0721335932187E-7,5.2633274279899E-7,4.4207784557139E-8,1.00015958190095,10.005763053894,2,20,10,3,2.11571027995793,0.187991358416919,0.0403775237500668,172.74836730957,9.99910163879395,10.0015840530396,-120.068092346191,-120.068092346191,,,19.0309867858887,0,1,,,,,,1,1,1,10.0004720687866,0,10.000220489502,,,,,,,,,,,,,,,,,,,,,,,,,,,,,,,,,
,3772410743.27598,9.99976921081543,-100.068893432617,,,5,,,,6.46999990567565,,,,,0.000641030337096245,1.98167026672965E-7,0.0372074590511309,7.61150310896685E-5,0.000640928006412818,1.98135392339769E-7,0.00064092787126968,1.92070159070142E-7,4.16213918021167E-7,4.86486144962496E-8,1.00015966018399,10.005763053894,2,20,10,3,2.09680288557128,0.185918656252987,0.0403775237500668,172.74836730957,9.9991455078125,10.0010786056519,-100.068893432617,-100.068893432617,,,19.0506534576416,0,1,,,,,,1,1,1,9.99984455108643,0,9.99974765777588,,,,,,,,,,,,,,,,,,,,,,,,,,,,,,,,,
,3772410764.9368,10.0002799034119,-80.1425399780273,,,5,,,,6.46999990567565,,,,,0.000636685489912356,2.28907079068554E-7,0.029855273379809,6.50873936950585E-5,0.000636583910811452,2.28870558407018E-7,0.000636583824389815,2.25126896341042E-7,3.31706558282834E-7,4.12263635237208E-8,1.0001595690673,10.005763053894,2,20,10,3,2.08261739438427,0.184346860517927,0.0403775237500668,172.74836730957,9.99912643432617,10.0008659362793,-80.1425399780273,-80.1425399780273,,,19.044885635376,0,1,,,,,,1,1,1,10.0002689361572,0,10.0001013755798,,,,,,,,,,,,,,,,,,,,,,,,,,,,,,,,,
,3772410786.90729,9.99979448318481,-60.1554756164551,,,5,,,,6.46999990567565,,,,,0.000633382895573093,1.74780875321806E-7,0.0201033062005278,3.89120711311279E-5,0.000633281784952978,1.74752974027326E-7,0.000633281745971644,1.73033409444645E-7,2.22198868417555E-7,2.44548798270879E-8,1.00015966134273,10.005763053894,2,20,10,3,2.071848454003,0.182993670082106,0.0403775237500668,172.74836730957,9.99868011474609,10.0010786056519,-60.1554756164551,-60.1554756164551,,,19.0554847717285,0,1,,,,,,1,1,1,9.99976634979248,0,9.99972238540649,,,,,,,,,,,,,,,,,,,,,,,,,,,,,,,,,
,3772410809.99912,10.0003218650818,-40.0955581665039,,,5,,,,6.46999990567565,,,,,0.000631020878359432,1.58035750353087E-7,0.0138681748158342,3.23908229782344E-5,0.000630920201797432,1.58010536455157E-7,0.000630920183315907,1.56705926400358E-7,1.5271127546027E-7,2.02628295618369E-8,1.00015957099125,10.005763053894,2,20,10,3,2.06414468105299,0.182042304788342,0.0403775237500668,172.74836730957,9.99918842315674,10.0008268356323,-40.0955581665039,-40.0955581665039,,,19.0665168762207,0,1,,,,,,1,1,1,10.0004119873047,0,10.0001679333774,,,,,,,,,,,,,,,,,,,,,,,,,,,,,,,,,
,3772410833.04818,9.99999713897705,-20.0113487243652,,,5,,,,6.46999990567565,,,,,0.000629863851011282,2.40327991949201E-7,0.0112683785127992,4.1121223765303E-5,0.000629763368422742,2.40289652268823E-7,0.000629763356243367,2.38923380673317E-7,1.2385575383463E-7,2.55877930878128E-8,1.00015955610246,10.005763053894,2,20,10,3,2.06037089979745,0.181570739683603,0.0403775237500668,172.74836730957,9.99911117553711,10.0010833740234,-20.0113487243652,-20.0113487243652,,,19.0775375366211,0,1,,,,,,1,1,1,9.99978446960449,0,9.99996280670166,,,,,,,,,,,,,,,,,,,,,,,,,,,,,,,,,
,3772410854.75491,10.000301361084,-0.109285280108452,,,5,,,,6.46999990567565,,,,,0.000629578097909337,2.25718460760867E-7,0.0122673415283439,3.68467289983045E-5,0.000629477652128199,2.25682448601003E-7,0.000629477637700204,2.24519024186279E-7,1.34774626503786E-7,2.28861395824116E-8,1.00015957005114,10.005763053894,2,20,10,3,2.05943572211499,0.181480403981611,0.0403775237500668,172.74836730957,9.99973297119141,10.0020122528076,-0.109285280108452,-0.109285280108452,,,19.0879135131836,0,1,,,,,,1,1,1,10.0004444122314,0,10.0004859924316,,,,,,,,,,,,,,,,,,,,,,,,,,,,,,,,,