File: Experimental_Data/AC_Suceptibillity_FieldScans/HFCd_Down_56K.dat
[Header]
; MPMS3 Data File (default extension .dat)
; Copyright (c) 2007, Quantum Design, Inc. All rights reserved.
TITLE,HFCd_Down_56K
FILEOPENTIME,3762240944.66157,03/20/2019,10:55 am
BYAPP,SQUID AC,0.9.1.0
INFO,MPMS3 Measurement Release 1.1.16 Build 347, MultiVu Release 2.3.3.2,APPNAME
INFO,0,MOMENT_UNITS
INFO,SrM,SAMPLE_MATERIAL
INFO,MvsH,SAMPLE_COMMENT
INFO,,SAMPLE_MASS
INFO,,SAMPLE_VOLUME
INFO,,SAMPLE_MOLECULAR_WEIGHT
INFO,,SAMPLE_SIZE
INFO,,SAMPLE_SHAPE
INFO,Quartz,SAMPLE_HOLDER
INFO,Standard,SAMPLE_HOLDER_DETAIL
INFO,65.34,SAMPLE_OFFSET
DATATYPE,COMMENT,1
DATATYPE,TIME,2
STARTUPAXIS,X,2
STARTUPAXIS,Y1,5
FIELDGROUP, VSM,2,3,4,5,6,8,9,10,11,14,15
FIELDGROUP, DC, 2,3,4,14,56,57,58,59,60,61,62,63,64,65,66,67,68,69
FIELDGROUP, AC, 2,3,4,11,16,17,18,19,20,21,22,23,24,25,26,27,28,29,30
STARTUPGROUP, All
[Data]
Comment,Time Stamp (sec),Temperature (K),Magnetic Field (Oe),Moment (emu),M. Std. Err. (emu),Transport Action,Averaging Time (sec),Frequency (Hz),Peak Amplitude (mm),Center Position (mm),Lockin Signal' (V),Lockin Signal (V),Range,M. Quad. Signal (emu),AC Moment (emu),AC M. Std Err. (emu),AC Phase (deg),AC Phase Std. Err. (deg),AC Susceptibility (emu/Oe),AC Suscept. Std Err. (emu/Oe),AC X' (emu/Oe),AC X' Std Err. (emu/Oe),AC X'' (emu/Oe),AC X'' Std Err. (emu/Oe),AC Drive (Oe),AC Frequency (Hz),AC Averaging Time (sec),AC Cycles,AC Range,AC Measure Type,AC Signal' (V),AC Signal'' (V),AC Trim Coil Ratio,AC Trim Coil Phase,Min. Temperature (K),Max. Temperature (K),Min. Field (Oe),Max. Field (Oe),Mass (grams),Motor Lag (deg),Pressure (Torr),Measure Count,Measurement Number,SQUID Status (code),Motor Status (code),Measure Status (code),Motor Current (amps),Motor Temp. (C),Temp. Status (code),Field Status (code),Chamber Status (code),Chamber Temp (K),Redirection State,Average Temp (K),Rotation Angle (deg),Rotator state,DC Moment Fixed Ctr (emu),DC Moment Err Fixed Ctr (emu),DC Moment Free Ctr (emu),DC Moment Err Free Ctr (emu),DC Fixed Fit,DC Free Fit,DC Calculated Center (mm),DC Calculated Center Err (mm),DC Scan Length (mm),DC Scan Time (s),DC Number of Points,DC Squid Drift,DC Min V (V),DC Max V (V),DC Scans per Measure,Map 01,Map 02,Map 03,Map 04,Map 05,Map 06,Map 07,Map 08,Map 09,Map 10,Map 11,Map 12,Map 13,Map 14,Map 15,Map 16
,3762241071.50227,55.9860439300537,-999.972534179688,,,5,,,,31.6299982368946,,,,,6.18023209185374E-5,5.3175569720538E-7,-2.10005004113386,0.00438218394800333,6.17925840377311E-5,5.31671919739343E-7,6.17510817762265E-5,4.56786273084714E-7,-2.26436338202198E-6,2.7206861443521E-7,1.00015757361434,10.005763053894,2,20,1,3,0.20267906773506,0.0105390976548775,0.0413267537951469,172.859115600586,55.9206237792969,55.9880599975586,-999.972534179688,-999.972534179688,,,25.6809406280518,0,1,,,,,,1,1,1,55.9846954345703,0,55.9587523142497,,,,,,,,,,,,,,,,,,,,,,,,,,,,,,,,,
,3762241114.46631,55.8973255157471,-979.948974609375,,,5,,,,31.6299982368946,,,,,5.3184232907526E-5,3.14502380485287E-7,-1.37882032966884,0.00355198223785934,5.31758621388066E-5,3.14452880350664E-7,5.31604652250771E-5,2.51212231129174E-7,-1.27955119426236E-6,1.89137592487404E-7,1.00015741669966,10.005763053894,2,20,1,3,0.174288440429318,0.0112604927632754,0.0413267537951469,172.859115600586,55.8918991088867,55.9032020568848,-979.948974609375,-979.948974609375,,,25.7830123901367,0,1,,,,,,1,1,1,55.8959465026855,0,55.8968354930048,,,,,,,,,,,,,,,,,,,,,,,,,,,,,,,,,
,3762241152.90469,55.9222831726074,-959.840515136719,,,5,,,,31.6299982368946,,,,,5.3451474606845E-5,3.33012514208212E-7,-1.0344959050776,0.00339135615182769,5.34430252903353E-5,3.32959873412893E-7,5.34343144204299E-5,2.79087938536515E-7,-9.64880615440986E-7,1.81582487775028E-7,1.00015809951746,10.005763053894,2,20,1,3,0.175093205081405,0.0123657581414735,0.0413267537951469,172.859115600586,55.9139442443848,55.9470367431641,-959.840515136719,-959.840515136719,,,25.8169059753418,0,1,,,,,,1,1,1,55.9244041442871,0,55.9299091157459,,,,,,,,,,,,,,,,,,,,,,,,,,,,,,,,,
,3762241185.61593,55.9585208892822,-939.999145507812,,,5,,,,31.6299982368946,,,,,5.85967586968747E-5,5.1571944644311E-7,-1.31010898051743,0.00357227929969754,5.85875199363506E-5,5.15638134633903E-7,5.85722046268115E-5,4.70600700372615E-7,-1.33952881536842E-6,2.10754992105847E-7,1.00015769161306,10.005763053894,2,20,1,3,0.192010976267458,0.0126285236862078,0.0413267537951469,172.859115600586,55.95751953125,55.9589881896973,-939.999145507812,-939.999145507812,,,25.8328952789307,0,1,,,,,,1,1,1,55.958683013916,0,55.9585113525391,,,,,,,,,,,,,,,,,,,,,,,,,,,,,,,,,
,3762241206.07664,56.001989364624,-919.975708007812,,,5,,,,31.6299982368946,,,,,6.02576012324999E-5,3.43623689332819E-7,-1.15306367349927,0.00258891799160147,6.02480706863534E-5,3.43569340647156E-7,6.0235870687037E-5,3.05776022613695E-7,-1.21239597590851E-6,1.56655404717712E-7,1.00015818840401,10.005763053894,2,20,1,3,0.197417100383566,0.0135233842522693,0.0413267537951469,172.859115600586,55.9921035766602,56.0159454345703,-919.975708007812,-919.975708007812,,,25.8157806396484,0,1,,,,,,1,1,1,56.0063056945801,0,56.0069412231445,,,,,,,,,,,,,,,,,,,,,,,,,,,,,,,,,
,3762241227.91334,56.0160827636719,-899.842895507812,,,5,,,,31.6299982368946,,,,,5.52417984382746E-5,3.95894497416554E-7,-0.424682493916524,0.00383661446297879,5.52330953197364E-5,3.95832125863906E-7,5.52315780917272E-5,3.34234738964211E-7,-4.0938990770354E-7,2.1206180970525E-7,1.00015757071893,10.005763053894,2,20,1,3,0.180812219408982,0.0146935349142202,0.0413267537951469,172.859115600586,56.0125885009766,56.0165596008301,-899.842895507812,-899.842895507812,,,25.798698425293,0,1,,,,,,1,1,1,56.0158195495605,0,56.0148544311523,,,,,,,,,,,,,,,,,,,,,,,,,,,,,,,,,
,3762241249.58601,56.0249519348145,-880.171508789063,,,5,,,,31.6299982368946,,,,,5.65063257790686E-5,3.7586369462797E-7,-0.194684689100027,0.0024641870201906,5.64974134833558E-5,3.75804412621079E-7,5.64970873340314E-5,3.49015334829394E-7,-1.91971560680427E-7,1.39345802230998E-7,1.00015774696864,10.005763053894,2,20,1,3,0.184889558134042,0.0157682984555959,0.0413267537951469,172.859115600586,56.0226898193359,56.0251922607422,-880.171508789063,-880.171508789063,,,25.7655715942383,0,1,,,,,,1,1,1,56.0250434875488,0,56.0242851257324,,,,,,,,,,,,,,,,,,,,,,,,,,,,,,,,,
,3762241270.37827,56.0153656005859,-860.220825195313,,,5,,,,31.6299982368946,,,,,5.64779137939368E-5,3.58745444711779E-7,-0.102955699714451,0.00313932240801839,5.64690177831168E-5,3.58688937607614E-7,5.64689266165405E-5,3.11821988848173E-7,-1.01470023773995E-7,1.77270418380645E-7,1.00015753790608,10.005763053894,2,20,1,3,0.184771364886753,0.0160522608317642,0.0413267537951469,172.859115600586,56.0106735229492,56.0167770385742,-860.220825195313,-860.220825195313,,,25.7480812072754,0,1,,,,,,1,1,1,56.0148468017578,0,56.0136864402077,,,,,,,,,,,,,,,,,,,,,,,,,,,,,,,,,
,3762241293.12054,56.0165138244629,-840.221740722656,,,5,,,,31.6299982368946,,,,,5.91160650994752E-5,3.42196428773906E-7,-0.238275550342753,0.00226719500635493,5.91067436577438E-5,3.4214247112185E-7,5.91062325409983E-5,3.14746328612665E-7,-2.45806085511701E-7,1.34149987589319E-7,1.00015770521525,10.005763053894,2,20,1,3,0.193441643096591,0.0163411213832429,0.0413267537951469,172.859115600586,56.0139122009277,56.0165939331055,-840.221740722656,-840.221740722656,,,25.7148704528809,0,1,,,,,,1,1,1,56.0165596008301,0,56.015588760376,,,,,,,,,,,,,,,,,,,,,,,,,,,,,,,,,
,3762241313.91312,56.0471649169922,-820.258911132813,,,5,,,,31.6299982368946,,,,,6.08083601251176E-5,4.28536572559566E-7,-0.0839106224027475,0.00433890206579867,6.07987633380491E-5,4.28468940835418E-7,6.07986981371939E-5,3.37654016694745E-7,-8.9040768668949E-8,2.63771488736993E-7,1.00015784510312,10.005763053894,2,20,1,3,0.198933481948564,0.0173406795177421,0.0413267537951469,172.859115600586,56.044361114502,56.0482025146484,-820.258911132813,-820.258911132813,,,25.7131576538086,0,1,,,,,,1,1,1,56.0480270385742,0,56.0469939491966,,,,,,,,,,,,,,,,,,,,,,,,,,,,,,,,,
,3762241336.68184,56.0325565338135,-800.101806640625,,,5,,,,31.6299982368946,,,,,6.02204141906473E-5,3.67776965971744E-7,0.0326926981384172,0.00266158014187896,6.02109297025027E-5,3.67719042486486E-7,6.02109199007986E-5,3.31016383889117E-7,3.43560670491132E-8,1.60141961409715E-7,1.00015752103798,10.005763053894,2,20,1,3,0.196974938336445,0.0175696710442814,0.0413267537951469,172.859115600586,56.0248031616211,56.035961151123,-800.101806640625,-800.101806640625,,,25.6794109344482,0,1,,,,,,1,1,1,56.0309982299805,0,56.0297248840332,,,,,,,,,,,,,,,,,,,,,,,,,,,,,,,,,
,3762241357.21953,56.0379905700684,-780.2119140625,,,5,,,,31.6299982368946,,,,,6.26649946713219E-5,3.839001858555E-7,0.0365085877073597,0.0021518116342388,6.26551095956746E-5,3.83839627606065E-7,6.26550968761381E-5,3.59446396867897E-7,3.99235236632892E-8,1.34651949482541E-7,1.00015776966493,10.005763053894,2,20,1,3,0.204969973960286,0.0182921782095634,0.0413267537951469,172.859115600586,56.0346069335937,56.0382881164551,-780.2119140625,-780.2119140625,,,25.6460723876953,0,1,,,,,,1,1,1,56.0382881164551,0,56.0369850158691,,,,,,,,,,,,,,,,,,,,,,,,,,,,,,,,,
,3762241379.0362,56.0236320495605,-760.164123535156,,,5,,,,31.6299982368946,,,,,6.38979732449131E-5,3.87894994768479E-7,0.40299507711989,0.00318293588244088,6.38879063121787E-5,3.87833883083365E-7,6.388632600655E-5,3.30437747480904E-7,4.49357695534039E-7,2.03041906776083E-7,1.0001575718053,10.005763053894,2,20,1,3,0.208879635628371,0.0199840853611316,0.0413267537951469,172.859115600586,56.016773223877,56.0256195068359,-760.164123535156,-760.164123535156,,,25.6286125183105,0,1,,,,,,1,1,1,56.0227203369141,0,56.0211315155029,,,,,,,,,,,,,,,,,,,,,,,,,,,,,,,,,
,3762241400.70657,56.0614967346191,-740.116333007812,,,5,,,,31.6299982368946,,,,,6.68489630022197E-5,4.80127255119112E-7,0.344161359533699,0.00238336375304098,6.68384074153222E-5,4.8005144205133E-7,6.68372016195849E-5,4.531436379043E-7,4.0147911470988E-7,1.58462078878253E-7,1.00015792696603,10.005763053894,2,20,1,3,0.218547965518111,0.020677904831384,0.0413267537951469,172.859115600586,56.0562210083008,56.0625076293945,-740.116333007812,-740.116333007812,,,25.6107978820801,0,1,,,,,,1,1,1,56.0623741149902,0,56.0603736877441,,,,,,,,,,,,,,,,,,,,,,,,,,,,,,,,,
,3762241422.35512,56.0709762573242,-720.250732421875,,,5,,,,31.6299982368946,,,,,6.69222437950606E-5,3.73368189245145E-7,0.477660016621644,0.00246900603542358,6.69116936915241E-5,3.73309328800092E-7,6.69093684823594E-5,3.35021907274697E-7,5.57818931373547E-7,1.64682047033669E-7,1.00015767204437,10.005763053894,2,20,1,3,0.218739044899292,0.0212056350171535,0.0413267537951469,172.859115600586,56.0599174499512,56.0718460083008,-720.250732421875,-720.250732421875,,,25.5614032745361,0,1,,,,,,1,1,1,56.0702743530273,0,56.0675884593617,,,,,,,,,,,,,,,,,,,,,,,,,,,,,,,,,
,3762241444.36047,56.0503578186035,-700.227233886719,,,5,,,,31.6299982368946,,,,,6.8937750127114E-5,5.38962459654163E-7,0.410245736378561,0.00377736251228128,6.89268919294675E-5,5.38877569142068E-7,6.8925125079259E-5,4.72104705537076E-7,4.9352189919618E-7,2.59819517231124E-7,1.00015753209441,10.005763053894,2,20,1,3,0.225352720665963,0.0215743279187753,0.0413267537951469,172.859115600586,56.0389518737793,56.0529823303223,-700.227233886719,-700.227233886719,,,25.559289932251,0,1,,,,,,1,1,1,56.0490837097168,0,56.0469564958052,,,,,,,,,,,,,,,,,,,,,,,,,,,,,,,,,
,3762241466.06317,56.0255336761475,-680.130920410156,,,5,,,,31.6299982368946,,,,,7.16638663620233E-5,3.95693371295596E-7,0.306395315425385,0.00261194140165413,7.16525779255689E-5,3.95631041983712E-7,7.16515534071595E-5,3.4874246286906E-7,3.83168005831106E-7,1.86822418283085E-7,1.00015754403793,10.005763053894,2,20,1,3,0.234304812476968,0.0219977943222277,0.0413267537951469,172.859115600586,56.0183639526367,56.028148651123,-680.130920410156,-680.130920410156,,,25.5097427368164,0,1,,,,,,1,1,1,56.0242233276367,0,56.0227439880371,,,,,,,,,,,,,,,,,,,,,,,,,,,,,,,,,
,3762241487.87468,56.0251846313477,-660.240966796875,,,5,,,,31.6299982368946,,,,,7.45525130779116E-5,4.55744908150853E-7,0.204485202124157,0.00282508764261414,7.45407622603335E-5,4.55673074552538E-7,7.45402875355793E-5,4.04248782786007E-7,2.66030946934522E-7,2.10287594708281E-7,1.0001576428416,10.005763053894,2,20,1,3,0.243789895968108,0.0224457123200738,0.0413267537951469,172.859115600586,56.0217323303223,56.0254745483398,-660.240966796875,-660.240966796875,,,25.5083885192871,0,1,,,,,,1,1,1,56.0250701904297,0,56.0239653153853,,,,,,,,,,,,,,,,,,,,,,,,,,,,,,,,,
,3762241511.12735,56.0135936737061,-640.375366210937,,,5,,,,31.6299982368946,,,,,7.53682951168146E-5,4.14641446870493E-7,0.321056460432866,0.00274795069722537,7.53564210844015E-5,4.14576121444565E-7,7.53552380246103E-5,3.59336749128785E-7,4.22256917002533E-7,2.06761846571305E-7,1.0001575716076,10.005763053894,2,20,1,3,0.246411217579303,0.0231874687222434,0.0413267537951469,172.859115600586,56.0079193115234,56.0150680541992,-640.375366210937,-640.375366210937,,,25.4268016815186,0,1,,,,,,1,1,1,56.0127220153809,0,56.0113560069691,,,,,,,,,,,,,,,,,,,,,,,,,,,,,,,,,
,3762241532.84442,56.0128364562988,-620.291137695313,,,5,,,,31.6299982368946,,,,,7.85573622078717E-5,4.07594443156165E-7,0.303628905057374,0.00208478661540859,7.85449794555223E-5,4.07530195313483E-7,7.85438765752193E-5,3.73390172146791E-7,4.16233354189228E-7,1.63280860594361E-7,1.0001576517358,10.005763053894,2,20,1,3,0.256845356392995,0.0240849580050798,0.0413267537951469,172.859115600586,56.0111770629883,56.013370513916,-620.291137695313,-620.291137695313,,,25.4407405853271,0,1,,,,,,1,1,1,56.0124168395996,0,56.0121154785156,,,,,,,,,,,,,,,,,,,,,,,,,,,,,,,,,
,3762241554.62983,56.007453918457,-600.27978515625,,,5,,,,31.6299982368946,,,,,8.135036072108E-5,4.16779528156758E-7,0.282430998935689,0.00255578038103692,8.13375390771192E-5,4.1671383946561E-7,8.13365508890351E-5,3.61323956301186E-7,4.00939642954882E-7,2.07594370359672E-7,1.00015763501215,10.005763053894,2,20,1,3,0.265986731210706,0.0248371633492312,0.0413267537951469,172.859115600586,56.005298614502,56.0081977844238,-600.27978515625,-600.27978515625,,,25.3916072845459,0,1,,,,,,1,1,1,56.0069351196289,0,56.0066612243652,,,,,,,,,,,,,,,,,,,,,,,,,,,,,,,,,
,3762241576.09795,56.050386428833,-580.219848632813,,,5,,,,31.6299982368946,,,,,8.65732835556405E-5,4.8121157587839E-7,0.23657628569642,0.00228823228845715,8.65596077868968E-5,4.81135560068913E-7,8.65588699135548E-5,4.38671645568453E-7,3.57406644743806E-7,1.9763252398604E-7,1.00015799249897,10.005763053894,2,20,1,3,0.283085298993546,0.026199138631344,0.0413267537951469,172.859115600586,56.0448417663574,56.052734375,-580.219848632813,-580.219848632813,,,25.3583202362061,0,1,,,,,,1,1,1,56.0513000488281,0,56.050594329834,,,,,,,,,,,,,,,,,,,,,,,,,,,,,,,,,
,3762241598.18646,56.073917388916,-560.3056640625,,,5,,,,31.6299982368946,,,,,8.75182597743743E-5,4.11111289362601E-7,0.410371853814921,0.00182013699535095,8.75044610351132E-5,4.11046470689289E-7,8.75022165940308E-5,3.79207357601197E-7,6.26731343533745E-7,1.58622132778621E-7,1.00015769183763,10.005763053894,2,20,1,3,0.2860940402343,0.0273469390337799,0.0413267537951469,172.859115600586,56.0644149780273,56.0744209289551,-560.3056640625,-560.3056640625,,,25.3562564849854,0,1,,,,,,1,1,1,56.073413848877,0,56.0709243774414,,,,,,,,,,,,,,,,,,,,,,,,,,,,,,,,,
,3762241618.95858,56.0928401947022,-540.245727539063,,,5,,,,31.6299982368946,,,,,9.28909166408806E-5,5.36965404021878E-7,0.406545349111901,0.00193036899454249,9.28762650195598E-5,5.36880708832654E-7,9.28739270133857E-5,5.06437729800106E-7,6.59003107589357E-7,1.78218184682619E-7,1.00015775420467,10.005763053894,2,20,1,3,0.30365945338593,0.0289989329870367,0.0413267537951469,172.859115600586,56.0812721252441,56.0931358337402,-540.245727539063,-540.245727539063,,,25.3074073791504,0,1,,,,,,1,1,1,56.0929145812988,0,56.089300329035,,,,,,,,,,,,,,,,,,,,,,,,,,,,,,,,,
,3762241641.68365,56.0539722442627,-520.161499023438,,,5,,,,31.6299982368946,,,,,9.61919043113688E-5,4.58770596735401E-7,0.663677226925806,0.00209826210136023,9.61767705939723E-5,4.58698419096228E-7,9.61703184521426E-5,4.12350460672206E-7,1.11402455047606E-6,2.00926198552599E-7,1.0001573531457,10.005763053894,2,20,1,3,0.314312914325511,0.0314335821515063,0.0413267537951469,172.859115600586,56.0380821228027,56.0602226257324,-520.161499023438,-520.161499023438,,,25.2736263275146,0,1,,,,,,1,1,1,56.051513671875,0,56.0483428955078,,,,,,,,,,,,,,,,,,,,,,,,,,,,,,,,,
,3762241662.21111,56.0410194396973,-500.186614990234,,,5,,,,31.6299982368946,,,,,0.000102706391491338,5.59560683165152E-7,0.496984192040757,0.00166344684798798,0.000102690199434283,5.59472466274499E-7,0.000102686336332384,5.33241144261478E-7,8.90724696680928E-7,1.6930245888935E-7,1.00015767869908,10.005763053894,2,20,1,3,0.335696131772417,0.0325786972521844,0.0413267537951469,172.859115600586,56.0349388122559,56.0416641235352,-500.186614990234,-500.186614990234,,,25.2559452056885,0,1,,,,,,1,1,1,56.0403785705566,0,56.0390022277832,,,,,,,,,,,,,,,,,,,,,,,,,,,,,,,,,
,3762241684.15059,56.0731830596924,-480.308807373047,,,5,,,,31.6299982368946,,,,,0.000109495843100414,5.19446526631656E-7,0.321490066506092,0.00161547568625216,0.000109478570336463,5.19364584916014E-7,0.000109476846929535,4.88619787247944E-7,6.14287622427095E-7,1.76040550938575E-7,1.00015777301345,10.005763053894,2,20,1,3,0.357992696427187,0.0336283438043691,0.0413267537951469,172.859115600586,56.0638084411621,56.0735321044922,-480.308807373047,-480.308807373047,,,25.2224197387695,0,1,,,,,,1,1,1,56.0734481811523,0,56.0703926086426,,,,,,,,,,,,,,,,,,,,,,,,,,,,,,,,,
,3762241705.81128,56.0837478637695,-460.188201904297,,,5,,,,31.6299982368946,,,,,0.000116465886092572,6.52382225807502E-7,0.462694525498288,0.00246335973345459,0.00011644752435341,6.52279372751843E-7,0.000116443727346728,5.8625726903503E-7,9.40366757633653E-7,2.85955931257121E-7,1.00015768252064,10.005763053894,2,20,1,3,0.380692268676673,0.036699097023597,0.0413267537951469,172.859115600586,56.0734634399414,56.0842247009277,-460.188201904297,-460.188201904297,,,25.2045059204102,0,1,,,,,,1,1,1,56.0834312438965,0,56.0802864074707,,,,,,,,,,,,,,,,,,,,,,,,,,,,,,,,,
,3762241727.43928,56.0474853515625,-439.946105957031,,,5,,,,31.6299982368946,,,,,0.000124368479795335,5.31114588635538E-7,0.452821995614211,0.00204770877757086,0.000124348907194192,5.31031004000417E-7,0.00012434502372843,4.66322932062563E-7,9.82748373658796E-7,2.54041040468394E-7,1.00015740066868,10.005763053894,2,20,1,3,0.406530855082256,0.0391104111118763,0.0413267537951469,172.859115600586,56.0339050292969,56.0514106750488,-439.946105957031,-439.946105957031,,,25.1711711883545,0,1,,,,,,1,1,1,56.0455474853516,0,56.0424224853516,,,,,,,,,,,,,,,,,,,,,,,,,,,,,,,,,
,3762241749.29967,56.0691146850586,-420.007659912109,,,5,,,,31.6299982368946,,,,,0.000141311933311254,5.58480521717058E-7,0.245038762159241,0.0012941847179103,0.000141289635486973,5.58392398228508E-7,0.000141288343363661,5.27863547655806E-7,6.04256232129451E-7,1.82104765054653E-7,1.00015781641876,10.005763053894,2,20,1,3,0.462073733542467,0.0427533566191942,0.0413267537951469,172.859115600586,56.0627098083496,56.0692863464355,-420.007659912109,-420.007659912109,,,25.1218872070313,0,1,,,,,,1,1,1,56.0692939758301,0,56.066926574707,,,,,,,,,,,,,,,,,,,,,,,,,,,,,,,,,
,3762241769.94156,56.0914402008057,-399.959838867188,,,5,,,,31.6299982368946,,,,,0.000164897456247469,5.83441901072157E-7,0.30447091440282,0.00114708825997222,0.000164871457642581,5.8334991253694E-7,0.000164869129761353,5.52165354816383E-7,8.76126088803853E-7,1.88176888584525E-7,1.00015769015001,10.005763053894,2,20,1,3,0.539144417909514,0.0504367527597362,0.0413267537951469,172.859115600586,56.0810317993164,56.0916519165039,-399.959838867188,-399.959838867188,,,25.1045188903809,0,1,,,,,,1,1,1,56.0913772583008,0,56.0881301879883,,,,,,,,,,,,,,,,,,,,,,,,,,,,,,,,,
,3762241792.79164,56.0610980987549,-379.984924316406,,,5,,,,31.6299982368946,,,,,0.000257553414576214,6.93332227483949E-7,0.240529756025576,0.000866097674596484,0.000257512869269907,6.93223079765671E-7,0.000257510600133201,6.56684178694446E-7,1.08104516970669E-6,2.22090359476054E-7,1.00015744963124,10.005763053894,2,20,1,3,0.842178502248804,0.0778194030109124,0.0413267537951469,172.859115600586,56.0466461181641,56.065486907959,-379.984924316406,-379.984924316406,,,25.0869998931885,0,1,,,,,,1,1,1,56.0592002868652,0,56.0560836791992,,,,,,,,,,,,,,,,,,,,,,,,,,,,,,,,,
,3762241813.3794,56.0696697235107,-359.925018310547,,,5,,,,31.6299982368946,,,,,0.000356688799920474,8.7184446557986E-7,0.187491166419726,0.000758231348326981,0.000356632508398504,8.71706873785839E-7,0.000356630598954609,8.29041475580054E-7,1.16702008797868E-6,2.69375398976089E-7,1.00015784181375,10.005763053894,2,20,1,3,1.16644397148414,0.106668234069806,0.0413267537951469,172.859115600586,56.0645294189453,56.0705680847168,-359.925018310547,-359.925018310547,,,25.0378856658936,0,1,,,,,,1,1,1,56.0705375671387,0,56.0682151794434,,,,,,,,,,,,,,,,,,,,,,,,,,,,,,,,,
,3762241836.39105,56.0405139923096,-339.986511230469,,,5,,,,31.6299982368946,,,,,0.000494210184301997,7.11277353106187E-7,0.140354722473075,0.000393936231863891,0.000494132395003049,7.11165397164337E-7,0.000494130912410174,6.8423867306284E-7,1.21045121284699E-6,1.93839264363834E-7,1.00015742602536,10.005763053894,2,20,1,3,1.61628976552156,0.146430091858569,0.0413267537951469,172.859115600586,56.0292358398438,56.0453186035156,-339.986511230469,-339.986511230469,,,25.0202808380127,0,1,,,,,,1,1,1,56.0385856628418,0,56.0366100311279,,,,,,,,,,,,,,,,,,,,,,,,,,,,,,,,,
,3762241858.05534,56.0195713043213,-319.9873046875,,,5,,,,31.6299982368946,,,,,0.000603119864845425,6.2245353464164E-7,0.105592015558302,0.000262139876393072,0.000603024887952166,6.22355513159735E-7,0.000603023863900159,6.02117807968998E-7,1.11133102381896E-6,1.57418328306858E-7,1.00015750078505,10.005763053894,2,20,1,3,1.97258419908226,0.177460102854116,0.0413267537951469,172.859115600586,56.0142021179199,56.021297454834,-319.9873046875,-319.9873046875,,,25.0024433135986,0,1,,,,,,1,1,1,56.0186500549316,0,56.0173831939697,,,,,,,,,,,,,,,,,,,,,,,,,,,,,,,,,
,3762241880.71193,56.0413722991943,-299.866668701172,,,5,,,,31.6299982368946,,,,,0.000661471733229993,3.32732616272351E-7,0.0517157481761918,0.000268167463828334,0.000661367211308031,3.32680039796585E-7,0.000661366941898477,2.81510573711939E-7,5.96956630984448E-7,1.77278892616781E-7,1.00015803916519,10.005763053894,2,20,10,3,2.16361678672156,0.19254832566462,0.0413267537951469,172.859115600586,56.0337753295898,56.0424613952637,-299.866668701172,-299.866668701172,,,24.9378070831299,0,1,,,,,,1,1,1,56.0424003601074,0,56.039102935791,,,,,,,,,,,,,,,,,,,,,,,,,,,,,,,,,
,3762241906.72397,56.0227355957031,-279.903900146484,,,5,,,,31.6299982368946,,,,,0.000742868871034895,4.68454368020034E-7,0.0814319137454502,0.000210460928414138,0.000742751864747422,4.6838058365702E-7,0.000742751114580864,4.41631465346238E-7,1.05563945435236E-6,1.56019293560204E-7,1.00015753078925,10.005763053894,2,20,10,3,2.42975058975725,0.217450626942428,0.0413267537951469,172.859115600586,56.0164527893066,56.0246887207031,-279.903900146484,-279.903900146484,,,24.9198513031006,0,1,,,,,,1,1,1,56.0218544006348,0,56.0201084136963,,,,,,,,,,,,,,,,,,,,,,,,,,,,,,,,,
,3762241928.58628,56.0412425994873,-260.013977050781,,,5,,,,31.6299982368946,,,,,0.000772297441473768,4.49123045516992E-7,0.180019453531406,0.000194674295172793,0.000772175677933211,4.49052234959775E-7,0.000772171866578419,4.23308474955934E-7,2.42611962079969E-6,1.49859416630556E-7,1.00015768890945,10.005763053894,2,20,10,3,2.52561535651297,0.230357161896068,0.0413267537951469,172.859115600586,56.037281036377,56.0412902832031,-260.013977050781,-260.013977050781,,,24.8865604400635,0,1,,,,,,1,1,1,56.0411949157715,0,56.039965057373,,,,,,,,,,,,,,,,,,,,,,,,,,,,,,,,,
,3762241951.64085,56.0739727020264,-239.893341064453,,,5,,,,31.6299982368946,,,,,0.000806090248932154,3.57347238716827E-7,0.885634074878538,0.000203600814721458,0.000805963153081777,3.57290895954655E-7,0.000805866872231898,3.17802426328651E-7,1.24574622093405E-5,1.63274009418837E-7,1.0001576943684,10.005763053894,2,20,10,3,2.63297023619663,0.272825537546853,0.0413267537951469,172.859115600586,56.065372467041,56.0743293762207,-239.893341064453,-239.893341064453,,,24.8381538391113,0,1,,,,,,1,1,1,56.0736961364746,0,56.0711238861084,,,,,,,,,,,,,,,,,,,,,,,,,,,,,,,,,
,3762241973.25714,56.0676174163818,-219.991271972656,,,5,,,,31.6299982368946,,,,,0.000787971436789955,2.25207266227661E-7,1.21481136936977,0.000136677533227197,0.00078784724595522,2.25171771694388E-7,0.000787670166496118,1.98108188918612E-7,1.67030467640867E-5,1.07030239892178E-7,1.00015763313938,10.005763053894,2,20,10,3,2.57221779624067,0.281420843954864,0.0413267537951469,172.859115600586,56.055046081543,56.0686950683594,-219.991271972656,-219.991271972656,,,24.8202590942383,0,1,,,,,,1,1,1,56.0665626525879,0,56.0630760192871,,,,,,,,,,,,,,,,,,,,,,,,,,,,,,,,,
,3762241995.1834,56.0448894500732,-200.052780151367,,,5,,,,31.6299982368946,,,,,0.000701717815730299,3.06421215882719E-7,0.238979899042923,0.000163244925484127,0.000701607304550258,3.06372958635435E-7,0.000701601201584146,2.84290866072327E-7,2.92638581884652E-6,1.142063625674E-7,1.00015751144454,10.005763053894,2,20,10,3,2.29459459761479,0.211519100947804,0.0413267537951469,172.859115600586,56.0348472595215,56.048900604248,-200.052780151367,-200.052780151367,,,24.7870330810547,0,1,,,,,,1,1,1,56.0429382324219,0,56.04128074646,,,,,,,,,,,,,,,,,,,,,,,,,,,,,,,,,
,3762242016.84648,56.0530662536621,-180.041427612305,,,5,,,,31.6299982368946,,,,,0.000668212990670621,2.81503825526737E-7,0.0840964489301248,0.000204875546210456,0.000668107582810162,2.81459419452066E-7,0.000668106863151797,2.45988145695422E-7,9.80621182249954E-7,1.36781712869892E-7,1.00015777078897,10.005763053894,2,20,10,3,2.18557437104089,0.195465520517931,0.0413267537951469,172.859115600586,56.0465660095215,56.0531196594238,-180.041427612305,-180.041427612305,,,24.7852363586426,0,1,,,,,,1,1,1,56.0530052185059,0,56.0507942199707,,,,,,,,,,,,,,,,,,,,,,,,,,,,,,,,,
,3762242038.7401,56.0305099487305,-159.99365234375,,,5,,,,31.6299982368946,,,,,0.000642049968187252,2.4995182763294E-7,0.0877930731653524,0.000123623023160242,0.000641948907840232,2.49912484560453E-7,0.00064194815423202,2.37036983725462E-7,9.83643923854902E-7,7.91815526844092E-8,1.00015742739926,10.005763053894,2,20,10,3,2.09999174266482,0.187902802662984,0.0413267537951469,172.859115600586,56.0228576660156,56.0346374511719,-159.99365234375,-159.99365234375,,,24.736442565918,0,1,,,,,,1,1,1,56.0283622741699,0,56.0278450012207,,,,,,,,,,,,,,,,,,,,,,,,,,,,,,,,,
,3762242059.29585,56.0494499206543,-139.921585083008,,,5,,,,31.6299982368946,,,,,0.000640651242529031,2.14686240962089E-7,0.323018995758665,0.000108158427372547,0.000640550141376612,2.1465236133316E-7,0.000640539961726622,2.03288771247271E-7,3.61123924108059E-6,6.89152502039748E-8,1.00015783487644,10.005763053894,2,20,10,3,2.09463248598536,0.196049457245346,0.0413267537951469,172.859115600586,56.0464820861816,56.0508041381836,-139.921585083008,-139.921585083008,,,24.7188053131104,0,1,,,,,,1,1,1,56.050365447998,0,56.0491360751065,,,,,,,,,,,,,,,,,,,,,,,,,,,,,,,,,
,3762242082.30056,56.0316867828369,-120.043807983398,,,5,,,,31.6299982368946,,,,,0.000684591576416971,2.67686297751471E-7,1.68205822328591,0.000175646606927998,0.000684483783059517,2.67644148818044E-7,0.000684188839606918,2.39762140636187E-7,2.00918149704311E-5,1.1894329032816E-7,1.00015748124371,10.005763053894,2,20,10,3,2.23270299451225,0.26247625628975,0.0413267537951469,172.859115600586,56.0227012634277,56.0361862182617,-120.043807983398,-120.043807983398,,,24.6858673095703,0,1,,,,,,1,1,1,56.0296096801758,0,56.0287153070623,,,,,,,,,,,,,,,,,,,,,,,,,,,,,,,,,
,3762242102.72327,56.0148105621338,-99.9231796264648,,,5,,,,31.6299982368946,,,,,0.000775833701028216,3.23458749469705E-7,2.02596833854262,0.000177432039578661,0.000775711516759377,3.23407808693672E-7,0.000775226624740445,2.93666917679981E-7,2.74233026215211E-5,1.3547085363421E-7,1.00015751251103,10.005763053894,2,20,10,3,2.52845114253803,0.312586735872472,0.0413267537951469,172.859115600586,56.0110282897949,56.0167617797852,-99.9231796264648,-99.9231796264648,,,24.6529636383057,0,1,,,,,,1,1,1,56.0141143798828,0,56.0135334014893,,,,,,,,,,,,,,,,,,,,,,,,,,,,,,,,,
,3762242124.58057,56.0064716339111,-79.8875350952148,,,5,,,,31.6299982368946,,,,,0.000815248126605175,2.78903381846858E-7,0.937548787204569,0.000150903419950459,0.000815119671839847,2.78859436369039E-7,0.000815010546860098,2.50627482337719E-7,1.33374632934413E-5,1.2226385544843E-7,1.000157590069,10.005763053894,2,20,10,3,2.66266765610088,0.277881775833869,0.0413267537951469,172.859115600586,56.0043029785156,56.007251739502,-79.8875350952148,-79.8875350952148,,,24.6355133056641,0,1,,,,,,1,1,1,56.0061721801758,0,56.00573387146,,,,,,,,,,,,,,,,,,,,,,,,,,,,,,,,,
,3762242146.31154,56.0490474700928,-59.8276252746582,,,5,,,,31.6299982368946,,,,,0.000763348961921732,2.42127717552069E-7,0.710276654160632,0.000151470329046634,0.00076322842431276,2.42089484060447E-7,0.000763169779609341,2.12923275620419E-7,9.46124568794253E-6,1.15199813331986E-7,1.00015793123675,10.005763053894,2,20,10,3,2.49417716327858,0.250246468885626,0.0413267537951469,172.859115600586,56.0450973510742,56.0509834289551,-59.8276252746582,-59.8276252746582,,,24.6026363372803,0,1,,,,,,1,1,1,56.0503997802734,0,56.0491924285889,,,,,,,,,,,,,,,,,,,,,,,,,,,,,,,,,
,3762242167.65367,56.0537357330322,-39.9498405456543,,,5,,,,31.6299982368946,,,,,0.000696284733127354,3.29510918578769E-7,0.571382889439674,0.000123453873359179,0.00069617503552358,3.29459005106498E-7,0.00069614041815535,3.18386318585162E-7,6.94249931590956E-6,8.46958569444291E-8,1.00015757187227,10.005763053894,2,20,10,3,2.27560068854567,0.222696830360853,0.0413267537951469,172.859115600586,56.0446624755859,56.0545921325684,-39.9498405456543,-39.9498405456543,,,24.5541839599609,0,1,,,,,,1,1,1,56.0529518127441,0,56.0507517727939,,,,,,,,,,,,,,,,,,,,,,,,,,,,,,,,,
,3762242189.87819,56.0770244598389,-19.8899211883545,,,5,,,,31.6299982368946,,,,,0.000634108509605314,2.72386685414472E-7,0.181586893772137,4.61749800857801E-5,0.000634008514274961,2.72343731572693E-7,0.000634005330162008,2.70879745573428E-7,2.00935295722552E-6,2.82005596578211E-8,1.00015771922317,10.005763053894,2,20,10,3,2.07373078696993,0.188662507302799,0.0413267537951469,172.859115600586,56.0675163269043,56.0774040222168,-19.8899211883545,-19.8899211883545,,,24.5521793365479,0,1,,,,,,1,1,1,56.0769348144531,0,56.0740699768066,,,,,,,,,,,,,,,,,,,,,,,,,,,,,,,,,
,3762242212.85133,56.0492668151855,0.18214213848114,,,5,,,,31.6299982368946,,,,,0.000601506314937327,3.13435717765957E-7,0.00801311245151304,5.3721120113623E-5,0.000601411603328722,3.13386364998934E-7,0.000601411597447074,3.11757976676664E-7,8.41105371523454E-8,3.19057635188019E-8,1.00015748217707,10.005763053894,2,20,10,3,1.96764722580797,0.172961087021991,0.0413267537951469,172.859115600586,56.0352058410645,56.0534934997559,0.18214213848114,0.18214213848114,,,24.5033683776855,0,1,,,,,,1,1,1,56.0464286804199,0,56.044059753418,,,,,,,,,,,,,,,,,,,,,,,,,,,,,,,,,