File: Experimental_Data/AC_Suceptibillity_FieldScans/ZFCd_Down_48K.dat
[Header]
; MPMS3 Data File (default extension .dat)
; Copyright (c) 2007, Quantum Design, Inc. All rights reserved.
TITLE,ZFCd_Down_48K
FILEOPENTIME,3762238115.72408,03/20/2019,10:08 am
BYAPP,SQUID AC,0.9.1.0
INFO,MPMS3 Measurement Release 1.1.16 Build 347, MultiVu Release 2.3.3.2,APPNAME
INFO,0,MOMENT_UNITS
INFO,SrM,SAMPLE_MATERIAL
INFO,MvsH,SAMPLE_COMMENT
INFO,,SAMPLE_MASS
INFO,,SAMPLE_VOLUME
INFO,,SAMPLE_MOLECULAR_WEIGHT
INFO,,SAMPLE_SIZE
INFO,,SAMPLE_SHAPE
INFO,Quartz,SAMPLE_HOLDER
INFO,Standard,SAMPLE_HOLDER_DETAIL
INFO,65.34,SAMPLE_OFFSET
DATATYPE,COMMENT,1
DATATYPE,TIME,2
STARTUPAXIS,X,2
STARTUPAXIS,Y1,5
FIELDGROUP, VSM,2,3,4,5,6,8,9,10,11,14,15
FIELDGROUP, DC, 2,3,4,14,56,57,58,59,60,61,62,63,64,65,66,67,68,69
FIELDGROUP, AC, 2,3,4,11,16,17,18,19,20,21,22,23,24,25,26,27,28,29,30
STARTUPGROUP, All
[Data]
Comment,Time Stamp (sec),Temperature (K),Magnetic Field (Oe),Moment (emu),M. Std. Err. (emu),Transport Action,Averaging Time (sec),Frequency (Hz),Peak Amplitude (mm),Center Position (mm),Lockin Signal' (V),Lockin Signal (V),Range,M. Quad. Signal (emu),AC Moment (emu),AC M. Std Err. (emu),AC Phase (deg),AC Phase Std. Err. (deg),AC Susceptibility (emu/Oe),AC Suscept. Std Err. (emu/Oe),AC X' (emu/Oe),AC X' Std Err. (emu/Oe),AC X'' (emu/Oe),AC X'' Std Err. (emu/Oe),AC Drive (Oe),AC Frequency (Hz),AC Averaging Time (sec),AC Cycles,AC Range,AC Measure Type,AC Signal' (V),AC Signal'' (V),AC Trim Coil Ratio,AC Trim Coil Phase,Min. Temperature (K),Max. Temperature (K),Min. Field (Oe),Max. Field (Oe),Mass (grams),Motor Lag (deg),Pressure (Torr),Measure Count,Measurement Number,SQUID Status (code),Motor Status (code),Measure Status (code),Motor Current (amps),Motor Temp. (C),Temp. Status (code),Field Status (code),Chamber Status (code),Chamber Temp (K),Redirection State,Average Temp (K),Rotation Angle (deg),Rotator state,DC Moment Fixed Ctr (emu),DC Moment Err Fixed Ctr (emu),DC Moment Free Ctr (emu),DC Moment Err Free Ctr (emu),DC Fixed Fit,DC Free Fit,DC Calculated Center (mm),DC Calculated Center Err (mm),DC Scan Length (mm),DC Scan Time (s),DC Number of Points,DC Squid Drift,DC Min V (V),DC Max V (V),DC Scans per Measure,Map 01,Map 02,Map 03,Map 04,Map 05,Map 06,Map 07,Map 08,Map 09,Map 10,Map 11,Map 12,Map 13,Map 14,Map 15,Map 16
,3762238256.47129,47.9385433197022,-0.303570240736008,,,5,,,,31.6299982368946,,,,,0.000619647386362045,1.55496922160656E-8,0.00985146148168514,6.69583049439883E-6,0.000619549212024596,1.5547228587937E-8,0.000619549202866569,1.49855855315992E-8,1.06525562965799E-7,4.1410799365251E-9,1.00015846091891,10.005763053894,2,20,1,3,2.02698241513665,0.178266679681809,0.0413267537951469,172.859115600586,47.9091148376465,47.9487342834473,-0.303570240736008,-0.303570240736008,,,24.9652118682861,0,1,,,,,,1,1,1,47.9330787658691,0,47.9273816888983,,,,,,,,,,,,,,,,,,,,,,,,,,,,,,,,,
,3762238276.98871,47.8942489624023,-19.8777770996094,,,5,,,,31.6299982368946,,,,,0.000619348467654976,1.965568479048E-8,0.00869258423779407,1.3252219523561E-5,0.000619250033142601,1.96525608661486E-8,0.000619250026015899,1.78594903085305E-8,9.39490325892143E-8,8.20132638767529E-9,1.00015895762149,10.005763053894,2,20,1,3,2.02600555786456,0.178182306361545,0.0413267537951469,172.859115600586,47.8905410766602,47.8960952758789,-19.8777770996094,-19.8777770996094,,,24.9989433288574,0,1,,,,,,1,1,1,47.8934326171875,0,47.8926748795943,,,,,,,,,,,,,,,,,,,,,,,,,,,,,,,,,
,3762238300.05978,47.8900585174561,-39.8041305541992,,,5,,,,31.6299982368946,,,,,0.000620880799823617,2.6029289330218E-8,0.00823046862535204,3.61675734521975E-5,0.000620782027186082,2.602514846846E-8,0.000620782020781172,1.31620892642376E-8,8.91745783683608E-8,2.24514533829243E-8,1.0001591100148,10.005763053894,2,20,1,3,2.03101686266321,0.178650091831872,0.0413267537951469,172.859115600586,47.8890037536621,47.9013862609863,-39.8041305541992,-39.8041305541992,,,25.0316143035889,0,1,,,,,,1,1,1,47.8906898498535,0,47.8933129744096,,,,,,,,,,,,,,,,,,,,,,,,,,,,,,,,,
,3762238325.10122,47.9308528900146,-59.8276252746582,,,5,,,,31.6299982368946,,,,,0.000629642531413204,3.40855575168487E-8,0.0178654290340834,3.39613920798844E-5,0.000629542128447357,3.40801222247639E-8,0.000629542097843481,2.65429820201939E-8,1.96297879757855E-7,2.1375800250061E-8,1.00015948569811,10.005763053894,2,20,10,3,2.05964489958393,0.181561479897009,0.0413267537951469,172.859115600586,47.9218559265137,47.9535064697266,-59.8276252746582,-59.8276252746582,,,25.0478229522705,0,1,,,,,,1,1,1,47.9347076416016,0,47.9396540323893,,,,,,,,,,,,,,,,,,,,,,,,,,,,,,,,,
,3762238353.98296,47.9563598632812,-79.8996810913086,,,5,,,,31.6299982368946,,,,,0.000644511138446683,5.10916846884541E-8,0.0252179161043911,4.29709100245747E-5,0.000644408647229282,5.10835600050306E-8,0.000644408584812053,4.29334892498952E-8,2.83627220297861E-7,2.76811416602837E-8,1.00015904693061,10.005763053894,2,20,10,3,2.1082554227038,0.186164683793439,0.0413267537951469,172.859115600586,47.9559631347656,47.9584541320801,-79.8996810913086,-79.8996810913086,,,25.0468654632568,0,1,,,,,,1,1,1,47.9563407897949,0,47.9565395008434,,,,,,,,,,,,,,,,,,,,,,,,,,,,,,,,,
,3762238376.97795,47.960958480835,-99.8017501831055,,,5,,,,31.6299982368946,,,,,0.00066364951729259,1.0223031416663E-7,0.0441525097182955,9.02330050203221E-5,0.000663543995251704,1.02214059274386E-7,0.00066354379823401,8.28554720168763E-8,5.11331376381213E-7,5.98555316592239E-8,1.00015902794938,10.005763053894,2,20,10,3,2.17079246557581,0.192456347749922,0.0413267537951469,172.859115600586,47.9601249694824,47.9722290039063,-99.8017501831055,-99.8017501831055,,,25.03076171875,0,1,,,,,,1,1,1,47.9614295959473,0,47.9644726839932,,,,,,,,,,,,,,,,,,,,,,,,,,,,,,,,,
,3762238400.04094,47.9971122741699,-119.78881072998,,,5,,,,31.6299982368946,,,,,0.000696114754234934,2.15329582001401E-7,0.09053490303749,0.000109720879379333,0.000696003956516108,2.15295308878563E-7,0.000696003087618825,2.01346969648418E-7,1.09977776776144E-6,7.62329839276601E-8,1.0001591912198,10.005763053894,2,20,10,3,2.2768187645114,0.203762921739457,0.0413267537951469,172.859115600586,47.994083404541,48.0011596679687,-119.78881072998,-119.78881072998,,,25.0138645172119,0,1,,,,,,1,1,1,47.9983940124512,0,47.9986595153809,,,,,,,,,,,,,,,,,,,,,,,,,,,,,,,,,
,3762238421.7558,48.0432262420654,-139.860870361328,,,5,,,,31.6299982368946,,,,,0.00074728887691123,3.35098206540863E-7,0.140092003654591,0.000179136285679277,0.000747169985746569,3.35044893535301E-7,0.000747167752325368,3.07245212618316E-7,1.82687864566135E-6,1.33624324159963E-7,1.00015912197616,10.005763053894,2,20,10,3,2.44400316103698,0.220908611821074,0.0413267537951469,172.859115600586,48.0379257202148,48.0435791015625,-139.860870361328,-139.860870361328,,,25.0122051239014,0,1,,,,,,1,1,1,48.0435791015625,0,48.0414970397949,,,,,,,,,,,,,,,,,,,,,,,,,,,,,,,,,
,3762238443.73116,48.0231685638428,-159.945083618164,,,5,,,,31.6299982368946,,,,,0.000797179898880424,2.78731901810773E-7,0.120216465050238,0.000108707045576365,0.000797053253241643,2.78687620488824E-7,0.00079705149879637,2.64955973819831E-7,1.6723544922748E-6,8.64009360534253E-8,1.00015889231775,10.005763053894,2,20,10,3,2.6072494003646,0.23480879837336,0.0413267537951469,172.859115600586,48.0148506164551,48.025691986084,-159.945083618164,-159.945083618164,,,24.9637355804443,0,1,,,,,,1,1,1,48.0218276977539,0,48.019660949707,,,,,,,,,,,,,,,,,,,,,,,,,,,,,,,,,
,3762238466.79779,48.0270137786865,-179.798568725586,,,5,,,,31.6299982368946,,,,,0.000827549532006113,2.09353970870265E-7,0.0675127738719112,9.50797134567139E-5,0.00082741801094838,2.09320698595163E-7,0.000827417436538946,1.94016268203655E-7,9.74963123266193E-7,7.85674393925018E-8,1.00015895358331,10.005763053894,2,20,10,3,2.70679549433014,0.241321889373005,0.0413267537951469,172.859115600586,48.0212631225586,48.0274543762207,-179.798568725586,-179.798568725586,,,24.9777374267578,0,1,,,,,,1,1,1,48.0267333984375,0,48.0250629078258,,,,,,,,,,,,,,,,,,,,,,,,,,,,,,,,,
,3762238489.83055,48.0121002197266,-199.858489990234,,,5,,,,31.6299982368946,,,,,0.000843110021627002,3.06069487933432E-7,0.0188891808396754,0.00026748004967942,0.00084297611938786,3.06020878156872E-7,0.000842976073577231,2.06924729014313E-7,2.77911012111592E-7,2.25457167529125E-7,1.0001588446411,10.005763053894,2,20,10,3,2.75789557606027,0.243578402050447,0.0413267537951469,172.859115600586,48.0069198608398,48.0146560668945,-199.858489990234,-199.858489990234,,,24.9291744232178,0,1,,,,,,1,1,1,48.010856628418,0,48.0100803375244,,,,,,,,,,,,,,,,,,,,,,,,,,,,,,,,,
,3762238512.94389,48.0033645629883,-219.881988525391,,,5,,,,31.6299982368946,,,,,0.000851284918035428,2.52591409881627E-7,-0.0325057181586823,0.000235205633583855,0.000851149667176574,2.52551278540871E-7,0.000851149530198772,1.53984440637532E-7,-4.8288425330863E-7,2.00177272271792E-7,1.00015890373229,10.005763053894,2,20,10,3,2.78485228634606,0.243501943343169,0.0413267537951469,172.859115600586,48.0019340515137,48.0043640136719,-219.881988525391,-219.881988525391,,,24.9274826049805,0,1,,,,,,1,1,1,48.0030555725098,0,48.0028343200684,,,,,,,,,,,,,,,,,,,,,,,,,,,,,,,,,
,3762238534.5691,48.0137577056885,-239.844757080078,,,5,,,,31.6299982368946,,,,,0.000856499553240278,1.40337615363402E-7,-0.0137762960022743,0.000148067144615777,0.000856363361290375,1.40315300286402E-7,0.000856363336536241,6.00973872339621E-8,-2.05905480948585E-7,1.26793878172861E-7,1.00015903523675,10.005763053894,2,20,10,3,2.80182726478318,0.245969245671072,0.0413267537951469,172.859115600586,48.0123329162598,48.0141906738281,-239.844757080078,-239.844757080078,,,24.8940353393555,0,1,,,,,,1,1,1,48.0140419006348,0,48.0132556915283,,,,,,,,,,,,,,,,,,,,,,,,,,,,,,,,,
,3762238556.45984,48.0368671417236,-259.734710693359,,,5,,,,31.6299982368946,,,,,0.000859825634280338,1.83492250619985E-7,-0.0229420819441382,0.000165109651815438,0.000859688891837716,1.83463068914356E-7,0.000859688822919869,1.16252147683838E-7,-3.44232204249236E-7,1.41930038449825E-7,1.00015906038094,10.005763053894,2,20,10,3,2.81274350668245,0.246534219886567,0.0413267537951469,172.859115600586,48.0300903320313,48.0371017456055,-259.734710693359,-259.734710693359,,,24.8456230163574,0,1,,,,,,1,1,1,48.0365753173828,0,48.0346992492676,,,,,,,,,,,,,,,,,,,,,,,,,,,,,,,,,
,3762238578.13136,48.0195636749268,-279.782470703125,,,5,,,,31.6299982368946,,,,,0.000862842142321799,1.72273509130974E-7,-0.0326741572616651,0.000166615210710899,0.000862705108472103,1.72246149199187E-7,0.000862704968192061,9.49256682666833E-8,-4.91976217033212E-7,1.43728401570713E-7,1.00015884205199,10.005763053894,2,20,10,3,2.8226496452904,0.246980352248658,0.0413267537951469,172.859115600586,48.0136985778809,48.0224761962891,-279.782470703125,-279.782470703125,,,24.8437232971191,0,1,,,,,,1,1,1,48.0179786682129,0,48.0171123504639,,,,,,,,,,,,,,,,,,,,,,,,,,,,,,,,,
,3762238600.03524,48.0380954742432,-299.745239257812,,,5,,,,31.6299982368946,,,,,0.000864858925268491,2.09361930504084E-7,-0.0425071262851535,0.000228590233706905,0.000864721432943229,2.09328646857694E-7,0.000864721194972011,6.89335821231315E-8,-6.41527527719207E-7,1.97652836182399E-7,1.00015900187046,10.005763053894,2,20,10,3,2.82928597422143,0.247132424145224,0.0413267537951469,172.859115600586,48.0305252075195,48.038501739502,-299.745239257812,-299.745239257812,,,24.8103866577148,0,1,,,,,,1,1,1,48.0376472473145,0,48.0355644226074,,,,,,,,,,,,,,,,,,,,,,,,,,,,,,,,,
,3762238621.72103,48.0176010131836,-319.720153808594,,,5,,,,31.6299982368946,,,,,0.000867024658054542,2.83276472150998E-7,-0.0526037324885413,0.000201968372546428,0.000866886938369147,2.83231476029766E-7,0.000866886573009743,2.22652689503136E-7,-7.9589600813348E-7,1.75059558068162E-7,1.00015886695173,10.005763053894,2,20,10,3,2.83641081435039,0.247312206397388,0.0413267537951469,172.859115600586,48.0133438110352,48.0197219848633,-319.720153808594,-319.720153808594,,,24.762357711792,0,1,,,,,,1,1,1,48.0164947509766,0,48.0159160614014,,,,,,,,,,,,,,,,,,,,,,,,,,,,,,,,,
,3762238643.57028,48.009973526001,-339.755798339844,,,5,,,,31.6299982368946,,,,,0.00086917921180738,2.28384883961362E-7,-0.076057983912011,0.000223100362015802,0.000869041054472225,2.28348581842617E-7,0.000869040288779382,1.20668879932819E-7,-1.15361884748389E-6,1.93861023017247E-7,1.00015897676461,10.005763053894,2,20,10,3,2.84355683012829,0.246823784050445,0.0413267537951469,172.859115600586,48.0072174072266,48.0105514526367,-339.755798339844,-339.755798339844,,,24.7603816986084,0,1,,,,,,1,1,1,48.0099754333496,0,48.0090003967285,,,,,,,,,,,,,,,,,,,,,,,,,,,,,,,,,
,3762238665.26602,48.0308399200439,-359.827850341797,,,5,,,,31.6299982368946,,,,,0.000870453577121614,2.72918383991527E-7,-0.0832686390733244,0.000249317446520028,0.000870315085006936,2.72874961751528E-7,0.000870314165904097,1.65498002095966E-7,-1.26483883801859E-6,2.16958881019289E-7,1.0001591287076,10.005763053894,2,20,10,3,2.84775335558164,0.246888340160043,0.0413267537951469,172.859115600586,48.0259971618652,48.0310363769531,-359.827850341797,-359.827850341797,,,24.7276000976562,0,1,,,,,,1,1,1,48.0310363769531,0,48.029322052002,,,,,,,,,,,,,,,,,,,,,,,,,,,,,,,,,
,3762238687.1626,48.0158920288086,-379.899932861328,,,5,,,,31.6299982368946,,,,,0.000872168461863847,2.59743137092912E-7,-0.0992709001041812,0.000246997386924555,0.000872029893294498,2.5970186956665E-7,0.000872028584414222,1.45137834998804E-7,-1.51088177610162E-6,2.15360325752616E-7,1.00015890346239,10.005763053894,2,20,10,3,2.85342899614111,0.246639189978883,0.0413267537951469,172.859115600586,48.0101928710937,48.0183715820313,-379.899932861328,-379.899932861328,,,24.7098541259766,0,1,,,,,,1,1,1,48.014835357666,0,48.0135418285023,,,,,,,,,,,,,,,,,,,,,,,,,,,,,,,,,
,3762238710.23387,48.0445938110352,-399.765563964844,,,5,,,,31.6299982368946,,,,,0.000873262262159519,2.83137361510944E-7,-0.110293040151364,0.000234004434686029,0.000873123374565293,2.83092330059707E-7,0.000873121756871064,1.95975543097318E-7,-1.68074110786045E-6,2.0429110075171E-7,1.00015906983855,10.005763053894,2,20,10,3,2.85705133594281,0.246459465684391,0.0413267537951469,172.859115600586,48.0382995605469,48.0448913574219,-399.765563964844,-399.765563964844,,,24.6608734130859,0,1,,,,,,1,1,1,48.0447196960449,0,48.0425605773926,,,,,,,,,,,,,,,,,,,,,,,,,,,,,,,,,
,3762238731.95316,48.0225505828857,-419.7890625,,,5,,,,31.6299982368946,,,,,0.000874897202989382,3.93669325881782E-7,-0.117105971254624,0.000360810747493353,0.000874758235368673,3.93606795918974E-7,0.00087475640823337,2.35238227134464E-7,-1.78790379175505E-6,3.1557770245731E-7,1.00015886403247,10.005763053894,2,20,10,3,2.86242601098279,0.246641997466291,0.0413267537951469,172.859115600586,48.0145835876465,48.0251159667969,-419.7890625,-419.7890625,,,24.6439037322998,0,1,,,,,,1,1,1,48.0214347839355,0,48.0194374084473,,,,,,,,,,,,,,,,,,,,,,,,,,,,,,,,,
,3762238753.81114,48.05006980896,-439.824676513672,,,5,,,,31.6299982368946,,,,,0.000875918682051433,2.90356843469678E-7,-0.132379522343526,0.000280279052491452,0.00087577945389023,2.90310690955481E-7,0.000875777116340183,1.55075041982204E-7,-2.02345030683898E-6,2.45422143738633E-7,1.00015897628174,10.005763053894,2,20,10,3,2.86583006996602,0.246227307101746,0.0413267537951469,172.859115600586,48.0408706665039,48.0504150390625,-439.824676513672,-439.824676513672,,,24.6264877319336,0,1,,,,,,1,1,1,48.0497245788574,0,48.0469287872314,,,,,,,,,,,,,,,,,,,,,,,,,,,,,,,,,
,3762238775.46857,48.0373401641846,-460.163879394531,,,5,,,,31.6299982368946,,,,,0.000876806245099684,4.07444766502452E-7,-0.135236759154437,0.000363195779869095,0.000876666984298153,4.07380053134955E-7,0.000876664542281066,2.5418125965951E-7,-2.06921858360603E-6,3.1835576786065E-7,1.00015885256776,10.005763053894,2,20,10,3,2.86874254118637,0.246396270104563,0.0413267537951469,172.859115600586,48.0281066894531,48.0395698547363,-460.163879394531,-460.163879394531,,,24.578254699707,0,1,,,,,,1,1,1,48.0358390808105,0,48.0336933135986,,,,,,,,,,,,,,,,,,,,,,,,,,,,,,,,,
,3762238797.38804,48.0228404998779,-480.029510498047,,,5,,,,31.6299982368946,,,,,0.000877369486671673,5.09711695727359E-7,-0.145033903554896,0.000492302167932287,0.000877230114717716,5.09630726972385E-7,0.000877227304259635,2.70710914977625E-7,-2.22054701173533E-6,4.31785917309006E-7,1.00015887730211,10.005763053894,2,20,10,3,2.87062382613041,0.24612480534102,0.0413267537951469,172.859115600586,48.016544342041,48.0246658325195,-480.029510498047,-480.029510498047,,,24.5456466674805,0,1,,,,,,1,1,1,48.0219039916992,0,48.0204643249512,,,,,,,,,,,,,,,,,,,,,,,,,,,,,,,,,
,3762238819.0016,48.0106887817383,-500.089477539063,,,5,,,,31.6299982368946,,,,,0.000877328178174686,4.5314385310603E-7,-0.160345568021168,0.000276012014455226,0.000877188797461978,4.53071862356415E-7,0.000877185362424707,3.82940010982958E-7,-2.45486061256948E-6,2.42138515002223E-7,1.00015889477056,10.005763053894,2,20,10,3,2.87055066911363,0.245407793716227,0.0413267537951469,172.859115600586,48.0068550109863,48.0123252868652,-500.089477539063,-500.089477539063,,,24.5275173187256,0,1,,,,,,1,1,1,48.009937286377,0,48.0092258453369,,,,,,,,,,,,,,,,,,,,,,,,,,,,,,,,,
,3762238840.94464,48.0010795593262,-520.112915039063,,,5,,,,31.6299982368946,,,,,0.000875669940299724,5.39357574190004E-7,-0.169085884615336,0.000479786125627861,0.000875530806303885,5.39271876404766E-7,0.000875526993797638,3.38250997414808E-7,-2.58377994451889E-6,4.20000499319947E-7,1.00015891387812,10.005763053894,2,20,10,3,2.86515872659796,0.244568327112449,0.0413267537951469,172.859115600586,47.9986114501953,48.0016822814941,-520.112915039063,-520.112915039063,,,24.4955425262451,0,1,,,,,,1,1,1,48.0006675720215,0,48.0000061035156,,,,,,,,,,,,,,,,,,,,,,,,,,,,,,,,,
,3762238862.66625,47.99951171875,-540.184997558594,,,5,,,,31.6299982368946,,,,,0.000872377025460863,3.50520747857573E-7,-0.181116675298184,0.00032982162724745,0.000872238277139581,3.50464998836312E-7,0.000872233919248275,2.0024024154006E-7,-2.75721239976469E-6,2.87627469267654E-7,1.00015907158046,10.005763053894,2,20,10,3,2.85443190535554,0.243110600751491,0.0413267537951469,172.859115600586,47.9992027282715,48.0014610290527,-540.184997558594,-540.184997558594,,,24.4782123565674,0,1,,,,,,1,1,1,47.9995918273926,0,48.0001003265381,,,,,,,,,,,,,,,,,,,,,,,,,,,,,,,,,
,3762238884.59682,48.0124530792236,-560.074951171875,,,5,,,,31.6299982368946,,,,,0.000865167865506335,5.09020246721458E-7,-0.188749975624106,0.000476653753697482,0.000865030247623641,5.08939279441702E-7,0.000865025553771025,2.9845709964404E-7,-2.84967137578026E-6,4.12240888111194E-7,1.00015909025502,10.005763053894,2,20,10,3,2.83087196127463,0.240784620095273,0.0413267537951469,172.859115600586,48.0111618041992,48.0130882263184,-560.074951171875,-560.074951171875,,,24.4455280303955,0,1,,,,,,1,1,1,48.0128173828125,0,48.012151891535,,,,,,,,,,,,,,,,,,,,,,,,,,,,,,,,,
,3762238907.65986,48.0398864746094,-580.110595703125,,,5,,,,31.6299982368946,,,,,0.000847923951199492,3.92173444174305E-7,-0.214724496886516,0.000360111146842098,0.000847789081652339,3.92111065638179E-7,0.000847783128112857,2.46125501490991E-7,-3.17720885284972E-6,3.05243059399746E-7,1.00015908384535,10.005763053894,2,20,10,3,2.77455224591325,0.234787020757651,0.0413267537951469,172.859115600586,48.0330619812012,48.0400009155273,-580.110595703125,-580.110595703125,,,24.4431209564209,0,1,,,,,,1,1,1,48.039794921875,0,48.0375019073486,,,,,,,,,,,,,,,,,,,,,,,,,,,,,,,,,
,3762238929.53414,48.0180015563965,-600.255493164062,,,5,,,,31.6299982368946,,,,,0.000808279230496933,3.61157532151188E-7,-0.223296408141945,0.000309003075982923,0.000808150827222597,3.61100158649643E-7,0.00080814468988397,2.60850079556724E-7,-3.14956392379806E-6,2.49700942273049E-7,1.00015888528479,10.005763053894,2,20,10,3,2.64485804685363,0.223470989853108,0.0413267537951469,172.859115600586,48.0127372741699,48.0205116271973,-600.255493164062,-600.255493164062,,,24.379711151123,0,1,,,,,,1,1,1,48.0168647766113,0,48.0159004211426,,,,,,,,,,,,,,,,,,,,,,,,,,,,,,,,,
,3762238951.29603,48.0312023162842,-620.0361328125,,,5,,,,31.6299982368946,,,,,0.000697774276933475,5.88789185398288E-7,-0.278344593616765,0.000672507740258621,0.000697663247110453,5.8869549727992E-7,0.000697655014542751,3.55713639755553E-7,-3.38925538351624E-6,4.69073762866256E-7,1.00015914529464,10.005763053894,2,20,10,3,2.28344433731389,0.190773348307045,0.0413267537951469,172.859115600586,48.0267524719238,48.0314178466797,-620.0361328125,-620.0361328125,,,24.3777713775635,0,1,,,,,,1,1,1,48.0313949584961,0,48.0298149108887,,,,,,,,,,,,,,,,,,,,,,,,,,,,,,,,,
,3762238976.18302,48.0131797790527,-640.120361328125,,,5,,,,31.6299982368946,,,,,0.000489678994693264,5.10770119082042E-7,-0.354738876387316,0.000763268168448745,0.000489601256138066,5.10689032224068E-7,0.000489591872236409,3.48131626867326E-7,-3.03127894136749E-6,3.73641081799986E-7,1.00015877932138,10.005763053894,2,20,1,3,1.60263422250335,0.131777321267306,0.0413267537951469,172.859115600586,48.007625579834,48.0178909301758,-640.120361328125,-640.120361328125,,,24.3601779937744,0,1,,,,,,1,1,1,48.0114593505859,0,48.011741910662,,,,,,,,,,,,,,,,,,,,,,,,,,,,,,,,,
,3762238999.95789,48.004732131958,-660.143859863281,,,5,,,,31.6299982368946,,,,,0.000276375009718261,6.12076839255666E-7,-0.657544326680402,0.0015164898447695,0.00027633108238116,6.11979555113815E-7,0.000276312885381747,4.45978389865118E-7,-3.17119251343137E-6,4.19073086287606E-7,1.00015896632663,10.005763053894,2,20,1,3,0.904906807976403,0.069613169686641,0.0413267537951469,172.859115600586,48.0019607543945,48.0065879821777,-660.143859863281,-660.143859863281,,,24.2965316772461,0,1,,,,,,1,1,1,48.0040473937988,0,48.0035369873047,,,,,,,,,,,,,,,,,,,,,,,,,,,,,,,,,
,3762239021.64952,48.0170612335205,-680.094482421875,,,5,,,,31.6299982368946,,,,,0.000157434142680882,5.6327721619556E-7,-1.33140520793763,0.00269749710044843,0.000157409103345774,5.63187628976838E-7,0.000157366606612718,3.70204364855314E-7,-3.65744983817054E-6,4.24416109113009E-7,1.00015907170917,10.005763053894,2,20,1,3,0.515901015987326,0.0336003110775516,0.0413267537951469,172.859115600586,48.0154838562012,48.0174407958984,-680.094482421875,-680.094482421875,,,24.2946949005127,0,1,,,,,,1,1,1,48.0174369812012,0,48.0167499542236,,,,,,,,,,,,,,,,,,,,,,,,,,,,,,,,,
,3762239043.59107,48.0104026794434,-700.032958984375,,,5,,,,31.6299982368946,,,,,0.000102328399367666,6.1020697955832E-7,-3.0740845720649,0.00331692451168626,0.00010231213210625,6.10109974264426E-7,0.000102164907868789,5.06096735629768E-7,-5.48670905812422E-6,3.40734904114374E-7,1.00015899640718,10.005763053894,2,20,1,3,0.335832228240102,0.0116390043056019,0.0413267537951469,172.859115600586,48.0061187744141,48.0119171142578,-700.032958984375,-700.032958984375,,,24.277006149292,0,1,,,,,,1,1,1,48.0097732543945,0,48.0087072199041,,,,,,,,,,,,,,,,,,,,,,,,,,,,,,,,,
,3762239066.60131,48.0228023529053,-720.1171875,,,5,,,,31.6299982368946,,,,,6.63895104812463E-5,7.73615268020083E-7,-4.24678027388621,0.00840034767931732,6.63789492572252E-5,7.73492201528216E-7,6.61966957649808E-5,5.36231394123021E-7,-4.91552380645768E-6,5.57446031272846E-7,1.00015910501958,10.005763053894,2,20,1,3,0.217993121708198,0.00309513335112092,0.0413267537951469,172.859115600586,48.0182991027832,48.0230331420898,-720.1171875,-720.1171875,,,24.2295989990234,0,1,,,,,,1,1,1,48.0225715637207,0,48.021097946167,,,,,,,,,,,,,,,,,,,,,,,,,,,,,,,,,
,3762239088.00965,48.0111122131348,-740.079956054687,,,5,,,,31.6299982368946,,,,,4.90819330469692E-5,1.08825703806966E-6,-6.05860101233626,0.0132928464385411,4.90741344725424E-5,1.0880841261043E-6,4.8800029202698E-5,8.69422260358607E-7,-5.17955828666859E-6,6.54241544594261E-7,1.00015891415122,10.005763053894,2,20,1,3,0.16115479039795,-0.00280494744743409,0.0413267537951469,172.859115600586,48.006290435791,48.013599395752,-740.079956054687,-740.079956054687,,,24.2273731231689,0,1,,,,,,1,1,1,48.0099105834961,0,48.0094278508967,,,,,,,,,,,,,,,,,,,,,,,,,,,,,,,,,
,3762239110.25235,48.0001010894775,-760.17626953125,,,5,,,,31.6299982368946,,,,,3.99234450594625E-5,8.70028642161446E-7,-7.5449033606015,0.0159644681389071,3.99170988864124E-5,8.69890343667578E-7,3.95715071038694E-5,5.9240953249847E-7,-5.24124117323793E-6,6.36993057898625E-7,1.00015898382466,10.005763053894,2,20,1,3,0.130980878784635,-0.00567802849615565,0.0413267537951469,172.859115600586,47.9971656799316,48.0011291503906,-760.17626953125,-760.17626953125,,,24.2099075317383,0,1,,,,,,1,1,1,47.9993095397949,0,47.9988040924072,,,,,,,,,,,,,,,,,,,,,,,,,,,,,,,,,
,3762239131.9555,47.9993553161621,-780.041931152344,,,5,,,,31.6299982368946,,,,,3.48236408616735E-5,9.09520447913757E-7,-9.32943152306152,0.0188727474495209,3.48181025403237E-5,9.0937579857813E-7,3.43575486672382E-5,6.28728073435932E-7,-5.64438783986856E-6,6.57012444869314E-7,1.00015906442183,10.005763053894,2,20,1,3,0.114040036880309,-0.00850572836302087,0.0413267537951469,172.859115600586,47.9987716674805,48.0016555786133,-780.041931152344,-780.041931152344,,,24.1927223205566,0,1,,,,,,1,1,1,47.9995193481445,0,47.9998023986816,,,,,,,,,,,,,,,,,,,,,,,,,,,,,,,,,
,3762239153.82828,48.0258846282959,-800.126098632813,,,5,,,,31.6299982368946,,,,,3.20227040620371E-5,8.65770341381371E-7,-11.2379279782882,0.0190046951312307,3.20176090562018E-5,8.65632592085346E-7,3.14037150581129E-5,6.15881790172338E-7,-6.2397091458358E-6,6.08283983855002E-7,1.00015913136507,10.005763053894,2,20,1,3,0.104549206118107,-0.0113074711309808,0.0413267537951469,172.859115600586,48.023494720459,48.0264739990234,-800.126098632813,-800.126098632813,,,24.1453151702881,0,1,,,,,,1,1,1,48.0264739990234,0,48.0251384735107,,,,,,,,,,,,,,,,,,,,,,,,,,,,,,,,,
,3762239175.47505,48.0297451019287,-820.210388183594,,,5,,,,31.6299982368946,,,,,2.91516674636706E-5,8.54905365759619E-7,-12.1888953797092,0.0176651860656723,2.91470341384566E-5,8.54769488297662E-7,2.84899676875831E-5,6.8378081239241E-7,-6.15396946927951E-6,5.12908060697649E-7,1.00015896386548,10.005763053894,2,20,1,3,0.0949920694310285,-0.0118698448795357,0.0413267537951469,172.859115600586,48.0230751037598,48.0310401916504,-820.210388183594,-820.210388183594,,,24.1126976013184,0,1,,,,,,1,1,1,48.0291900634766,0,48.0273727416992,,,,,,,,,,,,,,,,,,,,,,,,,,,,,,,,,
,3762239197.39495,48.0348625183105,-840.015319824219,,,5,,,,31.6299982368946,,,,,2.69236074974768E-5,9.12100208694477E-7,-12.9539424091072,0.0201633240655709,2.69193281688E-5,9.1195523642137E-7,2.62342468355656E-5,7.35290021112871E-7,-6.03444463311796E-6,5.39454296570331E-7,1.00015896862841,10.005763053894,2,20,1,3,0.0875779403919922,-0.0121312239926352,0.0413267537951469,172.859115600586,48.0286331176758,48.034984588623,-840.015319824219,-840.015319824219,,,24.0650959014893,0,1,,,,,,1,1,1,48.034740447998,0,48.0328369140625,,,,,,,,,,,,,,,,,,,,,,,,,,,,,,,,,
,3762239219.0555,48.0224914550781,-860.06298828125,,,5,,,,31.6299982368946,,,,,2.4681729195966E-5,8.86016590833229E-7,-12.6140358906046,0.0235421892040678,2.46778060156481E-5,8.85875757797466E-7,2.40821650562644E-5,6.69994191624638E-7,-5.38919622474415E-6,5.79554692365166E-7,1.0001589760579,10.005763053894,2,20,1,3,0.0803503246817017,-0.0106428778899421,0.0413267537951469,172.859115600586,48.01611328125,48.0243110656738,-860.06298828125,-860.06298828125,,,24.0630302429199,0,1,,,,,,1,1,1,48.021671295166,0,48.0202453613281,,,,,,,,,,,,,,,,,,,,,,,,,,,,,,,,,
,3762239241.02736,48.0085525512695,-880.159423828125,,,5,,,,31.6299982368946,,,,,2.60982970131029E-5,8.9156371103333E-7,-14.5683608878296,0.0261649412327922,2.60941503466359E-5,8.91422053616304E-7,2.52551768953527E-5,5.71605873069486E-7,-6.56359065582903E-6,6.84032165578475E-7,1.00015891172588,10.005763053894,2,20,1,3,0.0845290494706383,-0.0141427923983573,0.0413267537951469,172.859115600586,48.0052795410156,48.0097007751465,-880.159423828125,-880.159423828125,,,24.0151882171631,0,1,,,,,,1,1,1,48.0080680847168,0,48.0071660822088,,,,,,,,,,,,,,,,,,,,,,,,,,,,,,,,,
,3762239264.20674,48.0034561157227,-899.782165527344,,,5,,,,31.6299982368946,,,,,2.47935668912786E-5,9.18877701573274E-7,-14.7645783603458,0.0255305993285164,2.47896276230483E-5,9.18731707826057E-7,2.3971102046757E-5,6.6787616499227E-7,-6.31758690904726E-6,6.30879845295601E-7,1.00015890792271,10.005763053894,2,20,1,3,0.0802570428002195,-0.0137090081567649,0.0413267537951469,172.859115600586,48.0010604858398,48.0048713684082,-899.782165527344,-899.782165527344,,,24.013256072998,0,1,,,,,,1,1,1,48.0031242370605,0,48.0025107643821,,,,,,,,,,,,,,,,,,,,,,,,,,,,,,,,,
,3762239287.0695,48.0018119812012,-919.672058105469,,,5,,,,31.6299982368946,,,,,2.36399301842089E-5,9.55700947945151E-7,-14.4994879642571,0.025886291364152,2.36361732758865E-5,9.5554906590417E-7,2.28833582713761E-5,7.37400602767858E-7,-5.9178206589567E-6,6.0771240598488E-7,1.00015894740145,10.005763053894,2,20,1,3,0.0765826775473612,-0.0127153263623527,0.0413267537951469,172.859115600586,48.0009765625,48.0025291442871,-919.672058105469,-919.672058105469,,,23.9659881591797,0,1,,,,,,1,1,1,48.0015487670898,0,48.0015622919256,,,,,,,,,,,,,,,,,,,,,,,,,,,,,,,,,
,3762239310.11396,48.0299873352051,-939.744201660156,,,5,,,,31.6299982368946,,,,,2.26053935119645E-5,7.76528410292716E-7,-14.7479145983517,0.0236577706013802,2.26017977990861E-5,7.76404892283446E-7,2.18571862051464E-5,5.64537957474502E-7,-5.75366621766778E-6,5.33011680296207E-7,1.00015908968439,10.005763053894,2,20,1,3,0.0731781467122018,-0.01247472292425,0.0413267537951469,172.859115600586,48.0259666442871,48.0303649902344,-939.744201660156,-939.744201660156,,,23.9631958007813,0,1,,,,,,1,1,1,48.0305061340332,0,48.0287342071533,,,,,,,,,,,,,,,,,,,,,,,,,,,,,,,,,
,3762239331.79193,48.021017074585,-959.755554199219,,,5,,,,31.6299982368946,,,,,2.23893046696984E-5,1.09673176733662E-6,-16.6632209463818,0.0343665294149412,2.23857473824861E-5,1.09655751494474E-6,2.14456972907432E-5,7.84866969720294E-7,-6.41901500125145E-6,7.65782099179573E-7,1.0001589085748,10.005763053894,2,20,1,3,0.072025540974285,-0.0147694332182392,0.0413267537951469,172.859115600586,48.0157203674316,48.0221099853516,-959.755554199219,-959.755554199219,,,23.9312400817871,0,1,,,,,,1,1,1,48.0203399658203,0,48.0188854217529,,,,,,,,,,,,,,,,,,,,,,,,,,,,,,,,,
,3762239353.69998,48.0111026763916,-979.693969726563,,,5,,,,31.6299982368946,,,,,2.29730796196732E-5,8.70230203152045E-7,-16.8425474552751,0.0238492116499154,2.29694294623122E-5,8.70091933610724E-7,2.19841466105119E-5,6.83094188977151E-7,-6.65522258317902E-6,5.38926991270707E-7,1.00015891371472,10.005763053894,2,20,1,3,0.073856098208641,-0.0153841949774503,0.0413267537951469,172.859115600586,48.0071411132812,48.0126953125,-979.693969726563,-979.693969726563,,,23.9143581390381,0,1,,,,,,1,1,1,48.0103759765625,0,48.0095893859863,,,,,,,,,,,,,,,,,,,,,,,,,,,,,,,,,
,3762239375.32386,48.0220279693604,-999.705322265625,,,5,,,,31.6299982368946,,,,,2.25444958773968E-5,1.05811477739931E-6,-17.1580625784486,0.0316530511447353,2.25409103043595E-5,1.05794649030002E-6,2.1537716915395E-5,7.87355266772009E-7,-6.64976596742236E-6,7.0662752580445E-7,1.00015906957567,10.005763053894,2,20,1,3,0.0723943808017452,-0.0154945427132687,0.0413267537951469,172.859115600586,48.0181083679199,48.0224609375,-999.705322265625,-999.705322265625,,,23.8816604614258,0,1,,,,,,1,1,1,48.0220718383789,0,48.0208625793457,,,,,,,,,,,,,,,,,,,,,,,,,,,,,,,,,