File: Experimental_Data/AC_Suceptibillity_FieldScans/ZFCd_Up_56K.dat
[Header]
; MPMS3 Data File (default extension .dat)
; Copyright (c) 2007, Quantum Design, Inc. All rights reserved.
TITLE,ZFCd_Up_56K
FILEOPENTIME,3762233898.97592,03/20/2019,8:58 am
BYAPP,SQUID AC,0.9.1.0
INFO,MPMS3 Measurement Release 1.1.16 Build 347, MultiVu Release 2.3.3.2,APPNAME
INFO,0,MOMENT_UNITS
INFO,SrM,SAMPLE_MATERIAL
INFO,MvsH,SAMPLE_COMMENT
INFO,,SAMPLE_MASS
INFO,,SAMPLE_VOLUME
INFO,,SAMPLE_MOLECULAR_WEIGHT
INFO,,SAMPLE_SIZE
INFO,,SAMPLE_SHAPE
INFO,Quartz,SAMPLE_HOLDER
INFO,Standard,SAMPLE_HOLDER_DETAIL
INFO,65.34,SAMPLE_OFFSET
DATATYPE,COMMENT,1
DATATYPE,TIME,2
STARTUPAXIS,X,2
STARTUPAXIS,Y1,5
FIELDGROUP, VSM,2,3,4,5,6,8,9,10,11,14,15
FIELDGROUP, DC, 2,3,4,14,56,57,58,59,60,61,62,63,64,65,66,67,68,69
FIELDGROUP, AC, 2,3,4,11,16,17,18,19,20,21,22,23,24,25,26,27,28,29,30
STARTUPGROUP, All
[Data]
Comment,Time Stamp (sec),Temperature (K),Magnetic Field (Oe),Moment (emu),M. Std. Err. (emu),Transport Action,Averaging Time (sec),Frequency (Hz),Peak Amplitude (mm),Center Position (mm),Lockin Signal' (V),Lockin Signal (V),Range,M. Quad. Signal (emu),AC Moment (emu),AC M. Std Err. (emu),AC Phase (deg),AC Phase Std. Err. (deg),AC Susceptibility (emu/Oe),AC Suscept. Std Err. (emu/Oe),AC X' (emu/Oe),AC X' Std Err. (emu/Oe),AC X'' (emu/Oe),AC X'' Std Err. (emu/Oe),AC Drive (Oe),AC Frequency (Hz),AC Averaging Time (sec),AC Cycles,AC Range,AC Measure Type,AC Signal' (V),AC Signal'' (V),AC Trim Coil Ratio,AC Trim Coil Phase,Min. Temperature (K),Max. Temperature (K),Min. Field (Oe),Max. Field (Oe),Mass (grams),Motor Lag (deg),Pressure (Torr),Measure Count,Measurement Number,SQUID Status (code),Motor Status (code),Measure Status (code),Motor Current (amps),Motor Temp. (C),Temp. Status (code),Field Status (code),Chamber Status (code),Chamber Temp (K),Redirection State,Average Temp (K),Rotation Angle (deg),Rotator state,DC Moment Fixed Ctr (emu),DC Moment Err Fixed Ctr (emu),DC Moment Free Ctr (emu),DC Moment Err Free Ctr (emu),DC Fixed Fit,DC Free Fit,DC Calculated Center (mm),DC Calculated Center Err (mm),DC Scan Length (mm),DC Scan Time (s),DC Number of Points,DC Squid Drift,DC Min V (V),DC Max V (V),DC Scans per Measure,Map 01,Map 02,Map 03,Map 04,Map 05,Map 06,Map 07,Map 08,Map 09,Map 10,Map 11,Map 12,Map 13,Map 14,Map 15,Map 16
,3762234033.50735,55.9657535552978,0.339998662471771,,,5,,,,31.6299982368946,,,,,0.000577056064096518,2.42292941752042E-8,0.0132696042786486,1.33074281692403E-5,0.000576965354110714,2.42254854656742E-8,0.000576965338637148,2.29797928443152E-8,1.33624185379112E-7,7.66832881923744E-9,1.00015721912097,10.005763053894,2,20,1,3,1.88765030856351,0.166104171688762,0.0413267537951469,172.859115600586,55.937084197998,55.974552154541,0.339998662471771,0.339998662471771,,,24.7947807312012,0,1,,,,,,1,1,1,55.9616165161133,0,55.9537329240279,,,,,,,,,,,,,,,,,,,,,,,,,,,,,,,,,
,3762234056.58573,55.9176807403564,20.0963497161865,,,5,,,,31.6299982368946,,,,,0.000579319871477489,4.77236740308629E-8,0.0322545922555015,2.43990237605189E-5,0.00057922861712588,4.77161566071657E-8,0.00057922852534381,4.55828975578503E-8,3.26076057260896E-7,1.41078365311657E-8,1.00015754461867,10.005763053894,2,20,1,3,1.89499775077856,0.167423883437345,0.0413267537951469,172.859115600586,55.908519744873,55.9211044311523,20.0963497161865,20.0963497161865,,,24.8452339172363,0,1,,,,,,1,1,1,55.9162902832031,0,55.9138999938965,,,,,,,,,,,,,,,,,,,,,,,,,,,,,,,,,
,3762234078.21697,55.9001960754395,40.0348434448242,,,5,,,,31.6299982368946,,,,,0.000616046353635862,1.54939612038506E-7,0.501964289672717,8.10291975819352E-5,0.000615949241346353,1.54915187674379E-7,0.000615925603248268,1.46786897219761E-7,5.39621889891183E-6,4.95209266551366E-8,1.00015766281211,10.005763053894,2,20,1,3,2.0136024790994,0.194594731338088,0.0413267537951469,172.859115600586,55.8984794616699,55.9009819030762,40.0348434448242,40.0348434448242,,,24.8779754638672,0,1,,,,,,1,1,1,55.8997077941895,0,55.8997695922852,,,,,,,,,,,,,,,,,,,,,,,,,,,,,,,,,
,3762234102.04814,55.9235057830811,60.009765625,,,5,,,,31.6299982368946,,,,,0.000699209354759791,1.30736126421773E-7,0.850210535638557,5.15670237359881E-5,0.000699098868696794,1.30715468059865E-7,0.000699021901027711,1.25839490664064E-7,1.03735286543309E-5,3.53688588947753E-8,1.00015804068343,10.005763053894,2,20,10,3,2.28403980231315,0.234799538318464,0.0413267537951469,172.859115600586,55.9155769348145,55.940357208252,60.009765625,60.009765625,,,24.9101676940918,0,1,,,,,,1,1,1,55.9270362854004,0,55.9287223815918,,,,,,,,,,,,,,,,,,,,,,,,,,,,,,,,,
,3762234128.27374,55.9651107788086,80.1061096191406,,,5,,,,31.6299982368946,,,,,0.000775673934900293,2.45735675160163E-7,0.757261848561376,0.000205002095274166,0.000775551581107385,2.45696913135869E-7,0.000775483844840219,1.8742720436317E-7,1.02499439020658E-5,1.58864773279357E-7,1.00015776357871,10.005763053894,2,20,10,3,2.53423441949699,0.256420458818826,0.0413267537951469,172.859115600586,55.9627494812012,55.9662590026855,80.1061096191406,80.1061096191406,,,24.9104423522949,0,1,,,,,,1,1,1,55.9656600952148,0,55.965311570601,,,,,,,,,,,,,,,,,,,,,,,,,,,,,,,,,
,3762234151.3169,55.9868507385254,100.09317779541,,,5,,,,31.6299982368946,,,,,0.000818230980821244,3.36750240479967E-7,1.5290954076148,0.000210184299291183,0.000818101945444506,3.36697134822561E-7,0.00081781062191964,2.90095391118003E-7,2.18307080851271E-5,1.70908234587496E-7,1.0001577253024,10.005763053894,2,20,10,3,2.66938292685526,0.306532089414444,0.0413267537951469,172.859115600586,55.9854927062988,55.9932556152344,100.09317779541,100.09317779541,,,24.8781757354736,0,1,,,,,,1,1,1,55.9873046875,0,55.988854598999,,,,,,,,,,,,,,,,,,,,,,,,,,,,,,,,,
,3762234172.96873,56.0231227874756,120.007377624512,,,5,,,,31.6299982368946,,,,,0.000722171182195431,1.38397364689969E-7,2.17136710907622,6.08419459229482E-5,0.000722057174547667,1.3837551618868E-7,0.000721538719797378,1.31767056479503E-7,2.73576159217376E-5,4.2251938502408E-8,1.00015789282592,10.005763053894,2,20,10,3,2.35281334635685,0.296988141257197,0.0413267537951469,172.859115600586,56.0199546813965,56.0255813598633,120.007377624512,120.007377624512,,,24.8616142272949,0,1,,,,,,1,1,1,56.0245056152344,0,56.0240688323975,,,,,,,,,,,,,,,,,,,,,,,,,,,,,,,,,
,3762234194.82585,56.0184001922607,140.043014526367,,,5,,,,31.6299982368946,,,,,0.000648922186041387,6.22258088649058E-8,0.848233142051416,7.58572022471108E-5,0.000648819956686881,6.22160059880575E-8,0.000648748856379,3.80305148966627E-8,9.60507897446674E-6,4.92393271461006E-8,1.0001575619761,10.005763053894,2,20,10,3,2.11976516126784,0.218021021472334,0.0413267537951469,172.859115600586,56.0133972167969,56.0199928283691,140.043014526367,140.043014526367,,,24.8595752716064,0,1,,,,,,1,1,1,56.0174446105957,0,56.0165802001953,,,,,,,,,,,,,,,,,,,,,,,,,,,,,,,,,
,3762234216.48595,56.0101089477539,160.127227783203,,,5,,,,31.6299982368946,,,,,0.000633842394845833,1.59446890603106E-7,0.141121132952224,8.92282242358556E-5,0.000633742490592181,1.59421759083453E-7,0.000633740568290902,1.49104298280761E-7,1.5609241833618E-6,5.64199034336664E-8,1.00015764171589,10.005763053894,2,20,10,3,2.07297315940828,0.187430607126853,0.0413267537951469,172.859115600586,56.0067863464355,56.010913848877,160.127227783203,160.127227783203,,,24.858247756958,0,1,,,,,,1,1,1,56.0098762512207,0,56.0087524414063,,,,,,,,,,,,,,,,,,,,,,,,,,,,,,,,,
,3762234238.41819,56.0060939788818,179.944290161133,,,5,,,,31.6299982368946,,,,,0.000647033726781055,1.2146732516841E-7,0.0318400422596623,9.42434376176137E-5,0.000646931713695347,1.21448174301708E-7,0.000646931613803409,1.05051843867223E-7,3.59508714569186E-7,6.09407018446187E-8,1.00015768756354,10.005763053894,2,20,10,3,2.11647351044468,0.187339809614176,0.0413267537951469,172.859115600586,56.0043716430664,56.0062484741211,179.944290161133,179.944290161133,,,24.8097267150879,0,1,,,,,,1,1,1,56.0061302185059,0,56.005448774858,,,,,,,,,,,,,,,,,,,,,,,,,,,,,,,,,
,3762234261.46119,56.0121040344238,200.052780151367,,,5,,,,31.6299982368946,,,,,0.000679561357946476,1.1187142468773E-7,0.0961519759512317,7.47811162344151E-5,0.000679454263571622,1.11853794491206E-7,0.000679453306815405,9.96713814127702E-8,1.14023824968318E-6,5.07630482669338E-8,1.0001576182248,10.005763053894,2,20,10,3,2.22264741445335,0.199300514611944,0.0413267537951469,172.859115600586,56.0111656188965,56.0121688842773,200.052780151367,200.052780151367,,,24.7767791748047,0,1,,,,,,1,1,1,56.0121040344238,0,56.0118089155717,,,,,,,,,,,,,,,,,,,,,,,,,,,,,,,,,
,3762234283.10456,56.0074672698975,220.051986694336,,,5,,,,31.6299982368946,,,,,0.000733505230208101,1.86531871968821E-7,0.546927790396899,0.000143360436735974,0.000733389621878132,1.86502472535367E-7,0.000733356208823235,1.54144048857124E-7,7.00060418541491E-6,1.0498944929724E-7,1.00015763562303,10.005763053894,2,20,10,3,2.39731174568246,0.234040391740706,0.0413267537951469,172.859115600586,56.005313873291,56.0077476501465,220.051986694336,220.051986694336,,,24.7748641967773,0,1,,,,,,1,1,1,56.007495880127,0,56.0066432952881,,,,,,,,,,,,,,,,,,,,,,,,,,,,,,,,,
,3762234305.00067,56.0189666748047,240.111907958984,,,5,,,,31.6299982368946,,,,,0.000830533721469375,1.23797185805637E-7,2.01225183586073,0.000107872014901892,0.000830402764737468,1.23777665737453E-7,0.000829890689765078,8.54299491075126E-8,2.91580987870448E-5,8.95691594852847E-8,1.00015770266847,10.005763053894,2,20,10,3,2.7067596477475,0.334384093509823,0.0413267537951469,172.859115600586,56.0176811218262,56.0192337036133,240.111907958984,240.111907958984,,,24.7421531677246,0,1,,,,,,1,1,1,56.0192108154297,0,56.0185917941007,,,,,,,,,,,,,,,,,,,,,,,,,,,,,,,,,
,3762234328.05738,56.0315895080566,260.026092529297,,,5,,,,31.6299982368946,,,,,0.000781973312978264,1.23754556455554E-7,0.247008599359392,8.98425601975703E-5,0.000781850010274242,1.23735042654772E-7,0.000781842744671321,1.01899715502991E-7,3.3706335678768E-6,7.01912299449714E-8,1.0001577063406,10.005763053894,2,20,10,3,2.55698354016432,0.236233030962014,0.0413267537951469,172.859115600586,56.0274505615234,56.0318069458008,260.026092529297,260.026092529297,,,24.7088947296143,0,1,,,,,,1,1,1,56.0318069458008,0,56.0302890430797,,,,,,,,,,,,,,,,,,,,,,,,,,,,,,,,,
,3762234351.1678,56.050121307373,280.001037597656,,,5,,,,31.6299982368946,,,,,0.000745374338551927,1.69520080977449E-7,0.040055514998528,0.000102684048994547,0.000745256859206606,1.6949336271375E-7,0.00074525667708757,1.51260147856212E-7,5.21009490119008E-7,7.64746211140135E-8,1.00015763604705,10.005763053894,2,20,10,3,2.43810230644569,0.216423571160122,0.0413267537951469,172.859115600586,56.0445213317871,56.050350189209,280.001037597656,280.001037597656,,,24.6911678314209,0,1,,,,,,1,1,1,56.0498924255371,0,56.048205947876,,,,,,,,,,,,,,,,,,,,,,,,,,,,,,,,,
,3762234372.75035,56.0507106781006,300.085235595703,,,5,,,,31.6299982368946,,,,,0.000690700060316856,1.8805977501347E-7,0.024964823309876,0.000129173268069128,0.000690591179630802,1.88030129616721E-7,0.000690591114076265,1.65547390187751E-7,3.00903249416236E-7,8.91593587107123E-8,1.00015766301289,10.005763053894,2,20,10,3,2.2593137088412,0.200002098622371,0.0413267537951469,172.859115600586,56.0432624816895,56.0512390136719,300.085235595703,300.085235595703,,,24.6584529876709,0,1,,,,,,1,1,1,56.0503082275391,0,56.0480449676514,,,,,,,,,,,,,,,,,,,,,,,,,,,,,,,,,
,3762234394.74065,56.067533493042,320.145141601562,,,5,,,,31.6299982368946,,,,,0.000604071214348113,1.68444677149753E-7,0.0382996603787049,0.000176743910130306,0.000603975940722888,1.6841811019099E-7,0.000603975805784907,1.30285098793254E-7,4.03730813691447E-7,1.06726064636228E-7,1.00015774407356,10.005763053894,2,20,10,3,1.9759030915359,0.175419731347342,0.0413267537951469,172.859115600586,56.0594596862793,56.067684173584,320.145141601562,320.145141601562,,,24.6253509521484,0,1,,,,,,1,1,1,56.0675582885742,0,56.0651168823242,,,,,,,,,,,,,,,,,,,,,,,,,,,,,,,,,
,3762234416.34096,56.0638618469238,339.986511230469,,,5,,,,31.6299982368946,,,,,0.000510721580017259,3.04141338834999E-7,0.0241294859518151,0.000466220056376758,0.000510641115190705,3.04093420984972E-7,0.000510641069907553,1.89214643012434E-7,2.15050870341684E-7,2.38055933671103E-7,1.00015757608261,10.005763053894,2,20,10,3,1.67059298833675,0.147933715252352,0.0413267537951469,172.859115600586,56.0523452758789,56.0651664733887,339.986511230469,339.986511230469,,,24.6081962585449,0,1,,,,,,1,1,1,56.062931060791,0,56.0596279144287,,,,,,,,,,,,,,,,,,,,,,,,,,,,,,,,,
,3762234441.42972,56.0609970092773,360.095031738281,,,5,,,,31.6299982368946,,,,,0.000409647162605697,3.74248768970327E-7,0.00286339285517645,0.000430049905377214,0.000409582628856811,3.74189811705924E-7,0.000409582628345332,3.30181325245626E-7,2.04691511757338E-8,1.7606336258165E-7,1.00015755977998,10.005763053894,2,20,1,3,1.34001623224304,0.118188361321386,0.0413267537951469,172.859115600586,56.0421371459961,56.0634346008301,360.095031738281,360.095031738281,,,24.5600490570068,0,1,,,,,,1,1,1,56.0597076416016,0,56.0551324732163,,,,,,,,,,,,,,,,,,,,,,,,,,,,,,,,,
,3762234472.17743,56.0684623718262,380.082061767578,,,5,,,,31.6299982368946,,,,,0.000280212171799221,2.98113684844072E-7,-0.0147055696642466,0.00080828227561947,0.000280167965056124,2.98066653928195E-7,0.000280167955828138,1.93833854895814E-7,-7.19080797504127E-8,2.26433581608777E-7,1.00015778657309,10.005763053894,2,20,1,3,0.916638838805562,0.0805832664879756,0.0413267537951469,172.859115600586,56.0449333190918,56.0691528320313,380.082061767578,380.082061767578,,,24.5263214111328,0,1,,,,,,1,1,1,56.0678215026855,0,56.0601439225046,,,,,,,,,,,,,,,,,,,,,,,,,,,,,,,,,
,3762234502.39338,56.0279121398926,400.020568847656,,,5,,,,31.6299982368946,,,,,0.000197475613988657,2.70312838301266E-7,-0.0320455103209447,0.000519236522137608,0.000197444508958313,2.70270260441306E-7,0.000197444478076401,2.50090639508266E-7,-1.10430642074034E-7,1.02472853524034E-7,1.00015753808758,10.005763053894,2,20,1,3,0.646004723422509,0.0566082414253296,0.0413267537951469,172.859115600586,56.0179595947266,56.0311431884766,400.020568847656,400.020568847656,,,24.4925308227539,0,1,,,,,,1,1,1,56.0264167785645,0,56.0235246930804,,,,,,,,,,,,,,,,,,,,,,,,,,,,,,,,,
,3762234528.8597,56.0121326446533,420.080474853516,,,5,,,,31.6299982368946,,,,,0.000134129880102165,3.92181690131818E-7,-0.0849337859712911,0.00123887372741817,0.000134108741944779,3.92119884378441E-7,0.000134108594597298,3.55186295209087E-7,-1.98799267771944E-7,1.66134582253681E-7,1.00015761953382,10.005763053894,2,20,1,3,0.438815675421888,0.0380539752298147,0.0413267537951469,172.859115600586,56.0071792602539,56.0137214660645,420.080474853516,420.080474853516,,,24.4439029693604,0,1,,,,,,1,1,1,56.0113716125488,0,56.0100975036621,,,,,,,,,,,,,,,,,,,,,,,,,,,,,,,,,
,3762234554.87419,56.0031242370605,440.128265380859,,,5,,,,31.6299982368946,,,,,0.00011336245527214,5.78151870142834E-7,0.0325134763824568,0.00122478435921111,0.000113344584632666,5.78060729353694E-7,0.00011334456638311,5.61241200292993E-7,6.43193322277187E-8,1.38428761153903E-7,1.00015766646048,10.005763053894,2,20,1,3,0.370806326064144,0.0329301745923718,0.0413267537951469,172.859115600586,56.0029525756836,56.0035171508789,440.128265380859,440.128265380859,,,24.4260368347168,0,1,,,,,,1,1,1,56.0030784606934,0,56.0031749725342,,,,,,,,,,,,,,,,,,,,,,,,,,,,,,,,,
,3762234576.7043,56.0074882507324,460.394622802734,,,5,,,,31.6299982368946,,,,,0.000102887413951199,5.21713688823841E-7,-0.0949230011989632,0.00144754864783345,0.000102871197687108,5.21631460622814E-7,0.000102871056510951,4.99915182434312E-7,-1.70428580209949E-7,1.48943583558199E-7,1.00015763658298,10.005763053894,2,20,1,3,0.336607875727072,0.0291460170636244,0.0413267537951469,172.859115600586,56.0062866210937,56.0075454711914,460.394622802734,460.394622802734,,,24.3778877258301,0,1,,,,,,1,1,1,56.0074310302734,0,56.0069942474365,,,,,,,,,,,,,,,,,,,,,,,,,,,,,,,,,
,3762234598.31246,56.0407161712646,480.320983886719,,,5,,,,31.6299982368946,,,,,9.72811982037353E-5,5.2109776300824E-7,-0.241853317970088,0.0020623468350399,9.72658516368348E-5,5.21015557383419E-7,9.72649850968882E-5,4.80754748385037E-7,-4.1057123726926E-7,2.00828491357165E-7,1.00015777959728,10.005763053894,2,20,1,3,0.318335733951317,0.0267484030036303,0.0413267537951469,172.859115600586,56.0347633361816,56.0420722961426,480.320983886719,480.320983886719,,,24.3753566741943,0,1,,,,,,1,1,1,56.0415153503418,0,56.0393667954665,,,,,,,,,,,,,,,,,,,,,,,,,,,,,,,,,
,3762234625.33399,56.0344505310059,500.2958984375,,,5,,,,31.6299982368946,,,,,8.97640921707261E-5,5.30730277004377E-7,-0.239488767689203,0.00163856233486039,8.9749946888448E-5,5.30646643009978E-7,8.97491628658041E-5,5.0974357624923E-7,-3.75141795345259E-7,1.47469814573712E-7,1.00015760769525,10.005763053894,2,20,1,3,0.293735933446297,0.024699906020293,0.0413267537951469,172.859115600586,56.026985168457,56.0362968444824,500.2958984375,500.2958984375,,,24.3270893096924,0,1,,,,,,1,1,1,56.0334587097168,0,56.0319606781006,,,,,,,,,,,,,,,,,,,,,,,,,,,,,,,,,
,3762234647.17278,56.0163860321045,520.367919921875,,,5,,,,31.6299982368946,,,,,8.3709111589934E-5,6.64628244805985E-7,-0.332058881911403,0.0032825253252353,8.36959224019347E-5,6.64523526135533E-7,8.36945168139811E-5,6.04889654584979E-7,-4.85058743768181E-7,2.75136370848471E-7,1.00015758459458,10.005763053894,2,20,1,3,0.273958684519774,0.0225970859095702,0.0413267537951469,172.859115600586,56.0123558044434,56.0178031921387,520.367919921875,520.367919921875,,,24.3099365234375,0,1,,,,,,1,1,1,56.0155715942383,0,56.0148143768311,,,,,,,,,,,,,,,,,,,,,,,,,,,,,,,,,
,3762234668.83877,56.0080966949463,540.440002441406,,,5,,,,31.6299982368946,,,,,7.82167717874771E-5,5.92350423923691E-7,-0.374484384896616,0.00207528260463171,7.82044417294088E-5,5.92257046059112E-7,7.82027713234125E-5,5.69344607907195E-7,-5.11139458999472E-7,1.63141429605321E-7,1.00015766442155,10.005763053894,2,20,1,3,0.255998907430154,0.0209303891891971,0.0413267537951469,172.859115600586,56.0057258605957,56.0086517333984,540.440002441406,540.440002441406,,,24.2616291046143,0,1,,,,,,1,1,1,56.0079727172852,0,56.0072631835937,,,,,,,,,,,,,,,,,,,,,,,,,,,,,,,,,
,3762234690.52483,56.0037059783936,560.3056640625,,,5,,,,31.6299982368946,,,,,7.35380829277287E-5,5.6004904442785E-7,-0.332196791644205,0.00216258458159715,7.35264883095237E-5,5.59960742495195E-7,7.35252524810007E-5,5.36716315745609E-7,-4.26298880626425E-7,1.59660983174444E-7,1.00015769307731,10.005763053894,2,20,1,3,0.240670954605468,0.0198611491886283,0.0413267537951469,172.859115600586,56.003116607666,56.0041847229004,560.3056640625,560.3056640625,,,24.2290458679199,0,1,,,,,,1,1,1,56.0035781860352,0,56.003524017334,,,,,,,,,,,,,,,,,,,,,,,,,,,,,,,,,
,3762234712.38635,56.0015830993652,580.329162597656,,,5,,,,31.6299982368946,,,,,7.05429931842821E-5,5.5425786974912E-7,-0.514818281153364,0.00327544614709686,7.05318776461804E-5,5.54170534718506E-7,7.05290304644805E-5,5.03458019458119E-7,-6.33739722713619E-7,2.31592323261163E-7,1.00015759594771,10.005763053894,2,20,1,3,0.230928096826545,0.0183212299564198,0.0413267537951469,172.859115600586,56.0004577636719,56.0017890930176,580.329162597656,580.329162597656,,,24.2116680145264,0,1,,,,,,1,1,1,56.0013465881348,0,56.0010963439941,,,,,,,,,,,,,,,,,,,,,,,,,,,,,,,,,
,3762234734.15428,56.0010662078857,600.352600097656,,,5,,,,31.6299982368946,,,,,6.72955283279168E-5,5.48848959410222E-7,-0.617889600096322,0.00220681209040477,6.72849183661744E-5,5.48762426670136E-7,6.72810058149962E-5,5.27892547701602E-7,-7.25600485941756E-7,1.4989882923495E-7,1.00015768707164,10.005763053894,2,20,1,3,0.220328104026261,0.0170861997000473,0.0413267537951469,172.859115600586,56.0001106262207,56.0014038085937,600.352600097656,600.352600097656,,,24.1946067810059,0,1,,,,,,1,1,1,56.0007286071777,0,56.0007225036621,,,,,,,,,,,,,,,,,,,,,,,,,,,,,,,,,
,3762234756.11531,56.0135135650635,620.436828613281,,,5,,,,31.6299982368946,,,,,6.47897444876948E-5,5.55927025537729E-7,-0.540200696110356,0.0027110341341643,6.47795298754813E-5,5.55839379274733E-7,6.47766506903342E-5,5.27035404733881E-7,-6.10750547114385E-7,1.76610015881079E-7,1.00015768271602,10.005763053894,2,20,1,3,0.212101331996128,0.0167421509810771,0.0413267537951469,172.859115600586,56.0126876831055,56.014102935791,620.436828613281,620.436828613281,,,24.1467704772949,0,1,,,,,,1,1,1,56.0135498046875,0,56.0134349822998,,,,,,,,,,,,,,,,,,,,,,,,,,,,,,,,,
,3762234777.86723,56.022876739502,640.266052246094,,,5,,,,31.6299982368946,,,,,6.24747398196408E-5,6.12462546500268E-7,-0.602134834667947,0.00396207770416952,6.24648921031693E-5,6.12366005761967E-7,6.24614426977449E-5,5.5977065361442E-7,-6.56446172134453E-7,2.4829204651972E-7,1.00015765202084,10.005763053894,2,20,1,3,0.204539838198991,0.0159271849845593,0.0413267537951469,172.859115600586,56.020076751709,56.0231285095215,640.266052246094,640.266052246094,,,24.1289596557617,0,1,,,,,,1,1,1,56.0231323242188,0,56.0221942901611,,,,,,,,,,,,,,,,,,,,,,,,,,,,,,,,,
,3762234799.59191,56.0613803863525,660.325988769531,,,5,,,,31.6299982368946,,,,,6.23556530015599E-5,5.82209207790387E-7,-0.818110571012084,0.00423233538955715,6.23458144038099E-5,5.82117345674828E-7,6.23394589191942E-5,5.18460473984794E-7,-8.90188371302994E-7,2.64687251394868E-7,1.00015780686874,10.005763053894,2,20,1,3,0.204208214801387,0.0151315475152668,0.0413267537951469,172.859115600586,56.0561561584473,56.0619583129883,660.325988769531,660.325988769531,,,24.0966720581055,0,1,,,,,,1,1,1,56.0618858337402,0,56.0599033355713,,,,,,,,,,,,,,,,,,,,,,,,,,,,,,,,,
,3762234821.21841,56.0382556915283,680.422302246094,,,5,,,,31.6299982368946,,,,,6.01423345432395E-5,8.4278394159825E-7,-1.15733461736344,0.00344417927676678,6.01328673765108E-5,8.42651276709998E-7,6.01206003367337E-5,8.1562460321669E-7,-1.21455920883864E-6,2.11701867654978E-7,1.00015743747374,10.005763053894,2,20,1,3,0.197042605217072,0.013432328636427,0.0413267537951469,172.859115600586,56.0278739929199,56.041561126709,680.422302246094,680.422302246094,,,24.0638198852539,0,1,,,,,,1,1,1,56.0365753173828,0,56.0341930389404,,,,,,,,,,,,,,,,,,,,,,,,,,,,,,,,,
,3762234843.11121,56.0503463745117,700.312255859375,,,5,,,,31.6299982368946,,,,,5.60763257021481E-5,6.66598605977453E-7,-1.95454241791802,0.00638033058357041,5.60674868677878E-5,6.66493535707794E-7,5.60348668710643E-5,5.61549051221343E-7,-1.91227048600717E-6,3.58993448704409E-7,1.00015764634468,10.005763053894,2,20,1,3,0.183877618086739,0.0099707157661658,0.0413267537951469,172.859115600586,56.0435600280762,56.0505523681641,700.312255859375,700.312255859375,,,24.0315742492676,0,1,,,,,,1,1,1,56.0501403808594,0,56.0480048439719,,,,,,,,,,,,,,,,,,,,,,,,,,,,,,,,,
,3762234866.17746,56.0756759643555,720.311462402344,,,5,,,,31.6299982368946,,,,,5.76548579003029E-5,8.60220731114462E-7,-1.52039782590104,0.00479587763709994,5.76457696109565E-5,8.60085132221483E-7,5.76254749791487E-5,8.13023877018783E-7,-1.52950562829444E-6,2.80604009354451E-7,1.0001576575247,10.005763053894,2,20,1,3,0.188970470763704,0.0116876252416759,0.0413267537951469,172.859115600586,56.0670890808105,56.0759811401367,720.311462402344,720.311462402344,,,24.0139427185059,0,1,,,,,,1,1,1,56.0752868652344,0,56.0731589577415,,,,,,,,,,,,,,,,,,,,,,,,,,,,,,,,,
,3762234887.77469,56.0438632965088,740.383544921875,,,5,,,,31.6299982368946,,,,,5.45548596296277E-5,1.01410029960395E-6,-2.02081813455252,0.00526498260752411,5.45462767882232E-5,1.01394075630939E-6,5.4512353394624E-5,9.70215065200554E-7,-1.92344452404626E-6,2.9454810229085E-7,1.00015734972046,10.005763053894,2,20,1,3,0.178899532558123,0.00950092463121558,0.0413267537951469,172.859115600586,56.0308113098145,56.0479965209961,740.383544921875,740.383544921875,,,23.9966411590576,0,1,,,,,,1,1,1,56.0417137145996,0,56.0388877868652,,,,,,,,,,,,,,,,,,,,,,,,,,,,,,,,,
,3762234909.69686,56.0185832977295,760.45556640625,,,5,,,,31.6299982368946,,,,,5.06912667442862E-5,8.82088957953871E-7,-1.79189916562074,0.00593531370689938,5.06832863780268E-5,8.81950089990808E-7,5.06585018163528E-5,8.27435499776072E-7,-1.58483809887788E-6,3.05264565492159E-7,1.00015745558013,10.005763053894,2,20,1,3,0.166193099756147,0.00949571839206549,0.0413267537951469,172.859115600586,56.0132637023926,56.0212516784668,760.45556640625,760.45556640625,,,23.9639892578125,0,1,,,,,,1,1,1,56.017463684082,0,56.0166625976562,,,,,,,,,,,,,,,,,,,,,,,,,,,,,,,,,
,3762234931.29778,56.0512599945068,780.296875,,,5,,,,31.6299982368946,,,,,5.01282134967475E-5,8.16539142965619E-7,-1.94350250104381,0.00816572014162294,5.0120298614774E-5,8.1641021734684E-7,5.0091467133546E-5,7.05289107465669E-7,-1.69978046905914E-6,4.11209092650679E-7,1.00015791769387,10.005763053894,2,20,1,3,0.164371281642452,0.00895883496627603,0.0413267537951469,172.859115600586,56.0485305786133,56.0519790649414,780.296875,780.296875,,,23.9318675994873,0,1,,,,,,1,1,1,56.0519752502441,0,56.0505874633789,,,,,,,,,,,,,,,,,,,,,,,,,,,,,,,,,
,3762234953.18958,56.0326957702637,800.368957519531,,,5,,,,31.6299982368946,,,,,4.89653643528634E-5,1.33494192194068E-6,-2.74378675270111,0.00576991786403737,4.89576521807863E-5,1.33473166512035E-6,4.89015263174908E-5,1.30066068892027E-6,-2.34359358136147E-6,2.99650446641417E-7,1.00015752740856,10.005763053894,2,20,1,3,0.160664793524833,0.00651106942961234,0.0413267537951469,172.859115600586,56.0221328735352,56.0360069274902,800.368957519531,800.368957519531,,,23.9290008544922,0,1,,,,,,1,1,1,56.0314331054687,0,56.0287208557129,,,,,,,,,,,,,,,,,,,,,,,,,,,,,,,,,
,3762234976.26808,56.0143566131592,820.441040039063,,,5,,,,31.6299982368946,,,,,4.51924416215433E-5,1.00860489749704E-6,-2.25923985296392,0.00911900564445345,4.5185320120715E-5,1.00844595984386E-6,4.51501972089816E-5,9.18436918340275E-7,-1.78124855131392E-6,4.16457537997595E-7,1.00015760651489,10.005763053894,2,20,1,3,0.148228910661642,0.00726636493910601,0.0413267537951469,172.859115600586,56.0108947753906,56.0165863037109,820.441040039063,820.441040039063,,,23.8820247650146,0,1,,,,,,1,1,1,56.0133171081543,0,56.0131541165439,,,,,,,,,,,,,,,,,,,,,,,,,,,,,,,,,
,3762234997.90681,56.0084762573242,840.452331542969,,,5,,,,31.6299982368946,,,,,4.35028325915757E-5,8.36065668685718E-7,-3.06610742060792,0.00617098783688157,4.34959740686165E-5,8.35933857140526E-7,4.34337089400252E-5,7.89356667451835E-7,-2.32651840545665E-6,2.75138992262402E-7,1.00015768178794,10.005763053894,2,20,1,3,0.142771402508818,0.00498773456910254,0.0413267537951469,172.859115600586,56.006233215332,56.0095520019531,840.452331542969,840.452331542969,,,23.8497943878174,0,1,,,,,,1,1,1,56.0078468322754,0,56.0075088500977,,,,,,,,,,,,,,,,,,,,,,,,,,,,,,,,,
,3762235019.84711,56.0169067382812,860.366577148438,,,5,,,,31.6299982368946,,,,,4.42948961711216E-5,8.8952275010512E-7,-2.76033413751783,0.00723427319395243,4.42879160227054E-5,8.89382575923621E-7,4.42365294922919E-5,8.27481323163657E-7,-2.1328300710072E-6,3.26000040140884E-7,1.0001576084188,10.005763053894,2,20,1,3,0.145341648657705,0.00585737165491199,0.0413267537951469,172.859115600586,56.0154724121094,56.0171318054199,860.366577148438,860.366577148438,,,23.8324165344238,0,1,,,,,,1,1,1,56.0168647766113,0,56.0164321899414,,,,,,,,,,,,,,,,,,,,,,,,,,,,,,,,,
,3762235041.42322,56.010440826416,880.450805664062,,,5,,,,31.6299982368946,,,,,4.22733881055689E-5,9.99419421128763E-7,-3.05836038790493,0.00823720642990412,4.22667293151357E-5,9.99261995268705E-7,4.22065291640064E-5,9.33986040723772E-7,-2.25506162373342E-6,3.55238808298763E-7,1.00015754212689,10.005763053894,2,20,1,3,0.138735792871766,0.00487146431349549,0.0413267537951469,172.859115600586,56.0077743530273,56.0114555358887,880.450805664062,880.450805664062,,,23.7854957580566,0,1,,,,,,1,1,1,56.0098991394043,0,56.0093391418457,,,,,,,,,,,,,,,,,,,,,,,,,,,,,,,,,
,3762235063.34715,56.0369911193848,900.267883300781,,,5,,,,31.6299982368946,,,,,4.10833704295289E-5,6.91224914576606E-7,-2.68252364848995,0.00769430634783655,4.1076886906679E-5,6.91115829745414E-7,4.10318747266082E-5,6.13236416992782E-7,-1.92247090069602E-6,3.18719605607415E-7,1.00015783871024,10.005763053894,2,20,1,3,0.134796308062223,0.00562150473656158,0.0413267537951469,172.859115600586,56.0343818664551,56.0381355285645,900.267883300781,900.267883300781,,,23.7528457641602,0,1,,,,,,1,1,1,56.0376739501953,0,56.0369976043701,,,,,,,,,,,,,,,,,,,,,,,,,,,,,,,,,
,3762235084.98825,56.0433330535889,920.206359863281,,,5,,,,31.6299982368946,,,,,4.2309356805464E-5,1.01153673638868E-6,-2.97291734216178,0.00830766528122326,4.23026820955808E-5,1.01137715669375E-6,4.22457495145596E-5,9.45698733079931E-7,-2.19398277861652E-6,3.58521490754674E-7,1.00015778455532,10.005763053894,2,20,1,3,0.13884634916124,0.0050885661835042,0.0413267537951469,172.859115600586,56.0358200073242,56.043342590332,920.206359863281,920.206359863281,,,23.7353706359863,0,1,,,,,,1,1,1,56.0432205200195,0,56.0406295776367,,,,,,,,,,,,,,,,,,,,,,,,,,,,,,,,,
,3762235106.88505,56.0637035369873,940.254089355469,,,5,,,,31.6299982368946,,,,,4.24299795830824E-5,8.97461884740416E-7,-2.97731688863669,0.00751207821563264,4.24232901254064E-5,8.97320392018695E-7,4.23660261518167E-5,8.36489413097358E-7,-2.20349113181632E-6,3.24760446650485E-7,1.00015768361332,10.005763053894,2,20,1,3,0.139242555834872,0.00509536225184642,0.0413267537951469,172.859115600586,56.0570182800293,56.0641746520996,940.254089355469,940.254089355469,,,23.7185859680176,0,1,,,,,,1,1,1,56.063289642334,0,56.0614585876465,,,,,,,,,,,,,,,,,,,,,,,,,,,,,,,,,
,3762235128.2796,56.0538311004639,960.253356933594,,,5,,,,31.6299982368946,,,,,4.14360629473538E-5,5.65533074733799E-7,-2.58265071164773,0.00428134051559827,4.14295393915208E-5,5.65444039088855E-7,4.13874577514247E-5,5.35481236542818E-7,-1.86683557594287E-6,1.81622704119541E-7,1.00015746146177,10.005763053894,2,20,1,3,0.135943264707085,0.00591545306149251,0.0413267537951469,172.859115600586,56.0435638427734,56.0568923950195,960.253356933594,960.253356933594,,,23.6859931945801,0,1,,,,,,1,1,1,56.0519714355469,0,56.0504302978516,,,,,,,,,,,,,,,,,,,,,,,,,,,,,,,,,
,3762235150.44157,56.0589427947998,980.386108398438,,,5,,,,31.6299982368946,,,,,3.95060877566205E-5,9.82951199084215E-7,-3.16800488707824,0.00775883934802274,3.94998588129486E-5,9.82796216700513E-7,3.94394943527533E-5,9.309822347567E-7,-2.18291810245251E-6,3.14897574027274E-7,1.00015769534016,10.005763053894,2,20,1,3,0.129662243982102,0.00431828903115379,0.0413267537951469,172.859115600586,56.0512008666992,56.0590896606445,980.386108398438,980.386108398438,,,23.6688652038574,0,1,,,,,,1,1,1,56.0589942932129,0,56.056534576416,,,,,,,,,,,,,,,,,,,,,,,,,,,,,,,,,
,3762235172.07676,56.033540725708,1000.19104003906,,,5,,,,31.6299982368946,,,,,3.79902583763912E-5,9.16044077681137E-7,-3.75290867119506,0.00610804722071332,3.79842777026943E-5,9.15899868061232E-7,3.79028242823429E-5,8.83008390748878E-7,-2.48621479708417E-6,2.43246274753918E-7,1.00015745129455,10.005763053894,2,20,1,3,0.124723068051375,0.00288217853646987,0.0413267537951469,172.859115600586,56.0241165161133,56.0373802185059,1000.19104003906,1000.19104003906,,,23.6220264434814,0,1,,,,,,1,1,1,56.031177520752,0,56.0298416137695,,,,,,,,,,,,,,,,,,,,,,,,,,,,,,,,,