File: Experimental_Data/AC_Suceptibillity_FieldScans/ZFCd_Down_10K.dat
[Header]
; MPMS3 Data File (default extension .dat)
; Copyright (c) 2007, Quantum Design, Inc. All rights reserved.
TITLE,ZFCd_Down_10K
FILEOPENTIME,3772406418.18086,07/16/2019,2:40 am
BYAPP,SQUID AC,0.9.1.0
INFO,MPMS3 Measurement Release 1.1.16 Build 347, MultiVu Release 2.3.3.2,APPNAME
INFO,0,MOMENT_UNITS
INFO,Cu2OSeO3,SAMPLE_MATERIAL
INFO,,SAMPLE_COMMENT
INFO,,SAMPLE_MASS
INFO,,SAMPLE_VOLUME
INFO,,SAMPLE_MOLECULAR_WEIGHT
INFO,,SAMPLE_SIZE
INFO,,SAMPLE_SHAPE
INFO,Quartz,SAMPLE_HOLDER
INFO,Standard,SAMPLE_HOLDER_DETAIL
INFO,64.77,SAMPLE_OFFSET
DATATYPE,COMMENT,1
DATATYPE,TIME,2
STARTUPAXIS,X,2
STARTUPAXIS,Y1,5
FIELDGROUP, VSM,2,3,4,5,6,8,9,10,11,14,15
FIELDGROUP, DC, 2,3,4,14,56,57,58,59,60,61,62,63,64,65,66,67,68,69
FIELDGROUP, AC, 2,3,4,11,16,17,18,19,20,21,22,23,24,25,26,27,28,29,30
STARTUPGROUP, All
[Data]
Comment,Time Stamp (sec),Temperature (K),Magnetic Field (Oe),Moment (emu),M. Std. Err. (emu),Transport Action,Averaging Time (sec),Frequency (Hz),Peak Amplitude (mm),Center Position (mm),Lockin Signal' (V),Lockin Signal (V),Range,M. Quad. Signal (emu),AC Moment (emu),AC M. Std Err. (emu),AC Phase (deg),AC Phase Std. Err. (deg),AC Susceptibility (emu/Oe),AC Suscept. Std Err. (emu/Oe),AC X' (emu/Oe),AC X' Std Err. (emu/Oe),AC X'' (emu/Oe),AC X'' Std Err. (emu/Oe),AC Drive (Oe),AC Frequency (Hz),AC Averaging Time (sec),AC Cycles,AC Range,AC Measure Type,AC Signal' (V),AC Signal'' (V),AC Trim Coil Ratio,AC Trim Coil Phase,Min. Temperature (K),Max. Temperature (K),Min. Field (Oe),Max. Field (Oe),Mass (grams),Motor Lag (deg),Pressure (Torr),Measure Count,Measurement Number,SQUID Status (code),Motor Status (code),Measure Status (code),Motor Current (amps),Motor Temp. (C),Temp. Status (code),Field Status (code),Chamber Status (code),Chamber Temp (K),Redirection State,Average Temp (K),Rotation Angle (deg),Rotator state,DC Moment Fixed Ctr (emu),DC Moment Err Fixed Ctr (emu),DC Moment Free Ctr (emu),DC Moment Err Free Ctr (emu),DC Fixed Fit,DC Free Fit,DC Calculated Center (mm),DC Calculated Center Err (mm),DC Scan Length (mm),DC Scan Time (s),DC Number of Points,DC Squid Drift,DC Min V (V),DC Max V (V),DC Scans per Measure,Map 01,Map 02,Map 03,Map 04,Map 05,Map 06,Map 07,Map 08,Map 09,Map 10,Map 11,Map 12,Map 13,Map 14,Map 15,Map 16
,3772406640.17496,10.0005087852478,-0.145713716745377,,,5,,,,6.46999990567565,,,,,0.000594803195174164,1.1003470530551E-8,0.0308491975445113,9.5092575402537E-6,0.000594708291885669,1.10017148817134E-8,0.000594708205683843,9.43840691521752E-9,3.2020286393227E-7,5.65280507724163E-9,1.00015957956159,10.005763053894,2,20,1,3,1.94562656526518,0.172087368533794,0.0403775237500668,172.74836730957,9.99924468994141,10.0009384155273,-0.145713716745377,-0.145713716745377,,,17.7360973358154,0,1,,,,,,1,1,1,10.0005168914795,0,10.000287437439,,,,,,,,,,,,,,,,,,,,,,,,,,,,,,,,,
,3772406661.70632,9.99980068206787,-19.9506359100342,,,5,,,,6.46999990567565,,,,,0.000594714715059934,9.3642211944441E-9,0.0303983551470113,1.30409387145642E-5,0.000594619845191089,9.36272739848772E-9,0.000594619761502875,5.24724354393304E-9,3.15476367320524E-7,7.75416659152005E-9,1.00015954709486,10.005763053894,2,20,1,3,1.94533592279232,0.172087698808579,0.0403775237500668,172.74836730957,9.9988603591919,10.000997543335,-19.9506359100342,-19.9506359100342,,,17.7787094116211,0,1,,,,,,1,1,1,9.99967861175537,0,9.99976568222046,,,,,,,,,,,,,,,,,,,,,,,,,,,,,,,,,
,3772406683.62943,9.99855709075928,-40.0348434448242,,,5,,,,6.46999990567565,,,,,0.000594539956348307,1.13738745396641E-8,0.03004425080172,1.40851095597088E-5,0.000594445080174351,1.13720595065652E-8,0.000594444998448543,7.69630417043043E-9,3.11709804979009E-7,8.37201526139761E-9,1.00015960460793,10.005763053894,2,20,1,3,1.94476273288752,0.172066916996348,0.0403775237500668,172.74836730957,9.99842071533203,10.0014896392822,-40.0348434448242,-40.0348434448242,,,17.7850227355957,0,1,,,,,,1,1,1,9.9987154006958,0,9.99938782778653,,,,,,,,,,,,,,,,,,,,,,,,,,,,,,,,,
,3772406705.27742,10.0003833770752,-59.9247627258301,,,5,,,,6.46999990567565,,,,,0.000594319629311756,2.02297786005848E-8,0.0290139305405175,2.91111888051406E-5,0.000594224806594425,2.02265509727507E-8,0.000594224730406062,1.04824501374552E-8,3.00908665065028E-7,1.72983121537636E-8,1.00015957381159,10.005763053894,2,20,1,3,1.94404254384671,0.172009573210777,0.0403775237500668,172.74836730957,9.99923133850098,10.0009269714355,-59.9247627258301,-59.9247627258301,,,17.8220539093018,0,1,,,,,,1,1,1,10.0004558563232,0,10.0001365661621,,,,,,,,,,,,,,,,,,,,,,,,,,,,,,,,,
,3772406727.2231,9.99981832504273,-79.8875350952148,,,5,,,,6.46999990567565,,,,,0.0005943667939308,1.96191069691258E-8,0.0301549542122128,2.10893413134397E-5,0.000594271979082254,1.96159772810697E-8,0.000594271896777044,1.50923259625657E-8,3.12767251686164E-7,1.25302937607667E-8,1.00015954790379,10.005763053894,2,20,1,3,1.94419079944728,0.17210348184447,0.0403775237500668,172.74836730957,9.99887657165527,10.0010347366333,-79.8875350952148,-79.8875350952148,,,17.8363494873047,0,1,,,,,,1,1,1,9.9998254776001,0,9.99971981048584,,,,,,,,,,,,,,,,,,,,,,,,,,,,,,,,,
,3772406750.18416,9.99996042251587,-99.959602355957,,,5,,,,6.46999990567565,,,,,0.000594754298261443,3.14478545954636E-8,0.0274981082014447,2.69541598707953E-5,0.000594659417723543,3.14428377517543E-8,0.000594659349238038,2.70547512751009E-8,2.85396385611541E-7,1.60216253646618E-8,1.000159554419,10.005763053894,2,20,1,3,1.94546371063506,0.172167267429038,0.0403775237500668,172.74836730957,9.99895477294922,10.0010766983032,-99.959602355957,-99.959602355957,,,17.8570232391357,0,1,,,,,,1,1,1,9.99999618530273,0,9.9998875617981,,,,,,,,,,,,,,,,,,,,,,,,,,,,,,,,,
,3772406771.82114,10.0029773712158,-119.861663818359,,,5,,,,6.46999990567565,,,,,0.000595447670646929,5.13473122625196E-8,0.0269213471405871,3.22100145664717E-5,0.000595352733507512,5.13391255364927E-8,0.000595352667788253,4.76308332153377E-8,2.79736084512879E-7,1.91574930005061E-8,1.00015946368274,10.005763053894,2,20,1,3,1.94773090166709,0.17238985824564,0.0403775237500668,172.74836730957,9.99999713897705,10.0048971176147,-119.861663818359,-119.861663818359,,,17.8928375244141,0,1,,,,,,1,1,1,10.0024080276489,0,10.0017512321472,,,,,,,,,,,,,,,,,,,,,,,,,,,,,,,,,
,3772406793.78794,9.99993944168091,-139.933731079102,,,5,,,,6.46999990567565,,,,,0.000596405485880771,4.89311233447542E-8,0.0232028835295335,5.13231317662232E-5,0.000596310342504163,4.89233174603242E-8,0.000596310293607301,3.81739654492923E-8,2.41485833057536E-7,3.05980285835526E-8,1.00015955345703,10.005763053894,2,20,1,3,1.95087253517445,0.172582463632644,0.0403775237500668,172.74836730957,9.99887561798096,10.0010719299316,-139.933731079102,-139.933731079102,,,17.9369220733643,0,1,,,,,,1,1,1,9.99969577789307,0,9.9998672803243,,,,,,,,,,,,,,,,,,,,,,,,,,,,,,,,,
,3772406816.88531,9.99975681304932,-160.030090332031,,,5,,,,6.46999990567565,,,,,0.000597634173236033,6.065303306817E-8,0.0244811748491003,8.6963132158245E-5,0.000597538838852123,6.0643357718602E-8,0.000597538784307068,3.12647055549783E-8,2.55314657942965E-7,5.19628234601127E-8,1.00015954508345,10.005763053894,2,20,1,3,1.95488514827225,0.173023671947352,0.0403775237500668,172.74836730957,9.99888610839844,10.0009479522705,-160.030090332031,-160.030090332031,,,17.9880619049072,0,1,,,,,,1,1,1,9.99940586090088,0,9.99976746241252,,,,,,,,,,,,,,,,,,,,,,,,,,,,,,,,,
,3772406839.94615,9.99980592727661,-179.992858886719,,,5,,,,6.46999990567565,,,,,0.000599154510287155,9.19107159518037E-8,0.0229083135695554,6.57244745069349E-5,0.000599058863430308,9.18960436578621E-8,0.000599058815547406,8.30466931172584E-8,2.39519001941681E-7,3.93462781245648E-8,1.00015966186745,10.005763053894,2,20,1,3,1.95986037692226,0.173451902767812,0.0403775237500668,172.74836730957,9.99877262115479,10.0007219314575,-179.992858886719,-179.992858886719,,,18.0087604522705,0,1,,,,,,1,1,1,9.99978542327881,0,9.9996693351052,,,,,,,,,,,,,,,,,,,,,,,,,,,,,,,,,
,3772406861.47463,9.99994802474976,-199.894912719727,,,5,,,,6.46999990567565,,,,,0.000601684582488648,1.17035779322399E-7,0.0238264046915093,0.000136477551499102,0.000601588596711588,1.1701710879211E-7,0.00060158854469506,8.33893154945297E-8,2.50170135946093E-7,8.20927878160943E-8,1.00015955385056,10.005763053894,2,20,1,3,1.9681309413157,0.174257803864167,0.0403775237500668,172.74836730957,9.998854637146,10.0006828308105,-199.894912719727,-199.894912719727,,,18.0414009094238,0,1,,,,,,1,1,1,9.99979686737061,0,9.99980916976929,,,,,,,,,,,,,,,,,,,,,,,,,,,,,,,,,
,3772406883.42404,10.0003528594971,-219.979141235352,,,5,,,,6.46999990567565,,,,,0.000606146183917743,1.08725353087052E-7,0.0236456798113229,5.16026811193341E-5,0.00060604947514099,1.08708006288246E-7,0.000606049423530685,1.04128785072925E-7,2.50113560789328E-7,3.12190126429719E-8,1.00015957241235,10.005763053894,2,20,1,3,1.98272288219329,0.175586322226205,0.0403775237500668,172.74836730957,9.99889183044434,10.0011920928955,-219.979141235352,-219.979141235352,,,18.0665702819824,0,1,,,,,,1,1,1,10.0002641677856,0,10.0000710487366,,,,,,,,,,,,,,,,,,,,,,,,,,,,,,,,,
,3772406904.20107,9.99991703033447,-239.954040527344,,,5,,,,6.46999990567565,,,,,0.000612148957174599,1.53921578830093E-7,0.0213595033402854,0.000103213372329765,0.000612051232813938,1.53897006562663E-7,0.000612051190283994,1.40355044279184E-7,2.28168813829018E-7,6.31248776183886E-8,1.00015966696156,10.005763053894,2,20,1,3,2.00236253726276,0.177288096234826,0.0403775237500668,172.74836730957,9.99864292144775,10.0006771087646,-239.954040527344,-239.954040527344,,,18.0982913970947,0,1,,,,,,1,1,1,9.99998760223389,0,9.99976322867654,,,,,,,,,,,,,,,,,,,,,,,,,,,,,,,,,
,3772406926.99609,9.99962949752808,-259.989685058594,,,5,,,,6.46999990567565,,,,,0.000619140435320658,1.43096291811498E-7,0.0177646262610525,0.00012995841227401,0.000619041602989943,1.43073449594726E-7,0.000619041573235165,1.18328960676146E-7,1.91934600321722E-7,8.04255496980753E-8,1.00015965377809,10.005763053894,2,20,1,3,2.02524046238743,0.179229300916728,0.0403775237500668,172.74836730957,9.99871730804443,10.0002164840698,-259.989685058594,-259.989685058594,,,18.122989654541,0,1,,,,,,1,1,1,9.99951839447021,0,9.99955706162886,,,,,,,,,,,,,,,,,,,,,,,,,,,,,,,,,
,3772406948.40033,9.99917030334473,-279.903900146484,,,5,,,,6.46999990567565,,,,,0.000628094248636133,5.81614022572405E-7,0.0398004051446676,0.000373605381885327,0.000627994072157274,5.81521259352612E-7,0.000627993920642406,5.32183544351008E-7,4.36234862368605E-7,2.34409151274105E-7,1.00015951819181,10.005763053894,2,20,1,3,2.0544560172189,0.182655200110677,0.0403775237500668,172.74836730957,9.99818515777588,10.0005235671997,-279.903900146484,-279.903900146484,,,18.1625003814697,0,1,,,,,,1,1,1,9.99893569946289,0,9.99913753162731,,,,,,,,,,,,,,,,,,,,,,,,,,,,,,,,,
,3772406970.49486,9.99504566192627,-299.878814697266,,,5,,,,6.46999990567565,,,,,0.000651505435315803,1.21273747791778E-6,0.133394757112129,0.00120566932153565,0.000651401498904272,1.21254400665146E-6,0.000651399733472988,9.2400228665115E-7,1.51657708416722E-6,7.85164149926516E-7,1.00015955813996,10.005763053894,2,20,1,3,2.13071723022834,0.192989789886074,0.0403775237500668,172.74836730957,9.99205017089844,9.99733066558838,-299.878814697266,-299.878814697266,,,18.1585540771484,0,1,,,,,,1,1,1,9.99431800842285,0,9.99425029754639,,,,,,,,,,,,,,,,,,,,,,,,,,,,,,,,,
,3772406993.65288,9.99930191040039,-319.9873046875,,,5,,,,6.46999990567565,,,,,0.000701753246257777,2.04695273532492E-6,0.252725838146323,0.00161930291331586,0.000701641237122032,2.04662601448961E-6,0.000701634411559778,1.70292570271895E-6,3.09485788024195E-6,1.13521896311011E-6,1.00015963875813,10.005763053894,2,20,1,3,2.29460907086511,0.212703131372994,0.0403775237500668,172.74836730957,9.99765491485596,10.0007257461548,-319.9873046875,-319.9873046875,,,18.1675281524658,0,1,,,,,,1,1,1,9.99930095672607,0,9.99920988082886,,,,,,,,,,,,,,,,,,,,,,,,,,,,,,,,,
,3772407017.78292,9.99871730804443,-339.828643798828,,,5,,,,6.46999990567565,,,,,0.00076048810685885,4.58107904278789E-6,0.272299819839636,0.00395579822003314,0.000760366743237252,4.58034796449956E-6,0.000760358156231702,3.45521362409421E-6,3.61365094499392E-6,3.00683991721691E-6,1.00015961195394,10.005763053894,2,20,10,3,2.48657925131252,0.231408128990579,0.0403775237500668,172.74836730957,9.99753093719482,9.9994535446167,-339.828643798828,-339.828643798828,,,18.1666069030762,0,1,,,,,,1,1,1,9.99892234802246,0,9.99847802248868,,,,,,,,,,,,,,,,,,,,,,,,,,,,,,,,,
,3772407039.84326,9.99915456771851,-359.973602294922,,,5,,,,6.46999990567565,,,,,0.000812900866673336,1.6852755036756E-6,0.171866133962196,0.00109229655642318,0.000812771122391558,1.68500652271029E-6,0.000812767465826588,1.43260043482051E-6,2.43800891285019E-6,8.87075518616264E-7,1.00015963200242,10.005763053894,2,20,10,3,2.6583797966763,0.242754571115682,0.0403775237500668,172.74836730957,9.99824237823486,9.99995899200439,-359.973602294922,-359.973602294922,,,18.1676902770996,0,1,,,,,,1,1,1,9.99917793273926,0,9.99904069900513,,,,,,,,,,,,,,,,,,,,,,,,,,,,,,,,,
,3772407061.50875,9.99923229217529,-380.033477783203,,,5,,,,6.46999990567565,,,,,0.000847035308158016,5.52392003672108E-6,0.0925213522038897,0.00182896991120183,0.000846900112779073,5.52303836336529E-6,0.000846899008596779,5.30279178079781E-6,1.36757559157691E-6,1.54413473916883E-6,1.00015963556611,10.005763053894,2,20,10,3,2.77035139771574,0.249171310391364,0.0403775237500668,172.74836730957,9.99828815460205,10.0003681182861,-380.033477783203,-380.033477783203,,,18.1593818664551,0,1,,,,,,1,1,1,9.99925804138184,0,9.99918012619019,,,,,,,,,,,,,,,,,,,,,,,,,,,,,,,,,
,3772407083.39437,9.99966239929199,-400.020568847656,,,5,,,,6.46999990567565,,,,,0.00086280417726852,4.11909660698174E-7,-0.0180408585875869,0.000250589108445399,0.000862666448009481,4.11843907641045E-7,0.000862666405245113,3.50584306830285E-7,-2.71629835074898E-7,2.16115820951114E-7,1.00015965528665,10.005763053894,2,20,10,3,2.82240653773919,0.248424525417613,0.0403775237500668,172.74836730957,9.99868297576904,10.0003700256348,-400.020568847656,-400.020568847656,,,18.1769905090332,0,1,,,,,,1,1,1,9.99951267242432,0,9.9994571685791,,,,,,,,,,,,,,,,,,,,,,,,,,,,,,,,,
,3772407105.05464,10.0000467300415,-419.910491943359,,,5,,,,6.46999990567565,,,,,0.00086564758113599,3.20670778955686E-7,-0.067419708444465,0.000264474380348175,0.000865509481848456,3.20619621409507E-7,0.000865508882650588,2.24525053886414E-7,-1.01844121769743E-6,2.28878661762249E-7,1.00015955837623,10.005763053894,2,20,10,3,2.83191795212448,0.246862974411485,0.0403775237500668,172.74836730957,9.99883556365967,10.0008716583252,-419.910491943359,-419.910491943359,,,18.1712284088135,0,1,,,,,,1,1,1,9.99998378753662,0,9.9998893737793,,,,,,,,,,,,,,,,,,,,,,,,,,,,,,,,,
,3772407126.94407,9.99944162368774,-440.0068359375,,,5,,,,6.46999990567565,,,,,0.000862074754379604,3.44111677921431E-7,-0.0971673207753678,0.000206819853206801,0.00086193715028187,3.44056750924997E-7,0.000861935910798538,2.94278260185697E-7,-1.46174961115172E-6,1.78256426080925E-7,1.00015964516402,10.005763053894,2,20,10,3,2.82035323026355,0.244440467012134,0.0403775237500668,172.74836730957,9.99886894226074,10.0006799697876,-440.0068359375,-440.0068359375,,,18.1736793518066,0,1,,,,,,1,1,1,9.99957275390625,0,9.99945087432861,,,,,,,,,,,,,,,,,,,,,,,,,,,,,,,,,
,3772407148.55036,9.99984931945801,-460.321746826172,,,5,,,,6.46999990567565,,,,,0.000855497187631505,3.86542884726862E-7,-0.125276587448435,0.000282841339011165,0.000855360617456202,3.86481177651383E-7,0.000855358572831298,3.01404511780726E-7,-1.87023502816658E-6,2.4191531773954E-7,1.00015966385699,10.005763053894,2,20,10,3,2.79894915270646,0.241263119243234,0.0403775237500668,172.74836730957,9.998779296875,10.000828742981,-460.321746826172,-460.321746826172,,,18.1924114227295,0,1,,,,,,1,1,1,10.0003471374512,0,9.99971466064453,,,,,,,,,,,,,,,,,,,,,,,,,,,,,,,,,
,3772407170.45028,9.9999098777771,-480.381683349609,,,5,,,,6.46999990567565,,,,,0.00084787579397695,3.79475344761558E-7,-0.13310880489104,0.000202546135612662,0.000847740535193022,3.79414808331543E-7,0.000847738247482539,3.38323966535679E-7,-1.9694579417782E-6,1.71733777833095E-7,1.00015955210151,10.005763053894,2,20,10,3,2.77404315386034,0.238794122057353,0.0403775237500668,172.74836730957,9.99877262115479,10.0008115768433,-480.381683349609,-480.381683349609,,,18.2030544281006,0,1,,,,,,1,1,1,9.99991416931152,0,9.99986457824707,,,,,,,,,,,,,,,,,,,,,,,,,,,,,,,,,
,3772407192.13597,9.99965190887451,-500.344451904297,,,5,,,,6.46999990567565,,,,,0.00083973947583037,3.71916100613463E-7,-0.154327465334327,0.000275388518558148,0.000839605428788806,3.71856731899198E-7,0.000839602383095549,2.91237741992357E-7,-2.26149329198416E-6,2.31209875865944E-7,1.00015965480566,10.005763053894,2,20,10,3,2.74750699447348,0.235543839308697,0.0403775237500668,172.74836730957,9.99901294708252,10.0009994506836,-500.344451904297,-500.344451904297,,,18.1975975036621,0,1,,,,,,1,1,1,9.99961662292481,0,9.99976100921631,,,,,,,,,,,,,,,,,,,,,,,,,,,,,,,,,
,3772407213.98321,10.0001740455627,-520.270812988281,,,5,,,,6.46999990567565,,,,,0.00083157017096524,4.2549884219936E-7,-0.161663544691024,0.000270207815549151,0.000831437503293801,4.25430958642968E-7,0.000831434193672862,3.61258418858128E-7,-2.34594863296069E-6,2.24686126354076E-7,1.00015956421368,10.005763053894,2,20,10,3,2.7208045874217,0.232962031737044,0.0403775237500668,172.74836730957,9.99917697906494,10.0009937286377,-520.270812988281,-520.270812988281,,,18.2252616882324,0,1,,,,,,1,1,1,10.0002374649048,0,10.0000761985779,,,,,,,,,,,,,,,,,,,,,,,,,,,,,,,,,
,3772407235.69026,9.99959278106689,-540.355041503906,,,5,,,,6.46999990567565,,,,,0.000823360091990358,3.17529062366511E-7,-0.158409569355199,0.000294945414920323,0.000823228661810138,3.17478376278737E-7,0.000823225515454775,2.04583376224143E-7,-2.2760338155585E-6,2.42771830279615E-7,1.00015965209463,10.005763053894,2,20,10,3,2.69392556771407,0.230872902136982,0.0403775237500668,172.74836730957,9.99876594543457,10.000657081604,-540.355041503906,-540.355041503906,,,18.2126655578613,0,1,,,,,,1,1,1,9.99961185455322,0,9.99952926635742,,,,,,,,,,,,,,,,,,,,,,,,,,,,,,,,,
,3772407257.7184,9.9996075630188,-560.414916992188,,,5,,,,6.46999990567565,,,,,0.000815512261884846,3.95698428795645E-7,-0.183845087686726,0.000255059382866742,0.000815382177247121,3.95635309834516E-7,0.000815377979757399,3.36541568260718E-7,-2.61631400984057E-6,2.08007382610498E-7,1.00015953824029,10.005763053894,2,20,10,3,2.6683463616645,0.227545080861334,0.0403775237500668,172.74836730957,9.9987850189209,10.0008773803711,-560.414916992188,-560.414916992188,,,18.239559173584,0,1,,,,,,1,1,1,9.99945640563965,0,9.99979027834806,,,,,,,,,,,,,,,,,,,,,,,,,,,,,,,,,
,3772407280.70624,9.99971389770508,-580.353454589844,,,5,,,,6.46999990567565,,,,,0.000807413205309719,4.54943503652586E-7,-0.181330025588513,0.000396239023032344,0.000807284316194636,4.54870880037796E-7,0.000807280273319412,3.234298569057E-7,-2.55489396587027E-6,3.1984472040088E-7,1.00015965764787,10.005763053894,2,20,10,3,2.64183311028969,0.225457610471874,0.0403775237500668,172.74836730957,9.99880981445313,10.0007276535034,-580.353454589844,-580.353454589844,,,18.2418403625488,0,1,,,,,,1,1,1,9.99978542327881,0,9.99954223632813,,,,,,,,,,,,,,,,,,,,,,,,,,,,,,,,,
,3772407302.36591,10.0000514984131,-600.401184082031,,,5,,,,6.46999990567565,,,,,0.00079957415322056,5.10167400480641E-7,-0.212872312531024,0.000296580837533863,0.000799446594645252,5.10086011873329E-7,0.000799441077021874,4.51572567538704E-7,-2.97019527924799E-6,2.37212891208172E-7,1.00015955859486,10.005763053894,2,20,10,3,2.61630317136215,0.221884520835412,0.0403775237500668,172.74836730957,9.99893760681152,10.0008592605591,-600.401184082031,-600.401184082031,,,18.2534694671631,0,1,,,,,,1,1,1,9.99995899200439,0,9.99996509552002,,,,,,,,,,,,,,,,,,,,,,,,,,,,,,,,,
,3772407324.38831,10.0000257492065,-620.412536621094,,,5,,,,6.46999990567565,,,,,0.000791583148207365,4.98959304181767E-7,-0.211777555959094,0.000347681388865462,0.000791456865396431,4.98879704226138E-7,0.000791451458956778,4.16092566022984E-7,-2.92538857784568E-6,2.7522342885221E-7,1.00015955741425,10.005763053894,2,20,10,3,2.59014817755541,0.219771949773128,0.0403775237500668,172.74836730957,9.99881649017334,10.0008735656738,-620.412536621094,-620.412536621094,,,18.2715625762939,0,1,,,,,,1,1,1,9.9999942779541,0,9.99988529898904,,,,,,,,,,,,,,,,,,,,,,,,,,,,,,,,,
,3772407345.91817,10.0002164840698,-640.290283203125,,,5,,,,6.46999990567565,,,,,0.000783298070213444,5.35522867298883E-7,-0.225170735592127,0.000437147780856144,0.000783173102289288,5.35437429604589E-7,0.000783167054372083,4.11679921076269E-7,-3.07783943422848E-6,3.42363671560237E-7,1.0001595661595,10.005763053894,2,20,10,3,2.56308604962308,0.216927107660162,0.0403775237500668,172.74836730957,9.99890804290771,10.0008754730225,-640.290283203125,-640.290283203125,,,18.2750053405762,0,1,,,,,,1,1,1,10.0001602172852,0,9.99991436004639,,,,,,,,,,,,,,,,,,,,,,,,,,,,,,,,,
,3772407367.9143,9.9997706413269,-660.410949707031,,,5,,,,6.46999990567565,,,,,0.000774879077501352,5.26478004529616E-7,-0.230046027693547,0.000434109142018495,0.000774755468584244,5.26394020617918E-7,0.000774749223787845,4.04934504519399E-7,-3.11068180994327E-6,3.36331253367757E-7,1.00015954571748,10.005763053894,2,20,10,3,2.53555271122795,0.21443439435762,0.0403775237500668,172.74836730957,9.99895572662354,10.0010862350464,-660.410949707031,-660.410949707031,,,18.2773036956787,0,1,,,,,,1,1,1,9.99973583221436,0,9.99974779649214,,,,,,,,,,,,,,,,,,,,,,,,,,,,,,,,,
,3772407390.97922,10.0000710487366,-680.313049316406,,,5,,,,6.46999990567565,,,,,0.000766588380920493,6.09415881618486E-7,-0.281906796422663,0.000481911898308162,0.000766466083982074,6.09318659043241E-7,0.000766456806547546,4.84559578616352E-7,-3.77115257610477E-6,3.69420144319984E-7,1.00015955949125,10.005763053894,2,20,10,3,2.50861187310147,0.209922950922963,0.0403775237500668,172.74836730957,9.99898815155029,10.0008211135864,-680.313049316406,-680.313049316406,,,18.2885150909424,0,1,,,,,,1,1,1,9.99990558624268,0,9.99990367889404,,,,,,,,,,,,,,,,,,,,,,,,,,,,,,,,,
,3772407412.56842,10.0000867843628,-700.372924804687,,,5,,,,6.46999990567565,,,,,0.000759510471503686,8.38804587603641E-7,-0.440562240306683,0.000534025501410786,0.000759389303184924,8.38670769117309E-7,0.000759366853946166,7.33834586636372E-7,-5.83908550944643E-6,4.06023962874169E-7,1.00015956021273,10.005763053894,2,20,10,3,2.48601332612326,0.201154947577184,0.0403775237500668,172.74836730957,9.99903106689453,10.0012865066528,-700.372924804687,-700.372924804687,,,18.2916393280029,0,1,,,,,,1,1,1,9.99992179870605,0,9.99995460510254,,,,,,,,,,,,,,,,,,,,,,,,,,,,,,,,,
,3772407434.54602,10.0002970695496,-720.250732421875,,,5,,,,6.46999990567565,,,,,0.000749261110986562,8.23226128188444E-7,-0.446291855267225,0.000587070438036321,0.000749141570575245,8.2309478707314E-7,0.000749118844504037,6.9552787320953E-7,-5.83520118591793E-6,4.40143165453703E-7,1.00015956985437,10.005763053894,2,20,10,3,2.45248231198619,0.198247338585963,0.0403775237500668,172.74836730957,9.99900150299072,10.0011405944824,-720.250732421875,-720.250732421875,,,18.3019828796387,0,1,,,,,,1,1,1,10.0003023147583,0,10.0000285148621,,,,,,,,,,,,,,,,,,,,,,,,,,,,,,,,,
,3772407456.14675,10.0001363754272,-740.23779296875,,,5,,,,6.46999990567565,,,,,0.000733632686317979,2.43677483705239E-7,-0.169769635105028,0.00024185294638694,0.000733515644737821,2.4363860812312E-7,0.000733512424752934,1.67020580373613E-7,-2.17343235733321E-6,1.77380655934724E-7,1.0001595624865,10.005763053894,2,20,10,3,2.40035947866315,0.205750586515476,0.0403775237500668,172.74836730957,9.99905681610107,10.0014686584473,-740.23779296875,-740.23779296875,,,18.3120403289795,0,1,,,,,,1,1,1,10.0002737045288,0,10.0000403086344,,,,,,,,,,,,,,,,,,,,,,,,,,,,,,,,,
,3772407483.18471,9.99993133544922,-760.358459472656,,,5,,,,6.46999990567565,,,,,0.000724926940727872,9.49489015091866E-7,-0.505973300798791,0.000652158867986615,0.000724811211848575,9.49337436645201E-7,0.000724782949905259,8.22942447775354E-7,-6.40065215663259E-6,4.73294090672586E-7,1.00015966761745,10.005763053894,2,20,10,3,2.37302470610289,0.189438857549041,0.0403775237500668,172.74836730957,9.99907207489014,10.0008964538574,-760.358459472656,-760.358459472656,,,18.3259696960449,0,1,,,,,,1,1,1,10.0000600814819,0,9.99987783432007,,,,,,,,,,,,,,,,,,,,,,,,,,,,,,,,,
,3772407504.83757,10.0001535415649,-780.381958007812,,,5,,,,6.46999990567565,,,,,0.000709779341914581,1.07246117949496E-6,-0.514151129713396,0.000969391970192092,0.000709666105267684,1.07229008137936E-6,0.000709637532160053,8.22398135467117E-7,-6.3681956309023E-6,6.88089620183861E-7,1.00015956327357,10.005763053894,2,20,10,3,2.32346331190101,0.185198622468738,0.0403775237500668,172.74836730957,9.99914836883545,10.0008678436279,-780.381958007812,-780.381958007812,,,18.3365364074707,0,1,,,,,,1,1,1,10.0000982284546,0,9.99987897872925,,,,,,,,,,,,,,,,,,,,,,,,,,,,,,,,,
,3772407526.80091,10.0002017021179,-800.235412597656,,,5,,,,6.46999990567565,,,,,0.000691951289892428,1.04719940459623E-6,-0.559063920340622,0.000960365303833283,0.000691840895966574,1.04703233437739E-6,0.000691807961513527,8.09057260383018E-7,-6.7505346699246E-6,6.64607447034184E-7,1.00015956548174,10.005763053894,2,20,10,3,2.26524145070546,0.17881935795128,0.0403775237500668,172.74836730957,9.99918460845947,10.0010747909546,-800.235412597656,-800.235412597656,,,18.3480987548828,0,1,,,,,,1,1,1,10.0000104904175,0,10.0001157413829,,,,,,,,,,,,,,,,,,,,,,,,,,,,,,,,,
,3772407549.87592,10.0001411437988,-820.356018066406,,,5,,,,6.46999990567565,,,,,0.000664986883493062,5.09360404838493E-7,-0.199371072497346,0.000535332558314964,0.000664880793315094,5.0927914288079E-7,0.000664876768069539,3.64282748992603E-7,-2.31356882595341E-6,3.55897912553283E-7,1.00015956270513,10.005763053894,2,20,10,3,2.17584353573772,0.185561008030801,0.0403775237500668,172.74836730957,9.99907970428467,10.0014686584473,-820.356018066406,-820.356018066406,,,18.359167098999,0,1,,,,,,1,1,1,10.0001373291016,0,10.0001220067342,,,,,,,,,,,,,,,,,,,,,,,,,,,,,,,,,
,3772407575.87177,10.0000801086426,-840.343139648438,,,5,,,,6.46999990567565,,,,,0.000637784615561956,5.16973567736884E-7,-0.243530297817769,0.000577561804935272,0.000637682866943236,5.16891092642395E-7,0.000637677106779428,3.6271275839048E-7,-2.71040262001787E-6,3.68260582405745E-7,1.00015955990665,10.005763053894,2,20,10,3,2.08697138576212,0.176406572772321,0.0403775237500668,172.74836730957,9.99914932250977,10.0013637542725,-840.343139648438,-840.343139648438,,,18.3545246124268,0,1,,,,,,1,1,1,10.0001211166382,0,9.99999794593224,,,,,,,,,,,,,,,,,,,,,,,,,,,,,,,,,
,3772407601.39446,9.99992656707764,-860.415161132813,,,5,,,,6.46999990567565,,,,,0.000607713263967016,1.11663916981355E-6,-0.697853624620698,0.00117639986728951,0.000607616247461304,1.11646090740458E-6,0.00060757117851278,8.57433912501415E-7,-7.40048779121002E-6,7.15046881998083E-7,1.00015966739882,10.005763053894,2,20,10,3,1.98983947685373,0.152358418141846,0.0403775237500668,172.74836730957,9.99900722503662,10.0008697509766,-860.415161132813,-860.415161132813,,,18.3742084503174,0,1,,,,,,1,1,1,10.0000295639038,0,9.99989058754661,,,,,,,,,,,,,,,,,,,,,,,,,,,,,,,,,
,3772407624.35836,9.99993515014648,-880.268615722656,,,5,,,,6.46999990567565,,,,,0.000554981940704961,3.81172575660758E-7,-0.2583734393041,0.000534982956407937,0.000554893405652993,3.81111768035645E-7,0.000554887763702125,2.39075511961674E-7,-2.50226514018507E-6,2.9679804466256E-7,1.00015955326026,10.005763053894,2,20,10,3,1.81605802581253,0.153111083990581,0.0403775237500668,172.74836730957,9.99903869628906,10.0014553070068,-880.268615722656,-880.268615722656,,,18.3920364379883,0,1,,,,,,1,1,1,9.99992752075195,0,10.0000367164612,,,,,,,,,,,,,,,,,,,,,,,,,,,,,,,,,
,3772407653.36994,9.9998722076416,-899.940002441406,,,5,,,,6.46999990567565,,,,,0.000486585757634076,6.48770493632853E-7,-0.764547593527759,0.000797410227939296,0.000486508135079012,6.48666998570417E-7,0.000486464822160002,5.1965141710903E-7,-6.49171001318217E-6,3.88241264848201E-7,1.00015955037433,10.005763053894,2,20,1,3,1.59336848865498,0.120203545747824,0.0403775237500668,172.74836730957,9.99917030334473,10.0010747909546,-899.940002441406,-899.940002441406,,,18.3886966705322,0,1,,,,,,1,1,1,9.99998950958252,0,10.000026141896,,,,,,,,,,,,,,,,,,,,,,,,,,,,,,,,,
,3772407680.69171,10.0000944137573,-920.036376953125,,,5,,,,6.46999990567565,,,,,0.000372443759863463,6.35009643672584E-7,-0.426511385895025,0.000873705956073494,0.000372384342008371,6.34908337341116E-7,0.000372374024486357,5.45033466534526E-7,-2.77201386028359E-6,3.25648763520788E-7,1.00015956056254,10.005763053894,2,20,1,3,1.21903483151943,0.0992265406688127,0.0403775237500668,172.74836730957,9.99894618988037,10.0014810562134,-920.036376953125,-920.036376953125,,,18.4074649810791,0,1,,,,,,1,1,1,10.0002603530884,0,10.0000790187291,,,,,,,,,,,,,,,,,,,,,,,,,,,,,,,,,
,3772407707.25723,9.99995803833008,-939.950622558594,,,5,,,,6.46999990567565,,,,,0.000285067951933922,1.17583404404072E-6,-1.53400435140352,0.00189794303564852,0.000285022475369618,1.17564646458063E-6,0.000284920327082732,1.04228104246191E-6,-7.63011670248295E-6,5.43870240227799E-7,1.00015955430969,10.005763053894,2,20,1,3,0.934340535480257,0.0579194475725265,0.0403775237500668,172.74836730957,9.99885559082031,10.0009613037109,-939.950622558594,-939.950622558594,,,18.4197063446045,0,1,,,,,,1,1,1,9.99987411499023,0,9.99983085285534,,,,,,,,,,,,,,,,,,,,,,,,,,,,,,,,,
,3772407729.49414,10.0001735687256,-959.949829101562,,,5,,,,6.46999990567565,,,,,0.000208503464684827,1.13385481820319E-6,-2.18748300328954,0.00281198277245079,0.000208470200305797,1.13367392443965E-6,0.000208318283666609,9.68715569763729E-7,-7.95720464342587E-6,5.88902973206726E-7,1.00015956419182,10.005763053894,2,20,1,3,0.683830633307044,0.034580957239339,0.0403775237500668,172.74836730957,9.99919414520264,10.0007743835449,-959.949829101562,-959.949829101562,,,18.4215965270996,0,1,,,,,,1,1,1,10.0001964569092,0,10.0000162124634,,,,,,,,,,,,,,,,,,,,,,,,,,,,,,,,,
,3772407751.38205,10.0003824234009,-979.985412597656,,,5,,,,6.46999990567565,,,,,0.000144752567756924,3.48682390180384E-7,-1.09944871946827,0.00149671493544073,0.000144729472729639,3.48626758494952E-7,0.000144702827568641,2.73019003460706E-7,-2.77704343493025E-6,2.16797694840192E-7,1.00015957376787,10.005763053894,2,20,1,3,0.47420434627804,0.0330282904201273,0.0403775237500668,172.74836730957,9.99892234802246,10.0017290115356,-979.985412597656,-979.985412597656,,,18.4314117431641,0,1,,,,,,1,1,1,10.000316619873,0,10.0001467977251,,,,,,,,,,,,,,,,,,,,,,,,,,,,,,,,,
,3772407778.19484,10.0000200271606,-1000.10607910156,,,5,,,,6.46999990567565,,,,,0.000106094087345411,4.02462957480158E-7,-1.35968338537438,0.00228123181441669,0.000106077161975566,4.02398751881382E-7,0.00010604729427206,3.21263770118296E-7,-2.51707575678224E-6,2.42310432142474E-7,1.00015955715189,10.005763053894,2,20,1,3,0.347666588632353,0.0226361941422948,0.0403775237500668,172.74836730957,9.99913120269775,10.0014762878418,-1000.10607910156,-1000.10607910156,,,18.4438610076904,0,1,,,,,,1,1,1,9.99995136260986,0,9.99996600832258,,,,,,,,,,,,,,,,,,,,,,,,,,,,,,,,,