File: Experimental_Data/AC_Suceptibillity_FieldScans/ZFCd_Down_20K.dat
[Header]
; MPMS3 Data File (default extension .dat)
; Copyright (c) 2007, Quantum Design, Inc. All rights reserved.
TITLE,ZFCd_Down_20K
FILEOPENTIME,3772415605.94714,07/16/2019,5:13 am
BYAPP,SQUID AC,0.9.1.0
INFO,MPMS3 Measurement Release 1.1.16 Build 347, MultiVu Release 2.3.3.2,APPNAME
INFO,0,MOMENT_UNITS
INFO,Cu2OSeO3,SAMPLE_MATERIAL
INFO,,SAMPLE_COMMENT
INFO,,SAMPLE_MASS
INFO,,SAMPLE_VOLUME
INFO,,SAMPLE_MOLECULAR_WEIGHT
INFO,,SAMPLE_SIZE
INFO,,SAMPLE_SHAPE
INFO,Quartz,SAMPLE_HOLDER
INFO,Standard,SAMPLE_HOLDER_DETAIL
INFO,64.77,SAMPLE_OFFSET
DATATYPE,COMMENT,1
DATATYPE,TIME,2
STARTUPAXIS,X,2
STARTUPAXIS,Y1,5
FIELDGROUP, VSM,2,3,4,5,6,8,9,10,11,14,15
FIELDGROUP, DC, 2,3,4,14,56,57,58,59,60,61,62,63,64,65,66,67,68,69
FIELDGROUP, AC, 2,3,4,11,16,17,18,19,20,21,22,23,24,25,26,27,28,29,30
STARTUPGROUP, All
[Data]
Comment,Time Stamp (sec),Temperature (K),Magnetic Field (Oe),Moment (emu),M. Std. Err. (emu),Transport Action,Averaging Time (sec),Frequency (Hz),Peak Amplitude (mm),Center Position (mm),Lockin Signal' (V),Lockin Signal (V),Range,M. Quad. Signal (emu),AC Moment (emu),AC M. Std Err. (emu),AC Phase (deg),AC Phase Std. Err. (deg),AC Susceptibility (emu/Oe),AC Suscept. Std Err. (emu/Oe),AC X' (emu/Oe),AC X' Std Err. (emu/Oe),AC X'' (emu/Oe),AC X'' Std Err. (emu/Oe),AC Drive (Oe),AC Frequency (Hz),AC Averaging Time (sec),AC Cycles,AC Range,AC Measure Type,AC Signal' (V),AC Signal'' (V),AC Trim Coil Ratio,AC Trim Coil Phase,Min. Temperature (K),Max. Temperature (K),Min. Field (Oe),Max. Field (Oe),Mass (grams),Motor Lag (deg),Pressure (Torr),Measure Count,Measurement Number,SQUID Status (code),Motor Status (code),Measure Status (code),Motor Current (amps),Motor Temp. (C),Temp. Status (code),Field Status (code),Chamber Status (code),Chamber Temp (K),Redirection State,Average Temp (K),Rotation Angle (deg),Rotator state,DC Moment Fixed Ctr (emu),DC Moment Err Fixed Ctr (emu),DC Moment Free Ctr (emu),DC Moment Err Free Ctr (emu),DC Fixed Fit,DC Free Fit,DC Calculated Center (mm),DC Calculated Center Err (mm),DC Scan Length (mm),DC Scan Time (s),DC Number of Points,DC Squid Drift,DC Min V (V),DC Max V (V),DC Scans per Measure,Map 01,Map 02,Map 03,Map 04,Map 05,Map 06,Map 07,Map 08,Map 09,Map 10,Map 11,Map 12,Map 13,Map 14,Map 15,Map 16
,3772415773.27474,19.945951461792,-0.18214213848114,,,5,,,,6.46999990567565,,,,,0.000598636434736073,1.45623870047079E-8,0.0308167982714247,7.73798492642955E-6,0.000598541906291927,1.45600875125508E-8,0.000598541819716564,1.38061067677881E-8,3.21928498933426E-7,4.62466910054934E-9,1.0001579312044,10.005763053894,2,20,1,3,1.9581682892862,0.173162614004981,0.0403775237500668,172.74836730957,19.9455738067627,19.9478569030762,-0.18214213848114,-0.18214213848114,,,23.5404224395752,0,1,,,,,,1,1,1,19.945369720459,0,19.9464440779253,,,,,,,,,,,,,,,,,,,,,,,,,,,,,,,,,
,3772415795.14417,19.9558982849121,-19.9384937286377,,,5,,,,6.46999990567565,,,,,0.000598618618099217,1.25891113593918E-8,0.031988204619398,1.25690679984625E-5,0.000598524025382684,1.25871220489925E-8,0.000598523932103219,1.0093137642502E-8,3.34155642207142E-7,7.52091842833985E-9,1.0001580433074,10.005763053894,2,20,1,3,1.95810388956322,0.173238843015003,0.0403775237500668,172.74836730957,19.9543743133545,19.9597568511963,-19.9384937286377,-19.9384937286377,,,23.5783500671387,0,1,,,,,,1,1,1,19.9565658569336,0,19.9570079803467,,,,,,,,,,,,,,,,,,,,,,,,,,,,,,,,,
,3772415816.86332,19.96351146698,-39.8405570983887,,,5,,,,6.46999990567565,,,,,0.000598650004800969,1.15226207570967E-8,0.0300795790743944,1.64678676253021E-5,0.000598555404040542,1.15207999124011E-8,0.000598555321555995,5.96427876512617E-9,3.14234205943549E-7,9.85678494405996E-9,1.00015804846099,10.005763053894,2,20,1,3,1.95820972620057,0.173224371695171,0.0403775237500668,172.74836730957,19.9631633758545,19.9693832397461,-39.8405570983887,-39.8405570983887,,,23.6697616577148,0,1,,,,,,1,1,1,19.9636249542236,0,19.965255355835,,,,,,,,,,,,,,,,,,,,,,,,,,,,,,,,,
,3772415838.40687,19.9752225875854,-59.9247627258301,,,5,,,,6.46999990567565,,,,,0.000598895313824999,2.40811836859801E-8,0.0306109028192392,1.87012810718913E-5,0.000598800627376757,2.40773764066443E-8,0.000598800541917473,2.13180927511481E-8,3.19915831436569E-7,1.11919156573249E-8,1.0001581268354,10.005763053894,2,20,1,3,1.95900791152485,0.173355564230254,0.0403775237500668,172.74836730957,19.9722175598145,19.987964630127,-59.9247627258301,-59.9247627258301,,,23.7274799346924,0,1,,,,,,1,1,1,19.9773101806641,0,19.9806164828214,,,,,,,,,,,,,,,,,,,,,,,,,,,,,,,,,
,3772415860.36511,19.989426612854,-79.9361114501953,,,5,,,,6.46999990567565,,,,,0.000599388108158941,3.17993899826489E-8,0.0294561697558073,3.97702814219288E-5,0.00059929343435698,3.17943672451125E-8,0.000599293355158509,2.10455783140335E-8,3.08101024339872E-7,2.38320251331053E-8,1.00015797570361,10.005763053894,2,20,1,3,1.96062073843072,0.173500626632772,0.0403775237500668,172.74836730957,19.9880599975586,19.9898071289062,-79.9361114501953,-79.9361114501953,,,23.8353862762451,0,1,,,,,,1,1,1,19.9894523620605,0,19.9889797210693,,,,,,,,,,,,,,,,,,,,,,,,,,,,,,,,,
,3772415881.97697,19.987174987793,-100.03246307373,,,5,,,,6.46999990567565,,,,,0.000600089794110687,2.8727877890611E-8,0.0276805844475465,3.73703433642282E-5,0.000599995002641462,2.87233399734865E-8,0.000599994932621338,1.79540195436977E-8,2.89867976905083E-7,2.24206030573891E-8,1.00015798709791,10.005763053894,2,20,1,3,1.96291872410171,0.173685137819735,0.0403775237500668,172.74836730957,19.9869575500488,19.9874401092529,-100.03246307373,-100.03246307373,,,23.9578189849854,0,1,,,,,,1,1,1,19.9873828887939,0,19.9871473312378,,,,,,,,,,,,,,,,,,,,,,,,,,,,,,,,,
,3772415903.88078,19.9949913024902,-119.84952545166,,,5,,,,6.46999990567565,,,,,0.000601049686967851,4.75761291866131E-8,0.0271304543928688,6.23683901751399E-5,0.000600954597483771,4.75686023719803E-8,0.000600954530111602,2.92940780762777E-8,2.84561460346592E-7,3.74783793844467E-8,1.00015823072904,10.005763053894,2,20,1,3,1.96605764364293,0.173985738093961,0.0403775237500668,172.74836730957,19.9905204772949,20.0003662109375,-119.84952545166,-119.84952545166,,,24.1078681945801,0,1,,,,,,1,1,1,19.9967231750488,0,19.9967454910278,,,,,,,,,,,,,,,,,,,,,,,,,,,,,,,,,
,3772415925.54156,20.0004415512085,-139.970169067383,,,5,,,,6.46999990567565,,,,,0.000602460889664479,5.84385385238771E-8,0.0241473242292463,7.97055511198792E-5,0.000602365702528239,5.84293053981697E-8,0.000602365649032032,3.33019957910105E-8,2.5386720656465E-7,4.80100073489694E-8,1.00015802217132,10.005763053894,2,20,1,3,1.97068017398971,0.174334054608665,0.0403775237500668,172.74836730957,19.9999179840088,20.0006675720215,-139.970169067383,-139.970169067383,,,24.2562923431396,0,1,,,,,,1,1,1,20.0003128051758,0,20.0002910614014,,,,,,,,,,,,,,,,,,,,,,,,,,,,,,,,,
,3772415947.98865,19.9999341964722,-160.05436706543,,,5,,,,6.46999990567565,,,,,0.000604709339302789,4.11177997363862E-8,0.0255815615359092,3.28820455105218E-5,0.00060461381097385,4.1111304194738E-8,0.000604613750709997,3.59900002240235E-8,2.69949462743157E-7,1.98710648045612E-8,1.00015799891965,10.005763053894,2,20,1,3,1.97802792984983,0.17507672255998,0.0403775237500668,172.74836730957,19.9997291564941,20.0002174377441,-160.05436706543,-160.05436706543,,,24.3647308349609,0,1,,,,,,1,1,1,20.0001068115234,0,20.0000834831825,,,,,,,,,,,,,,,,,,,,,,,,,,,,,,,,,
,3772415973.60602,20.0012178421021,-180.053573608398,,,5,,,,6.46999990567565,,,,,0.000609054152696675,5.34722358775995E-8,0.0303156997612328,6.53662868082815E-5,0.000608957902181961,5.3463785512056E-8,0.000608957816941225,3.56959219064107E-8,3.22204955151815E-7,3.98017276073609E-8,1.00015805774811,10.005763053894,2,20,10,3,1.99222274008115,0.176541889965386,0.0403775237500668,172.74836730957,20.0001964569092,20.0013198852539,-180.053573608398,-180.053573608398,,,24.4362335205078,0,1,,,,,,1,1,1,20.0012798309326,0,20.0008309104226,,,,,,,,,,,,,,,,,,,,,,,,,,,,,,,,,
,3772415995.21976,19.999680519104,-199.931350708008,,,5,,,,6.46999990567565,,,,,0.000615841877983501,5.72268169982882E-8,0.0314939754210073,5.5778291266037E-5,0.000615744598160755,5.72177773164918E-8,0.000615744505139904,4.57700094795181E-8,3.38458511750117E-7,3.43362821703874E-8,1.00015798729382,10.005763053894,2,20,10,3,2.01441910761806,0.178593684705522,0.0403775237500668,172.74836730957,19.9992237091064,20.0005054473877,-199.931350708008,-199.931350708008,,,24.5160884857178,0,1,,,,,,1,1,1,20.0000591278076,0,20.0000091552734,,,,,,,,,,,,,,,,,,,,,,,,,,,,,,,,,
,3772416017.11943,20.000584602356,-219.966979980469,,,5,,,,6.46999990567565,,,,,0.000624301838382625,7.12164664331986E-8,0.0362486728201876,5.74908774362951E-5,0.00062420319634597,7.12052139638634E-8,0.000624203071425119,6.15110393386721E-8,3.94907550268848E-7,3.58688518789756E-8,1.00015802872724,10.005763053894,2,20,10,3,2.042073864992,0.181260316405827,0.0403775237500668,172.74836730957,20.0002098083496,20.0008983612061,-219.966979980469,-219.966979980469,,,24.5715923309326,0,1,,,,,,1,1,1,20.0006065368652,0,20.0004610581831,,,,,,,,,,,,,,,,,,,,,,,,,,,,,,,,,
,3772416038.72935,20.0010576248169,-239.941909790039,,,5,,,,6.46999990567565,,,,,0.000633751435448249,1.49765143842006E-7,0.0333540667865675,6.34643552817031E-5,0.000633651359200686,1.49741494296186E-7,0.000633651251833225,1.4426551481132E-7,3.688726942905E-7,4.01245105923998E-8,1.00015793582087,10.005763053894,2,20,10,3,2.07298974803714,0.183943507444609,0.0403775237500668,172.74836730957,19.9999313354492,20.0014591217041,-239.941909790039,-239.941909790039,,,24.6135540008545,0,1,,,,,,1,1,1,20.0011081695557,0,20.0006452560425,,,,,,,,,,,,,,,,,,,,,,,,,,,,,,,,,
,3772416060.65278,20.000301361084,-259.758972167969,,,5,,,,6.46999990567565,,,,,0.00064626309269458,1.93384424707726E-7,0.0514196491215255,9.83074019928754E-5,0.000646160989083522,1.9335387175134E-7,0.000646160728873714,1.82657655534969E-7,5.79892047147041E-7,6.34184562702541E-8,1.00015801574651,10.005763053894,2,20,10,3,2.11385308342995,0.188286313751097,0.0403775237500668,172.74836730957,19.999885559082,20.0006294250488,-259.758972167969,-259.758972167969,,,24.654655456543,0,1,,,,,,1,1,1,20.0005550384521,0,20.0002492904663,,,,,,,,,,,,,,,,,,,,,,,,,,,,,,,,,
,3772416082.28671,19.9998598098755,-279.903900146484,,,5,,,,6.46999990567565,,,,,0.000671960906470633,5.27243062268876E-7,0.138266654115421,0.000382350908673946,0.000671854833407418,5.27159833786184E-7,0.00067185287711,4.60466330271552E-7,1.62132412705412E-6,2.56648103526456E-7,1.00015788092597,10.005763053894,2,20,10,3,2.19760537832017,0.199151953164127,0.0403775237500668,172.74836730957,19.9989452362061,20.0007152557373,-279.903900146484,-279.903900146484,,,24.7216091156006,0,1,,,,,,1,1,1,19.9994297027588,0,19.9998542785645,,,,,,,,,,,,,,,,,,,,,,,,,,,,,,,,,
,3772416104.23361,19.9998846054077,-299.903106689453,,,5,,,,6.46999990567565,,,,,0.000721681316258939,6.6367401619484E-7,0.227264831901462,0.000377190951621225,0.00072156731104326,6.63569174490264E-7,0.000721561634741273,6.05447363754164E-7,2.8621033701833E-6,2.71583392453999E-7,1.00015799664693,10.005763053894,2,20,10,3,2.35987439099849,0.217604204290963,0.0403775237500668,172.74836730957,19.9994506835938,20.0004901885986,-299.903106689453,-299.903106689453,,,24.7375545501709,0,1,,,,,,1,1,1,20.0000820159912,0,19.9999575181441,,,,,,,,,,,,,,,,,,,,,,,,,,,,,,,,,
,3772416125.92259,20.0007972717285,-319.975189208984,,,5,,,,6.46999990567565,,,,,0.000780821913838164,6.39978726732406E-7,0.197314517835258,0.000257019463074034,0.000780698533433517,6.39877601452915E-7,0.000780693904022349,6.07858929187756E-7,2.68855492541977E-6,1.99877129876958E-7,1.0001580384737,10.005763053894,2,20,10,3,2.55338133848481,0.234156660532865,0.0403775237500668,172.74836730957,20.000020980835,20.0010604858398,-319.975189208984,-319.975189208984,,,24.764856338501,0,1,,,,,,1,1,1,20.0009460449219,0,20.0004914023659,,,,,,,,,,,,,,,,,,,,,,,,,,,,,,,,,
,3772416147.79689,20.0022621154785,-339.877227783203,,,5,,,,6.46999990567565,,,,,0.000832169256364639,4.31638142183215E-7,0.116947699902203,0.000261700468259962,0.000832037706538555,4.31569908561147E-7,0.000832035973329433,3.72707375815894E-7,1.69828963448209E-6,2.1758170416629E-7,1.00015810560633,10.005763053894,2,20,10,3,2.72163694958067,0.245795602698996,0.0403775237500668,172.74836730957,19.9995460510254,20.0030689239502,-339.877227783203,-339.877227783203,,,24.7924365997314,0,1,,,,,,1,1,1,20.0030689239502,0,20.0019264221191,,,,,,,,,,,,,,,,,,,,,,,,,,,,,,,,,
,3772416169.42233,20.0008163452148,-359.997863769531,,,5,,,,6.46999990567565,,,,,0.000863199452888936,4.33459018948949E-7,0.0200877083876492,0.000252258364063179,0.000863063153844721,4.33390575844877E-7,0.000863063100801718,3.74791170987009E-7,3.02587044747828E-7,2.17621160233421E-7,1.00015792476322,10.005763053894,2,20,10,3,2.82354540541877,0.250248806895793,0.0403775237500668,172.74836730957,20.0001163482666,20.0016899108887,-359.997863769531,-359.997863769531,,,24.8212261199951,0,1,,,,,,1,1,1,20.0006198883057,0,20.0006060166792,,,,,,,,,,,,,,,,,,,,,,,,,,,,,,,,,
,3772416191.40349,20.0027132034302,-379.984924316406,,,5,,,,6.46999990567565,,,,,0.00087461437398544,2.84307932670186E-7,-0.0305500562310437,0.000263036972645891,0.000874476096333959,2.84262983222296E-7,0.00087447597202664,1.6704914707705E-7,-4.66269817373563E-7,2.30000056720144E-7,1.00015812627934,10.005763053894,2,20,10,3,2.86110307732563,0.251090733660263,0.0403775237500668,172.74836730957,19.9996852874756,20.0038051605225,-379.984924316406,-379.984924316406,,,24.8480606079102,0,1,,,,,,1,1,1,20.003719329834,0,20.0025072097778,,,,,,,,,,,,,,,,,,,,,,,,,,,,,,,,,
,3772416213.05334,19.9993181228638,-400.008422851562,,,5,,,,6.46999990567565,,,,,0.000876153046052348,3.06710443076203E-7,-0.0668496885877206,0.000177711459256728,0.000876014661415789,3.06661999469935E-7,0.000876014065156934,2.64221182044841E-7,-1.02208739500574E-6,1.55655866827194E-7,1.00015797068548,10.005763053894,2,20,10,3,2.86629152134791,0.249778036388804,0.0403775237500668,172.74836730957,19.9987182617187,20.0003147125244,-400.008422851562,-400.008422851562,,,24.8752708435059,0,1,,,,,,1,1,1,19.9993629455566,0,19.9995008468628,,,,,,,,,,,,,,,,,,,,,,,,,,,,,,,,,
,3772416234.94377,20.0005989074707,-419.971221923828,,,5,,,,6.46999990567565,,,,,0.000873030156757991,4.41789694012185E-7,-0.084874807717279,0.000295801175556209,0.000872892214140116,4.41719889290698E-7,0.000872891256410567,3.58414835410303E-7,-1.29305391019997E-6,2.58176812190389E-7,1.00015802938283,10.005763053894,2,20,10,3,2.85614959108735,0.248050230812255,0.0403775237500668,172.74836730957,20.0001335144043,20.0008888244629,-419.971221923828,-419.971221923828,,,24.8772869110107,0,1,,,,,,1,1,1,20.0008888244629,0,20.0005228042603,,,,,,,,,,,,,,,,,,,,,,,,,,,,,,,,,
,3772416256.57456,20.0001974105835,-439.933959960937,,,5,,,,6.46999990567565,,,,,0.000867874824653468,3.00813987647858E-7,-0.0991350398309763,0.000202629551473844,0.000867737712564915,3.00766463243484E-7,0.000867736413689566,2.44027235332436E-7,-1.50138754560384E-6,1.75815738283017E-7,1.00015801098254,10.005763053894,2,20,10,3,2.83934134508228,0.245939463706495,0.0403775237500668,172.74836730957,20.0001049041748,20.0003128051758,-439.933959960937,-439.933959960937,,,24.9040336608887,0,1,,,,,,1,1,1,20.0001907348633,0,20.0002101898193,,,,,,,,,,,,,,,,,,,,,,,,,,,,,,,,,
,3772416278.54679,20.0002965927124,-460.163879394531,,,5,,,,6.46999990567565,,,,,0.000861614935769246,4.18153297723682E-7,-0.111861746382794,0.000352788136436787,0.000861478808740438,4.18087233448746E-7,0.000861477166894545,2.87144072115977E-7,-1.68191206431788E-6,3.03883557668855E-7,1.00015801552798,10.005763053894,2,20,10,3,2.81891195777526,0.243600417473847,0.0403775237500668,172.74836730957,20.0001068115234,20.0007877349854,-460.163879394531,-460.163879394531,,,24.9066162109375,0,1,,,,,,1,1,1,20.0004291534424,0,20.0004034042358,,,,,,,,,,,,,,,,,,,,,,,,,,,,,,,,,
,3772416300.15408,20.0004749298096,-480.150939941406,,,5,,,,6.46999990567565,,,,,0.000855424848878154,3.53493433126109E-7,-0.126387883738036,0.000264425058701688,0.000855289692835439,3.53437581611379E-7,0.000855287611947535,2.71619878938362E-7,-1.8866689224359E-6,2.26143241023936E-7,1.00015802370103,10.005763053894,2,20,10,3,2.79871771722491,0.241200638852188,0.0403775237500668,172.74836730957,20.0001087188721,20.0007343292236,-480.150939941406,-480.150939941406,,,24.9334201812744,0,1,,,,,,1,1,1,20.0004730224609,0,20.0003358840942,,,,,,,,,,,,,,,,,,,,,,,,,,,,,,,,,
,3772416322.02895,20.0004777908325,-500.210906982422,,,5,,,,6.46999990567565,,,,,0.000848834397522824,3.92259674155204E-7,-0.130727327380565,0.000353743768036575,0.000848700282651814,3.92197697572074E-7,0.000848698073570699,2.52408698674115E-7,-1.93641179819237E-6,3.00181416504213E-7,1.00015802383215,10.005763053894,2,20,10,3,2.77717008692819,0.239191642304977,0.0403775237500668,172.74836730957,20.0001392364502,20.0005722045898,-500.210906982422,-500.210906982422,,,24.9475440979004,0,1,,,,,,1,1,1,20.0003871917725,0,20.0003004941073,,,,,,,,,,,,,,,,,,,,,,,,,,,,,,,,,
,3772416343.66738,20.0004119873047,-520.222229003906,,,5,,,,6.46999990567565,,,,,0.000842596792638962,3.73430126759145E-7,-0.157414380507989,0.000284377252633181,0.000842463665842677,3.7337112634893E-7,0.000842460486301491,2.86381790135857E-7,-2.31458111489038E-6,2.39565164975317E-7,1.00015802081642,10.005763053894,2,20,10,3,2.75686900187363,0.236208936534657,0.0403775237500668,172.74836730957,19.9999294281006,20.0005760192871,-520.222229003906,-520.222229003906,,,24.9743976593018,0,1,,,,,,1,1,1,20.0004615783691,0,20.0003171920776,,,,,,,,,,,,,,,,,,,,,,,,,,,,,,,,,
,3772416365.56699,20.0015125274658,-540.355041503906,,,5,,,,6.46999990567565,,,,,0.000836054738079916,6.90574181460913E-7,-0.164142163597069,0.000495116254867072,0.000835922602746432,6.90465038786867E-7,0.000835919172456582,5.52670637978222E-7,-2.39476551493721E-6,4.13880581452785E-7,1.00015807125331,10.005763053894,2,20,10,3,2.73548822827416,0.234112696807415,0.0403775237500668,172.74836730957,20.0001392364502,20.0019626617432,-540.355041503906,-540.355041503906,,,24.976001739502,0,1,,,,,,1,1,1,20.0019035339355,0,20.0014659881592,,,,,,,,,,,,,,,,,,,,,,,,,,,,,,,,,
,3772416387.20164,19.9999465942383,-560.20849609375,,,5,,,,6.46999990567565,,,,,0.000829679102814804,5.9713720118203E-7,-0.189709766751087,0.000510045118576249,0.000829548034650199,5.97042868714561E-7,0.000829543487437578,4.2128262581328E-7,-2.74667834087254E-6,4.23061622309068E-7,1.00015799948783,10.005763053894,2,20,10,3,2.714727773764,0.231173677873412,0.0403775237500668,172.74836730957,19.9988460540771,20.0007572174072,-560.20849609375,-560.20849609375,,,25.0143089294434,0,1,,,,,,1,1,1,20.0007572174072,0,20.0000387191772,,,,,,,,,,,,,,,,,,,,,,,,,,,,,,,,,
,3772416409.11626,20.0002546310425,-580.292724609375,,,5,,,,6.46999990567565,,,,,0.000823373473366854,5.44048006308868E-7,-0.19359190324956,0.000404231693836185,0.000823243389711125,5.43962052903953E-7,0.000823238690478357,4.30286642858594E-7,-2.78158274067672E-6,3.32788401205577E-7,1.00015801360491,10.005763053894,2,20,10,3,2.6941077362377,0.229292104149474,0.0403775237500668,172.74836730957,19.9998550415039,20.0006618499756,-580.292724609375,-580.292724609375,,,25.0161647796631,0,1,,,,,,1,1,1,20.0006484985352,0,20.0001777648926,,,,,,,,,,,,,,,,,,,,,,,,,,,,,,,,,
,3772416430.76874,19.9999952316284,-600.36474609375,,,5,,,,6.46999990567565,,,,,0.000816736174419986,5.38161415738282E-7,-0.2013725452405,0.000345202247734473,0.000816607149088444,5.38076398743488E-7,0.000816602105519187,4.58285489511991E-7,-2.87005295896851E-6,2.8195854480316E-7,1.00015800171684,10.005763053894,2,20,10,3,2.67241773093495,0.227138257311247,0.0403775237500668,172.74836730957,19.9997005462646,20.0003681182861,-600.36474609375,-600.36474609375,,,25.0178413391113,0,1,,,,,,1,1,1,20.0002899169922,0,20.0000623703003,,,,,,,,,,,,,,,,,,,,,,,,,,,,,,,,,
,3772416452.69447,19.9955997467041,-620.473266601562,,,5,,,,6.46999990567565,,,,,0.000810314077451834,3.78898103159393E-7,-0.214672489617331,0.000357189341373213,0.000810186044201399,3.78838235563505E-7,0.000810180357482313,2.44540317210889E-7,-3.03555078074551E-6,2.89341393484008E-7,1.00015802944441,10.005763053894,2,20,10,3,2.65145306644502,0.224793850305505,0.0403775237500668,172.74836730957,19.9942245483398,20.0021667480469,-620.473266601562,-620.473266601562,,,25.0309543609619,0,1,,,,,,1,1,1,19.9969749450684,0,19.9984182357788,,,,,,,,,,,,,,,,,,,,,,,,,,,,,,,,,
,3772416473.32824,20.0003643035889,-640.25390625,,,5,,,,6.46999990567565,,,,,0.000803887185552055,6.32283636910741E-7,-0.244985741896613,0.000504557028382076,0.000803760176469222,6.32183740101515E-7,0.000803752829094648,4.84960111047175E-7,-3.4367135731746E-6,4.05548976008881E-7,1.00015801863112,10.005763053894,2,20,10,3,2.63053781798032,0.221674893220487,0.0403775237500668,172.74836730957,20,20.0006484985352,-640.25390625,-640.25390625,,,25.057731628418,0,1,,,,,,1,1,1,20.0002880096436,0,20.0003140189431,,,,,,,,,,,,,,,,,,,,,,,,,,,,,,,,,
,3772416496.29547,20.0004901885986,-660.277404785156,,,5,,,,6.46999990567565,,,,,0.000796837767362734,6.75888777653515E-7,-0.244986237041402,0.000579157801613654,0.000796711958724147,6.75782065032157E-7,0.000796704675749671,4.93758644628563E-7,-3.40658372552463E-6,4.61393324912369E-7,1.00015790981572,10.005763053894,2,20,10,3,2.60746694779683,0.219786842942516,0.0403775237500668,172.74836730957,19.9998264312744,20.0026111602783,-660.277404785156,-660.277404785156,,,25.0330543518066,0,1,,,,,,1,1,1,19.9999542236328,0,20.0005359649658,,,,,,,,,,,,,,,,,,,,,,,,,,,,,,,,,
,3772416518.08386,20.0007991790771,-680.300903320312,,,5,,,,6.46999990567565,,,,,0.000789955836466799,7.39611364114279E-7,-0.296881528452348,0.000668385850036831,0.000789831012710024,7.39494495468262E-7,0.000789820409818833,5.17902105508025E-7,-4.09253859528038E-6,5.27853689897317E-7,1.00015803856112,10.005763053894,2,20,10,3,2.58514053672763,0.215602639619717,0.0403775237500668,172.74836730957,19.9994850158691,20.0012855529785,-680.300903320312,-680.300903320312,,,25.0598640441895,0,1,,,,,,1,1,1,20.0011558532715,0,20.0008457183838,,,,,,,,,,,,,,,,,,,,,,,,,,,,,,,,,
,3772416539.75116,20.0001649856567,-700.154357910156,,,5,,,,6.46999990567565,,,,,0.000784079202576099,1.05056797298829E-6,-0.412565505861974,0.000692924505534336,0.000783955330189069,1.05040199949719E-6,0.000783935006618545,8.98757423238738E-7,-5.64492071111881E-6,5.43672194176755E-7,1.00015800949654,10.005763053894,2,20,10,3,2.5663330051176,0.208872082380258,0.0403775237500668,172.74836730957,20.0000057220459,20.000394821167,-700.154357910156,-700.154357910156,,,25.048189163208,0,1,,,,,,1,1,1,20.0003929138184,0,20.0002105712891,,,,,,,,,,,,,,,,,,,,,,,,,,,,,,,,,
,3772416561.41264,20.0008010864258,-720.153625488281,,,5,,,,6.46999990567565,,,,,0.000774970909142352,9.52510749493003E-7,-0.432684875169681,0.000711747345743441,0.000774848541911689,9.5236034887639E-7,0.000774826447475458,7.76248270561443E-7,-5.85142676882625E-6,5.51750719584785E-7,1.00015792406392,10.005763053894,2,20,10,3,2.53659042420361,0.205609284152547,0.0403775237500668,172.74836730957,19.9998760223389,20.0017013549805,-720.153625488281,-720.153625488281,,,25.0734767913818,0,1,,,,,,1,1,1,20.0003910064697,0,20.0004523884166,,,,,,,,,,,,,,,,,,,,,,,,,,,,,,,,,
,3772416583.37393,20.0005407333374,-740.189208984375,,,5,,,,6.46999990567565,,,,,0.000764739243795917,9.49872366409543E-7,-0.451028091110524,0.000823059123487044,0.000764618413658437,9.4972228491503E-7,0.00076459472314721,7.11238251589002E-7,-6.01895680219991E-6,6.29374743647093E-7,1.00015802671675,10.005763053894,2,20,10,3,2.50316261350418,0.202146983217158,0.0403775237500668,172.74836730957,20.000093460083,20.0009880065918,-740.189208984375,-740.189208984375,,,25.0878124237061,0,1,,,,,,1,1,1,20.0009880065918,0,20.0004755020142,,,,,,,,,,,,,,,,,,,,,,,,,,,,,,,,,
,3772416604.99023,20.0028591156006,-760.309875488281,,,5,,,,6.46999990567565,,,,,0.000747195401627621,4.51679729334461E-7,-0.178304683677708,0.000489275250221224,0.000747077264083741,4.51608315171944E-7,0.000747073646526503,2.65311318893326E-7,-2.32490353352539E-6,3.65458580963049E-7,1.00015813296637,10.005763053894,2,20,10,3,2.44476672800512,0.209201403318239,0.0403775237500668,172.74836730957,20.0004615783691,20.0041828155518,-760.309875488281,-760.309875488281,,,25.0888481140137,0,1,,,,,,1,1,1,20.0038909912109,0,20.0025324140276,,,,,,,,,,,,,,,,,,,,,,,,,,,,,,,,,
,3772416632.04819,20.0007352828979,-780.175476074219,,,5,,,,6.46999990567565,,,,,0.000734898713103321,9.26389042544756E-7,-0.500203076469076,0.000747832870825677,0.000734782675453014,9.26242769315738E-7,0.000734754674448847,7.4545035379146E-7,-6.41471133091958E-6,5.49753979286986E-7,1.0001579210482,10.005763053894,2,20,10,3,2.4056481713628,0.192297415137704,0.0403775237500668,172.74836730957,20.0000762939453,20.0013198852539,-780.175476074219,-780.175476074219,,,25.1026878356934,0,1,,,,,,1,1,1,20.0005073547363,0,20.0004653930664,,,,,,,,,,,,,,,,,,,,,,,,,,,,,,,,,
,3772416653.65488,20.0009851455688,-800.235412597656,,,5,,,,6.46999990567565,,,,,0.000707420149791547,4.40807398632348E-7,-0.224370140673333,0.000465799467181308,0.000707308442801465,4.40737791811393E-7,0.000707303019507482,2.92808324165326E-7,-2.76981115451875E-6,3.2941324568128E-7,1.00015793249921,10.005763053894,2,20,10,3,2.31477779948662,0.196302954040527,0.0403775237500668,172.74836730957,20.0003089904785,20.0016498565674,-800.235412597656,-800.235412597656,,,25.1154899597168,0,1,,,,,,1,1,1,20.0008869171143,0,20.0006720225016,,,,,,,,,,,,,,,,,,,,,,,,,,,,,,,,,
,3772416680.71545,20.0006160736084,-820.283142089844,,,5,,,,6.46999990567565,,,,,0.000673861136977969,3.65148398086214E-7,-0.241285188809955,0.000410752582949389,0.000673754663414282,3.65090702740563E-7,0.000673748689111773,2.38178089389947E-7,-2.83732138826264E-6,2.76699148828024E-7,1.00015803016954,10.005763053894,2,20,10,3,2.20502034992877,0.186386962268442,0.0403775237500668,172.74836730957,19.9998359680176,20.001012802124,-820.283142089844,-820.283142089844,,,25.1161308288574,0,1,,,,,,1,1,1,20.0005321502686,0,20.000278200422,,,,,,,,,,,,,,,,,,,,,,,,,,,,,,,,,
,3772416707.43209,20.0000228881836,-840.282409667969,,,5,,,,6.46999990567565,,,,,0.000625455366670644,1.13641555976835E-6,-0.695600470119658,0.00105705354752788,0.000625356558468142,1.13623603108454E-6,0.00062531047269817,9.23764463389061E-7,-7.59196635329736E-6,6.61582598406485E-7,1.00015800298432,10.005763053894,2,20,10,3,2.04793131458397,0.156808392654447,0.0403775237500668,172.74836730957,19.9992275238037,20.0004196166992,-840.282409667969,-840.282409667969,,,25.1175479888916,0,1,,,,,,1,1,1,19.999927520752,0,20.0000211542303,,,,,,,,,,,,,,,,,,,,,,,,,,,,,,,,,
,3772416732.54523,20.0007295608521,-860.220825195313,,,5,,,,6.46999990567565,,,,,0.00052663804720849,9.23268312038986E-7,-0.807249234265765,0.00111730330751981,0.000526554832920345,9.23122426044306E-7,0.00052650257207359,7.11144012557233E-7,-7.41846828306572E-6,5.88582370505542E-7,1.00015803537057,10.005763053894,2,20,1,3,1.72462554474912,0.128710185836858,0.0403775237500668,172.74836730957,19.9996910095215,20.0011463165283,-860.220825195313,-860.220825195313,,,25.1178646087646,0,1,,,,,,1,1,1,20.0003566741943,0,20.000311255455,,,,,,,,,,,,,,,,,,,,,,,,,,,,,,,,,
,3772416758.77733,20.0008096694946,-880.329406738281,,,5,,,,6.46999990567565,,,,,0.00038683119146796,4.66848101673381E-7,-0.384108726115773,0.000840688358135913,0.00038677006669719,4.66774333105E-7,0.000386761375405705,3.34913019798536E-7,-2.59287239093906E-6,3.25133122297688E-7,1.00015803904188,10.005763053894,2,20,1,3,1.26605409804227,0.103921487760971,0.0403775237500668,172.74836730957,20.0001564025879,20.001091003418,-880.329406738281,-880.329406738281,,,25.1440868377686,0,1,,,,,,1,1,1,20.0010547637939,0,20.000483921596,,,,,,,,,,,,,,,,,,,,,,,,,,,,,,,,,
,3772416785.80791,20.0015544891357,-899.915710449219,,,5,,,,6.46999990567565,,,,,0.00028893908050263,1.08334133174046E-6,-1.49332185205732,0.00230324575374244,0.000288893414203012,1.08317011160036E-6,0.000288795297118099,8.54058964463686E-7,-7.52868729207872E-6,6.66213761403612E-7,1.00015807317638,10.005763053894,2,20,1,3,0.946989160637438,0.0593218699322524,0.0403775237500668,172.74836730957,20.00071144104,20.0020637512207,-899.915710449219,-899.915710449219,,,25.1451396942139,0,1,,,,,,1,1,1,20.0019359588623,0,20.0012087388472,,,,,,,,,,,,,,,,,,,,,,,,,,,,,,,,,
,3772416807.48943,20,-920.024230957031,,,5,,,,6.46999990567565,,,,,0.000197365051182157,7.30712010305035E-7,-0.803715184684958,0.00124868449848753,0.000197333872048459,7.30596574632266E-7,0.000197314457665014,6.87141317708207E-7,-2.76800541890011E-6,2.48209919952102E-7,1.00015800193537,10.005763053894,2,20,1,3,0.646322804825434,0.0483171810589685,0.0403775237500668,172.74836730957,19.9996814727783,20.0005111694336,-920.024230957031,-920.024230957031,,,25.1718044281006,0,1,,,,,,1,1,1,20.0002880096436,0,20.000139100211,,,,,,,,,,,,,,,,,,,,,,,,,,,,,,,,,
,3772416834.61807,20.0001382827759,-939.865600585938,,,5,,,,6.46999990567565,,,,,0.000145661333539826,9.28988632305581E-7,-2.61713722382643,0.0032208538839142,0.0001456383214802,9.2884186760641E-7,0.00014548641444729,8.00110664881467E-7,-6.6501048744851E-6,4.71773397895113E-7,1.00015800827276,10.005763053894,2,20,1,3,0.477895007899242,0.0205570114997872,0.0403775237500668,172.74836730957,19.9998474121094,20.0007781982422,-939.865600585938,-939.865600585938,,,25.1845436096191,0,1,,,,,,1,1,1,20.0001316070557,0,20.0001055399577,,,,,,,,,,,,,,,,,,,,,,,,,,,,,,,,,
,3772416857.61298,20.0030126571655,-959.937622070312,,,5,,,,6.46999990567565,,,,,0.000110920437465765,1.07938781505225E-6,-4.28492837188658,0.00661781174518444,0.000110902899280933,1.07921714764921E-6,0.000110592905952687,7.90810302484844E-7,-8.28626706405427E-6,7.34390030749282E-7,1.00015814000306,10.005763053894,2,20,1,3,0.364216389864269,0.00506374402663085,0.0403775237500668,172.74836730957,20.000696182251,20.0038738250732,-959.937622070312,-959.937622070312,,,25.1852474212646,0,1,,,,,,1,1,1,20.0038738250732,0,20.0024175643921,,,,,,,,,,,,,,,,,,,,,,,,,,,,,,,,,
,3772416880.62868,19.9999322891235,-980.009704589844,,,5,,,,6.46999990567565,,,,,8.22772927210716E-5,1.30303654000075E-6,-5.33736245427875,0.0096315795269288,8.22642950585175E-5,1.30283069427245E-6,8.19076177910333E-5,1.03252800025399E-6,-7.65221466458032E-6,7.94514786917108E-7,1.00015799883224,10.005763053894,2,20,1,3,0.270187856190598,-0.0012009318475924,0.0403775237500668,172.74836730957,19.9995632171631,20.0004138946533,-980.009704589844,-980.009704589844,,,25.1862163543701,0,1,,,,,,1,1,1,20.0004043579102,0,20.0000110626221,,,,,,,,,,,,,,,,,,,,,,,,,,,,,,,,,
,3772416902.27779,20.0007839202881,-999.863220214844,,,5,,,,6.46999990567565,,,,,6.13279185765069E-5,1.26014038977336E-6,-7.57266037459797,0.0123264605123284,6.13182279748673E-5,1.25994127134881E-6,6.07834432399584E-5,1.00673364320769E-6,-8.08072458833691E-6,7.57587868753077E-7,1.00015803786182,10.005763053894,2,20,1,3,0.201204992037606,-0.00874521881966239,0.0403775237500668,172.74836730957,19.9992771148682,20.0015983581543,-999.863220214844,-999.863220214844,,,25.2252311706543,0,1,,,,,,1,1,1,20.0014400482178,0,20.0010724501176,,,,,,,,,,,,,,,,,,,,,,,,,,,,,,,,,