File: Experimental_Data/AC_Suceptibillity_FieldScans/ZFCd_Down_5K.dat
[Header]
; MPMS3 Data File (default extension .dat)
; Copyright (c) 2007, Quantum Design, Inc. All rights reserved.
TITLE,ZFCd_Down_5K
FILEOPENTIME,3772370672.62216,07/15/2019,4:44 pm
BYAPP,SQUID AC,0.9.1.0
INFO,MPMS3 Measurement Release 1.1.16 Build 347, MultiVu Release 2.3.3.2,APPNAME
INFO,0,MOMENT_UNITS
INFO,Cu2OSeO3,SAMPLE_MATERIAL
INFO,,SAMPLE_COMMENT
INFO,,SAMPLE_MASS
INFO,,SAMPLE_VOLUME
INFO,,SAMPLE_MOLECULAR_WEIGHT
INFO,,SAMPLE_SIZE
INFO,,SAMPLE_SHAPE
INFO,Quartz,SAMPLE_HOLDER
INFO,Standard,SAMPLE_HOLDER_DETAIL
INFO,64.77,SAMPLE_OFFSET
DATATYPE,COMMENT,1
DATATYPE,TIME,2
STARTUPAXIS,X,2
STARTUPAXIS,Y1,5
FIELDGROUP, VSM,2,3,4,5,6,8,9,10,11,14,15
FIELDGROUP, DC, 2,3,4,14,56,57,58,59,60,61,62,63,64,65,66,67,68,69
FIELDGROUP, AC, 2,3,4,11,16,17,18,19,20,21,22,23,24,25,26,27,28,29,30
STARTUPGROUP, All
[Data]
Comment,Time Stamp (sec),Temperature (K),Magnetic Field (Oe),Moment (emu),M. Std. Err. (emu),Transport Action,Averaging Time (sec),Frequency (Hz),Peak Amplitude (mm),Center Position (mm),Lockin Signal' (V),Lockin Signal (V),Range,M. Quad. Signal (emu),AC Moment (emu),AC M. Std Err. (emu),AC Phase (deg),AC Phase Std. Err. (deg),AC Susceptibility (emu/Oe),AC Suscept. Std Err. (emu/Oe),AC X' (emu/Oe),AC X' Std Err. (emu/Oe),AC X'' (emu/Oe),AC X'' Std Err. (emu/Oe),AC Drive (Oe),AC Frequency (Hz),AC Averaging Time (sec),AC Cycles,AC Range,AC Measure Type,AC Signal' (V),AC Signal'' (V),AC Trim Coil Ratio,AC Trim Coil Phase,Min. Temperature (K),Max. Temperature (K),Min. Field (Oe),Max. Field (Oe),Mass (grams),Motor Lag (deg),Pressure (Torr),Measure Count,Measurement Number,SQUID Status (code),Motor Status (code),Measure Status (code),Motor Current (amps),Motor Temp. (C),Temp. Status (code),Field Status (code),Chamber Status (code),Chamber Temp (K),Redirection State,Average Temp (K),Rotation Angle (deg),Rotator state,DC Moment Fixed Ctr (emu),DC Moment Err Fixed Ctr (emu),DC Moment Free Ctr (emu),DC Moment Err Free Ctr (emu),DC Fixed Fit,DC Free Fit,DC Calculated Center (mm),DC Calculated Center Err (mm),DC Scan Length (mm),DC Scan Time (s),DC Number of Points,DC Squid Drift,DC Min V (V),DC Max V (V),DC Scans per Measure,Map 01,Map 02,Map 03,Map 04,Map 05,Map 06,Map 07,Map 08,Map 09,Map 10,Map 11,Map 12,Map 13,Map 14,Map 15,Map 16
,3772370889.18578,4.99995350837708,0.157856523990631,,,5,,,,6.47999998182058,,,,,0.000593778179585341,1.09635439294483E-8,0.030467058152432,1.14337975376569E-5,0.000593682917574774,1.09617850078955E-8,0.000593682833640309,8.60836913500017E-9,3.15691160416346E-7,6.7865095148315E-9,1.00016045940981,10.005763053894,2,20,1,3,1.94227399461213,0.171787329616727,0.0403775237500668,172.74836730957,4.99868965148926,5.00136280059814,0.157856523990631,0.157856523990631,,,10.6839866638184,0,1,,,,,,1,1,1,4.9998927116394,0,4.99993239916288,,,,,,,,,,,,,,,,,,,,,,,,,,,,,,,,,
,3772370913.96083,5.00008988380432,-19.8656349182129,,,5,,,,6.47999998182058,,,,,0.000593691128425571,1.00018007040975E-8,0.0323719658138799,1.24194816114141E-5,0.000593595876669014,1.00001960160027E-8,0.000593595781924571,6.75763580339122E-9,3.35380102474166E-7,7.3714502445042E-9,1.0001604656641,10.005763053894,2,20,1,3,1.94198097642171,0.171867670865029,0.0403775237500668,172.74836730957,4.9994068145752,5.00140571594238,-19.8656349182129,-19.8656349182129,,,10.6999368667603,0,1,,,,,,1,1,1,5.00015687942505,0,5.00014233589172,,,,,,,,,,,,,,,,,,,,,,,,,,,,,,,,,
,3772370937.05448,5.00001096725464,-39.8405570983887,,,5,,,,6.47999998182058,,,,,0.000593449839960523,1.7520589394342E-8,0.0311193651444306,2.08762443364302E-5,0.00059335462906338,1.75177784557886E-8,0.000593354541544748,1.23883899951322E-8,3.22271877807405E-7,1.23854897099226E-8,1.00016046204492,10.005763053894,2,20,1,3,1.94119287807347,0.171796882170354,0.0403775237500668,172.74836730957,4.99972772598267,5.0007848739624,-39.8405570983887,-39.8405570983887,,,10.7140073776245,0,1,,,,,,1,1,1,4.99996948242188,0,5.00008217493693,,,,,,,,,,,,,,,,,,,,,,,,,,,,,,,,,
,3772370960.95035,4.99991297721863,-59.8397636413574,,,5,,,,6.47999998182058,,,,,0.000593139609683906,2.55243185988127E-8,0.0331298643374902,2.80413568916862E-5,0.000593044519119789,2.55202266079649E-8,0.000593044419979236,1.93606690463442E-8,3.42913274531974E-7,1.66266791693293E-8,1.00016034304517,10.005763053894,2,20,1,3,1.94016948262667,0.17181668260872,0.0403775237500668,172.74836730957,4.99895191192627,5.00147819519043,-59.8397636413574,-59.8397636413574,,,10.7270259857178,0,1,,,,,,1,1,1,5.00027513504028,0,5.00006327262292,,,,,,,,,,,,,,,,,,,,,,,,,,,,,,,,,
,3772370985.72197,5.00003004074097,-79.9361114501953,,,5,,,,6.47999998182058,,,,,0.000592840082292652,3.22369956812867E-8,0.0303817218381166,2.95659256222101E-5,0.00059274503656625,3.22318273588958E-8,0.000592744953233172,2.705521406944E-8,3.1430960763583E-7,1.75187353011123E-8,1.0001603484138,10.005763053894,2,20,1,3,1.93919535178212,0.171678615160585,0.0403775237500668,172.74836730957,4.99869108200073,5.00108289718628,-79.9361114501953,-79.9361114501953,,,10.740216255188,0,1,,,,,,1,1,1,5.00024843215942,0,5.00002821286519,,,,,,,,,,,,,,,,,,,,,,,,,,,,,,,,,
,3772371009.95844,5.00025701522827,-99.9474563598633,,,5,,,,6.47999998182058,,,,,0.000592950219589045,6.07151010009974E-8,0.0265309752625473,7.90946145480951E-5,0.000592855082160463,6.07053594098916E-8,0.000592855018601075,3.85567157300369E-8,2.74523238721026E-7,4.68883816440409E-8,1.00016047332889,10.005763053894,2,20,1,3,1.93956455571703,0.17162169597829,0.0403775237500668,172.74836730957,4.99878835678101,5.00112104415894,-99.9474563598633,-99.9474563598633,,,10.7526998519897,0,1,,,,,,1,1,1,5.00013399124146,0,5.00004947185516,,,,,,,,,,,,,,,,,,,,,,,,,,,,,,,,,
,3772371034.55764,5.00001001358032,-119.91024017334,,,5,,,,6.47999998182058,,,,,0.000593379149011208,6.23088183462645E-8,0.0315831984214219,7.23919932258714E-5,0.000593283949481403,6.22988217526546E-8,0.000593283859345141,4.51336816470891E-8,3.2703636999139E-7,4.29429152800348E-8,1.00016046200118,10.005763053894,2,20,1,3,1.94094985564925,0.171958463524803,0.0403775237500668,172.74836730957,4.99916791915894,5.00078439712524,-119.91024017334,-119.91024017334,,,10.774284362793,0,1,,,,,,1,1,1,5.00012922286987,0,5.00004210838905,,,,,,,,,,,,,,,,,,,,,,,,,,,,,,,,,
,3772371058.56513,4.99993944168091,-139.897308349609,,,5,,,,6.47999998182058,,,,,0.000594295311666177,5.5969997522547E-8,0.0300846746983199,3.96755578090719E-5,0.000594199967073477,5.59610180867136E-8,0.00059419988516139,5.07609595337876E-8,3.12000500658926E-7,2.35576003130766E-8,1.0001604587647,10.005763053894,2,20,1,3,1.94394853656207,0.1722147055383,0.0403775237500668,172.74836730957,4.99842596054077,5.00117969512939,-139.897308349609,-139.897308349609,,,10.7921133041382,0,1,,,,,,1,1,1,4.99980783462524,0,4.99992631031917,,,,,,,,,,,,,,,,,,,,,,,,,,,,,,,,,
,3772371083.40089,5.00012946128845,-159.93293762207,,,5,,,,6.47999998182058,,,,,0.000595320212841237,5.51869410464803E-8,0.0253499545222544,7.09487758293574E-5,0.000595224698634315,5.51780867579936E-8,0.000595224640375715,3.55172953101859E-8,2.63351309238631E-7,4.22272778204056E-8,1.00016046747916,10.005763053894,2,20,1,3,1.94731264291298,0.172392539203391,0.0403775237500668,172.74836730957,4.99964237213135,5.00069522857666,-159.93293762207,-159.93293762207,,,10.8149709701538,0,1,,,,,,1,1,1,5.00018119812012,0,5.00004124641418,,,,,,,,,,,,,,,,,,,,,,,,,,,,,,,,,
,3772371106.7322,4.99984955787659,-179.847152709961,,,5,,,,6.47999998182058,,,,,0.00059665258478929,7.04166857673357E-8,0.0261485861065687,0.000106418581299338,0.000596556864470841,7.04053888958268E-8,0.000596556802344897,3.04397422587494E-8,2.72255969447397E-7,6.34849657540548E-8,1.00016045464255,10.005763053894,2,20,1,3,1.95166586745437,0.172847168571304,0.0403775237500668,172.74836730957,4.99901866912842,5.00203084945679,-179.847152709961,-179.847152709961,,,10.8276529312134,0,1,,,,,,1,1,1,4.99972009658814,0,4.99999636870164,,,,,,,,,,,,,,,,,,,,,,,,,,,,,,,,,
,3772371132.04652,4.99966835975647,-199.894912719727,,,5,,,,6.47999998182058,,,,,0.000598495941577144,1.2915265334983E-7,0.0220754323459804,6.54118888760904E-5,0.000598399930502836,1.29131934604495E-7,0.00059839988608732,1.23075659364357E-7,2.30556892097226E-7,3.90824590670571E-8,1.00016044633265,10.005763053894,2,20,1,3,1.95770523111729,0.173284012401327,0.0403775237500668,172.74836730957,4.99924182891846,5.00073528289795,-199.894912719727,-199.894912719727,,,10.8465213775635,0,1,,,,,,1,1,1,4.99961709976196,0,4.99985432624817,,,,,,,,,,,,,,,,,,,,,,,,,,,,,,,,,
,3772371155.47514,4.99983978271484,-219.94270324707,,,5,,,,6.47999998182058,,,,,0.000601410972216995,1.08140104573958E-7,0.0248698949015722,6.16275260940601E-5,0.000601314488785204,1.08122755824292E-7,0.000601314432138545,1.0159001761374E-7,2.61007491238814E-7,3.70134927868134E-8,1.00016045419425,10.005763053894,2,20,1,3,1.96722928319856,0.174266165024617,0.0403775237500668,172.74836730957,4.99925756454468,5.00137090682983,-219.94270324707,-219.94270324707,,,10.8629903793335,0,1,,,,,,1,1,1,5.00005388259888,0,5.00011242352999,,,,,,,,,,,,,,,,,,,,,,,,,,,,,,,,,
,3772371180.77037,5.00007271766663,-239.893341064453,,,5,,,,6.47999998182058,,,,,0.00060587375997102,1.86966303081633E-7,0.0275271973580287,0.00011162733006057,0.000605776554110868,1.86936306370253E-7,0.000605776484197345,1.7430533694049E-7,2.91039414422508E-7,6.75487390956744E-8,1.00016046487685,10.005763053894,2,20,1,3,1.98181637188292,0.175693543611199,0.0403775237500668,172.74836730957,4.99918460845947,5.00061368942261,-239.893341064453,-239.893341064453,,,10.8849802017212,0,1,,,,,,1,1,1,5.0000901222229,0,5.00004494190216,,,,,,,,,,,,,,,,,,,,,,,,,,,,,,,,,
,3772371204.18727,4.99994730949402,-259.79541015625,,,5,,,,6.47999998182058,,,,,0.000611471782395503,2.56399248231145E-7,0.0330587324969995,9.41639076757839E-5,0.000611373681909137,2.56358113232475E-7,0.000611373580142865,2.49854003233617E-7,3.52752646988661E-7,5.73799554570224E-8,1.00016045912552,10.005763053894,2,20,1,3,2.00010773304127,0.177552581969271,0.0403775237500668,172.74836730957,4.99937677383423,5.00099515914917,-259.79541015625,-259.79541015625,,,10.9039268493652,0,1,,,,,,1,1,1,4.99979639053345,0,5.0000402377202,,,,,,,,,,,,,,,,,,,,,,,,,,,,,,,,,
,3772371229.54103,4.999915599823,-279.891754150391,,,5,,,,6.47999998182058,,,,,0.000618832387462455,2.68249197282541E-7,0.0328980310312064,0.000357945662612848,0.000618733106988958,2.68206161546434E-7,0.000618733004996539,1.5128553099776E-7,3.55263511698272E-7,2.21466099442325E-7,1.00016045767129,10.005763053894,2,20,1,3,2.02418184606656,0.179727734938614,0.0403775237500668,172.74836730957,4.99922132492065,5.00078058242798,-279.891754150391,-279.891754150391,,,10.9200439453125,0,1,,,,,,1,1,1,4.99999856948853,0,4.99997278054555,,,,,,,,,,,,,,,,,,,,,,,,,,,,,,,,,
,3772371253.9848,5.0002121925354,-299.878814697266,,,5,,,,6.47999998182058,,,,,0.000633771151297113,7.19518680948638E-7,0.104153569384716,0.000710088837403194,0.000633669538098361,7.19403319757799E-7,0.000633668491124676,5.61423216168004E-7,1.1518982447835E-6,4.4982786577325E-7,1.00016035676743,10.005763053894,2,20,1,3,2.07281273164537,0.18668873584092,0.0403775237500668,172.74836730957,4.99909639358521,5.0013542175293,-299.878814697266,-299.878814697266,,,10.9406795501709,0,1,,,,,,1,1,1,5.00032186508179,0,5.00001720587413,,,,,,,,,,,,,,,,,,,,,,,,,,,,,,,,,
,3772371278.23899,4.99946236610413,-319.878021240234,,,5,,,,6.47999998182058,,,,,0.00067856997128304,1.61969489613977E-6,0.169060892885823,0.00131750329447217,0.000678461121093765,1.61943507901925E-6,0.000678458167602391,1.35078334255013E-6,2.00191144016511E-6,8.93282898441013E-7,1.00016043688561,10.005763053894,2,20,1,3,2.21910084981951,0.202446574135714,0.0403775237500668,172.74836730957,4.9985523223877,5.00066375732422,-319.878021240234,-319.878021240234,,,10.957462310791,0,1,,,,,,1,1,1,4.99967241287231,0,4.99948488871256,,,,,,,,,,,,,,,,,,,,,,,,,,,,,,,,,
,3772371304.14705,4.99852728843689,-339.840789794922,,,5,,,,6.47999998182058,,,,,0.000737235108881147,2.68114265042992E-6,0.197758404074037,0.00206882741528755,0.000737116879754742,2.6807126801945E-6,0.000737112489087117,2.20537427709942E-6,2.54417986044607E-6,1.52398975444844E-6,1.00016039400216,10.005763053894,2,20,10,3,2.4108373037358,0.221207957187353,0.0403775237500668,172.74836730957,4.99516344070435,4.99941873550415,-339.840789794922,-339.840789794922,,,10.964430809021,0,1,,,,,,1,1,1,4.99820613861084,0,4.99693639461811,,,,,,,,,,,,,,,,,,,,,,,,,,,,,,,,,
,3772371329.51827,4.99977970123291,-359.888580322266,,,5,,,,6.47999998182058,,,,,0.000790971921359773,4.1112733835881E-6,0.21063392624534,0.00317575956194234,0.000790845029136928,4.11061382968451E-6,0.000790839685065111,3.25503782825327E-6,2.90734186252307E-6,2.51035351961308E-6,1.00016045143887,10.005763053894,2,20,10,3,2.58650534361106,0.237968474725535,0.0403775237500668,172.74836730957,4.99608135223389,5.00132131576538,-359.888580322266,-359.888580322266,,,10.9538583755493,0,1,,,,,,1,1,1,4.99989461898804,0,4.99974795182546,,,,,,,,,,,,,,,,,,,,,,,,,,,,,,,,,
,3772371353.51044,4.99909973144531,-379.912048339844,,,5,,,,6.47999998182058,,,,,0.000831473454788088,1.71425587274395E-6,0.0974718394899368,0.00116627096717364,0.000831340090998799,1.71398091548863E-6,0.000831338888009723,1.41369103971034E-6,1.41427884416907E-6,9.69127557601137E-7,1.00016042025488,10.005763053894,2,20,10,3,2.71943178191883,0.244841335622082,0.0403775237500668,172.74836730957,4.99758005142212,5.00020885467529,-379.912048339844,-379.912048339844,,,10.9366340637207,0,1,,,,,,1,1,1,4.99897003173828,0,4.99918482853816,,,,,,,,,,,,,,,,,,,,,,,,,,,,,,,,,
,3772371378.3764,4.99944281578064,-399.789825439453,,,5,,,,6.47999998182058,,,,,0.000852826667135118,1.28181957243681E-6,0.0247836904999925,0.000508984988121415,0.000852689864993304,1.28161395543434E-6,0.000852689785221799,1.20608290478263E-6,3.68836958447148E-7,4.33472441517487E-7,1.00016043598902,10.005763053894,2,20,10,3,2.78958260229425,0.24764969315293,0.0403775237500668,172.74836730957,4.9987359046936,5.00033712387085,-399.789825439453,-399.789825439453,,,10.9325952529907,0,1,,,,,,1,1,1,4.99938011169434,0,4.99954216296856,,,,,,,,,,,,,,,,,,,,,,,,,,,,,,,,,
,3772371402.29785,4.99975085258484,-419.837615966797,,,5,,,,6.47999998182058,,,,,0.000858998203492463,4.00966772075957E-7,-0.00359152138615659,0.000379356864954959,0.000858860399241912,4.00902447231857E-7,0.000858860397554565,2.33626681827668E-7,-5.38366964511925E-8,3.25793409593696E-7,1.00016045011584,10.005763053894,2,20,10,3,2.80988903620201,0.248110572565861,0.0403775237500668,172.74836730957,4.99880504608154,5.00091075897217,-419.837615966797,-419.837615966797,,,10.9329891204834,0,1,,,,,,1,1,1,4.99978685379028,0,4.99970982624934,,,,,,,,,,,,,,,,,,,,,,,,,,,,,,,,,
,3772371427.02575,4.99976301193237,-439.90966796875,,,5,,,,6.47999998182058,,,,,0.000857540803996126,5.88935801873305E-7,-0.0624071097593539,0.000591857860794085,0.000857403233069936,5.88841321886635E-7,0.000857402724468066,2.98781746769031E-7,-9.33891598104155E-7,5.07408681595858E-7,1.00016045067348,10.005763053894,2,20,10,3,2.80537079326752,0.244870226512571,0.0403775237500668,172.74836730957,4.99906826019287,5.00122308731079,-439.90966796875,-439.90966796875,,,10.9320020675659,0,1,,,,,,1,1,1,4.99987125396729,0,4.99991424878438,,,,,,,,,,,,,,,,,,,,,,,,,,,,,,,,,
,3772371450.50504,4.9998185634613,-460.224609375,,,5,,,,6.47999998182058,,,,,0.000850856724764673,3.70031584152197E-7,-0.0682528223454284,0.000336432776146266,0.000850720223964465,3.69972220917626E-7,0.000850719620359679,2.34481510525996E-7,-1.01340872002753E-6,2.86178031078851E-7,1.00016045322112,10.005763053894,2,20,10,3,2.78352547663691,0.242738117126951,0.0403775237500668,172.74836730957,4.99912118911743,5.00087022781372,-460.224609375,-460.224609375,,,10.9434080123901,0,1,,,,,,1,1,1,4.99986982345581,0,4.99988812666673,,,,,,,,,,,,,,,,,,,,,,,,,,,,,,,,,
,3772371475.7994,4.99988889694214,-480.150939941406,,,5,,,,6.47999998182058,,,,,0.000843908402488088,6.4970547853351E-7,-0.104638784430514,0.000540126481431348,0.000843773013668516,6.4960124582585E-7,0.000843771606533982,4.62952786697073E-7,-1.54097446889779E-6,4.55693423112417E-7,1.00016045644667,10.005763053894,2,20,10,3,2.76094323849264,0.239061427432679,0.0403775237500668,172.74836730957,4.99932670593262,5.00053310394287,-480.150939941406,-480.150939941406,,,10.9486198425293,0,1,,,,,,1,1,1,4.99985980987549,0,4.99988241990407,,,,,,,,,,,,,,,,,,,,,,,,,,,,,,,,,
,3772371499.97163,5.00010991096497,-500.162292480469,,,5,,,,6.47999998182058,,,,,0.000835410572286612,5.88647438084663E-7,-0.116141462928397,0.000281104951403525,0.000835276633943726,5.88553062378852E-7,0.000835274917895425,5.39670939513835E-7,-1.69314711494911E-6,2.34840337846333E-7,1.00016035207672,10.005763053894,2,20,10,3,2.73318553279553,0.236163997063685,0.0403775237500668,172.74836730957,4.99892282485962,5.00129699707031,-500.162292480469,-500.162292480469,,,10.9545621871948,0,1,,,,,,1,1,1,5.0000433921814,0,5.00014499823252,,,,,,,,,,,,,,,,,,,,,,,,,,,,,,,,,
,3772371524.60542,5.00006461143494,-520.185791015625,,,5,,,,6.47999998182058,,,,,0.000826731517473206,3.4831565414659E-7,-0.119331485322989,0.000322524066560086,0.000826598877693391,3.48259770814824E-7,0.000826597084903121,2.24118695175811E-7,-1.72157882077207E-6,2.66562710146573E-7,1.00016046450509,10.005763053894,2,20,10,3,2.70480006265534,0.233617865506561,0.0403775237500668,172.74836730957,4.99944543838501,5.00132274627686,-520.185791015625,-520.185791015625,,,10.9598989486694,0,1,,,,,,1,1,1,5.00003099441528,0,5.00004827059232,,,,,,,,,,,,,,,,,,,,,,,,,,,,,,,,,
,3772371548.53485,5.0000011920929,-540.209289550781,,,5,,,,6.47999998182058,,,,,0.00081821626775997,4.39761886048554E-7,-0.131815443034554,0.000343632886231899,0.000818084996535253,4.39691332475324E-7,0.000818082831546905,3.38098470880027E-7,-1.88209571539694E-6,2.81101212808684E-7,1.00016046159662,10.005763053894,2,20,10,3,2.6769877639625,0.230685717627791,0.0403775237500668,172.74836730957,4.99871015548706,5.00138282775879,-540.209289550781,-540.209289550781,,,10.9735460281372,0,1,,,,,,1,1,1,5.0000205039978,0,5.0000419983497,,,,,,,,,,,,,,,,,,,,,,,,,,,,,,,,,
,3772371573.32143,5.00000190734863,-560.159912109375,,,5,,,,6.47999998182058,,,,,0.000809648048432662,7.1983534813575E-7,-0.127604749276871,0.000285096990997325,0.00080951815183097,7.1971986071417E-7,0.000809516144195646,6.81670554229441E-7,-1.80289501744655E-6,2.30915424783515E-7,1.00016046162943,10.005763053894,2,20,10,3,2.6489346210461,0.228521247320208,0.0403775237500668,172.74836730957,4.99933099746704,5.00074911117554,-560.159912109375,-560.159912109375,,,10.9870853424072,0,1,,,,,,1,1,1,5.00003671646118,0,4.99997572104136,,,,,,,,,,,,,,,,,,,,,,,,,,,,,,,,,
,3772371597.49987,4.99994301795959,-580.183410644531,,,5,,,,6.47999998182058,,,,,0.000801043904788159,4.89554119516072E-7,-0.144212104131986,0.000477286106596029,0.000800915390762571,4.89475578789071E-7,0.000800912853796982,3.05782500412835E-7,-2.01588271878645E-6,3.82208587910018E-7,1.00016045892871,10.005763053894,2,20,10,3,2.6208464031341,0.225389259367157,0.0403775237500668,172.74836730957,4.99878263473511,5.00123453140259,-580.183410644531,-580.183410644531,,,10.9901132583618,0,1,,,,,,1,1,1,4.99988460540771,0,4.99990753332774,,,,,,,,,,,,,,,,,,,,,,,,,,,,,,,,,
,3772371621.98247,4.99989819526672,-600.291870117187,,,5,,,,6.47999998182058,,,,,0.000792660530812292,6.98652665936017E-7,-0.165649734274277,0.00050093949754792,0.000792533363386974,6.98540580298767E-7,0.000792530051134158,5.74739034232663E-7,-2.29131638094318E-6,3.97031465822854E-7,1.0001604568731,10.005763053894,2,20,10,3,2.59349771454399,0.222115884608552,0.0403775237500668,172.74836730957,4.99947500228882,5.00066804885864,-600.291870117187,-600.291870117187,,,10.99951171875,0,1,,,,,,1,1,1,4.99987888336182,0,4.99992148081462,,,,,,,,,,,,,,,,,,,,,,,,,,,,,,,,,
,3772371646.27278,5.00004267692566,-620.30322265625,,,5,,,,6.47999998182058,,,,,0.000783968415682263,3.73605034262878E-7,-0.165577894429227,0.000271871462801173,0.000783842637549857,3.73545093910018E-7,0.000783839364459218,3.06786804931717E-7,-2.26520755877294E-6,2.13114507962346E-7,1.00016046349915,10.005763053894,2,20,10,3,2.56505452232704,0.219738367062813,0.0403775237500668,172.74836730957,4.99809312820435,5.00138187408447,-620.30322265625,-620.30322265625,,,11.0077905654907,0,1,,,,,,1,1,1,5.00002813339233,0,4.99995823701223,,,,,,,,,,,,,,,,,,,,,,,,,,,,,,,,,
,3772371670.73572,5.00001645088196,-640.156799316406,,,5,,,,6.47999998182058,,,,,0.000775474719749349,6.71428505740331E-7,-0.168565566174129,0.000617268874401537,0.00077535030525885,6.71320784065696E-7,0.000775346949736655,4.7081381476758E-7,-2.28109602065039E-6,4.78545658158738E-7,1.0001604622964,10.005763053894,2,20,10,3,2.53727224300071,0.217279275318391,0.0403775237500668,172.74836730957,4.99955081939697,5.00178098678589,-640.156799316406,-640.156799316406,,,11.0169382095337,0,1,,,,,,1,1,1,4.99996185302734,0,5.00013077259064,,,,,,,,,,,,,,,,,,,,,,,,,,,,,,,,,
,3772371693.95873,4.9999988079071,-660.240966796875,,,5,,,,6.47999998182058,,,,,0.000766458562314423,4.6234106564587E-7,-0.168741361327899,0.000397054843404928,0.000766335594965098,4.62266889613241E-7,0.000766332271535213,3.48019364164536E-7,-2.25692582759076E-6,3.04258441787919E-7,1.00016046148728,10.005763053894,2,20,10,3,2.50776976314811,0.214799256834413,0.0403775237500668,172.74836730957,4.99947166442871,5.00092363357544,-660.240966796875,-660.240966796875,,,11.025842666626,0,1,,,,,,1,1,1,5.00010871887207,0,5.00004319349925,,,,,,,,,,,,,,,,,,,,,,,,,,,,,,,,,
,3772371717.80671,4.99986338615417,-680.203735351562,,,5,,,,6.47999998182058,,,,,0.00075795370412416,3.42366184197221E-7,-0.201428835836446,0.000266910671683244,0.000757832105963885,3.42311258549504E-7,0.000757827422786821,2.76146323862429E-7,-2.66422633078066E-6,2.02287432993281E-7,1.00016045527673,10.005763053894,2,20,10,3,2.4800604348086,0.211053910736077,0.0403775237500668,172.74836730957,4.99882650375366,5.00141477584839,-680.203735351562,-680.203735351562,,,11.0352029800415,0,1,,,,,,1,1,1,4.99981021881103,0,4.99991809404813,,,,,,,,,,,,,,,,,,,,,,,,,,,,,,,,,
,3772371742.51303,5.00010204315186,-700.057189941406,,,5,,,,6.47999998182058,,,,,0.000749663217446624,4.99175637692432E-7,-0.323575099323676,0.000408193857499806,0.00074954302693612,4.99095606855479E-7,0.00074953107411721,3.94277631167255E-7,-4.23298491156673E-6,3.0600910826898E-7,1.00016035171589,10.005763053894,2,20,10,3,2.45337004133577,0.203567760988341,0.0403775237500668,172.74836730957,4.99943351745605,5.00101137161255,-700.057189941406,-700.057189941406,,,11.0449495315552,0,1,,,,,,1,1,1,5.00009107589722,0,5.00017885367076,,,,,,,,,,,,,,,,,,,,,,,,,,,,,,,,,
,3772371765.81219,5.00010538101196,-720.153625488281,,,5,,,,6.47999998182058,,,,,0.00073864324635305,7.57107637299911E-7,-0.359605097517238,0.000460649341030332,0.000738524737965638,7.56986166473992E-7,0.000738510192084318,6.76023022352953E-7,-4.63516718122448E-6,3.40618451469926E-7,1.00016046637481,10.005763053894,2,20,10,3,2.41742848060848,0.199107180437468,0.0403775237500668,172.74836730957,4.99944686889648,5.0014328956604,-720.153625488281,-720.153625488281,,,11.0517654418945,0,1,,,,,,1,1,1,5.00004720687866,0,5.00017026754526,,,,,,,,,,,,,,,,,,,,,,,,,,,,,,,,,
,3772371791.2357,5.00009059906006,-740.140686035156,,,5,,,,6.47999998182058,,,,,0.000726163470464441,6.70054507211945E-7,-0.308563221580128,0.000617917648750803,0.000726046964832246,6.69947003699109E-7,0.00072603643608441,4.97552269404012E-7,-3.91006649114172E-6,4.48632061913024E-7,1.0001604656969,10.005763053894,2,20,10,3,2.37640649197314,0.197911085412525,0.0403775237500668,172.74836730957,4.99920463562012,5.0009617805481,-740.140686035156,-740.140686035156,,,11.0604820251465,0,1,,,,,,1,1,1,4.99995136260986,0,5.00003496805827,,,,,,,,,,,,,,,,,,,,,,,,,,,,,,,,,
,3772371814.64692,5.00009226799011,-760.224853515625,,,5,,,,6.47999998182058,,,,,0.000711722974363845,4.46607240699593E-7,-0.275026007837567,0.000395793560813484,0.000711608785509691,4.46535587021253E-7,0.000711600587418657,3.46492601099326E-7,-3.41578687855807E-6,2.8166808100997E-7,1.00016046577344,10.005763053894,2,20,10,3,2.32903240555834,0.195388779325752,0.0403775237500668,172.74836730957,4.9994969367981,5.00186252593994,-760.224853515625,-760.224853515625,,,11.070182800293,0,1,,,,,,1,1,1,5.00011539459229,0,5.00023144942064,,,,,,,,,,,,,,,,,,,,,,,,,,,,,,,,,
,3772371840.03439,5.00002598762512,-780.11474609375,,,5,,,,6.47999998182058,,,,,0.000697955224115767,7.96112533812618E-7,-0.382050996877829,0.000585833579027267,0.000697843246280728,7.95984807914303E-7,0.000697827732284392,6.82788406557932E-7,-4.65321764458446E-6,4.09135437600373E-7,1.00016046273377,10.005763053894,2,20,10,3,2.28433021595522,0.187391084928407,0.0403775237500668,172.74836730957,4.99926853179932,5.00152158737183,-780.11474609375,-780.11474609375,,,11.0863838195801,0,1,,,,,,1,1,1,5.000084400177,0,5.00007331371307,,,,,,,,,,,,,,,,,,,,,,,,,,,,,,,,,
,3772371864.00365,5.00002241134644,-800.223266601562,,,5,,,,6.47999998182058,,,,,0.0006794791110165,6.91059586665589E-7,-0.365698636716982,0.000499142770409304,0.000679370097544833,6.90948715259169E-7,0.000679356259447679,6.01842692601456E-7,-4.33614890572623E-6,3.39404626486624E-7,1.00016046256976,10.005763053894,2,20,10,3,2.22380509026162,0.18311305055632,0.0403775237500668,172.74836730957,4.99870777130127,5.00107908248901,-800.223266601562,-800.223266601562,,,11.0905141830444,0,1,,,,,,1,1,1,5.00002813339233,0,5.00001914684589,,,,,,,,,,,,,,,,,,,,,,,,,,,,,,,,,
,3772371888.80403,5.00022721290588,-820.222473144531,,,5,,,,6.47999998182058,,,,,0.000655286208535973,7.88371160322635E-7,-0.143560881563933,0.000510818672705923,0.000655181070344066,7.8824466915394E-7,0.000655179013704974,7.13623231081327E-7,-1.64162656349684E-6,3.34770880619344E-7,1.00016047196213,10.005763053894,2,20,10,3,2.14392281141263,0.184952627558781,0.0403775237500668,172.74836730957,4.99953269958496,5.00138902664185,-820.222473144531,-820.222473144531,,,11.1017274856567,0,1,,,,,,1,1,1,5.00041675567627,0,5.00016824404399,,,,,,,,,,,,,,,,,,,,,,,,,,,,,,,,,
,3772371917.89112,5.00000858306885,-840.270263671875,,,5,,,,6.47999998182058,,,,,0.000633167375577993,7.89087255535838E-7,-0.452919551158621,0.00071251603186753,0.000633065792615561,7.88960657381658E-7,0.00063304601319969,6.47129309545625E-7,-5.00429335134959E-6,4.51312060134781E-7,1.00016046193558,10.005763053894,2,20,10,3,2.07248812510693,0.167566553037264,0.0403775237500668,172.74836730957,4.99905633926392,5.00109815597534,-840.270263671875,-840.270263671875,,,11.1174669265747,0,1,,,,,,1,1,1,4.99995422363281,0,5.00007647734422,,,,,,,,,,,,,,,,,,,,,,,,,,,,,,,,,
,3772371942.68064,4.99998497962952,-860.135864257812,,,5,,,,6.47999998182058,,,,,0.000603600311164516,7.06767457350637E-7,-0.487574769181354,0.000789650367279284,0.000603503472482469,7.06654067036189E-7,0.000603481620827241,5.21760075621774E-7,-5.1356228565045E-6,4.76577794222462E-7,1.00016046085311,10.005763053894,2,20,10,3,1.97580297096037,0.158588652897281,0.0403775237500668,172.74836730957,4.99932289123535,5.00101375579834,-860.135864257812,-860.135864257812,,,11.1266527175903,0,1,,,,,,1,1,1,4.99991750717163,0,5.00003929932912,,,,,,,,,,,,,,,,,,,,,,,,,,,,,,,,,
,3772371966.86768,4.9999897480011,-880.207946777344,,,5,,,,6.47999998182058,,,,,0.000564918520490104,6.48864264887724E-7,-0.546579203352977,0.000603201788877539,0.000564827952267609,6.48760238411374E-7,0.000564802251633807,5.51863888999317E-7,-5.3881548050134E-6,3.41080774835129E-7,1.00016034656594,10.005763053894,2,20,10,3,1.84933318203335,0.146560793549109,0.0403775237500668,172.74836730957,4.99950456619263,5.00084781646729,-880.207946777344,-880.207946777344,,,11.1319265365601,0,1,,,,,,1,1,1,4.99991750717163,0,5.00006218751272,,,,,,,,,,,,,,,,,,,,,,,,,,,,,,,,,
,3772371994.55682,5.00007510185242,-899.927917480469,,,5,,,,6.47999998182058,,,,,0.00051525565874141,6.70066626471924E-7,-0.641872457804531,0.000845523822778593,0.000515173050495304,6.69959198192684E-7,0.000515140723092433,5.08933514408711E-7,-5.77125362823271E-6,4.3569714843522E-7,1.00016035048034,10.005763053894,2,20,1,3,1.68697359726133,0.13090643869869,0.0403775237500668,172.74836730957,4.99882745742798,5.00249433517456,-899.927917480469,-899.927917480469,,,11.1440773010254,0,1,,,,,,1,1,1,4.99999332427978,0,5.00024512608846,,,,,,,,,,,,,,,,,,,,,,,,,,,,,,,,,
,3772372019.67396,5.00007629394531,-919.769287109375,,,5,,,,6.47999998182058,,,,,0.000434810613558904,8.98224918810595E-7,-0.756044080956636,0.00145236364666619,0.00043474085285019,8.98080808237009E-7,0.000434703004833527,6.38681510256342E-7,-5.73643840835947E-6,6.31375535303924E-7,1.00016046504086,10.005763053894,2,20,1,3,1.4238081719304,0.107661736253178,0.0403775237500668,172.74836730957,4.99890661239624,5.00060510635376,-919.769287109375,-919.769287109375,,,11.1512565612793,0,1,,,,,,1,1,1,4.99992418289185,0,5.00002541908851,,,,,,,,,,,,,,,,,,,,,,,,,,,,,,,,,
,3772372043.0612,4.99997234344482,-939.829162597656,,,5,,,,6.47999998182058,,,,,0.000334036417959507,1.4849554438131E-6,-0.931820090322007,0.00151475474190865,0.000333982826983712,1.48471720568406E-6,0.000333938659420121,1.39434661936639E-6,-5.43143302680648E-6,5.10081058181729E-7,1.0001604602736,10.005763053894,2,20,1,3,1.09406574418635,0.0793768394433941,0.0403775237500668,172.74836730957,4.99898529052734,5.00077247619629,-939.829162597656,-939.829162597656,,,11.1606760025024,0,1,,,,,,1,1,1,4.99988269805908,0,5.00003484579233,,,,,,,,,,,,,,,,,,,,,,,,,,,,,,,,,
,3772372068.4824,4.99998259544373,-959.828308105469,,,5,,,,6.47999998182058,,,,,0.000252620547620359,6.14725967501303E-7,-1.40281642664591,0.001465722746287,0.00025258001844274,6.14627343940556E-7,0.000252504317075998,4.90241034433996E-7,-6.18349209739214E-6,3.70716198832083E-7,1.00016046074377,10.005763053894,2,20,1,3,0.827870086914771,0.0532441680623877,0.0403775237500668,172.74836730957,4.99936532974243,5.00104236602783,-959.828308105469,-959.828308105469,,,11.1740818023682,0,1,,,,,,1,1,1,4.99999761581421,0,5.00000605216393,,,,,,,,,,,,,,,,,,,,,,,,,,,,,,,,,
,3772372094.13479,5.00003814697266,-979.888305664062,,,5,,,,6.47999998182058,,,,,0.000184178005971662,7.03332450351638E-7,-2.05848545665918,0.00226773788159477,0.00018414845690416,7.0321960941853E-7,0.000184029622630954,5.651504534742E-7,-6.61454265173917E-6,4.18476742494319E-7,1.0001604632914,10.005763053894,2,20,1,3,0.603979404918987,0.0319222163831084,0.0403775237500668,172.74836730957,4.99862813949585,5.00171279907227,-979.888305664062,-979.888305664062,,,11.1841487884521,0,1,,,,,,1,1,1,5.00014925003052,0,5.00000854638907,,,,,,,,,,,,,,,,,,,,,,,,,,,,,,,,,
,3772372119.77878,5.00013375282288,-999.790344238281,,,5,,,,6.47999998182058,,,,,0.000133836830624265,6.29548740895871E-7,-2.73161362747517,0.00342361837344282,0.000133815357584825,6.29447734880711E-7,0.000133663307391455,4.31818092509295E-7,-6.37731783211441E-6,4.57971162769111E-7,1.00016046767597,10.005763053894,2,20,1,3,0.439136455166749,0.0180485477352346,0.0403775237500668,172.74836730957,4.99939060211182,5.00094556808472,-999.790344238281,-999.790344238281,,,11.1880407333374,0,1,,,,,,1,1,1,5.00010299682617,0,5.00008591016134,,,,,,,,,,,,,,,,,,,,,,,,,,,,,,,,,