File: Experimental_Data/AC_Suceptibillity_FieldScans/ZFCd_Down_40K.dat
[Header]
; MPMS3 Data File (default extension .dat)
; Copyright (c) 2007, Quantum Design, Inc. All rights reserved.
TITLE,ZFCd_Down_40K
FILEOPENTIME,3772397563.79167,07/16/2019,12:12 am
BYAPP,SQUID AC,0.9.1.0
INFO,MPMS3 Measurement Release 1.1.16 Build 347, MultiVu Release 2.3.3.2,APPNAME
INFO,0,MOMENT_UNITS
INFO,Cu2OSeO3,SAMPLE_MATERIAL
INFO,,SAMPLE_COMMENT
INFO,,SAMPLE_MASS
INFO,,SAMPLE_VOLUME
INFO,,SAMPLE_MOLECULAR_WEIGHT
INFO,,SAMPLE_SIZE
INFO,,SAMPLE_SHAPE
INFO,Quartz,SAMPLE_HOLDER
INFO,Standard,SAMPLE_HOLDER_DETAIL
INFO,64.77,SAMPLE_OFFSET
DATATYPE,COMMENT,1
DATATYPE,TIME,2
STARTUPAXIS,X,2
STARTUPAXIS,Y1,5
FIELDGROUP, VSM,2,3,4,5,6,8,9,10,11,14,15
FIELDGROUP, DC, 2,3,4,14,56,57,58,59,60,61,62,63,64,65,66,67,68,69
FIELDGROUP, AC, 2,3,4,11,16,17,18,19,20,21,22,23,24,25,26,27,28,29,30
STARTUPGROUP, All
[Data]
Comment,Time Stamp (sec),Temperature (K),Magnetic Field (Oe),Moment (emu),M. Std. Err. (emu),Transport Action,Averaging Time (sec),Frequency (Hz),Peak Amplitude (mm),Center Position (mm),Lockin Signal' (V),Lockin Signal (V),Range,M. Quad. Signal (emu),AC Moment (emu),AC M. Std Err. (emu),AC Phase (deg),AC Phase Std. Err. (deg),AC Susceptibility (emu/Oe),AC Suscept. Std Err. (emu/Oe),AC X' (emu/Oe),AC X' Std Err. (emu/Oe),AC X'' (emu/Oe),AC X'' Std Err. (emu/Oe),AC Drive (Oe),AC Frequency (Hz),AC Averaging Time (sec),AC Cycles,AC Range,AC Measure Type,AC Signal' (V),AC Signal'' (V),AC Trim Coil Ratio,AC Trim Coil Phase,Min. Temperature (K),Max. Temperature (K),Min. Field (Oe),Max. Field (Oe),Mass (grams),Motor Lag (deg),Pressure (Torr),Measure Count,Measurement Number,SQUID Status (code),Motor Status (code),Measure Status (code),Motor Current (amps),Motor Temp. (C),Temp. Status (code),Field Status (code),Chamber Status (code),Chamber Temp (K),Redirection State,Average Temp (K),Rotation Angle (deg),Rotator state,DC Moment Fixed Ctr (emu),DC Moment Err Fixed Ctr (emu),DC Moment Free Ctr (emu),DC Moment Err Free Ctr (emu),DC Fixed Fit,DC Free Fit,DC Calculated Center (mm),DC Calculated Center Err (mm),DC Scan Length (mm),DC Scan Time (s),DC Number of Points,DC Squid Drift,DC Min V (V),DC Max V (V),DC Scans per Measure,Map 01,Map 02,Map 03,Map 04,Map 05,Map 06,Map 07,Map 08,Map 09,Map 10,Map 11,Map 12,Map 13,Map 14,Map 15,Map 16
,3772397711.21138,39.9192810058594,-0.279284596443176,,,5,,,,6.47999998182058,,,,,0.000582600417813356,1.21128520487999E-8,0.0306009124600468,9.76213283797885E-6,0.000582510541795731,1.21109834354743E-8,0.000582510458715582,1.06946259447887E-8,3.11111104527913E-7,5.68338769356679E-9,1.00015429080021,10.005763053894,2,20,1,3,1.90573010661609,0.168342247198013,0.0403775237500668,172.74836730957,39.9003486633301,39.9275283813477,-0.279284596443176,-0.279284596443176,,,23.6480026245117,0,1,,,,,,1,1,1,39.915641784668,0,39.9117948358709,,,,,,,,,,,,,,,,,,,,,,,,,,,,,,,,,
,3772397734.23607,39.900505065918,-19.8292083740234,,,5,,,,6.47999998182058,,,,,0.000582533971876887,1.57866395475226E-8,0.0322927822197769,7.94387458073248E-6,0.000582443872072418,1.57841978476302E-8,0.000582443779562193,1.50933742184948E-8,3.28274303624396E-7,4.61854483507628E-9,1.00015469268163,10.005763053894,2,20,1,3,1.90550528984828,0.168419297259963,0.0403775237500668,172.74836730957,39.8999252319336,39.9061050415039,-19.8292083740234,-19.8292083740234,,,23.6062278747559,0,1,,,,,,1,1,1,39.9008865356445,0,39.9021322076971,,,,,,,,,,,,,,,,,,,,,,,,,,,,,,,,,
,3772397757.3778,39.9011268615723,-39.9377021789551,,,5,,,,6.47999998182058,,,,,0.000582617397459162,1.32877185540507E-8,0.0313045429674803,1.53361435544637E-5,0.000582527201369993,1.32856614574848E-8,0.000582527114422779,9.83477592762568E-9,3.18273824925766E-7,8.93229997348337E-9,1.00015483584107,10.005763053894,2,20,1,3,1.90577852955466,0.168451543009031,0.0403775237500668,172.74836730957,39.8976745605469,39.9242286682129,-39.9377021789551,-39.9377021789551,,,23.5907955169678,0,1,,,,,,1,1,1,39.9032669067383,0,39.9087928771973,,,,,,,,,,,,,,,,,,,,,,,,,,,,,,,,,
,3772397780.48944,39.9529304504395,-60.0219039916992,,,5,,,,6.47999998182058,,,,,0.000583070790389053,1.61304572521882E-8,0.0296627877141633,1.69536129888722E-5,0.000582980411699515,1.61279569561485E-8,0.00058298033357225,1.27464058677163E-8,3.01816705667107E-7,9.88130219327523E-9,1.00015502869003,10.005763053894,2,20,1,3,1.90726391648762,0.168568581036046,0.0403775237500668,172.74836730957,39.9475708007812,39.9651870727539,-60.0219039916992,-60.0219039916992,,,23.5903301239014,0,1,,,,,,1,1,1,39.9556312561035,0,39.9571975708008,,,,,,,,,,,,,,,,,,,,,,,,,,,,,,,,,
,3772397802.31777,39.9706211090088,-79.8875350952148,,,5,,,,6.47999998182058,,,,,0.00058532319162387,2.52995847857783E-8,0.0318879104114895,2.66437382857761E-5,0.000585232660929357,2.52956717527491E-8,0.000585232570292381,1.99210706117872E-8,3.25710651932469E-7,1.55891614624718E-8,1.00015469180132,10.005763053894,2,20,1,3,1.91462256972167,0.169334711697551,0.0403775237500668,172.74836730957,39.9699287414551,39.9708137512207,-79.8875350952148,-79.8875350952148,,,23.5790042877197,0,1,,,,,,1,1,1,39.9705352783203,0,39.9703121185303,,,,,,,,,,,,,,,,,,,,,,,,,,,,,,,,,
,3772397824.42198,39.9702091217041,-99.8746109008789,,,5,,,,6.47999998182058,,,,,0.000591414199553605,3.35055337821309E-8,0.0369871217046835,3.25806529481208E-5,0.000591322737928661,3.3500352184248E-8,0.000591322614717407,2.74105285625056E-8,3.8172662526467E-7,1.92597123652643E-8,1.0001546729376,10.005763053894,2,20,1,3,1.9345287508786,0.171310403997584,0.0403775237500668,172.74836730957,39.9688262939453,39.9703521728516,-99.8746109008789,-99.8746109008789,,,23.5914421081543,0,1,,,,,,1,1,1,39.9700927734375,0,39.9695999839089,,,,,,,,,,,,,,,,,,,,,,,,,,,,,,,,,
,3772397847.4165,39.9899787902832,-119.97095489502,,,5,,,,6.47999998182058,,,,,0.000600661637731971,7.21956707767553E-8,0.0431961561727245,8.16220098793416E-5,0.000600568615660808,7.21844901212868E-8,0.000600568444982803,5.29946286491673E-8,4.52777734720465E-7,4.90119367951013E-8,1.00015488999714,10.005763053894,2,20,1,3,1.96475582421393,0.174244050763947,0.0403775237500668,172.74836730957,39.986701965332,39.9956245422363,-119.97095489502,-119.97095489502,,,23.6300067901611,0,1,,,,,,1,1,1,39.991268157959,0,39.9920612335205,,,,,,,,,,,,,,,,,,,,,,,,,,,,,,,,,
,3772397869.22986,39.9989776611328,-139.897308349609,,,5,,,,6.47999998182058,,,,,0.000611897487053049,9.11346406816624E-8,0.046768139293234,5.075624077846E-5,0.000611802823669967,9.11205417294925E-8,0.000611802619854858,8.56822413394346E-8,4.99388903392204E-7,3.1008170602715E-8,1.00015472858153,10.005763053894,2,20,1,3,2.0014943884684,0.177670825710073,0.0403775237500668,172.74836730957,39.9986877441406,39.9993629455566,-139.897308349609,-139.897308349609,,,23.6309871673584,0,1,,,,,,1,1,1,39.9991111755371,0,39.9991642345082,,,,,,,,,,,,,,,,,,,,,,,,,,,,,,,,,
,3772397893.65596,40.015287399292,-159.957229614258,,,5,,,,6.47999998182058,,,,,0.000628385886933822,4.97153544932471E-8,0.0495095650515234,4.9357512110204E-5,0.000628288707930257,4.97076660828101E-8,0.000628288473365809,3.88541826252583E-8,5.42907297006873E-7,3.10032991780428E-8,1.00015467252927,10.005763053894,2,20,1,3,2.05541585127339,0.182600757604367,0.0403775237500668,172.74836730957,40.0093955993652,40.0164909362793,-159.957229614258,-159.957229614258,,,23.644905090332,0,1,,,,,,1,1,1,40.0141296386719,0,40.0133336385091,,,,,,,,,,,,,,,,,,,,,,,,,,,,,,,,,
,3772397916.95303,40.0040397644043,-179.96858215332,,,5,,,,6.47999998182058,,,,,0.000653391747059662,2.03400175139419E-7,0.0985066205795979,7.93376449263045E-5,0.000653290662754352,2.03368707699715E-7,0.000653289697232908,1.96707046526386E-7,1.12317912920658E-6,5.16252759636052E-8,1.00015473098128,10.005763053894,2,20,1,3,2.13704258042668,0.191740581435101,0.0403775237500668,172.74836730957,40.0029487609863,40.004753112793,-179.96858215332,-179.96858215332,,,23.6467361450195,0,1,,,,,,1,1,1,40.003589630127,0,40.0036066228693,,,,,,,,,,,,,,,,,,,,,,,,,,,,,,,,,
,3772397941.94526,40.000919342041,-200.077056884766,,,5,,,,6.47999998182058,,,,,0.000693123038808805,1.14336470286619E-7,0.086702487427341,6.30072602101804E-5,0.000693015906792188,1.14318797960136E-7,0.000693015113321342,1.0567668749426E-7,1.04870167618385E-6,4.36030421793145E-8,1.00015458810623,10.005763053894,2,20,10,3,2.2670301198711,0.202981659399617,0.0403775237500668,172.74836730957,40.0001640319824,40.0026092529297,-200.077056884766,-200.077056884766,,,23.671516418457,0,1,,,,,,1,1,1,40.0010719299316,0,40.0008046767291,,,,,,,,,,,,,,,,,,,,,,,,,,,,,,,,,
,3772397971.90252,40.0093746185303,-219.991271972656,,,5,,,,6.47999998182058,,,,,0.000733879850107963,2.81495402441713E-7,0.122478232955895,0.000159069337623237,0.000733766302803505,2.81451848930658E-7,0.000733764626316615,2.56181917763076E-7,1.56853318847052E-6,1.1655886185837E-7,1.00015474586939,10.005763053894,2,20,10,3,2.40019740170185,0.216467147042465,0.0403775237500668,172.74836730957,40.0061874389648,40.0096817016602,-219.991271972656,-219.991271972656,,,23.6958274841309,0,1,,,,,,1,1,1,40.0090713500977,0,40.0081335703532,,,,,,,,,,,,,,,,,,,,,,,,,,,,,,,,,
,3772397995.08492,40.0237808227539,-239.893341064453,,,5,,,,6.47999998182058,,,,,0.000770408278584819,2.166889413705E-7,0.0866929571160062,7.50814681908245E-5,0.000770289101497104,2.16655421018123E-7,0.000770288219745935,2.08846890341551E-7,1.16550669403542E-6,5.76415462249609E-8,1.00015471734896,10.005763053894,2,20,10,3,2.5198038246619,0.22572144859054,0.0403775237500668,172.74836730957,40.0158004760742,40.0243721008301,-239.893341064453,-239.893341064453,,,23.6860179901123,0,1,,,,,,1,1,1,40.023265838623,0,40.0210363214666,,,,,,,,,,,,,,,,,,,,,,,,,,,,,,,,,
,3772398018.06073,40.0150375366211,-259.953247070313,,,5,,,,6.47999998182058,,,,,0.000794465865501641,1.46555857748376E-7,0.0467067605596707,7.12452902600595E-5,0.000794343011546603,1.4653319476493E-7,0.000794342747614457,1.35188730054502E-7,6.4753782998877E-7,5.65330384312392E-8,1.00015466108879,10.005763053894,2,20,10,3,2.59864819428692,0.231012433644439,0.0403775237500668,172.74836730957,40.008861541748,40.0165977478027,-259.953247070313,-259.953247070313,,,23.6864261627197,0,1,,,,,,1,1,1,40.0141410827637,0,40.0129448572795,,,,,,,,,,,,,,,,,,,,,,,,,,,,,,,,,
,3772398041.10694,40.0123119354248,-279.988891601562,,,5,,,,6.47999998182058,,,,,0.000808335740816099,1.88778815262488E-7,0.0230206269296822,9.27129124111582E-5,0.000808210750230563,1.88749624947789E-7,0.000808210684995115,1.73265315267524E-7,3.24727542222917E-7,7.4870230687347E-8,1.0001546509812,10.005763053894,2,20,10,3,2.64410908792428,0.234009140247305,0.0403775237500668,172.74836730957,40.0076675415039,40.0130996704102,-279.988891601562,-279.988891601562,,,23.6991119384766,0,1,,,,,,1,1,1,40.0117568969727,0,40.0106258392334,,,,,,,,,,,,,,,,,,,,,,,,,,,,,,,,,
,3772398064.11154,40.0041618347168,-299.878814697266,,,5,,,,6.47999998182058,,,,,0.000815589451778153,1.52248587278923E-7,0.00309946466697575,0.000108556715722788,0.000815463363299121,1.5222504995538E-7,0.00081546336210595,1.23853835521556E-7,4.41131947589438E-8,8.8502504261278E-8,1.00015462188089,10.005763053894,2,20,10,3,2.66791475634426,0.235238336565926,0.0403775237500668,172.74836730957,40.0021286010742,40.0052032470703,-299.878814697266,-299.878814697266,,,23.6995964050293,0,1,,,,,,1,1,1,40.003776550293,0,40.0033897399902,,,,,,,,,,,,,,,,,,,,,,,,,,,,,,,,,
,3772398085.78739,40.0005340576172,-319.914459228516,,,5,,,,6.47999998182058,,,,,0.000819618434581501,1.99130501196847E-7,-0.022221785276515,0.000174107982048767,0.000819491671385462,1.99099703428404E-7,0.000819491609750494,1.38880383635524E-7,-3.17834361546922E-7,1.42663698769266E-7,1.00015468515479,10.005763053894,2,20,10,3,2.68119482171384,0.2352730300212,0.0403775237500668,172.74836730957,39.9995040893555,40.000789642334,-319.914459228516,-319.914459228516,,,23.7245216369629,0,1,,,,,,1,1,1,40.0005035400391,0,40.0001556396484,,,,,,,,,,,,,,,,,,,,,,,,,,,,,,,,,
,3772398107.68576,40.0192222595215,-340.02294921875,,,5,,,,6.47999998182058,,,,,0.00082203427904189,2.08712355729105E-7,-0.0490821462232942,0.00011136451716217,0.000821907098776932,2.08680064992114E-7,0.000821906797202489,1.87546220421881E-7,-7.04082566167864E-7,9.15083861216038E-8,1.00015473800524,10.005763053894,2,20,10,3,2.68920450402732,0.234763500772574,0.0403775237500668,172.74836730957,40.0136375427246,40.0194664001465,-340.02294921875,-340.02294921875,,,23.7121410369873,0,1,,,,,,1,1,1,40.0189781188965,0,40.0172361894087,,,,,,,,,,,,,,,,,,,,,,,,,,,,,,,,,
,3772398130.69132,40.0068244934082,-360.070709228516,,,5,,,,6.47999998182058,,,,,0.000823027719855344,2.75484827280882E-7,-0.0598794475644038,0.000211679175425253,0.000822900475489984,2.75442235894021E-7,0.00082290002609566,2.13386306235474E-7,-8.60007793274656E-7,1.7416862411318E-7,1.00015462910662,10.005763053894,2,20,10,3,2.69249515290808,0.23459773063392,0.0403775237500668,172.74836730957,40.00244140625,40.0093383789063,-360.070709228516,-360.070709228516,,,23.7129669189453,0,1,,,,,,1,1,1,40.0060119628906,0,40.0051422119141,,,,,,,,,,,,,,,,,,,,,,,,,,,,,,,,,
,3772398152.34144,40.0056934356689,-379.936370849609,,,5,,,,6.47999998182058,,,,,0.00082371096932409,2.57845138665559E-7,-0.0759847693850331,0.000224297589662088,0.000823583473086034,2.5780522868936E-7,0.000823582748841213,1.79852681743509E-7,-1.09222323982203E-6,1.84706656104324E-7,1.00015480669807,10.005763053894,2,20,10,3,2.69479277646338,0.234092305542502,0.0403775237500668,172.74836730957,40.0049629211426,40.0070037841797,-379.936370849609,-379.936370849609,,,23.726001739502,0,1,,,,,,1,1,1,40.0060157775879,0,40.0062129974365,,,,,,,,,,,,,,,,,,,,,,,,,,,,,,,,,
,3772398174.3103,40.0040512084961,-399.947692871094,,,5,,,,6.47999998182058,,,,,0.000823522710723455,2.79092054452304E-7,-0.0839904082952412,0.000127131188513961,0.000823395305528396,2.79048876799552E-7,0.000823394420835717,2.58672348007566E-7,-1.20702229237244E-6,1.04675173844348E-7,1.00015473150527,10.005763053894,2,20,10,3,2.694206052695,0.23372008189287,0.0403775237500668,172.74836730957,40.0021514892578,40.004581451416,-399.947692871094,-399.947692871094,,,23.7262058258057,0,1,,,,,,1,1,1,40.0038795471191,0,40.0033851623535,,,,,,,,,,,,,,,,,,,,,,,,,,,,,,,,,
,3772398195.93917,40.0011501312256,-419.971221923828,,,5,,,,6.47999998182058,,,,,0.000823258612912387,3.11968395510344E-7,-0.0984144259667676,0.000237179815776172,0.00082313126350641,3.11920137296912E-7,0.000823130049247617,2.43282439367684E-7,-1.41385546454178E-6,1.95212260748738E-7,1.00015471336301,10.005763053894,2,20,10,3,2.69339728069561,0.233024828332183,0.0403775237500668,172.74836730957,40.0003623962402,40.0014610290527,-419.971221923828,-419.971221923828,,,23.7385807037354,0,1,,,,,,1,1,1,40.0012855529785,0,40.0008613586426,,,,,,,,,,,,,,,,,,,,,,,,,,,,,,,,,
,3772398217.78445,40.0014896392822,-439.897552490234,,,5,,,,6.47999998182058,,,,,0.000823059769076349,3.57522911864286E-7,-0.104840426986732,0.000256994057883744,0.000822932437638835,3.57467601292657E-7,0.000822931059965154,2.88204642038869E-7,-1.50580969019338E-6,2.11473805189138E-7,1.0001547289081,10.005763053894,2,20,10,3,2.69276938098217,0.232723962277128,0.0403775237500668,172.74836730957,40.0006866455078,40.001636505127,-439.897552490234,-439.897552490234,,,23.7276096343994,0,1,,,,,,1,1,1,40.0014114379883,0,40.0011604309082,,,,,,,,,,,,,,,,,,,,,,,,,,,,,,,,,
,3772398239.4235,40.0126495361328,-460.236755371094,,,5,,,,6.47999998182058,,,,,0.00082252774083588,4.13888934271628E-7,-0.121731929197924,0.000367916711215209,0.000822400448766242,4.13824881989342E-7,0.000822398592599768,2.82349967663323E-7,-1.74728956886679E-6,3.02538474766456E-7,1.00015478112862,10.005763053894,2,20,10,3,2.6910937044662,0.231838628502916,0.0403775237500668,172.74836730957,40.008659362793,40.0127029418945,-460.236755371094,-460.236755371094,,,23.7272605895996,0,1,,,,,,1,1,1,40.0126113891602,0,40.0112075805664,,,,,,,,,,,,,,,,,,,,,,,,,,,,,,,,,
,3772398261.38691,40.0050468444824,-480.308807373047,,,5,,,,6.47999998182058,,,,,0.000822110732976145,3.66810423268817E-7,-0.131162641347198,0.00023548887223242,0.000821983603016952,3.6675370026026E-7,0.000821981449203863,3.11507893422715E-7,-1.88169961671526E-6,1.93574556669866E-7,1.00015466240291,10.005763053894,2,20,10,3,2.68976399630141,0.231336227973316,0.0403775237500668,172.74836730957,40.0028648376465,40.0056610107422,-480.308807373047,-480.308807373047,,,23.7281475067139,0,1,,,,,,1,1,1,40.0048141479492,0,40.0042423248291,,,,,,,,,,,,,,,,,,,,,,,,,,,,,,,,,
,3772398281.99895,40.0021018981934,-500.368774414063,,,5,,,,6.47999998182058,,,,,0.000821333656713895,4.00324318909385E-7,-0.142935728479668,0.000272964324425408,0.000821206663466073,4.00262421427132E-7,0.000821204108067913,3.31602389065548E-7,-2.04866138343556E-6,2.24164808952546E-7,1.00015464225203,10.005763053894,2,20,10,3,2.68726555625812,0.230623111257174,0.0403775237500668,172.74836730957,40.0009765625,40.0024185180664,-500.368774414063,-500.368774414063,,,23.7278690338135,0,1,,,,,,1,1,1,40.0020523071289,0,40.0016387939453,,,,,,,,,,,,,,,,,,,,,,,,,,,,,,,,,
,3772398303.50618,39.9999656677246,-520.197937011719,,,5,,,,6.47999998182058,,,,,0.000820540039266863,4.16069764924382E-7,-0.14586589785008,0.000311632637692836,0.000820413060803889,4.16005378183075E-7,0.00082041040213282,3.28175538503407E-7,-2.08863828137508E-6,2.55658542992879E-7,1.00015477381948,10.005763053894,2,20,10,3,2.68467734631552,0.230319966627175,0.0403775237500668,172.74836730957,39.9996185302734,40.0001029968262,-520.197937011719,-520.197937011719,,,23.7401714324951,0,1,,,,,,1,1,1,40.0000381469727,0,39.999840927124,,,,,,,,,,,,,,,,,,,,,,,,,,,,,,,,,
,3772398325.42497,40.0029792785645,-540.282165527344,,,5,,,,6.47999998182058,,,,,0.000819782592044505,4.25745744602083E-7,-0.158791598171618,0.000316766334743538,0.000819655805697041,4.25679899403087E-7,0.000819652657868851,3.37331918104242E-7,-2.27162087377299E-6,2.59635424747732E-7,1.00015468242472,10.005763053894,2,20,10,3,2.68224751057087,0.22955988232819,0.0403775237500668,172.74836730957,40.0019035339355,40.0033340454102,-540.282165527344,-540.282165527344,,,23.7286605834961,0,1,,,,,,1,1,1,40.002571105957,0,40.002537467263,,,,,,,,,,,,,,,,,,,,,,,,,,,,,,,,,
,3772398347.07313,40.0148086547852,-560.3056640625,,,5,,,,6.47999998182058,,,,,0.000818701690212513,3.89357114837107E-7,-0.171693703898842,0.000250890475917092,0.000818575003207672,3.89296865191502E-7,0.000818571327917509,3.30699703887879E-7,-2.45295491347988E-6,2.05401448622933E-7,1.00015476529865,10.005763053894,2,20,10,3,2.67875906831487,0.22871126645507,0.0403775237500668,172.74836730957,40.010799407959,40.0148468017578,-560.3056640625,-560.3056640625,,,23.7294311523438,0,1,,,,,,1,1,1,40.0147933959961,0,40.0134460449219,,,,,,,,,,,,,,,,,,,,,,,,,,,,,,,,,
,3772398368.93744,40.0086288452148,-580.219848632813,,,5,,,,6.47999998182058,,,,,0.000817452257312091,3.85184849850698E-7,-0.180670352970886,0.000243898419682732,0.000817325807428487,3.85125266457303E-7,0.000817321743992918,3.29497176681298E-7,-2.57726308396605E-6,1.99381747968217E-7,1.00015471172261,10.005763053894,2,20,10,3,2.67470333783767,0.228000247838261,0.0403775237500668,172.74836730957,40.0056648254395,40.0094413757324,-580.219848632813,-580.219848632813,,,23.7414779663086,0,1,,,,,,1,1,1,40.0084228515625,0,40.0076160430908,,,,,,,,,,,,,,,,,,,,,,,,,,,,,,,,,
,3772398390.64254,40.0192279815674,-600.267639160156,,,5,,,,6.47999998182058,,,,,0.000815510578837319,4.98919868584985E-7,-0.197666556350426,0.000339466476995122,0.000815384501168692,4.98842735736564E-7,0.000815379648807134,4.14978022525428E-7,-2.8130156898217E-6,2.76834455619283E-7,1.00015462357752,10.005763053894,2,20,10,3,2.66841415758395,0.226724280464063,0.0403775237500668,172.74836730957,40.011402130127,40.0209846496582,-600.267639160156,-600.267639160156,,,23.7165870666504,0,1,,,,,,1,1,1,40.0182838439941,0,40.0162048339844,,,,,,,,,,,,,,,,,,,,,,,,,,,,,,,,,
,3772398412.4944,40.0099563598633,-620.3154296875,,,5,,,,6.47999998182058,,,,,0.000812934659121357,5.13220808407087E-7,-0.195239308943901,0.000440720457645137,0.000812808858657705,5.13141388228689E-7,0.000812804139687111,3.67444946439629E-7,-2.76969672298356E-6,3.58187514647349E-7,1.00015477250563,10.005763053894,2,20,10,3,2.65997259576494,0.22617797868818,0.0403775237500668,172.74836730957,40.0090293884277,40.0100021362305,-620.3154296875,-620.3154296875,,,23.752799987793,0,1,,,,,,1,1,1,40.0099105834961,0,40.0095699310303,,,,,,,,,,,,,,,,,,,,,,,,,,,,,,,,,
,3772398434.14039,40.0272941589355,-640.411743164062,,,5,,,,6.47999998182058,,,,,0.000808210757746792,5.65527204549818E-7,-0.221025021304881,0.000423399679546661,0.000808085788221279,5.6543975994983E-7,0.000808079775590274,4.50160321041825E-7,-3.1172756020563E-6,3.42166344767633E-7,1.00015464883473,10.005763053894,2,20,10,3,2.64461331274905,0.22373019819295,0.0403775237500668,172.74836730957,40.0188980102539,40.028148651123,-640.411743164062,-640.411743164062,,,23.7408332824707,0,1,,,,,,1,1,1,40.0269546508789,0,40.0244831085205,,,,,,,,,,,,,,,,,,,,,,,,,,,,,,,,,
,3772398456.08837,40.0091571807861,-660.277404785156,,,5,,,,6.47999998182058,,,,,0.000799708911057471,4.89724518106407E-7,-0.224957832754733,0.000317019334092195,0.000799585278203147,4.89648808008434E-7,0.000799579115216742,4.18881655858058E-7,-3.13936751848375E-6,2.53562839488935E-7,1.00015462122389,10.005763053894,2,20,10,3,2.61680563348443,0.221252906024664,0.0403775237500668,172.74836730957,40.0057411193848,40.0103225708008,-660.277404785156,-660.277404785156,,,23.7410945892334,0,1,,,,,,1,1,1,40.0086555480957,0,40.0079105377197,,,,,,,,,,,,,,,,,,,,,,,,,,,,,,,,,
,3772398477.8001,40.0094528198242,-680.264465332031,,,5,,,,6.47999998182058,,,,,0.000782890902573776,5.92913954963793E-7,-0.268412236708849,0.000403534146033576,0.000782769859144206,5.92822284031977E-7,0.000782761269747485,5.01585670148124E-7,-3.66701076425538E-6,3.15990626359307E-7,1.00015463476034,10.005763053894,2,20,10,3,2.56193415618578,0.214711750849826,0.0403775237500668,172.74836730957,40.0041656494141,40.0110626220703,-680.264465332031,-680.264465332031,,,23.7277374267578,0,1,,,,,,1,1,1,40.0085563659668,0,40.0076009576971,,,,,,,,,,,,,,,,,,,,,,,,,,,,,,,,,
,3772398499.77976,40.0066509246826,-700.287963867187,,,5,,,,6.47999998182058,,,,,0.000749581003520456,8.3898831787623E-7,-0.434109066728825,0.000631444274624329,0.000749465034412016,8.38858516391455E-7,0.0007494435228597,6.92441104269829E-7,-5.67836682922886E-6,4.73507051309749E-7,1.00015473584906,10.005763053894,2,20,10,3,2.45351213045294,0.19853431405619,0.0403775237500668,172.74836730957,40.0060386657715,40.007209777832,-700.287963867187,-700.287963867187,,,23.7296409606934,0,1,,,,,,1,1,1,40.0069427490234,0,40.0068834478205,,,,,,,,,,,,,,,,,,,,,,,,,,,,,,,,,
,3772398522.80721,40.0136871337891,-720.396423339844,,,5,,,,6.47999998182058,,,,,0.000658159592807332,8.64249389119981E-7,-0.478043588799352,0.000625107152803989,0.000658057782090185,8.64115698369193E-7,0.000658034877567503,7.59604817785442E-7,-5.49039836207651E-6,4.11942302956645E-7,1.0001547139475,10.005763053894,2,20,10,3,2.1544040998731,0.172714756087719,0.0403775237500668,172.74836730957,40.0092582702637,40.0146141052246,-720.396423339844,-720.396423339844,,,23.7296161651611,0,1,,,,,,1,1,1,40.0129737854004,0,40.0121872641823,,,,,,,,,,,,,,,,,,,,,,,,,,,,,,,,,
,3772398547.62383,40.0037746429443,-740.201354980469,,,5,,,,6.47999998182058,,,,,0.000480468275554852,7.55299231624384E-7,-0.60179097881457,0.000948519305427234,0.000480394004646892,7.55182477277494E-7,0.000480367506855789,6.02040654015005E-7,-5.04559786659915E-6,4.55903087179893E-7,1.00015460415251,10.005763053894,2,20,1,3,1.573020440542,0.122721132912855,0.0403775237500668,172.74836730957,40.0020523071289,40.005989074707,-740.201354980469,-740.201354980469,,,23.7293033599854,0,1,,,,,,1,1,1,40.003116607666,0,40.0035031636556,,,,,,,,,,,,,,,,,,,,,,,,,,,,,,,,,
,3772398571.57253,40.0015048980713,-760.2734375,,,5,,,,6.47999998182058,,,,,0.000318554008026865,1.04401023835109E-6,-1.03729398416382,0.00138810174974129,0.000318504725915875,1.0438487240485E-6,0.000318452530486271,9.44575200027058E-7,-5.76595678417521E-6,4.44294778487811E-7,1.00015472960675,10.005763053894,2,20,1,3,1.0435114696237,0.0734579299079264,0.0403775237500668,172.74836730957,40.0005912780762,40.0018768310547,-760.2734375,-760.2734375,,,23.7293033599854,0,1,,,,,,1,1,1,40.0012741088867,0,40.0011929598722,,,,,,,,,,,,,,,,,,,,,,,,,,,,,,,,,
,3772398593.23049,39.9984226226807,-780.296875,,,5,,,,6.47999998182058,,,,,0.000203491381913836,9.66801122495573E-7,-1.58083350160807,0.00230061614234351,0.000203459906021828,9.66651578434106E-7,0.000203382469062668,8.44572306644029E-7,-5.6128991068999E-6,4.70226427308305E-7,1.00015470316793,10.005763053894,2,20,1,3,0.667006771248434,0.0406133268686585,0.0403775237500668,172.74836730957,39.998119354248,39.9987831115723,-780.296875,-780.296875,,,23.7056102752686,0,1,,,,,,1,1,1,39.9983215332031,0,39.9983669281006,,,,,,,,,,,,,,,,,,,,,,,,,,,,,,,,,
,3772398615.08724,40.0069389343262,-800.174682617187,,,5,,,,6.47999998182058,,,,,0.000139422187122554,9.78897574388127E-7,-2.35631922763334,0.00381943504890347,0.000139400630997074,9.78746226604955E-7,0.000139282762832184,8.19932505448483E-7,-5.73130876990616E-6,5.34466895703009E-7,1.00015463434653,10.005763053894,2,20,1,3,0.457334453021024,0.0216481859843209,0.0403775237500668,172.74836730957,40.0039596557617,40.0077476501465,-800.174682617187,-800.174682617187,,,23.729133605957,0,1,,,,,,1,1,1,40.0065078735352,0,40.0057037353516,,,,,,,,,,,,,,,,,,,,,,,,,,,,,,,,,
,3772398636.74785,40.0063495635986,-820.258911132813,,,5,,,,6.47999998182058,,,,,8.8429435457116E-5,2.83692781100913E-6,-4.02361567549177,0.00981721946875815,8.84157555901044E-5,2.83648894362322E-6,8.81978296655034E-5,2.69135153513483E-6,-6.20392447277754E-6,8.95710020946613E-7,1.00015472205062,10.005763053894,2,20,1,3,0.29034411330167,0.00529120602431292,0.0403775237500668,172.74836730957,40.0050735473633,40.007137298584,-820.258911132813,-820.258911132813,,,23.7288818359375,0,1,,,,,,1,1,1,40.0060729980469,0,40.0065017700195,,,,,,,,,,,,,,,,,,,,,,,,,,,,,,,,,
,3772398658.65684,40.0045490264893,-840.282409667969,,,5,,,,6.47999998182058,,,,,6.77609016658314E-5,9.6942653270067E-7,-5.0915293343352,0.00875089385324176,6.77504247666173E-5,9.69276644139142E-7,6.74830949202322E-5,7.65603196651792E-7,-6.01264966915683E-6,5.94431626135583E-7,1.00015463960927,10.005763053894,2,20,1,3,0.222519287424385,-8.79670769311002E-5,0.0403775237500668,172.74836730957,40.0022087097168,40.005744934082,-840.282409667969,-840.282409667969,,,23.7289485931396,0,1,,,,,,1,1,1,40.0040512084961,0,40.0037071921609,,,,,,,,,,,,,,,,,,,,,,,,,,,,,,,,,
,3772398680.11464,40.0155487060547,-860.305847167969,,,5,,,,6.47999998182058,,,,,5.00234922952448E-5,7.67511813195494E-7,-7.02157211381225,0.00691371834152171,5.00157556334059E-5,7.67393109380874E-7,4.96406473166272E-5,6.83366114134878E-7,-6.11407765462715E-6,3.49146012976582E-7,1.00015468449374,10.005763053894,2,20,1,3,0.16417643271199,-0.00559394425608151,0.0403775237500668,172.74836730957,40.0096321105957,40.0168151855469,-860.305847167969,-860.305847167969,,,23.7053470611572,0,1,,,,,,1,1,1,40.0143966674805,0,40.0132585005327,,,,,,,,,,,,,,,,,,,,,,,,,,,,,,,,,
,3772398702.34451,40.0149230957031,-880.232177734375,,,5,,,,6.47999998182058,,,,,4.07995120317396E-5,1.06121361109742E-6,-9.30776900808121,0.0125891282431315,4.07931984464462E-5,1.06104939191158E-6,4.02561068209253E-5,9.27776769025664E-7,-6.5977953221809E-6,5.14835972842073E-7,1.00015477053857,10.005763053894,2,20,1,3,0.133615153051513,-0.00989754401638618,0.0403775237500668,172.74836730957,40.0127601623535,40.01513671875,-880.232177734375,-880.232177734375,,,23.728551864624,0,1,,,,,,1,1,1,40.0146064758301,0,40.0140939192338,,,,,,,,,,,,,,,,,,,,,,,,,,,,,,,,,
,3772398723.97997,40.0114097595215,-899.915710449219,,,5,,,,6.47999998182058,,,,,3.33308630976664E-5,1.05196733841148E-6,-10.578331446392,0.0168338397373995,3.3325710620438E-5,1.05180471922756E-6,3.27593350688088E-5,8.90238164900265E-7,-6.11792074210591E-6,5.6015103065547E-7,1.00015460967321,10.005763053894,2,20,1,3,0.108950074684394,-0.0105018403908313,0.0403775237500668,172.74836730957,40.0045852661133,40.0140686035156,-899.915710449219,-899.915710449219,,,23.7171115875244,0,1,,,,,,1,1,1,40.0096855163574,0,40.0084980010986,,,,,,,,,,,,,,,,,,,,,,,,,,,,,,,,,
,3772398745.83566,40.0074367523193,-920.012145996094,,,5,,,,6.47999998182058,,,,,3.01379003966079E-5,9.33876072994318E-7,-12.889903612471,0.0142325168254027,3.01332366204379E-5,9.33731557652585E-7,2.93738947004265E-5,8.33386737236559E-7,-6.72207254881673E-6,4.21095200583578E-7,1.00015477182981,10.005763053894,2,20,1,3,0.0980502757006645,-0.0134593698521996,0.0403775237500668,172.74836730957,40.0067977905273,40.0079803466797,-920.012145996094,-920.012145996094,,,23.7175807952881,0,1,,,,,,1,1,1,40.0078468322754,0,40.0075202941895,,,,,,,,,,,,,,,,,,,,,,,,,,,,,,,,,
,3772398767.19702,40.0079498291016,-940.023498535156,,,5,,,,6.47999998182058,,,,,2.52008300882479E-5,8.87058652542112E-7,-13.7921686342067,0.0221897397023968,2.51969355001567E-5,8.86921564674282E-7,2.4470429092502E-5,6.91151281525223E-7,-6.0069675068115E-6,5.55823504298188E-7,1.0001545659428,10.005763053894,2,20,1,3,0.0818009963595112,-0.0125424263214466,0.0403775237500668,172.74836730957,40.0021743774414,40.0103149414063,-940.023498535156,-940.023498535156,,,23.7283763885498,0,1,,,,,,1,1,1,40.0068092346191,0,40.0058715126731,,,,,,,,,,,,,,,,,,,,,,,,,,,,,,,,,
,3772398789.37981,40.0060768127441,-959.876953125,,,5,,,,6.47999998182058,,,,,2.42660910778826E-5,1.02934667746246E-6,-15.8484754943355,0.023179436876805,2.42623374622771E-5,1.02918745232234E-6,2.33400601326263E-5,8.71604499877033E-7,-6.62590462795852E-6,5.47295539733209E-7,1.00015470956215,10.005763053894,2,20,1,3,0.0782831536545274,-0.0148940619715524,0.0403775237500668,172.74836730957,40.0051078796387,40.0071411132812,-959.876953125,-959.876953125,,,23.7175979614258,0,1,,,,,,1,1,1,40.0066947937012,0,40.0064994812012,,,,,,,,,,,,,,,,,,,,,,,,,,,,,,,,,
,3772398811.01541,40.0047569274902,-979.948974609375,,,5,,,,6.47999998182058,,,,,2.28724309351879E-5,1.36559559060996E-6,-18.1453549861575,0.0326936041626647,2.28688942806187E-5,1.36538443509707E-6,2.17316128319072E-5,1.16582119628352E-6,-7.12203126518008E-6,7.10728917310533E-7,1.00015464912845,10.005763053894,2,20,1,3,0.0731656533158733,-0.0169830174364631,0.0403775237500668,172.74836730957,40.0028343200684,40.0051803588867,-979.948974609375,-979.948974609375,,,23.7045307159424,0,1,,,,,,1,1,1,40.0046234130859,0,40.0040328979492,,,,,,,,,,,,,,,,,,,,,,,,,,,,,,,,,
,3772398832.92083,40.0127506256103,-999.996765136719,,,5,,,,6.47999998182058,,,,,2.14659451833514E-5,9.8438876200263E-7,-19.716877255088,0.0235913865816385,2.14626255361477E-5,9.84236529087971E-7,2.02042977267929E-5,8.70770167811422E-7,-7.24090106768573E-6,4.58781930813329E-7,1.00015467106753,10.005763053894,2,20,1,3,0.068203981275518,-0.0178144089076028,0.0403775237500668,172.74836730957,40.0065612792969,40.0147857666016,-999.996765136719,-999.996765136719,,,23.7047557830811,0,1,,,,,,1,1,1,40.0115509033203,0,40.0100933421742,,,,,,,,,,,,,,,,,,,,,,,,,,,,,,,,,