File: Experimental_Data/AC_Suceptibillity_FieldScans/ZFCd_Up_52K.dat
[Header]
; MPMS3 Data File (default extension .dat)
; Copyright (c) 2007, Quantum Design, Inc. All rights reserved.
TITLE,ZFCd_Up_52K
FILEOPENTIME,3772390521.72377,07/15/2019,10:15 pm
BYAPP,SQUID AC,0.9.1.0
INFO,MPMS3 Measurement Release 1.1.16 Build 347, MultiVu Release 2.3.3.2,APPNAME
INFO,0,MOMENT_UNITS
INFO,Cu2OSeO3,SAMPLE_MATERIAL
INFO,,SAMPLE_COMMENT
INFO,,SAMPLE_MASS
INFO,,SAMPLE_VOLUME
INFO,,SAMPLE_MOLECULAR_WEIGHT
INFO,,SAMPLE_SIZE
INFO,,SAMPLE_SHAPE
INFO,Quartz,SAMPLE_HOLDER
INFO,Standard,SAMPLE_HOLDER_DETAIL
INFO,64.77,SAMPLE_OFFSET
DATATYPE,COMMENT,1
DATATYPE,TIME,2
STARTUPAXIS,X,2
STARTUPAXIS,Y1,5
FIELDGROUP, VSM,2,3,4,5,6,8,9,10,11,14,15
FIELDGROUP, DC, 2,3,4,14,56,57,58,59,60,61,62,63,64,65,66,67,68,69
FIELDGROUP, AC, 2,3,4,11,16,17,18,19,20,21,22,23,24,25,26,27,28,29,30
STARTUPGROUP, All
[Data]
Comment,Time Stamp (sec),Temperature (K),Magnetic Field (Oe),Moment (emu),M. Std. Err. (emu),Transport Action,Averaging Time (sec),Frequency (Hz),Peak Amplitude (mm),Center Position (mm),Lockin Signal' (V),Lockin Signal (V),Range,M. Quad. Signal (emu),AC Moment (emu),AC M. Std Err. (emu),AC Phase (deg),AC Phase Std. Err. (deg),AC Susceptibility (emu/Oe),AC Suscept. Std Err. (emu/Oe),AC X' (emu/Oe),AC X' Std Err. (emu/Oe),AC X'' (emu/Oe),AC X'' Std Err. (emu/Oe),AC Drive (Oe),AC Frequency (Hz),AC Averaging Time (sec),AC Cycles,AC Range,AC Measure Type,AC Signal' (V),AC Signal'' (V),AC Trim Coil Ratio,AC Trim Coil Phase,Min. Temperature (K),Max. Temperature (K),Min. Field (Oe),Max. Field (Oe),Mass (grams),Motor Lag (deg),Pressure (Torr),Measure Count,Measurement Number,SQUID Status (code),Motor Status (code),Measure Status (code),Motor Current (amps),Motor Temp. (C),Temp. Status (code),Field Status (code),Chamber Status (code),Chamber Temp (K),Redirection State,Average Temp (K),Rotation Angle (deg),Rotator state,DC Moment Fixed Ctr (emu),DC Moment Err Fixed Ctr (emu),DC Moment Free Ctr (emu),DC Moment Err Free Ctr (emu),DC Fixed Fit,DC Free Fit,DC Calculated Center (mm),DC Calculated Center Err (mm),DC Scan Length (mm),DC Scan Time (s),DC Number of Points,DC Squid Drift,DC Min V (V),DC Max V (V),DC Scans per Measure,Map 01,Map 02,Map 03,Map 04,Map 05,Map 06,Map 07,Map 08,Map 09,Map 10,Map 11,Map 12,Map 13,Map 14,Map 15,Map 16
,3772390656.56803,51.963716506958,0.230713382363319,,,5,,,,6.47999998182058,,,,,0.000536979400134562,1.82655435996324E-8,0.0218485385827991,1.81831575207943E-5,0.000536897619156086,1.82627617908189E-8,0.000536897580120473,1.54366414200306E-8,2.04734592365149E-7,9.75902504851743E-9,1.00015232136549,10.005763053894,2,20,1,3,1.75652866774241,0.154839724047197,0.0403775237500668,172.74836730957,51.9296226501465,51.9735946655273,0.230713382363319,0.230713382363319,,,23.6072387695313,0,1,,,,,,1,1,1,51.9589538574219,0,51.9506614685059,,,,,,,,,,,,,,,,,,,,,,,,,,,,,,,,,
,3772390679.55915,51.9022808074951,20.0842056274414,,,5,,,,6.47999998182058,,,,,0.000537038190812896,9.36164333508647E-9,0.0218687767699732,1.21444907964021E-5,0.000536956308463646,9.36021596295126E-9,0.000536956269351408,6.71569308184242E-9,2.0494663760054E-7,6.52020776536925E-9,1.00015249350452,10.005763053894,2,20,1,3,1.7567185924437,0.154894771092794,0.0403775237500668,172.74836730957,51.8949356079102,51.9054718017578,20.0842056274414,20.0842056274414,,,23.6098651885986,0,1,,,,,,1,1,1,51.9005508422852,0,51.899021842263,,,,,,,,,,,,,,,,,,,,,,,,,,,,,,,,,
,3772390701.53751,51.8960285186768,39.9984130859375,,,5,,,,6.47999998182058,,,,,0.0005428952740751,2.12857146518384E-8,0.02661648830611,2.07791651159139E-5,0.000542812342582649,2.12824630927104E-8,0.000542812284012551,1.80504676928763E-8,2.52160943997994E-7,1.12749213461119E-8,1.00015278114727,10.005763053894,2,20,1,3,1.77586250115966,0.156769109370359,0.0403775237500668,172.74836730957,51.8947296142578,51.9001579284668,39.9984130859375,39.9984130859375,,,23.634880065918,0,1,,,,,,1,1,1,51.8966445922852,0,51.8970932006836,,,,,,,,,,,,,,,,,,,,,,,,,,,,,,,,,
,3772390722.9853,51.9243812561035,60.0461921691895,,,5,,,,6.47999998182058,,,,,0.000556420717137178,1.72472245891716E-8,0.0465541844350898,1.93982561863364E-5,0.000556335572282372,1.72445853768127E-8,0.000556335388637422,1.34522894774208E-8,4.52035842956067E-7,1.07894222567223E-8,1.00015304585766,10.005763053894,2,20,1,3,1.8200470628745,0.161347104782593,0.0403775237500668,172.74836730957,51.9186058044434,51.9405632019043,60.0461921691895,60.0461921691895,,,23.6602001190186,0,1,,,,,,1,1,1,51.9265937805176,0,51.9291693947532,,,,,,,,,,,,,,,,,,,,,,,,,,,,,,,,,
,3772390747.04223,51.9534015655518,80.1304016113281,,,5,,,,6.47999998182058,,,,,0.000582635046441289,4.23416208321067E-8,0.0914950986685543,5.2888024177121E-5,0.000582545985584578,4.23351485454688E-8,0.000582545242821135,2.90381356266958E-8,9.30261883683558E-7,3.08066791733957E-8,1.0001528821053,10.005763053894,2,20,1,3,1.90565819877934,0.170484235956059,0.0403775237500668,172.74836730957,51.9515762329102,51.955638885498,80.1304016113281,80.1304016113281,,,23.6498699188232,0,1,,,,,,1,1,1,51.9545478820801,0,51.9540308438815,,,,,,,,,,,,,,,,,,,,,,,,,,,,,,,,,
,3772390770.81289,51.9710712432861,100.166030883789,,,5,,,,6.47999998182058,,,,,0.000636632305818654,1.40464899744794E-7,0.255832981351523,0.000208642984408154,0.000636534987615652,1.40443427709047E-7,0.000636528642210429,4.55432279080053E-8,2.84220066257084E-6,1.32853945287243E-7,1.00015288743729,10.005763053894,2,20,1,3,2.08172433498136,0.192300582194237,0.0403775237500668,172.74836730957,51.9689331054687,51.9742393493652,100.166030883789,100.166030883789,,,23.6740741729736,0,1,,,,,,1,1,1,51.9714164733887,0,51.9714191436768,,,,,,,,,,,,,,,,,,,,,,,,,,,,,,,,,
,3772390794.3637,51.9942455291748,120.031669616699,,,5,,,,6.47999998182058,,,,,0.000686923719803516,2.7210325481164E-8,0.215864010676698,2.84168114388155E-5,0.000686818616007921,2.72061621244404E-8,0.000686813741545041,1.89563101025583E-8,2.58760892300108E-6,1.95149574643908E-8,1.0001530299167,10.005763053894,2,20,10,3,2.24631332741609,0.205972289664641,0.0403775237500668,172.74836730957,51.9899444580078,52.0018310546875,120.031669616699,120.031669616699,,,23.6745319366455,0,1,,,,,,1,1,1,51.9958724975586,0,51.996885172526,,,,,,,,,,,,,,,,,,,,,,,,,,,,,,,,,
,3772390819.5407,52.0331115722656,140.115875244141,,,5,,,,6.47999998182058,,,,,0.000711203822636473,9.09938148724879E-8,0.129864683357193,7.25694221823018E-5,0.000711095044681291,9.097989745416E-8,0.000711093218119672,7.49472913184371E-8,1.61174268908744E-6,5.15775655183413E-8,1.00015297245565,10.005763053894,2,20,10,3,2.32602610547242,0.209811425100614,0.0403775237500668,172.74836730957,52.0299034118652,52.0341033935547,140.115875244141,140.115875244141,,,23.6866989135742,0,1,,,,,,1,1,1,52.0339813232422,0,52.0327545166016,,,,,,,,,,,,,,,,,,,,,,,,,,,,,,,,,
,3772390841.0967,52.051441192627,160.163650512695,,,5,,,,6.47999998182058,,,,,0.000720881260609843,6.83934911698973E-8,0.0507601380576563,7.93173856853664E-5,0.000720771142293037,6.83830437126812E-8,0.000720770859435543,3.75222986749789E-8,6.38553803015343E-7,5.71692029816417E-8,1.0001527784762,10.005763053894,2,20,10,3,2.35796482484147,0.209461600154289,0.0403775237500668,172.74836730957,52.0429763793945,52.0517959594727,160.163650512695,160.163650512695,,,23.6864852905273,0,1,,,,,,1,1,1,52.051097869873,0,52.0486465454102,,,,,,,,,,,,,,,,,,,,,,,,,,,,,,,,,
,3772390862.95905,52.0622138977051,180.126434326172,,,5,,,,6.47999998182058,,,,,0.000727003711789471,8.65267979916518E-8,0.0230232546213358,6.57964815213365E-5,0.000726892716951143,8.65135875667277E-8,0.000726892658265957,7.21017815825578E-8,2.92088453924689E-7,4.7811441374288E-8,1.00015269768941,10.005763053894,2,20,10,3,2.37808986105561,0.21014012453905,0.0403775237500668,172.74836730957,52.050895690918,52.0632286071777,180.126434326172,180.126434326172,,,23.6858520507813,0,1,,,,,,1,1,1,52.061222076416,0,52.0585121154785,,,,,,,,,,,,,,,,,,,,,,,,,,,,,,,,,
,3772390884.35143,52.0317325592041,200.064926147461,,,5,,,,6.47999998182058,,,,,0.000731741303448335,1.28630645708177E-7,0.0102113429930677,0.000132440310609941,0.000731629766242904,1.28611038911776E-7,0.000731629754623554,8.45776455875326E-8,1.30392194869932E-7,9.68887052077588E-8,1.00015245033838,10.005763053894,2,20,10,3,2.39363097213287,0.211025473731111,0.0403775237500668,172.74836730957,52.0209770202637,52.0364875793457,200.064926147461,200.064926147461,,,23.6731338500977,0,1,,,,,,1,1,1,52.029670715332,0,52.028228412975,,,,,,,,,,,,,,,,,,,,,,,,,,,,,,,,,
,3772390906.65287,52.0145664215088,220.124847412109,,,5,,,,6.47999998182058,,,,,0.00073534895076722,1.18067856710115E-7,0.00580483515943442,6.01985524692703E-5,0.000735236766277744,1.18049844333522E-7,0.000735236762504354,1.09452726706228E-7,7.44893997492803E-8,4.42251779390493E-8,1.00015258280682,10.005763053894,2,20,10,3,2.40544519724209,0.211932576494343,0.0403775237500668,172.74836730957,52.0107803344727,52.0167274475098,220.124847412109,220.124847412109,,,23.6726512908936,0,1,,,,,,1,1,1,52.0136451721191,0,52.0131076465954,,,,,,,,,,,,,,,,,,,,,,,,,,,,,,,,,
,3772390929.64292,52.0117816925049,240.087615966797,,,5,,,,6.47999998182058,,,,,0.000738091181619327,1.06960954725716E-7,-0.00296432296374416,0.000105803381295909,0.000737978503461641,1.0694462589857E-7,0.000737978502473953,7.30880285937277E-8,-3.81809383199936E-8,7.80723580076038E-8,1.00015268487789,10.005763053894,2,20,10,3,2.414444810838,0.212404968440975,0.0403775237500668,172.74836730957,52.0077857971191,52.0120887756348,240.087615966797,240.087615966797,,,23.6595439910889,0,1,,,,,,1,1,1,52.0114822387695,0,52.0104690551758,,,,,,,,,,,,,,,,,,,,,,,,,,,,,,,,,
,3772390952.62824,52.0130767822266,260.220397949219,,,5,,,,6.47999998182058,,,,,0.0007406624886317,1.38196834409814E-7,-0.00934408807040033,7.90478559853558E-5,0.000740549374051785,1.38175728876444E-7,0.000740549364203681,1.25176508072585E-7,-1.20772569982504E-7,5.8509605000295E-8,1.00015274414358,10.005763053894,2,20,10,3,2.42287656374717,0.212927347580944,0.0403775237500668,172.74836730957,52.0123519897461,52.0135192871094,260.220397949219,260.220397949219,,,23.6473445892334,0,1,,,,,,1,1,1,52.0133476257324,0,52.012828133323,,,,,,,,,,,,,,,,,,,,,,,,,,,,,,,,,
,3772390974.26077,52.0103855133057,280.049621582031,,,5,,,,6.47999998182058,,,,,0.000743247899677635,1.44511116914626E-7,-0.016776874953889,0.000122265489532429,0.000743134396496531,1.44489048273084E-7,0.000743134364638845,1.12358318464743E-7,-2.1759844742058E-7,9.08443357762995E-8,1.00015273573884,10.005763053894,2,20,10,3,2.43135854681129,0.213406809094259,0.0403775237500668,172.74836730957,52.0076179504395,52.0116081237793,280.049621582031,280.049621582031,,,23.6345310211182,0,1,,,,,,1,1,1,52.0095252990723,0,52.0093437194824,,,,,,,,,,,,,,,,,,,,,,,,,,,,,,,,,
,3772390996.18633,52.0034103393555,300.121673583984,,,5,,,,6.47999998182058,,,,,0.000745668505762116,2.17751336287795E-7,-0.0256367145252678,0.00010210868334025,0.000745554614242856,2.17718077500118E-7,0.000745554539610194,2.03992240407059E-7,-3.33594731287273E-7,7.60810562758961E-8,1.00015276079993,10.005763053894,2,20,10,3,2.43930683135457,0.213777059658302,0.0403775237500668,172.74836730957,52.0006790161133,52.0044441223145,300.121673583984,300.121673583984,,,23.6205787658691,0,1,,,,,,1,1,1,52.0028495788574,0,52.0022957541726,,,,,,,,,,,,,,,,,,,,,,,,,,,,,,,,,
,3772391017.88324,52.019868850708,320.193725585937,,,5,,,,6.47999998182058,,,,,0.000747582282446564,2.45520731910161E-7,-0.0275767607835533,0.000111320393187106,0.000747468050301178,2.45483215825843E-7,0.000747467963723911,2.30969959534708E-7,-3.59760299900587E-7,8.31557998261874E-8,1.00015282545567,10.005763053894,2,20,10,3,2.44557139825401,0.21429539123235,0.0403775237500668,172.74836730957,52.0182685852051,52.0206298828125,320.193725585937,320.193725585937,,,23.6324005126953,0,1,,,,,,1,1,1,52.0204200744629,0,52.0200420379639,,,,,,,,,,,,,,,,,,,,,,,,,,,,,,,,,
,3772391039.84285,52.0145359039307,340.035095214844,,,5,,,,6.47999998182058,,,,,0.000749290639423766,2.46456514846125E-7,-0.0566350626067136,0.000231811443030672,0.000749176243086056,2.464188876275E-7,0.000749175877087416,1.74839435319072E-7,-7.40536857719182E-7,1.73647459056798E-7,1.00015269616297,10.005763053894,2,20,10,3,2.4512653922851,0.213594003597341,0.0403775237500668,172.74836730957,52.0104942321777,52.0158500671387,340.035095214844,340.035095214844,,,23.6074142456055,0,1,,,,,,1,1,1,52.0139198303223,0,52.0130941217596,,,,,,,,,,,,,,,,,,,,,,,,,,,,,,,,,
,3772391061.54734,52.0075263977051,360.070709228516,,,5,,,,6.47999998182058,,,,,0.000750879693983039,2.43784500778996E-7,-0.0578728968101867,0.000181931367966448,0.000750765037406971,2.43747275779597E-7,0.000750764654424246,2.01896165112046E-7,-7.58327062127187E-7,1.3656746670794E-7,1.00015271965309,10.005763053894,2,20,10,3,2.45646530492015,0.214046609373286,0.0403775237500668,172.74836730957,52.0047760009766,52.0083236694336,360.070709228516,360.070709228516,,,23.6182594299316,0,1,,,,,,1,1,1,52.0070381164551,0,52.0064163208008,,,,,,,,,,,,,,,,,,,,,,,,,,,,,,,,,
,3772391083.463,52.002893447876,380.154937744141,,,5,,,,6.47999998182058,,,,,0.00075191258181799,3.23684317909819E-7,-0.0677371499395143,0.000226393960260635,0.00075179775437461,3.23634886840853E-7,0.000751797228987332,2.75278749832071E-7,-8.88802382693638E-7,1.70179757525341E-7,1.00015273714601,10.005763053894,2,20,10,3,2.45987798704423,0.213970435443844,0.0403775237500668,172.74836730957,52.0017013549805,52.0034294128418,380.154937744141,380.154937744141,,,23.5810966491699,0,1,,,,,,1,1,1,52.0028839111328,0,52.0024157437411,,,,,,,,,,,,,,,,,,,,,,,,,,,,,,,,,
,3772391106.54707,52.0086402893066,400.141998291016,,,5,,,,6.47999998182058,,,,,0.000752362237715223,3.81584498496934E-7,-0.0792788193291658,0.000218841053663555,0.000752247316421161,3.81526212498298E-7,0.000752246596309796,3.44189655039688E-7,-1.04086654490712E-6,1.6460781326218E-7,1.00015277062683,10.005763053894,2,20,10,3,2.4613889141972,0.213655205224423,0.0403775237500668,172.74836730957,52.0058937072754,52.0085792541504,400.141998291016,400.141998291016,,,23.5680370330811,0,1,,,,,,1,1,1,52.0085830688477,0,52.0076268513997,,,,,,,,,,,,,,,,,,,,,,,,,,,,,,,,,
,3772391129.58867,52.0039100646973,420.104766845703,,,5,,,,6.47999998182058,,,,,0.000752515981500833,2.56114475389693E-7,-0.0856092586296846,0.000177656901391512,0.000752401026911919,2.5607535125817E-7,0.000752400187035262,2.18426512953303E-7,-1.12420968326927E-6,1.33657936393825E-7,1.00015278366829,10.005763053894,2,20,10,3,2.46191229717065,0.213479471090209,0.0403775237500668,172.74836730957,52.0035972595215,52.0043449401855,420.104766845703,420.104766845703,,,23.5662040710449,0,1,,,,,,1,1,1,52.0038871765137,0,52.0039513905843,,,,,,,,,,,,,,,,,,,,,,,,,,,,,,,,,
,3772391152.56216,52.0232620239258,440.334686279297,,,5,,,,6.47999998182058,,,,,0.000750828705568502,3.06200768498978E-7,-0.0882414193271837,0.000187787607460436,0.000750714033078073,3.06154003099048E-7,0.000750713142762115,2.71769321907196E-7,-1.15617670556231E-6,1.40967050347499E-7,1.000152751228,10.005763053894,2,20,10,3,2.45639881056461,0.212941080756855,0.0403775237500668,172.74836730957,52.0211791992188,52.0234870910645,440.334686279297,440.334686279297,,,23.5541877746582,0,1,,,,,,1,1,1,52.0230369567871,0,52.022709274292,,,,,,,,,,,,,,,,,,,,,,,,,,,,,,,,,
,3772391174.20598,52.0427074432373,460.382446289063,,,5,,,,6.47999998182058,,,,,0.000746964951609504,3.25906521125237E-7,-0.0988560968537504,0.000217275247111449,0.000746850890253952,3.25856755283476E-7,0.000746849778610657,2.82581223257377E-7,-1.28858928072507E-6,1.62266685509501E-7,1.00015272306298,10.005763053894,2,20,10,3,2.44379425583796,0.211444917320661,0.0403775237500668,172.74836730957,52.0369338989258,52.0428924560547,460.382446289063,460.382446289063,,,23.5648365020752,0,1,,,,,,1,1,1,52.0425224304199,0,52.0408500671387,,,,,,,,,,,,,,,,,,,,,,,,,,,,,,,,,
,3772391196.10331,52.0377960205078,480.466674804687,,,5,,,,6.47999998182058,,,,,0.000737786371232294,3.17098520067619E-7,-0.11862032138462,0.00024744259827688,0.000737673792577248,3.17050134076364E-7,0.000737672211667302,2.59240235915402E-7,-1.52721615076705E-6,1.82524758869494E-7,1.00015261306038,10.005763053894,2,20,10,3,2.41383409572806,0.208065977594706,0.0403775237500668,172.74836730957,52.0297241210937,52.0395736694336,480.466674804687,480.466674804687,,,23.5275421142578,0,1,,,,,,1,1,1,52.0369606018066,0,52.0350605010986,,,,,,,,,,,,,,,,,,,,,,,,,,,,,,,,,
,3772391217.75179,52.0201568603516,500.332336425781,,,5,,,,6.47999998182058,,,,,0.000712599759183425,3.5743287693946E-7,-0.131826112138262,0.000229582340150861,0.00071249102654768,3.57378337742231E-7,0.000712489140699032,3.17733652010436E-7,-1.63929769161598E-6,1.63598907904396E-7,1.00015260913007,10.005763053894,2,20,10,3,2.3314737077447,0.200475269361242,0.0403775237500668,172.74836730957,52.0143547058105,52.0224876403809,500.332336425781,500.332336425781,,,23.5269432067871,0,1,,,,,,1,1,1,52.0183601379395,0,52.017805480957,,,,,,,,,,,,,,,,,,,,,,,,,,,,,,,,,
,3772391239.68983,52.0092601776123,520.367919921875,,,5,,,,6.47999998182058,,,,,0.000644281573063635,3.63087651132581E-7,-0.139276884485103,0.000390845557113996,0.00064418321643791,3.63032221833187E-7,0.000644181313204653,2.61560630609029E-7,-1.56590492051447E-6,2.51750731090393E-7,1.0001526842414,10.005763053894,2,20,10,3,2.10797208800401,0.18102646114433,0.0403775237500668,172.74836730957,52.0061340332031,52.0105018615723,520.367919921875,520.367919921875,,,23.5136394500732,0,1,,,,,,1,1,1,52.0089912414551,0,52.0082009055398,,,,,,,,,,,,,,,,,,,,,,,,,,,,,,,,,
,3772391265.83102,52.0205039978027,540.4521484375,,,5,,,,6.47999998182058,,,,,0.000475288268352648,3.38225241213734E-7,-0.165791551212219,0.000539734712630645,0.000475215684019113,3.38173588658111E-7,0.000475213694537214,2.20438473807932E-7,-1.37508619547544E-6,2.56453222500976E-7,1.00015273976844,10.005763053894,2,20,1,3,1.55511639102286,0.132857468518779,0.0403775237500668,172.74836730957,52.0162353515625,52.0211029052734,540.4521484375,540.4521484375,,,23.5116767883301,0,1,,,,,,1,1,1,52.0200805664063,0,52.0193604689378,,,,,,,,,,,,,,,,,,,,,,,,,,,,,,,,,
,3772391288.30724,52.0286254882812,560.269226074219,,,5,,,,6.47999998182058,,,,,0.00025816008598852,2.63804025155096E-7,-0.353823239677745,0.000654710039030805,0.000258120653628209,2.63763730717899E-7,0.000258115731886426,2.02500798887547E-7,-1.59398312047291E-6,1.69011041332007E-7,1.00015276716434,10.005763053894,2,20,1,3,0.844916502412947,0.0694090236006884,0.0403775237500668,172.74836730957,52.0243644714355,52.0287399291992,560.269226074219,560.269226074219,,,23.4862861633301,0,1,,,,,,1,1,1,52.0285110473633,0,52.0272525787353,,,,,,,,,,,,,,,,,,,,,,,,,,,,,,,,,
,3772391309.96008,52.0150985717773,580.401977539063,,,5,,,,6.47999998182058,,,,,0.000132071412805435,3.81625234212956E-7,-0.666933556766307,0.00149747875410591,0.000132051260837678,3.81567004356458E-7,0.000132042314865832,3.2615235016573E-7,-1.53706658702933E-6,1.98035409194751E-7,1.00015260715899,10.005763053894,2,20,1,3,0.432435644729198,0.0331554237480474,0.0403775237500668,172.74836730957,52.010326385498,52.0168991088867,580.401977539063,580.401977539063,,,23.4743366241455,0,1,,,,,,1,1,1,52.0142135620117,0,52.0132012800737,,,,,,,,,,,,,,,,,,,,,,,,,,,,,,,,,
,3772391331.92781,52.0243759155273,600.425476074219,,,5,,,,6.47999998182058,,,,,7.38707538678371E-5,4.07271286113005E-7,-1.28928578961481,0.00216963745295862,7.38594679785134E-5,4.07209063671523E-7,7.38407692971588E-5,3.73834273865038E-7,-1.66186632218599E-6,1.61453266365344E-7,1.0001528022017,10.005763053894,2,20,1,3,0.242058730236287,0.0159215392589912,0.0403775237500668,172.74836730957,52.0201110839844,52.0244560241699,600.425476074219,600.425476074219,,,23.4730949401855,0,1,,,,,,1,1,1,52.0244560241699,0,52.0229294516823,,,,,,,,,,,,,,,,,,,,,,,,,,,,,,,,,
,3772391355.01584,52.0437068939209,620.461120605469,,,5,,,,6.47999998182058,,,,,4.96952680990308E-5,4.95625098195378E-7,-1.98190721717194,0.00552259910861852,4.96876773722027E-5,4.95549393709348E-7,4.96579540896405E-5,4.12079740064206E-7,-1.71839409777203E-6,2.75244417626077E-7,1.00015276879962,10.005763053894,2,20,1,3,0.162958293062257,0.00874518640170833,0.0403775237500668,172.74836730957,52.0371398925781,52.0438079833984,620.461120605469,620.461120605469,,,23.4592189788818,0,1,,,,,,1,1,1,52.0435523986816,0,52.0418288490989,,,,,,,,,,,,,,,,,,,,,,,,,,,,,,,,,
,3772391376.70212,52.0240058898926,640.375366210937,,,5,,,,6.47999998182058,,,,,3.93988924908717E-5,4.71413454074844E-7,-2.75482389077925,0.00525563751104084,3.93928828795606E-5,4.71341548205244E-7,3.93473582397054E-5,4.22444250192741E-7,-1.89330956768028E-6,2.09054324383902E-7,1.00015255576317,10.005763053894,2,20,1,3,0.129276653647776,0.00519261489521086,0.0403775237500668,172.74836730957,52.016170501709,52.0262756347656,640.375366210937,640.375366210937,,,23.4466800689697,0,1,,,,,,1,1,1,52.0224571228027,0,52.0208541870117,,,,,,,,,,,,,,,,,,,,,,,,,,,,,,,,,
,3772391398.62166,52.0351886749268,660.37451171875,,,5,,,,6.47999998182058,,,,,3.21352870965009E-5,6.53038281373262E-7,-3.19955546603768,0.00727459939204867,3.21303800404629E-5,6.52938562474468E-7,3.20802951156206E-5,6.079174426755E-7,-1.7933172723378E-6,2.38254379303099E-7,1.00015272324921,10.005763053894,2,20,1,3,0.105472809038357,0.0034189813889176,0.0403775237500668,172.74836730957,52.0310897827148,52.0353775024414,660.37451171875,660.37451171875,,,23.4450435638428,0,1,,,,,,1,1,1,52.0349998474121,0,52.0338256835937,,,,,,,,,,,,,,,,,,,,,,,,,,,,,,,,,
,3772391420.42926,52.0179748535156,680.41015625,,,5,,,,6.47999998182058,,,,,2.83626150333222E-5,6.42838776594433E-7,-4.51892264104491,0.0157432655127862,2.83582868772898E-5,6.42740678921652E-7,2.82701313787255E-5,4.62260664043732E-7,-2.23430222760252E-6,4.46576599049384E-7,1.00015262403019,10.005763053894,2,20,1,3,0.093135170148823,0.000875359737305921,0.0403775237500668,172.74836730957,52.0125694274902,52.0195541381836,680.41015625,680.41015625,,,23.419282913208,0,1,,,,,,1,1,1,52.0172080993652,0,52.0159430070357,,,,,,,,,,,,,,,,,,,,,,,,,,,,,,,,,
,3772391442.11664,52.0070686340332,700.470092773437,,,5,,,,6.47999998182058,,,,,2.29028328425483E-5,8.08060734377745E-7,-7.93113526562223,0.0198719383435677,2.28993361435742E-5,8.07937363388649E-7,2.26802954714946E-5,6.66661364573895E-7,-3.15971409183002E-6,4.56426782894994E-7,1.00015269870498,10.005763053894,2,20,1,3,0.075115584128835,-0.00376903128684984,0.0403775237500668,172.74836730957,52.0047569274902,52.0079917907715,700.470092773437,700.470092773437,,,23.4067993164062,0,1,,,,,,1,1,1,52.0067024230957,0,52.0063255310059,,,,,,,,,,,,,,,,,,,,,,,,,,,,,,,,,
,3772391463.76648,52.0298843383789,720.347839355469,,,5,,,,6.47999998182058,,,,,2.17763278398296E-5,7.85676968479659E-7,-7.28002939115708,0.0158569893267692,2.17730003860187E-5,7.8555691592341E-7,2.15974810681567E-5,7.03931142995985E-7,-2.75905007569372E-6,3.48684117899662E-7,1.00015282477159,10.005763053894,2,20,1,3,0.0714571383534992,-0.00277029663816892,0.0403775237500668,172.74836730957,52.0277061462402,52.030200958252,720.347839355469,720.347839355469,,,23.3940410614014,0,1,,,,,,1,1,1,52.0297813415527,0,52.029280090332,,,,,,,,,,,,,,,,,,,,,,,,,,,,,,,,,
,3772391485.67604,52.0180892944336,740.383544921875,,,5,,,,6.47999998182058,,,,,2.10112805376134E-5,8.3436634892883E-7,-8.36305763779152,0.0191634008097248,2.10080740906595E-5,8.34239019638584E-7,2.07846808834798E-5,7.29542020081179E-7,-3.05552247096107E-6,4.04627214635174E-7,1.00015262926721,10.005763053894,2,20,1,3,0.0688839854226012,-0.00397420125115608,0.0403775237500668,172.74836730957,52.0117416381836,52.0200729370117,740.383544921875,740.383544921875,,,23.3927726745605,0,1,,,,,,1,1,1,52.0172080993652,0,52.0156940113414,,,,,,,,,,,,,,,,,,,,,,,,,,,,,,,,,
,3772391508.6983,52.0072364807129,760.45556640625,,,5,,,,6.47999998182058,,,,,1.97773247544749E-5,8.07767690932745E-7,-8.17125446033008,0.0233105236947433,1.97743050918096E-5,8.07644358481624E-7,1.95735497001562E-5,6.62361178657947E-7,-2.81056826984883E-6,4.62133182961415E-7,1.00015270638596,10.005763053894,2,20,1,3,0.0648508202698658,-0.00352234048278175,0.0403775237500668,172.74836730957,52.0046653747559,52.0086555480957,760.45556640625,760.45556640625,,,23.3800392150879,0,1,,,,,,1,1,1,52.0066680908203,0,52.0062644958496,,,,,,,,,,,,,,,,,,,,,,,,,,,,,,,,,
,3772391530.35978,52.0316257476807,780.272644042969,,,5,,,,6.47999998182058,,,,,1.8563921198633E-5,1.14752528640337E-6,-9.31561388434699,0.0276540083829728,1.85610831262104E-5,1.14734985149203E-6,1.83162928894148E-5,1.02530279542087E-6,-3.00453350909339E-6,5.14942578760921E-7,1.00015290446163,10.005763053894,2,20,1,3,0.0607939677191874,-0.00451999824007557,0.0403775237500668,172.74836730957,52.029598236084,52.0325736999512,780.272644042969,780.272644042969,,,23.3786888122559,0,1,,,,,,1,1,1,52.0323104858398,0,52.0313793182373,,,,,,,,,,,,,,,,,,,,,,,,,,,,,,,,,
,3772391552.24438,52.0194988250732,800.320434570312,,,5,,,,6.47999998182058,,,,,1.72177981221621E-5,8.87000857606659E-7,-11.344818274523,0.0257290477527627,1.72151694730358E-5,8.86865438779416E-7,1.68788037278721E-5,7.69664049031225E-7,-3.38645016223686E-6,4.40621785809856E-7,1.0001526937699,10.005763053894,2,20,1,3,0.0562019852031736,-0.00618496307508413,0.0403775237500668,172.74836730957,52.0136489868164,52.0215721130371,800.320434570312,800.320434570312,,,23.3531150817871,0,1,,,,,,1,1,1,52.0186424255371,0,52.0174770355225,,,,,,,,,,,,,,,,,,,,,,,,,,,,,,,,,
,3772391573.9157,52.0344829559326,820.416809082031,,,5,,,,6.47999998182058,,,,,1.67379609698018E-5,8.85672737062637E-7,-11.6156757111633,0.0237205833072506,1.67354037046061E-5,8.85537421890774E-7,1.6392665974981E-5,7.93439875867259E-7,-3.36960522744823E-6,3.93229816968024E-7,1.00015280570704,10.005763053894,2,20,1,3,0.0546068412522262,-0.00626964347108436,0.0403775237500668,172.74836730957,52.0309867858887,52.0346908569336,820.416809082031,820.416809082031,,,23.3403244018555,0,1,,,,,,1,1,1,52.0346717834473,0,52.0334087371826,,,,,,,,,,,,,,,,,,,,,,,,,,,,,,,,,
,3772391595.78409,52.0382289886475,840.415954589844,,,5,,,,6.47999998182058,,,,,1.57142678017281E-5,9.86011692253484E-7,-12.9991882623604,0.0281520207246346,1.57118678512046E-5,9.85861104309654E-7,1.53092237681488E-5,8.85601254263505E-7,-3.5341843458515E-6,4.33165713598798E-7,1.00015274762659,10.005763053894,2,20,1,3,0.051110204246441,-0.00712120736808771,0.0403775237500668,172.74836730957,52.0314712524414,52.0386352539063,840.415954589844,840.415954589844,,,23.3157806396484,0,1,,,,,,1,1,1,52.0378723144531,0,52.0359687805176,,,,,,,,,,,,,,,,,,,,,,,,,,,,,,,,,
,3772391617.41295,52.0346336364746,860.366577148438,,,5,,,,6.47999998182058,,,,,1.5997106164716E-5,8.6059987959104E-7,-11.8706150315681,0.0289051526506141,1.59946638139456E-5,8.60468487903242E-7,1.56526117096333E-5,7.27393589926477E-7,-3.29013938741078E-6,4.59678783509055E-7,1.00015269784965,10.005763053894,2,20,1,3,0.0521629802736028,-0.0062220785961017,0.0403775237500668,172.74836730957,52.0279083251953,52.0354957580566,860.366577148438,860.366577148438,,,23.3136081695557,0,1,,,,,,1,1,1,52.0340232849121,0,52.0322978973389,,,,,,,,,,,,,,,,,,,,,,,,,,,,,,,,,
,3772391639.34994,52.0169715881348,880.353637695313,,,5,,,,6.47999998182058,,,,,1.4668976457742E-5,8.51531753880358E-7,-13.3462230679489,0.0348210192333511,1.46667369515593E-5,8.51401750902094E-7,1.42706318688934E-5,6.83864018717377E-7,-3.38559283859712E-6,5.071636277799E-7,1.00015269287164,10.005763053894,2,20,1,3,0.0476696345685961,-0.00693434134489468,0.0403775237500668,172.74836730957,52.0115852355957,52.0184135437012,880.353637695313,880.353637695313,,,23.3006935119629,0,1,,,,,,1,1,1,52.0163841247559,0,52.0151458740234,,,,,,,,,,,,,,,,,,,,,,,,,,,,,,,,,
,3772391660.99162,52.0407905578613,900.243530273437,,,5,,,,6.47999998182058,,,,,1.42932473348247E-5,7.94252296955983E-7,-13.8785724997234,0.0262176913535204,1.4291062733684E-5,7.94130902255864E-7,1.38738530821673E-5,7.0512687933043E-7,-3.42792571572523E-6,3.65294366180812E-7,1.00015286484857,10.005763053894,2,20,1,3,0.0463840266761414,-0.00718701453196491,0.0403775237500668,172.74836730957,52.0357818603516,52.0411224365234,900.243530273437,900.243530273437,,,23.2764530181885,0,1,,,,,,1,1,1,52.0411224365234,0,52.0392795562744,,,,,,,,,,,,,,,,,,,,,,,,,,,,,,,,,
,3772391683.00123,52.0221042633057,920.291320800781,,,5,,,,6.47999998182058,,,,,1.42719282288939E-5,8.87682233487266E-7,-15.2811190850101,0.0278034934672305,1.42697509004425E-5,8.87546808494107E-7,1.37652341719185E-5,8.03215090607384E-7,-3.7608667821298E-6,3.77604098876914E-7,1.00015258349404,10.005763053894,2,20,1,3,0.0461255190052277,-0.00830679097527463,0.0403775237500668,172.74836730957,52.0152587890625,52.0246543884277,920.291320800781,920.291320800781,,,23.2744998931885,0,1,,,,,,1,1,1,52.0208625793457,0,52.019658279419,,,,,,,,,,,,,,,,,,,,,,,,,,,,,,,,,
,3772391706.29572,52.0072822570801,940.193481445313,,,5,,,,6.47999998182058,,,,,1.31891379704427E-5,8.3195975983042E-7,-15.7887939288895,0.0337771049280079,1.31871241847428E-5,8.31832731917677E-7,1.26895901892185E-5,7.1051298486147E-7,-3.58811163336896E-6,4.32570216534693E-7,1.00015270848077,10.005763053894,2,20,1,3,0.0425565469070804,-0.0080530520362006,0.0403775237500668,172.74836730957,52.0051803588867,52.0081748962402,940.193481445313,940.193481445313,,,23.2618942260742,0,1,,,,,,1,1,1,52.0068664550781,0,52.0065845489502,,,,,,,,,,,,,,,,,,,,,,,,,,,,,,,,,
,3772391727.91679,52.0339527130127,960.253356933594,,,5,,,,6.47999998182058,,,,,1.55676923321919E-5,5.84521781451512E-7,-9.30880167153997,0.022114677200538,1.5565312455144E-5,5.84432423957672E-7,1.53603309795376E-5,4.72068398037028E-7,-2.51777362471615E-6,3.44547073340923E-7,1.00015289619497,10.005763053894,2,20,1,3,0.0509832123912238,-0.00377462679100633,0.0403775237500668,172.74836730957,52.0309066772461,52.0350303649902,960.253356933594,960.253356933594,,,23.2606201171875,0,1,,,,,,1,1,1,52.0348358154297,0,52.0332381508567,,,,,,,,,,,,,,,,,,,,,,,,,,,,,,,,,
,3772391751.24245,52.0190105438232,980.289001464844,,,5,,,,6.47999998182058,,,,,1.30978334360126E-5,1.10184650803595E-6,-17.3887221394952,0.0333167303587483,1.30958340763592E-5,1.10167831323769E-6,1.24973436152382E-5,1.03376413428792E-6,-3.91372874867373E-6,3.80823870730543E-7,1.00015267142526,10.005763053894,2,20,1,3,0.0420226159852706,-0.00917236672045396,0.0403775237500668,172.74836730957,52.0132942199707,52.0212478637695,980.289001464844,980.289001464844,,,23.2592487335205,0,1,,,,,,1,1,1,52.0181503295898,0,52.0171581268311,,,,,,,,,,,,,,,,,,,,,,,,,,,,,,,,,
,3772391772.82365,52.0075073242188,1000.16674804688,,,5,,,,6.47999998182058,,,,,1.19548431300761E-5,9.02793199765406E-7,-19.0254748620754,0.032756713863376,1.19530176797957E-5,9.02655347341769E-7,1.13000688843357E-5,8.38317261600989E-7,-3.89654653029795E-6,3.34680213019097E-7,1.00015271878026,10.005763053894,2,20,1,3,0.0381009338089824,-0.00946325632122327,0.0403775237500668,172.74836730957,52.0046195983887,52.0088920593262,1000.16674804688,1000.16674804688,,,23.2344646453857,0,1,,,,,,1,1,1,52.0067176818848,0,52.0062580108643,,,,,,,,,,,,,,,,,,,,,,,,,,,,,,,,,