File: Experimental_Data/AC_Suceptibillity_FieldScans/ZFCd_Down_52K.dat
[Header]
; MPMS3 Data File (default extension .dat)
; Copyright (c) 2007, Quantum Design, Inc. All rights reserved.
TITLE,ZFCd_Down_52K
FILEOPENTIME,3772389132.70157,07/15/2019,9:52 pm
BYAPP,SQUID AC,0.9.1.0
INFO,MPMS3 Measurement Release 1.1.16 Build 347, MultiVu Release 2.3.3.2,APPNAME
INFO,0,MOMENT_UNITS
INFO,Cu2OSeO3,SAMPLE_MATERIAL
INFO,,SAMPLE_COMMENT
INFO,,SAMPLE_MASS
INFO,,SAMPLE_VOLUME
INFO,,SAMPLE_MOLECULAR_WEIGHT
INFO,,SAMPLE_SIZE
INFO,,SAMPLE_SHAPE
INFO,Quartz,SAMPLE_HOLDER
INFO,Standard,SAMPLE_HOLDER_DETAIL
INFO,64.77,SAMPLE_OFFSET
DATATYPE,COMMENT,1
DATATYPE,TIME,2
STARTUPAXIS,X,2
STARTUPAXIS,Y1,5
FIELDGROUP, VSM,2,3,4,5,6,8,9,10,11,14,15
FIELDGROUP, DC, 2,3,4,14,56,57,58,59,60,61,62,63,64,65,66,67,68,69
FIELDGROUP, AC, 2,3,4,11,16,17,18,19,20,21,22,23,24,25,26,27,28,29,30
STARTUPGROUP, All
[Data]
Comment,Time Stamp (sec),Temperature (K),Magnetic Field (Oe),Moment (emu),M. Std. Err. (emu),Transport Action,Averaging Time (sec),Frequency (Hz),Peak Amplitude (mm),Center Position (mm),Lockin Signal' (V),Lockin Signal (V),Range,M. Quad. Signal (emu),AC Moment (emu),AC M. Std Err. (emu),AC Phase (deg),AC Phase Std. Err. (deg),AC Susceptibility (emu/Oe),AC Suscept. Std Err. (emu/Oe),AC X' (emu/Oe),AC X' Std Err. (emu/Oe),AC X'' (emu/Oe),AC X'' Std Err. (emu/Oe),AC Drive (Oe),AC Frequency (Hz),AC Averaging Time (sec),AC Cycles,AC Range,AC Measure Type,AC Signal' (V),AC Signal'' (V),AC Trim Coil Ratio,AC Trim Coil Phase,Min. Temperature (K),Max. Temperature (K),Min. Field (Oe),Max. Field (Oe),Mass (grams),Motor Lag (deg),Pressure (Torr),Measure Count,Measurement Number,SQUID Status (code),Motor Status (code),Measure Status (code),Motor Current (amps),Motor Temp. (C),Temp. Status (code),Field Status (code),Chamber Status (code),Chamber Temp (K),Redirection State,Average Temp (K),Rotation Angle (deg),Rotator state,DC Moment Fixed Ctr (emu),DC Moment Err Fixed Ctr (emu),DC Moment Free Ctr (emu),DC Moment Err Free Ctr (emu),DC Fixed Fit,DC Free Fit,DC Calculated Center (mm),DC Calculated Center Err (mm),DC Scan Length (mm),DC Scan Time (s),DC Number of Points,DC Squid Drift,DC Min V (V),DC Max V (V),DC Scans per Measure,Map 01,Map 02,Map 03,Map 04,Map 05,Map 06,Map 07,Map 08,Map 09,Map 10,Map 11,Map 12,Map 13,Map 14,Map 15,Map 16
,3772389266.56878,51.9667148590088,-0.352141469717026,,,5,,,,6.47999998182058,,,,,0.000536823825995995,1.99700312490366E-8,0.0222042399045446,1.21292784601889E-5,0.000536742179825095,1.99669939833541E-8,0.000536742139519784,1.8878705484684E-8,2.08007499517257E-7,6.50194801223933E-9,1.00015211431851,10.005763053894,2,20,1,3,1.75601879014648,0.154805986707985,0.0403775237500668,172.74836730957,51.932445526123,51.9794120788574,-0.352141469717026,-0.352141469717026,,,23.6459884643555,0,1,,,,,,1,1,1,51.9617118835449,0,51.9541563554244,,,,,,,,,,,,,,,,,,,,,,,,,,,,,,,,,
,3772389288.21133,51.9057846069336,-19.9020652770996,,,5,,,,6.47999998182058,,,,,0.000536534327706305,1.87866848398254E-8,0.0218075380601324,1.1085564662754E-5,0.000536452497728613,1.87838195730159E-8,0.000536452458871611,1.78203020944787E-8,2.04180972466569E-7,5.93874658603398E-9,1.00015253909347,10.005763053894,2,20,1,3,1.75507058104388,0.154747218886903,0.0403775237500668,172.74836730957,51.8965263366699,51.9095497131348,-19.9020652770996,-19.9020652770996,,,23.6829719543457,0,1,,,,,,1,1,1,51.9037170410156,0,51.9017383575439,,,,,,,,,,,,,,,,,,,,,,,,,,,,,,,,,
,3772389310.09168,51.8769359588623,-39.8162727355957,,,5,,,,6.47999998182058,,,,,0.00053904351061141,2.66965988889554E-8,0.0249544540090572,2.91329048795382E-5,0.000538961329145617,2.66925287803553E-8,0.000538961278027072,2.1588992773155E-8,2.34737800757941E-7,1.56973400208684E-8,1.00015248119178,10.005763053894,2,20,1,3,1.76326754455741,0.155605417092754,0.0403775237500668,172.74836730957,51.873363494873,51.8819007873535,-39.8162727355957,-39.8162727355957,,,23.6963500976562,0,1,,,,,,1,1,1,51.8751220703125,0,51.876336184415,,,,,,,,,,,,,,,,,,,,,,,,,,,,,,,,,
,3772389331.73398,51.9179172515869,-59.8883361816406,,,5,,,,6.47999998182058,,,,,0.000549289479986781,3.52438599672691E-8,0.0406406722334536,1.89735806503409E-5,0.000549205273740326,3.52384570726815E-8,0.000549205135580688,3.36686113312038E-8,3.89558704620378E-7,1.04006474746311E-8,1.00015332381257,10.005763053894,2,20,1,3,1.79673729931717,0.159093502520387,0.0403775237500668,172.74836730957,51.909294128418,51.9438743591309,-59.8883361816406,-59.8883361816406,,,23.7111148834229,0,1,,,,,,1,1,1,51.922721862793,0,51.9269180297852,,,,,,,,,,,,,,,,,,,,,,,,,,,,,,,,,
,3772389353.63945,51.960563659668,-79.8754043579102,,,5,,,,6.47999998182058,,,,,0.000567164156324957,1.16290242905955E-7,0.0843953033543379,8.09005069864052E-5,0.000567077469687534,1.16272468845288E-7,0.000567076854505546,1.06864364636582E-7,8.35291153733306E-7,4.58180595638662E-8,1.0001528655996,10.005763053894,2,20,1,3,1.85507724614991,0.165726921456404,0.0403775237500668,172.74836730957,51.9596061706543,51.9611892700195,-79.8754043579102,-79.8754043579102,,,23.7123680114746,0,1,,,,,,1,1,1,51.9609260559082,0,51.9605855941772,,,,,,,,,,,,,,,,,,,,,,,,,,,,,,,,,
,3772389376.73257,51.9658870697022,-99.9838943481445,,,5,,,,6.47999998182058,,,,,0.000607787189844953,2.21330541883244E-7,0.222787253899405,9.78623002340715E-5,0.000607694355445957,2.21296735498085E-7,0.00060768976145564,2.13256026286753E-7,2.36293522227165E-6,5.91110175389746E-8,1.00015276495193,10.005763053894,2,20,1,3,1.98750925282839,0.182441002392193,0.0403775237500668,172.74836730957,51.9632225036621,51.9661254882812,-99.9838943481445,-99.9838943481445,,,23.736177444458,0,1,,,,,,1,1,1,51.9656105041504,0,51.9645784551447,,,,,,,,,,,,,,,,,,,,,,,,,,,,,,,,,
,3772389399.81146,51.9825878143311,-119.837387084961,,,5,,,,6.47999998182058,,,,,0.00066535699433028,3.6286078467136E-7,0.312945859928964,0.000141338002365103,0.000665255163589166,3.62805249999088E-7,0.000665245240421374,3.50626029249349E-7,3.63356281861805E-6,9.32150043701941E-8,1.00015307020026,10.005763053894,2,20,1,3,2.17544671286803,0.203191507185523,0.0403775237500668,172.74836730957,51.9771194458008,51.9964790344238,-119.837387084961,-119.837387084961,,,23.7373847961426,0,1,,,,,,1,1,1,51.9848136901855,0,51.9872566858927,,,,,,,,,,,,,,,,,,,,,,,,,,,,,,,,,
,3772389422.79608,52.0131206512451,-139.897308349609,,,5,,,,6.47999998182058,,,,,0.000701623734292015,1.79180690461329E-7,0.183561708350854,0.000107856718923205,0.000701516499845825,1.79153304925222E-7,0.00070151289964738,1.62450892678742E-7,2.2474839849651E-6,7.55355157095601E-8,1.00015286090379,10.005763053894,2,20,1,3,2.29449900505344,0.209135217343435,0.0403775237500668,172.74836730957,52.010913848877,52.013313293457,-139.897308349609,-139.897308349609,,,23.7488479614258,0,1,,,,,,1,1,1,52.0133399963379,0,52.0123870849609,,,,,,,,,,,,,,,,,,,,,,,,,,,,,,,,,
,3772389446.41546,52.0055027008057,-160.005798339844,,,5,,,,6.47999998182058,,,,,0.000716979720554845,7.54076436756783E-8,0.0824493768381513,3.83432458986188E-5,0.000716870306758289,7.53961361862091E-8,0.000716869564525713,7.02237990770174E-8,1.03158540069478E-6,2.74444055319128E-8,1.00015262704498,10.005763053894,2,20,10,3,2.34508752214173,0.20962476686148,0.0403775237500668,172.74836730957,52.0051612854004,52.0074348449707,-160.005798339844,-160.005798339844,,,23.7369441986084,0,1,,,,,,1,1,1,52.0058441162109,0,52.0059425830841,,,,,,,,,,,,,,,,,,,,,,,,,,,,,,,,,
,3772389472.62168,52.0387554168701,-179.822860717773,,,5,,,,6.47999998182058,,,,,0.00072396021442311,9.67280569496195E-8,0.0460798183805915,9.05334051671561E-5,0.000723849547621176,9.67132707990732E-8,0.00072384931352488,7.1135877351841E-8,5.82151990548208E-7,6.55220856050744E-8,1.00015288646971,10.005763053894,2,20,10,3,2.36804996779822,0.210212657496554,0.0403775237500668,172.74836730957,52.0354804992676,52.0394248962402,-179.822860717773,-179.822860717773,,,23.7489700317383,0,1,,,,,,1,1,1,52.0394172668457,0,52.0379499955611,,,,,,,,,,,,,,,,,,,,,,,,,,,,,,,,,
,3772389494.5256,52.0295867919922,-199.882781982422,,,5,,,,6.47999998182058,,,,,0.000729310664305067,1.05186167252966E-7,0.027965498306191,0.000113875071809016,0.000729199318192431,1.05170108155794E-7,0.000729199231333174,6.45467862034969E-8,3.55914897421762E-7,8.30329093811698E-8,1.00015269640256,10.005763053894,2,20,10,3,2.38561474338727,0.211063281986687,0.0403775237500668,172.74836730957,52.0228652954102,52.0314292907715,-199.882781982422,-199.882781982422,,,23.7359390258789,0,1,,,,,,1,1,1,52.0285491943359,0,52.0271697998047,,,,,,,,,,,,,,,,,,,,,,,,,,,,,,,,,
,3772389515.98142,52.0139198303223,-219.906265258789,,,5,,,,6.47999998182058,,,,,0.000733609073929232,9.69433605902611E-8,0.0170276484333849,6.92904347583483E-5,0.0007334970924169,9.69285627033276E-8,0.000733497060025294,8.25465243578704E-8,2.17986918737745E-7,5.08056845654934E-8,1.00015266797032,10.005763053894,2,20,10,3,2.39971235357698,0.211900622251509,0.0403775237500668,172.74836730957,52.0078506469727,52.0163192749023,-219.906265258789,-219.906265258789,,,23.7236042022705,0,1,,,,,,1,1,1,52.0125617980957,0,52.0118723782626,,,,,,,,,,,,,,,,,,,,,,,,,,,,,,,,,
,3772389538.15182,52.0198421478271,-239.881195068359,,,5,,,,6.47999998182058,,,,,0.000736804147386532,1.52210300053949E-7,0.0136013066183356,0.000171146677147096,0.000736691563062936,1.52187042185848E-7,0.000736691542305596,8.52381164950266E-8,1.74881427976088E-7,1.26076799236248E-7,1.0001528242337,10.005763053894,2,20,10,3,2.41017329348934,0.212730877770503,0.0403775237500668,172.74836730957,52.0185127258301,52.0205841064453,-239.881195068359,-239.881195068359,,,23.7228755950928,0,1,,,,,,1,1,1,52.0203323364258,0,52.0197925567627,,,,,,,,,,,,,,,,,,,,,,,,,,,,,,,,,
,3772389559.78065,52.0136985778809,-259.79541015625,,,5,,,,6.47999998182058,,,,,0.000739703998853038,1.27204904707051E-7,1.74953335196903E-5,9.43914994914964E-5,0.00073959109447008,1.27185488844358E-7,0.000739591094470045,1.06326374193774E-7,2.25835008719834E-10,6.97914803065799E-8,1.0001526578454,10.005763053894,2,20,10,3,2.41970641472373,0.213046060253033,0.0403775237500668,172.74836730957,52.01025390625,52.0158081054687,-259.79541015625,-259.79541015625,,,23.7218551635742,0,1,,,,,,1,1,1,52.0126647949219,0,52.012528852983,,,,,,,,,,,,,,,,,,,,,,,,,,,,,,,,,
,3772389581.72074,52.0071582794189,-279.855346679687,,,5,,,,6.47999998182058,,,,,0.000742355407087835,1.47899540553402E-7,-0.0114079467025681,7.50186188453138E-5,0.000742242064640853,1.47876959326575E-7,0.000742242049928394,1.37007597454526E-7,-1.47785018893883E-7,5.56463236828097E-8,1.00015270280732,10.005763053894,2,20,10,3,2.42841901617734,0.213377611211436,0.0403775237500668,172.74836730957,52.0049324035645,52.0080795288086,-279.855346679687,-279.855346679687,,,23.7097702026367,0,1,,,,,,1,1,1,52.0069160461426,0,52.0064022064209,,,,,,,,,,,,,,,,,,,,,,,,,,,,,,,,,
,3772389603.33984,52.0376033782959,-299.890960693359,,,5,,,,6.47999998182058,,,,,0.000744658915930677,2.52003278717168E-7,-0.0101531084350102,0.000134166145230251,0.000744545038881434,2.51964741087166E-7,0.000744545027191455,2.31342214325478E-7,-1.31937230616137E-7,9.98349168483014E-8,1.00015294850317,10.005763053894,2,20,10,3,2.43594642458645,0.21414519192407,0.0403775237500668,172.74836730957,52.0354385375977,52.0387001037598,-299.890960693359,-299.890960693359,,,23.7081661224365,0,1,,,,,,1,1,1,52.0384063720703,0,52.0374710083008,,,,,,,,,,,,,,,,,,,,,,,,,,,,,,,,,
,3772389625.29233,52.0236377716064,-319.950866699219,,,5,,,,6.47999998182058,,,,,0.000747211666754532,1.52141208848951E-7,-0.0243363984531983,9.48217817551121E-5,0.000747097705279368,1.5211800493316E-7,0.000747097637886374,1.34628231307607E-7,-3.17329950774062E-7,7.08175596856481E-8,1.00015253891741,10.005763053894,2,20,10,3,2.44434692286693,0.21432675160344,0.0403775237500668,172.74836730957,52.0158576965332,52.0267219543457,-319.950866699219,-319.950866699219,,,23.6944847106934,0,1,,,,,,1,1,1,52.0224990844727,0,52.0211129622026,,,,,,,,,,,,,,,,,,,,,,,,,,,,,,,,,
,3772389646.88618,52.0097522735596,-339.840789794922,,,5,,,,6.47999998182058,,,,,0.000749864592040326,2.23194928704777E-7,-0.0547246655006584,0.000202246003113651,0.000749750186153961,2.23160876138591E-7,0.000749749844168597,1.63748254218811E-7,-7.16105483801271E-7,1.51615585871754E-7,1.00015259200795,10.005763053894,2,20,10,3,2.45313594932815,0.213838918643954,0.0403775237500668,172.74836730957,52.0058860778809,52.0119323730469,-339.840789794922,-339.840789794922,,,23.6821537017822,0,1,,,,,,1,1,1,52.0084686279297,0,52.0081066131592,,,,,,,,,,,,,,,,,,,,,,,,,,,,,,,,,
,3772389668.78992,52.0144882202148,-359.985717773438,,,5,,,,6.47999998182058,,,,,0.000751530484066933,1.8793651713517E-7,-0.0536961328413073,0.000142631391981867,0.000751415661191359,1.87907803181737E-7,0.000751415331208813,1.54357619262386E-7,-7.04207353473477E-7,1.07159077414071E-7,1.00015280873357,10.005763053894,2,20,10,3,2.45857872443729,0.214411100874197,0.0403775237500668,172.74836730957,52.0126342773438,52.0146903991699,-359.985717773438,-359.985717773438,,,23.6817111968994,0,1,,,,,,1,1,1,52.0146484375,0,52.0139186859131,,,,,,,,,,,,,,,,,,,,,,,,,,,,,,,,,
,3772389690.43961,52.0074729919434,-380.009216308594,,,5,,,,6.47999998182058,,,,,0.000752981718044071,2.73851625597725E-7,-0.0663064256244015,0.000195216929442721,0.000752866742336322,2.73809810127686E-7,0.000752866238192978,2.31034178710009E-7,-8.71266469143026E-7,1.46952442613081E-7,1.00015271720915,10.005763053894,2,20,10,3,2.46337033374778,0.21433579222344,0.0403775237500668,172.74836730957,52.0053596496582,52.0087852478027,-380.009216308594,-380.009216308594,,,23.6681137084961,0,1,,,,,,1,1,1,52.0068206787109,0,52.0066883087158,,,,,,,,,,,,,,,,,,,,,,,,,,,,,,,,,
,3772389712.3728,52.0200157165527,-399.899139404297,,,5,,,,6.47999998182058,,,,,0.000753895731476089,2.65979327411482E-7,-0.0823713884000892,0.000228083960395928,0.000753780529557139,2.65938683423674E-7,0.000753779750584233,2.02907684963747E-7,-1.08367366510892E-6,1.71906529031825E-7,1.00015283217652,10.005763053894,2,20,10,3,2.46641740675214,0.213956877392841,0.0403775237500668,172.74836730957,52.0183029174805,52.0204887390137,-399.899139404297,-399.899139404297,,,23.6550827026367,0,1,,,,,,1,1,1,52.0203666687012,0,52.0195468902588,,,,,,,,,,,,,,,,,,,,,,,,,,,,,,,,,
,3772389734.00243,52.0098323822022,-419.910491943359,,,5,,,,6.47999998182058,,,,,0.000754392813679233,2.90729510150325E-7,-0.0881631603197759,0.000196264762901722,0.000754277714163157,2.90685152853542E-7,0.000754276821206809,2.50171511882276E-7,-1.1606348907822E-6,1.48027270230939E-7,1.00015259567387,10.005763053894,2,20,10,3,2.46806206355442,0.213901363269156,0.0403775237500668,172.74836730957,52.0068969726562,52.0113487243652,-419.910491943359,-419.910491943359,,,23.6418209075928,0,1,,,,,,1,1,1,52.0088996887207,0,52.0086730957031,,,,,,,,,,,,,,,,,,,,,,,,,,,,,,,,,
,3772389755.93747,52.0239677429199,-439.970397949219,,,5,,,,6.47999998182058,,,,,0.000753630299603429,3.66734246444658E-7,-0.095384310888126,0.000185071257713413,0.000753515174900387,3.66678224053786E-7,0.000753514130732013,3.39121758064517E-7,-1.25442908907648E-6,1.39460937909044E-7,1.00015278352298,10.005763053894,2,20,10,3,2.46559114451177,0.213427294709099,0.0403775237500668,172.74836730957,52.0195045471191,52.0240173339844,-439.970397949219,-439.970397949219,,,23.6404418945313,0,1,,,,,,1,1,1,52.0239944458008,0,52.0226299285889,,,,,,,,,,,,,,,,,,,,,,,,,,,,,,,,,
,3772389777.50989,52.0340900421143,-460.309631347656,,,5,,,,6.47999998182058,,,,,0.000751384196548367,3.42890735501669E-7,-0.108265684748583,0.000242793572592329,0.000751269411802874,3.42838354008969E-7,0.000751268070576852,2.90291381747062E-7,-1.41959232578393E-6,1.82398055535033E-7,1.0001527877266,10.005763053894,2,20,10,3,2.45828730444974,0.212292002118172,0.0403775237500668,172.74836730957,52.0309638977051,52.0341567993164,-460.309631347656,-460.309631347656,,,23.6275310516357,0,1,,,,,,1,1,1,52.0341949462891,0,52.0331008911133,,,,,,,,,,,,,,,,,,,,,,,,,,,,,,,,,
,3772389799.52224,52.0525054931641,-480.175231933594,,,5,,,,6.47999998182058,,,,,0.00074497992877232,4.55465261394116E-7,-0.123816788410259,0.000393099991606724,0.000744866092987507,4.55395664558708E-7,0.000744864353738173,3.48801687545816E-7,-1.60966228979546E-6,2.92784210749244E-7,1.00015282718046,10.005763053894,2,20,10,3,2.43738853251667,0.209872788075763,0.0403775237500668,172.74836730957,52.0442848205566,52.052604675293,-480.175231933594,-480.175231933594,,,23.6149444580078,0,1,,,,,,1,1,1,52.0523109436035,0,52.0499368147417,,,,,,,,,,,,,,,,,,,,,,,,,,,,,,,,,
,3772389821.13161,52.0439376831055,-500.259460449219,,,5,,,,6.47999998182058,,,,,0.000728538141769236,3.62424882945228E-7,-0.138606426925849,0.000192381822166446,0.000728426936756409,3.62369561938069E-7,0.000728424805296044,3.34154188841573E-7,-1.76216393878086E-6,1.40188007685459E-7,1.0001526646081,10.005763053894,2,20,10,3,2.38364493641312,0.204676860189184,0.0403775237500668,172.74836730957,52.0357704162598,52.045970916748,-500.259460449219,-500.259460449219,,,23.6128444671631,0,1,,,,,,1,1,1,52.042854309082,0,52.0410396575928,,,,,,,,,,,,,,,,,,,,,,,,,,,,,,,,,
,3772389843.0444,52.0228137969971,-520.282958984375,,,5,,,,6.47999998182058,,,,,0.000683785599203209,3.11240570462249E-7,-0.146886771101623,0.000259295576940906,0.000683681258529156,3.11193077430877E-7,0.000683679011837125,2.55760597127467E-7,-1.75272285983953E-6,1.77278448768882E-7,1.00015261596358,10.005763053894,2,20,10,3,2.23724758787314,0.191828683684716,0.0403775237500668,172.74836730957,52.0161781311035,52.025447845459,-520.282958984375,-520.282958984375,,,23.5881881713867,0,1,,,,,,1,1,1,52.0215034484863,0,52.0205940246582,,,,,,,,,,,,,,,,,,,,,,,,,,,,,,,,,
,3772389864.67889,52.0332984924316,-540.330749511719,,,5,,,,6.47999998182058,,,,,0.000555233223175938,4.91463541188577E-7,-0.224115886397667,0.000445519292997161,0.000555148359724298,4.91388424479562E-7,0.000555144112760766,4.24554618039234E-7,-2.17149064919496E-6,2.47418592700845E-7,1.00015286625666,10.005763053894,2,20,10,3,1.81684883762255,0.153354850359905,0.0403775237500668,172.74836730957,52.0286254882812,52.0334281921387,-540.330749511719,-540.330749511719,,,23.5753402709961,0,1,,,,,,1,1,1,52.0333442687988,0,52.0317268371582,,,,,,,,,,,,,,,,,,,,,,,,,,,,,,,,,
,3772389889.77934,52.0151348114014,-560.244934082031,,,5,,,,6.47999998182058,,,,,0.000369603652033167,4.87713179664059E-7,-0.303505471322352,0.000732929751783305,0.000369547298263562,4.8763881763866E-7,0.000369542113525688,4.05436698612529E-7,-1.95754562301016E-6,2.70947780736812E-7,1.00015249406468,10.005763053894,2,20,1,3,1.20956566071577,0.100434070953364,0.0403775237500668,172.74836730957,52.0095558166504,52.0200538635254,-560.244934082031,-560.244934082031,,,23.5619831085205,0,1,,,,,,1,1,1,52.0138893127441,0,52.0143312726702,,,,,,,,,,,,,,,,,,,,,,,,,,,,,,,,,
,3772389912.25105,52.0055656433105,-580.244140625,,,5,,,,6.47999998182058,,,,,0.000178390945858323,4.86918653571274E-7,-0.733521932420991,0.00117943682542873,0.000178363701752133,4.86844290696858E-7,0.000178349084979464,4.38719103341726E-7,-2.28341623706873E-6,2.11051917184277E-7,1.00015274467799,10.005763053894,2,20,1,3,0.584149320568798,0.0441046034329792,0.0403775237500668,172.74836730957,52.0040130615234,52.0063705444336,-580.244140625,-580.244140625,,,23.5491504669189,0,1,,,,,,1,1,1,52.0053443908691,0,52.0050994873047,,,,,,,,,,,,,,,,,,,,,,,,,,,,,,,,,
,3772389933.95472,52.0324287414551,-600.376953125,,,5,,,,6.47999998182058,,,,,9.80121274619273E-5,4.61990693855749E-7,-1.2546690174723,0.00234101731425053,9.79971396609998E-5,4.61920047245689E-7,9.79736444617717E-5,4.00480763100605E-7,-2.1457801881477E-6,2.30185334966885E-7,1.00015294120807,10.005763053894,2,20,1,3,0.321152050017917,0.0213188026977443,0.0403775237500668,172.74836730957,52.0302543640137,52.0337715148926,-600.376953125,-600.376953125,,,23.5601348876953,0,1,,,,,,1,1,1,52.0332527160645,0,52.0323154449463,,,,,,,,,,,,,,,,,,,,,,,,,,,,,,,,,
,3772389955.80909,52.019718170166,-620.351867675781,,,5,,,,6.47999998182058,,,,,6.34625670359531E-5,6.09073547905146E-7,-2.08284142660969,0.00634499006364227,6.34528848202334E-5,6.08980624127313E-7,6.34109629453097E-5,4.56653256432593E-7,-2.30615922224932E-6,4.02896021266033E-7,1.00015258905481,10.005763053894,2,20,1,3,0.208122697597969,0.0108012678190354,0.0403775237500668,172.74836730957,52.0122261047363,52.0222434997559,-620.351867675781,-620.351867675781,,,23.5342254638672,0,1,,,,,,1,1,1,52.0185852050781,0,52.016829403964,,,,,,,,,,,,,,,,,,,,,,,,,,,,,,,,,
,3772389978.86366,52.0275974273682,-640.302490234375,,,5,,,,6.47999998182058,,,,,4.88627539548451E-5,5.02520575278547E-7,-2.79245012844078,0.00511237589878769,4.88552871633252E-5,5.02443784347494E-7,4.87972747152127E-5,4.35055715590408E-7,-2.38013952931995E-6,2.51348922340138E-7,1.00015283487118,10.005763053894,2,20,1,3,0.160333912661472,0.00633460986388175,0.0403775237500668,172.74836730957,52.0226707458496,52.0277404785156,-640.302490234375,-640.302490234375,,,23.5090827941895,0,1,,,,,,1,1,1,52.0271759033203,0,52.0259936939586,,,,,,,,,,,,,,,,,,,,,,,,,,,,,,,,,
,3772390000.4912,52.0469055175781,-660.313842773437,,,5,,,,6.47999998182058,,,,,4.10701990946299E-5,4.88762168669594E-7,-3.65989880864885,0.00613720049872075,4.10639245096582E-5,4.8868749701409E-7,4.09801762729465E-5,4.17731956084964E-7,-2.6212685427368E-6,2.5360497353823E-7,1.00015280042145,10.005763053894,2,20,1,3,0.134829280321,0.00328641664462843,0.0403775237500668,172.74836730957,52.042667388916,52.0470848083496,-660.313842773437,-660.313842773437,,,23.5196533203125,0,1,,,,,,1,1,1,52.0470695495605,0,52.0455348968506,,,,,,,,,,,,,,,,,,,,,,,,,,,,,,,,,
,3772390022.39919,52.0294666290283,-680.288696289063,,,5,,,,6.47999998182058,,,,,3.63864560941614E-5,4.966867330405E-7,-4.32867228807132,0.00761800949208446,3.63809052356738E-5,4.96610962051409E-7,3.62771282441605E-5,4.11220638569591E-7,-2.74594831047598E-6,2.7842419802173E-7,1.00015257615091,10.005763053894,2,20,1,3,0.119478910055056,0.00151972020901335,0.0403775237500668,172.74836730957,52.0206565856934,52.0327186584473,-680.288696289063,-680.288696289063,,,23.5066871643066,0,1,,,,,,1,1,1,52.0280952453613,0,52.0263553619385,,,,,,,,,,,,,,,,,,,,,,,,,,,,,,,,,
,3772390043.98717,52.0486755371094,-700.178649902344,,,5,,,,6.47999998182058,,,,,3.56330349315073E-5,5.5775461008879E-7,-6.89396455443882,0.00755257231143129,3.56275881352178E-5,5.57669352805863E-7,3.53700003681535E-5,4.87307061049725E-7,-4.27646001846493E-6,2.71158505877999E-7,1.00015288142068,10.005763053894,2,20,1,3,0.116954469338667,-0.00374764980715389,0.0403775237500668,172.74836730957,52.0432624816895,52.0489921569824,-700.178649902344,-700.178649902344,,,23.4705123901367,0,1,,,,,,1,1,1,52.0489845275879,0,52.0469497680664,,,,,,,,,,,,,,,,,,,,,,,,,,,,,,,,,
,3772390065.94899,52.032205581665,-720.2021484375,,,5,,,,6.47999998182058,,,,,3.22456731476559E-5,6.93635879503257E-7,-6.7050091320961,0.0100535332170266,3.22407536362434E-5,6.93530056014639E-7,3.20202412512321E-5,6.11584556518339E-7,-3.76435190249732E-6,3.27029461706335E-7,1.00015258673752,10.005763053894,2,20,1,3,0.105847229474445,-0.00304006959365835,0.0403775237500668,172.74836730957,52.0240135192871,52.0354843139648,-720.2021484375,-720.2021484375,,,23.4808979034424,0,1,,,,,,1,1,1,52.0306549072266,0,52.0292678833008,,,,,,,,,,,,,,,,,,,,,,,,,,,,,,,,,
,3772390087.55533,52.0150318145752,-740.225646972656,,,5,,,,6.47999998182058,,,,,3.07816551693666E-5,6.45321486479659E-7,-7.60064833074196,0.00897669997467212,3.07769584791923E-5,6.45223022798348E-7,3.05065534651035E-5,5.81764148317509E-7,-4.07079462890341E-6,2.79039826694041E-7,1.00015260410406,10.005763053894,2,20,1,3,0.100983998361458,-0.00447893309250674,0.0403775237500668,172.74836730957,52.0099754333496,52.0169067382812,-740.225646972656,-740.225646972656,,,23.4666061401367,0,1,,,,,,1,1,1,52.0140571594238,0,52.0130214691162,,,,,,,,,,,,,,,,,,,,,,,,,,,,,,,,,
,3772390109.47094,52.0372982025146,-760.297729492188,,,5,,,,6.47999998182058,,,,,3.02859709038932E-5,6.749135424569E-7,-7.8930062901912,0.0100628521670258,3.02813433155192E-5,6.74810418073916E-7,2.99944649181126E-5,6.00896343024355E-7,-4.15834429412149E-6,3.070711404236E-7,1.00015281978497,10.005763053894,2,20,1,3,0.0993342098424558,-0.00491160929396404,0.0403775237500668,172.74836730957,52.0315055847168,52.0374412536621,-760.297729492188,-760.297729492188,,,23.4423046112061,0,1,,,,,,1,1,1,52.0373916625977,0,52.0354530334473,,,,,,,,,,,,,,,,,,,,,,,,,,,,,,,,,
,3772390131.11006,52.0286197662354,-780.199768066406,,,5,,,,6.47999998182058,,,,,2.88628422070436E-5,7.28810652597523E-7,-8.03667550752451,0.016840855112507,2.88584369046126E-5,7.28699415065315E-7,2.85750118471041E-5,5.42691545926755E-7,-4.03461008219726E-6,4.86301062610562E-7,1.00015265214972,10.005763053894,2,20,1,3,0.0946546469798539,-0.00491616553860788,0.0403775237500668,172.74836730957,52.0226402282715,52.0299224853516,-780.199768066406,-780.199768066406,,,23.4297199249268,0,1,,,,,,1,1,1,52.0280570983887,0,52.026452255249,,,,,,,,,,,,,,,,,,,,,,,,,,,,,,,,,
,3772390153.02366,52.0461196899414,-800.308227539063,,,5,,,,6.47999998182058,,,,,2.85443652603645E-5,6.96157450076261E-7,-9.07862068477371,0.0136107502890673,2.85400053618402E-5,6.96051118202645E-7,2.81824776659268E-5,5.77140755667481E-7,-4.50331640720538E-6,3.89096012956599E-7,1.00015276446059,10.005763053894,2,20,1,3,0.093506516727865,-0.00656135704693704,0.0403775237500668,172.74836730957,52.0403251647949,52.0462875366211,-800.308227539063,-800.308227539063,,,23.4168949127197,0,1,,,,,,1,1,1,52.0460052490234,0,52.0443790435791,,,,,,,,,,,,,,,,,,,,,,,,,,,,,,,,,
,3772390174.67734,52.0244388580322,-820.343933105469,,,5,,,,6.47999998182058,,,,,2.68485251042512E-5,7.39857720324168E-7,-8.77084593001375,0.0141691554816973,2.6844429299973E-5,7.39744853326655E-7,2.65305131740667E-5,6.33745118060799E-7,-4.09331835579852E-6,3.81562017707971E-7,1.00015257557657,10.005763053894,2,20,1,3,0.0879832842809953,-0.00569712734508024,0.0403775237500668,172.74836730957,52.0168037414551,52.027530670166,-820.343933105469,-820.343933105469,,,23.4146461486816,0,1,,,,,,1,1,1,52.022590637207,0,52.0214946746826,,,,,,,,,,,,,,,,,,,,,,,,,,,,,,,,,
,3772390196.64554,52.0393619537354,-840.40380859375,,,5,,,,6.47999998182058,,,,,2.86302438388393E-5,7.2656316445055E-7,-10.1158780015385,0.013039273524533,2.86258698210138E-5,7.26452162942823E-7,2.81808676197346E-5,6.23290011655859E-7,-5.02783484301318E-6,3.73151854362732E-7,1.0001527994731,10.005763053894,2,20,1,3,0.0936537953585781,-0.00827381818031385,0.0403775237500668,172.74836730957,52.0328598022461,52.0398139953613,-840.40380859375,-840.40380859375,,,23.3904838562012,0,1,,,,,,1,1,1,52.0387573242188,0,52.0375105539958,,,,,,,,,,,,,,,,,,,,,,,,,,,,,,,,,
,3772390218.0112,52.0278797149658,-860.257263183594,,,5,,,,6.47999998182058,,,,,2.6432526512703E-5,6.8762922192187E-7,-10.0531298446567,0.0109166352552993,2.64284930414558E-5,6.8752429314429E-7,2.60227180804874E-5,6.24069890324045E-7,-4.61339226012187E-6,2.88489905637078E-7,1.00015261828364,10.005763053894,2,20,1,3,0.0864732556378528,-0.00754217462009001,0.0403775237500668,172.74836730957,52.0208854675293,52.0297508239746,-860.257263183594,-860.257263183594,,,23.3897361755371,0,1,,,,,,1,1,1,52.0269165039063,0,52.0254932750355,,,,,,,,,,,,,,,,,,,,,,,,,,,,,,,,,
,3772390240.15608,52.0471153259277,-880.317260742188,,,5,,,,6.47999998182058,,,,,2.60882466931388E-5,7.10775338805472E-7,-9.76158972831994,0.0136886084734576,2.60842607566616E-5,7.10666741804556E-7,2.57066071707313E-5,6.14282495646938E-7,-4.42255661255134E-6,3.57357291025206E-7,1.00015281002266,10.005763053894,2,20,1,3,0.0853839235446401,-0.0070077478797209,0.0403775237500668,172.74836730957,52.040454864502,52.0472297668457,-880.317260742188,-880.317260742188,,,23.3651638031006,0,1,,,,,,1,1,1,52.047191619873,0,52.0452301025391,,,,,,,,,,,,,,,,,,,,,,,,,,,,,,,,,
,3772390261.85627,52.0466136932373,-900.000671386719,,,5,,,,6.47999998182058,,,,,2.39374655200209E-5,7.25996495521126E-7,-9.41395801793953,0.0169838730748264,2.39338114896333E-5,7.25885672875608E-7,2.36114791483816E-5,6.01092532637544E-7,-3.91476497977108E-6,4.0693706797668E-7,1.00015267231419,10.005763053894,2,20,1,3,0.0783823949559238,-0.00595290963938464,0.0403775237500668,172.74836730957,52.0383682250977,52.0474624633789,-900.000671386719,-900.000671386719,,,23.363208770752,0,1,,,,,,1,1,1,52.0459671020508,0,52.0437858581543,,,,,,,,,,,,,,,,,,,,,,,,,,,,,,,,,
,3772390283.69524,52.0330715179443,-919.951354980469,,,5,,,,6.47999998182058,,,,,2.44694824184109E-5,9.07115719881663E-7,-9.55762613502902,0.0140575040132662,2.44657483001976E-5,9.06977291235188E-7,2.41261417798417E-5,8.38701738092897E-7,-4.0622804811584E-6,3.45234994367999E-7,1.00015262636431,10.005763053894,2,20,1,3,0.0801091334734348,-0.00628440126273401,0.0403775237500668,172.74836730957,52.0250663757324,52.0352096557617,-919.951354980469,-919.951354980469,,,23.3498878479004,0,1,,,,,,1,1,1,52.0319557189941,0,52.0302906036377,,,,,,,,,,,,,,,,,,,,,,,,,,,,,,,,,
,3772390305.31148,52.0145950317383,-939.974853515625,,,5,,,,6.47999998182058,,,,,2.42719295636512E-5,8.00634815448849E-7,-10.8434175265881,0.0197352943428136,2.42682238333248E-5,8.00512578083739E-7,2.38349140931648E-5,6.41899994327907E-7,-4.56547458604338E-6,4.7831452513185E-7,1.00015269886877,10.005763053894,2,20,1,3,0.0793027047827795,-0.00801349057665636,0.0403775237500668,172.74836730957,52.0100021362305,52.0158424377441,-939.974853515625,-939.974853515625,,,23.3369255065918,0,1,,,,,,1,1,1,52.0140495300293,0,52.0129669189453,,,,,,,,,,,,,,,,,,,,,,,,,,,,,,,,,
,3772390327.20621,52.0368824005127,-960.010498046875,,,5,,,,6.47999998182058,,,,,2.43111318027336E-5,6.85824703785033E-7,-11.0927325672779,0.014411730944353,2.4307417610919E-5,6.85719925261278E-7,2.38532839679056E-5,5.90251428281786E-7,-4.67668631170305E-6,3.49020153159734E-7,1.00015280075712,10.005763053894,2,20,1,3,0.0793953336474023,-0.00837029749988513,0.0403775237500668,172.74836730957,52.0310173034668,52.0371932983398,-960.010498046875,-960.010498046875,,,23.3233413696289,0,1,,,,,,1,1,1,52.0368919372559,0,52.0349544525146,,,,,,,,,,,,,,,,,,,,,,,,,,,,,,,,,
,3772390348.85181,52.0198268890381,-980.070373535156,,,5,,,,6.47999998182058,,,,,2.24934884356141E-5,8.16549049359915E-7,-10.6182662560005,0.0171010561982249,2.24900565872449E-5,8.16424467860187E-7,2.21049515745652E-5,7.20682072483245E-7,-4.14412369308694E-6,3.83622551633823E-7,1.00015259402998,10.005763053894,2,20,1,3,0.0735210773957071,-0.00713433725705722,0.0403775237500668,172.74836730957,52.0148468017578,52.0216522216797,-980.070373535156,-980.070373535156,,,23.3110427856445,0,1,,,,,,1,1,1,52.0190467834473,0,52.0180820465088,,,,,,,,,,,,,,,,,,,,,,,,,,,,,,,,,
,3772390370.8428,52.0114307403564,-999.984619140625,,,5,,,,6.47999998182058,,,,,2.38466825474818E-5,6.83157420496814E-7,-11.4312905441172,0.0174247246184549,2.38430424583799E-5,6.83053139581585E-7,2.33700700093607E-5,5.4285371478826E-7,-4.72551599613035E-6,4.14573800224817E-7,1.00015266881767,10.005763053894,2,20,1,3,0.0778291167659075,-0.00866710713422747,0.0403775237500668,172.74836730957,52.0084571838379,52.0126342773438,-999.984619140625,-999.984619140625,,,23.2857151031494,0,1,,,,,,1,1,1,52.011043548584,0,52.010404586792,,,,,,,,,,,,,,,,,,,,,,,,,,,,,,,,,