File: Experimental_Data/AC_Suceptibillity_FieldScans/ZFCd_Down_30K.dat
[Header]
; MPMS3 Data File (default extension .dat)
; Copyright (c) 2007, Quantum Design, Inc. All rights reserved.
TITLE,ZFCd_Down_30K
FILEOPENTIME,3772424415.04033,07/16/2019,7:40 am
BYAPP,SQUID AC,0.9.1.0
INFO,MPMS3 Measurement Release 1.1.16 Build 347, MultiVu Release 2.3.3.2,APPNAME
INFO,0,MOMENT_UNITS
INFO,Cu2OSeO3,SAMPLE_MATERIAL
INFO,,SAMPLE_COMMENT
INFO,,SAMPLE_MASS
INFO,,SAMPLE_VOLUME
INFO,,SAMPLE_MOLECULAR_WEIGHT
INFO,,SAMPLE_SIZE
INFO,,SAMPLE_SHAPE
INFO,Quartz,SAMPLE_HOLDER
INFO,Standard,SAMPLE_HOLDER_DETAIL
INFO,64.77,SAMPLE_OFFSET
DATATYPE,COMMENT,1
DATATYPE,TIME,2
STARTUPAXIS,X,2
STARTUPAXIS,Y1,5
FIELDGROUP, VSM,2,3,4,5,6,8,9,10,11,14,15
FIELDGROUP, DC, 2,3,4,14,56,57,58,59,60,61,62,63,64,65,66,67,68,69
FIELDGROUP, AC, 2,3,4,11,16,17,18,19,20,21,22,23,24,25,26,27,28,29,30
STARTUPGROUP, All
[Data]
Comment,Time Stamp (sec),Temperature (K),Magnetic Field (Oe),Moment (emu),M. Std. Err. (emu),Transport Action,Averaging Time (sec),Frequency (Hz),Peak Amplitude (mm),Center Position (mm),Lockin Signal' (V),Lockin Signal (V),Range,M. Quad. Signal (emu),AC Moment (emu),AC M. Std Err. (emu),AC Phase (deg),AC Phase Std. Err. (deg),AC Susceptibility (emu/Oe),AC Suscept. Std Err. (emu/Oe),AC X' (emu/Oe),AC X' Std Err. (emu/Oe),AC X'' (emu/Oe),AC X'' Std Err. (emu/Oe),AC Drive (Oe),AC Frequency (Hz),AC Averaging Time (sec),AC Cycles,AC Range,AC Measure Type,AC Signal' (V),AC Signal'' (V),AC Trim Coil Ratio,AC Trim Coil Phase,Min. Temperature (K),Max. Temperature (K),Min. Field (Oe),Max. Field (Oe),Mass (grams),Motor Lag (deg),Pressure (Torr),Measure Count,Measurement Number,SQUID Status (code),Motor Status (code),Measure Status (code),Motor Current (amps),Motor Temp. (C),Temp. Status (code),Field Status (code),Chamber Status (code),Chamber Temp (K),Redirection State,Average Temp (K),Rotation Angle (deg),Rotator state,DC Moment Fixed Ctr (emu),DC Moment Err Fixed Ctr (emu),DC Moment Free Ctr (emu),DC Moment Err Free Ctr (emu),DC Fixed Fit,DC Free Fit,DC Calculated Center (mm),DC Calculated Center Err (mm),DC Scan Length (mm),DC Scan Time (s),DC Number of Points,DC Squid Drift,DC Min V (V),DC Max V (V),DC Scans per Measure,Map 01,Map 02,Map 03,Map 04,Map 05,Map 06,Map 07,Map 08,Map 09,Map 10,Map 11,Map 12,Map 13,Map 14,Map 15,Map 16
,3772424573.56213,29.9083290100098,-0.230713382363319,,,5,,,,6.46999990567565,,,,,0.000598968745489247,7.45652896469713E-9,0.0292607965657137,8.14249580759993E-6,0.000598875074114594,7.45536285490672E-9,0.00059887499601779,5.64023922863892E-9,3.05843835255226E-7,4.87546272081385E-9,1.00015641221133,10.005763053894,2,20,1,3,1.9592668663298,0.17312932454339,0.0403775237500668,172.74836730957,29.9075756072998,29.9140586853027,-0.230713382363319,-0.230713382363319,,,29.9288444519043,0,1,,,,,,1,1,1,29.908899307251,0,29.909765625,,,,,,,,,,,,,,,,,,,,,,,,,,,,,,,,,
,3772424595.44561,29.9252862930298,-19.9263496398926,,,5,,,,6.46999990567565,,,,,0.000598955938857465,1.34201300242573E-8,0.0284799806158178,1.3210616433525E-5,0.000598862078934706,1.34180270108539E-8,0.000598862004951879,1.08391845287165E-8,2.97676021553583E-7,7.90920524556271E-9,1.0001567304494,10.005763053894,2,20,1,3,1.95922477867228,0.173140013647234,0.0403775237500668,172.74836730957,29.9180850982666,29.937801361084,-19.9263496398926,-19.9263496398926,,,29.7920379638672,0,1,,,,,,1,1,1,29.9283676147461,0,29.9300788879394,,,,,,,,,,,,,,,,,,,,,,,,,,,,,,,,,
,3772424617.06672,29.942403793335,-39.8891258239746,,,5,,,,6.46999990567565,,,,,0.000599056304674303,1.63876920946348E-8,0.0291440005633543,1.9035847680148E-5,0.000598962508655543,1.63851262251778E-8,0.000598962431169639,1.17689002496132E-8,3.04667518014128E-7,1.14002345734491E-8,1.00015659747882,10.005763053894,2,20,1,3,1.95954847910144,0.173233434424312,0.0403775237500668,172.74836730957,29.939380645752,29.9503288269043,-39.8891258239746,-39.8891258239746,,,29.729850769043,0,1,,,,,,1,1,1,29.9440689086914,0,29.9453636169434,,,,,,,,,,,,,,,,,,,,,,,,,,,,,,,,,
,3772424639.35756,29.9692878723145,-59.8883361816406,,,5,,,,6.46999990567565,,,,,0.000599452607043782,6.14471391857433E-8,0.0294009827483581,5.31913020550797E-5,0.000599358766649004,6.14375200369875E-8,0.000599358687738414,5.25264829579185E-8,3.07557312854978E-7,3.1867498432835E-8,1.00015656798565,10.005763053894,2,20,1,3,1.96084143781815,0.173398508995973,0.0403775237500668,172.74836730957,29.9655113220215,29.9795532226562,-59.8883361816406,-59.8883361816406,,,29.7547264099121,0,1,,,,,,1,1,1,29.9712753295898,0,29.9729305614125,,,,,,,,,,,,,,,,,,,,,,,,,,,,,,,,,
,3772424662.10095,29.9790019989014,-79.9482574462891,,,5,,,,6.46999990567565,,,,,0.000600125315235705,5.71531553791176E-8,0.0270117165654691,3.8041894335104E-5,0.000600031446443744,5.71442157501501E-8,0.000600031379762589,5.23954591285683E-8,2.82880849149025E-7,2.28073947746391E-8,1.00015643978748,10.005763053894,2,20,1,3,1.96304651910878,0.173553290670716,0.0403775237500668,172.74836730957,29.9769096374512,29.9813423156738,-79.9482574462891,-79.9482574462891,,,29.7920379638672,0,1,,,,,,1,1,1,29.9798488616943,0,29.9799879391988,,,,,,,,,,,,,,,,,,,,,,,,,,,,,,,,,
,3772424685.12765,29.9792900085449,-100.03246307373,,,5,,,,6.46999990567565,,,,,0.000601309888615069,8.5789303438554E-8,0.0260992886027243,7.20169196515963E-5,0.00060121589551777,8.57758933774558E-8,0.000601215833142488,7.40571186720587E-8,2.7386496458139E-7,4.32787136903731E-8,1.00015633834368,10.005763053894,2,20,1,3,1.96692146187877,0.173906829316573,0.0403775237500668,172.74836730957,29.97780418396,29.9799747467041,-100.03246307373,-100.03246307373,,,29.8666572570801,0,1,,,,,,1,1,1,29.9790306091309,0,29.9789093017578,,,,,,,,,,,,,,,,,,,,,,,,,,,,,,,,,
,3772424706.73514,29.9967021942139,-119.946670532227,,,5,,,,6.46999990567565,,,,,0.00060371966164616,1.21688172686592E-7,0.0295537145079665,9.03759697601664E-5,0.000603625225601302,1.21669137776078E-7,0.00060362514530117,1.08770720850268E-7,3.11355687064154E-7,5.45188900555338E-8,1.00015644814175,10.005763053894,2,20,1,3,1.97479083573389,0.174764718912789,0.0403775237500668,172.74836730957,29.9951667785645,29.9989337921143,-119.946670532227,-119.946670532227,,,29.9412803649902,0,1,,,,,,1,1,1,29.9976100921631,0,29.9975610733032,,,,,,,,,,,,,,,,,,,,,,,,,,,,,,,,,
,3772424728.65856,29.9999742507935,-140.006591796875,,,5,,,,6.46999990567565,,,,,0.000608890756128046,1.6947841774851E-7,0.0305203053057079,0.00016802777164285,0.000608795559524717,1.69451920762729E-7,0.000608795473152523,1.35111192986002E-7,3.24293091474726E-7,1.02268856354599E-7,1.0001563687544,10.005763053894,2,20,1,3,1.99170004579405,0.176337983984362,0.0403775237500668,172.74836730957,29.999439239502,30.0006046295166,-140.006591796875,-140.006591796875,,,30.0034675598145,0,1,,,,,,1,1,1,29.9998359680176,0,30.0001012628729,,,,,,,,,,,,,,,,,,,,,,,,,,,,,,,,,
,3772424749.41506,29.9925212860107,-160.030090332031,,,5,,,,6.46999990567565,,,,,0.000616474859827708,1.55583568999756E-7,0.0375322743965691,0.000179237444555154,0.000616378475949319,1.55559244004901E-7,0.000616378343703499,1.09527267249935E-7,4.03765942859565E-7,1.10464727963896E-7,1.00015637125914,10.005763053894,2,20,1,3,2.01648329908011,0.178824459917657,0.0403775237500668,172.74836730957,29.9915809631348,29.9996147155762,-160.030090332031,-160.030090332031,,,30.0656509399414,0,1,,,,,,1,1,1,29.9924449920654,0,29.9944467544556,,,,,,,,,,,,,,,,,,,,,,,,,,,,,,,,,
,3772424770.87343,30.0083293914795,-180.041427612305,,,5,,,,6.46999990567565,,,,,0.000626109128666909,1.44830294808588E-7,0.0389438567463145,0.000113568559350128,0.000626011287522764,1.44807662393404E-7,0.000626011142917266,1.26174606856862E-7,4.25498915153613E-7,7.10579177316523E-8,1.00015629293927,10.005763053894,2,20,1,3,2.04798969042512,0.181713271080121,0.0403775237500668,172.74836730957,30.0035457611084,30.0090675354004,-180.041427612305,-180.041427612305,,,30.1029624938965,0,1,,,,,,1,1,1,30.0081310272217,0,30.0063462257385,,,,,,,,,,,,,,,,,,,,,,,,,,,,,,,,,
,3772424795.35627,29.9926538467407,-199.967788696289,,,5,,,,6.46999990567565,,,,,0.000637906519401509,7.85225298372824E-8,0.0493411208203689,5.08099018326946E-5,0.000637806853983979,7.85102616122625E-8,0.00063780661748356,7.15232237841273E-8,5.49256881051166E-7,3.23773012765354E-8,1.00015626269443,10.005763053894,2,20,10,3,2.08654226060617,0.185560497036376,0.0403775237500668,172.74836730957,29.9922122955322,30.0011310577393,-199.967788696289,-199.967788696289,,,30.1402740478516,0,1,,,,,,1,1,1,29.9929943084717,0,29.9952854156494,,,,,,,,,,,,,,,,,,,,,,,,,,,,,,,,,
,3772424817.00208,29.9979782104492,-220.051986694336,,,5,,,,6.46999990567565,,,,,0.000654795647742348,1.57459761158525E-7,0.071891782698839,7.76449885860273E-5,0.000654693334023011,1.57435157614098E-7,0.000654692818650669,1.49036569206273E-7,8.21475140989535E-7,5.07339126443021E-8,1.0001562773195,10.005763053894,2,20,10,3,2.14170723457409,0.191362305377493,0.0403775237500668,172.74836730957,29.9978008270264,30.003870010376,-220.051986694336,-220.051986694336,,,30.2024612426758,0,1,,,,,,1,1,1,29.9981842041016,0,29.9999135971069,,,,,,,,,,,,,,,,,,,,,,,,,,,,,,,,,
,3772424838.88324,30.0049829483032,-239.941909790039,,,5,,,,6.46999990567565,,,,,0.000680610486252605,3.08448387117785E-7,0.0956373263410404,0.000223324730922269,0.000680504154564446,3.08400198266195E-7,0.000680503206560222,2.68418202953949E-7,1.13588763846246E-6,1.5186293363952E-7,1.00015625428213,10.005763053894,2,20,10,3,2.22605683317862,0.199876517932577,0.0403775237500668,172.74836730957,30.0020713806152,30.0061645507812,-239.941909790039,-239.941909790039,,,30.2148971557617,0,1,,,,,,1,1,1,30.0043849945068,0,30.0038152694702,,,,,,,,,,,,,,,,,,,,,,,,,,,,,,,,,
,3772424860.40535,29.9962701797485,-259.892547607422,,,5,,,,6.46999990567565,,,,,0.000720081620182038,3.81770762108954E-7,0.144375332296325,0.000204595677062499,0.000719969079140681,3.81711095429617E-7,0.000719966793413734,3.52258048430622E-7,1.81419409817777E-6,1.47029342955508E-7,1.00015631371488,10.005763053894,2,20,10,3,2.35497015526856,0.213521803724896,0.0403775237500668,172.74836730957,29.9958896636963,30.0006141662598,-259.892547607422,-259.892547607422,,,30.2522087097168,0,1,,,,,,1,1,1,29.9961242675781,0,29.9976000352339,,,,,,,,,,,,,,,,,,,,,,,,,,,,,,,,,
,3772424882.59945,29.9980306625366,-279.903900146484,,,5,,,,6.46999990567565,,,,,0.000770415420881555,4.11756468305861E-7,0.135883192731589,0.000201590333073007,0.00077029503938676,4.11692129174267E-7,0.000770292873114083,3.81403537352406E-7,1.82683702127212E-6,1.54989518739535E-7,1.00015627972224,10.005763053894,2,20,10,3,2.51961323522544,0.228127500120549,0.0403775237500668,172.74836730957,29.9977321624756,30.0016803741455,-279.903900146484,-279.903900146484,,,30.2895202636719,0,1,,,,,,1,1,1,29.9981746673584,0,29.9991774125533,,,,,,,,,,,,,,,,,,,,,,,,,,,,,,,,,
,3772424904.25806,30.001275062561,-299.95166015625,,,5,,,,6.46999990567565,,,,,0.000814382026965001,3.30090542341833E-7,0.10505685315482,0.000275492339709861,0.000814254747788512,3.30038952730318E-7,0.000814253379008378,2.42124023327555E-7,1.49300688921164E-6,2.24280332724478E-7,1.00015631370506,10.005763053894,2,20,10,3,2.66352999030391,0.239770540011347,0.0403775237500668,172.74836730957,30.0006942749023,30.0015487670898,-299.95166015625,-299.95166015625,,,30.3019561767578,0,1,,,,,,1,1,1,30.0015678405762,0,30.0010110855103,,,,,,,,,,,,,,,,,,,,,,,,,,,,,,,,,
,3772424926.15547,29.9961442947388,-320.011596679687,,,5,,,,6.46999990567565,,,,,0.000844159506981684,2.03894534771551E-7,0.0507791153027668,0.000122530569846548,0.000844027578762524,2.03862669415956E-7,0.000844027247286891,1.75714280117377E-7,7.4803010787612E-7,1.03365757116327E-7,1.00015630794832,10.005763053894,2,20,10,3,2.76115112193183,0.24598139966812,0.0403775237500668,172.74836730957,29.9958267211914,30.0025100708008,-320.011596679687,-320.011596679687,,,30.326831817627,0,1,,,,,,1,1,1,29.9958667755127,0,29.998154258728,,,,,,,,,,,,,,,,,,,,,,,,,,,,,,,,,
,3772424947.78978,30.0014219284058,-339.901519775391,,,5,,,,6.46999990567565,,,,,0.000858745777117251,2.36853729138215E-7,-0.00895972904059228,0.000224383945199275,0.000858611657000262,2.36816736991402E-7,0.000858611646502148,1.37731090093402E-7,-1.34266918642871E-7,1.92645565069477E-7,1.0001562057956,10.005763053894,2,20,10,3,2.80911685007072,0.247362673267617,0.0403775237500668,172.74836730957,30.0012855529785,30.0058135986328,-339.901519775391,-339.901519775391,,,30.3517074584961,0,1,,,,,,1,1,1,30.0012855529785,0,30.0027248382568,,,,,,,,,,,,,,,,,,,,,,,,,,,,,,,,,
,3772424969.71092,29.9976930618286,-359.985717773438,,,5,,,,6.46999990567565,,,,,0.000863591906002459,3.77432450588493E-7,-0.0422585742810142,0.000240369574193355,0.000863456978538933,3.77373480601794E-7,0.000863456743686478,3.15198942034462E-7,-6.36843723359056E-7,2.07509929405483E-7,1.00015626425737,10.005763053894,2,20,10,3,2.82510979544195,0.247177544285031,0.0403775237500668,172.74836730957,29.9974613189697,30.0040187835693,-359.985717773438,-359.985717773438,,,30.3890190124512,0,1,,,,,,1,1,1,29.9977722167969,0,29.9999401092529,,,,,,,,,,,,,,,,,,,,,,,,,,,,,,,,,
,3772424991.35681,30.0048522949219,-380.009216308594,,,5,,,,6.46999990567565,,,,,0.000863960470479386,3.76953389171733E-7,-0.0656271213542272,0.000144824483395601,0.000863825499216103,3.76894500047897E-7,0.000863824932562804,3.55535759087655E-7,-9.89433583970088E-7,1.25075130127133E-7,1.00015624829714,10.005763053894,2,20,10,3,2.82641242984496,0.24619074385012,0.0403775237500668,172.74836730957,30.0023212432861,30.0061950683594,-380.009216308594,-380.009216308594,,,30.3890190124512,0,1,,,,,,1,1,1,30.0044918060303,0,30.0038858413696,,,,,,,,,,,,,,,,,,,,,,,,,,,,,,,,,
,3772425013.22817,30.0086402893066,-400.069122314453,,,5,,,,6.46999990567565,,,,,0.0008625860606471,2.86426678572509E-7,-0.0796941157784765,0.000258126800815612,0.000862451253323014,2.86381915022705E-7,0.000862450419043192,1.80182501248335E-7,-1.19960437675037E-6,2.22595749051876E-7,1.00015630718092,10.005763053894,2,20,10,3,2.82197268327483,0.245166799847622,0.0403775237500668,172.74836730957,30.0042705535889,30.0103130340576,-400.069122314453,-400.069122314453,,,30.413890838623,0,1,,,,,,1,1,1,30.0077419281006,0,30.007025718689,,,,,,,,,,,,,,,,,,,,,,,,,,,,,,,,,
,3772425034.94481,29.9946184158325,-419.946929931641,,,5,,,,6.46999990567565,,,,,0.000859751557017057,4.04967904949534E-7,-0.0934149216868496,0.000317903521501215,0.0008596172520933,4.04904643437351E-7,0.000859616109577343,2.98804938269508E-7,-1.40151758805567E-6,2.73246004806811E-7,1.00015623805063,10.005763053894,2,20,10,3,2.81275432258822,0.24374763817423,0.0403775237500668,172.74836730957,29.9942512512207,30.0011768341064,-419.946929931641,-419.946929931641,,,30.4263305664063,0,1,,,,,,1,1,1,29.9944744110107,0,29.9967378616333,,,,,,,,,,,,,,,,,,,,,,,,,,,,,,,,,
,3772425056.80727,29.997462272644,-440.018981933594,,,5,,,,6.46999990567565,,,,,0.000857143648219356,4.9326387319186E-7,-0.101747544800064,0.000318467036272221,0.000857009639059777,4.93186754406422E-7,0.000857008287739764,4.10793635964324E-7,-1.52190233825586E-6,2.72913472318885E-7,1.00015636832244,10.005763053894,2,20,10,3,2.80425398642359,0.242660635646311,0.0403775237500668,172.74836730957,29.9971389770508,30.0043869018555,-440.018981933594,-440.018981933594,,,30.4512023925781,0,1,,,,,,1,1,1,29.9977169036865,0,29.9998170852661,,,,,,,,,,,,,,,,,,,,,,,,,,,,,,,,,
,3772425078.52069,30.0050067901611,-460.358184814453,,,5,,,,6.46999990567565,,,,,0.000853848000012786,5.73288128902193E-7,-0.121385690448068,0.000327606248244703,0.00085371460251804,5.73198563546108E-7,0.00085371268662053,5.00325993548825E-7,-1.80866129812807E-6,2.796971459109E-7,1.00015625537428,10.005763053894,2,20,10,3,2.79355089443974,0.240830845986026,0.0403775237500668,172.74836730957,30.0021991729736,30.0057106018066,-460.358184814453,-460.358184814453,,,30.4636383056641,0,1,,,,,,1,1,1,30.0048370361328,0,30.0039583206177,,,,,,,,,,,,,,,,,,,,,,,,,,,,,,,,,
,3772425100.40575,30.0004472732544,-480.248107910156,,,5,,,,6.46999990567565,,,,,0.000850370126608238,5.55998831574263E-7,-0.121580708869044,0.000487527053439197,0.000850237255113271,5.5591195599663E-7,0.000850235340883574,3.70485927409041E-7,-1.80418822266178E-6,4.14461434167115E-7,1.00015627578557,10.005763053894,2,20,10,3,2.78216951480758,0.239899718452056,0.0403775237500668,172.74836730957,30.0001811981201,30.0058212280273,-480.248107910156,-480.248107910156,,,30.4636383056641,0,1,,,,,,1,1,1,30.0004997253418,0,30.002195930481,,,,,,,,,,,,,,,,,,,,,,,,,,,,,,,,,
,3772425121.7698,30.0062379837036,-500.271606445313,,,5,,,,6.46999990567565,,,,,0.000846729118538037,5.18464612874642E-7,-0.143178712008584,0.000318827380236561,0.000846596785493521,5.18383583417649E-7,0.000846594142123068,4.42554697140599E-7,-2.11559232127632E-6,2.69938658949982E-7,1.00015631177295,10.005763053894,2,20,10,3,2.77034347279804,0.237887549987313,0.0403775237500668,172.74836730957,30.0030860900879,30.0072994232178,-500.271606445313,-500.271606445313,,,30.5009498596191,0,1,,,,,,1,1,1,30.0057048797607,0,30.0049653486772,,,,,,,,,,,,,,,,,,,,,,,,,,,,,,,,,
,3772425143.98439,30.0067691802978,-520.282958984375,,,5,,,,6.46999990567565,,,,,0.000842971560253747,3.94621735361646E-7,-0.146312667918025,0.000312241658350829,0.000842839890567969,3.94560096603774E-7,0.000842837142462196,2.93990687192331E-7,-2.15230545839745E-6,2.63148523986284E-7,1.00015622146893,10.005763053894,2,20,10,3,2.75805884467399,0.236740066979464,0.0403775237500668,172.74836730957,30.003511428833,30.008846282959,-520.282958984375,-520.282958984375,,,30.5009498596191,0,1,,,,,,1,1,1,30.0062732696533,0,30.0055355072021,,,,,,,,,,,,,,,,,,,,,,,,,,,,,,,,,
,3772425165.59218,30.001935005188,-540.403564453125,,,5,,,,6.46999990567565,,,,,0.000839081141409221,1.04849072273203E-6,-0.164449352348201,0.000655201815747506,0.000838949976667928,1.04832682319049E-6,0.00083894652105697,8.92615523063508E-7,-2.4079363622184E-6,5.49751449481233E-7,1.0001563439358,10.005763053894,2,20,10,3,2.74540099075544,0.234837634653252,0.0403775237500668,172.74836730957,30.0008144378662,30.002254486084,-540.403564453125,-540.403564453125,,,30.5133895874023,0,1,,,,,,1,1,1,30.0017604827881,0,30.0014583587646,,,,,,,,,,,,,,,,,,,,,,,,,,,,,,,,,
,3772425187.48347,30.0047492980957,-560.257080078125,,,5,,,,6.46999990567565,,,,,0.000835654519773996,6.33779101815674E-7,-0.172145969631465,0.000444758792867186,0.000835523878750735,6.33680020738E-7,0.000835520107573031,5.13273247073914E-7,-2.51033938419847E-6,3.71619351649929E-7,1.00015635821618,10.005763053894,2,20,10,3,2.73421732654848,0.233569371710463,0.0403775237500668,172.74836730957,30.0022449493408,30.0054206848145,-560.257080078125,-560.257080078125,,,30.5133895874023,0,1,,,,,,1,1,1,30.0045890808105,0,30.0038200378418,,,,,,,,,,,,,,,,,,,,,,,,,,,,,,,,,
,3772425209.10433,30.0095233917236,-580.292724609375,,,5,,,,6.46999990567565,,,,,0.000832272312698267,6.40551382156777E-7,-0.20154813284166,0.000432342319112479,0.000832142209232551,6.40451249119169E-7,0.000832137060748147,5.29819789737006E-7,-2.92720273754157E-6,3.59817721772204E-7,1.00015634763418,10.005763053894,2,20,10,3,2.72326650635545,0.231284898461381,0.0403775237500668,172.74836730957,30.0043449401855,30.0105152130127,-580.292724609375,-580.292724609375,,,30.5382614135742,0,1,,,,,,1,1,1,30.0090351104736,0,30.007470703125,,,,,,,,,,,,,,,,,,,,,,,,,,,,,,,,,
,3772425231.03677,30.0005493164063,-600.389038085938,,,5,,,,6.46999990567565,,,,,0.000828284440530803,4.49423891091283E-7,-0.194395730935444,0.000351906125595597,0.000828155016083954,4.49353665893683E-7,0.000828150249476298,3.42039834662097E-7,-2.80979667574335E-6,2.91423177795481E-7,1.00015628045998,10.005763053894,2,20,10,3,2.71018563851079,0.230573421515402,0.0403775237500668,172.74836730957,30.000415802002,30.0012454986572,-600.389038085938,-600.389038085938,,,30.5507011413574,0,1,,,,,,1,1,1,30.0005855560303,0,30.0006126403809,,,,,,,,,,,,,,,,,,,,,,,,,,,,,,,,,
,3772425252.67865,30.0005598068237,-620.436828613281,,,5,,,,6.46999990567565,,,,,0.000824061245861884,6.89810421634982E-7,-0.193818791463452,0.000431382261425327,0.000823932480918836,6.89702634258616E-7,0.000823927766722003,5.9101716511578E-7,-2.78717375851304E-6,3.55511510702228E-7,1.00015628094053,10.005763053894,2,20,10,3,2.69636141831221,0.22948280048637,0.0403775237500668,172.74836730957,29.9996509552002,30.0016174316406,-620.436828613281,-620.436828613281,,,30.5507011413574,0,1,,,,,,1,1,1,29.9999942779541,0,30.0002401351929,,,,,,,,,,,,,,,,,,,,,,,,,,,,,,,,,
,3772425274.60484,30.0077857971191,-640.25390625,,,5,,,,6.46999990567565,,,,,0.00081968763347333,6.89798502387439E-7,-0.237470651868206,0.000715189406142666,0.000819559562508279,6.89690725770733E-7,0.000819552523288442,3.63719540931975E-7,-3.39677351463903E-6,5.85987536350726E-7,1.00015626803824,10.005763053894,2,20,10,3,2.68222060333334,0.226278187937581,0.0403775237500668,172.74836730957,30.0041275024414,30.0089168548584,-640.25390625,-640.25390625,,,30.5755729675293,0,1,,,,,,1,1,1,30.0070972442627,0,30.0064933083274,,,,,,,,,,,,,,,,,,,,,,,,,,,,,,,,,
,3772425296.24095,29.9995212554932,-660.362365722656,,,5,,,,6.46999990567565,,,,,0.000814837625021755,5.43571140371216E-7,-0.241293558385867,0.000428810724065231,0.000814710340082662,5.43486229687946E-7,0.000814703115399896,4.16323080619679E-7,-3.4310341458444E-6,3.49359949627543E-7,1.00015623336643,10.005763053894,2,20,10,3,2.66636182396562,0.224818915816094,0.0403775237500668,172.74836730957,29.9983310699463,30.0011081695557,-660.362365722656,-660.362365722656,,,30.5755729675293,0,1,,,,,,1,1,1,29.9988784790039,0,29.9994789470326,,,,,,,,,,,,,,,,,,,,,,,,,,,,,,,,,
,3772425318.17533,30.0034055709839,-680.264465332031,,,5,,,,6.46999990567565,,,,,0.00080961420871094,8.27959121190398E-7,-0.274244433505142,0.000743137640226235,0.000809487688486849,8.27829734165783E-7,0.000809478415710166,5.68790283735968E-7,-3.87457238168822E-6,6.01481239854202E-7,1.00015629666256,10.005763053894,2,20,10,3,2.64939421367102,0.221910472453027,0.0403775237500668,172.74836730957,30.0020961761475,30.0042991638184,-680.264465332031,-680.264465332031,,,30.5755729675293,0,1,,,,,,1,1,1,30.0030841827393,0,30.0028671264648,,,,,,,,,,,,,,,,,,,,,,,,,,,,,,,,,
,3772425339.79633,30.0001068115234,-700.372924804687,,,5,,,,6.46999990567565,,,,,0.000804696130010489,8.10463763432189E-7,-0.427456833212889,0.000562651317264959,0.000804570407685992,8.10337139997007E-7,0.000804548016798478,6.71922520342892E-7,-6.00246529681165E-6,4.52952985545505E-7,1.00015626018966,10.005763053894,2,20,10,3,2.63387747304254,0.213576786013223,0.0403775237500668,172.74836730957,29.9996376037598,30.0003967285156,-700.372924804687,-700.372924804687,,,30.5755729675293,0,1,,,,,,1,1,1,30.00026512146,0,29.9999580383301,,,,,,,,,,,,,,,,,,,,,,,,,,,,,,,,,
,3772425361.73003,30.0030603408814,-720.323547363281,,,5,,,,6.46999990567565,,,,,0.000790221889224424,3.39032588399435E-7,-0.161880384061438,0.000232216189575269,0.000790098411974431,3.38979612378087E-7,0.000790095258465309,2.8502404751154E-7,-2.2322981779792E-6,1.83489699842082E-7,1.00015628084821,10.005763053894,2,20,10,3,2.58549812008742,0.221776911043824,0.0403775237500668,172.74836730957,30.0014057159424,30.0034027099609,-720.323547363281,-720.323547363281,,,30.5880126953125,0,1,,,,,,1,1,1,30.0030307769775,0,30.0023380007063,,,,,,,,,,,,,,,,,,,,,,,,,,,,,,,,,
,3772425387.61726,29.9992074966431,-740.274230957031,,,5,,,,6.46999990567565,,,,,0.000778880197527633,9.29161295742947E-7,-0.442991870330472,0.000709304415721306,0.000778758451391395,9.29016059289308E-7,0.000778735174935145,7.46801954328518E-7,-6.0210407947812E-6,5.52591783714291E-7,1.00015633363082,10.005763053894,2,20,10,3,2.54942847888367,0.206142530856529,0.0403775237500668,172.74836730957,29.9990558624268,30.0000877380371,-740.274230957031,-740.274230957031,,,30.6004486083984,0,1,,,,,,1,1,1,29.9991722106934,0,29.9993915557861,,,,,,,,,,,,,,,,,,,,,,,,,,,,,,,,,
,3772425410.37091,29.9994735717773,-760.37060546875,,,5,,,,6.46999990567565,,,,,0.000748286567917034,4.74716337390643E-7,-0.210519516552939,0.000296622415015586,0.000748169594728825,4.74642129078133E-7,0.000748164544523522,4.19512195089658E-7,-2.74896245991159E-6,2.22024027679166E-7,1.00015634581923,10.005763053894,2,20,10,3,2.44846268342073,0.208034220449238,0.0403775237500668,172.74836730957,29.9991188049316,30.0073204040527,-760.37060546875,-760.37060546875,,,30.6253242492676,0,1,,,,,,1,1,1,29.9996891021729,0,30.0023919514247,,,,,,,,,,,,,,,,,,,,,,,,,,,,,,,,,
,3772425436.0049,29.9985990524292,-780.296875,,,5,,,,6.46999990567565,,,,,0.000698442982150072,3.42494352948239E-7,-0.201061785398422,0.000363835770150926,0.000698333828550881,3.42440827474746E-7,0.000698329528768816,2.29625878263245E-7,-2.45058116656612E-6,2.54042666403544E-7,1.00015630575912,10.005763053894,2,20,10,3,2.28533490564919,0.194602994473282,0.0403775237500668,172.74836730957,29.9981117248535,30.0070514678955,-780.296875,-780.296875,,,30.6128845214844,0,1,,,,,,1,1,1,29.9981117248535,0,30.001790864127,,,,,,,,,,,,,,,,,,,,,,,,,,,,,,,,,
,3772425461.75509,30.004469871521,-800.344665527344,,,5,,,,6.46999990567565,,,,,0.000586686650679845,5.13695525270351E-7,-0.222196094018106,0.000513963044430357,0.000586594939249942,5.13615223884418E-7,0.000586590528267312,4.15795535296933E-7,-2.27484081163716E-6,3.01520598024377E-7,1.00015634541618,10.005763053894,2,20,10,3,1.91972122420846,0.16279801499226,0.0403775237500668,172.74836730957,30.0011692047119,30.0053997039795,-800.344665527344,-800.344665527344,,,30.6253242492676,0,1,,,,,,1,1,1,30.0040760040283,0,30.003013757559,,,,,,,,,,,,,,,,,,,,,,,,,,,,,,,,,
,3772425490.39169,30.0037536621094,-820.392456054687,,,5,,,,6.46999990567565,,,,,0.000429819447981319,1.28493583406448E-6,-0.817066323146958,0.00148090487558356,0.000429752272282862,1.28473501378394E-6,0.000429708575427661,1.11521301771682E-6,-6.12827350993786E-6,6.37843225845799E-7,1.00015631260796,10.005763053894,2,20,1,3,1.40759069908116,0.104691233534698,0.0403775237500668,172.74836730957,30.0019054412842,30.0054988861084,-820.392456054687,-820.392456054687,,,30.6128845214844,0,1,,,,,,1,1,1,30.0032787322998,0,30.0033527101789,,,,,,,,,,,,,,,,,,,,,,,,,,,,,,,,,
,3772425512.94883,30.0011138916016,-840.415954589844,,,5,,,,6.46999990567565,,,,,0.000303013677370177,9.80860334057058E-7,-1.3152053934588,0.00234113268090583,0.000302966321818687,9.80707043346037E-7,0.00030288650632828,6.77416881530883E-7,-6.95387953544218E-6,7.09149260371538E-7,1.00015630632212,10.005763053894,2,20,1,3,0.992925176822783,0.0651963047672404,0.0403775237500668,172.74836730957,30.000244140625,30.0014247894287,-840.415954589844,-840.415954589844,,,30.6253242492676,0,1,,,,,,1,1,1,30.0011596679687,0,30.000748721036,,,,,,,,,,,,,,,,,,,,,,,,,,,,,,,,,
,3772425535.94703,30.0004663467407,-860.318054199219,,,5,,,,6.46999990567565,,,,,0.000204611789222323,1.63338874247159E-6,-1.69892980669948,0.00431495640059014,0.000204579794723009,1.63313333463219E-6,0.000204489864322233,1.37226114256746E-6,-6.06529458338044E-6,8.85451209997648E-7,1.0001563912964,10.005763053894,2,20,1,3,0.670757966806584,0.0395471510461547,0.0403775237500668,172.74836730957,29.9998798370361,30.0008010864258,-860.318054199219,-860.318054199219,,,30.6128845214844,0,1,,,,,,1,1,1,30.0008163452148,0,30.0001899719238,,,,,,,,,,,,,,,,,,,,,,,,,,,,,,,,,
,3772425557.57824,29.9994373321533,-880.341491699219,,,5,,,,6.46999990567565,,,,,0.000147027464070989,1.20491472832084E-6,-2.83603843573429,0.00482002367673582,0.000147004497628585,1.20472651447328E-6,0.000146824448545662,9.72874582495411E-7,-7.27348831682832E-6,7.10549802202016E-7,1.00015622952205,10.005763053894,2,20,1,3,0.482454031952146,0.0188570582490255,0.0403775237500668,172.74836730957,29.9990863800049,30.0050830841064,-880.341491699219,-880.341491699219,,,30.6253242492676,0,1,,,,,,1,1,1,29.9993419647217,0,30.0012424468994,,,,,,,,,,,,,,,,,,,,,,,,,,,,,,,,,
,3772425579.49706,30.0059108734131,-900.025024414062,,,5,,,,6.46999990567565,,,,,0.000108844770465918,1.2265821472207E-6,-4.10742377487311,0.00635624240887587,0.000108827761036353,1.22639046632919E-6,0.000108548238094793,1.01064730940271E-6,-7.79497137273601E-6,6.9471259661834E-7,1.00015629678864,10.005763053894,2,20,1,3,0.35738371494771,0.00603926942559988,0.0403775237500668,172.74836730957,30.0027980804443,30.0072631835937,-900.025024414062,-900.025024414062,,,30.6750717163086,0,1,,,,,,1,1,1,30.0053291320801,0,30.0047723770142,,,,,,,,,,,,,,,,,,,,,,,,,,,,,,,,,
,3772425600.913,30.00390625,-920.036376953125,,,5,,,,6.46999990567565,,,,,7.64702590267964E-5,1.01115368924449E-6,-4.98532529864845,0.00701715268204077,7.64583070949885E-5,1.01099565081105E-6,7.61690643946872E-5,8.54847599668732E-7,-6.64427220014075E-6,5.39766419203226E-7,1.00015631959773,10.005763053894,2,20,1,3,0.251120079054422,0.00040080209722312,0.0403775237500668,172.74836730957,30.0019626617432,30.0051555633545,-920.036376953125,-920.036376953125,,,30.6501960754395,0,1,,,,,,1,1,1,30.0035228729248,0,30.0032454403964,,,,,,,,,,,,,,,,,,,,,,,,,,,,,,,,,
,3772425623.04733,30.0004224777222,-939.950622558594,,,5,,,,6.46999990567565,,,,,5.80341980639266E-5,1.16723586166436E-6,-7.45704280225803,0.0125567081582142,5.80251302070276E-5,1.16705348079042E-6,5.75343794194978E-5,9.10668697405844E-7,-7.5306653328756E-6,7.29860500774074E-7,1.00015627464974,10.005763053894,2,20,1,3,0.190414127474245,-0.00791097327775374,0.0403775237500668,172.74836730957,29.9994049072266,30.002571105957,-939.950622558594,-939.950622558594,,,30.6501960754395,0,1,,,,,,1,1,1,29.9998741149902,0,30.0000982284546,,,,,,,,,,,,,,,,,,,,,,,,,,,,,,,,,
,3772425646.0648,29.99232006073,-959.949829101562,,,5,,,,6.46999990567565,,,,,4.55217377987385E-5,1.32461903623194E-6,-9.56970757509331,0.0171536063537828,4.55146210396803E-5,1.32441194847606E-6,4.48812427739985E-5,1.06946794738024E-6,-7.56668853905784E-6,7.81220403466556E-7,1.00015636204138,10.005763053894,2,20,1,3,0.149029950768612,-0.0117040216700493,0.0403775237500668,172.74836730957,29.9917945861816,30.0020942687988,-959.949829101562,-959.949829101562,,,30.6626319885254,0,1,,,,,,1,1,1,29.9929637908936,0,29.9954627990723,,,,,,,,,,,,,,,,,,,,,,,,,,,,,,,,,
,3772425667.75608,30.0044231414795,-980.070373535156,,,5,,,,6.46999990567565,,,,,3.70724305925085E-5,1.44334534604852E-6,-11.493013807195,0.0240357159481928,3.70666397218536E-5,1.44311988939311E-6,3.63234167764163E-5,1.13668080189203E-6,-7.38547046277037E-6,8.89129782299563E-7,1.00015622863843,10.005763053894,2,20,1,3,0.120980531741914,-0.0135970137332568,0.0403775237500668,172.74836730957,30.0020694732666,30.0056247711182,-980.070373535156,-980.070373535156,,,30.6750717163086,0,1,,,,,,1,1,1,30.004035949707,0,30.0034650802612,,,,,,,,,,,,,,,,,,,,,,,,,,,,,,,,,
,3772425689.65176,30.0000553131103,-999.984619140625,,,5,,,,6.46999990567565,,,,,3.22609724399531E-5,1.32100034103741E-6,-14.7852261736832,0.0199016995953854,3.22559285008149E-5,1.32079380525074E-6,3.11879096659411E-5,1.1650792700309E-6,-8.23159851540264E-6,6.22162816739297E-7,1.00015637246772,10.005763053894,2,20,1,3,0.104426209797567,-0.0178565790955963,0.0403775237500668,172.74836730957,29.9999942779541,30.0012798309326,-999.984619140625,-999.984619140625,,,30.6626319885254,0,1,,,,,,1,1,1,30.0001163482666,0,30.0004667282104,,,,,,,,,,,,,,,,,,,,,,,,,,,,,,,,,