File: Experimental_Data/AC_Suceptibillity_FieldScans/ZFCd_Up_10K.dat
[Header]
; MPMS3 Data File (default extension .dat)
; Copyright (c) 2007, Quantum Design, Inc. All rights reserved.
TITLE,ZFCd_Up_10K
FILEOPENTIME,3772407988.87258,07/16/2019,3:06 am
BYAPP,SQUID AC,0.9.1.0
INFO,MPMS3 Measurement Release 1.1.16 Build 347, MultiVu Release 2.3.3.2,APPNAME
INFO,0,MOMENT_UNITS
INFO,Cu2OSeO3,SAMPLE_MATERIAL
INFO,,SAMPLE_COMMENT
INFO,,SAMPLE_MASS
INFO,,SAMPLE_VOLUME
INFO,,SAMPLE_MOLECULAR_WEIGHT
INFO,,SAMPLE_SIZE
INFO,,SAMPLE_SHAPE
INFO,Quartz,SAMPLE_HOLDER
INFO,Standard,SAMPLE_HOLDER_DETAIL
INFO,64.77,SAMPLE_OFFSET
DATATYPE,COMMENT,1
DATATYPE,TIME,2
STARTUPAXIS,X,2
STARTUPAXIS,Y1,5
FIELDGROUP, VSM,2,3,4,5,6,8,9,10,11,14,15
FIELDGROUP, DC, 2,3,4,14,56,57,58,59,60,61,62,63,64,65,66,67,68,69
FIELDGROUP, AC, 2,3,4,11,16,17,18,19,20,21,22,23,24,25,26,27,28,29,30
STARTUPGROUP, All
[Data]
Comment,Time Stamp (sec),Temperature (K),Magnetic Field (Oe),Moment (emu),M. Std. Err. (emu),Transport Action,Averaging Time (sec),Frequency (Hz),Peak Amplitude (mm),Center Position (mm),Lockin Signal' (V),Lockin Signal (V),Range,M. Quad. Signal (emu),AC Moment (emu),AC M. Std Err. (emu),AC Phase (deg),AC Phase Std. Err. (deg),AC Susceptibility (emu/Oe),AC Suscept. Std Err. (emu/Oe),AC X' (emu/Oe),AC X' Std Err. (emu/Oe),AC X'' (emu/Oe),AC X'' Std Err. (emu/Oe),AC Drive (Oe),AC Frequency (Hz),AC Averaging Time (sec),AC Cycles,AC Range,AC Measure Type,AC Signal' (V),AC Signal'' (V),AC Trim Coil Ratio,AC Trim Coil Phase,Min. Temperature (K),Max. Temperature (K),Min. Field (Oe),Max. Field (Oe),Mass (grams),Motor Lag (deg),Pressure (Torr),Measure Count,Measurement Number,SQUID Status (code),Motor Status (code),Measure Status (code),Motor Current (amps),Motor Temp. (C),Temp. Status (code),Field Status (code),Chamber Status (code),Chamber Temp (K),Redirection State,Average Temp (K),Rotation Angle (deg),Rotator state,DC Moment Fixed Ctr (emu),DC Moment Err Fixed Ctr (emu),DC Moment Free Ctr (emu),DC Moment Err Free Ctr (emu),DC Fixed Fit,DC Free Fit,DC Calculated Center (mm),DC Calculated Center Err (mm),DC Scan Length (mm),DC Scan Time (s),DC Number of Points,DC Squid Drift,DC Min V (V),DC Max V (V),DC Scans per Measure,Map 01,Map 02,Map 03,Map 04,Map 05,Map 06,Map 07,Map 08,Map 09,Map 10,Map 11,Map 12,Map 13,Map 14,Map 15,Map 16
,3772408199.81028,9.99989318847656,-0.0607140436768532,,,5,,,,6.46999990567565,,,,,0.000594837454944064,1.35381792951703E-8,0.0296686102681178,1.36744383046246E-5,0.000594742562973385,1.35360196051541E-8,0.000594742483238539,1.08219877121871E-8,3.07966567033952E-7,8.13070776183638E-9,1.0001595513363,10.005763053894,2,20,1,3,1.94574218699844,0.172057012949551,0.0403775237500668,172.74836730957,9.99894905090332,10.0011501312256,-0.0607140436768532,-0.0607140436768532,,,18.3139095306396,0,1,,,,,,1,1,1,9.99974822998047,0,9.99986352920532,,,,,,,,,,,,,,,,,,,,,,,,,,,,,,,,,
,3772408221.68726,10.0002760887146,20.0113487243652,,,5,,,,6.46999990567565,,,,,0.000594764645666765,1.21481009539025E-8,0.0300126541733317,1.8675242565128E-5,0.000594669754872642,1.2146162804157E-8,0.000594669673287816,4.91847567317562E-9,3.11499678262776E-7,1.1105758322486E-8,1.00015956889239,10.005763053894,2,20,1,3,1.9455003985131,0.172089175829554,0.0403775237500668,172.74836730957,9.998948097229,10.0012235641479,20.0113487243652,20.0113487243652,,,18.347864151001,0,1,,,,,,1,1,1,10.0000333786011,0,10.00005235672,,,,,,,,,,,,,,,,,,,,,,,,,,,,,,,,,
,3772408242.26347,9.99999237060547,40.0469856262207,,,5,,,,6.46999990567565,,,,,0.00059457243209398,1.41513889419999E-8,0.0278272525415657,1.27096370122772E-5,0.000594477579698332,1.41491313648395E-8,0.000594477509584958,1.19646846656121E-8,2.887241823184E-7,7.55276368172288E-9,1.00015955588383,10.005763053894,2,20,1,3,1.94487561778117,0.172001083895937,0.0403775237500668,172.74836730957,9.99904346466065,10.0012006759644,40.0469856262207,40.0469856262207,,,18.3697757720947,0,1,,,,,,1,1,1,9.99985408782959,0,9.99993896484375,,,,,,,,,,,,,,,,,,,,,,,,,,,,,,,,,
,3772408263.06627,10.0000157356262,59.9126205444336,,,5,,,,6.46999990567565,,,,,0.000594432464915157,1.48428050606339E-8,0.0275154773764346,1.26586648464109E-5,0.000594337634211926,1.4840437165667E-8,0.000594337565676981,1.27939360530421E-8,2.85422124256069E-7,7.52022443406972E-9,1.00015955695513,10.005763053894,2,20,1,3,1.9444161337314,0.171991353767415,0.0403775237500668,172.74836730957,9.99886989593506,10.0012216567993,59.9126205444336,59.9126205444336,,,18.3912105560303,0,1,,,,,,1,1,1,10.0000991821289,0,9.99995769153942,,,,,,,,,,,,,,,,,,,,,,,,,,,,,,,,,
,3772408285.85409,9.99996042251587,80.0089721679688,,,5,,,,6.46999990567565,,,,,0.000594577303101485,2.15865913951478E-8,0.0246245497351376,2.59032941355172E-5,0.000594482382722987,2.15831452369864E-8,0.000594482327819451,1.51247104125457E-8,2.5549631532676E-7,1.53972495354683E-8,1.0001596689511,10.005763053894,2,20,1,3,1.94489597415983,0.171976960609634,0.0403775237500668,172.74836730957,9.99894714355469,10.0011491775513,80.0089721679688,80.0089721679688,,,18.3859615325928,0,1,,,,,,1,1,1,10.0001335144043,0,9.99990057945251,,,,,,,,,,,,,,,,,,,,,,,,,,,,,,,,,
,3772408308.90482,9.999924659729,100.068893432617,,,5,,,,6.46999990567565,,,,,0.000595116166558822,2.02142441584174E-8,0.0210710305674171,2.61244064378803E-5,0.000595021229267967,2.02110194340948E-8,0.000595021189030675,1.2918487485333E-8,2.1882432413178E-7,1.55434226493606E-8,1.00015955277927,10.005763053894,2,20,1,3,1.94666669337804,0.172053884052241,0.0403775237500668,172.74836730957,9.998948097229,10.0012941360474,100.068893432617,100.068893432617,,,18.4116287231445,0,1,,,,,,1,1,1,9.9998664855957,0,9.99993953704834,,,,,,,,,,,,,,,,,,,,,,,,,,,,,,,,,
,3772408330.47981,9.99989128112793,120.031669616699,,,5,,,,6.46999990567565,,,,,0.000595867859143224,2.56373124833581E-8,0.0212823304839462,2.64689382519249E-5,0.000595772802848498,2.56332226706689E-8,0.000595772761748313,2.02113061466006E-8,2.21297859977703E-7,1.57659509174828E-8,1.00015955124885,10.005763053894,2,20,1,3,1.94912229984212,0.172320038293065,0.0403775237500668,172.74836730957,9.99886798858643,10.0008611679077,120.031669616699,120.031669616699,,,18.4157295227051,0,1,,,,,,1,1,1,9.99969863891602,0,9.99975481033325,,,,,,,,,,,,,,,,,,,,,,,,,,,,,,,,,
,3772408352.39448,10.000141620636,139.945877075195,,,5,,,,6.46999990567565,,,,,0.000596857146663185,4.38136752769665E-8,0.0196433245514607,3.78574506475242E-5,0.000596761925702956,4.38066853627897E-8,0.000596761890631336,3.75371084207698E-8,2.0459426604398E-7,2.2582984166886E-8,1.00015956272699,10.005763053894,2,20,1,3,1.95236066518416,0.172591893415222,0.0403775237500668,172.74836730957,9.9990873336792,10.0007181167603,139.945877075195,139.945877075195,,,18.4253597259521,0,1,,,,,,1,1,1,10.0001773834229,0,9.99996480941772,,,,,,,,,,,,,,,,,,,,,,,,,,,,,,,,,
,3772408374.02978,10.0000882148743,160.030090332031,,,5,,,,6.46999990567565,,,,,0.000598209934228549,5.09219113934787E-8,0.0191175292834318,5.29566940064744E-5,0.000598114430420263,5.09137817450309E-8,0.000598114397125759,3.98671108686426E-8,1.99569148433038E-7,3.1667438206587E-8,1.00015967481042,10.005763053894,2,20,1,3,1.95678468991104,0.173007180616289,0.0403775237500668,172.74836730957,9.99899387359619,10.000919342041,160.030090332031,160.030090332031,,,18.4642887115479,0,1,,,,,,1,1,1,10.0003700256348,0,9.99988136291504,,,,,,,,,,,,,,,,,,,,,,,,,,,,,,,,,
,3772408399.0931,10.0000562667847,180.005004882813,,,5,,,,6.46999990567565,,,,,0.000599984092398663,5.388973366098E-8,0.0205269862489734,7.48653883716539E-5,0.000599888374921334,5.38811364507784E-8,0.000599888336422678,2.97713583299787E-8,2.14918101545283E-7,4.49092761956303E-8,1.00015955881349,10.005763053894,2,20,10,3,1.9625811916953,0.173610518802125,0.0403775237500668,172.74836730957,9.99897003173828,10.0014419555664,180.005004882813,180.005004882813,,,18.4514236450195,0,1,,,,,,1,1,1,9.99989223480225,0,9.99996353598202,,,,,,,,,,,,,,,,,,,,,,,,,,,,,,,,,
,3772408425.55815,10.0004563331604,200.101348876953,,,5,,,,6.46999990567565,,,,,0.000603003557143077,1.05073247888211E-7,0.0209552650887694,9.76222633534777E-5,0.000602907346902935,1.05056483273323E-7,0.000602907306579118,8.70335444068657E-8,2.20506346261814E-7,5.88389906927041E-8,1.00015957715665,10.005763053894,2,20,10,3,1.9724540745349,0.174541393655902,0.0403775237500668,172.74836730957,9.99889087677002,10.0007295608521,200.101348876953,200.101348876953,,,18.4819622039795,0,1,,,,,,1,1,1,10.0005865097046,0,9.99996185302734,,,,,,,,,,,,,,,,,,,,,,,,,,,,,,,,,
,3772408448.50689,9.99972677230835,219.906265258789,,,5,,,,6.46999990567565,,,,,0.000608232184638807,1.47673696180586E-7,0.0205383152548082,0.000127500318981644,0.000608135160501506,1.47650139530123E-7,0.000608135121430511,1.2567038475426E-7,2.17992869327789E-7,7.75081808519651E-8,1.00015954370607,10.005763053894,2,20,10,3,1.98955581705902,0.17608253327134,0.0403775237500668,172.74836730957,9.99904918670654,10.0009088516235,219.906265258789,219.906265258789,,,18.4972953796387,0,1,,,,,,1,1,1,9.99956512451172,0,9.99978513717651,,,,,,,,,,,,,,,,,,,,,,,,,,,,,,,,,
,3772408470.43163,9.99947881698608,239.990478515625,,,5,,,,6.46999990567565,,,,,0.000614583932373043,2.0806023529509E-7,0.0201899288732745,9.94868517267327E-5,0.000614485831633765,2.080270244319E-7,0.000614485793482742,1.98871907663559E-7,2.16532964260176E-7,6.10344758005424E-8,1.00015964686935,10.005763053894,2,20,10,3,2.01033106174214,0.177952346857988,0.0403775237500668,172.74836730957,9.99917030334473,10.0010299682617,239.990478515625,239.990478515625,,,18.5090274810791,0,1,,,,,,1,1,1,9.99942111968994,0,9.99967994689942,,,,,,,,,,,,,,,,,,,,,,,,,,,,,,,,,
,3772408492.05818,10.0001049041748,260.086822509766,,,5,,,,6.46999990567565,,,,,0.000622011877898345,2.90607955344525E-7,0.0132352355187662,0.000216238246020421,0.000621912644867745,2.90561593033531E-7,0.00062191262827503,2.5760276515011E-7,1.43660847686715E-7,1.34413000610806E-7,1.00015956104353,10.005763053894,2,20,10,3,2.03464731474648,0.179899895109988,0.0403775237500668,172.74836730957,9.99913501739502,10.0008363723755,260.086822509766,260.086822509766,,,18.5397720336914,0,1,,,,,,1,1,1,9.99995708465576,0,9.99998044967651,,,,,,,,,,,,,,,,,,,,,,,,,,,,,,,,,
,3772408513.98028,9.99985933303833,280.025299072266,,,5,,,,6.46999990567565,,,,,0.000633252605354338,3.65171360433746E-7,0.0415390018311275,0.000242352495426365,0.000633151586155514,3.65113106716426E-7,0.000633151419758881,3.31362149848234E-7,4.59030016106275E-7,1.53318969289766E-7,1.00015954978402,10.005763053894,2,20,10,3,2.07132306554484,0.184218414659996,0.0403775237500668,172.74836730957,9.99878120422363,10.0008487701416,280.025299072266,280.025299072266,,,18.5463066101074,0,1,,,,,,1,1,1,9.99970436096191,0,9.99972360784357,,,,,,,,,,,,,,,,,,,,,,,,,,,,,,,,,
,3772408536.99592,9.99987745285034,299.988098144531,,,5,,,,6.46999990567565,,,,,0.000665523959780787,2.06444206104698E-6,0.148672637811588,0.00192807391825138,0.000665417791962967,2.06411273059176E-6,0.000665415551792855,1.61731552073215E-6,1.72664214015886E-6,1.28251778583763E-6,1.00015955061482,10.005763053894,2,20,10,3,2.17651148055955,0.197722989091288,0.0403775237500668,172.74836730957,9.99899291992188,10.0009603500366,299.988098144531,299.988098144531,,,18.5773468017578,0,1,,,,,,1,1,1,9.99971866607666,0,9.99997596740723,,,,,,,,,,,,,,,,,,,,,,,,,,,,,,,,,
,3772408558.91386,10.0001459121704,320.035888671875,,,5,,,,6.46999990567565,,,,,0.00072301792458522,2.38617711052711E-6,0.256070046060845,0.00221268481465602,0.000722902576136579,2.38579642587391E-6,0.000722895356400065,1.77055104144817E-6,3.23083272954453E-6,1.59911650461732E-6,1.00015956292376,10.005763053894,2,20,10,3,2.36412800707114,0.219286616202213,0.0403775237500668,172.74836730957,9.99877738952637,10.0007429122925,320.035888671875,320.035888671875,,,18.5993213653564,0,1,,,,,,1,1,1,10.0003385543823,0,9.99982213973999,,,,,,,,,,,,,,,,,,,,,,,,,,,,,,,,,
,3772408580.67331,9.99909591674805,340.120086669922,,,5,,,,6.46999990567565,,,,,0.000779734148315692,1.87015472816018E-6,0.166879523177148,0.00164860342240716,0.000779609699754711,1.86985624429202E-6,0.000779606392955946,1.35833203298724E-6,2.27068576637343E-6,1.28502780611106E-6,1.00015962931326,10.005763053894,2,20,10,3,2.54994050161223,0.232573962218949,0.0403775237500668,172.74836730957,9.99818801879883,10.0001096725464,340.120086669922,340.120086669922,,,18.6196308135986,0,1,,,,,,1,1,1,9.99924755096436,0,9.99899435043335,,,,,,,,,,,,,,,,,,,,,,,,,,,,,,,,,
,3772408602.42836,9.99767780303955,359.973602294922,,,5,,,,6.46999990567565,,,,,0.00082720056712456,1.52506932215551E-6,0.10241763505448,0.00108620716065251,0.000827068596509251,1.5248260143716E-6,0.000827067275166028,1.23233997990425E-6,1.47840495918803E-6,8.98015895201178E-7,1.00015956429233,10.005763053894,2,20,10,3,2.70544066121046,0.243745764840348,0.0403775237500668,172.74836730957,9.99375534057617,9.9999303817749,359.973602294922,359.973602294922,,,18.633279800415,0,1,,,,,,1,1,1,9.99662590026855,0,9.99595346450806,,,,,,,,,,,,,,,,,,,,,,,,,,,,,,,,,
,3772408624.2901,9.99828147888184,380.021362304687,,,5,,,,6.46999990567565,,,,,0.000855089373184004,7.50305716021325E-7,0.0233199567017204,0.00042147728903619,0.000854952831656918,7.50185906453507E-7,0.00085495276084239,6.58074514080567E-7,3.47974364520799E-7,3.60162224780855E-7,1.00015970650313,10.005763053894,2,20,10,3,2.79699515233872,0.248162523187273,0.0403775237500668,172.74836730957,9.99757480621338,10.000340461731,380.021362304687,380.021362304687,,,18.6160469055176,0,1,,,,,,1,1,1,9.99863052368164,0,9.99867792129517,,,,,,,,,,,,,,,,,,,,,,,,,,,,,,,,,
,3772408645.90315,9.99733114242554,400.032684326172,,,5,,,,6.46999990567565,,,,,0.000864556891041006,6.2545822700857E-7,-0.0341544645328149,0.000208225031261868,0.000864418875390682,6.25358380457295E-7,0.000864418721807404,5.98938080349545E-7,-5.15286855740699E-7,1.79850715637644E-7,1.00015966292992,10.005763053894,2,20,10,3,2.82820991115788,0.248133838638309,0.0403775237500668,172.74836730957,9.99679183959961,9.99899482727051,400.032684326172,400.032684326172,,,18.6311321258545,0,1,,,,,,1,1,1,9.99755859375,0,9.99752988815308,,,,,,,,,,,,,,,,,,,,,,,,,,,,,,,,,
,3772408667.8261,9.99882793426514,420.129089355469,,,5,,,,6.46999990567565,,,,,0.000864529917942184,3.43259198736887E-7,-0.0634423834535776,0.000239740278575568,0.000864391946270264,3.43204417468398E-7,0.000864391416369693,2.73598963920547E-7,-9.57122401849664E-7,2.07202507493094E-7,1.00015961702618,10.005763053894,2,20,10,3,2.82824441703194,0.246741237240712,0.0403775237500668,172.74836730957,9.99807071685791,10.0000076293945,420.129089355469,420.129089355469,,,18.6205387115479,0,1,,,,,,1,1,1,9.9989767074585,0,9.99883079528809,,,,,,,,,,,,,,,,,,,,,,,,,,,,,,,,,
,3772408690.99732,9.99936532974243,440.225402832031,,,5,,,,6.46999990567565,,,,,0.000859379388467406,3.68355088842521E-7,-0.0843530842675788,0.000169219204559059,0.000859242316003469,3.68296335583706E-7,0.000859241384805004,3.3838297771843E-7,-1.26500963807299E-6,1.45393091977557E-7,1.00015952713383,10.005763053894,2,20,10,3,2.8114804952803,0.244305653154448,0.0403775237500668,172.74836730957,9.9984245300293,10.0002946853638,440.225402832031,440.225402832031,,,18.603178024292,0,1,,,,,,1,1,1,9.99912166595459,0,9.99926861849698,,,,,,,,,,,,,,,,,,,,,,,,,,,,,,,,,
,3772408712.61801,9.99876832962036,460.297485351562,,,5,,,,6.46999990567565,,,,,0.000852193807673244,4.00620346887053E-7,-0.100952864459157,0.000245487551942103,0.000852057807068525,4.00556412358371E-7,0.000852056484461029,3.41609953890312E-7,-1.50129088970166E-6,2.09160414238613E-7,1.00015961429329,10.005763053894,2,20,10,3,2.78803913606278,0.241515074724714,0.0403775237500668,172.74836730957,9.99820232391357,10.0004863739014,460.297485351562,460.297485351562,,,18.6103363037109,0,1,,,,,,1,1,1,9.9985933303833,0,9.99903392791748,,,,,,,,,,,,,,,,,,,,,,,,,,,,,,,,,
,3772408734.55687,9.9992938041687,480.357360839844,,,5,,,,6.46999990567565,,,,,0.000843959500708807,4.05561904306596E-7,-0.110174294921809,0.00017197720884126,0.000843824793880262,4.05497171392444E-7,0.000843823233834107,3.78628439847311E-7,-1.62259323812386E-6,1.45149786586353E-7,1.00015963838645,10.005763053894,2,20,10,3,2.76113463514794,0.238796328365869,0.0403775237500668,172.74836730957,9.99917411804199,10.0009298324585,480.357360839844,480.357360839844,,,18.5937519073486,0,1,,,,,,1,1,1,9.99927711486816,0,9.99972360784357,,,,,,,,,,,,,,,,,,,,,,,,,,,,,,,,,
,3772408757.63685,9.9995756149292,500.223022460937,,,5,,,,6.46999990567565,,,,,0.00083562636178384,3.90503176775999E-7,-0.123093042827207,0.000223126934163348,0.000835492974238046,3.90440842384988E-7,0.00083549104611658,3.43054247182058E-7,-1.79495408249819E-6,1.86434532457509E-7,1.00015965130756,10.005763053894,2,20,10,3,2.73392131486074,0.235880184164775,0.0403775237500668,172.74836730957,9.99852561950684,10.0007381439209,500.223022460937,500.223022460937,,,18.6120548248291,0,1,,,,,,1,1,1,9.99990844726563,0,9.99952898025513,,,,,,,,,,,,,,,,,,,,,,,,,,,,,,,,,
,3772408779.3236,9.9997878074646,520.258666992188,,,5,,,,6.46999990567565,,,,,0.000827119868072959,5.27876721741961E-7,-0.141610791857374,0.000316054913570483,0.00082698783033867,5.27792453851643E-7,0.000826985304437583,4.58512180705534E-7,-2.04396001370902E-6,2.61402858606012E-7,1.00015966103665,10.005763053894,2,20,10,3,2.70616243316161,0.232662392597555,0.0403775237500668,172.74836730957,9.99884414672852,10.0008678436279,520.258666992188,520.258666992188,,,18.6141128540039,0,1,,,,,,1,1,1,9.99988079071045,0,9.99974753639915,,,,,,,,,,,,,,,,,,,,,,,,,,,,,,,,,
,3772408801.19895,10.0000138282776,540.342834472656,,,5,,,,6.46999990567565,,,,,0.000818859499904214,4.940140265592E-7,-0.142720579907242,0.000252561773835668,0.000818728772335103,4.93935159240928E-7,0.000818726232311389,4.48541141571863E-7,-2.03940543840265E-6,2.06840000608613E-7,1.00015967139977,10.005763053894,2,20,10,3,2.67913725299808,0.230344506888723,0.0403775237500668,172.74836730957,9.99911022186279,10.0005578994751,540.342834472656,540.342834472656,,,18.6139125823975,0,1,,,,,,1,1,1,10.0000715255737,0,9.99985342025757,,,,,,,,,,,,,,,,,,,,,,,,,,,,,,,,,
,3772408823.16492,10.0000419616699,560.378540039063,,,5,,,,6.46999990567565,,,,,0.000810458463218922,4.71468212040973E-7,-0.154068191348125,0.000293666885269966,0.000810329168589734,4.71392997442796E-7,0.000810326238965507,4.06900331824329E-7,-2.1789702489123E-6,2.37998903357463E-7,1.0001595581576,10.005763053894,2,20,10,3,2.65169251771934,0.227512987395228,0.0403775237500668,172.74836730957,9.99891948699951,10.0008630752563,560.378540039063,560.378540039063,,,18.6163959503174,0,1,,,,,,1,1,1,10.0002126693726,0,9.99988212585449,,,,,,,,,,,,,,,,,,,,,,,,,,,,,,,,,
,3772408845.77539,9.99976062774658,580.268432617187,,,5,,,,6.46999990567565,,,,,0.000802615504801942,5.79225775892851E-7,-0.150211571340849,0.000290740749526325,0.000802487471730937,5.7913337790845E-7,0.000802484713887991,5.30015643818382E-7,-2.10386815656907E-6,2.33407126530955E-7,1.00015954525836,10.005763053894,2,20,10,3,2.62601307442483,0.225543960532703,0.0403775237500668,172.74836730957,9.99874305725098,10.0008630752563,580.268432617187,580.268432617187,,,18.627384185791,0,1,,,,,,1,1,1,9.99965858459473,0,9.99971129677512,,,,,,,,,,,,,,,,,,,,,,,,,,,,,,,,,
,3772408867.92529,9.99933099746704,600.27978515625,,,5,,,,6.46999990567565,,,,,0.000794015444021933,5.44602893219413E-7,-0.169175028802032,0.000230335063031134,0.000793888707555798,5.44515966640524E-7,0.000793885246914655,5.1283308297447E-7,-2.34408102928912E-6,1.83029688666524E-7,1.00015964009178,10.005763053894,2,20,10,3,2.59794562176469,0.222323041720188,0.0403775237500668,172.74836730957,9.9985179901123,10.000506401062,600.27978515625,600.27978515625,,,18.6371040344238,0,1,,,,,,1,1,1,9.99946784973145,0,9.99943447113037,,,,,,,,,,,,,,,,,,,,,,,,,,,,,,,,,
,3772408890.96023,9.99990463256836,620.30322265625,,,5,,,,6.46999990567565,,,,,0.000785678979085859,6.01933273954137E-7,-0.186066717186479,0.000359654342167004,0.000785553642540262,6.01837249700917E-7,0.00078554950027797,5.31348498976698E-7,-2.55106277933615E-6,2.82624924171195E-7,1.00015955186102,10.005763053894,2,20,10,3,2.57073095325477,0.219286048915727,0.0403775237500668,172.74836730957,9.99875640869141,10.0009937286377,620.30322265625,620.30322265625,,,18.6480560302734,0,1,,,,,,1,1,1,9.99970817565918,0,9.99984407424927,,,,,,,,,,,,,,,,,,,,,,,,,,,,,,,,,
,3772408912.6336,9.9997181892395,640.472473144531,,,5,,,,6.46999990567565,,,,,0.000777077831955965,5.10427134211435E-7,-0.1965575864888,0.000331462408342693,0.000776953785189241,5.10345653524375E-7,0.000776949213263981,4.40562006071067E-7,-2.66539459937504E-6,2.57600087107631E-7,1.00015965784463,10.005763053894,2,20,10,3,2.54262454167169,0.216474764757973,0.0403775237500668,172.74836730957,9.9988956451416,10.0009984970093,640.472473144531,640.472473144531,,,18.6413707733154,0,1,,,,,,1,1,1,9.99985313415527,0,9.9996618270874,,,,,,,,,,,,,,,,,,,,,,,,,,,,,,,,,
,3772408934.54814,9.99985885620117,660.277404785156,,,5,,,,6.46999990567565,,,,,0.000768471659914486,6.65451293599569E-7,-0.205241919039458,0.000445758466725442,0.00076834898201653,6.65345061749848E-7,0.000768344052379665,5.70365910175222E-7,-2.75233330700897E-6,3.42588353136675E-7,1.00015966429426,10.005763053894,2,20,10,3,2.51449413576136,0.213749470242415,0.0403775237500668,172.74836730957,9.99921703338623,10.0009393692017,660.277404785156,660.277404785156,,,18.6524505615234,0,1,,,,,,1,1,1,10.0000028610229,0,9.99988307952881,,,,,,,,,,,,,,,,,,,,,,,,,,,,,,,,,
,3772408956.16744,10.000011920929,680.276611328125,,,5,,,,6.46999990567565,,,,,0.000758519361656423,6.97812055171492E-7,-0.224670354004147,0.000444532544690247,0.000758398354056924,6.9770073228909E-7,0.000758392523458861,6.1075985708796E-7,-2.97385237579019E-6,3.37281349627617E-7,1.00015955678022,10.005763053894,2,20,10,3,2.4819977881239,0.210192761594678,0.0403775237500668,172.74836730957,9.99905872344971,10.0010137557983,680.276611328125,680.276611328125,,,18.6626663208008,0,1,,,,,,1,1,1,9.99991989135742,0,9.99993934631348,,,,,,,,,,,,,,,,,,,,,,,,,,,,,,,,,
,3772408978.07005,10.0002093315125,700.348693847656,,,5,,,,6.46999990567565,,,,,0.000745718082932198,8.62069036371865E-7,-0.328487932216471,0.000540544224310205,0.000745599110790079,8.61931501555078E-7,0.000745586857075225,7.6170192075941E-7,-4.27464239972502E-6,4.03405623763994E-7,1.00015956583155,10.005763053894,2,20,10,3,2.44047738405271,0.202276112694058,0.0403775237500668,172.74836730957,9.99925899505615,10.0009603500366,700.348693847656,700.348693847656,,,18.6645927429199,0,1,,,,,,1,1,1,10.0002508163452,0,10.0001001358032,,,,,,,,,,,,,,,,,,,,,,,,,,,,,,,,,
,3772408999.99177,10.0000557899475,720.226440429688,,,5,,,,6.46999990567565,,,,,0.00073551757366764,1.05499166788826E-6,-0.337046657686523,0.000626320308791224,0.000735400234094925,1.05482336154731E-6,0.000735387509988276,9.4867013686045E-7,-4.32602127991175E-6,4.61169486734698E-7,1.00015955879163,10.005763053894,2,20,10,3,2.40712151532521,0.199200857558836,0.0403775237500668,172.74836730957,9.99922370910644,10.0008277893066,720.226440429688,720.226440429688,,,18.6738605499268,0,1,,,,,,1,1,1,10.0001583099365,0,9.9999321937561,,,,,,,,,,,,,,,,,,,,,,,,,,,,,,,,,
,3772409021.67141,9.99996709823608,740.262084960937,,,5,,,,6.46999990567565,,,,,0.000722238402368698,1.03475740767784E-6,-0.384716689199582,0.000640870824585086,0.000722123101509484,1.03459221510736E-6,0.000722106822933919,9.2499937626983E-7,-4.84871178328462E-6,4.63419038734039E-7,1.00015966925718,10.005763053894,2,20,10,3,2.36382198545173,0.193688495624808,0.0403775237500668,172.74836730957,9.99932765960693,10.0005121231079,740.262084960937,740.262084960937,,,18.686128616333,0,1,,,,,,1,1,1,10.0002088546753,0,9.99991321563721,,,,,,,,,,,,,,,,,,,,,,,,,,,,,,,,,
,3772409043.49926,10.0008201599121,760.406982421875,,,5,,,,6.46999990567565,,,,,0.000708539019061307,9.55568691567053E-7,-0.379466547894133,0.000675662939832917,0.000708425958643479,9.55416213026527E-7,0.00070841042173486,8.26628566829984E-7,-4.69182878740809E-6,4.7906716920966E-7,1.00015959383821,10.005763053894,2,20,10,3,2.31896490128191,0.190277102903512,0.0403775237500668,172.74836730957,9.99933624267578,10.0014972686768,760.406982421875,760.406982421875,,,18.6884803771973,0,1,,,,,,1,1,1,10.0007581710815,0,10.0004295349121,,,,,,,,,,,,,,,,,,,,,,,,,,,,,,,,,
,3772409065.33201,9.99971580505371,780.357604980469,,,5,,,,6.46999990567565,,,,,0.000692664827917634,9.29338210641643E-7,-0.397594662761359,0.000748616457111056,0.00069255433558053,9.29189964698273E-7,0.000692537660883917,7.70918071669014E-7,-4.80582863017302E-6,5.18728558371435E-7,1.00015954320322,10.005763053894,2,20,10,3,2.26706658260822,0.185345233411768,0.0403775237500668,172.74836730957,9.99911212921143,10.0009393692017,780.357604980469,780.357604980469,,,18.6989631652832,0,1,,,,,,1,1,1,9.99980926513672,0,9.99985074996948,,,,,,,,,,,,,,,,,,,,,,,,,,,,,,,,,
,3772409087.02704,10.0002722740173,800.198974609375,,,5,,,,6.46999990567565,,,,,0.000673624587012137,1.39032516167907E-6,-0.422091752869758,0.00114438001417915,0.000673517114749932,1.39010334467119E-6,0.000673498838581796,1.15655274852799E-6,-4.96168217898848E-6,7.7121530634342E-7,1.00015956871748,10.005763053894,2,20,10,3,2.20482284750246,0.179354535429918,0.0403775237500668,172.74836730957,9.9991512298584,10.0011148452759,800.198974609375,800.198974609375,,,18.7115383148193,0,1,,,,,,1,1,1,10.0000886917114,0,10.0001093864441,,,,,,,,,,,,,,,,,,,,,,,,,,,,,,,,,
,3772409108.89908,10.0002241134644,820.295349121094,,,5,,,,6.46999990567565,,,,,0.000649380586257548,1.30853748279504E-6,-0.475849068323495,0.00101362302057772,0.000649276909044549,1.30832856752688E-6,0.000649254517159925,1.13031809734532E-6,-5.39226908423425E-6,6.58866177171495E-7,1.00015968104141,10.005763053894,2,20,10,3,2.12562924767932,0.170950926292459,0.0403775237500668,172.74836730957,9.99919986724854,10.0008220672607,820.295349121094,820.295349121094,,,18.7222766876221,0,1,,,,,,1,1,1,10.0002212524414,0,9.99994335174561,,,,,,,,,,,,,,,,,,,,,,,,,,,,,,,,,
,3772409130.5432,10.0002498626709,840.258178710937,,,5,,,,6.46999990567565,,,,,0.000620808649953451,9.99343435526078E-7,-0.488430676103491,0.000752278297472237,0.00062070960475571,9.99183998043707E-7,0.000620687051126329,8.82974980795775E-7,-5.29131364510299E-6,4.67679211891342E-7,1.00015956768992,10.005763053894,2,20,10,3,2.03213769561749,0.163026472804471,0.0403775237500668,172.74836730957,9.99910736083984,10.0009279251099,840.258178710937,840.258178710937,,,18.73313331604,0,1,,,,,,1,1,1,10.0001497268677,0,10.0001006126404,,,,,,,,,,,,,,,,,,,,,,,,,,,,,,,,,
,3772409152.47063,9.99981546401978,860.330139160156,,,5,,,,6.46999990567565,,,,,0.000583614435526529,1.17174822033819E-6,-0.560876402825382,0.00105851945822033,0.000583521335997097,1.17156130034224E-6,0.000583493377594829,9.95082595704982E-7,-5.71208077804622E-6,6.18357912688631E-7,1.00015954777262,10.005763053894,2,20,10,3,1.91057727561998,0.150884532585444,0.0403775237500668,172.74836730957,9.99907302856445,10.0008325576782,860.330139160156,860.330139160156,,,18.7346515655518,0,1,,,,,,1,1,1,9.99984264373779,0,9.99980001449585,,,,,,,,,,,,,,,,,,,,,,,,,,,,,,,,,
,3772409174.11248,10.0002160072327,880.280822753906,,,5,,,,6.46999990567565,,,,,0.000532995703181997,1.17716936606169E-6,-0.58374781577437,0.000933927988413098,0.000532910668684889,1.17698155966015E-6,0.000532883010356121,1.06594010708065E-6,-5.42937123193068E-6,4.99056389496142E-7,1.00015956613764,10.005763053894,2,20,10,3,1.74491975293762,0.137138557112929,0.0403775237500668,172.74836730957,9.9991979598999,10.0009450912476,880.280822753906,880.280822753906,,,18.7446842193604,0,1,,,,,,1,1,1,10.00022315979,0,10.0001579284668,,,,,,,,,,,,,,,,,,,,,,,,,,,,,,,,,
,3772409199.36006,10.0001063346863,900.061462402344,,,5,,,,6.46999990567565,,,,,0.000449719704183758,1.13746259060476E-6,-0.664124111860888,0.00107286309065274,0.000449647957856889,1.13728112476711E-6,0.000449617752011252,1.02919276879635E-6,-5.21182129572918E-6,4.83911770273097E-7,1.00015956110912,10.005763053894,2,20,1,3,1.47245031396483,0.1136775113641,0.0403775237500668,172.74836730957,9.99909019470215,10.0011644363403,900.061462402344,900.061462402344,,,18.7559585571289,0,1,,,,,,1,1,1,9.99991798400879,0,10.0000863442054,,,,,,,,,,,,,,,,,,,,,,,,,,,,,,,,,
,3772409221.85032,10.0002946853638,920.169921875,,,5,,,,6.46999990567565,,,,,0.00034134562748305,1.20427119460462E-6,-0.939744812869634,0.00131424235585157,0.000341291167738426,1.20407906001599E-6,0.000341245262745235,1.11623236336175E-6,-5.59748427366255E-6,4.51477235032785E-7,1.00015956974505,10.005763053894,2,20,1,3,1.11801821568703,0.0809301359076355,0.0403775237500668,172.74836730957,9.99930191040039,10.0010232925415,920.169921875,920.169921875,,,18.7673511505127,0,1,,,,,,1,1,1,10.0002002716064,0,10.0001958500255,,,,,,,,,,,,,,,,,,,,,,,,,,,,,,,,,
,3772409243.50881,9.9999885559082,940.157043457031,,,5,,,,6.46999990567565,,,,,0.000251825486771882,1.37389687590797E-6,-1.30883054456439,0.00221309379668274,0.00025178531298777,1.37367769778906E-6,0.000251719622408589,1.25384240625721E-6,-5.75113300375835E-6,5.6113246000761E-7,1.00015955570893,10.005763053894,2,20,1,3,0.825177358091747,0.0544088814064676,0.0403775237500668,172.74836730957,9.99915027618408,10.0012683868408,940.157043457031,940.157043457031,,,18.7684726715088,0,1,,,,,,1,1,1,9.99994468688965,0,9.99997482299805,,,,,,,,,,,,,,,,,,,,,,,,,,,,,,,,,
,3772409265.43216,10.0002632141113,960.071228027344,,,5,,,,6.46999990567565,,,,,0.000179157473180956,1.26198068838018E-6,-1.84387055851224,0.00320916030213376,0.000179128889888142,1.26177934839195E-6,0.000179036139923696,1.12130208975791E-6,-5.76366149082071E-6,5.78592038947097E-7,1.00015956830209,10.005763053894,2,20,1,3,0.587395562153427,0.0332371950605577,0.0403775237500668,172.74836730957,9.99917411804199,10.0009603500366,960.071228027344,960.071228027344,,,18.7786388397217,0,1,,,,,,1,1,1,10.0001316070557,0,10.0001681934703,,,,,,,,,,,,,,,,,,,,,,,,,,,,,,,,,
,3772409288.46743,10.000340461731,980.228271484375,,,5,,,,6.46999990567565,,,,,0.000124638278211422,1.23592552874507E-6,-2.83891786825062,0.00444266212319859,0.000124618392624725,1.23572834129508E-6,0.000124465451708253,1.10214766052466E-6,-6.17212373747603E-6,5.58833667453833E-7,1.00015957184391,10.005763053894,2,20,1,3,0.408985735408995,0.0160316126926609,0.0403775237500668,172.74836730957,9.999342918396,10.000955581665,980.228271484375,980.228271484375,,,18.7819862365723,0,1,,,,,,1,1,1,10.0005159378052,0,10.0001545906067,,,,,,,,,,,,,,,,,,,,,,,,,,,,,,,,,
,3772409310.59937,9.99999618530273,1000.15460205078,,,5,,,,6.46999990567565,,,,,8.96474802348626E-5,1.24566169124242E-6,-3.94314925021676,0.00629059310716161,8.96331787181342E-5,1.24546297007961E-6,8.94209967129904E-5,1.10744036059573E-6,-6.16377108370661E-6,5.69871790460918E-7,1.00015955605874,10.005763053894,2,20,1,3,0.29433520315964,0.00586605626422921,0.0403775237500668,172.74836730957,9.9990234375,10.0010538101196,1000.15460205078,1000.15460205078,,,18.7919387817383,0,1,,,,,,1,1,1,10.0000534057617,0,9.99987421035767,,,,,,,,,,,,,,,,,,,,,,,,,,,,,,,,,