File: Experimental_Data/AC_Suceptibillity_FieldScans/ZFCd_Up_48K.dat
[Header]
; MPMS3 Data File (default extension .dat)
; Copyright (c) 2007, Quantum Design, Inc. All rights reserved.
TITLE,ZFCd_Up_48K
FILEOPENTIME,3762239534.72141,03/20/2019,10:32 am
BYAPP,SQUID AC,0.9.1.0
INFO,MPMS3 Measurement Release 1.1.16 Build 347, MultiVu Release 2.3.3.2,APPNAME
INFO,0,MOMENT_UNITS
INFO,SrM,SAMPLE_MATERIAL
INFO,MvsH,SAMPLE_COMMENT
INFO,,SAMPLE_MASS
INFO,,SAMPLE_VOLUME
INFO,,SAMPLE_MOLECULAR_WEIGHT
INFO,,SAMPLE_SIZE
INFO,,SAMPLE_SHAPE
INFO,Quartz,SAMPLE_HOLDER
INFO,Standard,SAMPLE_HOLDER_DETAIL
INFO,65.34,SAMPLE_OFFSET
DATATYPE,COMMENT,1
DATATYPE,TIME,2
STARTUPAXIS,X,2
STARTUPAXIS,Y1,5
FIELDGROUP, VSM,2,3,4,5,6,8,9,10,11,14,15
FIELDGROUP, DC, 2,3,4,14,56,57,58,59,60,61,62,63,64,65,66,67,68,69
FIELDGROUP, AC, 2,3,4,11,16,17,18,19,20,21,22,23,24,25,26,27,28,29,30
STARTUPGROUP, All
[Data]
Comment,Time Stamp (sec),Temperature (K),Magnetic Field (Oe),Moment (emu),M. Std. Err. (emu),Transport Action,Averaging Time (sec),Frequency (Hz),Peak Amplitude (mm),Center Position (mm),Lockin Signal' (V),Lockin Signal (V),Range,M. Quad. Signal (emu),AC Moment (emu),AC M. Std Err. (emu),AC Phase (deg),AC Phase Std. Err. (deg),AC Susceptibility (emu/Oe),AC Suscept. Std Err. (emu/Oe),AC X' (emu/Oe),AC X' Std Err. (emu/Oe),AC X'' (emu/Oe),AC X'' Std Err. (emu/Oe),AC Drive (Oe),AC Frequency (Hz),AC Averaging Time (sec),AC Cycles,AC Range,AC Measure Type,AC Signal' (V),AC Signal'' (V),AC Trim Coil Ratio,AC Trim Coil Phase,Min. Temperature (K),Max. Temperature (K),Min. Field (Oe),Max. Field (Oe),Mass (grams),Motor Lag (deg),Pressure (Torr),Measure Count,Measurement Number,SQUID Status (code),Motor Status (code),Measure Status (code),Motor Current (amps),Motor Temp. (C),Temp. Status (code),Field Status (code),Chamber Status (code),Chamber Temp (K),Redirection State,Average Temp (K),Rotation Angle (deg),Rotator state,DC Moment Fixed Ctr (emu),DC Moment Err Fixed Ctr (emu),DC Moment Free Ctr (emu),DC Moment Err Free Ctr (emu),DC Fixed Fit,DC Free Fit,DC Calculated Center (mm),DC Calculated Center Err (mm),DC Scan Length (mm),DC Scan Time (s),DC Number of Points,DC Squid Drift,DC Min V (V),DC Max V (V),DC Scans per Measure,Map 01,Map 02,Map 03,Map 04,Map 05,Map 06,Map 07,Map 08,Map 09,Map 10,Map 11,Map 12,Map 13,Map 14,Map 15,Map 16
,3762239676.55741,47.9338226318359,0.437141120433807,,,5,,,,31.6299982368946,,,,,0.000619117124351314,1.30350162325786E-8,0.0113000089589956,1.63099536863916E-5,0.000619018954727161,1.30329493496027E-8,0.000619018942688276,8.24258457770838E-9,1.22084379483159E-7,1.00954231327188E-8,1.00015858904385,10.005763053894,2,20,1,3,2.02524330598975,0.178165635004364,0.0413267537951469,172.859115600586,47.9080467224121,47.9419937133789,0.437141120433807,0.437141120433807,,,25.1788330078125,0,1,,,,,,1,1,1,47.9292831420898,0,47.9232330322266,,,,,,,,,,,,,,,,,,,,,,,,,,,,,,,,,
,3762239701.48192,47.8793601989746,20.1327781677246,,,5,,,,31.6299982368946,,,,,0.000618941176348977,1.63657528198398E-8,0.0144422081270186,2.08389828641593E-5,0.000618842873278266,1.63631535360659E-8,0.000618842853618773,1.00730335360402E-8,1.55988059768417E-7,1.28952234965771E-8,1.00015884980656,10.005763053894,2,20,10,3,2.02465531286585,0.178268915544972,0.0413267537951469,172.859115600586,47.8788032531738,47.9023780822754,20.1327781677246,20.1327781677246,,,25.2288799285889,0,1,,,,,,1,1,1,47.8791770935059,0,47.8855887518989,,,,,,,,,,,,,,,,,,,,,,,,,,,,,,,,,
,3762239730.25465,47.9169158935547,40.0348434448242,,,5,,,,31.6299982368946,,,,,0.000618487518284052,3.02302146717444E-8,0.00723890889995626,3.52758905308797E-5,0.000618389146636423,3.02254064970642E-8,0.000618389141700904,2.09241225500626E-8,7.81290127013875E-8,2.18118383778794E-8,1.00015907725445,10.005763053894,2,20,10,3,2.02319105074401,0.17792683589049,0.0413267537951469,172.859115600586,47.9151268005371,47.9304962158203,40.0348434448242,40.0348434448242,,,25.2617263793945,0,1,,,,,,1,1,1,47.9178047180176,0,47.9206649780273,,,,,,,,,,,,,,,,,,,,,,,,,,,,,,,,,
,3762239752.51469,47.9506721496582,60.0461921691895,,,5,,,,31.6299982368946,,,,,0.00062098778397485,7.04922582234705E-8,0.0148721391795981,7.76396712207573E-5,0.000620888981417947,7.04810425191779E-8,0.000620888960501612,5.1424225854875E-8,1.61162782346438E-7,4.81988210417741E-8,1.00015913079449,10.005763053894,2,20,10,3,2.03134339226417,0.178960113350318,0.0413267537951469,172.859115600586,47.9489250183105,47.9559898376465,60.0461921691895,60.0461921691895,,,25.2618675231934,0,1,,,,,,1,1,1,47.9515151977539,0,47.95259995894,,,,,,,,,,,,,,,,,,,,,,,,,,,,,,,,,
,3762239775.27506,47.9691982269287,80.0818252563477,,,5,,,,31.6299982368946,,,,,0.000632388507909163,4.68405223816596E-8,0.0202432796404306,4.37395941944312E-5,0.000632287935625342,4.6833073071224E-8,0.000632287896161317,3.78004207263361E-8,2.23394835302277E-7,2.76489588629768E-8,1.00015906089323,10.005763053894,2,20,10,3,2.06861701045864,0.182483854691701,0.0413267537951469,172.859115600586,47.9676780700684,47.9695663452148,80.0818252563477,80.0818252563477,,,25.2294578552246,0,1,,,,,,1,1,1,47.9688186645508,0,47.9684398651123,,,,,,,,,,,,,,,,,,,,,,,,,,,,,,,,,
,3762239797.02405,47.9941387176514,100.008171081543,,,5,,,,31.6299982368946,,,,,0.000648822777771026,3.92260120185231E-8,0.0286925469336943,5.06853294435131E-5,0.000648719521182088,3.92197694137049E-8,0.000648719439839142,2.13802302041255E-8,3.24865368593021E-7,3.28797212470359E-8,1.00015916985009,10.005763053894,2,20,10,3,2.12234499096425,0.187584303324227,0.0413267537951469,172.859115600586,47.9892539978027,48.0056457519531,100.008171081543,100.008171081543,,,25.2439384460449,0,1,,,,,,1,1,1,47.9962387084961,0,47.997896194458,,,,,,,,,,,,,,,,,,,,,,,,,,,,,,,,,
,3762239818.5831,48.0217666625977,120.092384338379,,,5,,,,31.6299982368946,,,,,0.000671600030534137,6.28736270592355E-8,0.048911482429471,7.82913846304765E-5,0.000671493224423016,6.28636281204432E-8,0.000671492979748916,3.44682473324967E-8,5.73231140894969E-7,5.2571624154968E-8,1.00015905761553,10.005763053894,2,20,10,3,2.19677937999366,0.194991885324103,0.0413267537951469,172.859115600586,48.0186538696289,48.0218887329102,120.092384338379,120.092384338379,,,25.2589988708496,0,1,,,,,,1,1,1,48.0218620300293,0,48.0207500457764,,,,,,,,,,,,,,,,,,,,,,,,,,,,,,,,,
,3762239840.53127,48.0151557922363,140.115875244141,,,5,,,,31.6299982368946,,,,,0.000710295566068617,7.98522252383722E-8,0.0854433750008718,7.97992297702573E-5,0.000710182658036539,7.9839531990604E-8,0.000710181868355862,5.62443931448346E-8,1.0590724342075E-6,5.66649724984312E-8,1.00015898449617,10.005763053894,2,20,10,3,2.32321595397706,0.207757872412993,0.0413267537951469,172.859115600586,48.012336730957,48.0163154602051,140.115875244141,140.115875244141,,,25.2263469696045,0,1,,,,,,1,1,1,48.0147018432617,0,48.0140155792236,,,,,,,,,,,,,,,,,,,,,,,,,,,,,,,,,
,3762239862.35157,48.0092124938965,160.175796508789,,,5,,,,31.6299982368946,,,,,0.000765038469041108,7.22011089474986E-8,0.110147762231471,6.19770807429073E-5,0.000764916891672689,7.21896349874587E-8,0.000764915478190911,5.44510421292199E-8,1.47050677605792E-6,4.7396491543831E-8,1.00015894193179,10.005763053894,2,20,10,3,2.50216744495688,0.224902537624161,0.0413267537951469,172.859115600586,48.005916595459,48.0105056762695,160.175796508789,160.175796508789,,,25.2089729309082,0,1,,,,,,1,1,1,48.008430480957,0,48.0079658508301,,,,,,,,,,,,,,,,,,,,,,,,,,,,,,,,,
,3762239884.05929,48.0342140197754,180.005004882813,,,5,,,,31.6299982368946,,,,,0.000810032141777689,1.71134730448379E-7,0.0969486607739016,0.00019384785461401,0.000809903323675125,1.71107515168735E-7,0.000809902164253369,6.80036544692401E-8,1.37041516470815E-6,1.57013645031402E-7,1.00015905367813,10.005763053894,2,20,10,3,2.64937689164197,0.237575342014786,0.0413267537951469,172.859115600586,48.0301742553711,48.0345268249512,180.005004882813,180.005004882813,,,25.1603488922119,0,1,,,,,,1,1,1,48.0345039367676,0,48.033031463623,,,,,,,,,,,,,,,,,,,,,,,,,,,,,,,,,
,3762239905.47891,48.0527687072754,200.101348876953,,,5,,,,31.6299982368946,,,,,0.000833929764431502,1.35505669043627E-7,0.0525604179444397,0.000113262690063431,0.000833797107468911,1.35484113546707E-7,0.000833796756634072,9.71588677245504E-8,7.64885628142103E-7,9.44250996611611E-8,1.00015909981146,10.005763053894,2,20,10,3,2.72772397259125,0.242529726867225,0.0413267537951469,172.859115600586,48.0433349609375,48.0529823303223,200.101348876953,200.101348876953,,,25.1426200866699,0,1,,,,,,1,1,1,48.0522651672363,0,48.0498948530717,,,,,,,,,,,,,,,,,,,,,,,,,,,,,,,,,
,3762239927.65225,48.056468963623,220.100570678711,,,5,,,,31.6299982368946,,,,,0.000845691381087551,1.62382885139138E-7,0.0140552334942905,0.00014764874883028,0.000845557000959762,1.62357082543364E-7,0.000845556975518201,1.03806776610684E-7,2.07423671743783E-7,1.24835793671895E-7,1.00015892497802,10.005763053894,2,20,10,3,2.76635635176987,0.244150473315864,0.0413267537951469,172.859115600586,48.0425987243652,48.0594596862793,220.100570678711,220.100570678711,,,25.1254081726074,0,1,,,,,,1,1,1,48.0545463562012,0,48.0518486022949,,,,,,,,,,,,,,,,,,,,,,,,,,,,,,,,,
,3762239949.34505,48.0528907775879,240.136184692383,,,5,,,,31.6299982368946,,,,,0.00085278353497375,1.01087175379796E-7,0.000758739677451992,0.000103519470788034,0.000852647971904175,1.01071106017259E-7,0.000852647971829414,4.92453348432719E-8,1.12911954887715E-8,8.82624805210346E-8,1.00015899066677,10.005763053894,2,20,10,3,2.7896089735669,0.245610432740655,0.0413267537951469,172.859115600586,48.0420455932617,48.0538864135742,240.136184692383,240.136184692383,,,25.1240997314453,0,1,,,,,,1,1,1,48.0520477294922,0,48.0493076324463,,,,,,,,,,,,,,,,,,,,,,,,,,,,,,,,,
,3762239971.31066,48.0501804351807,260.013977050781,,,5,,,,31.6299982368946,,,,,0.000857230553762052,1.62856225957736E-7,-0.00565307602130183,0.000177130039339296,0.000857094390079048,1.62830357650279E-7,0.000857094385907252,5.88762541155471E-8,-8.45650373878013E-8,1.5181341203543E-7,1.00015886661327,10.005763053894,2,20,10,3,2.80417989146269,0.246637086257384,0.0413267537951469,172.859115600586,48.037109375,48.0518951416016,260.013977050781,260.013977050781,,,25.0748901367187,0,1,,,,,,1,1,1,48.0490493774414,0,48.0459625244141,,,,,,,,,,,,,,,,,,,,,,,,,,,,,,,,,
,3762239992.92308,48.0217533111572,280.086029052734,,,5,,,,31.6299982368946,,,,,0.000860537975527209,2.08425057451684E-7,-0.0154812804774975,0.000198504897515062,0.000860401320101293,2.08391959069268E-7,0.000860401288693345,1.19418382227155E-7,-2.32479845999433E-7,1.70781903581663E-7,1.00015882754097,10.005763053894,2,20,10,3,2.81503783693204,0.247166436438577,0.0413267537951469,172.859115600586,48.0155906677246,48.0246849060059,280.086029052734,280.086029052734,,,25.0734195709229,0,1,,,,,,1,1,1,48.0199127197266,0,48.0191432952881,,,,,,,,,,,,,,,,,,,,,,,,,,,,,,,,,
,3762240014.82307,48.00856590271,300.085235595703,,,5,,,,31.6299982368946,,,,,0.000863102591119663,1.46896319374577E-7,-0.0232019516517115,0.000146496438693866,0.000862965455262433,1.46872979446174E-7,0.000862965384505797,7.47754225658544E-8,-3.49458239211035E-7,1.26413244050986E-7,1.00015891233698,10.005763053894,2,20,10,3,2.82345699263256,0.247583088961067,0.0413267537951469,172.859115600586,48.005256652832,48.0105133056641,300.085235595703,300.085235595703,,,25.0086574554443,0,1,,,,,,1,1,1,48.0082359313965,0,48.0074859619141,,,,,,,,,,,,,,,,,,,,,,,,,,,,,,,,,
,3762240036.45318,48.0038661956787,320.048034667969,,,5,,,,31.6299982368946,,,,,0.000864978195430999,1.85088827701243E-7,-0.0283570921612428,0.000148307257308778,0.000864840749151386,1.85059416820253E-7,0.000864840643229852,1.33416275735276E-7,-4.28030965556121E-7,1.28246189505891E-7,1.00015892669228,10.005763053894,2,20,10,3,2.8296112217926,0.247927002030315,0.0413267537951469,172.859115600586,48.0030937194824,48.0048332214355,320.048034667969,320.048034667969,,,25.0223827362061,0,1,,,,,,1,1,1,48.0032234191895,0,48.0035663604736,,,,,,,,,,,,,,,,,,,,,,,,,,,,,,,,,
,3762240058.40057,48.0030155181885,340.059387207031,,,5,,,,31.6299982368946,,,,,0.000866064906358787,1.70339486262658E-7,-0.0486464822476718,0.000160515662497825,0.000865927221776129,1.70312406166347E-7,0.000865926909665192,9.84399528745266E-8,-7.35207872531986E-7,1.38981622426246E-7,1.00015900248796,10.005763053894,2,20,10,3,2.83325020053646,0.247295877275098,0.0413267537951469,172.859115600586,48.0022277832031,48.0032005310059,340.059387207031,340.059387207031,,,24.9738330841064,0,1,,,,,,1,1,1,48.0030746459961,0,48.0026973377575,,,,,,,,,,,,,,,,,,,,,,,,,,,,,,,,,
,3762240081.47922,48.0022602081299,360.1435546875,,,5,,,,31.6299982368946,,,,,0.000868290869094729,2.61076219599858E-7,-0.0512220314990177,0.000181389267205817,0.000868152860642811,2.61034723453598E-7,0.00086815251371868,2.08202739063564E-7,-7.76122563098535E-7,1.5745077419602E-7,1.00015896791703,10.005763053894,2,20,10,3,2.8405396323686,0.247864854653899,0.0413267537951469,172.859115600586,48.0003814697266,48.0033874511719,360.1435546875,360.1435546875,,,24.9559783935547,0,1,,,,,,1,1,1,48.0017852783203,0,48.0014892578125,,,,,,,,,,,,,,,,,,,,,,,,,,,,,,,,,
,3762240103.18927,48.002965927124,380.203491210937,,,5,,,,31.6299982368946,,,,,0.000868796756451181,2.08642340145656E-7,-0.0632707390960725,0.000171619342147169,0.000868658639537992,2.0860917124192E-7,0.000868658109899361,1.45939861311681E-7,-9.59244528002255E-7,1.49061541675135E-7,1.00015900021815,10.005763053894,2,20,10,3,2.84224296666685,0.24747259359948,0.0413267537951469,172.859115600586,48.0015296936035,48.0037803649902,380.203491210937,380.203491210937,,,24.8921890258789,0,1,,,,,,1,1,1,48.0023612976074,0,48.0023826599121,,,,,,,,,,,,,,,,,,,,,,,,,,,,,,,,,
,3762240125.05295,48.041862487793,400.020568847656,,,5,,,,31.6299982368946,,,,,0.000870036062282258,2.91524248025947E-7,-0.0746168169996633,0.000240810503944179,0.000869897696740394,2.91477885682714E-7,0.000869896959063302,2.02700064164849E-7,-1.1328753958846E-6,2.09456539238171E-7,1.00015905955652,10.005763053894,2,20,10,3,2.84634268516951,0.247322103356925,0.0413267537951469,172.859115600586,48.0360679626465,48.042308807373,400.020568847656,400.020568847656,,,24.8748168945313,0,1,,,,,,1,1,1,48.0423316955566,0,48.0401885986328,,,,,,,,,,,,,,,,,,,,,,,,,,,,,,,,,
,3762240146.63224,48.0602035522461,420.104766845703,,,5,,,,31.6299982368946,,,,,0.000871095290577997,2.72377071242515E-7,-0.0823757570642014,0.000223155188506495,0.000870956824834495,2.72333775297639E-7,0.000870955924673627,1.90785420525003E-7,-1.25219874323286E-6,1.94336328263562E-7,1.00015898117972,10.005763053894,2,20,10,3,2.84983776883675,0.247298447183279,0.0413267537951469,172.859115600586,48.0482940673828,48.0609092712402,420.104766845703,420.104766845703,,,24.8569068908691,0,1,,,,,,1,1,1,48.059497833252,0,48.0562232971191,,,,,,,,,,,,,,,,,,,,,,,,,,,,,,,,,
,3762240168.55061,48.0403823852539,440.176818847656,,,5,,,,31.6299982368946,,,,,0.000872349446846695,2.34210939599547E-7,-0.087451263887826,0.000200245954769386,0.000872210872530345,2.34173734760416E-7,0.000872209856566315,1.56011366092637E-7,-1.33126583165317E-6,1.74636169511218E-7,1.00015887707974,10.005763053894,2,20,10,3,2.85395900957213,0.247463099768744,0.0413267537951469,172.859115600586,48.0301971435547,48.0433464050293,440.176818847656,440.176818847656,,,24.8391189575195,0,1,,,,,,1,1,1,48.0390129089355,0,48.0370128631592,,,,,,,,,,,,,,,,,,,,,,,,,,,,,,,,,
,3762240190.23334,48.0190372467041,460.431060791016,,,5,,,,31.6299982368946,,,,,0.00087332006566666,4.47452639852252E-7,-0.0976740557863502,0.00030962366045248,0.000873181288616617,4.47381536301751E-7,0.000873180019833187,3.56468120948416E-7,-1.48854099397294E-6,2.70334455390393E-7,1.00015893268884,10.005763053894,2,20,10,3,2.85717486232682,0.247290712718725,0.0413267537951469,172.859115600586,48.0121116638184,48.0211563110352,460.431060791016,460.431060791016,,,24.7912826538086,0,1,,,,,,1,1,1,48.0178031921387,0,48.016418838501,,,,,,,,,,,,,,,,,,,,,,,,,,,,,,,,,
,3762240212.12015,48.014720916748,480.357360839844,,,5,,,,31.6299982368946,,,,,0.000874003117623903,3.57397845401702E-7,-0.109732408917604,0.000306598660231344,0.000873864204157484,3.57341040829047E-7,0.000873862601508609,2.36487416903533E-7,-1.67361656274042E-6,2.67892368512209E-7,1.00015896459171,10.005763053894,2,20,10,3,2.85945789256996,0.246943335543346,0.0413267537951469,172.859115600586,48.010570526123,48.0158271789551,480.357360839844,480.357360839844,,,24.7738094329834,0,1,,,,,,1,1,1,48.0140838623047,0,48.0131519317627,,,,,,,,,,,,,,,,,,,,,,,,,,,,,,,,,
,3762240233.77737,48.0473384857178,500.356597900391,,,5,,,,31.6299982368946,,,,,0.000873621205718836,3.66898139089025E-7,-0.119437349802647,0.000334225630098367,0.000873482151322885,3.66839739866601E-7,0.000873480253485778,2.22185483534051E-7,-1.82083774028318E-6,2.91898964801412E-7,1.00015919546351,10.005763053894,2,20,10,3,2.85824650304648,0.24641228138352,0.0413267537951469,172.859115600586,48.0394897460937,48.0478935241699,500.356597900391,500.356597900391,,,24.7716007232666,0,1,,,,,,1,1,1,48.0479164123535,0,48.044966506958,,,,,,,,,,,,,,,,,,,,,,,,,,,,,,,,,
,3762240255.65712,48.053955078125,520.404357910156,,,5,,,,31.6299982368946,,,,,0.000872756285133815,4.57477240367729E-7,-0.126318575764456,0.000377679001400959,0.000872617604687843,4.57404547510861E-7,0.000872615483969588,3.17219568483377E-7,-1.92383670581891E-6,3.29530977989681E-7,1.00015892464835,10.005763053894,2,20,10,3,2.85544258862001,0.245886620156032,0.0413267537951469,172.859115600586,48.0420570373535,48.0546188354492,520.404357910156,520.404357910156,,,24.7234268188477,0,1,,,,,,1,1,1,48.0532913208008,0,48.0495319366455,,,,,,,,,,,,,,,,,,,,,,,,,,,,,,,,,
,3762240277.38884,48.0622081756592,540.476440429687,,,5,,,,31.6299982368946,,,,,0.000870370358799435,4.49043475189693E-7,-0.139150085942909,0.000354660074069264,0.000870232028282462,4.48972107391562E-7,0.000870229461869459,3.26095026779294E-7,-2.11346705666585E-6,3.08606524113524E-7,1.0001589582002,10.005763053894,2,20,10,3,2.84768761393999,0.244637807718415,0.0413267537951469,172.859115600586,48.0491981506348,48.0633201599121,540.476440429687,540.476440429687,,,24.7216377258301,0,1,,,,,,1,1,1,48.0610961914063,0,48.0575008392334,,,,,,,,,,,,,,,,,,,,,,,,,,,,,,,,,
,3762240299.46943,48.0264205932617,560.317810058594,,,5,,,,31.6299982368946,,,,,0.000866421194459311,4.18735317352733E-7,-0.152971703785968,0.000397159941544456,0.000866283618484158,4.18668827843953E-7,0.000866280530985403,2.38646167306224E-7,-2.31285314161378E-6,3.43993596216964E-7,1.00015881170118,10.005763053894,2,20,10,3,2.8348217490614,0.242904353107116,0.0413267537951469,172.859115600586,48.0164489746094,48.0297737121582,560.317810058594,560.317810058594,,,24.6878681182861,0,1,,,,,,1,1,1,48.024658203125,0,48.0227609114213,,,,,,,,,,,,,,,,,,,,,,,,,,,,,,,,,
,3762240322.23483,48.0234279632568,580.401977539063,,,5,,,,31.6299982368946,,,,,0.000857401798989731,4.8152362743316E-7,-0.15036360189872,0.000335580840731737,0.000857265477557341,4.8144706823921E-7,0.000857262525496756,3.86047090260085E-7,-2.24975343949481E-6,2.87678507396455E-7,1.00015901892233,10.005763053894,2,20,10,3,2.80529686879768,0.240563735499851,0.0413267537951469,172.859115600586,48.0184020996094,48.0237464904785,580.401977539063,580.401977539063,,,24.6395359039307,0,1,,,,,,1,1,1,48.0231094360352,0,48.0218193054199,,,,,,,,,,,,,,,,,,,,,,,,,,,,,,,,,
,3762240343.89049,48.0088386535645,600.425476074219,,,5,,,,31.6299982368946,,,,,0.000836263896039871,4.2120001660614E-7,-0.158080659426473,0.000398699851332946,0.00083613101406819,4.21133088105528E-7,0.000836127831657134,2.57403550021766E-7,-2.3069059449319E-6,3.3331140144539E-7,1.00015892482093,10.005763053894,2,20,10,3,2.73616472868203,0.234323200459674,0.0413267537951469,172.859115600586,48.0030746459961,48.0111389160156,600.425476074219,600.425476074219,,,24.6065921783447,0,1,,,,,,1,1,1,48.0076789855957,0,48.0066020965576,,,,,,,,,,,,,,,,,,,,,,,,,,,,,,,,,
,3762240365.75574,48.0032234191895,620.327575683594,,,5,,,,31.6299982368946,,,,,0.000787401725057561,5.23586862322946E-7,-0.185319412278425,0.000528040923210059,0.000787276538637685,5.2350361896355E-7,0.000787272420569827,3.18275769857873E-7,-2.54638949491133E-6,4.1563995643984E-7,1.0001590120037,10.005763053894,2,20,10,3,2.57639435767542,0.219461985862393,0.0413267537951469,172.859115600586,48.0030517578125,48.004524230957,620.327575683594,620.327575683594,,,24.5742244720459,0,1,,,,,,1,1,1,48.0033874511719,0,48.0037086486816,,,,,,,,,,,,,,,,,,,,,,,,,,,,,,,,,
,3762240387.46536,48.0355472564697,640.375366210937,,,5,,,,31.6299982368946,,,,,0.000635884472246215,5.22012561553073E-7,-0.239633139012271,0.000532880163986879,0.000635783309774985,5.21929514894372E-7,0.000635777749106774,3.9702420278807E-7,-2.65908427067451E-6,3.38795219739553E-7,1.00015911470099,10.005763053894,2,20,10,3,2.08079132873086,0.1753036967134,0.0413267537951469,172.859115600586,48.0312194824219,48.0357704162598,640.375366210937,640.375366210937,,,24.5722942352295,0,1,,,,,,1,1,1,48.0356254577637,0,48.03424949646,,,,,,,,,,,,,,,,,,,,,,,,,,,,,,,,,
,3762240412.43191,48.0178852081299,660.4716796875,,,5,,,,31.6299982368946,,,,,0.000429060104892063,4.71329914474819E-7,-0.291593964046458,0.000636194408840421,0.000428991995880129,4.71255095552239E-7,0.000428986440291873,3.84134195750147E-7,-2.18324870860443E-6,2.72987700710742E-7,1.00015876522776,10.005763053894,2,20,1,3,1.40410927788525,0.117042284180317,0.0413267537951469,172.859115600586,48.0115776062012,48.0232200622559,660.4716796875,660.4716796875,,,24.523509979248,0,1,,,,,,1,1,1,48.0164947509766,0,48.0165889446552,,,,,,,,,,,,,,,,,,,,,,,,,,,,,,,,,
,3762240434.88595,48.0402069091797,680.41015625,,,5,,,,31.6299982368946,,,,,0.000217467566030801,5.43044210024231E-7,-0.710973265670811,0.00174011179125002,0.000217432972768421,5.42957826242115E-7,0.000217416232935792,3.89424549155104E-7,-2.69801833251717E-6,3.7835396336355E-7,1.00015909851178,10.005763053894,2,20,1,3,0.71208210976335,0.0541269874357063,0.0413267537951469,172.859115600586,48.0329322814941,48.0405120849609,680.41015625,680.41015625,,,24.5057430267334,0,1,,,,,,1,1,1,48.0402221679687,0,48.0377166748047,,,,,,,,,,,,,,,,,,,,,,,,,,,,,,,,,
,3762240456.56993,48.0587749481201,700.336486816406,,,5,,,,31.6299982368946,,,,,0.000127787366625369,8.78131089075125E-7,-1.90613559655595,0.00384211816191773,0.00012776706242146,8.77991562350678E-7,0.0001276963637624,7.26999706981792E-7,-4.24981431007164E-6,4.92281027064189E-7,1.00015891579194,10.005763053894,2,20,1,3,0.41900277928148,0.0230802358241155,0.0413267537951469,172.859115600586,48.04833984375,48.0602378845215,700.336486816406,700.336486816406,,,24.4730644226074,0,1,,,,,,1,1,1,48.0578346252441,0,48.055347442627,,,,,,,,,,,,,,,,,,,,,,,,,,,,,,,,,
,3762240478.45423,48.028995513916,720.323547363281,,,5,,,,31.6299982368946,,,,,7.89707218029145E-5,8.0996093231844E-7,-2.84553697665219,0.00457078078318659,7.89581820730681E-5,8.09832318940652E-7,7.88608264413409E-5,7.23250430827908E-7,-3.91976648188155E-6,3.64331166808494E-7,1.00015881482472,10.005763053894,2,20,1,3,0.259136554263738,0.0100216233285813,0.0413267537951469,172.859115600586,48.0199432373047,48.0327033996582,720.323547363281,720.323547363281,,,24.4405784606934,0,1,,,,,,1,1,1,48.0272903442383,0,48.0257965087891,,,,,,,,,,,,,,,,,,,,,,,,,,,,,,,,,
,3762240500.16177,48.0108489990234,740.456359863281,,,5,,,,31.6299982368946,,,,,4.88181342754026E-5,9.26684918745796E-7,-4.59484775437971,0.00974630283322182,4.88103782036196E-5,9.26537689957627E-7,4.86535058558269E-5,7.93113749410476E-7,-3.91016474300108E-6,4.79001744681658E-7,1.00015890210378,10.005763053894,2,20,1,3,0.160307600516063,0.00130560202586133,0.0413267537951469,172.859115600586,48.0067367553711,48.0137939453125,740.456359863281,740.456359863281,,,24.4230003356934,0,1,,,,,,1,1,1,48.0089492797852,0,48.0091986222701,,,,,,,,,,,,,,,,,,,,,,,,,,,,,,,,,
,3762240522.17169,48.0043926239014,760.479858398438,,,5,,,,31.6299982368946,,,,,3.43832747485194E-5,1.08179144793883E-6,-5.96433750670783,0.0135260958027938,3.43778103685E-5,1.08161952366412E-6,3.41917151730278E-5,9.73712144848902E-7,-3.5721785032507E-6,4.70941029158797E-7,1.00015895078717,10.005763053894,2,20,1,3,0.112896646240515,-0.0017767491563864,0.0413267537951469,172.859115600586,48.0023460388184,48.0053024291992,760.479858398438,760.479858398438,,,24.3905296325684,0,1,,,,,,1,1,1,48.004077911377,0,48.0034311467951,,,,,,,,,,,,,,,,,,,,,,,,,,,,,,,,,
,3762240545.0949,48.0019435882568,780.381958007812,,,5,,,,31.6299982368946,,,,,2.54677816989532E-5,9.79078827639545E-7,-9.3830088824215,0.0190570329817647,2.54637341511922E-5,9.78923224440042E-7,2.51230434619015E-5,8.49623409432859E-7,-4.151438802873E-6,4.86241443618058E-7,1.00015895342517,10.005763053894,2,20,1,3,0.0833957324675226,-0.00629850159156084,0.0413267537951469,172.859115600586,48.0011215209961,48.0021591186523,780.381958007812,780.381958007812,,,24.373083114624,0,1,,,,,,1,1,1,48.0018615722656,0,48.0016410827637,,,,,,,,,,,,,,,,,,,,,,,,,,,,,,,,,
,3762240566.75425,48.0330371856689,800.4296875,,,5,,,,31.6299982368946,,,,,2.01018864186134E-5,1.05273660794384E-6,-12.7147961368917,0.0259418621656185,2.00986884249358E-5,1.05256912888509E-6,1.96058231224718E-5,9.18143821515342E-7,-4.42368354349606E-6,5.14697672517684E-7,1.00015911454569,10.005763053894,2,20,1,3,0.0654248281612133,-0.0087872518230782,0.0413267537951469,172.859115600586,48.0279006958008,48.0333862304687,800.4296875,800.4296875,,,24.3552703857422,0,1,,,,,,1,1,1,48.032527923584,0,48.0313648223877,,,,,,,,,,,,,,,,,,,,,,,,,,,,,,,,,
,3762240588.6188,48.0307216644287,820.453247070312,,,5,,,,31.6299982368946,,,,,1.7512807838448E-5,1.02952155677392E-6,-13.5893400657092,0.031383254857296,1.75100235947546E-5,1.02935788005639E-6,1.70198257945091E-5,8.75198393725402E-7,-4.11417746498901E-6,5.41853685836555E-7,1.0001590085632,10.005763053894,2,20,1,3,0.0568749828702398,-0.00852333862500794,0.0413267537951469,172.859115600586,48.0243072509766,48.0316276550293,820.453247070312,820.453247070312,,,24.3222465515137,0,1,,,,,,1,1,1,48.0301208496094,0,48.0284194946289,,,,,,,,,,,,,,,,,,,,,,,,,,,,,,,,,
,3762240610.25123,48.0502891540527,840.31884765625,,,5,,,,31.6299982368946,,,,,1.48797790148294E-5,1.15947771775299E-6,-17.3976525395906,0.0414294067314162,1.48774120029118E-5,1.15929327297236E-6,1.41968087828853E-5,9.99264888069311E-7,-4.44837141958425E-6,5.87733422761374E-7,1.00015910105314,10.005763053894,2,20,1,3,0.0477364455115603,-0.010434477797597,0.0413267537951469,172.859115600586,48.0409393310547,48.0505981445313,840.31884765625,840.31884765625,,,24.2902278900146,0,1,,,,,,1,1,1,48.0501518249512,0,48.0470134735107,,,,,,,,,,,,,,,,,,,,,,,,,,,,,,,,,
,3762240632.19396,48.0610675811768,860.366577148438,,,5,,,,31.6299982368946,,,,,1.41809337913634E-5,1.11873609668244E-6,-16.8664557246004,0.0406575513631742,1.41786790875116E-5,1.11855822274103E-6,1.35687635550307E-5,9.73955911301853E-7,-4.11382987668524E-6,5.50074886267079E-7,1.00015902072668,10.005763053894,2,20,1,3,0.0455849190725081,-0.00952123494755422,0.0413267537951469,172.859115600586,48.0512657165527,48.0613784790039,860.366577148438,860.366577148438,,,24.2577266693115,0,1,,,,,,1,1,1,48.0607566833496,0,48.0581245422363,,,,,,,,,,,,,,,,,,,,,,,,,,,,,,,,,
,3762240653.83794,48.0315628051758,880.402282714844,,,5,,,,31.6299982368946,,,,,1.16304699914443E-5,1.1215526553038E-6,-24.0971075865697,0.0555636885438356,1.16286231614336E-5,1.12137456128835E-6,1.06152443477914E-5,9.82897110532632E-7,-4.74778517493303E-6,5.39809389332242E-7,1.00015881759904,10.005763053894,2,20,1,3,0.0361065202536918,-0.0124515587068204,0.0413267537951469,172.859115600586,48.0210952758789,48.0353851318359,880.402282714844,880.402282714844,,,24.2253227233887,0,1,,,,,,1,1,1,48.0298461914063,0,48.0278656005859,,,,,,,,,,,,,,,,,,,,,,,,,,,,,,,,,
,3762240675.75256,48.0119800567627,900.340759277344,,,5,,,,31.6299982368946,,,,,1.12148862613015E-5,1.09208814372132E-6,-23.4059486427612,0.0597324460732281,1.12131051813045E-5,1.09191470492735E-6,1.02904167402446E-5,9.10774930149398E-7,-4.45432948030246E-6,6.02301211561069E-7,1.00015883914118,10.005763053894,2,20,1,3,0.0349589160860258,-0.0115850433828266,0.0413267537951469,172.859115600586,48.0071640014648,48.0144538879395,900.340759277344,900.340759277344,,,24.2229328155518,0,1,,,,,,1,1,1,48.0110244750977,0,48.0101367950439,,,,,,,,,,,,,,,,,,,,,,,,,,,,,,,,,
,3762240697.40446,48.0045204162598,920.206359863281,,,5,,,,31.6299982368946,,,,,9.67785054266516E-6,1.29206451452851E-6,-28.5791165809669,0.0855834780840408,9.67631242858977E-6,1.29185916494108E-6,8.49732529449273E-6,1.16801946393535E-6,-4.62887513930273E-6,5.51933541208042E-7,1.0001589566363,10.005763053894,2,20,1,3,0.0291436735207215,-0.0126760485172729,0.0413267537951469,172.859115600586,48.0030403137207,48.0051727294922,920.206359863281,920.206359863281,,,24.1906509399414,0,1,,,,,,1,1,1,48.0041427612305,0,48.0039218902588,,,,,,,,,,,,,,,,,,,,,,,,,,,,,,,,,
,3762240720.11898,48.0026359558105,940.254089355469,,,5,,,,31.6299982368946,,,,,9.42649817898182E-6,9.79047659527957E-7,-28.9734347497864,0.0746967678186762,9.42499974431175E-6,9.78892030265761E-7,8.24540820509919E-6,7.80401748162586E-7,-4.56550804528473E-6,5.90933768186083E-7,1.0001589851152,10.005763053894,2,20,1,3,0.0283013962661908,-0.0125412961610523,0.0413267537951469,172.859115600586,48.0010566711426,48.0035820007324,940.254089355469,940.254089355469,,,24.1727294921875,0,1,,,,,,1,1,1,48.0021209716797,0,48.0020613236861,,,,,,,,,,,,,,,,,,,,,,,,,,,,,,,,,
,3762240742.35485,48.0000896453857,960.289794921875,,,5,,,,31.6299982368946,,,,,8.33886315579304E-6,1.10112449837263E-6,-35.1165969670064,0.117074289845134,8.33753762654019E-6,1.10094946579249E-6,6.81996504372261E-6,9.86827106566224E-7,-4.79610367656653E-6,4.88120874348658E-7,1.00015898330085,10.005763053894,2,20,1,3,0.0237052717854576,-0.0137092426670276,0.0413267537951469,172.859115600586,47.9994621276855,48.0008697509766,960.289794921875,960.289794921875,,,24.1248531341553,0,1,,,,,,1,1,1,47.9999351501465,0,48.0003444671631,,,,,,,,,,,,,,,,,,,,,,,,,,,,,,,,,
,3762240763.99746,48.0351428985596,980.3740234375,,,5,,,,31.6299982368946,,,,,9.13040478064856E-6,1.08903481135901E-6,-31.3907109518284,0.0876909086115714,9.12895135185824E-6,1.08886145271977E-6,7.79279471029197E-6,9.66296284643508E-7,-4.7550082426679E-6,5.01887192009475E-7,1.00015921092514,10.005763053894,2,20,1,3,0.026876295429525,-0.0132915921075356,0.0413267537951469,172.859115600586,48.0310974121094,48.0357933044434,980.3740234375,980.3740234375,,,24.1083984375,0,1,,,,,,1,1,1,48.0357933044434,0,48.0339614868164,,,,,,,,,,,,,,,,,,,,,,,,,,,,,,,,,
,3762240785.90808,48.052547454834,1000.16674804688,,,5,,,,31.6299982368946,,,,,1.03216653895525E-5,1.14277604981911E-6,-24.5248617304522,0.0619437818731572,1.03200247641033E-5,1.14259440592742E-6,9.388964946492E-6,1.02487340265259E-6,-4.28371898766132E-6,5.05130166384803E-7,1.00015897495275,10.005763053894,2,20,1,3,0.0319615249487506,-0.011285222927714,0.0413267537951469,172.859115600586,48.0412902832031,48.0539093017578,1000.16674804688,1000.16674804688,,,24.090648651123,0,1,,,,,,1,1,1,48.0514831542969,0,48.0489349365234,,,,,,,,,,,,,,,,,,,,,,,,,,,,,,,,,