File: Experimental_Data/AC_Suceptibillity_FieldScans/ZFCd_Up_5K.dat
[Header]
; MPMS3 Data File (default extension .dat)
; Copyright (c) 2007, Quantum Design, Inc. All rights reserved.
TITLE,ZFCd_Up_5K
FILEOPENTIME,3772372338.93702,07/15/2019,5:12 pm
BYAPP,SQUID AC,0.9.1.0
INFO,MPMS3 Measurement Release 1.1.16 Build 347, MultiVu Release 2.3.3.2,APPNAME
INFO,0,MOMENT_UNITS
INFO,Cu2OSeO3,SAMPLE_MATERIAL
INFO,,SAMPLE_COMMENT
INFO,,SAMPLE_MASS
INFO,,SAMPLE_VOLUME
INFO,,SAMPLE_MOLECULAR_WEIGHT
INFO,,SAMPLE_SIZE
INFO,,SAMPLE_SHAPE
INFO,Quartz,SAMPLE_HOLDER
INFO,Standard,SAMPLE_HOLDER_DETAIL
INFO,64.77,SAMPLE_OFFSET
DATATYPE,COMMENT,1
DATATYPE,TIME,2
STARTUPAXIS,X,2
STARTUPAXIS,Y1,5
FIELDGROUP, VSM,2,3,4,5,6,8,9,10,11,14,15
FIELDGROUP, DC, 2,3,4,14,56,57,58,59,60,61,62,63,64,65,66,67,68,69
FIELDGROUP, AC, 2,3,4,11,16,17,18,19,20,21,22,23,24,25,26,27,28,29,30
STARTUPGROUP, All
[Data]
Comment,Time Stamp (sec),Temperature (K),Magnetic Field (Oe),Moment (emu),M. Std. Err. (emu),Transport Action,Averaging Time (sec),Frequency (Hz),Peak Amplitude (mm),Center Position (mm),Lockin Signal' (V),Lockin Signal (V),Range,M. Quad. Signal (emu),AC Moment (emu),AC M. Std Err. (emu),AC Phase (deg),AC Phase Std. Err. (deg),AC Susceptibility (emu/Oe),AC Suscept. Std Err. (emu/Oe),AC X' (emu/Oe),AC X' Std Err. (emu/Oe),AC X'' (emu/Oe),AC X'' Std Err. (emu/Oe),AC Drive (Oe),AC Frequency (Hz),AC Averaging Time (sec),AC Cycles,AC Range,AC Measure Type,AC Signal' (V),AC Signal'' (V),AC Trim Coil Ratio,AC Trim Coil Phase,Min. Temperature (K),Max. Temperature (K),Min. Field (Oe),Max. Field (Oe),Mass (grams),Motor Lag (deg),Pressure (Torr),Measure Count,Measurement Number,SQUID Status (code),Motor Status (code),Measure Status (code),Motor Current (amps),Motor Temp. (C),Temp. Status (code),Field Status (code),Chamber Status (code),Chamber Temp (K),Redirection State,Average Temp (K),Rotation Angle (deg),Rotator state,DC Moment Fixed Ctr (emu),DC Moment Err Fixed Ctr (emu),DC Moment Free Ctr (emu),DC Moment Err Free Ctr (emu),DC Fixed Fit,DC Free Fit,DC Calculated Center (mm),DC Calculated Center Err (mm),DC Scan Length (mm),DC Scan Time (s),DC Number of Points,DC Squid Drift,DC Min V (V),DC Max V (V),DC Scans per Measure,Map 01,Map 02,Map 03,Map 04,Map 05,Map 06,Map 07,Map 08,Map 09,Map 10,Map 11,Map 12,Map 13,Map 14,Map 15,Map 16
,3772372555.71791,4.99964666366577,0.352141469717026,,,5,,,,6.47999998182058,,,,,0.000593745396129365,7.57185333566334E-9,0.0311331208620977,9.30477977969514E-6,0.000593650147730966,7.57063866198698E-9,0.000593650060091318,5.17770304860575E-9,3.225749094729E-7,5.52322015592632E-9,1.00016044533765,10.005763053894,2,20,1,3,1.94216473623444,0.171800826720027,0.0403775237500668,172.74836730957,4.99951219558716,5.00061845779419,0.352141469717026,0.352141469717026,,,11.2602376937866,0,1,,,,,,1,1,1,4.99973297119141,0,5.00002451737722,,,,,,,,,,,,,,,,,,,,,,,,,,,,,,,,,
,3772372579.86713,5.00015997886658,20.047779083252,,,5,,,,6.47999998182058,,,,,0.000593645817945198,1.25595110749043E-8,0.0327698044291882,1.15753669158385E-5,0.000593550639504632,1.25574974252799E-8,0.000593550542424534,1.05128425617695E-8,3.39475917427972E-7,6.86810620603362E-9,1.00016035437287,10.005763053894,2,20,1,3,1.94183154753501,0.171868415765268,0.0403775237500668,172.74836730957,4.99903011322022,5.00129508972168,20.047779083252,20.047779083252,,,11.2804012298584,0,1,,,,,,1,1,1,5.00016212463379,0,5.00012671947479,,,,,,,,,,,,,,,,,,,,,,,,,,,,,,,,,
,3772372604.38478,4.99998235702515,40.0348434448242,,,5,,,,6.47999998182058,,,,,0.000593433771235049,1.94295671848553E-8,0.0311760240259229,1.8624288887336E-5,0.000593338563694302,1.94264500024516E-8,0.000593338475859068,1.59796520264509E-8,3.22849895082273E-7,1.1047066615681E-8,1.00016046073283,10.005763053894,2,20,1,3,1.94114012165705,0.171794553840802,0.0403775237500668,172.74836730957,4.9995174407959,5.00160932540894,40.0348434448242,40.0348434448242,,,11.2946176528931,0,1,,,,,,1,1,1,4.99985885620117,0,5.00017726421356,,,,,,,,,,,,,,,,,,,,,,,,,,,,,,,,,
,3772372628.54621,5.00000691413879,59.9976196289063,,,5,,,,6.47999998182058,,,,,0.000593115121846935,1.91210720582551E-8,0.0281128769698888,2.08594033667224E-5,0.000593019964760941,1.91180043477363E-8,0.000593019893376324,1.45786738968848E-8,2.90972507621844E-7,1.23677143259517E-8,1.00016046185904,10.005763053894,2,20,1,3,1.94010439874413,0.171640036450831,0.0403775237500668,172.74836730957,4.9990177154541,5.00084924697876,59.9976196289063,59.9976196289063,,,11.3024826049805,0,1,,,,,,1,1,1,5.00018882751465,0,5.00001060962677,,,,,,,,,,,,,,,,,,,,,,,,,,,,,,,,,
,3772372653.06035,5.00013995170593,80.0332565307617,,,5,,,,6.47999998182058,,,,,0.000592910721414499,8.85561024392961E-8,0.0225239208651313,5.25278681141432E-5,0.000592815661375369,8.85419044390593E-8,0.000592815615568312,8.28982435237194E-8,2.33045659104129E-7,3.11054667603239E-8,1.00016035345441,10.005763053894,2,20,1,3,1.93944993092912,0.171433290009282,0.0403775237500668,172.74836730957,4.99960660934448,5.00111675262451,80.0332565307617,80.0332565307617,,,11.3134202957153,0,1,,,,,,1,1,1,5.00004625320435,0,5.00016327699025,,,,,,,,,,,,,,,,,,,,,,,,,,,,,,,,,
,3772372677.39132,5.00004863739014,100.105316162109,,,5,,,,6.47999998182058,,,,,0.000593139710537159,5.97582170914055E-8,0.0264569337084533,8.6497737703096E-5,0.000593044548371664,5.97486296008977E-8,0.00059304448514634,3.06366461411833E-8,2.73844598645585E-7,5.12961465648755E-8,1.0001604637725,10.005763053894,2,20,1,3,1.94018458976633,0.171674362372226,0.0403775237500668,172.74836730957,4.99903202056885,5.00146484375,100.105316162109,100.105316162109,,,11.3281326293945,0,1,,,,,,1,1,1,5.00003862380981,0,5.00005467732747,,,,,,,,,,,,,,,,,,,,,,,,,,,,,,,,,
,3772372701.7983,5.00005483627319,119.97095489502,,,5,,,,6.47999998182058,,,,,0.000593751023424897,3.90355067627031E-8,0.0230421996407344,4.93509843080568E-5,0.000593655763012827,3.90292439718819E-8,0.000593655715005526,2.57892971577612E-8,2.38745931318719E-7,2.92949490036315E-8,1.00016046405679,10.005763053894,2,20,1,3,1.9421918812342,0.171776839386996,0.0403775237500668,172.74836730957,4.99932098388672,5.00066471099854,119.97095489502,119.97095489502,,,11.3450498580933,0,1,,,,,,1,1,1,5.00010824203491,0,5.00010887781779,,,,,,,,,,,,,,,,,,,,,,,,,,,,,,,,,
,3772372725.15312,4.99991726875305,140.043014526367,,,5,,,,6.47999998182058,,,,,0.000594750469024014,6.71870339735143E-8,0.0165187811596121,7.02412604928654E-5,0.000594655052013634,6.71762550229258E-8,0.000594655027299474,5.26184861481101E-8,1.71443282857257E-7,4.17605574003307E-8,1.00016045774783,10.005763053894,2,20,1,3,1.94547809583673,0.171886279084526,0.0403775237500668,172.74836730957,4.99888610839844,5.00066757202148,140.043014526367,140.043014526367,,,11.3653774261475,0,1,,,,,,1,1,1,4.99988174438477,0,4.99991948787983,,,,,,,,,,,,,,,,,,,,,,,,,,,,,,,,,
,3772372750.56223,4.99983787536621,160.127227783203,,,5,,,,6.47999998182058,,,,,0.000595874481334116,3.7754069249195E-8,0.0192834243011664,4.6021779773385E-5,0.000595778886165098,3.77480124255785E-8,0.000595778852422528,2.59476785952653E-8,2.00514888397389E-7,2.74158789317147E-8,1.00016045410678,10.005763053894,2,20,1,3,1.94914390778944,0.172347073764279,0.0403775237500668,172.74836730957,4.9993166923523,5.00076627731323,160.127227783203,160.127227783203,,,11.381664276123,0,1,,,,,,1,1,1,4.99978351593018,0,4.99996248881022,,,,,,,,,,,,,,,,,,,,,,,,,,,,,,,,,
,3772372774.73189,4.99978184700012,180.175003051758,,,5,,,,6.47999998182058,,,,,0.000597374539325058,9.73074457600089E-8,0.0142923537060451,0.000129653975392945,0.000597278705038654,9.72918351354974E-8,0.000597278686455934,5.89028706737054E-8,1.489903531729E-7,7.74348307315871E-8,1.00016045153727,10.005763053894,2,20,1,3,1.95406312529166,0.172652648890626,0.0403775237500668,172.74836730957,4.99833965301514,5.00087642669678,180.175003051758,180.175003051758,,,11.3954601287842,0,1,,,,,,1,1,1,5.00013065338135,0,4.9998699426651,,,,,,,,,,,,,,,,,,,,,,,,,,,,,,,,,
,3772372799.3926,4.99979090690613,200.089218139648,,,5,,,,6.47999998182058,,,,,0.000599356424335875,1.32617736113875E-7,0.0196864715396865,0.000106973241360232,0.00059926027185504,1.32596460752817E-7,0.000599260236481707,1.16087471150549E-7,2.05902077864566E-7,6.40743353148815E-8,1.00016045195277,10.005763053894,2,20,1,3,1.96052711454386,0.173451813020172,0.0403775237500668,172.74836730957,4.99812364578247,5.00133228302002,200.089218139648,200.089218139648,,,11.4138050079346,0,1,,,,,,1,1,1,4.9998083114624,0,4.99999116017268,,,,,,,,,,,,,,,,,,,,,,,,,,,,,,,,,
,3772372824.90547,5.00001668930054,220.027694702148,,,5,,,,6.47999998182058,,,,,0.000602830597546731,1.54365863179758E-7,0.0102705660159348,0.000135860951514235,0.000602733950482885,1.54341114921301E-7,0.000602733940799234,1.30843687934014E-7,1.08043190055805E-7,8.18603022409299E-8,1.00016034780149,10.005763053894,2,20,1,3,1.97191734443301,0.174175246773486,0.0403775237500668,172.74836730957,4.99895143508911,5.0016188621521,220.027694702148,220.027694702148,,,11.436595916748,0,1,,,,,,1,1,1,5.00002956390381,0,5.00018640359243,,,,,,,,,,,,,,,,,,,,,,,,,,,,,,,,,
,3772372851.27796,4.99979019165039,240.051193237305,,,5,,,,6.47999998182058,,,,,0.000607744884638265,9.12355393125465E-8,0.00741172133631007,0.000131003990356689,0.000607647386448448,9.12209027435603E-8,0.000607647381364343,4.45510422098697E-8,7.86046219251459E-8,7.96018701750436E-8,1.00016045191997,10.005763053894,2,20,10,3,1.98799856062888,0.175538537192847,0.0403775237500668,172.74836730957,4.99899196624756,5.00082111358643,240.051193237305,240.051193237305,,,11.4572315216064,0,1,,,,,,1,1,1,4.9999418258667,0,4.999920129776,,,,,,,,,,,,,,,,,,,,,,,,,,,,,,,,,
,3772372879.9743,4.99983024597168,259.965393066406,,,5,,,,6.47999998182058,,,,,0.000614075119760923,2.41673091724311E-7,0.00953639156501929,0.000245261830333188,0.000613976604908023,2.41634320589779E-7,0.000613976596403603,1.88998543815701E-7,1.02191144598937E-7,1.50554625709171E-7,1.00016045375689,10.005763053894,2,20,10,3,2.00869619057378,0.177484236832323,0.0403775237500668,172.74836730957,4.99907541275024,5.00067520141602,259.965393066406,259.965393066406,,,11.4849185943604,0,1,,,,,,1,1,1,4.99969244003296,0,4.99987803972684,,,,,,,,,,,,,,,,,,,,,,,,,,,,,,,,,
,3772372904.48135,4.99943804740906,279.976776123047,,,5,,,,6.47999998182058,,,,,0.000622256311674429,3.75279800152146E-7,0.0166895752498801,0.000174883342470159,0.000622156495517803,3.75219601506334E-7,0.000622156469123211,3.59150877330657E-7,1.81226742886656E-7,1.08629630705399E-7,1.00016043577033,10.005763053894,2,20,10,3,2.03543242916245,0.180146534864719,0.0403775237500668,172.74836730957,4.9992413520813,5.00065803527832,279.976776123047,279.976776123047,,,11.4980850219727,0,1,,,,,,1,1,1,4.99930095672607,0,4.9997437397639,,,,,,,,,,,,,,,,,,,,,,,,,,,,,,,,,
,3772372928.73994,4.99956703186035,300.048828125,,,5,,,,6.47999998182058,,,,,0.000644603331271472,9.69529774043727E-7,0.105279299623309,0.00114889447927753,0.000644499926616832,9.69374246005653E-7,0.000644498838605387,6.25662295031254E-7,1.18424887969807E-6,7.40427661149455E-7,1.00016044168567,10.005763053894,2,20,10,3,2.10823671734202,0.189921357882568,0.0403775237500668,172.74836730957,4.99582529067993,5.00033473968506,300.048828125,300.048828125,,,11.5147848129272,0,1,,,,,,1,1,1,4.99908542633057,0,4.99845027923584,,,,,,,,,,,,,,,,,,,,,,,,,,,,,,,,,
,3772372953.25953,4.99901580810547,320.120880126953,,,5,,,,6.47999998182058,,,,,0.000696187365759324,1.77782177642418E-6,0.158008847155726,0.00101059719290885,0.000696075624104618,1.77753642688059E-6,0.000696072977167046,1.63297708286776E-6,1.91961726360037E-6,7.02154965599567E-7,1.00016053091192,10.005763053894,2,20,10,3,2.2767543101332,0.207264021982545,0.0403775237500668,172.74836730957,4.99746751785278,5.00053787231445,320.120880126953,320.120880126953,,,11.4961853027344,0,1,,,,,,1,1,1,4.99960422515869,0,4.99949749310811,,,,,,,,,,,,,,,,,,,,,,,,,,,,,,,,,
,3772372976.60676,4.99942135810852,340.010803222656,,,5,,,,6.47999998182058,,,,,0.000755077031556756,2.16466472827811E-6,0.164316715535554,0.00159837963081307,0.000754955910201567,2.16431749598993E-6,0.00075495280557391,1.7972065340877E-6,2.16511070353268E-6,1.20595144897321E-6,1.00016043500495,10.005763053894,2,20,10,3,2.46931407755593,0.225120666410983,0.0403775237500668,172.74836730957,4.9983868598938,5.00050592422485,340.010803222656,340.010803222656,,,11.4802865982056,0,1,,,,,,1,1,1,4.99941873550415,0,4.99927152906145,,,,,,,,,,,,,,,,,,,,,,,,,,,,,,,,,
,3772373001.98398,4.99957227706909,360.107147216797,,,5,,,,6.47999998182058,,,,,0.000806600421232328,2.46938276654942E-6,0.0878062791238481,0.00177496105495282,0.00080647102946692,2.46898663757748E-6,0.000806470082435096,2.01207517479324E-6,1.23592336472273E-6,1.43089080908255E-6,1.00016044192622,10.005763053894,2,20,10,3,2.63812519815076,0.237016093365308,0.0403775237500668,172.74836730957,4.99883460998535,5.00043249130249,360.107147216797,360.107147216797,,,11.4676456451416,0,1,,,,,,1,1,1,4.99957942962646,0,4.99972790938157,,,,,,,,,,,,,,,,,,,,,,,,,,,,,,,,,
,3772373025.96652,4.99942803382874,380.179229736328,,,5,,,,6.47999998182058,,,,,0.000841749567960795,1.20408011320791E-6,0.0852787778019302,0.000861978883945126,0.000841614543269717,1.20388696722779E-6,0.000841613611046691,9.60941608281178E-7,1.25265479832364E-6,7.25213799741086E-7,1.0001604353111,10.005763053894,2,20,10,3,2.7530936552899,0.247282218484233,0.0403775237500668,172.74836730957,4.99846363067627,5.00104951858521,380.179229736328,380.179229736328,,,11.4649219512939,0,1,,,,,,1,1,1,4.99939584732056,0,4.99961798007672,,,,,,,,,,,,,,,,,,,,,,,,,,,,,,,,,
,3772373050.70972,4.99960422515869,400.154113769531,,,5,,,,6.47999998182058,,,,,0.000857034314756543,1.00728976115589E-6,0.00796806019250962,0.000372950568150279,0.000856896831322858,1.00712817409608E-6,0.000856896823036599,9.55207787284894E-7,1.19167686813369E-7,3.19194677537715E-7,1.00016044339139,10.005763053894,2,20,10,3,2.80341860333153,0.248049871837465,0.0403775237500668,172.74836730957,4.99907970428467,5.000403881073,400.154113769531,400.154113769531,,,11.4684114456177,0,1,,,,,,1,1,1,4.99968814849854,0,4.99965651830037,,,,,,,,,,,,,,,,,,,,,,,,,,,,,,,,,
,3772373074.71631,4.99990820884705,420.019775390625,,,5,,,,6.47999998182058,,,,,0.00086014483975594,3.27061499598118E-7,-0.0340225777453274,0.000209381523243963,0.000860006943811769,3.27009066040182E-7,0.000860006792190155,2.72989515200177E-7,-5.10677254703499E-7,1.80032368931936E-7,1.00016034282649,10.005763053894,2,20,10,3,2.81377134702317,0.246947890556488,0.0403775237500668,172.74836730957,4.99852514266968,5.00154685974121,420.019775390625,420.019775390625,,,11.4698781967163,0,1,,,,,,1,1,1,4.99993658065796,0,5.00006129191472,,,,,,,,,,,,,,,,,,,,,,,,,,,,,,,,,
,3772373099.37977,5.00004911422729,440.128265380859,,,5,,,,6.47999998182058,,,,,0.000856198478864979,3.17192913657596E-7,-0.0553823133610578,0.000292870861145997,0.000856061112050725,3.17142023845095E-7,0.000856060712132073,1.9425234554642E-7,-8.27471722767585E-7,2.50689229003316E-7,1.00016046379437,10.005763053894,2,20,10,3,2.80094945559313,0.244830995832168,0.0403775237500668,172.74836730957,4.99942302703857,5.00104236602783,440.128265380859,440.128265380859,,,11.4769096374512,0,1,,,,,,1,1,1,5.00006580352783,0,5.00014901161194,,,,,,,,,,,,,,,,,,,,,,,,,,,,,,,,,
,3772373123.39043,4.99991416931152,460.382446289063,,,5,,,,6.47999998182058,,,,,0.000849211713022618,4.40358995776197E-7,-0.0781056368783659,0.000337155724228813,0.00084907547240527,4.4028834816204E-7,0.00084907468348026,3.34546782783439E-7,-1.15745977371753E-6,2.86238151993244E-7,1.00016045760569,10.005763053894,2,20,10,3,2.77818551365482,0.241791541952445,0.0403775237500668,172.74836730957,4.99878740310669,5.00155305862427,460.382446289063,460.382446289063,,,11.4897041320801,0,1,,,,,,1,1,1,4.99987363815308,0,5.00009580758902,,,,,,,,,,,,,,,,,,,,,,,,,,,,,,,,,
,3772373148.16366,5.00007557868958,480.454528808594,,,5,,,,6.47999998182058,,,,,0.000841154794904238,3.16298892510772E-7,-0.0888848766827932,0.000243089947682743,0.000841019840648734,3.16248145749517E-7,0.00084101882863445,2.41297724390066E-7,-1.30470194270626E-6,2.04421862564119E-7,1.00016046500805,10.005763053894,2,20,10,3,2.75186881946562,0.239038938249741,0.0403775237500668,172.74836730957,4.9991250038147,5.00096702575684,480.454528808594,480.454528808594,,,11.50119972229,0,1,,,,,,1,1,1,5.00011825561523,0,4.99988659222921,,,,,,,,,,,,,,,,,,,,,,,,,,,,,,,,,
,3772373172.3515,5.00005602836609,500.320159912109,,,5,,,,6.47999998182058,,,,,0.000832700272576445,2.6904949751723E-7,-0.10741256833222,0.00023005766287216,0.000832566675504628,2.69006331655244E-7,0.000832565212472584,1.88906960426362E-7,-1.5608143095543E-6,1.91516492169954E-7,1.00016046411146,10.005763053894,2,20,10,3,2.72428241173035,0.235813318647161,0.0403775237500668,172.74836730957,4.99802684783936,5.00097227096558,500.320159912109,500.320159912109,,,11.5088195800781,0,1,,,,,,1,1,1,4.99998426437378,0,4.99981375535329,,,,,,,,,,,,,,,,,,,,,,,,,,,,,,,,,
,3772373196.86803,4.9998664855957,520.343688964844,,,5,,,,6.47999998182058,,,,,0.000823550530356154,7.51826302475878E-7,-0.085694636965485,0.000553560586907166,0.000823418408410528,7.51705687224967E-7,0.000823417487425612,5.977789227062E-7,-1.23154821997843E-6,4.55765070814531E-7,1.00016045541887,10.005763053894,2,20,10,3,2.69425577891721,0.234301204785823,0.0403775237500668,172.74836730957,4.99932909011841,5.00101804733276,520.343688964844,520.343688964844,,,11.5250606536865,0,1,,,,,,1,1,1,4.99983072280884,0,4.99992402394613,,,,,,,,,,,,,,,,,,,,,,,,,,,,,,,,,
,3772373221.08837,5.00007486343384,540.391479492188,,,5,,,,6.47999998182058,,,,,0.000815264558576628,6.34614150734199E-7,-0.0719718136591245,0.000426294796037554,0.000815133851480913,6.34512406371992E-7,0.00081513320838092,5.30931742133493E-7,-1.02392613795009E-6,3.47444209960492E-7,1.00016035046941,10.005763053894,2,20,10,3,2.66708898883952,0.232639856845526,0.0403775237500668,172.74836730957,4.99896955490112,5.0013632774353,540.391479492188,540.391479492188,,,11.5258617401123,0,1,,,,,,1,1,1,5.00015592575073,0,5.00003719329834,,,,,,,,,,,,,,,,,,,,,,,,,,,,,,,,,
,3772373245.62956,4.99998712539673,560.342102050781,,,5,,,,6.47999998182058,,,,,0.000806076097250361,3.87385824473597E-7,-0.13811749701414,0.000245063409966874,0.000805946866534915,3.87323718492014E-7,0.000805944524850642,3.33173038419271E-7,-1.94281772704679E-6,1.97523136308009E-7,1.00016034644567,10.005763053894,2,20,10,3,2.63728989747176,0.227029695526332,0.0403775237500668,172.74836730957,4.99945831298828,5.00075435638428,560.342102050781,560.342102050781,,,11.5352687835693,0,1,,,,,,1,1,1,4.99988698959351,0,5.0000870625178,,,,,,,,,,,,,,,,,,,,,,,,,,,,,,,,,
,3772373269.61382,5.00002264976501,580.389892578125,,,5,,,,6.47999998182058,,,,,0.000797608453493179,3.26571671352126E-7,-0.129125248511442,0.000312792253341174,0.000797480487716071,3.26519277226257E-7,0.000797478462520531,2.10733438343822E-7,-1.79724893991323E-6,2.49411820818798E-7,1.00016046258069,10.005763053894,2,20,10,3,2.60954711328792,0.225110346219885,0.0403775237500668,172.74836730957,4.99872970581055,5.00138521194458,580.389892578125,580.389892578125,,,11.5448312759399,0,1,,,,,,1,1,1,5.00004959106445,0,4.99999548838689,,,,,,,,,,,,,,,,,,,,,,,,,,,,,,,,,
,3772373294.34263,5.00006484985352,600.437622070312,,,5,,,,6.47999998182058,,,,,0.000788750846508965,3.48980745071649E-7,-0.144900876441193,0.000306006826760298,0.000788624300292296,3.48924755029705E-7,0.000788621778341043,2.52036936036533E-7,-1.99442666554657E-6,2.41300367894159E-7,1.00016046451602,10.005763053894,2,20,10,3,2.58062542656798,0.221955283654131,0.0403775237500668,172.74836730957,4.99947690963745,5.00092267990112,600.437622070312,600.437622070312,,,11.5521402359009,0,1,,,,,,1,1,1,5.00005722045898,0,5.00018906593323,,,,,,,,,,,,,,,,,,,,,,,,,,,,,,,,,
,3772373318.5915,5.00012993812561,620.412536621094,,,5,,,,6.47999998182058,,,,,0.000780186700273268,2.74878420015645E-7,-0.138486189623669,0.000261186516581435,0.00078006161505687,2.74834349504524E-7,0.000780059336465921,1.84483006399746E-7,-1.88543827267007E-6,2.037153406528E-7,1.00016035299518,10.005763053894,2,20,10,3,2.55257748124564,0.219885672891337,0.0403775237500668,172.74836730957,4.99863243103027,5.00184154510498,620.412536621094,620.412536621094,,,11.5681591033936,0,1,,,,,,1,1,1,5.00018358230591,0,5.00016864140828,,,,,,,,,,,,,,,,,,,,,,,,,,,,,,,,,
,3772373343.27342,4.99986815452576,640.375366210937,,,5,,,,6.47999998182058,,,,,0.000771232264122294,4.255863087797E-7,-0.137940805579867,0.000391790888681213,0.000771108535520213,4.25518032073059E-7,0.000771106300787656,2.99689244020093E-7,-1.85645837668131E-6,3.02079381351978E-7,1.00016045549541,10.005763053894,2,20,10,3,2.52327547451556,0.21743990664671,0.0403775237500668,172.74836730957,4.99880933761597,5.0015606880188,640.375366210937,640.375366210937,,,11.5751552581787,0,1,,,,,,1,1,1,4.99983692169189,0,5.00002131095299,,,,,,,,,,,,,,,,,,,,,,,,,,,,,,,,,
,3772373368.70453,4.99992537498474,660.410949707031,,,5,,,,6.47999998182058,,,,,0.000761627727217096,6.06112730419316E-7,-0.164420987010039,0.000562559284272167,0.000761505537470499,6.060154903133E-7,0.000761502401932927,4.2868959192405E-7,-2.18527998570086E-6,4.28345664476321E-7,1.00016045811959,10.005763053894,2,20,10,3,2.49194766268976,0.213633778822643,0.0403775237500668,172.74836730957,4.99911975860596,5.00105953216553,660.410949707031,660.410949707031,,,11.5879726409912,0,1,,,,,,1,1,1,5.00004863739014,0,5.00002876917521,,,,,,,,,,,,,,,,,,,,,,,,,,,,,,,,,
,3772373392.83832,5.00008153915405,680.385864257812,,,5,,,,6.47999998182058,,,,,0.000751909786497836,5.49561098475735E-7,-0.176675439198941,0.000573377178746751,0.000751789236510702,5.49472990055629E-7,0.000751785662360018,3.40839270178612E-7,-2.31818965002399E-6,4.30986262779667E-7,1.00016035077556,10.005763053894,2,20,10,3,2.46019373768084,0.210434340115127,0.0403775237500668,172.74836730957,4.99860143661499,5.00096893310547,680.385864257812,680.385864257812,,,11.5952444076538,0,1,,,,,,1,1,1,5.00009155273438,0,5.00009030562181,,,,,,,,,,,,,,,,,,,,,,,,,,,,,,,,,
,3772373417.50611,4.99998807907105,700.482238769531,,,5,,,,6.47999998182058,,,,,0.000738920279393206,4.53946000869692E-7,-0.28346403663966,0.000463830785009983,0.000738801730532233,4.53873171928807E-7,0.000738792688882216,2.97681209938982E-7,-3.65511854912422E-6,3.42617503122623E-7,1.00016046099525,10.005763053894,2,20,10,3,2.41807125870115,0.202344532332575,0.0403775237500668,172.74836730957,4.99957704544067,5.00110244750977,700.482238769531,700.482238769531,,,11.6053609848022,0,1,,,,,,1,1,1,4.99994373321533,0,5.00013017654419,,,,,,,,,,,,,,,,,,,,,,,,,,,,,,,,,
,3772373441.74578,4.99998235702515,720.347839355469,,,5,,,,6.47999998182058,,,,,0.000728684393724238,7.07715901625686E-7,-0.243984998762705,0.000768909117881016,0.000728567487251317,7.07602359232571E-7,0.000728560881531946,4.32442643772394E-7,-3.10247982929533E-6,5.6008433172036E-7,1.00016046073283,10.005763053894,2,20,10,3,2.38443393421055,0.201235266274318,0.0403775237500668,172.74836730957,4.99936819076538,5.0007848739624,720.347839355469,720.347839355469,,,11.6212768554687,0,1,,,,,,1,1,1,4.99998950958252,0,4.99995470046997,,,,,,,,,,,,,,,,,,,,,,,,,,,,,,,,,
,3772373466.35159,4.99998879432678,740.383544921875,,,5,,,,6.47999998182058,,,,,0.000715116827583226,7.41877622672854E-7,-0.265081670879116,0.00050638259461909,0.000715002097611584,7.41758599325441E-7,0.000714994445334634,6.47277006722774E-7,-3.30797968310633E-6,3.62268265572967E-7,1.00016046102805,10.005763053894,2,20,10,3,2.34010717902193,0.196676958403703,0.0403775237500668,172.74836730957,4.99940872192383,5.00067520141602,740.383544921875,740.383544921875,,,11.6271486282349,0,1,,,,,,1,1,1,5.00005674362183,0,4.99994007746379,,,,,,,,,,,,,,,,,,,,,,,,,,,,,,,,,
,3772373490.58874,5.00017476081848,760.406982421875,,,5,,,,6.47999998182058,,,,,0.000700641689626406,8.87624988137164E-7,-0.269497252224922,0.000806958876505351,0.000700529276004079,8.87482574201964E-7,0.000700521526767647,6.84131024849542E-7,-3.29500742388804E-6,5.65322969947675E-7,1.00016046955663,10.005763053894,2,20,10,3,2.29275156579121,0.192568328947413,0.0403775237500668,172.74836730957,4.99847173690796,5.00135135650635,760.406982421875,760.406982421875,,,11.6340551376343,0,1,,,,,,1,1,1,5.00028085708618,0,4.99996049587543,,,,,,,,,,,,,,,,,,,,,,,,,,,,,,,,,
,3772373515.09209,4.99991869926453,780.333312988281,,,5,,,,6.47999998182058,,,,,0.000684200078240569,1.04914560020828E-6,-0.324031945377055,0.000755781175961316,0.000684090310605139,1.04897728360702E-6,0.000684079370722135,9.12495116234382E-7,-3.86880036221947E-6,5.17403135255244E-7,1.00016045781343,10.005763053894,2,20,10,3,2.2391239506839,0.185966031744498,0.0403775237500668,172.74836730957,4.99934768676758,5.00151395797729,780.333312988281,780.333312988281,,,11.6428651809692,0,1,,,,,,1,1,1,4.99990558624268,0,5.00007875760396,,,,,,,,,,,,,,,,,,,,,,,,,,,,,,,,,
,3772373539.10532,5.0002064704895,800.417541503906,,,5,,,,6.47999998182058,,,,,0.000666201611339387,7.94607745925797E-7,-0.303329097013828,0.000802710164620847,0.000666094798705456,7.94480345834234E-7,0.000666085464273116,5.87645976754595E-7,-3.52635031291047E-6,5.34669267791803E-7,1.00016035650502,10.005763053894,2,20,10,3,2.18015362372146,0.181908667741962,0.0403775237500668,172.74836730957,4.99880218505859,5.00203561782837,800.417541503906,800.417541503906,,,11.6557884216309,0,1,,,,,,1,1,1,5.00012540817261,0,5.00024744180533,,,,,,,,,,,,,,,,,,,,,,,,,,,,,,,,,
,3772373563.82529,5.00015616416931,820.416809082031,,,5,,,,6.47999998182058,,,,,0.000642884070541004,9.40449473232169E-7,-0.346858696852644,0.000632627799276653,0.000642780924319269,9.40298584737117E-7,0.000642769145776338,8.47562161856015E-7,-3.89126029585708E-6,4.07185228426308E-7,1.00016046870377,10.005763053894,2,20,10,3,2.10397686762442,0.173988343984979,0.0403775237500668,172.74836730957,4.99962997436523,5.00182056427002,820.416809082031,820.416809082031,,,11.6649990081787,0,1,,,,,,1,1,1,5.00021648406982,0,5.000168800354,,,,,,,,,,,,,,,,,,,,,,,,,,,,,,,,,
,3772373588.36812,5.00004744529724,840.48876953125,,,5,,,,6.47999998182058,,,,,0.000617522447078086,7.39509980567232E-7,-0.383985385534944,0.000580114802059689,0.000617423443715423,7.39391419735726E-7,0.000617409578212694,6.4664622322975E-7,-4.13782317595987E-6,3.58536376901303E-7,1.00016034921199,10.005763053894,2,20,10,3,2.02108091775899,0.165858363476634,0.0403775237500668,172.74836730957,4.9992241859436,5.00145292282105,840.48876953125,840.48876953125,,,11.674596786499,0,1,,,,,,1,1,1,5.00003004074097,0,5.00014992554982,,,,,,,,,,,,,,,,,,,,,,,,,,,,,,,,,
,3772373612.74549,5.00012803077698,860.415161132813,,,5,,,,6.47999998182058,,,,,0.000585184829765029,8.69056492993877E-7,-0.387537643972407,0.00067689235049197,0.000585090941734916,8.68917060120648E-7,0.000585077558094874,7.73150792654093E-7,-3.95741253728868E-6,3.96553538865886E-7,1.00016046741355,10.005763053894,2,20,10,3,1.91525101820015,0.157095003189156,0.0403775237500668,172.74836730957,4.99947643280029,5.00067806243897,860.415161132813,860.415161132813,,,11.6842002868652,0,1,,,,,,1,1,1,5.00017881393433,0,5.00003536542257,,,,,,,,,,,,,,,,,,,,,,,,,,,,,,,,,
,3772373637.07602,5.00006699562073,880.414367675781,,,5,,,,6.47999998182058,,,,,0.000544920365317997,8.05820534365086E-7,-0.394865779542319,0.000958539247461242,0.000544833001287081,8.05691341670965E-7,0.00054482006274264,6.13469789456709E-7,-3.75480020697931E-6,5.22296233441809E-7,1.00016035010858,10.005763053894,2,20,10,3,1.78348604254107,0.146095922079873,0.0403775237500668,172.74836730957,4.99912023544312,5.00118017196655,880.414367675781,880.414367675781,,,11.6908140182495,0,1,,,,,,1,1,1,5.00009441375732,0,5.00010820229848,,,,,,,,,,,,,,,,,,,,,,,,,,,,,,,,,
,3772373664.57031,5.00009417533874,900.292175292969,,,5,,,,6.47999998182058,,,,,0.000490381006300752,8.1051610477662E-7,-0.43040840041545,0.00113623000499081,0.000490302329515338,8.10386065478951E-7,0.000490288495503854,5.88543732169287E-7,-3.68313789249515E-6,5.57083342460265E-7,1.00016046586091,10.005763053894,2,20,1,3,1.60506191614126,0.13051212974121,0.0403775237500668,172.74836730957,4.99892663955688,5.00208425521851,900.292175292969,900.292175292969,,,11.7022743225098,0,1,,,,,,1,1,1,5.00027322769165,0,5.00013389587402,,,,,,,,,,,,,,,,,,,,,,,,,,,,,,,,,
,3772373689.60339,4.99993324279785,920.303527832031,,,5,,,,6.47999998182058,,,,,0.000401807978080955,1.22935531144813E-6,-0.560385739983524,0.00151027834667733,0.000401743514927035,1.22915808261001E-6,0.000401724299753847,1.06845245911659E-6,-3.92922043289602E-6,6.0765033913693E-7,1.00016045848041,10.005763053894,2,20,1,3,1.31539200411469,0.103983342650393,0.0403775237500668,172.74836730957,4.99932289123535,5.00113201141357,920.303527832031,920.303527832031,,,11.7112340927124,0,1,,,,,,1,1,1,4.99993848800659,0,5.00010466575623,,,,,,,,,,,,,,,,,,,,,,,,,,,,,,,,,
,3772373713.91772,5.00001358985901,940.254089355469,,,5,,,,6.47999998182058,,,,,0.000304233551561727,9.748216171379E-7,-0.871526582608997,0.00139879025857973,0.000304184776244846,9.74665331833291E-7,0.000304149586581106,8.76105685897422E-7,-4.62677875730536E-6,4.27096401548769E-7,1.00016034765935,10.005763053894,2,20,1,3,0.996376098596188,0.0733438052518666,0.0403775237500668,172.74836730957,4.99897146224976,5.00102281570435,940.254089355469,940.254089355469,,,11.7243099212646,0,1,,,,,,1,1,1,5.0000057220459,0,5.00010475745568,,,,,,,,,,,,,,,,,,,,,,,,,,,,,,,,,
,3772373738.44236,5.00002956390381,960.265441894531,,,5,,,,6.47999998182058,,,,,0.000225033715293726,7.20356104468982E-7,-1.16213930205995,0.00212710640304254,0.000224997637284399,7.20240615044554E-7,0.000224951356129778,5.3807583561932E-7,-4.56334953031496E-6,4.7877023579409E-7,1.00016034839193,10.005763053894,2,20,1,3,0.737258728315346,0.0505274805938536,0.0403775237500668,172.74836730957,4.99923992156982,5.00068807601929,960.265441894531,960.265441894531,,,11.7329149246216,0,1,,,,,,1,1,1,4.99999284744263,0,5.00007208188375,,,,,,,,,,,,,,,,,,,,,,,,,,,,,,,,,
,3772373762.6611,5.00014209747314,980.325439453125,,,5,,,,6.47999998182058,,,,,0.000159567061937112,1.03565762127214E-6,-1.64012510990669,0.00244975508140615,0.00015954147889415,1.03549157651893E-6,0.000159476117297577,9.57214175668568E-7,-4.56634420757325E-6,3.94947878764795E-7,1.00016035355282,10.005763053894,2,20,1,3,0.52305624111332,0.0314768666800268,0.0403775237500668,172.74836730957,4.99919080734253,5.00129795074463,980.325439453125,980.325439453125,,,11.7409410476685,0,1,,,,,,1,1,1,4.99999332427978,0,5.00013224283854,,,,,,,,,,,,,,,,,,,,,,,,,,,,,,,,,
,3772373787.08816,4.99997711181641,1000.16674804688,,,5,,,,6.47999998182058,,,,,0.000114277902142248,8.88169229584191E-7,-2.28646040311543,0.00450897438316363,0.00011425956799572,8.88026736376913E-7,0.000114168600329929,7.22330821158515E-7,-4.55846216102448E-6,5.16555582028398E-7,1.00016046049228,10.005763053894,2,20,1,3,0.374829954800107,0.0183238056186762,0.0403775237500668,172.74836730957,4.99954843521118,5.00080633163452,1000.16674804688,1000.16674804688,,,11.7526779174805,0,1,,,,,,1,1,1,4.99997711181641,0,5.00011781851451,,,,,,,,,,,,,,,,,,,,,,,,,,,,,,,,,