File: Experimental_Data/AC_Suceptibillity_FieldScans/ZFCd_Up_30K.dat
[Header]
; MPMS3 Data File (default extension .dat)
; Copyright (c) 2007, Quantum Design, Inc. All rights reserved.
TITLE,ZFCd_Up_30K
FILEOPENTIME,3772425867.02932,07/16/2019,8:04 am
BYAPP,SQUID AC,0.9.1.0
INFO,MPMS3 Measurement Release 1.1.16 Build 347, MultiVu Release 2.3.3.2,APPNAME
INFO,0,MOMENT_UNITS
INFO,Cu2OSeO3,SAMPLE_MATERIAL
INFO,,SAMPLE_COMMENT
INFO,,SAMPLE_MASS
INFO,,SAMPLE_VOLUME
INFO,,SAMPLE_MOLECULAR_WEIGHT
INFO,,SAMPLE_SIZE
INFO,,SAMPLE_SHAPE
INFO,Quartz,SAMPLE_HOLDER
INFO,Standard,SAMPLE_HOLDER_DETAIL
INFO,64.77,SAMPLE_OFFSET
DATATYPE,COMMENT,1
DATATYPE,TIME,2
STARTUPAXIS,X,2
STARTUPAXIS,Y1,5
FIELDGROUP, VSM,2,3,4,5,6,8,9,10,11,14,15
FIELDGROUP, DC, 2,3,4,14,56,57,58,59,60,61,62,63,64,65,66,67,68,69
FIELDGROUP, AC, 2,3,4,11,16,17,18,19,20,21,22,23,24,25,26,27,28,29,30
STARTUPGROUP, All
[Data]
Comment,Time Stamp (sec),Temperature (K),Magnetic Field (Oe),Moment (emu),M. Std. Err. (emu),Transport Action,Averaging Time (sec),Frequency (Hz),Peak Amplitude (mm),Center Position (mm),Lockin Signal' (V),Lockin Signal (V),Range,M. Quad. Signal (emu),AC Moment (emu),AC M. Std Err. (emu),AC Phase (deg),AC Phase Std. Err. (deg),AC Susceptibility (emu/Oe),AC Suscept. Std Err. (emu/Oe),AC X' (emu/Oe),AC X' Std Err. (emu/Oe),AC X'' (emu/Oe),AC X'' Std Err. (emu/Oe),AC Drive (Oe),AC Frequency (Hz),AC Averaging Time (sec),AC Cycles,AC Range,AC Measure Type,AC Signal' (V),AC Signal'' (V),AC Trim Coil Ratio,AC Trim Coil Phase,Min. Temperature (K),Max. Temperature (K),Min. Field (Oe),Max. Field (Oe),Mass (grams),Motor Lag (deg),Pressure (Torr),Measure Count,Measurement Number,SQUID Status (code),Motor Status (code),Measure Status (code),Motor Current (amps),Motor Temp. (C),Temp. Status (code),Field Status (code),Chamber Status (code),Chamber Temp (K),Redirection State,Average Temp (K),Rotation Angle (deg),Rotator state,DC Moment Fixed Ctr (emu),DC Moment Err Fixed Ctr (emu),DC Moment Free Ctr (emu),DC Moment Err Free Ctr (emu),DC Fixed Fit,DC Free Fit,DC Calculated Center (mm),DC Calculated Center Err (mm),DC Scan Length (mm),DC Scan Time (s),DC Number of Points,DC Squid Drift,DC Min V (V),DC Max V (V),DC Scans per Measure,Map 01,Map 02,Map 03,Map 04,Map 05,Map 06,Map 07,Map 08,Map 09,Map 10,Map 11,Map 12,Map 13,Map 14,Map 15,Map 16
,3772426027.98867,29.9061155319214,0.206427752971649,,,5,,,,6.46999990567565,,,,,0.00059905793784128,1.00629358462821E-8,0.0288223728997368,1.26283469601427E-5,0.000598964175935985,1.00613608399627E-8,0.000598964100150673,6.63532647809075E-9,3.01306104062421E-7,7.56329455205088E-9,1.00015654008881,10.005763053894,2,20,1,3,1.95955994708581,0.173140076345835,0.0403775237500668,172.74836730957,29.9035587310791,29.9118843078613,0.206427752971649,0.206427752971649,,,30.1900253295898,0,1,,,,,,1,1,1,29.9073619842529,0,29.9079986919056,,,,,,,,,,,,,,,,,,,,,,,,,,,,,,,,,
,3772426051.1038,29.9254350662231,20.108491897583,,,5,,,,6.46999990567565,,,,,0.00059906958485132,1.27513281077757E-8,0.0286620859692981,1.47602946415075E-5,0.000598975840345881,1.27493327353224E-8,0.000598975765399679,9.18707723320132E-9,2.99636316311363E-7,8.83985843252925E-9,1.00015650799102,10.005763053894,2,20,1,3,1.95959594618361,0.173179496336635,0.0403775237500668,172.74836730957,29.9234924316406,29.9344062805176,20.108491897583,20.108491897583,,,30.0656509399414,0,1,,,,,,1,1,1,29.9264297485352,0,29.9286355105313,,,,,,,,,,,,,,,,,,,,,,,,,,,,,,,,,
,3772426074.10499,29.9394912719727,39.986270904541,,,5,,,,6.46999990567565,,,,,0.000599279428673984,2.75693680210013E-8,0.0280518440525332,3.72923347514226E-5,0.000599185471615563,2.75650456021131E-8,0.000599185399801609,1.61423119000273E-8,2.93359421577656E-7,2.23440709265079E-8,1.00015680797161,10.005763053894,2,20,1,3,1.96028161991381,0.173260807969177,0.0403775237500668,172.74836730957,29.930793762207,29.9536609649658,39.986270904541,39.986270904541,,,30.0159034729004,0,1,,,,,,1,1,1,29.9427967071533,0,29.9450555281206,,,,,,,,,,,,,,,,,,,,,,,,,,,,,,,,,
,3772426095.74972,29.9673624038696,60.0704803466797,,,5,,,,6.46999990567565,,,,,0.000599693031416689,4.80281395655581E-8,0.0248805058481771,5.0564387478955E-5,0.000599599137537324,4.80206198044366E-8,0.000599599081004049,3.72445059702816E-8,2.60373966564051E-7,3.03121543515453E-8,1.00015659442032,10.005763053894,2,20,1,3,1.96164153352199,0.173313685424166,0.0403775237500668,172.74836730957,29.9628829956055,29.9777774810791,60.0704803466797,60.0704803466797,,,30.0656509399414,0,1,,,,,,1,1,1,29.9697875976562,0,29.9712133407593,,,,,,,,,,,,,,,,,,,,,,,,,,,,,,,,,
,3772426117.67628,29.979832649231,80.0818252563477,,,5,,,,6.46999990567565,,,,,0.000600529347355258,3.95235349389244E-8,0.0224940557966162,4.89602948576699E-5,0.000600435461344491,3.95173558786617E-8,0.000600435415071603,2.64114970082898E-8,2.35728155504214E-7,2.93947995642408E-8,1.00015636320106,10.005763053894,2,20,1,3,1.9643818025736,0.173515530643994,0.0403775237500668,172.74836730957,29.9788150787354,29.9800205230713,80.0818252563477,80.0818252563477,,,30.1029624938965,0,1,,,,,,1,1,1,29.9796447753906,0,29.9793493097479,,,,,,,,,,,,,,,,,,,,,,,,,,,,,,,,,
,3772426139.4445,29.9788007736206,100.117462158203,,,5,,,,6.46999990567565,,,,,0.000601948041396289,9.08156558863679E-8,0.020919745825382,0.000106270438284031,0.000601853962032856,9.08014621711168E-8,0.000601853921915836,6.44603392892761E-8,2.197479768489E-7,6.39513110977731E-8,1.00015631593272,10.005763053894,2,20,1,3,1.96902461712318,0.173913574185958,0.0403775237500668,172.74836730957,29.9777393341064,29.9791526794434,100.117462158203,100.117462158203,,,30.1651496887207,0,1,,,,,,1,1,1,29.9787788391113,0,29.978363609314,,,,,,,,,,,,,,,,,,,,,,,,,,,,,,,,,
,3772426161.29575,29.9873476028442,120.01953125,,,5,,,,6.46999990567565,,,,,0.000605025886850276,7.46617788064802E-8,0.0237771680900272,6.55962442894996E-5,0.00060493122831666,7.46500976955515E-8,0.000604931176227063,6.32392462684974E-8,2.5104032457504E-7,3.96665453165224E-8,1.00015647817336,10.005763053894,2,20,1,3,1.9790811799457,0.174943559926587,0.0403775237500668,172.74836730957,29.984037399292,30.0003871917725,120.01953125,120.01953125,,,30.2522087097168,0,1,,,,,,1,1,1,29.9893074035645,0,29.9925890835849,,,,,,,,,,,,,,,,,,,,,,,,,,,,,,,,,
,3772426184.29459,30.0018167495728,140.079452514648,,,5,,,,6.46999990567565,,,,,0.000611025670038246,9.31389036805189E-8,0.0219188770836158,8.43435222214351E-5,0.000610930158122276,9.31243447584015E-8,0.000610930113417605,7.75804030039007E-8,2.33715342207243E-7,5.15114031689486E-8,1.00015633851873,10.005763053894,2,20,1,3,1.99870994830407,0.176656353102742,0.0403775237500668,172.74836730957,30.0009803771973,30.0024471282959,140.079452514648,140.079452514648,,,30.326831817627,0,1,,,,,,1,1,1,30.0014991760254,0,30.0014587402344,,,,,,,,,,,,,,,,,,,,,,,,,,,,,,,,,
,3772426206.44093,29.9956426620483,160.127227783203,,,5,,,,6.46999990567565,,,,,0.000619450167130756,5.09702766756595E-8,0.0237693836168189,5.14104597872758E-5,0.000619353371508009,5.09623120322803E-8,0.000619353318211461,3.97960402549783E-8,2.56941219485587E-7,3.18344534694667E-8,1.00015628496945,10.005763053894,2,20,1,3,2.0262585946324,0.179200979461399,0.0403775237500668,172.74836730957,29.9951782226562,30.001335144043,160.127227783203,160.127227783203,,,30.3890190124512,0,1,,,,,,1,1,1,29.9958572387695,0,29.9976000352339,,,,,,,,,,,,,,,,,,,,,,,,,,,,,,,,,
,3772426229.09346,29.9993677139282,180.017150878906,,,5,,,,6.46999990567565,,,,,0.00062957320096322,1.05672636513924E-7,0.0262094191118853,0.000100452860597882,0.000629474788264185,1.05656118133921E-7,0.00062947472240477,8.46574908113172E-8,2.87947351634081E-7,6.32164895312988E-8,1.00015634097008,10.005763053894,2,20,1,3,2.05936115128096,0.182260980797552,0.0403775237500668,172.74836730957,29.9985294342041,30.001781463623,180.017150878906,180.017150878906,,,30.4263305664063,0,1,,,,,,1,1,1,29.9989986419678,0,29.9999206542969,,,,,,,,,,,,,,,,,,,,,,,,,,,,,,,,,
,3772426250.99934,30.0022487640381,200.016342163086,,,5,,,,6.46999990567565,,,,,0.000643021861575337,1.95464048126592E-7,0.0295100269491142,0.000170801481892194,0.000642921409173951,1.95433512877027E-7,0.000642921323898931,1.61689152594045E-7,3.3113481365117E-7,1.09776481492507E-7,1.00015624367139,10.005763053894,2,20,1,3,2.10333876149529,0.186320512430051,0.0403775237500668,172.74836730957,30.000955581665,30.0032806396484,200.016342163086,200.016342163086,,,30.4760780334473,0,1,,,,,,1,1,1,30.0018825531006,0,30.0017158190409,,,,,,,,,,,,,,,,,,,,,,,,,,,,,,,,,
,3772426275.08063,30.0083255767822,220.039855957031,,,5,,,,6.46999990567565,,,,,0.000662289639772143,1.39072044356961E-7,0.0480723600796127,0.000166038943125548,0.000662186144868929,1.39050311799322E-7,0.000662185911793929,8.51314384787088E-8,5.55587991499086E-7,1.09943746498081E-7,1.00015629276453,10.005763053894,2,20,10,3,2.16629889225398,0.192651690301427,0.0403775237500668,172.74836730957,30.0041580200195,30.0097789764404,220.039855957031,220.039855957031,,,30.5133895874023,0,1,,,,,,1,1,1,30.0077037811279,0,30.0068300420588,,,,,,,,,,,,,,,,,,,,,,,,,,,,,,,,,
,3772426297.2836,30.0004587173462,240.09977722168,,,5,,,,6.46999990567565,,,,,0.000691814398789673,1.29617061791994E-7,0.0657152835427954,8.13132399970971E-5,0.000691706301481408,1.2959680888094E-7,0.000691705846515142,1.16779676107416E-7,7.93351031269776E-7,5.61946627391775E-8,1.00015627630981,10.005763053894,2,20,10,3,2.26280697264244,0.201985533142578,0.0403775237500668,172.74836730957,29.9997539520264,30.0012645721436,240.09977722168,240.09977722168,,,30.5631370544434,0,1,,,,,,1,1,1,30.0004043579102,0,30.0002895702015,,,,,,,,,,,,,,,,,,,,,,,,,,,,,,,,,
,3772426318.90609,29.9987878799438,260.013977050781,,,5,,,,6.46999990567565,,,,,0.000735540875021803,2.91934351774863E-7,0.0925478099297896,0.000149399226415068,0.000735425917354199,2.91888725361276E-7,0.000735424957962696,2.70488545624138E-7,1.18790649151858E-6,1.09704032191934E-7,1.00015631440896,10.005763053894,2,20,10,3,2.40572471836861,0.215930091639562,0.0403775237500668,172.74836730957,29.9984683990479,30.0049152374268,260.013977050781,260.013977050781,,,30.6004486083984,0,1,,,,,,1,1,1,29.9988327026367,0,30.0006284713745,,,,,,,,,,,,,,,,,,,,,,,,,,,,,,,,,
,3772426340.82427,30.0006494522095,280.061737060547,,,5,,,,6.46999990567565,,,,,0.000785434052545088,2.70092442225451E-7,0.0770407806388187,0.000183500003312682,0.0007853113201285,2.70050237411401E-7,0.000785310610211001,2.28433945886424E-7,1.05594128276969E-6,1.4403146563412E-7,1.00015628504702,10.005763053894,2,20,10,3,2.56896855102061,0.229936870767566,0.0403775237500668,172.74836730957,30.000394821167,30.0065765380859,280.061737060547,280.061737060547,,,30.6253242492676,0,1,,,,,,1,1,1,30.0005187988281,0,30.0024719238281,,,,,,,,,,,,,,,,,,,,,,,,,,,,,,,,,
,3772426363.87337,30.0027084350586,300.085235595703,,,5,,,,6.46999990567565,,,,,0.000826495388174794,2.85384873999211E-7,0.0419654816448274,0.000141683076676929,0.000826366256276478,2.85340285377111E-7,0.000826366034619341,2.60259536858649E-7,6.05260198111232E-7,1.16978852504257E-7,1.00015626472806,10.005763053894,2,20,10,3,2.70341441901246,0.240360607069132,0.0403775237500668,172.74836730957,30.0024852752686,30.0036735534668,300.085235595703,300.085235595703,,,30.6501960754395,0,1,,,,,,1,1,1,30.0024852752686,0,30.0029636383057,,,,,,,,,,,,,,,,,,,,,,,,,,,,,,,,,
,3772426385.5766,30.0031251907349,320.133026123047,,,5,,,,6.46999990567565,,,,,0.000851109780467299,3.14310820301439E-7,0.0120352745729253,0.000255030347896914,0.000850976786565332,3.1426170628186E-7,0.000850976767791434,2.27317983025751E-7,1.78752070278485E-7,2.16995287110781E-7,1.00015628381886,10.005763053894,2,20,10,3,2.78405174226073,0.246124365770254,0.0403775237500668,172.74836730957,30.0012912750244,30.0035076141357,320.133026123047,320.133026123047,,,30.6750717163086,0,1,,,,,,1,1,1,30.0030479431152,0,30.0023241043091,,,,,,,,,,,,,,,,,,,,,,,,,,,,,,,,,
,3772426407.596,30.0002288818359,339.998657226562,,,5,,,,6.46999990567565,,,,,0.00086105069048594,2.84840303410015E-7,-0.0263886530029316,0.000182768043609846,0.000860916060072106,2.84795766928773E-7,0.00086091596876176,2.3740503195332E-7,-3.96511131601252E-7,1.57313316867299E-7,1.00015638041858,10.005763053894,2,20,10,3,2.8167319473199,0.247170100574594,0.0403775237500668,172.74836730957,29.999439239502,30.0005550384521,339.998657226562,339.998657226562,,,30.6875076293945,0,1,,,,,,1,1,1,30.0001354217529,0,29.9999738693237,,,,,,,,,,,,,,,,,,,,,,,,,,,,,,,,,
,3772426429.13343,29.999906539917,360.05859375,,,5,,,,6.46999990567565,,,,,0.000863584550402165,5.12856238920147E-7,-0.0424301207657072,0.000268063427180647,0.000863449536551814,5.12776058357096E-7,0.000863449299790786,4.57597001390799E-7,-6.39423445736042E-7,2.31396349025625E-7,1.00015636565269,10.005763053894,2,20,10,3,2.8250864627317,0.247167161456907,0.0403775237500668,172.74836730957,29.999475479126,30.0003089904785,360.05859375,360.05859375,,,30.7123832702637,0,1,,,,,,1,1,1,30.0003089904785,0,29.9999376296997,,,,,,,,,,,,,,,,,,,,,,,,,,,,,,,,,
,3772426451.02509,29.9952144622803,380.130645751953,,,5,,,,6.46999990567565,,,,,0.000862920990837248,3.45480029084119E-7,-0.065041772278823,0.000135233669476468,0.000862786167251038,3.45426050959842E-7,0.000862785611330653,3.25133191552683E-7,-9.79428674151548E-7,1.16651465625072E-7,1.00015626535442,10.005763053894,2,20,10,3,2.82300926600337,0.245923888310242,0.0403775237500668,172.74836730957,29.9948406219482,30.0026760101318,380.130645751953,380.130645751953,,,30.7248191833496,0,1,,,,,,1,1,1,29.9952812194824,0,29.9974737167358,,,,,,,,,,,,,,,,,,,,,,,,,,,,,,,,,
,3772426472.68038,30.0067567825317,399.996276855469,,,5,,,,6.46999990567565,,,,,0.000860705203323001,3.82651058303767E-7,-0.0693829868049267,0.000208463367218524,0.000860570665544884,3.82591245695478E-7,0.000860570034562539,3.37937195450204E-7,-1.04211774491046E-6,1.79372554238569E-7,1.00015633553815,10.005763053894,2,20,10,3,2.81577535049368,0.245138762487873,0.0403775237500668,172.74836730957,30.0032901763916,30.0080585479736,399.996276855469,399.996276855469,,,30.7372550964355,0,1,,,,,,1,1,1,30.0061073303223,0,30.0053657531738,,,,,,,,,,,,,,,,,,,,,,,,,,,,,,,,,
,3772426494.56579,30.0067367553711,420.031921386719,,,5,,,,6.46999990567565,,,,,0.000857545866523512,3.4444106343305E-7,-0.0891991469817777,0.000233936368392641,0.000857411921647169,3.4438726326043E-7,0.000857410882599262,2.79960202522084E-7,-1.33483446387891E-6,2.0056139234609E-7,1.0001562199836,10.005763053894,2,20,10,3,2.80552031226087,0.243328810024108,0.0403775237500668,172.74836730957,30.0035343170166,30.0085430145264,420.031921386719,420.031921386719,,,30.7621307373047,0,1,,,,,,1,1,1,30.0060043334961,0,30.0054353713989,,,,,,,,,,,,,,,,,,,,,,,,,,,,,,,,,
,3772426516.2214,30.00266456604,440.310394287109,,,5,,,,6.46999990567565,,,,,0.000854154463284001,5.07477587798262E-7,-0.0922754007099709,0.000217517010463872,0.000854021011639063,5.07398300360483E-7,0.000854019904084626,4.72167460649894E-7,-1.37540840995201E-6,1.85771161142243E-7,1.0001562627185,10.005763053894,2,20,10,3,2.79443442706139,0.242277174596441,0.0403775237500668,172.74836730957,30.0006885528564,30.0041179656982,440.310394287109,440.310394287109,,,30.7621307373047,0,1,,,,,,1,1,1,30.0017795562744,0,30.0016689300537,,,,,,,,,,,,,,,,,,,,,,,,,,,,,,,,,
,3772426538.08495,29.9991407394409,460.382446289063,,,5,,,,6.46999990567565,,,,,0.00085059007599098,3.37036105548445E-7,-0.098437800631701,0.000295719880530943,0.000850457123541718,3.36983424736633E-7,0.000850455868376605,2.2432634355952E-7,-1.46113881858714E-6,2.51466737626363E-7,1.0001563305728,10.005763053894,2,20,10,3,2.78279555797537,0.241026670264492,0.0403775237500668,172.74836730957,29.9989814758301,30.0043830871582,460.382446289063,460.382446289063,,,30.7621307373047,0,1,,,,,,1,1,1,29.9991569519043,0,30.0009777069092,,,,,,,,,,,,,,,,,,,,,,,,,,,,,,,,,
,3772426559.77949,30.0062055587769,480.296661376953,,,5,,,,6.46999990567565,,,,,0.000846581908751415,5.29055323528045E-7,-0.131765671359268,0.000328019180280519,0.000846449599970982,5.28972639662593E-7,0.000846447361609569,4.50239524746972E-7,-1.94661635545795E-6,2.77662427899836E-7,1.00015631028763,10.005763053894,2,20,10,3,2.76981795097221,0.238338723882055,0.0403775237500668,172.74836730957,30.0033416748047,30.0077590942383,480.296661376953,480.296661376953,,,30.7870063781738,0,1,,,,,,1,1,1,30.0053672790527,0,30.0050361633301,,,,,,,,,,,,,,,,,,,,,,,,,,,,,,,,,
,3772426581.71092,30.0005683898926,500.2958984375,,,5,,,,6.46999990567565,,,,,0.000843102597810536,3.42585646183516E-7,-0.134705661254091,0.000249063941731004,0.000842970857200702,3.42532114807779E-7,0.000842968527453513,2.70650713846569E-7,-1.98187097011493E-6,2.09943899099335E-7,1.0001562813337,10.005763053894,2,20,10,3,2.75844308659892,0.237276769853923,0.0403775237500668,172.74836730957,29.9997901916504,30.0015144348145,500.2958984375,500.2958984375,,,30.7994422912598,0,1,,,,,,1,1,1,30.0000038146973,0,30.0004471865567,,,,,,,,,,,,,,,,,,,,,,,,,,,,,,,,,
,3772426604.85102,29.9988899230957,520.319396972656,,,5,,,,6.46999990567565,,,,,0.000839109060546306,5.15794005280941E-7,-0.133740815586232,0.000345669117616349,0.000838977912288094,5.15713389436625E-7,0.000838975626673479,4.26444963506155E-7,-1.95835521060124E-6,2.90008608741957E-7,1.00015631908337,10.005763053894,2,20,10,3,2.745369616466,0.23625793187252,0.0403775237500668,172.74836730957,29.9984111785889,30.0055503845215,520.319396972656,520.319396972656,,,30.8118782043457,0,1,,,,,,1,1,1,29.9992065429687,0,30.0010593732198,,,,,,,,,,,,,,,,,,,,,,,,,,,,,,,,,
,3772426627.87024,30.0056476593018,540.355041503906,,,5,,,,6.46999990567565,,,,,0.000835160994694094,5.12865567053009E-7,-0.143036353833657,0.000373372067548538,0.000835030492177999,5.12785426520413E-7,0.000835027890103597,4.07124373108774E-7,-2.08461415295035E-6,3.1176696180402E-7,1.0001562847313,10.005763053894,2,20,10,3,2.73248707674668,0.234761508864503,0.0403775237500668,172.74836730957,30.0020065307617,30.0065994262695,540.355041503906,540.355041503906,,,30.8243179321289,0,1,,,,,,1,1,1,30.0054359436035,0,30.0043640136719,,,,,,,,,,,,,,,,,,,,,,,,,,,,,,,,,
,3772426649.53604,29.9924926757812,560.281372070313,,,5,,,,6.46999990567565,,,,,0.000831155535664851,5.24635763170021E-7,-0.153131767515998,0.000307254518827968,0.000831025683487825,5.2455379885279E-7,0.000831022715449408,4.58189831622352E-7,-2.22104108443564E-6,2.55379650890148E-7,1.00015625531149,10.005763053894,2,20,10,3,2.71941962369819,0.233214618971836,0.0403775237500668,172.74836730957,29.9922275543213,30.0013828277588,560.281372070313,560.281372070313,,,30.8367538452148,0,1,,,,,,1,1,1,29.9923343658447,0,29.9955484390259,,,,,,,,,,,,,,,,,,,,,,,,,,,,,,,,,
,3772426671.38575,29.9993028640747,580.365539550781,,,5,,,,6.46999990567565,,,,,0.000827194281125963,6.45999407125296E-7,-0.153419005848299,0.00063446677276581,0.000827064979441682,6.45898428657128E-7,0.000827062014457094,3.76723426866751E-7,-2.21460177988414E-6,5.24656306348754E-7,1.00015633799942,10.005763053894,2,20,10,3,2.70645667425766,0.232147624758328,0.0403775237500668,172.74836730957,29.9989700317383,30.0034809112549,580.365539550781,580.365539550781,,,30.8491897583008,0,1,,,,,,1,1,1,29.9995250701904,0,30.0006954193115,,,,,,,,,,,,,,,,,,,,,,,,,,,,,,,,,
,3772426693.07741,30.0044527053833,600.340515136719,,,5,,,,6.46999990567565,,,,,0.000822800072069448,7.21583654578772E-7,-0.163149878420299,0.000463336845517429,0.000822671546099809,7.21470939179214E-7,0.00082266821088023,6.12530108707646E-7,-2.3425561618392E-6,3.81218024241687E-7,1.0001562299927,10.005763053894,2,20,10,3,2.69211523053769,0.230514680795644,0.0403775237500668,172.74836730957,30.0022659301758,30.005744934082,600.340515136719,600.340515136719,,,30.8740653991699,0,1,,,,,,1,1,1,30.0040969848633,0,30.0036806626753,,,,,,,,,,,,,,,,,,,,,,,,,,,,,,,,,
,3772426715.03269,29.9957637786865,620.230407714844,,,5,,,,6.46999990567565,,,,,0.000818878141662723,4.12240129916616E-7,-0.159899988400462,0.000214978476095807,0.000818750178773511,4.12175710761446E-7,0.000818746990374029,3.72673307153766E-7,-2.2849496989066E-6,1.76077888097222E-7,1.00015629051758,10.005763053894,2,20,10,3,2.67926665590658,0.229625043144055,0.0403775237500668,172.74836730957,29.9955520629883,30.0019207000732,620.230407714844,620.230407714844,,,30.8740653991699,0,1,,,,,,1,1,1,29.9957714080811,0,29.9977973591198,,,,,,,,,,,,,,,,,,,,,,,,,,,,,,,,,
,3772426738.15377,30.0094776153564,640.302490234375,,,5,,,,6.46999990567565,,,,,0.000813935735497983,5.51000391603769E-7,-0.186396484818989,0.000336477934157233,0.000813808593448924,5.50914321763405E-7,0.000813804286972601,4.78001797146401E-7,-2.64750379264763E-6,2.73899382709862E-7,1.00015623090009,10.005763053894,2,20,10,3,2.66319761455297,0.22706456902797,0.0403775237500668,172.74836730957,30.0048847198486,30.0114936828613,640.302490234375,640.302490234375,,,30.8989372253418,0,1,,,,,,1,1,1,30.0084075927734,0,30.0077255249023,,,,,,,,,,,,,,,,,,,,,,,,,,,,,,,,,
,3772426760.39104,30.0020561218262,660.38671875,,,5,,,,6.46999990567565,,,,,0.000808619999656764,8.9343126316133E-7,-0.200651280837095,0.000382197568043337,0.000808493592100879,8.93291597481066E-7,0.000808488634349426,8.3801125089203E-7,-2.83135938788283E-6,3.09365514414016E-7,1.00015634948393,10.005763053894,2,20,10,3,2.64585720497946,0.224980332832082,0.0403775237500668,172.74836730957,30.0005683898926,30.0027847290039,660.38671875,660.38671875,,,30.8989372253418,0,1,,,,,,1,1,1,30.001781463623,0,30.0015094063499,,,,,,,,,,,,,,,,,,,,,,,,,,,,,,,,,
,3772426782.28559,30.0003347396851,680.385864257812,,,5,,,,6.46999990567565,,,,,0.000801747647155447,7.10416782655636E-7,-0.215039336830229,0.000383918354494643,0.000801622285239751,7.10305701308367E-7,0.000801616639383246,6.40076945412783E-7,-3.00859716679468E-6,3.07954044075105E-7,1.00015638526773,10.005763053894,2,20,10,3,2.62342305314148,0.222465636752066,0.0403775237500668,172.74836730957,29.9996013641357,30.0004806518555,680.385864257812,680.385864257812,,,30.8865013122559,0,1,,,,,,1,1,1,30.0004806518555,0,30.0000423431396,,,,,,,,,,,,,,,,,,,,,,,,,,,,,,,,,
,3772426803.98051,29.9925403594971,700.312255859375,,,5,,,,6.46999990567565,,,,,0.000791554388992506,7.78302489376568E-7,-0.312299256076563,0.00040375197642239,0.000791430722009794,7.78180892778992E-7,0.000791418965498415,7.09349917210553E-7,-4.31379071842857E-6,3.19981557030543E-7,1.00015625749579,10.005763053894,2,20,10,3,2.59043532177498,0.21529562357316,0.0403775237500668,172.74836730957,29.9920616149902,30.000804901123,700.312255859375,700.312255859375,,,30.8865013122559,0,1,,,,,,1,1,1,29.9931297302246,0,29.9953119277954,,,,,,,,,,,,,,,,,,,,,,,,,,,,,,,,,
,3772426825.86891,29.9981145858765,720.311462402344,,,5,,,,6.46999990567565,,,,,0.000780495277482518,1.06854142361651E-6,-0.318064733337459,0.000716571140183419,0.000780373317957102,1.06837445424633E-6,0.000780361293732734,9.10159754083521E-7,-4.33204606971918E-6,5.59493696597879E-7,1.00015628356661,10.005763053894,2,20,10,3,2.55426158947494,0.212085214751568,0.0403775237500668,172.74836730957,29.9979686737061,30.004035949707,720.311462402344,720.311462402344,,,30.8989372253418,0,1,,,,,,1,1,1,29.9981212615967,0,30.0000979683616,,,,,,,,,,,,,,,,,,,,,,,,,,,,,,,,,
,3772426849.1541,30.0101919174194,740.298461914062,,,5,,,,6.46999990567565,,,,,0.000762623418640255,1.21015250466775E-6,-0.380729516878095,0.000934077254629805,0.000762504266962527,1.20996343140077E-6,0.000762487432528684,9.77951649177407E-7,-5.06679108281284E-6,7.12476018682961E-7,1.00015626362093,10.005763053894,2,20,10,3,2.49599603361777,0.204552333126785,0.0403775237500668,172.74836730957,30.0051975250244,30.0128746032715,740.298461914062,740.298461914062,,,30.911376953125,0,1,,,,,,1,1,1,30.0089855194092,0,30.0085374658758,,,,,,,,,,,,,,,,,,,,,,,,,,,,,,,,,
,3772426870.79802,30.0027770996094,760.382690429688,,,5,,,,6.46999990567565,,,,,0.000731882542256347,1.10696281336334E-6,-0.401153548541625,0.00077228332325682,0.000731768106522687,1.10678973080655E-6,0.000731750170847961,9.51350306507517E-7,-5.12339611769072E-6,5.65611264497888E-7,1.00015638251058,10.005763053894,2,20,10,3,2.3954509387086,0.195504636750196,0.0403775237500668,172.74836730957,30.0007781982422,30.0036201477051,760.382690429688,760.382690429688,,,30.9238128662109,0,1,,,,,,1,1,1,30.0024948120117,0,30.0020578384399,,,,,,,,,,,,,,,,,,,,,,,,,,,,,,,,,
,3772426892.66358,30.0101051330566,780.272644042969,,,5,,,,6.46999990567565,,,,,0.000674256071994774,1.15959068663136E-6,-0.41430366480245,0.000775491290162011,0.000674150729440779,1.15940951771113E-6,0.000674133104916398,1.0344636203654E-6,-4.87471653649808E-6,5.23560357456204E-7,1.0001562596455,10.005763053894,2,20,10,3,2.20687823579977,0.179651504790867,0.0403775237500668,172.74836730957,30.0048198699951,30.0113410949707,780.272644042969,780.272644042969,,,30.9238128662109,0,1,,,,,,1,1,1,30.009801864624,0,30.0079890164462,,,,,,,,,,,,,,,,,,,,,,,,,,,,,,,,,
,3772426914.44292,29.9994802474976,800.296142578125,,,5,,,,6.46999990567565,,,,,0.000547527630983276,9.45284145045041E-7,-0.50709376682079,0.000862570766943398,0.000547442040541559,9.45136376634929E-7,0.00054742059995833,8.18377159227031E-7,-4.84504835565991E-6,4.72801856694851E-7,1.00015634612503,10.005763053894,2,20,10,3,1.7923207210793,0.143021511105921,0.0403775237500668,172.74836730957,29.9984951019287,30.0002155303955,800.296142578125,800.296142578125,,,30.9238128662109,0,1,,,,,,1,1,1,29.999044418335,0,29.9994146347046,,,,,,,,,,,,,,,,,,,,,,,,,,,,,,,,,
,3772426939.48552,30.0012378692627,820.392456054687,,,5,,,,6.46999990567565,,,,,0.000387518873691601,6.84730867533737E-7,-0.693751115162413,0.000808905899749918,0.000387458309307851,6.84623852609195E-7,0.000387429907119636,6.08262261734354E-7,-4.69132401019539E-6,3.14208275688699E-7,1.0001563120013,10.005763053894,2,20,1,3,1.26885692213538,0.0971192154932299,0.0403775237500668,172.74836730957,30.0006141662598,30.0015239715576,820.392456054687,820.392456054687,,,30.9362487792969,0,1,,,,,,1,1,1,30.0010623931885,0,30.0010091341459,,,,,,,,,,,,,,,,,,,,,,,,,,,,,,,,,
,3772426961.97459,29.9998626708984,840.245971679688,,,5,,,,6.46999990567565,,,,,0.00026588886200908,1.30929589675735E-6,-1.11237777109493,0.00174468860655244,0.000265847293157804,1.30909120248773E-6,0.00026579719197903,1.22261147489799E-6,-5.16100914497047E-6,4.67911271373695E-7,1.00015636364314,10.005763053894,2,20,1,3,0.871065390495324,0.0602923429629101,0.0403775237500668,172.74836730957,29.9997177124023,30.0006084442139,840.245971679688,840.245971679688,,,30.9362487792969,0,1,,,,,,1,1,1,29.9998989105225,0,30.0000270843506,,,,,,,,,,,,,,,,,,,,,,,,,,,,,,,,,
,3772426983.57751,30.0012311935425,860.318054199219,,,5,,,,6.46999990567565,,,,,0.00017542613523119,1.35140651506152E-6,-1.71415963913394,0.00388124085653239,0.000175398718360134,1.35119530743206E-6,0.00017532022710179,1.16549672623932E-6,-5.24674864599683E-6,6.83627193689561E-7,1.0001563116955,10.005763053894,2,20,1,3,0.575090605281997,0.0337533156056432,0.0403775237500668,172.74836730957,29.9999923706055,30.0023822784424,860.318054199219,860.318054199219,,,30.9486885070801,0,1,,,,,,1,1,1,30.0004787445068,0,30.0006113052368,,,,,,,,,,,,,,,,,,,,,,,,,,,,,,,,,
,3772427005.4718,30.0069236755371,880.341491699219,,,5,,,,6.46999990567565,,,,,0.000123609745491089,1.21579125313311E-6,-2.4227200075344,0.00418084775537365,0.000123590437136787,1.21560134150293E-6,0.000123479965357313,1.0978755100489E-6,-5.22439537351931E-6,5.21877366723825E-7,1.00015622854607,10.005763053894,2,20,1,3,0.405486514858383,0.0187791436018479,0.0403775237500668,172.74836730957,30.0038089752197,30.0083751678467,880.341491699219,880.341491699219,,,30.961124420166,0,1,,,,,,1,1,1,30.0063877105713,0,30.005736541748,,,,,,,,,,,,,,,,,,,,,,,,,,,,,,,,,
,3772427027.11717,30.0023956298828,900.182861328125,,,5,,,,6.46999990567565,,,,,8.61050169926402E-5,1.12938217826432E-6,-3.51050399699643,0.00586214296376898,8.60915552834851E-5,1.12920560998828E-6,8.59300121990047E-5,1.00745952889299E-6,-5.27151729659282E-6,5.10030006246401E-7,1.00015636503616,10.005763053894,2,20,1,3,0.282654308535583,0.00772272276289098,0.0403775237500668,172.74836730957,30.0008792877197,30.0034084320068,900.182861328125,900.182861328125,,,30.9486885070801,0,1,,,,,,1,1,1,30.0019989013672,0,30.0017894744873,,,,,,,,,,,,,,,,,,,,,,,,,,,,,,,,,
,3772427049.03604,29.9998645782471,920.145690917969,,,5,,,,6.46999990567565,,,,,5.81786583820147E-5,1.83614735612687E-6,-5.17965410931611,0.0128498298852446,5.81695627721776E-5,1.83586029416258E-6,5.79320285089523E-5,1.67153768935736E-6,-5.25148607008027E-6,7.59173743447815E-7,1.00015636373051,10.005763053894,2,20,1,3,0.191052372267195,-0.000343032178165487,0.0403775237500668,172.74836730957,29.9996776580811,30.0001411437988,920.145690917969,920.145690917969,,,30.961124420166,0,1,,,,,,1,1,1,30.0000820159912,0,29.9998657920144,,,,,,,,,,,,,,,,,,,,,,,,,,,,,,,,,
,3772427070.69289,29.9919919967651,940.144897460937,,,5,,,,6.46999990567565,,,,,3.9379078230057E-5,1.11694673935807E-6,-7.90174291828861,0.0146656300611621,3.93729223912335E-5,1.11677213537008E-6,3.89990875869728E-5,9.54266265728169E-7,-5.41277978581424E-6,5.80134377909356E-7,1.00015634701337,10.005763053894,2,20,1,3,0.129159865517142,-0.00637060882038536,0.0403775237500668,172.74836730957,29.9916839599609,30.000825881958,940.144897460937,940.144897460937,,,30.9486885070801,0,1,,,,,,1,1,1,29.9923458099365,0,29.9948209762573,,,,,,,,,,,,,,,,,,,,,,,,,,,,,,,,,
,3772427092.54218,30.0051784515381,960.14404296875,,,5,,,,6.46999990567565,,,,,2.85330458936863E-5,1.461905123235E-6,-10.7606177135459,0.0199999243846698,2.85285879241683E-5,1.46167671689865E-6,2.80269359657331E-5,1.34708731007071E-6,-5.32646123797965E-6,5.67322310305236E-7,1.00015626323777,10.005763053894,2,20,1,3,0.0932393931493258,-0.00927594586496324,0.0403775237500668,172.74836730957,30.0026741027832,30.0066719055176,960.14404296875,960.14404296875,,,30.9860000610352,0,1,,,,,,1,1,1,30.0045394897461,0,30.0040650801225,,,,,,,,,,,,,,,,,,,,,,,,,,,,,,,,,
,3772427114.23286,30.0016183853149,980.301147460937,,,5,,,,6.46999990567565,,,,,2.09618448044684E-5,1.28110549590764E-6,-15.5590845502958,0.0359327272361689,2.09585683633798E-5,1.28090525271699E-6,2.01905281985155E-5,1.04534835589832E-6,-5.62175763506557E-6,7.40246635425416E-7,1.00015632943204,10.005763053894,2,20,1,3,0.0676886382510101,-0.0125192287995595,0.0403775237500668,172.74836730957,30.0005207061768,30.0021057128906,980.301147460937,980.301147460937,,,30.961124420166,0,1,,,,,,1,1,1,30.001537322998,0,30.0011310577393,,,,,,,,,,,,,,,,,,,,,,,,,,,,,,,,,
,3772427136.10059,29.9956636428833,1000.17895507813,,,5,,,,6.46999990567565,,,,,1.59263626843078E-5,1.18532015883987E-6,-20.299256037451,0.038112354087526,1.59238740068407E-5,1.18513493892312E-6,1.49348969600854E-5,1.05480240176222E-6,-5.5243656809962E-6,5.40311684764411E-7,1.00015628593055,10.005763053894,2,20,1,3,0.0504667700096957,-0.0137281448963302,0.0403775237500668,172.74836730957,29.9952602386475,30.0008869171143,1000.17895507813,1000.17895507813,,,30.973560333252,0,1,,,,,,1,1,1,29.9957847595215,0,29.9974779129028,,,,,,,,,,,,,,,,,,,,,,,,,,,,,,,,,