File: Experimental_Data/Supplementary_Fig1_Data/FC_Down_51K.dat
[Header]
; MPMS3 Data File (default extension .dat)
; Copyright (c) 2007, Quantum Design, Inc. All rights reserved.
TITLE,FC_51K
FILEOPENTIME,3754368328.46362,12/19/2018,8:05 am
BYAPP,SQUID AC,0.9.1.0
INFO,MPMS3 Measurement Release 1.1.16 Build 347, MultiVu Release 2.3.3.2,APPNAME
INFO,0,MOMENT_UNITS
INFO,CoIINO3,SAMPLE_MATERIAL
INFO,40 Hours Pumped Turbo,SAMPLE_COMMENT
INFO,,SAMPLE_MASS
INFO,,SAMPLE_VOLUME
INFO,,SAMPLE_MOLECULAR_WEIGHT
INFO,,SAMPLE_SIZE
INFO,,SAMPLE_SHAPE
INFO,Brass,SAMPLE_HOLDER
INFO,Standard,SAMPLE_HOLDER_DETAIL
INFO,65.37,SAMPLE_OFFSET
DATATYPE,COMMENT,1
DATATYPE,TIME,2
STARTUPAXIS,X,2
STARTUPAXIS,Y1,5
FIELDGROUP, VSM,2,3,4,5,6,8,9,10,11,14,15
FIELDGROUP, DC, 2,3,4,14,56,57,58,59,60,61,62,63,64,65,66,67,68,69
FIELDGROUP, AC, 2,3,4,11,16,17,18,19,20,21,22,23,24,25,26,27,28,29,30
STARTUPGROUP, All
[Data]
Comment,Time Stamp (sec),Temperature (K),Magnetic Field (Oe),Moment (emu),M. Std. Err. (emu),Transport Action,Averaging Time (sec),Frequency (Hz),Peak Amplitude (mm),Center Position (mm),Lockin Signal' (V),Lockin Signal (V),Range,M. Quad. Signal (emu),AC Moment (emu),AC M. Std Err. (emu),AC Phase (deg),AC Phase Std. Err. (deg),AC Susceptibility (emu/Oe),AC Suscept. Std Err. (emu/Oe),AC X' (emu/Oe),AC X' Std Err. (emu/Oe),AC X'' (emu/Oe),AC X'' Std Err. (emu/Oe),AC Drive (Oe),AC Frequency (Hz),AC Averaging Time (sec),AC Cycles,AC Range,AC Measure Type,AC Signal' (V),AC Signal'' (V),AC Trim Coil Ratio,AC Trim Coil Phase,Min. Temperature (K),Max. Temperature (K),Min. Field (Oe),Max. Field (Oe),Mass (grams),Motor Lag (deg),Pressure (Torr),Measure Count,Measurement Number,SQUID Status (code),Motor Status (code),Measure Status (code),Motor Current (amps),Motor Temp. (C),Temp. Status (code),Field Status (code),Chamber Status (code),Chamber Temp (K),Redirection State,Average Temp (K),Rotation Angle (deg),Rotator state,DC Moment Fixed Ctr (emu),DC Moment Err Fixed Ctr (emu),DC Moment Free Ctr (emu),DC Moment Err Free Ctr (emu),DC Fixed Fit,DC Free Fit,DC Calculated Center (mm),DC Calculated Center Err (mm),DC Scan Length (mm),DC Scan Time (s),DC Number of Points,DC Squid Drift,DC Min V (V),DC Max V (V),DC Scans per Measure,Map 01,Map 02,Map 03,Map 04,Map 05,Map 06,Map 07,Map 08,Map 09,Map 10,Map 11,Map 12,Map 13,Map 14,Map 15,Map 16
,3754368466.9927,50.9604034423828,220.270553588867,,,5,,,,3.65000008605421,,,,,0.000666471839982467,2.49934429165815E-8,0.000913430923359826,2.22750837950762E-5,0.000666385408792366,2.49902016498296E-8,0.000666385408707682,2.01064757386534E-8,1.06237674818956E-8,1.48404788288683E-8,1.00012970150451,10.005763053894,2,20,1,3,2.18015310564184,0.191899349907728,0.0404026173055172,172.741912841797,50.9260711669922,50.9718132019043,220.270553588867,220.270553588867,,,123.443450927734,0,1,,,,,,1,1,1,50.9552192687988,0,50.9469403353604,,,,,,,,,,,,,,,,,,,,,,,,,,,,,,,,,
,3754368491.90423,50.8748092651367,200.502075195313,,,5,,,,3.65000008605421,,,,,0.000664758422861629,2.61994251354281E-8,0.00889679447228886,2.23986019768253E-5,0.000664672376799177,2.61960338923932E-8,0.000664672368786096,2.15570734193289E-8,1.03209233808857E-7,1.48837084520316E-8,1.00012945635392,10.005763053894,2,20,10,3,2.17452434183926,0.19166326846031,0.0404026173055172,172.741912841797,50.8672409057617,50.8900566101074,200.502075195313,200.502075195313,,,123.406135559082,0,1,,,,,,1,1,1,50.8703193664551,0,50.8750298023224,,,,,,,,,,,,,,,,,,,,,,,,,,,,,,,,,
,3754368518.48982,50.9150123596191,180.405715942383,,,5,,,,3.65000008605421,,,,,0.000666098780177323,8.93685683900034E-8,0.0752407171799865,2.66160399515883E-5,0.00066601194673917,8.93569181959374E-8,0.000666011372473903,8.76020941037743E-8,8.74605469133049E-7,1.76219164141963E-8,1.00013037819904,10.005763053894,2,20,10,3,2.17868799153522,0.194525573185659,0.0404026173055172,172.741912841797,50.9101486206055,50.9292678833008,180.405715942383,180.405715942383,,,123.493202209473,0,1,,,,,,1,1,1,50.9174537658691,0,50.91928135265,,,,,,,,,,,,,,,,,,,,,,,,,,,,,,,,,
,3754368541.26784,50.9342746734619,160.260803222656,,,5,,,,3.65000008605421,,,,,0.000688989885434174,2.77590074022396E-7,0.250896893506836,0.000164923621590551,0.000688900172045729,2.77553929012627E-7,0.000688893567074853,2.53352158498566E-7,3.01666828136771E-6,1.13352844227501E-7,1.0001302269793,10.005763053894,2,20,10,3,2.25293640476322,0.208069951496612,0.0404026173055172,172.741912841797,50.9312896728516,50.9347915649414,160.260803222656,160.260803222656,,,123.555381774902,0,1,,,,,,1,1,1,50.9337577819824,0,50.9331806182861,,,,,,,,,,,,,,,,,,,,,,,,,,,,,,,,,
,3754368564.29649,50.9585628509521,140.273727416992,,,5,,,,3.65000008605421,,,,,0.000707922310148792,1.13112313166947E-7,0.172333629050755,7.06685087905548E-5,0.000707829994604439,1.13097562925835E-7,0.000707826792810034,1.0146922824016E-7,2.12900023059526E-6,4.99505201185097E-8,1.00013042050359,10.005763053894,2,20,10,3,2.31513796126108,0.210563498541212,0.0404026173055172,172.741912841797,50.9539947509766,50.9693489074707,140.273727416992,140.273727416992,,,123.692192077637,0,1,,,,,,1,1,1,50.9605102539063,0,50.9621059417725,,,,,,,,,,,,,,,,,,,,,,,,,,,,,,,,,
,3754368584.83396,50.9721221923828,120.42024230957,,,5,,,,3.65000008605421,,,,,0.000702798942679819,6.11624595836054E-8,0.0979737129474305,5.23745859828504E-5,0.000702707423618287,6.11544949573628E-8,0.000702706396268562,4.88494962089784E-8,1.20160372093017E-6,3.67912893715227E-8,1.00013023778952,10.005763053894,2,20,10,3,2.29865534196754,0.206007649561011,0.0404026173055172,172.741912841797,50.9719619750977,50.9790229797363,120.42024230957,120.42024230957,,,123.791687011719,0,1,,,,,,1,1,1,50.9723281860352,0,50.9739868164063,,,,,,,,,,,,,,,,,,,,,,,,,,,,,,,,,
,3754368607.85883,51.0064659118652,100.323883056641,,,5,,,,3.65000008605421,,,,,0.00068825292691599,3.65344284618389E-8,0.051150075391714,4.4852414195681E-5,0.00068816324703377,3.65296679978971E-8,0.000688162972807699,1.95377443241061E-8,6.14348868121873E-7,3.08657284178172E-8,1.00013031774453,10.005763053894,2,20,10,3,2.25124663230219,0.199855602498735,0.0404026173055172,172.741912841797,51.0043525695801,51.0096817016602,100.323883056641,100.323883056641,,,123.916061401367,0,1,,,,,,1,1,1,51.0075492858887,0,51.0078010559082,,,,,,,,,,,,,,,,,,,,,,,,,,,,,,,,,
,3754368629.70725,51.0173797607422,80.2153930664062,,,5,,,,3.65000008605421,,,,,0.000673766931053997,2.21609236710006E-8,0.0208391324328971,2.77052560162154E-5,0.000673679188747664,2.215803773157E-8,0.00067367914418849,1.19431071913114E-8,2.45024845483932E-7,1.86638909858187E-8,1.00013024345682,10.005763053894,2,20,10,3,2.20396969227197,0.194435749427028,0.0404026173055172,172.741912841797,51.0149688720703,51.0176582336426,80.2153930664062,80.2153930664062,,,124.015556335449,0,1,,,,,,1,1,1,51.0176658630371,0,51.0166103363037,,,,,,,,,,,,,,,,,,,,,,,,,,,,,,,,,
,3754368652.34448,51.0573749542236,60.495475769043,,,5,,,,3.65000008605421,,,,,0.000660119315098513,2.02831546430549E-8,0.00606370245485177,2.03648207041837E-5,0.000660033278085832,2.02805110269792E-8,0.000660033274389539,1.51882431011795E-8,6.98523597227265E-8,1.34393600671646E-8,1.00013035253757,10.005763053894,2,20,10,3,2.15937864695932,0.189894757892625,0.0404026173055172,172.741912841797,51.0511703491211,51.0579719543457,60.495475769043,60.495475769043,,,124.115051269531,0,1,,,,,,1,1,1,51.0579948425293,0,51.0555759776722,,,,,,,,,,,,,,,,,,,,,,,,,,,,,,,,,
,3754368674.4947,51.0287551879883,40.4841232299805,,,5,,,,3.65000008605421,,,,,0.000651544186376508,1.79987898725934E-8,-0.00105692999403306,1.64377032613513E-5,0.000651459447434373,1.79964489746998E-8,0.000651459447323531,1.44654778340408E-8,-1.20174127257196E-8,1.07061723660628E-8,1.00013007554418,10.005763053894,2,20,10,3,2.13135382113747,0.187117546880941,0.0404026173055172,172.741912841797,51.0181121826172,51.0322875976562,40.4841232299805,40.4841232299805,,,124.189674377441,0,1,,,,,,1,1,1,51.0270843505859,0,51.0249866485596,,,,,,,,,,,,,,,,,,,,,,,,,,,,,,,,,
,3754368697.57575,51.0422668457031,20.3027763366699,,,5,,,,3.65000008605421,,,,,0.000647982782547731,3.16713415455323E-8,-0.00602735211129435,4.53679371387349E-5,0.000647898403573036,3.16672173690899E-8,0.000647898399988072,1.1783949437336E-8,-6.81570586291772E-8,2.93930466532392E-8,1.00013023488595,10.005763053894,2,20,10,3,2.11972259770836,0.185865024942739,0.0404026173055172,172.741912841797,51.0361366271973,51.0425491333008,20.3027763366699,20.3027763366699,,,124.276733398438,0,1,,,,,,1,1,1,51.0424499511719,0,51.0405047734578,,,,,,,,,,,,,,,,,,,,,,,,,,,,,,,,,
,3754368720.64683,51.051685333252,0.194284945726395,,,5,,,,3.65000008605421,,,,,0.000647331368606639,3.23552672616613E-8,-0.003156267115485,2.08739944914459E-5,0.000647247092561323,3.23510549306942E-8,0.000647247091579254,2.93981904079167E-8,-3.5655064477217E-8,1.35032276093039E-8,1.00013020691214,10.005763053894,2,20,10,3,2.11758515819339,0.185738686078449,0.0404026173055172,172.741912841797,51.0417137145996,51.0519676208496,0.194284945726395,0.194284945726395,,,124.363792419434,0,1,,,,,,1,1,1,51.0514030456543,0,51.0485622406006,,,,,,,,,,,,,,,,,,,,,,,,,,,,,,,,,
,3754368742.26863,51.0252742767334,-19.7927799224854,,,5,,,,3.65000008605421,,,,,0.000649664010507074,5.47793586121876E-8,-0.00302522212256306,5.34683290184289E-5,0.00064957954503236,5.47722365237621E-8,0.000649579544126896,4.23569734932959E-8,-3.4297856243226E-8,3.47258504619133E-8,1.00013003099522,10.005763053894,2,20,10,3,2.12521263705053,0.186457517527902,0.0404026173055172,172.741912841797,51.0188179016113,51.0284461975098,-19.7927799224854,-19.7927799224854,,,124.438415527344,0,1,,,,,,1,1,1,51.02392578125,0,51.0230369567871,,,,,,,,,,,,,,,,,,,,,,,,,,,,,,,,,
,3754368762.75889,51.0119037628174,-39.9255561828613,,,5,,,,3.65000008605421,,,,,0.000654264684163715,6.54893990070702E-8,0.0031999363206543,3.3096687042164E-5,0.000654179570425426,6.54808794465579E-8,0.000654179569405181,6.18055486612511E-8,3.65355526067699E-8,2.1629140708229E-8,1.00013010760674,10.005763053894,2,20,10,3,2.14023931581497,0.18805663291759,0.0404026173055172,172.741912841797,51.0087585449219,51.0128479003906,-39.9255561828613,-39.9255561828613,,,124.488166809082,0,1,,,,,,1,1,1,51.011531829834,0,51.010725402832,,,,,,,,,,,,,,,,,,,,,,,,,,,,,,,,,