File: Experimental_Data/Supplementary_Fig1_Data/FC_Up_57K.dat
[Header]
; MPMS3 Data File (default extension .dat)
; Copyright (c) 2007, Quantum Design, Inc. All rights reserved.
TITLE,FC_57K
FILEOPENTIME,3754349384.22148,12/19/2018,2:49 am
BYAPP,SQUID AC,0.9.1.0
INFO,MPMS3 Measurement Release 1.1.16 Build 347, MultiVu Release 2.3.3.2,APPNAME
INFO,0,MOMENT_UNITS
INFO,CoIINO3,SAMPLE_MATERIAL
INFO,40 Hours Pumped Turbo,SAMPLE_COMMENT
INFO,,SAMPLE_MASS
INFO,,SAMPLE_VOLUME
INFO,,SAMPLE_MOLECULAR_WEIGHT
INFO,,SAMPLE_SIZE
INFO,,SAMPLE_SHAPE
INFO,Brass,SAMPLE_HOLDER
INFO,Standard,SAMPLE_HOLDER_DETAIL
INFO,65.37,SAMPLE_OFFSET
DATATYPE,COMMENT,1
DATATYPE,TIME,2
STARTUPAXIS,X,2
STARTUPAXIS,Y1,5
FIELDGROUP, VSM,2,3,4,5,6,8,9,10,11,14,15
FIELDGROUP, DC, 2,3,4,14,56,57,58,59,60,61,62,63,64,65,66,67,68,69
FIELDGROUP, AC, 2,3,4,11,16,17,18,19,20,21,22,23,24,25,26,27,28,29,30
STARTUPGROUP, All
[Data]
Comment,Time Stamp (sec),Temperature (K),Magnetic Field (Oe),Moment (emu),M. Std. Err. (emu),Transport Action,Averaging Time (sec),Frequency (Hz),Peak Amplitude (mm),Center Position (mm),Lockin Signal' (V),Lockin Signal (V),Range,M. Quad. Signal (emu),AC Moment (emu),AC M. Std Err. (emu),AC Phase (deg),AC Phase Std. Err. (deg),AC Susceptibility (emu/Oe),AC Suscept. Std Err. (emu/Oe),AC X' (emu/Oe),AC X' Std Err. (emu/Oe),AC X'' (emu/Oe),AC X'' Std Err. (emu/Oe),AC Drive (Oe),AC Frequency (Hz),AC Averaging Time (sec),AC Cycles,AC Range,AC Measure Type,AC Signal' (V),AC Signal'' (V),AC Trim Coil Ratio,AC Trim Coil Phase,Min. Temperature (K),Max. Temperature (K),Min. Field (Oe),Max. Field (Oe),Mass (grams),Motor Lag (deg),Pressure (Torr),Measure Count,Measurement Number,SQUID Status (code),Motor Status (code),Measure Status (code),Motor Current (amps),Motor Temp. (C),Temp. Status (code),Field Status (code),Chamber Status (code),Chamber Temp (K),Redirection State,Average Temp (K),Rotation Angle (deg),Rotator state,DC Moment Fixed Ctr (emu),DC Moment Err Fixed Ctr (emu),DC Moment Free Ctr (emu),DC Moment Err Free Ctr (emu),DC Fixed Fit,DC Free Fit,DC Calculated Center (mm),DC Calculated Center Err (mm),DC Scan Length (mm),DC Scan Time (s),DC Number of Points,DC Squid Drift,DC Min V (V),DC Max V (V),DC Scans per Measure,Map 01,Map 02,Map 03,Map 04,Map 05,Map 06,Map 07,Map 08,Map 09,Map 10,Map 11,Map 12,Map 13,Map 14,Map 15,Map 16
,3754349515.5173,56.9781684875488,220.379837036133,,,5,,,,3.65000008605421,,,,,0.000561881073832043,3.92348824736179E-7,0.320351668523059,0.000158206410418447,0.000561808508237578,3.922981538255E-7,0.000561799726794293,3.82341487825039E-7,3.14116252219971E-6,8.78227088094589E-8,1.00012916428534,10.005763053894,2,20,1,3,1.83708804588728,0.172015455019112,0.0404026173055172,172.741912841797,56.937141418457,56.9815216064453,220.379837036133,220.379837036133,,,86.5052490234375,0,1,,,,,,1,1,1,56.9764442443848,0,56.960412642535,,,,,,,,,,,,,,,,,,,,,,,,,,,,,,,,,
,3754349546.58611,56.9053478240967,239.941909790039,,,5,,,,3.65000008605421,,,,,0.00056621489674849,9.63727957764025E-7,0.738250007766623,0.000317686855470615,0.000566141773148912,9.63603497496924E-7,0.000566094778235666,9.47994132215418E-7,7.29447451883856E-6,1.72739183955005E-7,1.00012916128618,10.005763053894,2,20,10,3,1.84994116397752,0.186878893474216,0.0404026173055172,172.741912841797,56.8956909179687,56.9096794128418,239.941909790039,239.941909790039,,,86.5549926757812,0,1,,,,,,1,1,1,56.9030838012695,0,56.9010630520907,,,,,,,,,,,,,,,,,,,,,,,,,,,,,,,,,
,3754349572.49007,56.9057941436768,260.026092529297,,,5,,,,3.65000008605421,,,,,0.000484873160376074,6.83109203504581E-7,0.270450642966531,0.00021527680815231,0.000484810309170519,6.83020656147303E-7,0.000484804908199885,6.75384860720158E-7,2.28841939226972E-6,1.01845503749088E-7,1.00012964081903,10.005763053894,2,20,1,3,1.585432403675,0.147126720778021,0.0404026173055172,172.741912841797,56.9006195068359,56.9332504272461,260.026092529297,260.026092529297,,,86.6544876098633,0,1,,,,,,1,1,1,56.9083137512207,0,56.9149260748,,,,,,,,,,,,,,,,,,,,,,,,,,,,,,,,,
,3754349605.7541,56.9452953338623,280.098175048828,,,5,,,,3.65000008605421,,,,,0.00040616370966348,3.08459444410496E-7,0.240985515471036,0.000124341132222397,0.000406111119579603,3.08419505076508E-7,0.000406107527459408,3.04415647115378E-7,1.70809455377509E-6,4.95348857166757E-8,1.00012949678386,10.005763053894,2,20,1,3,1.32813051088652,0.122589133082482,0.0404026173055172,172.741912841797,56.9427452087402,56.9500617980957,280.098175048828,280.098175048828,,,86.7788619995117,0,1,,,,,,1,1,1,56.9459190368652,0,56.9466956002372,,,,,,,,,,,,,,,,,,,,,,,,,,,,,,,,,
,3754349636.81578,56.9917011260986,300.121673583984,,,5,,,,3.65000008605421,,,,,0.000317552189971667,1.17909280151642E-7,0.374578640360808,0.000118589000754876,0.000317510982314144,1.17893979469144E-7,0.000317504197031203,1.11797305457393E-7,2.07575472149988E-6,3.7421289228691E-8,1.0001297834085,10.005763053894,2,20,1,3,1.03814843784152,0.0982872875713843,0.0404026173055172,172.741912841797,56.9836769104004,57.006534576416,300.121673583984,300.121673583984,,,86.9156723022461,0,1,,,,,,1,1,1,56.9935722351074,0,56.9964551058682,,,,,,,,,,,,,,,,,,,,,,,,,,,,,,,,,
,3754349658.95937,57.0520038604736,319.999450683594,,,5,,,,3.65000008605421,,,,,0.000263852021768639,1.22922225817463E-7,0.168898098805694,6.5184882465395E-5,0.000263817842050608,1.22906302319929E-7,0.000263816695803876,1.21746003669297E-7,7.77688475469843E-7,1.68484343638584E-8,1.00012955802293,10.005763053894,2,20,1,3,0.862877113102285,0.0785875162405295,0.0404026173055172,172.741912841797,57.0425567626953,57.0536422729492,319.999450683594,319.999450683594,,,87.0027313232422,0,1,,,,,,1,1,1,57.0532112121582,0,57.0496413286994,,,,,,,,,,,,,,,,,,,,,,,,,,,,,,,,,
,3754349692.99405,57.0428924560547,340.035095214844,,,5,,,,3.65000008605421,,,,,0.000231780138082235,1.20678381414404E-7,0.114059890286248,0.000132178048053063,0.000231750209588073,1.20662798878888E-7,0.000231749750378819,1.16744823828726E-7,4.61349618505038E-7,3.04984777076914E-8,1.00012914117409,10.005763053894,2,20,1,3,0.758056891575098,0.0683257575024346,0.0404026173055172,172.741912841797,57.0255393981934,57.0463829040527,340.035095214844,340.035095214844,,,87.1146621704102,0,1,,,,,,1,1,1,57.0417137145996,0,57.0373093741281,,,,,,,,,,,,,,,,,,,,,,,,,,,,,,,,,
,3754349724.08908,57.0457897186279,360.095031738281,,,5,,,,3.65000008605421,,,,,0.000202185882079849,2.10425716950358E-7,0.256118670520103,0.000175587438869027,0.000202159701734836,2.10398469657853E-7,0.00020215768196872,2.07495570334068E-7,9.03673918876678E-7,3.48296472291434E-8,1.00012950328274,10.005763053894,2,20,1,3,0.66111557634951,0.0612553045376899,0.0404026173055172,172.741912841797,57.0379600524902,57.045841217041,360.095031738281,360.095031738281,,,87.2141571044922,0,1,,,,,,1,1,1,57.045841217041,0,57.0433371407645,,,,,,,,,,,,,,,,,,,,,,,,,,,,,,,,,
,3754349749.89084,57.0576267242432,380.154937744141,,,5,,,,3.65000008605421,,,,,0.000185504808511357,1.36640579401387E-7,0.209809420798085,0.000152609338075092,0.000185480815426517,1.3662290638773E-7,0.000185479571847972,1.33720197723225E-7,6.79204224342065E-7,2.80129839662244E-8,1.00012935615355,10.005763053894,2,20,1,3,0.606615497402211,0.0557242572562671,0.0404026173055172,172.741912841797,57.0512657165527,57.0577201843262,380.154937744141,380.154937744141,,,87.2887802124023,0,1,,,,,,1,1,1,57.0575256347656,0,57.0556209564209,,,,,,,,,,,,,,,,,,,,,,,,,,,,,,,,,
,3754349771.81011,57.0848808288574,400.032684326172,,,5,,,,3.65000008605421,,,,,0.000172641825804009,1.65033924590328E-7,0.156222637623237,0.000125203366704387,0.000172619479307653,1.65012562849178E-7,0.000172618837651734,1.63653348516427E-7,4.70663584264511E-7,2.11359271718711E-8,1.00012945524135,10.005763053894,2,20,1,3,0.564599997792915,0.0513442806468743,0.0404026173055172,172.741912841797,57.0768127441406,57.0855407714844,400.032684326172,400.032684326172,,,87.3758392333984,0,1,,,,,,1,1,1,57.0855598449707,0,57.0827255249023,,,,,,,,,,,,,,,,,,,,,,,,,,,,,,,,,
,3754349793.55555,57.0822010040283,420.104766845703,,,5,,,,3.65000008605421,,,,,0.000162619604085047,1.86807790816634E-7,0.0469976306742286,0.000204203450000903,0.00016259859344282,1.86783655032514E-7,0.000162598538742052,1.83845235394998E-7,1.3337365946988E-7,3.3000957711294E-8,1.00012921785965,10.005763053894,2,20,1,3,0.531914289234901,0.0473611443902171,0.0404026173055172,172.741912841797,57.0683708190918,57.0841255187988,420.104766845703,420.104766845703,,,87.4255905151367,0,1,,,,,,1,1,1,57.0810127258301,0,57.0774421691895,,,,,,,,,,,,,,,,,,,,,,,,,,,,,,,,,
,3754349815.35919,57.0962085723877,440.128265380859,,,5,,,,3.65000008605421,,,,,0.000151557200102279,1.59441208947772E-7,0.0977887087819855,0.000290539026123562,0.000151537591200031,1.59420579990003E-7,0.000151537370489815,1.53262269110252E-7,2.58634375987098E-7,4.3881638432556E-8,1.00012939959051,10.005763053894,2,20,1,3,0.495690146515199,0.0445893920376891,0.0404026173055172,172.741912841797,57.0844306945801,57.096794128418,440.128265380859,440.128265380859,,,87.475341796875,0,1,,,,,,1,1,1,57.0956344604492,0,57.0925731658936,,,,,,,,,,,,,,,,,,,,,,,,,,,,,,,,,
,3754349837.00333,57.0590591430664,460.224609375,,,5,,,,3.65000008605421,,,,,0.000143922228325658,2.74572219635862E-7,-0.0687779509852833,0.000276750660770443,0.000143903653623469,2.74536783155561E-7,0.000143903549943473,2.7163616415651E-7,-1.72742148595644E-7,3.980250780718E-8,1.00012907734947,10.005763053894,2,20,1,3,0.470839335174297,0.0409846439615307,0.0404026173055172,172.741912841797,57.0433082580566,57.0635528564453,460.224609375,460.224609375,,,87.5375289916992,0,1,,,,,,1,1,1,57.0563545227051,0,57.0532108306885,,,,,,,,,,,,,,,,,,,,,,,,,,,,,,,,,
,3754349858.90672,57.0279769897461,480.345245361328,,,5,,,,3.65000008605421,,,,,0.000131192529690683,2.72535542125351E-7,0.0529635624139138,0.000340625590592787,0.000131175588696301,2.72500349396779E-7,0.000131175532651916,2.68868249155845E-7,1.21257194660827E-7,4.43430379793401E-8,1.00012914746219,10.005763053894,2,20,1,3,0.429113388744925,0.0382807321804723,0.0404026173055172,172.741912841797,57.019115447998,57.0307579040527,480.345245361328,480.345245361328,,,87.5624008178711,0,1,,,,,,1,1,1,57.0267562866211,0,57.0247043609619,,,,,,,,,,,,,,,,,,,,,,,,,,,,,,,,,
,3754349880.59282,57.0215950012207,500.320159912109,,,5,,,,3.65000008605421,,,,,0.000122313840925058,3.00987074898908E-7,0.126489710666292,0.000372149267455663,0.000122298026004685,3.009481579081E-7,0.00012229772797851,2.97585022529209E-7,2.69992475712961E-7,4.48658903240427E-8,1.00012931460049,10.005763053894,2,20,1,3,0.400025692637761,0.0362119427774478,0.0404026173055172,172.741912841797,57.0180931091309,57.0223960876465,500.320159912109,500.320159912109,,,87.6245880126953,0,1,,,,,,1,1,1,57.0208396911621,0,57.0202419281006,,,,,,,,,,,,,,,,,,,,,,,,,,,,,,,,,
,3754349902.45286,57.0655574798584,520.331481933594,,,5,,,,3.65000008605421,,,,,0.00011840994726953,2.03951735503368E-7,0.0951009198286261,0.000364067858830772,0.000118394616418272,2.03925329328947E-7,0.000118394453328761,1.99372693027706E-7,1.96514156013467E-7,4.28493782545233E-8,1.00012948942884,10.005763053894,2,20,1,3,0.387276681638662,0.0348522825577267,0.0404026173055172,172.741912841797,57.0594635009766,57.0664825439453,520.331481933594,520.331481933594,,,87.6743316650391,0,1,,,,,,1,1,1,57.0665092468262,0,57.0636079961603,,,,,,,,,,,,,,,,,,,,,,,,,,,,,,,,,
,3754349924.12266,57.0591926574707,540.245727539063,,,5,,,,3.65000008605421,,,,,0.000115342862808843,2.68580248643939E-7,-0.11742548213176,0.000497036746668229,0.000115327949403861,2.68545522212491E-7,0.000115327707198438,2.62340704251727E-7,-2.36360002372588E-7,5.73938358457368E-8,1.00012931301614,10.005763053894,2,20,1,3,0.377368191073846,0.032558034687293,0.0404026173055172,172.741912841797,57.0488777160645,57.0608940124512,540.245727539063,540.245727539063,,,87.7240829467773,0,1,,,,,,1,1,1,57.0581970214844,0,57.0556175231934,,,,,,,,,,,,,,,,,,,,,,,,,,,,,,,,,
,3754349946.05003,57.0537071228027,560.29345703125,,,5,,,,3.65000008605421,,,,,0.000107123065303155,2.40458709360782E-7,0.0355947832431243,0.00069971529458845,0.000107109204687719,2.40427596493638E-7,0.000107109184018492,2.28488402468388E-7,6.65411782746298E-8,7.48229850590816E-8,1.00012940638927,10.005763053894,2,20,1,3,0.350392932497169,0.03118124629112,0.0404026173055172,172.741912841797,57.045238494873,57.0542793273926,560.29345703125,560.29345703125,,,87.7738265991211,0,1,,,,,,1,1,1,57.0531349182129,0,57.0510356903076,,,,,,,,,,,,,,,,,,,,,,,,,,,,,,,,,
,3754349967.63859,57.0314445495605,580.377685546875,,,5,,,,3.65000008605421,,,,,0.000102830093802203,3.99238999517055E-7,-0.113862966358456,0.000815713669293758,0.000102816810762196,3.99187427964344E-7,0.000102816607735236,3.90256365874009E-7,-2.04326033411849E-7,8.39676815185482E-8,1.00012919132492,10.005763053894,2,20,1,3,0.336427383860196,0.0290614105917215,0.0404026173055172,172.741912841797,57.0230178833008,57.0345001220703,580.377685546875,580.377685546875,,,87.8360137939453,0,1,,,,,,1,1,1,57.0299415588379,0,57.0283657073975,,,,,,,,,,,,,,,,,,,,,,,,,,,,,,,,,
,3754349989.55804,57.0399723052978,600.4619140625,,,5,,,,3.65000008605421,,,,,9.456601731019E-5,2.49140724635127E-7,0.169864214344764,0.000732098696387264,9.4553775745548E-5,2.49108473384918E-7,9.45533602110484E-5,2.39390179982898E-7,2.80322205905711E-7,6.89011846046196E-8,1.00012946669285,10.005763053894,2,20,1,3,0.309253379504916,0.0282642534534381,0.0404026173055172,172.741912841797,57.0376510620117,57.0415153503418,600.4619140625,600.4619140625,,,87.8733291625977,0,1,,,,,,1,1,1,57.040885925293,0,57.0398937225342,,,,,,,,,,,,,,,,,,,,,,,,,,,,,,,,,
,3754350011.1614,57.0699710845947,620.266845703125,,,5,,,,3.65000008605421,,,,,9.54079869323638E-5,2.34610379460012E-7,-0.0753682996009415,0.00077946482904519,9.53956368421113E-5,2.34580010311121E-7,9.53955543085428E-5,2.22486006557058E-7,-1.25485767464347E-7,7.43488945705219E-8,1.00012946179366,10.005763053894,2,20,1,3,0.312125610429134,0.0271868288909449,0.0404026173055172,172.741912841797,57.0632400512695,57.0705490112305,620.266845703125,620.266845703125,,,87.9355163574219,0,1,,,,,,1,1,1,57.0705490112305,0,57.0680934906006,,,,,,,,,,,,,,,,,,,,,,,,,,,,,,,,,
,3754350033.07019,57.0440731048584,640.290283203125,,,5,,,,3.65000008605421,,,,,9.21568607915978E-5,3.6043734202019E-7,-0.25484041910155,0.00078921592269722,9.21449666815242E-5,3.60390822625066E-7,9.21440552327563E-5,3.52882286498326E-7,-4.09841435129497E-7,7.31822171574807E-8,1.00012908040994,10.005763053894,2,20,1,3,0.301570009596725,0.0253223729955898,0.0404026173055172,172.741912841797,57.0313987731934,57.0482063293457,640.290283203125,640.290283203125,,,87.9852600097656,0,1,,,,,,1,1,1,57.0423011779785,0,57.0392355485396,,,,,,,,,,,,,,,,,,,,,,,,,,,,,,,,,
,3754350056.1348,57.0599594116211,660.423095703125,,,5,,,,3.65000008605421,,,,,8.43282285491381E-5,3.38370080166944E-7,0.1280883749925,0.00108259620763039,8.43173029108633E-5,3.38326240646506E-7,8.43170922127257E-5,3.25884889050822E-7,1.88496559596355E-7,9.09048084444988E-8,1.00012957765367,10.005763053894,2,20,1,3,0.275790534068375,0.025020957823385,0.0404026173055172,172.741912841797,57.0552864074707,57.0628356933594,660.423095703125,660.423095703125,,,88.0474472045898,0,1,,,,,,1,1,1,57.0615501403809,0,57.0604179382324,,,,,,,,,,,,,,,,,,,,,,,,,,,,,,,,,
,3754350077.77432,57.0410804748535,680.215881347656,,,5,,,,3.65000008605421,,,,,8.70216163193085E-5,3.43711890267366E-7,-0.370653671139431,0.00106832493974985,8.70103769231374E-5,3.43667497686915E-7,8.70085562546021E-5,3.30718453903628E-7,-5.62877247883214E-7,9.34486661969025E-8,1.00012917305462,10.005763053894,2,20,1,3,0.284812734002457,0.023347855310064,0.0404026173055172,172.741912841797,57.0299110412598,57.0442962646484,680.215881347656,680.215881347656,,,88.0847549438477,0,1,,,,,,1,1,1,57.0391998291016,0,57.0368194580078,,,,,,,,,,,,,,,,,,,,,,,,,,,,,,,,,
,3754350099.7648,57.0189762115479,700.300048828125,,,5,,,,3.65000008605421,,,,,8.015732926332E-5,3.53643341520809E-7,-0.237525561561475,0.000907219353057004,8.01469654937479E-5,3.53597617965198E-7,8.01462767908531E-5,3.45957055280036E-7,-3.32256557462354E-7,7.31094476290761E-8,1.00012930956909,10.005763053894,2,20,1,3,0.262295626217761,0.0221213237912659,0.0404026173055172,172.741912841797,57.0147285461426,57.0207977294922,700.300048828125,700.300048828125,,,88.1469421386719,0,1,,,,,,1,1,1,57.0181503295898,0,57.0173599243164,,,,,,,,,,,,,,,,,,,,,,,,,,,,,,,,,
,3754350121.42804,57.0263042449951,720.29931640625,,,5,,,,3.65000008605421,,,,,7.73662286394298E-5,2.5957784909301E-7,-0.186546728934105,0.00104893427220168,7.73562175635928E-5,2.59544260102328E-7,7.73558075532064E-5,2.464981689541E-7,-2.51860154036892E-7,8.12519270807841E-8,1.00012941527071,10.005763053894,2,20,1,3,0.253143001165208,0.0215817114181311,0.0404026173055172,172.741912841797,57.0236015319824,57.0263824462891,720.29931640625,720.29931640625,,,88.1842575073242,0,1,,,,,,1,1,1,57.0262680053711,0,57.0254337310791,,,,,,,,,,,,,,,,,,,,,,,,,,,,,,,,,
,3754350143.32951,57.0344886779785,740.359191894531,,,5,,,,3.65000008605421,,,,,7.54832506679643E-5,3.04970647206757E-7,-0.201197698562752,0.000986670756634108,7.54734896366748E-5,3.04931210272028E-7,7.54730243027225E-5,2.95644752755522E-7,-2.65029315219956E-7,7.46808085527326E-8,1.00012933059458,10.005763053894,2,20,1,3,0.246986943785797,0.0209985892545938,0.0404026173055172,172.741912841797,57.0284156799316,57.034496307373,740.359191894531,740.359191894531,,,88.234001159668,0,1,,,,,,1,1,1,57.034481048584,0,57.0323628512296,,,,,,,,,,,,,,,,,,,,,,,,,,,,,,,,,
,3754350165.02724,57.0650253295898,760.297729492188,,,5,,,,3.65000008605421,,,,,7.37638809617133E-5,2.58703408983207E-7,-0.200358632210436,0.00110771430250835,7.37543238865967E-5,2.58669890574464E-7,7.37538729371073E-5,2.45388281074185E-7,-2.57912283625185E-7,8.18211696400245E-8,1.00012957986207,10.005763053894,2,20,1,3,0.2413604312895,0.0205289572929771,0.0404026173055172,172.741912841797,57.0599212646484,57.0651741027832,760.297729492188,760.297729492188,,,88.2588806152344,0,1,,,,,,1,1,1,57.0648765563965,0,57.0634052276611,,,,,,,,,,,,,,,,,,,,,,,,,,,,,,,,,
,3754350186.97314,57.0682029724121,780.296875,,,5,,,,3.65000008605421,,,,,7.17217508217076E-5,4.07224417546272E-7,-0.337730093157761,0.00123242471267904,7.17124808273429E-5,4.0717178402837E-7,7.17112350003153E-5,3.97309679311518E-7,-4.22706921608555E-7,8.90723325967394E-8,1.00012926612296,10.005763053894,2,20,1,3,0.234725340904453,0.0194029241281466,0.0404026173055172,172.741912841797,57.0593147277832,57.0690765380859,780.296875,780.296875,,,88.3335037231445,0,1,,,,,,1,1,1,57.0674362182617,0,57.0651571100408,,,,,,,,,,,,,,,,,,,,,,,,,,,,,,,,,
,3754350210.06404,57.038537979126,800.381103515625,,,5,,,,3.65000008605421,,,,,7.09583603557689E-5,4.33279367020681E-7,-0.53522187483811,0.00102913951963818,7.09492038831757E-5,4.33223456615911E-7,7.09461083403404E-5,4.26732903491336E-7,-6.62754115125261E-7,7.47100558164136E-8,1.00012905673485,10.005763053894,2,20,1,3,0.232291498107743,0.0184008315617264,0.0404026173055172,172.741912841797,57.0268363952637,57.0429306030273,800.381103515625,800.381103515625,,,88.3708114624023,0,1,,,,,,1,1,1,57.036563873291,0,57.0343922701749,,,,,,,,,,,,,,,,,,,,,,,,,,,,,,,,,