File: Experimental_Data/Supplementary_Fig1_Data/FC_Up_50p5K.dat
[Header]
; MPMS3 Data File (default extension .dat)
; Copyright (c) 2007, Quantum Design, Inc. All rights reserved.
TITLE,FC_50p5K
FILEOPENTIME,3754368912.48233,12/19/2018,8:14 am
BYAPP,SQUID AC,0.9.1.0
INFO,MPMS3 Measurement Release 1.1.16 Build 347, MultiVu Release 2.3.3.2,APPNAME
INFO,0,MOMENT_UNITS
INFO,CoIINO3,SAMPLE_MATERIAL
INFO,40 Hours Pumped Turbo,SAMPLE_COMMENT
INFO,,SAMPLE_MASS
INFO,,SAMPLE_VOLUME
INFO,,SAMPLE_MOLECULAR_WEIGHT
INFO,,SAMPLE_SIZE
INFO,,SAMPLE_SHAPE
INFO,Brass,SAMPLE_HOLDER
INFO,Standard,SAMPLE_HOLDER_DETAIL
INFO,65.37,SAMPLE_OFFSET
DATATYPE,COMMENT,1
DATATYPE,TIME,2
STARTUPAXIS,X,2
STARTUPAXIS,Y1,5
FIELDGROUP, VSM,2,3,4,5,6,8,9,10,11,14,15
FIELDGROUP, DC, 2,3,4,14,56,57,58,59,60,61,62,63,64,65,66,67,68,69
FIELDGROUP, AC, 2,3,4,11,16,17,18,19,20,21,22,23,24,25,26,27,28,29,30
STARTUPGROUP, All
[Data]
Comment,Time Stamp (sec),Temperature (K),Magnetic Field (Oe),Moment (emu),M. Std. Err. (emu),Transport Action,Averaging Time (sec),Frequency (Hz),Peak Amplitude (mm),Center Position (mm),Lockin Signal' (V),Lockin Signal (V),Range,M. Quad. Signal (emu),AC Moment (emu),AC M. Std Err. (emu),AC Phase (deg),AC Phase Std. Err. (deg),AC Susceptibility (emu/Oe),AC Suscept. Std Err. (emu/Oe),AC X' (emu/Oe),AC X' Std Err. (emu/Oe),AC X'' (emu/Oe),AC X'' Std Err. (emu/Oe),AC Drive (Oe),AC Frequency (Hz),AC Averaging Time (sec),AC Cycles,AC Range,AC Measure Type,AC Signal' (V),AC Signal'' (V),AC Trim Coil Ratio,AC Trim Coil Phase,Min. Temperature (K),Max. Temperature (K),Min. Field (Oe),Max. Field (Oe),Mass (grams),Motor Lag (deg),Pressure (Torr),Measure Count,Measurement Number,SQUID Status (code),Motor Status (code),Measure Status (code),Motor Current (amps),Motor Temp. (C),Temp. Status (code),Field Status (code),Chamber Status (code),Chamber Temp (K),Redirection State,Average Temp (K),Rotation Angle (deg),Rotator state,DC Moment Fixed Ctr (emu),DC Moment Err Fixed Ctr (emu),DC Moment Free Ctr (emu),DC Moment Err Free Ctr (emu),DC Fixed Fit,DC Free Fit,DC Calculated Center (mm),DC Calculated Center Err (mm),DC Scan Length (mm),DC Scan Time (s),DC Number of Points,DC Squid Drift,DC Min V (V),DC Max V (V),DC Scans per Measure,Map 01,Map 02,Map 03,Map 04,Map 05,Map 06,Map 07,Map 08,Map 09,Map 10,Map 11,Map 12,Map 13,Map 14,Map 15,Map 16
,3754369053.72763,50.4513931274414,220.391983032227,,,5,,,,3.65000008605421,,,,,0.000665280516540137,3.25687866198162E-8,0.00411869785135632,3.25379643763209E-5,0.000665194240313405,3.25645629698686E-8,0.000665194238594733,2.4333722747222E-8,4.78173804290122E-8,2.16407185342786E-8,1.00012970080242,10.005763053894,2,20,10,3,2.17624517210573,0.191680095700283,0.0404026173055172,172.741912841797,50.420352935791,50.4633903503418,220.391983032227,220.391983032227,,,124.53791809082,0,1,,,,,,1,1,1,50.4451217651367,0,50.4384977167303,,,,,,,,,,,,,,,,,,,,,,,,,,,,,,,,,
,3754369076.68983,50.4014530181885,240.075469970703,,,5,,,,3.65000008605421,,,,,0.000670858724642227,7.01878347410231E-8,0.000250142428243727,6.41177049191327E-5,0.000670771410862977,7.01786996356969E-8,0.000670771410856584,5.5462411524552E-8,2.9284598435543E-9,4.29996603525959E-8,1.00013016920196,10.005763053894,2,20,10,3,2.19450260047678,0.193185501162227,0.0404026173055172,172.741912841797,50.3960037231445,50.4038162231445,240.075469970703,240.075469970703,,,124.52547454834,0,1,,,,,,1,1,1,50.4005355834961,0,50.3992492675781,,,,,,,,,,,,,,,,,,,,,,,,,,,,,,,,,
,3754369098.20139,50.3977375030518,260.135406494141,,,5,,,,3.65000008605421,,,,,0.00067654302117168,4.1644903789367E-8,-0.00364779586676978,4.1189578959361E-5,0.000676454849748596,4.1639476358566E-8,0.000676454848377637,3.09472792279597E-8,-4.30672071184386E-8,2.78587849663669E-8,1.00013034339707,10.005763053894,2,20,10,3,2.21310728764591,0.194719353961699,0.0404026173055172,172.741912841797,50.3961639404297,50.4037628173828,260.135406494141,260.135406494141,,,124.575225830078,0,1,,,,,,1,1,1,50.3983154296875,0,50.3992333845659,,,,,,,,,,,,,,,,,,,,,,,,,,,,,,,,,
,3754369120.23754,50.4129791259766,280.146728515625,,,5,,,,3.65000008605421,,,,,0.000684043758485356,7.43002552132487E-8,-0.00194777051671657,8.37243439209131E-5,0.000683954603325773,7.42905712551269E-8,0.000683954602930563,4.73340052554004E-8,-2.32510426107345E-8,5.72588938409992E-8,1.00013035245197,10.005763053894,2,20,10,3,2.23763488810283,0.196992441619669,0.0404026173055172,172.741912841797,50.4105262756348,50.4200782775879,280.146728515625,280.146728515625,,,124.624977111816,0,1,,,,,,1,1,1,50.4138336181641,0,50.4147510528564,,,,,,,,,,,,,,,,,,,,,,,,,,,,,,,,,
,3754369141.92022,50.4511108398438,300.243103027344,,,5,,,,3.65000008605421,,,,,0.000695771401769177,7.55245534517082E-8,-0.00575528086170429,5.43501593391105E-5,0.000695680541827866,7.55146907921094E-8,0.000695680538318185,6.53745323782392E-8,-6.98801366441786E-8,3.77973417286778E-8,1.00013060583968,10.005763053894,2,20,10,3,2.27600849023647,0.200267352232442,0.0404026173055172,172.741912841797,50.4454193115234,50.4657974243164,300.243103027344,300.243103027344,,,124.724472045898,0,1,,,,,,1,1,1,50.4540863037109,0,50.4561748504639,,,,,,,,,,,,,,,,,,,,,,,,,,,,,,,,,
,3754369163.84075,50.4665393829346,320.133026123047,,,5,,,,3.65000008605421,,,,,0.000711320033894687,1.51118369502132E-7,-0.0146225528467374,8.78310407009561E-5,0.000711227375752691,1.51098684484598E-7,0.000711227352590502,1.37595270264135E-7,-1.81513540150347E-7,6.24368004778888E-8,1.0001302792119,10.005763053894,2,20,10,3,2.32689980050744,0.20443216479333,0.0404026173055172,172.741912841797,50.4642868041992,50.4672012329102,320.133026123047,320.133026123047,,,124.836402893066,0,1,,,,,,1,1,1,50.4661712646484,0,50.4656177520752,,,,,,,,,,,,,,,,,,,,,,,,,,,,,,,,,
,3754369185.47535,50.4918575286865,340.144348144531,,,5,,,,3.65000008605421,,,,,0.000730374803953305,1.38412357329864E-7,-0.0135372766152475,6.29188085163234E-5,0.000730279487936497,1.38394294118337E-7,0.000730279467553105,1.30557344839598E-7,-1.72543168566227E-7,4.59103512614203E-8,1.00013051991516,10.005763053894,2,20,10,3,2.38922542774142,0.210004794270548,0.0404026173055172,172.741912841797,50.4874534606934,50.4989624023438,340.144348144531,340.144348144531,,,124.948341369629,0,1,,,,,,1,1,1,50.4938697814941,0,50.4948993682861,,,,,,,,,,,,,,,,,,,,,,,,,,,,,,,,,
,3754369207.3686,50.547550201416,360.228576660156,,,5,,,,3.65000008605421,,,,,0.000747762005383433,9.68685138598714E-8,-0.0191310593945238,7.16152047204568E-5,0.000747664487877969,9.68558809957226E-8,0.000747664446199714,8.07182323459808E-8,-2.4964514979189E-7,5.35315668591706E-8,1.00013042950019,10.005763053894,2,20,10,3,2.44612074719366,0.214817691729081,0.0404026173055172,172.741912841797,50.5435180664063,50.5489883422852,360.228576660156,360.228576660156,,,125.085151672363,0,1,,,,,,1,1,1,50.548828125,0,50.5470893166282,,,,,,,,,,,,,,,,,,,,,,,,,,,,,,,,,
,3754369230.43054,50.5462627410889,380.264190673828,,,5,,,,3.65000008605421,,,,,0.000759299952394234,1.42852301147059E-7,-0.0228807932660517,0.000103958883428214,0.000759201149128373,1.42833712611863E-7,0.000759201088590976,1.19058949416797E-7,-3.03183309948237E-7,7.89077690868063E-8,1.00013014109103,10.005763053894,2,20,10,3,2.4838753033484,0.218023041363743,0.0404026173055172,172.741912841797,50.5363464355469,50.548713684082,380.264190673828,380.264190673828,,,125.172210693359,0,1,,,,,,1,1,1,50.5452880859375,0,50.5429046630859,,,,,,,,,,,,,,,,,,,,,,,,,,,,,,,,,
,3754369252.01564,50.5493545532227,400.093414306641,,,5,,,,3.65000008605421,,,,,0.000766886573044023,6.62726977718574E-8,-0.031411414193963,5.46007873234505E-5,0.000766786674094486,6.62640647182572E-8,0.000766786558862177,5.13673854936275E-8,-4.20377431226974E-7,4.18606973249902E-8,1.00013028258434,10.005763053894,2,20,10,3,2.50872266790446,0.219881151197218,0.0404026173055172,172.741912841797,50.5406303405762,50.5498313903809,400.093414306641,400.093414306641,,,125.24683380127,0,1,,,,,,1,1,1,50.5488777160645,0,50.5464744567871,,,,,,,,,,,,,,,,,,,,,,,,,,,,,,,,,
,3754369273.98138,50.5547866821289,420.214080810547,,,5,,,,3.65000008605421,,,,,0.000771100330462351,1.22087375536044E-7,-0.0416584585824378,4.96659204293243E-5,0.000770999956333812,1.22071483422604E-7,0.000770999752542593,1.15917121002669E-7,-5.60576489072528E-7,3.82709827865415E-8,1.00013018694452,10.005763053894,2,20,10,3,2.52254333300314,0.220692475719232,0.0404026173055172,172.741912841797,50.5424308776855,50.5554618835449,420.214080810547,420.214080810547,,,125.346328735352,0,1,,,,,,1,1,1,50.5541114807129,0,50.5506813049316,,,,,,,,,,,,,,,,,,,,,,,,,,,,,,,,,
,3754369295.88422,50.5299453735352,440.273956298828,,,5,,,,3.65000008605421,,,,,0.000772632509387658,1.75651673046957E-7,-0.0382298733483015,0.000118917124705696,0.000772532016248728,1.75628826754873E-7,0.00077253184428101,1.49698202614667E-7,-5.1546203225176E-7,9.18473348618851E-8,1.00013008281445,10.005763053894,2,20,10,3,2.52753904983238,0.221336606931859,0.0404026173055172,172.741912841797,50.521900177002,50.5327339172363,440.273956298828,440.273956298828,,,125.408515930176,0,1,,,,,,1,1,1,50.528678894043,0,50.5269879427823,,,,,,,,,,,,,,,,,,,,,,,,,,,,,,,,,
,3754369318.3895,50.5145568847656,460.358184814453,,,5,,,,3.65000008605421,,,,,0.000772959814326268,1.99319787421375E-7,-0.0545166464450082,9.01748170613654E-5,0.000772859202131284,1.99293842991995E-7,0.000772858852280095,1.86719402263516E-7,-7.35371538267851E-7,6.96699409564346E-8,1.00013018179082,10.005763053894,2,20,10,3,2.52866927925795,0.220765997208751,0.0404026173055172,172.741912841797,50.5111465454102,50.516227722168,460.358184814453,460.358184814453,,,125.483139038086,0,1,,,,,,1,1,1,50.5138816833496,0,50.5133625377308,,,,,,,,,,,,,,,,,,,,,,,,,,,,,,,,,
,3754369340.54078,50.5287990570068,480.490966796875,,,5,,,,3.65000008605421,,,,,0.000772715074304051,1.48104062478189E-7,-0.0639945416648606,8.30454212448349E-5,0.000772614433668203,1.48084772978715E-7,0.000772613951749948,1.33468248607456E-7,-8.62944822574878E-7,6.4150811388602E-8,1.00013025984432,10.005763053894,2,20,10,3,2.52790178305849,0.220332340741238,0.0404026173055172,172.741912841797,50.5238342285156,50.5290489196777,480.490966796875,480.490966796875,,,125.557754516602,0,1,,,,,,1,1,1,50.5288047790527,0,50.5269989013672,,,,,,,,,,,,,,,,,,,,,,,,,,,,,,,,,
,3754369363.56179,50.5162544250488,500.490203857422,,,5,,,,3.65000008605421,,,,,0.000771619833021569,1.43235279611874E-7,-0.0716687617077989,9.45372894388542E-5,0.000771519423832823,1.43216640720531E-7,0.000771518820257676,1.23257801232714E-7,-9.65059342771063E-7,7.29281880657297E-8,1.00013014473213,10.005763053894,2,20,10,3,2.52434489726332,0.219736017204179,0.0404026173055172,172.741912841797,50.511775970459,50.5183029174805,500.490203857422,500.490203857422,,,125.632377624512,0,1,,,,,,1,1,1,50.5154151916504,0,50.5144629044966,,,,,,,,,,,,,,,,,,,,,,,,,,,,,,,,,
,3754369386.65606,50.5533790588379,520.197937011719,,,5,,,,3.65000008605421,,,,,0.000768038203894867,1.9264740876856E-7,-0.0803189352039659,0.000123607229881261,0.000767938013509356,1.92622277963798E-7,0.000767937258961623,1.67614947553709E-7,-1.07651809383526E-6,9.49134939011838E-8,1.00013046676131,10.005763053894,2,20,10,3,2.51265742019019,0.218389565331954,0.0404026173055172,172.741912841797,50.5484809875488,50.5544204711914,520.197937011719,520.197937011719,,,125.707000732422,0,1,,,,,,1,1,1,50.5543479919434,0,50.5522319793701,,,,,,,,,,,,,,,,,,,,,,,,,,,,,,,,,
,3754369408.52085,50.5839881896973,540.440002441406,,,5,,,,3.65000008605421,,,,,0.000760740970718278,2.95181978402335E-7,-0.0945452330741103,0.000167384927231703,0.000760641888653033,2.95143532674855E-7,0.000760640853071844,2.66269743261042E-7,-1.25515409029015E-6,1.27319003701301E-7,1.0001302611212,10.005763053894,2,20,10,3,2.4888347011468,0.21575045435539,0.0404026173055172,172.741912841797,50.5749092102051,50.5843544006348,540.440002441406,540.440002441406,,,125.769187927246,0,1,,,,,,1,1,1,50.5843849182129,0,50.5815612792969,,,,,,,,,,,,,,,,,,,,,,,,,,,,,,,,,
,3754369430.1609,50.5894088745117,560.475646972656,,,5,,,,3.65000008605421,,,,,0.000746834520029784,2.08780958528313E-7,-0.101825614370774,0.000156372076523147,0.000746737320998724,2.08753786100782E-7,0.000746736141746889,1.730457977668E-7,-1.32709506885932E-6,1.16761702140141E-7,1.00013016495671,10.005763053894,2,20,10,3,2.4433621794937,0.211548417468271,0.0404026173055172,172.741912841797,50.5705032348633,50.5920372009277,560.475646972656,560.475646972656,,,125.856246948242,0,1,,,,,,1,1,1,50.5874862670898,0,50.5832935333252,,,,,,,,,,,,,,,,,,,,,,,,,,,,,,,,,
,3754369453.22509,50.5399742126465,580.207702636719,,,5,,,,3.65000008605421,,,,,0.000717343841825784,2.07691184562198E-7,-0.109598788096218,0.000175480370308899,0.000717250622162098,2.07664194852038E-7,0.000717249309940914,1.65182037660857E-7,-1.37199897931375E-6,1.25854329515328E-7,1.00012996804855,10.005763053894,2,20,10,3,2.34690428543474,0.202926233742108,0.0404026173055172,172.741912841797,50.525634765625,50.5456123352051,580.207702636719,580.207702636719,,,125.881126403809,0,1,,,,,,1,1,1,50.5377616882324,0,50.5344168923118,,,,,,,,,,,,,,,,,,,,,,,,,,,,,,,,,
,3754369476.29699,50.5155906677246,600.267639160156,,,5,,,,3.65000008605421,,,,,0.000616941670750874,2.14885132900354E-7,-0.125242429242937,0.000214147262468295,0.000616861408226015,2.14857176897154E-7,0.000616859934505486,1.69456382785645E-7,-1.34839180834746E-6,1.32091410763228E-7,1.00013011435598,10.005763053894,2,20,10,3,2.01846760105615,0.174016212198394,0.0404026173055172,172.741912841797,50.5104026794434,50.518238067627,600.267639160156,600.267639160156,,,125.955741882324,0,1,,,,,,1,1,1,50.5143623352051,0,50.513684463501,,,,,,,,,,,,,,,,,,,,,,,,,,,,,,,,,
,3754369501.19435,50.5533618927002,620.485412597656,,,5,,,,3.65000008605421,,,,,0.000310266363786662,2.00447255968053E-7,-0.223179839482628,0.000318883474663793,0.000310225889863247,2.00421107832664E-7,0.000310223536374364,1.74282987610422E-7,-1.20839597275015E-6,9.89649467966203E-8,1.00013046597572,10.005763053894,2,20,1,3,1.01525511657173,0.0858011791231208,0.0404026173055172,172.741912841797,50.5432968139648,50.5540428161621,620.485412597656,620.485412597656,,,126.017929077148,0,1,,,,,,1,1,1,50.553165435791,0,50.5506043067345,,,,,,,,,,,,,,,,,,,,,,,,,,,,,,,,,
,3754369524.94969,50.5298919677734,640.229614257812,,,5,,,,3.65000008605421,,,,,0.000133295892374359,2.37411925676116E-7,-0.556911107173722,0.00095305088001981,0.0001332785554505,2.37381047061589E-7,0.000133272259615225,2.00455031255985E-7,-1.29543815906416E-6,1.27151649412103E-7,1.0001300803704,10.005763053894,2,20,1,3,0.436378293991511,0.0343297504049622,0.0404026173055172,172.741912841797,50.521297454834,50.5332679748535,640.229614257812,640.229614257812,,,126.067680358887,0,1,,,,,,1,1,1,50.5282821655273,0,50.5268177032471,,,,,,,,,,,,,,,,,,,,,,,,,,,,,,,,,
,3754369548.18895,50.5107955932617,660.28955078125,,,5,,,,3.65000008605421,,,,,7.039741935324E-5,3.5318974267364E-7,-1.01245090524655,0.00175610471497863,7.03882601228369E-5,3.53143790048404E-7,7.03772710357493E-5,3.30418665873629E-7,-1.24373818822322E-6,1.24635635722863E-7,1.00013012440408,10.005763053894,2,20,1,3,0.230600651586189,0.0163025935583656,0.0404026173055172,172.741912841797,50.5071792602539,50.5129737854004,660.28955078125,660.28955078125,,,126.142303466797,0,1,,,,,,1,1,1,50.5095825195313,0,50.5095773176713,,,,,,,,,,,,,,,,,,,,,,,,,,,,,,,,,
,3754369571.07085,50.5047416687012,680.300903320312,,,5,,,,3.65000008605421,,,,,4.61593625761328E-5,3.6274302866286E-7,-1.62381971073242,0.00368085273392967,4.61533485025956E-5,3.6269576710794E-7,4.61348142745212E-5,3.19971740557483E-7,-1.3078569713408E-6,1.70781453099076E-7,1.00013030633166,10.005763053894,2,20,1,3,0.151309450820603,0.00907881185624455,0.0404026173055172,172.741912841797,50.5028991699219,50.5053100585937,680.300903320312,680.300903320312,,,126.192047119141,0,1,,,,,,1,1,1,50.5047149658203,0,50.5044933319092,,,,,,,,,,,,,,,,,,,,,,,,,,,,,,,,,
,3754369594.13887,50.5453834533691,700.215087890625,,,5,,,,3.65000008605421,,,,,3.41722984161273E-5,3.39859640484438E-7,-2.27747912355208,0.0043629673345051,3.41678453091839E-5,3.39815352233575E-7,3.41408558639694E-5,3.04740658713099E-7,-1.357797462065E-6,1.5035825398273E-7,1.00013033034138,10.005763053894,2,20,1,3,0.112085431842078,0.0054451800042178,0.0404026173055172,172.741912841797,50.5410690307617,50.5460815429687,700.215087890625,700.215087890625,,,126.266670227051,0,1,,,,,,1,1,1,50.5456771850586,0,50.5442549965598,,,,,,,,,,,,,,,,,,,,,,,,,,,,,,,,,
,3754369617.18018,50.5256862640381,720.275024414062,,,5,,,,3.65000008605421,,,,,2.8107011148259E-5,3.36978699796318E-7,-2.96775092542262,0.00635206460562608,2.81033544131124E-5,3.36934858711661E-7,2.8065663149522E-5,2.8519554095741E-7,-1.45501932858721E-6,1.79411823559811E-7,1.00013011739072,10.005763053894,2,20,1,3,0.0922384820930188,0.00336971497687977,0.0404026173055172,172.741912841797,50.5175895690918,50.5295257568359,720.275024414062,720.275024414062,,,126.316421508789,0,1,,,,,,1,1,1,50.5239868164063,0,50.5231916254217,,,,,,,,,,,,,,,,,,,,,,,,,,,,,,,,,
,3754369640.22633,50.509147644043,740.249938964844,,,5,,,,3.65000008605421,,,,,2.37591048344636E-5,3.79079367838848E-7,-3.47607208564214,0.00489978280853853,2.37560126631929E-5,3.79030031875279E-7,2.37123065061153E-5,3.59577537739018E-7,-1.44036724963682E-6,1.19865588960802E-7,1.00013016373221,10.005763053894,2,20,1,3,0.0779922030514399,0.0021582730993387,0.0404026173055172,172.741912841797,50.5065803527832,50.5105857849121,740.249938964844,740.249938964844,,,126.378608703613,0,1,,,,,,1,1,1,50.5086936950684,0,50.5082740783691,,,,,,,,,,,,,,,,,,,,,,,,,,,,,,,,,
,3754369663.34077,50.525447845459,760.322021484375,,,5,,,,3.65000008605421,,,,,2.14069545656109E-5,3.94964018737172E-7,-3.91956771224001,0.00903273510780931,2.14041672887344E-5,3.94912592735726E-7,2.13541027702628E-5,3.43476295247295E-7,-1.46310361942811E-6,1.94884556864945E-7,1.00013022122463,10.005763053894,2,20,1,3,0.0702839344482233,0.00140212705996768,0.0404026173055172,172.741912841797,50.521125793457,50.5257377624512,760.322021484375,760.322021484375,,,126.428352355957,0,1,,,,,,1,1,1,50.5253868103027,0,50.5243743260702,,,,,,,,,,,,,,,,,,,,,,,,,,,,,,,,,
,3754369686.37368,50.512882232666,780.39404296875,,,5,,,,3.65000008605421,,,,,2.01909052595892E-5,4.61631284112169E-7,-4.44359519063029,0.0148841861936946,2.01882786605227E-5,4.61571231316897E-7,2.01275945051978E-5,3.50009929642484E-7,-1.56414024602951E-6,3.00900400018113E-7,1.00013010515213,10.005763053894,2,20,1,3,0.0663007100994437,0.000717552332741215,0.0404026173055172,172.741912841797,50.5086326599121,50.515079498291,780.39404296875,780.39404296875,,,126.490539550781,0,1,,,,,,1,1,1,50.5115966796875,0,50.5113159179687,,,,,,,,,,,,,,,,,,,,,,,,,,,,,,,,,
,3754369709.38073,50.5067100524902,800.24755859375,,,5,,,,3.65000008605421,,,,,1.79314719268141E-5,4.40181045753537E-7,-4.99390998416386,0.0114694640841505,1.79291360890597E-5,4.40123705703058E-7,1.78610763053282E-5,3.88035595391129E-7,-1.56072871289918E-6,2.07695096310059E-7,1.00013028166794,10.005763053894,2,20,1,3,0.0588848628361004,7.29392193625347E-5,0.0404026173055172,172.741912841797,50.5063400268555,50.5072059631348,800.24755859375,800.24755859375,,,126.54029083252,0,1,,,,,,1,1,1,50.5068550109863,0,50.5068027496338,,,,,,,,,,,,,,,,,,,,,,,,,,,,,,,,,