File: Experimental_Data/Supplementary_Fig1_Data/FC_Up_53K.dat
[Header]
; MPMS3 Data File (default extension .dat)
; Copyright (c) 2007, Quantum Design, Inc. All rights reserved.
TITLE,FC_53K
FILEOPENTIME,3754361393.40939,12/19/2018,6:09 am
BYAPP,SQUID AC,0.9.1.0
INFO,MPMS3 Measurement Release 1.1.16 Build 347, MultiVu Release 2.3.3.2,APPNAME
INFO,0,MOMENT_UNITS
INFO,CoIINO3,SAMPLE_MATERIAL
INFO,40 Hours Pumped Turbo,SAMPLE_COMMENT
INFO,,SAMPLE_MASS
INFO,,SAMPLE_VOLUME
INFO,,SAMPLE_MOLECULAR_WEIGHT
INFO,,SAMPLE_SIZE
INFO,,SAMPLE_SHAPE
INFO,Brass,SAMPLE_HOLDER
INFO,Standard,SAMPLE_HOLDER_DETAIL
INFO,65.37,SAMPLE_OFFSET
DATATYPE,COMMENT,1
DATATYPE,TIME,2
STARTUPAXIS,X,2
STARTUPAXIS,Y1,5
FIELDGROUP, VSM,2,3,4,5,6,8,9,10,11,14,15
FIELDGROUP, DC, 2,3,4,14,56,57,58,59,60,61,62,63,64,65,66,67,68,69
FIELDGROUP, AC, 2,3,4,11,16,17,18,19,20,21,22,23,24,25,26,27,28,29,30
STARTUPGROUP, All
[Data]
Comment,Time Stamp (sec),Temperature (K),Magnetic Field (Oe),Moment (emu),M. Std. Err. (emu),Transport Action,Averaging Time (sec),Frequency (Hz),Peak Amplitude (mm),Center Position (mm),Lockin Signal' (V),Lockin Signal (V),Range,M. Quad. Signal (emu),AC Moment (emu),AC M. Std Err. (emu),AC Phase (deg),AC Phase Std. Err. (deg),AC Susceptibility (emu/Oe),AC Suscept. Std Err. (emu/Oe),AC X' (emu/Oe),AC X' Std Err. (emu/Oe),AC X'' (emu/Oe),AC X'' Std Err. (emu/Oe),AC Drive (Oe),AC Frequency (Hz),AC Averaging Time (sec),AC Cycles,AC Range,AC Measure Type,AC Signal' (V),AC Signal'' (V),AC Trim Coil Ratio,AC Trim Coil Phase,Min. Temperature (K),Max. Temperature (K),Min. Field (Oe),Max. Field (Oe),Mass (grams),Motor Lag (deg),Pressure (Torr),Measure Count,Measurement Number,SQUID Status (code),Motor Status (code),Measure Status (code),Motor Current (amps),Motor Temp. (C),Temp. Status (code),Field Status (code),Chamber Status (code),Chamber Temp (K),Redirection State,Average Temp (K),Rotation Angle (deg),Rotator state,DC Moment Fixed Ctr (emu),DC Moment Err Fixed Ctr (emu),DC Moment Free Ctr (emu),DC Moment Err Free Ctr (emu),DC Fixed Fit,DC Free Fit,DC Calculated Center (mm),DC Calculated Center Err (mm),DC Scan Length (mm),DC Scan Time (s),DC Number of Points,DC Squid Drift,DC Min V (V),DC Max V (V),DC Scans per Measure,Map 01,Map 02,Map 03,Map 04,Map 05,Map 06,Map 07,Map 08,Map 09,Map 10,Map 11,Map 12,Map 13,Map 14,Map 15,Map 16
,3754361529.40253,52.9699592590332,220.22200012207,,,5,,,,3.65000008605421,,,,,0.000682548069520189,4.15512813376202E-8,0.0192900064271457,2.88886524733622E-5,0.000682459681203917,4.1545900547665E-8,0.000682459642525697,3.65753059510122E-8,2.29766511597673E-7,1.97055537071741E-8,1.00012951434159,10.005763053894,2,20,10,3,2.23267887306883,0.197237810199471,0.0404026173055172,172.741912841797,52.9419326782227,52.976993560791,220.22200012207,220.22200012207,,,109.974060058594,0,1,,,,,,1,1,1,52.9662399291992,0,52.9595756530762,,,,,,,,,,,,,,,,,,,,,,,,,,,,,,,,,
,3754361549.87633,52.9122180938721,239.990478515625,,,5,,,,3.65000008605421,,,,,0.000690741291339041,3.36050056161177E-8,0.020841294806945,2.60273718236129E-5,0.000690651685421389,3.36006462309127E-8,0.000690651639730122,2.83919367524967E-8,2.51224002704637E-7,1.79694561569674E-8,1.00012974111197,10.005763053894,2,20,10,3,2.25947127042477,0.199714578631449,0.0404026173055172,172.741912841797,52.9008636474609,52.9171409606934,239.990478515625,239.990478515625,,,109.974060058594,0,1,,,,,,1,1,1,52.9095649719238,0,52.9075576782227,,,,,,,,,,,,,,,,,,,,,,,,,,,,,,,,,
,3754361572.84767,52.8727207183838,260.013977050781,,,5,,,,3.65000008605421,,,,,0.00069986570944133,3.09114945476781E-8,0.0203266646880724,2.53935274462211E-5,0.000699774980036942,3.0907487233916E-8,0.000699774936000179,2.52920249172061E-8,2.48257222413602E-7,1.77647471893665E-8,1.0001296551134,10.005763053894,2,20,10,3,2.28931673552552,0.202381347276154,0.0404026173055172,172.741912841797,52.8662757873535,52.8782157897949,260.013977050781,260.013977050781,,,109.986503601074,0,1,,,,,,1,1,1,52.8702735900879,0,52.8702423789284,,,,,,,,,,,,,,,,,,,,,,,,,,,,,,,,,
,3754361594.83065,52.9143161773682,279.903900146484,,,5,,,,3.65000008605421,,,,,0.000707114557176628,2.40207210684598E-8,0.0256139766675956,2.46133726034304E-5,0.000707022353751575,2.40175889129522E-8,0.000707022283101619,1.65551526966504E-8,3.16073079433671E-7,1.7400330352673E-8,1.00013041090506,10.005763053894,2,20,10,3,2.31300635473682,0.204740042545973,0.0404026173055172,172.741912841797,52.9048080444336,52.9508743286133,279.903900146484,279.903900146484,,,110.085998535156,0,1,,,,,,1,1,1,52.919792175293,0,52.9282986034046,,,,,,,,,,,,,,,,,,,,,,,,,,,,,,,,,
,3754361616.78382,52.975076675415,299.963806152344,,,5,,,,3.65000008605421,,,,,0.000717792688051643,3.54475868446019E-8,0.0277826540522854,3.36151591870229E-5,0.000717699402901606,3.54429800361009E-8,0.000717699318526413,2.59679821373832E-8,3.48011557088692E-7,2.41219555084572E-8,1.00012997802375,10.005763053894,2,20,10,3,2.34792403881093,0.207970927667162,0.0404026173055172,172.741912841797,52.971752166748,52.9751243591309,299.963806152344,299.963806152344,,,110.173057556152,0,1,,,,,,1,1,1,52.9750595092773,0,52.9737479469993,,,,,,,,,,,,,,,,,,,,,,,,,,,,,,,,,
,3754361639.52545,52.9931793212891,320.023742675781,,,5,,,,3.65000008605421,,,,,0.00073040668771763,3.86646208302441E-8,0.0242791290322222,3.55259129982384E-5,0.00073031174494584,3.86595949640608E-8,0.00073031167937674,2.866419270667E-8,3.09470133914231E-7,2.59408623461157E-8,1.00013000307396,10.005763053894,2,20,10,3,2.38919459158147,0.211530811509385,0.0404026173055172,172.741912841797,52.9872741699219,52.9930076599121,320.023742675781,320.023742675781,,,110.272552490234,0,1,,,,,,1,1,1,52.9928665161133,0,52.9909217834473,,,,,,,,,,,,,,,,,,,,,,,,,,,,,,,,,
,3754361661.13275,52.9938545227051,339.840789794922,,,5,,,,3.65000008605421,,,,,0.00074016982280646,5.23003937186452E-8,0.0215868942749617,3.66296281195947E-5,0.000740073588099465,5.2293593775024E-8,0.000740073535572783,4.47249707898129E-8,2.78831880110547E-7,2.7097913900476E-8,1.00013003397033,10.005763053894,2,20,10,3,2.42113712751138,0.214295861981908,0.0404026173055172,172.741912841797,52.9919815063477,53.0012321472168,339.840789794922,339.840789794922,,,110.384490966797,0,1,,,,,,1,1,1,52.995059967041,0,52.9964984893799,,,,,,,,,,,,,,,,,,,,,,,,,,,,,,,,,
,3754361683.05298,53.0049209594727,359.912841796875,,,5,,,,3.65000008605421,,,,,0.000746414484743527,8.81684875676679E-8,0.00492984236938288,6.78638561888654E-5,0.000746317574056278,8.81570402164997E-8,0.000746317571293701,7.21647995138902E-8,6.4214642410405E-8,5.06350219793926E-8,1.00012985180923,10.005763053894,2,20,10,3,2.44162323094951,0.215446431229033,0.0404026173055172,172.741912841797,53.0042915344238,53.0051498413086,359.912841796875,359.912841796875,,,110.483985900879,0,1,,,,,,1,1,1,53.0048942565918,0,53.0047836303711,,,,,,,,,,,,,,,,,,,,,,,,,,,,,,,,,
,3754361704.74258,53.0292053222656,379.972778320313,,,5,,,,3.65000008605421,,,,,0.000748512266720888,6.07060867276597E-8,-0.0113403165365051,3.23994829633026E-5,0.000748414939125376,6.06981932331682E-8,0.00074841492446593,5.56502844373306E-8,-1.48130670828535E-7,2.42346137541993E-8,1.00013004496627,10.005763053894,2,20,10,3,2.44854336542872,0.215409125841084,0.0404026173055172,172.741912841797,53.0273056030273,53.0303955078125,379.972778320313,379.972778320313,,,110.571044921875,0,1,,,,,,1,1,1,53.0301895141602,0,53.0290988922119,,,,,,,,,,,,,,,,,,,,,,,,,,,,,,,,,
,3754361726.5913,53.033878326416,399.984130859375,,,5,,,,3.65000008605421,,,,,0.000749586886606411,7.51294488141198E-8,-0.0328826848572179,3.57322449452183E-5,0.000749489603032407,7.51196982949682E-8,0.000749489479601227,7.01889982574509E-8,-4.30140392133639E-7,2.67670244058359E-8,1.00012979976455,10.005763053894,2,20,10,3,2.4521363767287,0.214848939180467,0.0404026173055172,172.741912841797,53.0275268554687,53.0355224609375,399.984130859375,399.984130859375,,,110.658103942871,0,1,,,,,,1,1,1,53.0328369140625,0,53.0317420959473,,,,,,,,,,,,,,,,,,,,,,,,,,,,,,,,,
,3754361748.26616,53.0158462524414,419.874053955078,,,5,,,,3.65000008605421,,,,,0.000749684001930212,9.6576666853037E-8,-0.0444787688912278,5.86657074327189E-5,0.000749586722104449,9.65641349578651E-8,0.000749586496237795,8.59757108620319E-8,-5.81904836813454E-7,4.39637271159882E-8,1.00012977794683,10.005763053894,2,20,10,3,2.45249429968839,0.214432684397317,0.0404026173055172,172.741912841797,53.0107154846191,53.0182113647461,419.874053955078,419.874053955078,,,110.745162963867,0,1,,,,,,1,1,1,53.0144157409668,0,53.0138065338135,,,,,,,,,,,,,,,,,,,,,,,,,,,,,,,,,
,3754361770.13134,53.0083084106445,439.970397949219,,,5,,,,3.65000008605421,,,,,0.000747964924840498,1.30134225268637E-7,-0.0500651606020943,8.30708117979414E-5,0.000747867782756037,1.30117324061799E-7,0.000747867497246406,1.14335160870991E-7,-6.53488201160938E-7,6.21127121417813E-8,1.00012989205672,10.005763053894,2,20,10,3,2.44688817988573,0.213755051243843,0.0404026173055172,172.741912841797,53.0054473876953,53.0091247558594,439.970397949219,439.970397949219,,,110.807350158691,0,1,,,,,,1,1,1,53.0077705383301,0,53.0071872364391,,,,,,,,,,,,,,,,,,,,,,,,,,,,,,,,,
,3754361791.804,53.0194549560547,460.248931884766,,,5,,,,3.65000008605421,,,,,0.000742817629788245,1.53229196073003E-7,-0.0523435340051455,8.19020249263612E-5,0.000742721033099162,1.53209270007145E-7,0.000742720723159957,1.40622894946637E-7,-6.7852533947487E-7,6.08135004168434E-8,1.00013005783434,10.005763053894,2,20,10,3,2.43005455822439,0.212240114596915,0.0404026173055172,172.741912841797,53.0167846679687,53.0200233459473,460.248931884766,460.248931884766,,,110.881973266602,0,1,,,,,,1,1,1,53.0200233459473,0,53.0186416625977,,,,,,,,,,,,,,,,,,,,,,,,,,,,,,,,,
,3754361813.7201,53.027494430542,480.296661376953,,,5,,,,3.65000008605421,,,,,0.000733914509171847,1.40667381231976E-7,-0.0635058177558685,0.00010561508773457,0.000733819221336935,1.40649117673983E-7,0.000733818770581674,1.17376485049061E-7,-8.13354501678004E-7,7.74915160517425E-8,1.00012985192012,10.005763053894,2,20,10,3,2.4009665379855,0.209280030209143,0.0404026173055172,172.741912841797,53.024097442627,53.02783203125,480.296661376953,480.296661376953,,,110.931716918945,0,1,,,,,,1,1,1,53.0271949768066,0,53.0263408660889,,,,,,,,,,,,,,,,,,,,,,,,,,,,,,,,,
,3754361835.61522,53.0180797576904,500.125915527344,,,5,,,,3.65000008605421,,,,,0.00071116715787537,1.47109418371894E-7,-0.0710422745580903,0.000107420386685903,0.000711074803373889,1.47090314259948E-7,0.000711074256768777,1.25708126141791E-7,-8.81676781394856E-7,7.63742598720917E-8,1.0001298801491,10.005763053894,2,20,10,3,2.32657329519657,0.202536867456343,0.0404026173055172,172.741912841797,53.0135040283203,53.0195655822754,500.125915527344,500.125915527344,,,111.006340026855,0,1,,,,,,1,1,1,53.017276763916,0,53.0163414001465,,,,,,,,,,,,,,,,,,,,,,,,,,,,,,,,,
,3754361857.32269,53.0325946807861,520.185791015625,,,5,,,,3.65000008605421,,,,,0.000626997106837784,1.29182267600894E-7,-0.0834995085609336,0.000108431068680742,0.000626915626273589,1.29165479893369E-7,0.000626914960538272,1.09834809411075E-7,-9.13629740590874E-7,6.79708454980321E-8,1.00012997054273,10.005763053894,2,20,10,3,2.05124826459942,0.178163672491507,0.0404026173055172,172.741912841797,53.0294723510742,53.0331420898438,520.185791015625,520.185791015625,,,111.06852722168,0,1,,,,,,1,1,1,53.0329971313477,0,53.0316715240479,,,,,,,,,,,,,,,,,,,,,,,,,,,,,,,,,
,3754361881.34679,53.0585994720459,540.257873535156,,,5,,,,3.65000008605421,,,,,0.000389589224496236,2.10538553356374E-7,-0.120429492599944,0.000125725569090774,0.00038953857945375,2.10511184185695E-7,0.000389537718973773,2.04722178511634E-7,-8.18767094679503E-7,4.90284437109151E-8,1.00013001290542,10.005763053894,2,20,1,3,1.27462751179667,0.109909095823008,0.0404026173055172,172.741912841797,53.0493965148926,53.0590057373047,540.257873535156,540.257873535156,,,111.14315032959,0,1,,,,,,1,1,1,53.0585479736328,0,53.0560223506047,,,,,,,,,,,,,,,,,,,,,,,,,,,,,,,,,
,3754361903.51602,53.0333557128906,560.354187011719,,,5,,,,3.65000008605421,,,,,0.000154787056650586,1.58900408455197E-7,-0.320124581848906,0.000485979651773112,0.000154766971635219,1.58879789695369E-7,0.00015476455595222,1.39914247640527E-7,-8.64713853731501E-7,7.52780903107263E-8,1.00012977585046,10.005763053894,2,20,1,3,0.506568670321757,0.0419134078095344,0.0404026173055172,172.741912841797,53.0263977050781,53.0361557006836,560.354187011719,560.354187011719,,,111.192901611328,0,1,,,,,,1,1,1,53.0322113037109,0,53.0310302734375,,,,,,,,,,,,,,,,,,,,,,,,,,,,,,,,,
,3754361925.2237,53.0175685882568,580.207702636719,,,5,,,,3.65000008605421,,,,,7.23291090725903E-5,2.4148390967035E-7,-0.729268130295401,0.00155986842958749,7.23197178684412E-5,2.41452555424134E-7,7.23138598589721E-5,2.1333190953179E-7,-9.20469916877668E-7,1.13087722129171E-7,1.00012985675865,10.005763053894,2,20,1,3,0.236843677033704,0.0178995821503749,0.0404026173055172,172.741912841797,53.0116195678711,53.0196113586426,580.207702636719,580.207702636719,,,111.267524719238,0,1,,,,,,1,1,1,53.0163917541504,0,53.015295791626,,,,,,,,,,,,,,,,,,,,,,,,,,,,,,,,,
,3754361947.11186,53.0577125549316,600.255493164062,,,5,,,,3.65000008605421,,,,,4.95125382421203E-5,2.81163711279766E-7,-0.985800156583742,0.00275224999753603,4.95061038188874E-5,2.81127172528566E-7,4.94987764080962E-5,2.45679315813689E-7,-8.51733190470683E-7,1.36653433602027E-7,1.00012997232132,10.005763053894,2,20,1,3,0.162183261471288,0.0115305105734368,0.0404026173055172,172.741912841797,53.0521125793457,53.0578460693359,600.255493164062,600.255493164062,,,111.317268371582,0,1,,,,,,1,1,1,53.0575790405273,0,53.0559307098389,,,,,,,,,,,,,,,,,,,,,,,,,,,,,,,,,
,3754361968.96764,53.078685760498,620.254699707031,,,5,,,,3.65000008605421,,,,,4.16419386711896E-5,2.87184766540338E-7,-1.54671096153537,0.00242254900883735,4.16365301191738E-5,2.8714746631375E-7,4.16213599221417E-5,2.68388265195506E-7,-1.12384989940803E-6,1.02085290398533E-7,1.0001298992015,10.005763053894,2,20,1,3,0.136490623190068,0.00836472954594031,0.0404026173055172,172.741912841797,53.0669136047363,53.0794105529785,620.254699707031,620.254699707031,,,111.36701965332,0,1,,,,,,1,1,1,53.0779876708984,0,53.0748302459717,,,,,,,,,,,,,,,,,,,,,,,,,,,,,,,,,
,3754361990.65269,53.0856494903564,640.205322265625,,,5,,,,3.65000008605421,,,,,3.6476421635457E-5,2.51327788428867E-7,-1.7911179007034,0.00322559938264082,3.64716849272831E-5,2.51295151828663E-7,3.64538655079626E-5,2.21697997061195E-7,-1.13995217548169E-6,1.18318432341056E-7,1.00012987357681,10.005763053894,2,20,1,3,0.119589591932395,0.0068195976593881,0.0404026173055172,172.741912841797,53.0718612670898,53.0862503051758,640.205322265625,640.205322265625,,,111.416763305664,0,1,,,,,,1,1,1,53.0850486755371,0,53.0814571380615,,,,,,,,,,,,,,,,,,,,,,,,,,,,,,,,,
,3754362012.2863,53.046854019165,660.253112792969,,,5,,,,3.65000008605421,,,,,3.32787339615083E-5,3.40453186278504E-7,-1.8534368368759,0.00336533866433152,3.32744181042375E-5,3.40409033536363E-7,3.3257009942315E-5,3.20808976643055E-7,-1.07619230269093E-6,1.13841603196707E-7,1.00012970496606,10.005763053894,2,20,1,3,0.109112460950971,0.00610543109433971,0.0404026173055172,172.741912841797,53.0317840576172,53.0509262084961,660.253112792969,660.253112792969,,,111.466514587402,0,1,,,,,,1,1,1,53.0447578430176,0,53.0414291381836,,,,,,,,,,,,,,,,,,,,,,,,,,,,,,,,,
,3754362034.2134,53.0204982757568,680.252319335938,,,5,,,,3.65000008605421,,,,,2.95820672196214E-5,3.36562513639201E-7,-2.12452840597171,0.00334218075809306,2.95782291101202E-5,3.36518846515746E-7,2.95578974785304E-5,3.20920424269361E-7,-1.09650989026578E-6,1.01267049661092E-7,1.00012976130136,10.005763053894,2,20,1,3,0.0970165759518931,0.0049703346096264,0.0404026173055172,172.741912841797,53.0159454345703,53.0225677490234,680.252319335938,680.252319335938,,,111.528701782227,0,1,,,,,,1,1,1,53.0197372436523,0,53.0190803527832,,,,,,,,,,,,,,,,,,,,,,,,,,,,,,,,,
,3754362056.13969,53.0307350158691,700.263671875,,,5,,,,3.65000008605421,,,,,2.80421415463135E-5,3.18697211419718E-7,-2.17194882431992,0.00496430935521871,2.80384997532411E-5,3.18655822665766E-7,2.80183566359759E-5,2.86074587031626E-7,-1.0626193258962E-6,1.40366890588489E-7,1.00012988544696,10.005763053894,2,20,1,3,0.0919700957740221,0.00463744830658981,0.0404026173055172,172.741912841797,53.0269317626953,53.0308647155762,700.263671875,700.263671875,,,111.603324890137,0,1,,,,,,1,1,1,53.0308036804199,0,53.0295032501221,,,,,,,,,,,,,,,,,,,,,,,,,,,,,,,,,
,3754362077.7943,53.0526371002197,720.1171875,,,5,,,,3.65000008605421,,,,,2.68644096905145E-5,3.50235637573488E-7,-2.54564360829858,0.00511581384083778,2.68609185878885E-5,3.50190123506062E-7,2.68344110518121E-5,3.21329891828731E-7,-1.19303431952209E-6,1.39212870161228E-7,1.00012996959186,10.005763053894,2,20,1,3,0.0881345450075777,0.00386980440464125,0.0404026173055172,172.741912841797,53.0464057922363,53.0529289245605,720.1171875,720.1171875,,,111.640632629395,0,1,,,,,,1,1,1,53.0529174804687,0,53.0507987976074,,,,,,,,,,,,,,,,,,,,,,,,,,,,,,,,,
,3754362099.41647,53.028076171875,740.249938964844,,,5,,,,3.65000008605421,,,,,2.65995130464725E-5,3.34090251314211E-7,-2.9772116542244,0.00562236956135039,2.65960648926224E-5,3.34046942454219E-7,2.65601674240987E-5,2.9798453196029E-7,-1.38136677838409E-6,1.50972111581642E-7,1.0001296490238,10.005763053894,2,20,1,3,0.0872918593595851,0.0031761167489471,0.0404026173055172,172.741912841797,53.0191917419434,53.0316162109375,740.249938964844,740.249938964844,,,111.690383911133,0,1,,,,,,1,1,1,53.0260887145996,0,53.0245624542236,,,,,,,,,,,,,,,,,,,,,,,,,,,,,,,,,
,3754362121.32339,53.0124568939209,760.285583496094,,,5,,,,3.65000008605421,,,,,2.4285741186453E-5,3.32729555610506E-7,-3.08228753247833,0.00563180525039278,2.42825880348446E-5,3.32686355498746E-7,2.42474594002069E-5,3.02480815613751E-7,-1.30567771877094E-6,1.38511975369201E-7,1.0001298523701,10.005763053894,2,20,1,3,0.0797039028009904,0.00275538301278001,0.0404026173055172,172.741912841797,53.0096893310547,53.0138320922852,760.285583496094,760.285583496094,,,111.740135192871,0,1,,,,,,1,1,1,53.0118179321289,0,53.0114032745361,,,,,,,,,,,,,,,,,,,,,,,,,,,,,,,,,
,3754362142.96855,53.0061492919922,780.260498046875,,,5,,,,3.65000008605421,,,,,2.28883127237181E-5,3.13707317268454E-7,-3.36130914889504,0.00567873579651029,2.28853397346344E-5,3.13666569466684E-7,2.28459689150018E-5,2.84693455808832E-7,-1.34181932629019E-6,1.31667585307175E-7,1.00012990801614,10.005763053894,2,20,1,3,0.0751294011779678,0.00223259879163296,0.0404026173055172,172.741912841797,53.0046577453613,53.0065536499023,780.260498046875,780.260498046875,,,111.789878845215,0,1,,,,,,1,1,1,53.0059242248535,0,53.0055721282959,,,,,,,,,,,,,,,,,,,,,,,,,,,,,,,,,
,3754362164.88354,53.0023498535156,800.174682617187,,,5,,,,3.65000008605421,,,,,2.19046113002512E-5,3.81302643639789E-7,-3.57715657966902,0.00611582531345422,2.19017673794852E-5,3.81253138332824E-7,2.18590957990388E-5,3.55853703334629E-7,-1.36650839497217E-6,1.36828715230602E-7,1.00012984891661,10.005763053894,2,20,1,3,0.0719080040186913,0.00186729447453654,0.0404026173055172,172.741912841797,53.001594543457,53.0032653808594,800.174682617187,800.174682617187,,,111.839630126953,0,1,,,,,,1,1,1,53.0023994445801,0,53.0022533416748,,,,,,,,,,,,,,,,,,,,,,,,,,,,,,,,,