File: Experimental_Data/Supplementary_Fig1_Data/FC_Up_54p5K.dat
[Header]
; MPMS3 Data File (default extension .dat)
; Copyright (c) 2007, Quantum Design, Inc. All rights reserved.
TITLE,FC_54p5K
FILEOPENTIME,3754356917.33808,12/19/2018,4:54 am
BYAPP,SQUID AC,0.9.1.0
INFO,MPMS3 Measurement Release 1.1.16 Build 347, MultiVu Release 2.3.3.2,APPNAME
INFO,0,MOMENT_UNITS
INFO,CoIINO3,SAMPLE_MATERIAL
INFO,40 Hours Pumped Turbo,SAMPLE_COMMENT
INFO,,SAMPLE_MASS
INFO,,SAMPLE_VOLUME
INFO,,SAMPLE_MOLECULAR_WEIGHT
INFO,,SAMPLE_SIZE
INFO,,SAMPLE_SHAPE
INFO,Brass,SAMPLE_HOLDER
INFO,Standard,SAMPLE_HOLDER_DETAIL
INFO,65.37,SAMPLE_OFFSET
DATATYPE,COMMENT,1
DATATYPE,TIME,2
STARTUPAXIS,X,2
STARTUPAXIS,Y1,5
FIELDGROUP, VSM,2,3,4,5,6,8,9,10,11,14,15
FIELDGROUP, DC, 2,3,4,14,56,57,58,59,60,61,62,63,64,65,66,67,68,69
FIELDGROUP, AC, 2,3,4,11,16,17,18,19,20,21,22,23,24,25,26,27,28,29,30
STARTUPGROUP, All
[Data]
Comment,Time Stamp (sec),Temperature (K),Magnetic Field (Oe),Moment (emu),M. Std. Err. (emu),Transport Action,Averaging Time (sec),Frequency (Hz),Peak Amplitude (mm),Center Position (mm),Lockin Signal' (V),Lockin Signal (V),Range,M. Quad. Signal (emu),AC Moment (emu),AC M. Std Err. (emu),AC Phase (deg),AC Phase Std. Err. (deg),AC Susceptibility (emu/Oe),AC Suscept. Std Err. (emu/Oe),AC X' (emu/Oe),AC X' Std Err. (emu/Oe),AC X'' (emu/Oe),AC X'' Std Err. (emu/Oe),AC Drive (Oe),AC Frequency (Hz),AC Averaging Time (sec),AC Cycles,AC Range,AC Measure Type,AC Signal' (V),AC Signal'' (V),AC Trim Coil Ratio,AC Trim Coil Phase,Min. Temperature (K),Max. Temperature (K),Min. Field (Oe),Max. Field (Oe),Mass (grams),Motor Lag (deg),Pressure (Torr),Measure Count,Measurement Number,SQUID Status (code),Motor Status (code),Measure Status (code),Motor Current (amps),Motor Temp. (C),Temp. Status (code),Field Status (code),Chamber Status (code),Chamber Temp (K),Redirection State,Average Temp (K),Rotation Angle (deg),Rotator state,DC Moment Fixed Ctr (emu),DC Moment Err Fixed Ctr (emu),DC Moment Free Ctr (emu),DC Moment Err Free Ctr (emu),DC Fixed Fit,DC Free Fit,DC Calculated Center (mm),DC Calculated Center Err (mm),DC Scan Length (mm),DC Scan Time (s),DC Number of Points,DC Squid Drift,DC Min V (V),DC Max V (V),DC Scans per Measure,Map 01,Map 02,Map 03,Map 04,Map 05,Map 06,Map 07,Map 08,Map 09,Map 10,Map 11,Map 12,Map 13,Map 14,Map 15,Map 16
,3754357051.27651,54.473201751709,220.391983032227,,,5,,,,3.65000008605421,,,,,0.00066081632524272,1.03977700346742E-7,0.0763805002111679,5.47749059428357E-5,0.000660730875069846,1.0396425498813E-7,0.000660730287966882,9.74840748852896E-8,8.80814262829503E-7,3.61306166429E-8,1.00012932674421,10.005763053894,2,20,10,3,2.16140129516922,0.193107991489431,0.0404026173055172,172.741912841797,54.4473114013672,54.4792518615723,220.391983032227,220.391983032227,,,101.168594360352,0,1,,,,,,1,1,1,54.4697494506836,0,54.4635585784912,,,,,,,,,,,,,,,,,,,,,,,,,,,,,,,,,
,3754357073.18754,54.4184074401855,239.941909790039,,,5,,,,3.65000008605421,,,,,0.000665531626262239,4.04429229378188E-8,0.146211963523752,3.56203828061734E-5,0.000665445478223663,4.04376879071338E-8,0.000665443311503619,3.27701292579097E-8,1.69813527655583E-6,2.36923032163327E-8,1.00012945919898,10.005763053894,2,20,10,3,2.17658251837963,0.197184555745489,0.0404026173055172,172.741912841797,54.403923034668,54.4244918823242,239.941909790039,239.941909790039,,,101.193466186523,0,1,,,,,,1,1,1,54.4159202575684,0,54.4127561395818,,,,,,,,,,,,,,,,,,,,,,,,,,,,,,,,,
,3754357096.23907,54.4000873565674,260.074676513672,,,5,,,,3.65000008605421,,,,,0.000683034430947997,3.97592564394084E-8,0.269937713141301,5.03779281402844E-5,0.00068294580602534,3.97540976057286E-8,0.000682938226582062,1.99021797198006E-8,3.2175519497522E-6,3.44135368546529E-8,1.00012976860225,10.005763053894,2,20,10,3,2.233378997629,0.207241773058146,0.0404026173055172,172.741912841797,54.3993530273438,54.4052772521973,260.074676513672,260.074676513672,,,101.268089294434,0,1,,,,,,1,1,1,54.4003601074219,0,54.401047446511,,,,,,,,,,,,,,,,,,,,,,,,,,,,,,,,,
,3754357119.28051,54.4314193725586,280.037475585938,,,5,,,,3.65000008605421,,,,,0.000709940488571771,3.75250903373574E-8,0.381740316989683,3.58473468113524E-5,0.000709848251029054,3.75202149679727E-8,0.000709832495800445,2.75797913850417E-8,4.72941801054609E-6,2.5438585621069E-8,1.00012993980415,10.005763053894,2,20,10,3,2.32092800543591,0.219984239965125,0.0404026173055172,172.741912841797,54.4272117614746,54.4415054321289,280.037475585938,280.037475585938,,,101.330276489258,0,1,,,,,,1,1,1,54.432991027832,0,54.4345644170588,,,,,,,,,,,,,,,,,,,,,,,,,,,,,,,,,
,3754357140.89457,54.441478729248,300.158111572266,,,5,,,,3.65000008605421,,,,,0.000725994548987051,4.00959255446341E-8,0.264533854662629,3.2914090347359E-5,0.000725900308072039,4.00907207166958E-8,0.000725892571234644,3.22044039825728E-8,3.35146019493955E-6,2.38776517210414E-8,1.00012982625019,10.005763053894,2,20,10,3,2.37386353747157,0.220154289614982,0.0404026173055172,172.741912841797,54.4408340454102,54.4422569274902,300.158111572266,300.158111572266,,,101.417335510254,0,1,,,,,,1,1,1,54.4415054321289,0,54.4415501681241,,,,,,,,,,,,,,,,,,,,,,,,,,,,,,,,,
,3754357162.81647,54.4509143829346,320.023742675781,,,5,,,,3.65000008605421,,,,,0.000732030742141572,3.29818523387415E-8,0.131677502624286,2.99156492626853E-5,0.00073193573767094,3.29775718854196E-8,0.000731933804720748,2.46634916966146E-8,1.68213760236798E-6,2.18913778641054E-8,1.00012979892324,10.005763053894,2,20,10,3,2.39410576078789,0.216484782192343,0.0404026173055172,172.741912841797,54.4476165771484,54.4600105285645,320.023742675781,320.023742675781,,,101.529266357422,0,1,,,,,,1,1,1,54.4524841308594,0,54.4531940460205,,,,,,,,,,,,,,,,,,,,,,,,,,,,,,,,,
,3754357184.46258,54.5224151611328,340.047241210937,,,5,,,,3.65000008605421,,,,,0.000730812014792127,6.70297238656126E-8,0.0191710509992458,3.4689028912754E-5,0.00073071687447317,6.70209976416602E-8,0.000730716833569176,6.20519503586687E-8,2.44496371708237E-7,2.53252755477357E-8,1.00013020134375,10.005763053894,2,20,10,3,2.39053651019712,0.211481717160248,0.0404026173055172,172.741912841797,54.5160331726074,54.5335960388184,340.047241210937,340.047241210937,,,101.641204833984,0,1,,,,,,1,1,1,54.5251998901367,0,54.5273971557617,,,,,,,,,,,,,,,,,,,,,,,,,,,,,,,,,
,3754357206.39507,54.5254554748535,360.095031738281,,,5,,,,3.65000008605421,,,,,0.000730464155530893,1.01270686330357E-7,-0.0144124946797728,4.9342458788755E-5,0.000730369545582528,1.01257569719046E-7,0.000730369522475414,9.46369942060799E-8,-1.83721160064894E-7,3.60129803410645E-8,1.00012953709384,10.005763053894,2,20,10,3,2.38951895603045,0.210031759204142,0.0404026173055172,172.741912841797,54.5185241699219,54.5287284851074,360.095031738281,360.095031738281,,,101.72826385498,0,1,,,,,,1,1,1,54.5246047973633,0,54.5228666825728,,,,,,,,,,,,,,,,,,,,,,,,,,,,,,,,,
,3754357229.41079,54.5158367156982,379.9970703125,,,5,,,,3.65000008605421,,,,,0.00072915478389215,6.49557427648167E-8,-0.0240112700277875,3.08898272124589E-5,0.000729060246058277,6.49473209929868E-8,0.000729060182037872,6.09231569013853E-8,-3.05531438283856E-7,2.25060760092748E-8,1.00012967081168,10.005763053894,2,20,10,3,2.38526764769485,0.209306504909835,0.0404026173055172,172.741912841797,54.5125732421875,54.5170707702637,379.9970703125,379.9970703125,,,101.802886962891,0,1,,,,,,1,1,1,54.5149917602539,0,54.5145259857178,,,,,,,,,,,,,,,,,,,,,,,,,,,,,,,,,
,3754357251.0375,54.5437545776367,399.959838867188,,,5,,,,3.65000008605421,,,,,0.000724248954062061,1.09392528432719E-7,-0.0303367054351753,4.3342337879097E-5,0.000724154875253445,1.09378318514032E-7,0.00072415477374714,1.04786373096741E-7,-3.83422170014079E-7,3.13597285413584E-8,1.00012991531485,10.005763053894,2,20,10,3,2.36923914270714,0.207687239787218,0.0404026173055172,172.741912841797,54.5400276184082,54.5490112304687,399.959838867188,399.959838867188,,,101.889945983887,0,1,,,,,,1,1,1,54.5455093383789,0,54.5460357666016,,,,,,,,,,,,,,,,,,,,,,,,,,,,,,,,,
,3754357272.96814,54.5873908996582,420.068359375,,,5,,,,3.65000008605421,,,,,0.000707680346468678,8.10953673617928E-8,-0.0410013995336813,6.57666691534247E-5,0.000707588550044801,8.10848481142909E-8,0.000707588368867878,6.6407338638761E-8,-5.06356988529175E-7,4.65276043723995E-8,1.00012973135853,10.005763053894,2,20,10,3,2.31507285700331,0.202554787676026,0.0404026173055172,172.741912841797,54.5796890258789,54.5879592895508,420.068359375,420.068359375,,,101.977005004883,0,1,,,,,,1,1,1,54.5868225097656,0,54.5847991943359,,,,,,,,,,,,,,,,,,,,,,,,,,,,,,,,,
,3754357294.61357,54.5555629730225,440.298248291016,,,5,,,,3.65000008605421,,,,,0.000663422642335662,7.49221767113583E-8,-0.0432176423839348,4.9457999648098E-5,0.00066333679148416,7.4912481334299E-8,0.000663336602780228,6.73511017017102E-8,-5.0034836352086E-7,3.27980023664184E-8,1.00012942271951,10.005763053894,2,20,10,3,2.17029469281471,0.189850317658415,0.0404026173055172,172.741912841797,54.5446929931641,54.5601997375488,440.298248291016,440.298248291016,,,102.039192199707,0,1,,,,,,1,1,1,54.5528450012207,0,54.55146484375,,,,,,,,,,,,,,,,,,,,,,,,,,,,,,,,,
,3754357316.56331,54.5357475280762,460.212493896484,,,5,,,,3.65000008605421,,,,,0.000543081760049601,1.70755987388716E-7,-0.0464240877677407,6.92869051271713E-5,0.000543011413492053,1.70733868995544E-7,0.000543011235245791,1.66545197437734E-7,-4.39976678470311E-7,3.75865831463016E-8,1.00012954894833,10.005763053894,2,20,10,3,1.7766226379629,0.155351089775778,0.0404026173055172,172.741912841797,54.5264511108398,54.5382308959961,460.212493896484,460.212493896484,,,102.113815307617,0,1,,,,,,1,1,1,54.5342750549316,0,54.5321814797141,,,,,,,,,,,,,,,,,,,,,,,,,,,,,,,,,
,3754357342.87652,54.5349617004395,480.296661376953,,,5,,,,3.65000008605421,,,,,0.000324898802174545,2.37197396354286E-7,-0.0562903361388791,0.000128636811582264,0.000324856729007472,2.37166680187839E-7,0.000324856572229784,2.33463877915624E-7,-3.19155995197559E-7,4.17450823441459E-8,1.00012951299239,10.005763053894,2,20,1,3,1.06287953727399,0.0927786513284381,0.0404026173055172,172.741912841797,54.5272178649902,54.5380897521973,480.296661376953,480.296661376953,,,102.188438415527,0,1,,,,,,1,1,1,54.5336799621582,0,54.5335878644671,,,,,,,,,,,,,,,,,,,,,,,,,,,,,,,,,
,3754357365.24051,54.5163860321045,500.332336425781,,,5,,,,3.65000008605421,,,,,0.000133057127645792,9.68897818965289E-8,-0.213637927080875,0.000308946790485298,0.000133039888180078,9.68772284309416E-8,0.000133038963348142,8.77125453921117E-8,-4.9606271721318E-7,4.11303631068045E-8,1.00012958118012,10.005763053894,2,20,1,3,0.435387536318068,0.0368098263491029,0.0404026173055172,172.741912841797,54.5116691589355,54.5195083618164,500.332336425781,500.332336425781,,,102.250617980957,0,1,,,,,,1,1,1,54.5148468017578,0,54.5145252227783,,,,,,,,,,,,,,,,,,,,,,,,,,,,,,,,,
,3754357386.79308,54.5057792663574,520.343688964844,,,5,,,,3.65000008605421,,,,,7.22763422858665E-5,2.53915434898644E-7,-0.40550363051522,0.000986325242010932,7.22669714500287E-5,2.53882514031568E-7,7.2265161559634E-5,2.43558075706059E-7,-5.11456077549044E-7,7.16644590389888E-8,1.00012966969073,10.005763053894,2,20,1,3,0.236566913754222,0.0192080054155099,0.0404026173055172,172.741912841797,54.5037994384766,54.5069198608398,520.343688964844,520.343688964844,,,102.312805175781,0,1,,,,,,1,1,1,54.505199432373,0,54.5049430847168,,,,,,,,,,,,,,,,,,,,,,,,,,,,,,,,,
,3754357408.69779,54.5527858734131,540.282165527344,,,5,,,,3.65000008605421,,,,,5.80244701602273E-5,2.01094780898995E-7,-0.504563085382448,0.00141882157770737,5.80169355308525E-5,2.01068668215172E-7,5.80146859186154E-5,1.83352651708884E-7,-5.1090718874193E-7,8.25252352262234E-8,1.00012986948218,10.005763053894,2,20,1,3,0.189945426321767,0.0150961230905268,0.0404026173055172,172.741912841797,54.548210144043,54.5541496276855,540.282165527344,540.282165527344,,,102.374992370605,0,1,,,,,,1,1,1,54.5537033081055,0,54.5522415161133,,,,,,,,,,,,,,,,,,,,,,,,,,,,,,,,,
,3754357430.34985,54.5351829528809,560.281372070313,,,5,,,,3.65000008605421,,,,,5.29043738694023E-5,3.46963016263019E-7,-0.741727858088289,0.00189117859635086,5.28975224174749E-5,3.46918082352028E-7,5.28930899741933E-5,3.31881122479699E-7,-6.84770683622926E-7,1.01030076731752E-7,1.00012952311591,10.005763053894,2,20,1,3,0.173239892623279,0.0130507680121744,0.0404026173055172,172.741912841797,54.5266494750977,54.5388412475586,560.281372070313,560.281372070313,,,102.424743652344,0,1,,,,,,1,1,1,54.5328674316406,0,54.5318309783936,,,,,,,,,,,,,,,,,,,,,,,,,,,,,,,,,
,3754357452.30544,54.5163135528564,580.365539550781,,,5,,,,3.65000008605421,,,,,4.75821030759255E-5,2.28832689484345E-7,-0.75702504249996,0.00162729354636125,4.7575938287474E-5,2.28803041674975E-7,4.75717856284149E-5,2.1511696769333E-7,-6.28582578246666E-7,7.79456354785E-8,1.0001295778638,10.005763053894,2,20,1,3,0.15581462582157,0.0116995896863177,0.0404026173055172,172.741912841797,54.511360168457,54.5177154541016,580.365539550781,580.365539550781,,,102.474487304688,0,1,,,,,,1,1,1,54.5157814025879,0,54.514587020874,,,,,,,,,,,,,,,,,,,,,,,,,,,,,,,,,
,3754357473.90667,54.5251121520996,600.413330078125,,,5,,,,3.65000008605421,,,,,4.38616784291192E-5,2.17960599278533E-7,-0.86911630992834,0.00202902722238733,4.38559880744645E-5,2.17932322359932E-7,4.38509426104601E-5,1.98753139620836E-7,-6.65223392331604E-7,8.9396233813589E-8,1.00012975091668,10.005763053894,2,20,1,3,0.143652224632272,0.0105068673953368,0.0404026173055172,172.741912841797,54.5219268798828,54.5254058837891,600.413330078125,600.413330078125,,,102.536674499512,0,1,,,,,,1,1,1,54.5254058837891,0,54.5240474700928,,,,,,,,,,,,,,,,,,,,,,,,,,,,,,,,,
,3754357495.85831,54.5146045684814,620.242553710937,,,5,,,,3.65000008605421,,,,,4.21070537846483E-5,3.12263209750551E-7,-1.10435968330459,0.00246080787729479,4.21015968100022E-5,3.12222741176634E-7,4.20937763743155E-5,2.941525024605E-7,-8.11445932339306E-7,1.04677339496555E-7,1.00012961443412,10.005763053894,2,20,1,3,0.13794574426918,0.0095231905448618,0.0404026173055172,172.741912841797,54.511302947998,54.5155639648438,620.242553710937,620.242553710937,,,102.598861694336,0,1,,,,,,1,1,1,54.5141296386719,0,54.5134437561035,,,,,,,,,,,,,,,,,,,,,,,,,,,,,,,,,
,3754357517.47938,54.5086460113525,640.351013183594,,,5,,,,3.65000008605421,,,,,3.87209412012978E-5,2.94853757665337E-7,-1.00848311160739,0.00252342768824306,3.87159202848021E-5,2.94815524191415E-7,3.87099231974639E-5,2.77828284884019E-7,-6.81417306500341E-7,9.86287859737866E-8,1.00012968609447,10.005763053894,2,20,1,3,0.126837641265409,0.00897235377844154,0.0404026173055172,172.741912841797,54.5072250366211,54.5094413757324,640.351013183594,640.351013183594,,,102.64860534668,0,1,,,,,,1,1,1,54.5082664489746,0,54.5081513144753,,,,,,,,,,,,,,,,,,,,,,,,,,,,,,,,,
,3754357539.46654,54.5058040618897,660.362365722656,,,5,,,,3.65000008605421,,,,,3.74000625630814E-5,3.6497548228644E-7,-1.29458012673846,0.00259502559071138,3.73952177860213E-5,3.64928203626383E-7,3.73856726921986E-5,3.51234055545393E-7,-8.4486129971874E-7,9.90314698826305E-8,1.00012955605949,10.005763053894,2,20,1,3,0.122552499512644,0.00805706239860466,0.0404026173055172,172.741912841797,54.5034141540527,54.5075836181641,660.362365722656,660.362365722656,,,102.710792541504,0,1,,,,,,1,1,1,54.5049667358398,0,54.504906463623,,,,,,,,,,,,,,,,,,,,,,,,,,,,,,,,,
,3754357560.89872,54.5462875366211,680.373779296875,,,5,,,,3.65000008605421,,,,,3.58057749591447E-5,3.14253716951428E-7,-1.1520189344665,0.00408277075723909,3.58011196961725E-5,3.14212859472598E-7,3.57938832397308E-5,2.77838769819245E-7,-7.19787552122958E-7,1.46749238646322E-7,1.00013003121164,10.005763053894,2,20,1,3,0.117308677314703,0.00800801946143796,0.0404026173055172,172.741912841797,54.5402297973633,54.5487289428711,680.373779296875,680.373779296875,,,102.760543823242,0,1,,,,,,1,1,1,54.5472640991211,0,54.5462896173651,,,,,,,,,,,,,,,,,,,,,,,,,,,,,,,,,
,3754357583.04933,54.5409355163574,700.300048828125,,,5,,,,3.65000008605421,,,,,3.54129210763712E-5,3.64253141827561E-7,-1.62687087139142,0.00324397958535635,3.5408333686129E-5,3.64205956470981E-7,3.53940609506563E-5,3.44978001310706E-7,-1.00525810092942E-6,1.16773958315253E-7,1.00012955679538,10.005763053894,2,20,1,3,0.116083160333242,0.00696081528543336,0.0404026173055172,172.741912841797,54.5342903137207,54.543025970459,700.300048828125,700.300048828125,,,102.810287475586,0,1,,,,,,1,1,1,54.5401420593262,0,54.5389850616455,,,,,,,,,,,,,,,,,,,,,,,,,,,,,,,,,
,3754357604.68017,54.528434753418,720.347839355469,,,5,,,,3.65000008605421,,,,,3.35159560229065E-5,3.86983210623983E-7,-1.7449143083908,0.00424654645740529,3.35116143035193E-5,3.86933080097887E-7,3.34960748862198E-5,3.59142963367907E-7,-1.02042169939414E-6,1.43991459251428E-7,1.00012955864638,10.005763053894,2,20,1,3,0.109878194230588,0.00636393995658569,0.0404026173055172,172.741912841797,54.5219192504883,54.5315551757812,720.347839355469,720.347839355469,,,102.860038757324,0,1,,,,,,1,1,1,54.5262832641602,0,54.5259788513184,,,,,,,,,,,,,,,,,,,,,,,,,,,,,,,,,
,3754357626.62487,54.5262413024902,740.371337890625,,,5,,,,3.65000008605421,,,,,3.2188706580652E-5,3.93458845099674E-7,-1.78400840502893,0.00457283261077065,3.21845326389156E-5,3.93407824898194E-7,3.21689324214981E-5,3.6415470660272E-7,-1.00196209833983E-6,1.48865934149539E-7,1.00012968781567,10.005763053894,2,20,1,3,0.105531035059034,0.00604217978250603,0.0404026173055172,172.741912841797,54.521915435791,54.5270614624023,740.371337890625,740.371337890625,,,102.909790039062,0,1,,,,,,1,1,1,54.525749206543,0,54.5247577667236,,,,,,,,,,,,,,,,,,,,,,,,,,,,,,,,,
,3754357648.23582,54.5281085968018,760.297729492188,,,5,,,,3.65000008605421,,,,,3.10228923991686E-5,3.23265998218139E-7,-1.83720576961832,0.00403400985477958,3.10188705392899E-5,3.23224089471152E-7,3.10029253709192E-5,2.97455109283215E-7,-9.94458635864455E-7,1.26468454468954E-7,1.00012965848881,10.005763053894,2,20,1,3,0.101714197276677,0.00573107456459724,0.0404026173055172,172.741912841797,54.5234031677246,54.5286331176758,760.297729492188,760.297729492188,,,102.94709777832,0,1,,,,,,1,1,1,54.5275840759277,0,54.5266807556152,,,,,,,,,,,,,,,,,,,,,,,,,,,,,,,,,
,3754357670.26882,54.5150394439697,780.333312988281,,,5,,,,3.65000008605421,,,,,2.99465922178733E-5,4.62273538040967E-7,-2.29274243688099,0.00470141396459575,2.9942710614582E-5,4.62213619287151E-7,2.99187405922421E-5,4.39175711252781E-7,-1.19786490170077E-6,1.4410456099701E-7,1.00012963433208,10.005763053894,2,20,1,3,0.0982261849630939,0.00475354735912226,0.0404026173055172,172.741912841797,54.5126113891602,54.5164947509766,780.333312988281,780.333312988281,,,103.02172088623,0,1,,,,,,1,1,1,54.513858795166,0,54.5140342712402,,,,,,,,,,,,,,,,,,,,,,,,,,,,,,,,,
,3754357691.86584,54.510383605957,800.393310546875,,,5,,,,3.65000008605421,,,,,2.81964963080989E-5,3.9465549196504E-7,-2.2710586882129,0.00536164667418685,2.81928410827598E-5,3.94604331184683E-7,2.81706967073321E-5,3.63685752609089E-7,-1.11719977678997E-6,1.53118423250999E-7,1.00012965083329,10.005763053894,2,20,1,3,0.0924840448914449,0.00451273245609569,0.0404026173055172,172.741912841797,54.5072937011719,54.5109519958496,800.393310546875,800.393310546875,,,103.071472167969,0,1,,,,,,1,1,1,54.510555267334,0,54.509260559082,,,,,,,,,,,,,,,,,,,,,,,,,,,,,,,,,