File: Experimental_Data/Supplementary_Fig1_Data/FC_Up_51K.dat
[Header]
; MPMS3 Data File (default extension .dat)
; Copyright (c) 2007, Quantum Design, Inc. All rights reserved.
TITLE,FC_51K
FILEOPENTIME,3754367392.45343,12/19/2018,7:49 am
BYAPP,SQUID AC,0.9.1.0
INFO,MPMS3 Measurement Release 1.1.16 Build 347, MultiVu Release 2.3.3.2,APPNAME
INFO,0,MOMENT_UNITS
INFO,CoIINO3,SAMPLE_MATERIAL
INFO,40 Hours Pumped Turbo,SAMPLE_COMMENT
INFO,,SAMPLE_MASS
INFO,,SAMPLE_VOLUME
INFO,,SAMPLE_MOLECULAR_WEIGHT
INFO,,SAMPLE_SIZE
INFO,,SAMPLE_SHAPE
INFO,Brass,SAMPLE_HOLDER
INFO,Standard,SAMPLE_HOLDER_DETAIL
INFO,65.37,SAMPLE_OFFSET
DATATYPE,COMMENT,1
DATATYPE,TIME,2
STARTUPAXIS,X,2
STARTUPAXIS,Y1,5
FIELDGROUP, VSM,2,3,4,5,6,8,9,10,11,14,15
FIELDGROUP, DC, 2,3,4,14,56,57,58,59,60,61,62,63,64,65,66,67,68,69
FIELDGROUP, AC, 2,3,4,11,16,17,18,19,20,21,22,23,24,25,26,27,28,29,30
STARTUPGROUP, All
[Data]
Comment,Time Stamp (sec),Temperature (K),Magnetic Field (Oe),Moment (emu),M. Std. Err. (emu),Transport Action,Averaging Time (sec),Frequency (Hz),Peak Amplitude (mm),Center Position (mm),Lockin Signal' (V),Lockin Signal (V),Range,M. Quad. Signal (emu),AC Moment (emu),AC M. Std Err. (emu),AC Phase (deg),AC Phase Std. Err. (deg),AC Susceptibility (emu/Oe),AC Suscept. Std Err. (emu/Oe),AC X' (emu/Oe),AC X' Std Err. (emu/Oe),AC X'' (emu/Oe),AC X'' Std Err. (emu/Oe),AC Drive (Oe),AC Frequency (Hz),AC Averaging Time (sec),AC Cycles,AC Range,AC Measure Type,AC Signal' (V),AC Signal'' (V),AC Trim Coil Ratio,AC Trim Coil Phase,Min. Temperature (K),Max. Temperature (K),Min. Field (Oe),Max. Field (Oe),Mass (grams),Motor Lag (deg),Pressure (Torr),Measure Count,Measurement Number,SQUID Status (code),Motor Status (code),Measure Status (code),Motor Current (amps),Motor Temp. (C),Temp. Status (code),Field Status (code),Chamber Status (code),Chamber Temp (K),Redirection State,Average Temp (K),Rotation Angle (deg),Rotator state,DC Moment Fixed Ctr (emu),DC Moment Err Fixed Ctr (emu),DC Moment Free Ctr (emu),DC Moment Err Free Ctr (emu),DC Fixed Fit,DC Free Fit,DC Calculated Center (mm),DC Calculated Center Err (mm),DC Scan Length (mm),DC Scan Time (s),DC Number of Points,DC Squid Drift,DC Min V (V),DC Max V (V),DC Scans per Measure,Map 01,Map 02,Map 03,Map 04,Map 05,Map 06,Map 07,Map 08,Map 09,Map 10,Map 11,Map 12,Map 13,Map 14,Map 15,Map 16
,3754367531.78945,50.9483852386475,220.294845581055,,,5,,,,3.65000008605421,,,,,0.00066717780509991,2.28271090966237E-8,0.00478731583753156,2.33349972498555E-5,0.000667091343054737,2.28241508469296E-8,0.000667091340726141,1.66940591385158E-8,5.57384326578722E-8,1.55643904912185E-8,1.00012961050398,10.005763053894,2,20,10,3,2.18244944792134,0.192250278986561,0.0404026173055172,172.741912841797,50.9209938049316,50.9599227905273,220.294845581055,220.294845581055,,,121.577880859375,0,1,,,,,,1,1,1,50.9429244995117,0,50.9373687744141,,,,,,,,,,,,,,,,,,,,,,,,,,,,,,,,,
,3754367552.57014,50.8856391906738,240.026901245117,,,5,,,,3.65000008605421,,,,,0.000673381821893861,2.17647001569001E-8,-0.00281165580734921,2.26918584680972E-5,0.000673294403221162,2.17618746556206E-8,0.000673294402410474,1.54987236983245E-8,-3.30403414387698E-8,1.52764116287149E-8,1.00012983721873,10.005763053894,2,20,10,3,2.20276663307075,0.193792574534863,0.0404026173055172,172.741912841797,50.8707733154297,50.8920631408691,240.026901245117,240.026901245117,,,121.565444946289,0,1,,,,,,1,1,1,50.8820953369141,0,50.8789551474831,,,,,,,,,,,,,,,,,,,,,,,,,,,,,,,,,
,3754367575.32899,50.9025115966797,259.892547607422,,,5,,,,3.65000008605421,,,,,0.000680113009655174,4.28677334185262E-8,0.00138899759222078,5.13753644548791E-5,0.000680024192135288,4.28621352227686E-8,0.000680024191935462,2.48344423368528E-8,1.64855417530292E-8,3.49344115403771E-8,1.00013060935319,10.005763053894,2,20,10,3,2.22476841177819,0.19594007297599,0.0404026173055172,172.741912841797,50.8938751220703,50.9217910766602,259.892547607422,259.892547607422,,,121.627632141113,0,1,,,,,,1,1,1,50.9060173034668,0,50.9091665094549,,,,,,,,,,,,,,,,,,,,,,,,,,,,,,,,,
,3754367598.44175,50.9446353912354,279.964599609375,,,5,,,,3.65000008605421,,,,,0.000691191199678806,5.7368936414421E-8,-0.00232512608697366,4.18349859331068E-5,0.000691101030605432,5.73614523726112E-8,0.000691101030036371,4.95479984514312E-8,-2.80456439935009E-8,2.890211182167E-8,1.00013047162337,10.005763053894,2,20,10,3,2.26101701119718,0.199033554634661,0.0404026173055172,172.741912841797,50.9395065307617,50.9529495239258,279.964599609375,279.964599609375,,,121.714691162109,0,1,,,,,,1,1,1,50.9466819763184,0,50.9472416964444,,,,,,,,,,,,,,,,,,,,,,,,,,,,,,,,,
,3754367620.04347,50.9572792053223,300.012390136719,,,5,,,,3.65000008605421,,,,,0.000705588469985942,8.63955026033857E-8,-0.00942188757373419,3.3963450051005E-5,0.000705496581163605,8.63842513126871E-8,0.000705496571624767,8.30035282385817E-8,-1.16013945493169E-7,2.39301728953314E-8,1.00013024701294,10.005763053894,2,20,10,3,2.30813528961305,0.202942951325567,0.0404026173055172,172.741912841797,50.9565467834473,50.9573783874512,300.012390136719,300.012390136719,,,121.78931427002,0,1,,,,,,1,1,1,50.9573097229004,0,50.9570652008057,,,,,,,,,,,,,,,,,,,,,,,,,,,,,,,,,
,3754367642.04117,50.9582767486572,320.072296142578,,,5,,,,3.65000008605421,,,,,0.000721075704249339,6.89212929541017E-8,-0.00571891868499996,4.97356903916952E-5,0.00072098184833457,6.89123220915984E-8,0.000720981844743061,5.88546860080534E-8,-7.1964053760686E-8,3.58473718834399E-8,1.00013017791639,10.005763053894,2,20,10,3,2.35878089697067,0.207600509079825,0.0404026173055172,172.741912841797,50.9578895568848,50.9604148864746,320.072296142578,320.072296142578,,,121.901252746582,0,1,,,,,,1,1,1,50.9581985473633,0,50.9584632873535,,,,,,,,,,,,,,,,,,,,,,,,,,,,,,,,,
,3754367663.83136,50.9806156158447,339.925811767578,,,5,,,,3.65000008605421,,,,,0.000737490334486655,6.22752273155111E-8,-0.00773108527619115,3.88644634656437E-5,0.00073739418051287,6.22671078727269E-8,0.000737394173800044,5.52862895072172E-8,-9.94987296247758E-8,2.8646446819073E-8,1.00013039697943,10.005763053894,2,20,10,3,2.41248067819789,0.212292793008971,0.0404026173055172,172.741912841797,50.9772033691406,50.9891014099121,339.925811767578,339.925811767578,,,122.025619506836,0,1,,,,,,1,1,1,50.9824447631836,0,50.9837207794189,,,,,,,,,,,,,,,,,,,,,,,,,,,,,,,,,
,3754367685.51972,51.0420227050781,360.010009765625,,,5,,,,3.65000008605421,,,,,0.000750101348884947,5.86743593709596E-8,-0.014301230673099,4.78488937628613E-5,0.00075000359457071,5.86667128418977E-8,0.000750003571207371,4.64154878174476E-8,-1.87203567023383E-7,3.58801572786695E-8,1.00013033846097,10.005763053894,2,20,10,3,2.45375536904963,0.215694122793022,0.0404026173055172,172.741912841797,51.0381660461426,51.0434608459473,360.010009765625,360.010009765625,,,122.137550354004,0,1,,,,,,1,1,1,51.0431938171387,0,51.0414608001709,,,,,,,,,,,,,,,,,,,,,,,,,,,,,,,,,
,3754367707.17682,51.0477142333984,380.106353759766,,,5,,,,3.65000008605421,,,,,0.000759454238811381,7.02186872342872E-8,-0.0211177943504133,3.96035490724767E-5,0.000759355329226991,7.02095421129411E-8,0.000759355277648707,6.3448775549232E-8,-2.79879416157891E-7,3.00604837787424E-8,1.00013025467865,10.005763053894,2,20,10,3,2.48437350445208,0.218141427978569,0.0404026173055172,172.741912841797,51.0406913757324,51.0485076904297,380.106353759766,380.106353759766,,,122.224617004395,0,1,,,,,,1,1,1,51.0471839904785,0,51.0454059947621,,,,,,,,,,,,,,,,,,,,,,,,,,,,,,,,,
,3754367729.0587,51.0341873168945,399.923431396484,,,5,,,,3.65000008605421,,,,,0.000765364745284367,8.3133491862766E-8,-0.0339542561860462,5.581528048422E-5,0.00076526527618695,8.31226875848689E-8,0.000765265141809877,7.13148272107333E-8,-4.53506557339236E-7,4.2703355971574E-8,1.0001299798913,10.005763053894,2,20,10,3,2.50375423268837,0.219331356322039,0.0404026173055172,172.741912841797,51.0241584777832,51.0379333496094,399.923431396484,399.923431396484,,,122.299240112305,0,1,,,,,,1,1,1,51.0321998596191,0,51.0306621551514,,,,,,,,,,,,,,,,,,,,,,,,,,,,,,,,,
,3754367750.80029,51.015718460083,420.044036865234,,,5,,,,3.65000008605421,,,,,0.000767902153584902,1.10909441545871E-7,-0.0450586100806101,6.69995289240247E-5,0.000767802210743691,1.10895006627758E-7,0.000767801973316936,9.82480793374564E-8,-6.03815798666132E-7,5.1429732659926E-8,1.0001301674309,10.005763053894,2,20,10,3,2.5120941862891,0.219625805538719,0.0404026173055172,172.741912841797,51.0120658874512,51.0168075561523,420.044036865234,420.044036865234,,,122.361419677734,0,1,,,,,,1,1,1,51.0151214599609,0,51.0143001556396,,,,,,,,,,,,,,,,,,,,,,,,,,,,,,,,,
,3754367772.68648,51.0307807922363,440.310394287109,,,5,,,,3.65000008605421,,,,,0.000768476202157517,8.76845303830812E-8,-0.0508324424560547,6.04428329472157E-5,0.00076837618398074,8.76731181274566E-8,0.000768375881581593,7.43667124631581E-8,-6.81698257093959E-7,4.64345530786387E-8,1.00013016824163,10.005763053894,2,20,10,3,2.51399091130761,0.219591115407813,0.0404026173055172,172.741912841797,51.0268974304199,51.0308570861816,440.310394287109,440.310394287109,,,122.44847869873,0,1,,,,,,1,1,1,51.0308418273926,0,51.0296849337491,,,,,,,,,,,,,,,,,,,,,,,,,,,,,,,,,
,3754367795.70452,51.0356616973877,460.346008300781,,,5,,,,3.65000008605421,,,,,0.00076883624921994,1.05723945801197E-7,-0.0577563580229068,7.87451381090995E-5,0.000768736188895017,1.0571018634022E-7,0.000768735798322547,8.66678605934832E-8,-7.74915629195686E-7,6.05254114916421E-8,1.00013016211071,10.005763053894,2,20,10,3,2.5151919987393,0.219443969896389,0.0404026173055172,172.741912841797,51.0262680053711,51.0370178222656,460.346008300781,460.346008300781,,,122.510665893555,0,1,,,,,,1,1,1,51.0344734191895,0,51.0324577331543,,,,,,,,,,,,,,,,,,,,,,,,,,,,,,,,,
,3754367817.34128,51.0160942077637,480.272369384766,,,5,,,,3.65000008605421,,,,,0.000768330783549809,2.14378530245583E-7,-0.064409210570533,0.000105831314040669,0.000768230859855018,2.1435064968257E-7,0.000768230374440909,1.98339880538473E-7,-8.636086849324E-7,8.12864860067399E-8,1.00013006987875,10.005763053894,2,20,10,3,2.51356056881301,0.21906151518566,0.0404026173055172,172.741912841797,51.0123062133789,51.017406463623,480.272369384766,480.272369384766,,,122.597724914551,0,1,,,,,,1,1,1,51.0157012939453,0,51.0146938323975,,,,,,,,,,,,,,,,,,,,,,,,,,,,,,,,,
,3754367839.29352,51.0511989593506,500.283721923828,,,5,,,,3.65000008605421,,,,,0.000765633197944694,1.60396866993735E-7,-0.07324927338394,0.000115716951332337,0.000765533449394075,1.60375970100746E-7,0.00076553282379587,1.33697352606429E-7,-9.78689078338511E-7,8.85746560353885E-8,1.00013029940194,10.005763053894,2,20,10,3,2.50476592645316,0.217959448784436,0.0404026173055172,172.741912841797,51.0446968078613,51.0519027709961,500.283721923828,500.283721923828,,,122.697227478027,0,1,,,,,,1,1,1,51.0518951416016,0,51.0493906194514,,,,,,,,,,,,,,,,,,,,,,,,,,,,,,,,,
,3754367862.288,51.0269393920898,520.331481933594,,,5,,,,3.65000008605421,,,,,0.000761420390794999,2.1810907201729E-7,-0.0861288392549451,0.000115993115603281,0.000761321424759157,2.18080723170188E-7,0.000761320564578052,1.99402943269721E-7,-1.14444216443528E-6,8.83044055175325E-8,1.00012999244816,10.005763053894,2,20,10,3,2.4910291498917,0.216253747372816,0.0404026173055172,172.741912841797,51.0171165466309,51.0318908691406,520.331481933594,520.331481933594,,,122.746971130371,0,1,,,,,,1,1,1,51.0245094299316,0,51.0233661651611,,,,,,,,,,,,,,,,,,,,,,,,,,,,,,,,,
,3754367884.1401,51.0103130340576,540.427917480469,,,5,,,,3.65000008605421,,,,,0.000751765308453625,2.59537560581399E-7,-0.0928134171670099,0.000216500955542085,0.000751667479263582,2.59503786278366E-7,0.000751666493047839,2.02148866119454E-7,-1.21762540636143E-6,1.62720776237783E-7,1.00013014955781,10.005763053894,2,20,10,3,2.4594636893632,0.213277586387666,0.0404026173055172,172.741912841797,51.0070877075195,51.0116348266602,540.427917480469,540.427917480469,,,122.809158325195,0,1,,,,,,1,1,1,51.0096817016602,0,51.0091346740723,,,,,,,,,,,,,,,,,,,,,,,,,,,,,,,,,
,3754367905.89749,51.0042095184326,560.29345703125,,,5,,,,3.65000008605421,,,,,0.000730388472036056,2.36530672666641E-7,-0.100320087172436,0.000160296489836406,0.000730293377259763,2.36499876956872E-7,0.00073029225782757,2.05497243824606E-7,-1.27868157928762E-6,1.17060132329952E-7,1.00013021448538,10.005763053894,2,20,10,3,2.38955161252705,0.206950681702289,0.0404026173055172,172.741912841797,51.0036888122559,51.0043754577637,560.29345703125,560.29345703125,,,122.87134552002,0,1,,,,,,1,1,1,51.0043716430664,0,51.0041355133057,,,,,,,,,,,,,,,,,,,,,,,,,,,,,,,,,
,3754367927.56838,51.0043258666992,580.389892578125,,,5,,,,3.65000008605421,,,,,0.000668105543743173,2.27397410243719E-7,-0.116012397282125,0.000171516778029483,0.000668018554494056,2.27367802451727E-7,0.000668017185120557,1.96387243944608E-7,-1.35260191308376E-6,1.14578217858233E-7,1.00013021980981,10.005763053894,2,20,10,3,2.18583463142442,0.18875158834483,0.0404026173055172,172.741912841797,51.0040817260742,51.0048484802246,580.389892578125,580.389892578125,,,122.933525085449,0,1,,,,,,1,1,1,51.0040817260742,0,51.004430770874,,,,,,,,,,,,,,,,,,,,,,,,,,,,,,,,,
,3754367952.54803,51.0117645263672,600.486206054687,,,5,,,,3.65000008605421,,,,,0.000460193034459172,1.52790311194149E-7,-0.139051774602709,0.000198595479907976,0.000460133117773248,1.52770418044095E-7,0.000460131762705246,1.22429150929271E-7,-1.11670116569446E-6,9.13778071093051E-8,1.00013021598231,10.005763053894,2,20,1,3,1.50565944637714,0.129439571954868,0.0404026173055172,172.741912841797,51.0073471069336,51.0127983093262,600.486206054687,600.486206054687,,,123.008148193359,0,1,,,,,,1,1,1,51.0109825134277,0,51.0105071434608,,,,,,,,,,,,,,,,,,,,,,,,,,,,,,,,,
,3754367975.03257,51.0077857971191,620.278991699219,,,5,,,,3.65000008605421,,,,,0.000178000819337602,2.45561868715461E-7,-0.378759209063821,0.000881164217400263,0.000177977655785702,2.45529913328335E-7,0.000177973766990769,1.88901840392696E-7,-1.17652968048058E-6,1.56847164575175E-7,1.00013014865151,10.005763053894,2,20,1,3,0.582586710392047,0.0476421119556421,0.0404026173055172,172.741912841797,51.0065841674805,51.0088233947754,620.278991699219,620.278991699219,,,123.070335388184,0,1,,,,,,1,1,1,51.0072822570801,0,51.007315826416,,,,,,,,,,,,,,,,,,,,,,,,,,,,,,,,,
,3754367996.68925,51.0075511932373,640.375366210937,,,5,,,,3.65000008605421,,,,,8.37261522935302E-5,3.18792225016192E-7,-0.800921816493703,0.00154736680956957,8.37152481595435E-5,3.18750706887862E-7,8.37070691166856E-5,2.90992646744761E-7,-1.1701941327693E-6,1.3009724317598E-7,1.00013025266276,10.005763053894,2,20,1,3,0.274188396314363,0.0203956049850663,0.0404026173055172,172.741912841797,51.0045051574707,51.0076599121094,640.375366210937,640.375366210937,,,123.120086669922,0,1,,,,,,1,1,1,51.0076217651367,0,51.0064994812012,,,,,,,,,,,,,,,,,,,,,,,,,,,,,,,,,
,3754368018.87214,51.0424861907959,660.423095703125,,,5,,,,3.65000008605421,,,,,5.07426607536825E-5,2.76285566101061E-7,-1.38973043691965,0.00291013621503159,5.07360468192913E-5,2.7624955429994E-7,5.07211229577475E-5,2.33229495152173E-7,-1.23050101762785E-6,1.48046677916048E-7,1.00013035967139,10.005763053894,2,20,1,3,0.166291389169758,0.0106560897728259,0.0404026173055172,172.741912841797,51.039722442627,51.0438537597656,660.423095703125,660.423095703125,,,123.169830322266,0,1,,,,,,1,1,1,51.0436592102051,0,51.042424288663,,,,,,,,,,,,,,,,,,,,,,,,,,,,,,,,,
,3754368041.6094,51.0278739929199,680.458740234375,,,5,,,,3.65000008605421,,,,,3.81879988325717E-5,3.51903888557732E-7,-1.968910232263,0.00355188453281861,3.81830336934549E-5,3.51858134608433E-7,3.81604910799954E-5,3.24019045388145E-7,-1.31186225233632E-6,1.3717071522698E-7,1.00013003521817,10.005763053894,2,20,1,3,0.125222455381529,0.00675680728256779,0.0404026173055172,172.741912841797,51.0191764831543,51.0316390991211,680.458740234375,680.458740234375,,,123.23201751709,0,1,,,,,,1,1,1,51.0267066955566,0,51.0249210357666,,,,,,,,,,,,,,,,,,,,,,,,,,,,,,,,,
,3754368063.51195,51.0514736175537,700.324401855469,,,5,,,,3.65000008605421,,,,,2.99007358830579E-5,3.76826657286481E-7,-2.54394720190598,0.00466259325219708,2.98968433970581E-5,3.76777601888863E-7,2.98673791793177E-5,3.49179387658187E-7,-1.32699135908181E-6,1.41545457432501E-7,1.00013019722343,10.005763053894,2,20,1,3,0.0980957713052506,0.00430829254574185,0.0404026173055172,172.741912841797,51.0449905395508,51.0516929626465,700.324401855469,700.324401855469,,,123.294204711914,0,1,,,,,,1,1,1,51.0516815185547,0,51.0496471405029,,,,,,,,,,,,,,,,,,,,,,,,,,,,,,,,,
,3754368085.16843,51.0609302520752,720.347839355469,,,5,,,,3.65000008605421,,,,,2.64452791201803E-5,3.85700935073393E-7,-3.15592086358987,0.00903881153488672,2.64418371599289E-5,3.85650734533576E-7,2.64017358305305E-5,3.02281205351278E-7,-1.45571203439474E-6,2.39483949227636E-7,1.00013017099495,10.005763053894,2,20,1,3,0.086795140543958,0.00288539103677262,0.0404026173055172,172.741912841797,51.0499572753906,51.0613327026367,720.347839355469,720.347839355469,,,123.356391906738,0,1,,,,,,1,1,1,51.0605278015137,0,51.0574638366699,,,,,,,,,,,,,,,,,,,,,,,,,,,,,,,,,
,3754368106.7798,51.0251998901367,740.407775878906,,,5,,,,3.65000008605421,,,,,2.35274546604163E-5,3.27894350004359E-7,-3.80361444388478,0.00689195229724861,2.35243958398938E-5,3.27851720234947E-7,2.34725783117783E-5,2.84252856826096E-7,-1.56053421283997E-6,1.63361757603232E-7,1.00013002759107,10.005763053894,2,20,1,3,0.0772427400338889,0.00169563812323575,0.0404026173055172,172.741912841797,51.0183982849121,51.0271530151367,740.407775878906,740.407775878906,,,123.393699645996,0,1,,,,,,1,1,1,51.0239448547363,0,51.0224781036377,,,,,,,,,,,,,,,,,,,,,,,,,,,,,,,,,
,3754368128.71964,51.027515411377,760.1884765625,,,5,,,,3.65000008605421,,,,,2.11115824387022E-5,3.08900177496292E-7,-4.16628804442605,0.00736942116950601,2.11088330490092E-5,3.08859949011921E-7,2.10530507796159E-5,2.66159719330123E-7,-1.53358585082734E-6,1.56695475077479E-7,1.00013024830348,10.005763053894,2,20,1,3,0.0693194726783068,0.00108423208144952,0.0404026173055172,172.741912841797,51.0247688293457,51.0276184082031,760.1884765625,760.1884765625,,,123.45588684082,0,1,,,,,,1,1,1,51.0276031494141,0,51.0267070770264,,,,,,,,,,,,,,,,,,,,,,,,,,,,,,,,,
,3754368150.39037,51.01833152771,780.381958007812,,,5,,,,3.65000008605421,,,,,1.97049389575521E-5,4.38998655203686E-7,-4.48871633476478,0.00889694702912726,1.97023742548701E-5,4.38941517192204E-7,1.96419424608674E-5,4.01165240842704E-7,-1.54196227027163E-6,1.78146302388259E-7,1.00013017226497,10.005763053894,2,20,1,3,0.0647054785426327,0.000649273794292743,0.0404026173055172,172.741912841797,51.0142974853516,51.0198936462402,780.381958007812,780.381958007812,,,123.493202209473,0,1,,,,,,1,1,1,51.0177116394043,0,51.0168933868408,,,,,,,,,,,,,,,,,,,,,,,,,,,,,,,,,
,3754368172.4373,51.0096893310547,800.453979492188,,,5,,,,3.65000008605421,,,,,1.84909661589462E-5,3.68191564194283E-7,-4.95997694605479,0.00797218338555741,1.84885604086935E-5,3.68143660967324E-7,1.84193269675885E-5,3.36284624287395E-7,-1.59851807840195E-6,1.49807898918281E-7,1.00013012101535,10.005763053894,2,20,1,3,0.0607221219505748,0.000111143122434077,0.0404026173055172,172.741912841797,51.0080299377441,51.011173248291,800.453979492188,800.453979492188,,,123.555381774902,0,1,,,,,,1,1,1,51.0092315673828,0,51.009257923473,,,,,,,,,,,,,,,,,,,,,,,,,,,,,,,,,