File: Experimental_Data/Supplementary_Fig1_Data/FC_Up_58K.dat
[Header]
; MPMS3 Data File (default extension .dat)
; Copyright (c) 2007, Quantum Design, Inc. All rights reserved.
TITLE,FC_58K
FILEOPENTIME,3754346310.18651,12/19/2018,1:58 am
BYAPP,SQUID AC,0.9.1.0
INFO,MPMS3 Measurement Release 1.1.16 Build 347, MultiVu Release 2.3.3.2,APPNAME
INFO,0,MOMENT_UNITS
INFO,CoIINO3,SAMPLE_MATERIAL
INFO,40 Hours Pumped Turbo,SAMPLE_COMMENT
INFO,,SAMPLE_MASS
INFO,,SAMPLE_VOLUME
INFO,,SAMPLE_MOLECULAR_WEIGHT
INFO,,SAMPLE_SIZE
INFO,,SAMPLE_SHAPE
INFO,Brass,SAMPLE_HOLDER
INFO,Standard,SAMPLE_HOLDER_DETAIL
INFO,65.37,SAMPLE_OFFSET
DATATYPE,COMMENT,1
DATATYPE,TIME,2
STARTUPAXIS,X,2
STARTUPAXIS,Y1,5
FIELDGROUP, VSM,2,3,4,5,6,8,9,10,11,14,15
FIELDGROUP, DC, 2,3,4,14,56,57,58,59,60,61,62,63,64,65,66,67,68,69
FIELDGROUP, AC, 2,3,4,11,16,17,18,19,20,21,22,23,24,25,26,27,28,29,30
STARTUPGROUP, All
[Data]
Comment,Time Stamp (sec),Temperature (K),Magnetic Field (Oe),Moment (emu),M. Std. Err. (emu),Transport Action,Averaging Time (sec),Frequency (Hz),Peak Amplitude (mm),Center Position (mm),Lockin Signal' (V),Lockin Signal (V),Range,M. Quad. Signal (emu),AC Moment (emu),AC M. Std Err. (emu),AC Phase (deg),AC Phase Std. Err. (deg),AC Susceptibility (emu/Oe),AC Suscept. Std Err. (emu/Oe),AC X' (emu/Oe),AC X' Std Err. (emu/Oe),AC X'' (emu/Oe),AC X'' Std Err. (emu/Oe),AC Drive (Oe),AC Frequency (Hz),AC Averaging Time (sec),AC Cycles,AC Range,AC Measure Type,AC Signal' (V),AC Signal'' (V),AC Trim Coil Ratio,AC Trim Coil Phase,Min. Temperature (K),Max. Temperature (K),Min. Field (Oe),Max. Field (Oe),Mass (grams),Motor Lag (deg),Pressure (Torr),Measure Count,Measurement Number,SQUID Status (code),Motor Status (code),Measure Status (code),Motor Current (amps),Motor Temp. (C),Temp. Status (code),Field Status (code),Chamber Status (code),Chamber Temp (K),Redirection State,Average Temp (K),Rotation Angle (deg),Rotator state,DC Moment Fixed Ctr (emu),DC Moment Err Fixed Ctr (emu),DC Moment Free Ctr (emu),DC Moment Err Free Ctr (emu),DC Fixed Fit,DC Free Fit,DC Calculated Center (mm),DC Calculated Center Err (mm),DC Scan Length (mm),DC Scan Time (s),DC Number of Points,DC Squid Drift,DC Min V (V),DC Max V (V),DC Scans per Measure,Map 01,Map 02,Map 03,Map 04,Map 05,Map 06,Map 07,Map 08,Map 09,Map 10,Map 11,Map 12,Map 13,Map 14,Map 15,Map 16
,3754346437.9373,57.9881782531738,220.076263427734,,,5,,,,3.65000008605421,,,,,0.000287448420985885,3.73715265588319E-7,0.538937553846735,0.000193802607416172,0.000287411344967835,3.73667062596335E-7,0.000287398630378485,3.69878207947977E-7,2.70341872282991E-6,5.30771603852916E-8,1.00012899984186,10.005763053894,2,20,1,3,0.93947930823091,0.0915836404926103,0.0404026173055172,172.741912841797,57.934024810791,57.9914588928223,220.076263427734,220.076263427734,,,80.1250076293945,0,1,,,,,,1,1,1,57.9864158630371,0,57.9647089640299,,,,,,,,,,,,,,,,,,,,,,,,,,,,,,,,,
,3754346477.15967,57.8999423980713,239.929779052734,,,5,,,,3.65000008605421,,,,,0.000257662854606452,1.76311520084204E-7,0.31991579213772,0.000110987717737977,0.000257629654942337,1.76288802478069E-7,0.000257625638968999,1.74068199066429E-7,1.43848931947976E-6,2.78927222214303E-8,1.00012886584862,10.005763053894,2,20,1,3,0.842436381283819,0.0788919054390813,0.0404026173055172,172.741912841797,57.8953628540039,57.9070587158203,239.929779052734,239.929779052734,,,80.2618179321289,0,1,,,,,,1,1,1,57.8983497619629,0,57.8999390602112,,,,,,,,,,,,,,,,,,,,,,,,,,,,,,,,,
,3754346519.69194,57.9469776153564,260.098968505859,,,5,,,,3.65000008605421,,,,,0.000221513785220113,7.16202033886198E-8,0.457209830556661,0.000125453442571732,0.000221485097264175,7.16109279512602E-8,0.00022147804549539,6.60521530222206E-8,1.7673917684095E-6,2.76629369946457E-8,1.0001295254457,10.005763053894,2,20,1,3,0.724080230036768,0.0695745504478143,0.0404026173055172,172.741912841797,57.9399795532227,57.9518508911133,260.098968505859,260.098968505859,,,80.4359359741211,0,1,,,,,,1,1,1,57.9486999511719,0,57.9473345620292,,,,,,,,,,,,,,,,,,,,,,,,,,,,,,,,,
,3754346542.22969,57.9532680511475,280.073883056641,,,5,,,,3.65000008605421,,,,,0.000211336660269012,1.07902759069076E-7,0.292714962898484,0.000101812747127207,0.000211309350795712,1.07888815593704E-7,0.000211306593188813,1.05785559637408E-7,1.07954094070132E-6,2.11993373106954E-8,1.00012923930341,10.005763053894,2,20,1,3,0.691000159908114,0.0644092413423618,0.0404026173055172,172.741912841797,57.9513931274414,57.9535522460937,280.073883056641,280.073883056641,,,80.5354309082031,0,1,,,,,,1,1,1,57.952995300293,0,57.9525361494585,,,,,,,,,,,,,,,,,,,,,,,,,,,,,,,,,
,3754346565.05177,57.9724655151367,300.121673583984,,,5,,,,3.65000008605421,,,,,0.000194508830952681,1.99351801877534E-7,0.375959710742471,0.000123914253295726,0.000194483659156052,1.9932600334186E-7,0.000194479472291495,1.98014099085184E-7,1.27614103802421E-6,2.28313856724035E-8,1.00012942885144,10.005763053894,2,20,1,3,0.635891054096043,0.0602181907343071,0.0404026173055172,172.741912841797,57.9672927856445,57.9879989624023,300.121673583984,300.121673583984,,,80.6598052978516,0,1,,,,,,1,1,1,57.9752044677734,0,57.9782229336825,,,,,,,,,,,,,,,,,,,,,,,,,,,,,,,,,
,3754346588.09047,57.998067855835,320.048034667969,,,5,,,,3.65000008605421,,,,,0.000187603594474485,1.69840769467055E-7,0.237025668228219,9.2606171579921E-5,0.000187579354962722,1.69818825019024E-7,0.000187577749870769,1.6901578582441E-7,7.75990753902489E-7,1.64953773221156E-8,1.0001292227056,10.005763053894,2,20,1,3,0.613454524387552,0.0566060883492646,0.0404026173055172,172.741912841797,57.9969749450684,58.0009231567383,320.048034667969,320.048034667969,,,80.7468643188477,0,1,,,,,,1,1,1,57.9988861083984,0,57.9992156982422,,,,,,,,,,,,,,,,,,,,,,,,,,,,,,,,,
,3754346609.70427,58.0010852813721,340.071502685547,,,5,,,,3.65000008605421,,,,,0.000180858868361801,4.38014609509622E-8,0.209202134841215,8.21993270018224E-5,0.000180835496103896,4.37958005205326E-8,0.000180834290678983,4.12138828184123E-8,6.6027704138618E-7,1.48151276155308E-8,1.00012924596337,10.005763053894,2,20,1,3,0.59142519909323,0.0542964627301298,0.0404026173055172,172.741912841797,57.9999847412109,58.0014381408691,340.071502685547,340.071502685547,,,80.8214874267578,0,1,,,,,,1,1,1,58.0012969970703,0,58.0007511138916,,,,,,,,,,,,,,,,,,,,,,,,,,,,,,,,,
,3754346631.60519,58.0012474060059,360.119293212891,,,5,,,,3.65000008605421,,,,,0.000175859357834588,1.90474796475547E-7,0.172011593465481,0.000108116444601416,0.000175836630355738,1.90450180145988E-7,0.000175835837947094,1.89576437853321E-7,5.27890427525824E-7,1.82221109777399E-8,1.00012925338028,10.005763053894,2,20,1,3,0.575109682679815,0.0524345860211227,0.0404026173055172,172.741912841797,58.0008010864258,58.0015068054199,360.119293212891,360.119293212891,,,80.896110534668,0,1,,,,,,1,1,1,58.0013542175293,0,58.0011241912842,,,,,,,,,,,,,,,,,,,,,,,,,,,,,,,,,
,3754346653.25619,58.0339870452881,380.191345214844,,,5,,,,3.65000008605421,,,,,0.000166057257221919,7.63627326913593E-8,0.214666730903154,9.04057169567632E-5,0.000166035757495173,7.63528458733187E-8,0.000166034592147952,7.48981074979281E-8,6.22074962419312E-7,1.48334273242419E-8,1.0001294885335,10.005763053894,2,20,1,3,0.5430162721582,0.0499278955701026,0.0404026173055172,172.741912841797,58.0292015075684,58.0365524291992,380.191345214844,380.191345214844,,,80.9831695556641,0,1,,,,,,1,1,1,58.0354804992676,0,58.0346693559126,,,,,,,,,,,,,,,,,,,,,,,,,,,,,,,,,
,3754346675.2024,58.0406951904297,400.069122314453,,,5,,,,3.65000008605421,,,,,0.000161805503787046,1.45473209008726E-7,0.166138378896973,9.88090435121233E-5,0.000161784597739102,1.45454413171682E-7,0.000161783917594046,1.4463094197112E-7,4.69119948471248E-7,1.5455644136196E-8,1.0001292214972,10.005763053894,2,20,1,3,0.529153090050886,0.0482126253254533,0.0404026173055172,172.741912841797,58.0375442504883,58.0408134460449,400.069122314453,400.069122314453,,,81.0453567504883,0,1,,,,,,1,1,1,58.0405693054199,0,58.039852142334,,,,,,,,,,,,,,,,,,,,,,,,,,,,,,,,,
,3754346696.84268,58.0259666442871,420.116912841797,,,5,,,,3.65000008605421,,,,,0.000158310266925545,2.27708296405814E-7,0.122492004452823,0.000162465068690966,0.000158289846454143,2.27678924269408E-7,0.000158289484716991,2.26295451479078E-7,3.38405829740018E-7,2.50611491427444E-8,1.00012900683056,10.005763053894,2,20,1,3,0.517757673268825,0.04678787838436,0.0404026173055172,172.741912841797,58.0189971923828,58.0278854370117,420.116912841797,420.116912841797,,,81.1075439453125,0,1,,,,,,1,1,1,58.025203704834,0,58.0234531402588,,,,,,,,,,,,,,,,,,,,,,,,,,,,,,,,,
,3754346718.80706,58.0451374053955,440.152526855469,,,5,,,,3.65000008605421,,,,,0.000150389104874099,8.34797120311356E-8,0.183367056390634,8.96415353289877E-5,0.000150369660582922,8.34689186706098E-8,0.000150368890518224,8.24082722188291E-8,4.81236056088071E-7,1.32641265806779E-8,1.00012930993593,10.005763053894,2,20,1,3,0.491803125415494,0.0449799043278293,0.0404026173055172,172.741912841797,58.0419960021973,58.0459938049316,440.152526855469,440.152526855469,,,81.1697235107422,0,1,,,,,,1,1,1,58.0458564758301,0,58.0442390441895,,,,,,,,,,,,,,,,,,,,,,,,,,,,,,,,,
,3754346740.29971,58.0290298461914,460.273193359375,,,5,,,,3.65000008605421,,,,,0.000148906568495334,2.23505674384081E-7,0.0793129970557738,0.000167029010047997,0.000148887357234734,2.23476838679924E-7,0.000148887214584918,2.22145123524719E-7,2.0610067364518E-7,2.43606551751016E-8,1.00012903218216,10.005763053894,2,20,1,3,0.487034339430661,0.0436625642077998,0.0404026173055172,172.741912841797,58.0219993591309,58.0327644348145,460.273193359375,460.273193359375,,,81.2319107055664,0,1,,,,,,1,1,1,58.0274276733398,0,58.026480588046,,,,,,,,,,,,,,,,,,,,,,,,,,,,,,,,,
,3754346762.44406,58.0170631408691,480.357360839844,,,5,,,,3.65000008605421,,,,,0.000140551132014184,3.02713168208239E-7,0.242947562973046,0.000309389774704724,0.000140532978886899,3.0267407075954E-7,0.00014053171552599,2.99692842075944E-7,5.95891053718997E-7,4.23768040158074E-8,1.00012917343267,10.005763053894,2,20,1,3,0.45958566407758,0.0425351902843734,0.0404026173055172,172.741912841797,58.0160827636719,58.0181427001953,480.357360839844,480.357360839844,,,81.2940979003906,0,1,,,,,,1,1,1,58.0170783996582,0,58.0176254272461,,,,,,,,,,,,,,,,,,,,,,,,,,,,,,,,,
,3754346784.33216,58.0150566101074,500.320159912109,,,5,,,,3.65000008605421,,,,,0.000137996230506431,2.2505757152944E-7,0.129575518821862,0.000222315791773707,0.000137978404190336,2.25028498652631E-7,0.000137978051347272,2.23002988945383E-7,3.1204057648172E-7,3.01246099938649E-8,1.00012919642171,10.005763053894,2,20,1,3,0.451312566100219,0.0408787011844556,0.0404026173055172,172.741912841797,58.0117568969727,58.016185760498,500.320159912109,500.320159912109,,,81.3687210083008,0,1,,,,,,1,1,1,58.0145225524902,0,58.0137149810791,,,,,,,,,,,,,,,,,,,,,,,,,,,,,,,,,
,3754346806.30284,58.0264148712158,520.41650390625,,,5,,,,3.65000008605421,,,,,0.000131316496390701,2.70821349968081E-7,0.202282631319038,0.000235892282308618,0.000131299525020516,2.70786348962794E-7,0.000131298706735437,2.69133238336183E-7,4.6355173911282E-7,2.98755218745982E-8,1.00012925690464,10.005763053894,2,20,1,3,0.429416377876729,0.039454144227292,0.0404026173055172,172.741912841797,58.0249519348145,58.0286140441895,520.41650390625,520.41650390625,,,81.4060287475586,0,1,,,,,,1,1,1,58.0268478393555,0,58.0271814519709,,,,,,,,,,,,,,,,,,,,,,,,,,,,,,,,,
,3754346829.0716,58.0514068603516,540.318603515625,,,5,,,,3.65000008605421,,,,,0.000128492443822185,1.92520104167582E-7,0.1247280014136,0.000273588320871852,0.000128475838011952,1.92495223698187E-7,0.00012847553359141,1.89320517404877E-7,2.79680667315448E-7,3.48159853539272E-8,1.00012925239866,10.005763053894,2,20,1,3,0.420232774763762,0.0380458110977875,0.0404026173055172,172.741912841797,58.0493240356445,58.0527801513672,540.318603515625,540.318603515625,,,81.4806518554687,0,1,,,,,,1,1,1,58.0521011352539,0,58.0513248443603,,,,,,,,,,,,,,,,,,,,,,,,,,,,,,,,,
,3754346850.81443,58.0358543395996,560.354187011719,,,5,,,,3.65000008605421,,,,,0.000128057510912639,2.42707940271179E-7,-0.0364938487968196,0.000311137297514034,0.000128040993619692,2.42676634976227E-7,0.000128040967647231,2.39399848737657E-7,-8.15541456057797E-8,3.97449567589633E-8,1.00012900003725,10.005763053894,2,20,1,3,0.418914812682809,0.036747401181934,0.0404026173055172,172.741912841797,58.0256462097168,58.0389976501465,560.354187011719,560.354187011719,,,81.5552749633789,0,1,,,,,,1,1,1,58.0342979431152,0,58.0320018768311,,,,,,,,,,,,,,,,,,,,,,,,,,,,,,,,,
,3754346872.73306,58.0636672973633,580.365539550781,,,5,,,,3.65000008605421,,,,,0.000118741010569891,3.05107722529284E-7,0.239561442657886,0.00037354056266665,0.000118725639287544,3.05068225670306E-7,0.000118724601514315,3.01985173329751E-7,4.96406590497835E-7,4.32617313873233E-8,1.00012946893729,10.005763053894,2,20,1,3,0.388268493930716,0.035953361149279,0.0404026173055172,172.741912841797,58.0595397949219,58.0672073364258,580.365539550781,580.365539550781,,,81.5801544189453,0,1,,,,,,1,1,1,58.0650939941406,0,58.0645349675959,,,,,,,,,,,,,,,,,,,,,,,,,,,,,,,,,
,3754346895.72726,58.0440444946289,600.109741210937,,,5,,,,3.65000008605421,,,,,0.00012149595535119,2.82231534993875E-7,-0.107836594598779,0.000392181204851948,0.000121480280705794,2.82195123253106E-7,0.000121480065545203,2.78131108019234E-7,-2.28638342291211E-7,4.7719747901985E-8,1.0001290303686,10.005763053894,2,20,1,3,0.397492063375023,0.0343864875031763,0.0404026173055172,172.741912841797,58.0318489074707,58.0486450195313,600.109741210937,600.109741210937,,,81.642333984375,0,1,,,,,,1,1,1,58.0419464111328,0,58.0397365570068,,,,,,,,,,,,,,,,,,,,,,,,,,,,,,,,,
,3754346917.40619,58.069507598877,620.339660644531,,,5,,,,3.65000008605421,,,,,0.000112390964694486,1.85182965294725E-7,0.216595334698813,0.000310699529128,0.00011237641121305,1.85158985993051E-7,0.000112375608246272,1.81924231053515E-7,4.24815730457147E-7,3.44590227598287E-8,1.00012950655106,10.005763053894,2,20,1,3,0.367517196017003,0.0338990548822429,0.0404026173055172,172.741912841797,58.0654754638672,58.071834564209,620.339660644531,620.339660644531,,,81.6920852661133,0,1,,,,,,1,1,1,58.0710678100586,0,58.0695579528809,,,,,,,,,,,,,,,,,,,,,,,,,,,,,,,,,
,3754346939.35411,58.0980968475342,640.387451171875,,,5,,,,3.65000008605421,,,,,0.000112369149570449,2.56582969921969E-7,0.00663747505111356,0.0003575870447293,0.000112354619617732,2.56549792324425E-7,0.000112354618863819,2.53418475637582E-7,1.30158100519734E-8,3.99608827133483E-8,1.00012932225453,10.005763053894,2,20,1,3,0.367567098671103,0.0325536386202743,0.0404026173055172,172.741912841797,58.0906600952148,58.0983581542969,640.387451171875,640.387451171875,,,81.7418365478516,0,1,,,,,,1,1,1,58.0983581542969,0,58.0960189819336,,,,,,,,,,,,,,,,,,,,,,,,,,,,,,,,,
,3754346961.2482,58.0630664825439,660.398803710937,,,5,,,,3.65000008605421,,,,,0.000112255545446107,2.96328900370442E-7,-0.155921269150006,0.000488406754485117,0.000112241081215331,2.96290718117765E-7,0.00011224066560433,2.91139986582706E-7,-3.05445713134895E-7,5.50063437738134E-8,1.00012886752889,10.005763053894,2,20,1,3,0.367285810468417,0.0314866751163038,0.0404026173055172,172.741912841797,58.0474128723145,58.068359375,660.398803710937,660.398803710937,,,81.7791442871094,0,1,,,,,,1,1,1,58.0602264404297,0,58.0574634552002,,,,,,,,,,,,,,,,,,,,,,,,,,,,,,,,,
,3754346982.98218,58.0785160064697,680.288696289063,,,5,,,,3.65000008605421,,,,,0.000105390748972219,1.67783492022094E-7,0.0499408531255234,0.000427113415261709,0.000105377118995538,1.67761792915616E-7,0.000105377078965782,1.61644087856486E-7,9.18500908949492E-8,4.48910684135133E-8,1.00012934474591,10.005763053894,2,20,1,3,0.344716170893214,0.0308072467312208,0.0404026173055172,172.741912841797,58.0706367492676,58.0789489746094,680.288696289063,680.288696289063,,,81.8413314819336,0,1,,,,,,1,1,1,58.0789375305176,0,58.0765705108643,,,,,,,,,,,,,,,,,,,,,,,,,,,,,,,,,
,3754347004.37599,58.051607131958,700.433654785156,,,5,,,,3.65000008605421,,,,,0.00010595136907082,2.90735027839963E-7,-0.183369745628513,0.00066809412113925,0.000105937711876832,2.90697551923331E-7,0.000105937169338632,2.81906078106167E-7,-3.39043089782508E-7,7.09508972530824E-8,1.00012891720754,10.005763053894,2,20,1,3,0.346672667327526,0.0295671904318378,0.0404026173055172,172.741912841797,58.038272857666,58.0567741394043,700.433654785156,700.433654785156,,,81.9035186767578,0,1,,,,,,1,1,1,58.0496520996094,0,58.0473972667347,,,,,,,,,,,,,,,,,,,,,,,,,,,,,,,,,
,3754347026.60204,58.023904800415,720.359985351562,,,5,,,,3.65000008605421,,,,,0.00010022589210585,3.00877560476225E-7,-0.0416644929161052,0.000654848227228302,0.00010021296189903,3.00838744068581E-7,0.000100212935402999,2.93611212859739E-7,-7.28731140172284E-8,6.55469725906122E-8,1.00012902728924,10.005763053894,2,20,1,3,0.327868308048239,0.0287873973641779,0.0404026173055172,172.741912841797,58.019287109375,58.0263404846191,720.359985351562,720.359985351562,,,81.9532623291016,0,1,,,,,,1,1,1,58.0230979919434,0,58.0222764448686,,,,,,,,,,,,,,,,,,,,,,,,,,,,,,,,,
,3754347049.57814,58.0133934020996,740.407775878906,,,5,,,,3.65000008605421,,,,,9.87147986774307E-5,2.14755141754149E-7,-0.0866539955541041,0.000625112978835556,9.87020542353258E-5,2.14727416078693E-7,9.87019413524582E-5,2.05670833701195E-7,-1.49276686363119E-7,6.17039008530845E-8,1.00012912033294,10.005763053894,2,20,1,3,0.322946818957544,0.0281067312511178,0.0404026173055172,172.741912841797,58.0090637207031,58.0146751403809,740.407775878906,740.407775878906,,,82.0154495239258,0,1,,,,,,1,1,1,58.0127601623535,0,58.0118103027344,,,,,,,,,,,,,,,,,,,,,,,,,,,,,,,,,
,3754347071.27115,58.0061092376709,760.322021484375,,,5,,,,3.65000008605421,,,,,9.54358057550479E-5,2.46123407755759E-7,-0.0668916108148334,0.000902592332876651,9.54234835824388E-5,2.46091629587288E-7,9.54234185510146E-5,2.3053424382343E-7,-1.11404873633244E-7,8.61106995540392E-8,1.00012913144801,10.005763053894,2,20,1,3,0.31220974898762,0.0272874597000526,0.0404026173055172,172.741912841797,58.0041275024414,58.0070571899414,760.322021484375,760.322021484375,,,82.0527648925781,0,1,,,,,,1,1,1,58.0055122375488,0,58.0051872253418,,,,,,,,,,,,,,,,,,,,,,,,,,,,,,,,,
,3754347093.1615,57.9996089935303,780.321228027344,,,5,,,,3.65000008605421,,,,,9.18774897925058E-5,2.73903627161069E-7,-0.0205919805561416,0.00100062768824882,9.18656227359746E-5,2.73868249291745E-7,9.18656168029794E-5,2.58004882809235E-7,-3.30163075275215E-8,9.18547680674138E-8,1.00012917842581,10.005763053894,2,20,1,3,0.300547308116355,0.0265193592910365,0.0404026173055172,172.741912841797,57.9986991882324,57.999870300293,780.321228027344,780.321228027344,,,82.1025085449219,0,1,,,,,,1,1,1,57.9997215270996,0,57.9993179321289,,,,,,,,,,,,,,,,,,,,,,,,,,,,,,,,,
,3754347114.7871,58.013111114502,800.368957519531,,,5,,,,3.65000008605421,,,,,9.07077450003596E-5,3.44762530587709E-7,-0.173077487196804,0.000784963343874675,9.0696014651076E-5,3.44717945807174E-7,9.06956008479418E-5,3.37237389668882E-7,-2.73971566049568E-7,7.14241217715439E-8,1.00012933698717,10.005763053894,2,20,1,3,0.296789118325883,0.0253983127992976,0.0404026173055172,172.741912841797,58.0117149353027,58.0146522521973,800.368957519531,800.368957519531,,,82.1522598266602,0,1,,,,,,1,1,1,58.0136528015137,0,58.0137256622314,,,,,,,,,,,,,,,,,,,,,,,,,,,,,,,,,