File: Experimental_Data/Supplementary_Fig1_Data/Tc_110.dat
[Header]
; MPMS3 Data File (default extension .dat)
; Copyright (c) 2007, Quantum Design, Inc. All rights reserved.
TITLE,
FILEOPENTIME,3772384980.91504,07/15/2019,8:42 pm
BYAPP,SQUID AC,0.9.1.0
INFO,MPMS3 Measurement Release 1.1.16 Build 347, MultiVu Release 2.3.3.2,APPNAME
INFO,0,MOMENT_UNITS
INFO,Cu2OSeO3,SAMPLE_MATERIAL
INFO,,SAMPLE_COMMENT
INFO,,SAMPLE_MASS
INFO,,SAMPLE_VOLUME
INFO,,SAMPLE_MOLECULAR_WEIGHT
INFO,,SAMPLE_SIZE
INFO,,SAMPLE_SHAPE
INFO,Quartz,SAMPLE_HOLDER
INFO,Standard,SAMPLE_HOLDER_DETAIL
INFO,64.77,SAMPLE_OFFSET
DATATYPE,COMMENT,1
DATATYPE,TIME,2
STARTUPAXIS,X,2
STARTUPAXIS,Y1,5
FIELDGROUP, VSM,2,3,4,5,6,8,9,10,11,14,15
FIELDGROUP, DC, 2,3,4,14,56,57,58,59,60,61,62,63,64,65,66,67,68,69
FIELDGROUP, AC, 2,3,4,11,16,17,18,19,20,21,22,23,24,25,26,27,28,29,30
STARTUPGROUP, All
[Data]
Comment,Time Stamp (sec),Temperature (K),Magnetic Field (Oe),Moment (emu),M. Std. Err. (emu),Transport Action,Averaging Time (sec),Frequency (Hz),Peak Amplitude (mm),Center Position (mm),Lockin Signal' (V),Lockin Signal (V),Range,M. Quad. Signal (emu),AC Moment (emu),AC M. Std Err. (emu),AC Phase (deg),AC Phase Std. Err. (deg),AC Susceptibility (emu/Oe),AC Suscept. Std Err. (emu/Oe),AC X' (emu/Oe),AC X' Std Err. (emu/Oe),AC X'' (emu/Oe),AC X'' Std Err. (emu/Oe),AC Drive (Oe),AC Frequency (Hz),AC Averaging Time (sec),AC Cycles,AC Range,AC Measure Type,AC Signal' (V),AC Signal'' (V),AC Trim Coil Ratio,AC Trim Coil Phase,Min. Temperature (K),Max. Temperature (K),Min. Field (Oe),Max. Field (Oe),Mass (grams),Motor Lag (deg),Pressure (Torr),Measure Count,Measurement Number,SQUID Status (code),Motor Status (code),Measure Status (code),Motor Current (amps),Motor Temp. (C),Temp. Status (code),Field Status (code),Chamber Status (code),Chamber Temp (K),Redirection State,Average Temp (K),Rotation Angle (deg),Rotator state,DC Moment Fixed Ctr (emu),DC Moment Err Fixed Ctr (emu),DC Moment Free Ctr (emu),DC Moment Err Free Ctr (emu),DC Fixed Fit,DC Free Fit,DC Calculated Center (mm),DC Calculated Center Err (mm),DC Scan Length (mm),DC Scan Time (s),DC Number of Points,DC Squid Drift,DC Min V (V),DC Max V (V),DC Scans per Measure,Map 01,Map 02,Map 03,Map 04,Map 05,Map 06,Map 07,Map 08,Map 09,Map 10,Map 11,Map 12,Map 13,Map 14,Map 15,Map 16
,3772384999.64812,70.0055999755859,200.198501586914,0.00198785410241935,2.23061540761261E-7,1,2,13.9012460708618,4.99945235919426,6.47999998182058,2.38478503006011,0.363236770241618,1,-2.34646842538041E-6,,,,,,,,,,,,,,,,,,,,,70.0055999755859,70.0055999755859,200.198501586914,200.198501586914,52.7016937233998,5.66783657803533,24.3368549346924,28,1,0,0,1,0.314788818359375,30.7917900085449,1,1,1,70.0055999755859,0,70.0055999755859,,,,,,,,,,,,,,,,,,,,,,,,,,,,,,,,,
,3772385012.54505,70.0278434753418,200.198501586914,0.00198188625420383,1.74176003923221E-7,1,2,13.9012460708618,4.99914621462412,6.47999998182058,2.37824187310754,0.356763041293295,10,-6.80178483118446E-6,,,,,,,,,,,,,,,,,,,,,70.0233001708984,70.0323867797852,200.198501586914,200.198501586914,52.6665204400344,5.66817451213709,24.3363590240479,28,1,0,0,1,0.313873291015625,30.7917900085449,2,1,1,70.0323867797852,0,70.0278434753418,,,,,,,,,,,,,,,,,,,,,,,,,,,,,,,,,
,3772385020.64425,70.0130729675293,200.198501586914,0.00199420815035625,6.78800546871655E-7,1,2,13.9012460708618,4.99913519029175,6.47999998182058,2.39303003647133,0.358918365115757,10,-6.89547375226276E-6,,,,,,,,,,,,,,,,,,,,,69.9965286254883,70.0296173095703,200.198501586914,200.198501586914,52.7505455058517,5.66834014090719,24.3233089447021,28,1,0,0,1,0.307083129882812,30.7917900085449,2,1,1,69.9965286254883,0,70.0130729675293,,,,,,,,,,,,,,,,,,,,,,,,,,,,,,,,,
,3772385030.53525,69.783519744873,200.198501586914,0.00208264717720151,8.20880817776434E-7,1,2,13.9012460708618,4.99913799967539,6.47999998182058,2.49914151552156,0.374943156200502,10,-7.11188965247688E-6,,,,,,,,,,,,,,,,,,,,,69.7636947631836,69.8033447265625,200.198501586914,200.198501586914,52.7321772356498,5.66855387698213,24.3396263122559,28,1,0,0,1,0.31494140625,31.2805480957031,2,1,1,69.7636947631836,0,69.783519744873,,,,,,,,,,,,,,,,,,,,,,,,,,,,,,,,,
,3772385038.70004,69.6229057312012,200.198501586914,0.00212569236599098,4.31643400989757E-7,1,2,13.9012460708618,4.99907924306605,6.47999998182058,2.55076577056043,0.382601441494901,10,-7.32965737633041E-6,,,,,,,,,,,,,,,,,,,,,69.6032791137695,69.6425323486328,200.198501586914,200.198501586914,52.6227492429575,5.66896225525582,24.3392677307129,28,1,0,0,1,0.307083129882812,31.2805480957031,2,1,1,69.6032791137695,0,69.6229057312012,,,,,,,,,,,,,,,,,,,,,,,,,,,,,,,,,
,3772385048.64686,69.4901580810547,200.198501586914,0.00215879088447111,3.23477488133694E-7,1,2,13.9012460708618,4.99907470198351,6.47999998182058,2.59050213164985,0.388411949916994,10,-7.56582491600071E-6,,,,,,,,,,,,,,,,,,,,,69.4785919189453,69.5017242431641,200.198501586914,200.198501586914,52.842777671121,5.66921250330271,24.3110618591309,28,1,0,0,1,0.30670166015625,31.2805480957031,2,1,1,69.4785919189453,0,69.4901580810547,,,,,,,,,,,,,,,,,,,,,,,,,,,,,,,,,
,3772385056.85526,69.385555267334,200.198501586914,0.00218502537311916,3.37187667987442E-7,1,2,13.9012460708618,4.99898357888991,6.47999998182058,2.62193692705956,0.392982734571677,10,-7.77387448417303E-6,,,,,,,,,,,,,,,,,,,,,69.368766784668,69.40234375,200.198501586914,200.198501586914,52.6606582261402,5.6693693871063,24.3624687194824,28,1,0,0,1,0.307159423828125,31.7693061828613,2,1,1,69.368766784668,0,69.385555267334,,,,,,,,,,,,,,,,,,,,,,,,,,,,,,,,,
,3772385066.78344,69.250114440918,200.198501586914,0.00221809856506607,4.13772464066127E-7,1,2,13.9012460708618,4.99891103168412,6.47999998182058,2.66152818926642,0.399187856138291,10,-7.67059018275084E-6,,,,,,,,,,,,,,,,,,,,,69.2382965087891,69.2619323730469,200.198501586914,200.198501586914,52.7904085603325,5.66956864341271,24.3501071929932,28,1,0,0,1,0.3070068359375,31.7693061828613,2,1,1,69.2382965087891,0,69.250114440918,,,,,,,,,,,,,,,,,,,,,,,,,,,,,,,,,
,3772385074.91258,69.1340293884277,200.198501586914,0.00224508967038887,3.71054951555038E-7,1,2,13.9012460708618,4.99889095290769,6.47999998182058,2.69391897557671,0.403919144371671,10,-7.86730287969011E-6,,,,,,,,,,,,,,,,,,,,,69.1181488037109,69.1499099731445,200.198501586914,200.198501586914,52.710682451371,5.66985065538398,24.2988185882568,28,1,0,0,1,0.307083129882812,31.7693061828613,2,1,1,69.1181488037109,0,69.1340293884277,,,,,,,,,,,,,,,,,,,,,,,,,,,,,,,,,
,3772385082.80066,69.0200614929199,200.198501586914,0.00227319441255763,4.63488679911715E-7,1,2,13.9012460708618,4.99900090643608,6.47999998182058,2.72772879721882,0.408975945173231,10,-7.97602138403643E-6,,,,,,,,,,,,,,,,,,,,,69.0062789916992,69.0338439941406,200.198501586914,200.198501586914,52.7044294232171,5.66926763318816,24.310998916626,28,1,0,0,1,0.313491821289063,31.7693061828613,2,1,1,69.0033187866211,0,69.0200614929199,,,,,,,,,,,,,,,,,,,,,,,,,,,,,,,,,
,3772385092.97361,68.8639907836914,200.198501586914,0.00231096194873576,5.03292472736073E-7,1,2,13.9012460708618,4.99909978809041,6.47999998182058,2.77310563796344,0.415911483635267,10,-8.00090214617525E-6,,,,,,,,,,,,,,,,,,,,,68.8491363525391,68.8788452148438,200.198501586914,200.198501586914,52.7642240049383,5.66895535692956,24.3664798736572,28,1,0,0,1,0.314102172851562,31.7693061828613,2,1,1,68.8491363525391,0,68.8639907836914,,,,,,,,,,,,,,,,,,,,,,,,,,,,,,,,,
,3772385100.93781,68.741382598877,200.198501586914,0.00234404838643428,4.59936969662909E-7,1,2,13.9012460708618,4.99895909207912,6.47999998182058,2.81271505017332,0.421732030223769,10,-8.21333162693443E-6,,,,,,,,,,,,,,,,,,,,,68.7257614135742,68.7570037841797,200.198501586914,200.198501586914,52.7524995771498,5.66952974706673,24.3548126220703,28,1,0,0,1,0.306625366210937,31.7693061828613,2,1,1,68.7257614135742,0,68.741382598877,,,,,,,,,,,,,,,,,,,,,,,,,,,,,,,,,
,3772385108.98172,68.6134414672852,200.198501586914,0.00237981743638809,5.01171365420668E-7,1,2,13.9012460708618,4.99901525635053,6.47999998182058,2.85566259431629,0.428293952804881,10,-8.23884685786071E-6,,,,,,,,,,,,,,,,,,,,,68.5984344482422,68.6284484863281,200.198501586914,200.198501586914,52.7990064740441,5.66959662128889,24.4026832580566,28,1,0,0,1,0.321578979492188,31.7693061828613,2,1,1,68.5984344482422,0,68.6134414672852,,,,,,,,,,,,,,,,,,,,,,,,,,,,,,,,,
,3772385119.05421,68.4471931457519,200.198501586914,0.00242709127406873,5.4078240756063E-7,1,2,13.9012460708618,4.99900468673784,6.47999998182058,2.91239819550557,0.436683043496551,10,-8.5004335582642E-6,,,,,,,,,,,,,,,,,,,,,68.4309463500977,68.4634399414062,200.198501586914,200.198501586914,52.6868427815344,5.66937214427583,24.3511638641357,28,1,0,0,1,0.30792236328125,31.7693061828613,2,1,1,68.4309463500977,0,68.4471931457519,,,,,,,,,,,,,,,,,,,,,,,,,,,,,,,,,
,3772385127.10793,68.3064460754394,200.198501586914,0.00246677763668509,5.73065551317624E-7,1,2,13.9012460708618,4.99899011791104,6.47999998182058,2.95995671576127,0.44415464375573,10,-8.36173234392075E-6,,,,,,,,,,,,,,,,,,,,,68.2864227294922,68.3264694213867,200.198501586914,200.198501586914,52.7892361175537,5.66946046179044,24.3524112701416,28,1,0,0,1,0.313796997070313,31.7693061828613,2,1,1,68.2864227294922,0,68.3064460754394,,,,,,,,,,,,,,,,,,,,,,,,,,,,,,,,,
,3772385135.16213,68.1733436584473,200.198501586914,0.0025076747198239,4.8530778723332E-7,1,2,13.9012460708618,4.99892045868307,6.47999998182058,3.00898933847239,0.451391069714306,10,-8.59909610008722E-6,,,,,,,,,,,,,,,,,,,,,68.1574630737305,68.1892242431641,200.198501586914,200.198501586914,52.7298323500921,5.670048438817,24.3769950866699,28,1,0,0,1,0.3076171875,31.7693061828613,2,1,1,68.1574630737305,0,68.1733436584473,,,,,,,,,,,,,,,,,,,,,,,,,,,,,,,,,
,3772385143.56969,68.0369377136231,200.198501586914,0.00254980409922543,5.8780357206402E-7,1,2,13.9012460708618,4.99897560017616,6.47999998182058,3.05955615241094,0.459192269015956,10,-8.56795183396281E-6,,,,,,,,,,,,,,,,,,,,,68.026725769043,68.0471496582031,200.198501586914,200.198501586914,52.9232854086018,5.66977595892822,24.3921356201172,28,1,0,0,1,0.307235717773438,31.7693061828613,2,1,1,68.026725769043,0,68.0369377136231,,,,,,,,,,,,,,,,,,,,,,,,,,,,,,,,,
,3772385151.44021,67.8996772766113,200.198501586914,0.00259267056681774,5.95501345223942E-7,1,2,13.9012460708618,4.99892567075818,6.47999998182058,3.1109560725364,0.4668567099313,10,-8.75266098278589E-6,,,,,,,,,,,,,,,,,,,,,67.8865661621094,67.9127883911133,200.198501586914,200.198501586914,52.7396027065825,5.66987568216972,24.3533477783203,28,1,0,0,1,0.3076171875,31.7693061828613,2,1,1,67.8865661621094,0,67.8996772766113,,,,,,,,,,,,,,,,,,,,,,,,,,,,,,,,,
,3772385159.5554,67.7610778808594,200.198501586914,0.00263689628735102,5.46569670182184E-7,1,2,13.9012460708618,4.99887953382456,6.47999998182058,3.16398051698007,0.474820662377367,10,-8.89654333236136E-6,,,,,,,,,,,,,,,,,,,,,67.7412185668945,67.7809371948242,200.198501586914,200.198501586914,52.6887968528325,5.66969407656027,24.351110458374,28,1,0,0,1,0.307464599609375,32.2580642700195,2,1,1,67.7412185668945,0,67.7610778808594,,,,,,,,,,,,,,,,,,,,,,,,,,,,,,,,,
,3772385167.4255,67.6306915283203,200.198501586914,0.00268260514664648,5.93249740221018E-7,1,2,13.9012460708618,4.99891932848469,6.47999998182058,3.2188824731711,0.482924540651166,10,-9.16103180223342E-6,,,,,,,,,,,,,,,,,,,,,67.6149978637695,67.6463851928711,200.198501586914,200.198501586914,52.8079952020152,5.66986264678261,24.364538192749,28,1,0,0,1,0.308074951171875,32.2580642700195,2,1,1,67.6149978637695,0,67.6306915283203,,,,,,,,,,,,,,,,,,,,,,,,,,,,,,,,,
,3772385177.58856,67.4695587158203,200.198501586914,0.0027415482666374,6.1814964110478E-7,1,2,13.9012460708618,4.99885833986449,6.47999998182058,3.28952611618321,0.493697348979649,10,-9.22030335037931E-6,,,,,,,,,,,,,,,,,,,,,67.452766418457,67.4863510131836,200.198501586914,200.198501586914,52.666911254294,5.67012393490357,24.3644599914551,28,1,0,0,1,0.308685302734375,31.7693061828613,2,1,1,67.452766418457,0,67.4695587158203,,,,,,,,,,,,,,,,,,,,,,,,,,,,,,,,,
,3772385185.5179,67.3400840759277,200.198501586914,0.00279028076016545,6.65489011553858E-7,1,2,13.9012460708618,4.99889170170071,6.47999998182058,3.34803021089122,0.502481137546309,10,-9.38142773483719E-6,,,,,,,,,,,,,,,,,,,,,67.3217620849609,67.3584060668945,200.198501586914,200.198501586914,52.7399935208421,5.66982646131618,24.3757152557373,28,1,0,0,1,0.308303833007812,32.2580642700195,2,1,1,67.3217620849609,0,67.3400840759277,,,,,,,,,,,,,,,,,,,,,,,,,,,,,,,,,
,3772385193.60656,67.2069053649902,200.198501586914,0.00284096679335085,7.35577763594442E-7,1,2,13.9012460708618,4.99887074898235,6.47999998182058,3.40881111396466,0.511714019118738,10,-9.46159564564575E-6,,,,,,,,,,,,,,,,,,,,,67.1923217773437,67.2214889526367,200.198501586914,200.198501586914,52.7001304663613,5.66995225421896,24.3652420043945,28,1,0,0,1,0.308456420898438,31.7693061828613,2,1,1,67.1923217773437,0,67.2069053649902,,,,,,,,,,,,,,,,,,,,,,,,,,,,,,,,,
,3772385201.64741,67.0643653869629,200.198501586914,0.00289301765421925,7.75929799428777E-7,1,2,13.9012460708618,4.99913840257812,6.47999998182058,3.47150672297476,0.521266416846125,10,-9.5201619325576E-6,,,,,,,,,,,,,,,,,,,,,67.0483474731445,67.0803833007812,200.198501586914,200.198501586914,52.690360109871,5.66893236324312,24.3388557434082,28,1,0,0,1,0.308380126953125,32.2580642700195,2,1,1,67.0483474731445,0,67.0643653869629,,,,,,,,,,,,,,,,,,,,,,,,,,,,,,,,,
,3772385209.69088,66.9313125610352,200.198501586914,0.0029468019457135,6.74809430305478E-7,1,2,13.9012460708618,4.99902035028127,6.47999998182058,3.5359423139636,0.530846345054501,10,-9.77493847984275E-6,,,,,,,,,,,,,,,,,,,,,66.9161529541016,66.9464721679688,200.198501586914,200.198501586914,52.6606582261402,5.66946553686124,24.3378105163574,28,1,0,0,1,0.315017700195313,32.2580642700195,2,1,1,66.9161529541016,0,66.9313125610352,,,,,,,,,,,,,,,,,,,,,,,,,,,,,,,,,
,3772385219.00454,66.7790603637695,200.198501586914,0.00301659151212975,8.12685664126136E-7,1,2,13.9012460708618,4.99900053101578,6.47999998182058,3.61963638812338,0.543597528870284,10,-9.85459735522141E-6,,,,,,,,,,,,,,,,,,,,,66.7505569458008,66.8075637817383,200.198501586914,200.198501586914,52.741165963621,5.66939025974137,24.3601016998291,28,1,0,0,1,0.313568115234375,32.2580642700195,2,1,1,66.7505569458008,0,66.7790603637695,,,,,,,,,,,,,,,,,,,,,,,,,,,,,,,,,
,3772385228.23735,66.6310386657715,200.198501586914,0.00307413468511574,8.40598215220337E-7,1,2,13.9012460708618,4.99906381529216,6.47999998182058,3.68875576567336,0.553931678456163,10,-1.00802398636752E-5,,,,,,,,,,,,,,,,,,,,,66.6212921142578,66.6407852172852,200.198501586914,200.198501586914,52.8029146166402,5.66950464058102,24.3269844055176,28,1,0,0,1,0.307998657226562,32.2580642700195,2,1,1,66.6212921142578,0,66.6310386657715,,,,,,,,,,,,,,,,,,,,,,,,,,,,,,,,,
,3772385236.02752,66.5020332336426,200.198501586914,0.00313141211923285,7.24587395001969E-7,1,2,13.9012460708618,4.9989909938343,6.47999998182058,3.75738123045148,0.56441314755582,10,-1.0124491448674E-5,,,,,,,,,,,,,,,,,,,,,66.4896926879883,66.5143737792969,200.198501586914,200.198501586914,52.8232369581402,5.66972754928533,24.3361873626709,28,1,0,0,1,0.307388305664063,32.2580642700195,2,1,1,66.48681640625,0,66.5020332336426,,,,,,,,,,,,,,,,,,,,,,,,,,,,,,,,,
,3772385244.15662,66.3746070861816,200.198501586914,0.00318832856997708,7.45082919035377E-7,1,2,13.9012460708618,4.99890959844559,6.47999998182058,3.82557600007277,0.57473317714536,10,-1.02464190432347E-5,,,,,,,,,,,,,,,,,,,,,66.3563003540039,66.3929138183594,200.198501586914,200.198501586914,52.8083860162748,5.67039891206112,24.3206443786621,28,1,0,0,1,0.308151245117188,32.2580642700195,2,1,1,66.3563003540039,0,66.3746070861816,,,,,,,,,,,,,,,,,,,,,,,,,,,,,,,,,
,3772385254.09356,66.2156639099121,200.198501586914,0.00326217046652382,8.13906580546939E-7,1,2,13.9012460708618,4.99886042721552,6.47999998182058,3.91410638516245,0.588139493074462,10,-1.0397327372124E-5,,,,,,,,,,,,,,,,,,,,,66.2016372680664,66.2296905517578,200.198501586914,200.198501586914,52.710682451371,5.6700329966592,24.3133029937744,28,1,0,0,1,0.30731201171875,32.2580642700195,2,1,1,66.2016372680664,0,66.2156639099121,,,,,,,,,,,,,,,,,,,,,,,,,,,,,,,,,
,3772385262.21237,66.0789031982422,200.198501586914,0.00332557546539139,8.81582204795172E-7,1,2,13.9012460708618,4.99890488136133,6.47999998182058,3.99021487555203,0.599694732165633,10,-1.05023737447057E-5,,,,,,,,,,,,,,,,,,,,,66.0623168945313,66.0954895019531,200.198501586914,200.198501586914,52.852938841871,5.66985437172972,24.3241653442383,28,1,0,0,1,0.307769775390625,32.2580642700195,2,1,1,66.0623168945313,0,66.0789031982422,,,,,,,,,,,,,,,,,,,,,,,,,,,,,,,,,
,3772385270.13111,65.9474563598633,200.198501586914,0.00339247912967539,9.16923880082433E-7,1,2,13.9012460708618,4.99882922389688,6.47999998182058,4.07038746808869,0.611846307853134,10,-1.06302561321938E-5,,,,,,,,,,,,,,,,,,,,,65.9271697998047,65.9677429199219,200.198501586914,200.198501586914,52.7974432170056,5.6701924258127,24.3474445343018,28,1,0,0,1,0.307083129882812,32.2580642700195,2,1,1,65.9271697998047,0,65.9474563598633,,,,,,,,,,,,,,,,,,,,,,,,,,,,,,,,,
,3772385280.24199,65.7785186767578,200.198501586914,0.00348123401064844,8.78551910487311E-7,1,2,13.9012460708618,4.99880104782372,6.47999998182058,4.17687148302744,0.627674483273077,10,-1.10535500690869E-5,,,,,,,,,,,,,,,,,,,,,65.7590789794922,65.7979583740234,200.198501586914,200.198501586914,52.7720402901306,5.66992687511694,24.3211650848389,28,1,0,0,1,0.307464599609375,32.2580642700195,2,1,1,65.7590789794922,0,65.7785186767578,,,,,,,,,,,,,,,,,,,,,,,,,,,,,,,,,
,3772385288.24321,65.6473808288574,200.198501586914,0.00355580842558186,9.88888463689927E-7,1,2,13.9012460708618,4.99880172300445,6.47999998182058,4.26636684979955,0.64100128303757,10,-1.1389784104865E-5,,,,,,,,,,,,,,,,,,,,,65.6326141357422,65.6621475219727,200.198501586914,200.198501586914,52.7450741062171,5.6698941825995,24.297191619873,28,1,0,0,1,0.308685302734375,32.2580642700195,2,1,1,65.6326141357422,0,65.6473808288574,,,,,,,,,,,,,,,,,,,,,,,,,,,,,,,,,
,3772385296.31405,65.5118293762207,200.198501586914,0.00363349532846787,1.04960721977858E-6,1,2,13.9012460708618,4.99866723009114,6.47999998182058,4.35934062164582,0.655449384842808,10,-1.1248005710959E-5,,,,,,,,,,,,,,,,,,,,,65.4941253662109,65.5295333862305,200.198501586914,200.198501586914,52.8545020989094,5.67068676643687,24.308666229248,28,1,0,0,1,0.308761596679687,32.2580642700195,2,1,1,65.4941253662109,0,65.5118293762207,,,,,,,,,,,,,,,,,,,,,,,,,,,,,,,,,
,3772385306.42934,65.3427925109863,200.198501586914,0.00373563085904279,1.1452909107798E-6,1,2,13.9012460708618,4.99867789965743,6.47999998182058,4.4818817176966,0.673947597360415,10,-1.15042519287288E-5,,,,,,,,,,,,,,,,,,,,,65.3285369873047,65.357048034668,200.198501586914,200.198501586914,52.7845463464383,5.67059086256494,24.321704864502,28,1,0,0,1,0.307540893554687,32.2580642700195,2,1,1,65.3285369873047,0,65.3427925109863,,,,,,,,,,,,,,,,,,,,,,,,,,,,,,,,,
,3772385314.45628,65.2087020874023,200.198501586914,0.00382013010350448,1.15774244523628E-6,1,2,13.9012460708618,4.99877252361037,6.47999998182058,4.58335901057182,0.689369219510658,10,-1.16321748683852E-5,,,,,,,,,,,,,,,,,,,,,65.1902694702148,65.2271347045898,200.198501586914,200.198501586914,52.671991839669,5.67045090195629,24.2690143585205,28,1,0,0,1,0.308609008789063,32.2580642700195,2,1,1,65.1902694702148,0,65.2087020874023,,,,,,,,,,,,,,,,,,,,,,,,,,,,,,,,,
,3772385322.50305,65.0754241943359,200.198501586914,0.00390813559884667,1.16488265969742E-6,1,2,13.9012460708618,4.99875776232213,6.47999998182058,4.68893462052021,0.70520250643812,10,-1.19376594786644E-5,,,,,,,,,,,,,,,,,,,,,65.0600738525391,65.0907745361328,200.198501586914,200.198501586914,52.7943167029287,5.67068293453061,24.3055076599121,28,1,0,0,1,0.308151245117188,32.7468223571777,2,1,1,65.0600738525391,0,65.0754241943359,,,,,,,,,,,,,,,,,,,,,,,,,,,,,,,,,
,3772385331.94245,64.9217834472656,200.198501586914,0.00402284751719197,1.30300560789512E-6,1,2,13.9012460708618,4.99877904571006,6.47999998182058,4.82654781889715,0.726204216092854,10,-1.2039405020752E-5,,,,,,,,,,,,,,,,,,,,,64.8932189941406,64.9503479003906,200.198501586914,200.198501586914,52.6942682524671,5.67087188363623,24.3096580505371,28,1,0,0,1,0.307769775390625,32.2580642700195,2,1,1,64.8932189941406,0,64.9217834472656,,,,,,,,,,,,,,,,,,,,,,,,,,,,,,,,,
,3772385342.64557,64.7398719787598,200.198501586914,0.00414370503513548,1.30094729220577E-6,1,2,13.9012460708618,4.99873762742994,6.47999998182058,4.97147437773744,0.748131586839516,10,-1.23019386500796E-5,,,,,,,,,,,,,,,,,,,,,64.7207412719727,64.7590026855469,200.198501586914,200.198501586914,52.8302716148133,5.67062655422799,24.2916069030762,28,1,0,0,1,0.307083129882812,32.2580642700195,2,1,1,64.7207412719727,0,64.7398719787598,,,,,,,,,,,,,,,,,,,,,,,,,,,,,,,,,
,3772385352.72103,64.5637092590332,200.198501586914,0.00427123065773076,1.49888276912965E-6,1,2,13.9012460708618,4.99865938400155,6.47999998182058,5.12440339237664,0.770869907514304,10,-1.29048289805303E-5,,,,,,,,,,,,,,,,,,,,,64.5477905273437,64.5796279907227,200.198501586914,200.198501586914,52.7661780762363,5.67077671086229,24.2835063934326,28,1,0,0,1,0.308151245117188,32.2580642700195,2,1,1,64.5477905273437,0,64.5637092590332,,,,,,,,,,,,,,,,,,,,,,,,,,,,,,,,,
,3772385360.77435,64.4349021911621,200.198501586914,0.00437798501505251,1.44397512763121E-6,1,2,13.9012460708618,4.99876922482572,6.47999998182058,5.25256805271206,0.790659761761753,10,-1.28117808677971E-5,,,,,,,,,,,,,,,,,,,,,64.4193420410156,64.4504623413086,200.198501586914,200.198501586914,52.7775116897652,5.67056793646182,24.2817478179932,28,1,0,0,1,0.308380126953125,32.7468223571777,2,1,1,64.4193420410156,0,64.4349021911621,,,,,,,,,,,,,,,,,,,,,,,,,,,,,,,,,
,3772385368.81693,64.2988891601562,200.198501586914,0.00448962542084377,1.44332077603832E-6,1,2,13.9012460708618,4.99863236249264,6.47999998182058,5.38628025689535,0.810936772268478,10,-1.30165940537335E-5,,,,,,,,,,,,,,,,,,,,,64.2820281982422,64.3157501220703,200.198501586914,200.198501586914,52.741165963621,5.6714741221186,24.2529983520508,28,1,0,0,1,0.307693481445313,32.7468223571777,2,1,1,64.2820281982422,0,64.2988891601562,,,,,,,,,,,,,,,,,,,,,,,,,,,,,,,,,
,3772385378.22084,64.1417503356934,200.198501586914,0.00463673941979302,1.61928820755023E-6,1,2,13.9012460708618,4.99858771776672,6.47999998182058,5.56267414912593,0.83770195387602,10,-1.32735613142413E-5,,,,,,,,,,,,,,,,,,,,,64.1141738891602,64.1693267822266,200.198501586914,200.198501586914,52.722797693419,5.67107764079621,24.2807121276855,28,1,0,0,1,0.308761596679687,32.2580642700195,2,1,1,64.1141738891602,0,64.1417503356934,,,,,,,,,,,,,,,,,,,,,,,,,,,,,,,,,
,3772385386.94622,63.9983024597168,200.198501586914,0.00476028657768041,1.56082518966085E-6,1,2,13.9012460708618,4.99863662364315,6.47999998182058,5.71096900348015,0.860053388509652,10,-1.36115817489433E-5,,,,,,,,,,,,,,,,,,,,,63.9815368652344,64.0150680541992,200.198501586914,200.198501586914,52.7528903914094,5.67108101859461,24.2654247283936,28,1,0,0,1,0.3076171875,32.2580642700195,2,1,1,63.9815368652344,0,63.9983024597168,,,,,,,,,,,,,,,,,,,,,,,,,,,,,,,,,
,3772385395.22934,63.8626441955566,200.198501586914,0.00489026755735757,1.69680046413127E-6,1,2,13.9012460708618,4.9986295189713,6.47999998182058,5.86685340309663,0.883818797437287,10,-1.37471077530771E-5,,,,,,,,,,,,,,,,,,,,,63.8504371643066,63.8748512268066,200.198501586914,200.198501586914,52.7302231643517,5.67092467280078,24.2555446624756,28,1,0,0,1,0.30853271484375,32.2580642700195,2,1,1,63.8504371643066,0,63.8626441955566,,,,,,,,,,,,,,,,,,,,,,,,,,,,,,,,,
,3772385403.38791,63.7180366516113,200.198501586914,0.00502700147634516,1.92407850804908E-6,1,2,13.9012460708618,4.99868930796031,6.47999998182058,6.03096828276367,0.908718808917257,10,-1.39874337176084E-5,,,,,,,,,,,,,,,,,,,,,63.6974716186523,63.7386016845703,200.198501586914,200.198501586914,52.7333496784287,5.67063554923861,24.2297039031982,28,1,0,0,1,0.307464599609375,32.7468223571777,2,1,1,63.6974716186523,0,63.7180366516113,,,,,,,,,,,,,,,,,,,,,,,,,,,,,,,,,
,3772385413.29557,63.5547027587891,200.198501586914,0.00520757018777398,1.97994333662916E-6,1,2,13.9012460708618,4.99870521139564,6.47999998182058,6.24768011815053,0.941019813240256,10,-1.47768696946226E-5,,,,,,,,,,,,,,,,,,,,,63.5409545898438,63.5684509277344,200.198501586914,200.198501586914,52.6630031116979,5.67059067324465,24.2388305664062,28,1,0,0,1,0.307464599609375,32.2580642700195,2,1,1,63.5379219055176,0,63.5547027587891,,,,,,,,,,,,,,,,,,,,,,,,,,,,,,,,,
,3772385421.39198,63.4202728271484,200.198501586914,0.00535960080190924,2.01715903133201E-6,1,2,13.9012460708618,4.99863898367927,6.47999998182058,6.42986417156641,0.969070303342701,10,-1.47110075384496E-5,,,,,,,,,,,,,,,,,,,,,63.4014892578125,63.4390563964844,200.198501586914,200.198501586914,52.7790749468037,5.67074500497461,24.2388553619385,28,1,0,0,1,0.308074951171875,32.2580642700195,2,1,1,63.4014892578125,0,63.4202728271484,,,,,,,,,,,,,,,,,,,,,,,,,,,,,,,,,
,3772385429.3862,63.2858238220215,200.198501586914,0.00551926017171088,2.20923310754367E-6,1,2,13.9012460708618,4.99855162433964,6.47999998182058,6.62120167602981,0.998182002446529,10,-1.49255334982753E-5,,,,,,,,,,,,,,,,,,,,,63.2686653137207,63.3029823303223,200.198501586914,200.198501586914,52.8119033446114,5.67139163916815,24.2663078308105,28,1,0,0,1,0.308609008789063,32.7468223571777,2,1,1,63.2686653137207,0,63.2858238220215,,,,,,,,,,,,,,,,,,,,,,,,,,,,,,,,,
,3772385437.31238,63.1543083190918,200.198501586914,0.00568724698357344,2.26894077261163E-6,1,2,13.9012460708618,4.9985619594795,6.47999998182058,6.82270781816864,1.02882524067064,10,-1.51637464353314E-5,,,,,,,,,,,,,,,,,,,,,63.1416435241699,63.1669731140137,200.198501586914,200.198501586914,52.7779025040248,5.67103589986537,24.2293510437012,28,1,0,0,1,0.307998657226562,32.7468223571777,2,1,1,63.1416435241699,0,63.1543083190918,,,,,,,,,,,,,,,,,,,,,,,,,,,,,,,,,
,3772385445.3755,63.0180644989014,200.198501586914,0.00586537589400889,2.35609211749739E-6,1,2,13.9012460708618,4.99859190148413,6.47999998182058,7.03643844824538,1.06119603343533,10,-1.5523408176446E-5,,,,,,,,,,,,,,,,,,,,,63.0021438598633,63.0339851379395,200.198501586914,200.198501586914,52.7997881025633,5.67128399949352,24.2131462097168,28,1,0,0,1,0.307846069335937,32.2580642700195,2,1,1,63.0021438598633,0,63.0180644989014,,,,,,,,,,,,,,,,,,,,,,,,,,,,,,,,,
,3772385455.47958,62.8495559692383,200.198501586914,0.00610134956324268,2.4963832593179E-6,1,2,13.9012460708618,4.99866549659806,6.47999998182058,7.31963561602553,1.10418780200383,10,-1.59184576051618E-5,,,,,,,,,,,,,,,,,,,,,62.8326950073242,62.8664169311523,200.198501586914,200.198501586914,52.7220160648998,5.67120572018433,24.2616939544678,28,1,0,0,1,0.307998657226562,32.7468223571777,2,1,1,62.8326950073242,0,62.8495559692383,,,,,,,,,,,,,,,,,,,,,,,,,,,,,,,,,
,3772385463.51057,62.7194232940674,200.198501586914,0.0063019409007074,2.57172176837624E-6,1,2,13.9012460708618,4.99870182095752,6.47999998182058,7.56028103484333,1.14099931210058,10,-1.60265821083691E-5,,,,,,,,,,,,,,,,,,,,,62.702564239502,62.7362823486328,200.198501586914,200.198501586914,52.7286599073133,5.67075243991447,24.1886157989502,28,1,0,0,1,0.308074951171875,32.2580642700195,2,1,1,62.702564239502,0,62.7194232940674,,,,,,,,,,,,,,,,,,,,,,,,,,,,,,,,,
,3772385471.60935,62.5865726470947,200.198501586914,0.00651454069503655,2.82582145042758E-6,1,2,13.9012460708618,4.99869747492431,6.47999998182058,7.81528620550404,1.17972406138958,10,-1.63722090315194E-5,,,,,,,,,,,,,,,,,,,,,62.5712928771973,62.6018524169922,200.198501586914,200.198501586914,52.8537204703902,5.6710251436355,24.1981258392334,28,1,0,0,1,0.3076171875,32.7468223571777,2,1,1,62.5712928771973,0,62.5865726470947,,,,,,,,,,,,,,,,,,,,,,,,,,,,,,,,,
,3772385480.92143,62.4290943145752,200.198501586914,0.00679845559523318,3.05237162397703E-6,1,2,13.9012460708618,4.99855721570919,6.47999998182058,8.15555480253734,1.2311697969155,10,-1.70189845690951E-5,,,,,,,,,,,,,,,,,,,,,62.4013481140137,62.4568405151367,200.198501586914,200.198501586914,52.6809805676402,5.67181575819674,24.2220115661621,28,1,0,0,1,0.308609008789063,32.7468223571777,2,1,1,62.4013481140137,0,62.4290943145752,,,,,,,,,,,,,,,,,,,,,,,,,,,,,,,,,
,3772385490.02311,62.2834815979004,200.198501586914,0.0070413227874476,3.24607683158197E-6,1,2,13.9012460708618,4.99853543541815,6.47999998182058,8.44680388200927,1.27545058848838,10,-1.73713967984954E-5,,,,,,,,,,,,,,,,,,,,,62.2744331359863,62.2925300598145,200.198501586914,200.198501586914,52.7751668042075,5.67190131560579,24.2126731872559,28,1,0,0,1,0.309066772460937,32.7468223571777,2,1,1,62.270881652832,0,62.2834815979004,,,,,,,,,,,,,,,,,,,,,,,,,,,,,,,,,
,3772385497.92664,62.1413516998291,200.198501586914,0.0072997886386289,3.48790128939115E-6,1,2,13.9012460708618,4.99853853368144,6.47999998182058,8.75688072454698,1.32218934115199,10,-1.807607175846E-5,,,,,,,,,,,,,,,,,,,,,62.1270065307617,62.1556968688965,200.198501586914,200.198501586914,52.7165446652652,5.6717611590364,24.2236404418945,28,1,0,0,1,0.308914184570313,32.7468223571777,2,1,1,62.1270065307617,0,62.1413516998291,,,,,,,,,,,,,,,,,,,,,,,,,,,,,,,,,
,3772385506.10707,62.0029411315918,200.198501586914,0.00757544389634762,3.68899680396203E-6,1,2,13.9012460708618,4.99857178626948,6.47999998182058,9.08748470137858,1.37316900388687,10,-1.78929249332997E-5,,,,,,,,,,,,,,,,,,,,,61.9842071533203,62.0216751098633,200.198501586914,200.198501586914,52.675118353746,5.67189357506427,24.1850490570068,28,1,0,0,1,0.308914184570313,32.7468223571777,2,1,1,61.9842071533203,0,62.0029411315918,,,,,,,,,,,,,,,,,,,,,,,,,,,,,,,,,
,3772385515.95034,61.8429756164551,200.198501586914,0.00794559545229521,3.97446915036187E-6,1,2,13.9012460708618,4.99865704876071,6.47999998182058,9.53172291326406,1.44045591860866,10,-1.86367514397735E-5,,,,,,,,,,,,,,,,,,,,,61.8292198181152,61.8567314147949,200.198501586914,200.198501586914,52.7556260912267,5.67139212604341,24.1706314086914,28,1,0,0,1,0.308456420898438,32.7468223571777,2,1,1,61.8292198181152,0,61.8429756164551,,,,,,,,,,,,,,,,,,,,,,,,,,,,,,,,,
,3772385524.12121,61.7113494873047,200.198501586914,0.00826532581197682,4.24501348107901E-6,1,2,13.9012460708618,4.998747475988,6.47999998182058,9.91545977479578,1.49892799599044,10,-1.89947932322477E-5,,,,,,,,,,,,,,,,,,,,,61.6922721862793,61.7304267883301,200.198501586914,200.198501586914,52.7454649204767,5.6712102409957,24.1822071075439,28,1,0,0,1,0.3076171875,32.7468223571777,2,1,1,61.6922721862793,0,61.7113494873047,,,,,,,,,,,,,,,,,,,,,,,,,,,,,,,,,
,3772385531.99126,61.5762825012207,200.198501586914,0.00860799393630327,4.60670648657482E-6,1,2,13.9012460708618,4.99867728352935,6.47999998182058,10.3263262292133,1.56110081343932,10,-1.9731918341176E-5,,,,,,,,,,,,,,,,,,,,,61.5602836608887,61.5922813415527,200.198501586914,200.198501586914,52.8412144140825,5.6715153301992,24.1812973022461,28,1,0,0,1,0.308074951171875,32.7468223571777,2,1,1,61.5602836608887,0,61.5762825012207,,,,,,,,,,,,,,,,,,,,,,,,,,,,,,,,,
,3772385542.11127,61.4088954925537,200.198501586914,0.00907388577227298,5.03367199290398E-6,1,2,13.9012460708618,4.99877201625568,6.47999998182058,10.8854247817417,1.64619530486895,10,-2.03339067987152E-5,,,,,,,,,,,,,,,,,,,,,61.3919525146484,61.425838470459,200.198501586914,200.198501586914,52.7153722224863,5.67138792916085,24.1964263916016,28,1,0,0,1,0.31402587890625,32.7468223571777,2,1,1,61.3919525146484,0,61.4088954925537,,,,,,,,,,,,,,,,,,,,,,,,,,,,,,,,,
,3772385550.13135,61.270694732666,200.198501586914,0.00947798751255443,5.41992758374612E-6,1,2,13.9012460708618,4.9988548938295,6.47999998182058,11.3704225489943,1.7198475362792,10,-2.09898135489834E-5,,,,,,,,,,,,,,,,,,,,,61.2547340393066,61.2866554260254,200.198501586914,200.198501586914,52.8009605453421,5.67061117694853,24.1453151702881,28,1,0,0,1,0.3082275390625,32.7468223571777,2,1,1,61.2547340393066,0,61.270694732666,,,,,,,,,,,,,,,,,,,,,,,,,,,,,,,,,
,3772385558.15898,61.1387672424316,200.198501586914,0.0099152664939124,5.86460348963176E-6,1,2,13.9012460708618,4.99870994711792,6.47999998182058,11.8943631133509,1.80017588623302,10,-2.10788145600988E-5,,,,,,,,,,,,,,,,,,,,,61.123779296875,61.1537551879883,200.198501586914,200.198501586914,52.8208920725825,5.67108200606028,24.131462097168,28,1,0,0,1,0.307388305664063,32.7468223571777,2,1,1,61.123779296875,0,61.1387672424316,,,,,,,,,,,,,,,,,,,,,,,,,,,,,,,,,
,3772385568.23261,60.9741687774658,200.198501586914,0.0105095684808889,6.40238406389648E-6,1,2,13.9012460708618,4.99871529778071,6.47999998182058,12.6072230880377,1.90862685654244,10,-2.1884426764113E-5,,,,,,,,,,,,,,,,,,,,,60.9577217102051,60.9906158447266,200.198501586914,200.198501586914,52.7083375658133,5.67131243394715,24.1824359893799,28,1,0,0,1,0.3094482421875,32.7468223571777,2,1,1,60.9577217102051,0,60.9741687774658,,,,,,,,,,,,,,,,,,,,,,,,,,,,,,,,,
,3772385576.30871,60.8342933654785,200.198501586914,0.0110307229762106,6.95040417871171E-6,1,2,13.9012460708618,4.99859641283856,6.47999998182058,13.2318871672226,2.00363749865213,10,-2.26096010189678E-5,,,,,,,,,,,,,,,,,,,,,60.8181648254394,60.8504219055176,200.198501586914,200.198501586914,52.7263150217556,5.67141755166235,24.1578254699707,28,1,0,0,1,0.308151245117188,32.7468223571777,2,1,1,60.8181648254394,0,60.8342933654785,,,,,,,,,,,,,,,,,,,,,,,,,,,,,,,,,
,3772385584.3484,60.6989440917969,200.198501586914,0.0115973304068004,7.59957409830505E-6,1,2,13.9012460708618,4.99874772077724,6.47999998182058,13.9119228891796,2.10815319738813,10,-2.25148885133126E-5,,,,,,,,,,,,,,,,,,,,,60.6817321777344,60.7161560058594,200.198501586914,200.198501586914,52.7368670067652,5.67118318689843,24.1552715301514,28,1,0,0,1,0.308380126953125,32.7468223571777,2,1,1,60.6817321777344,0,60.6989440917969,,,,,,,,,,,,,,,,,,,,,,,,,,,,,,,,,
,3772385593.76724,60.5414867401123,200.198501586914,0.0123794484384363,8.54045509571008E-6,1,2,13.9012460708618,4.99879639988622,6.47999998182058,14.8502100102178,2.25120228779116,10,-2.33283240307999E-5,,,,,,,,,,,,,,,,,,,,,60.5164604187012,60.5665130615234,200.198501586914,200.198501586914,52.793925888669,5.67116038973699,24.1393547058105,28,1,0,0,1,0.307464599609375,32.7468223571777,2,1,1,60.5164604187012,0,60.5414867401123,,,,,,,,,,,,,,,,,,,,,,,,,,,,,,,,,
,3772385602.48075,60.4020538330078,200.198501586914,0.0130735025973846,9.40496469119526E-6,1,2,13.9012460708618,4.99882149710705,6.47999998182058,15.6827042289605,2.37869849264529,10,-2.35808602955766E-5,,,,,,,,,,,,,,,,,,,,,60.3846092224121,60.4194984436035,200.198501586914,200.198501586914,52.8126849731306,5.67134705400447,24.1419124603271,28,1,0,0,1,0.30792236328125,32.7468223571777,2,1,1,60.3846092224121,0,60.4020538330078,,,,,,,,,,,,,,,,,,,,,,,,,,,,,,,,,
,3772385610.77106,60.2551212310791,200.198501586914,0.0138372899950143,1.02848281192467E-5,1,2,13.9012460708618,4.99881199754605,6.47999998182058,16.5988415736084,2.51793358161886,10,-2.47315399685607E-5,,,,,,,,,,,,,,,,,,,,,60.2441139221191,60.2661285400391,200.198501586914,200.198501586914,52.8298808005537,5.6714673703913,24.1167678833008,28,1,0,0,1,0.309295654296875,32.7468223571777,2,1,1,60.2441139221191,0,60.2551212310791,,,,,,,,,,,,,,,,,,,,,,,,,,,,,,,,,
,3772385618.96006,60.1230983734131,200.198501586914,0.0146796541879818,1.14693856102132E-5,1,2,13.9012460708618,4.99887657291301,6.47999998182058,17.609357761996,2.67310236420031,10,-2.47049822653719E-5,,,,,,,,,,,,,,,,,,,,,60.1022758483887,60.1439208984375,200.198501586914,200.198501586914,52.7204528078614,5.67112234256498,24.1035137176514,28,1,0,0,1,0.31524658203125,32.7468223571777,2,1,1,60.1022758483887,0,60.1230983734131,,,,,,,,,,,,,,,,,,,,,,,,,,,,,,,,,
,3772385633.96969,59.8766975402832,200.198501586914,0.0166527063386066,1.41664559420352E-5,1,2,13.9012460708618,4.99882763758627,6.47999998182058,19.9744792375645,3.0416486685165,10,-2.02674977447265E-5,,,,,,,,,,,,,,,,,,,,,59.8470497131348,59.9063453674316,200.198501586914,200.198501586914,52.7962707742267,5.67111556615657,24.0894222259521,28,1,0,0,1,0.307235717773438,32.7468223571777,2,1,1,59.8470497131348,0,59.8766975402832,,,,,,,,,,,,,,,,,,,,,,,,,,,,,,,,,
,3772385642.77837,59.7261047363281,200.198501586914,0.017820546076001,1.60400612584187E-5,1,2,13.9012460708618,4.99882456501065,6.47999998182058,21.3752074346859,3.25525390749246,10,-2.1438767666278E-5,,,,,,,,,,,,,,,,,,,,,59.7106094360352,59.7416000366211,200.198501586914,200.198501586914,52.7454649204767,5.67136930719738,24.0774345397949,28,1,0,0,1,0.313796997070313,32.7468223571777,2,1,1,59.7106094360352,0,59.7261047363281,,,,,,,,,,,,,,,,,,,,,,,,,,,,,,,,,
,3772385652.92696,59.557918548584,200.198501586914,0.0194827178959373,1.83997011741468E-5,1,2,13.9012460708618,4.99876118616701,6.47999998182058,23.3685276898929,3.55873123467359,10,-2.35098092529274E-5,,,,,,,,,,,,,,,,,,,,,59.5380935668945,59.5777435302734,200.198501586914,200.198501586914,52.8400419713037,5.67124406698332,24.1252212524414,28,1,0,0,1,0.308151245117188,32.7468223571777,2,1,1,59.5380935668945,0,59.557918548584,,,,,,,,,,,,,,,,,,,,,,,,,,,,,,,,,
,3772385666.61327,59.327392578125,200.198501586914,0.0218356397343454,2.20461207499939E-5,1,2,13.9012460708618,4.99869543260789,6.47999998182058,26.189524182179,3.99318311048986,10,-2.23973034476672E-5,,,,,,,,,,,,,,,,,,,,,59.327392578125,59.327392578125,200.198501586914,200.198501586914,52.7552352769671,5.67101064758529,24.0604496002197,28,1,0,0,1,0.307998657226562,32.7468223571777,2,1,1,59.327392578125,0,59.327392578125,,,,,,,,,,,,,,,,,,,,,,,,,,,,,,,,,
,3772385677.02764,59.1605453491211,200.198501586914,0.0246869500266041,2.68195959240905E-5,1,2,13.9012460708618,4.99864698045823,6.47999998182058,29.6191725546425,4.44804771540827,100,-8.07809790603679E-5,,,,,,,,,,,,,,,,,,,,,59.146167755127,59.1749229431152,200.198501586914,200.198501586914,52.8029146166402,5.6715021088647,24.0746459960938,28,1,0,0,1,0.308303833007812,32.7468223571777,2,1,1,59.146167755127,0,59.1605453491211,,,,,,,,,,,,,,,,,,,,,,,,,,,,,,,,,
,3772385685.31329,59.0126438140869,200.198501586914,0.0269349783210897,3.09401924904498E-5,1,2,13.9012460708618,4.99857354380029,6.47999998182058,32.3156234136839,4.85327249852367,100,-8.79036190275787E-5,,,,,,,,,,,,,,,,,,,,,59.0012016296387,59.0240859985352,200.198501586914,200.198501586914,52.7966615884864,5.67170928856722,24.0607471466064,28,1,0,0,1,0.30914306640625,32.7468223571777,2,1,1,59.0012016296387,0,59.0126438140869,,,,,,,,,,,,,,,,,,,,,,,,,,,,,,,,,
,3772385693.49759,58.8884983062744,200.198501586914,0.029532957030392,3.5881529940285E-5,1,2,13.9012460708618,4.99862410617576,6.47999998182058,35.432637634184,5.32441639709528,100,-9.3920714973977E-5,,,,,,,,,,,,,,,,,,,,,58.8729667663574,58.9040298461914,200.198501586914,200.198501586914,52.720843622121,5.67168262519269,24.0337505340576,28,1,0,0,1,0.308990478515625,32.7468223571777,2,1,1,58.8618545532227,0,58.8884983062744,,,,,,,,,,,,,,,,,,,,,,,,,,,,,,,,,
,3772385701.31739,58.7498989105225,200.198501586914,0.0325204223497371,4.10043587871852E-5,1,2,13.9012460708618,4.99857682612902,6.47999998182058,39.0164505082749,5.86245792508558,100,-0.000103823606508623,,,,,,,,,,,,,,,,,,,,,58.7314758300781,58.7683219909668,200.198501586914,200.198501586914,52.7294415358325,5.67186689704425,24.0317630767822,28,1,0,0,1,0.308074951171875,32.7468223571777,2,1,1,58.7314758300781,0,58.7498989105225,,,,,,,,,,,,,,,,,,,,,,,,,,,,,,,,,
,3772385709.26293,58.6198043823242,200.198501586914,0.0359654193104692,4.73277161949588E-5,1,2,13.9012460708618,4.99855895702571,6.47999998182058,43.1486516787113,6.48817224722943,100,-0.000110888178783508,,,,,,,,,,,,,,,,,,,,,58.6053657531738,58.6342430114746,200.198501586914,200.198501586914,52.8056503164575,5.67190612048918,24.0568065643311,28,1,0,0,1,0.308914184570313,32.7468223571777,2,1,1,58.6053657531738,0,58.6198043823242,,,,,,,,,,,,,,,,,,,,,,,,,,,,,,,,,
,3772385719.35085,58.4467086791992,200.198501586914,0.0410012221154395,5.62825714580202E-5,1,2,13.9012460708618,4.99850382075701,6.47999998182058,49.1890191237909,7.39945716979262,100,-0.000123963020954568,,,,,,,,,,,,,,,,,,,,,58.4302253723145,58.463191986084,200.198501586914,200.198501586914,52.7700862188325,5.67190263450222,24.0468235015869,28,1,0,0,1,0.308303833007812,32.7468223571777,2,1,1,58.4302253723145,0,58.4467086791992,,,,,,,,,,,,,,,,,,,,,,,,,,,,,,,,,
,3772385727.35343,58.3140525817871,200.198501586914,0.0457132603158638,6.46183737751144E-5,1,2,13.9012460708618,4.9984753468113,6.47999998182058,54.8406161275336,8.256137209437,100,-0.000132898354456932,,,,,,,,,,,,,,,,,,,,,58.2982559204102,58.3298492431641,200.198501586914,200.198501586914,52.7689137760537,5.67210051850964,24.0058250427246,28,1,0,0,1,0.308380126953125,32.7468223571777,2,1,1,58.2982559204102,0,58.3140525817871,,,,,,,,,,,,,,,,,,,,,,,,,,,,,,,,,
,3772385735.43302,58.1793231964111,200.198501586914,0.0510823715182703,7.29576403070953E-5,1,2,13.9012460708618,4.99846572477145,6.47999998182058,61.2803331559981,9.23397622620515,100,-0.000141698641401179,,,,,,,,,,,,,,,,,,,,,58.162971496582,58.1956748962402,200.198501586914,200.198501586914,52.6930958096883,5.67198548380735,24.0281524658203,28,1,0,0,1,0.307998657226562,32.7468223571777,2,1,1,58.162971496582,0,58.1793231964111,,,,,,,,,,,,,,,,,,,,,,,,,,,,,,,,,
,3772385745.58966,58.0075645446777,200.198501586914,0.058745835605849,8.37907665795331E-5,1,2,13.9012460708618,4.99846761821689,6.47999998182058,70.4723767746487,10.6282261538041,100,-0.000155494865555934,,,,,,,,,,,,,,,,,,,,,57.9926872253418,58.0224418640137,200.198501586914,200.198501586914,52.7865004177364,5.6723146078778,24.0316352844238,28,1,0,0,1,0.309524536132812,32.7468223571777,2,1,1,57.9926872253418,0,58.0075645446777,,,,,,,,,,,,,,,,,,,,,,,,,,,,,,,,,
,3772385753.55746,57.8743515014648,200.198501586914,0.0656435774163346,9.20598798562538E-5,1,2,13.9012460708618,4.99850401192301,6.47999998182058,78.7464095672889,11.8854593462393,100,-0.000166097021005421,,,,,,,,,,,,,,,,,,,,,57.8564071655273,57.8922958374023,200.198501586914,200.198501586914,52.7575801625248,5.67198000095263,24.0314140319824,28,1,0,0,1,0.307769775390625,32.7468223571777,2,1,1,57.8564071655273,0,57.8743515014648,,,,,,,,,,,,,,,,,,,,,,,,,,,,,,,,,
,3772385761.63585,57.7400951385498,200.198501586914,0.0731039355305702,9.88336413259864E-5,1,2,13.9012460708618,4.9985057974447,6.47999998182058,87.695101475542,13.2417162366138,100,-0.00018040891841299,,,,,,,,,,,,,,,,,,,,,57.7274475097656,57.752742767334,200.198501586914,200.198501586914,52.685279524496,5.67207546323422,24.004114151001,28,1,0,0,1,0.308761596679687,32.7468223571777,2,1,1,57.7243461608887,0,57.7400951385498,,,,,,,,,,,,,,,,,,,,,,,,,,,,,,,,,
,3772385770.9377,57.5864009857178,200.198501586914,0.0830294168308322,0.000103775400062928,1,2,13.9012460708618,4.99848701174973,6.47999998182058,99.5991097994756,15.0526482456591,100,-0.000193933070601703,,,,,,,,,,,,,,,,,,,,,57.5577430725098,57.6150588989258,200.198501586914,200.198501586914,52.7931442601498,5.67211950775525,23.9778251647949,28,1,0,0,1,0.309982299804687,32.7468223571777,2,1,1,57.5577430725098,0,57.5864009857178,,,,,,,,,,,,,,,,,,,,,,,,,,,,,,,,,
,3772385780.0884,57.4362487792969,200.198501586914,0.0911977020413031,0.000104821870750214,1,2,13.9012460708618,4.99848091926894,6.47999998182058,109.395399991914,16.5458722574563,100,-0.000202671147418844,,,,,,,,,,,,,,,,,,,,,57.4268913269043,57.4456062316895,200.198501586914,200.198501586914,52.7947075171883,5.67224591034249,24.0155296325684,28,1,0,0,1,0.307769775390625,32.7468223571777,2,1,1,57.4268913269043,0,57.4362487792969,,,,,,,,,,,,,,,,,,,,,,,,,,,,,,,,,
,3772385788.0531,57.2984466552734,200.198501586914,0.0992835600828449,0.000102215785598973,1,2,13.9012460708618,4.99847641391235,6.47999998182058,119.093041744906,18.0227993475632,100,-0.000212347888889116,,,,,,,,,,,,,,,,,,,,,57.2875595092773,57.3093338012695,200.198501586914,200.198501586914,52.8353522001883,5.67205776500916,23.9916706085205,28,1,0,0,1,0.307693481445313,32.7468223571777,2,1,1,57.2875595092773,0,57.2984466552734,,,,,,,,,,,,,,,,,,,,,,,,,,,,,,,,,
,3772385796.23435,57.1614856719971,200.198501586914,0.106979049402671,9.49930466828899E-5,1,2,13.9012460708618,4.99843608655366,6.47999998182058,128.320600509465,19.4319537972266,100,-0.000218445637510067,,,,,,,,,,,,,,,,,,,,,57.1407890319824,57.1821823120117,200.198501586914,200.198501586914,52.7911901888517,5.67221490551773,23.952672958374,28,1,0,0,1,0.307998657226562,32.7468223571777,2,1,1,57.1407890319824,0,57.1614856719971,,,,,,,,,,,,,,,,,,,,,,,,,,,,,,,,,
,3772385806.13467,57.0003700256348,200.198501586914,0.115529577761668,7.99278071383678E-5,1,2,13.9012460708618,4.99837769455462,6.47999998182058,138.573003821779,20.9952405673412,100,-0.000227155264703568,,,,,,,,,,,,,,,,,,,,,56.9877738952637,57.0129661560059,200.198501586914,200.198501586914,52.7829830893998,5.67266519769906,23.9362277984619,28,1,0,0,1,0.308990478515625,33.2355842590332,2,1,1,56.9877738952637,0,57.0003700256348,,,,,,,,,,,,,,,,,,,,,,,,,,,,,,,,,
,3772385814.21325,56.8704490661621,200.198501586914,0.121235185254396,6.65363918857671E-5,1,2,13.9012460708618,4.99833477256454,6.47999998182058,145.413547445523,22.0405720412295,100,-0.000231104982062906,,,,,,,,,,,,,,,,,,,,,56.8510284423828,56.8898696899414,200.198501586914,200.198501586914,52.7571893482652,5.67241230557348,23.9499492645264,28,1,0,0,1,0.308380126953125,32.7468223571777,2,1,1,56.8483543395996,0,56.8704490661621,,,,,,,,,,,,,,,,,,,,,,,,,,,,,,,,,
,3772385822.09489,56.7382030487061,200.198501586914,0.12582013715402,5.14440809052249E-5,1,2,13.9012460708618,4.99834141418923,6.47999998182058,150.912067381365,22.8813767704348,100,-0.000233826284522567,,,,,,,,,,,,,,,,,,,,,56.7220993041992,56.7543067932129,200.198501586914,200.198501586914,52.6927049954287,5.67273637514896,23.948091506958,28,1,0,0,1,0.30914306640625,32.7468223571777,2,1,1,56.7203254699707,0,56.7382030487061,,,,,,,,,,,,,,,,,,,,,,,,,,,,,,,,,
,3772385832.23911,56.5658264160156,200.198501586914,0.129834285727515,3.30308891483574E-5,1,2,13.9012460708618,4.99838945008832,6.47999998182058,155.729658391048,23.6064762182533,100,-0.000245643614320774,,,,,,,,,,,,,,,,,,,,,56.5466957092285,56.5849571228027,200.198501586914,200.198501586914,52.7423384063998,5.67219693936473,23.9137725830078,28,1,0,0,1,0.30853271484375,33.2355842590332,2,1,1,56.5466957092285,0,56.5658264160156,,,,,,,,,,,,,,,,,,,,,,,,,,,,,,,,,
,3772385840.15403,56.43385887146,200.198501586914,0.131826228050214,2.26839662022378E-5,1,2,13.9012460708618,4.99835432387506,6.47999998182058,158.115276057607,23.9817616990078,100,-0.000238280549838119,,,,,,,,,,,,,,,,,,,,,56.4167823791504,56.4509353637695,200.198501586914,200.198501586914,52.7657872619767,5.67251191743383,23.9349174499512,28,1,0,0,1,0.308914184570313,32.7468223571777,2,1,1,56.4167823791504,0,56.43385887146,,,,,,,,,,,,,,,,,,,,,,,,,,,,,,,,,
,3772385848.30066,56.2949180603027,200.198501586914,0.133099895498343,1.2891375637406E-5,1,2,13.9012460708618,4.99836937538631,6.47999998182058,159.644495873296,24.2078565342642,100,-0.000245347134425182,,,,,,,,,,,,,,,,,,,,,56.2795600891113,56.3102760314941,200.198501586914,200.198501586914,52.7435108491787,5.67247933126976,23.8962116241455,28,1,0,0,1,0.309524536132812,32.7468223571777,2,1,1,56.2795600891113,0,56.2949180603027,,,,,,,,,,,,,,,,,,,,,,,,,,,,,,,,,
,3772385858.3019,56.1345138549805,200.198501586914,0.134097775243245,1.47085427686633E-5,1,2,13.9012460708618,4.99834016293854,6.47999998182058,160.838993731681,24.3960968466452,100,-0.000241390782261431,,,,,,,,,,,,,,,,,,,,,56.1174736022949,56.151554107666,200.198501586914,200.198501586914,52.9060895811787,5.67242607982125,23.9083976745605,28,1,0,0,1,0.307769775390625,33.2355842590332,2,1,1,56.1174736022949,0,56.1345138549805,,,,,,,,,,,,,,,,,,,,,,,,,,,,,,,,,
,3772385866.35464,56.0009956359863,200.198501586914,0.134616729652903,1.44769553382555E-5,1,2,13.9012460708618,4.99837175967999,6.47999998182058,161.463561908794,24.4862556082494,100,-0.000246054234050197,,,,,,,,,,,,,,,,,,,,,55.9832916259766,56.0186996459961,200.198501586914,200.198501586914,52.7657872619767,5.67247798974906,23.921724319458,28,1,0,0,1,0.308837890625,33.2355842590332,2,1,1,55.9832916259766,0,56.0009956359863,,,,,,,,,,,,,,,,,,,,,,,,,,,,,,,,,
,3772385874.42843,55.8661594390869,200.198501586914,0.135304373155816,1.67603764149567E-5,1,2,13.9012460708618,4.99837475016498,6.47999998182058,162.287436206766,24.6181563693088,100,-0.000241639900390999,,,,,,,,,,,,,,,,,,,,,55.8498573303223,55.8824615478516,200.198501586914,200.198501586914,52.731004792871,5.67204889100488,23.8957424163818,28,1,0,0,1,0.308685302734375,33.2355842590332,2,1,1,55.8498573303223,0,55.8661594390869,,,,,,,,,,,,,,,,,,,,,,,,,,,,,,,,,
,3772385882.83592,55.7259979248047,200.198501586914,0.136247738102344,1.70094293642038E-5,1,2,13.9012460708618,4.99833020798686,6.47999998182058,163.416651721796,24.7909588677093,100,-0.000242096948049536,,,,,,,,,,,,,,,,,,,,,55.7157440185547,55.7362518310547,200.198501586914,200.198501586914,52.7087283800729,5.67227262819744,23.8830757141113,28,1,0,0,1,0.309677124023438,33.2355842590332,2,1,1,55.7157440185547,0,55.7259979248047,,,,,,,,,,,,,,,,,,,,,,,,,,,,,,,,,
,3772385890.72368,55.5955677032471,200.198501586914,0.13731077258864,1.44567810870053E-5,1,2,13.9012460708618,4.99826520019557,6.47999998182058,164.688632989306,24.9839901009431,100,-0.000243931566790989,,,,,,,,,,,,,,,,,,,,,55.5823822021484,55.6087532043457,200.198501586914,200.198501586914,52.8248002151787,5.67256773521355,23.857105255127,28,1,0,0,1,0.308380126953125,32.7468223571777,2,1,1,55.5823822021484,0,55.5955677032471,,,,,,,,,,,,,,,,,,,,,,,,,,,,,,,,,
,3772385898.83207,55.457878112793,200.198501586914,0.138373897611798,2.20488147654312E-5,1,2,13.9012460708618,4.99829699344016,6.47999998182058,165.967067294446,25.1656164845824,100,-0.000255859126881194,,,,,,,,,,,,,,,,,,,,,55.4376602172852,55.4780960083008,200.198501586914,200.198501586914,52.7243609504575,5.67286351263419,23.8287086486816,28,1,0,0,1,0.307846069335937,33.2355842590332,2,1,1,55.4376602172852,0,55.457878112793,,,,,,,,,,,,,,,,,,,,,,,,,,,,,,,,,
,3772385904.65946,55.3640460968018,200.198501586914,0.139155607862746,2.14327989539341E-5,1,2,13.9012460708618,4.99831689621928,6.47999998182058,166.90537092473,25.3093912100598,100,-0.000256082382961354,,,,,,,,,,,,,,,,,,,,,55.3468856811523,55.3812065124512,200.198501586914,200.198501586914,52.6930958096883,5.67278248779746,23.8429050445557,28,1,0,0,1,0.307846069335937,33.2355842590332,2,1,1,55.3468856811523,0,55.3640460968018,,,,,,,,,,,,,,,,,,,,,,,,,,,,,,,,,