File: Experimental_Data/Supplementary_Fig1_Data/ZFC_58K.dat
[Header]
; MPMS3 Data File (default extension .dat)
; Copyright (c) 2007, Quantum Design, Inc. All rights reserved.
TITLE,ZFC_58K
FILEOPENTIME,3754323973.8616,12/18/2018,7:45 pm
BYAPP,SQUID AC,0.9.1.0
INFO,MPMS3 Measurement Release 1.1.16 Build 347, MultiVu Release 2.3.3.2,APPNAME
INFO,0,MOMENT_UNITS
INFO,CoIINO3,SAMPLE_MATERIAL
INFO,40 Hours Pumped Turbo,SAMPLE_COMMENT
INFO,,SAMPLE_MASS
INFO,,SAMPLE_VOLUME
INFO,,SAMPLE_MOLECULAR_WEIGHT
INFO,,SAMPLE_SIZE
INFO,,SAMPLE_SHAPE
INFO,Brass,SAMPLE_HOLDER
INFO,Standard,SAMPLE_HOLDER_DETAIL
INFO,65.37,SAMPLE_OFFSET
DATATYPE,COMMENT,1
DATATYPE,TIME,2
STARTUPAXIS,X,2
STARTUPAXIS,Y1,5
FIELDGROUP, VSM,2,3,4,5,6,8,9,10,11,14,15
FIELDGROUP, DC, 2,3,4,14,56,57,58,59,60,61,62,63,64,65,66,67,68,69
FIELDGROUP, AC, 2,3,4,11,16,17,18,19,20,21,22,23,24,25,26,27,28,29,30
STARTUPGROUP, All
[Data]
Comment,Time Stamp (sec),Temperature (K),Magnetic Field (Oe),Moment (emu),M. Std. Err. (emu),Transport Action,Averaging Time (sec),Frequency (Hz),Peak Amplitude (mm),Center Position (mm),Lockin Signal' (V),Lockin Signal (V),Range,M. Quad. Signal (emu),AC Moment (emu),AC M. Std Err. (emu),AC Phase (deg),AC Phase Std. Err. (deg),AC Susceptibility (emu/Oe),AC Suscept. Std Err. (emu/Oe),AC X' (emu/Oe),AC X' Std Err. (emu/Oe),AC X'' (emu/Oe),AC X'' Std Err. (emu/Oe),AC Drive (Oe),AC Frequency (Hz),AC Averaging Time (sec),AC Cycles,AC Range,AC Measure Type,AC Signal' (V),AC Signal'' (V),AC Trim Coil Ratio,AC Trim Coil Phase,Min. Temperature (K),Max. Temperature (K),Min. Field (Oe),Max. Field (Oe),Mass (grams),Motor Lag (deg),Pressure (Torr),Measure Count,Measurement Number,SQUID Status (code),Motor Status (code),Measure Status (code),Motor Current (amps),Motor Temp. (C),Temp. Status (code),Field Status (code),Chamber Status (code),Chamber Temp (K),Redirection State,Average Temp (K),Rotation Angle (deg),Rotator state,DC Moment Fixed Ctr (emu),DC Moment Err Fixed Ctr (emu),DC Moment Free Ctr (emu),DC Moment Err Free Ctr (emu),DC Fixed Fit,DC Free Fit,DC Calculated Center (mm),DC Calculated Center Err (mm),DC Scan Length (mm),DC Scan Time (s),DC Number of Points,DC Squid Drift,DC Min V (V),DC Max V (V),DC Scans per Measure,Map 01,Map 02,Map 03,Map 04,Map 05,Map 06,Map 07,Map 08,Map 09,Map 10,Map 11,Map 12,Map 13,Map 14,Map 15,Map 16
,3754324102.53347,57.9852466583252,0.0607140436768532,,,5,,,,3.65000008605421,,,,,0.000426669477146299,1.35811261834527E-6,-0.0831878477288264,0.000418003882093535,0.00042661440323422,1.3579373150275E-6,0.000426613953578675,1.34615992827578E-6,-6.19402019627688E-7,1.78457835492469E-7,1.00012909529463,10.005763053894,2,20,1,3,1.39591480028052,0.120462634361471,0.0404026173055172,172.741912841797,57.9698181152344,57.9882392883301,0.0607140436768532,0.0607140436768532,,,38.833812713623,0,1,,,,,,1,1,1,57.9836730957031,0,57.9797451019287,,,,,,,,,,,,,,,,,,,,,,,,,,,,,,,,,
,3754324124.25422,57.9372749328613,19.9870643615723,,,5,,,,3.65000008605421,,,,,0.000377995627323525,8.0636838703278E-7,-0.00653577664710969,0.000286976625235659,0.000377946971483922,8.06264590776779E-7,0.00037794696902497,7.99023484207863E-7,-4.31127214902344E-8,1.0781494342054E-7,1.00012873721256,10.005763053894,2,20,1,3,1.23652530537539,0.108401217710088,0.0404026173055172,172.741912841797,57.9161186218262,57.9442520141602,19.9870643615723,19.9870643615723,,,38.9084358215332,0,1,,,,,,1,1,1,57.9334182739258,0,57.9292182922363,,,,,,,,,,,,,,,,,,,,,,,,,,,,,,,,,
,3754324146.12862,57.899845123291,40.0591278076172,,,5,,,,3.65000008605421,,,,,0.000359092380220897,6.15651298986738E-7,0.0256136428995823,0.000228744114198682,0.000359046030622093,6.15571834224234E-7,0.000359045994744974,6.10167018075895E-7,1.60508794621642E-7,8.13934465578041E-8,1.00012909096565,10.005763053894,2,20,1,3,1.17462816096729,0.103664551730899,0.0404026173055172,172.741912841797,57.8968696594238,57.9015121459961,40.0591278076172,40.0591278076172,,,38.9457473754883,0,1,,,,,,1,1,1,57.8992080688477,0,57.8988227844238,,,,,,,,,,,,,,,,,,,,,,,,,,,,,,,,,
,3754324167.81394,57.9137191772461,59.9247627258301,,,5,,,,3.65000008605421,,,,,0.00032918281742352,4.81947877539628E-7,0.0598368429340193,0.000211141941832885,0.000329140157272097,4.81885419937513E-7,0.000329139977780999,4.76951589385592E-7,3.43737435484435E-7,6.87803702440678E-8,1.00012961089821,10.005763053894,2,20,1,3,1.07673250928259,0.0956961463337717,0.0404026173055172,172.741912841797,57.9086380004883,57.9294929504394,59.9247627258301,59.9247627258301,,,38.9830589294434,0,1,,,,,,1,1,1,57.9162788391113,0,57.919758605957,,,,,,,,,,,,,,,,,,,,,,,,,,,,,,,,,
,3754324189.65839,57.9506778717041,79.8875350952148,,,5,,,,3.65000008605421,,,,,0.000302937850338322,3.21363403842502E-7,0.0662134940754546,0.000144368473828941,0.00030289867028181,3.21321840741987E-7,0.00030289846801945,3.18405002238553E-7,3.50042795759891E-7,4.3196989331266E-8,1.00012935037475,10.005763053894,2,20,1,3,0.990876036778349,0.0881979351621059,0.0404026173055172,172.741912841797,57.9476051330566,57.9538116455078,79.8875350952148,79.8875350952148,,,39.0452461242676,0,1,,,,,,1,1,1,57.9518508911133,0,57.9516201019287,,,,,,,,,,,,,,,,,,,,,,,,,,,,,,,,,
,3754324211.19826,57.9547214508057,100.020317077637,,,5,,,,3.65000008605421,,,,,0.000288504297220541,2.23986441997803E-7,0.0657160462881254,0.000113795239577034,0.000288467029873563,2.23957508701028E-7,0.000288466840131452,2.21589056698638E-7,3.30860469872365E-7,3.24846987823291E-8,1.00012919101013,10.005763053894,2,20,1,3,0.943664937606214,0.0840078602089463,0.0404026173055172,172.741912841797,57.9531478881836,57.9553680419922,100.020317077637,100.020317077637,,,39.1074295043945,0,1,,,,,,1,1,1,57.9543075561523,0,57.9540942798961,,,,,,,,,,,,,,,,,,,,,,,,,,,,,,,,,
,3754324233.36222,57.9663791656494,120.01953125,,,5,,,,3.65000008605421,,,,,0.000269803386829137,2.53953642911456E-7,0.102234390367189,0.000130856235359689,0.000269768453227181,2.53920761502586E-7,0.000269768023779948,2.51527292570883E-7,4.81354804064111E-7,3.4781808665085E-8,1.00012949476315,10.005763053894,2,20,1,3,0.882444920798716,0.0791437861886453,0.0404026173055172,172.741912841797,57.9615669250488,57.9816093444824,120.01953125,120.01953125,,,39.1696166992188,0,1,,,,,,1,1,1,57.9686851501465,0,57.9716732025146,,,,,,,,,,,,,,,,,,,,,,,,,,,,,,,,,
,3754324255.16703,57.9934120178223,139.909454345703,,,5,,,,3.65000008605421,,,,,0.000255622822138058,1.20265991913627E-7,0.0719103191114963,0.000114821721997022,0.000255589789898299,1.20250450832253E-7,0.000255589588595128,1.16641524536074E-7,3.20783462310198E-7,2.92391121489818E-8,1.00012923927741,10.005763053894,2,20,1,3,0.836103048039526,0.0745593540498975,0.0404026173055172,172.741912841797,57.9919128417969,57.9960670471191,139.909454345703,139.909454345703,,,39.2318000793457,0,1,,,,,,1,1,1,57.9942512512207,0,57.9943328857422,,,,,,,,,,,,,,,,,,,,,,,,,,,,,,,,,
,3754324277.16312,57.9977855682373,160.030090332031,,,5,,,,3.65000008605421,,,,,0.000247481674589507,1.16755639176332E-7,0.0629626759807804,0.000130115527782215,0.000247449701665162,1.16740555153548E-7,0.00024744955225574,1.12237143298422E-7,2.71923907557412E-7,3.21120052592158E-8,1.00012920979144,10.005763053894,2,20,1,3,0.809484767990073,0.0720757827555574,0.0404026173055172,172.741912841797,57.9970359802246,57.9986763000488,160.030090332031,160.030090332031,,,39.281551361084,0,1,,,,,,1,1,1,57.9981460571289,0,57.9981190074574,,,,,,,,,,,,,,,,,,,,,,,,,,,,,,,,,
,3754324299.90401,57.9992828369141,179.956420898438,,,5,,,,3.65000008605421,,,,,0.000241054351882224,1.08907301733631E-7,0.0778578252108666,0.000109425297318704,0.000241023220478348,1.08893236701538E-7,0.00024102299794859,1.05676706755233E-7,3.27520423947642E-7,2.62710991149123E-8,1.00012916350472,10.005763053894,2,20,1,3,0.788442375642273,0.0704256975102706,0.0404026173055172,172.741912841797,57.9989700317383,57.9994773864746,179.956420898438,179.956420898438,,,39.3437347412109,0,1,,,,,,1,1,1,57.9991264343262,0,57.9991886138916,,,,,,,,,,,,,,,,,,,,,,,,,,,,,,,,,
,3754324321.52587,57.9983520507812,199.979919433594,,,5,,,,3.65000008605421,,,,,0.000232431506765728,1.12886875433868E-7,0.095178223801244,0.000132311350797165,0.000232401472197156,1.12872288303886E-7,0.000232401151541647,1.08632147668559E-7,3.86058961887889E-7,3.0646532591338E-8,1.00012923570702,10.005763053894,2,20,1,3,0.76021711035232,0.0681525820991008,0.0404026173055172,172.741912841797,57.9979057312012,57.9985008239746,199.979919433594,199.979919433594,,,39.381046295166,0,1,,,,,,1,1,1,57.9983406066895,0,57.9982578277588,,,,,,,,,,,,,,,,,,,,,,,,,,,,,,,,,
,3754324343.44399,58.0077667236328,219.869857788086,,,5,,,,3.65000008605421,,,,,0.000225222432864328,1.06219008100463E-7,0.0894630104394132,0.000129430600018323,0.000225193310401711,1.06205273415808E-7,0.000225193035886033,1.02153876587791E-7,3.51622117095389E-7,2.90541838538433E-8,1.00012932205919,10.005763053894,2,20,1,3,0.736643875565995,0.065980963401878,0.0404026173055172,172.741912841797,58.0057716369629,58.0086631774902,219.869857788086,219.869857788086,,,39.4183578491211,0,1,,,,,,1,1,1,58.0082740783691,0,58.0078231811523,,,,,,,,,,,,,,,,,,,,,,,,,,,,,,,,,
,3754324365.16451,58.0144195556641,239.954040527344,,,5,,,,3.65000008605421,,,,,0.000215469803616947,4.20571484470213E-8,0.118033989078049,4.36706676933513E-5,0.000215441950837342,4.20517119150021E-8,0.000215441493676495,4.09983402213747E-8,4.43827714734907E-7,9.35321196566931E-9,1.00012928206181,10.005763053894,2,20,1,3,0.704713032579918,0.0634904052727867,0.0404026173055172,172.741912841797,58.0126991271973,58.0146331787109,239.954040527344,239.954040527344,,,39.4556694030762,0,1,,,,,,1,1,1,58.0146484375,0,58.0138332366943,,,,,,,,,,,,,,,,,,,,,,,,,,,,,,,,,
,3754324387.06959,58.0160636901855,259.989685058594,,,5,,,,3.65000008605421,,,,,0.000209983949362658,1.35475764647144E-7,0.0928340071436349,7.01424857225029E-5,0.000209956838117036,1.35458273230575E-7,0.000209956562523605,1.34692292825683E-7,3.40184325042881E-7,1.43850630853519E-8,1.0001291277096,10.005763053894,2,20,1,3,0.686797271580606,0.0615866054220888,0.0404026173055172,172.741912841797,58.0142097473145,58.017162322998,259.989685058594,259.989685058594,,,39.5054168701172,0,1,,,,,,1,1,1,58.0155372619629,0,58.015323638916,,,,,,,,,,,,,,,,,,,,,,,,,,,,,,,,,
,3754324408.76741,58.0294284820557,279.806762695313,,,5,,,,3.65000008605421,,,,,0.000200079891964144,1.18325288419533E-7,0.126085662639941,0.000116123729454017,0.000200054028981764,1.18309993305069E-7,0.00020005354458272,1.16044427528517E-7,4.40240531915645E-7,2.30422515267992E-8,1.00012927998757,10.005763053894,2,20,1,3,0.654368883518455,0.0590754697914077,0.0404026173055172,172.741912841797,58.0274543762207,58.0296936035156,279.806762695313,279.806762695313,,,39.5427284240723,0,1,,,,,,1,1,1,58.0296096801758,0,58.0287888266824,,,,,,,,,,,,,,,,,,,,,,,,,,,,,,,,,
,3754324430.63014,58.029354095459,299.854553222656,,,5,,,,3.65000008605421,,,,,0.000193191225085855,2.14918334433831E-7,0.12782481412464,0.000116179514679786,0.000193166275381981,2.1489057877982E-7,0.000193165794668606,2.13786754888394E-7,4.30946624224628E-7,2.17527994202137E-8,1.00012916180024,10.005763053894,2,20,1,3,0.63183663365372,0.0570742628444454,0.0404026173055172,172.741912841797,58.0269012451172,58.029956817627,299.854553222656,299.854553222656,,,39.5924758911133,0,1,,,,,,1,1,1,58.0291748046875,0,58.0286388397217,,,,,,,,,,,,,,,,,,,,,,,,,,,,,,,,,
,3754324451.99013,58.0357723236084,319.963012695313,,,5,,,,3.65000008605421,,,,,0.000184822760396683,1.14282434687521E-7,0.142014479306812,0.000113171090833346,0.000184798879603687,1.14267668350518E-7,0.000184798311942628,1.1237703484544E-7,4.5804577604834E-7,2.07002915344381E-8,1.00012922585379,10.005763053894,2,20,1,3,0.604452984384857,0.054764681115619,0.0404026173055172,172.741912841797,58.0313148498535,58.0357055664062,319.963012695313,319.963012695313,,,39.6173515319824,0,1,,,,,,1,1,1,58.0357131958008,0,58.0344905853271,,,,,,,,,,,,,,,,,,,,,,,,,,,,,,,,,
,3754324474.19003,58.0430774688721,339.950073242188,,,5,,,,3.65000008605421,,,,,0.000180078809070518,1.83102927669358E-7,0.0912105312191827,0.000127976512211158,0.000180055543067901,1.83079270953632E-7,0.000180055314917564,1.81672712436912E-7,2.86634634089586E-7,2.26504968759783E-8,1.00012921569767,10.005763053894,2,20,1,3,0.588984424141914,0.0528493703840386,0.0404026173055172,172.741912841797,58.0384368896484,58.0432662963867,339.950073242188,339.950073242188,,,39.6546630859375,0,1,,,,,,1,1,1,58.0428848266602,0,58.0414672851562,,,,,,,,,,,,,,,,,,,,,,,,,,,,,,,,,
,3754324496.01539,58.0828037261963,359.864288330078,,,5,,,,3.65000008605421,,,,,0.00016972984934082,8.42255779637472E-8,0.147632518927188,9.43948003525406E-5,0.000169707884708404,8.42146783849918E-8,0.000169707321342474,8.27068526294396E-8,4.37281331897566E-7,1.5864696140165E-8,1.00012942611626,10.005763053894,2,20,1,3,0.555085958291516,0.0503706227427942,0.0404026173055172,172.741912841797,58.0772132873535,58.0833969116211,359.864288330078,359.864288330078,,,39.7168502807617,0,1,,,,,,1,1,1,58.083438873291,0,58.0810304121538,,,,,,,,,,,,,,,,,,,,,,,,,,,,,,,,,
,3754324517.91212,58.0822563171387,379.924224853516,,,5,,,,3.65000008605421,,,,,0.000166307053406396,2.37994609995407E-7,0.0740981586971738,0.000237274131634213,0.000166285593133213,2.37963899155176E-7,0.000166285454075804,2.34727050106991E-7,2.15049920589567E-7,3.91155883146995E-8,1.00012905671969,10.005763053894,2,20,1,3,0.543954171046556,0.0486684411774847,0.0404026173055172,172.741912841797,58.0694160461426,58.0849113464355,379.924224853516,379.924224853516,,,39.7417221069336,0,1,,,,,,1,1,1,58.0809898376465,0,58.0780580694025,,,,,,,,,,,,,,,,,,,,,,,,,,,,,,,,,
,3754324540.9782,58.0711059570312,399.923431396484,,,5,,,,3.65000008605421,,,,,0.000162198787478262,9.85843630734372E-8,0.040157290424907,0.000208958946673223,0.000162177846987905,9.85716354511388E-8,0.000162177807154718,9.25798521525247E-8,1.13666703274275E-7,3.38428469684345E-8,1.00012912053493,10.005763053894,2,20,1,3,0.530544238116051,0.047163275416376,0.0404026173055172,172.741912841797,58.0568618774414,58.0735168457031,399.923431396484,399.923431396484,,,39.7914695739746,0,1,,,,,,1,1,1,58.0702705383301,0,58.0666335423788,,,,,,,,,,,,,,,,,,,,,,,,,,,,,,,,,
,3754324564.01131,58.069372177124,419.959045410156,,,5,,,,3.65000008605421,,,,,0.000154887108576255,3.02081973791146E-7,0.109269135117221,0.000267246736104837,0.000154867106559881,3.02042963129499E-7,0.000154866824929954,2.99284253033936E-7,2.95347836749827E-7,4.07294422005403E-8,1.00012915600232,10.005763053894,2,20,1,3,0.506572706838898,0.0456591660219901,0.0404026173055172,172.741912841797,58.0639991760254,58.0699920654297,419.959045410156,419.959045410156,,,39.8287811279297,0,1,,,,,,1,1,1,58.0688667297363,0,58.0678704001687,,,,,,,,,,,,,,,,,,,,,,,,,,,,,,,,,
,3754324585.64307,58.0824413299561,439.861114501953,,,5,,,,3.65000008605421,,,,,0.000151747777087582,2.13000452644939E-7,0.00254211918251546,0.000379014376524832,0.000151728176846518,2.12972940807213E-7,0.000151728176697176,2.05087877748441E-7,6.73192880943374E-9,5.7414596721681E-8,1.00012917996822,10.005763053894,2,20,1,3,0.496387039559455,0.0438197262357138,0.0404026173055172,172.741912841797,58.0716323852539,58.083251953125,439.861114501953,439.861114501953,,,39.8660926818848,0,1,,,,,,1,1,1,58.0817451477051,0,58.0787445068359,,,,,,,,,,,,,,,,,,,,,,,,,,,,,,,,,
,3754324607.58068,58.1012916564941,460.176055908203,,,5,,,,3.65000008605421,,,,,0.000146179312499443,1.61936939256555E-7,0.0084087204845158,0.000381548124964172,0.000146160422895724,1.6191601341857E-7,0.000146160421321689,1.52029736795312E-7,2.14504828813136E-8,5.57113501120797E-8,1.00012923884144,10.005763053894,2,20,1,3,0.478166883549745,0.0422710866595292,0.0404026173055172,172.741912841797,58.088981628418,58.1016082763672,460.176055908203,460.176055908203,,,39.8909683227539,0,1,,,,,,1,1,1,58.1009750366211,0,58.0974922180176,,,,,,,,,,,,,,,,,,,,,,,,,,,,,,,,,
,3754324629.39865,58.0919818878174,480.235931396484,,,5,,,,3.65000008605421,,,,,0.000143397027444498,1.75225989987078E-7,-0.0321478030991598,0.00039652488067829,0.00014337852552009,1.75203381303489E-7,0.000143378502951135,1.65735043356185E-7,-8.04475373996407E-8,5.68165488559392E-8,1.00012904250718,10.005763053894,2,20,1,3,0.46909436878529,0.0411445649019859,0.0404026173055172,172.741912841797,58.0768394470215,58.0939979553223,480.235931396484,480.235931396484,,,39.928279876709,0,1,,,,,,1,1,1,58.0905303955078,0,58.0869522094727,,,,,,,,,,,,,,,,,,,,,,,,,,,,,,,,,
,3754324651.15609,58.0491542816162,499.980163574219,,,5,,,,3.65000008605421,,,,,0.00013894982297824,3.02050316392631E-7,-0.00221372735784264,0.000411026860512192,0.000138931911906909,3.02011381152222E-7,0.00013893191180321,2.96598949609849E-7,-5.36788881838955E-9,5.69204483099601E-8,1.00012891977865,10.005763053894,2,20,1,3,0.454524748386006,0.0401156342394938,0.0404026173055172,172.741912841797,58.0361213684082,58.0540237426758,499.980163574219,499.980163574219,,,39.9904632568359,0,1,,,,,,1,1,1,58.0467834472656,0,58.0443555658514,,,,,,,,,,,,,,,,,,,,,,,,,,,,,,,,,
,3754324674.11202,58.0471992492676,520.076538085937,,,5,,,,3.65000008605421,,,,,0.0001336252218175,2.04877961465496E-7,0.0516387726375411,0.000411261454069087,0.000133607963049928,2.04851499835952E-7,0.000133607908786294,1.9738455870091E-7,1.20416378851937E-7,5.48039503273801E-8,1.00012917469272,10.005763053894,2,20,1,3,0.437070169271246,0.0389986126960609,0.0404026173055172,172.741912841797,58.0418395996094,58.0473136901855,520.076538085937,520.076538085937,,,40.0029029846191,0,1,,,,,,1,1,1,58.0471839904785,0,58.0454261086204,,,,,,,,,,,,,,,,,,,,,,,,,,,,,,,,,
,3754324695.84937,58.0425071716309,540.184997558594,,,5,,,,3.65000008605421,,,,,0.000128001124013332,3.26756205138777E-7,0.101254345505529,0.00057130513765766,0.000127984589734401,3.26713997085685E-7,0.000127984389881872,3.18517502334203E-7,2.26177027927135E-7,7.2723012853471E-8,1.00012918960763,10.005763053894,2,20,1,3,0.418641415898418,0.0377287673247784,0.0404026173055172,172.741912841797,58.0399208068848,58.0432357788086,540.184997558594,540.184997558594,,,40.0526504516602,0,1,,,,,,1,1,1,58.0421829223633,0,58.041862487793,,,,,,,,,,,,,,,,,,,,,,,,,,,,,,,,,
,3754324717.71941,58.027811050415,560.196350097656,,,5,,,,3.65000008605421,,,,,0.000125853466618872,3.09647071456044E-7,-0.00167814176284065,0.000506391272073726,0.000125837222139759,3.0960710390076E-7,0.000125837222085784,3.03015038445824E-7,-3.6856588662726E-9,6.35487628635812E-8,1.00012909120876,10.005763053894,2,20,1,3,0.411682700683345,0.0363650269021841,0.0404026173055172,172.741912841797,58.0187568664551,58.0300178527832,560.196350097656,560.196350097656,,,40.0899620056152,0,1,,,,,,1,1,1,58.0267143249512,0,58.0249404907227,,,,,,,,,,,,,,,,,,,,,,,,,,,,,,,,,
,3754324740.74174,58.0631713867187,580.049865722656,,,5,,,,3.65000008605421,,,,,0.000120937334886888,1.89334784683143E-7,0.0377990256106866,0.000542154081140143,0.000120921682028568,1.89310279177357E-7,0.000120921655714371,1.77628107336466E-7,7.97741380460872E-8,6.54724162244968E-8,1.00012944625031,10.005763053894,2,20,1,3,0.395576709114025,0.0352254787078759,0.0404026173055172,172.741912841797,58.0591468811035,58.065013885498,580.049865722656,580.049865722656,,,40.1148376464844,0,1,,,,,,1,1,1,58.0644683837891,0,58.0630020141602,,,,,,,,,,,,,,,,,,,,,,,,,,,,,,,,,
,3754324762.46016,58.0993022918701,600.134094238281,,,5,,,,3.65000008605421,,,,,0.000119218435537155,1.90282118186048E-7,-0.0879868125357985,0.000497332541144404,0.000119203013361067,1.90257503164723E-7,0.000119202872805821,1.80784368420886E-7,-1.83055177136936E-7,5.92868420911077E-8,1.00012937740124,10.005763053894,2,20,1,3,0.390029107192414,0.0338770050105029,0.0404026173055172,172.741912841797,58.0892448425293,58.0997314453125,600.134094238281,600.134094238281,,,40.1645851135254,0,1,,,,,,1,1,1,58.0992088317871,0,58.0961196899414,,,,,,,,,,,,,,,,,,,,,,,,,,,,,,,,,
,3754324784.33655,58.1199989318848,620.133239746094,,,5,,,,3.65000008605421,,,,,0.000116504612936527,2.24745757544517E-7,-0.126239475112924,0.000480615132519954,0.000116489565235691,2.24716729449933E-7,0.000116489282486124,2.17615559578764E-7,-2.56660609182817E-7,5.6045309561955E-8,1.00012917638422,10.005763053894,2,20,1,3,0.381172227454382,0.032859521810331,0.0404026173055172,172.741912841797,58.1053276062012,58.1206932067871,620.133239746094,620.133239746094,,,40.2018966674805,0,1,,,,,,1,1,1,58.1193046569824,0,58.1153045654297,,,,,,,,,,,,,,,,,,,,,,,,,,,,,,,,,
,3754324806.05686,58.0890998840332,640.181030273437,,,5,,,,3.65000008605421,,,,,0.000114449070971627,2.750156875335E-7,-0.246060909724845,0.000569276737068968,0.000114434319167881,2.74980239648995E-7,0.000114433263892971,2.67085431841013E-7,-4.91445030741601E-7,6.5417920294963E-8,1.00012891066118,10.005763053894,2,20,1,3,0.374513258033623,0.0315046704238634,0.0404026173055172,172.741912841797,58.0708389282227,58.093391418457,640.181030273437,640.181030273437,,,40.2392082214355,0,1,,,,,,1,1,1,58.0860252380371,0,58.0824489593506,,,,,,,,,,,,,,,,,,,,,,,,,,,,,,,,,
,3754324827.94575,58.0678157806397,660.070983886719,,,5,,,,3.65000008605421,,,,,0.000110806669951829,2.36016868607217E-7,-0.172037160745365,0.000734787960581438,0.000110792381056706,2.35986433433195E-7,0.000110791881621858,2.21473309253349E-7,-3.32666353276554E-7,8.14811024280484E-8,1.00012897001569,10.005763053894,2,20,1,3,0.362554010385341,0.030978172859317,0.0404026173055172,172.741912841797,58.0546264648438,58.0712432861328,660.070983886719,660.070983886719,,,40.2765197753906,0,1,,,,,,1,1,1,58.0665740966797,0,58.0634554082697,,,,,,,,,,,,,,,,,,,,,,,,,,,,,,,,,
,3754324850.97839,58.0424404144287,680.058044433594,,,5,,,,3.65000008605421,,,,,0.000106792198073014,3.94868110193951E-7,-0.162624373535212,0.000769542875860311,0.000106778415993941,3.94817150445805E-7,0.000106777985884283,3.86121880857055E-7,-3.03072055921464E-7,8.24043409630545E-8,1.00012907176927,10.005763053894,2,20,1,3,0.34941349876827,0.0299207347446045,0.0404026173055172,172.741912841797,58.0334358215332,58.0456275939941,680.058044433594,680.058044433594,,,40.3013916015625,0,1,,,,,,1,1,1,58.0408058166504,0,58.0394050598145,,,,,,,,,,,,,,,,,,,,,,,,,,,,,,,,,
,3754324872.60059,58.0380268096924,700.178649902344,,,5,,,,3.65000008605421,,,,,0.000102928133136687,2.2384930058316E-7,-0.114350988230334,0.000873002848342171,0.000102914835077776,2.23820379810037E-7,0.000102914630111495,2.04990248372342E-7,-2.05397419880089E-7,8.9858558248811E-8,1.00012921420805,10.005763053894,2,20,1,3,0.33674580581385,0.029129093259861,0.0404026173055172,172.741912841797,58.0323867797852,58.0384292602539,700.178649902344,700.178649902344,,,40.3387031555176,0,1,,,,,,1,1,1,58.0376243591309,0,58.0359893798828,,,,,,,,,,,,,,,,,,,,,,,,,,,,,,,,,
,3754324894.56196,58.0534267425537,719.959289550781,,,5,,,,3.65000008605421,,,,,0.000100336925470003,3.23643723515263E-7,-0.144540968199359,0.000829848804592003,0.000100323949088423,3.23601867295007E-7,0.000100323629853021,3.12679227846576E-7,-2.53088542946605E-7,8.33658742537046E-8,1.00012934480448,10.005763053894,2,20,1,3,0.328282756906188,0.0282297419035452,0.0404026173055172,172.741912841797,58.0512657165527,58.0540313720703,719.959289550781,719.959289550781,,,40.3760147094727,0,1,,,,,,1,1,1,58.053638458252,0,58.0528358459473,,,,,,,,,,,,,,,,,,,,,,,,,,,,,,,,,
,3754324916.3848,58.0469264984131,740.055603027344,,,5,,,,3.65000008605421,,,,,9.69702464837754E-5,3.17636087342365E-7,-0.137843066736255,0.000922151426099593,9.69577232094962E-5,3.17595066060199E-7,9.69574426165222E-5,3.04724875425336E-7,-2.33262155292069E-7,8.94951187651903E-8,1.00012916221488,10.005763053894,2,20,1,3,0.317264041248657,0.0273264426578496,0.0404026173055172,172.741912841797,58.0412216186523,58.0476837158203,740.055603027344,740.055603027344,,,40.4008903503418,0,1,,,,,,1,1,1,58.0465278625488,0,58.045153427124,,,,,,,,,,,,,,,,,,,,,,,,,,,,,,,,,
,3754324938.14852,58.0761528015137,760.139831542969,,,5,,,,3.65000008605421,,,,,9.54663813549212E-5,3.2105102772026E-7,-0.252525664605072,0.000909518373440071,9.5454045195434E-5,3.21009541527684E-7,9.54531180893739E-5,3.08968920225616E-7,-4.20703206547827E-7,8.70938119870207E-8,1.00012923663384,10.005763053894,2,20,1,3,0.312396578012176,0.0262841182006223,0.0404026173055172,172.741912841797,58.0698661804199,58.0765266418457,760.139831542969,760.139831542969,,,40.4506378173828,0,1,,,,,,1,1,1,58.076545715332,0,58.0743400573731,,,,,,,,,,,,,,,,,,,,,,,,,,,,,,,,,
,3754324960.03057,58.0740070343018,780.126892089844,,,5,,,,3.65000008605421,,,,,9.52084727870177E-5,4.40399974873203E-7,-0.28402784373213,0.000807967110009066,9.51961792981566E-5,4.40343109638134E-7,9.51950096231718E-5,4.33435911134477E-7,-4.71906570208027E-7,7.76876125570098E-8,1.00012913846913,10.005763053894,2,20,1,3,0.311566600049177,0.0260484743442725,0.0404026173055172,172.741912841797,58.0595626831055,58.0760650634766,780.126892089844,780.126892089844,,,40.4879493713379,0,1,,,,,,1,1,1,58.0727577209473,0,58.0691476301713,,,,,,,,,,,,,,,,,,,,,,,,,,,,,,,,,
,3754324982.86004,58.0448722839356,800.004699707031,,,5,,,,3.65000008605421,,,,,9.29008503226018E-5,3.16667116960452E-7,-0.525722520059879,0.00110916653268117,9.28888719817169E-5,3.16626286907112E-7,9.2884961785569E-5,2.99213993020217E-7,-8.52298145705776E-7,1.03552846129317E-7,1.00012895345405,10.005763053894,2,20,1,3,0.304119148936002,0.0241409301602757,0.0404026173055172,172.741912841797,58.0339698791504,58.0477867126465,800.004699707031,800.004699707031,,,40.525260925293,0,1,,,,,,1,1,1,58.0431594848633,0,58.0410049438477,,,,,,,,,,,,,,,,,,,,,,,,,,,,,,,,,