File: Experimental_Data/Supplementary_Fig1_Data/ZFC_50K.dat
[Header]
; MPMS3 Data File (default extension .dat)
; Copyright (c) 2007, Quantum Design, Inc. All rights reserved.
TITLE,ZFC_50K
FILEOPENTIME,3754342777.1477,12/19/2018,12:59 am
BYAPP,SQUID AC,0.9.1.0
INFO,MPMS3 Measurement Release 1.1.16 Build 347, MultiVu Release 2.3.3.2,APPNAME
INFO,0,MOMENT_UNITS
INFO,CoIINO3,SAMPLE_MATERIAL
INFO,40 Hours Pumped Turbo,SAMPLE_COMMENT
INFO,,SAMPLE_MASS
INFO,,SAMPLE_VOLUME
INFO,,SAMPLE_MOLECULAR_WEIGHT
INFO,,SAMPLE_SIZE
INFO,,SAMPLE_SHAPE
INFO,Brass,SAMPLE_HOLDER
INFO,Standard,SAMPLE_HOLDER_DETAIL
INFO,65.37,SAMPLE_OFFSET
DATATYPE,COMMENT,1
DATATYPE,TIME,2
STARTUPAXIS,X,2
STARTUPAXIS,Y1,5
FIELDGROUP, VSM,2,3,4,5,6,8,9,10,11,14,15
FIELDGROUP, DC, 2,3,4,14,56,57,58,59,60,61,62,63,64,65,66,67,68,69
FIELDGROUP, AC, 2,3,4,11,16,17,18,19,20,21,22,23,24,25,26,27,28,29,30
STARTUPGROUP, All
[Data]
Comment,Time Stamp (sec),Temperature (K),Magnetic Field (Oe),Moment (emu),M. Std. Err. (emu),Transport Action,Averaging Time (sec),Frequency (Hz),Peak Amplitude (mm),Center Position (mm),Lockin Signal' (V),Lockin Signal (V),Range,M. Quad. Signal (emu),AC Moment (emu),AC M. Std Err. (emu),AC Phase (deg),AC Phase Std. Err. (deg),AC Susceptibility (emu/Oe),AC Suscept. Std Err. (emu/Oe),AC X' (emu/Oe),AC X' Std Err. (emu/Oe),AC X'' (emu/Oe),AC X'' Std Err. (emu/Oe),AC Drive (Oe),AC Frequency (Hz),AC Averaging Time (sec),AC Cycles,AC Range,AC Measure Type,AC Signal' (V),AC Signal'' (V),AC Trim Coil Ratio,AC Trim Coil Phase,Min. Temperature (K),Max. Temperature (K),Min. Field (Oe),Max. Field (Oe),Mass (grams),Motor Lag (deg),Pressure (Torr),Measure Count,Measurement Number,SQUID Status (code),Motor Status (code),Measure Status (code),Motor Current (amps),Motor Temp. (C),Temp. Status (code),Field Status (code),Chamber Status (code),Chamber Temp (K),Redirection State,Average Temp (K),Rotation Angle (deg),Rotator state,DC Moment Fixed Ctr (emu),DC Moment Err Fixed Ctr (emu),DC Moment Free Ctr (emu),DC Moment Err Free Ctr (emu),DC Fixed Fit,DC Free Fit,DC Calculated Center (mm),DC Calculated Center Err (mm),DC Scan Length (mm),DC Scan Time (s),DC Number of Points,DC Squid Drift,DC Min V (V),DC Max V (V),DC Scans per Measure,Map 01,Map 02,Map 03,Map 04,Map 05,Map 06,Map 07,Map 08,Map 09,Map 10,Map 11,Map 12,Map 13,Map 14,Map 15,Map 16
,3754342916.30978,49.9410514831543,0.169999331235886,,,5,,,,3.65000008605421,,,,,0.000576479847902375,2.24617506680355E-8,-0.00046883317358315,1.11330570264046E-5,0.000576404991586529,2.24588339938299E-8,0.000576404991567232,2.15251005580388E-8,-4.71653904996549E-9,6.40853105857563E-9,1.00012986757044,10.005763053894,2,20,1,3,1.88580379893368,0.165501023934258,0.0404026173055172,172.741912841797,49.916877746582,49.9520568847656,0.169999331235886,0.169999331235886,,,71.9165191650391,0,1,,,,,,1,1,1,49.9364204406738,0,49.9313571929932,,,,,,,,,,,,,,,,,,,,,,,,,,,,,,,,,
,3754342939.35799,49.9017734527588,20.1206340789795,,,5,,,,3.65000008605421,,,,,0.000575542239536811,1.5040552701871E-8,-0.00152174998993715,1.5418430658762E-5,0.000575467284867318,1.50385939235585E-8,0.000575467284664348,1.21436247206271E-8,-1.52841508099753E-8,8.87083343560592E-9,1.00013025009669,10.005763053894,2,20,1,3,1.882737201862,0.165237559966012,0.0404026173055172,172.741912841797,49.8979949951172,49.903491973877,20.1206340789795,20.1206340789795,,,71.9413909912109,0,1,,,,,,1,1,1,49.9009246826172,0,49.9002040516246,,,,,,,,,,,,,,,,,,,,,,,,,,,,,,,,,
,3754342960.94909,49.9030456542969,40.0834121704102,,,5,,,,3.65000008605421,,,,,0.000574942569371833,1.29380050097407E-8,-0.00157209319406615,1.08428558740266E-5,0.000574867593380698,1.29363178155746E-8,0.000574867593164302,1.13369235495081E-8,-1.57733333695762E-8,6.23076905832336E-9,1.00013042306089,10.005763053894,2,20,1,3,1.88077320092635,0.165103918129004,0.0404026173055172,172.741912841797,49.9020881652832,49.9083518981934,40.0834121704102,40.0834121704102,,,72.0035781860352,0,1,,,,,,1,1,1,49.903392791748,0,49.9043960571289,,,,,,,,,,,,,,,,,,,,,,,,,,,,,,,,,
,3754342982.87557,49.9332847595215,59.9611892700195,,,5,,,,3.65000008605421,,,,,0.000575051820320085,1.53305481918244E-8,-0.000149350979711471,2.1674574490122E-5,0.000574976694128003,1.53285453710916E-8,0.00057497669412605,8.92594206322978E-9,-1.49877239316686E-9,1.24616155243804E-8,1.00013065954299,10.005763053894,2,20,1,3,1.88112402151846,0.16522192181907,0.0404026173055172,172.741912841797,49.9272689819336,49.9446907043457,59.9611892700195,59.9611892700195,,,72.0533294677734,0,1,,,,,,1,1,1,49.9354057312012,0,49.9370441436768,,,,,,,,,,,,,,,,,,,,,,,,,,,,,,,,,
,3754343004.53887,49.9542560577393,80.021110534668,,,5,,,,3.65000008605421,,,,,0.000580836333302754,1.26256970236042E-8,0.00850675102564669,8.7377215195255E-6,0.000580760627009764,1.26240513883998E-8,0.000580760620608742,1.15607572597377E-8,8.62260027406007E-8,5.07105166985921E-9,1.00013035713764,10.005763053894,2,20,1,3,1.9000187098789,0.167211692500838,0.0404026173055172,172.741912841797,49.9532508850098,49.9567031860352,80.021110534668,80.021110534668,,,72.1279525756836,0,1,,,,,,1,1,1,49.9544677734375,0,49.9550231933594,,,,,,,,,,,,,,,,,,,,,,,,,,,,,,,,,
,3754343029.57372,49.9584484100342,100.044609069824,,,5,,,,3.65000008605421,,,,,0.000596707193913369,1.61816714390931E-8,0.0186504376100256,1.83473364918976E-5,0.000596629441452513,1.61795629262613E-8,0.000596629409843752,1.19158253291563E-8,1.94209766795616E-7,1.09449240842451E-8,1.00013031951737,10.005763053894,2,20,10,3,1.95190206911046,0.172167996225661,0.0404026173055172,172.741912841797,49.9580535888672,49.9723815917969,100.044609069824,100.044609069824,,,72.2150115966797,0,1,,,,,,1,1,1,49.9586334228516,0,49.9617578983307,,,,,,,,,,,,,,,,,,,,,,,,,,,,,,,,,
,3754343054.90885,49.9881420135498,119.97095489502,,,5,,,,3.65000008605421,,,,,0.000620943139041722,3.46035797474249E-8,0.0679139141010747,2.93321527059354E-5,0.000620862168503632,3.45990674655494E-8,0.000620861732352095,2.94241380699248E-8,7.35921048026733E-7,1.82020759345643E-8,1.00013041628593,10.005763053894,2,20,10,3,2.03102328737589,0.180950370912992,0.0404026173055172,172.741912841797,49.9859504699707,49.9947700500488,119.97095489502,119.97095489502,,,72.3145065307617,0,1,,,,,,1,1,1,49.9894371032715,0,49.9906845092773,,,,,,,,,,,,,,,,,,,,,,,,,,,,,,,,,
,3754343077.71808,49.9972763061523,140.006591796875,,,5,,,,3.65000008605421,,,,,0.000658287826196162,7.48635914052455E-8,0.115368613544918,6.43483354765798E-5,0.000658202012879062,7.48538323107388E-8,0.000658200678561673,6.17329108012739E-8,1.32532977107335E-6,4.23337210224445E-8,1.00013037534894,10.005763053894,2,20,10,3,2.15301027396732,0.193662487112757,0.0404026173055172,172.741912841797,49.9966430664063,49.9984474182129,140.006591796875,140.006591796875,,,72.3891296386719,0,1,,,,,,1,1,1,49.9974594116211,0,49.9975249550559,,,,,,,,,,,,,,,,,,,,,,,,,,,,,,,,,
,3754343099.30499,49.9990425109863,160.078659057617,,,5,,,,3.65000008605421,,,,,0.000697076537451718,8.66907148577179E-8,0.116143754165936,9.0418206714132E-5,0.000696985691334965,8.66794169379341E-8,0.000696984259344346,5.95193460222452E-8,1.41285239577149E-6,6.30140362918013E-8,1.00013034143725,10.005763053894,2,20,10,3,2.27986755878264,0.205153600558439,0.0404026173055172,172.741912841797,49.9986915588379,49.9999847412109,160.078659057617,160.078659057617,,,72.463752746582,0,1,,,,,,1,1,1,49.9993934631348,0,49.9993991851807,,,,,,,,,,,,,,,,,,,,,,,,,,,,,,,,,
,3754343121.19346,50.0132656097412,180.15071105957,,,5,,,,3.65000008605421,,,,,0.000724227763197302,7.32592099620158E-8,0.0830883017546942,3.73661245194995E-5,0.000724133322709203,7.32496568408871E-8,0.000724132561291515,6.80851276398914E-8,1.05011202310026E-6,2.7017172716023E-8,1.00013041864687,10.005763053894,2,20,10,3,2.3687880635963,0.211828612903318,0.0404026173055172,172.741912841797,50.0117797851562,50.0133590698242,180.15071105957,180.15071105957,,,72.5383758544922,0,1,,,,,,1,1,1,50.0131721496582,0,50.0127517700195,,,,,,,,,,,,,,,,,,,,,,,,,,,,,,,,,
,3754343142.83638,50.0513458251953,200.016342163086,,,5,,,,3.65000008605421,,,,,0.000739478531974075,8.9758162602966E-8,0.0399553412374791,3.19033382847502E-5,0.000739382001960746,8.97464457562181E-8,0.000739381822179956,8.66067820120926E-8,5.15609667061877E-7,2.35306148534984E-8,1.00013055499468,10.005763053894,2,20,10,3,2.41882887106314,0.214519701994576,0.0404026173055172,172.741912841797,50.0450325012207,50.0520782470703,200.016342163086,200.016342163086,,,72.5881271362305,0,1,,,,,,1,1,1,50.0520782470703,0,50.0495830535889,,,,,,,,,,,,,,,,,,,,,,,,,,,,,,,,,
,3754343164.79175,50.0552368164063,219.954833984375,,,5,,,,3.65000008605421,,,,,0.000747707160077167,9.9053373235485E-8,0.00330709468840773,2.52226559015231E-5,0.000747609765890761,9.90404708276814E-8,0.000747609764645407,9.7241111362358E-8,4.31518046428136E-8,1.87931137064166E-8,1.00013027409599,10.005763053894,2,20,10,3,2.44587965730837,0.215394554671673,0.0404026173055172,172.741912841797,50.0445327758789,50.0559959411621,219.954833984375,219.954833984375,,,72.6627502441406,0,1,,,,,,1,1,1,50.0545768737793,0,50.0517265319824,,,,,,,,,,,,,,,,,,,,,,,,,,,,,,,,,
,3754343186.49309,50.0708961486816,240.075469970703,,,5,,,,3.65000008605421,,,,,0.000753191365338749,1.02306142976494E-7,-0.00611700385451552,3.80315910081548E-5,0.000753093149165812,1.02292802252883E-7,0.000753093144873898,9.82122974325906E-8,-8.04016234119556E-8,2.860353170082E-8,1.00013041703147,10.005763053894,2,20,10,3,2.46385182022975,0.216622145935052,0.0404026173055172,172.741912841797,50.0593338012695,50.071475982666,240.075469970703,240.075469970703,,,72.7124938964844,0,1,,,,,,1,1,1,50.0703163146973,0,50.0670440673828,,,,,,,,,,,,,,,,,,,,,,,,,,,,,,,,,
,3754343208.34432,50.0626907348633,260.159698486328,,,5,,,,3.65000008605421,,,,,0.000757206104177765,8.92689328527094E-8,-0.0136423165163713,2.91988941876394E-5,0.000757107561893549,8.92573154548777E-8,0.000757107540432124,8.64850599761754E-8,-1.80269838135932E-7,2.20726700498353E-8,1.00013015625411,10.005763053894,2,20,10,3,2.47701018841919,0.217504757542203,0.0404026173055172,172.741912841797,50.0479354858398,50.0664215087891,260.159698486328,260.159698486328,,,72.7622451782227,0,1,,,,,,1,1,1,50.0608406066895,0,50.0577098846436,,,,,,,,,,,,,,,,,,,,,,,,,,,,,,,,,
,3754343229.9419,50.046012878418,280.025299072266,,,5,,,,3.65000008605421,,,,,0.000760324972197139,1.23150561810263E-7,-0.0161510576144215,5.67577997594281E-5,0.000760225993668937,1.23134530163532E-7,0.000760225963464595,1.15338283312591E-7,-2.14299443440046E-7,4.31183594434933E-8,1.00013019619038,10.005763053894,2,20,10,3,2.48721907366912,0.2183446812085,0.0404026173055172,172.741912841797,50.0380210876465,50.0474052429199,280.025299072266,280.025299072266,,,72.8244323730469,0,1,,,,,,1,1,1,50.0453643798828,0,50.0433368682861,,,,,,,,,,,,,,,,,,,,,,,,,,,,,,,,,
,3754343251.84634,50.0647296905518,300.073089599609,,,5,,,,3.65000008605421,,,,,0.00076290237188287,1.19229335909307E-7,-0.0241807404546197,5.34364238314862E-5,0.000762802929605935,1.19213794685322E-7,0.000762802861673641,1.12038454394188E-7,-3.21928408480105E-7,4.07346729486736E-8,1.00013036430915,10.005763053894,2,20,10,3,2.49567779870636,0.218788555234742,0.0404026173055172,172.741912841797,50.0536155700684,50.0649833679199,300.073089599609,300.073089599609,,,72.8866119384766,0,1,,,,,,1,1,1,50.0646133422852,0,50.0611560821533,,,,,,,,,,,,,,,,,,,,,,,,,,,,,,,,,
,3754343273.52088,50.0618095397949,320.120880126953,,,5,,,,3.65000008605421,,,,,0.000765112800035151,1.19352449075573E-7,-0.0312274879029033,5.11839287948316E-5,0.00076501317185817,1.19336907750269E-7,0.000765013058234781,1.12738715023537E-7,-4.16949356306143E-7,3.91315689212417E-8,1.00013023066876,10.005763053894,2,20,10,3,2.50293242067872,0.219168357546113,0.0404026173055172,172.741912841797,50.0494689941406,50.0628662109375,320.120880126953,320.120880126953,,,72.9487991333008,0,1,,,,,,1,1,1,50.0610961914063,0,50.0575492858887,,,,,,,,,,,,,,,,,,,,,,,,,,,,,,,,,
,3754343295.37119,50.0286254882812,340.132232666016,,,5,,,,3.65000008605421,,,,,0.000767458453424872,1.08091992300473E-7,-0.0370885341487455,6.49971931347122E-5,0.000767358628576252,1.08077932559883E-7,0.000767358467807203,9.58885536665062E-8,-4.96724278028606E-7,4.98620575404203E-8,1.00013008891137,10.005763053894,2,20,10,3,2.51062497321828,0.219637365515199,0.0404026173055172,172.741912841797,50.018196105957,50.032527923584,340.132232666016,340.132232666016,,,72.9861145019531,0,1,,,,,,1,1,1,50.0267143249512,0,50.0248958587647,,,,,,,,,,,,,,,,,,,,,,,,,,,,,,,,,
,3754343317.01942,50.0101566314697,360.022155761719,,,5,,,,3.65000008605421,,,,,0.000769536812790845,1.2410397203646E-7,-0.042311069832917,5.99748387267821E-5,0.000769436573391379,1.24087806328178E-7,0.000769436363591343,1.15195176886741E-7,-5.68203834671188E-7,4.61286776460344E-8,1.00013027636446,10.005763053894,2,20,10,3,2.51744078169194,0.220056363177264,0.0404026173055172,172.741912841797,50.0077934265137,50.0116500854492,360.022155761719,360.022155761719,,,73.0482940673828,0,1,,,,,,1,1,1,50.0092582702637,0,50.0091243743897,,,,,,,,,,,,,,,,,,,,,,,,,,,,,,,,,
,3754343338.92971,50.0043888092041,380.142791748047,,,5,,,,3.65000008605421,,,,,0.000771359168692825,1.89330899960857E-7,-0.0518027110391959,7.53968185354693E-5,0.000771258630019677,1.89306222640303E-7,0.000771258314788093,1.80161966286244E-7,-6.97316326676194E-7,5.81249673910829E-8,1.00013035662647,10.005763053894,2,20,10,3,2.52343556189766,0.220213813369936,0.0404026173055172,172.741912841797,50.0017700195313,50.0050354003906,380.142791748047,380.142791748047,,,73.0856094360352,0,1,,,,,,1,1,1,50.0040550231934,0,50.0032646872781,,,,,,,,,,,,,,,,,,,,,,,,,,,,,,,,,
,3754343361.95827,50.0307846069336,400.069122314453,,,5,,,,3.65000008605421,,,,,0.000772572115042747,2.09373564172915E-7,-0.0726326426788697,8.80655068366956E-5,0.000772471371483298,2.09346261817965E-7,0.000772470750798989,1.97988252808749E-7,-9.79245287420818E-7,6.80184466662871E-8,1.0001304172079,10.005763053894,2,20,10,3,2.52748035816204,0.219695026918825,0.0404026173055172,172.741912841797,50.0270462036133,50.0313453674316,400.069122314453,400.069122314453,,,73.1353530883789,0,1,,,,,,1,1,1,50.0313682556152,0,50.0293998718262,,,,,,,,,,,,,,,,,,,,,,,,,,,,,,,,,
,3754343383.61421,50.0183773040771,420.056213378906,,,5,,,,3.65000008605421,,,,,0.000774376690389976,2.23418431880053E-7,-0.080163629862029,0.000122697659339377,0.00077427579578321,2.23389322384495E-7,0.00077427503794744,2.02185454468273E-7,-1.08330384160025E-6,9.49938490475125E-8,1.00013030835694,10.005763053894,2,20,10,3,2.53340967502336,0.21992944856737,0.0404026173055172,172.741912841797,50.0138740539551,50.0195083618164,420.056213378906,420.056213378906,,,73.1851043701172,0,1,,,,,,1,1,1,50.0176429748535,0,50.0166343688965,,,,,,,,,,,,,,,,,,,,,,,,,,,,,,,,,
,3754343405.54867,50.0209770202637,440.043273925781,,,5,,,,3.65000008605421,,,,,0.000775419947308643,2.31886895206661E-7,-0.0869872969109755,0.000119424191668221,0.000775318913492412,2.31856681361843E-7,0.000775318019946842,2.12567149078656E-7,-1.17710014930891E-6,9.25890264810023E-8,1.00013031259069,10.005763053894,2,20,10,3,2.53684565704426,0.219977870577604,0.0404026173055172,172.741912841797,50.0170211791992,50.0218696594238,440.043273925781,440.043273925781,,,73.2472915649414,0,1,,,,,,1,1,1,50.0201988220215,0,50.0194275595925,,,,,,,,,,,,,,,,,,,,,,,,,,,,,,,,,
,3754343427.25434,50.0076847076416,460.346008300781,,,5,,,,3.65000008605421,,,,,0.000775913326949624,2.8695568197828E-7,-0.0967187632561997,0.000158828784922915,0.000775812255696856,2.86918302841643E-7,0.000775811150339409,2.59110771270467E-7,-1.30961768722595E-6,1.23222241162675E-7,1.00013027797902,10.005763053894,2,20,10,3,2.53849379207303,0.219741900088628,0.0404026173055172,172.741912841797,50.0040283203125,50.0090827941895,460.346008300781,460.346008300781,,,73.2845993041992,0,1,,,,,,1,1,1,50.0066871643066,0,50.0062210083008,,,,,,,,,,,,,,,,,,,,,,,,,,,,,,,,,
,3754343449.12722,50.0034523010254,480.442413330078,,,5,,,,3.65000008605421,,,,,0.000776025819701283,3.41359127725205E-7,-0.107989096852637,0.000204461587173982,0.000775924706029809,3.41314649727413E-7,0.000775923327855946,3.02201037575484E-7,-1.46243509264794E-6,1.58651262228976E-7,1.00013031376716,10.005763053894,2,20,10,3,2.53890171009334,0.219328967571665,0.0404026173055172,172.741912841797,50.0033988952637,50.0040740966797,480.442413330078,480.442413330078,,,73.3467864990234,0,1,,,,,,1,1,1,50.0035018920898,0,50.0036155700684,,,,,,,,,,,,,,,,,,,,,,,,,,,,,,,,,
,3754343470.77556,50.0056419372559,500.259460449219,,,5,,,,3.65000008605421,,,,,0.000775399658708519,3.13208038841554E-7,-0.111059177577276,0.000196286009919681,0.000775298637890069,3.13167233391005E-7,0.000775297181416759,2.73704282166358E-7,-1.50279786599192E-6,1.52183054226071E-7,1.00013029923376,10.005763053894,2,20,10,3,2.53686161131107,0.219069856502001,0.0404026173055172,172.741912841797,50.0048446655273,50.0057563781738,500.259460449219,500.259460449219,,,73.4089736938477,0,1,,,,,,1,1,1,50.0056266784668,0,50.0053379058838,,,,,,,,,,,,,,,,,,,,,,,,,,,,,,,,,
,3754343492.67165,50.0321998596191,520.307250976562,,,5,,,,3.65000008605421,,,,,0.000773423264062023,3.55577294584516E-7,-0.116154497884389,0.000241562497934412,0.000773322448153,3.55530944998401E-7,0.000773320859030885,3.0249982954397E-7,-1.56773884400205E-6,1.86804994519218E-7,1.0001303672346,10.005763053894,2,20,10,3,2.53041163591443,0.218340626534059,0.0404026173055172,172.741912841797,50.0281372070313,50.0323371887207,520.307250976562,520.307250976562,,,73.4587249755859,0,1,,,,,,1,1,1,50.0320701599121,0,50.0308879852295,,,,,,,,,,,,,,,,,,,,,,,,,,,,,,,,,
,3754343514.33995,50.0166816711426,540.318603515625,,,5,,,,3.65000008605421,,,,,0.000769497260782001,3.57650498667878E-7,-0.125645956824512,0.000220842229998431,0.000769397061620757,3.5760392763792E-7,0.000769395211619069,3.14649481783095E-7,-1.68723688420154E-6,1.69930199422281E-7,1.00013023075632,10.005763053894,2,20,10,3,2.51759962166684,0.216869228454598,0.0404026173055172,172.741912841797,50.0115814208984,50.0184631347656,540.318603515625,540.318603515625,,,73.4835968017578,0,1,,,,,,1,1,1,50.0158309936523,0,50.0146118164063,,,,,,,,,,,,,,,,,,,,,,,,,,,,,,,,,
,3754343536.21331,50.0155506134033,560.366333007812,,,5,,,,3.65000008605421,,,,,0.000760629449766764,3.67415794809379E-7,-0.135432980510728,0.0002389456356234,0.000760530357425402,3.67367929069534E-7,0.000760528232762848,3.192631196913E-7,-1.79770304259521E-6,1.81742278278382E-7,1.00013029373567,10.005763053894,2,20,10,3,2.48861977582158,0.213998295023109,0.0404026173055172,172.741912841797,50.0126075744629,50.0158920288086,560.366333007812,560.366333007812,,,73.5333404541016,0,1,,,,,,1,1,1,50.0153541564941,0,50.0145874023438,,,,,,,,,,,,,,,,,,,,,,,,,,,,,,,,,
,3754343557.85229,50.0120983123779,580.268432617187,,,5,,,,3.65000008605421,,,,,0.000741771736145588,3.61614830662251E-7,-0.152560422738884,0.000242423788749654,0.000741675047510773,3.61567694808185E-7,0.000741672418321099,3.13677917546407E-7,-1.97484223168356E-6,1.79825921303504E-7,1.0001303652255,10.005763053894,2,20,10,3,2.42698048808243,0.208019013317987,0.0404026173055172,172.741912841797,50.0073776245117,50.0123977661133,580.268432617187,580.268432617187,,,73.5830917358398,0,1,,,,,,1,1,1,50.0118751525879,0,50.0103881835937,,,,,,,,,,,,,,,,,,,,,,,,,,,,,,,,,
,3754343579.82258,50.0464687347412,600.316223144531,,,5,,,,3.65000008605421,,,,,0.000689288338498862,4.01293718256443E-7,-0.163366847722853,0.000260869871452814,0.000689198434949489,4.01241377708087E-7,0.000689195633411048,3.58677382657107E-7,-1.96510151656058E-6,1.79847653182719E-7,1.00013044653733,10.005763053894,2,20,10,3,2.25529519784356,0.192923705808897,0.0404026173055172,172.741912841797,50.0424270629883,50.0472679138184,600.316223144531,600.316223144531,,,73.6452789306641,0,1,,,,,,1,1,1,50.0472831726074,0,50.0454624176025,,,,,,,,,,,,,,,,,,,,,,,,,,,,,,,,,
,3754343603.69913,50.0612888336182,620.388305664062,,,5,,,,3.65000008605421,,,,,0.000512840499220509,3.23499091347035E-7,-0.206844227539564,0.000394944865952519,0.000512773732573824,3.23456975036861E-7,0.000512770391109346,2.52210489323184E-7,-1.85116699921934E-6,2.02519835510887E-7,1.0001302068387,10.005763053894,2,20,1,3,1.67807858696268,0.14230071690553,0.0404026173055172,172.741912841797,50.0461769104004,50.0652770996094,620.388305664062,620.388305664062,,,73.7074661254883,0,1,,,,,,1,1,1,50.0589866638184,0,50.0576641376202,,,,,,,,,,,,,,,,,,,,,,,,,,,,,,,,,
,3754343626.02633,50.0589256286621,640.266052246094,,,5,,,,3.65000008605421,,,,,0.000206239863717068,3.92007386243703E-7,-0.555124199158838,0.00107811285062837,0.00020621298835531,3.91956303295299E-7,0.000206203309640853,3.2269183898719E-7,-1.99791380833348E-6,2.22485327030754E-7,1.00013032817172,10.005763053894,2,20,1,3,0.675177394711204,0.0531377344192828,0.0404026173055172,172.741912841797,50.0509910583496,50.0592308044434,640.266052246094,640.266052246094,,,73.7199020385742,0,1,,,,,,1,1,1,50.058723449707,0,50.0564777374268,,,,,,,,,,,,,,,,,,,,,,,,,,,,,,,,,
,3754343647.55351,50.034029006958,660.338073730469,,,5,,,,3.65000008605421,,,,,0.000103190534368411,4.36867028672911E-7,-1.13655971765181,0.00210105048306014,0.000103177110333153,4.36810196731574E-7,0.000103156811158604,3.78839890263425E-7,-2.04656011098863E-6,2.17447661550711E-7,1.00013010671858,10.005763053894,2,20,1,3,0.338071927787387,0.0231648380664463,0.0404026173055172,172.741912841797,50.022388458252,50.0379943847656,660.338073730469,660.338073730469,,,73.7945251464844,0,1,,,,,,1,1,1,50.031982421875,0,50.0298324584961,,,,,,,,,,,,,,,,,,,,,,,,,,,,,,,,,
,3754343669.47231,50.0152549743652,680.300903320312,,,5,,,,3.65000008605421,,,,,5.85429084536857E-5,4.89008079472168E-7,-1.86616552009359,0.00341679713908543,5.85352824650424E-5,4.88944379697779E-7,5.85042365556232E-5,4.4533713152274E-7,-1.90619996484655E-6,2.01845103297414E-7,1.00013028020575,10.005763053894,2,20,1,3,0.191949439632053,0.0107028141189932,0.0404026173055172,172.741912841797,50.0119361877441,50.0168991088867,680.300903320312,680.300903320312,,,73.8318328857422,0,1,,,,,,1,1,1,50.0147399902344,0,50.0141403198242,,,,,,,,,,,,,,,,,,,,,,,,,,,,,,,,,
,3754343691.36398,50.0486145019531,700.348693847656,,,5,,,,3.65000008605421,,,,,3.96831018173932E-5,5.5276216283892E-7,-2.95875447455322,0.00652227392107196,3.96779266255878E-5,5.52690075474666E-7,3.96250340089959E-5,4.87226136073722E-7,-2.04805788283665E-6,2.60915717914546E-7,1.00013042999586,10.005763053894,2,20,1,3,0.130226894200041,0.00477533280556789,0.0404026173055172,172.741912841797,50.042308807373,50.0488319396973,700.348693847656,700.348693847656,,,73.8940200805664,0,1,,,,,,1,1,1,50.0487670898438,0,50.0466171264648,,,,,,,,,,,,,,,,,,,,,,,,,,,,,,,,,
,3754343712.99034,50.0569343566895,720.214294433594,,,5,,,,3.65000008605421,,,,,3.05360887002072E-5,4.26533624740801E-7,-4.03376975807503,0.00676910985740816,3.05321087853648E-5,4.26478032568517E-7,3.04564735152792E-5,3.72087464094273E-7,-2.14776346333745E-6,2.08409288006572E-7,1.00013035178377,10.005763053894,2,20,1,3,0.100260724310295,0.00179601717598447,0.0404026173055172,172.741912841797,50.0464248657227,50.0579261779785,720.214294433594,720.214294433594,,,73.9437713623047,0,1,,,,,,1,1,1,50.0559959411621,0,50.0535301208496,,,,,,,,,,,,,,,,,,,,,,,,,,,,,,,,,
,3754343734.70281,50.0686779022217,740.225646972656,,,5,,,,3.65000008605421,,,,,2.44611416473009E-5,4.80923122566202E-7,-5.46779319200521,0.0092411254327841,2.44579543964101E-5,4.80860458988479E-7,2.43466686842929E-5,4.23254227265373E-7,-2.33050578934054E-6,2.28216213535767E-7,1.00013031551368,10.005763053894,2,20,1,3,0.0803254429329199,-0.000569961183260824,0.0404026173055172,172.741912841797,50.0558853149414,50.0692977905273,740.225646972656,740.225646972656,,,73.9810791015625,0,1,,,,,,1,1,1,50.068000793457,0,50.0644618988037,,,,,,,,,,,,,,,,,,,,,,,,,,,,,,,,,
,3754343756.55762,50.0623188018799,760.358459472656,,,5,,,,3.65000008605421,,,,,2.19909280982541E-5,4.85945337545629E-7,-5.91221118067488,0.00996542033728953,2.19880665881411E-5,4.85882105221302E-7,2.18711095736869E-5,4.32443663096144E-7,-2.26487048201603E-6,2.21526292846409E-7,1.00013013923264,10.005763053894,2,20,1,3,0.0722076775932955,-0.00107096003647921,0.0404026173055172,172.741912841797,50.0484390258789,50.0652046203613,760.358459472656,760.358459472656,,,74.0308303833008,0,1,,,,,,1,1,1,50.0605659484863,0,50.057657623291,,,,,,,,,,,,,,,,,,,,,,,,,,,,,,,,,
,3754343778.41702,50.0627937316895,780.2119140625,,,5,,,,3.65000008605421,,,,,1.92496238471424E-5,4.52652413944271E-7,-7.08226141749146,0.0113381907913196,1.92471164153821E-5,4.5259345201088E-7,1.91002639376377E-5,3.9559949874171E-7,-2.37305874766087E-6,2.19867845303565E-7,1.0001302757102,10.005763053894,2,20,1,3,0.0631743073121938,-0.00222659053967733,0.0404026173055172,172.741912841797,50.0510368347168,50.0639266967773,780.2119140625,780.2119140625,,,74.0805740356445,0,1,,,,,,1,1,1,50.0617637634277,0,50.0588233947754,,,,,,,,,,,,,,,,,,,,,,,,,,,,,,,,,
,3754343800.10232,50.0433692932129,800.296142578125,,,5,,,,3.65000008605421,,,,,1.82730204064045E-5,6.04234654565225E-7,-7.11993469042057,0.0137847931758803,1.82706417524822E-5,6.04155999526313E-7,1.8129754525596E-5,5.477413670134E-7,-2.26458625121152E-6,2.54919333566385E-7,1.00013018994924,10.005763053894,2,20,1,3,0.0599679216967691,-0.00215177131415485,0.0404026173055172,172.741912841797,50.0332298278809,50.0466194152832,800.296142578125,800.296142578125,,,74.1427612304687,0,1,,,,,,1,1,1,50.041919708252,0,50.0400371551514,,,,,,,,,,,,,,,,,,,,,,,,,,,,,,,,,