File: Experimental_Data/Supplementary_Fig1_Data/ZFC_51p5K.dat
[Header]
; MPMS3 Data File (default extension .dat)
; Copyright (c) 2007, Quantum Design, Inc. All rights reserved.
TITLE,ZFC_51p5K
FILEOPENTIME,3754339253.1187,12/19/2018,12:00 am
BYAPP,SQUID AC,0.9.1.0
INFO,MPMS3 Measurement Release 1.1.16 Build 347, MultiVu Release 2.3.3.2,APPNAME
INFO,0,MOMENT_UNITS
INFO,CoIINO3,SAMPLE_MATERIAL
INFO,40 Hours Pumped Turbo,SAMPLE_COMMENT
INFO,,SAMPLE_MASS
INFO,,SAMPLE_VOLUME
INFO,,SAMPLE_MOLECULAR_WEIGHT
INFO,,SAMPLE_SIZE
INFO,,SAMPLE_SHAPE
INFO,Brass,SAMPLE_HOLDER
INFO,Standard,SAMPLE_HOLDER_DETAIL
INFO,65.37,SAMPLE_OFFSET
DATATYPE,COMMENT,1
DATATYPE,TIME,2
STARTUPAXIS,X,2
STARTUPAXIS,Y1,5
FIELDGROUP, VSM,2,3,4,5,6,8,9,10,11,14,15
FIELDGROUP, DC, 2,3,4,14,56,57,58,59,60,61,62,63,64,65,66,67,68,69
FIELDGROUP, AC, 2,3,4,11,16,17,18,19,20,21,22,23,24,25,26,27,28,29,30
STARTUPGROUP, All
[Data]
Comment,Time Stamp (sec),Temperature (K),Magnetic Field (Oe),Moment (emu),M. Std. Err. (emu),Transport Action,Averaging Time (sec),Frequency (Hz),Peak Amplitude (mm),Center Position (mm),Lockin Signal' (V),Lockin Signal (V),Range,M. Quad. Signal (emu),AC Moment (emu),AC M. Std Err. (emu),AC Phase (deg),AC Phase Std. Err. (deg),AC Susceptibility (emu/Oe),AC Suscept. Std Err. (emu/Oe),AC X' (emu/Oe),AC X' Std Err. (emu/Oe),AC X'' (emu/Oe),AC X'' Std Err. (emu/Oe),AC Drive (Oe),AC Frequency (Hz),AC Averaging Time (sec),AC Cycles,AC Range,AC Measure Type,AC Signal' (V),AC Signal'' (V),AC Trim Coil Ratio,AC Trim Coil Phase,Min. Temperature (K),Max. Temperature (K),Min. Field (Oe),Max. Field (Oe),Mass (grams),Motor Lag (deg),Pressure (Torr),Measure Count,Measurement Number,SQUID Status (code),Motor Status (code),Measure Status (code),Motor Current (amps),Motor Temp. (C),Temp. Status (code),Field Status (code),Chamber Status (code),Chamber Temp (K),Redirection State,Average Temp (K),Rotation Angle (deg),Rotator state,DC Moment Fixed Ctr (emu),DC Moment Err Fixed Ctr (emu),DC Moment Free Ctr (emu),DC Moment Err Free Ctr (emu),DC Fixed Fit,DC Free Fit,DC Calculated Center (mm),DC Calculated Center Err (mm),DC Scan Length (mm),DC Scan Time (s),DC Number of Points,DC Squid Drift,DC Min V (V),DC Max V (V),DC Scans per Measure,Map 01,Map 02,Map 03,Map 04,Map 05,Map 06,Map 07,Map 08,Map 09,Map 10,Map 11,Map 12,Map 13,Map 14,Map 15,Map 16
,3754339386.93031,51.4769153594971,-0.0121428091078997,,,5,,,,3.65000008605421,,,,,0.00056910227836718,2.18515261661118E-8,-0.00138297647176699,1.20069422290539E-5,0.00056902854057057,2.18486948940307E-8,0.000569028540404807,2.07554051520825E-8,-1.37349223622468E-8,6.82485351823393E-9,1.00012958540979,10.005763053894,2,20,1,3,1.86167302734871,0.163348505283026,0.0404026173055172,172.741912841797,51.4396286010742,51.4858055114746,-0.0121428091078997,-0.0121428091078997,,,65.4367904663086,0,1,,,,,,1,1,1,51.4721755981445,0,51.4641036987305,,,,,,,,,,,,,,,,,,,,,,,,,,,,,,,,,
,3754339408.89881,51.4089736938477,20.0720634460449,,,5,,,,3.65000008605421,,,,,0.000567200368141065,1.79046487771028E-8,-0.000841578549935384,8.14743892664737E-6,0.000567126752816682,1.79023249836045E-8,0.000567126752755505,1.72978068393233E-8,-8.3301373033748E-9,4.61292947789708E-9,1.00012980400593,10.005763053894,2,20,1,3,1.85544739912998,0.162860149804368,0.0404026173055172,172.741912841797,51.3999252319336,51.4146270751953,20.0720634460449,20.0720634460449,,,65.4492263793945,0,1,,,,,,1,1,1,51.4069175720215,0,51.4054882049561,,,,,,,,,,,,,,,,,,,,,,,,,,,,,,,,,
,3754339430.56579,51.3953189849854,40.1076965332031,,,5,,,,3.65000008605421,,,,,0.000566487682009677,1.44968874371657E-8,-0.00192503496579377,8.12529750367025E-6,0.000566413928185306,1.44950000159138E-8,0.000566413927865611,1.37465772787559E-8,-1.90304875146207E-8,4.59746001402222E-9,1.0001302118834,10.005763053894,2,20,1,3,1.85311665250572,0.162660242416684,0.0404026173055172,172.741912841797,51.394359588623,51.3990287780762,40.1076965332031,40.1076965332031,,,65.4865341186523,0,1,,,,,,1,1,1,51.3954429626465,0,51.3963062286377,,,,,,,,,,,,,,,,,,,,,,,,,,,,,,,,,
,3754339452.47446,51.4177951812744,60.009765625,,,5,,,,3.65000008605421,,,,,0.000567643698343026,1.17944893236115E-8,0.00199938013449774,1.07782657570141E-5,0.000567569666148133,1.17929510841581E-8,0.000567569665802564,1.00834399863614E-8,1.9805778450936E-8,6.11538496865024E-9,1.00013043719443,10.005763053894,2,20,1,3,1.85688465066174,0.16315884836826,0.0404026173055172,172.741912841797,51.4117012023926,51.4355392456055,60.009765625,60.009765625,,,65.5362854003906,0,1,,,,,,1,1,1,51.4203224182129,0,51.4234036532315,,,,,,,,,,,,,,,,,,,,,,,,,,,,,,,,,
,3754339474.23062,51.447696685791,80.0332565307617,,,5,,,,3.65000008605421,,,,,0.000577655177188142,1.22926335524587E-8,0.0162134059109098,1.28191133733028E-5,0.000577579976822166,1.22910332715671E-8,0.000577579953696972,9.81197420719627E-9,1.63442029497374E-7,7.40234159169147E-9,1.00013019905293,10.005763053894,2,20,1,3,1.88959059538547,0.166545659109965,0.0404026173055172,172.741912841797,51.4457664489746,51.4517631530762,80.0332565307617,80.0332565307617,,,65.5984725952148,0,1,,,,,,1,1,1,51.4487457275391,0,51.4491432189941,,,,,,,,,,,,,,,,,,,,,,,,,,,,,,,,,
,3754339496.08666,51.4553718566895,100.09317779541,,,5,,,,3.65000008605421,,,,,0.00059937485210876,2.77075451424581E-8,0.0562773160766872,2.00924481178278E-5,0.000599296820046179,2.77039379225541E-8,0.000599296530955937,2.49550558804805E-8,5.88643900633502E-7,1.20313491520621E-8,1.00013020603476,10.005763053894,2,20,1,3,1.96051472210446,0.17422073008587,0.0404026173055172,172.741912841797,51.454704284668,51.4559936523438,100.09317779541,100.09317779541,,,65.673095703125,0,1,,,,,,1,1,1,51.4557113647461,0,51.4553539276123,,,,,,,,,,,,,,,,,,,,,,,,,,,,,,,,,
,3754339517.69201,51.508373260498,120.128807067871,,,5,,,,3.65000008605421,,,,,0.000637816861597626,9.65954503072738E-8,0.231470933453211,0.000109873811288263,0.000637733595283869,9.65828398738451E-8,0.0006377283910552,6.64779640220828E-8,2.57639201886328E-6,7.00637228355407E-8,1.000130565983,10.005763053894,2,20,1,3,2.08567637628788,0.19181753404239,0.0404026173055172,172.741912841797,51.4995269775391,51.5193061828613,120.128807067871,120.128807067871,,,65.7477188110352,0,1,,,,,,1,1,1,51.5113182067871,0,51.5128408578726,,,,,,,,,,,,,,,,,,,,,,,,,,,,,,,,,
,3754339542.22968,51.515115737915,140.043014526367,,,5,,,,3.65000008605421,,,,,0.000678963998295453,1.00587736760849E-7,0.181025453288,8.46824140966282E-5,0.00067887569606407,1.00574654886658E-7,0.000678872307669894,8.25481089228478E-8,2.14489753326792E-6,5.74549468612758E-8,1.00013007128094,10.005763053894,2,20,10,3,2.22040433678339,0.20228461821389,0.0404026173055172,172.741912841797,51.5102882385254,51.5173225402832,140.043014526367,140.043014526367,,,65.8347778320312,0,1,,,,,,1,1,1,51.5141296386719,0,51.5134449005127,,,,,,,,,,,,,,,,,,,,,,,,,,,,,,,,,
,3754339563.85306,51.5357971191406,160.078659057617,,,5,,,,3.65000008605421,,,,,0.000708495372274129,1.05000734497142E-7,0.131723169752417,9.8448703995155E-5,0.000708403046673209,1.04987051618906E-7,0.00070840117457204,7.84895174238682E-8,1.62861930430747E-6,6.97257245369251E-8,1.00013032919798,10.005763053894,2,20,10,3,2.31715787592901,0.209138745575552,0.0404026173055172,172.741912841797,51.5292434692383,51.535888671875,160.078659057617,160.078659057617,,,65.8969573974609,0,1,,,,,,1,1,1,51.5357246398926,0,51.5335540771484,,,,,,,,,,,,,,,,,,,,,,,,,,,,,,,,,
,3754339585.78633,51.5376510620117,180.089996337891,,,5,,,,3.65000008605421,,,,,0.000724959210711087,6.98744544698423E-8,0.0657695573095829,2.93713789409251E-5,0.000724864927684198,6.98653670964118E-8,0.000724864450120159,6.65570303972744E-8,8.32068877297001E-7,2.12445575198137E-8,1.0001300697872,10.005763053894,2,20,10,3,2.37124497333712,0.211320020213285,0.0404026173055172,172.741912841797,51.5312919616699,51.538631439209,180.089996337891,180.089996337891,,,65.9591445922852,0,1,,,,,,1,1,1,51.5371513366699,0,51.53561668396,,,,,,,,,,,,,,,,,,,,,,,,,,,,,,,,,
,3754339607.39863,51.5199661254883,199.979919433594,,,5,,,,3.65000008605421,,,,,0.000733274030054166,7.61703143697192E-8,0.0136392638472076,4.15780599820575E-5,0.00073317867009174,7.61604086618685E-8,0.000733178649317917,6.98031815695225E-8,1.74533225990863E-7,3.04618399036415E-8,1.00013006374342,10.005763053894,2,20,10,3,2.39863193956038,0.211612551029439,0.0404026173055172,172.741912841797,51.5144958496094,51.5214462280273,199.979919433594,199.979919433594,,,66.0088958740234,0,1,,,,,,1,1,1,51.5192451477051,0,51.5179874420166,,,,,,,,,,,,,,,,,,,,,,,,,,,,,,,,,
,3754339629.30517,51.5474643707275,219.954833984375,,,5,,,,3.65000008605421,,,,,0.000738569851103915,1.23902550936134E-7,0.000363632852304896,6.89609664621258E-5,0.000738473635845531,1.23886409854914E-7,0.000738473635830659,1.12949121045903E-7,4.68678979210608E-9,5.08953691576919E-8,1.00013028936134,10.005763053894,2,20,10,3,2.41600136793199,0.212632606232547,0.0404026173055172,172.741912841797,51.5419158935547,51.5483055114746,219.954833984375,219.954833984375,,,66.0710830688477,0,1,,,,,,1,1,1,51.5483055114746,0,51.5458480834961,,,,,,,,,,,,,,,,,,,,,,,,,,,,,,,,,
,3754339651.05248,51.5482406616211,240.075469970703,,,5,,,,3.65000008605421,,,,,0.000742942918780658,1.17231884861044E-7,-0.00278250338863639,5.0661861610968E-5,0.000742846277907908,1.17216635517682E-7,0.000742846277031926,1.11023939790096E-7,-3.60754719155232E-8,3.75955374422322E-8,1.00013009538531,10.005763053894,2,20,10,3,2.43031499707372,0.213810490436994,0.0404026173055172,172.741912841797,51.5399932861328,51.5490226745605,240.075469970703,240.075469970703,,,66.1457061767578,0,1,,,,,,1,1,1,51.5476684570313,0,51.5454936981201,,,,,,,,,,,,,,,,,,,,,,,,,,,,,,,,,
,3754339672.97219,51.5258407592773,260.135406494141,,,5,,,,3.65000008605421,,,,,0.0007469573938508,1.05718015165732E-7,-0.0059668941367006,3.20093924782312E-5,0.000746860310728474,1.05704274843884E-7,0.00074686030667842,1.02976945126512E-7,-7.77794881025602E-8,2.38567074987859E-8,1.00012998832704,10.005763053894,2,20,10,3,2.44345583724383,0.214882551094904,0.0404026173055172,172.741912841797,51.5180549621582,51.5290679931641,260.135406494141,260.135406494141,,,66.1830139160156,0,1,,,,,,1,1,1,51.524341583252,0,51.5232374017889,,,,,,,,,,,,,,,,,,,,,,,,,,,,,,,,,
,3754339694.33537,51.5111198425293,280.001037597656,,,5,,,,3.65000008605421,,,,,0.000750107607746404,9.95104644278427E-8,-0.0123970004831531,3.16782382136216E-5,0.000750010104054259,9.94975294334652E-8,0.000750010086498278,9.66290917937588E-8,-1.62278541784394E-7,2.37187053288455E-8,1.00013000317145,10.005763053894,2,20,10,3,2.45378182654416,0.215565638139592,0.0404026173055172,172.741912841797,51.5074920654297,51.5125465393066,280.001037597656,280.001037597656,,,66.2327651977539,0,1,,,,,,1,1,1,51.5103721618652,0,51.5099355524236,,,,,,,,,,,,,,,,,,,,,,,,,,,,,,,,,
,3754339716.4714,51.5434379577637,300.024505615234,,,5,,,,3.65000008605421,,,,,0.000752753392835531,1.02772958861799E-7,-0.0115843884371545,3.22422399479618E-5,0.000752655295804145,1.02759565734293E-7,0.000752655280420223,9.98633917701241E-8,-1.52176151901055E-7,2.42246018350594E-8,1.00013033460594,10.005763053894,2,20,10,3,2.46243050301324,0.216413552242222,0.0404026173055172,172.741912841797,51.5396766662598,51.5450096130371,300.024505615234,300.024505615234,,,66.2949447631836,0,1,,,,,,1,1,1,51.5449180603027,0,51.5427486419678,,,,,,,,,,,,,,,,,,,,,,,,,,,,,,,,,
,3754339738.09263,51.556510925293,320.084442138672,,,5,,,,3.65000008605421,,,,,0.000755575795086634,8.98744168129995E-8,-0.0168725376974201,4.29205493433556E-5,0.000755477485106417,8.98627230131234E-8,0.000755477452349194,8.38168962868727E-8,-2.22474015906655E-7,3.24042726221244E-8,1.00013012959639,10.005763053894,2,20,10,3,2.4716799975273,0.21704988178691,0.0404026173055172,172.741912841797,51.548713684082,51.5570602416992,320.084442138672,320.084442138672,,,66.3322601318359,0,1,,,,,,1,1,1,51.5559616088867,0,51.5538047790527,,,,,,,,,,,,,,,,,,,,,,,,,,,,,,,,,
,3754339760.03758,51.5317554473877,340.132232666016,,,5,,,,3.65000008605421,,,,,0.000758033378703313,1.52969295508452E-7,-0.0280554695473691,5.48818711236262E-5,0.000757934911783704,1.52949425123128E-7,0.00075793482091973,1.47196010519094E-7,-3.71130634182864E-7,4.15555186799323E-8,1.00012991474344,10.005763053894,2,20,10,3,2.47975854477145,0.217325163964085,0.0404026173055172,172.741912841797,51.5229263305664,51.5353775024414,340.132232666016,340.132232666016,,,66.3695678710937,0,1,,,,,,1,1,1,51.5302696228027,0,51.5284759521484,,,,,,,,,,,,,,,,,,,,,,,,,,,,,,,,,
,3754339781.73353,51.5296230316162,360.022155761719,,,5,,,,3.65000008605421,,,,,0.000759808626288744,1.32163087131546E-7,-0.0385585164625129,8.58842839617046E-5,0.000759709741397083,1.32145886836498E-7,0.000759709569363573,1.1492346662127E-7,-5.11264156072495E-7,6.52313745643481E-8,1.0001301614107,10.005763053894,2,20,10,3,2.48560256030484,0.217431395198533,0.0404026173055172,172.741912841797,51.5231628417969,51.5298461914063,360.022155761719,360.022155761719,,,66.419319152832,0,1,,,,,,1,1,1,51.5293998718262,0,51.527547454834,,,,,,,,,,,,,,,,,,,,,,,,,,,,,,,,,
,3754339803.64137,51.5144634246826,380.082061767578,,,5,,,,3.65000008605421,,,,,0.000761754750793641,1.7629210040094E-7,-0.0497356238396804,7.31655839747139E-5,0.000761655703996817,1.76269178104976E-7,0.000761655417038676,1.67236591775289E-7,-6.61155449038541E-7,5.57022936797834E-8,1.00013004142988,10.005763053894,2,20,10,3,2.49200821564605,0.217555737465625,0.0404026173055172,172.741912841797,51.5108451843262,51.5162696838379,380.082061767578,380.082061767578,,,66.4690704345703,0,1,,,,,,1,1,1,51.5136604309082,0,51.512882232666,,,,,,,,,,,,,,,,,,,,,,,,,,,,,,,,,
,3754339826.67058,51.547384262085,400.069122314453,,,5,,,,3.65000008605421,,,,,0.000762225306288116,2.11985626031736E-7,-0.065157977515816,0.000130631922859241,0.000762126099613376,2.11958035253947E-7,0.000762125606795199,1.87129606593417E-7,-8.66705802437112E-7,9.95425489170652E-8,1.00013017094519,10.005763053894,2,20,10,3,2.49360285528445,0.217072142430313,0.0404026173055172,172.741912841797,51.5425491333008,51.5483207702637,400.069122314453,400.069122314453,,,66.5188140869141,0,1,,,,,,1,1,1,51.5482177734375,0,51.5461776733398,,,,,,,,,,,,,,,,,,,,,,,,,,,,,,,,,
,3754339848.30475,51.5395889282227,420.104766845703,,,5,,,,3.65000008605421,,,,,0.000763239002085556,2.58883215529005E-7,-0.0837386425848772,0.000141850548821959,0.000763139760554326,2.58849553770829E-7,0.000763138945511222,2.35129874662286E-7,-1.11533982859197E-6,1.08245247141178E-7,1.00013004371723,10.005763053894,2,20,10,3,2.49698624165439,0.216604662465963,0.0404026173055172,172.741912841797,51.5301361083984,51.5422439575195,420.104766845703,420.104766845703,,,66.5561294555664,0,1,,,,,,1,1,1,51.5381050109863,0,51.5361366271973,,,,,,,,,,,,,,,,,,,,,,,,,,,,,,,,,
,3754339870.18905,51.5293235778809,440.091827392578,,,5,,,,3.65000008605421,,,,,0.000763828036176386,2.01070965552396E-7,-0.08420227756225,0.000126174144543873,0.000763728726271761,2.01044823099558E-7,0.000763727901542383,1.76450236100156E-7,-1.12238066381631E-6,9.6355254528914E-8,1.000130032957,10.005763053894,2,20,10,3,2.49891181001733,0.216805095945506,0.0404026173055172,172.741912841797,51.521240234375,51.5308685302734,440.091827392578,440.091827392578,,,66.6307525634766,0,1,,,,,,1,1,1,51.5284767150879,0,51.5265270233154,,,,,,,,,,,,,,,,,,,,,,,,,,,,,,,,,
,3754339891.81072,51.5476684570313,460.358184814453,,,5,,,,3.65000008605421,,,,,0.000763232456902363,2.69711781774952E-7,-0.0957208481317409,0.00013146106969883,0.000763133109219482,2.69676674200159E-7,0.00076313204424792,2.50319175849266E-7,-1.27492312859144E-6,1.00328554309343E-7,1.00013018395046,10.005763053894,2,20,10,3,2.49700356314825,0.216188149128215,0.0404026173055172,172.741912841797,51.542236328125,51.5478591918945,460.358184814453,460.358184814453,,,66.6556243896484,0,1,,,,,,1,1,1,51.547477722168,0,51.5457191467285,,,,,,,,,,,,,,,,,,,,,,,,,,,,,,,,,
,3754339913.78688,51.5484809875488,480.454528808594,,,5,,,,3.65000008605421,,,,,0.000761638585184231,3.24070624979202E-7,-0.106984967532741,0.000188886953194143,0.000761539591409299,3.24028503984894E-7,0.000761538263823439,2.90346654292887E-7,-1.42197630977867E-6,1.43851630980031E-7,1.0001299916328,10.005763053894,2,20,10,3,2.49182815618477,0.215300392937794,0.0404026173055172,172.741912841797,51.5373001098633,51.5499114990234,480.454528808594,480.454528808594,,,66.7053756713867,0,1,,,,,,1,1,1,51.5473594665527,0,51.5447608947754,,,,,,,,,,,,,,,,,,,,,,,,,,,,,,,,,
,3754339935.41151,51.5585250854492,500.259460449219,,,5,,,,3.65000008605421,,,,,0.000757550636391451,3.21468824860056E-7,-0.117847629418961,0.00017904563073089,0.000757452086559493,3.21427004951065E-7,0.000757450484342054,2.91406660714841E-7,-1.55794843213392E-6,1.35637301664541E-7,1.0001301070176,10.005763053894,2,20,10,3,2.47849114314412,0.213727410930238,0.0404026173055172,172.741912841797,51.55078125,51.5588455200195,500.259460449219,500.259460449219,,,66.7426834106445,0,1,,,,,,1,1,1,51.5581398010254,0,51.5560138702393,,,,,,,,,,,,,,,,,,,,,,,,,,,,,,,,,
,3754339957.31321,51.5750560760498,520.331481933594,,,5,,,,3.65000008605421,,,,,0.000749441885433204,3.16798194239253E-7,-0.120894594335243,0.000190106670858237,0.000749344425508372,3.16756996744427E-7,0.000749342757417046,2.82908345416811E-7,-1.58112209813711E-6,1.42470569171571E-7,1.00013006025202,10.005763053894,2,20,10,3,2.45196968311821,0.211361911388073,0.0404026173055172,172.741912841797,51.562671661377,51.5757522583008,520.331481933594,520.331481933594,,,66.7924346923828,0,1,,,,,,1,1,1,51.5743179321289,0,51.5708118438721,,,,,,,,,,,,,,,,,,,,,,,,,,,,,,,,,
,3754339979.17569,51.5596694946289,540.415710449219,,,5,,,,3.65000008605421,,,,,0.00073315599480289,3.30488070558753E-7,-0.131629888833267,0.000229102203963179,0.000733060748302581,3.30445135859538E-7,0.000733058813781158,2.8457824302711E-7,-1.68411392159824E-6,1.67955980568815E-7,1.00012992988716,10.005763053894,2,20,10,3,2.39872228632675,0.206371050356299,0.0404026173055172,172.741912841797,51.5476760864258,51.5622215270996,540.415710449219,540.415710449219,,,66.8297424316406,0,1,,,,,,1,1,1,51.5580139160156,0,51.5554737091064,,,,,,,,,,,,,,,,,,,,,,,,,,,,,,,,,
,3754340000.86823,51.530725479126,560.439208984375,,,5,,,,3.65000008605421,,,,,0.000689345560103454,3.20362407482158E-7,-0.145405995627321,0.00021232699751701,0.000689255968985692,3.20320771432205E-7,0.000689253749411476,2.84919130370648E-7,-1.74920113984543E-6,1.46377886853707E-7,1.00012998236039,10.005763053894,2,20,10,3,2.25542804315969,0.193545292005106,0.0404026173055172,172.741912841797,51.5220985412598,51.5342903137207,560.439208984375,560.439208984375,,,66.867057800293,0,1,,,,,,1,1,1,51.5293045043945,0,51.527713394165,,,,,,,,,,,,,,,,,,,,,,,,,,,,,,,,,
,3754340022.48929,51.5127468109131,580.304809570312,,,5,,,,3.65000008605421,,,,,0.000546446976336732,2.96988642025687E-7,-0.183343606078339,0.000329244120983739,0.000546375967745423,2.96950049543675E-7,0.000546373170390994,2.36256701730756E-7,-1.74837256937993E-6,1.79894699230676E-7,1.00012996287447,10.005763053894,2,20,10,3,1.78798575389498,0.152278324405503,0.0404026173055172,172.741912841797,51.508472442627,51.5143051147461,580.304809570312,580.304809570312,,,66.9292373657227,0,1,,,,,,1,1,1,51.5121803283691,0,51.5112102508545,,,,,,,,,,,,,,,,,,,,,,,,,,,,,,,,,
,3754340047.56194,51.5509967803955,600.401184082031,,,5,,,,3.65000008605421,,,,,0.000224487329174259,2.58116019152786E-7,-0.389881640118124,0.000603742549997394,0.000224458099901514,2.58082411271435E-7,0.000224452903246166,2.19581550202085E-7,-1.52736235565494E-6,1.35611481145688E-7,1.0001302215102,10.005763053894,2,20,1,3,0.734747021179315,0.0599254196609373,0.0404026173055172,172.741912841797,51.5407218933105,51.551830291748,600.401184082031,600.401184082031,,,66.966552734375,0,1,,,,,,1,1,1,51.5503578186035,0,51.5478477478027,,,,,,,,,,,,,,,,,,,,,,,,,,,,,,,,,
,3754340070.00809,51.5614376068115,620.376098632813,,,5,,,,3.65000008605421,,,,,9.51425262563913E-5,3.68992018355547E-7,-1.03889873534804,0.00204757089740523,9.51301473936998E-5,3.68944009313648E-7,9.51145095292073E-5,3.13071691940717E-7,-1.724824676711E-6,1.95207063688295E-7,1.00013012554937,10.005763053894,2,20,1,3,0.311668898855223,0.0218753785674859,0.0404026173055172,172.741912841797,51.5517272949219,51.5620384216309,620.376098632813,620.376098632813,,,67.0038604736328,0,1,,,,,,1,1,1,51.5608367919922,0,51.5582599639893,,,,,,,,,,,,,,,,,,,,,,,,,,,,,,,,,
,3754340091.68274,51.5353183746338,640.423889160156,,,5,,,,3.65000008605421,,,,,5.74958435693622E-5,4.61938853818752E-7,-1.84787641249872,0.00379734168748542,5.74883722057899E-5,4.61878826642685E-7,5.74584762150748E-5,4.06364398364141E-7,-1.85376641277017E-6,2.19545043767728E-7,1.00012996303923,10.005763053894,2,20,1,3,0.188513245148859,0.0105630792534483,0.0404026173055172,172.741912841797,51.5250282287598,51.5391502380371,640.423889160156,640.423889160156,,,67.0536117553711,0,1,,,,,,1,1,1,51.5334625244141,0,51.5313461303711,,,,,,,,,,,,,,,,,,,,,,,,,,,,,,,,,
,3754340113.59924,51.5142211914063,660.277404785156,,,5,,,,3.65000008605421,,,,,4.09118367644425E-5,4.95092522666006E-7,-2.59211485642506,0.00564082261862106,4.0906517675843E-5,4.95028153984438E-7,4.08646622604313E-5,4.37022149095758E-7,-1.85001802827532E-6,2.32517772303465E-7,1.00013003034484,10.005763053894,2,20,1,3,0.134225058229705,0.00577616563743586,0.0404026173055172,172.741912841797,51.5094718933105,51.515983581543,660.277404785156,660.277404785156,,,67.1033630371094,0,1,,,,,,1,1,1,51.5135650634766,0,51.5124691009521,,,,,,,,,,,,,,,,,,,,,,,,,,,,,,,,,
,3754340135.30316,51.5063304901123,680.313049316406,,,5,,,,3.65000008605421,,,,,3.21638155561616E-5,4.92444352184753E-7,-3.34346294904361,0.00632004857079208,3.21596306796393E-5,4.92380279599696E-7,3.21048905806158E-5,4.47244084341133E-7,-1.87559224179531E-6,2.05939478392407E-7,1.00013012825191,10.005763053894,2,20,1,3,0.105574694047853,0.00315918943001748,0.0404026173055172,172.741912841797,51.5038070678711,51.507640838623,680.313049316406,680.313049316406,,,67.1282348632813,0,1,,,,,,1,1,1,51.5057106018066,0,51.505260848999,,,,,,,,,,,,,,,,,,,,,,,,,,,,,,,,,
,3754340157.30928,51.5015163421631,700.433654785156,,,5,,,,3.65000008605421,,,,,2.68732547018705E-5,4.43380218452653E-7,-4.20164962184285,0.00590721025522793,2.68697610230606E-5,4.43322576455391E-7,2.67975449984953E-5,4.12598006361161E-7,-1.96866439242524E-6,1.6216593952443E-7,1.00013002269752,10.005763053894,2,20,1,3,0.0882385868260036,0.00131998177860927,0.0404026173055172,172.741912841797,51.5011138916016,51.5022010803223,700.433654785156,700.433654785156,,,67.1904220581055,0,1,,,,,,1,1,1,51.5012702941895,0,51.5014587402344,,,,,,,,,,,,,,,,,,,,,,,,,,,,,,,,,
,3754340179.00812,51.522388458252,720.250732421875,,,5,,,,3.65000008605421,,,,,2.44773059579436E-5,4.58102956923971E-7,-4.30376210638719,0.00940303528532385,2.44741200493074E-5,4.58043331319372E-7,2.44051081259515E-5,3.95035650883817E-7,-1.83664083275095E-6,2.31841600876433E-7,1.0001301745938,10.005763053894,2,20,1,3,0.0803735031142614,0.00106075476743664,0.0404026173055172,172.741912841797,51.5174789428711,51.5223960876465,720.250732421875,720.250732421875,,,67.2152938842773,0,1,,,,,,1,1,1,51.5223731994629,0,51.5206654866537,,,,,,,,,,,,,,,,,,,,,,,,,,,,,,,,,
,3754340203.44337,51.5505695343018,740.298461914062,,,5,,,,3.65000008605421,,,,,2.25974136984486E-5,5.13973248714041E-7,-5.29492655227148,0.010283849794158,2.25944718539584E-5,5.13906337102383E-7,2.24980583853879E-5,4.57052486961086E-7,-2.08507248003464E-6,2.34952649435316E-7,1.00013020195866,10.005763053894,2,20,1,3,0.0742065878486046,-0.000302813966848077,0.0404026173055172,172.741912841797,51.5434112548828,51.5509796142578,740.298461914062,740.298461914062,,,67.2774810791016,0,1,,,,,,1,1,1,51.5501556396484,0,51.5484199523926,,,,,,,,,,,,,,,,,,,,,,,,,,,,,,,,,
,3754340225.94254,51.5269412994385,760.382690429688,,,5,,,,3.65000008605421,,,,,2.10027547113358E-5,5.09303516568656E-7,-5.47910759424967,0.0100480835735484,2.1000026305186E-5,5.09237354445362E-7,2.09040788966609E-5,4.62039545946379E-7,-2.00514096778272E-6,2.14107779270569E-7,1.00012992393963,10.005763053894,2,20,1,3,0.0689687499403965,-0.000501670206553846,0.0404026173055172,172.741912841797,51.5194129943848,51.5297508239746,760.382690429688,760.382690429688,,,67.3147888183594,0,1,,,,,,1,1,1,51.5255317687988,0,51.5239438143643,,,,,,,,,,,,,,,,,,,,,,,,,,,,,,,,,
,3754340248.18023,51.5117683410645,780.406188964844,,,5,,,,3.65000008605421,,,,,2.05540692270616E-5,4.20113194475898E-7,-4.80364330888107,0.00751491171517972,2.05513968703974E-5,4.20058573063341E-7,2.04792108359399E-5,3.89354053896934E-7,-1.7209987977046E-6,1.57647155121917E-7,1.00013003284794,10.005763053894,2,20,1,3,0.0674964868861386,0.000306215437410944,0.0404026173055172,172.741912841797,51.5075721740723,51.5132598876953,780.406188964844,780.406188964844,,,67.3645401000977,0,1,,,,,,1,1,1,51.5110054016113,0,51.5101280212402,,,,,,,,,,,,,,,,,,,,,,,,,,,,,,,,,
,3754340271.16956,51.544095993042,800.283996582031,,,5,,,,3.65000008605421,,,,,1.81965037439048E-5,5.27371261709904E-7,-7.26530462918106,0.0132735747386557,1.81941339585281E-5,5.27302580565348E-7,1.80480569777578E-5,4.67658090569128E-7,-2.30090195976995E-6,2.43606079144409E-7,1.00013024996859,10.005763053894,2,20,1,3,0.0597111773553876,-0.00229440699152572,0.0404026173055172,172.741912841797,51.5382194519043,51.5450096130371,800.283996582031,800.283996582031,,,67.3894119262695,0,1,,,,,,1,1,1,51.5450096130371,0,51.5422512401234,,,,,,,,,,,,,,,,,,,,,,,,,,,,,,,,,