File: Experimental_Data/Supplementary_Fig1_Data/ZFC_49p5K.dat
[Header]
; MPMS3 Data File (default extension .dat)
; Copyright (c) 2007, Quantum Design, Inc. All rights reserved.
TITLE,ZFC_49p5K
FILEOPENTIME,3754343955.25457,12/19/2018,1:18 am
BYAPP,SQUID AC,0.9.1.0
INFO,MPMS3 Measurement Release 1.1.16 Build 347, MultiVu Release 2.3.3.2,APPNAME
INFO,0,MOMENT_UNITS
INFO,CoIINO3,SAMPLE_MATERIAL
INFO,40 Hours Pumped Turbo,SAMPLE_COMMENT
INFO,,SAMPLE_MASS
INFO,,SAMPLE_VOLUME
INFO,,SAMPLE_MOLECULAR_WEIGHT
INFO,,SAMPLE_SIZE
INFO,,SAMPLE_SHAPE
INFO,Brass,SAMPLE_HOLDER
INFO,Standard,SAMPLE_HOLDER_DETAIL
INFO,65.37,SAMPLE_OFFSET
DATATYPE,COMMENT,1
DATATYPE,TIME,2
STARTUPAXIS,X,2
STARTUPAXIS,Y1,5
FIELDGROUP, VSM,2,3,4,5,6,8,9,10,11,14,15
FIELDGROUP, DC, 2,3,4,14,56,57,58,59,60,61,62,63,64,65,66,67,68,69
FIELDGROUP, AC, 2,3,4,11,16,17,18,19,20,21,22,23,24,25,26,27,28,29,30
STARTUPGROUP, All
[Data]
Comment,Time Stamp (sec),Temperature (K),Magnetic Field (Oe),Moment (emu),M. Std. Err. (emu),Transport Action,Averaging Time (sec),Frequency (Hz),Peak Amplitude (mm),Center Position (mm),Lockin Signal' (V),Lockin Signal (V),Range,M. Quad. Signal (emu),AC Moment (emu),AC M. Std Err. (emu),AC Phase (deg),AC Phase Std. Err. (deg),AC Susceptibility (emu/Oe),AC Suscept. Std Err. (emu/Oe),AC X' (emu/Oe),AC X' Std Err. (emu/Oe),AC X'' (emu/Oe),AC X'' Std Err. (emu/Oe),AC Drive (Oe),AC Frequency (Hz),AC Averaging Time (sec),AC Cycles,AC Range,AC Measure Type,AC Signal' (V),AC Signal'' (V),AC Trim Coil Ratio,AC Trim Coil Phase,Min. Temperature (K),Max. Temperature (K),Min. Field (Oe),Max. Field (Oe),Mass (grams),Motor Lag (deg),Pressure (Torr),Measure Count,Measurement Number,SQUID Status (code),Motor Status (code),Measure Status (code),Motor Current (amps),Motor Temp. (C),Temp. Status (code),Field Status (code),Chamber Status (code),Chamber Temp (K),Redirection State,Average Temp (K),Rotation Angle (deg),Rotator state,DC Moment Fixed Ctr (emu),DC Moment Err Fixed Ctr (emu),DC Moment Free Ctr (emu),DC Moment Err Free Ctr (emu),DC Fixed Fit,DC Free Fit,DC Calculated Center (mm),DC Calculated Center Err (mm),DC Scan Length (mm),DC Scan Time (s),DC Number of Points,DC Squid Drift,DC Min V (V),DC Max V (V),DC Scans per Measure,Map 01,Map 02,Map 03,Map 04,Map 05,Map 06,Map 07,Map 08,Map 09,Map 10,Map 11,Map 12,Map 13,Map 14,Map 15,Map 16
,3754344092.75084,49.4607963562012,0.327855855226517,,,5,,,,3.65000008605421,,,,,0.000578605711259877,1.38058142751696E-8,-0.00041241335333897,1.03510371490735E-5,0.000578530549395365,1.38040208764495E-8,0.000578530549380378,1.24389345355554E-8,-4.16424605635465E-9,5.98530700780004E-9,1.0001299185749,10.005763053894,2,20,1,3,1.8927576859808,0.166115064192335,0.0404026173055172,172.741912841797,49.4253845214844,49.4716300964355,0.327855855226517,0.327855855226517,,,74.2173843383789,0,1,,,,,,1,1,1,49.4551086425781,0,49.4471806612882,,,,,,,,,,,,,,,,,,,,,,,,,,,,,,,,,
,3754344115.56844,49.4017429351807,20.047779083252,,,5,,,,3.65000008605421,,,,,0.000577927222850585,1.93810330340693E-8,-0.000766583181947667,1.85038047051629E-5,0.000577851987018115,1.9378509968713E-8,0.000577851986966395,1.61635438050743E-8,-7.73131317270531E-9,1.06895509853759E-8,1.00013019914123,10.005763053894,2,20,1,3,1.89053673415806,0.165948666332965,0.0404026173055172,172.741912841797,49.3960151672363,49.405200958252,20.047779083252,20.047779083252,,,74.2298202514648,0,1,,,,,,1,1,1,49.4004554748535,0,49.3992931365967,,,,,,,,,,,,,,,,,,,,,,,,,,,,,,,,,
,3754344137.23653,49.3962535858154,40.1562690734863,,,5,,,,3.65000008605421,,,,,0.000577416906960267,1.60712755317827E-8,-0.00198180712565854,1.87450371766962E-5,0.000577341551412093,1.6069178156796E-8,0.000577341551066727,1.18798187408453E-8,-1.99697012593719E-8,1.08207390375847E-8,1.0001305216089,10.005763053894,2,20,1,3,1.88886837541676,0.16580273185464,0.0404026173055172,172.741912841797,49.3953895568848,49.4018669128418,40.1562690734863,40.1562690734863,,,74.2671356201172,0,1,,,,,,1,1,1,49.3969192504883,0,49.3978588104248,,,,,,,,,,,,,,,,,,,,,,,,,,,,,,,,,
,3754344159.11625,49.4143180847168,60.1676177978516,,,5,,,,3.65000008605421,,,,,0.000577451399086639,1.72424353928579E-8,-0.00115028805420891,2.49216906696959E-5,0.000577376025428952,1.72401847698183E-8,0.000577376025312594,9.49721082248768E-9,-1.15915823196242E-8,1.43884313770021E-8,1.0001305451809,10.005763053894,2,20,1,3,1.8889763071848,0.165880443469313,0.0404026173055172,172.741912841797,49.410587310791,49.4297142028809,60.1676177978516,60.1676177978516,,,74.304443359375,0,1,,,,,,1,1,1,49.4163055419922,0,49.4193649291992,,,,,,,,,,,,,,,,,,,,,,,,,,,,,,,,,
,3754344180.74917,49.4411163330078,80.0696868896484,,,5,,,,3.65000008605421,,,,,0.000582113292474874,1.30852126037888E-8,0.00605178243175875,1.3732477149814E-5,0.000582037331070551,1.3083505082009E-8,0.000582037327823851,1.03595231207207E-8,6.14768368313553E-8,7.99114421983532E-9,1.00013050950561,10.005763053894,2,20,1,3,1.90420289362563,0.167499470424888,0.0404026173055172,172.741912841797,49.4401245117188,49.4448852539063,80.0696868896484,80.0696868896484,,,74.3790664672852,0,1,,,,,,1,1,1,49.4413223266602,0,49.4419498443604,,,,,,,,,,,,,,,,,,,,,,,,,,,,,,,,,
,3754344202.66846,49.4609279632568,100.129608154297,,,5,,,,3.65000008605421,,,,,0.000596270029388001,2.00003426236904E-8,0.0171594645892696,1.68041462394901E-5,0.000596192158921418,1.99977306594206E-8,0.000596192132184061,1.73096100466474E-8,1.78553083201242E-7,1.0014321322972E-8,1.00013061303376,10.005763053894,2,20,1,3,1.9504763681842,0.171992923132965,0.0404026173055172,172.741912841797,49.4568710327148,49.4670906066895,100.129608154297,100.129608154297,,,74.4536895751953,0,1,,,,,,1,1,1,49.461986541748,0,49.4626087188721,,,,,,,,,,,,,,,,,,,,,,,,,,,,,,,,,
,3754344224.24719,49.4861297607422,120.140960693359,,,5,,,,3.65000008605421,,,,,0.000618271261567303,2.41470158573875E-8,0.0458431500888796,2.56255155782562E-5,0.000618190514122414,2.41438622095417E-8,0.000618190316245122,1.82227553986291E-8,4.94622775700116E-7,1.5838474297579E-8,1.00013061902932,10.005763053894,2,20,1,3,2.02235300310315,0.179394822412783,0.0404026173055172,172.741912841797,49.4822120666504,49.498291015625,120.140960693359,120.140960693359,,,74.5531845092773,0,1,,,,,,1,1,1,49.4880676269531,0,49.4903930664062,,,,,,,,,,,,,,,,,,,,,,,,,,,,,,,,,
,3754344246.14573,49.5044536590576,140.164443969727,,,5,,,,3.65000008605421,,,,,0.000652346910543151,6.71190430378895E-8,0.0950842451307414,6.50196434072795E-5,0.000652261839301003,6.71102901791409E-8,0.000652260941120266,5.20208515941246E-8,1.08244964423163E-6,4.23983731686791E-8,1.00013042498736,10.005763053894,2,20,1,3,2.13364741217363,0.191161498779632,0.0404026173055172,172.741912841797,49.5035438537598,49.5052146911621,140.164443969727,140.164443969727,,,74.6278076171875,0,1,,,,,,1,1,1,49.5039863586426,0,49.5043254852295,,,,,,,,,,,,,,,,,,,,,,,,,,,,,,,,,
,3754344270.26911,49.5167274475098,160.078659057617,,,5,,,,3.65000008605421,,,,,0.000691679630241004,2.85841752239404E-8,0.0943165575445981,1.55871741853235E-5,0.000691589437978965,2.85804479616224E-8,0.000691588500958933,2.64762192838436E-8,1.13844869761565E-6,1.07634482449089E-8,1.00013041301253,10.005763053894,2,20,10,3,2.26229358080738,0.202705284001464,0.0404026173055172,172.741912841797,49.5093307495117,49.5174026489258,160.078659057617,160.078659057617,,,74.7148666381836,0,1,,,,,,1,1,1,49.51611328125,0,49.513738155365,,,,,,,,,,,,,,,,,,,,,,,,,,,,,,,,,
,3754344297.34826,49.5417671203613,180.077865600586,,,5,,,,3.65000008605421,,,,,0.000721913165806625,9.78810725583798E-8,0.0822719668721561,7.15855199959325E-5,0.000721818949434083,9.78682981693898E-8,0.000721818205290563,8.31330381071371E-8,1.03647153058788E-6,5.1643990566666E-8,1.00013052632189,10.005763053894,2,20,10,3,2.36122037890586,0.211119665675647,0.0404026173055172,172.741912841797,49.5383110046387,49.5423851013184,180.077865600586,180.077865600586,,,74.8143692016602,0,1,,,,,,1,1,1,49.5422744750977,0,49.5408897399902,,,,,,,,,,,,,,,,,,,,,,,,,,,,,,,,,
,3754344319.03762,49.5379390716553,200.18635559082,,,5,,,,3.65000008605421,,,,,0.00074028871348518,1.18589196479626E-7,0.0451202029721287,5.3497321005926E-5,0.000740192228593668,1.185737402589E-7,0.000740191999078535,1.11787203687145E-7,5.8289843378411E-7,3.95392586019751E-8,1.00013035112743,10.005763053894,2,20,10,3,2.42145938234858,0.214975553064229,0.0404026173055172,172.741912841797,49.529052734375,49.5396537780762,200.18635559082,200.18635559082,,,74.8765487670898,0,1,,,,,,1,1,1,49.5366859436035,0,49.5347537994385,,,,,,,,,,,,,,,,,,,,,,,,,,,,,,,,,
,3754344340.99409,49.5177669525146,220.06413269043,,,5,,,,3.65000008605421,,,,,0.000750210544400816,8.21582595385039E-8,0.00946436789148919,3.62286397274649E-5,0.000750112856372864,8.21475613706173E-8,0.000750112846139119,7.75327937027702E-8,1.23906927541535E-7,2.71456762631364E-8,1.00013023110739,10.005763053894,2,20,10,3,2.45404520432008,0.216381947075209,0.0404026173055172,172.741912841797,49.5117645263672,49.5201988220215,220.06413269043,220.06413269043,,,74.9387359619141,0,1,,,,,,1,1,1,49.516658782959,0,49.5155559539795,,,,,,,,,,,,,,,,,,,,,,,,,,,,,,,,,
,3754344362.59433,49.5409469604492,240.063339233398,,,5,,,,3.65000008605421,,,,,0.00075646211573037,1.05809832868396E-7,-0.00583429298253879,3.6129051305725E-5,0.000756363418785732,1.05796027673133E-7,0.000756363414864417,1.02217424868422E-7,-7.7018688223572E-8,2.72836494018457E-8,1.00013048878646,10.005763053894,2,20,10,3,2.47454988293489,0.217577211336513,0.0404026173055172,172.741912841797,49.5349464416504,49.541145324707,240.063339233398,240.063339233398,,,75.0133590698242,0,1,,,,,,1,1,1,49.541145324707,0,49.5390628814697,,,,,,,,,,,,,,,,,,,,,,,,,,,,,,,,,
,3754344384.50093,49.5450401306152,260.147521972656,,,5,,,,3.65000008605421,,,,,0.000760817657225383,9.16541240529545E-8,-0.0120818714990234,3.38315586509652E-5,0.000760718511340023,9.16421801539271E-8,0.000760718494427159,8.79632347679512E-8,-1.60411522644996E-7,2.57052234482238E-8,1.00013033189528,10.005763053894,2,20,10,3,2.48881833545441,0.218612073599379,0.0404026173055172,172.741912841797,49.5360221862793,49.5456161499023,260.147521972656,260.147521972656,,,75.0506744384766,0,1,,,,,,1,1,1,49.5446395874023,0,49.5420356750488,,,,,,,,,,,,,,,,,,,,,,,,,,,,,,,,,
,3754344406.1203,49.5437316894531,280.073883056641,,,5,,,,3.65000008605421,,,,,0.000763996146707347,1.1575285745079E-7,-0.0178440238119775,5.09425230271991E-5,0.00076389654471732,1.1573776677919E-7,0.000763896507671017,1.0900983800923E-7,-2.37905619389629E-7,3.88855484240052E-8,1.00013038675291,10.005763053894,2,20,10,3,2.49923471669095,0.219327338744256,0.0404026173055172,172.741912841797,49.534294128418,49.5449867248535,280.073883056641,280.073883056641,,,75.1128540039063,0,1,,,,,,1,1,1,49.5428581237793,0,49.5405300140381,,,,,,,,,,,,,,,,,,,,,,,,,,,,,,,,,
,3754344428.04528,49.5493621826172,300.073089599609,,,5,,,,3.65000008605421,,,,,0.000766387098356561,1.1024668980459E-7,-0.026308589774735,3.82100170339986E-5,0.000766287250960149,1.10232326508334E-7,0.000766287170178732,1.06281236549575E-7,-3.51857264148083E-7,2.92483258483842E-8,1.00013030021873,10.005763053894,2,20,10,3,2.50708532897281,0.219696988253737,0.0404026173055172,172.741912841797,49.538948059082,49.5503807067871,300.073089599609,300.073089599609,,,75.1750411987305,0,1,,,,,,1,1,1,49.5483245849609,0,49.5459823608398,,,,,,,,,,,,,,,,,,,,,,,,,,,,,,,,,
,3754344449.6757,49.5581951141357,320.023742675781,,,5,,,,3.65000008605421,,,,,0.000768459331058788,1.06331548679172E-7,-0.029852591860771,4.50937168336319E-5,0.000768359167567903,1.06317689078961E-7,0.000768359063275399,1.0052133205944E-7,-4.00335099531172E-7,3.46253203896589E-8,1.00013036024702,10.005763053894,2,20,10,3,2.51387455335712,0.220189168330182,0.0404026173055172,172.741912841797,49.548210144043,49.5586776733398,320.023742675781,320.023742675781,,,75.2247924804687,0,1,,,,,,1,1,1,49.5577278137207,0,49.5549152374268,,,,,,,,,,,,,,,,,,,,,,,,,,,,,,,,,
,3754344471.56805,49.5674362182617,340.095825195313,,,5,,,,3.65000008605421,,,,,0.000770413563726244,1.28801727120788E-7,-0.0362682192106893,5.15738606378179E-5,0.000770313261640287,1.2878495809891E-7,0.000770313107312345,1.22512453526952E-7,-4.87608138082121E-7,3.970219343241E-8,1.00013020947574,10.005763053894,2,20,10,3,2.52028884672827,0.220521024198791,0.0404026173055172,172.741912841797,49.5488395690918,49.5704727172852,340.095825195313,340.095825195313,,,75.2745361328125,0,1,,,,,,1,1,1,49.5652275085449,0,49.5608898162842,,,,,,,,,,,,,,,,,,,,,,,,,,,,,,,,,
,3754344492.97705,49.5305938720703,360.131439208984,,,5,,,,3.65000008605421,,,,,0.000772638830516908,1.53711055812297E-7,-0.0412576124250981,0.000119216371945133,0.000772538211705236,1.5369103840809E-7,0.000772538011418184,1.23050348588095E-7,-5.562901777151E-7,9.20844557963241E-8,1.00013024444635,10.005763053894,2,20,10,3,2.52758437046154,0.220992229574227,0.0404026173055172,172.741912841797,49.5216178894043,49.5346603393555,360.131439208984,360.131439208984,,,75.3367233276367,0,1,,,,,,1,1,1,49.5289764404297,0,49.5275976007635,,,,,,,,,,,,,,,,,,,,,,,,,,,,,,,,,
,3754344515.19445,49.5152587890625,380.057800292969,,,5,,,,3.65000008605421,,,,,0.00077436038837342,1.61276608444823E-7,-0.0491872716071375,7.43989453127463E-5,0.00077425946690547,1.61255589456359E-7,0.000774259181595661,1.50623779247723E-7,-6.64686061326921E-7,5.75833505108114E-8,1.00013034579784,10.005763053894,2,20,10,3,2.53324352886008,0.221188127000063,0.0404026173055172,172.741912841797,49.5099754333496,49.5171966552734,380.057800292969,380.057800292969,,,75.386474609375,0,1,,,,,,1,1,1,49.5140991210937,0,49.5134033203125,,,,,,,,,,,,,,,,,,,,,,,,,,,,,,,,,
,3754344536.74651,49.536340713501,400.020568847656,,,5,,,,3.65000008605421,,,,,0.000775592600340424,2.13236095180267E-7,-0.0682813226903161,0.000121757970683471,0.000775491392931319,2.1320826991129E-7,0.000775490842243436,1.91167059436636E-7,-9.24179162242064E-7,9.44082715916116E-8,1.00013050745634,10.005763053894,2,20,10,3,2.53734498073218,0.220748636949747,0.0404026173055172,172.741912841797,49.5315361022949,49.5368423461914,400.020568847656,400.020568847656,,,75.4362182617187,0,1,,,,,,1,1,1,49.5368576049805,0,49.5349605560303,,,,,,,,,,,,,,,,,,,,,,,,,,,,,,,,,
,3754344558.64905,49.5211658477783,420.104766845703,,,5,,,,3.65000008605421,,,,,0.000777152850786782,2.18198907309E-7,-0.0817590973140652,0.000122872477392776,0.000777051622778591,2.18170485820546E-7,0.000777050831650668,1.96172597028926E-7,-1.10882543573152E-6,9.54707968862701E-8,1.00013027192174,10.005763053894,2,20,10,3,2.54249796218694,0.220649367409684,0.0404026173055172,172.741912841797,49.514533996582,49.5232429504395,420.104766845703,420.104766845703,,,75.4735336303711,0,1,,,,,,1,1,1,49.5200462341309,0,49.5189331054687,,,,,,,,,,,,,,,,,,,,,,,,,,,,,,,,,
,3754344580.02267,49.538782119751,439.994659423828,,,5,,,,3.65000008605421,,,,,0.000778443102366046,3.01021586631593E-7,-0.0838546477858681,0.000163618431093118,0.000778341525333323,3.00982307101127E-7,0.000778340691749762,2.72716121390285E-7,-1.13913331345959E-6,1.27343104727961E-7,1.00013050445006,10.005763053894,2,20,10,3,2.54672388708461,0.220976681076822,0.0404026173055172,172.741912841797,49.5324630737305,49.5388793945313,439.994659423828,439.994659423828,,,75.5232772827148,0,1,,,,,,1,1,1,49.5386695861816,0,49.5367081382058,,,,,,,,,,,,,,,,,,,,,,,,,,,,,,,,,
,3754344602.22623,49.5203704833984,460.321746826172,,,5,,,,3.65000008605421,,,,,0.000779449866371625,2.89653119514606E-7,-0.0964097695231194,0.000184213786870107,0.000779348367530884,2.89615401301907E-7,0.000779347264218847,2.51530062736033E-7,-1.31138386934811E-6,1.435608171169E-7,1.00013023552107,10.005763053894,2,20,10,3,2.55006263423424,0.220759247953208,0.0404026173055172,172.741912841797,49.5133438110352,49.5239562988281,460.321746826172,460.321746826172,,,75.5730285644531,0,1,,,,,,1,1,1,49.5186614990234,0,49.5180160522461,,,,,,,,,,,,,,,,,,,,,,,,,,,,,,,,,
,3754344623.88231,49.5131702423096,480.345245361328,,,5,,,,3.65000008605421,,,,,0.000779555452440433,3.20917646717347E-7,-0.108880048616586,0.00016097202261645,0.000779453838977443,3.20875815756746E-7,0.000779452431596645,2.9532051362251E-7,-1.48120719405347E-6,1.25487383315193E-7,1.00013036495288,10.005763053894,2,20,10,3,2.55045276505987,0.220288739496611,0.0404026173055172,172.741912841797,49.5095596313477,49.5145149230957,480.345245361328,480.345245361328,,,75.6600875854492,0,1,,,,,,1,1,1,49.5124473571777,0,49.511722946167,,,,,,,,,,,,,,,,,,,,,,,,,,,,,,,,,
,3754344645.75647,49.5060176849365,500.356597900391,,,5,,,,3.65000008605421,,,,,0.000779224746085707,3.58029829334273E-7,-0.111769902312005,0.000189959810891228,0.000779123162584189,3.57983154836454E-7,0.000779121680132804,3.25948176614322E-7,-1.51987572697246E-6,1.48019340994544E-7,1.00013038182716,10.005763053894,2,20,10,3,2.54937860850834,0.220121330304606,0.0404026173055172,172.741912841797,49.5043983459473,49.5065879821777,500.356597900391,500.356597900391,,,75.6725234985352,0,1,,,,,,1,1,1,49.5060195922852,0,49.5056480407715,,,,,,,,,,,,,,,,,,,,,,,,,,,,,,,,,
,3754344667.36737,49.5456314086914,520.222229003906,,,5,,,,3.65000008605421,,,,,0.000777831573692298,3.24244944613024E-7,-0.117618511196368,0.000195514575286886,0.00077773010037205,3.24202644695901E-7,0.000777728461651687,2.86326585413371E-7,-1.59654677967191E-6,1.52067226295925E-7,1.00013047369544,10.005763053894,2,20,10,3,2.5448397587252,0.219521935812787,0.0404026173055172,172.741912841797,49.5402069091797,49.5459938049316,520.222229003906,520.222229003906,,,75.7222747802734,0,1,,,,,,1,1,1,49.5460014343262,0,49.5440235137939,,,,,,,,,,,,,,,,,,,,,,,,,,,,,,,,,
,3754344689.37405,49.5297527313232,540.282165527344,,,5,,,,3.65000008605421,,,,,0.000775153625884907,3.79509906779433E-7,-0.129980386322462,0.000209899535670451,0.000775052620492347,3.79460455230947E-7,0.000775050626096372,3.42803370870578E-7,-1.7582717868081E-6,1.62714738127335E-7,1.00013032069035,10.005763053894,2,20,10,3,2.53612215432772,0.218273500952559,0.0404026173055172,172.741912841797,49.5212821960449,49.5319328308105,540.282165527344,540.282165527344,,,75.7595825195313,0,1,,,,,,1,1,1,49.5287399291992,0,49.5268592834473,,,,,,,,,,,,,,,,,,,,,,,,,,,,,,,,,
,3754344711.12784,49.5345897674561,560.354187011719,,,5,,,,3.65000008605421,,,,,0.000768963840972672,3.44557928616386E-7,-0.138468784310309,0.000232079326695452,0.000768863560157129,3.44512994708909E-7,0.000768861314840644,2.94694885631526E-7,-1.85813858795149E-6,1.78449230611742E-7,1.00013042732253,10.005763053894,2,20,10,3,2.51589943538082,0.216211826382699,0.0404026173055172,172.741912841797,49.5273742675781,49.5349960327148,560.354187011719,560.354187011719,,,75.8217697143555,0,1,,,,,,1,1,1,49.5341835021973,0,49.5319660186768,,,,,,,,,,,,,,,,,,,,,,,,,,,,,,,,,
,3754344732.91143,49.5501842498779,580.438415527344,,,5,,,,3.65000008605421,,,,,0.000756219532790041,3.74797929208777E-7,-0.150881276487258,0.000214266078718417,0.000756120894867612,3.74749042228919E-7,0.000756118273146886,3.37895762190341E-7,-1.99114760126518E-6,1.62059552465446E-7,1.00013045258119,10.005763053894,2,20,10,3,2.47424538499566,0.212145572999851,0.0404026173055172,172.741912841797,49.5418815612793,49.5504264831543,580.438415527344,580.438415527344,,,75.8715209960937,0,1,,,,,,1,1,1,49.5499420166016,0,49.5479835510254,,,,,,,,,,,,,,,,,,,,,,,,,,,,,,,,,
,3754344754.5593,49.5331363677978,600.352600097656,,,5,,,,3.65000008605421,,,,,0.000728534586084383,3.88619603145602E-7,-0.162060268986508,0.000240058105860784,0.000728439709677466,3.88568993562601E-7,0.000728436795800749,3.46970619759823E-7,-2.06037824925492E-6,1.74920701409917E-7,1.00013024606657,10.005763053894,2,20,10,3,2.3837008805851,0.203964789237614,0.0404026173055172,172.741912841797,49.5244407653809,49.535945892334,600.352600097656,600.352600097656,,,75.9212646484375,0,1,,,,,,1,1,1,49.5315742492676,0,49.5300556182861,,,,,,,,,,,,,,,,,,,,,,,,,,,,,,,,,
,3754344776.49533,49.5149536132812,620.351867675781,,,5,,,,3.65000008605421,,,,,0.000642640790025122,3.20935918989457E-7,-0.189261459688542,0.000227276884362316,0.000642557044388907,3.20894096274284E-7,0.000642553538804695,2.85706617934979E-7,-2.12251345614425E-6,1.46098423988233E-7,1.00013033183115,10.005763053894,2,20,10,3,2.10274647332329,0.178964270358114,0.0404026173055172,172.741912841797,49.5080718994141,49.517650604248,620.351867675781,620.351867675781,,,75.9710159301758,0,1,,,,,,1,1,1,49.5136032104492,0,49.5123523365368,,,,,,,,,,,,,,,,,,,,,,,,,,,,,,,,,
,3754344802.6617,49.5039978027344,640.448181152344,,,5,,,,3.65000008605421,,,,,0.000387025409723126,1.89069341281642E-7,-0.270234700411399,0.000364704936021807,0.000386974990989502,1.89044710762521E-7,0.000386970686822993,1.2580225261888E-7,-1.82515508006784E-6,1.41108808737444E-7,1.0001302893851,10.005763053894,2,20,1,3,1.26651216558354,0.106017302793618,0.0404026173055172,172.741912841797,49.5027389526367,49.5055236816406,640.448181152344,640.448181152344,,,76.0207672119141,0,1,,,,,,1,1,1,49.5038299560547,0,49.5038425738995,,,,,,,,,,,,,,,,,,,,,,,,,,,,,,,,,
,3754344825.14844,49.5029258728027,660.325988769531,,,5,,,,3.65000008605421,,,,,0.000153338618886715,4.48659752325902E-7,-0.764948865938365,0.00144627570537997,0.000153318633026098,4.48601274876843E-7,0.000153304969020311,3.89702045857349E-7,-2.04687729790775E-6,2.22205803874979E-7,1.00013035506659,10.005763053894,2,20,1,3,0.502132787803969,0.0376803459288977,0.0404026173055172,172.741912841797,49.5020332336426,49.5038681030273,660.325988769531,660.325988769531,,,76.0829544067383,0,1,,,,,,1,1,1,49.5023231506348,0,49.5025375366211,,,,,,,,,,,,,,,,,,,,,,,,,,,,,,,,,
,3754344846.7718,49.5101146697998,680.300903320312,,,5,,,,3.65000008605421,,,,,7.94913409624607E-5,4.50808459270102E-7,-1.49727626612206,0.00253879560867054,7.94809723047672E-5,4.50749656908198E-7,7.9453834977224E-5,4.02476125236049E-7,-2.07679221956065E-6,2.02948815758641E-7,1.00013045459049,10.005763053894,2,20,1,3,0.260535803719473,0.016210568460739,0.0404026173055172,172.741912841797,49.5085983276367,49.5105476379395,680.300903320312,680.300903320312,,,76.1202621459961,0,1,,,,,,1,1,1,49.5105476379395,0,49.5095798492432,,,,,,,,,,,,,,,,,,,,,,,,,,,,,,,,,
,3754344868.71432,49.5464553833008,700.348693847656,,,5,,,,3.65000008605421,,,,,4.8532494003947E-5,5.04797346646988E-7,-2.53181561923158,0.00480303851863234,4.85261607865018E-5,5.04731473433017E-7,4.84787917934344E-5,4.46742075672952E-7,-2.14360139164479E-6,2.34894397756282E-7,1.00013051140545,10.005763053894,2,20,1,3,0.159219744217909,0.00702698188860392,0.0404026173055172,172.741912841797,49.5417213439941,49.5472373962402,700.348693847656,700.348693847656,,,76.1700134277344,0,1,,,,,,1,1,1,49.5472373962402,0,49.5452266693115,,,,,,,,,,,,,,,,,,,,,,,,,,,,,,,,,
,3754344890.33517,49.5516090393066,720.29931640625,,,5,,,,3.65000008605421,,,,,3.52860349268066E-5,5.36636667521788E-7,-3.68804335219837,0.00740016907525524,3.52814381679046E-5,5.36566759146317E-7,3.52083725438534E-5,4.67593256946044E-7,-2.26944530863953E-6,2.63173769740398E-7,1.00013028830855,10.005763053894,2,20,1,3,0.115841834553717,0.00277454342864444,0.0404026173055172,172.741912841797,49.5407180786133,49.5540580749512,720.29931640625,720.29931640625,,,76.2073211669922,0,1,,,,,,1,1,1,49.5501174926758,0,49.5478038787842,,,,,,,,,,,,,,,,,,,,,,,,,,,,,,,,,
,3754344912.21571,49.5547943115234,740.249938964844,,,5,,,,3.65000008605421,,,,,2.72538431415026E-5,5.09297624632803E-7,-4.85954993520712,0.00831728398294187,2.72502919012885E-5,5.09231261947873E-7,2.71523366697361E-5,4.54675969098784E-7,-2.3084674740471E-6,2.29316901403068E-7,1.00013031934582,10.005763053894,2,20,1,3,0.0894978079716886,0.000315141630759755,0.0404026173055172,172.741912841797,49.5442543029785,49.5558662414551,740.249938964844,740.249938964844,,,76.2695083618164,0,1,,,,,,1,1,1,49.5537490844727,0,49.5514808654785,,,,,,,,,,,,,,,,,,,,,,,,,,,,,,,,,
,3754344933.87089,49.5262794494629,760.334167480469,,,5,,,,3.65000008605421,,,,,2.26225081458229E-5,4.81962678983159E-7,-6.06200657852953,0.0100716976964174,2.26195639442008E-5,4.81899954050446E-7,2.24930796474751E-5,4.23515431032337E-7,-2.38873209007008E-6,2.29917910114276E-7,1.00013016173209,10.005763053894,2,20,1,3,0.074278350786106,-0.00129585218841981,0.0404026173055172,172.741912841797,49.5167961120605,49.5291976928711,760.334167480469,760.334167480469,,,76.3068161010742,0,1,,,,,,1,1,1,49.5245742797852,0,49.5225028991699,,,,,,,,,,,,,,,,,,,,,,,,,,,,,,,,,
,3754344955.84873,49.5188121795654,780.369750976563,,,5,,,,3.65000008605421,,,,,2.00248092985789E-5,4.94678001504988E-7,-6.91328137807425,0.00978266050146221,2.00222008274129E-5,4.94613563772566E-7,1.98766287572631E-5,4.52926771785459E-7,-2.41001145623711E-6,1.98745860001663E-7,1.00013027894328,10.005763053894,2,20,1,3,0.0657248947328403,-0.00212235422271261,0.0404026173055172,172.741912841797,49.510814666748,49.5218696594238,780.369750976563,780.369750976563,,,76.3690032958984,0,1,,,,,,1,1,1,49.5171890258789,0,49.515714263916,,,,,,,,,,,,,,,,,,,,,,,,,,,,,,,,,
,3754344977.45303,49.5195426940918,800.405395507812,,,5,,,,3.65000008605421,,,,,1.76475405653522E-5,5.99772340554535E-7,-7.48046292486221,0.0153859306129563,1.76452391477055E-5,5.99694124179657E-7,1.74950660116264E-5,5.33525017242825E-7,-2.29720043282094E-6,2.73832245273725E-7,1.00013042711563,10.005763053894,2,20,1,3,0.0579010179682328,-0.00244244170031695,0.0404026173055172,172.741912841797,49.5184707641602,49.5203819274902,800.405395507812,800.405395507812,,,76.3938751220703,0,1,,,,,,1,1,1,49.5193252563477,0,49.5196285247803,,,,,,,,,,,,,,,,,,,,,,,,,,,,,,,,,