File: Experimental_Data/Supplementary_Fig1_Data/ZFC_53p5K.dat
[Header]
; MPMS3 Data File (default extension .dat)
; Copyright (c) 2007, Quantum Design, Inc. All rights reserved.
TITLE,ZFC_53p5K
FILEOPENTIME,3754334574.42651,12/18/2018,10:42 pm
BYAPP,SQUID AC,0.9.1.0
INFO,MPMS3 Measurement Release 1.1.16 Build 347, MultiVu Release 2.3.3.2,APPNAME
INFO,0,MOMENT_UNITS
INFO,CoIINO3,SAMPLE_MATERIAL
INFO,40 Hours Pumped Turbo,SAMPLE_COMMENT
INFO,,SAMPLE_MASS
INFO,,SAMPLE_VOLUME
INFO,,SAMPLE_MOLECULAR_WEIGHT
INFO,,SAMPLE_SIZE
INFO,,SAMPLE_SHAPE
INFO,Brass,SAMPLE_HOLDER
INFO,Standard,SAMPLE_HOLDER_DETAIL
INFO,65.37,SAMPLE_OFFSET
DATATYPE,COMMENT,1
DATATYPE,TIME,2
STARTUPAXIS,X,2
STARTUPAXIS,Y1,5
FIELDGROUP, VSM,2,3,4,5,6,8,9,10,11,14,15
FIELDGROUP, DC, 2,3,4,14,56,57,58,59,60,61,62,63,64,65,66,67,68,69
FIELDGROUP, AC, 2,3,4,11,16,17,18,19,20,21,22,23,24,25,26,27,28,29,30
STARTUPGROUP, All
[Data]
Comment,Time Stamp (sec),Temperature (K),Magnetic Field (Oe),Moment (emu),M. Std. Err. (emu),Transport Action,Averaging Time (sec),Frequency (Hz),Peak Amplitude (mm),Center Position (mm),Lockin Signal' (V),Lockin Signal (V),Range,M. Quad. Signal (emu),AC Moment (emu),AC M. Std Err. (emu),AC Phase (deg),AC Phase Std. Err. (deg),AC Susceptibility (emu/Oe),AC Suscept. Std Err. (emu/Oe),AC X' (emu/Oe),AC X' Std Err. (emu/Oe),AC X'' (emu/Oe),AC X'' Std Err. (emu/Oe),AC Drive (Oe),AC Frequency (Hz),AC Averaging Time (sec),AC Cycles,AC Range,AC Measure Type,AC Signal' (V),AC Signal'' (V),AC Trim Coil Ratio,AC Trim Coil Phase,Min. Temperature (K),Max. Temperature (K),Min. Field (Oe),Max. Field (Oe),Mass (grams),Motor Lag (deg),Pressure (Torr),Measure Count,Measurement Number,SQUID Status (code),Motor Status (code),Measure Status (code),Motor Current (amps),Motor Temp. (C),Temp. Status (code),Field Status (code),Chamber Status (code),Chamber Temp (K),Redirection State,Average Temp (K),Rotation Angle (deg),Rotator state,DC Moment Fixed Ctr (emu),DC Moment Err Fixed Ctr (emu),DC Moment Free Ctr (emu),DC Moment Err Free Ctr (emu),DC Fixed Fit,DC Free Fit,DC Calculated Center (mm),DC Calculated Center Err (mm),DC Scan Length (mm),DC Scan Time (s),DC Number of Points,DC Squid Drift,DC Min V (V),DC Max V (V),DC Scans per Measure,Map 01,Map 02,Map 03,Map 04,Map 05,Map 06,Map 07,Map 08,Map 09,Map 10,Map 11,Map 12,Map 13,Map 14,Map 15,Map 16
,3754334704.19642,53.4799308776855,0.0364284291863441,,,5,,,,3.65000008605421,,,,,0.000558758281794349,1.91676703023871E-8,0.00173082062120145,9.30533148923278E-6,0.000558685901992225,1.91651873822607E-8,0.000558685901737309,1.84488694450278E-8,1.68770734600933E-8,5.19072476610794E-9,1.00012955365773,10.005763053894,2,20,1,3,1.82782700826687,0.160473834812159,0.0404026173055172,172.741912841797,53.4522399902344,53.485969543457,0.0364284291863441,0.0364284291863441,,,57.0541725158691,0,1,,,,,,1,1,1,53.4768714904785,0,53.4703199213201,,,,,,,,,,,,,,,,,,,,,,,,,,,,,,,,,
,3754334726.94412,53.4178829193115,19.9263496398926,,,5,,,,3.65000008605421,,,,,0.000553966952695424,2.00002843826205E-8,-0.000879306399611757,1.24406878048694E-5,0.000553895177026924,1.9997693011827E-8,0.000553895176961696,1.87751919485821E-8,-8.50051396444543E-9,6.88475802691526E-9,1.00012958348705,10.005763053894,2,20,1,3,1.81215831918079,0.159053943326307,0.0404026173055172,172.741912841797,53.4049797058105,53.4229850769043,19.9263496398926,19.9263496398926,,,57.0914878845215,0,1,,,,,,1,1,1,53.4153900146484,0,53.4131126403809,,,,,,,,,,,,,,,,,,,,,,,,,,,,,,,,,
,3754334748.59952,53.396427154541,39.961986541748,,,5,,,,3.65000008605421,,,,,0.00055341239001558,1.71214972644659E-8,-1.67624800733179E-5,1.19965698670857E-5,0.000553340530958201,1.7119274085736E-8,0.000553340530958178,1.57817560387886E-8,-1.61885564744399E-10,6.63368084510496E-9,1.00012986407711,10.005763053894,2,20,1,3,1.81033941804408,0.158960835278517,0.0404026173055172,172.741912841797,53.3960914611816,53.3984603881836,39.961986541748,39.961986541748,,,57.1412315368652,0,1,,,,,,1,1,1,53.3963851928711,0,53.396626663208,,,,,,,,,,,,,,,,,,,,,,,,,,,,,,,,,
,3754334770.51825,53.4156684875488,59.9976196289063,,,5,,,,3.65000008605421,,,,,0.000559285972329002,8.31200639395389E-9,0.0205260530385436,1.01439291073081E-5,0.00055921317914698,8.3109245549228E-9,0.000559213143261974,6.07471281699282E-9,2.00336555799486E-7,5.67180140243662E-9,1.00013017071975,10.005763053894,2,20,1,3,1.82949310900508,0.161343085499438,0.0404026173055172,172.741912841797,53.4101486206055,53.4322128295898,59.9976196289063,59.9976196289063,,,57.1909828186035,0,1,,,,,,1,1,1,53.4181900024414,0,53.4210334777832,,,,,,,,,,,,,,,,,,,,,,,,,,,,,,,,,
,3754334792.31121,53.4395847320557,79.8754043579102,,,5,,,,3.65000008605421,,,,,0.000580333643047699,4.24800052752339E-8,0.0946140786903831,6.94211155073239E-5,0.000580258274487629,4.24744883508444E-8,0.000580257483340033,1.34553569624661E-8,9.58195831498323E-7,4.02869151174253E-8,1.00012988795401,10.005763053894,2,20,1,3,1.89812199889745,0.169909825640995,0.0404026173055172,172.741912841797,53.4385032653809,53.4422798156738,79.8754043579102,79.8754043579102,,,57.2531700134277,0,1,,,,,,1,1,1,53.4400405883789,0,53.4401664733887,,,,,,,,,,,,,,,,,,,,,,,,,,,,,,,,,
,3754334817.22704,53.454029083252,100.008171081543,,,5,,,,3.65000008605421,,,,,0.000624395955934456,5.01492398391671E-8,0.26430901119758,2.62721594697913E-5,0.00062431473892071,5.01427167804211E-8,0.000624308096115812,4.74087550508366E-8,2.87999268831051E-6,1.63310131544645E-8,1.00013008985482,10.005763053894,2,20,10,3,2.04168517208053,0.188902087819769,0.0404026173055172,172.741912841797,53.4496269226074,53.4640693664551,100.008171081543,100.008171081543,,,57.3402290344238,0,1,,,,,,1,1,1,53.4550514221191,0,53.4557819366455,,,,,,,,,,,,,,,,,,,,,,,,,,,,,,,,,
,3754334842.61884,53.5112113952637,120.031669616699,,,5,,,,3.65000008605421,,,,,0.000671388957754838,1.40778019091439E-7,0.239276736505301,0.000171138466780085,0.000671301566603486,1.40759694760913E-7,0.000671295712738219,8.13112208177381E-8,2.8034592169726E-6,1.14898986237105E-7,1.00013018165859,10.005763053894,2,20,10,3,2.19543098422248,0.202206883165486,0.0404026173055172,172.741912841797,53.5042839050293,53.5189247131348,120.031669616699,120.031669616699,,,57.4272880554199,0,1,,,,,,1,1,1,53.5137596130371,0,53.514350197532,,,,,,,,,,,,,,,,,,,,,,,,,,,,,,,,,
,3754334865.36992,53.5518836975098,140.140167236328,,,5,,,,3.65000008605421,,,,,0.000699550804198284,1.19859102310274E-7,0.188897763784012,0.000114829207274532,0.000699459890475932,1.19843525404232E-7,0.000699456089100225,8.89634761880678E-8,2.30603669123892E-6,8.02992558237614E-8,1.00012997703455,10.005763053894,2,20,10,3,2.28770093505009,0.208726258921682,0.0404026173055172,172.741912841797,53.5456771850586,53.5528297424316,140.140167236328,140.140167236328,,,57.4894752502441,0,1,,,,,,1,1,1,53.5524978637695,0,53.5504282171076,,,,,,,,,,,,,,,,,,,,,,,,,,,,,,,,,
,3754334887.01742,53.5796718597412,159.969375610352,,,5,,,,3.65000008605421,,,,,0.000710165507119939,7.99980970127693E-8,0.153158680204717,3.9914793899346E-5,0.00071007320741375,7.99876997169616E-8,0.000710070670470002,7.48236218829819E-8,1.89811093770072E-6,2.82746832753858E-8,1.00012998618343,10.005763053894,2,20,10,3,2.32254213403505,0.210493918108047,0.0404026173055172,172.741912841797,53.5724601745605,53.5802421569824,159.969375610352,159.969375610352,,,57.5516586303711,0,1,,,,,,1,1,1,53.5802421569824,0,53.5776878356934,,,,,,,,,,,,,,,,,,,,,,,,,,,,,,,,,
,3754334908.93376,53.5617637634277,179.932144165039,,,5,,,,3.65000008605421,,,,,0.000712572990409811,4.13723022570025E-8,0.0689235852336676,1.63526669516154E-5,0.000712480552785684,4.13669352877562E-8,0.000712480037280043,3.9701272391588E-8,8.5707363929908E-7,1.16203401667222E-8,1.0001297405575,10.005763053894,2,20,10,3,2.33072046990376,0.207830999484733,0.0404026173055172,172.741912841797,53.546947479248,53.5645179748535,179.932144165039,179.932144165039,,,57.6014060974121,0,1,,,,,,1,1,1,53.5602149963379,0,53.5563892364502,,,,,,,,,,,,,,,,,,,,,,,,,,,,,,,,,
,3754334930.57906,53.5524616241455,200.077056884766,,,5,,,,3.65000008605421,,,,,0.000713946410652175,7.39107506853974E-8,0.0437387459783256,1.87580686011906E-5,0.000713853771023208,7.39011602393666E-8,0.000713853563021629,7.26917889599343E-8,5.44945299448254E-7,1.33148527039885E-8,1.00012977395754,10.005763053894,2,20,10,3,2.33530086832926,0.207255468351231,0.0404026173055172,172.741912841797,53.5432434082031,53.5534210205078,200.077056884766,200.077056884766,,,57.6635932922363,0,1,,,,,,1,1,1,53.5517692565918,0,53.5491779327393,,,,,,,,,,,,,,,,,,,,,,,,,,,,,,,,,
,3754334952.51122,53.5804252624512,219.857711791992,,,5,,,,3.65000008605421,,,,,0.000711728985369086,1.08734643579758E-7,0.0284158086645219,2.79359515009527E-5,0.00071163645792909,1.08720507667893E-7,0.000711636370409966,1.06905262531613E-7,3.52935674670737E-7,1.97841762682031E-8,1.00013002065727,10.005763053894,2,20,10,3,2.32809982706898,0.206038349627903,0.0404026173055172,172.741912841797,53.57421875,53.5814476013184,219.857711791992,219.857711791992,,,57.7009048461914,0,1,,,,,,1,1,1,53.5812339782715,0,53.5790431976318,,,,,,,,,,,,,,,,,,,,,,,,,,,,,,,,,
,3754334974.16464,53.5492496490479,239.929779052734,,,5,,,,3.65000008605421,,,,,0.000712379223686001,1.27490412884197E-7,0.0370082757147694,2.55018008425844E-5,0.00071228697381545,1.27473903455378E-7,0.000712286825229608,1.26195966786116E-7,4.60077707399258E-7,1.80048334918354E-8,1.00012951222463,10.005763053894,2,20,10,3,2.33019268990344,0.206626204248328,0.0404026173055172,172.741912841797,53.5338859558105,53.5549736022949,239.929779052734,239.929779052734,,,57.7630882263184,0,1,,,,,,1,1,1,53.5460586547852,0,53.5436614990234,,,,,,,,,,,,,,,,,,,,,,,,,,,,,,,,,
,3754334996.03856,53.5747299194336,260.026092529297,,,5,,,,3.65000008605421,,,,,0.000716147571381577,8.52606173775705E-8,0.0408740177345139,3.35174941947724E-5,0.000716054573927404,8.52495456087422E-8,0.000716054391720217,8.18164201486045E-8,5.10823399555852E-7,2.39490797435733E-8,1.0001298748134,10.005763053894,2,20,10,3,2.34250178396493,0.207927564279339,0.0404026173055172,172.741912841797,53.5648307800293,53.5749053955078,260.026092529297,260.026092529297,,,57.8128395080566,0,1,,,,,,1,1,1,53.5748710632324,0,53.5718029022217,,,,,,,,,,,,,,,,,,,,,,,,,,,,,,,,,
,3754335017.87988,53.5423011779785,279.964599609375,,,5,,,,3.65000008605421,,,,,0.000723705407295606,1.03185496561696E-7,0.0514862053691862,3.47601159316042E-5,0.000723611588649,1.03172119953564E-7,0.000723611296494894,1.00079296940412E-7,6.50240037980982E-7,2.5072308621771E-8,1.00012965332241,10.005763053894,2,20,10,3,2.36718113935201,0.210610988183761,0.0404026173055172,172.741912841797,53.5279922485352,53.5468063354492,279.964599609375,279.964599609375,,,57.8625869750977,0,1,,,,,,1,1,1,53.5398941040039,0,53.536582253196,,,,,,,,,,,,,,,,,,,,,,,,,,,,,,,,,
,3754335039.74789,53.5446968078613,299.903106689453,,,5,,,,3.65000008605421,,,,,0.000729979584143759,1.1617084684235E-7,0.0565453534039584,7.48237889421176E-5,0.000729884704633956,1.1615574747075E-7,0.000729884349188627,1.02535885707516E-7,7.20324991104331E-7,5.45760919511814E-8,1.0001299924621,10.005763053894,2,20,10,3,2.3876814803861,0.212698651038196,0.0404026173055172,172.741912841797,53.540210723877,53.5452461242676,299.903106689453,299.903106689453,,,57.8998985290527,0,1,,,,,,1,1,1,53.545280456543,0,53.5433570861816,,,,,,,,,,,,,,,,,,,,,,,,,,,,,,,,,
,3754335061.32381,53.5271377563477,319.999450683594,,,5,,,,3.65000008605421,,,,,0.000735985916026326,1.17963569890807E-7,0.0400057131243363,2.92527692764336E-5,0.000735890509260648,1.17948278127166E-7,0.00073589032987737,1.15988775937145E-7,5.13821828806127E-7,2.1410281870307E-8,1.00012964804475,10.005763053894,2,20,10,3,2.40738606852642,0.213805658528406,0.0404026173055172,172.741912841797,53.5189170837402,53.5304183959961,319.999450683594,319.999450683594,,,57.9496459960937,0,1,,,,,,1,1,1,53.5254402160645,0,53.5239303588867,,,,,,,,,,,,,,,,,,,,,,,,,,,,,,,,,
,3754335083.31105,53.5128746032715,340.02294921875,,,5,,,,3.65000008605421,,,,,0.000740435646840784,1.32727817475268E-7,0.0209910064358647,5.37245838621458E-5,0.000740339551713966,1.32710591810206E-7,0.000740339502029319,1.2662944504232E-7,2.71232402790875E-7,3.97125273294104E-8,1.00012979872086,10.005763053894,2,20,10,3,2.42200899936644,0.214346481007706,0.0404026173055172,172.741912841797,53.5100631713867,53.513729095459,340.02294921875,340.02294921875,,,57.9869575500488,0,1,,,,,,1,1,1,53.5126113891602,0,53.5118269486861,,,,,,,,,,,,,,,,,,,,,,,,,,,,,,,,,
,3754335105.02835,53.5596809387207,360.022155761719,,,5,,,,3.65000008605421,,,,,0.000742611122917631,1.21954674552133E-7,-0.0113350618865029,6.85418471672343E-5,0.000742514603789569,1.21938823781134E-7,0.00074251458925917,1.10822269819479E-7,-1.46894745166426E-7,5.0867487230892E-8,1.00012998953498,10.005763053894,2,20,10,3,2.42924280712811,0.213657562439232,0.0404026173055172,172.741912841797,53.5560302734375,53.5617637634277,360.022155761719,360.022155761719,,,58.0367050170898,0,1,,,,,,1,1,1,53.560920715332,0,53.5592041015625,,,,,,,,,,,,,,,,,,,,,,,,,,,,,,,,,
,3754335126.88056,53.538122177124,379.960632324219,,,5,,,,3.65000008605421,,,,,0.000744233140769946,1.92751940892132E-7,-0.0460350711911621,9.59466152457928E-5,0.00074413671786904,1.92726967936377E-7,0.000744136477678947,1.79024606786121E-7,-5.9788667487305E-7,7.13713831659717E-8,1.00012957686214,10.005763053894,2,20,10,3,2.43467482142465,0.212701791628337,0.0404026173055172,172.741912841797,53.5248184204102,53.5422554016113,379.960632324219,379.960632324219,,,58.0740165710449,0,1,,,,,,1,1,1,53.5361824035645,0,53.5333248485218,,,,,,,,,,,,,,,,,,,,,,,,,,,,,,,,,
,3754335149.96898,53.5652675628662,400.008422851562,,,5,,,,3.65000008605421,,,,,0.000743001479026866,2.24134917851503E-7,-0.0693507550940007,0.000147036129328621,0.000742904889769497,2.24105780594207E-7,0.000742904345567298,1.95690001264472E-7,-8.99211127348355E-7,1.09219157206279E-7,1.00013001564359,10.005763053894,2,20,10,3,2.43072861995423,0.211412712981287,0.0404026173055172,172.741912841797,53.5579605102539,53.5653839111328,400.008422851562,400.008422851562,,,58.1362037658691,0,1,,,,,,1,1,1,53.5651664733887,0,53.5631197149103,,,,,,,,,,,,,,,,,,,,,,,,,,,,,,,,,
,3754335171.58913,53.5667476654053,420.031921386719,,,5,,,,3.65000008605421,,,,,0.000740841085202167,2.65952421540822E-7,-0.08274916893998,0.00015509202627029,0.000740744896627127,2.65917891079475E-7,0.000740744124087771,2.39824836791914E-7,-1.06981707560908E-6,1.14875464977894E-7,1.00012985384777,10.005763053894,2,20,10,3,2.4237069677944,0.210283163940196,0.0404026173055172,172.741912841797,53.5543251037598,53.5676116943359,420.031921386719,420.031921386719,,,58.1859512329102,0,1,,,,,,1,1,1,53.5658836364746,0,53.5623447418213,,,,,,,,,,,,,,,,,,,,,,,,,,,,,,,,,
,3754335193.46091,53.5338706970215,440.091827392578,,,5,,,,3.65000008605421,,,,,0.000737657672951388,2.34819055927864E-7,-0.0864257327365614,0.000161556128951765,0.00073756207616914,2.34788624540812E-7,0.000737561237077535,2.02310100244437E-7,-1.11254824073081E-6,1.19148317457075E-7,1.00012961184602,10.005763053894,2,20,10,3,2.413302517101,0.20927662781365,0.0404026173055172,172.741912841797,53.5252532958984,53.5373725891113,440.091827392578,440.091827392578,,,58.2232627868652,0,1,,,,,,1,1,1,53.5324363708496,0,53.5307666778564,,,,,,,,,,,,,,,,,,,,,,,,,,,,,,,,,
,3754335215.30532,53.5174427032471,460.163879394531,,,5,,,,3.65000008605421,,,,,0.000729611983992017,2.91624339012525E-7,-0.0957033948588153,0.000204659944754509,0.000729517308530459,2.91586497434394E-7,0.00072951629084182,2.50466814595966E-7,-1.21854089712257E-6,1.49295211819427E-7,1.00012977822521,10.005763053894,2,20,10,3,2.38701081866161,0.206658839585521,0.0404026173055172,172.741912841797,53.5122680664063,53.5190010070801,460.163879394531,460.163879394531,,,58.2481346130371,0,1,,,,,,1,1,1,53.5166969299316,0,53.5154914855957,,,,,,,,,,,,,,,,,,,,,,,,,,,,,,,,,
,3754335236.97012,53.5542392730713,480.284545898438,,,5,,,,3.65000008605421,,,,,0.000700859364151889,2.76298675907682E-7,-0.108140666598752,0.000205008799364425,0.000700768285256369,2.76262770019108E-7,0.000700767037076615,2.35971888912073E-7,-1.32263676574263E-6,1.43660661775932E-7,1.0001299700592,10.005763053894,2,20,10,3,2.2929833327999,0.198066334622774,0.0404026173055172,172.741912841797,53.550838470459,53.5553665161133,480.284545898438,480.284545898438,,,58.3103218078613,0,1,,,,,,1,1,1,53.55517578125,0,53.5533107757568,,,,,,,,,,,,,,,,,,,,,,,,,,,,,,,,,
,3754335258.5841,53.5396003723145,500.247344970703,,,5,,,,3.65000008605421,,,,,0.000621063510469515,1.92869439442001E-7,-0.134730941621532,0.000243117498286445,0.000620982932182839,1.92844416092987E-7,0.000620981215306984,1.2001283474304E-7,-1.46023910992158E-6,1.50949953014848E-7,1.00012975926149,10.005763053894,2,20,10,3,2.03199594754422,0.174616078944874,0.0404026173055172,172.741912841797,53.530403137207,53.541877746582,500.247344970703,500.247344970703,,,58.3476333618164,0,1,,,,,,1,1,1,53.5382843017578,0,53.5363536834717,,,,,,,,,,,,,,,,,,,,,,,,,,,,,,,,,
,3754335283.62669,53.5227108001709,520.185791015625,,,5,,,,3.65000008605421,,,,,0.00042253210912652,1.55160786886813E-7,-0.159920426708684,0.000117358896380279,0.000422477324379888,1.55140669020707E-7,0.000422475678736454,1.46988474977807E-7,-1.17919097775998E-6,4.9628776006376E-8,1.00012967499904,10.005763053894,2,20,1,3,1.3824911327361,0.118219415246694,0.0404026173055172,172.741912841797,53.515552520752,53.5263404846191,520.185791015625,520.185791015625,,,58.3849449157715,0,1,,,,,,1,1,1,53.5216407775879,0,53.5211539635291,,,,,,,,,,,,,,,,,,,,,,,,,,,,,,,,,
,3754335306.07053,53.5462779998779,540.27001953125,,,5,,,,3.65000008605421,,,,,0.000151479188690503,2.68353122969502E-7,-0.432295888535554,0.00119062978330691,0.000151459506519619,2.68318254998071E-7,0.000151455195485829,1.98677587920724E-7,-1.14274910454558E-6,1.80338298825327E-7,1.0001299500529,10.005763053894,2,20,1,3,0.495823036817071,0.0400360904588963,0.0404026173055172,172.741912841797,53.5427856445313,53.5471458435059,540.27001953125,540.27001953125,,,58.4222564697266,0,1,,,,,,1,1,1,53.5468978881836,0,53.5455268859863,,,,,,,,,,,,,,,,,,,,,,,,,,,,,,,,,
,3754335327.80326,53.5653629302978,560.257080078125,,,5,,,,3.65000008605421,,,,,7.03082469214577E-5,3.72061558385662E-7,-1.11036446572743,0.00249968424306891,7.02991227641701E-5,3.72013274602066E-7,7.0285922210027E-5,3.27551217634944E-7,-1.36227768751114E-6,1.76363477812209E-7,1.0001297904857,10.005763053894,2,20,1,3,0.23033716730905,0.0158626943897544,0.0404026173055172,172.741912841797,53.5550880432129,53.5663871765137,560.257080078125,560.257080078125,,,58.4471321105957,0,1,,,,,,1,1,1,53.5643920898438,0,53.5618576049805,,,,,,,,,,,,,,,,,,,,,,,,,,,,,,,,,
,3754335349.67024,53.5434894561768,580.304809570312,,,5,,,,3.65000008605421,,,,,5.23530923162211E-5,5.07505011784289E-7,-1.4609058350174,0.00297431346734509,5.23463025979615E-5,5.07439193016134E-7,5.23292876090963E-5,4.82142371717376E-7,-1.33456135184301E-6,1.58219050697472E-7,1.00012970769515,10.005763053894,2,20,1,3,0.171583122891129,0.0107658449868919,0.0404026173055172,172.741912841797,53.532958984375,53.5461196899414,580.304809570312,580.304809570312,,,58.5093154907227,0,1,,,,,,1,1,1,53.5424919128418,0,53.5401210784912,,,,,,,,,,,,,,,,,,,,,,,,,,,,,,,,,
,3754335371.29815,53.5180397033691,600.219055175781,,,5,,,,3.65000008605421,,,,,4.39302292637092E-5,3.80923871518588E-7,-1.79853423723796,0.00370387598987051,4.39245326567229E-5,3.80874475610028E-7,4.39028938331199E-5,3.43775369685898E-7,-1.37857977256337E-6,1.63962987800717E-7,1.00012969078193,10.005763053894,2,20,1,3,0.144028493275604,0.00818827244945752,0.0404026173055172,172.741912841797,53.5107269287109,53.5199813842773,600.219055175781,600.219055175781,,,58.5341911315918,0,1,,,,,,1,1,1,53.5168609619141,0,53.5153308868408,,,,,,,,,,,,,,,,,,,,,,,,,,,,,,,,,
,3754335393.2304,53.5077667236328,620.21826171875,,,5,,,,3.65000008605421,,,,,3.75231456258942E-5,4.29192752017807E-7,-2.12316143072854,0.00479560880457484,3.75182759593733E-5,4.29137052381206E-7,3.74925196312856E-5,3.88809410536071E-7,-1.38996498565841E-6,1.81620075996633E-7,1.00012979451737,10.005763053894,2,20,1,3,0.123059983081488,0.00629954154787178,0.0404026173055172,172.741912841797,53.5070762634277,53.5082778930664,620.21826171875,620.21826171875,,,58.5839385986328,0,1,,,,,,1,1,1,53.5076179504395,0,53.5074885975231,,,,,,,,,,,,,,,,,,,,,,,,,,,,,,,,,
,3754335414.90581,53.5067653656006,640.302490234375,,,5,,,,3.65000008605421,,,,,3.40085410829528E-5,4.53167946716238E-7,-2.37621977634782,0.00496089535028889,3.40041251896659E-5,4.53109104401042E-7,3.39748858669743E-5,4.19551001945096E-7,-1.40984404830615E-6,1.71128072676521E-7,1.0001298634581,10.005763053894,2,20,1,3,0.11155765190787,0.00521922612220282,0.0404026173055172,172.741912841797,53.5059051513672,53.5070266723633,640.302490234375,640.302490234375,,,58.608814239502,0,1,,,,,,1,1,1,53.5066604614258,0,53.5064693450928,,,,,,,,,,,,,,,,,,,,,,,,,,,,,,,,,
,3754335436.75679,53.5582942962646,660.362365722656,,,5,,,,3.65000008605421,,,,,3.21434439884367E-5,3.54128108310324E-7,-2.54962187167219,0.00489196093521798,3.2139264571269E-5,3.54082063179131E-7,3.21074489388938E-5,3.16559480144149E-7,-1.42970270278611E-6,1.58632288630203E-7,1.0001300408464,10.005763053894,2,20,1,3,0.105454011350019,0.00461611913138511,0.0404026173055172,172.741912841797,53.5534858703613,53.5592880249023,660.362365722656,660.362365722656,,,58.6585578918457,0,1,,,,,,1,1,1,53.5591583251953,0,53.5568147139116,,,,,,,,,,,,,,,,,,,,,,,,,,,,,,,,,
,3754335458.42228,53.5470371246338,680.179443359375,,,5,,,,3.65000008605421,,,,,3.11546626774415E-5,4.22751281763238E-7,-3.11222369874297,0.00554188101084224,3.11506207203286E-5,4.22696434674441E-7,3.1104676988278E-5,3.84812937444012E-7,-1.69122462040283E-6,1.7490362792748E-7,1.00012975526713,10.005763053894,2,20,1,3,0.102249072206435,0.00347246120642186,0.0404026173055172,172.741912841797,53.5379638671875,53.5485305786133,680.179443359375,680.179443359375,,,58.708309173584,0,1,,,,,,1,1,1,53.5460815429687,0,53.543826675415,,,,,,,,,,,,,,,,,,,,,,,,,,,,,,,,,
,3754335480.32025,53.525598526001,700.227233886719,,,5,,,,3.65000008605421,,,,,2.93719203425643E-5,4.66770772652328E-7,-3.07481051491564,0.00705193345361421,2.93681115224647E-5,4.66710243892885E-7,2.93258316914938E-5,4.17202385488228E-7,-1.57529997083127E-6,2.09190394849975E-7,1.00012969237388,10.005763053894,2,20,1,3,0.096395965840351,0.00333877264780458,0.0404026173055172,172.741912841797,53.5188865661621,53.5280647277832,700.227233886719,700.227233886719,,,58.7331809997559,0,1,,,,,,1,1,1,53.5245666503906,0,53.5232746124268,,,,,,,,,,,,,,,,,,,,,,,,,,,,,,,,,
,3754335502.16678,53.5179023742676,720.262878417969,,,5,,,,3.65000008605421,,,,,2.62293956135274E-5,4.37173189605014E-7,-3.3536504256216,0.0063195115319341,2.6225991499273E-5,4.37116452213566E-7,2.61810788946045E-5,4.03315231861563E-7,-1.53418969962422E-6,1.68545591886079E-7,1.00012979925867,10.005763053894,2,20,1,3,0.0860959696669052,0.00256442982954459,0.0404026173055172,172.741912841797,53.5154724121094,53.5187835693359,720.262878417969,720.262878417969,,,58.7953681945801,0,1,,,,,,1,1,1,53.5175476074219,0,53.5171207427978,,,,,,,,,,,,,,,,,,,,,,,,,,,,,,,,,
,3754335523.84215,53.5295486450195,740.177062988281,,,5,,,,3.65000008605421,,,,,2.57755369177714E-5,4.70057458939179E-7,-3.45390248969248,0.00682882039335416,2.57721898030232E-5,4.69996419036952E-7,2.57253769957491E-5,4.34522329189872E-7,-1.55265761507022E-6,1.79128387875756E-7,1.00012987312191,10.005763053894,2,20,1,3,0.0846104895304254,0.00237381387751451,0.0404026173055172,172.741912841797,53.5280494689941,53.5302925109863,740.177062988281,740.177062988281,,,58.807804107666,0,1,,,,,,1,1,1,53.5300483703613,0,53.5293651580811,,,,,,,,,,,,,,,,,,,,,,,,,,,,,,,,,
,3754335545.76444,53.5197486877441,760.1884765625,,,5,,,,3.65000008605421,,,,,2.63979410162342E-5,4.80960330946556E-7,-3.94236318276662,0.00795994960485638,2.63945158268111E-5,4.80897925312818E-7,2.63320589377582E-5,4.31348957567248E-7,-1.81470047947548E-6,2.12605012583949E-7,1.00012976898101,10.005763053894,2,20,1,3,0.0866711748106716,0.0016941661685375,0.0404026173055172,172.741912841797,53.5127563476562,53.5219612121582,760.1884765625,760.1884765625,,,58.8451194763184,0,1,,,,,,1,1,1,53.5185050964355,0,53.5171188354492,,,,,,,,,,,,,,,,,,,,,,,,,,,,,,,,,
,3754335567.5356,53.5336723327637,780.260498046875,,,5,,,,3.65000008605421,,,,,2.36387734433135E-5,4.56432368030948E-7,-4.13487755151107,0.00943539705551918,2.36357020535248E-5,4.56373063697E-7,2.35741801086183E-5,3.97142980110785E-7,-1.70424287277954E-6,2.24841781297227E-7,1.00012994705136,10.005763053894,2,20,1,3,0.0776167992313544,0.00125796559046672,0.0404026173055172,172.741912841797,53.5318832397461,53.5347290039063,780.260498046875,780.260498046875,,,58.9197425842285,0,1,,,,,,1,1,1,53.5342178344727,0,53.5333817221902,,,,,,,,,,,,,,,,,,,,,,,,,,,,,,,,,
,3754335590.5385,53.5713348388672,800.296142578125,,,5,,,,3.65000008605421,,,,,2.38680158459637E-5,4.30610540905414E-7,-4.63657833316265,0.00837737374881847,2.3864917362942E-5,4.30554640177906E-7,2.37868188325383E-5,3.8025157014606E-7,-1.92912689267705E-6,2.01955543573783E-7,1.00012983422379,10.005763053894,2,20,1,3,0.0783776542300462,0.000585569280987342,0.0404026173055172,172.741912841797,53.5625267028809,53.571605682373,800.296142578125,800.296142578125,,,58.9321784973145,0,1,,,,,,1,1,1,53.5711784362793,0,53.5685726512562,,,,,,,,,,,,,,,,,,,,,,,,,,,,,,,,,