File: Experimental_Data/Fig3C/Lifetime_300Oe_49K.dat
[Header]
; MPMS3 Data File (default extension .dat)
; Copyright (c) 2007, Quantum Design, Inc. All rights reserved.
TITLE,300Oe_49K
FILEOPENTIME,3768151728.91796,05/27/2019,8:48 pm
BYAPP,SQUID AC,0.9.1.0
INFO,MPMS3 Measurement Release 1.1.16 Build 347, MultiVu Release 2.3.3.2,APPNAME
INFO,0,MOMENT_UNITS
INFO,,SAMPLE_MATERIAL
INFO,,SAMPLE_COMMENT
INFO,,SAMPLE_MASS
INFO,,SAMPLE_VOLUME
INFO,,SAMPLE_MOLECULAR_WEIGHT
INFO,,SAMPLE_SIZE
INFO,,SAMPLE_SHAPE
INFO,Quartz,SAMPLE_HOLDER
INFO,Standard,SAMPLE_HOLDER_DETAIL
INFO,66.2,SAMPLE_OFFSET
DATATYPE,COMMENT,1
DATATYPE,TIME,2
STARTUPAXIS,X,2
STARTUPAXIS,Y1,5
FIELDGROUP, VSM,2,3,4,5,6,8,9,10,11,14,15
FIELDGROUP, DC, 2,3,4,14,56,57,58,59,60,61,62,63,64,65,66,67,68,69
FIELDGROUP, AC, 2,3,4,11,16,17,18,19,20,21,22,23,24,25,26,27,28,29,30
STARTUPGROUP, All
[Data]
Comment,Time Stamp (sec),Temperature (K),Magnetic Field (Oe),Moment (emu),M. Std. Err. (emu),Transport Action,Averaging Time (sec),Frequency (Hz),Peak Amplitude (mm),Center Position (mm),Lockin Signal' (V),Lockin Signal (V),Range,M. Quad. Signal (emu),AC Moment (emu),AC M. Std Err. (emu),AC Phase (deg),AC Phase Std. Err. (deg),AC Susceptibility (emu/Oe),AC Suscept. Std Err. (emu/Oe),AC X' (emu/Oe),AC X' Std Err. (emu/Oe),AC X'' (emu/Oe),AC X'' Std Err. (emu/Oe),AC Drive (Oe),AC Frequency (Hz),AC Averaging Time (sec),AC Cycles,AC Range,AC Measure Type,AC Signal' (V),AC Signal'' (V),AC Trim Coil Ratio,AC Trim Coil Phase,Min. Temperature (K),Max. Temperature (K),Min. Field (Oe),Max. Field (Oe),Mass (grams),Motor Lag (deg),Pressure (Torr),Measure Count,Measurement Number,SQUID Status (code),Motor Status (code),Measure Status (code),Motor Current (amps),Motor Temp. (C),Temp. Status (code),Field Status (code),Chamber Status (code),Chamber Temp (K),Redirection State,Average Temp (K),Rotation Angle (deg),Rotator state,DC Moment Fixed Ctr (emu),DC Moment Err Fixed Ctr (emu),DC Moment Free Ctr (emu),DC Moment Err Free Ctr (emu),DC Fixed Fit,DC Free Fit,DC Calculated Center (mm),DC Calculated Center Err (mm),DC Scan Length (mm),DC Scan Time (s),DC Number of Points,DC Squid Drift,DC Min V (V),DC Max V (V),DC Scans per Measure,Map 01,Map 02,Map 03,Map 04,Map 05,Map 06,Map 07,Map 08,Map 09,Map 10,Map 11,Map 12,Map 13,Map 14,Map 15,Map 16
,3768151732.98732,49.0951595306396,300.425231933594,,,5,,,,25.0400006771088,,,,,0.000606196400541056,4.08488959338235E-7,0.126040734313565,0.000320063490277128,0.000606105058140095,4.08427407731729E-7,0.000606103591598713,3.59514946966073E-7,1.33332447230323E-6,1.93809056275607E-7,1.00015070390807,10.005763053894,2,20,10,5,1.98258355583106,0.179050415590647,0.0410455763339996,172.855895996094,49.0940895080566,49.107780456543,300.425231933594,300.425231933594,,,19.312370300293,0,1,,,,,,1,1,1,49.096004486084,0,49.0997536603142,,,,,,,,,,,,,,,,,,,,,,,,,,,,,,,,,
,3768151941.16134,48.9288425445557,300.425231933594,,,5,,,,25.0300001353025,,,,,0.00063259116719047,1.45453396944509E-7,0.0192161631090642,0.000172709631209228,0.000632495654809517,1.4543143552459E-7,0.000632495619236915,9.60179103298408E-8,2.12129750987375E-7,1.09228491405098E-7,1.00015100875433,10.005763053894,2,20,10,5,2.06925314715168,0.182989487278703,0.0410455763339996,172.855895996094,48.9221267700195,48.9523735046387,300.425231933594,300.425231933594,,,21.419771194458,0,1,,,,,,1,1,1,48.9320411682129,0,48.9400657205021,,,,,,,,,,,,,,,,,,,,,,,,,,,,,,,,,
,3768152148.97925,49.000337600708,300.425231933594,,,5,,,,25.0300001353025,,,,,0.000659715570364435,1.54161947042336E-7,0.00335676141135455,0.000184220447615051,0.000659616225976353,1.54138732304072E-7,0.000659616224844326,9.48420444293723E-8,3.86446316152926E-8,1.21506112623042E-7,1.00015060937583,10.005763053894,2,20,10,5,2.15803186818427,0.190238159887127,0.0410455763339996,172.855895996094,48.9993209838867,49.0007476806641,300.425231933594,300.425231933594,,,22.4787330627441,0,1,,,,,,1,1,1,48.9999160766602,0,48.9999798668755,,,,,,,,,,,,,,,,,,,,,,,,,,,,,,,,,
,3768152354.4948,49.0004978179932,300.425231933594,,,5,,,,25.0300001353025,,,,,0.000673763304809511,1.51536613017712E-7,0.00235850949623018,0.000142005101952906,0.000673661840080407,1.51513792508967E-7,0.000673661839509662,1.1750884438471E-7,2.77304517039698E-8,9.5645704617721E-8,1.00015061670866,10.005763053894,2,20,10,5,2.20398756939342,0.19425061868388,0.0410455763339996,172.855895996094,48.999340057373,49.0009498596191,300.425231933594,300.425231933594,,,23.4388847351074,0,1,,,,,,1,1,1,49.0002288818359,0,49.0000392689424,,,,,,,,,,,,,,,,,,,,,,,,,,,,,,,,,
,3768152562.64255,49.0006580352783,300.425231933594,,,5,,,,25.0300001353025,,,,,0.000682661610992959,1.2886557782193E-7,0.00652716723737701,0.00010108173528231,0.00068255880122776,1.28846170490999E-7,0.000682558796798672,1.08830917492183E-7,7.77574801003178E-8,6.89722193930659E-8,1.0001506240415,10.005763053894,2,20,10,5,2.23308102707103,0.196978533375129,0.0410455763339996,172.855895996094,48.999195098877,49.0011215209961,300.425231933594,300.425231933594,,,24.4127712249756,0,1,,,,,,1,1,1,49.0004425048828,0,49.0001472024357,,,,,,,,,,,,,,,,,,,,,,,,,,,,,,,,,
,3768152768.31324,49.0008602142334,300.425231933594,,,5,,,,25.0300001353025,,,,,0.000688891594645239,1.39180119087427E-7,0.00316518516336028,0.00011036567870434,0.00068878784026342,1.3915915708509E-7,0.000688787839212406,1.16575467075747E-7,3.80506395082394E-8,7.59962596231161E-8,1.00015063329483,10.005763053894,2,20,10,5,2.25347182952839,0.198643934744647,0.0410455763339996,172.855895996094,48.9997520446777,49.0013236999512,300.425231933594,300.425231933594,,,25.2889747619629,0,1,,,,,,1,1,1,49.0005912780762,0,49.0004220850327,,,,,,,,,,,,,,,,,,,,,,,,,,,,,,,,,
,3768152976.18048,49.000337600708,300.425231933594,,,5,,,,25.0300001353025,,,,,0.000692912612575953,1.82045670830194E-7,0.00628587088434518,0.000122661416011201,0.000692808269154966,1.82018257174092E-7,0.000692808264985612,1.6098323398628E-7,7.60074015187177E-8,8.49414169884881E-8,1.00015060937583,10.005763053894,2,20,10,5,2.26661432014212,0.19992686321746,0.0410455763339996,172.855895996094,48.9997138977051,49.0007514953613,300.425231933594,300.425231933594,,,26.2078857421875,0,1,,,,,,1,1,1,49.0001564025879,0,49.0002739850213,,,,,,,,,,,,,,,,,,,,,,,,,,,,,,,,,
,3768153182.61246,49.0003795623779,300.425231933594,,,5,,,,25.0300001353025,,,,,0.000696010713400554,1.73876447668627E-7,0.00691226241552112,0.000160091522918074,0.000695905902110511,1.73850263855019E-7,0.000695905897046255,1.33478422305199E-7,8.39552972506638E-8,1.11388621597427E-7,1.00015061129633,10.005763053894,2,20,10,5,2.27674644670235,0.200845653008387,0.0410455763339996,172.855895996094,48.9995765686035,49.000919342041,300.425231933594,300.425231933594,,,27.0806159973145,0,1,,,,,,1,1,1,49.0000381469727,0,49.0001006656223,,,,,,,,,,,,,,,,,,,,,,,,,,,,,,,,,
,3768153388.58749,48.999584197998,300.425231933594,,,5,,,,25.0300001353025,,,,,0.000698373724077069,1.24294709207379E-7,-0.00035715551826776,0.000144762039494497,0.00069826850225418,1.24275982105503E-7,0.000698268502240613,7.23052762587981E-8,-4.35268445477883E-9,1.01076539085122E-7,1.00015068963092,10.005763053894,2,20,10,5,2.28450172883468,0.201237696359693,0.0410455763339996,172.855895996094,48.9992752075195,49.0001564025879,300.425231933594,300.425231933594,,,27.9675540924072,0,1,,,,,,1,1,1,48.999584197998,0,48.9997116537655,,,,,,,,,,,,,,,,,,,,,,,,,,,,,,,,,
,3768153596.7309,49.0003414154053,300.425231933594,,,5,,,,25.0300001353025,,,,,0.000700279892733596,1.50872362777285E-7,0.00225156395542392,0.000147304946062277,0.000700174439776005,1.50849643380314E-7,0.000700174439235376,1.10094863246698E-7,2.75148980274031E-8,1.0312485633764E-7,1.00015060955042,10.005763053894,2,20,10,5,2.29072794783199,0.201891259100738,0.0410455763339996,172.855895996094,48.9994239807129,49.0007591247559,300.425231933594,300.425231933594,,,28.8201141357422,0,1,,,,,,1,1,1,49.0000915527344,0,49.0000930362278,,,,,,,,,,,,,,,,,,,,,,,,,,,,,,,,,
,3768153804.09941,48.9985446929932,300.425231933594,,,5,,,,25.0300001353025,,,,,0.000701764544807618,1.48363859302185E-7,-0.00130635638128673,0.000159332462353037,0.000701658845477367,1.4834151283188E-7,0.000701658845294989,9.75137526741043E-8,-1.59979760810643E-8,1.11786727605134E-7,1.0001506420548,10.005763053894,2,20,10,5,2.29559704166977,0.202176740935636,0.0410455763339996,172.855895996094,48.9982109069824,49.0018081665039,300.425231933594,300.425231933594,,,29.7020511627197,0,1,,,,,,1,1,1,48.9987030029297,0,48.9998402315028,,,,,,,,,,,,,,,,,,,,,,,,,,,,,,,,,
,3768154010.6042,48.99924659729,300.425231933594,,,5,,,,25.0300001353025,,,,,0.00070299959780796,1.03809641016321E-7,0.00575879976273441,0.000107135690986171,0.000702893689877896,1.03794001940232E-7,0.000702893686327488,7.14393481680807E-8,7.06478564753053E-8,7.52968417139035E-8,1.00015067417959,10.005763053894,2,20,10,5,2.29961212889745,0.20281612061152,0.0410455763339996,172.855895996094,48.9989356994629,49.0002250671387,300.425231933594,300.425231933594,,,30.4387664794922,0,1,,,,,,1,1,1,48.9995498657227,0,48.999677770278,,,,,,,,,,,,,,,,,,,,,,,,,,,,,,,,,
,3768154217.05614,48.9999198913574,300.425231933594,,,5,,,,25.0300001353025,,,,,0.000704067051780277,1.47151494971373E-7,0.000187105625790274,0.000137420257473716,0.000703961042105263,1.47129338726282E-7,0.000703961042101509,1.10867866962663E-7,2.29886166894317E-9,9.6723101631318E-8,1.00015059025809,10.005763053894,2,20,10,5,2.30312366531147,0.202900115468398,0.0410455763339996,172.855895996094,48.9997215270996,49.001049041748,300.425231933594,300.425231933594,,,31.0730590820313,0,1,,,,,,1,1,1,48.9999847412109,0,49.0002275354722,,,,,,,,,,,,,,,,,,,,,,,,,,,,,,,,,
,3768154422.07333,49.0000038146973,300.425231933594,,,5,,,,25.0300001353025,,,,,0.000704963233782775,1.22760475076696E-7,0.00531279722915734,0.000149858927324474,0.000704857086464848,1.22741990857162E-7,0.000704857083434641,6.25211972607206E-8,6.53584400523083E-8,1.05625263136551E-7,1.00015059409909,10.005763053894,2,20,10,5,2.30603704607459,0.20336467835279,0.0410455763339996,172.855895996094,48.9996910095215,49.0007743835449,300.425231933594,300.425231933594,,,31.6700401306152,0,1,,,,,,1,1,1,49.0001831054687,0,49.0001650916206,,,,,,,,,,,,,,,,,,,,,,,,,,,,,,,,,
,3768154630.615,48.9994106292725,300.425231933594,,,5,,,,25.0300001353025,,,,,0.000705921663871314,1.1675475000409E-7,4.18820872027936E-5,0.000101503547083154,0.000705815391400459,1.16737173243944E-7,0.00070581539140027,9.21788674406171E-8,5.15937160169985E-10,7.16283743662512E-8,1.00015056695016,10.005763053894,2,20,10,5,2.30919093376933,0.203428733494635,0.0410455763339996,172.855895996094,48.9988975524902,48.9999389648438,300.425231933594,300.425231933594,,,32.2794570922852,0,1,,,,,,1,1,1,48.9991645812988,0,48.9994218614366,,,,,,,,,,,,,,,,,,,,,,,,,,,,,,,,,
,3768154837.29299,49.0004711151123,300.425231933594,,,5,,,,25.0300001353025,,,,,0.000706597073280424,1.67115831024759E-7,-0.00153246040342925,9.88058825950452E-5,0.000706490664845214,1.67090664583019E-7,0.000706490664592511,1.51828877260182E-7,-1.88961382206416E-8,6.97659101618235E-8,1.00015061548652,10.005763053894,2,20,10,5,2.31140590853132,0.20355985264976,0.0410455763339996,172.855895996094,48.9998626708984,49.0006370544434,300.425231933594,300.425231933594,,,32.8640022277832,0,1,,,,,,1,1,1,49.0004272460937,0,49.0003047269933,,,,,,,,,,,,,,,,,,,,,,,,,,,,,,,,,
,3768155043.66046,49.0008220672607,300.425231933594,,,5,,,,25.0300001353025,,,,,0.000707247453971311,1.32345908133194E-7,0.00261194054556579,0.000128888566469398,0.000707140936236782,1.32325975666517E-7,0.000707140935502002,9.59451413081393E-8,3.22364072509869E-8,9.11300921510394E-8,1.00015063154892,10.005763053894,2,20,10,5,2.31351867671441,0.20391456332287,0.0410455763339996,172.855895996094,48.9994773864746,49.0013618469238,300.425231933594,300.425231933594,,,33.4734191894531,0,1,,,,,,1,1,1,49.0002822875977,0,49.0000236034393,,,,,,,,,,,,,,,,,,,,,,,,,,,,,,,,,
,3768155250.19246,48.9996509552002,300.425231933594,,,5,,,,25.0300001353025,,,,,0.000707792231819195,1.27863473245506E-7,-0.00301871580717528,0.000133047764137963,0.000707685588776789,1.2784420805837E-7,0.000707685587794567,8.64905030985568E-8,-3.7285497998583E-8,9.41463456955724E-8,1.00015069268627,10.005763053894,2,20,10,5,2.31532077502198,0.203844102445465,0.0410455763339996,172.855895996094,48.9989128112793,49.000057220459,300.425231933594,300.425231933594,,,34.0579605102539,0,1,,,,,,1,1,1,48.9998741149902,0,48.999444400563,,,,,,,,,,,,,,,,,,,,,,,,,,,,,,,,,
,3768155455.40234,49.0004177093506,300.425231933594,,,5,,,,25.0300001353025,,,,,0.000708247880656254,1.35409124659518E-7,-0.000867167189414708,0.000154741682528487,0.000708141225351964,1.35388733350503E-7,0.000708141225270859,7.95241635061695E-8,-1.07176626497157E-8,1.09571969667874E-7,1.00015061304225,10.005763053894,2,20,10,5,2.31680362652528,0.204062327245815,0.0410455763339996,172.855895996094,48.9997329711914,49.0008239746094,300.425231933594,300.425231933594,,,34.642505645752,0,1,,,,,,1,1,1,49.0003242492676,0,49.0001118977865,,,,,,,,,,,,,,,,,,,,,,,,,,,,,,,,,
,3768155662.72698,48.9997539520264,300.425231933594,,,5,,,,25.0300001353025,,,,,0.000708690235464486,1.37003775215069E-7,-0.00472062254409078,0.000144369936370789,0.000708583535068557,1.36983147927818E-7,0.000708583532663561,9.11125512696356E-8,-5.83804851711295E-8,1.0228824867673E-7,1.00015058266337,10.005763053894,2,20,10,5,2.31826437428174,0.204033868798521,0.0410455763339996,172.855895996094,48.9992561340332,49.0005378723145,300.425231933594,300.425231933594,,,35.2394866943359,0,1,,,,,,1,1,1,48.9992179870605,0,48.9997865888808,,,,,,,,,,,,,,,,,,,,,,,,,,,,,,,,,
,3768155869.64345,49.0009670257568,300.425231933594,,,5,,,,25.0300001353025,,,,,0.000709327111780485,1.15701195197919E-7,0.000297014613295232,9.84912455031521E-5,0.000709220276126468,1.15683768805139E-7,0.000709220276116939,9.22252777689058E-8,3.67651488196962E-9,6.98371856922154E-8,1.00015063818339,10.005763053894,2,20,10,5,2.32032982875127,0.204420423166464,0.0410455763339996,172.855895996094,48.9997329711914,49.0014038085937,300.425231933594,300.425231933594,,,35.824031829834,0,1,,,,,,1,1,1,49.0006828308105,0,49.0003458658854,,,,,,,,,,,,,,,,,,,,,,,,,,,,,,,,,
,3768156076.45774,48.999927520752,300.425231933594,,,5,,,,25.0300001353025,,,,,0.000709748575620045,1.97623151298849E-7,-0.00603293823796491,0.000222502292683192,0.000709641710243955,1.97593395589415E-7,0.00070964170631007,1.18807809636941E-7,-7.47214653061327E-8,1.57885573596283E-7,1.00015059060727,10.005763053894,2,20,10,5,2.32173109183003,0.204285387224783,0.0410455763339996,172.855895996094,48.9994316101074,49.000171661377,300.425231933594,300.425231933594,,,36.3712615966797,0,1,,,,,,1,1,1,48.9999885559082,0,48.9998363918728,,,,,,,,,,,,,,,,,,,,,,,,,,,,,,,,,
,3768156284.07487,48.9998512268066,300.425231933594,,,5,,,,25.0300001353025,,,,,0.000710056694649493,1.40321696330208E-7,0.00195054019813501,0.000122441497503385,0.000709949785359205,1.40300568872247E-7,0.000709949784947807,1.10140212288881E-7,2.41690680622781E-8,8.69102022943008E-8,1.00015058711544,10.005763053894,2,20,10,5,2.32271051174178,0.204697717480715,0.0410455763339996,172.855895996094,48.9993171691895,49.0003852844238,300.425231933594,300.425231933594,,,36.9433746337891,0,1,,,,,,1,1,1,48.9996910095215,0,48.9997925228543,,,,,,,,,,,,,,,,,,,,,,,,,,,,,,,,,
,3768156489.47528,48.9998474121094,300.425231933594,,,5,,,,25.0300001353025,,,,,0.00071052202211841,1.00994743742491E-7,0.00262912370598922,0.00011063602883565,0.000710415042890365,1.00979537542844E-7,0.000710415042142439,6.34054636354303E-8,3.25987192350263E-8,7.85914383603121E-8,1.00015058694085,10.005763053894,2,20,10,5,2.32423024722565,0.204859390620984,0.0410455763339996,172.855895996094,48.9988670349121,49.0001602172852,300.425231933594,300.425231933594,,,37.490608215332,0,1,,,,,,1,1,1,48.9997444152832,0,48.999584197998,,,,,,,,,,,,,,,,,,,,,,,,,,,,,,,,,
,3768156694.64637,49.0009269714355,300.425231933594,,,5,,,,25.0300001353025,,,,,0.000710899442811123,1.58458908293659E-7,0.00218473730168522,0.000147549517453934,0.000710792371642524,1.58435042217159E-7,0.000710792371125792,1.18768291040939E-7,2.71031238409079E-8,1.04860648698965E-7,1.00015063635018,10.005763053894,2,20,10,5,2.32546644036602,0.204950167364978,0.0410455763339996,172.855895996094,49.0001831054687,49.0011978149414,300.425231933594,300.425231933594,,,38.0254020690918,0,1,,,,,,1,1,1,49.0011253356934,0,49.0006092295927,,,,,,,,,,,,,,,,,,,,,,,,,,,,,,,,,
,3768156899.82037,49.0006160736084,300.425231933594,,,5,,,,25.0300001353025,,,,,0.000710798683370375,1.10968140315154E-7,0.00105625457043068,0.000115705765021696,0.000710691637488565,1.10951428575655E-7,0.0007106916373678,7.44956343099057E-8,1.31016856145616E-8,8.22229893140813E-8,1.00015062212099,10.005763053894,2,20,10,5,2.32514087540766,0.204875326064943,0.0410455763339996,172.855895996094,48.9994583129883,49.0008735656738,300.425231933594,300.425231933594,,,38.5477600097656,0,1,,,,,,1,1,1,49.0004844665527,0,49.0001676222857,,,,,,,,,,,,,,,,,,,,,,,,,,,,,,,,,
,3768157104.8024,49.0003414154053,300.425231933594,,,5,,,,25.0300001353025,,,,,0.000711265728378969,9.0999291987619E-8,-0.0065880762222168,0.00010582625968033,0.000711158621098768,9.09855886890118E-8,0.000711158616397571,5.11381188521647E-8,-8.17715934991611E-8,7.52547018421301E-8,1.00015060955042,10.005763053894,2,20,10,5,2.3266959888639,0.204699520760136,0.0410455763339996,172.855895996094,48.9998512268066,49.0005798339844,300.425231933594,300.425231933594,,,39.0701179504395,0,1,,,,,,1,1,1,49.0004501342773,0,49.0002072652181,,,,,,,,,,,,,,,,,,,,,,,,,,,,,,,,,
,3768157310.88422,48.999755859375,300.425231933594,,,5,,,,25.0300001353025,,,,,0.000711795765093839,1.01454013240324E-7,0.00110287871546344,9.90490639975289E-5,0.000711688597067277,1.01438738316084E-7,0.00071168859693543,7.29518547546307E-8,1.36991976087148E-8,7.04829377865187E-8,1.00015058275066,10.005763053894,2,20,10,5,2.32840232857546,0.205164615109336,0.0410455763339996,172.855895996094,48.9994049072266,49.0000381469727,300.425231933594,300.425231933594,,,39.5551681518555,0,1,,,,,,1,1,1,48.9997901916504,0,48.9997311760398,,,,,,,,,,,,,,,,,,,,,,,,,,,,,,,,,
,3768157517.54622,49.0002670288086,300.425231933594,,,5,,,,25.0300001353025,,,,,0.000712035106316054,1.45601200679008E-7,0.000170029849330788,0.000174494755047172,0.000711927885601051,1.45579275545397E-7,0.000711927885597916,7.59090171787653E-8,2.11270345131297E-9,1.2422216621552E-7,1.00015060614589,10.005763053894,2,20,10,5,2.32918859490318,0.205195677009923,0.0410455763339996,172.855895996094,48.9994583129883,49.0007171630859,300.425231933594,300.425231933594,,,40.0775260925293,0,1,,,,,,1,1,1,49.0003929138184,0,49.0000430836397,,,,,,,,,,,,,,,,,,,,,,,,,,,,,,,,,
,3768157723.76278,48.9999961853027,300.425231933594,,,5,,,,25.0300001353025,,,,,0.000712242189636061,1.2569595133212E-7,1.68692308335494E-5,0.000135975521251631,0.000712134946564014,1.25677025157624E-7,0.000712134946563983,8.01226998442158E-8,2.09669349126886E-10,9.68249328538046E-8,1.00015059374991,10.005763053894,2,20,10,5,2.32986654811118,0.205249131211373,0.0410455763339996,172.855895996094,48.999267578125,49.0008506774902,300.425231933594,300.425231933594,,,40.575008392334,0,1,,,,,,1,1,1,48.9992866516113,0,48.9998775058322,,,,,,,,,,,,,,,,,,,,,,,,,,,,,,,,,
,3768157930.55826,48.9997367858887,300.425231933594,,,5,,,,25.0300001353025,,,,,0.000712396541331293,1.20879116541473E-7,0.00515039041209153,8.68890306476782E-5,0.000712289283473516,1.20860917077638E-7,0.000712289280595711,1.03825409921486E-7,6.4028588536077E-8,6.18679685417499E-8,1.00015058187771,10.005763053894,2,20,10,5,2.33035305617419,0.20550240248307,0.0410455763339996,172.855895996094,48.9992523193359,49.0001792907715,300.425231933594,300.425231933594,,,41.0600547790527,0,1,,,,,,1,1,1,48.9997329711914,0,48.9996939266429,,,,,,,,,,,,,,,,,,,,,,,,,,,,,,,,,
,3768158138.34566,49.0002365112305,300.425231933594,,,5,,,,25.0300001353025,,,,,0.000712942848098764,1.44586856578931E-7,0.00258962315417133,0.000173948151757673,0.000712835491688345,1.44565084390659E-7,0.000712835490960251,7.43316466579924E-8,3.22183467866294E-8,1.2399141071054E-7,1.00015060474916,10.005763053894,2,20,10,5,2.33214929493851,0.205555758940188,0.0410455763339996,172.855895996094,48.9994010925293,49.0004196166992,300.425231933594,300.425231933594,,,41.5326652526855,0,1,,,,,,1,1,1,49.0002555847168,0,49.0000480203068,,,,,,,,,,,,,,,,,,,,,,,,,,,,,,,,,
,3768158346.02184,49.0003700256348,300.425231933594,,,5,,,,25.0300001353025,,,,,0.000712720576792335,1.38886407519106E-7,0.00109420050057363,0.000106824684792492,0.000712613249498084,1.38865492867821E-7,0.000712613249368135,1.16154913549271E-7,1.36090612763331E-8,7.61029642509678E-8,1.00015061085986,10.005763053894,2,20,10,5,2.33142757275418,0.205430823189709,0.0410455763339996,172.855895996094,48.9995498657227,49.0007247924805,300.425231933594,300.425231933594,,,42.0052757263184,0,1,,,,,,1,1,1,49.0002937316895,0,49.0000276004567,,,,,,,,,,,,,,,,,,,,,,,,,,,,,,,,,
,3768158551.07911,49.0000629425049,300.425231933594,,,5,,,,25.0300001353025,,,,,0.000712946283187854,1.10713522941698E-7,-0.00311459136241066,0.000111356605747485,0.000712838931922042,1.10696852349382E-7,0.000712838930868824,7.71631724261651E-8,-3.87498345939083E-8,7.93702585430515E-8,1.00015059680526,10.005763053894,2,20,10,5,2.33218098473539,0.205324565190577,0.0410455763339996,172.855895996094,48.9992218017578,49.0003547668457,300.425231933594,300.425231933594,,,42.453010559082,0,1,,,,,,1,1,1,49.000129699707,0,48.9999991522895,,,,,,,,,,,,,,,,,,,,,,,,,,,,,,,,,
,3768158756.349,49.000020980835,300.425231933594,,,5,,,,25.0300001353025,,,,,0.000712879753023154,1.22031405904652E-7,0.00347257489645614,7.4420809235216E-5,0.00071277241314374,1.22013031366255E-7,0.000712772411834621,1.09892872282199E-7,4.31996144967174E-8,5.30163790233831E-8,1.00015059488476,10.005763053894,2,20,10,5,2.33193973321271,0.205573503720172,0.0410455763339996,172.855895996094,48.9990539550781,49.0003700256348,300.425231933594,300.425231933594,,,42.9256210327148,0,1,,,,,,1,1,1,49.0002136230469,0,48.9998539195341,,,,,,,,,,,,,,,,,,,,,,,,,,,,,,,,,
,3768158968.64075,48.9991588592529,300.425231933594,,,5,,,,25.0300001353025,,,,,0.000713285194014192,1.71400011206099E-7,0.00401425077991835,0.000122629463796284,0.000713177739407239,1.71374190228753E-7,0.000713177737656862,1.47397180739027E-7,4.99665825061353E-8,8.74253063291595E-8,1.00015067016399,10.005763053894,2,20,10,5,2.33326404822528,0.205712483674868,0.0410455763339996,172.855895996094,48.9988327026367,49.0016441345215,300.425231933594,300.425231933594,,,43.3733558654785,0,1,,,,,,1,1,1,48.9992637634277,0,49.0001417461194,,,,,,,,,,,,,,,,,,,,,,,,,,,,,,,,,
,3768159175.7534,48.9996471405029,300.425231933594,,,5,,,,25.0300001353025,,,,,0.000713228939451155,9.89838293472942E-8,0.00426655521674579,8.52639241095755E-5,0.000713121559193601,9.89689268265171E-8,0.000713121557216435,7.80979783769875E-8,5.31029079558076E-8,6.0791070484242E-8,1.00015057777481,10.005763053894,2,20,10,5,2.33307912530921,0.205706532412954,0.0410455763339996,172.855895996094,48.9991798400879,49.0004539489746,300.425231933594,300.425231933594,,,43.8335304260254,0,1,,,,,,1,1,1,48.9995460510254,0,48.9997789719526,,,,,,,,,,,,,,,,,,,,,,,,,,,,,,,,,
,3768159381.86358,49.0010395050049,300.425231933594,,,5,,,,25.0300001353025,,,,,0.000713454407471932,1.05411484343152E-7,0.0055297730139543,0.000113883560392316,0.00071334694781725,1.05395607390696E-7,0.00071334694449494,6.71535365130211E-8,6.88470726644349E-8,8.12319924109216E-8,1.00015064150062,10.005763053894,2,20,10,5,2.33381212824985,0.205823010711711,0.0410455763339996,172.855895996094,48.9995460510254,49.0015449523926,300.425231933594,300.425231933594,,,44.2812690734863,0,1,,,,,,1,1,1,49.0006408691406,0,49.0003693524529,,,,,,,,,,,,,,,,,,,,,,,,,,,,,,,,,
,3768159587.6432,48.9993915557861,300.425231933594,,,5,,,,25.0300001353025,,,,,0.000713581796780735,1.50576172347351E-7,-0.00111993015528977,0.000173825775747669,0.000713474289893921,1.50553486825396E-7,0.000713474289757625,8.53645744209094E-8,-1.39459028049847E-8,1.24013071203086E-7,1.00015068081406,10.005763053894,2,20,10,5,2.33425271288698,0.205588854642911,0.0410455763339996,172.855895996094,48.9987945556641,49.0001335144043,300.425231933594,300.425231933594,,,44.7165641784668,0,1,,,,,,1,1,1,48.9997329711914,0,48.9997355143229,,,,,,,,,,,,,,,,,,,,,,,,,,,,,,,,,
,3768159795.71664,49.0005378723145,300.425231933594,,,5,,,,25.0300001353025,,,,,0.000713643116807167,1.52182533972225E-7,-0.00137459710864629,0.000163493909217179,0.000713535645108728,1.52159615912745E-7,0.00071353564490338,9.7701610423473E-8,-1.71186087862629E-8,1.16648806403555E-7,1.00015061854187,10.005763053894,2,20,10,5,2.33445421569065,0.205596142420777,0.0410455763339996,172.855895996094,48.9995002746582,49.0010108947754,300.425231933594,300.425231933594,,,45.1518630981445,0,1,,,,,,1,1,1,49.0004272460937,0,49.0001814100477,,,,,,,,,,,,,,,,,,,,,,,,,,,,,,,,,
,3768160004.38237,49.0006580352783,300.425231933594,,,5,,,,25.0300001353025,,,,,0.000713838574851224,1.26615049219018E-7,0.000281895338222427,0.00015308546598358,0.000713731069792951,1.2659598082075E-7,0.000713731069784312,6.39480827619829E-8,3.51155814665873E-9,1.09257425702028E-7,1.0001506240415,10.005763053894,2,20,10,5,2.33508764734265,0.205719962027412,0.0410455763339996,172.855895996094,48.9994049072266,49.0007781982422,300.425231933594,300.425231933594,,,45.5747261047363,0,1,,,,,,1,1,1,49.0006713867188,0,49.0000544096294,,,,,,,,,,,,,,,,,,,,,,,,,,,,,,,,,
,3768160209.74039,49.000114440918,300.425231933594,,,5,,,,25.0300001353025,,,,,0.000714008242472457,1.12556054103788E-7,0.000302923255310894,0.000107085215714055,0.000713900729620653,1.12539105808734E-7,0.000713900729610675,8.2597664307837E-8,3.77439900150281E-9,7.64374004471581E-8,1.00015059916224,10.005763053894,2,20,10,5,2.33564258323289,0.205769718778137,0.0410455763339996,172.855895996094,48.9994468688965,49.0004577636719,300.425231933594,300.425231933594,,,46.0349006652832,0,1,,,,,,1,1,1,48.9998779296875,0,48.9999171362983,,,,,,,,,,,,,,,,,,,,,,,,,,,,,,,,,
,3768160415.26189,49.0001926422119,300.425231933594,,,5,,,,25.0300001353025,,,,,0.000714190847596953,1.68258602212902E-7,0.00337774659450307,0.000162644151261011,0.000714083304693706,1.68233265821881E-7,0.000714083303452831,1.2172592047982E-7,4.2097209772193E-8,1.16125931696741E-7,1.00015060274136,10.005763053894,2,20,10,5,2.33622886687319,0.20594771779322,0.0410455763339996,172.855895996094,48.9996566772461,49.0006103515625,300.425231933594,300.425231933594,,,46.4577598571777,0,1,,,,,,1,1,1,49.0002937316895,0,49.0000065074247,,,,,,,,,,,,,,,,,,,,,,,,,,,,,,,,,
,3768160620.30036,48.9998054504395,300.425231933594,,,5,,,,25.0300001353025,,,,,0.000714121557109925,1.46046213621085E-7,-0.00229272775285239,0.000157886919900036,0.000714013955380201,1.4602420780842E-7,0.000714013954808543,9.28242248248486E-8,-2.85717311972939E-8,1.12724143606162E-7,1.00015069975722,10.005763053894,2,20,10,5,2.33602257569074,0.205696547280163,0.0410455763339996,172.855895996094,48.9996871948242,49.0004272460937,300.425231933594,300.425231933594,,,46.8930587768555,0,1,,,,,,1,1,1,48.9998245239258,0,48.9999012947082,,,,,,,,,,,,,,,,,,,,,,,,,,,,,,,,,
,3768160825.38939,49.0007743835449,300.425231933594,,,5,,,,25.0300001353025,,,,,0.000714474416588864,1.17043085278487E-7,0.00107991082835124,9.22142196517995E-5,0.000714366811968509,1.1702545780791E-7,0.00071436681184162,9.67355304223611E-8,1.34643853730574E-8,6.58573832539328E-8,1.00015062936653,10.005763053894,2,20,10,5,2.33716472595798,0.205935756670235,0.0410455763339996,172.855895996094,48.9995994567871,49.0011825561523,300.425231933594,300.425231933594,,,47.3159217834473,0,1,,,,,,1,1,1,49.0005722045898,0,49.0001380022834,,,,,,,,,,,,,,,,,,,,,,,,,,,,,,,,,
,3768161030.60177,49.0009746551514,300.425231933594,,,5,,,,25.0300001353025,,,,,0.000714350225885064,1.57926107809241E-7,-0.00209887119932972,0.000113763483366983,0.000714242633422867,1.57902321635221E-7,0.000714242632943639,1.35407477029958E-7,-2.61642882779368E-8,8.12278175391533E-8,1.00015063853257,10.005763053894,2,20,10,5,2.33676989738768,0.205770315261202,0.0410455763339996,172.855895996094,48.9996643066406,49.0010757446289,300.425231933594,300.425231933594,,,47.7512168884277,0,1,,,,,,1,1,1,49.0008735656738,0,49.0004837933709,,,,,,,,,,,,,,,,,,,,,,,,,,,,,,,,,
,3768161235.56205,49.0006885528564,300.425231933594,,,5,,,,25.0300001353025,,,,,0.000714627082275625,1.30531903965262E-7,-0.00185562632621039,0.000151820294217626,0.000714519457469223,1.30512245501089E-7,0.000714519457094492,7.25751098232564E-8,-2.3140990957893E-8,1.08472575611898E-7,1.00015062543823,10.005763053894,2,20,10,5,2.33767467115623,0.205859989349506,0.0410455763339996,172.855895996094,48.999813079834,49.0007667541504,300.425231933594,300.425231933594,,,48.1740798950195,0,1,,,,,,1,1,1,49.0007514953613,0,49.0002838583554,,,,,,,,,,,,,,,,,,,,,,,,,,,,,,,,,
,3768161441.92278,49.0011672973633,300.425231933594,,,5,,,,25.0300001353025,,,,,0.000714711297508038,1.90106175814747E-7,0.000534796818127958,0.000119952650002889,0.000714603644363123,1.90077541136989E-7,0.000714603644331994,1.69672728739172E-7,6.67008562358824E-9,8.56775161106295E-8,1.00015064734943,10.005763053894,2,20,10,5,2.33794156286613,0.205981788602723,0.0410455763339996,172.855895996094,48.9999008178711,49.0016746520996,300.425231933594,300.425231933594,,,48.5969429016113,0,1,,,,,,1,1,1,49.001033782959,0,49.000711777631,,,,,,,,,,,,,,,,,,,,,,,,,,,,,,,,,
,3768161648.36289,49.000862121582,300.425231933594,,,5,,,,25.0300001353025,,,,,0.000714334120051032,1.22094920179086E-7,0.00147786694274465,0.000107022258348702,0.000714226533692657,1.22076531378286E-7,0.000714226533455065,9.51950940285577E-8,1.84225049842882E-8,7.64236454655743E-8,1.00015063338213,10.005763053894,2,20,10,5,2.3367043625631,0.205911547685657,0.0410455763339996,172.855895996094,48.9993782043457,49.0012550354004,300.425231933594,300.425231933594,,,49.0571174621582,0,1,,,,,,1,1,1,49.0007362365723,0,49.0001599928912,,,,,,,,,,,,,,,,,,,,,,,,,,,,,,,,,
,3768161856.15028,48.9999008178711,300.425231933594,,,5,,,,25.0300001353025,,,,,0.000714800327825343,2.19755856982968E-7,-0.00334478597823207,0.000197578651822075,0.000714692702690687,2.19722769066275E-7,0.000714692701472874,1.6836019676569E-7,-4.17219933066971E-8,1.411840621004E-7,1.00015058938513,10.005763053894,2,20,10,5,2.3382467393543,0.20584912671957,0.0410455763339996,172.855895996094,48.9992828369141,49.0000381469727,300.425231933594,300.425231933594,,,49.4551048278809,0,1,,,,,,1,1,1,48.9998321533203,0,48.9996998310089,,,,,,,,,,,,,,,,,,,,,,,,,,,,,,,,,
,3768162061.1613,48.9997901916504,300.425231933594,,,5,,,,25.0300001353025,,,,,0.000714972423447877,1.20724793731763E-7,-0.000413672968276657,0.000101957199496147,0.000714864776020269,1.20706617207652E-7,0.000714864776001637,9.62289791495162E-8,-5.16129174475481E-9,7.28702340435141E-8,1.00015058432198,10.005763053894,2,20,10,5,2.33879916028888,0.206018334374253,0.0410455763339996,172.855895996094,48.9995079040527,49.0000686645508,300.425231933594,300.425231933594,,,49.8530921936035,0,1,,,,,,1,1,1,48.999885559082,0,48.9997630399816,,,,,,,,,,,,,,,,,,,,,,,,,,,,,,,,,
,3768162266.157,48.9998626708984,300.425231933594,,,5,,,,25.0300001353025,,,,,0.000714972543214896,1.95009127375506E-7,0.00240158288595271,0.000247334948579433,0.000714864893398239,1.94979765832873E-7,0.000714864892770262,8.21970944971871E-8,2.99639398894802E-8,1.76807089056018E-7,1.00015058763922,10.005763053894,2,20,10,5,2.33878942636301,0.206133287451942,0.0410455763339996,172.855895996094,48.9988555908203,49.0000762939453,300.425231933594,300.425231933594,,,50.2510795593262,0,1,,,,,,1,1,1,48.9997024536133,0,48.9994521141052,,,,,,,,,,,,,,,,,,,,,,,,,,,,,,,,,
,3768162473.91827,49.0000782012939,300.425231933594,,,5,,,,25.0300001353025,,,,,0.000715058560855188,1.61429853353727E-7,-0.00369958462339692,0.000180676023261356,0.000714950891035784,1.61405546081416E-7,0.00071495088954537,9.67885947085758E-8,-4.61643308390281E-8,1.29165468451049E-7,1.00015059750362,10.005763053894,2,20,10,5,2.33909274357975,0.205909006782347,0.0410455763339996,172.855895996094,48.9996566772461,49.0004501342773,300.425231933594,300.425231933594,,,50.6615028381348,0,1,,,,,,1,1,1,49.0002174377441,0,48.9999995761447,,,,,,,,,,,,,,,,,,,,,,,,,,,,,,,,,
,3768162680.61114,49.0010643005371,300.425231933594,,,5,,,,25.0300001353025,,,,,0.00071529104761089,1.06513357514835E-7,-0.00014557414817773,0.000118675224818528,0.000715183310512155,1.06497314478712E-7,0.000715183310509847,6.43349587529681E-8,-1.81710070276383E-9,8.48686695632238E-8,1.00015064263546,10.005763053894,2,20,10,5,2.33984047136098,0.206121088861969,0.0410455763339996,172.855895996094,48.9999694824219,49.0012512207031,300.425231933594,300.425231933594,,,51.0719261169434,0,1,,,,,,1,1,1,49.0011329650879,0,49.0004880693224,,,,,,,,,,,,,,,,,,,,,,,,,,,,,,,,,
,3768162886.98228,49.0006656646729,300.425231933594,,,5,,,,25.0300001353025,,,,,0.000715523488857097,1.33568919621112E-7,0.00207975841073793,0.000134304054766416,0.000715415729798715,1.33548803913897E-7,0.000715415729327403,9.27651593016441E-8,2.59686122353327E-8,9.60724114747471E-8,1.00015062439068,10.005763053894,2,20,10,5,2.3405928166574,0.206278979106627,0.0410455763339996,172.855895996094,48.9997291564941,49.0010871887207,300.425231933594,300.425231933594,,,51.469913482666,0,1,,,,,,1,1,1,49.0007209777832,0,49.0003200330232,,,,,,,,,,,,,,,,,,,,,,,,,,,,,,,,,
,3768163093.5239,48.9998893737793,300.425231933594,,,5,,,,25.0300001353025,,,,,0.000715287273884416,1.15784991862474E-7,0.00399767581016519,0.000102319126377041,0.00071517957580643,1.15767558557649E-7,0.000715179574065605,8.9717956673527E-8,4.98999422313996E-8,7.31629405144829E-8,1.00015058886136,10.005763053894,2,20,10,5,2.33981321502009,0.20628920706676,0.0410455763339996,172.855895996094,48.9993896484375,48.999927520752,300.425231933594,300.425231933594,,,51.8430290222168,0,1,,,,,,1,1,1,48.9998512268066,0,48.9996876436121,,,,,,,,,,,,,,,,,,,,,,,,,,,,,,,,,
,3768163299.8115,48.9996948242188,300.425231933594,,,5,,,,25.0300001353025,,,,,0.000715567823939672,1.27007397513575E-7,-0.00241277450801114,0.000151098463325277,0.000715460007912662,1.26988261056424E-7,0.00071546000727829,6.66367744586086E-8,-3.01286356997511E-8,1.08099762885434E-7,1.00015069469407,10.005763053894,2,20,10,5,2.34075401149584,0.206108228361462,0.0410455763339996,172.855895996094,48.9995307922363,49.0001640319824,300.425231933594,300.425231933594,,,52.2534523010254,0,1,,,,,,1,1,1,48.9996376037598,0,48.9997374216715,,,,,,,,,,,,,,,,,,,,,,,,,,,,,,,,,
,3768163506.52729,49.0009918212891,300.425231933594,,,5,,,,25.0300001353025,,,,,0.000715659304464614,1.32667383038025E-7,-0.000804888077243326,0.000150575193130437,0.000715551514272346,1.32647401123955E-7,0.000715551514201741,7.7381831816126E-8,-1.00520297893979E-8,1.07737575291632E-7,1.00015063931823,10.005763053894,2,20,10,5,2.34104747592565,0.20620026949271,0.0410455763339996,172.855895996094,48.9997711181641,49.0012817382812,300.425231933594,300.425231933594,,,52.6390037536621,0,1,,,,,,1,1,1,49.0008544921875,0,49.0003614986644,,,,,,,,,,,,,,,,,,,,,,,,,,,,,,,,,
,3768163714.17823,49.0004558563232,300.425231933594,,,5,,,,25.0300001353025,,,,,0.000715562447258708,1.43263690470256E-7,0.00626464117744963,0.000148322011478707,0.000715454689202257,1.43242116089286E-7,0.00071545468492565,9.62265564001642E-8,7.82268246585601E-8,1.06107274326987E-7,1.00015061478816,10.005763053894,2,20,10,5,2.34070518222858,0.20646117576032,0.0410455763339996,172.855895996094,48.99951171875,49.0010147094727,300.425231933594,300.425231933594,,,53.0369911193848,0,1,,,,,,1,1,1,49.0007972717285,0,49.0001420413747,,,,,,,,,,,,,,,,,,,,,,,,,,,,,,,,,
,3768163919.70407,48.9998569488525,300.425231933594,,,5,,,,25.0300001353025,,,,,0.000715722066902716,1.25153365851439E-7,0.00072261429945808,0.00012813497159198,0.000715614304421432,1.25134522171931E-7,0.000715614304364519,8.51609404784158E-8,9.02532671084252E-9,9.16856742137462E-8,1.00015058737733,10.005763053894,2,20,10,5,2.34124728395475,0.206280774428261,0.0410455763339996,172.855895996094,48.9995079040527,49.0004539489746,300.425231933594,300.425231933594,,,53.3727912902832,0,1,,,,,,1,1,1,48.999942779541,0,48.9999910990397,,,,,,,,,,,,,,,,,,,,,,,,,,,,,,,,,
,3768164127.36295,48.9998970031738,300.425231933594,,,5,,,,25.0300001353025,,,,,0.000715631113726563,1.55507130770989E-7,0.000904541806583836,0.000131185975779126,0.000715523363628112,1.55483716600854E-7,0.000715523363538944,1.23967705737771E-7,1.12961338769193E-8,9.384665184293E-8,1.00015058921054,10.005763053894,2,20,10,5,2.34094910602476,0.206261992130593,0.0410455763339996,172.855895996094,48.998966217041,49.0006256103516,300.425231933594,300.425231933594,,,53.5717811584473,0,1,,,,,,1,1,1,49.0002822875977,0,48.9997968673706,,,,,,,,,,,,,,,,,,,,,,,,,,,,,,,,,
,3768164340.82231,48.9994220733643,300.425231933594,,,5,,,,25.0300001353025,,,,,0.000715873112289094,8.79216849667888E-8,0.00320164543598178,8.54788928867915E-5,0.00071576525919743,8.79084387288938E-8,0.000715765258079945,6.31310158010645E-8,3.99964289451359E-8,6.11749004386393E-8,1.00015068221079,10.005763053894,2,20,10,5,2.34173244932287,0.206425630746755,0.0410455763339996,172.855895996094,48.9989280700684,49.000186920166,300.425231933594,300.425231933594,,,53.9946479797363,0,1,,,,,,1,1,1,48.9993553161621,0,48.9995422363281,,,,,,,,,,,,,,,,,,,,,,,,,,,,,,,,,
,3768164548.44898,49.0005893707275,300.425231933594,,,5,,,,25.0300001353025,,,,,0.000716043718566065,1.27174907944441E-7,0.00539908084425722,0.000126674176870198,0.000715935883659748,1.27155755630233E-7,0.000715935880481128,8.91388138995489E-8,6.74638820225944E-8,9.06799759951293E-8,1.00015062089885,10.005763053894,2,20,10,5,2.342282608954,0.206564653195923,0.0410455763339996,172.855895996094,48.999828338623,49.0006904602051,300.425231933594,300.425231933594,,,54.4175071716309,0,1,,,,,,1,1,1,49.000602722168,0,49.000181983499,,,,,,,,,,,,,,,,,,,,,,,,,,,,,,,,,
,3768164753.58604,49.0010719299316,300.425231933594,,,5,,,,25.0300001353025,,,,,0.000716211219127545,1.1135847050717E-7,1.27571532448911E-5,0.000119364299587262,0.000716103343182613,1.11341697661519E-7,0.000716103343182596,7.13572251371724E-8,1.59443508157062E-10,8.54699950793963E-8,1.00015064298465,10.005763053894,2,20,10,5,2.34284994074934,0.206392724698917,0.0410455763339996,172.855895996094,48.9996566772461,49.0013732910156,300.425231933594,300.425231933594,,,54.8030586242676,0,1,,,,,,1,1,1,49.0008125305176,0,49.0003698012408,,,,,,,,,,,,,,,,,,,,,,,,,,,,,,,,,
,3768164961.52234,49.0015125274658,300.425231933594,,,5,,,,25.0300001353025,,,,,0.000716038996688446,1.80467821046511E-7,0.00239994558780232,0.000110042560086159,0.000715931132248925,1.80440635292021E-7,0.000715931131620868,1.62353483800128E-7,2.99881732321379E-8,7.87411529160564E-8,1.00015066314994,10.005763053894,2,20,10,5,2.34227797263415,0.206440681683963,0.0410455763339996,172.855895996094,49.0001487731934,49.0016403198242,300.425231933594,300.425231933594,,,55.1761665344238,0,1,,,,,,1,1,1,49.0014572143555,0,49.0008580824908,,,,,,,,,,,,,,,,,,,,,,,,,,,,,,,,,
,3768165169.32116,48.9999904632568,300.425231933594,,,5,,,,25.0300001353025,,,,,0.000716095214446075,1.3791510889565E-7,-0.00285227578050229,0.000151322603928555,0.00071598739140742,1.37894342905573E-7,0.000715987390520237,8.53110859478109E-8,-3.56430004472949E-8,1.08336828547659E-7,1.00015059348803,10.005763053894,2,20,10,5,2.34248078500126,0.206242166206792,0.0410455763339996,172.855895996094,48.9993515014648,49.0003204345703,300.425231933594,300.425231933594,,,55.5492820739746,0,1,,,,,,1,1,1,48.999698638916,0,48.9999073876275,,,,,,,,,,,,,,,,,,,,,,,,,,,,,,,,,
,3768165374.36006,48.9997253417969,300.425231933594,,,5,,,,25.0300001353025,,,,,0.000716159072429763,1.24217334919342E-7,0.00155899738337872,0.000121986371709159,0.000716051248463283,1.2419863292104E-7,0.000716051248198214,8.8303059845881E-8,1.94834948065711E-8,8.73376782454744E-8,1.00015058135393,10.005763053894,2,20,10,5,2.34267378912075,0.206440924281906,0.0410455763339996,172.855895996094,48.9989929199219,49.0002136230469,300.425231933594,300.425231933594,,,55.9223976135254,0,1,,,,,,1,1,1,48.9996032714844,0,48.9996275650828,,,,,,,,,,,,,,,,,,,,,,,,,,,,,,,,,
,3768165528.47856,48.9999713897705,300.425231933594,,,5,,,,25.0300001353025,,,,,0.00071631112727382,1.14159525978345E-7,-0.00240374041042468,0.000100585009807453,0.000716203272350115,1.14142336985328E-7,0.000716203271719832,8.85476614253551E-8,-3.00470080336069E-8,7.20262781807643E-8,1.00015059261507,10.005763053894,2,20,10,5,2.34318546100023,0.206322694081817,0.0410455763339996,172.855895996094,48.999397277832,49.0002784729004,300.425231933594,300.425231933594,,,56.2084541320801,0,1,,,,,,1,1,1,48.9998168945313,0,48.9998294605928,,,,,,,,,,,,,,,,,,,,,,,,,,,,,,,,,