File: Experimental_Data/Fig3C/Lifetime_260Oe_49p5K.dat
[Header]
; MPMS3 Data File (default extension .dat)
; Copyright (c) 2007, Quantum Design, Inc. All rights reserved.
TITLE,260Oe_49p5K
FILEOPENTIME,3768534404.212,06/01/2019,7:06 am
BYAPP,SQUID AC,0.9.1.0
INFO,MPMS3 Measurement Release 1.1.16 Build 347, MultiVu Release 2.3.3.2,APPNAME
INFO,0,MOMENT_UNITS
INFO,,SAMPLE_MATERIAL
INFO,,SAMPLE_COMMENT
INFO,,SAMPLE_MASS
INFO,,SAMPLE_VOLUME
INFO,,SAMPLE_MOLECULAR_WEIGHT
INFO,,SAMPLE_SIZE
INFO,,SAMPLE_SHAPE
INFO,Quartz,SAMPLE_HOLDER
INFO,Standard,SAMPLE_HOLDER_DETAIL
INFO,66.2,SAMPLE_OFFSET
DATATYPE,COMMENT,1
DATATYPE,TIME,2
STARTUPAXIS,X,2
STARTUPAXIS,Y1,5
FIELDGROUP, VSM,2,3,4,5,6,8,9,10,11,14,15
FIELDGROUP, DC, 2,3,4,14,56,57,58,59,60,61,62,63,64,65,66,67,68,69
FIELDGROUP, AC, 2,3,4,11,16,17,18,19,20,21,22,23,24,25,26,27,28,29,30
STARTUPGROUP, All
[Data]
Comment,Time Stamp (sec),Temperature (K),Magnetic Field (Oe),Moment (emu),M. Std. Err. (emu),Transport Action,Averaging Time (sec),Frequency (Hz),Peak Amplitude (mm),Center Position (mm),Lockin Signal' (V),Lockin Signal (V),Range,M. Quad. Signal (emu),AC Moment (emu),AC M. Std Err. (emu),AC Phase (deg),AC Phase Std. Err. (deg),AC Susceptibility (emu/Oe),AC Suscept. Std Err. (emu/Oe),AC X' (emu/Oe),AC X' Std Err. (emu/Oe),AC X'' (emu/Oe),AC X'' Std Err. (emu/Oe),AC Drive (Oe),AC Frequency (Hz),AC Averaging Time (sec),AC Cycles,AC Range,AC Measure Type,AC Signal' (V),AC Signal'' (V),AC Trim Coil Ratio,AC Trim Coil Phase,Min. Temperature (K),Max. Temperature (K),Min. Field (Oe),Max. Field (Oe),Mass (grams),Motor Lag (deg),Pressure (Torr),Measure Count,Measurement Number,SQUID Status (code),Motor Status (code),Measure Status (code),Motor Current (amps),Motor Temp. (C),Temp. Status (code),Field Status (code),Chamber Status (code),Chamber Temp (K),Redirection State,Average Temp (K),Rotation Angle (deg),Rotator state,DC Moment Fixed Ctr (emu),DC Moment Err Fixed Ctr (emu),DC Moment Free Ctr (emu),DC Moment Err Free Ctr (emu),DC Fixed Fit,DC Free Fit,DC Calculated Center (mm),DC Calculated Center Err (mm),DC Scan Length (mm),DC Scan Time (s),DC Number of Points,DC Squid Drift,DC Min V (V),DC Max V (V),DC Scans per Measure,Map 01,Map 02,Map 03,Map 04,Map 05,Map 06,Map 07,Map 08,Map 09,Map 10,Map 11,Map 12,Map 13,Map 14,Map 15,Map 16
,3768534408.58556,49.4741077423096,259.783264160156,,,5,,,,25.0300001353025,,,,,0.000600093724330505,1.11545856304673E-7,0.0513963853952255,9.27864341263715E-5,0.000600003703689165,1.11529123202632E-7,0.000600003462285535,9.66577053892633E-8,5.38224939422836E-7,5.56420103090297E-8,1.00015003347611,10.005763053894,2,20,10,5,1.96285931152331,0.17460418752435,0.0410455763339996,172.855895996094,49.417652130127,49.4835319519043,259.783264160156,259.783264160156,,,38.2243957519531,0,1,,,,,,1,1,3,49.468334197998,0,49.4463691711426,,,,,,,,,,,,,,,,,,,,,,,,,,,,,,,,,
,3768534614.6012,49.4991550445557,259.783264160156,,,5,,,,25.0300001353025,,,,,0.000615076081287085,1.01661169533299E-7,-0.000544676847205494,9.81609797583512E-5,0.000614983461014573,1.01645861044622E-7,0.000614983460986784,8.17879883958793E-8,-5.84628144464658E-9,6.03540058459928E-8,1.00015060611932,10.005763053894,2,20,10,5,2.01202684207925,0.177139455220302,0.0410455763339996,172.855895996094,49.4984321594238,49.4994773864746,259.783264160156,259.783264160156,,,38.4109535217285,0,1,,,,,,1,1,3,49.4991416931152,0,49.49899224674,,,,,,,,,,,,,,,,,,,,,,,,,,,,,,,,,
,3768534819.60439,49.5001678466797,259.783264160156,,,5,,,,25.0300001353025,,,,,0.000625425207283418,9.04182909376209E-8,-0.00113407075371885,0.000101342202534615,0.000625331071361716,9.04046816218194E-8,0.000625331071239222,6.44821234341254E-8,-1.23773458604358E-8,6.33645185933638E-8,1.00015053773275,10.005763053894,2,20,10,5,2.04588258738154,0.180098911701627,0.0410455763339996,172.855895996094,49.4997673034668,49.5006408691406,259.783264160156,259.783264160156,,,38.5228881835937,0,1,,,,,,1,1,3,49.5004959106445,0,49.5002739850213,,,,,,,,,,,,,,,,,,,,,,,,,,,,,,,,,
,3768535024.79004,49.4996528625488,259.783264160156,,,5,,,,25.0300001353025,,,,,0.000633247991713282,1.20174843804574E-7,-0.00230756505745511,0.000132709023969233,0.000633152693265304,1.20156758510582E-7,0.000633152692751803,8.59023242394088E-8,-2.54999764910089E-8,8.40145065214197E-8,1.00015051416347,10.005763053894,2,20,10,5,2.07147610946831,0.182309155412042,0.0410455763339996,172.855895996094,49.4992752075195,49.4999847412109,259.783264160156,259.783264160156,,,38.5850715637207,0,1,,,,,,1,1,3,49.499683380127,0,49.4996708140654,,,,,,,,,,,,,,,,,,,,,,,,,,,,,,,,,
,3768535231.16121,49.4993438720703,259.783264160156,,,5,,,,25.0300001353025,,,,,0.000639583858398458,9.79552744203736E-8,8.01788196573838E-5,7.37368218281482E-5,0.000639487615498317,9.79405343678058E-8,0.000639487615497691,8.58525421338006E-8,8.94888988890465E-10,4.71347990492728E-8,1.00015050002191,10.005763053894,2,20,10,5,2.09219427364248,0.184220415671688,0.0410455763339996,172.855895996094,49.498420715332,49.5000343322754,259.783264160156,259.783264160156,,,38.6472587585449,0,1,,,,,,1,1,3,49.4987335205078,0,49.4995647006565,,,,,,,,,,,,,,,,,,,,,,,,,,,,,,,,,
,3768535437.89425,49.4992504119873,259.783264160156,,,5,,,,25.0300001353025,,,,,0.000645009358096478,1.06068766670499E-7,-0.000851334407896864,8.80897542485465E-5,0.000644912301539509,1.06052806174475E-7,0.000644912301468318,8.95641330607308E-8,-9.58248647670424E-9,5.67931665481026E-8,1.00015049574452,10.005763053894,2,20,10,5,2.10994508305075,0.185748826097587,0.0410455763339996,172.855895996094,49.4992027282715,49.5002250671387,259.783264160156,259.783264160156,,,38.7218818664551,0,1,,,,,,1,1,3,49.4992790222168,0,49.4996133692124,,,,,,,,,,,,,,,,,,,,,,,,,,,,,,,,,
,3768535642.8874,49.5009956359863,259.783264160156,,,5,,,,25.0300001353025,,,,,0.000649341487578355,9.73177062232513E-8,-0.00303463281854466,8.50435258309161E-5,0.000649243727302764,9.73030547556303E-8,0.000649243726392129,8.01300316673261E-8,-3.43867617812272E-8,5.52002037113136E-8,1.00015057561818,10.005763053894,2,20,10,5,2.12412340547856,0.186915440909338,0.0410455763339996,172.855895996094,49.5001068115234,49.5015754699707,259.783264160156,259.783264160156,,,38.746753692627,0,1,,,,,,1,1,3,49.500415802002,0,49.5005695118624,,,,,,,,,,,,,,,,,,,,,,,,,,,,,,,,,
,3768535848.66104,49.4997825622559,259.783264160156,,,5,,,,25.0300001353025,,,,,0.000653047151009729,1.05005383724187E-7,-0.00417808443717771,0.000129654883482227,0.000652948869081026,1.04989580682062E-7,0.000652948867344992,6.21031225903467E-8,-4.76138998185644E-8,8.46523137092165E-8,1.00015052009944,10.005763053894,2,20,10,5,2.13624910855986,0.187939499289415,0.0410455763339996,172.855895996094,49.4993591308594,49.499942779541,259.783264160156,259.783264160156,,,38.8089408874512,0,1,,,,,,1,1,3,49.499870300293,0,49.4997080634622,,,,,,,,,,,,,,,,,,,,,,,,,,,,,,,,,
,3768536053.58318,49.4999084472656,259.783264160156,,,5,,,,25.0300001353025,,,,,0.000656212141265624,8.09210452590335E-8,-0.00134062465724316,6.63836500070727E-5,0.000656113379234421,8.09088663822734E-8,0.000656113379054816,6.81931381037607E-8,-1.53519470638792E-8,4.35423997366475E-8,1.00015052586082,10.005763053894,2,20,10,5,2.14659307569936,0.188956653948852,0.0410455763339996,172.855895996094,49.4994697570801,49.5002021789551,259.783264160156,259.783264160156,,,38.8462524414063,0,1,,,,,,1,1,3,49.4996871948242,0,49.499859978171,,,,,,,,,,,,,,,,,,,,,,,,,,,,,,,,,
,3768536260.10898,49.5000438690186,259.783264160156,,,5,,,,25.0300001353025,,,,,0.000659118511440213,9.30250498556629E-8,-0.00369521099395254,9.62005881951479E-5,0.000659019307907094,9.30110487110217E-8,0.000659019306536523,6.8065057683195E-8,-4.25025265527816E-8,6.33892980313507E-8,1.00015053205867,10.005763053894,2,20,10,5,2.15610815586293,0.189704938713827,0.0410455763339996,172.855895996094,49.4994926452637,49.5004196166992,259.783264160156,259.783264160156,,,38.9084358215332,0,1,,,,,,1,1,3,49.4998054504395,0,49.4998979007497,,,,,,,,,,,,,,,,,,,,,,,,,,,,,,,,,
,3768536468.16009,49.4995708465576,259.783264160156,,,5,,,,25.0300001353025,,,,,0.000661374675451836,4.35092833231881E-7,-0.00532129273655713,0.00022412155199261,0.000661275146658491,4.35027357086072E-7,0.000661275143806545,4.0904996081213E-7,-6.14153199349952E-8,1.48077449238185E-7,1.00015051040985,10.005763053894,2,20,10,5,2.16349391977929,0.190292900219296,0.0410455763339996,172.855895996094,49.4985008239746,49.5002746582031,259.783264160156,259.783264160156,,,38.9706230163574,0,1,,,,,,1,1,3,49.4992599487305,0,49.4996183183458,,,,,,,,,,,,,,,,,,,,,,,,,,,,,,,,,
,3768536674.11091,49.5008640289307,259.783264160156,,,5,,,,25.0300001353025,,,,,0.000663631447005149,1.02082401705208E-7,-0.00149507865422382,9.64568989563085E-5,0.000663531539330053,1.02067033513317E-7,0.000663531539104154,7.95167691404389E-8,-1.73142219056039E-8,6.39903332986687E-8,1.00015056959492,10.005763053894,2,20,10,5,2.17086353279807,0.191087190683362,0.0410455763339996,172.855895996094,49.4999008178711,49.500904083252,259.783264160156,259.783264160156,,,38.9954948425293,0,1,,,,,,1,1,3,49.5008773803711,0,49.5004905251896,,,,,,,,,,,,,,,,,,,,,,,,,,,,,,,,,
,3768536880.23135,49.499942779541,259.783264160156,,,5,,,,25.0300001353025,,,,,0.000665669551239275,9.77933136886388E-8,-0.00239034278772099,7.92905529856756E-5,0.000665569364791906,9.77785953277694E-8,0.000665569364212693,8.23239725351839E-8,-2.77671225335822E-8,5.27581012764673E-8,1.0001505274321,10.005763053894,2,20,10,5,2.17753355021995,0.191640025066816,0.0410455763339996,172.855895996094,49.498420715332,49.5002861022949,259.783264160156,259.783264160156,,,39.0701179504395,0,1,,,,,,1,1,3,49.499885559082,0,49.4991149902344,,,,,,,,,,,,,,,,,,,,,,,,,,,,,,,,,
,3768537087.02287,49.5003147125244,259.783264160156,,,5,,,,25.0300001353025,,,,,0.0006676588742558,1.04292380289748E-7,-0.0026605192370921,8.15123540698916E-5,0.000667558377044174,1.04276682013551E-7,0.000667558376324482,8.89639814617767E-8,-3.09979534001144E-8,5.43970257847243E-8,1.00015054445436,10.005763053894,2,20,10,5,2.18404191598622,0.19220243408451,0.0410455763339996,172.855895996094,49.4993591308594,49.5009574890137,259.783264160156,259.783264160156,,,39.1074295043945,0,1,,,,,,1,1,3,49.4997940063477,0,49.4998916177189,,,,,,,,,,,,,,,,,,,,,,,,,,,,,,,,,
,3768537292.0454,49.5031604766846,259.783264160156,,,5,,,,25.0300001353025,,,,,0.000669064994252214,1.71139051217449E-7,-0.00359003407035274,0.000154722771314714,0.000668964275019773,1.71113288408115E-7,0.000668964273706591,1.36275731364978E-7,-4.19159065119272E-8,1.03482764317441E-7,1.00015055995694,10.005763053894,2,20,10,5,2.18864473323679,0.192571702235807,0.0410455763339996,172.855895996094,49.5030555725098,49.5034027099609,259.783264160156,259.783264160156,,,39.1571807861328,0,1,,,,,,1,1,3,49.5030746459961,0,49.5032160141889,,,,,,,,,,,,,,,,,,,,,,,,,,,,,,,,,
,3768537499.83202,49.5008201599121,259.783264160156,,,5,,,,25.0300001353025,,,,,0.00067055826727884,1.03124976881229E-7,-0.00174397480605215,0.000128219401045367,0.000670457318138147,1.03109451939836E-7,0.000670457317827565,5.69408869191052E-8,-2.04074485262687E-8,8.59610055560016E-8,1.00015056758717,10.005763053894,2,20,10,5,2.19352330598778,0.1930721837567,0.0410455763339996,172.855895996094,49.4997673034668,49.5010833740234,259.783264160156,259.783264160156,,,39.2442398071289,0,1,,,,,,1,1,3,49.5005569458008,0,49.500460518731,,,,,,,,,,,,,,,,,,,,,,,,,,,,,,,,,
,3768537704.87319,49.5000514984131,259.783264160156,,,5,,,,25.0300001353025,,,,,0.000671795132256131,1.11763982039327E-7,-0.00317264676975793,0.00010502137882246,0.000671694020537887,1.11747160470192E-7,0.000671694019508119,8.66776207456473E-8,-3.71938017345524E-8,7.05295536284228E-8,1.00015053240784,10.005763053894,2,20,10,5,2.19757414831108,0.193373516100489,0.0410455763339996,172.855895996094,49.4994316101074,49.5002632141113,259.783264160156,259.783264160156,,,39.2691116333008,0,1,,,,,,1,1,3,49.5001907348633,0,49.4998247483197,,,,,,,,,,,,,,,,,,,,,,,,,,,,,,,,,
,3768537910.02334,49.5014915466309,259.783264160156,,,5,,,,25.0300001353025,,,,,0.000672977616340086,1.1643925315265E-7,-0.00595531259114868,0.000116901154415984,0.000672876282306086,1.16421720237808E-7,0.000672876278671381,8.58392072727068E-8,-6.99386346279226E-8,7.86488870736495E-8,1.00015059831453,10.005763053894,2,20,10,5,2.2014516924252,0.193606967826611,0.0410455763339996,172.855895996094,49.5000381469727,49.5016822814941,259.783264160156,259.783264160156,,,39.331298828125,0,1,,,,,,1,1,3,49.5013961791992,0,49.5008273405187,,,,,,,,,,,,,,,,,,,,,,,,,,,,,,,,,
,3768538117.78714,49.5004558563232,259.783264160156,,,5,,,,25.0300001353025,,,,,0.0006740155110327,7.70204921334513E-8,-0.00323078165610458,9.32951931239152E-5,0.000673914052656056,7.70088983734082E-8,0.000673914051584673,4.44730909374667E-8,-3.80005155084999E-8,6.28690274392227E-8,1.00015055091409,10.005763053894,2,20,10,5,2.20483764137938,0.19401040532789,0.0410455763339996,172.855895996094,49.499626159668,49.5005950927734,259.783264160156,259.783264160156,,,39.381046295166,0,1,,,,,,1,1,3,49.5003776550293,0,49.5002307891846,,,,,,,,,,,,,,,,,,,,,,,,,,,,,,,,,
,3768538325.87177,49.4998455047607,259.783264160156,,,5,,,,25.0300001353025,,,,,0.000674994376581484,8.074044191757E-8,-0.0044427779328835,8.46274893779931E-5,0.00067489278970751,8.072829045471E-8,0.000674892787678572,5.70594065376183E-8,-5.23319311762812E-8,5.71076265074536E-8,1.00015052298013,10.005763053894,2,20,10,5,2.20804381278306,0.194245459975905,0.0410455763339996,172.855895996094,49.4993705749512,49.5000648498535,259.783264160156,259.783264160156,,,39.4432334899902,0,1,,,,,,1,1,3,49.4996337890625,0,49.499714346493,,,,,,,,,,,,,,,,,,,,,,,,,,,,,,,,,
,3768538533.65433,49.4990882873535,259.783264160156,,,5,,,,25.0300001353025,,,,,0.000675822429644851,1.15412706363932E-7,-0.00698256384894869,0.000149182457889588,0.000675720664042406,1.15395327474038E-7,0.000675720659024509,5.6171115129129E-8,-8.23492185488728E-8,1.0080122731391E-7,1.00015060306405,10.005763053894,2,20,10,5,2.21076116137481,0.194385755495903,0.0410455763339996,172.855895996094,49.4986305236816,49.5010757446289,259.783264160156,259.783264160156,,,39.5054168701172,0,1,,,,,,1,1,3,49.4992561340332,0,49.4997547374052,,,,,,,,,,,,,,,,,,,,,,,,,,,,,,,,,
,3768538739.12505,49.4999485015869,259.783264160156,,,5,,,,25.0300001353025,,,,,0.000676690907309101,1.10815439446248E-7,-0.00491561038128285,6.97264232266515E-5,0.000676589061917835,1.10798761164233E-7,0.000676589059427805,1.00265099500194E-7,-5.80470017304912E-8,4.71516203087969E-8,1.00015052769398,10.005763053894,2,20,10,5,2.21359511669497,0.194715407880383,0.0410455763339996,172.855895996094,49.4995079040527,49.5001945495605,259.783264160156,259.783264160156,,,39.5427284240723,0,1,,,,,,1,1,3,49.4998817443848,0,49.499875461354,,,,,,,,,,,,,,,,,,,,,,,,,,,,,,,,,
,3768538944.00637,49.5004768371582,259.783264160156,,,5,,,,25.0300001353025,,,,,0.00067746303885652,9.00280022254369E-8,-0.00212994680899481,6.76410081510945E-5,0.000677361060879214,9.00144503812163E-8,0.000677361060411175,7.7490624901148E-8,-2.51806161306401E-8,4.58017939589929E-8,1.00015055187432,10.005763053894,2,20,10,5,2.21611143771531,0.195045328757557,0.0410455763339996,172.855895996094,49.4993896484375,49.500560760498,259.783264160156,259.783264160156,,,39.6049156188965,0,1,,,,,,1,1,3,49.500560760498,0,49.5000475715188,,,,,,,,,,,,,,,,,,,,,,,,,,,,,,,,,
,3768539150.36355,49.5006732940674,259.783264160156,,,5,,,,25.0300001353025,,,,,0.000678217530849598,9.56861308463582E-8,-0.00714709052285745,8.2499390728731E-5,0.000678115433203024,9.56717264284173E-8,0.000678115427927241,7.76190889833511E-8,-8.45882962875697E-8,5.59317107121582E-8,1.00015056086556,10.005763053894,2,20,10,5,2.21859661550441,0.195068278002544,0.0410455763339996,172.855895996094,49.4996337890625,49.5008354187012,259.783264160156,259.783264160156,,,39.6422271728516,0,1,,,,,,1,1,3,49.5008163452148,0,49.5001932031968,,,,,,,,,,,,,,,,,,,,,,,,,,,,,,,,,
,3768539356.83397,49.4998397827148,259.783264160156,,,5,,,,25.0300001353025,,,,,0.000678929153312744,8.30797301046118E-8,-0.00522329421978007,8.85788537002504E-5,0.000678826974431332,8.30672265998667E-8,0.000678826971610529,5.73181981542064E-8,-6.18843663006119E-8,6.0123109495008E-8,1.00015052271825,10.005763053894,2,20,10,5,2.22091792863882,0.195347529665117,0.0410455763339996,172.855895996094,49.4992980957031,49.5001602172852,259.783264160156,259.783264160156,,,39.7292861938477,0,1,,,,,,1,1,3,49.499626159668,0,49.499695248074,,,,,,,,,,,,,,,,,,,,,,,,,,,,,,,,,
,3768539564.34347,49.5012989044189,259.783264160156,,,5,,,,25.0300001353025,,,,,0.000679487229022624,8.66046763453255E-8,-0.00435438333708937,7.42300939384404E-5,0.000679384920788541,8.6591636554257E-8,0.000679384918826564,7.03989296495039E-8,-5.16321167255994E-8,5.04192644268908E-8,1.00015058949787,10.005763053894,2,20,10,5,2.2227405453446,0.195541805759954,0.0410455763339996,172.855895996094,49.500129699707,49.5015029907227,259.783264160156,259.783264160156,,,39.7914695739746,0,1,,,,,,1,1,3,49.5014762878418,0,49.5008260938856,,,,,,,,,,,,,,,,,,,,,,,,,,,,,,,,,
,3768539775.555,49.5005016326904,259.783264160156,,,5,,,,25.0300001353025,,,,,0.000680080229871823,1.02187161152395E-7,-0.00249522549453385,0.000115311723342072,0.000679977857159283,1.02171778883635E-7,0.000679977856514462,6.55139695159005E-8,-2.96129679844674E-8,7.84027563196355E-8,1.00015055300914,10.005763053894,2,20,10,5,2.2246740193378,0.195784649586977,0.0410455763339996,172.855895996094,49.4996070861816,49.5007629394531,259.783264160156,259.783264160156,,,39.8412208557129,0,1,,,,,,1,1,3,49.5005187988281,0,49.5002041985007,,,,,,,,,,,,,,,,,,,,,,,,,,,,,,,,,
,3768539982.02243,49.4990062713623,259.783264160156,,,5,,,,25.0300001353025,,,,,0.000680529055807437,1.06480567968726E-7,-0.00111328110076681,7.94746677566138E-5,0.00068042658403309,1.06464534483248E-7,0.000680426583904645,9.17193010398669E-8,-1.32209747882517E-8,5.40579958886103E-8,1.00015059931042,10.005763053894,2,20,10,5,2.22613748937176,0.195967558088065,0.0410455763339996,172.855895996094,49.498291015625,49.499927520752,259.783264160156,259.783264160156,,,39.878532409668,0,1,,,,,,1,1,3,49.499195098877,0,49.4994396882899,,,,,,,,,,,,,,,,,,,,,,,,,,,,,,,,,
,3768540190.23228,49.4995288848877,259.783264160156,,,5,,,,25.0300001353025,,,,,0.000681110584409089,9.17667433191418E-8,0.000209857266659341,0.000102149195789473,0.000681008008783915,9.17529231975909E-8,0.000681008008779347,5.9835202150007E-8,2.49432821249185E-9,6.95582309936848E-8,1.00015062322888,10.005763053894,2,20,10,5,2.22803524816633,0.196186466990672,0.0410455763339996,172.855895996094,49.4986152648926,49.4999504089355,259.783264160156,259.783264160156,,,39.9655914306641,0,1,,,,,,1,1,3,49.4998397827148,0,49.4996132320828,,,,,,,,,,,,,,,,,,,,,,,,,,,,,,,,,
,3768540398.19598,49.4991283416748,259.783264160156,,,5,,,,25.0300001353025,,,,,0.000681511513608682,8.49955143893446E-8,-0.00582072323109095,9.44424678978859E-5,0.000681408968265572,8.49827253256063E-8,0.000681408964749267,5.5510276402293E-8,-6.92248720296934E-8,6.43480599358557E-8,1.00015049015773,10.005763053894,2,20,10,5,2.22936740847091,0.196067306531932,0.0410455763339996,172.855895996094,49.4982833862305,49.5005531311035,259.783264160156,259.783264160156,,,40.027774810791,0,1,,,,,,1,1,3,49.4988327026367,0,49.4993629455566,,,,,,,,,,,,,,,,,,,,,,,,,,,,,,,,,
,3768540610.14951,49.5001449584961,259.783264160156,,,5,,,,25.0300001353025,,,,,0.000682030915004091,1.04218580192443E-7,-0.00263250345495258,8.42177702537535E-5,0.0006819282597843,1.04202893834214E-7,0.000681928259064517,8.69584836072003E-8,-3.1331775473453E-8,5.74148518430626E-8,1.00015053668523,10.005763053894,2,20,10,5,2.23105555814451,0.196340877756697,0.0410455763339996,172.855895996094,49.4996490478516,49.500373840332,259.783264160156,259.783264160156,,,40.0775260925293,0,1,,,,,,1,1,3,49.5001564025879,0,49.5000305175781,,,,,,,,,,,,,,,,,,,,,,,,,,,,,,,,,
,3768540816.86479,49.5006217956543,259.783264160156,,,5,,,,25.0300001353025,,,,,0.000682374289571172,7.86209420190969E-8,-0.00292102531383964,6.9457694298426E-5,0.000682271567781444,7.86091067492197E-8,0.000682271566894793,6.27264596140501E-8,-3.47832342360278E-8,4.7379140222224E-8,1.00015055850863,10.005763053894,2,20,10,5,2.23217979234998,0.19642848521284,0.0410455763339996,172.855895996094,49.4996337890625,49.5008125305176,259.783264160156,259.783264160156,,,40.1521492004395,0,1,,,,,,1,1,3,49.5005798339844,0,49.5001705394072,,,,,,,,,,,,,,,,,,,,,,,,,,,,,,,,,
,3768541024.69374,49.5004138946533,259.783264160156,,,5,,,,25.0300001353025,,,,,0.000682804226761665,8.91328015420285E-8,0.0024160562100155,8.85821270490836E-5,0.000682701446745908,8.91193847083478E-8,0.000682701446138935,6.54680365576995E-8,2.87882472937047E-8,6.04665272698393E-8,1.00015054899363,10.005763053894,2,20,10,5,2.23356788249125,0.196760304582848,0.0410455763339996,172.855895996094,49.4989318847656,49.5004386901855,259.783264160156,259.783264160156,,,40.2267684936523,0,1,,,,,,1,1,3,49.5004234313965,0,49.4996800142176,,,,,,,,,,,,,,,,,,,,,,,,,,,,,,,,,
,3768541229.89893,49.5012168884277,259.783264160156,,,5,,,,25.0300001353025,,,,,0.000683268397221538,1.08723641385012E-7,-0.00484783908763475,8.72604333049634E-5,0.00068316552223293,1.08707271619611E-7,0.000683165519787546,9.09145113846817E-8,-5.78031496595207E-8,5.95971687470506E-8,1.00015058574424,10.005763053894,2,20,10,5,2.23511120676599,0.196610695596742,0.0410455763339996,172.855895996094,49.4999542236328,49.5013084411621,259.783264160156,259.783264160156,,,40.2765197753906,0,1,,,,,,1,1,3,49.501293182373,0,49.5006516400505,,,,,,,,,,,,,,,,,,,,,,,,,,,,,,,,,
,3768541436.02326,49.5009727478027,259.783264160156,,,5,,,,25.0300001353025,,,,,0.000683598653914525,9.22070324650908E-8,0.000622763223232958,7.21637573300338E-5,0.000683495736837402,9.21931505210333E-8,0.000683495736797028,7.78988877522353E-8,7.42909882277238E-9,4.93086228763138E-8,1.00015057457066,10.005763053894,2,20,10,5,2.23617275243221,0.196919239122204,0.0410455763339996,172.855895996094,49.4993667602539,49.5010566711426,259.783264160156,259.783264160156,,,40.3387031555176,0,1,,,,,,1,1,3,49.5009460449219,0,49.5003381616929,,,,,,,,,,,,,,,,,,,,,,,,,,,,,,,,,
,3768541644.16366,49.499719619751,259.783264160156,,,5,,,,25.0300001353025,,,,,0.000683669217380878,8.38159084395854E-8,0.0003022318150947,8.1617764213303E-5,0.000683566328878224,8.380329460076E-8,0.000683566328868714,6.2540272455118E-8,3.6057715606497E-9,5.57826721050666E-8,1.00015051721875,10.005763053894,2,20,10,5,2.23640467924359,0.196927060695077,0.0410455763339996,172.855895996094,49.4993476867676,49.5014457702637,259.783264160156,259.783264160156,,,40.4008903503418,0,1,,,,,,1,1,3,49.4993743896484,0,49.5001589457194,,,,,,,,,,,,,,,,,,,,,,,,,,,,,,,,,
,3768541850.17978,49.500207901001,259.783264160156,,,5,,,,25.0300001353025,,,,,0.000684163239053779,8.26192122849673E-8,-0.00329554977154345,8.36733819451626E-5,0.000684060260919039,8.26067766966615E-8,0.000684060259787486,5.95699974835684E-8,-3.93459108944652E-8,5.72301926959866E-8,1.00015053956592,10.005763053894,2,20,10,5,2.23803308334118,0.196928823965758,0.0410455763339996,172.855895996094,49.4998092651367,49.5010833740234,259.783264160156,259.783264160156,,,40.4506378173828,0,1,,,,,,1,1,3,49.5004539489746,0,49.5003774431017,,,,,,,,,,,,,,,,,,,,,,,,,,,,,,,,,
,3768542056.3292,49.5004119873047,259.783264160156,,,5,,,,25.0300001353025,,,,,0.000684465941288113,8.86933161816583E-8,-0.00345533023802069,6.05346282125885E-5,0.000684362911200295,8.86799655098369E-8,0.000684362909955808,7.84176430262364E-8,-4.12717983682716E-8,4.14102589346605E-8,1.00015054890634,10.005763053894,2,20,10,5,2.23902383156069,0.197009709326313,0.0410455763339996,172.855895996094,49.4994926452637,49.5004997253418,259.783264160156,259.783264160156,,,40.512825012207,0,1,,,,,,1,1,3,49.5004997253418,0,49.5000197466682,,,,,,,,,,,,,,,,,,,,,,,,,,,,,,,,,
,3768542260.49332,49.5002975463867,259.783264160156,,,5,,,,25.0300001353025,,,,,0.000684801925432038,1.1474453745768E-7,-0.00387464996112818,0.000123197345410258,0.000684698848355439,1.14727265994156E-7,0.000684698846789809,7.77712637885479E-8,-4.63030329055402E-8,8.43443898029137E-8,1.00015054366872,10.005763053894,2,20,10,5,2.24012434460659,0.197090023261184,0.0410455763339996,172.855895996094,49.4998893737793,49.5006141662598,259.783264160156,259.783264160156,,,40.562572479248,0,1,,,,,,1,1,3,49.4999694824219,0,49.5001498951631,,,,,,,,,,,,,,,,,,,,,,,,,,,,,,,,,
,3768542465.7874,49.5006828308105,259.783264160156,,,5,,,,25.0300001353025,,,,,0.000685005357150484,1.03715277512041E-7,-0.000571414399494152,7.58235057701191E-5,0.000684902237377861,1.03699664355556E-7,0.0006849022373438,8.97700666800963E-8,-6.83057293229817E-9,5.1912960960689E-8,1.00015056130203,10.005763053894,2,20,10,5,2.24077844097525,0.197277755809199,0.0410455763339996,172.855895996094,49.499885559082,49.5009689331055,259.783264160156,259.783264160156,,,40.624755859375,0,1,,,,,,1,1,3,49.5006790161133,0,49.5004350998822,,,,,,,,,,,,,,,,,,,,,,,,,,,,,,,,,
,3768542673.44922,49.5008811950684,259.783264160156,,,5,,,,25.0300001353025,,,,,0.000685272837407103,1.15411108771849E-7,-0.000588776019417203,8.71433297215082E-5,0.000685169671148966,1.15393733893422E-7,0.00068516967111279,9.87574089716169E-8,-7.04085841968991E-9,5.96882567602594E-8,1.00015057038057,10.005763053894,2,20,10,5,2.24165347787796,0.197354109237015,0.0410455763339996,172.855895996094,49.4995765686035,49.5009803771973,259.783264160156,259.783264160156,,,40.6993789672852,0,1,,,,,,1,1,3,49.5007171630859,0,49.5002687242296,,,,,,,,,,,,,,,,,,,,,,,,,,,,,,,,,
,3768542881.01462,49.4999504089355,259.783264160156,,,5,,,,25.0300001353025,,,,,0.000685430847253027,1.00582349441886E-7,-0.00230419388303016,8.65044499932124E-5,0.000685327686396945,1.00567211282703E-7,0.000685327685842752,8.1245048101835E-8,-2.75609805095825E-8,5.92706178819679E-8,1.00015052778128,10.005763053894,2,20,10,5,2.24217626587609,0.197332488913506,0.0410455763339996,172.855895996094,49.499454498291,49.5005722045898,259.783264160156,259.783264160156,,,40.6993789672852,0,1,,,,,,1,1,3,49.4997215270996,0,49.4998779296875,,,,,,,,,,,,,,,,,,,,,,,,,,,,,,,,,
,3768543090.20262,49.4998645782471,259.783264160156,,,5,,,,25.0300001353025,,,,,0.000685700777528057,7.41093185914969E-8,-0.00140534963746131,6.48693655150371E-5,0.000685597578738853,7.40981650501884E-8,0.000685597578532618,5.9274106882724E-8,-1.68163225427169E-8,4.44647986283574E-8,1.00015052385307,10.005763053894,2,20,10,5,2.24305616269847,0.197445387815465,0.0410455763339996,172.855895996094,49.4994506835937,49.5002632141113,259.783264160156,259.783264160156,,,40.7366905212402,0,1,,,,,,1,1,3,49.5000953674316,0,49.4998296849868,,,,,,,,,,,,,,,,,,,,,,,,,,,,,,,,,
,3768543296.67062,49.5006160736084,259.783264160156,,,5,,,,25.0300001353025,,,,,0.000686157225330455,1.30181715114667E-7,-0.00309067532330065,0.000175303232492408,0.000686053934252935,1.30162118134367E-7,0.000686053933254799,4.97855502320669E-8,-3.70074372325527E-8,1.20264608199235E-7,1.00015055824675,10.005763053894,2,20,10,5,2.24455510024412,0.197510794648946,0.0410455763339996,172.855895996094,49.499698638916,49.5010833740234,259.783264160156,259.783264160156,,,40.8113136291504,0,1,,,,,,1,1,3,49.5010108947754,0,49.5002468333525,,,,,,,,,,,,,,,,,,,,,,,,,,,,,,,,,
,3768543504.24911,49.5038585662842,259.783264160156,,,5,,,,25.0300001353025,,,,,0.000686131286782778,1.17934800559449E-7,0.000339644841199416,0.000108867891200369,0.000686027976521949,1.17917043207115E-7,0.000686027976509895,9.12599948855241E-8,4.06671948829297E-9,7.46729027974861E-8,1.0001505919064,10.005763053894,2,20,10,5,2.24445842253519,0.197637694041556,0.0410455763339996,172.855895996094,49.5027732849121,49.5039825439453,259.783264160156,259.783264160156,,,40.8361892700195,0,1,,,,,,1,1,3,49.5038871765137,0,49.5034139296588,,,,,,,,,,,,,,,,,,,,,,,,,,,,,,,,,
,3768543710.06484,49.5002174377441,259.783264160156,,,5,,,,25.0300001353025,,,,,0.000686434705124848,1.15811265386166E-7,-0.00168294572053629,0.000108850514052365,0.000686331384796543,1.15793833782152E-7,0.00068633138450047,8.84809434338132E-8,-2.01595732977725E-8,7.4694943543931E-8,1.00015054000239,10.005763053894,2,20,10,5,2.24545793548372,0.197645840623358,0.0410455763339996,172.855895996094,49.4995994567871,49.5006637573242,259.783264160156,259.783264160156,,,40.8859367370605,0,1,,,,,,1,1,3,49.5001411437988,0,49.5002087487115,,,,,,,,,,,,,,,,,,,,,,,,,,,,,,,,,
,3768543918.25743,49.4990825653076,259.783264160156,,,5,,,,25.0300001353025,,,,,0.000686737782025727,7.18902783546479E-8,1.7684067747048E-5,8.55252560095703E-5,0.000686634372965095,7.18794531075918E-8,0.000686634372965062,4.14546842627777E-8,2.11926408404896E-10,5.87210774059868E-8,1.00015060280217,10.005763053894,2,20,10,5,2.24644348712493,0.197799787120778,0.0410455763339996,172.855895996094,49.4987525939941,49.5013580322266,259.783264160156,259.783264160156,,,40.9232482910156,0,1,,,,,,1,1,3,49.499324798584,0,49.5001693301731,,,,,,,,,,,,,,,,,,,,,,,,,,,,,,,,,
,3768544124.91111,49.5002670288086,259.783264160156,,,5,,,,25.0300001353025,,,,,0.000686825903422389,1.05667045566841E-7,0.00137846962703403,0.000115950222321264,0.000686722522653581,1.05651140604093E-7,0.000686722522454834,6.94483890736808E-8,1.65217429212336E-8,7.96183695262372E-8,1.00015054227202,10.005763053894,2,20,10,5,2.24672704951436,0.197878524556015,0.0410455763339996,172.855895996094,49.4997673034668,49.5005569458008,259.783264160156,259.783264160156,,,40.9854316711426,0,1,,,,,,1,1,3,49.5004234313965,0,49.5001530647278,,,,,,,,,,,,,,,,,,,,,,,,,,,,,,,,,
,3768544330.07089,49.5000267028809,259.783264160156,,,5,,,,25.0300001353025,,,,,0.000686955739744231,1.42328922213002E-7,-0.00187119478773567,8.86341757497665E-5,0.000686852346986061,1.42307500483794E-7,0.000686852346619769,1.28643538002161E-7,-2.24315742331843E-8,6.08462391954624E-8,1.00015053127302,10.005763053894,2,20,10,5,2.24716298820518,0.197788480171637,0.0410455763339996,172.855895996094,49.4994163513184,49.5003433227539,259.783264160156,259.783264160156,,,41.0103073120117,0,1,,,,,,1,1,3,49.4999542236328,0,49.4998642416561,,,,,,,,,,,,,,,,,,,,,,,,,,,,,,,,,
,3768544539.21552,49.4993228912354,259.783264160156,,,5,,,,25.0300001353025,,,,,0.000687319448280336,1.1274004556156E-7,-0.00294271597872697,8.51086845725668E-5,0.000687216022913719,1.12723080843663E-7,0.00068721602200733,9.63734131916837E-8,-3.52954718089589E-8,5.84692926643726E-8,1.00015049906168,10.005763053894,2,20,10,5,2.24835644818365,0.19785115587998,0.0410455763339996,172.855895996094,49.4986114501953,49.5006217956543,259.783264160156,259.783264160156,,,41.0724945068359,0,1,,,,,,1,1,3,49.4988136291504,0,49.4997327467974,,,,,,,,,,,,,,,,,,,,,,,,,,,,,,,,,
,3768544746.12493,49.5008220672607,259.783264160156,,,5,,,,25.0300001353025,,,,,0.000687443543349722,1.10891070870562E-7,-0.00206227422400396,8.627458242934E-5,0.000687340052156502,1.10874376773493E-7,0.000687340051711267,9.36948873516922E-8,-2.47397571763234E-8,5.92823372436025E-8,1.00015056767446,10.005763053894,2,20,10,5,2.24875934693253,0.197921426893019,0.0410455763339996,172.855895996094,49.4997749328613,49.5014762878418,259.783264160156,259.783264160156,,,41.109806060791,0,1,,,,,,1,1,3,49.500545501709,0,49.5004202898811,,,,,,,,,,,,,,,,,,,,,,,,,,,,,,,,,
,3768544953.7955,49.4999179840088,259.783264160156,,,5,,,,25.0300001353025,,,,,0.000687637957289635,1.00765649668176E-7,-0.00401200679076652,8.54800596235827E-5,0.000687534465272321,1.00750484070859E-7,0.000687534463586767,8.1842942192532E-8,-4.8143038889533E-8,5.87570664157283E-8,1.00015052629729,10.005763053894,2,20,10,5,2.24940204759364,0.197900857921481,0.0410455763339996,172.855895996094,49.4997024536133,49.5005340576172,259.783264160156,259.783264160156,,,41.159553527832,0,1,,,,,,1,1,3,49.4998245239258,0,49.5000936720106,,,,,,,,,,,,,,,,,,,,,,,,,,,,,,,,,
,3768545160.01775,49.4999599456787,259.783264160156,,,5,,,,25.0300001353025,,,,,0.000687514258984406,1.37143798314944E-7,-0.000660115604300238,0.000134463395768558,0.000687410784264191,1.37123157410448E-7,0.000687410784218568,1.01299738190834E-7,-7.91979076126207E-9,9.24181981033985E-8,1.00015052821775,10.005763053894,2,20,10,5,2.24898582629955,0.197996827155083,0.0410455763339996,172.855895996094,49.4990386962891,49.5001258850098,259.783264160156,259.783264160156,,,41.1844253540039,0,1,,,,,,1,1,3,49.4998512268066,0,49.499756083769,,,,,,,,,,,,,,,,,,,,,,,,,,,,,,,,,
,3768545368.11186,49.4999485015869,259.783264160156,,,5,,,,25.0300001353025,,,,,0.000687654276462021,1.04908091267761E-7,-0.00461790320737077,0.00013196952210419,0.000687550781028455,1.04892302071413E-7,0.000687550778795299,5.26322433712187E-8,-5.54149534308914E-8,9.07317033431722E-8,1.00015052769398,10.005763053894,2,20,10,5,2.24945752358894,0.197881766827953,0.0410455763339996,172.855895996094,49.4993896484375,49.5005302429199,259.783264160156,259.783264160156,,,41.2341766357422,0,1,,,,,,1,1,3,49.4998168945313,0,49.499916749842,,,,,,,,,,,,,,,,,,,,,,,,,,,,,,,,,
,3768545577.20927,49.5001411437988,259.783264160156,,,5,,,,25.0300001353025,,,,,0.00068812228807675,1.60799680954857E-7,-0.00153218523070109,0.000151202743129364,0.000688018716139967,1.60775478375346E-7,0.00068801871589396,1.22597139972886E-7,-1.83987742927774E-8,1.04012959371849E-7,1.00015053651064,10.005763053894,2,20,10,5,2.25097781756102,0.198137671594636,0.0410455763339996,172.855895996094,49.4996376037598,49.5003356933594,259.783264160156,259.783264160156,,,41.2590484619141,0,1,,,,,,1,1,3,49.4999923706055,0,49.5000531813678,,,,,,,,,,,,,,,,,,,,,,,,,,,,,,,,,
,3768545783.78481,49.5001983642578,259.783264160156,,,5,,,,25.0300001353025,,,,,0.000688393189922465,1.24315358089973E-7,-0.00307256155273716,9.00229573759527E-5,0.000688289575408973,1.24296646581003E-7,0.000688289574419288,1.0776418971077E-7,-3.69104339536021E-8,6.1939775324616E-8,1.00015053912945,10.005763053894,2,20,10,5,2.25186931693391,0.198155132262867,0.0410455763339996,172.855895996094,49.4994926452637,49.5006332397461,259.783264160156,259.783264160156,,,41.3087997436523,0,1,,,,,,1,1,3,49.5005302429199,0,49.4999674628763,,,,,,,,,,,,,,,,,,,,,,,,,,,,,,,,,
,3768545993.30188,49.5003852844238,259.783264160156,,,5,,,,25.0300001353025,,,,,0.000688438584385595,7.05443892673739E-8,-0.00454429069546336,7.55185504009307E-5,0.000688334957151825,7.05337705715547E-8,0.00068833495498683,4.76805029961373E-8,-5.45937966888737E-8,5.19767488890567E-8,1.00015054768422,10.005763053894,2,20,10,5,2.25202290062617,0.198110352792792,0.0410455763339996,172.855895996094,49.4990081787109,49.5006294250488,259.783264160156,259.783264160156,,,41.3336715698242,0,1,,,,,,1,1,3,49.5004730224609,0,49.4998639424642,,,,,,,,,,,,,,,,,,,,,,,,,,,,,,,,,
,3768546199.63449,49.4996433258057,259.783264160156,,,5,,,,25.0300001353025,,,,,0.000688652975219574,8.18918655479693E-8,-0.00341902972027786,7.77155865392887E-5,0.00068854933909232,8.18795415530046E-8,0.000688549337866391,6.19818256255423E-8,-4.10880290458327E-8,5.35024543087052E-8,1.000150513727,10.005763053894,2,20,10,5,2.25272032406159,0.198216292517664,0.0410455763339996,172.855895996094,49.4994239807129,49.5000305175781,259.783264160156,259.783264160156,,,41.3336715698242,0,1,,,,,,1,1,3,49.4997978210449,0,49.4997069414924,,,,,,,,,,,,,,,,,,,,,,,,,,,,,,,,,
,3768546406.17141,49.4988098144531,259.783264160156,,,5,,,,25.0300001353025,,,,,0.000688835729993732,9.55392459140284E-8,0.000908226563763215,7.54232532571352E-5,0.000688732013619974,9.55248607947519E-8,0.000688732013533445,8.01756807730302E-8,1.09174657430879E-8,5.19312934793454E-8,1.00015059031918,10.005763053894,2,20,10,5,2.25330317032625,0.198439077852881,0.0410455763339996,172.855895996094,49.4980354309082,49.4998207092285,259.783264160156,259.783264160156,,,41.3834190368652,0,1,,,,,,1,1,3,49.4993629455566,0,49.4992464850931,,,,,,,,,,,,,,,,,,,,,,,,,,,,,,,,,
,3768546612.77454,49.501106262207,259.783264160156,,,5,,,,25.0300001353025,,,,,0.000688875407977582,9.26745119096979E-8,-0.0028048765579447,0.000107771001472349,0.000688771692266959,9.2660559019599E-8,0.00068877169144163,5.54680171709744E-8,-3.37183574263569E-8,7.42245125881273E-8,1.00015058068121,10.005763053894,2,20,10,5,2.25344582058855,0.19830446599,0.0410455763339996,172.855895996094,49.4997520446777,49.5012664794922,259.783264160156,259.783264160156,,,41.4331703186035,0,1,,,,,,1,1,3,49.5009460449219,0,49.5005138621611,,,,,,,,,,,,,,,,,,,,,,,,,,,,,,,,,
,3768546820.77471,49.5009059906006,259.783264160156,,,5,,,,25.0300001353025,,,,,0.000688955923884951,1.16834381590709E-7,-0.000863326066341763,0.000134076338632425,0.000688852202364966,1.16816792309269E-7,0.000688852202286767,7.15349946429858E-8,-1.03795439592599E-8,9.23520844748775E-8,1.00015057151538,10.005763053894,2,20,10,5,2.25370248186966,0.198404014420195,0.0410455763339996,172.855895996094,49.4994583129883,49.5013771057129,259.783264160156,259.783264160156,,,41.4580421447754,0,1,,,,,,1,1,3,49.5008239746094,0,49.5001691182454,,,,,,,,,,,,,,,,,,,,,,,,,,,,,,,,,
,3768547032.57977,49.5003852844238,259.783264160156,,,5,,,,25.0300001353025,,,,,0.000689258803484238,9.45550455342301E-8,-0.00402938554323384,8.31382801701512E-5,0.000689155052786969,9.45408126338233E-8,0.000689155051082774,7.52101385012858E-8,-4.84655489122611E-8,5.72835082731592E-8,1.00015054768422,10.005763053894,2,20,10,5,2.25470422175387,0.198366649001942,0.0410455763339996,172.855895996094,49.4991760253906,49.5006904602051,259.783264160156,259.783264160156,,,41.4829177856445,0,1,,,,,,1,1,3,49.5001831054687,0,49.4998866810518,,,,,,,,,,,,,,,,,,,,,,,,,,,,,,,,,
,3768547241.74069,49.5004634857178,259.783264160156,,,5,,,,25.0300001353025,,,,,0.000689637106670798,1.20190002047618E-7,-0.00668242910560135,0.00014803395601239,0.000689533296561939,1.20171910014756E-7,0.0006895332918722,6.34287227743581E-8,-8.04205370611701E-8,1.0206902117591E-7,1.00015055126326,10.005763053894,2,20,10,5,2.25595091549716,0.198371062905999,0.0410455763339996,172.855895996094,49.4993095397949,49.5009918212891,259.783264160156,259.783264160156,,,41.5326652526855,0,1,,,,,,1,1,3,49.500316619873,0,49.5000358157688,,,,,,,,,,,,,,,,,,,,,,,,,,,,,,,,,
,3768547449.63174,49.500394821167,259.783264160156,,,5,,,,25.0300001353025,,,,,0.000689375673787888,9.82684957506378E-8,0.000130196708615138,6.8168585081362E-5,0.000689271905197914,9.82537038401736E-8,0.000689271905196134,8.63009330570777E-8,1.56627476160065E-9,4.69674277748988E-8,1.00015054812069,10.005763053894,2,20,10,5,2.25507211859705,0.198563998501668,0.0410455763339996,172.855895996094,49.499755859375,49.5006217956543,259.783264160156,259.783264160156,,,41.5699768066406,0,1,,,,,,1,1,3,49.5003356933594,0,49.5001700906193,,,,,,,,,,,,,,,,,,,,,,,,,,,,,,,,,
,3768547657.63988,49.5013046264648,259.783264160156,,,5,,,,25.0300001353025,,,,,0.000689264703653966,1.00242968879078E-7,-0.0023695261691854,8.54601403767116E-5,0.00068916092307613,1.00227875587373E-7,0.000689160922486787,8.11078347910635E-8,-2.85009621200896E-8,5.88824777014653E-8,1.00015058975975,10.005763053894,2,20,10,5,2.25471777502279,0.198433662929152,0.0410455763339996,172.855895996094,49.4995727539063,49.5017395019531,259.783264160156,259.783264160156,,,41.6072883605957,0,1,,,,,,1,1,3,49.5010604858398,0,49.5004995009478,,,,,,,,,,,,,,,,,,,,,,,,,,,,,,,,,
,3768547865.7786,49.5005702972412,259.783264160156,,,5,,,,25.0300001353025,,,,,0.000689510540654705,1.10823031738091E-7,-0.00279569192906148,0.000124162653030976,0.000689406746228032,1.10806349160577E-7,0.000689406745407343,7.03714458317121E-8,-3.36389327780308E-8,8.55915102440081E-8,1.00015055615171,10.005763053894,2,20,10,5,2.2555234315046,0.198487662731518,0.0410455763339996,172.855895996094,49.4996185302734,49.500659942627,259.783264160156,259.783264160156,,,41.6570358276367,0,1,,,,,,1,1,3,49.5005683898926,0,49.5001977284749,,,,,,,,,,,,,,,,,,,,,,,,,,,,,,,,,
,3768548073.65755,49.5003566741943,259.783264160156,,,5,,,,25.0300001353025,,,,,0.000689692724994001,1.13235370449832E-7,0.000338109283276822,9.24569404887667E-5,0.000689588909883501,1.13218325841314E-7,0.000689588909871495,9.35709679240793E-8,4.06934706284545E-9,6.37405935653314E-8,1.00015054637482,10.005763053894,2,20,10,5,2.25610852938056,0.198663506924141,0.0410455763339996,172.855895996094,49.4996299743652,49.5004539489746,259.783264160156,259.783264160156,,,41.6694755554199,0,1,,,,,,1,1,3,49.500373840332,0,49.500088186825,,,,,,,,,,,,,,,,,,,,,,,,,,,,,,,,,
,3768548227.54614,49.50048828125,259.783264160156,,,5,,,,25.0300001353025,,,,,0.000689750448601199,5.17224569733266E-8,-0.00372173194538838,4.49636471570617E-5,0.000689646620648632,5.17146712055607E-8,0.000689646619193704,4.13914541017384E-8,-4.47970143543672E-8,3.10024957905477E-8,1.00015055239808,10.005763053894,2,20,10,5,2.25631142604033,0.198520257013389,0.0410455763339996,172.855895996094,49.499641418457,49.5006217956543,259.783264160156,259.783264160156,,,41.6943473815918,0,1,,,,,,1,1,3,49.5005493164063,0,49.5001225191004,,,,,,,,,,,,,,,,,,,,,,,,,,,,,,,,,