File: Experimental_Data/Fig3C/Lifetime_340Oe_46p5K.dat
[Header]
; MPMS3 Data File (default extension .dat)
; Copyright (c) 2007, Quantum Design, Inc. All rights reserved.
TITLE,340Oe_46p5K
FILEOPENTIME,3768694716.57776,06/03/2019,3:38 am
BYAPP,SQUID AC,0.9.1.0
INFO,MPMS3 Measurement Release 1.1.16 Build 347, MultiVu Release 2.3.3.2,APPNAME
INFO,0,MOMENT_UNITS
INFO,,SAMPLE_MATERIAL
INFO,,SAMPLE_COMMENT
INFO,,SAMPLE_MASS
INFO,,SAMPLE_VOLUME
INFO,,SAMPLE_MOLECULAR_WEIGHT
INFO,,SAMPLE_SIZE
INFO,,SAMPLE_SHAPE
INFO,Quartz,SAMPLE_HOLDER
INFO,Standard,SAMPLE_HOLDER_DETAIL
INFO,66.2,SAMPLE_OFFSET
DATATYPE,COMMENT,1
DATATYPE,TIME,2
STARTUPAXIS,X,2
STARTUPAXIS,Y1,5
FIELDGROUP, VSM,2,3,4,5,6,8,9,10,11,14,15
FIELDGROUP, DC, 2,3,4,14,56,57,58,59,60,61,62,63,64,65,66,67,68,69
FIELDGROUP, AC, 2,3,4,11,16,17,18,19,20,21,22,23,24,25,26,27,28,29,30
STARTUPGROUP, All
[Data]
Comment,Time Stamp (sec),Temperature (K),Magnetic Field (Oe),Moment (emu),M. Std. Err. (emu),Transport Action,Averaging Time (sec),Frequency (Hz),Peak Amplitude (mm),Center Position (mm),Lockin Signal' (V),Lockin Signal (V),Range,M. Quad. Signal (emu),AC Moment (emu),AC M. Std Err. (emu),AC Phase (deg),AC Phase Std. Err. (deg),AC Susceptibility (emu/Oe),AC Suscept. Std Err. (emu/Oe),AC X' (emu/Oe),AC X' Std Err. (emu/Oe),AC X'' (emu/Oe),AC X'' Std Err. (emu/Oe),AC Drive (Oe),AC Frequency (Hz),AC Averaging Time (sec),AC Cycles,AC Range,AC Measure Type,AC Signal' (V),AC Signal'' (V),AC Trim Coil Ratio,AC Trim Coil Phase,Min. Temperature (K),Max. Temperature (K),Min. Field (Oe),Max. Field (Oe),Mass (grams),Motor Lag (deg),Pressure (Torr),Measure Count,Measurement Number,SQUID Status (code),Motor Status (code),Measure Status (code),Motor Current (amps),Motor Temp. (C),Temp. Status (code),Field Status (code),Chamber Status (code),Chamber Temp (K),Redirection State,Average Temp (K),Rotation Angle (deg),Rotator state,DC Moment Fixed Ctr (emu),DC Moment Err Fixed Ctr (emu),DC Moment Free Ctr (emu),DC Moment Err Free Ctr (emu),DC Fixed Fit,DC Free Fit,DC Calculated Center (mm),DC Calculated Center Err (mm),DC Scan Length (mm),DC Scan Time (s),DC Number of Points,DC Squid Drift,DC Min V (V),DC Max V (V),DC Scans per Measure,Map 01,Map 02,Map 03,Map 04,Map 05,Map 06,Map 07,Map 08,Map 09,Map 10,Map 11,Map 12,Map 13,Map 14,Map 15,Map 16
,3768694720.41005,46.4819145202637,339.525085449219,,,5,,,,25.0300001353025,,,,,0.00062151656614411,1.13727642872147E-7,0.0269420821912627,0.000114280161227972,0.000621423095485302,1.13710539228764E-7,0.000621423026782503,8.88198460393765E-8,2.92210554414262E-7,7.10008569049535E-8,1.00015041387983,10.005763053894,2,20,10,5,2.03299680850786,0.180155147261477,0.0410455763339996,172.855895996094,46.4174690246582,46.4960517883301,339.525085449219,339.525085449219,,,59.1187324523926,0,1,,,,,,1,1,1,46.4754600524902,0,46.4520880755256,,,,,,,,,,,,,,,,,,,,,,,,,,,,,,,,,
,3768694928.12121,46.5002689361572,339.525085449219,,,5,,,,25.0300001353025,,,,,0.000632368832725109,1.67397057646594E-7,-0.00296085869425333,0.000223167532171603,0.000632273343912174,1.67371780394623E-7,0.000632273343067936,9.00296365032474E-8,-3.26738206992422E-8,1.41095632191641E-7,1.00015102457482,10.005763053894,2,20,10,5,2.0685902481362,0.182221129688966,0.0410455763339996,172.855895996094,46.499340057373,46.500617980957,339.525085449219,339.525085449219,,,59.3923530578613,0,1,,,,,,1,1,1,46.500431060791,0,46.4999513065114,,,,,,,,,,,,,,,,,,,,,,,,,,,,,,,,,
,3768695135.52501,46.5000782012939,339.525085449219,,,5,,,,25.0300001353025,,,,,0.000638135410549121,1.94428898384269E-7,-0.00448419339162243,0.000168914512381886,0.000638039056542329,1.94399540973466E-7,0.000638039054588256,1.61808783507075E-7,-4.99354497370968E-8,1.07745529423056E-7,1.00015101584426,10.005763053894,2,20,10,5,2.08745863174182,0.183827307737312,0.0410455763339996,172.855895996094,46.4993476867676,46.5002517700195,339.525085449219,339.525085449219,,,59.7157173156738,0,1,,,,,,1,1,1,46.5001411437988,0,46.4997961256239,,,,,,,,,,,,,,,,,,,,,,,,,,,,,,,,,
,3768695344.59936,46.499605178833,339.525085449219,,,5,,,,25.0300001353025,,,,,0.000642215480564747,1.34836275905958E-7,-0.00846603630367504,0.000145703829833652,0.000642118524396695,1.34815919485065E-7,0.000642118517386983,9.70787001818486E-8,-9.48795664396526E-8,9.35470903748823E-8,1.00015099419245,10.005763053894,2,20,10,5,2.10081814507734,0.184856654561629,0.0410455763339996,172.855895996094,46.4991874694824,46.5001335144043,339.525085449219,339.525085449219,,,59.989330291748,0,1,,,,,,1,1,1,46.4997253417969,0,46.4996981901281,,,,,,,,,,,,,,,,,,,,,,,,,,,,,,,,,
,3768695552.48476,46.50071144104,339.525085449219,,,5,,,,25.0300001353025,,,,,0.000645395571071501,1.2564519265821E-7,-0.00604438067961333,0.000145963476625013,0.000645298102129538,1.25626217467582E-7,0.000645298098538759,8.31378321641629E-8,-6.80752999089168E-8,9.41809289519685E-8,1.00015104482973,10.005763053894,2,20,10,5,2.11121301789401,0.185861247968508,0.0410455763339996,172.855895996094,46.4996566772461,46.501091003418,339.525085449219,339.525085449219,,,60.2505073547363,0,1,,,,,,1,1,1,46.5003547668457,0,46.5002185597139,,,,,,,,,,,,,,,,,,,,,,,,,,,,,,,,,
,3768695760.52929,46.5005989074707,339.525085449219,,,5,,,,25.0300001353025,,,,,0.000648450889764606,1.37712450238332E-7,-0.00910186469409346,8.75840938359456E-5,0.00064835296274143,1.37691653335253E-7,0.000648352954560607,1.25450652950332E-7,-1.02995734872923E-7,5.67549563697374E-8,1.0001510396787,10.005763053894,2,20,10,5,2.12121751498625,0.186627924522438,0.0410455763339996,172.855895996094,46.4995994567871,46.5010185241699,339.525085449219,339.525085449219,,,60.4868125915527,0,1,,,,,,1,1,1,46.5004844665527,0,46.5001108506147,,,,,,,,,,,,,,,,,,,,,,,,,,,,,,,,,
,3768695968.02882,46.4997081756592,339.525085449219,,,5,,,,25.0300001353025,,,,,0.00065084729341081,1.03389565330837E-7,-0.00493059579449717,0.000131203366704863,0.000650749031018421,1.03373955976476E-7,0.000650749028608865,5.82857053245145E-8,-5.60002928473945E-8,8.53753555134637E-8,1.00015099890696,10.005763053894,2,20,10,5,2.12904300573835,0.18747262761787,0.0410455763339996,172.855895996094,46.4989051818848,46.5004119873047,339.525085449219,339.525085449219,,,60.7231178283691,0,1,,,,,,1,1,1,46.4995613098145,0,46.4995761447483,,,,,,,,,,,,,,,,,,,,,,,,,,,,,,,,,
,3768696174.59506,46.5001220703125,339.525085449219,,,5,,,,25.0300001353025,,,,,0.000653057344920401,1.24903457713687E-7,-0.00767031268331486,0.000126428545842044,0.000652958736494384,1.24884597909927E-7,0.000652958730643297,9.37192606349103E-8,-8.74130294729766E-8,8.2540068943331E-8,1.00015101785229,10.005763053894,2,20,10,5,2.13628148939838,0.188007067080083,0.0410455763339996,172.855895996094,46.4993515014648,46.500301361084,339.525085449219,339.525085449219,,,60.9221153259277,0,1,,,,,,1,1,1,46.4999809265137,0,46.4997354395249,,,,,,,,,,,,,,,,,,,,,,,,,,,,,,,,,
,3768696383.09916,46.5000896453857,339.525085449219,,,5,,,,25.0300001353025,,,,,0.00065538415847725,1.42083387809336E-7,-0.0101068037266128,0.000167871020325078,0.00065528519968633,1.42061934131999E-7,0.000655285189491435,8.99049923142962E-8,-1.15590344003015E-7,1.09994024775398E-7,1.00015101636809,10.005763053894,2,20,10,5,2.14390098463726,0.188585757310314,0.0410455763339996,172.855895996094,46.4994735717773,46.5003280639648,339.525085449219,339.525085449219,,,61.1584205627441,0,1,,,,,,1,1,1,46.5003204345703,0,46.4999050564236,,,,,,,,,,,,,,,,,,,,,,,,,,,,,,,,,
,3768696593.29647,46.5004615783691,339.525085449219,,,5,,,,25.0300001353025,,,,,0.000656930703776181,1.33690405612875E-7,-0.0057635004320673,0.000137361017587138,0.000656831500286266,1.33670216946508E-7,0.000656831496963105,9.8640008702599E-8,-6.60720329050866E-8,9.02101744908943E-8,1.00015103339269,10.005763053894,2,20,10,5,2.1489457273577,0.189193677488147,0.0410455763339996,172.855895996094,46.4993476867676,46.5015068054199,339.525085449219,339.525085449219,,,61.3698501586914,0,1,,,,,,1,1,1,46.499698638916,0,46.5000789040013,,,,,,,,,,,,,,,,,,,,,,,,,,,,,,,,,
,3768696801.00303,46.5015754699707,339.525085449219,,,5,,,,25.0300001353025,,,,,0.000659004826601275,8.66123759004287E-8,-0.00420918653268831,9.58407571443107E-5,0.000658905276306658,8.65992921001433E-8,0.000658905274528608,5.92652602807959E-8,-4.8405925120877E-8,6.31432206661607E-8,1.00015108437919,10.005763053894,2,20,10,5,2.15572543037728,0.189849489167905,0.0410455763339996,172.855895996094,46.4999237060547,46.5020790100098,339.525085449219,339.525085449219,,,61.5937156677246,0,1,,,,,,1,1,1,46.5014991760254,0,46.500737582936,,,,,,,,,,,,,,,,,,,,,,,,,,,,,,,,,
,3768697010.89112,46.5005569458008,339.525085449219,,,5,,,,25.0300001353025,,,,,0.000660672610684248,1.05819267499983E-7,-0.00606461963559735,0.000120949034565794,0.00066057283924363,1.05803287208697E-7,0.000660572835543197,6.93700827502354E-8,-6.99200366621056E-8,7.98882169245975E-8,1.00015103775797,10.005763053894,2,20,10,5,2.16118721926172,0.190259972761365,0.0410455763339996,172.855895996094,46.4994964599609,46.501594543457,339.525085449219,339.525085449219,,,61.7927131652832,0,1,,,,,,1,1,1,46.5001754760742,0,46.5001501195571,,,,,,,,,,,,,,,,,,,,,,,,,,,,,,,,,
,3768697218.173,46.5002632141113,339.525085449219,,,5,,,,25.0300001353025,,,,,0.000661984112483555,1.53142672864893E-7,-0.00510727785877751,0.000142343442987993,0.000661884151884295,1.53119548090351E-7,0.000661884149254719,1.20716993757125E-7,-5.89995685239937E-8,9.4196621094578E-8,1.0001510243129,10.005763053894,2,20,10,5,2.16547420844101,0.19067383942918,0.0410455763339996,172.855895996094,46.4998512268066,46.5004119873047,339.525085449219,339.525085449219,,,61.9917030334473,0,1,,,,,,1,1,1,46.5003852844238,0,46.5001083822811,,,,,,,,,,,,,,,,,,,,,,,,,,,,,,,,,
,3768697425.13496,46.5014133453369,339.525085449219,,,5,,,,25.0300001353025,,,,,0.000663689115192603,1.04630147069916E-7,2.64411617587612E-5,0.000104188664325196,0.000663588862205798,1.04614342253303E-7,0.000663588862205727,7.85209158628136E-8,3.06236525552269E-10,6.91276093696012E-8,1.00015107695821,10.005763053894,2,20,10,5,2.17103445542082,0.191359459154018,0.0410455763339996,172.855895996094,46.5000038146973,46.5014152526855,339.525085449219,339.525085449219,,,62.1907005310059,0,1,,,,,,1,1,1,46.5014038085937,0,46.5006997850206,,,,,,,,,,,,,,,,,,,,,,,,,,,,,,,,,
,3768697632.18119,46.5006103515625,339.525085449219,,,5,,,,25.0300001353025,,,,,0.000665044811892777,1.46146375583601E-7,-0.00482910554086757,0.000172813257158043,0.000664944378559166,1.46124304938988E-7,0.000664944376197364,9.0276029131938E-8,-5.60440333713207E-8,1.14902354449645E-7,1.00015104020253,10.005763053894,2,20,10,5,2.17548540035796,0.191565985996445,0.0410455763339996,172.855895996094,46.4998016357422,46.5010032653809,339.525085449219,339.525085449219,,,62.3896903991699,0,1,,,,,,1,1,1,46.5004959106445,0,46.5002995659323,,,,,,,,,,,,,,,,,,,,,,,,,,,,,,,,,
,3768697841.5673,46.499906539917,339.525085449219,,,5,,,,25.0300001353025,,,,,0.000666391250785664,1.18285981737651E-7,-0.00500055312510206,0.000126041264891295,0.000666290635578197,1.18268122306605E-7,0.000666290633040589,8.32848434173439E-8,-5.81512590290568E-8,8.3970135231989E-8,1.00015100798675,10.005763053894,2,20,10,5,2.17989042685983,0.191947306437648,0.0410455763339996,172.855895996094,46.499153137207,46.5004386901855,339.525085449219,339.525085449219,,,62.5638122558594,0,1,,,,,,1,1,1,46.5000801086426,0,46.4997804429796,,,,,,,,,,,,,,,,,,,,,,,,,,,,,,,,,
,3768698049.67182,46.4998035430908,339.525085449219,,,5,,,,25.0300001353025,,,,,0.000667516295650972,1.11866694657045E-7,-0.00941377929873344,0.000106177947881299,0.000667415513724455,1.11849804970494E-7,0.000667415504716025,8.6546473298146E-8,-1.09657332038749E-7,7.08525711007788E-8,1.00015100327224,10.005763053894,2,20,10,5,2.18358546237602,0.192103173053497,0.0410455763339996,172.855895996094,46.4994354248047,46.5005302429199,339.525085449219,339.525085449219,,,62.7628059387207,0,1,,,,,,1,1,1,46.500171661377,0,46.4999540117052,,,,,,,,,,,,,,,,,,,,,,,,,,,,,,,,,
,3768698258.44793,46.5002861022949,339.525085449219,,,5,,,,25.0300001353025,,,,,0.000668890866709379,1.23855186137175E-7,-0.00605992372990816,0.000145683622637385,0.000668789862479251,1.23836483687574E-7,0.000668789858738587,7.64460846920534E-8,-7.07349753305756E-8,9.74241798906117E-8,1.00015102536057,10.005763053894,2,20,10,5,2.18807070018857,0.192626837705625,0.0410455763339996,172.855895996094,46.4996032714844,46.5006370544434,339.525085449219,339.525085449219,,,62.9742393493652,0,1,,,,,,1,1,1,46.5004272460937,0,46.5000390445485,,,,,,,,,,,,,,,,,,,,,,,,,,,,,,,,,
,3768698466.07788,46.5000972747803,339.525085449219,,,5,,,,25.0300001353025,,,,,0.000669934764571757,1.49058602058917E-7,-0.0103319936491522,0.000135303628122075,0.000669833608499056,1.49036095117071E-7,0.000669833597608252,1.18325760112675E-7,-1.20789290420821E-7,9.06133110613577E-8,1.00015101671731,10.005763053894,2,20,10,5,2.19149986966725,0.192764059135384,0.0410455763339996,172.855895996094,46.4995346069336,46.5005493164063,339.525085449219,339.525085449219,,,63.1607933044434,0,1,,,,,,1,1,1,46.5000839233398,0,46.4999883439806,,,,,,,,,,,,,,,,,,,,,,,,,,,,,,,,,
,3768698674.13604,46.5007648468018,339.525085449219,,,5,,,,25.0300001353025,,,,,0.000671059055779037,1.70697056434804E-7,-0.00536103676780808,0.000106389849762119,0.000670957709445861,1.70671277003613E-7,0.000670957706508769,1.55044063343595E-7,-6.27799983751617E-8,7.13443986305261E-8,1.00015104727429,10.005763053894,2,20,10,5,2.19516090645873,0.193278006354528,0.0410455763339996,172.855895996094,46.4998435974121,46.5008697509766,339.525085449219,339.525085449219,,,63.3597869873047,0,1,,,,,,1,1,1,46.5007591247559,0,46.5003664353315,,,,,,,,,,,,,,,,,,,,,,,,,,,,,,,,,
,3768698882.82515,46.4998531341553,339.525085449219,,,5,,,,25.0300001353025,,,,,0.000672267266622374,1.46328183463048E-7,-0.0059842282674234,0.000172854566396426,0.000672165765866458,1.46306090432537E-7,0.000672165762200247,8.89273404561003E-8,-7.0204008102565E-8,1.16178312163064E-7,1.00015100554219,10.005763053894,2,20,10,5,2.19911529782725,0.193602079399971,0.0410455763339996,172.855895996094,46.4992599487305,46.5000610351562,339.525085449219,339.525085449219,,,63.5339088439941,0,1,,,,,,1,1,1,46.4999122619629,0,46.4996773214901,,,,,,,,,,,,,,,,,,,,,,,,,,,,,,,,,
,3768699090.65652,46.5009078979492,339.525085449219,,,5,,,,25.0300001353025,,,,,0.000673230992796712,1.17376748661424E-7,-0.00428332073886129,0.000128924815113181,0.000673129314040981,1.17359021132711E-7,0.00067312931216,7.90149408066705E-8,-5.03218347421779E-8,8.6774299020772E-8,1.00015105382221,10.005763053894,2,20,10,5,2.20226207498052,0.193944990137943,0.0410455763339996,172.855895996094,46.499454498291,46.5010643005371,339.525085449219,339.525085449219,,,63.7204627990723,0,1,,,,,,1,1,1,46.5007705688477,0,46.5001788419836,,,,,,,,,,,,,,,,,,,,,,,,,,,,,,,,,
,3768699298.43698,46.4998683929443,339.525085449219,,,5,,,,25.0300001353025,,,,,0.000674085893775904,1.65020233676855E-7,-0.00779398378484597,0.000113230325450359,0.000673984117968002,1.64995318354108E-7,0.000673984111732185,1.4630180130554E-7,-9.16825168472712E-8,7.62839302443693E-8,1.00015100624063,10.005763053894,2,20,10,5,2.20507050704218,0.194056164401293,0.0410455763339996,172.855895996094,46.4994888305664,46.5008010864258,339.525085449219,339.525085449219,,,63.8945808410644,0,1,,,,,,1,1,1,46.5000076293945,0,46.5002418966854,,,,,,,,,,,,,,,,,,,,,,,,,,,,,,,,,
,3768699503.96372,46.5002593994141,339.525085449219,,,5,,,,25.0300001353025,,,,,0.000675142978141897,1.62729314133788E-7,-0.00672777379374168,0.000203042944359998,0.000675041030651931,1.62704741790363E-7,0.000675041025998238,8.76859040843888E-8,-7.92645354313949E-8,1.37054789139132E-7,1.00015102413829,10.005763053894,2,20,10,5,2.20852482538671,0.194401576187671,0.0410455763339996,172.855895996094,46.4997901916504,46.5008926391602,339.525085449219,339.525085449219,,,64.0687026977539,0,1,,,,,,1,1,1,46.5000801086426,0,46.5001771714952,,,,,,,,,,,,,,,,,,,,,,,,,,,,,,,,,
,3768699711.32505,46.5008144378662,339.525085449219,,,5,,,,25.0300001353025,,,,,0.000676056003230585,1.04714394760363E-7,-0.00877515367923287,8.85103846434488E-5,0.000675953900701958,1.04698580087558E-7,0.000675953892774184,8.59300382246559E-8,-1.03525938314411E-7,5.98148911481083E-8,1.00015104954424,10.005763053894,2,20,10,5,2.21151846407267,0.194585445506798,0.0410455763339996,172.855895996094,46.4997711181641,46.5011558532715,339.525085449219,339.525085449219,,,64.2428283691406,0,1,,,,,,1,1,1,46.5007209777832,0,46.5003563376034,,,,,,,,,,,,,,,,,,,,,,,,,,,,,,,,,
,3768699919.24237,46.5009002685547,339.525085449219,,,5,,,,25.0300001353025,,,,,0.000677094594294446,1.33292312990342E-7,-0.00470828232429277,0.000120087064317045,0.000676992409906845,1.3327219705161E-7,0.00067699240762107,1.05616022935107E-7,-5.5631870632454E-8,8.12818196544227E-8,1.00015093874925,10.005763053894,2,20,10,5,2.21490207094467,0.195041591552348,0.0410455763339996,172.855895996094,46.4995269775391,46.5016212463379,339.525085449219,339.525085449219,,,64.4169464111328,0,1,,,,,,1,1,1,46.5008735656738,0,46.5003401812385,,,,,,,,,,,,,,,,,,,,,,,,,,,,,,,,,
,3768700127.52792,46.5002880096436,339.525085449219,,,5,,,,25.0300001353025,,,,,0.0006778216451077,1.50278048155881E-7,-0.0012422061948083,7.67125964545033E-5,0.000677719292248053,1.50255355773479E-7,0.000677719292088773,1.40991249170432E-7,-1.46933528134207E-8,5.19436193961862E-8,1.00015102544788,10.005763053894,2,20,10,5,2.217268573184,0.195385158764194,0.0410455763339996,172.855895996094,46.4998817443848,46.5008163452148,339.525085449219,339.525085449219,,,64.591064453125,0,1,,,,,,1,1,1,46.5003395080566,0,46.5003206729889,,,,,,,,,,,,,,,,,,,,,,,,,,,,,,,,,
,3768700331.5996,46.4999504089355,339.525085449219,,,5,,,,25.0300001353025,,,,,0.000678537458746456,8.75090788622781E-8,-0.00697096859692969,9.09356964630622E-5,0.000678435008279399,8.74958661119935E-8,0.000678435003258064,6.2050858257181E-8,-8.25427137268587E-8,6.16864456443644E-8,1.00015100999478,10.005763053894,2,20,10,5,2.21962966506868,0.195369566653246,0.0410455763339996,172.855895996094,46.499626159668,46.5003814697266,339.525085449219,339.525085449219,,,64.7651824951172,0,1,,,,,,1,1,1,46.4999809265137,0,46.4999570344624,,,,,,,,,,,,,,,,,,,,,,,,,,,,,,,,,
,3768700536.8665,46.4999141693115,339.525085449219,,,5,,,,25.0300001353025,,,,,0.000679357023283616,1.39504643918038E-7,-0.00377520977338897,0.000170197251504513,0.000679254450199391,1.39483580734616E-7,0.000679254448724909,7.80524098534598E-8,-4.47559673495617E-8,1.15600564923437E-7,1.00015100833597,10.005763053894,2,20,10,5,2.22229970849124,0.195729493547146,0.0410455763339996,172.855895996094,46.4996223449707,46.5003662109375,339.525085449219,339.525085449219,,,64.9393005371094,0,1,,,,,,1,1,1,46.5001182556152,0,46.4998934268951,,,,,,,,,,,,,,,,,,,,,,,,,,,,,,,,,
,3768700742.40083,46.5006542205811,339.525085449219,,,5,,,,25.0300001353025,,,,,0.000680055451842549,1.48646199973021E-7,-0.00954011185128412,0.000180248948586901,0.000679952750276069,1.4862375151305E-7,0.000679952740850439,8.40820910023594E-8,-1.13216458810321E-7,1.22552933406279E-7,1.00015104221056,10.005763053894,2,20,10,5,2.22460409743521,0.195706884736607,0.0410455763339996,172.855895996094,46.4999351501465,46.5008888244629,339.525085449219,339.525085449219,,,65.1134262084961,0,1,,,,,,1,1,1,46.5005378723145,0,46.5003130435944,,,,,,,,,,,,,,,,,,,,,,,,,,,,,,,,,
,3768700948.85173,46.499755859375,339.525085449219,,,5,,,,25.0300001353025,,,,,0.000681022301869974,1.39687232492603E-7,-0.00321648571461441,0.000128355309348656,0.000680919482286218,1.39666142752867E-7,0.000680919481213258,1.08953070155246E-7,-3.82256390442475E-8,8.73834076653588E-8,1.0001510010896,10.005763053894,2,20,10,5,2.22774522249174,0.19623100111342,0.0410455763339996,172.855895996094,46.4994354248047,46.5003128051758,339.525085449219,339.525085449219,,,65.2875442504883,0,1,,,,,,1,1,1,46.5000648498535,0,46.4998489828671,,,,,,,,,,,,,,,,,,,,,,,,,,,,,,,,,
,3768701155.32673,46.5008125305176,339.525085449219,,,5,,,,25.0300001353025,,,,,0.000681573204527551,1.70976874240103E-7,-0.00701427295877455,0.000178752497771392,0.000681470268813531,1.7095105217651E-7,0.000681470263706871,1.19954005920481E-7,-8.34270605519263E-8,1.21800240984511E-7,1.00015104945693,10.005763053894,2,20,10,5,2.22956033576168,0.196241955737268,0.0410455763339996,172.855895996094,46.499382019043,46.5016670227051,339.525085449219,339.525085449219,,,65.4616622924805,0,1,,,,,,1,1,1,46.500057220459,0,46.5001121097141,,,,,,,,,,,,,,,,,,,,,,,,,,,,,,,,,
,3768701360.7238,46.5002899169922,339.525085449219,,,5,,,,25.0300001353025,,,,,0.000682430194371111,1.28141933130245E-7,-0.0147019704804077,0.000160533344770988,0.000682327145548784,1.28122583348526E-7,0.000682327123085747,6.64725019484583E-8,-1.75083636648401E-7,1.09529917596117E-7,1.00015102553518,10.005763053894,2,20,10,5,2.23239006241848,0.196189173866779,0.0410455763339996,172.855895996094,46.4993667602539,46.5009155273438,339.525085449219,339.525085449219,,,65.6482162475586,0,1,,,,,,1,1,1,46.500072479248,0,46.5000596887925,,,,,,,,,,,,,,,,,,,,,,,,,,,,,,,,,
,3768701567.10096,46.5020751953125,339.525085449219,,,5,,,,25.0300001353025,,,,,0.000683123644344135,1.10837642081329E-7,-0.00825731325084966,0.000118785127290109,0.000683020513349109,1.10820908951962E-7,0.00068302050625601,7.54993751556784E-8,-9.84350743438034E-8,8.11240914404669E-8,1.00015099252952,10.005763053894,2,20,10,5,2.23463639760742,0.196639875895958,0.0410455763339996,172.855895996094,46.5005798339844,46.5026817321777,339.525085449219,339.525085449219,,,65.7974624633789,0,1,,,,,,1,1,1,46.5019760131836,0,46.5012186835794,,,,,,,,,,,,,,,,,,,,,,,,,,,,,,,,,
,3768701774.99186,46.5007228851318,339.525085449219,,,5,,,,25.0300001353025,,,,,0.000683799461807933,1.91962714763484E-7,-0.00326343872251922,0.000233558005919156,0.000683696192674779,1.91933724066271E-7,0.00068369619156576,1.06502779042466E-7,-3.89417972382762E-8,1.59673768948375E-7,1.00015104535357,10.005763053894,2,20,10,5,2.23682996899491,0.197029380190182,0.0410455763339996,172.855895996094,46.4995956420898,46.5008964538574,339.525085449219,339.525085449219,,,65.9715805053711,0,1,,,,,,1,1,1,46.5008277893066,0,46.5002430809869,,,,,,,,,,,,,,,,,,,,,,,,,,,,,,,,,
,3768701983.79188,46.4999923706055,339.525085449219,,,5,,,,25.0300001353025,,,,,0.000684193346598359,1.3827154329472E-7,-0.0104111495200589,0.000139643336793682,0.000684090040850914,1.38250665796858E-7,0.000684090029557237,9.99495121189026E-8,-1.24305205755382E-7,9.55161851230877E-8,1.0001510119155,10.005763053894,2,20,10,5,2.23814301231426,0.196863669423815,0.0410455763339996,172.855895996094,46.4991493225098,46.5002555847168,339.525085449219,339.525085449219,,,66.1083908081055,0,1,,,,,,1,1,1,46.4998474121094,0,46.4999055301442,,,,,,,,,,,,,,,,,,,,,,,,,,,,,,,,,
,3768702191.49464,46.4998435974121,339.525085449219,,,5,,,,25.0300001353025,,,,,0.000684856812720986,9.65782096734096E-8,-0.00579167441546335,0.000110831598030185,0.000684753411459737,9.65636280725495E-8,0.000684753407961355,5.97142049978191E-8,-6.92174683895042E-8,7.58864150425629E-8,1.00015100510566,10.005763053894,2,20,10,5,2.24029745729502,0.197235194247058,0.0410455763339996,172.855895996094,46.4992828369141,46.5007781982422,339.525085449219,339.525085449219,,,66.3073883056641,0,1,,,,,,1,1,1,46.4997901916504,0,46.4999573651482,,,,,,,,,,,,,,,,,,,,,,,,,,,,,,,,,
,3768702396.58716,46.4997844696045,339.525085449219,,,5,,,,25.0300001353025,,,,,0.000685458661675914,1.03309805257887E-7,-0.00501502128953835,0.000103875934107347,0.000685355171400738,1.0329420758472E-7,0.000685355168775395,7.48515240801752E-8,-5.9988201579427E-8,7.11824603637031E-8,1.00015100239919,10.005763053894,2,20,10,5,2.24226354409096,0.197438917781197,0.0410455763339996,172.855895996094,46.4993438720703,46.5003280639648,339.525085449219,339.525085449219,,,66.4566268920898,0,1,,,,,,1,1,1,46.4998054504395,0,46.4997803183163,,,,,,,,,,,,,,,,,,,,,,,,,,,,,,,,,
,3768702601.83774,46.4996128082275,339.525085449219,,,5,,,,25.0300001353025,,,,,0.000686207366488164,1.24758589217463E-7,-0.00568783594598976,0.00014702114143876,0.000686103768564086,1.2473975419545E-7,0.00068610376518337,7.3391207677524E-8,-6.81105258410378E-8,1.00864943921938E-7,1.00015099454168,10.005763053894,2,20,10,5,2.2447150184021,0.197628215831023,0.0410455763339996,172.855895996094,46.4991989135742,46.4998817443848,339.525085449219,339.525085449219,,,66.6307525634766,0,1,,,,,,1,1,1,46.4995918273926,0,46.4996126960306,,,,,,,,,,,,,,,,,,,,,,,,,,,,,,,,,
,3768702808.04634,46.5001392364502,339.525085449219,,,5,,,,25.0300001353025,,,,,0.000686777337329689,1.46349236827768E-7,-0.00536898953185094,0.000130963904342544,0.000686673636812282,1.46327138702574E-7,0.00068667363379747,1.15444630282372E-7,-6.43458138414168E-8,8.99120062052263E-8,1.00015101863804,10.005763053894,2,20,10,5,2.24657840102271,0.197804868187463,0.0410455763339996,172.855895996094,46.4991569519043,46.5009384155273,339.525085449219,339.525085449219,,,66.8173065185547,0,1,,,,,,1,1,1,46.4999313354492,0,46.5000139124253,,,,,,,,,,,,,,,,,,,,,,,,,,,,,,,,,
,3768703014.64995,46.5004119873047,339.525085449219,,,5,,,,25.0300001353025,,,,,0.000687345757283215,1.39054882903061E-7,-0.0101861807246015,0.000182305423540212,0.000687241962358043,1.39033884459391E-7,0.000687241951497359,6.02875236148866E-8,-1.22179519202355E-7,1.25283021691895E-7,1.00015103112274,10.005763053894,2,20,10,5,2.24845444660432,0.197779542642958,0.0410455763339996,172.855895996094,46.4993934631348,46.5007171630859,339.525085449219,339.525085449219,,,66.9789886474609,0,1,,,,,,1,1,1,46.5001792907715,0,46.5000823525822,,,,,,,,,,,,,,,,,,,,,,,,,,,,,,,,,
,3768703219.87135,46.5006923675537,339.525085449219,,,5,,,,25.0300001353025,,,,,0.000688104197975763,1.16624539562268E-7,-0.003731766214921,0.000105575987182966,0.000688000279691324,1.16606926790669E-7,0.000688000278232032,9.12311558677646E-8,-4.48105640522232E-8,7.26226657084146E-8,1.00015104395668,10.005763053894,2,20,10,5,2.25091314929174,0.198251342767901,0.0410455763339996,172.855895996094,46.4993057250977,46.5013122558594,339.525085449219,339.525085449219,,,67.1282348632813,0,1,,,,,,1,1,1,46.5011711120605,0,46.5000661962173,,,,,,,,,,,,,,,,,,,,,,,,,,,,,,,,,
,3768703424.98049,46.5,339.525085449219,,,5,,,,25.0300001353025,,,,,0.000688503756566448,1.9303639854432E-7,-0.0106930378220076,0.000139752300759156,0.000688399799753651,1.93007252082075E-7,0.000688399787765073,1.67339334536147E-7,-1.284751706889E-7,9.61735227246733E-8,1.00015101226472,10.005763053894,2,20,10,5,2.25224426156773,0.198092825176638,0.0410455763339996,172.855895996094,46.4996490478516,46.5006713867188,339.525085449219,339.525085449219,,,67.3023529052734,0,1,,,,,,1,1,1,46.500301361084,0,46.5002679263844,,,,,,,,,,,,,,,,,,,,,,,,,,,,,,,,,
,3768703631.24156,46.5003242492676,339.525085449219,,,5,,,,25.0300001353025,,,,,0.000689108151101517,1.15450124250965E-7,-0.00410740140150434,0.000135126125871887,0.000689004092806886,1.15432690785659E-7,0.000689004091036447,6.82481345842892E-8,-4.93931036118827E-8,9.30961772995129E-8,1.00015102710668,10.005763053894,2,20,10,5,2.25419856262306,0.198525818995459,0.0410455763339996,172.855895996094,46.4990692138672,46.5004577636719,339.525085449219,339.525085449219,,,67.4515991210937,0,1,,,,,,1,1,1,46.5004539489746,0,46.4998474121094,,,,,,,,,,,,,,,,,,,,,,,,,,,,,,,,,
,3768703838.08589,46.5009269714355,339.525085449219,,,5,,,,25.0300001353025,,,,,0.000689455043481588,1.21213591118326E-7,-0.00820345985570459,9.66057871364622E-5,0.000689350913789372,1.21195284001633E-7,0.000689350906723606,1.0127041481082E-7,-9.86994605274883E-8,6.65777736807171E-8,1.00015105469527,10.005763053894,2,20,10,5,2.25534750506274,0.198464519660061,0.0410455763339996,172.855895996094,46.4988899230957,46.501049041748,339.525085449219,339.525085449219,,,67.61328125,0,1,,,,,,1,1,1,46.5009078979492,0,46.5002270866843,,,,,,,,,,,,,,,,,,,,,,,,,,,,,,,,,
,3768704043.43709,46.5010528564453,339.525085449219,,,5,,,,25.0300001353025,,,,,0.000689897995998634,1.38133276401281E-7,-0.00976054860407771,0.000137515872863263,0.000689793795432354,1.38112413076983E-7,0.000689793785423313,1.0039655558713E-7,-1.17508931578579E-7,9.4844980216074E-8,1.00015106045744,10.005763053894,2,20,10,5,2.25680188890191,0.19853069511446,0.0410455763339996,172.855895996094,46.4999122619629,46.5013618469238,339.525085449219,339.525085449219,,,67.7625274658203,0,1,,,,,,1,1,1,46.500919342041,0,46.5005179012523,,,,,,,,,,,,,,,,,,,,,,,,,,,,,,,,,
,3768704248.60055,46.4999809265137,339.525085449219,,,5,,,,25.0300001353025,,,,,0.000690361255269568,1.04505055272033E-7,-0.0106212676709001,9.66809308191477E-5,0.000690257018596582,1.0448927620102E-7,0.000690257006736484,8.04113255441736E-8,-1.27957147569099E-7,6.67235158339389E-8,1.00015101139167,10.005763053894,2,20,10,5,2.25832029152597,0.198630084785336,0.0410455763339996,172.855895996094,46.4992904663086,46.5003662109375,339.525085449219,339.525085449219,,,67.9366455078125,0,1,,,,,,1,1,1,46.5001754760742,0,46.4998460657456,,,,,,,,,,,,,,,,,,,,,,,,,,,,,,,,,
,3768704453.53739,46.4996643066406,339.525085449219,,,5,,,,25.0300001353025,,,,,0.000690515686944851,1.54404218139237E-7,-0.0107272309545499,0.000186636956859432,0.000690411436958884,1.54380907101011E-7,0.000690411424858254,8.50385358095561E-8,-1.29262625582409E-7,1.28848406682806E-7,1.00015099689893,10.005763053894,2,20,10,5,2.25882583795393,0.198670343071022,0.0410455763339996,172.855895996094,46.4996147155762,46.5003356933594,339.525085449219,339.525085449219,,,68.0858917236328,0,1,,,,,,1,1,1,46.4996070861816,0,46.4998036552878,,,,,,,,,,,,,,,,,,,,,,,,,,,,,,,,,
,3768704661.24943,46.5001754760742,339.525085449219,,,5,,,,25.0300001353025,,,,,0.000691228570333972,9.99223097704747E-8,-0.00895362759731988,8.81126111390745E-5,0.000691124196552652,9.99072217521888E-8,0.000691124188113887,7.92116240390858E-8,-1.08002172356004E-7,6.08849043304787E-8,1.00015102029684,10.005763053894,2,20,10,5,2.26115167632798,0.198945440415628,0.0410455763339996,172.855895996094,46.499641418457,46.5002708435059,339.525085449219,339.525085449219,,,68.260009765625,0,1,,,,,,1,1,1,46.5002098083496,0,46.4999447990866,,,,,,,,,,,,,,,,,,,,,,,,,,,,,,,,,
,3768704868.12443,46.4985866546631,339.525085449219,,,5,,,,25.0300001353025,,,,,0.000691797135162225,1.19305088254319E-7,-0.00756759574000476,0.000112087042711728,0.000691692646483633,1.19287068475995E-7,0.00069169264045035,9.06668081918934E-8,-9.13583924363545E-8,7.75173180514594E-8,1.00015106229497,10.005763053894,2,20,10,5,2.2630067516756,0.199163831908976,0.0410455763339996,172.855895996094,46.4976043701172,46.5015602111816,339.525085449219,339.525085449219,,,68.4216918945313,0,1,,,,,,1,1,1,46.4989356994629,0,46.4998308817546,,,,,,,,,,,,,,,,,,,,,,,,,,,,,,,,,
,3768705075.36039,46.5009784698486,339.525085449219,,,5,,,,25.0300001353025,,,,,0.000692430798451211,9.89698009220933E-8,-0.00743051183861443,9.24512988743476E-5,0.000692326217693381,9.89548530936521E-8,0.000692326211871371,7.54756578682722E-8,-8.97856384196508E-8,6.39960000323285E-8,1.00015105705252,10.005763053894,2,20,10,5,2.2650791147562,0.199351670747297,0.0410455763339996,172.855895996094,46.4997940063477,46.5014724731445,339.525085449219,339.525085449219,,,68.5958099365234,0,1,,,,,,1,1,1,46.5005302429199,0,46.5003980748794,,,,,,,,,,,,,,,,,,,,,,,,,,,,,,,,,
,3768705281.94262,46.5005970001221,339.525085449219,,,5,,,,25.0300001353025,,,,,0.00069288877776106,1.27349325268976E-7,-0.00719870450696813,0.000135121306402158,0.000692784139927642,1.273300933837E-7,0.000692784134459606,8.63247482584748E-8,-8.70421580736766E-8,9.36001630298399E-8,1.00015103959139,10.005763053894,2,20,10,5,2.26657644917369,0.199492694471659,0.0410455763339996,172.855895996094,46.4996299743652,46.5013771057129,339.525085449219,339.525085449219,,,68.7699356079102,0,1,,,,,,1,1,1,46.5003700256348,0,46.5001860225902,,,,,,,,,,,,,,,,,,,,,,,,,,,,,,,,,
,3768705489.76712,46.5000095367432,339.525085449219,,,5,,,,25.0300001353025,,,,,0.000693189214781028,1.28783558949235E-7,-0.00671040478297513,0.000100076437758754,0.000693084550210905,1.28764113932565E-7,0.00069308454545746,1.08498363565556E-7,-8.11731319415416E-8,6.9341921955157E-8,1.00015101270125,10.005763053894,2,20,10,5,2.26755753707488,0.199598521117102,0.0410455763339996,172.855895996094,46.4996070861816,46.5000801086426,339.525085449219,339.525085449219,,,68.90673828125,0,1,,,,,,1,1,1,46.5000991821289,0,46.4998407363892,,,,,,,,,,,,,,,,,,,,,,,,,,,,,,,,,
,3768705695.78044,46.4996967315674,339.525085449219,,,5,,,,25.0300001353025,,,,,0.000693458967786051,1.17943447732826E-7,-0.0113884579821386,0.000110202802802062,0.000693354272411984,1.17925641151683E-7,0.000693354258715478,8.98325991270892E-8,-1.37815315773882E-7,7.63973885359126E-8,1.00015099838313,10.005763053894,2,20,10,5,2.26845624726971,0.199490983095483,0.0410455763339996,172.855895996094,46.4994163513184,46.5003242492676,339.525085449219,339.525085449219,,,69.0808563232422,0,1,,,,,,1,1,1,46.4997749328613,0,46.4997186099782,,,,,,,,,,,,,,,,,,,,,,,,,,,,,,,,,
,3768705900.83427,46.5011425018311,339.525085449219,,,5,,,,25.0300001353025,,,,,0.000694017623125188,1.45895456069112E-7,-0.0100640380559422,0.000114483798828451,0.000693912797493195,1.45873419765021E-7,0.000693912786788503,1.22357692862767E-7,-1.21886198685393E-7,7.94207126085065E-8,1.00015106456081,10.005763053894,2,20,10,5,2.27027911622944,0.199704166673393,0.0410455763339996,172.855895996094,46.4996032714844,46.501392364502,339.525085449219,339.525085449219,,,69.2425384521484,0,1,,,,,,1,1,1,46.501049041748,0,46.5003134783577,,,,,,,,,,,,,,,,,,,,,,,,,,,,,,,,,
,3768706108.47197,46.5012760162354,339.525085449219,,,5,,,,25.0300001353025,,,,,0.000694961028142357,9.8592661957946E-8,-0.00600061249580186,8.9145550078677E-5,0.000694856055770926,9.85777697480057E-8,0.000694856051960174,7.66941049906684E-8,-7.27725839294724E-8,6.19321479376517E-8,1.0001510706722,10.005763053894,2,20,10,5,2.27335100660107,0.200136857880577,0.0410455763339996,172.855895996094,46.4997711181641,46.5016708374023,339.525085449219,339.525085449219,,,69.4042205810547,0,1,,,,,,1,1,1,46.5013084411621,0,46.5004925447352,,,,,,,,,,,,,,,,,,,,,,,,,,,,,,,,,
,3768706313.63705,46.500431060791,339.525085449219,,,5,,,,25.0300001353025,,,,,0.000694942348160545,1.22653770206083E-7,-0.00109681206036782,0.00012056545275207,0.000694837405480438,1.22635248359767E-7,0.000694837405353125,8.95732397757468E-8,-1.33012597569263E-8,8.37617983112728E-8,1.0001510319958,10.005763053894,2,20,10,5,2.27327276340467,0.200326046260985,0.0410455763339996,172.855895996094,46.4997291564941,46.5006217956543,339.525085449219,339.525085449219,,,69.5659027099609,0,1,,,,,,1,1,1,46.5006103515625,0,46.5001786175896,,,,,,,,,,,,,,,,,,,,,,,,,,,,,,,,,
,3768706518.72388,46.501012802124,339.525085449219,,,5,,,,25.0300001353025,,,,,0.000695378806979434,1.21641869110745E-7,-0.00850643699346243,0.000140539871521689,0.000695273779878925,1.21623496832664E-7,0.000695273772216328,7.24270545736066E-8,-1.03224052980534E-7,9.77066873228076E-8,1.00015105862402,10.005763053894,2,20,10,5,2.27472639734996,0.200157687652407,0.0410455763339996,172.855895996094,46.4997367858887,46.5012016296387,339.525085449219,339.525085449219,,,69.7027130126953,0,1,,,,,,1,1,1,46.5010414123535,0,46.5003978504854,,,,,,,,,,,,,,,,,,,,,,,,,,,,,,,,,
,3768706724.37362,46.5004653930664,339.525085449219,,,5,,,,25.0300001353025,,,,,0.000695643093859056,1.22473083400565E-7,-0.00936519991387197,0.000144056735032763,0.000695538044267035,1.22454588647209E-7,0.000695538034975666,7.04061777037697E-8,-1.13688178407134E-7,1.00190301037089E-7,1.0001510335673,10.005763053894,2,20,10,5,2.27559393451411,0.200199655090902,0.0410455763339996,172.855895996094,46.4992446899414,46.5006294250488,339.525085449219,339.525085449219,,,69.8643951416016,0,1,,,,,,1,1,1,46.5005874633789,0,46.49990642772,,,,,,,,,,,,,,,,,,,,,,,,,,,,,,,,,
,3768706931.15873,46.4996109008789,339.525085449219,,,5,,,,25.0300001353025,,,,,0.00069583819307973,1.13942752059372E-7,-0.00784770395030776,0.000118526991655585,0.000695733141233681,1.13925549933121E-7,0.000695733134707597,7.86152734636273E-8,-9.52933662854056E-8,8.24540460244561E-8,1.00015099445437,10.005763053894,2,20,10,5,2.27622683978127,0.200316094155907,0.0410455763339996,172.855895996094,46.4989585876465,46.499942779541,339.525085449219,339.525085449219,,,70.0260772705078,0,1,,,,,,1,1,1,46.4996566772461,0,46.4995254067814,,,,,,,,,,,,,,,,,,,,,,,,,,,,,,,,,
,3768707139.61698,46.4997978210449,339.525085449219,,,5,,,,25.0300001353025,,,,,0.000696140830413316,1.77869121774276E-7,-0.0141314080742152,0.000185622091218006,0.000696035726923257,1.77842267056587E-7,0.00069603570575295,1.22225147861284E-7,-1.71669970724766E-7,1.2918546815379E-7,1.00015100301033,10.005763053894,2,20,10,5,2.27723879230091,0.200153469204876,0.0410455763339996,172.855895996094,46.4994812011719,46.4999580383301,339.525085449219,339.525085449219,,,70.1877593994141,0,1,,,,,,1,1,1,46.4998168945313,0,46.4997392542222,,,,,,,,,,,,,,,,,,,,,,,,,,,,,,,,,
,3768707344.8358,46.4999122619629,339.525085449219,,,5,,,,25.0300001353025,,,,,0.000696610425041368,1.53113141160207E-7,-0.00750354452921265,0.000174108742783516,0.000696505247003833,1.530900233039E-7,0.000696505241030977,9.34502171679043E-8,-9.12154117667778E-8,1.21258451855779E-7,1.00015100824866,10.005763053894,2,20,10,5,2.27875176156646,0.200552088278515,0.0410455763339996,172.855895996094,46.4994125366211,46.5000762939453,339.525085449219,339.525085449219,,,70.3370056152344,0,1,,,,,,1,1,1,46.5000190734863,0,46.4997026780072,,,,,,,,,,,,,,,,,,,,,,,,,,,,,,,,,
,3768707552.56212,46.500394821167,339.525085449219,,,5,,,,25.0300001353025,,,,,0.000697036854022929,2.26714740078595E-7,-0.00757752770308429,0.000110848701993022,0.000696931596209091,2.26680504445618E-7,0.000696931590114144,2.13133684492989E-7,-9.2171160021105E-8,7.71886237094753E-8,1.00015103033699,10.005763053894,2,20,10,5,2.2801469551008,0.200671910685015,0.0410455763339996,172.855895996094,46.4992179870605,46.5007781982422,339.525085449219,339.525085449219,,,70.4986877441406,0,1,,,,,,1,1,1,46.5002174377441,0,46.4999171986299,,,,,,,,,,,,,,,,,,,,,,,,,,,,,,,,,
,3768707757.62102,46.4997310638428,339.525085449219,,,5,,,,25.0300001353025,,,,,0.000697146193834688,1.54714256017414E-7,-0.0113077157762023,0.000138010932034549,0.000697040940684271,1.5469089769888E-7,0.000697040927109492,1.21154116542628E-7,-1.37565818240908E-7,9.61818791439458E-8,1.00015099995463,10.005763053894,2,20,10,5,2.28051768908252,0.200554920329806,0.0410455763339996,172.855895996094,46.4994316101074,46.5000839233398,339.525085449219,339.525085449219,,,70.6479339599609,0,1,,,,,,1,1,1,46.499813079834,0,46.499787274529,,,,,,,,,,,,,,,,,,,,,,,,,,,,,,,,,
,3768707962.70707,46.5006771087646,339.525085449219,,,5,,,,25.0300001353025,,,,,0.000697520830554112,1.82045294094687E-7,-0.00642448506054638,0.000168115780408593,0.000697415490646065,1.82017801532887E-7,0.000697415486261838,1.39241875975929E-7,-7.82000948296275E-8,1.1722704487263E-7,1.00015104325823,10.005763053894,2,20,10,5,2.28172609765477,0.200857160306598,0.0410455763339996,172.855895996094,46.4998626708984,46.5008811950684,339.525085449219,339.525085449219,,,70.8096160888672,0,1,,,,,,1,1,1,46.5006408691406,0,46.5003882015453,,,,,,,,,,,,,,,,,,,,,,,,,,,,,,,,,
,3768708170.25749,46.5012321472168,339.525085449219,,,5,,,,25.0300001353025,,,,,0.000698008977075045,1.04643218487535E-7,-0.006374005044818,0.000104300026485943,0.000697903545718671,1.04627412564083E-7,0.000697903541400051,7.51642845273569E-8,-7.76399370047113E-8,7.27820430555877E-8,1.00015106866417,10.005763053894,2,20,10,5,2.28332274291345,0.20099973494274,0.0410455763339996,172.855895996094,46.4998435974121,46.5014457702637,339.525085449219,339.525085449219,,,70.9837341308594,0,1,,,,,,1,1,1,46.5012512207031,0,46.5004703297335,,,,,,,,,,,,,,,,,,,,,,,,,,,,,,,,,
,3768708375.5867,46.5008239746094,339.525085449219,,,5,,,,25.0300001353025,,,,,0.000698385127099414,1.18081376930057E-7,-0.00513491702531876,0.000114429433283469,0.000698279651971415,1.18063543434092E-7,0.000698279649167137,8.69264015381411E-8,-6.25806664821283E-8,7.98924339586899E-8,1.00015104998077,10.005763053894,2,20,10,5,2.28454885269543,0.201157459668512,0.0410455763339996,172.855895996094,46.4997253417969,46.5008888244629,339.525085449219,339.525085449219,,,71.1578598022461,0,1,,,,,,1,1,1,46.5008735656738,0,46.5003384484185,,,,,,,,,,,,,,,,,,,,,,,,,,,,,,,,,
,3768708531.74597,46.4998531341553,339.525085449219,,,5,,,,25.0300001353025,,,,,0.00069854558278714,1.85360599925356E-7,-0.00453568762507572,0.000116568232482473,0.000698440114458969,1.85332613673543E-7,0.000698440112270501,1.66511449948234E-7,-5.52903932474809E-8,8.13763769604151E-8,1.00015100554219,10.005763053894,2,20,10,5,2.28507162840704,0.201227580635219,0.0410455763339996,172.855895996094,46.4988784790039,46.5003128051758,339.525085449219,339.525085449219,,,71.2573547363281,0,1,,,,,,1,1,1,46.4996757507324,0,46.499646579518,,,,,,,,,,,,,,,,,,,,,,,,,,,,,,,,,