File: Experimental_Data/Fig3C/Lifetime_260Oe_48p5K.dat
[Header]
; MPMS3 Data File (default extension .dat)
; Copyright (c) 2007, Quantum Design, Inc. All rights reserved.
TITLE,260Oe_48p5K
FILEOPENTIME,3768520288.04686,06/01/2019,3:11 am
BYAPP,SQUID AC,0.9.1.0
INFO,MPMS3 Measurement Release 1.1.16 Build 347, MultiVu Release 2.3.3.2,APPNAME
INFO,0,MOMENT_UNITS
INFO,,SAMPLE_MATERIAL
INFO,,SAMPLE_COMMENT
INFO,,SAMPLE_MASS
INFO,,SAMPLE_VOLUME
INFO,,SAMPLE_MOLECULAR_WEIGHT
INFO,,SAMPLE_SIZE
INFO,,SAMPLE_SHAPE
INFO,Quartz,SAMPLE_HOLDER
INFO,Standard,SAMPLE_HOLDER_DETAIL
INFO,66.2,SAMPLE_OFFSET
DATATYPE,COMMENT,1
DATATYPE,TIME,2
STARTUPAXIS,X,2
STARTUPAXIS,Y1,5
FIELDGROUP, VSM,2,3,4,5,6,8,9,10,11,14,15
FIELDGROUP, DC, 2,3,4,14,56,57,58,59,60,61,62,63,64,65,66,67,68,69
FIELDGROUP, AC, 2,3,4,11,16,17,18,19,20,21,22,23,24,25,26,27,28,29,30
STARTUPGROUP, All
[Data]
Comment,Time Stamp (sec),Temperature (K),Magnetic Field (Oe),Moment (emu),M. Std. Err. (emu),Transport Action,Averaging Time (sec),Frequency (Hz),Peak Amplitude (mm),Center Position (mm),Lockin Signal' (V),Lockin Signal (V),Range,M. Quad. Signal (emu),AC Moment (emu),AC M. Std Err. (emu),AC Phase (deg),AC Phase Std. Err. (deg),AC Susceptibility (emu/Oe),AC Suscept. Std Err. (emu/Oe),AC X' (emu/Oe),AC X' Std Err. (emu/Oe),AC X'' (emu/Oe),AC X'' Std Err. (emu/Oe),AC Drive (Oe),AC Frequency (Hz),AC Averaging Time (sec),AC Cycles,AC Range,AC Measure Type,AC Signal' (V),AC Signal'' (V),AC Trim Coil Ratio,AC Trim Coil Phase,Min. Temperature (K),Max. Temperature (K),Min. Field (Oe),Max. Field (Oe),Mass (grams),Motor Lag (deg),Pressure (Torr),Measure Count,Measurement Number,SQUID Status (code),Motor Status (code),Measure Status (code),Motor Current (amps),Motor Temp. (C),Temp. Status (code),Field Status (code),Chamber Status (code),Chamber Temp (K),Redirection State,Average Temp (K),Rotation Angle (deg),Rotator state,DC Moment Fixed Ctr (emu),DC Moment Err Fixed Ctr (emu),DC Moment Free Ctr (emu),DC Moment Err Free Ctr (emu),DC Fixed Fit,DC Free Fit,DC Calculated Center (mm),DC Calculated Center Err (mm),DC Scan Length (mm),DC Scan Time (s),DC Number of Points,DC Squid Drift,DC Min V (V),DC Max V (V),DC Scans per Measure,Map 01,Map 02,Map 03,Map 04,Map 05,Map 06,Map 07,Map 08,Map 09,Map 10,Map 11,Map 12,Map 13,Map 14,Map 15,Map 16
,3768520292.1145,48.4544811248779,259.528259277344,,,5,,,,25.0300001353025,,,,,0.000602002488528503,1.19710257131071E-7,0.0456674144788369,0.000139146819132533,0.000601912162620691,1.19692295514872E-7,0.000601911971428265,8.55181842129474E-8,4.79752078310665E-7,8.37429744786974E-8,1.0001500649321,10.005763053894,2,20,10,5,1.96911993868104,0.174965755514188,0.0410455763339996,172.855895996094,48.4094696044922,48.4674224853516,259.528259277344,259.528259277344,,,32.7147560119629,0,1,,,,,,1,1,3,48.4473304748535,0,48.4287954631605,,,,,,,,,,,,,,,,,,,,,,,,,,,,,,,,,
,3768520501.30748,48.5006656646729,259.528259277344,,,5,,,,25.0300001353025,,,,,0.000606503126431386,1.49163625033641E-7,-0.00463889173856291,0.000149033868219896,0.000606411747934026,1.49141151368919E-7,0.000606411745946464,1.18653249601809E-7,-4.90974809748941E-8,9.03575641027216E-8,1.00015068721487,10.005763053894,2,20,10,5,1.98399532283521,0.174531719789575,0.0410455763339996,172.855895996094,48.4995498657227,48.5010185241699,259.528259277344,259.528259277344,,,32.9261856079102,0,1,,,,,,1,1,3,48.500560760498,0,48.5001595441033,,,,,,,,,,,,,,,,,,,,,,,,,,,,,,,,,
,3768520706.53748,48.5003089904785,259.528259277344,,,5,,,,25.0300001353025,,,,,0.000608356959259004,1.26616252757352E-7,0.000236289409776269,0.000146560519821981,0.000608265311383052,1.26597178247807E-7,0.000608265311377879,8.98970971376598E-8,2.50850329003475E-9,8.91367346638257E-8,1.00015067089021,10.005763053894,2,20,10,5,1.99004468445055,0.175234523849047,0.0410455763339996,172.855895996094,48.499683380127,48.5006675720215,259.528259277344,259.528259277344,,,33.0505561828613,0,1,,,,,,1,1,3,48.4999542236328,0,48.5001894632975,,,,,,,,,,,,,,,,,,,,,,,,,,,,,,,,,
,3768520911.81274,48.5010318756103,259.528259277344,,,5,,,,25.0300001353025,,,,,0.000609958878858758,1.26344580795843E-7,0.00224085231924764,9.21216788630379E-5,0.000609866969481618,1.26325543034235E-7,0.000609866969015188,1.13158785757358E-7,2.38520502602635E-8,5.61536466208104E-8,1.00015070397601,10.005763053894,2,20,10,5,1.99527870280449,0.175765753744784,0.0410455763339996,172.855895996094,48.4994621276855,48.5015716552734,259.528259277344,259.528259277344,,,33.1624908447266,0,1,,,,,,1,1,3,48.5008430480957,0,48.5002677019905,,,,,,,,,,,,,,,,,,,,,,,,,,,,,,,,,
,3768521118.17711,48.4996643066406,259.528259277344,,,5,,,,25.0300001353025,,,,,0.000611273133787065,1.10688071430855E-7,0.00174094771714994,0.00011512674486367,0.000611181064625851,1.10671399738072E-7,0.00061118106434371,8.54338809359999E-8,1.85709015237146E-8,7.03506269211404E-8,1.00015064138361,10.005763053894,2,20,10,5,1.99957938928257,0.176127029349952,0.0410455763339996,172.855895996094,48.4987945556641,48.5003128051758,259.528259277344,259.528259277344,,,33.2371139526367,0,1,,,,,,1,1,3,48.4991874694824,0,48.4997239954331,,,,,,,,,,,,,,,,,,,,,,,,,,,,,,,,,
,3768521324.64072,48.5012378692627,259.528259277344,,,5,,,,25.0300001353025,,,,,0.00061275437251989,1.2932358543346E-7,-0.00303965178100452,0.000152141238696607,0.000612662036138825,1.29304097572744E-7,0.000612662035276654,8.96279439598057E-8,-3.25029044766631E-8,9.3200758101206E-8,1.00015071340416,10.005763053894,2,20,10,5,2.00443950048508,0.176386568100495,0.0410455763339996,172.855895996094,48.4993782043457,48.5015449523926,259.528259277344,259.528259277344,,,33.3117370605469,0,1,,,,,,1,1,3,48.5014686584473,0,48.5004200654871,,,,,,,,,,,,,,,,,,,,,,,,,,,,,,,,,
,3768521531.73508,48.5000114440918,259.528259277344,,,5,,,,25.0300001353025,,,,,0.000613805024838604,9.15486943820613E-8,-0.002326909507536,9.46980918351409E-5,0.000613712564577966,9.15349039831544E-8,0.000613712564071852,7.07262466339398E-8,-2.49242372327292E-8,5.81071138870312E-8,1.00015065727178,10.005763053894,2,20,10,5,2.00787419130805,0.17671398986849,0.0410455763339996,172.855895996094,48.4997138977051,48.5005836486816,259.528259277344,259.528259277344,,,33.3739242553711,0,1,,,,,,1,1,3,48.5000877380371,0,48.5000779628754,,,,,,,,,,,,,,,,,,,,,,,,,,,,,,,,,
,3768521741.83269,48.5008697509766,259.528259277344,,,5,,,,25.0300001353025,,,,,0.000614935650398547,9.77050235496213E-8,-0.00168611199287394,0.000103276522432388,0.000614842995676793,9.76903019575895E-8,0.000614842995410559,7.42469897197171E-8,-1.80937262291516E-8,6.34884211027903E-8,1.00015069655572,10.005763053894,2,20,10,5,2.01157070487891,0.177061990979923,0.0410455763339996,172.855895996094,48.4997482299805,48.5009803771973,259.528259277344,259.528259277344,,,33.4609832763672,0,1,,,,,,1,1,3,48.5007743835449,0,48.5003938113942,,,,,,,,,,,,,,,,,,,,,,,,,,,,,,,,,
,3768521951.57325,48.5008087158203,259.528259277344,,,5,,,,25.0300001353025,,,,,0.000616013211846539,8.67035957825473E-8,0.000312187156929156,9.40070818230231E-5,0.000615920396484782,8.66905320601248E-8,0.000615920396475639,6.45270807853078E-8,3.35596162765195E-9,5.78921773143305E-8,1.00015069376219,10.005763053894,2,20,10,5,2.01508942444614,0.17744254095934,0.0410455763339996,172.855895996094,48.4995307922363,48.5014266967773,259.528259277344,259.528259277344,,,33.5231666564941,0,1,,,,,,1,1,3,48.5004348754883,0,48.5002773509306,,,,,,,,,,,,,,,,,,,,,,,,,,,,,,,,,
,3768522159.59568,48.5000686645508,259.528259277344,,,5,,,,25.0300001353025,,,,,0.000617236880619629,1.06897138392828E-7,-0.00390248975856089,7.08615389375854E-5,0.00061714383098997,1.06881023446603E-7,0.000617143829558459,9.75361356708746E-8,-4.2034465690188E-8,4.37064687590525E-8,1.00015077462495,10.005763053894,2,20,10,5,2.01910533706803,0.177646493663153,0.0410455763339996,172.855895996094,48.4996032714844,48.500862121582,259.528259277344,259.528259277344,,,33.6226654052734,0,1,,,,,,1,1,3,48.5004539489746,0,48.5003720451804,,,,,,,,,,,,,,,,,,,,,,,,,,,,,,,,,
,3768522367.18528,48.5003204345703,259.528259277344,,,5,,,,25.0300001353025,,,,,0.000617895609865417,1.03968413781485E-7,-0.000253373016609437,6.71388216684848E-5,0.00061780252468545,1.03952751073491E-7,0.00061780252467941,9.53305145543724E-8,-2.73204223205005E-9,4.14519897055119E-8,1.000150671414,10.005763053894,2,20,10,5,2.02124884183484,0.17796481480696,0.0410455763339996,172.855895996094,48.499755859375,48.5006408691406,259.528259277344,259.528259277344,,,33.7097244262695,0,1,,,,,,1,1,3,48.5002212524414,0,48.5001285777372,,,,,,,,,,,,,,,,,,,,,,,,,,,,,,,,,
,3768522573.40264,48.4995288848877,259.528259277344,,,5,,,,25.0300001353025,,,,,0.000618913118523078,1.14355267844278E-7,-0.00294779534426048,8.9891379028743E-5,0.00061881983148316,1.14338031395224E-7,0.000618819830664161,9.99060758948963E-8,-3.18374971573755E-8,5.56054082137566E-8,1.00015074991972,10.005763053894,2,20,10,5,2.0245856779529,0.178162668877745,0.0410455763339996,172.855895996094,48.4987297058105,48.4998321533203,259.528259277344,259.528259277344,,,33.7967834472656,0,1,,,,,,1,1,3,48.4995002746582,0,48.4993322160509,,,,,,,,,,,,,,,,,,,,,,,,,,,,,,,,,
,3768522780.24415,48.5004348754883,259.528259277344,,,5,,,,25.0300001353025,,,,,0.000620060138320896,9.27341292427172E-8,-0.00439920668973581,6.93579750306302E-5,0.00061996672381069,9.27201584796779E-8,0.000619966721983256,8.21561012284625E-8,-4.76014425373005E-8,4.29814241206037E-8,1.00015067665186,10.005763053894,2,20,10,5,2.02834232499487,0.178441468504431,0.0410455763339996,172.855895996094,48.4996681213379,48.5009918212891,259.528259277344,259.528259277344,,,33.8714027404785,0,1,,,,,,1,1,3,48.5005836486816,0,48.5003179662368,,,,,,,,,,,,,,,,,,,,,,,,,,,,,,,,,
,3768522991.21201,48.5007190704346,259.528259277344,,,5,,,,25.0300001353025,,,,,0.000621196000252998,1.16316372828964E-7,0.00202497933885581,0.000116632180137681,0.000621102406543025,1.16298847795224E-7,0.000621102406155117,9.09935080981472E-8,2.19513470449292E-8,7.24265385234523E-8,1.0001506896592,10.005763053894,2,20,10,5,2.03203790273915,0.178996186348009,0.0410455763339996,172.855895996094,48.499626159668,48.5010147094727,259.528259277344,259.528259277344,,,33.9584655761719,0,1,,,,,,1,1,3,48.5009117126465,0,48.5003177418428,,,,,,,,,,,,,,,,,,,,,,,,,,,,,,,,,
,3768523199.20794,48.5011177062988,259.528259277344,,,5,,,,25.0300001353025,,,,,0.000621936109068622,7.60819257299679E-8,-0.000498724829199659,7.11420444336423E-5,0.000621842392504776,7.60704613101566E-8,0.000621842392481219,6.18913445713915E-8,-5.41275890864395E-9,4.42286847089682E-8,1.00015070790441,10.005763053894,2,20,10,5,2.0344668162245,0.179119836687987,0.0410455763339996,172.855895996094,48.4995994567871,48.5018997192383,259.528259277344,259.528259277344,,,34.0206489562988,0,1,,,,,,1,1,3,48.5004959106445,0,48.5003242492676,,,,,,,,,,,,,,,,,,,,,,,,,,,,,,,,,
,3768523406.19023,48.5000267028809,259.528259277344,,,5,,,,25.0300001353025,,,,,0.000622735522251522,9.90756164978003E-8,-0.00399325238275949,8.27686530969044E-5,0.000622641716314403,9.90606922149882E-8,0.000622641714802177,8.46097953511843E-8,-4.33952646494205E-8,5.15189603228107E-8,1.00015065797016,10.005763053894,2,20,10,5,2.03709277780433,0.179225828475168,0.0410455763339996,172.855895996094,48.4994964599609,48.5004577636719,259.528259277344,259.528259277344,,,34.1201477050781,0,1,,,,,,1,1,3,48.4999885559082,0,48.5000448787914,,,,,,,,,,,,,,,,,,,,,,,,,,,,,,,,,
,3768523612.9397,48.5008144378662,259.528259277344,,,5,,,,25.0300001353025,,,,,0.000623620383359903,7.68311426557671E-8,0.00146395741330441,7.50338141019567E-5,0.000623526421654301,7.6819566406177E-8,0.000623526421450767,6.09365554021281E-8,1.59316468862115E-8,4.67758698321731E-8,1.00015069402408,10.005763053894,2,20,10,5,2.03997023207434,0.179674792890465,0.0410455763339996,172.855895996094,48.4999732971191,48.5011825561523,259.528259277344,259.528259277344,,,34.1947708129883,0,1,,,,,,1,1,3,48.500675201416,0,48.5004377926097,,,,,,,,,,,,,,,,,,,,,,,,,,,,,,,,,
,3768523821.10562,48.4996643066406,259.528259277344,,,5,,,,25.0300001353025,,,,,0.000624330223494697,1.05037350131389E-7,0.00111410776937948,7.90146894383253E-5,0.000624236187691681,1.05021529542869E-7,0.000624236187573668,9.27296713943065E-8,1.2138178282966E-8,4.93024310823272E-8,1.00015064138361,10.005763053894,2,20,10,5,2.04229333993445,0.179866843259288,0.0410455763339996,172.855895996094,48.4990234375,48.5001792907715,259.528259277344,259.528259277344,,,34.2818298339844,0,1,,,,,,1,1,3,48.4994659423828,0,48.4995422363281,,,,,,,,,,,,,,,,,,,,,,,,,,,,,,,,,
,3768524030.676,48.5000114440918,259.528259277344,,,5,,,,25.0300001353025,,,,,0.000625199368490967,9.56697490141126E-8,-0.00172514715966088,7.84148011257788E-5,0.000625105120138028,9.56553268685938E-8,0.000625105119854673,8.21513153090558E-8,-1.88216013726878E-8,4.90010505125106E-8,1.00015077200602,10.005763053894,2,20,10,5,2.04514538854959,0.180015891659141,0.0410455763339996,172.855895996094,48.4992790222168,48.500415802002,259.528259277344,259.528259277344,,,34.3937644958496,0,1,,,,,,1,1,3,48.5002250671387,0,48.4998054504395,,,,,,,,,,,,,,,,,,,,,,,,,,,,,,,,,
,3768524237.10006,48.4996509552002,259.528259277344,,,5,,,,25.0300001353025,,,,,0.000625949229225743,9.69930417314919E-8,0.00349851456062389,7.46041341967723E-5,0.00062585494995259,9.69784328254523E-8,0.000625854948785872,8.50090948671881E-8,3.82150774890345E-8,4.66719425687658E-8,1.00015064077253,10.005763053894,2,20,10,5,2.04758188419744,0.180418485049842,0.0410455763339996,172.855895996094,48.4987564086914,48.5000839233398,259.528259277344,259.528259277344,,,34.4186363220215,0,1,,,,,,1,1,3,48.499095916748,0,48.4993067847358,,,,,,,,,,,,,,,,,,,,,,,,,,,,,,,,,
,3768524446.79933,48.5000305175781,259.528259277344,,,5,,,,25.0300001353025,,,,,0.000626587727594168,7.27856407595439E-8,-0.00133666662330523,8.05358386685461E-5,0.000626493269400266,7.27746683132841E-8,0.00062649326922978,5.24508528908781E-8,-1.46156078156776E-8,5.0448591448404E-8,1.000150772879,10.005763053894,2,20,10,5,2.0496857503049,0.180429546076552,0.0410455763339996,172.855895996094,48.4996337890625,48.5003356933594,259.528259277344,259.528259277344,,,34.5181350708008,0,1,,,,,,1,1,3,48.499755859375,0,48.4999961853027,,,,,,,,,,,,,,,,,,,,,,,,,,,,,,,,,
,3768524656.27053,48.5005798339844,259.528259277344,,,5,,,,25.0300001353025,,,,,0.000627442663510191,9.47229415001005E-8,0.000348093491262524,0.000119211444908857,0.000627348132631802,9.47086704863739E-8,0.000627348132620224,5.81156969067583E-8,3.81137674675713E-9,7.47816691331395E-8,1.00015068328648,10.005763053894,2,20,10,5,2.05247709244973,0.180736078701569,0.0410455763339996,172.855895996094,48.5001449584961,48.5009231567383,259.528259277344,259.528259277344,,,34.6176300048828,0,1,,,,,,1,1,3,48.500659942627,0,48.5004880693224,,,,,,,,,,,,,,,,,,,,,,,,,,,,,,,,,
,3768524866.25765,48.4999027252197,259.528259277344,,,5,,,,25.0300001353025,,,,,0.000628042207748672,1.1504245515171E-7,0.000160216576627903,0.000125491659001687,0.000627947533963944,1.15025113157017E-7,0.000627947533961489,8.38014959013212E-8,1.75593394571993E-9,7.87914077897166E-8,1.00015076703006,10.005763053894,2,20,10,5,2.05443890173821,0.180902044950956,0.0410455763339996,172.855895996094,48.4994506835937,48.5001068115234,259.528259277344,259.528259277344,,,34.642505645752,0,1,,,,,,1,1,3,48.4998741149902,0,48.499755859375,,,,,,,,,,,,,,,,,,,,,,,,,,,,,,,,,
,3768525073.52131,48.5002555847168,259.528259277344,,,5,,,,25.0300001353025,,,,,0.000628797158344378,1.42768508703419E-7,-0.00142340613222114,0.000132008409249547,0.000628702360603096,1.42746984859089E-7,0.000628702360409085,1.16154785393547E-7,-1.56189304506795E-8,8.29744991942709E-8,1.00015078318012,10.005763053894,2,20,10,5,2.05691348624355,0.181062647649937,0.0410455763339996,172.855895996094,48.4999046325684,48.5008506774902,259.528259277344,259.528259277344,,,34.7171287536621,0,1,,,,,,1,1,3,48.5004844665527,0,48.5002984439625,,,,,,,,,,,,,,,,,,,,,,,,,,,,,,,,,
,3768525285.83578,48.4991989135742,259.528259277344,,,5,,,,25.0300001353025,,,,,0.000629329740830503,1.34953133543974E-7,0.00465421944606614,0.000101429476145892,0.000629234965407792,1.34932809952941E-7,0.000629234963331773,1.18899456326131E-7,5.11136707417737E-8,6.37948468698435E-8,1.00015062008299,10.005763053894,2,20,10,5,2.05863642872817,0.181434383693824,0.0410455763339996,172.855895996094,48.4966430664063,48.5011177062988,259.528259277344,259.528259277344,,,34.8041877746582,0,1,,,,,,1,1,3,48.4982795715332,0,48.4979527122096,,,,,,,,,,,,,,,,,,,,,,,,,,,,,,,,,
,3768525492.47278,48.5006904602051,259.528259277344,,,5,,,,25.0300001353025,,,,,0.000630012587725677,1.4145299040407E-7,-0.00103410354948519,0.000100611306575876,0.000629917666472046,1.41431678297866E-7,0.000629917666369448,1.2645211163153E-7,-1.13690764011347E-8,6.33465317920269E-8,1.00015068834974,10.005763053894,2,20,10,5,2.06088815122663,0.181426633326659,0.0410455763339996,172.855895996094,48.499324798584,48.500789642334,259.528259277344,259.528259277344,,,34.8912467956543,0,1,,,,,,1,1,3,48.5007781982422,0,48.4999963972304,,,,,,,,,,,,,,,,,,,,,,,,,,,,,,,,,
,3768525703.48615,48.5003833770752,259.528259277344,,,5,,,,25.0300001353025,,,,,0.000630942576600839,1.03822223802038E-7,0.000912308414645402,0.000115973935216349,0.000630847524095007,1.03806582818374E-7,0.000630847524015036,7.36509204241309E-8,1.00448498904594E-8,7.31529121573858E-8,1.00015067429482,10.005763053894,2,20,10,5,2.06392414386132,0.181764560031814,0.0410455763339996,172.855895996094,48.4996566772461,48.5008506774902,259.528259277344,259.528259277344,,,34.9658699035645,0,1,,,,,,1,1,3,48.5005950927734,0,48.5001433877384,,,,,,,,,,,,,,,,,,,,,,,,,,,,,,,,,
,3768525911.02996,48.5003929138184,259.528259277344,,,5,,,,25.0300001353025,,,,,0.000631537573924547,1.17746133161537E-7,0.0010909454818826,0.000127254300032656,0.000631442431505843,1.17728394467334E-7,0.00063144243139138,8.60525499760629E-8,1.20230368367944E-8,8.03426008196979E-8,1.00015067473131,10.005763053894,2,20,10,5,2.06586991740377,0.181942411492077,0.0410455763339996,172.855895996094,48.4998054504395,48.5005531311035,259.528259277344,259.528259277344,,,35.0529289245605,0,1,,,,,,1,1,3,48.5002899169922,0,48.5002616433536,,,,,,,,,,,,,,,,,,,,,,,,,,,,,,,,,
,3768526119.05575,48.5002479553223,259.528259277344,,,5,,,,25.0300001353025,,,,,0.000632045686035266,8.97917925209856E-8,-0.00206519387267345,0.000115311009272754,0.00063195047126056,8.97782658005535E-8,0.000631950470850045,5.24466502005198E-8,-2.27782962704927E-8,7.2866219147827E-8,1.00015066809669,10.005763053894,2,20,10,5,2.06754206822177,0.18197490583902,0.0410455763339996,172.855895996094,48.4994010925293,48.5004692077637,259.528259277344,259.528259277344,,,35.1275520324707,0,1,,,,,,1,1,3,48.5001754760742,0,48.4998966016267,,,,,,,,,,,,,,,,,,,,,,,,,,,,,,,,,
,3768526326.58292,48.4997482299805,259.528259277344,,,5,,,,25.0300001353025,,,,,0.000632631906384907,1.00817610545665E-7,0.000796493158289557,7.14505179601946E-5,0.000632536545201319,1.00802413577932E-7,0.0006325365451402,9.01139314317754E-8,8.79316129191857E-9,4.51730665889063E-8,1.00015075995895,10.005763053894,2,20,10,5,2.06945060694959,0.182247047862945,0.0410455763339996,172.855895996094,48.4992599487305,48.5004920959473,259.528259277344,259.528259277344,,,35.2021751403809,0,1,,,,,,1,1,3,48.5001335144043,0,48.4997448640711,,,,,,,,,,,,,,,,,,,,,,,,,,,,,,,,,
,3768526531.76602,48.500825881958,259.528259277344,,,5,,,,25.0300001353025,,,,,0.000633352229990823,7.8719154261628E-8,-0.00412030778153927,0.000101239451310938,0.000633256801643413,7.87072935016197E-8,0.000633256800005979,4.56639508164225E-8,-4.55393564316435E-8,6.41064867715073E-8,1.00015069454787,10.005763053894,2,20,10,5,2.07182256226039,0.182276764494556,0.0410455763339996,172.855895996094,48.4998779296875,48.501579284668,259.528259277344,259.528259277344,,,35.289234161377,0,1,,,,,,1,1,3,48.5003814697266,0,48.5003902210909,,,,,,,,,,,,,,,,,,,,,,,,,,,,,,,,,
,3768526740.86256,48.5006084442139,259.528259277344,,,5,,,,25.0300001353025,,,,,0.000633943742405006,1.02538340473991E-7,3.12007929883507E-5,0.000104635483938489,0.000633848231240394,1.02522891853457E-7,0.0006338482312403,7.81900249267174E-8,3.45166216727136E-10,6.63118643679619E-8,1.00015068459594,10.005763053894,2,20,10,5,2.07374429343123,0.182597256912394,0.0410455763339996,172.855895996094,48.5001907348633,48.5009536743164,259.528259277344,259.528259277344,,,35.376293182373,0,1,,,,,,1,1,3,48.5008392333984,0,48.5005553750431,,,,,,,,,,,,,,,,,,,,,,,,,,,,,,,,,
,3768526948.04349,48.4997329711914,259.528259277344,,,5,,,,25.0300001353025,,,,,0.00063454532563087,9.19722127665973E-8,0.000848265157114447,9.65288636298818E-5,0.000634449676466778,9.19583491938698E-8,0.000634449676397246,6.86061959918586E-8,9.39304009899645E-9,6.12333884248486E-8,1.00015075926057,10.005763053894,2,20,10,5,2.07570957356673,0.182800139065392,0.0410455763339996,172.855895996094,48.499267578125,48.5004692077637,259.528259277344,259.528259277344,,,35.4509162902832,0,1,,,,,,1,1,3,48.4994926452637,0,48.4998520745171,,,,,,,,,,,,,,,,,,,,,,,,,,,,,,,,,
,3768527154.90832,48.4998207092285,259.528259277344,,,5,,,,25.0300001353025,,,,,0.000635077125035935,1.27279124144658E-7,-0.00110704642448489,0.000148005942576771,0.000634981466003872,1.27259952618338E-7,0.000634981465885345,8.58163141457445E-8,-1.22688611182874E-8,9.39715689283767E-8,1.00015064854202,10.005763053894,2,20,10,5,2.07745542554612,0.182882443153664,0.0410455763339996,172.855895996094,48.4990234375,48.5000228881836,259.528259277344,259.528259277344,,,35.5255393981934,0,1,,,,,,1,1,3,48.499626159668,0,48.4995318518745,,,,,,,,,,,,,,,,,,,,,,,,,,,,,,,,,
,3768527361.25469,48.5002632141113,259.528259277344,,,5,,,,25.0300001353025,,,,,0.000635625587001723,7.94283538625564E-8,-0.00198597622501584,0.000100238500868399,0.000635529832487632,7.94163882910238E-8,0.000635529832105856,4.74261724732216E-8,-2.20286231914834E-8,6.37002424935016E-8,1.00015066879507,10.005763053894,2,20,10,5,2.07925235447594,0.183008485080621,0.0410455763339996,172.855895996094,48.4997329711914,48.5004577636719,259.528259277344,259.528259277344,,,35.5752868652344,0,1,,,,,,1,1,3,48.5001106262207,0,48.5000194973416,,,,,,,,,,,,,,,,,,,,,,,,,,,,,,,,,
,3768527567.79041,48.5007572174072,259.528259277344,,,5,,,,25.0300001353025,,,,,0.000636117126755731,9.88233045262809E-8,0.00123079681239524,9.01172616542149E-5,0.000636021283814765,9.88084149473913E-8,0.000636021283668018,8.0495377963928E-8,1.36626637306819E-8,5.73026787407031E-8,1.00015069140516,10.005763053894,2,20,10,5,2.08084998897071,0.183266831659812,0.0410455763339996,172.855895996094,48.499755859375,48.501033782959,259.528259277344,259.528259277344,,,35.6499099731445,0,1,,,,,,1,1,3,48.5008659362793,0,48.5003868551815,,,,,,,,,,,,,,,,,,,,,,,,,,,,,,,,,
,3768527772.96155,48.4991416931152,259.528259277344,,,5,,,,25.0300001353025,,,,,0.000636516608235765,9.12508301777485E-8,-0.00295446124720478,7.32658875450619E-5,0.000636420679147754,9.12370778124434E-8,0.000636420678301646,7.84314561063324E-8,-3.28170809195326E-8,4.66123488015172E-8,1.0001507321983,10.005763053894,2,20,10,5,2.08217015186466,0.183229834068908,0.0410455763339996,172.855895996094,48.4985313415527,48.5029067993164,259.528259277344,259.528259277344,,,35.7494087219238,0,1,,,,,,1,1,3,48.4994049072266,0,48.5006435618681,,,,,,,,,,,,,,,,,,,,,,,,,,,,,,,,,
,3768527979.26642,48.5002841949463,259.528259277344,,,5,,,,25.0300001353025,,,,,0.000637170924678916,9.1907048565465E-8,-0.000528558320882055,8.27562908283472E-5,0.00063707493675406,9.18932030390453E-8,0.000637074936726952,7.52736584014007E-8,-5.87706916117802E-9,5.27089851509632E-8,1.00015066975534,10.005763053894,2,20,10,5,2.08430278118984,0.183506434799651,0.0410455763339996,172.855895996094,48.4996604919434,48.5007247924805,259.528259277344,259.528259277344,,,35.824031829834,0,1,,,,,,1,1,3,48.5000610351562,0,48.500141620636,,,,,,,,,,,,,,,,,,,,,,,,,,,,,,,,,
,3768528181.96969,48.4994049072266,259.528259277344,,,5,,,,25.0300001353025,,,,,0.000637891731856412,8.12295171069327E-8,0.00147417248251447,8.68774438959328E-5,0.00063779558784182,8.12172740702416E-8,0.000637795587630713,5.93870960760073E-8,1.64099469970059E-8,5.5402332325091E-8,1.00015074424537,10.005763053894,2,20,10,5,2.08665425037759,0.183786968760656,0.0410455763339996,172.855895996094,48.4993057250977,48.5000419616699,259.528259277344,259.528259277344,,,35.8986511230469,0,1,,,,,,1,1,3,48.499397277832,0,48.4996732076009,,,,,,,,,,,,,,,,,,,,,,,,,,,,,,,,,
,3768528389.93675,48.5001449584961,259.528259277344,,,5,,,,25.0300001353025,,,,,0.000638433101242678,6.72437368423871E-8,0.00339047311753227,5.87534873858232E-5,0.000638336927241971,6.72336071997009E-8,0.000638336926124348,5.58080987064108E-8,3.77735360068676E-8,3.74941869609034E-8,1.00015066338262,10.005763053894,2,20,10,5,2.0884190102303,0.184012792949108,0.0410455763339996,172.855895996094,48.499095916748,48.5006942749023,259.528259277344,259.528259277344,,,35.9608383178711,0,1,,,,,,1,1,3,48.4999046325684,0,48.499840842353,,,,,,,,,,,,,,,,,,,,,,,,,,,,,,,,,
,3768528598.53868,48.5000286102295,259.528259277344,,,5,,,,25.0300001353025,,,,,0.000638619198215288,8.1380066252362E-8,0.00138069641280669,8.26293063488649E-5,0.000638522926331119,8.13677982022724E-8,0.000638522926145724,6.19512741306947E-8,1.5386932882091E-8,5.27518551130597E-8,1.0001507727917,10.005763053894,2,20,10,5,2.08903421920541,0.183993152232455,0.0410455763339996,172.855895996094,48.4998359680176,48.5005569458008,259.528259277344,259.528259277344,,,36.0230255126953,0,1,,,,,,1,1,3,48.5002212524414,0,48.5001694174374,,,,,,,,,,,,,,,,,,,,,,,,,,,,,,,,,
,3768528804.86825,48.5006256103516,259.528259277344,,,5,,,,25.0300001353025,,,,,0.000639216892577092,1.04650823643229E-7,-0.000341099313302173,8.87052648832021E-5,0.000639120586447623,1.04635056669784E-7,0.000639120586436297,8.79558327363229E-8,-3.80488048170288E-9,5.66768609923734E-8,1.00015068538162,10.005763053894,2,20,10,5,2.09099491477616,0.184102516037549,0.0410455763339996,172.855895996094,48.4999122619629,48.5008544921875,259.528259277344,259.528259277344,,,36.0976448059082,0,1,,,,,,1,1,3,48.5007438659668,0,48.5003336738138,,,,,,,,,,,,,,,,,,,,,,,,,,,,,,,,,
,3768529011.23447,48.500789642334,259.528259277344,,,5,,,,25.0300001353025,,,,,0.00063940536630635,4.27755845611728E-7,-0.000446153909300584,0.000110704657240115,0.000639309026981973,4.27691395559639E-7,0.00063930902696259,4.21845857947733E-7,-4.9782064937462E-9,7.04698656738632E-8,1.00015069288922,10.005763053894,2,20,10,5,2.0916117843637,0.184152963505604,0.0410455763339996,172.855895996094,48.4997215270996,48.5010108947754,259.528259277344,259.528259277344,,,36.1598320007324,0,1,,,,,,1,1,3,48.5008125305176,0,48.5003238254123,,,,,,,,,,,,,,,,,,,,,,,,,,,,,,,,,
,3768529216.4186,48.5005016326904,259.528259277344,,,5,,,,25.0300001353025,,,,,0.000640186633833454,7.45364582382913E-8,-0.00407898219885094,7.1940067682666E-5,0.000640090185231715,7.45252287986314E-8,0.000640090183609645,5.86036815110672E-8,-4.55690888788372E-8,4.60393119066495E-8,1.00015067970727,10.005763053894,2,20,10,5,2.09417913935423,0.184245193977277,0.0410455763339996,172.855895996094,48.4997215270996,48.5006523132324,259.528259277344,259.528259277344,,,36.2095794677734,0,1,,,,,,1,1,3,48.5005722045898,0,48.5002270866843,,,,,,,,,,,,,,,,,,,,,,,,,,,,,,,,,
,3768529421.37838,48.5001640319824,259.528259277344,,,5,,,,25.0300001353025,,,,,0.000640620351844686,1.03527119325343E-7,-0.000320074327940567,0.000106129047552031,0.000640523847795969,1.03511523838659E-7,0.000640523847785974,7.80709547226805E-8,-3.57819095672349E-9,6.79673568420193E-8,1.00015066425559,10.005763053894,2,20,10,5,2.09558581779641,0.184507501582662,0.0410455763339996,172.855895996094,48.499813079834,48.5007476806641,259.528259277344,259.528259277344,,,36.2842025756836,0,1,,,,,,1,1,3,48.5000762939453,0,48.5001916324391,,,,,,,,,,,,,,,,,,,,,,,,,,,,,,,,,
,3768529626.69904,48.4989433288574,259.528259277344,,,5,,,,25.0300001353025,,,,,0.000641054562750105,1.22291945405458E-7,7.00836757561163E-5,0.000149056417094077,0.000640957955567673,1.2227351595972E-7,0.000640957955567193,7.63186152774689E-8,7.84013934587277E-10,9.55315741903245E-8,1.00015072311935,10.005763053894,2,20,10,5,2.09700494303363,0.184646844251256,0.0410455763339996,172.855895996094,48.4985961914063,48.5022010803223,259.528259277344,259.528259277344,,,36.3712615966797,0,1,,,,,,1,1,3,48.4989814758301,0,48.4999982048483,,,,,,,,,,,,,,,,,,,,,,,,,,,,,,,,,
,3768529831.99532,48.4998645782471,259.528259277344,,,5,,,,25.0300001353025,,,,,0.000641561693139147,9.87221347730847E-8,0.00106853483082681,9.93546819706329E-5,0.000641464982488819,9.87072531460209E-8,0.000641464982377267,7.5383454807378E-8,1.19629697393117E-8,6.37217118801484E-8,1.00015076528411,10.005763053894,2,20,10,5,2.09866063755845,0.184829485213457,0.0410455763339996,172.855895996094,48.4995956420898,48.5007362365723,259.528259277344,259.528259277344,,,36.421012878418,0,1,,,,,,1,1,3,48.4996757507324,0,48.4999939413632,,,,,,,,,,,,,,,,,,,,,,,,,,,,,,,,,
,3768530037.37679,48.5008068084717,259.528259277344,,,5,,,,25.0300001353025,,,,,0.000642077355089241,9.73325306443005E-8,-0.00341443224246962,8.03004108710062E-5,0.000641980612671507,9.73178654575219E-8,0.000641980611531562,8.25520078503948E-8,-3.8257605015184E-8,5.15357442662535E-8,1.00015069367489,10.005763053894,2,20,10,5,2.10036192522207,0.184813702226787,0.0410455763339996,172.855895996094,48.499755859375,48.5010986328125,259.528259277344,259.528259277344,,,36.4956398010254,0,1,,,,,,1,1,3,48.5008354187012,0,48.5004097433651,,,,,,,,,,,,,,,,,,,,,,,,,,,,,,,,,
,3768530242.49864,48.5000114440918,259.528259277344,,,5,,,,25.0300001353025,,,,,0.000642376450590502,7.63132117724157E-8,-0.0049304841178186,5.33559923588242E-5,0.000642279686485215,7.6301716363996E-8,0.000642279684107126,6.81808365785091E-8,-5.52702104136906E-8,3.42538383768348E-8,1.00015065727178,10.005763053894,2,20,10,5,2.10134521719761,0.184844194083857,0.0410455763339996,172.855895996094,48.4995765686035,48.5002517700195,259.528259277344,259.528259277344,,,36.5578231811523,0,1,,,,,,1,1,3,48.5001220703125,0,48.4999535504509,,,,,,,,,,,,,,,,,,,,,,,,,,,,,,,,,
,3768530447.64848,48.5002841949463,259.528259277344,,,5,,,,25.0300001353025,,,,,0.000642850061342978,8.906779918777E-8,-0.00328983231958624,0.000101752061314071,0.000642753217872895,8.90543813859143E-8,0.000642753216813357,6.04501128079087E-8,-3.69058650826382E-8,6.53946993688249E-8,1.00015066975534,10.005763053894,2,20,10,5,2.10288919741642,0.185040691957189,0.0410455763339996,172.855895996094,48.4993629455566,48.500545501709,259.528259277344,259.528259277344,,,36.6200103759766,0,1,,,,,,1,1,3,48.5000534057617,0,48.5000267028809,,,,,,,,,,,,,,,,,,,,,,,,,,,,,,,,,
,3768530652.77062,48.5013389587402,259.528259277344,,,5,,,,25.0300001353025,,,,,0.000643307985023858,1.10994773840411E-7,-0.00235487756735786,9.8206547161495E-5,0.000643211041522205,1.10978047447623E-7,0.000643211040978936,9.12577251687351E-8,-2.64362098779935E-8,6.31518377588062E-8,1.00015071803093,10.005763053894,2,20,10,5,2.10438413452536,0.185206836912667,0.0410455763339996,172.855895996094,48.4994812011719,48.5014953613281,259.528259277344,259.528259277344,,,36.7319450378418,0,1,,,,,,1,1,3,48.5013732910156,0,48.5005965762668,,,,,,,,,,,,,,,,,,,,,,,,,,,,,,,,,
,3768530860.54974,48.5001907348633,259.528259277344,,,5,,,,25.0300001353025,,,,,0.000643763214706674,1.18196456136037E-7,-0.00254334189214678,0.000125101630395704,0.000643666162586221,1.18178637136076E-7,0.000643666161952067,8.65096699078397E-8,-2.85721414253816E-8,8.05125287627761E-8,1.000150780212,10.005763053894,2,20,10,5,2.10587388762984,0.185330973547326,0.0410455763339996,172.855895996094,48.4994812011719,48.5004386901855,259.528259277344,259.528259277344,,,36.7816925048828,0,1,,,,,,1,1,3,48.500358581543,0,48.500005385455,,,,,,,,,,,,,,,,,,,,,,,,,,,,,,,,,
,3768531065.9163,48.5007705688477,259.528259277344,,,5,,,,25.0300001353025,,,,,0.000644178821989196,1.03906029032977E-7,-0.000257642830767679,9.48216615324609E-5,0.000644081764009554,1.03890373583114E-7,0.000644081764003042,8.40536665489439E-8,-2.8962525745341E-9,6.10589130505778E-8,1.00015069201624,10.005763053894,2,20,10,5,2.10722601967466,0.185534683329185,0.0410455763339996,172.855895996094,48.499927520752,48.5010108947754,259.528259277344,259.528259277344,,,36.8438758850098,0,1,,,,,,1,1,3,48.500804901123,0,48.500453737047,,,,,,,,,,,,,,,,,,,,,,,,,,,,,,,,,
,3768531273.52721,48.5000076293945,259.528259277344,,,5,,,,25.0300001353025,,,,,0.000644567612807405,1.12981442722231E-7,-0.00132174288330944,9.61442280845334E-5,0.000644470444818138,1.12964410871118E-7,0.000644470444646655,9.44658410005892E-8,-1.48671373547086E-8,6.19448384250876E-8,1.00015077183143,10.005763053894,2,20,10,5,2.10850127232116,0.185607505635932,0.0410455763339996,172.855895996094,48.4991836547852,48.5000534057617,259.528259277344,259.528259277344,,,36.893627166748,0,1,,,,,,1,1,3,48.5000534057617,0,48.4996950486127,,,,,,,,,,,,,,,,,,,,,,,,,,,,,,,,,
,3768531481.35762,48.5002593994141,259.528259277344,,,5,,,,25.0300001353025,,,,,0.000644934943114247,9.5449682601423E-8,-0.00596223826171283,9.65175166678108E-5,0.000644837786294556,9.54353034959008E-8,0.000644837782803203,7.23570728029673E-8,-6.7102263862681E-8,6.22282184281439E-8,1.00015066862047,10.005763053894,2,20,10,5,2.10971791283073,0.185542411489151,0.0410455763339996,172.855895996094,48.4991226196289,48.5008506774902,259.528259277344,259.528259277344,,,36.9433746337891,0,1,,,,,,1,1,3,48.5000114440918,0,48.4999923706055,,,,,,,,,,,,,,,,,,,,,,,,,,,,,,,,,
,3768531689.04653,48.4994831085205,259.528259277344,,,5,,,,25.0300001353025,,,,,0.000645340115303865,9.25162408150287E-8,-0.00178593519555381,7.88096505383003E-5,0.000645242920368751,9.25023069066758E-8,0.000645242920055293,7.72802833858969E-8,-2.01125117901355E-8,5.08373345372503E-8,1.00015063309034,10.005763053894,2,20,10,5,2.11102977776663,0.185812852579261,0.0410455763339996,172.855895996094,48.4990997314453,48.500602722168,259.528259277344,259.528259277344,,,37.0304336547852,0,1,,,,,,1,1,3,48.4993858337402,0,48.4997190587661,,,,,,,,,,,,,,,,,,,,,,,,,,,,,,,,,
,3768531894.34224,48.5001335144043,259.528259277344,,,5,,,,25.0300001353025,,,,,0.000645794047759798,1.01940212265268E-7,-0.00323231934238155,0.000117672087360487,0.000645696765239209,1.01924855975081E-7,0.000645696764211709,6.79467650652896E-8,-3.64267343986878E-8,7.59731096026962E-8,1.00015066285883,10.005763053894,2,20,10,5,2.1125193705277,0.185890220412896,0.0410455763339996,172.855895996094,48.4993743896484,48.5005874633789,259.528259277344,259.528259277344,,,37.0801811218262,0,1,,,,,,1,1,3,48.5004653930664,0,48.4999723995433,,,,,,,,,,,,,,,,,,,,,,,,,,,,,,,,,
,3768532101.06877,48.5012760162354,259.528259277344,,,5,,,,25.0300001353025,,,,,0.000646184880774851,9.32485299795792E-8,-0.00190500647231406,7.53188207675994E-5,0.00064608750559946,9.32344781312122E-8,0.000646087505242344,7.95369913596699E-8,-2.14815277858367E-8,4.86470442868965E-8,1.00015071515011,10.005763053894,2,20,10,5,2.11379355288608,0.186051686830435,0.0410455763339996,172.855895996094,48.5,48.5017929077148,259.528259277344,259.528259277344,,,37.1423683166504,0,1,,,,,,1,1,3,48.5009841918945,0,48.5007716908174,,,,,,,,,,,,,,,,,,,,,,,,,,,,,,,,,
,3768532309.90637,48.5007171630859,259.528259277344,,,5,,,,25.0300001353025,,,,,0.000646646973646039,1.04420018509267E-7,-0.00243003718439105,9.18247751090076E-5,0.000646549545371832,1.04404285872124E-7,0.000646549544790328,8.58912137613814E-8,-2.74215561719501E-8,5.93544800926165E-8,1.00015068957191,10.005763053894,2,20,10,5,2.11530685251058,0.186165350454724,0.0410455763339996,172.855895996094,48.4996528625488,48.5010719299316,259.528259277344,259.528259277344,,,37.2169914245605,0,1,,,,,,1,1,3,48.5009956359863,0,48.5003747379079,,,,,,,,,,,,,,,,,,,,,,,,,,,,,,,,,
,3768532521.13871,48.499454498291,259.528259277344,,,5,,,,25.0300001353025,,,,,0.000647099776701513,8.06331163953703E-8,-0.000804134434718051,6.93880962375361E-5,0.000647002243368055,8.0620963066143E-8,0.000647002243304333,6.69725773546499E-8,-9.08054288878655E-9,4.48822188420741E-8,1.00015074651511,10.005763053894,2,20,10,5,2.11678277053055,0.186355784799779,0.0410455763339996,172.855895996094,48.4993858337402,48.5000305175781,259.528259277344,259.528259277344,,,37.2916145324707,0,1,,,,,,1,1,3,48.4993286132812,0,48.4996789296468,,,,,,,,,,,,,,,,,,,,,,,,,,,,,,,,,
,3768532727.32071,48.5017986297607,259.528259277344,,,5,,,,25.0300001353025,,,,,0.000647414532676437,1.10652592419269E-7,-0.00143971497064577,7.92045344214864E-5,0.000647316956720605,1.10635915264331E-7,0.000647316956516246,9.8050741188933E-8,-1.62656293563935E-8,5.12480038506577E-8,1.00015073906966,10.005763053894,2,20,10,5,2.11781446444242,0.18642292702758,0.0410455763339996,172.855895996094,48.5005569458008,48.5019264221191,259.528259277344,259.528259277344,,,37.3786735534668,0,1,,,,,,1,1,3,48.5019302368164,0,48.5012797187356,,,,,,,,,,,,,,,,,,,,,,,,,,,,,,,,,
,3768532934.06986,48.5001945495605,259.528259277344,,,5,,,,25.0300001353025,,,,,0.00064776959275528,8.97176673125506E-8,-0.00475230288477579,6.77313981428219E-5,0.000647672010829257,8.97041519779739E-8,0.000647672008601396,7.82551960675675E-8,-5.37200748131977E-8,4.3851558359014E-8,1.00015066565235,10.005763053894,2,20,10,5,2.11898671255251,0.186402662811638,0.0410455763339996,172.855895996094,48.4992027282715,48.5004081726074,259.528259277344,259.528259277344,,,37.4408569335937,0,1,,,,,,1,1,3,48.500316619873,0,48.4998880274156,,,,,,,,,,,,,,,,,,,,,,,,,,,,,,,,,
,3768533141.27395,48.5009250640869,259.528259277344,,,5,,,,25.0300001353025,,,,,0.00064798715407767,7.53521525063328E-8,-0.00175503339394911,7.75107066816118E-5,0.000647889517718648,7.53407987167262E-8,0.000647889517414702,5.6170357672165E-8,-1.98455758638972E-8,5.02108242339768E-8,1.00015069908735,10.005763053894,2,20,10,5,2.11968864294925,0.186576152469338,0.0410455763339996,172.855895996094,48.500129699707,48.5011711120605,259.528259277344,259.528259277344,,,37.503044128418,0,1,,,,,,1,1,3,48.5007781982422,0,48.5005234612359,,,,,,,,,,,,,,,,,,,,,,,,,,,,,,,,,
,3768533347.7285,48.4993686676025,259.528259277344,,,5,,,,25.0300001353025,,,,,0.000648499816548626,9.76484020903174E-8,-0.00402174752630202,9.90340585079787E-5,0.000648402074742645,9.76336845361595E-8,0.0006484020731453,7.3554067889584E-8,-4.55131156285E-8,6.42038585522769E-8,1.00015074258672,10.005763053894,2,20,10,5,2.12137304373015,0.18663984666487,0.0410455763339996,172.855895996094,48.498233795166,48.4998321533203,259.528259277344,259.528259277344,,,37.5901031494141,0,1,,,,,,1,1,3,48.4989738464355,0,48.4988122827866,,,,,,,,,,,,,,,,,,,,,,,,,,,,,,,,,
,3768533554.1663,48.5001583099365,259.528259277344,,,5,,,,25.0300001353025,,,,,0.000648862358758258,1.10938857809796E-7,-0.00460933089089366,0.00011391811536281,0.000648764613290649,1.10922145836315E-7,0.000648764611191285,8.27239262510538E-8,-5.21918157872505E-8,7.3895023259641E-8,1.0001506639937,10.005763053894,2,20,10,5,2.12256090746554,0.186722415210433,0.0410455763339996,172.855895996094,48.4996643066406,48.5002746582031,259.528259277344,259.528259277344,,,37.6647262573242,0,1,,,,,,1,1,3,48.500129699707,0,48.5000356786391,,,,,,,,,,,,,,,,,,,,,,,,,,,,,,,,,
,3768533759.15187,48.5006904602051,259.528259277344,,,5,,,,25.0300001353025,,,,,0.000649224087227886,9.75561011656405E-8,-0.00301223543778484,7.379277311882E-5,0.000649126271461267,9.75414028126195E-8,0.000649126270564186,8.49796339928122E-8,-3.41267921338878E-8,4.78830561796276E-8,1.00015068834974,10.005763053894,2,20,10,5,2.1237389865183,0.186885706676069,0.0410455763339996,172.855895996094,48.4996337890625,48.5012092590332,259.528259277344,259.528259277344,,,37.7393493652344,0,1,,,,,,1,1,3,48.500415802002,0,48.5001932779948,,,,,,,,,,,,,,,,,,,,,,,,,,,,,,,,,
,3768533967.18837,48.4996242523193,259.528259277344,,,5,,,,25.0300001353025,,,,,0.00064956868387131,1.16455294978381E-7,-0.00247698297509391,8.07854824357165E-5,0.0006494707733695,1.16437741489962E-7,0.000649470772762582,1.03958806540707E-7,-2.80776012060173E-8,5.24434379681108E-8,1.0001507542846,10.005763053894,2,20,10,5,2.12486448240066,0.18700475546234,0.0410455763339996,172.855895996094,48.4990196228027,48.4999504089355,259.528259277344,259.528259277344,,,37.8388442993164,0,1,,,,,,1,1,3,48.499698638916,0,48.4995384216309,,,,,,,,,,,,,,,,,,,,,,,,,,,,,,,,,
,3768534124.02863,48.5001163482666,259.528259277344,,,5,,,,25.0300001353025,,,,,0.000649611673027647,8.02692102359328E-8,0.000239477874121263,6.36963440519334E-5,0.000649513741419358,8.02571093252181E-8,0.000649513741413684,6.87803763308288E-8,2.7147578989075E-9,4.13577493225825E-8,1.00015077680739,10.005763053894,2,20,10,5,2.12499623951637,0.187117876170463,0.0410455763339996,172.855895996094,48.4989738464355,48.5024757385254,259.528259277344,259.528259277344,,,37.8761558532715,0,1,,,,,,1,1,3,48.5007743835449,0,48.5012480417887,,,,,,,,,,,,,,,,,,,,,,,,,,,,,,,,,