File: Experimental_Data/Fig3C/Lifetime_160Oe_49p5K.dat
[Header]
; MPMS3 Data File (default extension .dat)
; Copyright (c) 2007, Quantum Design, Inc. All rights reserved.
TITLE,160Oe_49p5K
FILEOPENTIME,3768448049.62482,05/31/2019,7:07 am
BYAPP,SQUID AC,0.9.1.0
INFO,MPMS3 Measurement Release 1.1.16 Build 347, MultiVu Release 2.3.3.2,APPNAME
INFO,0,MOMENT_UNITS
INFO,,SAMPLE_MATERIAL
INFO,,SAMPLE_COMMENT
INFO,,SAMPLE_MASS
INFO,,SAMPLE_VOLUME
INFO,,SAMPLE_MOLECULAR_WEIGHT
INFO,,SAMPLE_SIZE
INFO,,SAMPLE_SHAPE
INFO,Quartz,SAMPLE_HOLDER
INFO,Standard,SAMPLE_HOLDER_DETAIL
INFO,66.2,SAMPLE_OFFSET
DATATYPE,COMMENT,1
DATATYPE,TIME,2
STARTUPAXIS,X,2
STARTUPAXIS,Y1,5
FIELDGROUP, VSM,2,3,4,5,6,8,9,10,11,14,15
FIELDGROUP, DC, 2,3,4,14,56,57,58,59,60,61,62,63,64,65,66,67,68,69
FIELDGROUP, AC, 2,3,4,11,16,17,18,19,20,21,22,23,24,25,26,27,28,29,30
STARTUPGROUP, All
[Data]
Comment,Time Stamp (sec),Temperature (K),Magnetic Field (Oe),Moment (emu),M. Std. Err. (emu),Transport Action,Averaging Time (sec),Frequency (Hz),Peak Amplitude (mm),Center Position (mm),Lockin Signal' (V),Lockin Signal (V),Range,M. Quad. Signal (emu),AC Moment (emu),AC M. Std Err. (emu),AC Phase (deg),AC Phase Std. Err. (deg),AC Susceptibility (emu/Oe),AC Suscept. Std Err. (emu/Oe),AC X' (emu/Oe),AC X' Std Err. (emu/Oe),AC X'' (emu/Oe),AC X'' Std Err. (emu/Oe),AC Drive (Oe),AC Frequency (Hz),AC Averaging Time (sec),AC Cycles,AC Range,AC Measure Type,AC Signal' (V),AC Signal'' (V),AC Trim Coil Ratio,AC Trim Coil Phase,Min. Temperature (K),Max. Temperature (K),Min. Field (Oe),Max. Field (Oe),Mass (grams),Motor Lag (deg),Pressure (Torr),Measure Count,Measurement Number,SQUID Status (code),Motor Status (code),Measure Status (code),Motor Current (amps),Motor Temp. (C),Temp. Status (code),Field Status (code),Chamber Status (code),Chamber Temp (K),Redirection State,Average Temp (K),Rotation Angle (deg),Rotator state,DC Moment Fixed Ctr (emu),DC Moment Err Fixed Ctr (emu),DC Moment Free Ctr (emu),DC Moment Err Free Ctr (emu),DC Fixed Fit,DC Free Fit,DC Calculated Center (mm),DC Calculated Center Err (mm),DC Scan Length (mm),DC Scan Time (s),DC Number of Points,DC Squid Drift,DC Min V (V),DC Max V (V),DC Scans per Measure,Map 01,Map 02,Map 03,Map 04,Map 05,Map 06,Map 07,Map 08,Map 09,Map 10,Map 11,Map 12,Map 13,Map 14,Map 15,Map 16
,3768448053.62641,49.4713497161865,159.605087280273,,,5,,,,25.0300001353025,,,,,0.000565206654519258,1.70253708383072E-7,0.198405150747285,0.000143474248175798,0.000565121873811846,1.702281704144E-7,0.000565118485586334,1.49732588102432E-7,1.9569131869141E-6,8.09801337537883E-8,1.00015002198878,10.005763053894,2,20,10,5,1.84833138618057,0.168998155044905,0.0410455763339996,172.855895996094,49.4225463867188,49.4822158813477,159.605087280273,159.605087280273,,,170.617401123047,0,1,,,,,,1,1,1,49.465705871582,0,49.4466954399558,,,,,,,,,,,,,,,,,,,,,,,,,,,,,,,,,
,3768448260.20094,49.4993839263916,159.605087280273,,,5,,,,25.0300001353025,,,,,0.000583958119245752,8.65352202452217E-8,0.0291058722309847,0.000120739192832088,0.000583870245690654,8.65221984938434E-8,0.000583870170354697,5.01676612213019E-8,2.96602161346969E-7,7.04932379721113E-8,1.00015050185507,10.005763053894,2,20,10,5,1.91015978040685,0.168961327257374,0.0410455763339996,172.855895996094,49.4983329772949,49.4999122619629,159.605087280273,159.605087280273,,,172.296401977539,0,1,,,,,,1,1,1,49.4990310668945,0,49.4993966046502,,,,,,,,,,,,,,,,,,,,,,,,,,,,,,,,,
,3768448467.88924,49.5000476837158,159.605087280273,,,5,,,,25.0300001353025,,,,,0.000596396784021858,8.02283866882953E-8,0.019991851078049,7.10699322987606E-5,0.000596307020594344,8.02163115477747E-8,0.000596306984294841,6.81171694430343E-8,2.08065602945452E-7,4.23639925573429E-8,1.00015053223325,10.005763053894,2,20,10,5,1.95087477572073,0.172249980281242,0.0410455763339996,172.855895996094,49.4992294311523,49.5002479553223,159.605087280273,159.605087280273,,,174.062469482422,0,1,,,,,,1,1,1,49.5001182556152,0,49.4997698465983,,,,,,,,,,,,,,,,,,,,,,,,,,,,,,,,,
,3768448676.63921,49.501106262207,159.605087280273,,,5,,,,25.0300001353025,,,,,0.000606292081395443,8.0357072666932E-8,0.0199457221948576,6.87131202687812E-5,0.000606200799266137,8.03449742659749E-8,0.000606200762534459,6.87139444316514E-8,2.11029723218775E-7,4.16378281187202E-8,1.00015058068121,10.005763053894,2,20,10,5,1.98324344506653,0.175106317847098,0.0410455763339996,172.855895996094,49.4994430541992,49.5012397766113,159.605087280273,159.605087280273,,,175.654418945313,0,1,,,,,,1,1,1,49.5010833740234,0,49.5002360624426,,,,,,,,,,,,,,,,,,,,,,,,,,,,,,,,,
,3768448885.98644,49.4997081756592,159.605087280273,,,5,,,,25.0300001353025,,,,,0.000615535600156864,8.97103114740838E-8,0.0190539978026152,0.000102933804890132,0.00061544296571571,8.96968106066003E-8,0.000615442931683922,6.35082249571186E-8,2.04668630043813E-7,6.33421123407828E-8,1.00015051669499,10.005763053894,2,20,10,5,2.01348270701255,0.177744654079178,0.0410455763339996,172.855895996094,49.4993476867676,49.5005340576172,159.605087280273,159.605087280273,,,177.221496582031,0,1,,,,,,1,1,1,49.4995956420898,0,49.4998873542337,,,,,,,,,,,,,,,,,,,,,,,,,,,,,,,,,
,3768449091.13843,49.4999866485596,159.605087280273,,,5,,,,25.0300001353025,,,,,0.000623280858629867,5.69677782789798E-8,0.0142972604808458,5.38481376525879E-5,0.00062318705063221,5.69592042418706E-8,0.000623187031230106,4.60305150288211E-8,1.55506523768975E-7,3.3549107798101E-8,1.00015052943986,10.005763053894,2,20,10,5,2.0388332102242,0.179811940979508,0.0410455763339996,172.855895996094,49.4996337890625,49.500602722168,159.605087280273,159.605087280273,,,178.763702392578,0,1,,,,,,1,1,1,49.5001029968262,0,49.5001344119801,,,,,,,,,,,,,,,,,,,,,,,,,,,,,,,,,
,3768449298.84101,49.5000095367432,159.605087280273,,,5,,,,25.0300001353025,,,,,0.000630824969164374,6.60350104004635E-8,0.0162441916670408,8.27799902859706E-5,0.000630730025066295,6.60250716142541E-8,0.000630729999717084,4.04175186769499E-8,1.78821186606525E-7,5.22085650603977E-8,1.00015053048738,10.005763053894,2,20,10,5,2.06350479738027,0.182058479074731,0.0410455763339996,172.855895996094,49.4996032714844,49.5008583068848,159.605087280273,159.605087280273,,,180.268585205078,0,1,,,,,,1,1,1,49.5003890991211,0,49.4999701556038,,,,,,,,,,,,,,,,,,,,,,,,,,,,,,,,,
,3768449503.91142,49.5001544952393,159.605087280273,,,5,,,,25.0300001353025,,,,,0.000637758267805221,9.02180486246314E-8,0.0120386304902214,6.54063959517212E-5,0.000637662275961584,9.02044695034282E-8,0.000637662261885896,7.99943182302422E-8,1.3398160434519E-7,4.16863930950335E-8,1.0001505371217,10.005763053894,2,20,10,5,2.08619796051409,0.18390632801864,0.0410455763339996,172.855895996094,49.4995384216309,49.5002479553223,159.605087280273,159.605087280273,,,181.736175537109,0,1,,,,,,1,1,1,49.5001258850098,0,49.4998830907485,,,,,,,,,,,,,,,,,,,,,,,,,,,,,,,,,
,3768449712.65306,49.5010528564453,159.605087280273,,,5,,,,25.0300001353025,,,,,0.000644117117226556,8.47122548580336E-8,0.0130782414426704,6.05796225587178E-5,0.000644020141809014,8.46995009565054E-8,0.000644020125031683,7.51892402668134E-8,1.47002988823264E-7,3.89946613061385E-8,1.00015057823699,10.005763053894,2,20,10,5,2.10699529062296,0.185778217989865,0.0410455763339996,172.855895996094,49.5000038146973,49.5016212463379,159.605087280273,159.605087280273,,,183.241058349609,0,1,,,,,,1,1,1,49.5006790161133,0,49.5004736956428,,,,,,,,,,,,,,,,,,,,,,,,,,,,,,,,,
,3768449919.55961,49.5010356903076,159.605087280273,,,5,,,,25.0300001353025,,,,,0.000650252241348627,9.60826365485553E-8,0.0170928398307355,6.04537177139163E-5,0.000650154342764709,9.60681708482331E-8,0.000650154313833296,8.76725627645798E-8,1.93958158449644E-7,3.92761401924391E-8,1.00015057745135,10.005763053894,2,20,10,5,2.1270509754877,0.18769676689369,0.0410455763339996,172.855895996094,49.4997749328613,49.5014801025391,159.605087280273,159.605087280273,,,184.77082824707,0,1,,,,,,1,1,1,49.5009078979492,0,49.5005374235265,,,,,,,,,,,,,,,,,,,,,,,,,,,,,,,,,
,3768450125.58727,49.4997863769531,159.605087280273,,,5,,,,25.0300001353025,,,,,0.000655673849671684,4.38972551399805E-7,0.0159252423655598,0.000482966655313425,0.000655575172317102,4.38906487075099E-7,0.000655575146993859,3.03993682966488E-7,1.82215748913642E-7,3.16586078520636E-7,1.00015052027403,10.005763053894,2,20,10,5,2.14478954514599,0.189218022877938,0.0410455763339996,172.855895996094,49.4989967346191,49.500301361084,159.605087280273,159.605087280273,,,186.263275146484,0,1,,,,,,1,1,1,49.4998321533203,0,49.4997446272108,,,,,,,,,,,,,,,,,,,,,,,,,,,,,,,,,
,3768450334.95905,49.500862121582,159.605087280273,,,5,,,,25.0300001353025,,,,,0.000660789685777661,8.89960717242894E-8,0.0149029256311106,5.81592922562277E-5,0.00066069020597865,8.89826736469308E-8,0.00066069018362926,8.02696666775382E-8,1.71848903663681E-7,3.84017814799405E-8,1.00015056950763,10.005763053894,2,20,10,5,2.16152747465813,0.190655808975738,0.0410455763339996,172.855895996094,49.4995651245117,49.5012626647949,159.605087280273,159.605087280273,,,187.780609130859,0,1,,,,,,1,1,1,49.5005874633789,0,49.500287161933,,,,,,,,,,,,,,,,,,,,,,,,,,,,,,,,,
,3768450541.38953,49.5002517700195,159.605087280273,,,5,,,,25.0300001353025,,,,,0.000665352255223733,1.00094648995999E-7,0.00907398748290156,0.000108407229236621,0.000665252107124639,1.00079582858103E-7,0.000665252098781925,6.93977720686816E-8,1.05356612984219E-7,7.21101389331299E-8,1.00015054157367,10.005763053894,2,20,10,5,2.17647174086148,0.191750815804142,0.0410455763339996,172.855895996094,49.4993667602539,49.5003929138184,159.605087280273,159.605087280273,,,189.310363769531,0,1,,,,,,1,1,1,49.5000801086426,0,49.4998781540815,,,,,,,,,,,,,,,,,,,,,,,,,,,,,,,,,
,3768450750.61712,49.5004253387451,159.605087280273,,,5,,,,25.0300001353025,,,,,0.000669526498325579,1.58775047700909E-7,0.00778301538670334,0.000121513266788323,0.000669425716607015,1.58751147792224E-7,0.000669425710430793,1.36344664020235E-7,9.0934283133271E-8,8.13145713790442E-8,1.00015054951739,10.005763053894,2,20,10,5,2.19013069271181,0.192904462668531,0.0410455763339996,172.855895996094,49.499454498291,49.5010261535645,159.605087280273,159.605087280273,,,190.865005493164,0,1,,,,,,1,1,1,49.4999237060547,0,49.4999259499943,,,,,,,,,,,,,,,,,,,,,,,,,,,,,,,,,
,3768450956.02895,49.5002593994141,159.605087280273,,,5,,,,25.0300001353025,,,,,0.000673287268015812,1.44669171074278E-7,0.0101884765237381,0.000126232943431133,0.000673185925312183,1.44647395577213E-7,0.000673185914668835,1.17068796920033E-7,1.19707577386944E-7,8.49574354307311E-8,1.00015054192285,10.005763053894,2,20,10,5,2.20242463947054,0.194080482054878,0.0410455763339996,172.855895996094,49.4998779296875,49.5004119873047,159.605087280273,159.605087280273,,,192.407211303711,0,1,,,,,,1,1,1,49.5002822875977,0,49.5001027724322,,,,,,,,,,,,,,,,,,,,,,,,,,,,,,,,,
,3768451164.63552,49.4996566772461,159.605087280273,,,5,,,,25.0300001353025,,,,,0.00067685778672813,1.00552762170684E-7,0.011262330948977,0.00010501090921673,0.000676755925258012,1.00537629815882E-7,0.000676755912183864,7.11235379323787E-8,1.33026362807662E-7,7.1058126635711E-8,1.00015051433806,10.005763053894,2,20,10,5,2.21410068958066,0.195151212966537,0.0410455763339996,172.855895996094,49.4994010925293,49.500072479248,159.605087280273,159.605087280273,,,193.974273681641,0,1,,,,,,1,1,1,49.4995613098145,0,49.4997534751892,,,,,,,,,,,,,,,,,,,,,,,,,,,,,,,,,
,3768451375.61609,49.5000782012939,159.605087280273,,,5,,,,25.0300001353025,,,,,0.000680083120274028,3.08012603708781E-7,0.0086911357157371,7.40806498920988E-5,0.000679980760301882,3.07966244432104E-7,0.000679980752478863,3.03859579090049E-7,1.03145556259702E-7,5.01254815920274E-8,1.00015053362995,10.005763053894,2,20,10,5,2.22466002381989,0.195981305628678,0.0410455763339996,172.855895996094,49.4991493225098,49.5007781982422,159.605087280273,159.605087280273,,,195.578674316406,0,1,,,,,,1,1,1,49.4996223449707,0,49.4998412662082,,,,,,,,,,,,,,,,,,,,,,,,,,,,,,,,,
,3768451581.60641,49.5000343322754,159.605087280273,,,5,,,,25.0300001353025,,,,,0.000683093885338319,9.84800086462511E-8,0.0109267264202764,0.000101606072929013,0.000682991073584066,9.84651865219939E-8,0.000682991061164114,6.98624892080403E-8,1.30251418633784E-7,6.93875028983427E-8,1.0001505316222,10.005763053894,2,20,10,5,2.23450103256802,0.196936113211029,0.0410455763339996,172.855895996094,49.4989547729492,49.5010871887207,159.605087280273,159.605087280273,,,197.183059692383,0,1,,,,,,1,1,1,49.4994125366211,0,49.4997471703423,,,,,,,,,,,,,,,,,,,,,,,,,,,,,,,,,
,3768451790.90462,49.5005512237549,159.605087280273,,,5,,,,25.0300001353025,,,,,0.000685653451495032,9.49219831866685E-8,0.0076574991825078,7.76548205718341E-5,0.000685550238287795,9.49076943322909E-8,0.000685550232165166,7.85808285292921E-8,9.16228109337472E-8,5.32214602498047E-8,1.00015055527877,10.005763053894,2,20,10,5,2.24288502746969,0.197546056109314,0.0410455763339996,172.855895996094,49.4994506835937,49.5006141662598,159.605087280273,159.605087280273,,,198.787445068359,0,1,,,,,,1,1,1,49.5006065368652,0,49.4999752044678,,,,,,,,,,,,,,,,,,,,,,,,,,,,,,,,,
,3768451998.53931,49.4992046356201,159.605087280273,,,5,,,,25.0300001353025,,,,,0.000688294162440481,9.63577156685664E-8,0.0073947316501366,8.80460266227686E-5,0.000688190594126439,9.63432166262945E-8,0.000688190588394807,7.49131144385639E-8,8.88195395338528E-8,6.05808606328413E-8,1.00015049364947,10.005763053894,2,20,10,5,2.25152413541063,0.198296561815726,0.0410455763339996,172.855895996094,49.4982376098633,49.4997329711914,159.605087280273,159.605087280273,,,200.429138183594,0,1,,,,,,1,1,1,49.4988212585449,0,49.4992368361529,,,,,,,,,,,,,,,,,,,,,,,,,,,,,,,,,
,3768452203.58058,49.5004291534424,159.605087280273,,,5,,,,25.0300001353025,,,,,0.000690369572577543,1.08071811466277E-7,0.0107305993148232,0.000110452649047967,0.000690265653296056,1.0805554373745E-7,0.000690265641190382,7.65808780611597E-8,1.29275911174453E-7,7.62323399075344E-8,1.00015054969198,10.005763053894,2,20,10,5,2.2583015622691,0.199025960667759,0.0410455763339996,172.855895996094,49.4997062683105,49.5007209777832,159.605087280273,159.605087280273,,,202.045959472656,0,1,,,,,,1,1,1,49.5005493164063,0,49.5002089606391,,,,,,,,,,,,,,,,,,,,,,,,,,,,,,,,,
,3768452410.04781,49.4996929168701,159.605087280273,,,5,,,,25.0300001353025,,,,,0.000692640452827244,1.33800245864038E-7,0.0086447987185343,7.83573066544901E-5,0.000692536215048628,1.33780109817478E-7,0.000692536207165891,1.2229619542306E-7,1.04490002798707E-7,5.4228759600614E-8,1.00015051599664,10.005763053894,2,20,10,5,2.26573721667688,0.199598152585836,0.0410455763339996,172.855895996094,49.4992980957031,49.5001220703125,159.605087280273,159.605087280273,,,203.700088500977,0,1,,,,,,1,1,1,49.4995079040527,0,49.499682931339,,,,,,,,,,,,,,,,,,,,,,,,,,,,,,,,,
,3768452617.59889,49.5002841949463,159.605087280273,,,5,,,,25.0300001353025,,,,,0.000694622445380231,9.18940676022939E-8,0.0066761022982238,5.71503739162267E-5,0.000694517890533389,9.18802356706772E-8,0.000694517885818688,8.28752321717448E-8,8.09252010193329E-8,3.96695550690776E-8,1.00015054305766,10.005763053894,2,20,10,5,2.27222750680428,0.200091225168455,0.0410455763339996,172.855895996094,49.4996528625488,49.5005111694336,159.605087280273,159.605087280273,,,205.354232788086,0,1,,,,,,1,1,1,49.5005111694336,0,49.5000542088559,,,,,,,,,,,,,,,,,,,,,,,,,,,,,,,,,
,3768452826.42067,49.500036239624,159.605087280273,,,5,,,,25.0300001353025,,,,,0.00069662424785874,1.98547928652292E-7,0.00921684950958213,0.000226203593231918,0.000696519399602824,1.98518045391554E-7,0.000696519390590787,1.20784911269503E-7,1.12045154346672E-7,1.57544976294713E-7,1.00015053170949,10.005763053894,2,20,10,5,2.27876684036392,0.200768912354985,0.0410455763339996,172.855895996094,49.499568939209,49.5002784729004,159.605087280273,159.605087280273,,,207.070541381836,0,1,,,,,,1,1,1,49.4999618530273,0,49.5000267028809,,,,,,,,,,,,,,,,,,,,,,,,,,,,,,,,,
,3768453031.47473,49.5007305145264,159.605087280273,,,5,,,,25.0300001353025,,,,,0.00069860200997046,1.40581428157948E-7,0.00717823455472555,9.89783422898356E-5,0.000698496841852129,1.40560264914698E-7,0.000698496836370312,1.22397950534963E-7,8.75103575873017E-8,6.91081021135072E-8,1.00015056348437,10.005763053894,2,20,10,5,2.28524357208454,0.201257595044722,0.0410455763339996,172.855895996094,49.4998779296875,49.5008239746094,159.605087280273,159.605087280273,,,208.724685668945,0,1,,,,,,1,1,1,49.5008239746094,0,49.5003110100241,,,,,,,,,,,,,,,,,,,,,,,,,,,,,,,,,
,3768453239.1909,49.5014400482178,159.605087280273,,,5,,,,25.0300001353025,,,,,0.000700460808284086,1.1191800899271E-7,0.00748601655289338,0.00011912412879134,0.000700355337601361,1.11901157130796E-7,0.000700355331623514,7.45838012621375E-8,9.15053722949552E-8,8.34213734992479E-8,1.0001505959576,10.005763053894,2,20,10,5,2.29132292719498,0.201805396060504,0.0410455763339996,172.855895996094,49.4995651245117,49.501651763916,159.605087280273,159.605087280273,,,210.465881347656,0,1,,,,,,1,1,1,49.5012474060059,0,49.5005623312557,,,,,,,,,,,,,,,,,,,,,,,,,,,,,,,,,
,3768453444.46412,49.4995365142822,159.605087280273,,,5,,,,25.0300001353025,,,,,0.000701898708834472,8.49703253164827E-8,0.0106935633616896,7.59176484162421E-5,0.000701793082772673,8.49575384560426E-8,0.000701793070549648,6.61838497450127E-8,1.30981179026324E-7,5.32680145438098E-8,1.00015050883856,10.005763053894,2,20,10,5,2.29601521218418,0.202348205399797,0.0410455763339996,172.855895996094,49.4990921020508,49.5003089904785,159.605087280273,159.605087280273,,,212.16975402832,0,1,,,,,,1,1,1,49.4991340637207,0,49.4995781393612,,,,,,,,,,,,,,,,,,,,,,,,,,,,,,,,,
,3768453651.98425,49.499979019165,159.605087280273,,,5,,,,25.0300001353025,,,,,0.000703130741821212,1.05922970792662E-7,0.00742686426574757,0.000109573886772314,0.000703024916119861,1.05907028703935E-7,0.000703024910213685,7.26873403537385E-8,9.11283633316683E-8,7.70249912768306E-8,1.00015052909068,10.005763053894,2,20,10,5,2.30005692918137,0.202572244608904,0.0410455763339996,172.855895996094,49.4994010925293,49.5002746582031,159.605087280273,159.605087280273,,,213.923385620117,0,1,,,,,,1,1,1,49.499927520752,0,49.4998839883243,,,,,,,,,,,,,,,,,,,,,,,,,,,,,,,,,
,3768453858.41653,49.5002384185791,159.605087280273,,,5,,,,25.0300001353025,,,,,0.000704949692626577,1.16596493330669E-7,0.00554948485264362,0.000106725268883322,0.000704843584794829,1.16578943424305E-7,0.000704843581488676,8.90722396034151E-8,6.82688816598262E-8,7.52116093562637E-8,1.00015054096262,10.005763053894,2,20,10,5,2.30601367169534,0.203020723792757,0.0410455763339996,172.855895996094,49.4998779296875,49.5002670288086,159.605087280273,159.605087280273,,,215.689468383789,0,1,,,,,,1,1,1,49.500301361084,0,49.5000944698558,,,,,,,,,,,,,,,,,,,,,,,,,,,,,,,,,
,3768454065.8563,49.4998264312744,159.605087280273,,,5,,,,25.0300001353025,,,,,0.000706160415263272,9.71175555367352E-8,0.00408698174420774,9.07895367063701E-5,0.000706054138506552,9.71029393976825E-8,0.000706054136710296,7.29463653919767E-8,5.03637509878478E-8,6.40921884145815E-8,1.00015052210719,10.005763053894,2,20,10,5,2.30997934711606,0.203310443880806,0.0410455763339996,172.855895996094,49.4989547729492,49.500804901123,159.605087280273,159.605087280273,,,217.49284362793,0,1,,,,,,1,1,1,49.4994239807129,0,49.4997026780072,,,,,,,,,,,,,,,,,,,,,,,,,,,,,,,,,
,3768454270.04884,49.5003337860107,159.605087280273,,,5,,,,25.0300001353025,,,,,0.00070736086570396,1.15226981669143E-7,0.00700981307768966,7.67881004201034E-5,0.000707254391860055,1.15209637396573E-7,0.000707254386566916,1.01619346393143E-7,8.65285561184153E-8,5.42841504279123E-8,1.0001505453273,10.005763053894,2,20,10,5,2.31389584748319,0.203774099495022,0.0410455763339996,172.855895996094,49.4995498657227,49.5005950927734,159.605087280273,159.605087280273,,,219.283782958984,0,1,,,,,,1,1,1,49.5006370544434,0,49.5000305175781,,,,,,,,,,,,,,,,,,,,,,,,,,,,,,,,,
,3768454476.43833,49.5001316070557,159.605087280273,,,5,,,,25.0300001353025,,,,,0.000708680952146411,7.90384276341323E-8,0.0073302376213098,7.12310910211032E-5,0.000708574286155114,7.90265312903563E-8,0.000708574280356205,6.081643946377E-8,9.06527133383686E-8,5.0463386120387E-8,1.00015053607417,10.005763053894,2,20,10,5,2.31821292930119,0.204167352642086,0.0410455763339996,172.855895996094,49.4996299743652,49.500560760498,159.605087280273,159.605087280273,,,221.124481201172,0,1,,,,,,1,1,1,49.4999771118164,0,49.4999724494086,,,,,,,,,,,,,,,,,,,,,,,,,,,,,,,,,
,3768454683.81616,49.5005435943604,159.605087280273,,,5,,,,25.0300001353025,,,,,0.000709742920908189,1.0926537807355E-7,0.00723076136241918,8.49319139523588E-5,0.00070963608169787,1.09248930108569E-7,0.000709636076046829,9.11311419850924E-8,8.95564942288193E-8,6.02531633224343E-8,1.0001505549296,10.005763053894,2,20,10,5,2.32168716047139,0.204469267046781,0.0410455763339996,172.855895996094,49.4996604919434,49.5009231567383,159.605087280273,159.605087280273,,,222.96516418457,0,1,,,,,,1,1,1,49.5005950927734,0,49.5002488030328,,,,,,,,,,,,,,,,,,,,,,,,,,,,,,,,,
,3768454890.29983,49.5005989074707,159.605087280273,,,5,,,,25.0300001353025,,,,,0.000710740686540343,9.00103462208409E-8,0.00747758096428086,7.35553958753181E-5,0.000710633695335394,8.99967965316471E-8,0.00071063368928348,7.32702880722816E-8,9.27436719229668E-8,5.22579015246838E-8,1.00015055746111,10.005763053894,2,20,10,5,2.32495013578776,0.20476672766527,0.0410455763339996,172.855895996094,49.4997329711914,49.5006790161133,159.605087280273,159.605087280273,,,224.805862426758,0,1,,,,,,1,1,1,49.5006790161133,0,49.5002421210794,,,,,,,,,,,,,,,,,,,,,,,,,,,,,,,,,
,3768455095.49735,49.5004367828369,159.605087280273,,,5,,,,25.0300001353025,,,,,0.000711643590653933,7.68759932773862E-8,0.00908573709078109,8.33726728748823E-5,0.000711536468809273,7.6864421335591E-8,0.000711536459862998,4.88825230785217E-8,1.12832625962148E-7,5.9318110259288E-8,1.00015055004115,10.005763053894,2,20,10,5,2.32789792844393,0.205092198663503,0.0410455763339996,172.855895996094,49.4995803833008,49.5010643005371,159.605087280273,159.605087280273,,,226.683883666992,0,1,,,,,,1,1,1,49.5,0,49.5001310460708,,,,,,,,,,,,,,,,,,,,,,,,,,,,,,,,,
,3768455300.49056,49.5003643035889,159.605087280273,,,5,,,,25.0300001353025,,,,,0.000712842574523081,6.67245545398224E-8,0.0114515428934228,7.29264968423855E-5,0.000712735274562421,6.67145108887652E-8,0.000712735260326649,4.18279351253149E-8,1.42452351348198E-7,5.1973549102208E-8,1.00015054672399,10.005763053894,2,20,10,5,2.33181150840238,0.205534021023569,0.0410455763339996,172.855895996094,49.4994430541992,49.5006523132324,159.605087280273,159.605087280273,,,228.549453735352,0,1,,,,,,1,1,1,49.5005378723145,0,49.4999753166648,,,,,,,,,,,,,,,,,,,,,,,,,,,,,,,,,
,3768455509.74477,49.4998455047607,159.605087280273,,,5,,,,25.0300001353025,,,,,0.000713648676650548,1.0000899608027E-7,0.00687044675781401,0.000105618080117345,0.000713541272291797,9.999394469372E-8,0.000713541267161839,6.57285351377538E-8,8.55621016189498E-8,7.53561453635721E-8,1.00015052298013,10.005763053894,2,20,10,5,2.3344648297903,0.205579795837408,0.0410455763339996,172.855895996094,49.4997253417969,49.5004692077637,159.605087280273,159.605087280273,,,230.489639282227,0,1,,,,,,1,1,1,49.4997367858887,0,49.5000540789436,,,,,,,,,,,,,,,,,,,,,,,,,,,,,,,,,
,3768455716.31107,49.5002479553223,159.605087280273,,,5,,,,25.0300001353025,,,,,0.000714524476476655,1.59464327529347E-7,0.0073552714307894,8.41481199226051E-5,0.000714416927152913,1.59440325159727E-7,0.000714416921266186,1.47691914049258E-7,9.17123467763892E-8,6.00692584564376E-8,1.00015054139908,10.005763053894,2,20,10,5,2.33732797679932,0.205851861015805,0.0410455763339996,172.855895996094,49.499641418457,49.5006294250488,159.605087280273,159.605087280273,,,232.392517089844,0,1,,,,,,1,1,1,49.500545501709,0,49.5000096489401,,,,,,,,,,,,,,,,,,,,,,,,,,,,,,,,,
,3768455925.80683,49.5000514984131,159.605087280273,,,5,,,,25.0300001353025,,,,,0.000715462442212872,6.94841997855689E-8,0.00335761624131425,5.43535788409883E-5,0.000715354758138669,6.94737417359437E-8,0.000715354756910358,5.75812851150577E-8,4.19208320973218E-8,3.88715370842348E-8,1.00015053240784,10.005763053894,2,20,10,5,2.34041059390194,0.205958792152829,0.0410455763339996,172.855895996094,49.4992866516113,49.5001487731934,159.605087280273,159.605087280273,,,234.370010375977,0,1,,,,,,1,1,1,49.5000801086426,0,49.4997287077062,,,,,,,,,,,,,,,,,,,,,,,,,,,,,,,,,
,3768456134.98606,49.5013046264648,159.605087280273,,,5,,,,25.0300001353025,,,,,0.000716205253762931,1.06213941750695E-7,0.0083718772593242,7.331948454051E-5,0.000716097416824973,1.06197949427004E-7,0.000716097409180588,9.23231661393333E-8,1.04633878952224E-7,5.2482734842133E-8,1.00015058975975,10.005763053894,2,20,10,5,2.34282241667091,0.20637765311785,0.0410455763339996,172.855895996094,49.5000495910645,49.5014381408691,159.605087280273,159.605087280273,,,236.347518920898,0,1,,,,,,1,1,1,49.5011978149414,0,49.5007306267233,,,,,,,,,,,,,,,,,,,,,,,,,,,,,,,,,
,3768456343.15493,49.5001449584961,159.605087280273,,,5,,,,25.0300001353025,,,,,0.000717192826135041,1.40480545336501E-7,0.00908291241550963,0.000105036045039312,0.000717084878554396,1.40459401043859E-7,0.000717084869543965,1.18572468908104E-7,1.13677118532412E-7,7.5295504239205E-8,1.00015053668523,10.005763053894,2,20,10,5,2.34605035925758,0.2066913453309,0.0410455763339996,172.855895996094,49.4995155334473,49.5006103515625,159.605087280273,159.605087280273,,,238.349884033203,0,1,,,,,,1,1,1,49.5000419616699,0,49.4998521243825,,,,,,,,,,,,,,,,,,,,,,,,,,,,,,,,,
,3768456551.20907,49.5004787445068,159.605087280273,,,5,,,,25.0300001353025,,,,,0.000718191888077194,1.58322622571708E-7,0.00154560099127732,0.000142706737968185,0.00071808377915564,1.58298790378296E-7,0.000718083778894367,1.20668261417127E-7,1.9370903235466E-8,1.02458175475653E-7,1.00015055196161,10.005763053894,2,20,10,5,2.34934565597703,0.206670210541961,0.0410455763339996,172.855895996094,49.4997444152832,49.5008163452148,159.605087280273,159.605087280273,,,240.327377319336,0,1,,,,,,1,1,1,49.5006942749023,0,49.5001889397116,,,,,,,,,,,,,,,,,,,,,,,,,,,,,,,,,
,3768456759.12657,49.4996910095215,159.605087280273,,,5,,,,25.0300001353025,,,,,0.000718263916710702,9.2984266349033E-8,0.00392533146881213,7.26115995213119E-5,0.000718155822833977,9.29702728438738E-8,0.000718155821148604,7.69785218332317E-8,4.92008254819537E-8,5.21323201961606E-8,1.00015051590935,10.005763053894,2,20,10,5,2.34957268848492,0.206788530336798,0.0410455763339996,172.855895996094,49.4992599487305,49.5000457763672,159.605087280273,159.605087280273,,,242.367065429687,0,1,,,,,,1,1,1,49.4994926452637,0,49.4995765686035,,,,,,,,,,,,,,,,,,,,,,,,,,,,,,,,,
,3768456968.63012,49.4995079040527,159.605087280273,,,5,,,,25.0300001353025,,,,,0.000718960797865361,8.93970867495207E-8,0.00443160291753308,9.68988103347431E-5,0.000718852605135933,8.93836338396444E-8,0.000718852602985697,5.60197342327369E-8,5.56004181476045E-8,6.96507241518216E-8,1.00015050752916,10.005763053894,2,20,10,5,2.35185048515055,0.207009944255958,0.0410455763339996,172.855895996094,49.4991760253906,49.5003318786621,159.605087280273,159.605087280273,,,244.431625366211,0,1,,,,,,1,1,1,49.4994201660156,0,49.4998713599311,,,,,,,,,,,,,,,,,,,,,,,,,,,,,,,,,
,3768457177.81239,49.5004043579102,159.605087280273,,,5,,,,25.0300001353025,,,,,0.000719356382702187,1.16683041998449E-7,0.00415451387800747,7.58002750691314E-5,0.00071924810093835,1.16665478179038E-7,0.000719248099047558,1.0315603504743E-7,5.21526409074891E-8,5.44946440674399E-8,1.00015054855716,10.005763053894,2,20,10,5,2.35314551655006,0.207112460454171,0.0410455763339996,172.855895996094,49.4995079040527,49.5007247924805,159.605087280273,159.605087280273,,,246.533493041992,0,1,,,,,,1,1,1,49.5004615783691,0,49.5000583424288,,,,,,,,,,,,,,,,,,,,,,,,,,,,,,,,,
,3768457383.33747,49.5006866455078,159.605087280273,,,5,,,,25.0300001353025,,,,,0.000720043538429939,7.95227262643675E-8,0.00807048356563644,8.2036688367839E-5,0.0007199351439316,7.95107550076866E-8,0.000719935136789643,5.32392228161295E-8,1.01407551788076E-7,5.90554427282268E-8,1.00015056147662,10.005763053894,2,20,10,5,2.35537915357456,0.207471282764849,0.0410455763339996,172.855895996094,49.5000228881836,49.5010414123535,159.605087280273,159.605087280273,,,248.598052978516,0,1,,,,,,1,1,1,49.5008811950684,0,49.5004786323099,,,,,,,,,,,,,,,,,,,,,,,,,,,,,,,,,
,3768457592.67131,49.5012397766113,159.605087280273,,,5,,,,25.0300001353025,,,,,0.000720857358809029,9.63736752299665E-8,0.00857752681973256,7.91841973743499E-5,0.000720748823556019,9.635916481248E-8,0.00072074881547934,7.76493524947357E-8,1.07900484011012E-7,5.70584498607083E-8,1.00015058679177,10.005763053894,2,20,10,5,2.35803945386973,0.207726641268878,0.0410455763339996,172.855895996094,49.499870300293,49.5013465881348,159.605087280273,159.605087280273,,,250.724792480469,0,1,,,,,,1,1,1,49.5011329650879,0,49.5005347307991,,,,,,,,,,,,,,,,,,,,,,,,,,,,,,,,,
,3768457799.4856,49.5012245178223,159.605087280273,,,5,,,,25.0300001353025,,,,,0.000721577455466307,1.0763266672438E-7,0.0064418810483744,9.84645918898228E-5,0.00072146881229634,1.07616461181903E-7,0.00072146880773631,8.08477271596359E-8,8.11162060910972E-8,7.1027795477807E-8,1.00015058609342,10.005763053894,2,20,10,5,2.36040275393376,0.207846166206757,0.0410455763339996,172.855895996094,49.5001449584961,49.5015411376953,159.605087280273,159.605087280273,,,252.863983154297,0,1,,,,,,1,1,1,49.5013465881348,0,49.5007223241469,,,,,,,,,,,,,,,,,,,,,,,,,,,,,,,,,
,3768458007.55451,49.4999752044678,159.605087280273,,,5,,,,25.0300001353025,,,,,0.000722119485208378,1.68318650301105E-7,0.00668552901270658,0.00012339394476877,0.000722010801704988,1.68293317290467E-7,0.000722010796789801,1.42795321140528E-7,8.42474645140406E-8,8.90625449052702E-8,1.0001505289161,10.005763053894,2,20,10,5,2.36217494048536,0.208012345422417,0.0410455763339996,172.855895996094,49.4993438720703,49.5002555847168,159.605087280273,159.605087280273,,,255.028030395508,0,1,,,,,,1,1,1,49.4999542236328,0,49.4999436771168,,,,,,,,,,,,,,,,,,,,,,,,,,,,,,,,,
,3768458215.58012,49.5007934570313,159.605087280273,,,5,,,,25.0300001353025,,,,,0.000722523645390114,1.03393804600457E-7,0.007872981834109,9.72180987240888E-5,0.00072241487400847,1.03378239314737E-7,0.000722414867188382,7.5868092289136E-8,9.92666337764381E-8,7.02217411933235E-8,1.00015056636506,10.005763053894,2,20,10,5,2.36349270326953,0.208177745271715,0.0410455763339996,172.855895996094,49.5001640319824,49.5012893676758,159.605087280273,159.605087280273,,,257.241851806641,0,1,,,,,,1,1,1,49.5012054443359,0,49.5005407894359,,,,,,,,,,,,,,,,,,,,,,,,,,,,,,,,,
,3768458424.90411,49.5008430480957,159.605087280273,,,5,,,,25.0300001353025,,,,,0.000723005219503581,7.67891979939615E-8,0.0062051291577454,8.66157476724896E-5,0.000722896373983525,7.67776376898795E-8,0.000722896369744145,4.44376190111653E-8,7.82896296653186E-8,6.26107312356031E-8,1.00015056863469,10.005763053894,2,20,10,5,2.36507407361973,0.208247654493666,0.0410455763339996,172.855895996094,49.4995002746582,49.5010871887207,159.605087280273,159.605087280273,,,259.480529785156,0,1,,,,,,1,1,1,49.5008735656738,0,49.5002535651712,,,,,,,,,,,,,,,,,,,,,,,,,,,,,,,,,
,3768458631.55789,49.4995670318604,159.605087280273,,,5,,,,25.0300001353025,,,,,0.000723429665628606,7.63753069630421E-8,0.00617720517012721,5.85312730956688E-5,0.000723320798445064,7.63638134275178E-8,0.000723320794241286,6.35613275679675E-8,7.79830731884767E-8,4.23248111512653E-8,1.00015051023526,10.005763053894,2,20,10,5,2.36646261077002,0.208368759904085,0.0410455763339996,172.855895996094,49.499454498291,49.5001640319824,159.605087280273,159.605087280273,,,261.6943359375,0,1,,,,,,1,1,1,49.499584197998,0,49.4997666676839,,,,,,,,,,,,,,,,,,,,,,,,,,,,,,,,,
,3768458840.33181,49.4994163513184,159.605087280273,,,5,,,,25.0300001353025,,,,,0.000723765515690405,5.35341257229213E-8,0.007890224978369,5.35685864259711E-5,0.000723656519935841,5.35260637300498E-8,0.000723656513074073,3.6913683519669E-8,9.96550318336567E-8,3.876105606718E-8,1.00015061807855,10.005763053894,2,20,10,5,2.36755500031025,0.208536278611406,0.0410455763339996,172.855895996094,49.4990043640137,49.4999618530273,159.605087280273,159.605087280273,,,263.982757568359,0,1,,,,,,1,1,1,49.4997634887695,0,49.4995399923886,,,,,,,,,,,,,,,,,,,,,,,,,,,,,,,,,
,3768459049.16172,49.5004825592041,159.605087280273,,,5,,,,25.0300001353025,,,,,0.000724309118648514,9.74756161244412E-8,5.64382528756013E-5,0.000115285657178065,0.000724200088778113,9.74609431712508E-8,0.000724200088777762,5.02859137964125E-8,7.13361229925374E-10,8.34863001784697E-8,1.0001505521362,10.005763053894,2,20,10,5,2.36936172598138,0.208368951960203,0.0410455763339996,172.855895996094,49.4995651245117,49.5007247924805,159.605087280273,159.605087280273,,,266.296051025391,0,1,,,,,,1,1,1,49.5005836486816,0,49.5000962151421,,,,,,,,,,,,,,,,,,,,,,,,,,,,,,,,,
,3768459257.1867,49.5001754760742,159.605087280273,,,5,,,,25.0300001353025,,,,,0.000724971310584494,7.78451381262212E-8,0.0084604650167206,8.73947601050315E-5,0.000724862191220567,7.78334212322791E-8,0.000724862183317991,4.52257126027339E-8,1.07035304181145E-7,6.33456895163066E-8,1.00015053808193,10.005763053894,2,20,10,5,2.37149727308132,0.208907301510595,0.0410455763339996,172.855895996094,49.4996528625488,49.5002555847168,159.605087280273,159.605087280273,,,268.634246826172,0,1,,,,,,1,1,1,49.5001258850098,0,49.4999730851915,,,,,,,,,,,,,,,,,,,,,,,,,,,,,,,,,
,3768459465.62246,49.5000743865967,159.605087280273,,,5,,,,25.0300001353025,,,,,0.000725334135062076,9.53805353025836E-8,0.00929859726163596,7.86680026506915E-5,0.000725224964442263,9.53661795020583E-8,0.000725224954891625,7.64282041322243E-8,1.17697584292235E-7,5.70389148383965E-8,1.00015053345536,10.005763053894,2,20,10,5,2.37268107227976,0.209046561526679,0.0410455763339996,172.855895996094,49.4995384216309,49.500373840332,159.605087280273,159.605087280273,,,270.98486328125,0,1,,,,,,1,1,1,49.4999465942383,0,49.5000048743354,,,,,,,,,,,,,,,,,,,,,,,,,,,,,,,,,
,3768459673.18668,49.5001277923584,159.605087280273,,,5,,,,25.0300001353025,,,,,0.000725736134249426,8.62826675709387E-8,0.00730296895328841,7.64347383508018E-5,0.000725626901351068,8.62696808869194E-8,0.000725626895456703,6.60862230858965E-8,9.24890238499847E-8,5.54533043070657E-8,1.00015053589959,10.005763053894,2,20,10,5,2.37400335814025,0.209079732635018,0.0410455763339996,172.855895996094,49.498966217041,49.5001640319824,159.605087280273,159.605087280273,,,273.397644042969,0,1,,,,,,1,1,1,49.5001640319824,0,49.4997966990751,,,,,,,,,,,,,,,,,,,,,,,,,,,,,,,,,
,3768459878.62842,49.500301361084,159.605087280273,,,5,,,,25.0300001353025,,,,,0.000726132371694972,7.06472759753074E-8,0.00625025144114044,5.42510011262262E-5,0.000726023073391176,7.0636642063733E-8,0.000726023069071311,5.86432601194545E-8,7.92000177033669E-8,3.93764300642139E-8,1.0001505438433,10.005763053894,2,20,10,5,2.37530335987982,0.209150242712704,0.0410455763339996,172.855895996094,49.499397277832,49.5005989074707,159.605087280273,159.605087280273,,,275.773132324219,0,1,,,,,,1,1,1,49.5003967285156,0,49.5000560158177,,,,,,,,,,,,,,,,,,,,,,,,,,,,,,,,,
,3768460090.49687,49.5000801086426,159.605087280273,,,5,,,,25.0300001353025,,,,,0.000726469866589635,6.23267612587044E-8,0.0058052564305644,5.79359578448166E-5,0.000726360524839771,6.23173803917851E-8,0.000726360521111394,4.59678670036722E-8,7.35954574028735E-8,4.20762534219379E-8,1.00015053371724,10.005763053894,2,20,10,5,2.37640898839775,0.209228997600865,0.0410455763339996,172.855895996094,49.4995269775391,49.5001678466797,159.605087280273,159.605087280273,,,278.272979736328,0,1,,,,,,1,1,1,49.4999504089355,0,49.4998683929443,,,,,,,,,,,,,,,,,,,,,,,,,,,,,,,,,
,3768460296.03132,49.5004577636719,159.605087280273,,,5,,,,25.0300001353025,,,,,0.000727163252104022,7.25133808304042E-8,0.00716865900202102,4.42993416575958E-5,0.000727053793427363,7.25024655116187E-8,0.000727053787736644,6.49642062697313E-8,9.09665729640395E-8,3.21909833494918E-8,1.00015055100138,10.005763053894,2,20,10,5,2.37867218878886,0.209485297665273,0.0410455763339996,172.855895996094,49.4997062683105,49.5009307861328,159.605087280273,159.605087280273,,,280.747985839844,0,1,,,,,,1,1,1,49.5006828308105,0,49.5002445894129,,,,,,,,,,,,,,,,,,,,,,,,,,,,,,,,,
,3768460501.36548,49.5009956359863,159.605087280273,,,5,,,,25.0300001353025,,,,,0.000727240836982975,1.11568849977747E-7,0.0047357633690428,7.31749899864727E-5,0.000727131348730639,1.11552052958413E-7,0.000727131346246833,9.80572170782037E-8,6.01007967976783E-8,5.31849856455246E-8,1.00015057561818,10.005763053894,2,20,10,5,2.37893487589195,0.209406633893384,0.0410455763339996,172.855895996094,49.4997367858887,49.5011558532715,159.605087280273,159.605087280273,,,283.210510253906,0,1,,,,,,1,1,1,49.5008354187012,0,49.5004039091222,,,,,,,,,,,,,,,,,,,,,,,,,,,,,,,,,
,3768460709.38368,49.4997882843018,159.605087280273,,,5,,,,25.0300001353025,,,,,0.000727533101520734,9.76314272827599E-8,0.00616042368639036,9.18137132138333E-5,0.000727423609456206,9.76167339766908E-8,0.000727423605251523,7.12018120047018E-8,7.82123511222353E-8,6.67782054230504E-8,1.00015052036132,10.005763053894,2,20,10,5,2.37988571530233,0.209549971474168,0.0410455763339996,172.855895996094,49.4994583129883,49.5000419616699,159.605087280273,159.605087280273,,,285.797454833984,0,1,,,,,,1,1,1,49.4996147155762,0,49.4997863769531,,,,,,,,,,,,,,,,,,,,,,,,,,,,,,,,,
,3768460917.23697,49.5007705688477,159.605087280273,,,5,,,,25.0300001353025,,,,,0.000727978335362144,7.83516523086906E-8,0.00607932977170744,6.22956541400668E-5,0.000727868743573643,7.83398570432392E-8,0.000727868739476423,6.38918410928976E-8,7.72300185459455E-8,4.533173108668E-8,1.00015056531754,10.005763053894,2,20,10,5,2.38134244879064,0.209674836814116,0.0410455763339996,172.855895996094,49.4998092651367,49.5010185241699,159.605087280273,159.605087280273,,,288.409240722656,0,1,,,,,,1,1,1,49.5006065368652,0,49.5003280639648,,,,,,,,,,,,,,,,,,,,,,,,,,,,,,,,,
,3768461125.14323,49.5011043548584,159.605087280273,,,5,,,,25.0300001353025,,,,,0.000728163228568317,8.69926924118451E-8,0.0134786722660065,6.7277667573709E-5,0.000728053597825151,8.69795949727752E-8,0.000728053577679453,7.18861170267621E-8,1.71272575921915E-7,4.89677048721164E-8,1.00015058059392,10.005763053894,2,20,10,5,2.38192016168476,0.210035698600225,0.0410455763339996,172.855895996094,49.4999847412109,49.5012626647949,159.605087280273,159.605087280273,,,291.058349609375,0,1,,,,,,1,1,1,49.5009956359863,0,49.5006192525228,,,,,,,,,,,,,,,,,,,,,,,,,,,,,,,,,
,3768461333.9735,49.499813079834,159.605087280273,,,5,,,,25.0300001353025,,,,,0.000728268852994095,1.01618749812731E-7,0.00902065536961239,8.21428605608226E-5,0.000728159249374453,1.01603456308475E-7,0.000728159240349867,8.21424631541183E-8,1.1464149142376E-7,5.97986461452298E-8,1.00015052149614,10.005763053894,2,20,10,5,2.38228201046449,0.209880812113155,0.0410455763339996,172.855895996094,49.4995803833008,49.500244140625,159.605087280273,159.605087280273,,,293.744750976562,0,1,,,,,,1,1,1,49.4999389648438,0,49.4998759219521,,,,,,,,,,,,,,,,,,,,,,,,,,,,,,,,,
,3768461542.69361,49.5002498626709,159.605087280273,,,5,,,,25.0300001353025,,,,,0.000728720325010837,7.62330746625242E-8,0.00493112816414065,7.10732522777847E-5,0.000728610638882269,7.62216001495436E-8,0.000728610636183829,5.59360030490795E-8,6.27074536411371E-8,5.17773685334653E-8,1.00015054148638,10.005763053894,2,20,10,5,2.38377383012114,0.209840778949297,0.0410455763339996,172.855895996094,49.499683380127,49.5007400512695,159.605087280273,159.605087280273,,,296.480926513672,0,1,,,,,,1,1,1,49.500057220459,0,49.5000712076823,,,,,,,,,,,,,,,,,,,,,,,,,,,,,,,,,
,3768461752.40589,49.4997329711914,159.605087280273,,,5,,,,25.0300001353025,,,,,0.000729118842715263,7.96646003195538E-8,0.00851251004005693,6.04964913935282E-5,0.000729009113845539,7.96526111813805E-8,0.00072900910579967,6.63373355328086E-8,1.08309851629753E-7,4.40896403072168E-8,1.00015051782981,10.005763053894,2,20,10,5,2.38506432389411,0.210104620992705,0.0410455763339996,172.855895996094,49.4991073608398,49.5001106262207,159.605087280273,159.605087280273,,,299.291687011719,0,1,,,,,,1,1,1,49.4994926452637,0,49.4996511671278,,,,,,,,,,,,,,,,,,,,,,,,,,,,,,,,,
,3768461909.06931,49.5001373291016,159.605087280273,,,5,,,,25.0300001353025,,,,,0.000729446266246296,4.94757533956428E-8,0.00621288623095939,4.54893264293924E-5,0.000729336474605659,4.94683066180138E-8,0.00072933647031781,3.66978016442033E-8,7.90858344269382E-8,3.31720471803676E-8,1.00015053633605,10.005763053894,2,20,10,5,2.38614381350536,0.210103199136697,0.0410455763339996,172.855895996094,49.4994468688965,49.5004348754883,159.605087280273,159.605087280273,,,301.381134033203,0,1,,,,,,1,1,1,49.5001945495605,0,49.4999470430262,,,,,,,,,,,,,,,,,,,,,,,,,,,,,,,,,