File: Experimental_Data/Fig3C/Lifetime_300Oe_48K.dat
[Header]
; MPMS3 Data File (default extension .dat)
; Copyright (c) 2007, Quantum Design, Inc. All rights reserved.
TITLE,300Oe_48K
FILEOPENTIME,3768635070.90877,06/02/2019,11:04 am
BYAPP,SQUID AC,0.9.1.0
INFO,MPMS3 Measurement Release 1.1.16 Build 347, MultiVu Release 2.3.3.2,APPNAME
INFO,0,MOMENT_UNITS
INFO,,SAMPLE_MATERIAL
INFO,,SAMPLE_COMMENT
INFO,,SAMPLE_MASS
INFO,,SAMPLE_VOLUME
INFO,,SAMPLE_MOLECULAR_WEIGHT
INFO,,SAMPLE_SIZE
INFO,,SAMPLE_SHAPE
INFO,Quartz,SAMPLE_HOLDER
INFO,Standard,SAMPLE_HOLDER_DETAIL
INFO,66.2,SAMPLE_OFFSET
DATATYPE,COMMENT,1
DATATYPE,TIME,2
STARTUPAXIS,X,2
STARTUPAXIS,Y1,5
FIELDGROUP, VSM,2,3,4,5,6,8,9,10,11,14,15
FIELDGROUP, DC, 2,3,4,14,56,57,58,59,60,61,62,63,64,65,66,67,68,69
FIELDGROUP, AC, 2,3,4,11,16,17,18,19,20,21,22,23,24,25,26,27,28,29,30
STARTUPGROUP, All
[Data]
Comment,Time Stamp (sec),Temperature (K),Magnetic Field (Oe),Moment (emu),M. Std. Err. (emu),Transport Action,Averaging Time (sec),Frequency (Hz),Peak Amplitude (mm),Center Position (mm),Lockin Signal' (V),Lockin Signal (V),Range,M. Quad. Signal (emu),AC Moment (emu),AC M. Std Err. (emu),AC Phase (deg),AC Phase Std. Err. (deg),AC Susceptibility (emu/Oe),AC Suscept. Std Err. (emu/Oe),AC X' (emu/Oe),AC X' Std Err. (emu/Oe),AC X'' (emu/Oe),AC X'' Std Err. (emu/Oe),AC Drive (Oe),AC Frequency (Hz),AC Averaging Time (sec),AC Cycles,AC Range,AC Measure Type,AC Signal' (V),AC Signal'' (V),AC Trim Coil Ratio,AC Trim Coil Phase,Min. Temperature (K),Max. Temperature (K),Min. Field (Oe),Max. Field (Oe),Mass (grams),Motor Lag (deg),Pressure (Torr),Measure Count,Measurement Number,SQUID Status (code),Motor Status (code),Measure Status (code),Motor Current (amps),Motor Temp. (C),Temp. Status (code),Field Status (code),Chamber Status (code),Chamber Temp (K),Redirection State,Average Temp (K),Rotation Angle (deg),Rotator state,DC Moment Fixed Ctr (emu),DC Moment Err Fixed Ctr (emu),DC Moment Free Ctr (emu),DC Moment Err Free Ctr (emu),DC Fixed Fit,DC Free Fit,DC Calculated Center (mm),DC Calculated Center Err (mm),DC Scan Length (mm),DC Scan Time (s),DC Number of Points,DC Squid Drift,DC Min V (V),DC Max V (V),DC Scans per Measure,Map 01,Map 02,Map 03,Map 04,Map 05,Map 06,Map 07,Map 08,Map 09,Map 10,Map 11,Map 12,Map 13,Map 14,Map 15,Map 16
,3768635074.99921,47.9764537811279,299.684539794922,,,5,,,,25.0300001353025,,,,,0.000612094841311879,1.64371752779946E-7,0.0324426472512318,0.000103816084381894,0.000612002839416846,1.643470466205E-7,0.00061200274130742,1.51594241353339E-7,3.46534968957757E-7,6.34754891386142E-8,1.00015032919638,10.005763053894,2,20,10,5,2.00216697362213,0.177524740680356,0.0410455763339996,172.855895996094,47.9133148193359,47.9865341186523,299.684539794922,299.684539794922,,,53.6090965270996,0,1,,,,,,1,1,1,47.9707183837891,0,47.9437785901521,,,,,,,,,,,,,,,,,,,,,,,,,,,,,,,,,
,3768635281.1957,47.999662399292,299.684539794922,,,5,,,,25.0300001353025,,,,,0.000621217794241723,1.22267737978282E-7,0.00398052709446794,0.000150091708006789,0.000621124117668167,1.22249300607594E-7,0.000621124116169227,7.90908711667223E-8,4.31515444667657E-8,9.32176249275578E-8,1.00015081780097,10.005763053894,2,20,10,5,2.03209748419799,0.179161101161796,0.0410455763339996,172.855895996094,47.9994010925293,47.9999198913574,299.684539794922,299.684539794922,,,53.8329658508301,0,1,,,,,,1,1,1,47.9997024536133,0,47.9996232425465,,,,,,,,,,,,,,,,,,,,,,,,,,,,,,,,,
,3768635486.31253,47.9999485015869,299.684539794922,,,5,,,,25.0300001353025,,,,,0.000627357931599285,1.01172733470422E-7,-0.00389176912452172,0.000108829648348634,0.000627263320910616,1.01157475797719E-7,0.000627263319463615,7.46597635342999E-8,-4.26063497893483E-8,6.82550702788331E-8,1.00015083089592,10.005763053894,2,20,10,5,2.05220764366824,0.18064996821691,0.0410455763339996,172.855895996094,47.9993896484375,48.0005378723145,299.684539794922,299.684539794922,,,54.0443916320801,0,1,,,,,,1,1,1,47.9998931884766,0,47.9998687295353,,,,,,,,,,,,,,,,,,,,,,,,,,,,,,,,,
,3768635691.63188,48.001392364502,299.684539794922,,,5,,,,25.0300001353025,,,,,0.000631363777391497,1.09980558800528E-7,-0.00388762314002999,0.000132639222592125,0.000631268593292569,1.09963978184464E-7,0.000631268591839429,7.12912706062159E-8,-4.2832725374038E-8,8.3723540497907E-8,1.00015078225012,10.005763053894,2,20,10,5,2.06531151794703,0.181803608911544,0.0410455763339996,172.855895996094,48.0003623962402,48.0015869140625,299.684539794922,299.684539794922,,,54.1563262939453,0,1,,,,,,1,1,1,48.0014915466309,0,48.0009319081026,,,,,,,,,,,,,,,,,,,,,,,,,,,,,,,,,
,3768635896.85533,48.0013198852539,299.684539794922,,,5,,,,25.0300001353025,,,,,0.000634805626372362,1.1502340092658E-7,0.00384357609955011,0.000103340296186791,0.000634709925487199,1.1500606043553E-7,0.000634709924059059,9.44797837909425E-8,4.25782827051525E-8,6.5574113731849E-8,1.00015077893274,10.005763053894,2,20,10,5,2.07654577905894,0.18307490341734,0.0410455763339996,172.855895996094,47.9998550415039,48.0018196105957,299.684539794922,299.684539794922,,,54.2931327819824,0,1,,,,,,1,1,1,48.0012855529785,0,48.0006639817182,,,,,,,,,,,,,,,,,,,,,,,,,,,,,,,,,
,3768636104.5726,47.9995784759521,299.684539794922,,,5,,,,25.0300001353025,,,,,0.000637737166385568,1.23145222822212E-7,-0.00420003439728234,9.89604367034947E-5,0.00063764107436781,1.23126667728418E-7,0.000637641072654615,1.05740366020226E-7,-4.67419147767225E-8,6.30805144225452E-8,1.00015069922817,10.005763053894,2,20,10,5,2.08616109109487,0.183627486321729,0.0410455763339996,172.855895996094,47.998462677002,48.0006561279297,299.684539794922,299.684539794922,,,54.4050712585449,0,1,,,,,,1,1,1,47.9988479614258,0,47.999340057373,,,,,,,,,,,,,,,,,,,,,,,,,,,,,,,,,
,3768636313.81906,47.9995536804199,299.684539794922,,,5,,,,25.0300001353025,,,,,0.000640500177349166,1.43691217101003E-7,-0.00223664632508225,0.000155419543182711,0.000640403596273741,1.43669549890333E-7,0.000640403595785794,1.03619790643385E-7,-2.49993343660554E-8,9.95182322627966E-8,1.00015081282489,10.005763053894,2,20,10,5,2.09519311134861,0.184494851340349,0.0410455763339996,172.855895996094,47.9989547729492,48.0000915527344,299.684539794922,299.684539794922,,,54.504566192627,0,1,,,,,,1,1,1,47.9994888305664,0,47.9996225568983,,,,,,,,,,,,,,,,,,,,,,,,,,,,,,,,,
,3768636520.37165,48.0003051757812,299.684539794922,,,5,,,,25.0300001353025,,,,,0.000642882637029341,1.05886516886162E-7,-0.000897082440177499,7.83919255178067E-5,0.000642785674596662,1.05870546608426E-7,0.000642785674517874,9.31213770826903E-8,-1.00641224598941E-8,5.03684600657017E-8,1.00015084722095,10.005763053894,2,20,10,5,2.10298224253154,0.185230278073736,0.0410455763339996,172.855895996094,47.9997482299805,48.0005302429199,299.684539794922,299.684539794922,,,54.604061126709,0,1,,,,,,1,1,1,48.0003623962402,0,48.0001537098604,,,,,,,,,,,,,,,,,,,,,,,,,,,,,,,,,
,3768636725.1997,48.0000953674316,299.684539794922,,,5,,,,25.0300001353025,,,,,0.000645119180770042,1.22926979424211E-7,-0.00261930633771801,0.000110524952091798,0.000645021887205026,1.2290844020786E-7,0.000645021886531007,1.00132238928552E-7,-2.9487510788621E-8,7.12742548293871E-8,1.00015083761799,10.005763053894,2,20,10,5,2.11030395686604,0.185811248740574,0.0410455763339996,172.855895996094,47.9994735717773,48.0003814697266,299.684539794922,299.684539794922,,,54.6911201477051,0,1,,,,,,1,1,1,48.0003814697266,0,47.9999775606043,,,,,,,,,,,,,,,,,,,,,,,,,,,,,,,,,
,3768636930.77943,48.0002899169922,299.684539794922,,,5,,,,25.0300001353025,,,,,0.000647094219402523,1.406987485257E-7,-0.00300198963348652,0.000135086367278341,0.000646996622211959,1.40677527809829E-7,0.000646996621323893,1.10246233280697E-7,-3.38991312867812E-8,8.73838364807998E-8,1.00015084652255,10.005763053894,2,20,10,5,2.11676591771477,0.186365973582462,0.0410455763339996,172.855895996094,47.9999618530273,48.0005989074707,299.684539794922,299.684539794922,,,54.7781791687012,0,1,,,,,,1,1,1,48.0003929138184,0,48.0001892513699,,,,,,,,,,,,,,,,,,,,,,,,,,,,,,,,,
,3768637136.21545,48.0001106262207,299.684539794922,,,5,,,,25.0300001353025,,,,,0.000649200772161567,1.1959520481345E-7,-0.00338269905106259,0.000143461678010744,0.000649102862578614,1.19577167994751E-7,0.000649102861447348,7.50232656444404E-8,-3.83225370990853E-8,9.31139555474296E-8,1.00015083831639,10.005763053894,2,20,10,5,2.12365808711237,0.186958559171941,0.0410455763339996,172.855895996094,47.9996795654297,48.0006446838379,299.684539794922,299.684539794922,,,54.8652420043945,0,1,,,,,,1,1,1,48.000373840332,0,48.0000610351562,,,,,,,,,,,,,,,,,,,,,,,,,,,,,,,,,
,3768637341.40885,48.0001220703125,299.684539794922,,,5,,,,25.0300001353025,,,,,0.000650799882576323,9.48721707384248E-8,-0.00179479055925036,0.000100554394450799,0.000650701731481841,9.48578624884647E-8,0.000650701731162588,6.86873119762956E-8,-2.0383234756302E-8,6.54222229013316E-8,1.00015083884018,10.005763053894,2,20,10,5,2.12888388372175,0.187478075285104,0.0410455763339996,172.855895996094,47.999683380127,48.0004997253418,299.684539794922,299.684539794922,,,54.9523010253906,0,1,,,,,,1,1,1,48.0004692077637,0,48.0001761492561,,,,,,,,,,,,,,,,,,,,,,,,,,,,,,,,,
,3768637546.34402,48.000093460083,299.684539794922,,,5,,,,25.0300001353025,,,,,0.000652711883181204,1.19408979863128E-7,-0.00499396127010154,0.000127013877224892,0.000652613444580729,1.19390971223842E-7,0.00065261344210176,8.59363959917005E-8,-5.68824840180932E-8,8.28802742136507E-8,1.00015083753069,10.005763053894,2,20,10,5,2.13514887817834,0.187909654690843,0.0410455763339996,172.855895996094,47.9995269775391,48.0004653930664,299.684539794922,299.684539794922,,,55.039363861084,0,1,,,,,,1,1,1,48.0002098083496,0,47.9999562431784,,,,,,,,,,,,,,,,,,,,,,,,,,,,,,,,,
,3768637754.02207,48.0005168914795,299.684539794922,,,5,,,,25.0300001353025,,,,,0.000654121523036741,1.20040640129757E-7,-0.00321850452866013,0.000111760736099165,0.000654022934194138,1.20022547669322E-7,0.000654022933162265,9.52093664454815E-8,-3.67387579387721E-8,7.30793301151877E-8,1.00015074217959,10.005763053894,2,20,10,5,2.13975425077332,0.188381782816372,0.0410455763339996,172.855895996094,47.9995460510254,48.001033782959,299.684539794922,299.684539794922,,,55.1264228820801,0,1,,,,,,1,1,1,48.0001831054687,0,48.0001022815704,,,,,,,,,,,,,,,,,,,,,,,,,,,,,,,,,
,3768637959.33134,48.0001583099365,299.684539794922,,,5,,,,25.0300001353025,,,,,0.000655674695512162,1.81999418259202E-7,-0.000175703151352735,0.000215143302438019,0.000655575883334149,1.8197199039133E-7,0.000655575883331067,1.14995364926496E-7,-2.01038801865296E-9,1.41031455116951E-7,1.00015072576726,10.005763053894,2,20,10,5,2.14482493811474,0.188942990861661,0.0410455763339996,172.855895996094,47.9996032714844,48.0007781982422,299.684539794922,299.684539794922,,,55.2010459899902,0,1,,,,,,1,1,1,47.999828338623,0,47.9999938540988,,,,,,,,,,,,,,,,,,,,,,,,,,,,,,,,,
,3768638165.68583,48.0005836486816,299.684539794922,,,5,,,,25.0300001353025,,,,,0.00065709344362799,9.32087804116039E-8,-0.000605074243591908,8.6073013241372E-5,0.000656994404851985,9.31947317498582E-8,0.000656994404815349,7.40860333927764E-8,-6.93821422678739E-9,5.65377544836408E-8,1.00015074523508,10.005763053894,2,20,10,5,2.14946732683509,0.189335715573261,0.0410455763339996,172.855895996094,47.9992752075195,48.0010147094727,299.684539794922,299.684539794922,,,55.2881050109863,0,1,,,,,,1,1,1,48.0002899169922,0,48.0000525580512,,,,,,,,,,,,,,,,,,,,,,,,,,,,,,,,,
,3768638371.69927,48.0005435943604,299.684539794922,,,5,,,,25.0300001353025,,,,,0.000658191295294703,1.50395793594549E-7,-0.0014174543269112,0.000131715212914106,0.000658092092254027,1.50373125838023E-7,0.000658092092052641,1.2289082881801E-7,-1.62807015019907E-8,8.66598013309534E-8,1.00015074340179,10.005763053894,2,20,10,5,2.15306128010216,0.189621523532897,0.0410455763339996,172.855895996094,47.9999580383301,48.0009002685547,299.684539794922,299.684539794922,,,55.3627281188965,0,1,,,,,,1,1,1,48.0004730224609,0,48.0002472821404,,,,,,,,,,,,,,,,,,,,,,,,,,,,,,,,,
,3768638579.47476,48.0005416870117,299.684539794922,,,5,,,,25.0300001353025,,,,,0.000659867311803932,7.85850531630269E-8,-0.00244075468053495,7.63559078840623E-5,0.000659767856210495,7.85732087771059E-8,0.000659767855611857,6.0305564895202E-8,-2.81055864203322E-8,5.03685217194356E-8,1.00015074331449,10.005763053894,2,20,10,5,2.15854722429132,0.190065824412184,0.0410455763339996,172.855895996094,48.0000839233398,48.0010223388672,299.684539794922,299.684539794922,,,55.4497871398926,0,1,,,,,,1,1,1,48.0003089904785,0,48.0004447488224,,,,,,,,,,,,,,,,,,,,,,,,,,,,,,,,,
,3768638787.20258,48.0009288787842,299.684539794922,,,5,,,,25.0300001353025,,,,,0.000661068387649456,1.35414949617836E-7,-0.000882292718806355,0.000141512048503353,0.000660968739317347,1.35394537397067E-7,0.00066096873923898,9.790399871638E-8,-1.01782000522763E-8,9.3522659245281E-8,1.00015076103631,10.005763053894,2,20,10,5,2.16247098417965,0.190470596124951,0.0410455763339996,172.855895996094,47.9999732971191,48.0015411376953,299.684539794922,299.684539794922,,,55.5119743347168,0,1,,,,,,1,1,1,48.0007362365723,0,48.0006114735323,,,,,,,,,,,,,,,,,,,,,,,,,,,,,,,,,
,3768638993.66737,47.9988098144531,299.684539794922,,,5,,,,25.0300001353025,,,,,0.000662188729631009,9.93045025070879E-8,-0.000566410627321545,0.000132336282823382,0.000662088900675618,9.9289531752819E-8,0.000662088900643266,4.6711418856897E-8,-6.54523234966328E-9,8.76153780113377E-8,1.00015077877803,10.005763053894,2,20,10,5,2.16613476725897,0.190805345294638,0.0410455763339996,172.855895996094,47.9987030029297,47.9997482299805,299.684539794922,299.684539794922,,,55.586597442627,0,1,,,,,,1,1,1,47.9988670349121,0,47.9991888158462,,,,,,,,,,,,,,,,,,,,,,,,,,,,,,,,,
,3768639200.21429,48.0007247924805,299.684539794922,,,5,,,,25.0300001353025,,,,,0.000663505641657246,1.07580925823153E-7,-0.00646060121753767,0.000113979811168723,0.000663405632133562,1.07564710260732E-7,0.000663405627916114,7.65112254195464E-8,-7.4804798224665E-8,7.56055505784769E-8,1.00015075169525,10.005763053894,2,20,10,5,2.17046227310156,0.190961515331527,0.0410455763339996,172.855895996094,47.999755859375,48.0011596679687,299.684539794922,299.684539794922,,,55.673656463623,0,1,,,,,,1,1,1,48.0008811950684,0,48.0003691280589,,,,,,,,,,,,,,,,,,,,,,,,,,,,,,,,,
,3768639406.71498,47.9991703033447,299.684539794922,,,5,,,,25.0300001353025,,,,,0.00066445914555477,1.04871518941508E-7,-0.00299966348724823,9.80569757548916E-5,0.000664358963360423,1.04855707196027E-7,0.000664358962449938,8.21733227246164E-8,-3.4781852011507E-8,6.51326674102554E-8,1.00015079527766,10.005763053894,2,20,10,5,2.17356982254541,0.191367242911932,0.0410455763339996,172.855895996094,47.9987831115723,48.0001487731934,299.684539794922,299.684539794922,,,55.7234039306641,0,1,,,,,,1,1,1,47.9989318847656,0,47.9996181064182,,,,,,,,,,,,,,,,,,,,,,,,,,,,,,,,,
,3768639613.10182,48.0002384185791,299.684539794922,,,5,,,,25.0300001353025,,,,,0.000665385918227308,8.9791860484792E-8,-0.00556471049003004,9.94366549459318E-5,0.000665285563781645,8.97783179493443E-8,0.000665285560643898,6.07019175606205E-8,-6.46142103534127E-8,6.61469846499233E-8,1.00015084416546,10.005763053894,2,20,10,5,2.17661004633711,0.191536708764379,0.0410455763339996,172.855895996094,47.9997100830078,48.0004081726074,299.684539794922,299.684539794922,,,55.8104667663574,0,1,,,,,,1,1,1,48.0002212524414,0,48.0001223087311,,,,,,,,,,,,,,,,,,,,,,,,,,,,,,,,,
,3768639818.26834,47.9997062683105,299.684539794922,,,5,,,,25.0300001353025,,,,,0.000666228774559943,1.20882376942089E-7,-0.00461262847837407,0.000153945577461949,0.00066612830921567,1.20864148234354E-7,0.000666128307057033,6.39782548931644E-8,-5.36270285897551E-8,1.02542309459272E-7,1.00015081980886,10.005763053894,2,20,10,5,2.17936401024423,0.191815548086537,0.0410455763339996,172.855895996094,47.9996223449707,48.0000305175781,299.684539794922,299.684539794922,,,55.8726501464844,0,1,,,,,,1,1,1,47.9997787475586,0,47.999764919281,,,,,,,,,,,,,,,,,,,,,,,,,,,,,,,,,
,3768640023.3778,48.0010032653809,299.684539794922,,,5,,,,25.0300001353025,,,,,0.000667503459041129,9.73878916925273E-8,-0.00455472599619444,0.000115766567542778,0.000667402838425274,9.73732112747614E-8,0.000667402836316464,5.92693647136146E-8,-5.305516533227E-8,7.72572629621569E-8,1.000150764441,10.005763053894,2,20,10,5,2.18353355759188,0.1921847467223,0.0410455763339996,172.855895996094,48.0000419616699,48.0011367797852,299.684539794922,299.684539794922,,,55.9223976135254,0,1,,,,,,1,1,1,48.0010795593262,0,48.0004983789781,,,,,,,,,,,,,,,,,,,,,,,,,,,,,,,,,
,3768640231.07043,48.0008010864258,299.684539794922,,,5,,,,25.0300001353025,,,,,0.000667994512037623,1.2648592551902E-7,-0.0060402685367098,0.000135963987163007,0.000667893823579195,1.26466859983864E-7,0.000667893819867737,8.80305268107956E-8,-7.04110856897295E-8,9.0799190654939E-8,1.00015075518724,10.005763053894,2,20,10,5,2.18514487314032,0.192269473884135,0.0410455763339996,172.855895996094,47.9995307922363,48.0011138916016,299.684539794922,299.684539794922,,,55.9970207214355,0,1,,,,,,1,1,1,48.0008926391602,0,48.0002293306239,,,,,,,,,,,,,,,,,,,,,,,,,,,,,,,,,
,3768640437.81515,47.9998149871826,299.684539794922,,,5,,,,25.0300001353025,,,,,0.000668874081511434,1.03388735195774E-7,0.0017105518483076,0.000116292469415485,0.000668773213935268,1.03373143963567E-7,0.000668773213637227,6.81060625178585E-8,1.99660649832758E-8,7.77661310676176E-8,1.00015082478494,10.005763053894,2,20,10,5,2.18799605809233,0.192818633146827,0.0410455763339996,172.855895996094,47.9996032714844,48.0006790161133,299.684539794922,299.684539794922,,,56.0592079162598,0,1,,,,,,1,1,1,47.9999694824219,0,47.9999809265137,,,,,,,,,,,,,,,,,,,,,,,,,,,,,,,,,
,3768640644.98836,48.0004024505615,299.684539794922,,,5,,,,25.0300001353025,,,,,0.000669663535374974,1.21843738839491E-7,-0.00514619591833387,0.000121758099640259,0.000669562530746877,1.218253612799E-7,0.000669562528046102,9.05378420990193E-8,-6.01388093058271E-8,8.15126848964696E-8,1.00015085167323,10.005763053894,2,20,10,5,2.19060157708662,0.192784056167193,0.0410455763339996,172.855895996094,47.9997634887695,48.0006790161133,299.684539794922,299.684539794922,,,56.1213912963867,0,1,,,,,,1,1,1,48.0003128051758,0,48.0002381801605,,,,,,,,,,,,,,,,,,,,,,,,,,,,,,,,,
,3768640851.75066,48.0010070800781,299.684539794922,,,5,,,,25.0300001353025,,,,,0.000670500146697775,1.48588527484041E-7,-2.46436126118965E-5,0.00017349844071521,0.000670399074239051,1.48566128968716E-7,0.000670399074238989,9.24402145284174E-8,-2.88346807065405E-10,1.16304348219184E-7,1.0001507646156,10.005763053894,2,20,10,5,2.19332103513226,0.193220956802323,0.0410455763339996,172.855895996094,47.9997825622559,48.0012664794922,299.684539794922,299.684539794922,,,56.1835746765137,0,1,,,,,,1,1,1,48.0007629394531,0,48.0003272162543,,,,,,,,,,,,,,,,,,,,,,,,,,,,,,,,,
,3768641056.62162,47.9998435974121,299.684539794922,,,5,,,,25.0300001353025,,,,,0.000671111961145674,1.30602509122511E-7,-0.00414635262562157,0.000151196183830589,0.000671010832188687,1.3058282880642E-7,0.000671010830431627,8.22227051823555E-8,-4.85593798894445E-8,1.01446054292823E-7,1.00015071136282,10.005763053894,2,20,10,5,2.19533629150439,0.193239345189316,0.0410455763339996,172.855895996094,47.9987258911133,48.0005683898926,299.684539794922,299.684539794922,,,56.2581977844238,0,1,,,,,,1,1,1,47.9994964599609,0,47.9995195725385,,,,,,,,,,,,,,,,,,,,,,,,,,,,,,,,,
,3768641264.33545,48.0005836486816,299.684539794922,,,5,,,,25.0300001353025,,,,,0.00067236329165692,9.27461354484403E-8,0.0044374002730132,0.000101289269809522,0.000672261951371027,9.27321565177067E-8,0.000672261949354888,6.29567973295175E-8,5.20648359952397E-8,6.80859348355776E-8,1.00015074523508,10.005763053894,2,20,10,5,2.19940060595405,0.193929151830458,0.0410455763339996,172.855895996094,47.9995651245117,48.0008544921875,299.684539794922,299.684539794922,,,56.332820892334,0,1,,,,,,1,1,1,48.0006904602051,0,48.0002903657801,,,,,,,,,,,,,,,,,,,,,,,,,,,,,,,,,
,3768641472.77699,48.0006504058838,299.684539794922,,,5,,,,25.0300001353025,,,,,0.000672808281525217,9.45603552453507E-8,0.000108623458865864,9.32862837422064E-5,0.000672706872114194,9.45461025820068E-8,0.000672706872112985,7.07253322053716E-8,1.27534257972967E-9,6.27446642981471E-8,1.00015074829057,10.005763053894,2,20,10,5,2.2008708891757,0.193891221982894,0.0410455763339996,172.855895996094,47.9995803833008,48.0009384155273,299.684539794922,299.684539794922,,,56.3950080871582,0,1,,,,,,1,1,1,48.0005836486816,0,48.0001911836512,,,,,,,,,,,,,,,,,,,,,,,,,,,,,,,,,
,3768641678.13269,48.000373840332,299.684539794922,,,5,,,,25.0300001353025,,,,,0.000673393011473846,1.21066505843592E-7,-0.00149100555436377,0.000101833315342083,0.000673291445214435,1.21048245671702E-7,0.00067329144498646,9.97703090183064E-8,-1.75210337120522E-8,6.85460663976314E-8,1.00015085036374,10.005763053894,2,20,10,5,2.20278905781159,0.193998231774811,0.0410455763339996,172.855895996094,48.0000762939453,48.0007629394531,299.684539794922,299.684539794922,,,56.4447555541992,0,1,,,,,,1,1,1,48.0005149841309,0,48.0003566741943,,,,,,,,,,,,,,,,,,,,,,,,,,,,,,,,,
,3768641883.21861,48.0006198883057,299.684539794922,,,5,,,,25.0300001353025,,,,,0.000674180004087143,1.33302682337006E-7,-0.00173368866800683,0.000140821023848294,0.000674078388863864,1.3328259040051E-7,0.000674078388555277,9.35720104712181E-8,-2.03966517931118E-8,9.49132644062159E-8,1.00015074689377,10.005763053894,2,20,10,5,2.20536427412491,0.194215616088246,0.0410455763339996,172.855895996094,47.9997024536133,48.0010108947754,299.684539794922,299.684539794922,,,56.5193786621094,0,1,,,,,,1,1,1,48.0004730224609,0,48.0002762289608,,,,,,,,,,,,,,,,,,,,,,,,,,,,,,,,,
,3768642090.90472,48.0013122558594,299.684539794922,,,5,,,,25.0300001353025,,,,,0.000675198973368643,8.44383556505271E-8,-0.00722788896440463,8.11186897425051E-5,0.000675097183171614,8.44256260742133E-8,0.000675097177799886,6.42625095704629E-8,-8.51638202442211E-8,5.47541432380148E-8,1.00015077858354,10.005763053894,2,20,10,5,2.20871614819429,0.19429735769409,0.0410455763339996,172.855895996094,47.9998207092285,48.0017127990723,299.684539794922,299.684539794922,,,56.5815620422363,0,1,,,,,,1,1,1,48.0011100769043,0,48.0005547018612,,,,,,,,,,,,,,,,,,,,,,,,,,,,,,,,,
,3768642296.31169,48.0010871887207,299.684539794922,,,5,,,,25.0300001353025,,,,,0.000675567495988318,1.15557564014023E-7,-0.00181971287767624,0.000117802592170858,0.00067546565719151,1.15540144224955E-7,0.00067546565685084,8.37829175842867E-8,-2.14527765405852E-8,7.95609681224913E-8,1.00015076828218,10.005763053894,2,20,10,5,2.20990330273018,0.194611998016203,0.0410455763339996,172.855895996094,47.9998054504395,48.00146484375,299.684539794922,299.684539794922,,,56.6437492370605,0,1,,,,,,1,1,1,48.0014801025391,0,48.0004821353488,,,,,,,,,,,,,,,,,,,,,,,,,,,,,,,,,
,3768642502.7304,48.000316619873,299.684539794922,,,5,,,,25.0300001353025,,,,,0.00067606676166513,1.07271292840756E-7,0.000698467768814659,0.000108105762645488,0.000675964871443287,1.07255125952447E-7,0.00067596487139306,7.85181489638295E-8,8.24039186751239E-9,7.30654660312876E-8,1.00015073301313,10.005763053894,2,20,10,5,2.21152792869014,0.19485302588119,0.0410455763339996,172.855895996094,47.9997711181641,48.0006332397461,299.684539794922,299.684539794922,,,56.6935005187988,0,1,,,,,,1,1,1,48.0002212524414,0,48.000061750412,,,,,,,,,,,,,,,,,,,,,,,,,,,,,,,,,
,3768642710.67314,47.999662399292,299.684539794922,,,5,,,,25.0300001353025,,,,,0.00067655300195591,1.03284157257154E-7,-0.00366708565033669,0.000113571063846337,0.000676450981106476,1.03268582516629E-7,0.000676450979720986,6.9017674848299E-8,-4.32947017277558E-8,7.6817710806352E-8,1.00015081780097,10.005763053894,2,20,10,5,2.21313335272517,0.194824546730678,0.0410455763339996,172.855895996094,47.9988822937012,48.0000419616699,299.684539794922,299.684539794922,,,56.7556838989258,0,1,,,,,,1,1,1,47.999267578125,0,47.9996223449707,,,,,,,,,,,,,,,,,,,,,,,,,,,,,,,,,
,3768642917.84056,48.0006103515625,299.684539794922,,,5,,,,25.0300001353025,,,,,0.000677021529821767,1.01873541840871E-7,-0.00788344447839862,9.73041183672958E-5,0.000676919486607301,1.01858187080024E-7,0.000676919480199725,7.77047897977692E-8,-9.31387480461516E-8,6.58563278486869E-8,1.00015074645727,10.005763053894,2,20,10,5,2.21468033771726,0.19479648597271,0.0410455763339996,172.855895996094,47.9998016357422,48.0010795593262,299.684539794922,299.684539794922,,,56.8303070068359,0,1,,,,,,1,1,1,48.000358581543,0,48.0003653133617,,,,,,,,,,,,,,,,,,,,,,,,,,,,,,,,,
,3768643121.84479,48.0008563995361,299.684539794922,,,5,,,,25.0300001353025,,,,,0.000677557709090462,1.14707505774486E-7,-0.00160164930635354,0.00012849687219576,0.000677455577432935,1.14690215339238E-7,0.000677455577168243,7.46815620972317E-8,-1.89376296955997E-8,8.70431489393517E-8,1.00015075771893,10.005763053894,2,20,10,5,2.21641290614351,0.1951937606849,0.0410455763339996,172.855895996094,47.9999465942383,48.0009651184082,299.684539794922,299.684539794922,,,56.880054473877,0,1,,,,,,1,1,1,48.000846862793,0,48.0005633705541,,,,,,,,,,,,,,,,,,,,,,,,,,,,,,,,,
,3768643328.57514,47.9989128112793,299.684539794922,,,5,,,,25.0300001353025,,,,,0.000678226260995367,8.58672314329533E-8,-0.00614961282419113,8.94393142074542E-5,0.000678124011088823,8.58542860238854E-8,0.000678124007182849,6.07726068273719E-8,-7.27837223337686E-8,6.06436203411108E-8,1.00015078349221,10.005763053894,2,20,10,5,2.21861536099798,0.19521026075713,0.0410455763339996,172.855895996094,47.9983215332031,47.9997520446777,299.684539794922,299.684539794922,,,56.9422416687012,0,1,,,,,,1,1,1,47.9992218017578,0,47.9991819593642,,,,,,,,,,,,,,,,,,,,,,,,,,,,,,,,,
,3768643535.71493,47.9997234344482,299.684539794922,,,5,,,,25.0300001353025,,,,,0.000678705795921452,1.33605894625056E-7,0.00138048887586262,0.000122478796469048,0.00067860352639141,1.33585762467446E-7,0.000678603526194438,1.04593510404763E-7,1.63503250531734E-8,8.30984567559324E-8,1.00015070586294,10.005763053894,2,20,10,5,2.22015832399257,0.195640068481175,0.0410455763339996,172.855895996094,47.9989547729492,48.000560760498,299.684539794922,299.684539794922,,,57.0168647766113,0,1,,,,,,1,1,1,47.9993171691895,0,47.9996333652072,,,,,,,,,,,,,,,,,,,,,,,,,,,,,,,,,
,3768643745.36708,48.0002174377441,299.684539794922,,,5,,,,25.0300001353025,,,,,0.000678986704676717,1.00859185981229E-7,-0.00530674084520566,0.000105814721448853,0.000678884377470785,1.00843985921164E-7,0.000678884374558886,7.07835645158516E-8,-6.2878339042804E-8,7.18275468806938E-8,1.00015072847355,10.005763053894,2,20,10,5,2.22110005135028,0.195461805742584,0.0410455763339996,172.855895996094,47.9989356994629,48.0004005432129,299.684539794922,299.684539794922,,,57.0666122436523,0,1,,,,,,1,1,1,48.000114440918,0,47.9996043934542,,,,,,,,,,,,,,,,,,,,,,,,,,,,,,,,,
,3768643950.42689,48.0005970001221,299.684539794922,,,5,,,,25.0300001353025,,,,,0.000679538139939257,1.04044906784328E-7,-0.0031395071169662,9.43561280990387E-5,0.000679435717827051,1.04029224810807E-7,0.00067943571680706,8.19373225994402E-8,-3.72295008236094E-8,6.40964490433955E-8,1.00015074584618,10.005763053894,2,20,10,5,2.22289650451187,0.19570462918377,0.0410455763339996,172.855895996094,47.9994583129883,48.0009841918945,299.684539794922,299.684539794922,,,57.1163597106934,0,1,,,,,,1,1,1,48.0005264282227,0,48.0002434674431,,,,,,,,,,,,,,,,,,,,,,,,,,,,,,,,,
,3768644155.53373,48.0007362365723,299.684539794922,,,5,,,,25.0300001353025,,,,,0.000679930767162718,1.11871796367493E-7,-0.000160192902426637,9.53045232565935E-5,0.000679828281540704,1.11854933987983E-7,0.000679828281538046,9.11904977606005E-8,-1.9007275317148E-9,6.47751447364642E-8,1.00015075221905,10.005763053894,2,20,10,5,2.22417067645867,0.195933358169806,0.0410455763339996,172.855895996094,47.9994583129883,48.000789642334,299.684539794922,299.684539794922,,,57.1785469055176,0,1,,,,,,1,1,1,48.0007247924805,0,48.0001595441033,,,,,,,,,,,,,,,,,,,,,,,,,,,,,,,,,
,3768644361.71473,48.0004367828369,299.684539794922,,,5,,,,25.0300001353025,,,,,0.000680542826931775,1.0096068720754E-7,-0.00256052948388152,0.000106815993953059,0.000680440258379037,1.00945470837372E-7,0.000680440257699561,7.00608032112411E-8,-3.04086506515149E-8,7.26737362186256E-8,1.00015073851301,10.005763053894,2,20,10,5,2.22618104303066,0.196016472644476,0.0410455763339996,172.855895996094,47.9997711181641,48.0011177062988,299.684539794922,299.684539794922,,,57.2282943725586,0,1,,,,,,1,1,1,48.0002098083496,0,48.0003242492676,,,,,,,,,,,,,,,,,,,,,,,,,,,,,,,,,
,3768644568.57469,48.0001697540283,299.684539794922,,,5,,,,25.0300001353025,,,,,0.000681223133965178,9.63424362237479E-8,-0.00502653491896599,0.000104205904825946,0.000681120393068523,9.63279060238911E-8,0.000681120390447408,6.51336846759022E-8,-5.97544088671546E-8,7.09694906244067E-8,1.00015084102268,10.005763053894,2,20,10,5,2.22841489581802,0.196116508743431,0.0410455763339996,172.855895996094,47.9996948242188,48.0010833740234,299.684539794922,299.684539794922,,,57.3029174804687,0,1,,,,,,1,1,1,48.0006370544434,0,48.0002212524414,,,,,,,,,,,,,,,,,,,,,,,,,,,,,,,,,
,3768644773.70101,47.9994564056396,299.684539794922,,,5,,,,25.0300001353025,,,,,0.000681395474222358,1.21377557829605E-7,-0.00612464066965845,0.000106824321374959,0.000681292729574541,1.21359255837731E-7,0.000681292725682121,9.71264085292884E-8,-7.2826885104086E-8,7.27635193190213E-8,1.00015080837261,10.005763053894,2,20,10,5,2.22898241344648,0.196123409291857,0.0410455763339996,172.855895996094,47.9989776611328,48.0004043579102,299.684539794922,299.684539794922,,,57.3402290344238,0,1,,,,,,1,1,1,47.999397277832,0,47.999702029758,,,,,,,,,,,,,,,,,,,,,,,,,,,,,,,,,
,3768644982.461,48.0004005432129,299.684539794922,,,5,,,,25.0300001353025,,,,,0.000682143174689902,1.18344226403867E-7,-0.00824420485240651,0.000111710800496091,0.000682040366070606,1.18326390256018E-7,0.000682040359010156,9.05424613566796E-8,-9.81377777539432E-8,7.61787196170535E-8,1.00015073685431,10.005763053894,2,20,10,5,2.23143555494423,0.196256065035132,0.0410455763339996,172.855895996094,47.9993515014648,48.0005950927734,299.684539794922,299.684539794922,,,57.414852142334,0,1,,,,,,1,1,1,48.0002670288086,0,47.9999755410587,,,,,,,,,,,,,,,,,,,,,,,,,,,,,,,,,
,3768645187.49564,48.0013732910156,299.684539794922,,,5,,,,25.0300001353025,,,,,0.000682578712267458,1.31723955978608E-7,-0.0037998524689371,0.000162690710965922,0.000682475807625329,1.31704097453421E-7,0.000682475806124451,7.08451932649519E-8,-4.52617523093788E-8,1.11026698938912E-7,1.00015078137713,10.005763053894,2,20,10,5,2.23284505191992,0.196554564244988,0.0410455763339996,172.855895996094,47.9996681213379,48.0017356872559,299.684539794922,299.684539794922,,,57.4894752502441,0,1,,,,,,1,1,1,48.0017356872559,0,48.0006437301636,,,,,,,,,,,,,,,,,,,,,,,,,,,,,,,,,
,3768645392.5493,48.0009689331055,299.684539794922,,,5,,,,25.0300001353025,,,,,0.000683108985954566,9.58569658334346E-8,-0.00451233487302716,0.000110046862090179,0.000683006014007937,9.5842516340641E-8,0.00068300601188981,5.94746934612093E-8,-5.37902072107369E-8,7.51568278747928E-8,1.0001507628696,10.005763053894,2,20,10,5,2.23458212400502,0.196679475164679,0.0410455763339996,172.855895996094,47.9998970031738,48.001522064209,299.684539794922,299.684539794922,,,57.514347076416,0,1,,,,,,1,1,1,48.0014343261719,0,48.0005017448874,,,,,,,,,,,,,,,,,,,,,,,,,,,,,,,,,
,3768645599.7117,47.9993152618408,299.684539794922,,,5,,,,25.0300001353025,,,,,0.000683177709728801,1.23161240598637E-7,-0.000605737403340356,0.000155742144169195,0.000683074779116045,1.23142684574659E-7,0.000683074779077871,6.2028986747489E-8,-7.22154313105834E-9,1.06379159459613E-7,1.00015068718082,10.005763053894,2,20,10,5,2.23479351498086,0.196851649512709,0.0410455763339996,172.855895996094,47.9976654052734,48.0006523132324,299.684539794922,299.684539794922,,,57.5765342712402,0,1,,,,,,1,1,1,47.9986381530762,0,47.9986578623454,,,,,,,,,,,,,,,,,,,,,,,,,,,,,,,,,
,3768645808.45686,48.0009250640869,299.684539794922,,,5,,,,25.0300001353025,,,,,0.000683577663722188,1.29483148212886E-7,-0.00072959840089748,0.000127704368235021,0.000683474622499141,1.29463630164442E-7,0.000683474622443727,9.56283046352822E-8,-8.70329360824991E-9,8.72700343069544E-8,1.00015076086171,10.005763053894,2,20,10,5,2.2361022609607,0.196962049055932,0.0410455763339996,172.855895996094,47.9995040893555,48.0012130737305,299.684539794922,299.684539794922,,,57.6262817382812,0,1,,,,,,1,1,1,48.0008697509766,0,48.0003033806296,,,,,,,,,,,,,,,,,,,,,,,,,,,,,,,,,
,3768646015.23509,47.999927520752,299.684539794922,,,5,,,,25.0300001353025,,,,,0.000684012369950425,9.27840293349208E-8,-0.00510788777135751,8.75521015743678E-5,0.000683909215967411,9.27700368362373E-8,0.000683909213249684,7.08670004402463E-8,-6.09701368236683E-8,5.98677541185483E-8,1.00015082993562,10.005763053894,2,20,10,5,2.23753931469663,0.196916325798634,0.0410455763339996,172.855895996094,47.9991073608398,48.000316619873,299.684539794922,299.684539794922,,,57.6635932922363,0,1,,,,,,1,1,1,47.9996528625488,0,47.9998842127183,,,,,,,,,,,,,,,,,,,,,,,,,,,,,,,,,
,3768646221.30057,48.0001621246338,299.684539794922,,,5,,,,25.0300001353025,,,,,0.000684539704770865,9.75368826179927E-8,-0.00505144314330597,0.000108142206504486,0.000684436463913697,9.75221723078429E-8,0.000684436461253652,6.35069110988002E-8,-6.03428718060635E-8,7.40097718840539E-8,1.00015084067348,10.005763053894,2,20,10,5,2.23926413704674,0.197070339462875,0.0410455763339996,172.855895996094,47.9992980957031,48.0008354187012,299.684539794922,299.684539794922,,,57.7257804870605,0,1,,,,,,1,1,1,48.0004959106445,0,48.0000249077292,,,,,,,,,,,,,,,,,,,,,,,,,,,,,,,,,
,3768646426.61122,48.0007667541504,299.684539794922,,,5,,,,25.0300001353025,,,,,0.000684658136668773,9.49374284871312E-8,-0.00242780662835429,8.60430625919871E-5,0.000684554937536696,9.49231184837926E-8,0.00068455493692214,7.44471146506038E-8,-2.90067964595443E-8,5.88899443274316E-8,1.00015075361584,10.005763053894,2,20,10,5,2.23964252327357,0.197206988739153,0.0410455763339996,172.855895996094,48.000072479248,48.0009307861328,299.684539794922,299.684539794922,,,57.7630882263184,0,1,,,,,,1,1,1,48.0008773803711,0,48.0005015204935,,,,,,,,,,,,,,,,,,,,,,,,,,,,,,,,,
,3768646633.79817,47.9967479705811,299.684539794922,,,5,,,,25.0300001353025,,,,,0.00068533764005411,1.33072718706305E-7,0.00238936586863225,0.000147872493418616,0.000685234307310749,1.33052654480606E-7,0.00068523430671491,8.62413011357605E-8,2.85758476338693E-8,1.01318541455878E-7,1.00015079913872,10.005763053894,2,20,10,5,2.24184869754196,0.197591212450949,0.0410455763339996,172.855895996094,47.9956169128418,48.0026168823242,299.684539794922,299.684539794922,,,57.8128395080566,0,1,,,,,,1,1,1,47.9971694946289,0,47.9993226793077,,,,,,,,,,,,,,,,,,,,,,,,,,,,,,,,,
,3768646839.77986,48.0009593963623,299.684539794922,,,5,,,,25.0300001353025,,,,,0.000685462216538268,1.19512218309828E-7,-0.00559907451974073,0.000129076388691914,0.000685358890164436,1.1949420307303E-7,0.000685358886891969,8.03406649311636E-8,-6.69748369827781E-8,8.84547462066177E-8,1.00015076243311,10.005763053894,2,20,10,5,2.24228374076612,0.197314486299295,0.0410455763339996,172.855895996094,47.9998626708984,48.0014152526855,299.684539794922,299.684539794922,,,57.8874626159668,0,1,,,,,,1,1,1,48.0007209777832,0,48.0004244910346,,,,,,,,,,,,,,,,,,,,,,,,,,,,,,,,,
,3768647044.98426,48.000825881958,299.684539794922,,,5,,,,25.0300001353025,,,,,0.000685880105117051,1.2496128622685E-7,-0.000264098693260273,0.000137215219341318,0.000685776719940949,1.24942450362556E-7,0.000685776719933664,8.22047770060742E-8,-3.16101355358515E-9,9.40903318092847E-8,1.00015075632213,10.005763053894,2,20,10,5,2.24363234422463,0.197643690602499,0.0410455763339996,172.855895996094,47.9997482299805,48.0014419555664,299.684539794922,299.684539794922,,,57.9123344421387,0,1,,,,,,1,1,1,48.0005912780762,0,48.0003562503391,,,,,,,,,,,,,,,,,,,,,,,,,,,,,,,,,
,3768647251.70077,47.9979515075684,299.684539794922,,,5,,,,25.0300001353025,,,,,0.000686329475263768,1.17087155904883E-7,-0.00520120854312722,0.000127713417534708,0.000686225955179264,1.17069495476895E-7,0.000686225952351778,7.76268393166553E-8,-6.22943666361491E-8,8.76318468875385E-8,1.0001508542248,10.005763053894,2,20,10,5,2.24511934422557,0.197579733402428,0.0410455763339996,172.855895996094,47.9969100952148,48.0026626586914,299.684539794922,299.684539794922,,,57.9745216369629,0,1,,,,,,1,1,1,47.9981803894043,0,47.9998290118049,,,,,,,,,,,,,,,,,,,,,,,,,,,,,,,,,
,3768647457.73985,48.00022315979,299.684539794922,,,5,,,,25.0300001353025,,,,,0.000686677128299695,2.09563857270163E-7,-0.00748277283775334,0.000259600831233941,0.000686573563163033,2.09532250699006E-7,0.000686573557307897,1.10178768984472E-7,-8.96658364474928E-8,1.78225707876438E-7,1.00015084346707,10.005763053894,2,20,10,5,2.24626445675773,0.197590358983598,0.0410455763339996,172.855895996094,47.9992408752441,48.000415802002,299.684539794922,299.684539794922,,,58.0242691040039,0,1,,,,,,1,1,1,48.000114440918,0,47.9998797248392,,,,,,,,,,,,,,,,,,,,,,,,,,,,,,,,,
,3768647662.75005,48.0007190704346,299.684539794922,,,5,,,,25.0300001353025,,,,,0.000687035425721018,1.36939300061435E-7,-0.00904315708034797,0.000147815306569979,0.000686931869757036,1.36918659377281E-7,0.000686931861200883,9.18619439693502E-8,-1.0842042518158E-7,1.01528826132502E-7,1.00015075143335,10.005763053894,2,20,10,5,2.24744190583453,0.197632250143606,0.0410455763339996,172.855895996094,48.0000648498535,48.0010375976562,299.684539794922,299.684539794922,,,58.0864524841309,0,1,,,,,,1,1,1,48.0005722045898,0,48.000465604994,,,,,,,,,,,,,,,,,,,,,,,,,,,,,,,,,
,3768647868.87464,48.0005302429199,299.684539794922,,,5,,,,25.0300001353025,,,,,0.000687184815574784,1.19900057078402E-7,-0.00244597647145284,0.000133744368211482,0.00068708124303078,1.19881985733319E-7,0.000687081242404689,7.69984880544574E-8,-2.93317338240535E-8,9.18853815396732E-8,1.00015074279069,10.005763053894,2,20,10,5,2.2479078164751,0.197934057428044,0.0410455763339996,172.855895996094,47.9995994567871,48.0011978149414,299.684539794922,299.684539794922,,,58.111328125,0,1,,,,,,1,1,1,47.9999351501465,0,48.0000855922699,,,,,,,,,,,,,,,,,,,,,,,,,,,,,,,,,
,3768648075.37173,47.9995594024658,299.684539794922,,,5,,,,25.0300001353025,,,,,0.000687625843965003,1.37411753919616E-7,-0.00461802340335815,0.0001328844010688,0.000687522156626326,1.37391033553749E-7,0.000687522154393147,1.02625435432215E-7,-5.54140886671255E-8,9.13472282191183E-8,1.00015081308679,10.005763053894,2,20,10,5,2.24935800790689,0.197975820560031,0.0410455763339996,172.855895996094,47.9985275268555,48.000072479248,299.684539794922,299.684539794922,,,58.161075592041,0,1,,,,,,1,1,1,47.9993362426758,0,47.9995963152717,,,,,,,,,,,,,,,,,,,,,,,,,,,,,,,,,
,3768648279.61958,48.0006370544434,299.684539794922,,,5,,,,25.0300001353025,,,,,0.000687903855074193,1.08857002315325E-7,0.00229994445266701,9.44790742496906E-5,0.000687800091893983,1.08840582362646E-7,0.00068780009133984,8.73235216245815E-8,2.76093984393633E-8,6.49682610212179E-8,1.00015086241109,10.005763053894,2,20,10,5,2.25024350708902,0.198327554951457,0.0410455763339996,172.855895996094,47.9999694824219,48.0009117126465,299.684539794922,299.684539794922,,,58.2108268737793,0,1,,,,,,1,1,1,48.0009765625,0,48.000415802002,,,,,,,,,,,,,,,,,,,,,,,,,,,,,,,,,
,3768648485.58832,48.001335144043,299.684539794922,,,5,,,,25.0300001353025,,,,,0.000688019260792135,1.08266506287001E-7,-0.0114802926742046,0.000111316294987649,0.000687915537141193,1.08250184364133E-7,0.000687915523332081,7.65218281087032E-8,-1.37836882852185E-7,7.65670440710025E-8,1.00015077963113,10.005763053894,2,20,10,5,2.25066866034621,0.197819524266841,0.0410455763339996,172.855895996094,47.9996681213379,48.0018692016602,299.684539794922,299.684539794922,,,58.2481346130371,0,1,,,,,,1,1,1,48.0008010864258,0,48.0005048864028,,,,,,,,,,,,,,,,,,,,,,,,,,,,,,,,,
,3768648695.7792,47.9996948242188,299.684539794922,,,5,,,,25.0300001353025,,,,,0.000688429483640605,1.45799782398068E-7,-0.00426549811676757,0.000159853338838173,0.000688325670855035,1.45777796295052E-7,0.000688325668947563,9.56375901093933E-8,-5.12437717925181E-8,1.10020985501446E-7,1.00015081928506,10.005763053894,2,20,10,5,2.25198565045184,0.198221051082091,0.0410455763339996,172.855895996094,47.9990921020508,48.0001068115234,299.684539794922,299.684539794922,,,58.3103218078613,0,1,,,,,,1,1,1,48.0000076293945,0,47.9996346866383,,,,,,,,,,,,,,,,,,,,,,,,,,,,,,,,,
,3768648850.56551,48.0010452270508,299.684539794922,,,5,,,,25.0300001353025,,,,,0.000688686609930459,9.02058622672683E-8,-0.00312141733263083,8.90898483918993E-5,0.000688582794807833,9.01922643077351E-8,0.000688582793785989,6.61240898294704E-8,-3.75133087963413E-8,6.13371770232416E-8,1.00015076636159,10.005763053894,2,20,10,5,2.25282280054788,0.198340065951581,0.0410455763339996,172.855895996094,47.9996719360352,48.0011329650879,299.684539794922,299.684539794922,,,58.3476333618164,0,1,,,,,,1,1,1,48.0010185241699,0,48.0003787769991,,,,,,,,,,,,,,,,,,,,,,,,,,,,,,,,,