File: Experimental_Data/Fig3C/Lifetime_200Oe_50p5K.dat
[Header]
; MPMS3 Data File (default extension .dat)
; Copyright (c) 2007, Quantum Design, Inc. All rights reserved.
TITLE,200Oe_50p5K
FILEOPENTIME,3768352984.98249,05/30/2019,4:43 am
BYAPP,SQUID AC,0.9.1.0
INFO,MPMS3 Measurement Release 1.1.16 Build 347, MultiVu Release 2.3.3.2,APPNAME
INFO,0,MOMENT_UNITS
INFO,,SAMPLE_MATERIAL
INFO,,SAMPLE_COMMENT
INFO,,SAMPLE_MASS
INFO,,SAMPLE_VOLUME
INFO,,SAMPLE_MOLECULAR_WEIGHT
INFO,,SAMPLE_SIZE
INFO,,SAMPLE_SHAPE
INFO,Quartz,SAMPLE_HOLDER
INFO,Standard,SAMPLE_HOLDER_DETAIL
INFO,66.2,SAMPLE_OFFSET
DATATYPE,COMMENT,1
DATATYPE,TIME,2
STARTUPAXIS,X,2
STARTUPAXIS,Y1,5
FIELDGROUP, VSM,2,3,4,5,6,8,9,10,11,14,15
FIELDGROUP, DC, 2,3,4,14,56,57,58,59,60,61,62,63,64,65,66,67,68,69
FIELDGROUP, AC, 2,3,4,11,16,17,18,19,20,21,22,23,24,25,26,27,28,29,30
STARTUPGROUP, All
[Data]
Comment,Time Stamp (sec),Temperature (K),Magnetic Field (Oe),Moment (emu),M. Std. Err. (emu),Transport Action,Averaging Time (sec),Frequency (Hz),Peak Amplitude (mm),Center Position (mm),Lockin Signal' (V),Lockin Signal (V),Range,M. Quad. Signal (emu),AC Moment (emu),AC M. Std Err. (emu),AC Phase (deg),AC Phase Std. Err. (deg),AC Susceptibility (emu/Oe),AC Suscept. Std Err. (emu/Oe),AC X' (emu/Oe),AC X' Std Err. (emu/Oe),AC X'' (emu/Oe),AC X'' Std Err. (emu/Oe),AC Drive (Oe),AC Frequency (Hz),AC Averaging Time (sec),AC Cycles,AC Range,AC Measure Type,AC Signal' (V),AC Signal'' (V),AC Trim Coil Ratio,AC Trim Coil Phase,Min. Temperature (K),Max. Temperature (K),Min. Field (Oe),Max. Field (Oe),Mass (grams),Motor Lag (deg),Pressure (Torr),Measure Count,Measurement Number,SQUID Status (code),Motor Status (code),Measure Status (code),Motor Current (amps),Motor Temp. (C),Temp. Status (code),Field Status (code),Chamber Status (code),Chamber Temp (K),Redirection State,Average Temp (K),Rotation Angle (deg),Rotator state,DC Moment Fixed Ctr (emu),DC Moment Err Fixed Ctr (emu),DC Moment Free Ctr (emu),DC Moment Err Free Ctr (emu),DC Fixed Fit,DC Free Fit,DC Calculated Center (mm),DC Calculated Center Err (mm),DC Scan Length (mm),DC Scan Time (s),DC Number of Points,DC Squid Drift,DC Min V (V),DC Max V (V),DC Scans per Measure,Map 01,Map 02,Map 03,Map 04,Map 05,Map 06,Map 07,Map 08,Map 09,Map 10,Map 11,Map 12,Map 13,Map 14,Map 15,Map 16
,3768352989.58503,50.4790344238281,199.919204711914,,,5,,,,25.0300001353025,,,,,0.000580017224270772,1.23654519386982E-7,0.0614916255779479,0.000115995153420533,0.000579930293505881,1.23635986520193E-7,0.000579929959516667,1.03752846121319E-7,6.22399239992603E-7,6.72398994983428E-8,1.00014989864448,10.005763053894,2,20,10,5,1.89716885081184,0.168972244287281,0.0410455763339996,172.855895996094,50.4181137084961,50.4898567199707,199.919204711914,199.919204711914,,,20.6768569946289,0,1,,,,,,1,1,1,50.4761657714844,0,50.4513024224175,,,,,,,,,,,,,,,,,,,,,,,,,,,,,,,,,
,3768353196.97392,50.4992752075195,199.919204711914,,,5,,,,25.0300001353025,,,,,0.000599175148692143,1.29066075969816E-7,0.00618612174324085,0.000103908539106869,0.000599085066676964,1.29046671740118E-7,0.000599085063185158,1.13054202333131E-7,6.46821315865826E-8,6.22237159129951E-8,1.00015036598338,10.005763053894,2,20,10,5,1.95999977579959,0.1726614775937,0.0410455763339996,172.855895996094,50.4984664916992,50.4999046325684,199.919204711914,199.919204711914,,,20.880163192749,0,1,,,,,,1,1,1,50.4992790222168,0,50.4994280198041,,,,,,,,,,,,,,,,,,,,,,,,,,,,,,,,,
,3768353404.22375,50.5001125335693,199.919204711914,,,5,,,,25.0300001353025,,,,,0.000615248234336783,1.03083449939133E-7,0.012083667918513,7.89944491066286E-5,0.000615155712270321,1.03067948076187E-7,0.000615155698589651,9.09058651401331E-8,1.29736210124333E-7,4.85708307913254E-8,1.00015040430352,10.005763053894,2,20,10,5,2.01255920472278,0.177500336845734,0.0410455763339996,172.855895996094,50.4996147155762,50.5004463195801,199.919204711914,199.919204711914,,,20.9063167572021,0,1,,,,,,1,1,1,50.5001945495605,0,50.5000172783347,,,,,,,,,,,,,,,,,,,,,,,,,,,,,,,,,
,3768353610.61286,50.5008449554443,199.919204711914,,,5,,,,25.0300001353025,,,,,0.00062809440435822,1.64787950056982E-7,0.00546854061375424,0.000151854282354423,0.000627999929416161,1.64763163445406E-7,0.000627999926555758,1.34376520539117E-7,5.99388496573095E-8,9.53407088097108E-8,1.00015043782274,10.005763053894,2,20,10,5,2.05460165163637,0.180969265816412,0.0410455763339996,172.855895996094,50.4994506835937,50.5009460449219,199.919204711914,199.919204711914,,,20.8794555664062,0,1,,,,,,1,1,1,50.5008697509766,0,50.5002360624426,,,,,,,,,,,,,,,,,,,,,,,,,,,,,,,,,
,3768353815.82064,50.5010795593262,199.919204711914,,,5,,,,25.0300001353025,,,,,0.000637937949361061,1.50362432888735E-7,0.00927430721916434,0.000145521166991445,0.000637841986953026,1.50339814480232E-7,0.00063784197859698,1.18279984150708E-7,1.03245693988712E-7,9.28003511160323E-8,1.00015044855936,10.005763053894,2,20,10,5,2.08678931709099,0.183944042004304,0.0410455763339996,172.855895996094,50.4997520446777,50.5012550354004,199.919204711914,199.919204711914,,,20.86572265625,0,1,,,,,,1,1,1,50.5008544921875,0,50.5004061530618,,,,,,,,,,,,,,,,,,,,,,,,,,,,,,,,,
,3768354023.43895,50.5002193450928,199.919204711914,,,5,,,,25.0300001353025,,,,,0.000646227120718015,1.1036656378436E-7,0.0061479851063222,0.000126766471284284,0.000646129936836456,1.10349966135145E-7,0.000646129933116737,7.39564390028982E-8,6.93314106999712E-8,8.18996957017434E-8,1.00015040919174,10.005763053894,2,20,10,5,2.11391458573612,0.18621881102216,0.0410455763339996,172.855895996094,50.4996109008789,50.500732421875,199.919204711914,199.919204711914,,,20.813892364502,0,1,,,,,,1,1,1,50.5006065368652,0,50.5001629723443,,,,,,,,,,,,,,,,,,,,,,,,,,,,,,,,,
,3768354232.69554,50.4995193481445,199.919204711914,,,5,,,,25.0300001353025,,,,,0.000653135304359757,9.32567547490436E-8,0.0100241558873568,9.60870780833309E-5,0.000653037102497226,9.32427331719695E-8,0.000653037092502792,6.89784274061742E-8,1.14251795470731E-7,6.27390137151537E-8,1.00015037715645,10.005763053894,2,20,10,5,2.13649964596504,0.188354038898149,0.0410455763339996,172.855895996094,50.4987106323242,50.5004196166992,199.919204711914,199.919204711914,,,20.811429977417,0,1,,,,,,1,1,1,50.4989967346191,0,50.4992843204074,,,,,,,,,,,,,,,,,,,,,,,,,,,,,,,,,
,3768354439.95656,50.5013580322266,199.919204711914,,,5,,,,25.0300001353025,,,,,0.00065869045491767,1.2350132255795E-7,0.00468392260468509,0.000157757288677237,0.000658591437961255,1.234827573503E-7,0.000658591435760558,6.67401839092786E-8,5.38397652723874E-8,1.03892921869532E-7,1.00015034655889,10.005763053894,2,20,10,5,2.15468903958788,0.189755224163598,0.0410455763339996,172.855895996094,50.4999008178711,50.501880645752,199.919204711914,199.919204711914,,,20.8092994689941,0,1,,,,,,1,1,1,50.5011329650879,0,50.5006622738308,,,,,,,,,,,,,,,,,,,,,,,,,,,,,,,,,
,3768354647.76606,50.501371383667,199.919204711914,,,5,,,,25.0300001353025,,,,,0.000663340072678974,9.81090298447464E-8,0.0040577402306301,0.000125653498690163,0.000663240356368417,9.80942816471154E-8,0.000663240354705142,5.1747194321723E-8,4.69712969652392E-8,8.33349624809025E-8,1.00015034716992,10.005763053894,2,20,10,5,2.1699008222187,0.191070968600182,0.0410455763339996,172.855895996094,50.4999465942383,50.5015411376953,199.919204711914,199.919204711914,,,20.769847869873,0,1,,,,,,1,1,1,50.5012664794922,0,50.5007279339959,,,,,,,,,,,,,,,,,,,,,,,,,,,,,,,,,
,3768354855.98881,50.4998664855957,199.919204711914,,,5,,,,25.0300001353025,,,,,0.000667242377811203,8.34970915137916E-8,0.00716697035073111,7.31694394166602E-5,0.000667142044288942,8.34845360203625E-8,0.000667142039069618,6.77346641133408E-8,8.34509501277374E-8,4.88024900183188E-8,1.00015039304316,10.005763053894,2,20,10,5,2.18265550795738,0.192313454411434,0.0410455763339996,172.855895996094,50.4992408752441,50.5006408691406,199.919204711914,199.919204711914,,,20.7426433563232,0,1,,,,,,1,1,1,50.4994697570801,0,50.4997088114421,,,,,,,,,,,,,,,,,,,,,,,,,,,,,,,,,
,3768355062.42093,50.5003852844238,199.919204711914,,,5,,,,25.0300001353025,,,,,0.000670187655469923,1.390858359269E-7,0.00957578798760661,0.000174311007371759,0.000670086863157667,1.39064918228863E-7,0.000670086853799197,7.54792743457586E-8,1.11990966167787E-7,1.16798675618511E-7,1.00015041678594,10.005763053894,2,20,10,5,2.19228185522117,0.193254509928355,0.0410455763339996,172.855895996094,50.4998931884766,50.5007362365723,199.919204711914,199.919204711914,,,20.7030487060547,0,1,,,,,,1,1,1,50.5005683898926,0,50.5003045025994,,,,,,,,,,,,,,,,,,,,,,,,,,,,,,,,,
,3768355268.97614,50.4995613098145,199.919204711914,,,5,,,,25.0300001353025,,,,,0.000673043947559269,1.03992690104433E-7,0.00673837658995602,0.000121975484624745,0.000672942751049612,1.03977054131022E-7,0.000672942746395751,6.38326970899441E-8,7.91426822034035E-8,8.20768820557224E-8,1.00015037907682,10.005763053894,2,20,10,5,2.20163481255316,0.193969121607741,0.0410455763339996,172.855895996094,50.4988822937012,50.4998245239258,199.919204711914,199.919204711914,,,20.7012786865234,0,1,,,,,,1,1,1,50.4993667602539,0,50.4994388156467,,,,,,,,,,,,,,,,,,,,,,,,,,,,,,,,,
,3768355477.68088,50.5004844665527,199.919204711914,,,5,,,,25.0300001353025,,,,,0.000675619067664428,7.01628537952423E-8,0.00893125495970093,7.96590817754369E-5,0.000675517455433722,7.01523013931151E-8,0.000675517447226687,4.50130677378974E-8,1.05299529058617E-7,5.3806775814705E-8,1.000150421325,10.005763053894,2,20,10,5,2.21005099042097,0.194795844436097,0.0410455763339996,172.855895996094,50.4996376037598,50.5007095336914,199.919204711914,199.919204711914,,,20.6489028930664,0,1,,,,,,1,1,1,50.5004730224609,0,50.5002221001519,,,,,,,,,,,,,,,,,,,,,,,,,,,,,,,,,
,3768355682.87465,50.5006923675537,199.919204711914,,,5,,,,25.0300001353025,,,,,0.000677592003370223,1.04996582136741E-7,0.00653438966825881,8.10869784165062E-5,0.000677490087967492,1.04980789788395E-7,0.000677490083561561,8.94711698455329E-8,7.72654506001621E-8,5.49169918246337E-8,1.00015043083957,10.005763053894,2,20,10,5,2.21651292900156,0.195271960460414,0.0410455763339996,172.855895996094,50.4999618530273,50.5006637573242,199.919204711914,199.919204711914,,,20.6345138549805,0,1,,,,,,1,1,1,50.500789642334,0,50.5003682304831,,,,,,,,,,,,,,,,,,,,,,,,,,,,,,,,,
,3768355889.73698,50.5012798309326,199.919204711914,,,5,,,,25.0300001353025,,,,,0.000679582581920812,9.22779618821608E-8,0.00577806267110592,8.58419125872735E-5,0.000679480426808581,9.22640906238276E-8,0.000679480423353437,7.14967705499662E-8,6.85230311307425E-8,5.83170148375872E-8,1.00015034298002,10.005763053894,2,20,10,5,2.22302701822326,0.195816269759922,0.0410455763339996,172.855895996094,50.499828338623,50.5018882751465,199.919204711914,199.919204711914,,,20.5825443267822,0,1,,,,,,1,1,1,50.5010948181152,0,50.5005879121668,,,,,,,,,,,,,,,,,,,,,,,,,,,,,,,,,
,3768356098.98721,50.5005645751953,199.919204711914,,,5,,,,25.0300001353025,,,,,0.000680908934821492,8.35185582656789E-8,0.00525322941889073,7.58946246015558E-5,0.00068080652450606,8.35059968768367E-8,0.000680806521644511,6.56092862340728E-8,6.24205288503072E-8,5.16592012544694E-8,1.00015042499116,10.005763053894,2,20,10,5,2.22736753488553,0.196178046352386,0.0410455763339996,172.855895996094,50.5000343322754,50.5007057189941,199.919204711914,199.919204711914,,,20.5555744171143,0,1,,,,,,1,1,1,50.5006790161133,0,50.500388039483,,,,,,,,,,,,,,,,,,,,,,,,,,,,,,,,,
,3768356304.05373,50.4994640350342,199.919204711914,,,5,,,,25.0300001353025,,,,,0.000682717694082902,7.62183321725854E-8,0.0074684063854944,7.1869675243345E-5,0.000682615046101289,7.62068725926929E-8,0.000682615040302244,5.83225405410854E-8,8.89776977994835E-8,4.90506747679619E-8,1.00015037462505,10.005763053894,2,20,10,5,2.23327668332632,0.196785521021231,0.0410455763339996,172.855895996094,50.4988594055176,50.4999961853027,199.919204711914,199.919204711914,,,20.5407886505127,0,1,,,,,,1,1,1,50.4989891052246,0,50.4994969087489,,,,,,,,,,,,,,,,,,,,,,,,,,,,,,,,,
,3768356509.91985,50.5000228881836,199.919204711914,,,5,,,,25.0300001353025,,,,,0.000683990695054569,7.44136865294871E-8,0.00436169474534509,6.07307701419458E-5,0.000683887838186306,7.44024963790834E-8,0.000683887836204687,6.17388940017342E-8,5.20616005697324E-8,4.15215659011332E-8,1.00015040020091,10.005763053894,2,20,10,5,2.23745155606307,0.197031128560359,0.0410455763339996,172.855895996094,50.4990196228027,50.501220703125,199.919204711914,199.919204711914,,,20.5268001556396,0,1,,,,,,1,1,1,50.4992027282715,0,50.4998382992215,,,,,,,,,,,,,,,,,,,,,,,,,,,,,,,,,
,3768356716.68188,50.5000076293945,199.919204711914,,,5,,,,25.0300001353025,,,,,0.000685254092415109,1.30807358744201E-7,0.00578354120794255,0.000142156324228482,0.000685151046038583,1.30787688340929E-7,0.000685151042547994,8.72968870761627E-8,6.91604047518892E-8,9.73892854906308E-8,1.00015039950259,10.005763053894,2,20,10,5,2.24157944765267,0.197450689917541,0.0410455763339996,172.855895996094,50.4991264343262,50.5006904602051,199.919204711914,199.919204711914,,,20.4872379302979,0,1,,,,,,1,1,1,50.4995346069336,0,50.499906652114,,,,,,,,,,,,,,,,,,,,,,,,,,,,,,,,,
,3768356921.81834,50.5005512237549,199.919204711914,,,5,,,,25.0300001353025,,,,,0.000686509742969102,7.97921787317714E-8,0.0093651339868126,9.58435737709928E-5,0.000686406490698219,7.97801778479716E-8,0.000686406481528963,4.51362923664112E-8,1.12194803540724E-7,6.57844350045498E-8,1.00015042438013,10.005763053894,2,20,10,5,2.24567451886365,0.197952870533341,0.0410455763339996,172.855895996094,50.4996070861816,50.5009880065918,199.919204711914,199.919204711914,,,20.4731636047363,0,1,,,,,,1,1,1,50.5007209777832,0,50.500208013198,,,,,,,,,,,,,,,,,,,,,,,,,,,,,,,,,
,3768357127.03487,50.5005741119385,199.919204711914,,,5,,,,25.0300001353025,,,,,0.000687434401313836,8.51352177366161E-8,0.00947171692774962,7.36505854311891E-5,0.000687331009252859,8.51224131612172E-8,0.000687330999861075,6.84427274074142E-8,1.13624507441581E-7,5.06104563052276E-8,1.00015042542761,10.005763053894,2,20,10,5,2.24869884380736,0.198223675908371,0.0410455763339996,172.855895996094,50.4994316101074,50.5007095336914,199.919204711914,199.919204711914,,,20.4582195281982,0,1,,,,,,1,1,1,50.5007095336914,0,50.5000594643986,,,,,,,,,,,,,,,,,,,,,,,,,,,,,,,,,
,3768357334.63125,50.4997215270996,199.919204711914,,,5,,,,25.0300001353025,,,,,0.000688298416986712,1.20160668725187E-7,0.00647317164507033,0.000105518825649349,0.000688194921823623,1.20142600910849E-7,0.000688194917431541,9.57248253761959E-8,7.77509946214451E-8,7.26016691290252E-8,1.00015038640915,10.005763053894,2,20,10,5,2.25153554939748,0.198354989121374,0.0410455763339996,172.855895996094,50.4991760253906,50.5003471374512,199.919204711914,199.919204711914,,,20.4312553405762,0,1,,,,,,1,1,1,50.4994506835937,0,50.4998817443848,,,,,,,,,,,,,,,,,,,,,,,,,,,,,,,,,
,3768357539.71445,50.5006618499756,199.919204711914,,,5,,,,25.0300001353025,,,,,0.00068929037575975,9.6167318999577E-8,0.00340422186418987,6.7364342047969E-5,0.000689186701788123,9.61528547791962E-8,0.000689186700571665,8.42123150914263E-8,4.09479451592063E-8,4.64075152225534E-8,1.00015042944293,10.005763053894,2,20,10,5,2.25479104426167,0.198520074063817,0.0410455763339996,172.855895996094,50.5000038146973,50.5011253356934,199.919204711914,199.919204711914,,,20.4162349700928,0,1,,,,,,1,1,1,50.501033782959,0,50.5004595588235,,,,,,,,,,,,,,,,,,,,,,,,,,,,,,,,,
,3768357747.47971,50.4997940063477,199.919204711914,,,5,,,,25.0300001353025,,,,,0.000690048745828248,9.43505879759427E-8,0.00391136450095164,8.17653911643748E-5,0.000689944985190862,9.43364007504673E-8,0.000689944983583197,7.56192809655557E-8,4.70999145752596E-8,5.64010713799401E-8,1.00015038972616,10.005763053894,2,20,10,5,2.25727004765568,0.198758473680942,0.0410455763339996,172.855895996094,50.4995536804199,50.5003967285156,199.919204711914,199.919204711914,,,20.3777389526367,0,1,,,,,,1,1,1,50.4998245239258,0,50.4999251365662,,,,,,,,,,,,,,,,,,,,,,,,,,,,,,,,,
,3768357952.58523,50.500358581543,199.919204711914,,,5,,,,25.0300001353025,,,,,0.000690863809945231,1.38107775275283E-7,0.0105764748196968,0.000171897879179844,0.000690759908904026,1.38087004840585E-7,0.000690759897135183,7.0495986647099E-8,1.27510347246788E-7,1.18736417212647E-7,1.00015041556388,10.005763053894,2,20,10,5,2.25991310120358,0.199256131877739,0.0410455763339996,172.855895996094,50.4997863769531,50.5005111694336,199.919204711914,199.919204711914,,,20.3757343292236,0,1,,,,,,1,1,1,50.500358581543,0,50.5001420413747,,,,,,,,,,,,,,,,,,,,,,,,,,,,,,,,,
,3768358157.9142,50.5007038116455,199.919204711914,,,5,,,,25.0300001353025,,,,,0.000691567746373279,7.17912752866525E-8,0.00583704562812315,7.20799088498324E-5,0.000691463728541919,7.17804772516009E-8,0.000691463724953689,5.16623290017352E-8,7.04433269083672E-8,4.98341316427212E-8,1.0001504313633,10.005763053894,2,20,10,5,2.26223226800453,0.19927202950186,0.0410455763339996,172.855895996094,50.4998893737793,50.5011825561523,199.919204711914,199.919204711914,,,20.3483467102051,0,1,,,,,,1,1,1,50.5005683898926,0,50.5004666646322,,,,,,,,,,,,,,,,,,,,,,,,,,,,,,,,,
,3768358366.50306,50.5006923675537,199.919204711914,,,5,,,,25.0300001353025,,,,,0.000692187820099851,6.71698333291539E-8,0.00451898367150694,6.92199088076282E-5,0.000692083709366401,6.71597304345196E-8,0.000692083707213793,4.70742099656792E-8,5.45854337837585E-8,4.7900398204446E-8,1.00015043083957,10.005763053894,2,20,10,5,2.26426521925521,0.199398611959768,0.0410455763339996,172.855895996094,50.4994735717773,50.5007781982422,199.919204711914,199.919204711914,,,20.3227119445801,0,1,,,,,,1,1,1,50.5007400512695,0,50.5001616226999,,,,,,,,,,,,,,,,,,,,,,,,,,,,,,,,,
,3768358574.92078,50.5003967285156,199.919204711914,,,5,,,,25.0300001353025,,,,,0.000692911772274765,1.06847687450597E-7,0.00491644900578958,9.67405498251444E-5,0.000692807562025162,1.0683161812601E-7,0.000692807559474573,8.32026552410322E-8,5.94485854680525E-8,6.70097962410246E-8,1.00015041730968,10.005763053894,2,20,10,5,2.26663200631542,0.19962288555384,0.0410455763339996,172.855895996094,50.4995651245117,50.5009078979492,199.919204711914,199.919204711914,,,20.3322219848633,0,1,,,,,,1,1,1,50.5005149841309,0,50.5002035253188,,,,,,,,,,,,,,,,,,,,,,,,,,,,,,,,,
,3768358781.09498,50.5004329681396,199.919204711914,,,5,,,,25.0300001353025,,,,,0.000693535782963111,8.53251360906887E-8,0.00559219843942849,7.88418847967945E-5,0.000693431477715731,8.5312303502023E-8,0.000693431474412846,6.5500261896436E-8,6.76804898079846E-8,5.46617308573335E-8,1.00015041896818,10.005763053894,2,20,10,5,2.2686708943498,0.199829417506317,0.0410455763339996,172.855895996094,50.4994468688965,50.5010223388672,199.919204711914,199.919204711914,,,20.2814083099365,0,1,,,,,,1,1,1,50.4999237060547,0,50.5000298023224,,,,,,,,,,,,,,,,,,,,,,,,,,,,,,,,,
,3768358986.08676,50.5000877380371,199.919204711914,,,5,,,,25.0300001353025,,,,,0.000694082602892615,9.30472924148452E-8,0.00487712675819996,7.91616712428908E-5,0.000693978226368321,9.30332999117385E-8,0.000693978223854127,7.50905132095598E-8,5.90727589729175E-8,5.49236717490047E-8,1.00015040316876,10.005763053894,2,20,10,5,2.27046212901253,0.199958637380311,0.0410455763339996,172.855895996094,50.4995307922363,50.5002670288086,199.919204711914,199.919204711914,,,20.2794284820557,0,1,,,,,,1,1,1,50.4999084472656,0,50.4998505536248,,,,,,,,,,,,,,,,,,,,,,,,,,,,,,,,,
,3768359192.60052,50.5013904571533,199.919204711914,,,5,,,,25.0300001353025,,,,,0.000694845131571253,9.51821800800186E-8,0.00747644384057544,9.17297678202746E-5,0.000694740598964097,9.51678608583871E-8,0.000694740593049331,7.06883771500909E-8,9.0655701018892E-8,6.37187184134131E-8,1.00015046278757,10.005763053894,2,20,10,5,2.27294740657382,0.200281425927453,0.0410455763339996,172.855895996094,50.4997749328613,50.5015029907227,199.919204711914,199.919204711914,,,20.2650203704834,0,1,,,,,,1,1,1,50.501277923584,0,50.5005499895881,,,,,,,,,,,,,,,,,,,,,,,,,,,,,,,,,
,3768359400.24949,50.5002174377441,199.919204711914,,,5,,,,25.0300001353025,,,,,0.000695253266497468,1.27790159037359E-7,0.00501116259818524,0.000161208501343102,0.000695148709802567,1.2777094112453E-7,0.000695148707143805,6.13828736123093E-8,6.07986005234957E-8,1.12060502510667E-7,1.00015040910445,10.005763053894,2,20,10,5,2.27429110000041,0.200301214956378,0.0410455763339996,172.855895996094,50.4996452331543,50.5005836486816,199.919204711914,199.919204711914,,,20.2388248443604,0,1,,,,,,1,1,1,50.4998931884766,0,50.5001613392549,,,,,,,,,,,,,,,,,,,,,,,,,,,,,,,,,
,3768359606.93101,50.5009689331055,199.919204711914,,,5,,,,25.0300001353025,,,,,0.000695638763744353,1.03470864013239E-7,0.00580582514060701,7.60571711908652E-5,0.000695534204955479,1.03455311705362E-7,0.000695534201384633,8.89188730911196E-8,7.04790126024907E-8,5.28813344031613E-8,1.00015032875181,10.005763053894,2,20,10,5,2.2755493472272,0.200443833128179,0.0410455763339996,172.855895996094,50.4999542236328,50.501148223877,199.919204711914,199.919204711914,,,20.2362995147705,0,1,,,,,,1,1,1,50.5008850097656,0,50.5004952374627,,,,,,,,,,,,,,,,,,,,,,,,,,,,,,,,,
,3768359814.81783,50.500732421875,199.919204711914,,,5,,,,25.0300001353025,,,,,0.000696197638102852,8.72983251724288E-8,0.00880196543249134,0.000108152996823304,0.000696093002845038,8.72852046413306E-8,0.000696092994631101,4.41736217447759E-8,1.06936088082065E-7,7.52821233177467E-8,1.0001503179279,10.005763053894,2,20,10,5,2.27736702417224,0.200723960770835,0.0410455763339996,172.855895996094,50.5,50.5011520385742,199.919204711914,199.919204711914,,,20.2338676452637,0,1,,,,,,1,1,1,50.5003128051758,0,50.5004035101997,,,,,,,,,,,,,,,,,,,,,,,,,,,,,,,,,
,3768360020.79119,50.5009212493897,199.919204711914,,,5,,,,25.0300001353025,,,,,0.00069661776416791,9.70633969285366E-8,0.00846579737323694,8.0986990937435E-5,0.000696512979839782,9.70487967799958E-8,0.0006965129722367,7.89819503002845E-8,1.02913997921109E-7,5.63943302399126E-8,1.00015044131432,10.005763053894,2,20,10,5,2.27874249817615,0.200831717260101,0.0410455763339996,172.855895996094,50.5002861022949,50.5011901855469,199.919204711914,199.919204711914,,,20.195972442627,0,1,,,,,,1,1,1,50.5008850097656,0,50.5006983139936,,,,,,,,,,,,,,,,,,,,,,,,,,,,,,,,,
,3768360226.98431,50.5002784729004,199.919204711914,,,5,,,,25.0300001353025,,,,,0.000697034863438224,8.40736238263114E-8,0.00934666869622003,9.9306184564129E-5,0.000696930036868801,8.40609800547773E-8,0.000696930027595644,4.7715543537555E-8,1.13690295961131E-7,6.92060349441099E-8,1.00015041189772,10.005763053894,2,20,10,5,2.28010380335403,0.200987021340676,0.0410455763339996,172.855895996094,50.4994316101074,50.500545501709,199.919204711914,199.919204711914,,,20.1818923950195,0,1,,,,,,1,1,1,50.5004196166992,0,50.4999881071203,,,,,,,,,,,,,,,,,,,,,,,,,,,,,,,,,
,3768360438.00048,50.5001411437988,199.919204711914,,,5,,,,25.0300001353025,,,,,0.000697480376766622,6.94002999218052E-8,0.0109279535631961,7.16385166232642E-5,0.000697375487579015,6.93898632968894E-8,0.000697375474894639,4.81623680981599E-8,1.33009568295163E-7,4.99533725341777E-8,1.00015040561287,10.005763053894,2,20,10,5,2.28155559167284,0.201178451982719,0.0410455763339996,172.855895996094,50.4995651245117,50.5002784729004,199.919204711914,199.919204711914,,,20.1793632507324,0,1,,,,,,1,1,1,50.500171661377,0,50.4999367209042,,,,,,,,,,,,,,,,,,,,,,,,,,,,,,,,,
,3768360644.62917,50.5010147094727,199.919204711914,,,5,,,,25.0300001353025,,,,,0.000697837247977388,8.42996593272168E-8,0.00935278535574824,7.1154771869206E-5,0.000697732277232223,8.42869787228461E-8,0.000697732267936237,6.81224218640553E-8,1.13895652545564E-7,4.96349717598508E-8,1.00015044559151,10.005763053894,2,20,10,5,2.28272850018302,0.201218627120204,0.0410455763339996,172.855895996094,50.499626159668,50.501148223877,199.919204711914,199.919204711914,,,20.1538753509521,0,1,,,,,,1,1,1,50.5009880065918,0,50.5004263485179,,,,,,,,,,,,,,,,,,,,,,,,,,,,,,,,,
,3768360849.62504,50.4996643066406,199.919204711914,,,5,,,,25.0300001353025,,,,,0.000698256771087934,1.35205518613713E-7,0.00451084825116244,0.000170693787061694,0.000698151780376883,1.35185188952584E-7,0.000698151778213213,6.38304710207804E-8,5.49648990042383E-8,1.19166716332251E-7,1.00015038379046,10.005763053894,2,20,10,5,2.28411782830371,0.201146574608115,0.0410455763339996,172.855895996094,50.4995346069336,50.5004768371582,199.919204711914,199.919204711914,,,20.1267509460449,0,1,,,,,,1,1,1,50.4997291564941,0,50.4999181959364,,,,,,,,,,,,,,,,,,,,,,,,,,,,,,,,,
,3768361057.2148,50.4994411468506,199.919204711914,,,5,,,,25.0300001353025,,,,,0.000698627652248064,1.27331648153674E-7,0.00270924628358049,0.000127216976380795,0.000698522612903743,1.2731250371702E-7,0.000698522612122831,9.1179405169569E-8,3.30298288701887E-8,8.88526289741608E-8,1.00015037357758,10.005763053894,2,20,10,5,2.28533737109387,0.201181557154037,0.0410455763339996,172.855895996094,50.4988288879395,50.4998397827148,199.919204711914,199.919204711914,,,20.1124629974365,0,1,,,,,,1,1,1,50.4989776611328,0,50.4993757360122,,,,,,,,,,,,,,,,,,,,,,,,,,,,,,,,,
,3768361263.74697,50.5003299713135,199.919204711914,,,5,,,,25.0300001353025,,,,,0.000698900373363583,7.97473650620132E-8,0.00590468668146826,7.6483380276721E-5,0.000698795264594784,7.97353717255147E-8,0.000698795260883977,5.91784624171379E-8,7.20152011140728E-8,5.34381800789417E-8,1.00015041425454,10.005763053894,2,20,10,5,2.28621826364984,0.201387591115486,0.0410455763339996,172.855895996094,50.4997863769531,50.5009307861328,199.919204711914,199.919204711914,,,20.0859470367432,0,1,,,,,,1,1,1,50.5005035400391,0,50.5001851250144,,,,,,,,,,,,,,,,,,,,,,,,,,,,,,,,,
,3768361468.94162,50.5005912780762,199.919204711914,,,5,,,,25.0300001353025,,,,,0.000699348589698268,1.11449258925173E-7,0.00188493289010072,0.000108426651193125,0.000699243405160713,1.11432496556687E-7,0.000699243404782319,8.16740843783823E-8,2.30039089010868E-8,7.58059709377094E-8,1.00015042621322,10.005763053894,2,20,10,5,2.28769858549255,0.201356244577037,0.0410455763339996,172.855895996094,50.4998588562012,50.5007171630859,199.919204711914,199.919204711914,,,20.0483512878418,0,1,,,,,,1,1,1,50.5005035400391,0,50.500244365019,,,,,,,,,,,,,,,,,,,,,,,,,,,,,,,,,
,3768361674.91076,50.5004806518555,199.919204711914,,,5,,,,25.0300001353025,,,,,0.000699528357896008,7.2227077703279E-8,0.00413832770939226,7.96811977960373E-5,0.000699423149861176,7.22162148571613E-8,0.0006994231480368,4.59319721504091E-8,5.05175463837335E-8,5.57264355819546E-8,1.00015042115042,10.005763053894,2,20,10,5,2.28827871753068,0.201497999715213,0.0410455763339996,172.855895996094,50.4999847412109,50.5006065368652,199.919204711914,199.919204711914,,,20.021656036377,0,1,,,,,,1,1,1,50.5004768371582,0,50.500301361084,,,,,,,,,,,,,,,,,,,,,,,,,,,,,,,,,
,3768361882.41882,50.5001239776611,199.919204711914,,,5,,,,25.0300001353025,,,,,0.000699901493531711,1.42227643446411E-7,0.00115836200166086,0.000107791363922496,0.000699796240798996,1.42206254939202E-7,0.00069979624065598,1.20566094665355E-7,1.41479421535117E-8,7.54084594788809E-8,1.00015040482726,10.005763053894,2,20,10,5,2.28950979121895,0.201486405554189,0.0410455763339996,172.855895996094,50.4991798400879,50.5005378723145,199.919204711914,199.919204711914,,,19.9954376220703,0,1,,,,,,1,1,1,50.4998321533203,0,50.4998370899874,,,,,,,,,,,,,,,,,,,,,,,,,,,,,,,,,
,3768362090.19877,50.4997520446777,199.919204711914,,,5,,,,25.0300001353025,,,,,0.000700021643528237,8.34033512046165E-8,-0.000143635235184014,7.05262920768336E-5,0.000699916384638919,8.33908102436413E-8,0.00069991638463672,6.72194931839398E-8,-1.7546258270855E-9,4.93514636985091E-8,1.00015038780578,10.005763053894,2,20,10,5,2.28990740328597,0.201468958363128,0.0410455763339996,172.855895996094,50.4993209838867,50.5001983642578,199.919204711914,199.919204711914,,,19.9805469512939,0,1,,,,,,1,1,1,50.4997329711914,0,50.4997486787684,,,,,,,,,,,,,,,,,,,,,,,,,,,,,,,,,
,3768362296.80261,50.5007915496826,199.919204711914,,,5,,,,25.0300001353025,,,,,0.00070056871278801,9.61136955695365E-8,0.00245942334720439,9.76423725636268E-5,0.000700463338320496,9.60992388441553E-8,0.000700463337675174,6.75151759522409E-8,3.00674133808366E-8,6.83868753677485E-8,1.00015043537863,10.005763053894,2,20,10,5,2.29168781126914,0.201730519505352,0.0410455763339996,172.855895996094,50.4997406005859,50.5010833740234,199.919204711914,199.919204711914,,,19.9421463012695,0,1,,,,,,1,1,1,50.5007095336914,0,50.500462214152,,,,,,,,,,,,,,,,,,,,,,,,,,,,,,,,,
,3768362502.68658,50.5010776519775,199.919204711914,,,5,,,,25.0300001353025,,,,,0.000700908673531354,1.61667426601956E-7,0.00203992240095552,0.000129863287212582,0.000700803319156266,1.616431261883E-7,0.000700803318712097,1.33605058826947E-7,2.49509545250607E-8,9.09845508851623E-8,1.00015033372732,10.005763053894,2,20,10,5,2.29280136257825,0.201811623123518,0.0410455763339996,172.855895996094,50.4996376037598,50.5013046264648,199.919204711914,199.919204711914,,,19.9293060302734,0,1,,,,,,1,1,1,50.5012016296387,0,50.5004644954906,,,,,,,,,,,,,,,,,,,,,,,,,,,,,,,,,
,3768362708.77397,50.5012264251709,199.919204711914,,,5,,,,25.0300001353025,,,,,0.000701192103373354,1.22625797142871E-7,0.0024297592461533,0.000164452693128307,0.000701086621188996,1.22607350219582E-7,0.000701086620558587,4.17109303948289E-8,2.97311898739209E-8,1.15294234953293E-7,1.00015045528066,10.005763053894,2,20,10,5,2.29372713998717,0.201908837980386,0.0410455763339996,172.855895996094,50.5000953674316,50.5015068054199,199.919204711914,199.919204711914,,,19.891580581665,0,1,,,,,,1,1,1,50.5009460449219,0,50.5005564970129,,,,,,,,,,,,,,,,,,,,,,,,,,,,,,,,,
,3768362919.01101,50.4990215301514,199.919204711914,,,5,,,,25.0300001353025,,,,,0.000701592241820024,1.03057629001793E-7,0.00451943104067265,6.53347722941001E-5,0.000701486770215916,1.03042136165928E-7,0.00070148676803363,9.23001455131083E-8,5.53325412026827E-8,4.58079137693115E-8,1.00015035437386,10.005763053894,2,20,10,5,2.29502869533224,0.202107770129421,0.0410455763339996,172.855895996094,50.4978523254395,50.5007858276367,199.919204711914,199.919204711914,,,19.8767337799072,0,1,,,,,,1,1,1,50.498664855957,0,50.4996402263641,,,,,,,,,,,,,,,,,,,,,,,,,,,,,,,,,
,3768363125.64289,50.5005130767822,199.919204711914,,,5,,,,25.0300001353025,,,,,0.000701780532437773,9.47497161713491E-8,0.00491180993348639,0.000100605762660191,0.000701674984638131,9.47354658130159E-8,0.00070167498205977,6.31858242606658E-8,6.01526706625236E-8,7.05858349480217E-8,1.00015042263434,10.005763053894,2,20,10,5,2.29564324256567,0.202177723268082,0.0410455763339996,172.855895996094,50.4997367858887,50.5012435913086,199.919204711914,199.919204711914,,,19.8507919311523,0,1,,,,,,1,1,1,50.5011367797852,0,50.5002508724437,,,,,,,,,,,,,,,,,,,,,,,,,,,,,,,,,
,3768363330.7941,50.4998989105225,199.919204711914,,,5,,,,25.0300001353025,,,,,0.000702090388870616,1.35950973607223E-7,0.00374535664826059,7.57632302000158E-5,0.000701984814196464,1.35930530399387E-7,0.000701984812696646,1.25109768826614E-7,4.58879085213585E-8,5.31474819611424E-8,1.00015039452709,10.005763053894,2,20,10,5,2.29666095238205,0.202220240154427,0.0410455763339996,172.855895996094,50.4992218017578,50.5002975463867,199.919204711914,199.919204711914,,,19.8249835968018,0,1,,,,,,1,1,1,50.4995002746582,0,50.4996867460363,,,,,,,,,,,,,,,,,,,,,,,,,,,,,,,,,
,3768363538.44804,50.4999656677246,199.919204711914,,,5,,,,25.0300001353025,,,,,0.000702281211301077,1.00216869727419E-7,0.00426303472013867,9.24005910531315E-5,0.000702175605787672,1.00201799619022E-7,0.000702175603844066,7.63690513601485E-8,5.22446681026807E-8,6.48703988059401E-8,1.00015039758222,10.005763053894,2,20,10,5,2.297283338515,0.202295956779598,0.0410455763339996,172.855895996094,50.4994087219238,50.5004005432129,199.919204711914,199.919204711914,,,19.7876796722412,0,1,,,,,,1,1,1,50.4999313354492,0,50.4999075496898,,,,,,,,,,,,,,,,,,,,,,,,,,,,,,,,,
,3768363743.62725,50.5014495849609,199.919204711914,,,5,,,,25.0300001353025,,,,,0.000702623615242101,1.124408651289E-7,0.00149975803662983,0.000130569434499013,0.000702517991136092,1.12423962102016E-7,0.00070251799089542,6.50094338897144E-8,1.83889112237754E-8,9.17219753388159E-8,1.00015035074879,10.005763053894,2,20,10,5,2.29841315992162,0.202283735281591,0.0410455763339996,172.855895996094,50.4997329711914,50.5017204284668,199.919204711914,199.919204711914,,,19.7716846466064,0,1,,,,,,1,1,1,50.5011787414551,0,50.5005367503447,,,,,,,,,,,,,,,,,,,,,,,,,,,,,,,,,
,3768363948.71789,50.4998435974121,199.919204711914,,,5,,,,25.0300001353025,,,,,0.000702729884844748,1.25315849755314E-7,0.00172397073459241,0.000105628940040324,0.000702624215786718,1.25297006088514E-7,0.000702624215468659,1.00963358952151E-7,2.1141235803815E-8,7.42006730686748E-8,1.00015039199569,10.005763053894,2,20,10,5,2.29875999539479,0.202323331626317,0.0410455763339996,172.855895996094,50.4991111755371,50.5002250671387,199.919204711914,199.919204711914,,,19.7338752746582,0,1,,,,,,1,1,1,50.4995536804199,0,50.4996432136087,,,,,,,,,,,,,,,,,,,,,,,,,,,,,,,,,
,3768364157.92798,50.5006923675537,199.919204711914,,,5,,,,25.0300001353025,,,,,0.000703043051490739,1.02056427426185E-7,0.00180497001930569,9.44132852028197E-5,0.000702937308041328,1.02041077301256E-7,0.000702937307692524,7.75197605862807E-8,2.2144401857147E-8,6.63556190193922E-8,1.00015043083957,10.005763053894,2,20,10,5,2.29978413591259,0.202416742375317,0.0410455763339996,172.855895996094,50.4999389648438,50.5008125305176,199.919204711914,199.919204711914,,,19.7086601257324,0,1,,,,,,1,1,1,50.5007667541504,0,50.50040102005,,,,,,,,,,,,,,,,,,,,,,,,,,,,,,,,,
,3768364362.33447,50.5005722045898,199.919204711914,,,5,,,,25.0300001353025,,,,,0.000703357439416607,1.21193686175302E-7,0.00520543340204949,0.000136583627138561,0.000703251652547442,1.21175458315746E-7,0.000703251649645095,7.3882536080531E-8,6.38917851941452E-8,9.60461480765373E-8,1.00015042534032,10.005763053894,2,20,10,5,2.30080053440612,0.202643810344216,0.0410455763339996,172.855895996094,50.4998741149902,50.5010871887207,199.919204711914,199.919204711914,,,19.671106338501,0,1,,,,,,1,1,1,50.500846862793,0,50.5002762289608,,,,,,,,,,,,,,,,,,,,,,,,,,,,,,,,,
,3768364569.97943,50.500057220459,199.919204711914,,,5,,,,25.0300001353025,,,,,0.000703827222926375,1.22300601984385E-7,0.00718776693038414,0.000103864137632492,0.000703721381983443,1.22282210523223E-7,0.000703721376445947,9.80459786688501E-8,8.82819870388966E-8,7.30747909837117E-8,1.00015040177212,10.005763053894,2,20,10,5,2.30233025778246,0.20285881994807,0.0410455763339996,172.855895996094,50.499382019043,50.5003890991211,199.919204711914,199.919204711914,,,19.6447124481201,0,1,,,,,,1,1,1,50.4997825622559,0,50.4997653961182,,,,,,,,,,,,,,,,,,,,,,,,,,,,,,,,,
,3768364777.57572,50.5003852844238,199.919204711914,,,5,,,,25.0300001353025,,,,,0.00070391672978602,1.60065377640971E-7,0.00341251850642266,0.000164527119068819,0.000703810864817826,1.60041304742294E-7,0.000703810863569493,1.10487294819473E-7,4.1918752484095E-8,1.15783318777321E-7,1.00015041678594,10.005763053894,2,20,10,5,2.30263641223678,0.202732894433998,0.0410455763339996,172.855895996094,50.4998970031738,50.5005493164063,199.919204711914,199.919204711914,,,19.6419448852539,0,1,,,,,,1,1,1,50.5003128051758,0,50.5001771714952,,,,,,,,,,,,,,,,,,,,,,,,,,,,,,,,,
,3768364985.09939,50.5010585784912,199.919204711914,,,5,,,,25.0300001353025,,,,,0.000703997202118151,1.30185739501952E-7,0.00580990116634705,0.000111352797486892,0.000703891303361481,1.30166156316241E-7,0.000703891299742654,1.0393491448215E-7,7.13759186475387E-8,7.83630129699737E-8,1.00015044759917,10.005763053894,2,20,10,5,2.3028911659446,0.202852426792925,0.0410455763339996,172.855895996094,50.4998168945313,50.5011329650879,199.919204711914,199.919204711914,,,19.615701675415,0,1,,,,,,1,1,1,50.5009918212891,0,50.5004223094267,,,,,,,,,,,,,,,,,,,,,,,,,,,,,,,,,
,3768365192.00609,50.500114440918,199.919204711914,,,5,,,,25.0300001353025,,,,,0.000703906570064789,1.48936676575607E-7,-0.000150581423096874,0.000155636695421541,0.000703800715346944,1.48914279214158E-7,0.000703800715344514,1.00893544006593E-7,-1.84968795597275E-9,1.0952604864443E-7,1.00015040439081,10.005763053894,2,20,10,5,2.30261578072035,0.202586775765201,0.0410455763339996,172.855895996094,50.4992408752441,50.5003471374512,199.919204711914,199.919204711914,,,19.5896339416504,0,1,,,,,,1,1,1,50.4998550415039,0,50.4997142992522,,,,,,,,,,,,,,,,,,,,,,,,,,,,,,,,,
,3768365397.94611,50.5010414123535,199.919204711914,,,5,,,,25.0300001353025,,,,,0.000704136287531934,1.22971345923561E-7,-0.000891466884106684,0.000113532085815646,0.000704030449177997,1.22952862165425E-7,0.00070403044909278,9.34381694694433E-8,-1.09540324986121E-8,7.99169243706836E-8,1.00015033206882,10.005763053894,2,20,10,5,2.30336985199319,0.202623101181971,0.0410455763339996,172.855895996094,50.4999237060547,50.5016784667969,199.919204711914,199.919204711914,,,19.5638084411621,0,1,,,,,,1,1,1,50.5008010864258,0,50.5004319583668,,,,,,,,,,,,,,,,,,,,,,,,,,,,,,,,,
,3768365604.39813,50.5000858306885,199.919204711914,,,5,,,,25.0300001353025,,,,,0.00070473409509442,8.66121879294672E-8,0.00611795241473167,9.41960298384401E-5,0.000704628116854356,8.65991631484771E-8,0.000704628112837402,5.56303719735747E-8,7.52390720126392E-8,6.63677389406801E-8,1.00015040308147,10.005763053894,2,20,10,5,2.30530057239139,0.20307715706453,0.0410455763339996,172.855895996094,50.499382019043,50.5004272460937,199.919204711914,199.919204711914,,,19.5376815795898,0,1,,,,,,1,1,1,50.4997215270996,0,50.4998343618293,,,,,,,,,,,,,,,,,,,,,,,,,,,,,,,,,
,3768365813.16956,50.5008068084717,199.919204711914,,,5,,,,25.0300001353025,,,,,0.000704609802124224,1.91774891551281E-7,0.0041673835326872,0.000128121261771343,0.000704503819333452,1.91746046028347E-7,0.000704503817469928,1.69193814447627E-7,5.12417779767955E-8,9.02219447815592E-8,1.00015043607694,10.005763053894,2,20,10,5,2.30490090112897,0.202962868444523,0.0410455763339996,172.855895996094,50.4995422363281,50.5009651184082,199.919204711914,199.919204711914,,,19.5124225616455,0,1,,,,,,1,1,1,50.5009765625,0,50.5003137027516,,,,,,,,,,,,,,,,,,,,,,,,,,,,,,,,,
,3768366019.77329,50.5006294250488,199.919204711914,,,5,,,,25.0300001353025,,,,,0.000704853520472237,9.65332413688487E-8,-0.00549775393243479,7.18901952268659E-5,0.000704747506743181,9.65187222544538E-8,0.000704747503498822,8.21616249254243E-8,-6.7623277029344E-8,5.06490980694257E-8,1.00015042795901,10.005763053894,2,20,10,5,2.30573236251523,0.202644125546802,0.0410455763339996,172.855895996094,50.4998245239258,50.5009613037109,199.919204711914,199.919204711914,,,19.5203285217285,0,1,,,,,,1,1,1,50.5005378723145,0,50.5003545424517,,,,,,,,,,,,,,,,,,,,,,,,,,,,,,,,,
,3768366227.43462,50.4997081756592,199.919204711914,,,5,,,,25.0300001353025,,,,,0.000705029729752079,1.01475229270178E-7,-0.000220564078164287,9.21770972466782E-5,0.000704923719235946,1.01459971131442E-7,0.000704923719230723,7.79324824117552E-8,-2.71365276169307E-9,6.49665600685042E-8,1.00015038579812,10.005763053894,2,20,10,5,2.30629010306997,0.202907208607705,0.0410455763339996,172.855895996094,50.4993286132812,50.5006904602051,199.919204711914,199.919204711914,,,19.4831504821777,0,1,,,,,,1,1,1,50.4997138977051,0,50.499787274529,,,,,,,,,,,,,,,,,,,,,,,,,,,,,,,,,
,3768366432.72962,50.5000114440918,199.919204711914,,,5,,,,25.0300001353025,,,,,0.000705758957237863,1.04558783573427E-7,-0.00119721225277925,9.00291313454956E-5,0.000705652827280444,1.04543060330902E-7,0.000705652827126395,8.30357178862386E-8,-1.4744824455597E-8,6.35163051386625E-8,1.00015039967717,10.005763053894,2,20,10,5,2.30867901087329,0.203077724987467,0.0410455763339996,172.855895996094,50.4996910095215,50.5006065368652,199.919204711914,199.919204711914,,,19.4455890655518,0,1,,,,,,1,1,1,50.5002174377441,0,50.5000511618222,,,,,,,,,,,,,,,,,,,,,,,,,,,,,,,,,
,3768366640.54981,50.500940322876,199.919204711914,,,5,,,,25.0300001353025,,,,,0.000705575859372265,1.12352179546625E-7,0.000978962376280812,0.000100305578308541,0.000705469726963525,1.12335279581463E-7,0.000705469726860549,8.72566506722912E-8,1.20537380962082E-8,7.07495014265066E-8,1.00015044218722,10.005763053894,2,20,10,5,2.3080723483948,0.203112701684453,0.0410455763339996,172.855895996094,50.4995727539063,50.5011558532715,199.919204711914,199.919204711914,,,19.4303207397461,0,1,,,,,,1,1,1,50.5007705688477,0,50.5002780241125,,,,,,,,,,,,,,,,,,,,,,,,,,,,,,,,,
,3768366796.99315,50.499755859375,199.919204711914,,,5,,,,25.0300001353025,,,,,0.000705706923696336,1.78220706423181E-7,-0.000262410100106081,0.000143695782901196,0.000705600809815605,1.78193908201214E-7,0.000705600809808205,1.46553535281283E-7,-3.231595428346E-9,1.01366316972554E-7,1.00015038798036,10.005763053894,2,20,10,5,2.30850548530916,0.203100417578876,0.0410455763339996,172.855895996094,50.4995002746582,50.5002479553223,199.919204711914,199.919204711914,,,19.4051704406738,0,1,,,,,,1,1,1,50.5000114440918,0,50.499838885139,,,,,,,,,,,,,,,,,,,,,,,,,,,,,,,,,