File: Experimental_Data/Fig3C/Lifetime_340Oe_47K.dat
[Header]
; MPMS3 Data File (default extension .dat)
; Copyright (c) 2007, Quantum Design, Inc. All rights reserved.
TITLE,340Oe_47K
FILEOPENTIME,3768666546.91204,06/02/2019,7:49 pm
BYAPP,SQUID AC,0.9.1.0
INFO,MPMS3 Measurement Release 1.1.16 Build 347, MultiVu Release 2.3.3.2,APPNAME
INFO,0,MOMENT_UNITS
INFO,,SAMPLE_MATERIAL
INFO,,SAMPLE_COMMENT
INFO,,SAMPLE_MASS
INFO,,SAMPLE_VOLUME
INFO,,SAMPLE_MOLECULAR_WEIGHT
INFO,,SAMPLE_SIZE
INFO,,SAMPLE_SHAPE
INFO,Quartz,SAMPLE_HOLDER
INFO,Standard,SAMPLE_HOLDER_DETAIL
INFO,66.2,SAMPLE_OFFSET
DATATYPE,COMMENT,1
DATATYPE,TIME,2
STARTUPAXIS,X,2
STARTUPAXIS,Y1,5
FIELDGROUP, VSM,2,3,4,5,6,8,9,10,11,14,15
FIELDGROUP, DC, 2,3,4,14,56,57,58,59,60,61,62,63,64,65,66,67,68,69
FIELDGROUP, AC, 2,3,4,11,16,17,18,19,20,21,22,23,24,25,26,27,28,29,30
STARTUPGROUP, All
[Data]
Comment,Time Stamp (sec),Temperature (K),Magnetic Field (Oe),Moment (emu),M. Std. Err. (emu),Transport Action,Averaging Time (sec),Frequency (Hz),Peak Amplitude (mm),Center Position (mm),Lockin Signal' (V),Lockin Signal (V),Range,M. Quad. Signal (emu),AC Moment (emu),AC M. Std Err. (emu),AC Phase (deg),AC Phase Std. Err. (deg),AC Susceptibility (emu/Oe),AC Suscept. Std Err. (emu/Oe),AC X' (emu/Oe),AC X' Std Err. (emu/Oe),AC X'' (emu/Oe),AC X'' Std Err. (emu/Oe),AC Drive (Oe),AC Frequency (Hz),AC Averaging Time (sec),AC Cycles,AC Range,AC Measure Type,AC Signal' (V),AC Signal'' (V),AC Trim Coil Ratio,AC Trim Coil Phase,Min. Temperature (K),Max. Temperature (K),Min. Field (Oe),Max. Field (Oe),Mass (grams),Motor Lag (deg),Pressure (Torr),Measure Count,Measurement Number,SQUID Status (code),Motor Status (code),Measure Status (code),Motor Current (amps),Motor Temp. (C),Temp. Status (code),Field Status (code),Chamber Status (code),Chamber Temp (K),Redirection State,Average Temp (K),Rotation Angle (deg),Rotator state,DC Moment Fixed Ctr (emu),DC Moment Err Fixed Ctr (emu),DC Moment Free Ctr (emu),DC Moment Err Free Ctr (emu),DC Fixed Fit,DC Free Fit,DC Calculated Center (mm),DC Calculated Center Err (mm),DC Scan Length (mm),DC Scan Time (s),DC Number of Points,DC Squid Drift,DC Min V (V),DC Max V (V),DC Scans per Measure,Map 01,Map 02,Map 03,Map 04,Map 05,Map 06,Map 07,Map 08,Map 09,Map 10,Map 11,Map 12,Map 13,Map 14,Map 15,Map 16
,3768666552.49205,47.0984153747559,340.047241210937,,,5,,,,25.0400006771088,,,,,0.000618956926332834,1.44056766441514E-7,0.0513758947841447,0.000124276033747937,0.00061886348785449,1.4403501945965E-7,0.000618863239061368,1.21803722279345E-7,5.54921522096491E-7,7.6876134590898E-8,1.00015098398949,10.005763053894,2,20,10,5,2.02454764192897,0.18027499243233,0.0410455763339996,172.855895996094,47.0980033874512,47.1102447509766,340.047241210937,340.047241210937,,,18.2849807739258,0,1,,,,,,1,1,1,47.0988616943359,0,47.1011950174967,,,,,,,,,,,,,,,,,,,,,,,,,,,,,,,,,
,3768666759.75608,46.9555339813232,340.047241210937,,,5,,,,25.0300001353025,,,,,0.000635095763758598,1.94719243012548E-7,-0.00309610062569554,0.000282731568561119,0.000634999816473266,1.94689825743791E-7,0.000634999815546162,7.53197838139927E-8,-3.43135802471058E-8,1.79530104479336E-7,1.00015109813081,10.005763053894,2,20,10,5,2.0775110664558,0.183001115253691,0.0410455763339996,172.855895996094,46.9537086486816,46.9605484008789,340.047241210937,340.047241210937,,,19.9051094055176,0,1,,,,,,1,1,1,46.956127166748,0,46.9576038784451,,,,,,,,,,,,,,,,,,,,,,,,,,,,,,,,,
,3768666967.46139,46.9998874664307,340.047241210937,,,5,,,,25.0300001353025,,,,,0.000648356779444238,2.29523719546159E-7,-0.0105800889175356,0.000312734558959433,0.000648258925736107,2.2948907851552E-7,0.000648258914683827,1.07555904578978E-7,-1.19705798493064E-7,2.02723862798883E-7,1.00015094849334,10.005763053894,2,20,10,5,2.1209146069171,0.186545011151751,0.0410455763339996,172.855895996094,46.9995231628418,47.000373840332,340.047241210937,340.047241210937,,,20.6332931518555,0,1,,,,,,1,1,1,46.9998435974121,0,46.9999517552993,,,,,,,,,,,,,,,,,,,,,,,,,,,,,,,,,
,3768667174.73018,47.0005474090576,340.047241210937,,,5,,,,25.0300001353025,,,,,0.000657001070954319,1.41548642501158E-7,-0.00970571049769564,0.000150085639635589,0.000656901892760261,1.41527274897123E-7,0.000656901883335292,1.01548711663821E-7,-1.11276949545152E-7,9.85790479728024E-8,1.0001509787004,10.005763053894,2,20,10,5,2.14918906072416,0.189064938768284,0.0410455763339996,172.855895996094,46.9997673034668,47.0008087158203,340.047241210937,340.047241210937,,,21.3150997161865,0,1,,,,,,1,1,1,47.0006294250488,0,47.000233968099,,,,,,,,,,,,,,,,,,,,,,,,,,,,,,,,,
,3768667380.63191,47.0007476806641,340.047241210937,,,5,,,,25.0300001353025,,,,,0.000663556833084193,1.88428905102025E-7,-0.000920003371014388,0.000239651824990743,0.000663456659178191,1.88400458918538E-7,0.000663456659092662,1.01077530269098E-7,-1.06531819293999E-8,1.58990772673811E-7,1.00015098786728,10.005763053894,2,20,10,5,2.17060503534515,0.19128432906035,0.0410455763339996,172.855895996094,46.9997291564941,47.0008735656738,340.047241210937,340.047241210937,,,21.9763031005859,0,1,,,,,,1,1,1,47.0007514953613,0,47.0002837181091,,,,,,,,,,,,,,,,,,,,,,,,,,,,,,,,,
,3768667587.27683,46.9999179840088,340.047241210937,,,5,,,,25.0300001353025,,,,,0.000668731058100209,1.75744735627735E-7,-0.0142280616148893,0.000205726538295246,0.000668630128455739,1.75718210983082E-7,0.000668630107839845,1.0935575548712E-7,-1.66038592167032E-7,1.37543478263915E-7,1.00015094989019,10.005763053894,2,20,10,5,2.18757550463703,0.192267811574315,0.0410455763339996,172.855895996094,46.9992828369141,47.0007247924805,340.047241210937,340.047241210937,,,22.606616973877,0,1,,,,,,1,1,1,46.9998550415039,0,46.9998638755397,,,,,,,,,,,,,,,,,,,,,,,,,,,,,,,,,
,3768667794.8764,47.0011901855469,340.047241210937,,,5,,,,25.0300001353025,,,,,0.000673196493331376,2.21926993471273E-7,-0.00133443141446143,0.00025860259886279,0.000673094927752331,2.2189351120596E-7,0.000673094927569776,1.3763368743811E-7,-1.56765301748111E-8,1.74050850033828E-7,1.00015089339536,10.005763053894,2,20,10,5,2.20213937494233,0.194047236210003,0.0410455763339996,172.855895996094,46.9997940063477,47.0015029907227,340.047241210937,340.047241210937,,,23.2834720611572,0,1,,,,,,1,1,1,47.0009613037109,0,47.0005775900448,,,,,,,,,,,,,,,,,,,,,,,,,,,,,,,,,
,3768668001.26276,47.0002040863037,340.047241210937,,,5,,,,25.0300001353025,,,,,0.000676889659446704,1.43126886351944E-7,-0.00859820829919755,0.000152335158673227,0.000676787489586564,1.43105282751185E-7,0.000676787481965897,9.92582781066344E-8,-1.0156349799877E-7,1.03086935052908E-7,1.00015096298574,10.005763053894,2,20,10,5,2.21424506237359,0.194831071661813,0.0410455763339996,172.855895996094,46.9994583129883,47.0004539489746,340.047241210937,340.047241210937,,,23.9003620147705,0,1,,,,,,1,1,1,47.0003700256348,0,46.9999804777258,,,,,,,,,,,,,,,,,,,,,,,,,,,,,,,,,
,3768668207.70711,46.9993267059326,340.047241210937,,,5,,,,25.0300001353025,,,,,0.000680510898491218,1.72346672683426E-7,-0.00903402605992465,0.000179018353842847,0.000680408209361385,1.72320665561591E-7,0.000680408200903594,1.21907313605594E-7,-1.07282342984523E-7,1.21790880894494E-7,1.00015092282606,10.005763053894,2,20,10,5,2.22609236832356,0.195856454449241,0.0410455763339996,172.855895996094,46.9991226196289,46.9996566772461,340.047241210937,340.047241210937,,,24.4807300567627,0,1,,,,,,1,1,1,46.9995346069336,0,46.9994316101074,,,,,,,,,,,,,,,,,,,,,,,,,,,,,,,,,
,3768668414.23268,47.000675201416,340.047241210937,,,5,,,,25.0300001353025,,,,,0.000683405966961709,2.12503473979754E-7,-0.0085687671451149,0.000273430406297468,0.000683302798796296,2.12471394081985E-7,0.000683302791154866,1.01190732966878E-7,-1.02190119419319E-7,1.86827537758137E-7,1.00015098454974,10.005763053894,2,20,10,5,2.23556114133302,0.196707825943793,0.0410455763339996,172.855895996094,47.0000801086426,47.0010643005371,340.047241210937,340.047241210937,,,25.108980178833,0,1,,,,,,1,1,1,47.0007362365723,0,47.0005650239832,,,,,,,,,,,,,,,,,,,,,,,,,,,,,,,,,
,3768668619.07644,47.00022315979,340.047241210937,,,5,,,,25.0300001353025,,,,,0.000686213113630061,1.64757350789679E-7,-0.00841500325900935,0.000139600225022493,0.00068610953588698,1.64732482138509E-7,0.000686109528487064,1.34040645030667E-7,-1.00768573337086E-7,9.57595747237676E-8,1.00015096385878,10.005763053894,2,20,10,5,2.24474336356981,0.197521848462613,0.0410455763339996,172.855895996094,46.9992942810059,47.0006828308105,340.047241210937,340.047241210937,,,25.686128616333,0,1,,,,,,1,1,1,46.9997634887695,0,46.9998918421128,,,,,,,,,,,,,,,,,,,,,,,,,,,,,,,,,
,3768668826.95638,47.0007553100586,340.047241210937,,,5,,,,25.0300001353025,,,,,0.000688737452649823,2.19497671285875E-7,-0.00834595522890691,0.000268269382335718,0.000688633477109296,2.19464534727192E-7,0.000688633469803543,1.18490265233407E-7,-1.00309380509325E-7,1.84728825709308E-7,1.00015098821649,10.005763053894,2,20,10,5,2.25300075395348,0.19825117362348,0.0410455763339996,172.855895996094,46.9993591308594,47.0013542175293,340.047241210937,340.047241210937,,,26.2383251190186,0,1,,,,,,1,1,1,47.0006103515625,0,47.0000998179118,,,,,,,,,,,,,,,,,,,,,,,,,,,,,,,,,
,3768669033.78116,47.0013046264648,340.047241210937,,,5,,,,25.0300001353025,,,,,0.000690683082272696,1.54583167257786E-7,-0.00503965475255352,0.000185584693662575,0.000690578795648458,1.5455982665905E-7,0.000690578792977054,8.64028965126038E-8,-6.07423222895525E-8,1.28153343659492E-7,1.00015101335995,10.005763053894,2,20,10,5,2.25935382944028,0.198941592776443,0.0410455763339996,172.855895996094,46.9995422363281,47.0013732910156,340.047241210937,340.047241210937,,,26.8262519836426,0,1,,,,,,1,1,1,47.0012741088867,0,47.0005706338321,,,,,,,,,,,,,,,,,,,,,,,,,,,,,,,,,
,3768669239.76942,47.0004730224609,340.047241210937,,,5,,,,25.0300001353025,,,,,0.000692602065252444,1.52912560883127E-7,-0.0121806598857663,0.000134596784902294,0.000692497594671152,1.52889495886755E-7,0.000692497579022222,1.21205555655727E-7,-1.47219876935901E-7,9.3190188489414E-8,1.00015086056919,10.005763053894,2,20,10,5,2.26565602827994,0.199211956921855,0.0410455763339996,172.855895996094,46.9995422363281,47.0014266967773,340.047241210937,340.047241210937,,,27.3577041625977,0,1,,,,,,1,1,1,47.0003776550293,0,47.0002930585076,,,,,,,,,,,,,,,,,,,,,,,,,,,,,,,,,
,3768669446.68202,47.0007343292236,340.047241210937,,,5,,,,25.0300001353025,,,,,0.000694601923345009,1.55337301465093E-7,-0.00672439927294732,0.000142774612303876,0.000694497063139038,1.5531385105288E-7,0.000694497058356019,1.19556397686707E-7,-8.15081944150687E-8,9.91395990563511E-8,1.00015098725615,10.005763053894,2,20,10,5,2.27217897499651,0.200003549648204,0.0410455763339996,172.855895996094,46.9998321533203,47.0011558532715,340.047241210937,340.047241210937,,,27.9255027770996,0,1,,,,,,1,1,1,47.0009841918945,0,47.0005181256463,,,,,,,,,,,,,,,,,,,,,,,,,,,,,,,,,
,3768669653.81209,47.000617980957,340.047241210937,,,5,,,,25.0300001353025,,,,,0.000696043655179923,1.63837531719195E-7,-0.00692275827620659,0.000147032713905413,0.000695938581029358,1.63812798946548E-7,0.000695938575949472,1.27937117453401E-7,-8.4086726819558E-8,1.02307023592797E-7,1.00015098193063,10.005763053894,2,20,10,5,2.27689585570594,0.200410803670033,0.0410455763339996,172.855895996094,46.9993934631348,47.001350402832,340.047241210937,340.047241210937,,,28.4672832489014,0,1,,,,,,1,1,1,47.0000152587891,0,47.0000137752957,,,,,,,,,,,,,,,,,,,,,,,,,,,,,,,,,
,3768669860.3757,46.9998531341553,340.047241210937,,,5,,,,25.0300001353025,,,,,0.000697635941404177,1.70355651509124E-7,-0.00625040121042364,0.000149462210009848,0.000697530651299454,1.70329940728869E-7,0.000697530647148921,1.3471281567009E-7,-7.60936748848441E-8,1.04234092325574E-7,1.00015094692187,10.005763053894,2,20,10,5,2.28210218009485,0.200896049097586,0.0410455763339996,172.855895996094,46.9991111755371,47.0001792907715,340.047241210937,340.047241210937,,,29.0301761627197,0,1,,,,,,1,1,1,46.9998664855957,0,46.9997255537245,,,,,,,,,,,,,,,,,,,,,,,,,,,,,,,,,
,3768670065.44385,47.0001010894775,340.047241210937,,,5,,,,25.0300001353025,,,,,0.000698872682690654,1.30352782941268E-7,-0.00149289752971082,0.000123059879402295,0.000698767198002372,1.30333108080573E-7,0.000698767197765171,9.79526414726449E-8,-1.82070622389292E-8,8.5976735751445E-8,1.00015095827134,10.005763053894,2,20,10,5,2.28613108163044,0.201442015915635,0.0410455763339996,172.855895996094,46.9991340637207,47.000186920166,340.047241210937,340.047241210937,,,29.5323638916016,0,1,,,,,,1,1,1,47.0001258850098,0,46.9997969234691,,,,,,,,,,,,,,,,,,,,,,,,,,,,,,,,,
,3768670273.33585,47.0000686645508,340.047241210937,,,5,,,,25.0300001353025,,,,,0.000700205948209174,2.48001243992819E-7,-0.00868055674317692,0.000238112507640378,0.000700100263322717,2.47963812172396E-7,0.000700100255287823,1.83587171626954E-7,-1.060681971706E-7,1.66678740579243E-7,1.00015095678718,10.005763053894,2,20,10,5,2.29051771996188,0.201538975084661,0.0410455763339996,172.855895996094,46.9990005493164,47.0002555847168,340.047241210937,340.047241210937,,,30.0407791137695,0,1,,,,,,1,1,1,46.9999771118164,0,46.999683380127,,,,,,,,,,,,,,,,,,,,,,,,,,,,,,,,,
,3768670483.64491,46.9992618560791,340.047241210937,,,5,,,,25.0300001353025,,,,,0.000701221260365256,1.76302648061486E-7,-0.00116972525331338,0.000132100500992736,0.000701115448121567,1.76276044505926E-7,0.000701115447975456,1.50002097695188E-7,-1.4313662403558E-8,9.25884147920159E-8,1.00015091985774,10.005763053894,2,20,10,5,2.29381253691872,0.20213191069373,0.0410455763339996,172.855895996094,46.9984512329102,46.9997520446777,340.047241210937,340.047241210937,,,30.4263305664063,0,1,,,,,,1,1,1,46.998851776123,0,46.9992733001709,,,,,,,,,,,,,,,,,,,,,,,,,,,,,,,,,
,3768670691.39122,47.0003871917725,340.047241210937,,,5,,,,25.0300001353025,,,,,0.000702237638793231,1.54939083701059E-7,-0.00293199049444137,0.00013277513683354,0.000702131637020253,1.54915695866701E-7,0.00070213163610093,1.2373968820779E-7,-3.5930103441937E-8,9.32060212009023E-8,1.00015097136689,10.005763053894,2,20,10,5,2.29714350700508,0.202354228834518,0.0410455763339996,172.855895996094,46.9993133544922,47.0008201599121,340.047241210937,340.047241210937,,,30.7994422912598,0,1,,,,,,1,1,1,47.0001068115234,0,46.9999640969669,,,,,,,,,,,,,,,,,,,,,,,,,,,,,,,,,
,3768670896.41287,47.0001754760742,340.047241210937,,,5,,,,25.0300001353025,,,,,0.000703342599279306,1.97771785445668E-7,0.000767256823430706,0.000144214719185052,0.000703236437527942,1.9774193399186E-7,0.000703236437464888,1.69774923975309E-7,9.41715008937248E-9,1.01382186048729E-7,1.00015096167619,10.005763053894,2,20,10,5,2.30074493812562,0.202821174708485,0.0410455763339996,172.855895996094,46.9995956420898,47.0003890991211,340.047241210937,340.047241210937,,,31.1601181030273,0,1,,,,,,1,1,1,47.0003776550293,0,47.000020868638,,,,,,,,,,,,,,,,,,,,,,,,,,,,,,,,,
,3768671102.26356,46.9998664855957,340.047241210937,,,5,,,,25.0300001353025,,,,,0.000704380975280264,1.89199464627213E-7,-0.00728922378108265,0.000198404200476,0.000704274666756767,1.89170909745073E-7,0.000704274661057364,1.27533731421712E-7,-8.95984953711513E-8,1.39716786548478E-7,1.00015094753299,10.005763053894,2,20,10,5,2.30417016850711,0.202796619392176,0.0410455763339996,172.855895996094,46.99951171875,47.0003395080566,340.047241210937,340.047241210937,,,31.5207939147949,0,1,,,,,,1,1,1,46.9997673034668,0,46.9998669343836,,,,,,,,,,,,,,,,,,,,,,,,,,,,,,,,,
,3768671309.83458,46.9990711212158,340.047241210937,,,5,,,,25.0300001353025,,,,,0.000705151180276089,1.25127335284389E-7,-0.000994916841956517,0.000101648611293812,0.000705044781173313,1.25108455026397E-7,0.000705044781067017,1.02559899134457E-7,-1.22428027517709E-8,7.16490935645526E-8,1.00015091112737,10.005763053894,2,20,10,5,2.30666734498491,0.203271774625506,0.0410455763339996,172.855895996094,46.9979133605957,46.99951171875,340.047241210937,340.047241210937,,,31.8814697265625,0,1,,,,,,1,1,1,46.9989433288574,0,46.999063067966,,,,,,,,,,,,,,,,,,,,,,,,,,,,,,,,,
,3768671516.06167,47.0001640319824,340.047241210937,,,5,,,,25.0300001353025,,,,,0.000706199768235145,1.71231922982551E-7,-0.00387304709342651,0.000142549528420797,0.00070609317559568,1.71206077515798E-7,0.000706093173982465,1.38509884767689E-7,-4.77300796426382E-8,1.0063067524362E-7,1.00015096115236,10.005763053894,2,20,10,5,2.31010767517455,0.203457998597794,0.0410455763339996,172.855895996094,46.9995155334473,47.0004463195801,340.047241210937,340.047241210937,,,32.2421455383301,0,1,,,,,,1,1,1,47.0002174377441,0,47.0000057220459,,,,,,,,,,,,,,,,,,,,,,,,,,,,,,,,,
,3768671721.77655,47.0009803771973,340.047241210937,,,5,,,,25.0300001353025,,,,,0.000706904273945196,1.13303231367116E-7,-0.00774932320923227,0.000129237993945541,0.000706797548562607,1.13286125330044E-7,0.000706797542097922,6.70148217860225E-8,-9.55952197029643E-8,9.13387095008578E-8,1.00015099851833,10.005763053894,2,20,10,5,2.31242601481875,0.203504520205699,0.0410455763339996,172.855895996094,46.9999122619629,47.0014114379883,340.047241210937,340.047241210937,,,32.5903854370117,0,1,,,,,,1,1,1,47.0011215209961,0,47.0005319383409,,,,,,,,,,,,,,,,,,,,,,,,,,,,,,,,,
,3768671930.44779,46.9999485015869,340.047241210937,,,5,,,,25.0300001353025,,,,,0.00070767043738761,2.00404802775276E-7,-0.00807217849248421,0.000152268779069773,0.000707563629747029,2.00374555978159E-7,0.000707563622724852,1.68963221191535E-7,-9.96858746621843E-8,1.07709760783435E-7,1.00015095128705,10.005763053894,2,20,10,5,2.31493343697226,0.203712044924076,0.0410455763339996,172.855895996094,46.9994277954102,47.0007095336914,340.047241210937,340.047241210937,,,32.9261856079102,0,1,,,,,,1,1,1,47.0001068115234,0,46.9998747507731,,,,,,,,,,,,,,,,,,,,,,,,,,,,,,,,,
,3768672138.35891,46.9996395111084,340.047241210937,,,5,,,,25.0300001353025,,,,,0.000708159970220799,1.22517077276221E-7,-0.00622808890735804,0.000113807592150461,0.000708053098708378,1.22498587689268E-7,0.00070805309452526,9.227400868551E-8,-7.69658372515025E-8,8.05692950631423E-8,1.00015093714386,10.005763053894,2,20,10,5,2.31652823548254,0.203927525310011,0.0410455763339996,172.855895996094,46.9990768432617,47.0004463195801,340.047241210937,340.047241210937,,,33.2619895935059,0,1,,,,,,1,1,1,46.999397277832,0,46.9996652042165,,,,,,,,,,,,,,,,,,,,,,,,,,,,,,,,,
,3768672343.71712,47.0010147094727,340.047241210937,,,5,,,,25.0300001353025,,,,,0.000708829784298909,1.09479512184889E-7,-0.00210937018267465,9.03401431755841E-5,0.000708722767097441,1.09462983264587E-7,0.000708722766617147,8.87957842655412E-8,-2.60919510139305E-8,6.40113536948773E-8,1.00015100008979,10.005763053894,2,20,10,5,2.31870464834177,0.204287083946552,0.0410455763339996,172.855895996094,46.9996032714844,47.0014533996582,340.047241210937,340.047241210937,,,33.5853538513184,0,1,,,,,,1,1,1,47.0009384155273,0,47.0003749623018,,,,,,,,,,,,,,,,,,,,,,,,,,,,,,,,,
,3768672550.01616,46.9998645782471,340.047241210937,,,5,,,,25.0300001353025,,,,,0.000709488460022337,1.45700593595053E-7,-0.0115082210404864,0.000180358935531274,0.000709381380714897,1.4567860378192E-7,0.000709381366405514,6.96730188372628E-8,-1.42483752656103E-7,1.2793719570927E-7,1.00015094744569,10.005763053894,2,20,10,5,2.3208928008691,0.204096207623033,0.0410455763339996,172.855895996094,46.9983100891113,47.0008735656738,340.047241210937,340.047241210937,,,33.9211540222168,0,1,,,,,,1,1,1,46.9989585876465,0,46.9997401767307,,,,,,,,,,,,,,,,,,,,,,,,,,,,,,,,,
,3768672757.80861,46.9998168945313,340.047241210937,,,5,,,,25.0300001353025,,,,,0.000710050595917517,1.33650106335114E-7,-0.00787007739054957,9.6302557020655E-5,0.000709943433319189,1.33629935529338E-7,0.000709943426621785,1.14828451563786E-7,-9.75169513888721E-8,6.83475411484437E-8,1.0001509452631,10.005763053894,2,20,10,5,2.32271869703828,0.204405396346321,0.0410455763339996,172.855895996094,46.9994125366211,47.0003967285156,340.047241210937,340.047241210937,,,34.2320823669434,0,1,,,,,,1,1,1,47.0002784729004,0,46.9998428821564,,,,,,,,,,,,,,,,,,,,,,,,,,,,,,,,,
,3768672964.45072,47.000316619873,340.047241210937,,,5,,,,25.0300001353025,,,,,0.000710456657881798,1.09457865479867E-7,-0.0106472940601483,8.08360910934735E-5,0.000710349417753825,1.09441343324192E-7,0.000710349405488607,9.31775471421754E-8,-1.32004471481581E-7,5.74051594995724E-8,1.00015096813666,10.005763053894,2,20,10,5,2.32405691833657,0.204409641468658,0.0410455763339996,172.855895996094,46.9997291564941,47.0010566711426,340.047241210937,340.047241210937,,,34.5305709838867,0,1,,,,,,1,1,1,47.000129699707,0,47.0001584221335,,,,,,,,,,,,,,,,,,,,,,,,,,,,,,,,,
,3768673172.25747,46.999942779541,340.047241210937,,,5,,,,25.0300001353025,,,,,0.000711176967047614,1.86729916980262E-7,-0.00514747958336681,0.000193012264586048,0.000711069630357965,1.86701734162095E-7,0.000711069627488334,1.26590723042137E-7,-6.38828275101884E-8,1.37230923551518E-7,1.00015095102514,10.005763053894,2,20,10,5,2.32639355309359,0.204840196691981,0.0410455763339996,172.855895996094,46.9994812011719,47.0005226135254,340.047241210937,340.047241210937,,,34.8539352416992,0,1,,,,,,1,1,1,47.0001907348633,0,47.0000186246984,,,,,,,,,,,,,,,,,,,,,,,,,,,,,,,,,
,3768673377.08587,47.0003833770752,340.047241210937,,,5,,,,25.0300001353025,,,,,0.000711552139709823,1.61140266560805E-7,-0.00350302772537781,0.000160069631107991,0.000711444732050381,1.61115942694841E-7,0.000711444730720683,1.1398541146508E-7,-4.34972809703159E-8,1.1386690899284E-7,1.00015097119228,10.005763053894,2,20,10,5,2.32761493021988,0.205015062603109,0.0410455763339996,172.855895996094,46.9995727539063,47.0004959106445,340.047241210937,340.047241210937,,,35.1524276733398,0,1,,,,,,1,1,1,47.0002326965332,0,47.0001063876682,,,,,,,,,,,,,,,,,,,,,,,,,,,,,,,,,
,3768673582.22397,47.000093460083,340.047241210937,,,5,,,,25.0300001353025,,,,,0.000712362718362429,1.49901303765564E-7,-0.00658812659844354,0.000121647627726195,0.000712255197797743,1.49878678391702E-7,0.000712255193089225,1.22310576635031E-7,-8.18983080957902E-8,8.66241368190728E-8,1.00015095792213,10.005763053894,2,20,10,5,2.33027752680451,0.205123137161758,0.0410455763339996,172.855895996094,46.9991760253906,47.0002403259277,340.047241210937,340.047241210937,,,35.4633522033691,0,1,,,,,,1,1,1,46.9999465942383,0,46.9996750775505,,,,,,,,,,,,,,,,,,,,,,,,,,,,,,,,,
,3768673787.30922,47.0001487731934,340.047241210937,,,5,,,,25.0300001353025,,,,,0.000712781279891652,1.46024762150408E-7,-0.00616184488064775,0.000171833120871707,0.000712673694347246,1.46002721513292E-7,0.00071267369022592,7.95096566757079E-8,-7.66441225503918E-8,1.22454110525531E-7,1.00015096045393,10.005763053894,2,20,10,5,2.33164519643866,0.205261005802933,0.0410455763339996,172.855895996094,46.9995346069336,47.0006675720215,340.047241210937,340.047241210937,,,35.7494087219238,0,1,,,,,,1,1,1,47.0004806518555,0,47.0000172783347,,,,,,,,,,,,,,,,,,,,,,,,,,,,,,,,,
,3768673995.33173,47.0006141662598,340.047241210937,,,5,,,,25.0300001353025,,,,,0.000712954250751249,1.74348830018104E-7,-0.0123598485498047,0.000164794380498883,0.000712846623916194,1.74322510499354E-7,0.000712846607329985,1.28811040946434E-7,-1.53775309759031E-7,1.17456602186057E-7,1.00015098175602,10.005763053894,2,20,10,5,2.33223321348986,0.205058527078083,0.0410455763339996,172.855895996094,46.999641418457,47.0009536743164,340.047241210937,340.047241210937,,,36.0478973388672,0,1,,,,,,1,1,1,47.0004844665527,0,47.0002638872932,,,,,,,,,,,,,,,,,,,,,,,,,,,,,,,,,
,3768674200.31083,47.0001201629639,340.047241210937,,,5,,,,25.0300001353025,,,,,0.000713705674113164,1.65954720819733E-7,-0.0047620597260547,0.000212387817182361,0.000713597949977204,1.65929672218388E-7,0.000713597947512481,6.75552329340559E-8,-5.93097097752784E-8,1.51555094357554E-7,1.00015095914438,10.005763053894,2,20,10,5,2.33466404649353,0.205584243648465,0.0410455763339996,172.855895996094,46.999568939209,47.0004959106445,340.047241210937,340.047241210937,,,36.3339500427246,0,1,,,,,,1,1,1,47.0004119873047,0,46.9999986536363,,,,,,,,,,,,,,,,,,,,,,,,,,,,,,,,,
,3768674405.4436,46.998571395874,340.047241210937,,,5,,,,25.0300001353025,,,,,0.000713887843911934,1.54625519201086E-7,-0.0074128508127238,0.000138706937703388,0.000713780060995534,1.54602173812099E-7,0.00071378005502161,1.1875564156629E-7,-9.23479030298801E-8,9.898954360742E-8,1.00015100298018,10.005763053894,2,20,10,5,2.33526946849254,0.205528683527334,0.0410455763339996,172.855895996094,46.9979133605957,47.0025863647461,340.047241210937,340.047241210937,,,36.6697578430176,0,1,,,,,,1,1,1,46.9990730285645,0,47.0003940357881,,,,,,,,,,,,,,,,,,,,,,,,,,,,,,,,,
,3768674613.14017,47.0000438690186,340.047241210937,,,5,,,,25.0300001353025,,,,,0.000713914194881269,1.76888077770615E-7,-0.00897011848763629,0.000183123497580757,0.000713806441764283,1.7686137954571E-7,0.000713806433016429,1.19151573123406E-7,-1.11752181192426E-7,1.30701377946177E-7,1.00015095565223,10.005763053894,2,20,10,5,2.33536125364872,0.205472791981999,0.0410455763339996,172.855895996094,46.9995269775391,47.0004806518555,340.047241210937,340.047241210937,,,36.955810546875,0,1,,,,,,1,1,1,46.9999313354492,0,47.000010546516,,,,,,,,,,,,,,,,,,,,,,,,,,,,,,,,,
,3768674820.84554,47.000919342041,340.047241210937,,,5,,,,25.0300001353025,,,,,0.000714646004025487,1.5444382540459E-7,-0.00805375849667467,0.000128595960563605,0.000714538111825532,1.54420508568004E-7,0.000714538104766464,1.24121208103637E-7,-1.00438765634528E-7,9.18673999049437E-8,1.00015099572461,10.005763053894,2,20,10,5,2.33775186347026,0.205720799810388,0.0410455763339996,172.855895996094,46.999870300293,47.0010719299316,340.047241210937,340.047241210937,,,37.2418632507324,0,1,,,,,,1,1,1,47.0007781982422,0,47.0004030115464,,,,,,,,,,,,,,,,,,,,,,,,,,,,,,,,,
,3768675027.77414,47.0002460479736,340.047241210937,,,5,,,,25.0300001353025,,,,,0.000715156191658957,1.83771993246543E-7,-0.010001096265051,0.000225025880656101,0.000715048244467645,1.83744254312385E-7,0.000715048233574449,8.87364355690799E-8,-1.24813142460679E-7,1.60896848929086E-7,1.00015096490642,10.005763053894,2,20,10,5,2.33942778581666,0.205788157031236,0.0410455763339996,172.855895996094,46.9991302490234,47.0004997253418,340.047241210937,340.047241210937,,,37.540355682373,0,1,,,,,,1,1,1,47.0000343322754,0,46.9998012118869,,,,,,,,,,,,,,,,,,,,,,,,,,,,,,,,,
,3768675236.64299,46.9998741149902,340.047241210937,,,5,,,,25.0300001353025,,,,,0.000715473711668324,1.34592271775161E-7,-0.00990301820675299,0.000149519139502035,0.000715365728726568,1.34571958423032E-7,0.000715365718041236,8.16745122551344E-8,-1.23644007656383E-7,1.06952728070378E-7,1.00015094788221,10.005763053894,2,20,10,5,2.34046610849746,0.205883533764164,0.0410455763339996,172.855895996094,46.9991188049316,47.0005378723145,340.047241210937,340.047241210937,,,37.8388442993164,0,1,,,,,,1,1,1,46.9994087219238,0,46.9997125513413,,,,,,,,,,,,,,,,,,,,,,,,,,,,,,,,,
,3768675442.85354,47.0005130767822,340.047241210937,,,5,,,,25.0300001353025,,,,,0.000715730998102894,1.07566830810731E-7,-0.00905953702825002,0.000126633875058142,0.00071562295540369,1.07550593130965E-7,0.000715622946457852,5.79283885702916E-8,-1.13153406600395E-7,9.06169513969197E-8,1.00015097712893,10.005763053894,2,20,10,5,2.341304715247,0.205992031337283,0.0410455763339996,172.855895996094,46.9996795654297,47.0006980895996,340.047241210937,340.047241210937,,,38.1249008178711,0,1,,,,,,1,1,1,47.0006866455078,0,47.0001593197093,,,,,,,,,,,,,,,,,,,,,,,,,,,,,,,,,
,3768675649.64376,46.9998340606689,340.047241210937,,,5,,,,25.0300001353025,,,,,0.000715747194589056,1.40381686629941E-7,-0.00947897453754099,0.000160994152477703,0.0007156391716837,1.40360499767089E-7,0.000715639161890118,8.01785666281863E-8,-1.18394854091539E-7,1.15206194921612E-7,1.00015094604883,10.005763053894,2,20,10,5,2.34135920493926,0.205979556357864,0.0410455763339996,172.855895996094,46.9996185302734,47.0005683898926,340.047241210937,340.047241210937,,,38.3860778808594,0,1,,,,,,1,1,1,46.9999542236328,0,47.0000237857594,,,,,,,,,,,,,,,,,,,,,,,,,,,,,,,,,
,3768675857.64107,47.0011425018311,340.047241210937,,,5,,,,25.0300001353025,,,,,0.000716375778886628,2.05732856982204E-7,-0.0114662093511235,0.000256940527602855,0.000716267700384653,2.0570181838536E-7,0.000716267686041658,9.19024594590245E-8,-1.43341715900088E-7,1.84030367147452E-7,1.00015089121276,10.005763053894,2,20,10,5,2.34342258555744,0.206079167558115,0.0410455763339996,172.855895996094,47.0001678466797,47.0021591186523,340.047241210937,340.047241210937,,,38.6845703125,0,1,,,,,,1,1,1,47.0011100769043,0,47.0006868699018,,,,,,,,,,,,,,,,,,,,,,,,,,,,,,,,,
,3768676065.13423,47.0001583099365,340.047241210937,,,5,,,,25.0300001353025,,,,,0.000716594202480283,1.78654876180551E-7,-0.000311657126659703,0.000193404488130171,0.00071648604110952,1.78627910352144E-7,0.00071648604109892,1.1273380581812E-7,-3.89728497911251E-9,1.38560526061848E-7,1.00015096089045,10.005763053894,2,20,10,5,2.3440969196204,0.206598369270372,0.0410455763339996,172.855895996094,46.9995765686035,47.0007629394531,340.047241210937,340.047241210937,,,38.9457473754883,0,1,,,,,,1,1,1,46.9997596740723,0,47.0000809563531,,,,,,,,,,,,,,,,,,,,,,,,,,,,,,,,,
,3768676270.28455,47.0000896453857,340.047241210937,,,5,,,,25.0300001353025,,,,,0.000717121984274903,1.27276667455768E-7,-0.0116824229041947,0.000138478491114997,0.000717013745494941,1.2725745695671E-7,0.000717013730590419,7.96078119734789E-8,-1.46196767303596E-7,9.92827105989971E-8,1.00015095774752,10.005763053894,2,20,10,5,2.34586436543663,0.206284979512441,0.0410455763339996,172.855895996094,46.9997520446777,47.0004501342773,340.047241210937,340.047241210937,,,39.2193641662598,0,1,,,,,,1,1,1,47.0002708435059,0,47.000103632609,,,,,,,,,,,,,,,,,,,,,,,,,,,,,,,,,
,3768676475.74081,47.0011863708496,340.047241210937,,,5,,,,25.0300001353025,,,,,0.000717511253160779,1.29920406850675E-7,-0.00996723538941424,0.000125829766899779,0.000717403001911247,1.29900805699725E-7,0.000717402991056058,9.34211443452438E-8,-1.2480019669553E-7,9.02591220357417E-8,1.00015089322075,10.005763053894,2,20,10,5,2.3471315705842,0.206467214530159,0.0410455763339996,172.855895996094,46.9998168945313,47.0016136169434,340.047241210937,340.047241210937,,,39.4681053161621,0,1,,,,,,1,1,1,47.0010452270508,0,47.0004324071548,,,,,,,,,,,,,,,,,,,,,,,,,,,,,,,,,
,3768676680.6409,47.0014553070068,340.047241210937,,,5,,,,25.0300001353025,,,,,0.000717657546416483,1.1027491282199E-7,-0.00672635174476266,9.69293326885915E-5,0.000717549264264056,1.10258274238617E-7,0.000717549259319405,8.55639159837305E-8,-8.42381197282983E-8,6.95392214480948E-8,1.00015090553056,10.005763053894,2,20,10,5,2.34759844233684,0.206642098579384,0.0410455763339996,172.855895996094,47.0000114440918,47.001636505127,340.047241210937,340.047241210937,,,39.7168502807617,0,1,,,,,,1,1,1,47.0015716552734,0,47.0006967432359,,,,,,,,,,,,,,,,,,,,,,,,,,,,,,,,,
,3768676885.94341,46.9999542236328,340.047241210937,,,5,,,,25.0300001353025,,,,,0.000718032818154863,2.36315372593069E-7,-0.0116715363156521,0.000302764105852407,0.000717924446347649,2.36279705805489E-7,0.000717924431451997,9.26571847427993E-8,-1.46246045707015E-7,2.17353963596404E-7,1.00015095154896,10.005763053894,2,20,10,5,2.34884386477401,0.206547435202831,0.0410455763339996,172.855895996094,46.9993133544922,47.0005989074707,340.047241210937,340.047241210937,,,40.0029029846191,0,1,,,,,,1,1,1,46.9998931884766,0,46.9997253417969,,,,,,,,,,,,,,,,,,,,,,,,,,,,,,,,,
,3768677092.68396,46.9996929168701,340.047241210937,,,5,,,,25.0300001353025,,,,,0.000718127621349626,9.99748603789961E-8,-0.00641851772724689,0.000108308291954782,0.000718019243820527,9.99597724920833E-8,0.000718019239315159,6.28105948621327E-8,-8.0435579627203E-8,7.77610782444153E-8,1.00015093958836,10.005763053894,2,20,10,5,2.3491350377326,0.206790082172202,0.0410455763339996,172.855895996094,46.9996643066406,47.000659942627,340.047241210937,340.047241210937,,,40.2516441345215,0,1,,,,,,1,1,1,46.9997406005859,0,46.9999943901511,,,,,,,,,,,,,,,,,,,,,,,,,,,,,,,,,
,3768677299.02631,47.0003261566162,340.047241210937,,,5,,,,25.0300001353025,,,,,0.000718459067379038,1.25966084829373E-7,-0.00827304967168452,0.000114484564372018,0.000718350619011047,1.25947070779802E-7,0.000718350611522588,9.54011177929478E-8,-1.03724050577861E-7,8.22270719524206E-8,1.00015096857317,10.005763053894,2,20,10,5,2.35022595761011,0.206809449702069,0.0410455763339996,172.855895996094,46.9995269775391,47.0005836486816,340.047241210937,340.047241210937,,,40.512825012207,0,1,,,,,,1,1,1,47.0004425048828,0,47.0001186794705,,,,,,,,,,,,,,,,,,,,,,,,,,,,,,,,,
,3768677507.20605,46.9990234375,340.047241210937,,,5,,,,25.0300001353025,,,,,0.000718483024423666,1.22667604136555E-7,-0.00547547694164052,9.74777622112209E-5,0.000718374532864457,1.22649081222046E-7,0.000718374529584112,1.00705455681767E-7,-6.86515345039654E-8,7.00086303289805E-8,1.00015102367114,10.005763053894,2,20,10,5,2.35029422444777,0.206931109517469,0.0410455763339996,172.855895996094,46.9986152648926,47.0030555725098,340.047241210937,340.047241210937,,,40.7864379882812,0,1,,,,,,1,1,1,46.9992332458496,0,47.0009892781576,,,,,,,,,,,,,,,,,,,,,,,,,,,,,,,,,
,3768677716.93986,47.0005970001221,340.047241210937,,,5,,,,25.0300001353025,,,,,0.000718726760604284,1.22855075716701E-7,-0.00835969148650584,9.81941739844791E-5,0.000718618262921678,1.22836529738253E-7,0.000718618255272699,1.005575862387E-7,-1.04849379907781E-7,7.05477489930272E-8,1.00015098097029,10.005763053894,2,20,10,5,2.35110194960146,0.206882949435106,0.0410455763339996,172.855895996094,46.9994621276855,47.0006904602051,340.047241210937,340.047241210937,,,41.0351829528809,0,1,,,,,,1,1,1,47.0006103515625,0,47.0000904307646,,,,,,,,,,,,,,,,,,,,,,,,,,,,,,,,,
,3768677920.83805,46.9996929168701,340.047241210937,,,5,,,,25.0300001353025,,,,,0.000718832577445878,1.15265706144774E-7,-0.0109011108431831,0.00011375506273252,0.000718724093527055,1.15248310612211E-7,0.000718724080518518,8.12361266504236E-8,-1.36744643820521E-7,8.17487909745759E-8,1.00015093958836,10.005763053894,2,20,10,5,2.35145727321447,0.20680911200809,0.0410455763339996,172.855895996094,46.9991493225098,46.9999313354492,340.047241210937,340.047241210937,,,41.2963600158691,0,1,,,,,,1,1,1,46.9996223449707,0,46.9996356964111,,,,,,,,,,,,,,,,,,,,,,,,,,,,,,,,,
,3768678126.80917,47.0007820129395,340.047241210937,,,5,,,,25.0300001353025,,,,,0.000719103315992247,1.39221682964665E-7,-0.00975370433083622,9.75933769612042E-5,0.000718994755377671,1.39200665134363E-7,0.000718994744959545,1.20234459233467E-7,-1.22397535823781E-7,7.01462756437214E-8,1.00015098943875,10.005763053894,2,20,10,5,2.35233877458309,0.206934106806939,0.0410455763339996,172.855895996094,46.999755859375,47.0009727478027,340.047241210937,340.047241210937,,,41.5699768066406,0,1,,,,,,1,1,1,47.0006408691406,0,47.0002836339614,,,,,,,,,,,,,,,,,,,,,,,,,,,,,,,,,
,3768678333.80489,47.0005512237549,340.047241210937,,,5,,,,25.0300001353025,,,,,0.000719670661658766,1.0292514308121E-7,-0.0060850511898165,9.35810910342121E-5,0.000719562022994038,1.02909605904684E-7,0.00071956201893595,7.78299221532337E-8,-7.64204933268368E-8,6.7326742124351E-8,1.000150978875,10.005763053894,2,20,10,5,2.35418141669175,0.207248109673813,0.0410455763339996,172.855895996094,46.9993476867676,47.0005645751953,340.047241210937,340.047241210937,,,41.8435935974121,0,1,,,,,,1,1,1,47.0004920959473,0,47.0000112321642,,,,,,,,,,,,,,,,,,,,,,,,,,,,,,,,,
,3768678540.38191,47.0000553131103,340.047241210937,,,5,,,,25.0300001353025,,,,,0.00071961205553715,1.77877208426571E-7,-0.00674194522021931,0.000173801370619001,0.000719503442048879,1.77850360816192E-7,0.000719503437067747,1.26478956779134E-7,-8.46633525555057E-8,1.25035292355845E-7,1.00015095617606,10.005763053894,2,20,10,5,2.35399208040698,0.207204245315559,0.0410455763339996,172.855895996094,46.9997673034668,47.0007057189941,340.047241210937,340.047241210937,,,42.1047744750977,0,1,,,,,,1,1,1,47.000244140625,0,47.0002300038057,,,,,,,,,,,,,,,,,,,,,,,,,,,,,,,,,
,3768678747.30872,47.00075340271,340.047241210937,,,5,,,,25.0300001353025,,,,,0.000719938109647731,1.18043662565612E-7,-0.00829062931311952,0.000101844623879512,0.000719829423949672,1.18025842064522E-7,0.000719829416413873,9.25073880847322E-8,-1.04158438065319E-7,7.32972205801849E-8,1.00015098812919,10.005763053894,2,20,10,5,2.35506426975288,0.207234471276995,0.0410455763339996,172.855895996094,46.9994125366211,47.0010757446289,340.047241210937,340.047241210937,,,42.3908271789551,0,1,,,,,,1,1,1,47.00048828125,0,47.0003069709329,,,,,,,,,,,,,,,,,,,,,,,,,,,,,,,,,
,3768678955.37641,47.0007724761963,340.047241210937,,,5,,,,25.0300001353025,,,,,0.000720129992212386,1.41808536059956E-7,-0.0099116070538745,0.000138408376776632,0.000720021276918201,1.41787127763006E-7,0.000720021266144666,1.00868806284166E-7,-1.24556607699496E-7,9.96447365297863E-8,1.00015098900223,10.005763053894,2,20,10,5,2.35569782033709,0.207223058408252,0.0410455763339996,172.855895996094,46.9999504089355,47.0010147094727,340.047241210937,340.047241210937,,,42.6520042419434,0,1,,,,,,1,1,1,47.0005760192871,0,47.0003908942727,,,,,,,,,,,,,,,,,,,,,,,,,,,,,,,,,
,3768679163.25137,47.0000305175781,340.047241210937,,,5,,,,25.0300001353025,,,,,0.000720210288894108,1.13715757923754E-7,-0.00738256036908602,0.000109618609391164,0.000720101585929602,1.1369859454774E-7,0.000720101579951924,8.18412969664621E-8,-9.27850787696472E-8,7.89263740012087E-8,1.00015095504111,10.005763053894,2,20,10,5,2.3559513376059,0.207350156906517,0.0410455763339996,172.855895996094,46.9993286132812,47.0006256103516,340.047241210937,340.047241210937,,,42.9007453918457,0,1,,,,,,1,1,1,47.000545501709,0,47.0001730077407,,,,,,,,,,,,,,,,,,,,,,,,,,,,,,,,,
,3768679371.92594,47.00075340271,340.047241210937,,,5,,,,25.0300001353025,,,,,0.000720310502493222,1.23957714313668E-7,-0.0065726288149941,0.000120016336259947,0.000720201760576753,1.23939000995774E-7,0.000720201755838075,8.88346368965949E-8,-8.26172341841263E-8,8.64250152171267E-8,1.00015098812919,10.005763053894,2,20,10,5,2.35627622465634,0.207412315321447,0.0410455763339996,172.855895996094,46.9999847412109,47.0009841918945,340.047241210937,340.047241210937,,,43.1619262695313,0,1,,,,,,1,1,1,47.000862121582,0,47.0004283680635,,,,,,,,,,,,,,,,,,,,,,,,,,,,,,,,,
,3768679579.97326,47.001127243042,340.047241210937,,,5,,,,25.0300001353025,,,,,0.000720559079204051,2.00053023206727E-7,-0.00363736475794152,0.000245462445619292,0.000720450370077157,2.00022841657271E-7,0.000720450368625371,9.34763780008652E-8,-4.57370648671601E-8,1.76836941673648E-7,1.00015089051434,10.005763053894,2,20,10,5,2.35707873518654,0.207604645009007,0.0410455763339996,172.855895996094,46.9996604919434,47.0014038085937,340.047241210937,340.047241210937,,,43.3982315063477,0,1,,,,,,1,1,1,47.0010757446289,0,47.0003674825033,,,,,,,,,,,,,,,,,,,,,,,,,,,,,,,,,
,3768679787.92926,47.0003318786621,340.047241210937,,,5,,,,25.0300001353025,,,,,0.00072087693117398,1.32953949095543E-7,-0.00695824040467219,0.000127807620613856,0.000720768117650892,1.32933880222503E-7,0.000720768112335698,9.58518942679168E-8,-8.75331109713707E-8,9.21077134460671E-8,1.00015096883508,10.005763053894,2,20,10,5,2.35813052020222,0.207559548916528,0.0410455763339996,172.855895996094,46.9999237060547,47.0005836486816,340.047241210937,340.047241210937,,,43.6469764709473,0,1,,,,,,1,1,1,47.0004653930664,0,47.0002030765309,,,,,,,,,,,,,,,,,,,,,,,,,,,,,,,,,
,3768679995.88232,46.9983291625977,340.047241210937,,,5,,,,25.0300001353025,,,,,0.0007210179470888,1.5328944471571E-7,-0.0124192217502772,0.000160170936233314,0.000720909178354843,1.53266320327617E-7,0.000720909161419497,1.00797315394363E-7,-1.56261612177678E-7,1.15457637928623E-7,1.00015087716625,10.005763053894,2,20,10,5,2.3586115855567,0.207375365537539,0.0410455763339996,172.855895996094,46.9955062866211,46.9998207092285,340.047241210937,340.047241210937,,,43.9081535339355,0,1,,,,,,1,1,1,46.9969253540039,0,46.996764014749,,,,,,,,,,,,,,,,,,,,,,,,,,,,,,,,,
,3768680202.01863,47.0010662078857,340.047241210937,,,5,,,,25.0300001353025,,,,,0.000721245374426206,9.67489245586658E-8,-0.00437389430744961,9.36979241164968E-5,0.000721136481052954,9.67343174400245E-8,0.000721136478951699,6.92323229797369E-8,-5.5050734506335E-8,6.75604442363786E-8,1.00015100244699,10.005763053894,2,20,10,5,2.35932640181128,0.207772048097561,0.0410455763339996,172.855895996094,46.9997711181641,47.0014724731445,340.047241210937,340.047241210937,,,44.1693305969238,0,1,,,,,,1,1,1,47.0012321472168,0,47.000569873386,,,,,,,,,,,,,,,,,,,,,,,,,,,,,,,,,
,3768680355.80624,47.0011138916016,340.047241210937,,,5,,,,25.0300001353025,,,,,0.000721435104465652,1.77457229860679E-7,-0.0111314363775952,0.000133411556368148,0.000721326180872902,1.77430437043257E-7,0.000721326167259745,1.49082655004167E-7,-1.401394048149E-7,9.62077022190508E-8,1.00015100462958,10.005763053894,2,20,10,5,2.35997153867741,0.207548367280758,0.0410455763339996,172.855895996094,46.9999580383301,47.0012626647949,340.047241210937,340.047241210937,,,44.3434524536133,0,1,,,,,,1,1,1,47.001293182373,0,47.0005739997415,,,,,,,,,,,,,,,,,,,,,,,,,,,,,,,,,