File: Experimental_Data/Fig3C/Lifetime_200Oe_49p5K.dat
[Header]
; MPMS3 Data File (default extension .dat)
; Copyright (c) 2007, Quantum Design, Inc. All rights reserved.
TITLE,200Oe_49p5K
FILEOPENTIME,3768338877.79414,05/30/2019,12:47 am
BYAPP,SQUID AC,0.9.1.0
INFO,MPMS3 Measurement Release 1.1.16 Build 347, MultiVu Release 2.3.3.2,APPNAME
INFO,0,MOMENT_UNITS
INFO,,SAMPLE_MATERIAL
INFO,,SAMPLE_COMMENT
INFO,,SAMPLE_MASS
INFO,,SAMPLE_VOLUME
INFO,,SAMPLE_MOLECULAR_WEIGHT
INFO,,SAMPLE_SIZE
INFO,,SAMPLE_SHAPE
INFO,Quartz,SAMPLE_HOLDER
INFO,Standard,SAMPLE_HOLDER_DETAIL
INFO,66.2,SAMPLE_OFFSET
DATATYPE,COMMENT,1
DATATYPE,TIME,2
STARTUPAXIS,X,2
STARTUPAXIS,Y1,5
FIELDGROUP, VSM,2,3,4,5,6,8,9,10,11,14,15
FIELDGROUP, DC, 2,3,4,14,56,57,58,59,60,61,62,63,64,65,66,67,68,69
FIELDGROUP, AC, 2,3,4,11,16,17,18,19,20,21,22,23,24,25,26,27,28,29,30
STARTUPGROUP, All
[Data]
Comment,Time Stamp (sec),Temperature (K),Magnetic Field (Oe),Moment (emu),M. Std. Err. (emu),Transport Action,Averaging Time (sec),Frequency (Hz),Peak Amplitude (mm),Center Position (mm),Lockin Signal' (V),Lockin Signal (V),Range,M. Quad. Signal (emu),AC Moment (emu),AC M. Std Err. (emu),AC Phase (deg),AC Phase Std. Err. (deg),AC Susceptibility (emu/Oe),AC Suscept. Std Err. (emu/Oe),AC X' (emu/Oe),AC X' Std Err. (emu/Oe),AC X'' (emu/Oe),AC X'' Std Err. (emu/Oe),AC Drive (Oe),AC Frequency (Hz),AC Averaging Time (sec),AC Cycles,AC Range,AC Measure Type,AC Signal' (V),AC Signal'' (V),AC Trim Coil Ratio,AC Trim Coil Phase,Min. Temperature (K),Max. Temperature (K),Min. Field (Oe),Max. Field (Oe),Mass (grams),Motor Lag (deg),Pressure (Torr),Measure Count,Measurement Number,SQUID Status (code),Motor Status (code),Measure Status (code),Motor Current (amps),Motor Temp. (C),Temp. Status (code),Field Status (code),Chamber Status (code),Chamber Temp (K),Redirection State,Average Temp (K),Rotation Angle (deg),Rotator state,DC Moment Fixed Ctr (emu),DC Moment Err Fixed Ctr (emu),DC Moment Free Ctr (emu),DC Moment Err Free Ctr (emu),DC Fixed Fit,DC Free Fit,DC Calculated Center (mm),DC Calculated Center Err (mm),DC Scan Length (mm),DC Scan Time (s),DC Number of Points,DC Squid Drift,DC Min V (V),DC Max V (V),DC Scans per Measure,Map 01,Map 02,Map 03,Map 04,Map 05,Map 06,Map 07,Map 08,Map 09,Map 10,Map 11,Map 12,Map 13,Map 14,Map 15,Map 16
,3768338881.96844,49.4756317138672,200.137786865234,,,5,,,,25.0300001353025,,,,,0.000578230079216457,1.58780517573195E-7,0.0592905975820957,0.000158120536015342,0.000578143298043626,1.58756687682581E-7,0.000578142988492883,1.29817482205536E-7,5.98271911170125E-7,9.13843925282641E-8,1.00015010322376,10.005763053894,2,20,10,5,1.89132946230097,0.168382552470229,0.0410455763339996,172.855895996094,49.4277420043945,49.4851036071777,200.137786865234,200.137786865234,,,20.3638591766357,0,1,,,,,,1,1,1,49.4699554443359,0,49.4509149439195,,,,,,,,,,,,,,,,,,,,,,,,,,,,,,,,,
,3768339088.27176,49.4990196228027,200.137786865234,,,5,,,,25.0300001353025,,,,,0.000583896282901295,1.07067837178984E-7,0.0103953970272022,0.000120028751510562,0.00058380836140791,1.07051715199081E-7,0.000583808351798932,8.09405935736098E-8,1.05922630303921E-7,7.0062044210949E-8,1.00015059992148,10.005763053894,2,20,10,5,1.91000743155591,0.168402568798702,0.0410455763339996,172.855895996094,49.4988021850586,49.4995460510254,200.137786865234,200.137786865234,,,20.5509910583496,0,1,,,,,,1,1,1,49.4992370605469,0,49.4991939067841,,,,,,,,,,,,,,,,,,,,,,,,,,,,,,,,,
,3768339293.52957,49.5001583099365,200.137786865234,,,5,,,,25.0300001353025,,,,,0.000586283201410018,9.49716098711984E-8,0.00835553473604467,0.00011000578278061,0.000586194957206065,9.49573152536977E-8,0.000586194950972804,6.97122275439551E-8,8.5485743475231E-8,6.44755539026224E-8,1.00015053729628,10.005763053894,2,20,10,5,1.91782139918545,0.16902270164871,0.0410455763339996,172.855895996094,49.4992523193359,49.5005569458008,200.137786865234,200.137786865234,,,20.5499420166016,0,1,,,,,,1,1,1,49.5003890991211,0,49.4999409843894,,,,,,,,,,,,,,,,,,,,,,,,,,,,,,,,,
,3768339501.19347,49.5000324249268,200.137786865234,,,5,,,,25.0300001353025,,,,,0.000588930113197556,8.32590034402905E-8,0.0066814633647736,8.78436761044732E-5,0.000588841473986661,8.32464722210518E-8,0.000588841469982917,6.52338975714758E-8,6.8666885425407E-8,5.17157011446672E-8,1.0001505315349,10.005763053894,2,20,10,5,1.9264848095846,0.169729506648811,0.0410455763339996,172.855895996094,49.4992332458496,49.5002326965332,200.137786865234,200.137786865234,,,20.5228004455566,0,1,,,,,,1,1,1,49.5001487731934,0,49.4997866013471,,,,,,,,,,,,,,,,,,,,,,,,,,,,,,,,,
,3768339706.2368,49.4996929168701,200.137786865234,,,5,,,,25.0300001353025,,,,,0.000590912555278661,7.54394945779744E-8,0.0042717531999239,8.59575191787097E-5,0.000590823626871624,7.54281414360915E-8,0.000590823625229542,5.57760980310868E-8,4.40495397355585E-8,5.07782572458885E-8,1.00015051599664,10.005763053894,2,20,10,5,1.93297685601673,0.17021955139215,0.0410455763339996,172.855895996094,49.4989891052246,49.4999122619629,200.137786865234,200.137786865234,,,20.4965896606445,0,1,,,,,,1,1,1,49.4997787475586,0,49.4995130651137,,,,,,,,,,,,,,,,,,,,,,,,,,,,,,,,,
,3768339911.17094,49.5001583099365,200.137786865234,,,5,,,,25.0300001353025,,,,,0.000592828741706998,1.25561095034086E-7,0.00685840241307289,0.000127364216316293,0.000592739512303415,1.25542196251293E-7,0.000592739508056882,1.00319813710531E-7,7.09519292056937E-8,7.54770032306695E-8,1.00015053729628,10.005763053894,2,20,10,5,1.939237320743,0.170859079505662,0.0410455763339996,172.855895996094,49.4995460510254,49.5004272460937,200.137786865234,200.137786865234,,,20.4701633453369,0,1,,,,,,1,1,1,49.5000190734863,0,49.5000350054573,,,,,,,,,,,,,,,,,,,,,,,,,,,,,,,,,
,3768340117.58156,49.5001945495605,200.137786865234,,,5,,,,25.0300001353025,,,,,0.000595041391830823,1.55392970638766E-7,0.0112024343209569,0.000179342852341588,0.000594951828404381,1.55369581464355E-7,0.000594951817032525,1.12950824557107E-7,1.16324601846936E-7,1.06685603884866E-7,1.00015053895486,10.005763053894,2,20,10,5,1.94646224397196,0.171644363528811,0.0410455763339996,172.855895996094,49.4992485046387,49.500301361084,200.137786865234,200.137786865234,,,20.4303665161133,0,1,,,,,,1,1,1,49.5000877380371,0,49.4997034072876,,,,,,,,,,,,,,,,,,,,,,,,,,,,,,,,,
,3768340321.50071,49.4999732971191,200.137786865234,,,5,,,,25.0300001353025,,,,,0.000596845506211595,1.22711362820948E-7,0.00914106641552248,9.99867607311825E-5,0.000596755677278414,1.22692894003311E-7,0.000596755669683637,1.07220998795225E-7,9.5207418470589E-8,5.96422975434558E-8,1.0001505288288,10.005763053894,2,20,10,5,1.95236994310728,0.172094532818654,0.0410455763339996,172.855895996094,49.499755859375,49.5004272460937,200.137786865234,200.137786865234,,,20.4038619995117,0,1,,,,,,1,1,1,49.500114440918,0,49.5000136880314,,,,,,,,,,,,,,,,,,,,,,,,,,,,,,,,,
,3768340529.22768,49.5008678436279,200.137786865234,,,5,,,,25.0300001353025,,,,,0.000598591021987091,8.16377494712918E-8,0.00615071211089369,9.31354459493246E-5,0.000598500905843646,8.16254591447221E-8,0.000598500902395065,5.96360101842013E-8,6.42491784589896E-8,5.57338485114435E-8,1.00015056976951,10.005763053894,2,20,10,5,1.95808878897085,0.17249563897076,0.0410455763339996,172.855895996094,49.4997329711914,49.5014533996582,200.137786865234,200.137786865234,,,20.3894653320313,0,1,,,,,,1,1,1,49.5003356933594,0,49.5003306070964,,,,,,,,,,,,,,,,,,,,,,,,,,,,,,,,,
,3768340734.49016,49.5010299682617,200.137786865234,,,5,,,,25.0300001353025,,,,,0.000600236015787078,1.4888190127151E-7,0.0102831518912954,0.000134461615796074,0.000600145647542199,1.48859486428417E-7,0.000600145637876486,1.25105232979253E-7,1.07711054285173E-7,8.06711062335146E-8,1.00015057718947,10.005763053894,2,20,10,5,1.96345735141653,0.173111288753663,0.0410455763339996,172.855895996094,49.4995231628418,49.5013771057129,200.137786865234,200.137786865234,,,20.384313583374,0,1,,,,,,1,1,1,49.500732421875,0,49.5002831851735,,,,,,,,,,,,,,,,,,,,,,,,,,,,,,,,,
,3768340940.64039,49.5002498626709,200.137786865234,,,5,,,,25.0300001353025,,,,,0.00060227167045169,8.77938684177476E-8,0.0099086711954115,0.00010871545345598,0.000602181017226289,8.77806537876513E-8,0.000602181008221312,5.84841643386054E-8,1.0414054439575E-7,6.54602604715448E-8,1.00015054148638,10.005763053894,2,20,10,5,1.97011740218961,0.173685509386916,0.0410455763339996,172.855895996094,49.4992866516113,49.5007667541504,200.137786865234,200.137786865234,,,20.3588485717773,0,1,,,,,,1,1,1,49.4997215270996,0,49.4999141693115,,,,,,,,,,,,,,,,,,,,,,,,,,,,,,,,,
,3768341147.33829,49.5002136230469,200.137786865234,,,5,,,,25.0300001353025,,,,,0.000603745158532481,8.63409740285618E-8,0.012715061232873,8.43392416239636E-5,0.00060365428452044,8.63279782295849E-8,0.000603654269655952,6.97265364194619E-8,1.33962766426976E-7,5.08992135907142E-8,1.0001505398278,10.005763053894,2,20,10,5,1.9749288635819,0.17420717317678,0.0410455763339996,172.855895996094,49.4987945556641,49.5011215209961,200.137786865234,200.137786865234,,,20.306489944458,0,1,,,,,,1,1,1,49.4998054504395,0,49.499376633588,,,,,,,,,,,,,,,,,,,,,,,,,,,,,,,,,
,3768341354.92431,49.4997863769531,200.137786865234,,,5,,,,25.0300001353025,,,,,0.00060529150595279,6.37844350051619E-8,0.00566867598798559,7.0023383861888E-5,0.000605200411021082,6.37748355994315E-8,0.000605200408059067,4.76642208862638E-8,5.98767494121271E-8,4.2371590754183E-8,1.00015052027403,10.005763053894,2,20,10,5,1.98000863119786,0.174409858355489,0.0410455763339996,172.855895996094,49.4994316101074,49.5002021789551,200.137786865234,200.137786865234,,,20.2799911499023,0,1,,,,,,1,1,1,49.4995384216309,0,49.4997951283174,,,,,,,,,,,,,,,,,,,,,,,,,,,,,,,,,
,3768341561.64839,49.5007171630859,200.137786865234,,,5,,,,25.0300001353025,,,,,0.000606981667755976,1.01382722080667E-7,0.00214058048125665,7.11120652903775E-5,0.000606890292609733,1.01367459904643E-7,0.00060689029218619,9.17327665196598E-8,2.26735289293987E-8,4.31330670619315E-8,1.00015056287332,10.005763053894,2,20,10,5,1.98554819627261,0.174774596568034,0.0410455763339996,172.855895996094,49.4993438720703,49.5009918212891,200.137786865234,200.137786865234,,,20.252513885498,0,1,,,,,,1,1,1,49.500919342041,0,49.5001326168285,,,,,,,,,,,,,,,,,,,,,,,,,,,,,,,,,
,3768341767.74508,49.4999027252197,200.137786865234,,,5,,,,25.0300001353025,,,,,0.000608649371515656,1.045336002433E-7,0.0126067236777248,0.000107755368133154,0.00060855776799314,1.04517867628675E-7,0.000608557753262181,8.13975550918138E-8,1.33900256289692E-7,6.55623571778842E-8,1.00015052559894,10.005763053894,2,20,10,5,1.99097151343996,0.175618492281554,0.0410455763339996,172.855895996094,49.4989852905273,49.5002746582031,200.137786865234,200.137786865234,,,20.213077545166,0,1,,,,,,1,1,1,49.4993858337402,0,49.4995498657227,,,,,,,,,,,,,,,,,,,,,,,,,,,,,,,,,
,3768341973.7392,49.4998016357422,200.137786865234,,,5,,,,25.0300001353025,,,,,0.000610116001179615,7.83891541555258E-8,0.0122785769734612,7.88618725262142E-5,0.000610024179746907,7.83773567195801E-8,0.000610024165739173,6.18842100291487E-8,1.30729154102058E-7,4.80973449934248E-8,1.00015052097238,10.005763053894,2,20,10,5,1.99577005870105,0.176030239825009,0.0410455763339996,172.855895996094,49.4994850158691,49.5003547668457,200.137786865234,200.137786865234,,,20.2099342346191,0,1,,,,,,1,1,1,49.4995727539063,0,49.4997551861931,,,,,,,,,,,,,,,,,,,,,,,,,,,,,,,,,
,3768342178.7463,49.4996795654297,200.137786865234,,,5,,,,25.0300001353025,,,,,0.000611666201340598,1.02948281002752E-7,0.00340503102860623,0.000119261789466843,0.000611574150021594,1.02932788034472E-7,0.000611574148941613,7.26399566896037E-8,3.63452417191696E-8,7.29287017893648E-8,1.00015051538558,10.005763053894,2,20,10,5,2.00086827561351,0.176167627005409,0.0410455763339996,172.855895996094,49.4987487792969,49.5003204345703,200.137786865234,200.137786865234,,,20.1696720123291,0,1,,,,,,1,1,1,49.4989738464355,0,49.4996897379557,,,,,,,,,,,,,,,,,,,,,,,,,,,,,,,,,
,3768342387.92563,49.4999141693115,200.137786865234,,,5,,,,25.0300001353025,,,,,0.000613067867300683,8.98307552498738E-8,0.00799714461643752,0.000123811592544627,0.000612975598460538,8.9817235409676E-8,0.000612975592489665,4.80393758346844E-8,8.55569909857031E-8,7.58904087882724E-8,1.0001505261227,10.005763053894,2,20,10,5,2.00543921492327,0.176732052118194,0.0410455763339996,172.855895996094,49.4997062683105,49.5007705688477,200.137786865234,200.137786865234,,,20.1081943511963,0,1,,,,,,1,1,1,49.5001258850098,0,49.5002524432014,,,,,,,,,,,,,,,,,,,,,,,,,,,,,,,,,
,3768342593.18672,49.5000476837158,200.137786865234,,,5,,,,25.0300001353025,,,,,0.00061445969475277,9.33570160573461E-8,0.010699332334176,8.46789176263042E-5,0.000614367212684207,9.33429649323764E-8,0.000614367201972316,7.75112361293382E-8,1.14726058383156E-7,5.2008820175705E-8,1.00015053223325,10.005763053894,2,20,10,5,2.00998374021299,0.177228076227815,0.0410455763339996,172.855895996094,49.4994354248047,49.5004425048828,200.137786865234,200.137786865234,,,20.0802669525146,0,1,,,,,,1,1,1,49.5001106262207,0,49.4999732971191,,,,,,,,,,,,,,,,,,,,,,,,,,,,,,,,,
,3768342799.81968,49.5011959075928,200.137786865234,,,5,,,,25.0300001353025,,,,,0.00061590458402294,9.12758087374608E-8,0.0125112642369967,0.000100761447233775,0.000615811852128193,9.12620660589546E-8,0.000615811837446533,6.69303007676698E-8,1.34470371229739E-7,6.2041111696183E-8,1.00015058478401,10.005763053894,2,20,10,5,2.01470455691247,0.17770853381222,0.0410455763339996,172.855895996094,49.5005989074707,49.5013236999512,200.137786865234,200.137786865234,,,20.0654926300049,0,1,,,,,,1,1,1,49.5012741088867,0,49.5009146796332,,,,,,,,,,,,,,,,,,,,,,,,,,,,,,,,,
,3768343007.55942,49.500940322876,200.137786865234,,,5,,,,25.0300001353025,,,,,0.000617105327062476,9.40847417270507E-8,0.00878531081736789,0.000109640624131466,0.000617012421597643,9.40705772298724E-8,0.000617012414344389,6.53745246588641E-8,9.46081182023841E-8,6.76420359391183E-8,1.00015057308667,10.005763053894,2,20,10,5,2.01864391926677,0.177923715602334,0.0410455763339996,172.855895996094,49.4998435974121,49.5014686584473,200.137786865234,200.137786865234,,,20.0501575469971,0,1,,,,,,1,1,1,49.5010833740234,0,49.5006260342068,,,,,,,,,,,,,,,,,,,,,,,,,,,,,,,,,
,3768343213.55988,49.5009231567383,200.137786865234,,,5,,,,25.0300001353025,,,,,0.000618592649135062,9.46709773692836E-8,0.009445253107498,9.84547487847015E-5,0.000618499520239116,9.46567246884397E-8,0.000618499511835015,7.24783560123748E-8,1.01960118855369E-7,6.08833592904212E-8,1.00015057230103,10.005763053894,2,20,10,5,2.02350711801598,0.178375847261994,0.0410455763339996,172.855895996094,49.4996337890625,49.501091003418,200.137786865234,200.137786865234,,,20.0233173370361,0,1,,,,,,1,1,1,49.5010604858398,0,49.5002816518148,,,,,,,,,,,,,,,,,,,,,,,,,,,,,,,,,
,3768343424.18861,49.5007915496826,200.137786865234,,,5,,,,25.0300001353025,,,,,0.000619776371350868,1.39898579744108E-7,0.0101264112232951,0.000173860904707956,0.000619683067977928,1.39877518906743E-7,0.000619683058299485,8.92183366668265E-8,1.095222998119E-7,1.07730258970779E-7,1.00015056627777,10.005763053894,2,20,10,5,2.02737712177964,0.178741285847648,0.0410455763339996,172.855895996094,49.4997177124023,49.500846862793,200.137786865234,200.137786865234,,,19.9961967468262,0,1,,,,,,1,1,1,49.5007781982422,0,49.5002918243408,,,,,,,,,,,,,,,,,,,,,,,,,,,,,,,,,
,3768343631.51288,49.5011043548584,200.137786865234,,,5,,,,25.0300001353025,,,,,0.00062100282898936,1.15257223186163E-7,0.00539370546763163,0.000156298618092099,0.000620909332093362,1.1523987029805E-7,0.000620909329342129,6.21521148724865E-8,5.84511125065389E-8,9.70429921384776E-8,1.00015058059392,10.005763053894,2,20,10,5,2.03140382676856,0.178927194134622,0.0410455763339996,172.855895996094,49.4998550415039,49.501277923584,200.137786865234,200.137786865234,,,19.9691410064697,0,1,,,,,,1,1,1,49.5012702941895,0,49.5005966635311,,,,,,,,,,,,,,,,,,,,,,,,,,,,,,,,,
,3768343840.64429,49.4995956420898,200.137786865234,,,5,,,,25.0300001353025,,,,,0.000622435774826486,8.28586533724471E-8,0.00365084902477619,8.44160287275789E-5,0.00062234210515493,8.28461840653138E-8,0.000622342103891527,6.40664046963853E-8,3.96552256632752E-8,5.2526050712602E-8,1.00015051154466,10.005763053894,2,20,10,5,2.03609668531657,0.179278135041497,0.0410455763339996,172.855895996094,49.4985504150391,49.5001182556152,200.137786865234,200.137786865234,,,19.9427280426025,0,1,,,,,,1,1,1,49.4993476867676,0,49.4994690838982,,,,,,,,,,,,,,,,,,,,,,,,,,,,,,,,,
,3768344047.55946,49.4999351501465,200.137786865234,,,5,,,,25.0300001353025,,,,,0.000623535782920188,9.81114950859605E-8,0.00755705685310204,0.000118977189653562,0.000623441938023881,9.80967288715186E-8,0.000623441932601049,6.4202382000676E-8,8.22292007654529E-8,7.41688773053193E-8,1.00015052708293,10.005763053894,2,20,10,5,2.03968275615225,0.179734023865574,0.0410455763339996,172.855895996094,49.499153137207,49.5003242492676,200.137786865234,200.137786865234,,,19.927490234375,0,1,,,,,,1,1,1,49.4996643066406,0,49.4997329711914,,,,,,,,,,,,,,,,,,,,,,,,,,,,,,,,,
,3768344253.88293,49.5000324249268,200.137786865234,,,5,,,,25.0300001353025,,,,,0.000624674468876034,1.14366698401327E-7,0.0111714419829996,0.000119033143625811,0.000624580449822251,1.14349485197805E-7,0.00062458043795004,8.68931407659568E-8,1.21779723986511E-7,7.43329459447874E-8,1.0001505315349,10.005763053894,2,20,10,5,2.04339621272733,0.180191151227838,0.0410455763339996,172.855895996094,49.4994316101074,49.5005989074707,200.137786865234,200.137786865234,,,19.9126396179199,0,1,,,,,,1,1,1,49.5003242492676,0,49.499922359691,,,,,,,,,,,,,,,,,,,,,,,,,,,,,,,,,
,3768344460.56283,49.4998435974121,200.137786865234,,,5,,,,25.0300001353025,,,,,0.000625549057281761,9.24473984583323E-8,0.00532464245501973,0.000109582215795336,0.000625454911999069,9.24334851027598E-8,0.000625454909298211,6.20266489940936E-8,5.8125115002175E-8,6.85320653621764E-8,1.00015052289284,10.005763053894,2,20,10,5,2.04627551456197,0.180234620041253,0.0410455763339996,172.855895996094,49.4995536804199,49.4999771118164,200.137786865234,200.137786865234,,,19.8982048034668,0,1,,,,,,1,1,1,49.4998817443848,0,49.4997962502872,,,,,,,,,,,,,,,,,,,,,,,,,,,,,,,,,
,3768344668.20822,49.500244140625,200.137786865234,,,5,,,,25.0300001353025,,,,,0.000626947320756296,8.98539962759241E-8,0.0106811515579786,0.000101887433128755,0.00062685295354509,8.98404715813229E-8,0.000626852942652615,6.31909736634435E-8,1.16858718382066E-7,6.38608736349612E-8,1.0001505412245,10.005763053894,2,20,10,5,2.05083257176742,0.18082921897771,0.0410455763339996,172.855895996094,49.4995193481445,49.5008316040039,200.137786865234,200.137786865234,,,19.8595390319824,0,1,,,,,,1,1,1,49.5005683898926,0,49.5001312704647,,,,,,,,,,,,,,,,,,,,,,,,,,,,,,,,,
,3768344873.24215,49.4979057312012,200.137786865234,,,5,,,,25.0300001353025,,,,,0.000627901456735885,9.7037709850363E-8,0.00951310735074351,0.000105841427515899,0.000627806941065131,9.70231031248385E-8,0.000627806932411554,7.07062854779521E-8,1.04237953462E-7,6.64387216454635E-8,1.00015054894199,10.005763053894,2,20,10,5,2.05395737518749,0.181062554296318,0.0410455763339996,172.855895996094,49.4971618652344,49.502815246582,200.137786865234,200.137786865234,,,19.8446407318115,0,1,,,,,,1,1,1,49.4982833862305,0,49.4999519796932,,,,,,,,,,,,,,,,,,,,,,,,,,,,,,,,,
,3768345078.25796,49.5001850128174,200.137786865234,,,5,,,,25.0300001353025,,,,,0.000629071092684163,1.33249327636757E-7,0.00806077082309908,0.000153778016555856,0.000628976407507672,1.33229271499618E-7,0.00062897640128306,9.16338236121027E-8,8.84887979606391E-8,9.67123629870817E-8,1.00015053851839,10.005763053894,2,20,10,5,2.05778802331705,0.181347664241859,0.0410455763339996,172.855895996094,49.4998626708984,49.5004501342773,200.137786865234,200.137786865234,,,19.8308525085449,0,1,,,,,,1,1,1,49.5002784729004,0,49.5001148897059,,,,,,,,,,,,,,,,,,,,,,,,,,,,,,,,,
,3768345285.97072,49.499755859375,200.137786865234,,,5,,,,25.0300001353025,,,,,0.000630142701843773,8.90721235050535E-8,0.00586601904254724,0.000114666158394051,0.000630047867746056,8.90587184867306E-8,0.000630047864443994,5.20835540331681E-8,6.45051488061895E-8,7.22409768605934E-8,1.00015051887733,10.005763053894,2,20,10,5,2.0613003780523,0.181577628321187,0.0410455763339996,172.855895996094,49.499382019043,49.5002975463867,200.137786865234,200.137786865234,,,19.804313659668,0,1,,,,,,1,1,1,49.4998512268066,0,49.499731487698,,,,,,,,,,,,,,,,,,,,,,,,,,,,,,,,,
,3768345491.29004,49.5012073516846,200.137786865234,,,5,,,,25.0300001353025,,,,,0.00063103119778215,1.068102586179E-7,0.00474960310765127,0.000102131684645382,0.000630936188062083,1.0679417698389E-7,0.000630936185894255,8.51731776132851E-8,5.23022201911569E-8,6.44245764667669E-8,1.00015058530778,10.005763053894,2,20,10,5,2.06421033745088,0.181793424901346,0.0410455763339996,172.855895996094,49.4998092651367,49.5014381408691,200.137786865234,200.137786865234,,,19.777904510498,0,1,,,,,,1,1,1,49.5012512207031,0,49.5006897870232,,,,,,,,,,,,,,,,,,,,,,,,,,,,,,,,,
,3768345696.42206,49.4997634887695,200.137786865234,,,5,,,,25.0300001353025,,,,,0.000632078953450581,1.34151054571858E-7,0.00683179251752541,0.000102158665805977,0.000631983827733668,1.34130865297763E-7,0.000631983823241044,1.17585393908382E-7,7.5356028174662E-8,6.45349840391809E-8,1.0001505192265,10.005763053894,2,20,10,5,2.06763110510621,0.182170416471069,0.0410455763339996,172.855895996094,49.4993209838867,49.5005302429199,200.137786865234,200.137786865234,,,19.7634544372559,0,1,,,,,,1,1,1,49.500072479248,0,49.4998088163488,,,,,,,,,,,,,,,,,,,,,,,,,,,,,,,,,
,3768345901.43348,49.5002975463867,200.137786865234,,,5,,,,25.0300001353025,,,,,0.000633054033745295,7.89731477227775E-8,0.00724067512617044,9.98331182890559E-5,0.000632958745813553,7.89612606049195E-8,0.000632958740759285,4.73537094042366E-8,7.99892884511505E-8,6.31862871355576E-8,1.00015054366872,10.005763053894,2,20,10,5,2.07081944639026,0.1824662190943,0.0410455763339996,172.855895996094,49.4999351501465,49.5007057189941,200.137786865234,200.137786865234,,,19.749174118042,0,1,,,,,,1,1,1,49.5005569458008,0,49.5002250671387,,,,,,,,,,,,,,,,,,,,,,,,,,,,,,,,,
,3768346109.12935,49.5004615783691,200.137786865234,,,5,,,,25.0300001353025,,,,,0.000633860277752226,1.14712793277111E-7,0.0050017206560371,9.21929054113455E-5,0.000633764863706707,1.14695525730834E-7,0.000633764861291848,9.87097958994399E-8,5.53254503697334E-8,5.84075321868957E-8,1.00015055117597,10.005763053894,2,20,10,5,2.07346393522591,0.182617579750001,0.0410455763339996,172.855895996094,49.4996795654297,49.5007057189941,200.137786865234,200.137786865234,,,19.7236289978027,0,1,,,,,,1,1,1,49.5004234313965,0,49.5002717410817,,,,,,,,,,,,,,,,,,,,,,,,,,,,,,,,,
,3768346317.91139,49.5004577636719,200.137786865234,,,5,,,,25.0300001353025,,,,,0.000634915154865564,1.10567044216388E-7,0.00821624570780966,9.53706366527173E-5,0.000634819582141775,1.10550400742853E-7,0.000634819575614651,9.25101365829919E-8,9.10334704136244E-8,6.0524918288268E-8,1.00015055100138,10.005763053894,2,20,10,5,2.07690435041833,0.183038016430728,0.0410455763339996,172.855895996094,49.4995040893555,49.5007629394531,200.137786865234,200.137786865234,,,19.7093887329102,0,1,,,,,,1,1,1,49.500560760498,0,49.5002573798684,,,,,,,,,,,,,,,,,,,,,,,,,,,,,,,,,
,3768346524.37393,49.5001678466797,200.137786865234,,,5,,,,25.0300001353025,,,,,0.000635754579762714,9.56486151729521E-8,0.00972883289051207,0.000114779826133104,0.000635658816190551,9.56342076431396E-8,0.000635658807026863,6.1834468054167E-8,1.07934972190565E-7,7.2954782105009E-8,1.00015065247224,10.005763053894,2,20,10,5,2.07964539804324,0.183334914493934,0.0410455763339996,172.855895996094,49.4997215270996,49.5004692077637,200.137786865234,200.137786865234,,,19.6829090118408,0,1,,,,,,1,1,1,49.5004081726074,0,49.5000020195456,,,,,,,,,,,,,,,,,,,,,,,,,,,,,,,,,
,3768346730.8018,49.4990100860596,200.137786865234,,,5,,,,25.0300001353025,,,,,0.000636654095137947,8.81186356653517E-8,0.00532992705866242,8.74524751668961E-5,0.000636558229796362,8.81053670424487E-8,0.000636558227042099,6.82987532620004E-8,5.92156866936047E-8,5.56582069828071E-8,1.00015059948501,10.005763053894,2,20,10,5,2.08260193229035,0.183434422817895,0.0410455763339996,172.855895996094,49.4983558654785,49.5001525878906,200.137786865234,200.137786865234,,,19.7036323547363,0,1,,,,,,1,1,1,49.4993591308594,0,49.4994636984432,,,,,,,,,,,,,,,,,,,,,,,,,,,,,,,,,
,3768346939.0688,49.5002822875977,200.137786865234,,,5,,,,25.0300001353025,,,,,0.000637575168273931,7.65198674485014E-8,0.00724810277337884,7.97397359869476E-5,0.000637479200261576,7.65083496542864E-8,0.000637479195160762,5.71874171453511E-8,8.06431954732113E-8,5.08244713407444E-8,1.00015054297037,10.005763053894,2,20,10,5,2.08560876563929,0.183769623838466,0.0410455763339996,172.855895996094,49.4994850158691,49.5005874633789,200.137786865234,200.137786865234,,,19.6657791137695,0,1,,,,,,1,1,1,49.5004920959473,0,49.5000316395479,,,,,,,,,,,,,,,,,,,,,,,,,,,,,,,,,
,3768347148.04664,49.5001354217529,200.137786865234,,,5,,,,25.0300001353025,,,,,0.000638550301836962,7.385922618224E-8,0.00740893745320381,8.36325964422671E-5,0.000638454191337993,7.38481093648782E-8,0.000638454186000143,5.10203796602364E-8,8.25587363916805E-8,5.33897379286726E-8,1.00015053624876,10.005763053894,2,20,10,5,2.08879806424971,0.184056553849089,0.0410455763339996,172.855895996094,49.4994049072266,49.5003395080566,200.137786865234,200.137786865234,,,19.6640701293945,0,1,,,,,,1,1,1,49.5,0,49.4999798668755,,,,,,,,,,,,,,,,,,,,,,,,,,,,,,,,,
,3768347354.83452,49.4995670318604,200.137786865234,,,5,,,,25.0300001353025,,,,,0.000639333190060797,1.0257560291147E-7,0.00911918135218048,9.63013119702676E-5,0.000639236978352798,1.02560166556674E-7,0.000639236970256279,8.2041168812936E-8,1.01740790640205E-7,6.1545384749305E-8,1.00015051023526,10.005763053894,2,20,10,5,2.09135351235087,0.184344643288774,0.0410455763339996,172.855895996094,49.4986534118652,49.5001335144043,200.137786865234,200.137786865234,,,19.6504535675049,0,1,,,,,,1,1,1,49.4991569519043,0,49.4994895037483,,,,,,,,,,,,,,,,,,,,,,,,,,,,,,,,,
,3768347560.99734,49.4996128082275,200.137786865234,,,5,,,,25.0300001353025,,,,,0.000640187866526417,9.99620825593288E-8,0.00660182093653727,7.78610750839119E-5,0.0006400915248594,9.99470392975369E-8,0.000640091520610326,8.66457824497936E-8,7.37535933131243E-8,4.98188623716602E-8,1.00015051233031,10.005763053894,2,20,10,5,2.09415739383892,0.184499070279457,0.0410455763339996,172.855895996094,49.4987640380859,49.5001029968262,200.137786865234,200.137786865234,,,19.635871887207,0,1,,,,,,1,1,1,49.4992408752441,0,49.4994915856255,,,,,,,,,,,,,,,,,,,,,,,,,,,,,,,,,
,3768347765.30053,49.5005035400391,200.137786865234,,,5,,,,25.0300001353025,,,,,0.000640999646241126,9.73234647566979E-8,0.0114572942752993,9.92665460229522E-5,0.000640903156286436,9.7308814613348E-8,0.000640903143472537,7.36399258328266E-8,1.28159806481517E-7,6.36094861226745E-8,1.00015055309643,10.005763053894,2,20,10,5,2.09679719359475,0.18491070855407,0.0410455763339996,172.855895996094,49.4997253417969,49.5007514953613,200.137786865234,200.137786865234,,,19.6342258453369,0,1,,,,,,1,1,1,49.5004539489746,0,49.5001685198616,,,,,,,,,,,,,,,,,,,,,,,,,,,,,,,,,
,3768347971.86518,49.4998149871826,200.137786865234,,,5,,,,25.0300001353025,,,,,0.000641790856111451,8.73438523125736E-8,0.00704473467229594,8.64670902465031E-5,0.000641694267274262,8.73307071562503E-8,0.00064169426242381,6.7447421457748E-8,7.88987580011596E-8,5.54751994238116E-8,1.00015052158343,10.005763053894,2,20,10,5,2.0993996007705,0.184977270342949,0.0410455763339996,172.855895996094,49.4992294311523,49.500415802002,200.137786865234,200.137786865234,,,19.5963249206543,0,1,,,,,,1,1,1,49.5000267028809,0,49.4996930290671,,,,,,,,,,,,,,,,,,,,,,,,,,,,,,,,,
,3768348179.82557,49.5014495849609,200.137786865234,,,5,,,,25.0300001353025,,,,,0.000642786638480053,1.15549438276288E-7,0.00615899069984316,0.000152499150362981,0.0006426899254367,1.15532052821824E-7,0.000642689921723526,6.11763232175725E-8,6.9085738943836E-8,9.80056769111046E-8,1.00015048165457,10.005763053894,2,20,10,5,2.10265982690914,0.185231765199113,0.0410455763339996,172.855895996094,49.4998207092285,49.5018539428711,200.137786865234,200.137786865234,,,19.5944976806641,0,1,,,,,,1,1,1,49.5013275146484,0,49.5006448957655,,,,,,,,,,,,,,,,,,,,,,,,,,,,,,,,,
,3768348390.6914,49.5007076263428,200.137786865234,,,5,,,,25.0300001353025,,,,,0.000643543345158611,9.77473952323487E-8,0.0093616787401043,9.35340703679645E-5,0.000643446466290666,9.77326803618338E-8,0.000643446457701626,7.70133255620934E-8,1.05134080175845E-7,6.01716253443048E-8,1.00015056243685,10.005763053894,2,20,10,5,2.10512476812811,0.185567498460469,0.0410455763339996,172.855895996094,49.5002021789551,49.5012512207031,200.137786865234,200.137786865234,,,19.5691146850586,0,1,,,,,,1,1,1,49.5008392333984,0,49.5006523132324,,,,,,,,,,,,,,,,,,,,,,,,,,,,,,,,,
,3768348597.39144,49.4997539520264,200.137786865234,,,5,,,,25.0300001353025,,,,,0.000644164540762273,1.22697252973389E-7,0.00447843016139782,0.000116985705918982,0.000644067596486949,1.2267878751073E-7,0.00064406759451948,9.68260397034211E-8,5.03424819709538E-8,7.53312879251003E-8,1.00015051879004,10.005763053894,2,20,10,5,2.10717261307908,0.185567035059361,0.0410455763339996,172.855895996094,49.4991607666016,49.5003089904785,200.137786865234,200.137786865234,,,19.555004119873,0,1,,,,,,1,1,1,49.4996871948242,0,49.4996975792779,,,,,,,,,,,,,,,,,,,,,,,,,,,,,,,,,
,3768348803.79191,49.5007514953613,200.137786865234,,,5,,,,25.0300001353025,,,,,0.000645022450633912,1.15968530862924E-7,0.0101348351459229,0.000125633164260432,0.000644925347807111,1.15951072754054E-7,0.000644925337717659,8.29544506277393E-8,1.14078420835076E-7,8.10136432575764E-8,1.0001505644446,10.005763053894,2,20,10,5,2.10996062929788,0.186022474540393,0.0410455763339996,172.855895996094,49.4997100830078,49.5008964538574,200.137786865234,200.137786865234,,,19.5421028137207,0,1,,,,,,1,1,1,49.5008811950684,0,49.500296200023,,,,,,,,,,,,,,,,,,,,,,,,,,,,,,,,,
,3768349013.9863,49.4998531341553,200.137786865234,,,5,,,,25.0300001353025,,,,,0.000645550280496875,9.19558932634998E-8,0.000260595745308123,9.69485381450835E-5,0.000645453124743629,9.19420538394529E-8,0.000645453124736953,6.73699680521841E-8,2.9356846094578E-9,6.2566993445942E-8,1.0001505233293,10.005763053894,2,20,10,5,2.11171928941544,0.185810777031089,0.0410455763339996,172.855895996094,49.4995536804199,49.5004653930664,200.137786865234,200.137786865234,,,19.5746479034424,0,1,,,,,,1,1,1,49.4995918273926,0,49.4999631245931,,,,,,,,,,,,,,,,,,,,,,,,,,,,,,,,,
,3768349220.80465,49.5005397796631,200.137786865234,,,5,,,,25.0300001353025,,,,,0.000646574509895412,8.84619941663633E-8,0.0101567947477976,7.77354257313012E-5,0.000646477179682007,8.84486777973468E-8,0.000646477169524402,7.27946726374463E-8,1.14600692137829E-7,5.02404641669032E-8,1.00015055475501,10.005763053894,2,20,10,5,2.11503756545303,0.186470894882437,0.0410455763339996,172.855895996094,49.4996223449707,49.5011100769043,200.137786865234,200.137786865234,,,19.5610599517822,0,1,,,,,,1,1,1,49.5007057189941,0,49.5002398771398,,,,,,,,,,,,,,,,,,,,,,,,,,,,,,,,,
,3768349426.58494,49.5008411407471,200.137786865234,,,5,,,,25.0300001353025,,,,,0.000647056613823339,1.38607773205334E-7,0.00487507514204832,0.000158404447772961,0.000646959202116049,1.38586906376152E-7,0.000646959199774171,9.33059700647993E-8,5.50472433947707E-8,1.02471101141635E-7,1.0001505685474,10.005763053894,2,20,10,5,2.11663178957701,0.186414815498581,0.0410455763339996,172.855895996094,49.4997863769531,49.5013160705566,200.137786865234,200.137786865234,,,19.5477962493896,0,1,,,,,,1,1,1,49.5006370544434,0,49.5003242492676,,,,,,,,,,,,,,,,,,,,,,,,,,,,,,,,,
,3768349634.45109,49.4995155334473,200.137786865234,,,5,,,,25.0300001353025,,,,,0.000647772359926979,1.24701922793217E-7,0.00584678102977865,0.000113298468024694,0.000647674879754978,1.24683156995794E-7,0.000647674876382761,1.00815348037737E-7,6.6092358390529E-8,7.33631735850337E-8,1.00015050787833,10.005763053894,2,20,10,5,2.11896995055853,0.186656961343486,0.0410455763339996,172.855895996094,49.4986190795898,49.4999885559082,200.137786865234,200.137786865234,,,19.5219974517822,0,1,,,,,,1,1,1,49.4992141723633,0,49.4994749181411,,,,,,,,,,,,,,,,,,,,,,,,,,,,,,,,,
,3768349841.55382,49.5011520385742,200.137786865234,,,5,,,,25.0300001353025,,,,,0.000648504262662541,1.58754148908958E-7,0.00776158192001919,0.000215154724357741,0.000648406623792984,1.58730246867708E-7,0.000648406617843591,7.5722598584574E-8,8.78365065529996E-8,1.39504047734405E-7,1.00015058277626,10.005763053894,2,20,10,5,2.12135787930581,0.186938747545764,0.0410455763339996,172.855895996094,49.5000038146973,49.5015563964844,200.137786865234,200.137786865234,,,19.5205669403076,0,1,,,,,,1,1,1,49.5014305114746,0,49.5006983015272,,,,,,,,,,,,,,,,,,,,,,,,,,,,,,,,,
,3768350048.54365,49.4999866485596,200.137786865234,,,5,,,,25.0300001353025,,,,,0.000649274988028723,9.32990862437537E-8,0.0089452438536215,0.000117885504762451,0.000649177267738242,9.32850440983185E-8,0.000649177259826495,5.33486188104536E-8,1.01352123837142E-7,7.6524664804507E-8,1.00015052943986,10.005763053894,2,20,10,5,2.12387517395524,0.187204799286037,0.0410455763339996,172.855895996094,49.499755859375,49.500244140625,200.137786865234,200.137786865234,,,19.5079498291016,0,1,,,,,,1,1,1,49.5001678466797,0,49.500027762519,,,,,,,,,,,,,,,,,,,,,,,,,,,,,,,,,
,3768350256.67147,49.4998664855957,200.137786865234,,,5,,,,25.0300001353025,,,,,0.000649749043682337,1.12832750455301E-7,0.0107484946502669,0.000135991384899097,0.000649651255615483,1.12815768981219E-7,0.000649651244184059,7.01662567823185E-8,1.21872379849043E-7,8.83407841259148E-8,1.00015052394036,10.005763053894,2,20,10,5,2.12541998326304,0.187408377571059,0.0410455763339996,172.855895996094,49.4993667602539,49.5004997253418,200.137786865234,200.137786865234,,,19.482458114624,0,1,,,,,,1,1,1,49.4997367858887,0,49.4997821134679,,,,,,,,,,,,,,,,,,,,,,,,,,,,,,,,,
,3768350467.43598,49.5006122589111,200.137786865234,,,5,,,,25.0300001353025,,,,,0.000650701869693177,1.07817292305219E-7,0.00344752064687537,7.62045430127927E-5,0.000650603916021837,1.07801061985149E-7,0.000650603914844082,9.57355228634565E-8,3.91472190644979E-8,4.95558132532052E-8,1.00015055807217,10.005763053894,2,20,10,5,2.12856070910898,0.187411967435038,0.0410455763339996,172.855895996094,49.4995765686035,49.5007514953613,200.137786865234,200.137786865234,,,19.4929141998291,0,1,,,,,,1,1,1,49.5005722045898,0,49.5001391242532,,,,,,,,,,,,,,,,,,,,,,,,,,,,,,,,,
,3768350674.12592,49.5008926391602,200.137786865234,,,5,,,,25.0300001353025,,,,,0.000651355435346836,1.20485458476148E-7,0.00710393543500132,8.38314504892422E-5,0.000651257374934942,1.20467319602894E-7,0.00065125736992912,1.07399554889318E-7,8.07474890920409E-8,5.45684038788218E-8,1.00015057090433,10.005763053894,2,20,10,5,2.13068666160827,0.187736175624217,0.0410455763339996,172.855895996094,49.5000305175781,49.5013847351074,200.137786865234,200.137786865234,,,19.4916343688965,0,1,,,,,,1,1,1,49.5010871887207,0,49.5005410138298,,,,,,,,,,,,,,,,,,,,,,,,,,,,,,,,,
,3768350881.46342,49.5001049041748,200.137786865234,,,5,,,,25.0300001353025,,,,,0.000651628346176247,1.05128550993581E-7,0.00579046245003756,9.23506370587534E-5,0.000651530268163715,1.05112727864642E-7,0.000651530264836462,8.61987277907949E-8,6.58453655488075E-8,6.01536772474868E-8,1.00015053485206,10.005763053894,2,20,10,5,2.13158370067669,0.18776597432671,0.0410455763339996,172.855895996094,49.4995765686035,49.5003929138184,200.137786865234,200.137786865234,,,19.4920883178711,0,1,,,,,,1,1,1,49.4998397827148,0,49.4998642416561,,,,,,,,,,,,,,,,,,,,,,,,,,,,,,,,,
,3768351090.74791,49.5004329681396,200.137786865234,,,5,,,,25.0300001353025,,,,,0.000652377635269984,9.66831973778005E-8,0.00228687842255493,8.18648257034636E-5,0.000652279434688128,9.66686439263564E-8,0.000652279434168558,8.05915606390704E-8,2.6034793085029E-8,5.33837716194699E-8,1.00015054986657,10.005763053894,2,20,10,5,2.13404623973738,0.187851386164655,0.0410455763339996,172.855895996094,49.499382019043,49.500804901123,200.137786865234,200.137786865234,,,19.4799251556396,0,1,,,,,,1,1,1,49.4999389648438,0,49.5001160471063,,,,,,,,,,,,,,,,,,,,,,,,,,,,,,,,,
,3768351301.60078,49.4994792938232,200.137786865234,,,5,,,,25.0300001353025,,,,,0.000653038178366785,1.13345984079438E-7,0.00195601607968143,8.79457668605943E-5,0.000652939906849679,1.1332892737099E-7,0.00065293990646919,9.77157173343804E-8,2.22906637708625E-8,5.7402825408569E-8,1.00015050621975,10.005763053894,2,20,10,5,2.13620808231191,0.188029255362238,0.0410455763339996,172.855895996094,49.4988670349121,49.500545501709,200.137786865234,200.137786865234,,,19.4461784362793,0,1,,,,,,1,1,1,49.4992866516113,0,49.4998292361989,,,,,,,,,,,,,,,,,,,,,,,,,,,,,,,,,
,3768351510.89987,49.5009117126465,200.137786865234,,,5,,,,25.0300001353025,,,,,0.000653655880952155,8.39263376218275E-8,0.0138368654256489,0.000101051780589325,0.000653557473641804,8.39137025864922E-8,0.000653557454583513,5.17724758502653E-8,1.57833383185607E-7,6.60387781996909E-8,1.00015057177726,10.005763053894,2,20,10,5,2.13818962894777,0.188650485291801,0.0410455763339996,172.855895996094,49.4992942810059,49.5014533996582,200.137786865234,200.137786865234,,,19.4688167572021,0,1,,,,,,1,1,1,49.5003929138184,0,49.5001583099365,,,,,,,,,,,,,,,,,,,,,,,,,,,,,,,,,
,3768351718.69086,49.499963760376,200.137786865234,,,5,,,,25.0300001353025,,,,,0.000654227798301016,9.88612628336392E-8,0.0086634923246276,9.4388535239193E-5,0.000654129333264102,9.88463836464209E-8,0.000654129325786293,7.72010415201975E-8,9.89085842729256E-8,6.17301121671762E-8,1.00015052839233,10.005763053894,2,20,10,5,2.14007748144282,0.188622314747213,0.0410455763339996,172.855895996094,49.4994506835937,49.5001106262207,200.137786865234,200.137786865234,,,19.4705104827881,0,1,,,,,,1,1,1,49.5000305175781,0,49.4997890696806,,,,,,,,,,,,,,,,,,,,,,,,,,,,,,,,,
,3768351926.53785,49.500602722168,200.137786865234,,,5,,,,25.0300001353025,,,,,0.000654672515583547,1.13464386546024E-7,0.00967934916552515,0.000126730294451514,0.000654573964475067,1.13447306187828E-7,0.000654573955134445,7.73969724440763E-8,1.10581442132793E-7,8.29457650381602E-8,1.0001505576357,10.005763053894,2,20,10,5,2.14152887192928,0.188788498677955,0.0410455763339996,172.855895996094,49.5002899169922,49.5012435913086,200.137786865234,200.137786865234,,,19.4720211029053,0,1,,,,,,1,1,1,49.5009078979492,0,49.5007158915202,,,,,,,,,,,,,,,,,,,,,,,,,,,,,,,,,
,3768352136.86483,49.5011157989502,200.137786865234,,,5,,,,25.0300001353025,,,,,0.000655441157697495,1.2278608479129E-7,0.00665267360117738,0.000166347411748856,0.000655342550677425,1.22767612393295E-7,0.000655342546259833,5.64649728004392E-8,7.60925170034247E-8,1.09011896137054E-7,1.00015046637818,10.005763053894,2,20,10,5,2.14405319343368,0.188896892709936,0.0410455763339996,172.855895996094,49.500129699707,49.5015525817871,200.137786865234,200.137786865234,,,19.4961605072021,0,1,,,,,,1,1,1,49.5008163452148,0,49.5006790161133,,,,,,,,,,,,,,,,,,,,,,,,,,,,,,,,,
,3768352343.89507,49.5008029937744,200.137786865234,,,5,,,,25.0300001353025,,,,,0.000656047720092931,9.52598016037525E-8,0.00764216968218623,9.5175159530666E-5,0.000655948955956667,9.52454607993599E-8,0.000655948950121838,7.19407600147021E-8,8.74911424892226E-8,6.24197472871321E-8,1.00015056680153,10.005763053894,2,20,10,5,2.14603409076637,0.189108764853758,0.0410455763339996,172.855895996094,49.4999504089355,49.5012168884277,200.137786865234,200.137786865234,,,19.5095405578613,0,1,,,,,,1,1,1,49.5008010864258,0,49.5005393558078,,,,,,,,,,,,,,,,,,,,,,,,,,,,,,,,,
,3768352550.81753,49.4998588562012,200.137786865234,,,5,,,,25.0300001353025,,,,,0.000656417911906876,1.46672064115842E-7,0.00701435572786746,0.000164501242466732,0.000656319120395911,1.46649989832725E-7,0.000656319115477607,9.92575083091913E-8,8.03489508142089E-8,1.07954465225804E-7,1.00015052359118,10.005763053894,2,20,10,5,2.14724711867841,0.189191948856844,0.0410455763339996,172.855895996094,49.4996376037598,49.5002593994141,200.137786865234,200.137786865234,,,19.4986362457275,0,1,,,,,,1,1,1,49.5000457763672,0,49.4998705246869,,,,,,,,,,,,,,,,,,,,,,,,,,,,,,,,,
,3768352706.17783,49.4990577697754,200.137786865234,,,5,,,,25.0300001353025,,,,,0.000656864478252026,9.43466305267307E-8,0.00735088917634741,8.80805233109284E-5,0.000656765568262389,9.43324239064053E-8,0.00065676556285715,7.45223755508689E-8,8.42611957620871E-8,5.78361629286815E-8,1.00015060166735,10.005763053894,2,20,10,5,2.14870679576414,0.189333280944752,0.0410455763339996,172.855895996094,49.4982147216797,49.5015754699707,200.137786865234,200.137786865234,,,19.4987201690674,0,1,,,,,,1,1,1,49.499340057373,0,49.499927520752,,,,,,,,,,,,,,,,,,,,,,,,,,,,,,,,,