File: Experimental_Data/Fig3C/Lifetime_200Oe_49K.dat
[Header]
; MPMS3 Data File (default extension .dat)
; Copyright (c) 2007, Quantum Design, Inc. All rights reserved.
TITLE,200Oe_49K
FILEOPENTIME,3767907786.32641,05/25/2019,1:03 am
BYAPP,SQUID AC,0.9.1.0
INFO,MPMS3 Measurement Release 1.1.16 Build 347, MultiVu Release 2.3.3.2,APPNAME
INFO,0,MOMENT_UNITS
INFO,,SAMPLE_MATERIAL
INFO,,SAMPLE_COMMENT
INFO,,SAMPLE_MASS
INFO,,SAMPLE_VOLUME
INFO,,SAMPLE_MOLECULAR_WEIGHT
INFO,,SAMPLE_SIZE
INFO,,SAMPLE_SHAPE
INFO,Quartz,SAMPLE_HOLDER
INFO,Standard,SAMPLE_HOLDER_DETAIL
INFO,66.2,SAMPLE_OFFSET
DATATYPE,COMMENT,1
DATATYPE,TIME,2
STARTUPAXIS,X,2
STARTUPAXIS,Y1,5
FIELDGROUP, VSM,2,3,4,5,6,8,9,10,11,14,15
FIELDGROUP, DC, 2,3,4,14,56,57,58,59,60,61,62,63,64,65,66,67,68,69
FIELDGROUP, AC, 2,3,4,11,16,17,18,19,20,21,22,23,24,25,26,27,28,29,30
STARTUPGROUP, All
[Data]
Comment,Time Stamp (sec),Temperature (K),Magnetic Field (Oe),Moment (emu),M. Std. Err. (emu),Transport Action,Averaging Time (sec),Frequency (Hz),Peak Amplitude (mm),Center Position (mm),Lockin Signal' (V),Lockin Signal (V),Range,M. Quad. Signal (emu),AC Moment (emu),AC M. Std Err. (emu),AC Phase (deg),AC Phase Std. Err. (deg),AC Susceptibility (emu/Oe),AC Suscept. Std Err. (emu/Oe),AC X' (emu/Oe),AC X' Std Err. (emu/Oe),AC X'' (emu/Oe),AC X'' Std Err. (emu/Oe),AC Drive (Oe),AC Frequency (Hz),AC Averaging Time (sec),AC Cycles,AC Range,AC Measure Type,AC Signal' (V),AC Signal'' (V),AC Trim Coil Ratio,AC Trim Coil Phase,Min. Temperature (K),Max. Temperature (K),Min. Field (Oe),Max. Field (Oe),Mass (grams),Motor Lag (deg),Pressure (Torr),Measure Count,Measurement Number,SQUID Status (code),Motor Status (code),Measure Status (code),Motor Current (amps),Motor Temp. (C),Temp. Status (code),Field Status (code),Chamber Status (code),Chamber Temp (K),Redirection State,Average Temp (K),Rotation Angle (deg),Rotator state,DC Moment Fixed Ctr (emu),DC Moment Err Fixed Ctr (emu),DC Moment Free Ctr (emu),DC Moment Err Free Ctr (emu),DC Fixed Fit,DC Free Fit,DC Calculated Center (mm),DC Calculated Center Err (mm),DC Scan Length (mm),DC Scan Time (s),DC Number of Points,DC Squid Drift,DC Min V (V),DC Max V (V),DC Scans per Measure,Map 01,Map 02,Map 03,Map 04,Map 05,Map 06,Map 07,Map 08,Map 09,Map 10,Map 11,Map 12,Map 13,Map 14,Map 15,Map 16
,3767907790.77868,48.9707355499268,200.113494873047,,,5,,,,25.0300001353025,,,,,0.000583340436178536,1.62273044975906E-7,0.0333329686069774,0.000165466504734289,0.000583252847674443,1.62248679695561E-7,0.000583252748971619,1.30444248037395E-7,3.39319020179091E-7,9.6482807882603E-8,1.00015017244141,10.005763053894,2,20,10,5,1.90812151310946,0.169007900048421,0.0410455763339996,172.855895996094,48.917552947998,48.9813270568848,200.113494873047,200.113494873047,,,125.993057250977,0,1,,,,,,1,1,1,48.9661560058594,0,48.9447631835937,,,,,,,,,,,,,,,,,,,,,,,,,,,,,,,,,
,3767907996.27525,48.9999351501465,200.113494873047,,,5,,,,25.0300001353025,,,,,0.000585512095126487,1.60139356540967E-7,0.00886986920423105,8.6145659548722E-5,0.000585423935576099,1.60115244633135E-7,0.000585423928561067,1.51985969529287E-7,9.06285552090228E-8,5.03701958520256E-8,1.00015059095645,10.005763053894,2,20,10,5,1.91529732960765,0.168819222871544,0.0410455763339996,172.855895996094,48.9992332458496,49.0001564025879,200.113494873047,200.113494873047,,,126.677101135254,0,1,,,,,,1,1,1,49.0000305175781,0,48.9997859281652,,,,,,,,,,,,,,,,,,,,,,,,,,,,,,,,,
,3767908201.83726,48.999231338501,200.113494873047,,,5,,,,25.0300001353025,,,,,0.00058651818511579,8.89682217915602E-8,0.00980839286742796,8.62737040840503E-5,0.000586429825692457,8.89548186593607E-8,0.000586429817099621,7.31754695233486E-8,1.00390188253947E-7,5.05797432057264E-8,1.00015067348123,10.005763053894,2,20,10,5,1.91858562948131,0.169140734547905,0.0410455763339996,172.855895996094,48.9984588623047,49.0015296936035,200.113494873047,200.113494873047,,,127.510383605957,0,1,,,,,,1,1,1,48.9996795654297,0,49.0002264135024,,,,,,,,,,,,,,,,,,,,,,,,,,,,,,,,,
,3767908409.69088,49.0010623931885,200.113494873047,,,5,,,,25.0300001353025,,,,,0.000587817673653241,2.44677838819397E-7,0.00953495798041004,0.000156618229734659,0.000587729136638466,2.44640985477958E-7,0.000587729128500056,2.26693598460991E-7,9.78077729890109E-8,9.19740408617221E-8,1.00015064254817,10.005763053894,2,20,10,5,1.92283725341124,0.169506301341524,0.0410455763339996,172.855895996094,48.9999008178711,49.0011596679687,200.113494873047,200.113494873047,,,128.231735229492,0,1,,,,,,1,1,1,49.0010299682617,0,49.000467412612,,,,,,,,,,,,,,,,,,,,,,,,,,,,,,,,,
,3767908617.34533,48.999626159668,200.113494873047,,,5,,,,25.0300001353025,,,,,0.000588390947135737,1.30110095121796E-7,0.0101533786621175,0.000156743218891596,0.000588302362440003,1.30090506507721E-7,0.000588302353202672,9.17739232548826E-8,1.0425299512758E-7,9.2201338893979E-8,1.00015057681456,10.005763053894,2,20,10,5,1.92471068260622,0.169692392723264,0.0410455763339996,172.855895996094,48.9994316101074,49.0000076293945,200.113494873047,200.113494873047,,,128.903335571289,0,1,,,,,,1,1,1,48.999641418457,0,48.9996081458198,,,,,,,,,,,,,,,,,,,,,,,,,,,,,,,,,
,3767908826.02957,48.999792098999,200.113494873047,,,5,,,,25.0300001353025,,,,,0.000589832801456463,1.33952055639564E-7,0.00820608771558362,0.000187719400731512,0.000589743995205319,1.33931887585388E-7,0.000589743989156639,7.53859610482856E-8,8.44650509858801E-8,1.10700981879166E-7,1.00015058440928,10.005763053894,2,20,10,5,1.92943297396915,0.170042649713939,0.0410455763339996,172.855895996094,48.9994201660156,49.0000343322754,200.113494873047,200.113494873047,,,129.587387084961,0,1,,,,,,1,1,1,48.9996528625488,0,48.9997459860409,,,,,,,,,,,,,,,,,,,,,,,,,,,,,,,,,
,3767909034.36474,49.0007171630859,200.113494873047,,,5,,,,25.0300001353025,,,,,0.00059007622838402,1.63973160868047E-7,0.00606952750227396,0.000211014367807192,0.000589987360506746,1.63948465843853E-7,0.000589987357196371,1.06689082962487E-7,6.24992719241146E-8,1.24485095610585E-7,1.00015062674766,10.005763053894,2,20,10,5,1.93023560308437,0.170040844614005,0.0410455763339996,172.855895996094,48.9999694824219,49.0010528564453,200.113494873047,200.113494873047,,,130.234115600586,0,1,,,,,,1,1,1,49.0008544921875,0,49.0004020267063,,,,,,,,,,,,,,,,,,,,,,,,,,,,,,,,,
,3767909240.29767,49.0004272460937,200.113494873047,,,5,,,,25.0300001353025,,,,,0.000590803225509425,2.09543682567278E-6,0.000189033127668381,0.000396184067270548,0.0005907142559804,2.09512127216962E-6,0.000590714255977185,2.08226236538108E-6,1.94891428853982E-9,2.31768390457468E-7,1.00015061347872,10.005763053894,2,20,10,5,1.93263119240423,0.170051990722573,0.0410455763339996,172.855895996094,48.999683380127,49.0006904602051,200.113494873047,200.113494873047,,,130.855972290039,0,1,,,,,,1,1,1,49.0003204345703,0,49.0002138349745,,,,,,,,,,,,,,,,,,,,,,,,,,,,,,,,,
,3767909447.03478,49.0008010864258,200.113494873047,,,5,,,,25.0300001353025,,,,,0.000592015244009368,1.24260897805425E-7,0.0104921768146635,8.41772993651562E-5,0.000591926081835214,1.24242183132242E-7,0.000591926071910376,1.13828472769773E-7,1.08395297697223E-7,4.97915540665956E-8,1.00015063058867,10.005763053894,2,20,10,5,1.93656526521826,0.170749089361086,0.0410455763339996,172.855895996094,48.999885559082,49.0010452270508,200.113494873047,200.113494873047,,,131.477828979492,0,1,,,,,,1,1,1,49.0009384155273,0,49.0004184947294,,,,,,,,,,,,,,,,,,,,,,,,,,,,,,,,,
,3767909654.76059,48.999963760376,200.113494873047,,,5,,,,25.0300001353025,,,,,0.000592848699230717,1.21974341878677E-7,0.0146246667186336,0.0001601064505202,0.000592759434244388,1.21955976251875E-7,0.000592759414934704,7.66006258770106E-8,1.51301005932524E-7,9.48978622456697E-8,1.00015059226589,10.005763053894,2,20,10,5,1.93927927662125,0.171129349813013,0.0410455763339996,172.855895996094,48.9994659423828,49.0000419616699,200.113494873047,200.113494873047,,,132.099685668945,0,1,,,,,,1,1,1,49.0000228881836,0,48.9997890696806,,,,,,,,,,,,,,,,,,,,,,,,,,,,,,,,,
,3767909862.50298,49.0000915527344,200.113494873047,,,5,,,,25.0300001353025,,,,,0.000593740346586152,1.2786010225009E-7,0.00748339392253516,0.000160269759161746,0.000593650943873218,1.2784084965915E-7,0.000593650938809691,8.53965324127036E-8,7.75366683307443E-8,9.51352463257418E-8,1.00015059811469,10.005763053894,2,20,10,5,1.94221730840894,0.171144656222715,0.0410455763339996,172.855895996094,48.9994125366211,49.0005645751953,200.113494873047,200.113494873047,,,132.74641418457,0,1,,,,,,1,1,1,48.999683380127,0,48.9998084174262,,,,,,,,,,,,,,,,,,,,,,,,,,,,,,,,,
,3767910067.8053,49.0002212524414,200.113494873047,,,5,,,,25.0300001353025,,,,,0.000594597024540969,1.58484327728814E-7,0.00841963143679436,0.000157738350361433,0.000594507489304851,1.58460462941204E-7,0.000594507482885838,1.27749077088521E-7,8.73630478699161E-8,9.37544218614343E-8,1.0001506040508,10.005763053894,2,20,10,5,1.94501683493404,0.17142337298142,0.0410455763339996,172.855895996094,48.999626159668,49.0004234313965,200.113494873047,200.113494873047,,,133.330947875977,0,1,,,,,,1,1,1,49.0001564025879,0,49.0000083025764,,,,,,,,,,,,,,,,,,,,,,,,,,,,,,,,,
,3767910275.49751,49.0011177062988,200.113494873047,,,5,,,,25.0300001353025,,,,,0.000594927071499335,9.85077523269692E-8,0.0084169770631739,0.000111228430434934,0.000594837462162415,9.84929148539571E-8,0.000594837455743888,7.29701986558375E-8,8.73839801094989E-8,6.61528864416093E-8,1.00015064507974,10.005763053894,2,20,10,5,1.94609647676119,0.171518432151358,0.0410455763339996,172.855895996094,48.9999465942383,49.0011711120605,200.113494873047,200.113494873047,,,133.965240478516,0,1,,,,,,1,1,1,49.0012435913086,0,49.0005279989804,,,,,,,,,,,,,,,,,,,,,,,,,,,,,,,,,
,3767910480.67199,48.9999675750732,200.113494873047,,,5,,,,25.0300001353025,,,,,0.000595404314580847,1.03027496384299E-7,0.00619932152207614,7.96242587413796E-5,0.000595314664692638,1.03011983558297E-7,0.000595314661207984,9.14697781458276E-8,6.44121964549435E-8,4.73787762882062E-8,1.00015059244048,10.005763053894,2,20,10,5,1.9476642532552,0.171580641544859,0.0410455763339996,172.855895996094,48.9993476867676,49.0001029968262,200.113494873047,200.113494873047,,,134.549789428711,0,1,,,,,,1,1,1,48.9999771118164,0,48.9997762792251,,,,,,,,,,,,,,,,,,,,,,,,,,,,,,,,,
,3767910685.73774,49.0002956390381,200.113494873047,,,5,,,,25.0300001353025,,,,,0.000595898416966531,3.53350936820228E-7,-0.014948791793346,0.000299171639419926,0.000595808683736812,3.53297727548509E-7,0.000595808663457942,3.05067154006543E-7,-1.55449841794495E-7,1.78194601032942E-7,1.00015060745533,10.005763053894,2,20,10,5,1.94934379349138,0.171003528570567,0.0410455763339996,172.855895996094,48.9997177124023,49.0007972717285,200.113494873047,200.113494873047,,,135.159210205078,0,1,,,,,,1,1,1,49.0004348754883,0,49.0002126693726,,,,,,,,,,,,,,,,,,,,,,,,,,,,,,,,,
,3767910890.78056,48.9996871948242,200.113494873047,,,5,,,,25.0300001353025,,,,,0.000596548287048687,2.16873657151511E-7,-0.00321790945064215,0.00013245986932875,0.000596458472565688,2.16841005317927E-7,0.000596458471624985,2.01959047580168E-7,-3.34989657368643E-8,7.89465938961303E-8,1.00015057960802,10.005763053894,2,20,10,5,1.95143460209123,0.171589568014065,0.0410455763339996,172.855895996094,48.9994087219238,49.0000076293945,200.113494873047,200.113494873047,,,135.768630981445,0,1,,,,,,1,1,1,48.9997024536133,0,48.9997044731589,,,,,,,,,,,,,,,,,,,,,,,,,,,,,,,,,
,3767911097.42354,49.0004997253418,200.113494873047,,,5,,,,25.0300001353025,,,,,0.000597728449755544,1.21146197914811E-7,0.00650740788742077,7.62803739059686E-5,0.000597638435369268,1.21127954010477E-7,0.000597638431514668,1.12236301378826E-7,6.7877199557057E-8,4.55521008907993E-8,1.00015061679596,10.005763053894,2,20,10,5,1.95526595096433,0.172260911017179,0.0410455763339996,172.855895996094,48.9998512268066,49.0006523132324,200.113494873047,200.113494873047,,,136.378036499023,0,1,,,,,,1,1,1,49.0005187988281,0,49.0002008325913,,,,,,,,,,,,,,,,,,,,,,,,,,,,,,,,,
,3767911303.96827,49.0010051727295,200.113494873047,,,5,,,,25.0300001353025,,,,,0.000598106178695489,7.91884444018101E-8,0.00948037719831873,8.04946021612211E-5,0.00059801609359343,7.91765172568484E-8,0.000598016085407108,6.28709258846825E-8,9.89500127276652E-8,4.81265785541292E-8,1.0001506399293,10.005763053894,2,20,10,5,1.95649261672569,0.172471286561147,0.0410455763339996,172.855895996094,48.9999961853027,49.0010948181152,200.113494873047,200.113494873047,,,136.962585449219,0,1,,,,,,1,1,1,49.001106262207,0,49.0004772859461,,,,,,,,,,,,,,,,,,,,,,,,,,,,,,,,,
,3767911509.09318,49.0008640289307,200.113494873047,,,5,,,,25.0300001353025,,,,,0.000598809285645057,2.04054450901594E-7,-0.00278766330848779,0.000147362218151583,0.000598719098510038,2.04023718101092E-7,0.000598719097801394,1.83981924044505E-7,-2.91300210335343E-8,8.81834971674153E-8,1.00015063346942,10.005763053894,2,20,10,5,1.95882950978057,0.172254620841108,0.0410455763339996,172.855895996094,48.9999771118164,49.0009803771973,200.113494873047,200.113494873047,,,137.584442138672,0,1,,,,,,1,1,1,49.0008659362793,0,49.000426124124,,,,,,,,,,,,,,,,,,,,,,,,,,,,,,,,,
,3767911714.25476,49.0010242462158,200.113494873047,,,5,,,,25.0300001353025,,,,,0.000599119335911326,2.26403345878704E-7,0.0142871995807745,0.00012379424251888,0.000599029097687476,2.26369245433966E-7,0.000599029079063737,2.13908553243911E-7,1.49373099683623E-7,7.40686581992691E-8,1.00015064080226,10.005763053894,2,20,10,5,1.95979230091147,0.172927861116759,0.0410455763339996,172.855895996094,48.9996948242188,49.0012397766113,200.113494873047,200.113494873047,,,138.193862915039,0,1,,,,,,1,1,1,49.0008087158203,0,49.0003623962402,,,,,,,,,,,,,,,,,,,,,,,,,,,,,,,,,
,3767911919.2764,49.0005168914795,200.113494873047,,,5,,,,25.0300001353025,,,,,0.000600231443727963,1.61781272818458E-7,-0.0150650995937802,0.000133846376935632,0.00060014105193409,1.61756909383956E-7,0.000600141031188677,1.40417282217016E-7,-1.57798439786677E-7,8.03012116237131E-8,1.00015061758162,10.005763053894,2,20,10,5,1.96351863754075,0.172242981876225,0.0410455763339996,172.855895996094,48.9992713928223,49.001049041748,200.113494873047,200.113494873047,,,138.828155517578,0,1,,,,,,1,1,1,49.0001678466797,0,48.9999264611138,,,,,,,,,,,,,,,,,,,,,,,,,,,,,,,,,
,3767912123.16276,48.9997692108154,200.113494873047,,,5,,,,25.0300001353025,,,,,0.000600911963360382,1.21264220556015E-6,0.0246215328697357,0.00058262912263892,0.000600821489640671,1.21245962931321E-6,0.000600821434165281,1.16101073603287E-6,2.58189097459739E-7,3.49445880689305E-7,1.00015058336173,10.005763053894,2,20,10,5,1.96562488731653,0.173799821407166,0.0410455763339996,172.855895996094,48.9995727539063,49.0002250671387,200.113494873047,200.113494873047,,,139.42512512207,0,1,,,,,,1,1,1,48.9999046325684,0,48.9998887005974,,,,,,,,,,,,,,,,,,,,,,,,,,,,,,,,,
,3767912329.81773,49.0004997253418,200.113494873047,,,5,,,,25.0300001353025,,,,,0.000601547587307663,1.69163478768218E-7,-0.00352051813702836,0.000132086750316538,0.000601456997781751,1.69138003744019E-7,0.000601456996646368,1.49336678305797E-7,-3.69563043909269E-8,7.94117171650548E-8,1.00015061679596,10.005763053894,2,20,10,5,1.96778927610592,0.173017158356115,0.0410455763339996,172.855895996094,48.9998092651367,49.0009269714355,200.113494873047,200.113494873047,,,140.046981811523,0,1,,,,,,1,1,1,49.0003318786621,0,49.0002057692584,,,,,,,,,,,,,,,,,,,,,,,,,,,,,,,,,
,3767912535.68062,49.0001754760742,200.113494873047,,,5,,,,25.0300001353025,,,,,0.000601718044140835,9.16033418367316E-8,0.0103915847443803,8.0536472721245E-5,0.000601627437872088,9.15895482716401E-8,0.000601627427977085,7.77338357605899E-8,1.09115584499375E-7,4.84365164989053E-8,1.0001506019557,10.005763053894,2,20,10,5,1.96830479582788,0.173544118622836,0.0410455763339996,172.855895996094,48.9996681213379,49.0003814697266,200.113494873047,200.113494873047,,,140.656402587891,0,1,,,,,,1,1,1,49.0002403259277,0,49.0000399421243,,,,,,,,,,,,,,,,,,,,,,,,,,,,,,,,,
,3767912740.69554,48.9999446868897,200.113494873047,,,5,,,,25.0300001353025,,,,,0.000602499373537709,8.0060082244853E-8,0.0067940345027182,7.61692925834516E-5,0.000602408655979091,8.00480277008601E-8,0.000602408651743916,6.5599858852181E-8,7.14325770353161E-8,4.58731430945342E-8,1.00015059139293,10.005763053894,2,20,10,5,1.97087154162389,0.173645717126902,0.0410455763339996,172.855895996094,48.9997634887695,49.0005531311035,200.113494873047,200.113494873047,,,141.29069519043,0,1,,,,,,1,1,1,49.0000152587891,0,49.0000652986414,,,,,,,,,,,,,,,,,,,,,,,,,,,,,,,,,
,3767912947.34643,49.0002002716064,200.113494873047,,,5,,,,25.0300001353025,,,,,0.000603171246159969,8.34242377654008E-8,0.00512217732752163,6.85643133411516E-5,0.000603080420384812,8.34116757092514E-8,0.000603080417974855,7.24502132685357E-8,5.39147015383083E-8,4.13336937856879E-8,1.00015060309054,10.005763053894,2,20,10,5,1.97307441578374,0.173781784122257,0.0410455763339996,172.855895996094,48.9994773864746,49.000602722168,200.113494873047,200.113494873047,,,141.912551879883,0,1,,,,,,1,1,1,48.9999122619629,0,48.9999026130227,,,,,,,,,,,,,,,,,,,,,,,,,,,,,,,,,
,3767913153.32687,49.0006484985352,200.113494873047,,,5,,,,25.0300001353025,,,,,0.000603460770450973,9.06635404038583E-7,0.0158556547191777,0.000924585483829818,0.000603369888703178,9.06498863911757E-7,0.000603369865599734,7.14604234807908E-7,1.66972586505E-7,5.57746338282836E-7,1.00015062360502,10.005763053894,2,20,10,5,1.97398889298724,0.174234996747951,0.0410455763339996,172.855895996094,48.9995384216309,49.0007247924805,200.113494873047,200.113494873047,,,142.534408569336,0,1,,,,,,1,1,1,49.0006332397461,0,49.0001631344066,,,,,,,,,,,,,,,,,,,,,,,,,,,,,,,,,
,3767913361.27002,49.0008792877197,200.113494873047,,,5,,,,25.0300001353025,,,,,0.000603703138108025,3.27194203989814E-7,0.0350697653670293,0.000456365806622475,0.00060361221348458,3.27144924786323E-7,0.000603612100414301,1.76476473305899E-7,3.69460675074004E-7,2.7546298514131E-7,1.00015063416779,10.005763053894,2,20,10,5,1.97472314112526,0.174967206234901,0.0410455763339996,172.855895996094,49.000057220459,49.0009384155273,200.113494873047,200.113494873047,,,143.156265258789,0,1,,,,,,1,1,1,49.0008201599121,0,49.0004876080681,,,,,,,,,,,,,,,,,,,,,,,,,,,,,,,,,
,3767913569.1993,49.0001525878906,200.113494873047,,,5,,,,25.0300001353025,,,,,0.000605128076277911,1.01334046591807E-6,0.0154146034083782,0.000671532339872598,0.000605036957162696,1.01318787890337E-6,0.000605036935266365,9.28284999856092E-7,1.62776468159188E-7,4.0600078448064E-7,1.00015060090815,10.005763053894,2,20,10,5,1.97944418499878,0.174701155196695,0.0410455763339996,172.855895996094,48.9998168945313,49.00048828125,200.113494873047,200.113494873047,,,143.802993774414,0,1,,,,,,1,1,1,49.0004196166992,0,49.000103632609,,,,,,,,,,,,,,,,,,,,,,,,,,,,,,,,,
,3767913776.71981,48.9997806549072,200.113494873047,,,5,,,,25.0300001353025,,,,,0.000605047537485686,2.4757377904053E-7,-0.00446858951656548,0.000168706844894794,0.000604956440794269,2.47536504031948E-7,0.000604956438954388,2.25543194714707E-7,-4.71815206904417E-8,1.02002883029071E-7,1.00015058388551,10.005763053894,2,20,10,5,1.97924123186342,0.173991065786762,0.0410455763339996,172.855895996094,48.9994964599609,49.0001602172852,200.113494873047,200.113494873047,,,144.437286376953,0,1,,,,,,1,1,1,48.9997863769531,0,48.9998154110379,,,,,,,,,,,,,,,,,,,,,,,,,,,,,,,,,
,3767913981.85777,48.9998264312744,200.113494873047,,,5,,,,25.0300001353025,,,,,0.00060613851295265,8.72772353296208E-8,0.0145346143835052,6.57880702290373E-5,0.000606047181207623,8.72640845694671E-8,0.000606047161707462,7.76339208245074E-8,1.53740154291401E-7,3.98496523593522E-8,1.00015070071747,10.005763053894,2,20,10,5,1.98275212793661,0.174962418622142,0.0410455763339996,172.855895996094,48.9995307922363,49.0001029968262,200.113494873047,200.113494873047,,,145.071578979492,0,1,,,,,,1,1,1,48.9999389648438,0,48.9998207092285,,,,,,,,,,,,,,,,,,,,,,,,,,,,,,,,,
,3767914189.9664,48.9998798370361,200.113494873047,,,5,,,,25.0300001353025,,,,,0.000606626379196682,9.28204072916543E-8,0.00427251353043268,7.80790138417762E-5,0.000606535042040068,9.28064317172834E-8,0.000606535040353718,7.98241015769047E-8,4.52289713730902E-8,4.73407496300469E-8,1.00015058842488,10.005763053894,2,20,10,5,1.98437932770438,0.174747827115863,0.0410455763339996,172.855895996094,48.9995155334473,49.0002670288086,200.113494873047,200.113494873047,,,145.705871582031,0,1,,,,,,1,1,1,49,0,48.9998796251085,,,,,,,,,,,,,,,,,,,,,,,,,,,,,,,,,
,3767914397.44299,49.0007915496826,200.113494873047,,,5,,,,25.0300001353025,,,,,0.000607337201140689,1.02575502145564E-7,0.00976466283253963,8.51255422587686E-5,0.000607245731623719,1.02560053509096E-7,0.000607245722805036,8.85920947688808E-8,1.03490167120368E-7,5.16720942119651E-8,1.00015063015219,10.005763053894,2,20,10,5,1.986687769411,0.175143025343799,0.0410455763339996,172.855895996094,48.9996070861816,49.0013275146484,200.113494873047,200.113494873047,,,146.352600097656,0,1,,,,,,1,1,1,49.0004539489746,0,49.0002369127776,,,,,,,,,,,,,,,,,,,,,,,,,,,,,,,,,
,3767914604.30662,49.0003223419189,200.113494873047,,,5,,,,25.0300001353025,,,,,0.000607867711953005,9.95431755959979E-8,0.00661931635377844,8.32105562040303E-5,0.000607776175587005,9.9528185787566E-8,0.000607776171531035,8.57325917321282E-8,7.02156913430621E-8,5.0554747364184E-8,1.00015060867746,10.005763053894,2,20,10,5,1.98843276699158,0.175186856744165,0.0410455763339996,172.855895996094,48.999397277832,49.0005989074707,200.113494873047,200.113494873047,,,146.999328613281,0,1,,,,,,1,1,1,49.0000343322754,0,48.9999785953098,,,,,,,,,,,,,,,,,,,,,,,,,,,,,,,,,
,3767914811.35779,49.0000629425049,200.113494873047,,,5,,,,25.0300001353025,,,,,0.00060801774506174,1.07267841412202E-7,0.0164070521603961,8.95969214529775E-5,0.000607926193319193,1.07251689650382E-7,0.000607926168394104,9.24040246332155E-8,1.74083967648365E-7,5.44464981835003E-8,1.00015059680526,10.005763053894,2,20,10,5,1.9888935860533,0.175569858190833,0.0410455763339996,172.855895996094,48.9994277954102,49.000545501709,200.113494873047,200.113494873047,,,147.658493041992,0,1,,,,,,1,1,1,48.9999351501465,0,48.9999319712321,,,,,,,,,,,,,,,,,,,,,,,,,,,,,,,,,
,3767915021.48638,49.0010890960693,200.113494873047,,,5,,,,25.0300001353025,,,,,0.000608682087177855,1.22270707619718E-7,0.00842261906192299,0.000147246034824785,0.000608590406824399,1.22252291073662E-7,0.000608590400248666,8.31676798961143E-8,8.94642709554307E-8,8.96033464411725E-8,1.00015064377031,10.005763053894,2,20,10,5,1.99109119718022,0.175484221700406,0.0410455763339996,172.855895996094,48.9998817443848,49.0013580322266,200.113494873047,200.113494873047,,,148.317657470703,0,1,,,,,,1,1,1,49.0011520385742,0,49.0005116182215,,,,,,,,,,,,,,,,,,,,,,,,,,,,,,,,,
,3767915226.6512,48.99973487854,200.113494873047,,,5,,,,25.0300001353025,,,,,0.000609424820926969,7.80900517431956E-8,0.00755971559237167,9.68712622436851E-5,0.000609333066462864,7.80782945738064E-8,0.000609333061159025,5.1114186424758E-8,8.03965791070181E-8,5.90216911795077E-8,1.00015058179041,10.005763053894,2,20,10,5,1.99352343714836,0.175668334008127,0.0410455763339996,172.855895996094,48.9994888305664,49.0004692077637,200.113494873047,200.113494873047,,,148.964385986328,0,1,,,,,,1,1,1,48.9999809265137,0,48.9998251971077,,,,,,,,,,,,,,,,,,,,,,,,,,,,,,,,,
,3767915434.52038,49.0003337860107,200.113494873047,,,5,,,,25.0300001353025,,,,,0.000609938750589818,1.29801255406456E-7,0.00644100725653018,9.95226033488422E-5,0.000609846902035025,1.29781709086915E-7,0.000609846898181545,1.14730014291281E-7,6.85570271752692E-8,6.06656066832213E-8,1.00015060920124,10.005763053894,2,20,10,5,1.99520801373259,0.175777516583937,0.0410455763339996,172.855895996094,49.0000114440918,49.0012130737305,200.113494873047,200.113494873047,,,149.6484375,0,1,,,,,,1,1,1,49.0006332397461,0,49.0006471521714,,,,,,,,,,,,,,,,,,,,,,,,,,,,,,,,,
,3767915639.73002,49.0000534057617,200.113494873047,,,5,,,,25.0300001353025,,,,,0.000610316543361016,6.16541111828393E-8,0.00585803014893571,7.12805962700355E-5,0.000610224645745226,6.16448276956342E-8,0.000610224642555762,4.36868656627149E-8,6.23905355080289E-8,4.34918676328383E-8,1.00015059636878,10.005763053894,2,20,10,5,1.99644562413497,0.175866080821294,0.0410455763339996,172.855895996094,48.9996795654297,49.0001487731934,200.113494873047,200.113494873047,,,150.282730102539,0,1,,,,,,1,1,1,49.0000305175781,0,48.9999562431784,,,,,,,,,,,,,,,,,,,,,,,,,,,,,,,,,
,3767915846.16181,48.9992237091064,200.113494873047,,,5,,,,25.0300001353025,,,,,0.0006111558389372,1.0417920536519E-7,0.00914851448189591,7.92434344490752E-5,0.000611063768045389,1.04163510722784E-7,0.000611063760255838,9.223621378791E-8,9.7569589855993E-8,4.83995643799253E-8,1.00015067313205,10.005763053894,2,20,10,5,1.99918098044447,0.176222743419576,0.0410455763339996,172.855895996094,48.9989051818848,49.0002212524414,200.113494873047,200.113494873047,,,150.966781616211,0,1,,,,,,1,1,1,48.999439239502,0,48.999671459198,,,,,,,,,,,,,,,,,,,,,,,,,,,,,,,,,
,3767916052.84844,49.0010433197022,200.113494873047,,,5,,,,25.0300001353025,,,,,0.000611219093474217,5.38330053265119E-8,0.0114937089857303,4.84527644348592E-5,0.000611127032274308,5.38248970538517E-8,0.000611127019977946,4.49539119004659E-8,1.22593954997328E-7,2.96017794685198E-8,1.00015064167521,10.005763053894,2,20,10,5,1.99938068044569,0.17632281408217,0.0410455763339996,172.855895996094,49.0004577636719,49.0012054443359,200.113494873047,200.113494873047,,,151.650817871094,0,1,,,,,,1,1,1,49.0010833740234,0,49.0008392333984,,,,,,,,,,,,,,,,,,,,,,,,,,,,,,,,,
,3767916263.91077,48.9991645812988,200.113494873047,,,5,,,,25.0300001353025,,,,,0.000611840406222606,8.81491161339927E-8,0.00711989001051805,7.96164721340298E-5,0.000611748233855679,8.81358366699463E-8,0.000611748229132395,7.34649879494401E-8,7.60192140675361E-8,4.86910797898349E-8,1.00015067042588,10.005763053894,2,20,10,5,2.00142654617204,0.176349271569143,0.0410455763339996,172.855895996094,48.9990196228027,48.9998588562012,200.113494873047,200.113494873047,,,152.322418212891,0,1,,,,,,1,1,1,48.9993133544922,0,48.9994592105641,,,,,,,,,,,,,,,,,,,,,,,,,,,,,,,,,
,3767916469.88819,48.9994506835937,200.113494873047,,,5,,,,25.0300001353025,,,,,0.000612534886029178,1.4986218906465E-7,0.00765928484372935,0.00010067366938896,0.000612442671281284,1.49839627894179E-7,0.000612442665809025,1.36584203771319E-7,8.18711761266044E-8,6.16171191116621E-8,1.00015056878336,10.005763053894,2,20,10,5,2.00369663715923,0.17656830212978,0.0410455763339996,172.855895996094,48.9993362426758,49,200.113494873047,200.113494873047,,,153.018890380859,0,1,,,,,,1,1,1,48.9995651245117,0,48.9996498955621,,,,,,,,,,,,,,,,,,,,,,,,,,,,,,,,,
,3767916677.16759,49.0005702972412,200.113494873047,,,5,,,,25.0300001353025,,,,,0.000612671943868462,1.24790356730799E-7,0.0154140088646333,0.000172578835646356,0.000612579677101634,1.24771563634654E-7,0.000612579654934041,6.62745801730052E-8,1.64799371602679E-7,1.05714819749779E-7,1.0001506200259,10.005763053894,2,20,10,5,2.00412105346281,0.176879057500632,0.0410455763339996,172.855895996094,48.9995918273926,49.0008354187012,200.113494873047,200.113494873047,,,153.690505981445,0,1,,,,,,1,1,1,49.0004043579102,0,49.0001115237965,,,,,,,,,,,,,,,,,,,,,,,,,,,,,,,,,
,3767916883.15703,49.0001564025879,200.113494873047,,,5,,,,25.0300001353025,,,,,0.000613586944353854,1.02140749742358E-7,0.0113354153731118,9.6783661077698E-5,0.000613494551410153,1.02125369551128E-7,0.000613494539403822,8.3101471426002E-8,1.21373957787266E-7,5.93610693366268E-8,1.00015060108274,10.005763053894,2,20,10,5,2.00712673096393,0.177000344092368,0.0410455763339996,172.855895996094,48.999828338623,49.000675201416,200.113494873047,200.113494873047,,,154.374542236328,0,1,,,,,,1,1,1,48.9999618530273,0,49.0001552806181,,,,,,,,,,,,,,,,,,,,,,,,,,,,,,,,,
,3767917091.04561,48.9999923706055,200.113494873047,,,5,,,,25.0300001353025,,,,,0.000613719396911004,8.71321502682572E-8,0.0032578652348727,6.81166056337806E-5,0.000613626988628873,8.71190307019453E-8,0.00061362698763691,7.64466888531069E-8,3.48911219874397E-8,4.17807284982293E-8,1.00015059357532,10.005763053894,2,20,10,5,2.00758494025344,0.176755525630394,0.0410455763339996,172.855895996094,48.9996109008789,49.000244140625,200.113494873047,200.113494873047,,,155.071014404297,0,1,,,,,,1,1,1,48.9998397827148,0,48.9998745637782,,,,,,,,,,,,,,,,,,,,,,,,,,,,,,,,,
,3767917300.31724,49.0007228851318,200.113494873047,,,5,,,,25.0300001353025,,,,,0.000614475478690067,7.19686035264218E-8,0.0114036290925439,6.23962203031296E-5,0.000614382936025697,7.19577647435048E-8,0.000614382923856833,6.09041766683461E-8,1.22281172130122E-7,3.83223325390362E-8,1.00015062700955,10.005763053894,2,20,10,5,2.01003303721472,0.177259050308932,0.0410455763339996,172.855895996094,48.9995384216309,49.0013732910156,200.113494873047,200.113494873047,,,155.767501831055,0,1,,,,,,1,1,1,49.0001754760742,0,49.0001597684972,,,,,,,,,,,,,,,,,,,,,,,,,,,,,,,,,
,3767917507.08922,49.000316619873,200.113494873047,,,5,,,,25.0300001353025,,,,,0.000614864260917549,1.14710598960837E-7,0.0135975783410398,0.000116252360058352,0.000614771671130218,1.14693325180854E-7,0.000614771653817641,8.9715537814585E-8,1.4589915614407E-7,7.14540489803123E-8,1.00015060841558,10.005763053894,2,20,10,5,2.01129800364844,0.177448218180932,0.0410455763339996,172.855895996094,48.9996147155762,49.0006256103516,200.113494873047,200.113494873047,,,156.463973999023,0,1,,,,,,1,1,1,49.0004501342773,0,49.000069869192,,,,,,,,,,,,,,,,,,,,,,,,,,,,,,,,,
,3767917717.26985,48.9988403320313,200.113494873047,,,5,,,,25.0300001353025,,,,,0.000615252381377555,7.36811185305495E-8,0.00777845328822657,8.9250158991772E-5,0.000615159704132077,7.36700197305841E-8,0.000615159698463173,4.9127285094687E-8,8.35138477800036E-8,5.48979204189922E-8,1.00015065558562,10.005763053894,2,20,10,5,2.01258561695527,0.177355830930938,0.0410455763339996,172.855895996094,48.9983749389648,49.000358581543,200.113494873047,200.113494873047,,,157.172882080078,0,1,,,,,,1,1,1,48.9989814758301,0,48.9993434482151,,,,,,,,,,,,,,,,,,,,,,,,,,,,,,,,,
,3767917925.42197,49.0008697509766,200.113494873047,,,5,,,,25.0300001353025,,,,,0.00061546437543932,2.12858480649918E-7,0.0062390324592192,0.000143751951967823,0.000615371679707064,2.12826421811879E-7,0.000615371676058711,1.93596107700435E-7,6.70088426969142E-8,8.84060682560281E-8,1.00015063373131,10.005763053894,2,20,10,5,2.01328384902579,0.17736284166904,0.0410455763339996,172.855895996094,48.9998435974121,49.0009574890137,200.113494873047,200.113494873047,,,157.869369506836,0,1,,,,,,1,1,1,49.000919342041,0,49.0003267923991,,,,,,,,,,,,,,,,,,,,,,,,,,,,,,,,,
,3767918135.072,48.9998359680176,200.113494873047,,,5,,,,25.0300001353025,,,,,0.000616239310244111,7.21097353088836E-8,0.00656152240672903,8.22917633221141E-5,0.000616146526946222,7.20988781971404E-8,0.000616146522905882,5.12641355920766E-8,7.05612048200841E-8,5.06975013120299E-8,1.00015058641708,10.005763053894,2,20,10,5,2.01581778651372,0.177597511172784,0.0410455763339996,172.855895996094,48.9995002746582,49.0004806518555,200.113494873047,200.113494873047,,,158.590713500977,0,1,,,,,,1,1,1,48.9995765686035,0,48.9998393058777,,,,,,,,,,,,,,,,,,,,,,,,,,,,,,,,,
,3767918340.34469,48.9997081756592,200.113494873047,,,5,,,,25.0300001353025,,,,,0.000616703034482694,1.0617357988457E-7,0.00598202004168424,9.31440782413166E-5,0.000616610184970639,1.06157594613647E-7,0.000616610181609928,8.92907689056811E-8,6.43777693408901E-8,5.74159688796388E-8,1.00015058056827,10.005763053894,2,20,10,5,2.01733650054638,0.177710750285628,0.0410455763339996,172.855895996094,48.9995346069336,49.0003509521484,200.113494873047,200.113494873047,,,159.29963684082,0,1,,,,,,1,1,1,48.9996948242188,0,48.9998077816433,,,,,,,,,,,,,,,,,,,,,,,,,,,,,,,,,
,3767918548.58246,49.0007762908936,200.113494873047,,,5,,,,25.0300001353025,,,,,0.000617029770647634,1.09733244635019E-7,0.00690346154633481,0.000108171471568478,0.000616936841788111,1.09716718065701E-7,0.000616936837309955,8.70982853739014E-8,7.43335685401415E-8,6.67206632763419E-8,1.00015062945382,10.005763053894,2,20,10,5,2.01840244855519,0.17783736020384,0.0410455763339996,172.855895996094,48.9997596740723,49.0009460449219,200.113494873047,200.113494873047,,,159.996109008789,0,1,,,,,,1,1,1,49.0006828308105,0,49.0002380819882,,,,,,,,,,,,,,,,,,,,,,,,,,,,,,,,,
,3767918757.38117,49.0005378723145,200.113494873047,,,5,,,,25.0300001353025,,,,,0.000617558463222838,1.03722674480651E-7,0.00624176542207433,0.000115129510869941,0.000617465461475375,1.03707054275355E-7,0.000617465457811402,7.55180241040224E-8,6.72662906743235E-8,7.10786968218723E-8,1.00015061854187,10.005763053894,2,20,10,5,2.02013394129334,0.177966408857291,0.0410455763339996,172.855895996094,48.9991912841797,49.0012588500977,200.113494873047,200.113494873047,,,160.692581176758,0,1,,,,,,1,1,1,49.0002746582031,0,49.0000583424288,,,,,,,,,,,,,,,,,,,,,,,,,,,,,,,,,
,3767918965.31815,49.0010318756103,200.113494873047,,,5,,,,25.0300001353025,,,,,0.000618414209952093,1.04651748116589E-7,0.0100564280094888,0.000125475182681244,0.000618321065354849,1.04635985631232E-7,0.000618321055830698,7.02180936513709E-8,1.08526340009832E-7,7.75764707433038E-8,1.00015064115144,10.005763053894,2,20,10,5,2.0229213583341,0.178347696204549,0.0410455763339996,172.855895996094,48.9999656677246,49.0012359619141,200.113494873047,200.113494873047,,,161.426376342773,0,1,,,,,,1,1,1,49.0010604858398,0,49.0005656348334,,,,,,,,,,,,,,,,,,,,,,,,,,,,,,,,,
,3767919175.54978,49.0002727508545,200.113494873047,,,5,,,,25.0300001353025,,,,,0.000618835096839438,1.09240784577786E-7,0.0187928358198928,9.08296945838998E-5,0.000618741910342979,1.09224334693096E-7,0.000618741877060252,9.36695328273922E-8,2.02945400626152E-7,5.61780554046461E-8,1.00015060640778,10.005763053894,2,20,10,5,2.02427090292927,0.178777742306484,0.0410455763339996,172.855895996094,48.9994468688965,49.0006484985352,200.113494873047,200.113494873047,,,162.160171508789,0,1,,,,,,1,1,1,49.0001525878906,0,48.999980714586,,,,,,,,,,,,,,,,,,,,,,,,,,,,,,,,,
,3767919381.46209,49.0001125335693,200.113494873047,,,5,,,,25.0300001353025,,,,,0.000619059565709692,6.92642592671529E-8,0.0125300852792156,8.67531969790149E-5,0.000618966349949967,6.92538297044629E-8,0.000618966335148668,4.37391978006497E-8,1.3536251978641E-7,5.36933469294883E-8,1.00015059907495,10.005763053894,2,20,10,5,2.02502469914228,0.178621245615854,0.0410455763339996,172.855895996094,48.999340057373,49.0003204345703,200.113494873047,200.113494873047,,,162.893951416016,0,1,,,,,,1,1,1,48.9998474121094,0,48.9997217278732,,,,,,,,,,,,,,,,,,,,,,,,,,,,,,,,,
,3767919589.73669,48.999927520752,200.113494873047,,,5,,,,25.0300001353025,,,,,0.000619578975579934,1.28308711405564E-7,0.00932115930954236,8.4147872869537E-5,0.000619485686854156,1.28289392228082E-7,0.000619485678656383,1.17236810771927E-7,1.00780978996184E-7,5.20931699772446E-8,1.00015059060727,10.005763053894,2,20,10,5,2.02673376577467,0.17865760501236,0.0410455763339996,172.855895996094,48.9993362426758,49.0001907348633,200.113494873047,200.113494873047,,,163.640182495117,0,1,,,,,,1,1,1,48.9997520446777,0,48.9998626708984,,,,,,,,,,,,,,,,,,,,,,,,,,,,,,,,,
,3767919796.49298,49.0003147125244,200.113494873047,,,5,,,,25.0300001353025,,,,,0.000619771720038894,1.73763640073571E-7,0.0189641195932468,0.000127677704015019,0.000619678391312306,1.73737473763088E-7,0.000619678357368818,1.5469905146813E-7,2.05105070696257E-7,7.907536445974E-8,1.00015060832828,10.005763053894,2,20,10,5,2.02733415474391,0.179054389808176,0.0410455763339996,172.855895996094,48.999153137207,49.0012359619141,200.113494873047,200.113494873047,,,164.349090576172,0,1,,,,,,1,1,1,48.9995918273926,0,49.0000112321642,,,,,,,,,,,,,,,,,,,,,,,,,,,,,,,,,
,3767920003.99262,48.9998874664307,200.113494873047,,,5,,,,25.0300001353025,,,,,0.000620233699455435,1.87643590620619E-7,-0.000990243432324789,0.00013130934864073,0.000620140313285911,1.87615337856896E-7,0.000620140313193292,1.69042834197442E-7,-1.07178901751467E-8,8.13881760801476E-8,1.00015058877406,10.005763053894,2,20,10,5,2.02890761750915,0.178481260424934,0.0410455763339996,172.855895996094,48.9995651245117,49.000129699707,200.113494873047,200.113494873047,,,165.082885742187,0,1,,,,,,1,1,1,49.0000076293945,0,48.9998263190774,,,,,,,,,,,,,,,,,,,,,,,,,,,,,,,,,
,3767920211.66183,48.9996070861816,200.113494873047,,,5,,,,25.0300001353025,,,,,0.000620971662002487,1.22820817390026E-7,0.00531613011315724,0.000125984439437617,0.000620878101460131,1.22802312226279E-7,0.000620878098787603,9.46789578671914E-8,5.76075375025245E-8,7.82067952629637E-8,1.00015069067847,10.005763053894,2,20,10,5,2.03130195893026,0.178917200982356,0.0410455763339996,172.855895996094,48.9993286132812,49.0002288818359,200.113494873047,200.113494873047,,,165.829116821289,0,1,,,,,,1,1,1,48.9998016357422,0,48.999755859375,,,,,,,,,,,,,,,,,,,,,,,,,,,,,,,,,
,3767920421.21308,49.0004482269287,200.113494873047,,,5,,,,25.0300001353025,,,,,0.000620450924278115,1.88484111104394E-7,0.0119358298209962,9.39455922744666E-5,0.000620357489482872,1.88455726950808E-7,0.000620357476022037,1.79242695144989E-7,1.29232579293243E-7,5.82032409554477E-8,1.00015061443898,10.005763053894,2,20,10,5,2.02957787149911,0.179001652174642,0.0410455763339996,172.855895996094,48.9995079040527,49.0008010864258,200.113494873047,200.113494873047,,,166.625091552734,0,1,,,,,,1,1,1,49.0000953674316,0,48.9999120375689,,,,,,,,,,,,,,,,,,,,,,,,,,,,,,,,,
,3767920628.3054,49.0013008117676,200.113494873047,,,5,,,,25.0300001353025,,,,,0.000621699581941699,1.08987352672697E-7,0.0104645337144404,9.50727575703564E-5,0.000621605934856781,1.08970935824162E-7,0.000621605924489148,9.15659258446244E-8,1.13530460385056E-7,5.90791509638594E-8,1.00015065346012,10.005763053894,2,20,10,5,2.03366700304649,0.179309666870496,0.0410455763339996,172.855895996094,49.0003128051758,49.0016326904297,200.113494873047,200.113494873047,,,167.371307373047,0,1,,,,,,1,1,1,49.0011329650879,0,49.0007977485657,,,,,,,,,,,,,,,,,,,,,,,,,,,,,,,,,
,3767920835.16433,48.999942779541,200.113494873047,,,5,,,,25.0300001353025,,,,,0.000621911374851949,1.19466199136765E-7,0.0110184682588814,7.95892090980483E-5,0.000621817663172775,1.19448197571625E-7,0.000621817651674565,1.08728204093608E-7,1.1958085221069E-7,4.9457552888196E-8,1.0001507060425,10.005763053894,2,20,10,5,2.034358072936,0.179390423767806,0.0410455763339996,172.855895996094,48.999397277832,49.0002517700195,200.113494873047,200.113494873047,,,168.117538452148,0,1,,,,,,1,1,1,49.0001029968262,0,48.9998036552878,,,,,,,,,,,,,,,,,,,,,,,,,,,,,,,,,
,3767921040.20296,49.0001068115234,200.113494873047,,,5,,,,25.0300001353025,,,,,0.000621983213954323,7.20183000279793E-8,0.0085398646072834,8.08404063645629E-5,0.000621889558125015,7.20074557906058E-8,0.000621889551217212,5.15583759649372E-8,9.26918640873784E-8,5.02673607552081E-8,1.00015059881306,10.005763053894,2,20,10,5,2.03460082794307,0.179323129660149,0.0410455763339996,172.855895996094,48.9994201660156,49.0002746582031,200.113494873047,200.113494873047,,,168.888641357422,0,1,,,,,,1,1,1,49.0000648498535,0,48.9998761345358,,,,,,,,,,,,,,,,,,,,,,,,,,,,,,,,,
,3767921248.1729,49.0004920959473,200.113494873047,,,5,,,,25.0300001353025,,,,,0.000622459558146342,7.5749243250412E-8,0.00709263062965171,6.10923547921477E-5,0.000622365819617997,7.57378358866843E-8,0.00062236581484946,6.55108363179863E-8,7.70425134505619E-8,3.80072375964937E-8,1.00015061644678,10.005763053894,2,20,10,5,2.03616355405166,0.17940903098822,0.0410455763339996,172.855895996094,48.9999885559082,49.0007286071777,200.113494873047,200.113494873047,,,169.672180175781,0,1,,,,,,1,1,1,49.0004539489746,0,49.0003318786621,,,,,,,,,,,,,,,,,,,,,,,,,,,,,,,,,
,3767921454.16084,49.000768661499,200.113494873047,,,5,,,,25.0300001353025,,,,,0.000623304203005167,1.18739972819711E-7,0.00694918063861483,8.23696794431029E-5,0.000623210329391248,1.18722089817621E-7,0.000623210324807438,1.07064342188245E-7,7.55867392149482E-8,5.13045928008568E-8,1.00015062910464,10.005763053894,2,20,10,5,2.03892697061871,0.179647374707639,0.0410455763339996,172.855895996094,48.9996109008789,49.0010604858398,200.113494873047,200.113494873047,,,170.418395996094,0,1,,,,,,1,1,1,49.0004768371582,0,49.0002729627821,,,,,,,,,,,,,,,,,,,,,,,,,,,,,,,,,
,3767921608.08349,49.0007648468018,200.113494873047,,,5,,,,25.0300001353025,,,,,0.000623724208945659,7.99755842396054E-8,0.00740693043071605,7.8186318033405E-5,0.000623630272185013,7.99635394172199E-8,0.000623630266973925,6.33853799418802E-8,8.06200049454281E-8,4.87489614838385E-8,1.00015062893005,10.005763053894,2,20,10,5,2.04029944051228,0.17978472743027,0.0410455763339996,172.855895996094,48.9998588562012,49.0009803771973,200.113494873047,200.113494873047,,,171.015380859375,0,1,,,,,,1,1,1,49.0007286071777,0,49.0003395080566,,,,,,,,,,,,,,,,,,,,,,,,,,,,,,,,,