File: Experimental_Data/Fig3C/Lifetime_300Oe_48p5K.dat
[Header]
; MPMS3 Data File (default extension .dat)
; Copyright (c) 2007, Quantum Design, Inc. All rights reserved.
TITLE,300Oe_48p5K
FILEOPENTIME,3768606858.59134,06/02/2019,3:14 am
BYAPP,SQUID AC,0.9.1.0
INFO,MPMS3 Measurement Release 1.1.16 Build 347, MultiVu Release 2.3.3.2,APPNAME
INFO,0,MOMENT_UNITS
INFO,,SAMPLE_MATERIAL
INFO,,SAMPLE_COMMENT
INFO,,SAMPLE_MASS
INFO,,SAMPLE_VOLUME
INFO,,SAMPLE_MOLECULAR_WEIGHT
INFO,,SAMPLE_SIZE
INFO,,SAMPLE_SHAPE
INFO,Quartz,SAMPLE_HOLDER
INFO,Standard,SAMPLE_HOLDER_DETAIL
INFO,66.2,SAMPLE_OFFSET
DATATYPE,COMMENT,1
DATATYPE,TIME,2
STARTUPAXIS,X,2
STARTUPAXIS,Y1,5
FIELDGROUP, VSM,2,3,4,5,6,8,9,10,11,14,15
FIELDGROUP, DC, 2,3,4,14,56,57,58,59,60,61,62,63,64,65,66,67,68,69
FIELDGROUP, AC, 2,3,4,11,16,17,18,19,20,21,22,23,24,25,26,27,28,29,30
STARTUPGROUP, All
[Data]
Comment,Time Stamp (sec),Temperature (K),Magnetic Field (Oe),Moment (emu),M. Std. Err. (emu),Transport Action,Averaging Time (sec),Frequency (Hz),Peak Amplitude (mm),Center Position (mm),Lockin Signal' (V),Lockin Signal (V),Range,M. Quad. Signal (emu),AC Moment (emu),AC M. Std Err. (emu),AC Phase (deg),AC Phase Std. Err. (deg),AC Susceptibility (emu/Oe),AC Suscept. Std Err. (emu/Oe),AC X' (emu/Oe),AC X' Std Err. (emu/Oe),AC X'' (emu/Oe),AC X'' Std Err. (emu/Oe),AC Drive (Oe),AC Frequency (Hz),AC Averaging Time (sec),AC Cycles,AC Range,AC Measure Type,AC Signal' (V),AC Signal'' (V),AC Trim Coil Ratio,AC Trim Coil Phase,Min. Temperature (K),Max. Temperature (K),Min. Field (Oe),Max. Field (Oe),Mass (grams),Motor Lag (deg),Pressure (Torr),Measure Count,Measurement Number,SQUID Status (code),Motor Status (code),Measure Status (code),Motor Current (amps),Motor Temp. (C),Temp. Status (code),Field Status (code),Chamber Status (code),Chamber Temp (K),Redirection State,Average Temp (K),Rotation Angle (deg),Rotator state,DC Moment Fixed Ctr (emu),DC Moment Err Fixed Ctr (emu),DC Moment Free Ctr (emu),DC Moment Err Free Ctr (emu),DC Fixed Fit,DC Free Fit,DC Calculated Center (mm),DC Calculated Center Err (mm),DC Scan Length (mm),DC Scan Time (s),DC Number of Points,DC Squid Drift,DC Min V (V),DC Max V (V),DC Scans per Measure,Map 01,Map 02,Map 03,Map 04,Map 05,Map 06,Map 07,Map 08,Map 09,Map 10,Map 11,Map 12,Map 13,Map 14,Map 15,Map 16
,3768606862.69169,48.470308303833,299.805969238281,,,5,,,,25.0300001353025,,,,,0.000611140420155264,1.53595740031234E-7,0.0337250972067382,0.000126248778510071,0.000611048631082782,1.53572671011333E-7,0.000611048525228868,1.32811813434094E-7,3.59671750109063E-7,7.71076357691157E-8,1.00015021565848,10.005763053894,2,20,10,5,1.99904124140588,0.177291048837675,0.0410455763339996,172.855895996094,48.4181137084961,48.4807662963867,299.805969238281,299.805969238281,,,38.1746482849121,0,1,,,,,,1,1,1,48.4643440246582,0,48.4444862814511,,,,,,,,,,,,,,,,,,,,,,,,,,,,,,,,,
,3768607069.26946,48.5002937316895,299.805969238281,,,5,,,,25.0300001353025,,,,,0.000629661611117583,2.02942383829687E-7,-0.00576245050677038,0.000232829681222674,0.000629566681951986,2.02911787790765E-7,0.000629566678767929,1.40327245530993E-7,-6.33178721046221E-8,1.46565540923265E-7,1.00015078492607,10.005763053894,2,20,10,5,2.05974949829559,0.181244372428207,0.0410455763339996,172.855895996094,48.4999351501465,48.5005378723145,299.805969238281,299.805969238281,,,38.4855766296387,0,1,,,,,,1,1,1,48.5004577636719,0,48.5002142962287,,,,,,,,,,,,,,,,,,,,,,,,,,,,,,,,,
,3768607277.02292,48.4984512329102,299.805969238281,,,5,,,,25.0300001353025,,,,,0.000640760025420594,1.33378982095783E-7,-0.00163658348816398,0.000124412814011776,0.000640663403557463,1.33358869533761E-7,0.000640663403296108,1.06930677528337E-7,-1.82997623298082E-8,7.96895117732157E-8,1.00015081533079,10.005763053894,2,20,10,5,2.0960413514631,0.184589927347383,0.0410455763339996,172.855895996094,48.4974822998047,48.501766204834,299.805969238281,299.805969238281,,,38.6970062255859,0,1,,,,,,1,1,1,48.4990196228027,0,48.4999757654527,,,,,,,,,,,,,,,,,,,,,,,,,,,,,,,,,
,3768607485.19564,48.5000858306885,299.805969238281,,,5,,,,25.0300001353025,,,,,0.000648759388666563,1.54885048479416E-7,-0.00428149702514879,0.000183983952869431,0.000648661660861989,1.54861716908399E-7,0.000648661659050923,9.870014498932E-8,-4.84720339320956E-8,1.19333284304524E-7,1.00015066067639,10.005763053894,2,20,10,5,2.12221733384389,0.186796409794078,0.0410455763339996,172.855895996094,48.4990386962891,48.5005111694336,299.805969238281,299.805969238281,,,38.8959999084473,0,1,,,,,,1,1,1,48.5002326965332,0,48.4998833151425,,,,,,,,,,,,,,,,,,,,,,,,,,,,,,,,,
,3768607694.02126,48.5001335144043,299.805969238281,,,5,,,,25.0300001353025,,,,,0.000655008224074802,1.74613937116936E-7,-0.00414542763912618,0.000151253826603319,0.000654909478399968,1.74587613216835E-7,0.000654909476685834,1.43782119514353E-7,-4.73835921875614E-8,9.90330086219318E-8,1.00015077759307,10.005763053894,2,20,10,5,2.14265803415678,0.188600717089972,0.0410455763339996,172.855895996094,48.4996299743652,48.5002098083496,299.805969238281,299.805969238281,,,39.0701179504395,0,1,,,,,,1,1,1,48.5002098083496,0,48.4998912811279,,,,,,,,,,,,,,,,,,,,,,,,,,,,,,,,,
,3768607901.70463,48.50022315979,299.805969238281,,,5,,,,25.0300001353025,,,,,0.000659872433689949,9.42209514935812E-8,-0.00277190898008239,8.5277084207419E-5,0.000659773027692377,9.42067576476236E-8,0.00065977302692027,7.55691109811682E-8,-3.19191185651933E-8,5.62514235552663E-8,1.00015066696182,10.005763053894,2,20,10,5,2.15856524510632,0.190053045995468,0.0410455763339996,172.855895996094,48.4998817443848,48.5003471374512,299.805969238281,299.805969238281,,,39.2318000793457,0,1,,,,,,1,1,1,48.5002708435059,0,48.5000946942498,,,,,,,,,,,,,,,,,,,,,,,,,,,,,,,,,
,3768608109.88371,48.4995079040527,299.805969238281,,,5,,,,25.0300001353025,,,,,0.000664103789131973,1.58354391806856E-7,-0.000973887465380408,0.000125218200941671,0.000664003691266446,1.58330523645168E-7,0.000664003691170525,1.34758234662733E-7,-1.12864311709368E-8,8.31190285574666E-8,1.00015074895945,10.005763053894,2,20,10,5,2.17240079057956,0.191339915994823,0.0410455763339996,172.855895996094,48.4990615844727,48.5000686645508,299.805969238281,299.805969238281,,,39.393482208252,0,1,,,,,,1,1,1,48.4993286132812,0,48.4995341830783,,,,,,,,,,,,,,,,,,,,,,,,,,,,,,,,,
,3768608318.62686,48.4993877410889,299.805969238281,,,5,,,,25.0300001353025,,,,,0.000667815504660445,1.17202688897276E-7,-0.00388555411023006,8.38694931914782E-5,0.000667714851013714,1.17185024021331E-7,0.000667714849478313,1.02950026586643E-7,-4.52815583255477E-8,5.59787627649046E-8,1.0001507434597,10.005763053894,2,20,10,5,2.18455224273513,0.19229831126685,0.0410455763339996,172.855895996094,48.4992179870605,48.500057220459,299.805969238281,299.805969238281,,,39.5302925109863,0,1,,,,,,1,1,1,48.4993743896484,0,48.4996687945198,,,,,,,,,,,,,,,,,,,,,,,,,,,,,,,,,
,3768608525.42503,48.4999980926514,299.805969238281,,,5,,,,25.0300001353025,,,,,0.000670690448830942,1.20449246515418E-7,-0.0046964017995883,0.000127340643578253,0.000670589343140245,1.20431088952142E-7,0.000670589340887501,8.49315853247502E-8,-5.49666488726782E-8,8.53830955190984E-8,1.00015077139494,10.005763053894,2,20,10,5,2.1939594681453,0.19309510322941,0.0410455763339996,172.855895996094,48.4991340637207,48.5002937316895,299.805969238281,299.805969238281,,,39.6919746398926,0,1,,,,,,1,1,1,48.5001068115234,0,48.4998054504395,,,,,,,,,,,,,,,,,,,,,,,,,,,,,,,,,
,3768608733.49442,48.4999809265137,299.805969238281,,,5,,,,25.0300001353025,,,,,0.000673277411769997,8.89637019173219E-8,-0.00066245473480997,8.14456269262264E-5,0.000673175993851601,8.89503010318866E-8,0.000673175993806605,7.00522350523066E-8,-7.78327179187153E-9,5.4816424708655E-8,1.00015065587502,10.005763053894,2,20,10,5,2.20240827636009,0.193994965177512,0.0410455763339996,172.855895996094,48.4995536804199,48.5002975463867,299.805969238281,299.805969238281,,,39.8536567687988,0,1,,,,,,1,1,1,48.5001029968262,0,48.4999409843894,,,,,,,,,,,,,,,,,,,,,,,,,,,,,,,,,
,3768608941.4231,48.5009441375732,299.805969238281,,,5,,,,25.0300001353025,,,,,0.000675799133580659,9.94004126867855E-8,-0.000320116534861192,8.96486822580791E-5,0.000675697306023451,9.93854353056283E-8,0.000675697306012905,7.88009685721589E-8,-3.77517998806101E-9,6.0562959826769E-8,1.00015069996032,10.005763053894,2,20,10,5,2.21065610657829,0.194734768280409,0.0410455763339996,172.855895996094,48.4997978210449,48.5012054443359,299.805969238281,299.805969238281,,,40.0029029846191,0,1,,,,,,1,1,1,48.5006828308105,0,48.5003388348748,,,,,,,,,,,,,,,,,,,,,,,,,,,,,,,,,
,3768609147.27465,48.5007133483887,299.805969238281,,,5,,,,25.0300001353025,,,,,0.000677848199919853,7.28350360455323E-8,-0.00145825801288435,7.0286897050286E-5,0.000677746070772919,7.2824062231485E-8,0.000677746070553406,5.50892275251751E-8,-1.7249588830066E-8,4.76289938018292E-8,1.00015068939731,10.005763053894,2,20,10,5,2.21736283733457,0.195281170030729,0.0410455763339996,172.855895996094,48.4998779296875,48.5010452270508,299.805969238281,299.805969238281,,,40.1397094726562,0,1,,,,,,1,1,1,48.500732421875,0,48.5003422007841,,,,,,,,,,,,,,,,,,,,,,,,,,,,,,,,,
,3768609353.58356,48.5008163452148,299.805969238281,,,5,,,,25.0300001353025,,,,,0.000679797310437427,9.56944408294976E-8,-0.00186015831057862,9.92462176729315E-5,0.000679694884420808,9.5680022413543E-8,0.000679694884062598,6.78624493077313E-8,-2.20668973951623E-8,6.74489040905164E-8,1.00015069411138,10.005763053894,2,20,10,5,2.22374010058686,0.195827089876081,0.0410455763339996,172.855895996094,48.4997024536133,48.5011901855469,299.805969238281,299.805969238281,,,40.2889556884766,0,1,,,,,,1,1,1,48.5008964538574,0,48.5004471672906,,,,,,,,,,,,,,,,,,,,,,,,,,,,,,,,,
,3768609566.49154,48.5002021789551,299.805969238281,,,5,,,,25.0300001353025,,,,,0.000681609107394161,1.14925945704041E-7,-0.00953679025443854,8.63490550989327E-5,0.000681506427545695,1.14908632879782E-7,0.000681506418105105,9.87073349101554E-8,-1.13435647124061E-7,5.88290399822653E-8,1.00015066600155,10.005763053894,2,20,10,5,2.22969310361997,0.196050272836785,0.0410455763339996,172.855895996094,48.499584197998,48.5002593994141,299.805969238281,299.805969238281,,,40.4008903503418,0,1,,,,,,1,1,1,48.5003280639648,0,48.4999605814616,,,,,,,,,,,,,,,,,,,,,,,,,,,,,,,,,
,3768609773.46232,48.4989833831787,299.805969238281,,,5,,,,25.0300001353025,,,,,0.000683212464545976,7.14751507368548E-8,-0.00998730675891135,8.01006842393984E-5,0.000683109502898534,7.14643792716767E-8,0.000683109492520577,4.59747883108458E-8,-1.1907376387589E-7,5.4712670785285E-8,1.0001507249526,10.005763053894,2,20,10,5,2.2349395816595,0.196493876196461,0.0410455763339996,172.855895996094,48.498649597168,48.5001220703125,299.805969238281,299.805969238281,,,40.5501365661621,0,1,,,,,,1,1,1,48.4990577697754,0,48.4992913140191,,,,,,,,,,,,,,,,,,,,,,,,,,,,,,,,,
,3768609982.7349,48.5003070831299,299.805969238281,,,5,,,,25.0300001353025,,,,,0.000684606269241947,8.55375139337983E-8,-0.00287316037667118,0.00010093455577998,0.000684503134605058,8.55246278694483E-8,0.000684503133744421,5.04148795990665E-8,-3.43251684494697E-8,6.90854679887112E-8,1.00015067080291,10.005763053894,2,20,10,5,2.23947456188961,0.197172799092216,0.0410455763339996,172.855895996094,48.4997901916504,48.5006561279297,299.805969238281,299.805969238281,,,40.6869430541992,0,1,,,,,,1,1,1,48.5004577636719,0,48.5001653783462,,,,,,,,,,,,,,,,,,,,,,,,,,,,,,,,,
,3768610190.50291,48.4993324279785,299.805969238281,,,5,,,,25.0300001353025,,,,,0.000686022799731957,8.93615568854539E-8,-0.00694062117752825,8.5091745568557E-5,0.000685919403604481,8.93480884716769E-8,0.000685919398571857,6.76576653015733E-8,-8.3090007109592E-8,5.83568439815151E-8,1.00015074092806,10.005763053894,2,20,10,5,2.24412231726714,0.197421464912373,0.0410455763339996,172.855895996094,48.4988403320313,48.5000953674316,299.805969238281,299.805969238281,,,40.8237495422363,0,1,,,,,,1,1,1,48.4996757507324,0,48.4994843426873,,,,,,,,,,,,,,,,,,,,,,,,,,,,,,,,,
,3768610398.69978,48.5001754760742,299.805969238281,,,5,,,,25.0300001353025,,,,,0.000687265009643618,1.12566205998378E-7,-0.00312822844954042,8.68576080835821E-5,0.000687161478611046,1.1254924879064E-7,0.000687161477586856,9.54314614237188E-8,-3.75175641909287E-8,5.96671565760478E-8,1.00015066477938,10.005763053894,2,20,10,5,2.24817267782763,0.197928532658999,0.0410455763339996,172.855895996094,48.4997215270996,48.5005035400391,299.805969238281,299.805969238281,,,40.9605598449707,0,1,,,,,,1,1,1,48.5003051757812,0,48.5001701778836,,,,,,,,,,,,,,,,,,,,,,,,,,,,,,,,,
,3768610606.78789,48.5013122558594,299.805969238281,,,5,,,,25.0300001353025,,,,,0.000688670044618227,7.86401305861282E-8,-0.00582220068504036,8.4182800263993E-5,0.000688566266107975,7.86282799826905E-8,0.000688566262552933,5.31328792430825E-8,-6.99697432062126E-8,5.79594992764463E-8,1.00015071680877,10.005763053894,2,20,10,5,2.25277813383163,0.198227248683323,0.0410455763339996,172.855895996094,48.4999618530273,48.5017318725586,299.805969238281,299.805969238281,,,41.0849304199219,0,1,,,,,,1,1,1,48.501220703125,0,48.5006584591336,,,,,,,,,,,,,,,,,,,,,,,,,,,,,,,,,
,3768610811.25332,48.4999961853027,299.805969238281,,,5,,,,25.0300001353025,,,,,0.000689541475270211,9.33909337674278E-8,-0.00557387658766473,8.35247188088729E-5,0.000689437527872596,9.33768552168632E-8,0.000689437524610217,7.35150684345627E-8,-6.70702052029453E-8,5.75740549488447E-8,1.00015077130764,10.005763053894,2,20,10,5,2.25562789806521,0.19848786171935,0.0410455763339996,172.855895996094,48.4994316101074,48.5005531311035,299.805969238281,299.805969238281,,,41.2341766357422,0,1,,,,,,1,1,1,48.5003204345703,0,48.4998499552409,,,,,,,,,,,,,,,,,,,,,,,,,,,,,,,,,
,3768611017.07871,48.4999446868897,299.805969238281,,,5,,,,25.0300001353025,,,,,0.000690547456685464,1.33467771459742E-7,-0.00379381479457397,0.000127590467058418,0.000690443359264734,1.33447651697334E-7,0.000690443357751156,1.00250312898981E-7,-4.57174027745225E-8,8.80803639138116E-8,1.00015076895061,10.005763053894,2,20,10,5,2.25891248734652,0.198847620121529,0.0410455763339996,172.855895996094,48.4991722106934,48.5000228881836,299.805969238281,299.805969238281,,,41.3585472106934,0,1,,,,,,1,1,1,48.4998664855957,0,48.4995671440573,,,,,,,,,,,,,,,,,,,,,,,,,,,,,,,,,
,3768611223.12651,48.4999618530273,299.805969238281,,,5,,,,25.0300001353025,,,,,0.000691204761983785,1.52113325957524E-7,-0.0059244623406558,0.000187238498030233,0.000691100564933863,1.52090395328729E-7,0.000691100561239294,7.99291760007889E-8,-7.1460748035126E-8,1.29394030677941E-7,1.00015076973628,10.005763053894,2,20,10,5,2.26107005845135,0.198952812752531,0.0410455763339996,172.855895996094,48.4996871948242,48.5003623962402,299.805969238281,299.805969238281,,,41.4829177856445,0,1,,,,,,1,1,1,48.5000648498535,0,48.500083025764,,,,,,,,,,,,,,,,,,,,,,,,,,,,,,,,,
,3768611430.84838,48.5007762908936,299.805969238281,,,5,,,,25.0300001353025,,,,,0.000692191416952274,7.60495847525471E-8,-0.00364461539429595,8.14016247680202E-5,0.000692087124766777,7.60381263940559E-8,0.000692087123366581,5.10741775595594E-8,-4.40240347343912E-8,5.63313860306403E-8,1.00015069227813,10.005763053894,2,20,10,5,2.26428967635579,0.199326901482889,0.0410455763339996,172.855895996094,48.4998245239258,48.5008316040039,299.805969238281,299.805969238281,,,41.6072883605957,0,1,,,,,,1,1,1,48.5007934570313,0,48.5004702674018,,,,,,,,,,,,,,,,,,,,,,,,,,,,,,,,,
,3768611640.23669,48.501033782959,299.805969238281,,,5,,,,25.0300001353025,,,,,0.000692785127164903,1.02589844607484E-7,-0.00428981381787441,9.91874004053834E-5,0.000692680737363205,1.02574386230687E-7,0.000692680735421717,7.61740518194602E-8,-5.18619594844928E-8,6.86951129266728E-8,1.00015070406331,10.005763053894,2,20,10,5,2.26623406177014,0.199472348402381,0.0410455763339996,172.855895996094,48.5004196166992,48.5011367797852,299.805969238281,299.805969238281,,,41.756534576416,0,1,,,,,,1,1,1,48.5010681152344,0,48.5007860520307,,,,,,,,,,,,,,,,,,,,,,,,,,,,,,,,,
,3768611848.46514,48.4999980926514,299.805969238281,,,5,,,,25.0300001353025,,,,,0.000693604540003105,1.09474037805783E-7,-0.00544331497899453,9.39211307334509E-5,0.000693499980043723,1.09457534740583E-7,0.000693499976914056,8.79788954766896E-8,-6.5885111533632E-8,6.51203951323062E-8,1.00015077139494,10.005763053894,2,20,10,5,2.26891853939464,0.199662605078049,0.0410455763339996,172.855895996094,48.499568939209,48.5004730224609,299.805969238281,299.805969238281,,,41.8684692382812,0,1,,,,,,1,1,1,48.5002746582031,0,48.5000118928797,,,,,,,,,,,,,,,,,,,,,,,,,,,,,,,,,
,3768612057.82987,48.4998397827148,299.805969238281,,,5,,,,25.0300001353025,,,,,0.000694209716020658,1.26683946006106E-7,-0.00437538488892741,0.000124780337185747,0.000694105149485943,1.26664864018441E-7,0.000694105147462073,9.24371460030872E-8,-5.30052510890847E-8,8.65988557407892E-8,1.000150649415,10.005763053894,2,20,10,5,2.27089446522642,0.199879142487777,0.0410455763339996,172.855895996094,48.499137878418,48.5003433227539,299.805969238281,299.805969238281,,,41.9928398132324,0,1,,,,,,1,1,1,48.4995574951172,0,48.4996676974826,,,,,,,,,,,,,,,,,,,,,,,,,,,,,,,,,
,3768612265.93661,48.50022315979,299.805969238281,,,5,,,,25.0300001353025,,,,,0.000694912488765232,1.12240574873696E-7,-0.00094853613260959,0.000114060169526388,0.000694807804184327,1.12223666474824E-7,0.000694807804089114,7.94678014129148E-8,-1.15025978014206E-8,7.92402666303566E-8,1.00015066696182,10.005763053894,2,20,10,5,2.27318140022494,0.200217444811804,0.0410455763339996,172.855895996094,48.4994697570801,48.5011177062988,299.805969238281,299.805969238281,,,42.1172103881836,0,1,,,,,,1,1,1,48.4998359680176,0,48.5000146230062,,,,,,,,,,,,,,,,,,,,,,,,,,,,,,,,,
,3768612474.23566,48.5011692047119,299.805969238281,,,5,,,,25.0300001353025,,,,,0.000695418260923903,1.04797339370591E-7,-0.00802668138081142,8.49609090777849E-5,0.000695313470049047,1.04781547716141E-7,0.000695313463226014,8.65510748526751E-8,-9.7407866915229E-8,5.9060004941047E-8,1.00015071026144,10.005763053894,2,20,10,5,2.27486060566561,0.200082133445846,0.0410455763339996,172.855895996094,48.4997177124023,48.5014038085937,299.805969238281,299.805969238281,,,42.2540168762207,0,1,,,,,,1,1,1,48.5012741088867,0,48.5004287719727,,,,,,,,,,,,,,,,,,,,,,,,,,,,,,,,,
,3768612683.5943,48.5006923675537,299.805969238281,,,5,,,,25.0300001353025,,,,,0.000696047857789771,9.6617020414314E-8,-0.0013145507139809,0.000118049761386261,0.000695942987228759,9.66024635400693E-8,0.00069594298704559,5.08239770145722E-8,-1.5967185688824E-8,8.21520500196596E-8,1.00015068843704,10.005763053894,2,20,10,5,2.27689667390861,0.200530019261177,0.0410455763339996,172.855895996094,48.4997329711914,48.501579284668,299.805969238281,299.805969238281,,,42.403263092041,0,1,,,,,,1,1,1,48.5002326965332,0,48.5003765953912,,,,,,,,,,,,,,,,,,,,,,,,,,,,,,,,,
,3768612891.62005,48.5001926422119,299.805969238281,,,5,,,,25.0300001353025,,,,,0.000696597640345506,7.1485054209527E-8,-0.00240845908310128,6.55877773898178E-5,0.000696492702878868,7.14742854959157E-8,0.000696492702263522,5.49773298645953E-8,-2.92774474895719E-8,4.5673479045406E-8,1.00015066556506,10.005763053894,2,20,10,5,2.27869894190108,0.200644904766133,0.0410455763339996,172.855895996094,48.4994964599609,48.5003547668457,299.805969238281,299.805969238281,,,42.5525093078613,0,1,,,,,,1,1,1,48.5002784729004,0,48.5000410640941,,,,,,,,,,,,,,,,,,,,,,,,,,,,,,,,,
,3768613098.07234,48.4999160766602,299.805969238281,,,5,,,,25.0300001353025,,,,,0.000697056750022731,8.35443528264852E-8,-0.00423494810166591,8.16440827926803E-5,0.000696951672263114,8.35317589402294E-8,0.000696951670359304,6.116057052287E-8,-5.15143381205263E-8,5.68941065925605E-8,1.00015076764114,10.005763053894,2,20,10,5,2.2802071732075,0.200704457049522,0.0410455763339996,172.855895996094,48.4995346069336,48.5003662109375,299.805969238281,299.805969238281,,,42.6768798828125,0,1,,,,,,1,1,1,48.4999809265137,0,48.4999620774213,,,,,,,,,,,,,,,,,,,,,,,,,,,,,,,,,
,3768613303.07805,48.4998397827148,299.805969238281,,,5,,,,25.0300001353025,,,,,0.00069749907996938,1.19727616450971E-7,-0.00705156722494227,9.40065037234928E-5,0.00069739393796564,1.19709568539715E-7,0.000697393932683934,1.00172964685339E-7,-8.58304095905406E-8,6.55420319040729E-8,1.00015076414924,10.005763053894,2,20,10,5,2.28166398985515,0.200719652699613,0.0410455763339996,172.855895996094,48.4994850158691,48.500301361084,299.805969238281,299.805969238281,,,42.8261222839355,0,1,,,,,,1,1,1,48.5000457763672,0,48.4997708937701,,,,,,,,,,,,,,,,,,,,,,,,,,,,,,,,,
,3768613508.4567,48.5006084442139,299.805969238281,,,5,,,,25.0300001353025,,,,,0.000697929997454264,1.29046435951681E-7,-0.0071585272888024,0.000137292750393014,0.000697824845999308,1.29026993571289E-7,0.000697824840552795,8.64346607561395E-8,-8.71861458618159E-8,9.57967352784869E-8,1.00015068459594,10.005763053894,2,20,10,5,2.28307398546809,0.200839392467554,0.0410455763339996,172.855895996094,48.4996948242188,48.5008926391602,299.805969238281,299.805969238281,,,42.9629325866699,0,1,,,,,,1,1,1,48.5008697509766,0,48.5001126457663,,,,,,,,,,,,,,,,,,,,,,,,,,,,,,,,,
,3768613713.79933,48.5010643005371,299.805969238281,,,5,,,,25.0300001353025,,,,,0.00069832673461598,9.3223306954754E-8,-0.00525795590050659,9.56049357696061E-5,0.00069822150882226,9.32092598103711E-8,0.000698221505882229,6.50612738944781E-8,-6.4074839861137E-8,6.67457620649054E-8,1.00015070546007,10.005763053894,2,20,10,5,2.28436512815035,0.201029332873234,0.0410455763339996,172.855895996094,48.5001983642578,48.501350402832,299.805969238281,299.805969238281,,,43.1121788024902,0,1,,,,,,1,1,1,48.5012741088867,0,48.500654557172,,,,,,,,,,,,,,,,,,,,,,,,,,,,,,,,,
,3768613918.9473,48.5012512207031,299.805969238281,,,5,,,,25.0300001353025,,,,,0.0006987038368824,1.48159445333335E-7,-0.00770588630238578,9.74297351214047E-5,0.000698598548290145,1.48137118993325E-7,0.000698598541971883,1.31589301241247E-7,-9.39566755816138E-8,6.80357393028319E-8,1.00015071401524,10.005763053894,2,20,10,5,2.28560729583484,0.20104023897753,0.0410455763339996,172.855895996094,48.4999961853027,48.501407623291,299.805969238281,299.805969238281,,,43.2241096496582,0,1,,,,,,1,1,1,48.5013427734375,0,48.5008648143095,,,,,,,,,,,,,,,,,,,,,,,,,,,,,,,,,
,3768614124.03588,48.5000419616699,299.805969238281,,,5,,,,25.0300001353025,,,,,0.000699142964359831,7.31871950941932E-8,-0.00549810643523418,8.44092796954051E-5,0.000699037568087016,7.31761620752343E-8,0.00069903756486853,4.32851680286537E-8,-6.70796868169599E-8,5.90012281634219E-8,1.00015077340279,10.005763053894,2,20,10,5,2.28703602053337,0.201254721976521,0.0410455763339996,172.855895996094,48.4994316101074,48.5002059936523,299.805969238281,299.805969238281,,,43.3733558654785,0,1,,,,,,1,1,1,48.5001945495605,0,48.4998747881721,,,,,,,,,,,,,,,,,,,,,,,,,,,,,,,,,
,3768614329.04445,48.500171661377,299.805969238281,,,5,,,,25.0300001353025,,,,,0.000699655374025753,1.13276183300456E-7,-0.00303380745568038,0.00011877625673854,0.000699549896354766,1.13259106167289E-7,0.000699549895374103,7.69748499854601E-8,-3.70411173078678E-8,8.30812710514784E-8,1.00015077933903,10.005763053894,2,20,10,5,2.28870355031542,0.201500660744676,0.0410455763339996,172.855895996094,48.499397277832,48.5005989074707,299.805969238281,299.805969238281,,,43.5101661682129,0,1,,,,,,1,1,1,48.5003547668457,0,48.5001436869303,,,,,,,,,,,,,,,,,,,,,,,,,,,,,,,,,
,3768614535.65439,48.4994869232178,299.805969238281,,,5,,,,25.0300001353025,,,,,0.000700045902986773,1.04443150844124E-7,-0.00774741648236166,8.50012570192595E-5,0.000699940468668718,1.0442742060081E-7,0.000699940462269901,8.58313443889579E-8,-9.46444983067737E-8,5.94816483776516E-8,1.00015063326493,10.005763053894,2,20,10,5,2.28999762150014,0.201424747185479,0.0410455763339996,172.855895996094,48.4983253479004,48.5003242492676,299.805969238281,299.805969238281,,,43.6594123840332,0,1,,,,,,1,1,1,48.498722076416,0,48.4993725944968,,,,,,,,,,,,,,,,,,,,,,,,,,,,,,,,,
,3768614742.38535,48.4994831085205,299.805969238281,,,5,,,,25.0300001353025,,,,,0.000700495718942893,1.13645739607404E-7,-0.00410404884817961,7.75534441685011E-5,0.000700390136653437,1.13628610341585E-7,0.000700390134856678,9.98167216755021E-8,-5.01683606642367E-8,5.42962536655629E-8,1.00015074782458,10.005763053894,2,20,10,5,2.29145624330578,0.201699881376345,0.0410455763339996,172.855895996094,48.4993667602539,48.500301361084,299.805969238281,299.805969238281,,,43.7837829589844,0,1,,,,,,1,1,1,48.4994163513184,0,48.4996815849753,,,,,,,,,,,,,,,,,,,,,,,,,,,,,,,,,
,3768614950.09566,48.500316619873,299.805969238281,,,5,,,,25.0300001353025,,,,,0.00070076070253067,1.06289358518288E-7,-0.00593136633419,7.08960098997016E-5,0.000700655133953243,1.06273346181503E-7,0.00070065513019886,9.39604835780296E-8,-7.25331307349763E-8,4.96533144351556E-8,1.0001506712394,10.005763053894,2,20,10,5,2.29232948995514,0.201703068164072,0.0410455763339996,172.855895996094,48.4997329711914,48.5003623962402,299.805969238281,299.805969238281,,,43.8832817077637,0,1,,,,,,1,1,1,48.5002975463867,0,48.5000601375804,,,,,,,,,,,,,,,,,,,,,,,,,,,,,,,,,
,3768615155.36875,48.501392364502,299.805969238281,,,5,,,,25.0300001353025,,,,,0.000701084699144338,1.53171107558634E-7,-0.00730209862341091,0.000182692444026534,0.000700979047249186,1.53148025015518E-7,0.000700979041556396,8.39995743862094E-8,-8.93367393829244E-8,1.28056194965684E-7,1.00015072047527,10.005763053894,2,20,10,5,2.29339417571198,0.201741453824503,0.0410455763339996,172.855895996094,48.4999465942383,48.5014877319336,299.805969238281,299.805969238281,,,44.0200843811035,0,1,,,,,,1,1,1,48.5014877319336,0,48.5008015632629,,,,,,,,,,,,,,,,,,,,,,,,,,,,,,,,,
,3768615360.42441,48.5008068084717,299.805969238281,,,5,,,,25.0300001353025,,,,,0.000701819645839724,1.05581602039843E-7,-0.00507878301509823,7.89644423808147E-5,0.000701713901993108,1.05565693957478E-7,0.000701713899236315,8.98647538415016E-8,-6.22009626628802E-8,5.53935172897534E-8,1.00015069367489,10.005763053894,2,20,10,5,2.29579050077436,0.202042030304695,0.0410455763339996,172.855895996094,48.499698638916,48.5012016296387,299.805969238281,299.805969238281,,,44.1693305969238,0,1,,,,,,1,1,1,48.5004119873047,0,48.5001981398639,,,,,,,,,,,,,,,,,,,,,,,,,,,,,,,,,
,3768615565.89947,48.5007400512695,299.805969238281,,,5,,,,25.0300001353025,,,,,0.000701676736104384,1.0291191607392E-7,-0.00822130863189763,0.000100325718079968,0.000701571015933386,1.02896410550072E-7,0.00070157100871104,7.50657989177575E-8,-1.00667656124183E-7,7.03761119764921E-8,1.00015069061948,10.005763053894,2,20,10,5,2.29533409063552,0.20187499592848,0.0410455763339996,172.855895996094,48.4997406005859,48.5010528564453,299.805969238281,299.805969238281,,,44.2812690734863,0,1,,,,,,1,1,1,48.5004653930664,0,48.5001758999295,,,,,,,,,,,,,,,,,,,,,,,,,,,,,,,,,
,3768615773.44554,48.4998035430908,299.805969238281,,,5,,,,25.0300001353025,,,,,0.000701956227957972,1.42620260479691E-7,-0.00711693410981518,0.000101503318326639,0.000701850415241355,1.42598761935188E-7,0.000701850409826895,1.23542354775083E-7,-8.71796001350125E-8,7.12158232563239E-8,1.00015076249058,10.005763053894,2,20,10,5,2.2962444746431,0.201999669947104,0.0410455763339996,172.855895996094,48.4994163513184,48.5006294250488,299.805969238281,299.805969238281,,,44.4180717468262,0,1,,,,,,1,1,1,48.4997444152832,0,48.4998310313505,,,,,,,,,,,,,,,,,,,,,,,,,,,,,,,,,
,3768615981.1468,48.5002918243408,299.805969238281,,,5,,,,25.0300001353025,,,,,0.000702218957778612,8.12100893911573E-8,-0.00744946914138467,5.98538252485727E-5,0.000702113170313846,8.1197855301811E-8,0.000702113164379368,6.9484945323303E-8,-9.12871842520664E-8,4.2011118516786E-8,1.00015067010453,10.005763053894,2,20,10,5,2.29710509140911,0.20206194023074,0.0410455763339996,172.855895996094,48.4992599487305,48.5005226135254,299.805969238281,299.805969238281,,,44.5424461364746,0,1,,,,,,1,1,1,48.5003547668457,0,48.5000170539407,,,,,,,,,,,,,,,,,,,,,,,,,,,,,,,,,
,3768616188.45363,48.5005416870117,299.805969238281,,,5,,,,25.0300001353025,,,,,0.000702541907235512,1.23495647526844E-7,-0.00513312027984458,0.000148101745597901,0.000702436063087406,1.23477041815964E-7,0.00070243606026841,6.65212510707532E-8,-6.29311412908075E-8,1.04026453422209E-7,1.00015068154052,10.005763053894,2,20,10,5,2.29815335220953,0.202247776209727,0.0410455763339996,172.855895996094,48.499828338623,48.5009498596191,299.805969238281,299.805969238281,,,44.679256439209,0,1,,,,,,1,1,1,48.5007553100586,0,48.5003051757812,,,,,,,,,,,,,,,,,,,,,,,,,,,,,,,,,
,3768616393.42447,48.4998302459717,299.805969238281,,,5,,,,25.0300001353025,,,,,0.000702590854092728,8.14923415601565E-8,-0.0101190441147843,8.36516762146988E-5,0.000702484944854292,8.14800573241994E-8,0.000702484933898577,5.64496170851308E-8,-1.24066312918834E-7,5.87574716312481E-8,1.00015076371275,10.005763053894,2,20,10,5,2.29833105896955,0.202061869264438,0.0410455763339996,172.855895996094,48.499267578125,48.4998931884766,299.805969238281,299.805969238281,,,44.791187286377,0,1,,,,,,1,1,1,48.499813079834,0,48.499688316794,,,,,,,,,,,,,,,,,,,,,,,,,,,,,,,,,
,3768616602.45431,48.5008773803711,299.805969238281,,,5,,,,25.0300001353025,,,,,0.000703002798596793,1.12367393363184E-7,-0.00595087731386101,7.3134261151539E-5,0.000702896874213381,1.12350462496221E-7,0.000702896870422167,9.99116958677415E-8,-7.30045579406911E-8,5.13836496557676E-8,1.00015069690491,10.005763053894,2,20,10,5,2.29966390721324,0.202347634798744,0.0410455763339996,172.855895996094,48.4998054504395,48.5009689331055,299.805969238281,299.805969238281,,,44.9279975891113,0,1,,,,,,1,1,1,48.5009346008301,0,48.5004929436578,,,,,,,,,,,,,,,,,,,,,,,,,,,,,,,,,
,3768616810.09132,48.4992027282715,299.805969238281,,,5,,,,25.0300001353025,,,,,0.000703016668061628,1.27157333752047E-7,-0.00619674305270568,0.000141147753602656,0.000702910714820776,1.27138169581095E-7,0.000702910710709734,7.9512423786208E-8,-7.60223024673534E-8,9.92062932886505E-8,1.00015073499182,10.005763053894,2,20,10,5,2.29971014450226,0.202341767698154,0.0410455763339996,172.855895996094,48.4979133605957,48.4997825622559,299.805969238281,299.805969238281,,,45.0523643493652,0,1,,,,,,1,1,1,48.4987831115723,0,48.4992200066062,,,,,,,,,,,,,,,,,,,,,,,,,,,,,,,,,
,3768617016.54668,48.4997215270996,299.805969238281,,,5,,,,25.0300001353025,,,,,0.000703381660767078,1.15245521696377E-7,-0.00673629250571039,0.000109111442854664,0.000703275635820611,1.15228150046034E-7,0.000703275630959986,8.59706423639871E-8,-8.26844564184905E-8,7.67240198018513E-8,1.00015075873678,10.005763053894,2,20,10,5,2.30090601644891,0.202425147348324,0.0410455763339996,172.855895996094,48.4994201660156,48.5002174377441,299.805969238281,299.805969238281,,,45.1643028259277,0,1,,,,,,1,1,1,48.4999160766602,0,48.499870300293,,,,,,,,,,,,,,,,,,,,,,,,,,,,,,,,,
,3768617222.70593,48.5015106201172,299.805969238281,,,5,,,,25.0300001353025,,,,,0.000703712962477249,1.01975437168864E-7,-0.00608951422585591,8.78253223783749E-5,0.000703606910701028,1.0196006914693E-7,0.000703606906727099,8.11099962938418E-8,-7.4780800967717E-8,6.17820702280169E-8,1.00015072588772,10.005763053894,2,20,10,5,2.30198748676166,0.202546471399237,0.0410455763339996,172.855895996094,48.4999847412109,48.5019912719727,299.805969238281,299.805969238281,,,45.2637977600098,0,1,,,,,,1,1,1,48.5014419555664,0,48.5007627275255,,,,,,,,,,,,,,,,,,,,,,,,,,,,,,,,,
,3768617429.63289,48.5009021759033,299.805969238281,,,5,,,,25.0300001353025,,,,,0.000703679786170612,1.40713393559123E-7,-0.00290832746642966,0.000127676495164224,0.000703573758984295,1.40692191521649E-7,0.000703573758077893,1.08294495849997E-7,-3.57133266084157E-8,8.98142245068076E-8,1.00015069803978,10.005763053894,2,20,10,5,2.3018677112945,0.202664729842639,0.0410455763339996,172.855895996094,48.5000610351562,48.5011329650879,299.805969238281,299.805969238281,,,45.3881683349609,0,1,,,,,,1,1,1,48.5008850097656,0,48.5005493164063,,,,,,,,,,,,,,,,,,,,,,,,,,,,,,,,,
,3768617635.51389,48.5003929138184,299.805969238281,,,5,,,,25.0300001353025,,,,,0.000703977098742519,1.22664239108412E-7,-0.00648396155866315,0.000104605024508161,0.000703871043162215,1.22645759491555E-7,0.0007038710386551,9.80972620854822E-8,-7.96546065899417E-8,7.36132426441906E-8,1.00015067473131,10.005763053894,2,20,10,5,2.30285292443588,0.202606646929085,0.0410455763339996,172.855895996094,48.4987297058105,48.5004730224609,299.805969238281,299.805969238281,,,45.4752311706543,0,1,,,,,,1,1,1,48.5004730224609,0,48.4998061236213,,,,,,,,,,,,,,,,,,,,,,,,,,,,,,,,,
,3768617843.18427,48.5005493164063,299.805969238281,,,5,,,,25.0300001353025,,,,,0.000704359474769589,1.17033183578639E-7,-0.00308763325631389,0.000106285511624897,0.000704253356542988,1.1701555145422E-7,0.00070425335552039,8.99542171598105E-8,-3.79517671626031E-8,7.48390145398831E-8,1.00015068188971,10.005763053894,2,20,10,5,2.30409173390085,0.202853277642132,0.0410455763339996,172.855895996094,48.4992446899414,48.5010147094727,299.805969238281,299.805969238281,,,45.5995979309082,0,1,,,,,,1,1,1,48.5001182556152,0,48.5000394185384,,,,,,,,,,,,,,,,,,,,,,,,,,,,,,,,,
,3768618050.8261,48.500057220459,299.805969238281,,,5,,,,25.0300001353025,,,,,0.000704452273350514,1.20935847782552E-7,-0.00478675218924884,0.00010742908237816,0.000704346157004403,1.20917630408904E-7,0.000704346154546342,9.43273106338737E-8,-5.88443081455585E-8,7.56533661662528E-8,1.00015065936693,10.005763053894,2,20,10,5,2.3044013108661,0.202811665980859,0.0410455763339996,172.855895996094,48.4996757507324,48.5005760192871,299.805969238281,299.805969238281,,,45.7115325927734,0,1,,,,,,1,1,1,48.5000991821289,0,48.5001469780417,,,,,,,,,,,,,,,,,,,,,,,,,,,,,,,,,
,3768618259.92331,48.5000438690186,299.805969238281,,,5,,,,25.0300001353025,,,,,0.000704636102112082,1.22484076178803E-7,-0.00706118830150526,6.60917059496408E-5,0.000704529877683555,1.22465611611125E-7,0.000704529872333236,1.13280765390874E-7,-8.68269558428985E-8,4.65327220324007E-8,1.00015077349008,10.005763053894,2,20,10,5,2.30501070198098,0.202773089040486,0.0410455763339996,172.855895996094,48.4996871948242,48.5003509521484,299.805969238281,299.805969238281,,,45.8110313415527,0,1,,,,,,1,1,1,48.5002708435059,0,48.4999849531386,,,,,,,,,,,,,,,,,,,,,,,,,,,,,,,,,
,3768618466.67198,48.4997482299805,299.805969238281,,,5,,,,25.0300001353025,,,,,0.000704589360538037,8.44883722869736E-8,-0.00247340824013342,6.57830366185352E-5,0.000704483233503022,8.4475646434234E-8,0.000704483232846594,7.06374182638802E-8,-3.04119194999895E-8,4.63302275139606E-8,1.00015064522471,10.005763053894,2,20,10,5,2.30484155767712,0.202944194039434,0.0410455763339996,172.855895996094,48.4995384216309,48.5003242492676,299.805969238281,299.805969238281,,,45.9229621887207,0,1,,,,,,1,1,1,48.4997596740723,0,48.4998384363511,,,,,,,,,,,,,,,,,,,,,,,,,,,,,,,,,
,3768618674.19561,48.5004615783691,299.805969238281,,,5,,,,25.0300001353025,,,,,0.000705078857767747,1.37788999557216E-7,-0.00399891814593545,0.000127837081222241,0.000704972633990014,1.37768240931565E-7,0.000704972632272967,1.04215004002114E-7,-4.92030631247125E-8,9.01072757895671E-8,1.00015067787402,10.005763053894,2,20,10,5,2.30644819987269,0.203023772561384,0.0410455763339996,172.855895996094,48.4999809265137,48.5007858276367,299.805969238281,299.805969238281,,,46.0473365783691,0,1,,,,,,1,1,1,48.5004043579102,0,48.5002845315372,,,,,,,,,,,,,,,,,,,,,,,,,,,,,,,,,
,3768618879.3742,48.4995746612549,299.805969238281,,,5,,,,25.0300001353025,,,,,0.000705161398733418,1.28686148142944E-7,-0.00269369023704336,0.000121754391106745,0.000705055191136735,1.28666766131187E-7,0.000705055190357545,9.58552275058547E-8,-3.31472981148373E-8,8.583071749938E-8,1.00015063728063,10.005763053894,2,20,10,5,2.30671358078914,0.203100091204403,0.0410455763339996,172.855895996094,48.4983329772949,48.5000686645508,299.805969238281,299.805969238281,,,46.1468315124512,0,1,,,,,,1,1,1,48.4996604919434,0,48.4993414037368,,,,,,,,,,,,,,,,,,,,,,,,,,,,,,,,,
,3768619083.67749,48.4999809265137,299.805969238281,,,5,,,,25.0300001353025,,,,,0.000705230148440766,1.10176032078602E-7,-0.00533821664411427,0.000126465175354186,0.000705123917379996,1.10159435912393E-7,0.000705123914319565,6.46856219787298E-8,-6.56960121402266E-8,8.91676602236569E-8,1.00015065587502,10.005763053894,2,20,10,5,2.30694784665342,0.203013412193395,0.0410455763339996,172.855895996094,48.4996566772461,48.5001564025879,299.805969238281,299.805969238281,,,46.2587661743164,0,1,,,,,,1,1,1,48.5000534057617,0,48.4999158522662,,,,,,,,,,,,,,,,,,,,,,,,,,,,,,,,,
,3768619292.59884,48.5015544891357,299.805969238281,,,5,,,,25.0300001353025,,,,,0.000705559324959987,1.01602656672414E-7,-0.00671620133352224,8.41952253377538E-5,0.000705452993514855,1.01587344625743E-7,0.000705452988668221,8.24239231669611E-8,-8.26930773120834E-8,5.93825351250372E-8,1.00015072789556,10.005763053894,2,20,10,5,2.30802953306349,0.203052657267567,0.0410455763339996,172.855895996094,48.5003967285156,48.5018043518066,299.805969238281,299.805969238281,,,46.3582649230957,0,1,,,,,,1,1,1,48.5013313293457,0,48.5009698306813,,,,,,,,,,,,,,,,,,,,,,,,,,,,,,,,,
,3768619498.80933,48.5001068115234,299.805969238281,,,5,,,,25.0300001353025,,,,,0.000705589838858669,1.518916025486E-7,-0.0046887330141594,0.000106300438207571,0.000705483549552454,1.51868721758422E-7,0.000705483547190221,1.32076420051776E-7,-5.7732419981924E-8,7.49661784729865E-8,1.00015066163666,10.005763053894,2,20,10,5,2.30812216274302,0.203143120598124,0.0410455763339996,172.855895996094,48.4993667602539,48.5004920959473,299.805969238281,299.805969238281,,,46.4577598571777,0,1,,,,,,1,1,1,48.4998435974121,0,48.4998247358534,,,,,,,,,,,,,,,,,,,,,,,,,,,,,,,,,
,3768619708.27886,48.5015907287598,299.805969238281,,,5,,,,25.0300001353025,,,,,0.000705861031028854,1.20657341427155E-7,-0.00624794073855117,9.66299545810154E-5,0.000705754652944627,1.20639157540718E-7,0.000705754648748464,9.95251823008687E-8,-7.69605244276122E-8,6.81802348200191E-8,1.00015072955422,10.005763053894,2,20,10,5,2.30901481533161,0.203158356078476,0.0410455763339996,172.855895996094,48.4999351501465,48.5018768310547,299.805969238281,299.805969238281,,,46.5448188781738,0,1,,,,,,1,1,1,48.5013160705566,0,48.5006685256958,,,,,,,,,,,,,,,,,,,,,,,,,,,,,,,,,
,3768619916.44328,48.5000476837158,299.805969238281,,,5,,,,25.0300001353025,,,,,0.000706017890560563,1.08140865770803E-7,-0.00386968256135667,0.000104283531318496,0.000705911538683162,1.08124575837853E-7,0.000705911537073163,7.92039595518242E-8,-4.76763488033571E-8,7.36047328059052E-8,1.00015065893044,10.005763053894,2,20,10,5,2.30951949750878,0.203299373821826,0.0410455763339996,172.855895996094,48.4994850158691,48.5005073547363,299.805969238281,299.805969238281,,,46.6443138122559,0,1,,,,,,1,1,1,48.4998588562012,0,48.5001180312213,,,,,,,,,,,,,,,,,,,,,,,,,,,,,,,,,
,3768620122.04765,48.4999752044678,299.805969238281,,,5,,,,25.0300001353025,,,,,0.00070609385893528,7.63579873016651E-8,-0.00523365842820578,6.11248166913015E-5,0.000705987416967186,7.63464765168803E-8,0.000705987414021866,6.29880790733399E-8,-6.44881179954209E-8,4.31426282369681E-8,1.00015077034737,10.005763053894,2,20,10,5,2.30977284426853,0.20326626189881,0.0410455763339996,172.855895996094,48.4993362426758,48.5001831054687,299.805969238281,299.805969238281,,,46.7438125610352,0,1,,,,,,1,1,1,48.5001106262207,0,48.4998278898351,,,,,,,,,,,,,,,,,,,,,,,,,,,,,,,,,
,3768620330.89576,48.5006694793701,299.805969238281,,,5,,,,25.0300001353025,,,,,0.000706244793577596,1.08689236902815E-7,-0.00639227167680545,0.000116136228293097,0.000706138387427394,1.08672861273044E-7,0.000706138383032737,7.13140305482755E-8,-7.87811675284498E-8,8.20006086820699E-8,1.00015068738946,10.005763053894,2,20,10,5,2.31027069217472,0.203262994488384,0.0410455763339996,172.855895996094,48.4997138977051,48.5013160705566,299.805969238281,299.805969238281,,,46.8681831359863,0,1,,,,,,1,1,1,48.5001678466797,0,48.5001709881951,,,,,,,,,,,,,,,,,,,,,,,,,,,,,,,,,
,3768620537.37062,48.4999160766602,299.805969238281,,,5,,,,25.0300001353025,,,,,0.000706438384835405,1.34223482200556E-7,-0.00196988590319158,0.000105759404608204,0.000706331892842058,1.34203248693317E-7,0.000706331892424598,1.11504305009269E-7,-2.42843932002423E-8,7.46813358493291E-8,1.00015076764114,10.005763053894,2,20,10,5,2.31088826858401,0.20349707839093,0.0410455763339996,172.855895996094,48.4994430541992,48.5003890991211,299.805969238281,299.805969238281,,,46.9428062438965,0,1,,,,,,1,1,1,48.5002136230469,0,48.4998884762035,,,,,,,,,,,,,,,,,,,,,,,,,,,,,,,,,
,3768620691.3691,48.5013980865479,299.805969238281,,,5,,,,25.0300001353025,,,,,0.000706590066485203,7.30592047532374E-8,-0.00628465753629204,6.34820051397916E-5,0.000706483584758517,7.30481948754577E-8,0.000706483580508506,5.76661388411858E-8,-7.74927475295481E-8,4.48403301249212E-8,1.00015072073716,10.005763053894,2,20,10,5,2.31139976881217,0.203366702213271,0.0410455763339996,172.855895996094,48.5000991821289,48.5015487670898,299.805969238281,299.805969238281,,,47.0174293518066,0,1,,,,,,1,1,1,48.5015449523926,0,48.5006976408117,,,,,,,,,,,,,,,,,,,,,,,,,,,,,,,,,