File: Experimental_Data/Fig3C/Lifetime_200Oe_50K.dat
[Header]
; MPMS3 Data File (default extension .dat)
; Copyright (c) 2007, Quantum Design, Inc. All rights reserved.
TITLE,200Oe_50K
FILEOPENTIME,3768324775.75894,05/29/2019,8:52 pm
BYAPP,SQUID AC,0.9.1.0
INFO,MPMS3 Measurement Release 1.1.16 Build 347, MultiVu Release 2.3.3.2,APPNAME
INFO,0,MOMENT_UNITS
INFO,,SAMPLE_MATERIAL
INFO,,SAMPLE_COMMENT
INFO,,SAMPLE_MASS
INFO,,SAMPLE_VOLUME
INFO,,SAMPLE_MOLECULAR_WEIGHT
INFO,,SAMPLE_SIZE
INFO,,SAMPLE_SHAPE
INFO,Quartz,SAMPLE_HOLDER
INFO,Standard,SAMPLE_HOLDER_DETAIL
INFO,66.2,SAMPLE_OFFSET
DATATYPE,COMMENT,1
DATATYPE,TIME,2
STARTUPAXIS,X,2
STARTUPAXIS,Y1,5
FIELDGROUP, VSM,2,3,4,5,6,8,9,10,11,14,15
FIELDGROUP, DC, 2,3,4,14,56,57,58,59,60,61,62,63,64,65,66,67,68,69
FIELDGROUP, AC, 2,3,4,11,16,17,18,19,20,21,22,23,24,25,26,27,28,29,30
STARTUPGROUP, All
[Data]
Comment,Time Stamp (sec),Temperature (K),Magnetic Field (Oe),Moment (emu),M. Std. Err. (emu),Transport Action,Averaging Time (sec),Frequency (Hz),Peak Amplitude (mm),Center Position (mm),Lockin Signal' (V),Lockin Signal (V),Range,M. Quad. Signal (emu),AC Moment (emu),AC M. Std Err. (emu),AC Phase (deg),AC Phase Std. Err. (deg),AC Susceptibility (emu/Oe),AC Suscept. Std Err. (emu/Oe),AC X' (emu/Oe),AC X' Std Err. (emu/Oe),AC X'' (emu/Oe),AC X'' Std Err. (emu/Oe),AC Drive (Oe),AC Frequency (Hz),AC Averaging Time (sec),AC Cycles,AC Range,AC Measure Type,AC Signal' (V),AC Signal'' (V),AC Trim Coil Ratio,AC Trim Coil Phase,Min. Temperature (K),Max. Temperature (K),Min. Field (Oe),Max. Field (Oe),Mass (grams),Motor Lag (deg),Pressure (Torr),Measure Count,Measurement Number,SQUID Status (code),Motor Status (code),Measure Status (code),Motor Current (amps),Motor Temp. (C),Temp. Status (code),Field Status (code),Chamber Status (code),Chamber Temp (K),Redirection State,Average Temp (K),Rotation Angle (deg),Rotator state,DC Moment Fixed Ctr (emu),DC Moment Err Fixed Ctr (emu),DC Moment Free Ctr (emu),DC Moment Err Free Ctr (emu),DC Fixed Fit,DC Free Fit,DC Calculated Center (mm),DC Calculated Center Err (mm),DC Scan Length (mm),DC Scan Time (s),DC Number of Points,DC Squid Drift,DC Min V (V),DC Max V (V),DC Scans per Measure,Map 01,Map 02,Map 03,Map 04,Map 05,Map 06,Map 07,Map 08,Map 09,Map 10,Map 11,Map 12,Map 13,Map 14,Map 15,Map 16
,3768324779.42703,49.9917945861816,200.222778320313,,,5,,,,25.0300001353025,,,,,0.000577643828445421,1.8816002532351E-7,0.0686247901836845,0.000141782502537507,0.000577557010605312,1.88131745532073E-7,0.000577556596337103,1.69410857016032E-7,6.91756348065725E-7,8.18139059209263E-8,1.00015031908282,10.005763053894,2,20,10,5,1.88938460941383,0.168518151949168,0.0410455763339996,172.855895996094,49.9338340759277,49.9946022033691,200.222778320313,200.222778320313,,,20.0518207550049,0,1,,,,,,1,1,1,49.9897041320801,0,49.9678429996266,,,,,,,,,,,,,,,,,,,,,,,,,,,,,,,,,
,3768324984.64906,50.0004348754883,200.222778320313,,,5,,,,25.0300001353025,,,,,0.000587705111333604,9.96414704595249E-8,0.00835846519335703,0.00012208191368346,0.00058761668381948,9.96264781659979E-8,0.000587616677566717,6.91399520730727E-8,8.57231304480007E-8,7.17293676194992E-8,1.00015048502971,10.005763053894,2,20,10,5,1.92247280895196,0.169431282076974,0.0410455763339996,172.855895996094,49.9999923706055,50.0007858276367,200.222778320313,200.222778320313,,,20.2774982452393,0,1,,,,,,1,1,1,50.0003776550293,0,50.0003552156336,,,,,,,,,,,,,,,,,,,,,,,,,,,,,,,,,
,3768325192.37495,49.999002456665,200.222778320313,,,5,,,,25.0300001353025,,,,,0.000594401028367057,9.58558370718802E-8,0.0138416101655618,0.000109379106721807,0.000594311632324106,9.5841420655826E-8,0.000594311614981586,7.04353055357546E-8,1.43574795934046E-7,6.49957356094374E-8,1.00015041947371,10.005763053894,2,20,10,5,1.94435976364708,0.171547745899859,0.0410455763339996,172.855895996094,49.9983406066895,50.0002136230469,200.222778320313,200.222778320313,,,20.288501739502,0,1,,,,,,1,1,1,49.9992179870605,0,49.9993209838867,,,,,,,,,,,,,,,,,,,,,,,,,,,,,,,,,
,3768325400.11933,50.0000152587891,200.222778320313,,,5,,,,25.0300001353025,,,,,0.000600244904259978,1.14608421919601E-7,0.00498912859723522,0.000146071651636952,0.000600154601502402,1.14591179863122E-7,0.00060015459922711,7.38048981134161E-8,5.22594946221188E-8,8.76582883525031E-8,1.00015046582556,10.005763053894,2,20,10,5,1.96350255166074,0.172930951708132,0.0410455763339996,172.855895996094,49.9995918273926,50.000373840332,200.222778320313,200.222778320313,,,20.2743148803711,0,1,,,,,,1,1,1,50.0002822875977,0,50.0000148100011,,,,,,,,,,,,,,,,,,,,,,,,,,,,,,,,,
,3768325607.90057,49.9998264312744,200.222778320313,,,5,,,,25.0300001353025,,,,,0.00060541172632383,9.14593151369812E-8,0.00909292375417081,9.88735331880503E-5,0.000605320651483381,9.14455564960902E-8,0.000605320643860532,6.91479538556575E-8,9.60652696312818E-8,5.98402062200281E-8,1.00015045718369,10.005763053894,2,20,10,5,1.9803916020856,0.174561363706864,0.0410455763339996,172.855895996094,49.9992446899414,50.0000953674316,200.222778320313,200.222778320313,,,20.247953414917,0,1,,,,,,1,1,1,49.9997673034668,0,49.9996924930149,,,,,,,,,,,,,,,,,,,,,,,,,,,,,,,,,
,3768325813.06566,50.0004806518555,200.222778320313,,,5,,,,25.0300001353025,,,,,0.000610545665170119,1.00587641482075E-7,0.00951063265447605,0.000107440728443749,0.000610453799733028,1.0057250661473E-7,0.000610453791323021,7.62532172015055E-8,1.01330357392254E-7,6.55764893326094E-8,1.00015048712471,10.005763053894,2,20,10,5,1.99718419466872,0.17605621591472,0.0410455763339996,172.855895996094,49.999080657959,50.0006446838379,200.222778320313,200.222778320313,,,20.2110652923584,0,1,,,,,,1,1,1,50.0004005432129,0,49.9998168945313,,,,,,,,,,,,,,,,,,,,,,,,,,,,,,,,,
,3768326020.24864,49.9999141693115,200.222778320313,,,5,,,,25.0300001353025,,,,,0.000615120584922318,1.34171350424937E-7,0.0104107578635659,0.000174016052505845,0.000615028047064877,1.34151165879658E-7,0.000615028036912112,8.08928786666405E-8,1.11751827036399E-7,1.07018117568456E-7,1.0001504611991,10.005763053894,2,20,10,5,2.0121466395193,0.177407046932318,0.0410455763339996,172.855895996094,49.9996604919434,50.0004920959473,200.222778320313,200.222778320313,,,20.1967067718506,0,1,,,,,,1,1,1,49.9999504089355,0,50.0000163184272,,,,,,,,,,,,,,,,,,,,,,,,,,,,,,,,,
,3768326225.75562,50.0010871887207,200.222778320313,,,5,,,,25.0300001353025,,,,,0.000619260494651674,1.20070817145176E-7,0.0118366028507708,0.00012279620981205,0.000619167300757567,1.20052747419891E-7,0.000619167287545009,9.2919838724209E-8,1.27912342713604E-7,7.60168779583265E-8,1.00015051488345,10.005763053894,2,20,10,5,2.02568442627794,0.178651445794506,0.0410455763339996,172.855895996094,50.0001335144043,50.0012245178223,200.222778320313,200.222778320313,,,20.1827163696289,0,1,,,,,,1,1,1,50.0011177062988,0,50.0006872812907,,,,,,,,,,,,,,,,,,,,,,,,,,,,,,,,,
,3768326431.1517,50.0001277923584,200.222778320313,,,5,,,,25.0300001353025,,,,,0.000623501459007917,1.15028468847459E-7,0.012755281084905,0.00013479803757993,0.000623407654249885,1.15011163005538E-7,0.000623407638801719,7.8532128870059E-8,1.38784040680361E-7,8.40254268125007E-8,1.00015047097576,10.005763053894,2,20,10,5,2.03955430674257,0.179907634730627,0.0410455763339996,172.855895996094,49.9995231628418,50.000415802002,200.222778320313,200.222778320313,,,20.1565990447998,0,1,,,,,,1,1,1,49.9998664855957,0,49.9998088163488,,,,,,,,,,,,,,,,,,,,,,,,,,,,,,,,,
,3768326634.79589,49.9995765686035,200.222778320313,,,5,,,,25.0300001353025,,,,,0.000627106311604372,1.08413346331653E-7,0.00982429097516402,0.000117909004594291,0.000627011980317686,1.08397038458069E-7,0.000627011971100401,7.92828557284168E-8,1.07511376260512E-7,7.39198669778775E-8,1.00015044574848,10.005763053894,2,20,10,5,2.05135550178146,0.180842856781819,0.0410455763339996,172.855895996094,49.9991455078125,50.000804901123,200.222778320313,200.222778320313,,,20.1180000305176,0,1,,,,,,1,1,1,49.9995651245117,0,49.9997338189019,,,,,,,,,,,,,,,,,,,,,,,,,,,,,,,,,
,3768326841.45592,50.0001010894775,200.222778320313,,,5,,,,25.0300001353025,,,,,0.000630653337295555,1.60473916661026E-7,0.0153737982922166,0.000188652079662361,0.000630558457319802,1.60449773823081E-7,0.000630558434620503,1.07685930361615E-7,1.69193586339944E-7,1.1894482049266E-7,1.00015046975368,10.005763053894,2,20,10,5,2.06294071160471,0.182065546407784,0.0410455763339996,172.855895996094,49.9997711181641,50.0003318786621,200.222778320313,200.222778320313,,,20.1034259796143,0,1,,,,,,1,1,1,49.9999885559082,0,50.0000619327321,,,,,,,,,,,,,,,,,,,,,,,,,,,,,,,,,
,3768327046.46883,50.0004997253418,200.222778320313,,,5,,,,25.0300001353025,,,,,0.000633778846575461,9.8500479026651E-8,0.00543279863029866,9.00886560819761E-5,0.000633683484816701,9.84856581171659E-8,0.000633683481968017,8.02622994722623E-8,6.00860096930912E-8,5.70735327292447E-8,1.00015048799763,10.005763053894,2,20,10,5,2.0731963318468,0.182608156221375,0.0410455763339996,172.855895996094,49.9994506835937,50.0008964538574,200.222778320313,200.222778320313,,,20.1013584136963,0,1,,,,,,1,1,1,50.0003204345703,0,50.0001332900103,,,,,,,,,,,,,,,,,,,,,,,,,,,,,,,,,
,3768327252.94189,50.0005493164063,200.222778320313,,,5,,,,25.0300001353025,,,,,0.00063685014380603,8.50075287252254E-8,0.00824174284044687,9.73109200258765E-5,0.000636754318478496,8.49947378444158E-8,0.000636754311890781,5.81848894626585E-8,9.15942739926843E-8,6.19566307949292E-8,1.00015049026721,10.005763053894,2,20,10,5,2.08323405919991,0.183595207322795,0.0410455763339996,172.855895996094,49.9997177124023,50.0008354187012,200.222778320313,200.222778320313,,,20.0755825042725,0,1,,,,,,1,1,1,50.0005798339844,0,50.0003291859346,,,,,,,,,,,,,,,,,,,,,,,,,,,,,,,,,
,3768327459.48177,50.0002632141113,200.222778320313,,,5,,,,25.0300001353025,,,,,0.000639950563223709,8.26663303328825E-8,0.00866031587517657,7.66322907119927E-5,0.00063985427976026,8.26538928087167E-8,0.000639854272451002,6.65470754562043E-8,9.67146306900675E-8,4.90219618605893E-8,1.00015047717347,10.005763053894,2,20,10,5,2.09337465653153,0.184504310618334,0.0410455763339996,172.855895996094,49.9993896484375,50.0004005432129,200.222778320313,200.222778320313,,,20.0368461608887,0,1,,,,,,1,1,1,50.0001258850098,0,49.9998956568101,,,,,,,,,,,,,,,,,,,,,,,,,,,,,,,,,
,3768327664.64256,50.0009174346924,200.222778320313,,,5,,,,25.0300001353025,,,,,0.000642196553384272,1.05294001977982E-7,0.0080345998429836,8.74594671409053E-5,0.000642099912779183,1.05278156866373E-7,0.000642099906465892,8.90609360787973E-8,9.00418125964967E-8,5.61394689852774E-8,1.00015050711449,10.005763053894,2,20,10,5,2.10072365063077,0.185128908819193,0.0410455763339996,172.855895996094,49.9996070861816,50.0011138916016,200.222778320313,200.222778320313,,,20.0105228424072,0,1,,,,,,1,1,1,50.0007629394531,0,50.0004060533312,,,,,,,,,,,,,,,,,,,,,,,,,,,,,,,,,
,3768327872.42774,50,200.222778320313,,,5,,,,25.0300001353025,,,,,0.000644708765554807,1.04461393806125E-7,0.0113087469990161,0.000134969765471441,0.000644611773962229,1.04445678373841E-7,0.00064461176140621,5.77928646864949E-8,1.27230163878482E-7,8.69993363325275E-8,1.00015046512722,10.005763053894,2,20,10,5,2.10893085868958,0.185973632211015,0.0410455763339996,172.855895996094,49.9996910095215,50.0004997253418,200.222778320313,200.222778320313,,,19.9957695007324,0,1,,,,,,1,1,1,50.0001335144043,0,50.0000695621266,,,,,,,,,,,,,,,,,,,,,,,,,,,,,,,,,
,3768328080.11388,49.9994697570801,200.222778320313,,,5,,,,25.0300001353025,,,,,0.000647191930271763,8.36831119939613E-8,0.00861304157891585,9.00932326905649E-5,0.000647094580806427,8.36705245282818E-8,0.000647094573494942,6.00239994261007E-8,9.72750969853358E-8,5.8291304392107E-8,1.00015044086015,10.005763053894,2,20,10,5,2.11706241226697,0.18659032694658,0.0410455763339996,172.855895996094,49.9990577697754,49.9999542236328,200.222778320313,200.222778320313,,,19.9694290161133,0,1,,,,,,1,1,1,49.9993515014648,0,49.9994725121392,,,,,,,,,,,,,,,,,,,,,,,,,,,,,,,,,
,3768328290.32107,50.0004405975342,200.222778320313,,,5,,,,25.0300001353025,,,,,0.000649677146768455,1.0316989806876E-7,0.0113759512391143,9.38334284890177E-5,0.000649579394623847,1.03154374852582E-7,0.000649579381820237,8.32312955855695E-8,1.28972561913324E-7,6.09374801446086E-8,1.00015048529159,10.005763053894,2,20,10,5,2.12518289586962,0.187409309912416,0.0410455763339996,172.855895996094,49.9998893737793,50.0006408691406,200.222778320313,200.222778320313,,,19.9431991577148,0,1,,,,,,1,1,1,50.000560760498,0,50.0002351648667,,,,,,,,,,,,,,,,,,,,,,,,,,,,,,,,,
,3768328496.5695,50.0007953643799,200.222778320313,,,5,,,,25.0300001353025,,,,,0.000651498903779122,7.90559776553838E-8,0.00880024026854009,7.75190734933566E-5,0.000651400866953417,7.90440814003672E-8,0.000651400859269863,6.08198292050596E-8,1.00050722173654E-7,5.04867822295623E-8,1.00015050152783,10.005763053894,2,20,10,5,2.13115055902778,0.187839016819632,0.0410455763339996,172.855895996094,49.999828338623,50.0012092590332,200.222778320313,200.222778320313,,,19.9408893585205,0,1,,,,,,1,1,1,50.0010871887207,0,50.0003798989689,,,,,,,,,,,,,,,,,,,,,,,,,,,,,,,,,
,3768328703.49566,50.0001602172852,200.222778320313,,,5,,,,25.0300001353025,,,,,0.000653618854978819,9.00998624164947E-8,0.00931692592233357,8.27351233531374E-5,0.000653520518138977,9.00863069083072E-8,0.000653520509498669,7.20652762517795E-8,1.06269646405665E-7,5.40568094797725E-8,1.00015047245972,10.005763053894,2,20,10,5,2.13808353739753,0.188469520939631,0.0410455763339996,172.855895996094,49.9995613098145,50.0004272460937,200.222778320313,200.222778320313,,,19.9025344848633,0,1,,,,,,1,1,1,50.0003623962402,0,50.0000312328339,,,,,,,,,,,,,,,,,,,,,,,,,,,,,,,,,
,3768328908.57367,50.0006237030029,200.222778320313,,,5,,,,25.0300001353025,,,,,0.000655409167763988,1.51708747096261E-7,0.00478912179932145,0.000137164999790947,0.000655310547673641,1.51685919325334E-7,0.000655310545384442,1.22200271117969E-7,5.47747504651388E-8,8.98649645872446E-8,1.00015049367158,10.005763053894,2,20,10,5,2.14395484223115,0.188816326614435,0.0410455763339996,172.855895996094,49.9994239807129,50.0007476806641,200.222778320313,200.222778320313,,,19.8770751953125,0,1,,,,,,1,1,1,50.0007400512695,0,49.9999798045439,,,,,,,,,,,,,,,,,,,,,,,,,,,,,,,,,
,3768329116.40861,50.0011177062988,200.222778320313,,,5,,,,25.0300001353025,,,,,0.000657233151308284,8.09246734119419E-8,0.0074786711417465,6.92139830000921E-5,0.000657134241906657,8.09124947642154E-8,0.000657134236308724,6.69274564514991E-8,8.57740468671628E-8,4.54702912009794E-8,1.00015051628011,10.005763053894,2,20,10,5,2.14991251238136,0.189442715198375,0.0410455763339996,172.855895996094,49.9996910095215,50.0012435913086,200.222778320313,200.222778320313,,,19.8395023345947,0,1,,,,,,1,1,1,50.0012321472168,0,50.000431060791,,,,,,,,,,,,,,,,,,,,,,,,,,,,,,,,,
,3768329321.51807,50.0007438659668,200.222778320313,,,5,,,,25.0300001353025,,,,,0.000658471812105273,8.67977675651709E-8,0.0069951144805156,9.41468043493905E-5,0.000658372727555597,8.67847065387853E-8,0.000658372722648934,6.07494627146672E-8,8.03792640190587E-8,6.19765122357037E-8,1.00015049917095,10.005763053894,2,20,10,5,2.15396596743715,0.189781572207307,0.0410455763339996,172.855895996094,50.0001487731934,50.001392364502,200.222778320313,200.222778320313,,,19.8367900848389,0,1,,,,,,1,1,1,50.0010375976562,0,50.0006108003504,,,,,,,,,,,,,,,,,,,,,,,,,,,,,,,,,
,3768329527.63977,50.001220703125,200.222778320313,,,5,,,,25.0300001353025,,,,,0.000660501015318067,1.41980414911035E-7,0.00825286278760107,0.000149010998957055,0.00066040161101123,1.41959047094179E-7,0.000660401604160417,1.02327763526474E-7,9.5124002288784E-8,9.83941048211603E-8,1.00015052099386,10.005763053894,2,20,10,5,2.16059963429578,0.190413848526135,0.0410455763339996,172.855895996094,50.0000762939453,50.0015678405762,200.222778320313,200.222778320313,,,19.8706073760986,0,1,,,,,,1,1,1,50.0010528564453,0,50.0007104312672,,,,,,,,,,,,,,,,,,,,,,,,,,,,,,,,,
,3768329733.12147,50.0001411437988,200.222778320313,,,5,,,,25.0300001353025,,,,,0.000661962424506962,8.80653873712016E-8,0.0040190767103141,9.74335060542558E-5,0.000661862832956241,8.80521380262714E-8,0.0006618628313279,5.99615402287288E-8,4.64271106490154E-8,6.44809483831937E-8,1.0001504715868,10.005763053894,2,20,10,5,2.16539422211612,0.19067514862595,0.0410455763339996,172.855895996094,49.9997634887695,50.0005340576172,200.222778320313,200.222778320313,,,19.8094387054443,0,1,,,,,,1,1,1,50.000244140625,0,50.0000691133387,,,,,,,,,,,,,,,,,,,,,,,,,,,,,,,,,
,3768329938.27298,50.000244140625,200.222778320313,,,5,,,,25.0300001353025,,,,,0.000663578956847495,1.00395078057336E-7,0.00788073921656096,8.52603948101732E-5,0.00066347911896418,1.00379973250312E-7,0.000663479112688137,8.29331489796268E-8,9.1258133498469E-8,5.65529117734562E-8,1.00015047630055,10.005763053894,2,20,10,5,2.17066929290495,0.191287084756059,0.0410455763339996,172.855895996094,49.9988822937012,50.0005912780762,200.222778320313,200.222778320313,,,19.782886505127,0,1,,,,,,1,1,1,50.0000076293945,0,49.9997529422536,,,,,,,,,,,,,,,,,,,,,,,,,,,,,,,,,
,3768330146.53602,50.001163482666,200.222778320313,,,5,,,,25.0300001353025,,,,,0.000664728151979368,8.83308279117627E-8,0.0114731499670784,9.25904519607061E-5,0.000664628113235711,8.83175344999759E-8,0.000664628099910663,6.3356279243926E-8,1.33087952190064E-7,6.15302265599609E-8,1.00015051837511,10.005763053894,2,20,10,5,2.17441646944848,0.191754689523956,0.0410455763339996,172.855895996094,49.9998359680176,50.0015029907227,200.222778320313,200.222778320313,,,19.7574501037598,0,1,,,,,,1,1,1,50.0010643005371,0,50.0004983789781,,,,,,,,,,,,,,,,,,,,,,,,,,,,,,,,,
,3768330352.61364,50.0002365112305,200.222778320313,,,5,,,,25.0300001353025,,,,,0.000666263744398576,9.22291658979658E-8,0.00518424932334671,9.71754265727681E-5,0.000666163502811713,9.22152897145138E-8,0.000666163500084762,6.56819617211219E-8,6.02759524929572E-8,6.47266526370459E-8,1.00015047595138,10.005763053894,2,20,10,5,2.17946068434065,0.191958445387691,0.0410455763339996,172.855895996094,49.9995384216309,50.0008659362793,200.222778320313,200.222778320313,,,19.7309989929199,0,1,,,,,,1,1,1,50.0002098083496,0,49.9999564675724,,,,,,,,,,,,,,,,,,,,,,,,,,,,,,,,,
,3768330559.44549,50.000358581543,200.222778320313,,,5,,,,25.0300001353025,,,,,0.000667531862755194,1.07763833157263E-7,0.00506836977879299,9.20609597298426E-5,0.00066743142664757,1.07747619129816E-7,0.000667431424036203,8.85217641123587E-8,5.90408106246823E-8,6.14283868140761E-8,1.00015048153805,10.005763053894,2,20,10,5,2.18360930164391,0.19231938822588,0.0410455763339996,172.855895996094,49.9998054504395,50.0005531311035,200.222778320313,200.222778320313,,,19.7410125732422,0,1,,,,,,1,1,1,50.0004081726074,0,50.0001169840495,,,,,,,,,,,,,,,,,,,,,,,,,,,,,,,,,
,3768330768.75157,50.0001773834229,200.222778320313,,,5,,,,25.0300001353025,,,,,0.000668711432956516,1.00422406984962E-7,0.000146844014525804,7.75942939685805E-5,0.000668610824915819,1.0040729837292E-7,0.000668610824913623,8.59758177856127E-8,1.71359039915886E-9,5.1863130667592E-8,1.00015047324534,10.005763053894,2,20,10,5,2.18748441518478,0.192471334231373,0.0410455763339996,172.855895996094,49.9990539550781,50.0008201599121,200.222778320313,200.222778320313,,,19.7155799865723,0,1,,,,,,1,1,1,49.999584197998,0,49.9997062683105,,,,,,,,,,,,,,,,,,,,,,,,,,,,,,,,,
,3768330976.50541,49.9989414215088,200.222778320313,,,5,,,,25.0300001353025,,,,,0.000669846762026126,8.57772189602188E-8,0.00872568073777646,9.780571582489E-5,0.000669745944216439,8.57643087368262E-8,0.000669745936449794,5.53653453350676E-8,1.01996854074203E-7,6.54995815943457E-8,1.00015053142248,10.005763053894,2,20,10,5,2.1911694039704,0.193126194572997,0.0410455763339996,172.855895996094,49.9984703063965,50.0012359619141,200.222778320313,200.222778320313,,,19.7006988525391,0,1,,,,,,1,1,1,49.9991683959961,0,49.9996764239143,,,,,,,,,,,,,,,,,,,,,,,,,,,,,,,,,
,3768331184.57558,50.000919342041,200.222778320313,,,5,,,,25.0300001353025,,,,,0.000670788218833174,1.04355676176988E-7,0.00646366521302877,0.000102876377733424,0.000670687275568056,1.04339972259729E-7,0.000670687271300271,7.82792114748548E-8,7.56617335440087E-8,6.89869180499889E-8,1.00015050720178,10.005763053894,2,20,10,5,2.19425668482129,0.193310994523493,0.0410455763339996,172.855895996094,50.0001831054687,50.0012435913086,200.222778320313,200.222778320313,,,19.6990070343018,0,1,,,,,,1,1,1,50.0010833740234,0,50.0006637573242,,,,,,,,,,,,,,,,,,,,,,,,,,,,,,,,,
,3768331391.84226,49.9992179870605,200.222778320313,,,5,,,,25.0300001353025,,,,,0.000671877979552884,8.84887911922963E-8,0.00669520118190636,8.75073342496433E-5,0.000671776924595063,8.84754818841575E-8,0.000671776920008609,6.61306704685055E-8,7.84993534866488E-8,5.87762308932771E-8,1.00015042933766,10.005763053894,2,20,10,5,2.19782068509549,0.193633936487507,0.0410455763339996,172.855895996094,49.9983749389648,49.9999237060547,200.222778320313,200.222778320313,,,19.6618270874023,0,1,,,,,,1,1,1,49.998908996582,0,49.9993692285874,,,,,,,,,,,,,,,,,,,,,,,,,,,,,,,,,
,3768331601.18464,50.0009880065918,200.222778320313,,,5,,,,25.0300001353025,,,,,0.000672793509551697,7.87338865959735E-8,0.00857962047418948,7.98956204486109E-5,0.000672692262407686,7.87220381149142E-8,0.000672692254865845,5.7527648624228E-8,1.00730705382851E-7,5.37375932540095E-8,1.00015051034428,10.005763053894,2,20,10,5,2.20080915294269,0.193970166283527,0.0410455763339996,172.855895996094,49.9994239807129,50.0011215209961,200.222778320313,200.222778320313,,,19.647777557373,0,1,,,,,,1,1,1,50.0009422302246,0,50.0003370397231,,,,,,,,,,,,,,,,,,,,,,,,,,,,,,,,,
,3768331809.44506,50.0003356933594,200.222778320313,,,5,,,,25.0300001353025,,,,,0.000673783678142758,9.53224142235777E-8,0.00662341060819038,7.909285324771E-5,0.000673682302099464,9.53080722181171E-8,0.000673682297598109,7.90322052667377E-8,7.78778914303588E-8,5.32685569600873E-8,1.00015048049055,10.005763053894,2,20,10,5,2.20405477470933,0.194180388839437,0.0410455763339996,172.855895996094,49.9999885559082,50.0010719299316,200.222778320313,200.222778320313,,,19.6340351104736,0,1,,,,,,1,1,1,50.000186920166,0,50.0004285924575,,,,,,,,,,,,,,,,,,,,,,,,,,,,,,,,,
,3768332015.87774,50.0002727508545,200.222778320313,,,5,,,,25.0300001353025,,,,,0.000674627978241532,1.25008062286063E-7,0.00595209779652883,0.000137780791424678,0.000674526477109426,1.24989254201824E-7,0.00067452647346974,8.35866153179715E-8,7.00723087285235E-8,9.2927882821109E-8,1.00015047760992,10.005763053894,2,20,10,5,2.20681889400694,0.194397854031553,0.0410455763339996,172.855895996094,49.9997482299805,50.0005531311035,200.222778320313,200.222778320313,,,19.6085510253906,0,1,,,,,,1,1,1,50.0003395080566,0,50.0001958211263,,,,,,,,,,,,,,,,,,,,,,,,,,,,,,,,,
,3768332224.60535,49.9990539550781,200.222778320313,,,5,,,,25.0300001353025,,,,,0.000675634734175639,7.51512638666794E-8,0.00319509751918634,7.40757019233009E-5,0.000675533041746794,7.51399525557495E-8,0.000675533040696431,5.60599514626503E-8,3.76710808900347E-8,5.00329322755081E-8,1.00015053657269,10.005763053894,2,20,10,5,2.21012152320454,0.194581612370042,0.0410455763339996,172.855895996094,49.9984664916992,49.9999732971191,200.222778320313,200.222778320313,,,19.6058712005615,0,1,,,,,,1,1,1,49.9992561340332,0,49.9993158228257,,,,,,,,,,,,,,,,,,,,,,,,,,,,,,,,,
,3768332433.61336,49.9995784759521,200.222778320313,,,5,,,,25.0300001353025,,,,,0.000676350418113529,1.40039798955283E-7,0.00578191517556981,0.00017156573297887,0.000676248679315778,1.40018733719865E-7,0.00067624867587248,7.83944585052227E-8,6.8242591827656E-8,1.16015320833877E-7,1.00015044583577,10.005763053894,2,20,10,5,2.21245385639846,0.194887614776873,0.0410455763339996,172.855895996094,49.9991264343262,50.0001525878906,200.222778320313,200.222778320313,,,19.5924434661865,0,1,,,,,,1,1,1,49.9999237060547,0,49.9998195872587,,,,,,,,,,,,,,,,,,,,,,,,,,,,,,,,,
,3768332641.45824,50.0002784729004,200.222778320313,,,5,,,,25.0300001353025,,,,,0.000677193064118355,8.25378905314032E-8,0.00630846381295314,8.47030036189507E-5,0.000677091176879044,8.25254722739661E-8,0.000677091172774933,5.93472659089326E-8,7.4550084056467E-8,5.73441854347553E-8,1.0001504778718,10.005763053894,2,20,10,5,2.21520849734625,0.195150776220924,0.0410455763339996,172.855895996094,49.9995918273926,50.0004425048828,200.222778320313,200.222778320313,,,19.5670280456543,0,1,,,,,,1,1,1,50.0002937316895,0,50.0000468360053,,,,,,,,,,,,,,,,,,,,,,,,,,,,,,,,,
,3768332849.44205,50.0025691986084,200.222778320313,,,5,,,,25.0300001353025,,,,,0.000677868487853856,1.03920142631323E-7,0.00671929202861588,0.000130005869513114,0.000677766505705706,1.03904508331202E-7,0.000677766501044998,5.50705231689112E-8,7.9484232648802E-8,8.8110069398743E-8,1.00015046796691,10.005763053894,2,20,10,5,2.2174165180074,0.195361309244013,0.0410455763339996,172.855895996094,50.0008277893066,50.0028610229492,200.222778320313,200.222778320313,,,19.5533809661865,0,1,,,,,,1,1,1,50.0023193359375,0,50.0016124949736,,,,,,,,,,,,,,,,,,,,,,,,,,,,,,,,,
,3768333057.31388,50.0002193450928,200.222778320313,,,5,,,,25.0300001353025,,,,,0.000678790130476697,1.04691632646999E-7,0.00542831077770067,9.46720382616916E-5,0.000678688004786678,1.04675881526376E-7,0.000678688001740717,8.26457637779313E-8,6.43001881967069E-8,6.4239535357023E-8,1.00015047516576,10.005763053894,2,20,10,5,2.22043576536117,0.195576903665017,0.0410455763339996,172.855895996094,49.9993591308594,50.0003471374512,200.222778320313,200.222778320313,,,19.5284976959229,0,1,,,,,,1,1,1,50.0001220703125,0,49.9997881721048,,,,,,,,,,,,,,,,,,,,,,,,,,,,,,,,,
,3768333262.73994,49.9985389709473,200.222778320313,,,5,,,,25.0300001353025,,,,,0.00067916737286431,1.30342003724485E-7,0.00639850664525365,9.80176620244188E-5,0.000679065242632141,1.30322403461525E-7,0.000679065238397726,1.12057384562842E-7,7.58346163615618E-8,6.65362413194781E-8,1.00015039826184,10.005763053894,2,20,10,5,2.22166647347179,0.195723225483525,0.0410455763339996,172.855895996094,49.9962577819824,50.0003471374512,200.222778320313,200.222778320313,,,19.5256290435791,0,1,,,,,,1,1,1,49.9977226257324,0,49.9973972544951,,,,,,,,,,,,,,,,,,,,,,,,,,,,,,,,,
,3768333469.66159,50.0006790161133,200.222778320313,,,5,,,,25.0300001353025,,,,,0.000679968987144063,1.12881590331592E-7,0.00749417101160077,0.000122308571852049,0.000679866669791686,1.12864604637136E-7,0.000679866663976071,7.63236125563758E-8,8.89251724521057E-8,8.31452051909269E-8,1.00015049620304,10.005763053894,2,20,10,5,2.22428493681894,0.195996761185591,0.0410455763339996,172.855895996094,49.9990882873535,50.0011215209961,200.222778320313,200.222778320313,,,19.5237598419189,0,1,,,,,,1,1,1,50.0002593994141,0,49.9999165254481,,,,,,,,,,,,,,,,,,,,,,,,,,,,,,,,,
,3768333677.74584,50.0002212524414,200.222778320313,,,5,,,,25.0300001353025,,,,,0.000680607834359793,9.08821794358634E-8,0.00761623869123973,0.000100006358260178,0.000680505435132239,9.08685059744326E-8,0.000680505429119983,6.0220199757631E-8,9.0458526848493E-8,6.80486070333295E-8,1.00015047525305,10.005763053894,2,20,10,5,2.22637428801764,0.196185648390129,0.0410455763339996,172.855895996094,49.9992942810059,50.0008010864258,200.222778320313,200.222778320313,,,19.5218963623047,0,1,,,,,,1,1,1,50.0001831054687,0,49.9998828040229,,,,,,,,,,,,,,,,,,,,,,,,,,,,,,,,,
,3768333884.86474,49.999963760376,200.222778320313,,,5,,,,25.0300001353025,,,,,0.000681307862364056,7.66781723365923E-8,0.00451476708344423,5.57084222048325E-5,0.000681205365841827,7.66666368084859E-8,0.000681205363727006,6.66241371159259E-8,5.36773142057243E-8,3.79341212245993E-8,1.00015046346868,10.005763053894,2,20,10,5,2.22867481603766,0.196266792400398,0.0410455763339996,172.855895996094,49.9995079040527,50.0001564025879,200.222778320313,200.222778320313,,,19.4963436126709,0,1,,,,,,1,1,1,50.0000877380371,0,49.999778145238,,,,,,,,,,,,,,,,,,,,,,,,,,,,,,,,,
,3768334092.28587,50.0002784729004,200.222778320313,,,5,,,,25.0300001353025,,,,,0.000682069206257288,9.95579101610368E-8,0.00771384371870809,0.000119574830393933,0.000681966585376882,9.95429311526043E-8,0.000681966579196298,5.70941382865501E-8,9.18145051833199E-8,8.15417348096569E-8,1.0001504778718,10.005763053894,2,20,10,5,2.23115432848569,0.196610688522461,0.0410455763339996,172.855895996094,49.9995002746582,50.0009956359863,200.222778320313,200.222778320313,,,19.4823837280273,0,1,,,,,,1,1,1,50.0007514953613,0,50.0001104018267,,,,,,,,,,,,,,,,,,,,,,,,,,,,,,,,,
,3768334298.60224,50.0010013580322,200.222778320313,,,5,,,,25.0300001353025,,,,,0.000682680438952663,1.31411409037965E-7,0.00767364697174511,0.000125093745620723,0.000682577703530422,1.31391633157737E-7,0.000682577697408603,9.98771353145304E-8,9.14179082042527E-8,8.53716528200104E-8,1.00015051095532,10.005763053894,2,20,10,5,2.23315390366555,0.196785313174661,0.0410455763339996,172.855895996094,49.9996109008789,50.0013771057129,200.222778320313,200.222778320313,,,19.4925861358643,0,1,,,,,,1,1,1,50.0008239746094,0,50.0002663556267,,,,,,,,,,,,,,,,,,,,,,,,,,,,,,,,,
,3768334505.10799,49.9997615814209,200.222778320313,,,5,,,,25.0300001353025,,,,,0.000683279980912406,8.84718107785706E-8,0.00767960811887303,8.57923377573396E-5,0.000683177194023447,8.84585018240505E-8,0.000683177187886728,6.62623702601807E-8,9.1569277086879E-8,5.8602088976915E-8,1.00015045421577,10.005763053894,2,20,10,5,2.23511507789453,0.196958369215201,0.0410455763339996,172.855895996094,49.9993362426758,50.0001907348633,200.222778320313,200.222778320313,,,19.4570541381836,0,1,,,,,,1,1,1,49.9999656677246,0,49.9998204848346,,,,,,,,,,,,,,,,,,,,,,,,,,,,,,,,,
,3768334712.87535,50.0000667572022,200.222778320313,,,5,,,,25.0300001353025,,,,,0.00068371362482886,8.7099075346177E-8,0.00437821208076272,7.58069463463294E-5,0.000683610763159838,8.70859716783035E-8,0.000683610761163991,6.99972724564305E-8,5.2237580574494E-8,5.18106968860149E-8,1.00015046818243,10.005763053894,2,20,10,5,2.23654494689158,0.196954498661983,0.0410455763339996,172.855895996094,49.9995727539063,50.0002479553223,200.222778320313,200.222778320313,,,19.4545803070068,0,1,,,,,,1,1,1,50.0000610351562,0,50.0000123416676,,,,,,,,,,,,,,,,,,,,,,,,,,,,,,,,,
,3768334919.53839,50.0004215240479,200.222778320313,,,5,,,,25.0300001353025,,,,,0.000684269676640889,8.21569724728408E-8,0.00779709552943686,8.20432425103504E-5,0.000684166720209724,8.21446109888092E-8,0.000684166713874639,5.99825151146638E-8,9.31048203620932E-8,5.61233908011795E-8,1.00015048441867,10.005763053894,2,20,10,5,2.23835212219586,0.197248241709908,0.0410455763339996,172.855895996094,49.9996566772461,50.0005836486816,200.222778320313,200.222778320313,,,19.4527549743652,0,1,,,,,,1,1,1,50.0003318786621,0,50.0000753963695,,,,,,,,,,,,,,,,,,,,,,,,,,,,,,,,,
,3768335126.035,50.0000324249268,200.222778320313,,,5,,,,25.0300001353025,,,,,0.000684834568086519,1.03766854138307E-7,0.00359960776828672,0.00012235266016362,0.000684731538852299,1.03751243040361E-7,0.000684731537500988,6.12070841171133E-8,4.30182639239506E-8,8.37735834634084E-8,1.00015046661118,10.005763053894,2,20,10,5,2.24021442593494,0.197246960498009,0.0410455763339996,172.855895996094,49.9996376037598,50.0005416870117,200.222778320313,200.222778320313,,,19.4392166137695,0,1,,,,,,1,1,1,50.0002861022949,0,50.0000006731819,,,,,,,,,,,,,,,,,,,,,,,,,,,,,,,,,
,3768335332.35325,50.0010070800781,200.222778320313,,,5,,,,25.0300001353025,,,,,0.000685243436940231,1.06939543984912E-7,0.00614211738171289,0.000115205915336007,0.000685140315637372,1.06923450806184E-7,0.000685140311700598,7.21357496997864E-8,7.34471590977771E-8,7.89243811984113E-8,1.0001505112172,10.005763053894,2,20,10,5,2.24154314784222,0.197464190137614,0.0410455763339996,172.855895996094,49.9999351501465,50.0011444091797,200.222778320313,200.222778320313,,,19.4139709472656,0,1,,,,,,1,1,1,50.000919342041,0,50.0004891788258,,,,,,,,,,,,,,,,,,,,,,,,,,,,,,,,,
,3768335540.03862,50.0001544952393,200.222778320313,,,5,,,,25.0300001353025,,,,,0.00068582258917832,1.15830159672574E-7,0.00912072231473005,8.04097326807002E-5,0.000685719407471973,1.1581273307609E-7,0.000685719398783777,1.01858085786757E-7,1.09157364261548E-7,5.5113696141806E-8,1.00015047219784,10.005763053894,2,20,10,5,2.24342737198928,0.197747712717211,0.0410455763339996,172.855895996094,49.9999465942383,50.0005187988281,200.222778320313,200.222778320313,,,19.4006729125977,0,1,,,,,,1,1,1,50.0003280639648,0,50.0001977284749,,,,,,,,,,,,,,,,,,,,,,,,,,,,,,,,,
,3768335745.35033,49.9997234344482,200.222778320313,,,5,,,,25.0300001353025,,,,,0.000686273950508164,1.13799069439956E-7,0.00714454540287779,9.01211879558826E-5,0.000686170714429379,1.13781950664444E-7,0.000686170709094727,9.55231152867429E-8,8.55626339727497E-8,6.18196307245659E-8,1.00015045246994,10.005763053894,2,20,10,5,2.24491066530615,0.19780042963591,0.0410455763339996,172.855895996094,49.9991111755371,50.0002670288086,200.222778320313,200.222778320313,,,19.3988876342773,0,1,,,,,,1,1,1,49.9999008178711,0,49.9999073252958,,,,,,,,,,,,,,,,,,,,,,,,,,,,,,,,,
,3768335950.58403,50.0004577636719,200.222778320313,,,5,,,,25.0300001353025,,,,,0.000686634426424483,1.07213956981314E-7,0.00361231558041375,0.000104539701189127,0.000686531113050397,1.07197825201114E-7,0.000686531111685951,7.96368121962765E-8,4.32835900923829E-8,7.17589846016756E-8,1.00015048607721,10.005763053894,2,20,10,5,2.24610203559162,0.197765855572835,0.0410455763339996,172.855895996094,49.9998893737793,50.0009880065918,200.222778320313,200.222778320313,,,19.396858215332,0,1,,,,,,1,1,1,50.0004692077637,0,50.0004200654871,,,,,,,,,,,,,,,,,,,,,,,,,,,,,,,,,
,3768336158.38016,49.9991092681885,200.222778320313,,,5,,,,25.0300001353025,,,,,0.000687120424460159,5.85095745653403E-8,0.00885530916366673,6.66114390866522E-5,0.000687017080354139,5.85007746236389E-8,0.00068701707214874,3.64468103059967E-8,1.06181444335634E-7,4.57599240611748E-8,1.00015042436204,10.005763053894,2,20,10,5,2.24767370089009,0.198111519317117,0.0410455763339996,172.855895996094,49.9981002807617,50.0000610351562,200.222778320313,200.222778320313,,,19.3732490539551,0,1,,,,,,1,1,1,49.9989204406738,0,49.9993743896484,,,,,,,,,,,,,,,,,,,,,,,,,,,,,,,,,
,3768336364.67799,50.0015316009521,200.222778320313,,,5,,,,25.0300001353025,,,,,0.00068744556592857,7.89115559758508E-8,0.00633602801802269,8.29631325106278E-5,0.000687342096733177,7.88996787951565E-8,0.000687342092530444,5.45355851450997E-8,7.60094165923212E-8,5.70177978078814E-8,1.00015053522239,10.005763053894,2,20,10,5,2.24874600097367,0.198106378635956,0.0410455763339996,172.855895996094,49.999927520752,50.001823425293,200.222778320313,200.222778320313,,,19.3710861206055,0,1,,,,,,1,1,1,50.0014228820801,0,50.0006121467142,,,,,,,,,,,,,,,,,,,,,,,,,,,,,,,,,
,3768336572.08023,49.9997940063477,200.222778320313,,,5,,,,25.0300001353025,,,,,0.000688073822917564,1.01944082469363E-7,0.00138063413478307,0.000121529684111663,0.0006879703138626,1.01928746708455E-7,0.000687970313662866,5.83080822410442E-8,1.6577753318241E-8,8.36040486515334E-8,1.00015045569973,10.005763053894,2,20,10,5,2.25081827212294,0.198092765475465,0.0410455763339996,172.855895996094,49.9995193481445,49.9999961853027,200.222778320313,200.222778320313,,,19.3575973510742,0,1,,,,,,1,1,1,50.0000343322754,0,49.9997329711914,,,,,,,,,,,,,,,,,,,,,,,,,,,,,,,,,
,3768336780.60079,50.0002574920654,200.222778320313,,,5,,,,25.0300001353025,,,,,0.00068798930211225,1.14028212074051E-7,0.000214165131788846,9.12595867156149E-5,0.000687885791182866,1.1401105604245E-7,0.00068788579117806,9.51833317089592E-8,2.57123914494212E-9,6.2758698717365E-8,1.00015047691159,10.005763053894,2,20,10,5,2.2505458208232,0.198022612837058,0.0410455763339996,172.855895996094,49.9994583129883,50.0004768371582,200.222778320313,200.222778320313,,,19.3560924530029,0,1,,,,,,1,1,1,50.0003967285156,0,49.9999550713433,,,,,,,,,,,,,,,,,,,,,,,,,,,,,,,,,
,3768336988.48229,50.0011291503906,200.222778320313,,,5,,,,25.0300001353025,,,,,0.000688742591675661,1.38243464139734E-7,0.00775849543493212,0.000158876003801904,0.000688638939943406,1.38222659306833E-7,0.000688638933629889,8.44804809085981E-8,9.32494871514872E-8,1.09400877013418E-7,1.00015051680386,10.005763053894,2,20,10,5,2.25298385420227,0.198536088363785,0.0410455763339996,172.855895996094,49.9995727539063,50.001392364502,200.222778320313,200.222778320313,,,19.3544616699219,0,1,,,,,,1,1,1,50.0009613037109,0,50.0003757476807,,,,,,,,,,,,,,,,,,,,,,,,,,,,,,,,,
,3768337205.82423,50.0005397796631,200.222778320313,,,5,,,,25.0300001353025,,,,,0.00068926097606865,8.19085326591974E-8,0.00684109218691198,8.57127377238743E-5,0.000689157264908493,8.18962081126993E-8,0.00068915725999609,5.67322574518576E-8,8.2285089920813E-8,5.90630160731291E-8,1.00015048983075,10.005763053894,2,20,10,5,2.25468275091056,0.198649416554158,0.0410455763339996,172.855895996094,49.9997482299805,50.0012054443359,200.222778320313,200.222778320313,,,19.3417644500732,0,1,,,,,,1,1,1,50.000789642334,0,50.0003083172966,,,,,,,,,,,,,,,,,,,,,,,,,,,,,,,,,
,3768337412.3526,49.9998054504395,200.222778320313,,,5,,,,25.0300001353025,,,,,0.000689721297139568,1.10562814483285E-7,0.00675169708100754,0.000118926998105463,0.000689617539888872,1.10546182122203E-7,0.000689617535100819,7.41312362995015E-8,8.12640784342649E-8,8.20062082192726E-8,1.00015045622348,10.005763053894,2,20,10,5,2.25618884457402,0.198778566426419,0.0410455763339996,172.855895996094,49.9993362426758,50.000301361084,200.222778320313,200.222778320313,,,19.3293800354004,0,1,,,,,,1,1,1,50.0000953674316,0,49.9998646904441,,,,,,,,,,,,,,,,,,,,,,,,,,,,,,,,,
,3768337617.56656,50.0012912750244,200.222778320313,,,5,,,,25.0300001353025,,,,,0.000690057810790844,1.06678848871476E-7,0.000436129800331919,0.000107027211646403,0.000689954035162138,1.06662805774161E-7,0.000689954035142149,7.69770548384932E-8,5.25186179763647E-9,7.38341869597549E-8,1.00015040948153,10.005763053894,2,20,10,5,2.25731154286188,0.198626729161227,0.0410455763339996,172.855895996094,50.0000991821289,50.0015640258789,200.222778320313,200.222778320313,,,19.3264827728271,0,1,,,,,,1,1,1,50.0012893676758,0,50.0006760989918,,,,,,,,,,,,,,,,,,,,,,,,,,,,,,,,,
,3768337825.09032,50.0003128051758,200.222778320313,,,5,,,,25.0300001353025,,,,,0.000690469412134987,9.90768191876066E-8,0.00534265743851314,7.81268279276558E-5,0.000690365526315087,9.90619124062003E-8,0.000690365523313724,8.31017791974595E-8,6.43744886702011E-8,5.39199108288431E-8,1.00015047944305,10.005763053894,2,20,10,5,2.2586409417861,0.198938626951157,0.0410455763339996,172.855895996094,49.9997825622559,50.0006866455078,200.222778320313,200.222778320313,,,19.3140716552734,0,1,,,,,,1,1,1,50.0005989074707,0,50.0002297794118,,,,,,,,,,,,,,,,,,,,,,,,,,,,,,,,,
,3768338032.72847,50.0013389587402,200.222778320313,,,5,,,,25.0300001353025,,,,,0.000690518993842767,1.44831027049166E-7,0.00373500617318268,0.000180927423284022,0.000690415147351729,1.44809246049532E-7,0.000690415145884771,7.32605619158413E-8,4.5006889818165E-8,1.24910399123568E-7,1.00015041166382,10.005763053894,2,20,10,5,2.25880871350214,0.198889531247937,0.0410455763339996,172.855895996094,50.0000610351562,50.0017127990723,200.222778320313,200.222778320313,,,19.3012027740479,0,1,,,,,,1,1,1,50.0010871887207,0,50.0006889767117,,,,,,,,,,,,,,,,,,,,,,,,,,,,,,,,,
,3768338240.8454,49.9999980926514,200.222778320313,,,5,,,,25.0300001353025,,,,,0.000690789137797405,7.98757151916262E-8,0.00423987921668179,8.96435394840739E-5,0.000690685213819128,7.98636984970428E-8,0.000690685211928039,5.04507732942356E-8,5.11106037051093E-8,6.19106599192756E-8,1.00015046503993,10.005763053894,2,20,10,5,2.25969064804893,0.19898725640902,0.0410455763339996,172.855895996094,49.9994773864746,50.0002174377441,200.222778320313,200.222778320313,,,19.2879581451416,0,1,,,,,,1,1,1,49.9999809265137,0,49.9998624589708,,,,,,,,,,,,,,,,,,,,,,,,,,,,,,,,,
,3768338447.37096,49.9997501373291,200.222778320313,,,5,,,,25.0300001353025,,,,,0.000691163910417329,9.94526620108551E-8,0.00919890643076915,7.68283943606352E-5,0.000691059937898265,9.94377012415772E-8,0.000691059928991646,8.40882305318059E-8,1.10950505141786E-7,5.30756621648664E-8,1.00015045369202,10.005763053894,2,20,10,5,2.26089935353787,0.199290898244636,0.0410455763339996,172.855895996094,49.9991073608398,50.0001640319824,200.222778320313,200.222778320313,,,19.2975826263428,0,1,,,,,,1,1,1,49.9997177124023,0,49.9998913933249,,,,,,,,,,,,,,,,,,,,,,,,,,,,,,,,,
,3768338601.17277,50.0000610351562,200.222778320313,,,5,,,,25.0300001353025,,,,,0.000691487581984912,9.65918697552996E-8,0.00324155524218028,9.93084225556118E-5,0.000691383550939697,9.65773379640835E-8,0.000691383549833199,6.79269451123297E-8,3.91155856811142E-8,6.8652110935756E-8,1.00015046792055,10.005763053894,2,20,10,5,2.26197885006044,0.199149035439636,0.0410455763339996,172.855895996094,49.9997940063477,50.0008163452148,200.222778320313,200.222778320313,,,19.2849884033203,0,1,,,,,,1,1,1,50.0001258850098,0,50.0001162360696,,,,,,,,,,,,,,,,,,,,,,,,,,,,,,,,,