File: Experimental_Data/Fig3C/Lifetime_340Oe_48K.dat
[Header]
; MPMS3 Data File (default extension .dat)
; Copyright (c) 2007, Quantum Design, Inc. All rights reserved.
TITLE,340Oe_48K
FILEOPENTIME,3768708819.18731,06/03/2019,7:33 am
BYAPP,SQUID AC,0.9.1.0
INFO,MPMS3 Measurement Release 1.1.16 Build 347, MultiVu Release 2.3.3.2,APPNAME
INFO,0,MOMENT_UNITS
INFO,,SAMPLE_MATERIAL
INFO,,SAMPLE_COMMENT
INFO,,SAMPLE_MASS
INFO,,SAMPLE_VOLUME
INFO,,SAMPLE_MOLECULAR_WEIGHT
INFO,,SAMPLE_SIZE
INFO,,SAMPLE_SHAPE
INFO,Quartz,SAMPLE_HOLDER
INFO,Standard,SAMPLE_HOLDER_DETAIL
INFO,66.2,SAMPLE_OFFSET
DATATYPE,COMMENT,1
DATATYPE,TIME,2
STARTUPAXIS,X,2
STARTUPAXIS,Y1,5
FIELDGROUP, VSM,2,3,4,5,6,8,9,10,11,14,15
FIELDGROUP, DC, 2,3,4,14,56,57,58,59,60,61,62,63,64,65,66,67,68,69
FIELDGROUP, AC, 2,3,4,11,16,17,18,19,20,21,22,23,24,25,26,27,28,29,30
STARTUPGROUP, All
[Data]
Comment,Time Stamp (sec),Temperature (K),Magnetic Field (Oe),Moment (emu),M. Std. Err. (emu),Transport Action,Averaging Time (sec),Frequency (Hz),Peak Amplitude (mm),Center Position (mm),Lockin Signal' (V),Lockin Signal (V),Range,M. Quad. Signal (emu),AC Moment (emu),AC M. Std Err. (emu),AC Phase (deg),AC Phase Std. Err. (deg),AC Susceptibility (emu/Oe),AC Suscept. Std Err. (emu/Oe),AC X' (emu/Oe),AC X' Std Err. (emu/Oe),AC X'' (emu/Oe),AC X'' Std Err. (emu/Oe),AC Drive (Oe),AC Frequency (Hz),AC Averaging Time (sec),AC Cycles,AC Range,AC Measure Type,AC Signal' (V),AC Signal'' (V),AC Trim Coil Ratio,AC Trim Coil Phase,Min. Temperature (K),Max. Temperature (K),Min. Field (Oe),Max. Field (Oe),Mass (grams),Motor Lag (deg),Pressure (Torr),Measure Count,Measurement Number,SQUID Status (code),Motor Status (code),Measure Status (code),Motor Current (amps),Motor Temp. (C),Temp. Status (code),Field Status (code),Chamber Status (code),Chamber Temp (K),Redirection State,Average Temp (K),Rotation Angle (deg),Rotator state,DC Moment Fixed Ctr (emu),DC Moment Err Fixed Ctr (emu),DC Moment Free Ctr (emu),DC Moment Err Free Ctr (emu),DC Fixed Fit,DC Free Fit,DC Calculated Center (mm),DC Calculated Center Err (mm),DC Scan Length (mm),DC Scan Time (s),DC Number of Points,DC Squid Drift,DC Min V (V),DC Max V (V),DC Scans per Measure,Map 01,Map 02,Map 03,Map 04,Map 05,Map 06,Map 07,Map 08,Map 09,Map 10,Map 11,Map 12,Map 13,Map 14,Map 15,Map 16
,3768708823.20908,47.9554862976074,339.525085449219,,,5,,,,25.0300001353025,,,,,0.000620103606530588,2.59632077347811E-7,0.0187075317729679,0.00022349955591821,0.000620010497923153,2.5959309357008E-7,0.000620010464874272,2.19544878342385E-7,2.02438399162281E-7,1.38522996729467E-7,1.00015017263054,10.005763053894,2,20,10,5,2.02840135558536,0.179447837060267,0.0410455763339996,172.855895996094,47.9053001403809,47.9677925109863,339.525085449219,339.525085449219,,,71.2946624755859,0,1,,,,,,1,1,1,47.9485015869141,0,47.9293200174967,,,,,,,,,,,,,,,,,,,,,,,,,,,,,,,,,
,3768709030.18437,48.0005512237549,339.525085449219,,,5,,,,25.0300001353025,,,,,0.00067990761926179,1.87666344003449E-7,0.000400966137667602,0.000163973933814245,0.000679805142884613,1.87638058738647E-7,0.000679805142867966,1.50956830767049E-7,4.75739827301857E-9,1.11445396190137E-7,1.00015074375098,10.005763053894,2,20,10,5,2.22408714759346,0.196043307589516,0.0410455763339996,172.855895996094,47.9995155334473,48.0011863708496,339.525085449219,339.525085449219,,,71.6180267333984,0,1,,,,,,1,1,1,48.0002212524414,0,48.0001891641056,,,,,,,,,,,,,,,,,,,,,,,,,,,,,,,,,
,3768709238.3081,47.9995975494385,339.525085449219,,,5,,,,25.0300001353025,,,,,0.000701029414453607,1.56832462546727E-7,-0.0104932945282847,0.000156918786830072,0.00070092370476228,1.56808813451747E-7,0.000700923693007372,1.11779303609286E-7,-1.28368946147802E-7,1.09974502775725E-7,1.00015081483278,10.005763053894,2,20,10,5,2.29321832821003,0.201697497286243,0.0410455763339996,172.855895996094,47.9988975524902,48.0003929138184,339.525085449219,339.525085449219,,,71.9787063598633,0,1,,,,,,1,1,1,48.0000419616699,0,47.9997987186208,,,,,,,,,,,,,,,,,,,,,,,,,,,,,,,,,
,3768709444.66596,48.0002098083496,339.525085449219,,,5,,,,25.0300001353025,,,,,0.000709671906627264,1.14647227602335E-7,-0.014892237537965,9.86982359874303E-5,0.000709564873835201,1.14629936495335E-7,0.000709564849866927,9.07593195885514E-8,-1.84429090948257E-7,7.00197704134178E-8,1.00015084285597,10.005763053894,2,20,10,5,2.32150545286366,0.204005844630246,0.0410455763339996,172.855895996094,47.9993782043457,48.0006866455078,339.525085449219,339.525085449219,,,72.2523193359375,0,1,,,,,,1,1,1,48.0004844665527,0,47.9998952080222,,,,,,,,,,,,,,,,,,,,,,,,,,,,,,,,,
,3768709650.21359,48.0002117156982,339.525085449219,,,5,,,,25.0300001353025,,,,,0.000714630841990952,1.38403434283462E-7,-0.00687634790568215,0.000141112173029628,0.000714523061229364,1.38382560250777E-7,0.000714523056083519,9.47926984256998E-8,-8.57534217285482E-8,1.00817048690856E-7,1.00015084294327,10.005763053894,2,20,10,5,2.33769854532285,0.205758420515655,0.0410455763339996,172.855895996094,47.9996910095215,48.0003280639648,339.525085449219,339.525085449219,,,72.476188659668,0,1,,,,,,1,1,1,48.0002975463867,0,48.0001146793366,,,,,,,,,,,,,,,,,,,,,,,,,,,,,,,,,
,3768709856.69746,48.0004615783691,339.525085449219,,,5,,,,25.0300001353025,,,,,0.000717847198564358,1.24147645575943E-7,-0.00866126515589372,0.000103147426001327,0.000717739006839181,1.24128934424073E-7,0.000717738998638424,9.96463549742684E-8,-1.08498878627984E-7,7.40175404995193E-8,1.0001507396479,10.005763053894,2,20,10,5,2.34822632020429,0.206611328865785,0.0410455763339996,172.855895996094,47.9995956420898,48.0009384155273,339.525085449219,339.525085449219,,,72.7373657226563,0,1,,,,,,1,1,1,48.0003356933594,0,48.0000249077292,,,,,,,,,,,,,,,,,,,,,,,,,,,,,,,,,
,3768710061.7943,48.0008373260498,339.525085449219,,,5,,,,25.0300001353025,,,,,0.00071963660904905,3.16737259525273E-7,-0.0138212479347777,0.000338228068320263,0.000719528135256821,3.16689516412639E-7,0.000719528114322107,2.02673389471704E-7,-1.7356909603986E-7,2.43342858957731E-7,1.00015075684593,10.005763053894,2,20,10,5,2.3540984954127,0.20691434914839,0.0410455763339996,172.855895996094,47.9996910095215,48.0010528564453,339.525085449219,339.525085449219,,,72.9487991333008,0,1,,,,,,1,1,1,48.0009956359863,0,48.0002849803251,,,,,,,,,,,,,,,,,,,,,,,,,,,,,,,,,
,3768710266.87375,47.9999961853027,339.525085449219,,,5,,,,25.0300001353025,,,,,0.000721471146581142,1.13208484925541E-7,-0.00924378441006191,9.9392037389194E-5,0.00072136234127856,1.13191411916432E-7,0.000721362331890457,8.75986158446608E-8,-1.1638061288383E-7,7.16852720838456E-8,1.00015083307841,10.005763053894,2,20,10,5,2.3600831128595,0.207630384067045,0.0410455763339996,172.855895996094,47.9992523193359,48.0003776550293,339.525085449219,339.525085449219,,,73.1851043701172,0,1,,,,,,1,1,1,47.9998168945313,0,47.9998220555923,,,,,,,,,,,,,,,,,,,,,,,,,,,,,,,,,
,3768710474.50598,48.0000076293945,339.525085449219,,,5,,,,25.0300001353025,,,,,0.000723394233514894,2.23484392992661E-7,-0.00869609267568805,0.000219108361804074,0.000723285137812136,2.23450689120305E-7,0.000723285129481415,1.57546726494154E-7,-1.09776926305327E-7,1.58458951906529E-7,1.00015083360221,10.005763053894,2,20,10,5,2.36637194272108,0.20820644276505,0.0410455763339996,172.855895996094,47.9995574951172,48.0006484985352,339.525085449219,339.525085449219,,,73.4214096069336,0,1,,,,,,1,1,1,48.0002326965332,0,47.999999775606,,,,,,,,,,,,,,,,,,,,,,,,,,,,,,,,,
,3768710682.38732,48.0010299682617,339.525085449219,,,5,,,,25.0300001353025,,,,,0.000723967997683326,3.92189568363738E-7,-0.00302242758489157,0.000277317682065357,0.000723858864621544,3.92130448556604E-7,0.000723858863614402,3.36893289262632E-7,-3.81845053436481E-8,2.00671872306528E-7,1.00015076566319,10.005763053894,2,20,10,5,2.36822819874138,0.208606091735204,0.0410455763339996,172.855895996094,47.9996147155762,48.0013885498047,339.525085449219,339.525085449219,,,73.6204071044922,0,1,,,,,,1,1,1,48.0010795593262,0,48.0004711151123,,,,,,,,,,,,,,,,,,,,,,,,,,,,,,,,,
,3768710890.03234,48.0012855529785,339.525085449219,,,5,,,,25.0300001353025,,,,,0.000724668443905451,1.72915422467966E-7,-0.0028121836968058,0.000135574893082888,0.000724559196781624,1.72889354667264E-7,0.000724559195908882,1.42288506580419E-7,-3.55627164349277E-8,9.8207483688246E-8,1.00015077736134,10.005763053894,2,20,10,5,2.37051871683249,0.208816618326086,0.0410455763339996,172.855895996094,47.9998435974121,48.0014114379883,339.525085449219,339.525085449219,,,73.8318328857422,0,1,,,,,,1,1,1,48.0011596679687,0,48.0006122589111,,,,,,,,,,,,,,,,,,,,,,,,,,,,,,,,,
,3768711095.0538,48.0002250671387,339.525085449219,,,5,,,,25.0300001353025,,,,,0.000725547712549257,1.69255196157986E-7,-0.00923002659395333,0.000161224273480826,0.00072543836807806,1.69229688366284E-7,0.000725438358664993,1.22323401708202E-7,-1.16864024847499E-7,1.16943032366548E-7,1.00015072882275,10.005763053894,2,20,10,5,2.37341836329505,0.208804137272119,0.0410455763339996,172.855895996094,47.9992485046387,48.0003852844238,339.525085449219,339.525085449219,,,74.0432662963867,0,1,,,,,,1,1,1,48.0001335144043,0,47.9997942307416,,,,,,,,,,,,,,,,,,,,,,,,,,,,,,,,,
,3768711301.32466,48.0007953643799,339.525085449219,,,5,,,,25.0300001353025,,,,,0.000726289419754733,2.48448473504154E-7,-0.00616498501329765,0.000173647090843842,0.000726179944551411,2.4841102431873E-7,0.000726179940347698,2.14050470252269E-7,-7.81364439846037E-8,1.26057261543567E-7,1.00015075492534,10.005763053894,2,20,10,5,2.37583345811335,0.209144685562665,0.0410455763339996,172.855895996094,47.9995384216309,48.001350402832,339.525085449219,339.525085449219,,,74.2298202514648,0,1,,,,,,1,1,1,48.0005722045898,0,48.0001927544089,,,,,,,,,,,,,,,,,,,,,,,,,,,,,,,,,
,3768711507.72114,47.9997940063477,339.525085449219,,,5,,,,25.0300001353025,,,,,0.000726730168361776,2.18995222497896E-7,-0.0105161405911121,0.000184982098074895,0.000726620576667337,2.18962197781774E-7,0.000726620564428358,1.72872007294556E-7,-1.33364868453908E-7,1.34386432169976E-7,1.00015082382465,10.005763053894,2,20,10,5,2.37729111756085,0.209091072892416,0.0410455763339996,172.855895996094,47.9988479614258,48.0002326965332,339.525085449219,339.525085449219,,,74.4536895751953,0,1,,,,,,1,1,1,47.9998092651367,0,47.9996993120979,,,,,,,,,,,,,,,,,,,,,,,,,,,,,,,,,
,3768711715.57583,48.0012531280518,339.525085449219,,,5,,,,25.0300001353025,,,,,0.000727355086011324,4.99056253725402E-7,-0.00871857678446197,0.000229458350936191,0.000727245434942895,4.98981019424467E-7,0.000727245426523189,4.70302012281012E-7,-1.10663389085789E-7,1.66727547184954E-7,1.00015077587725,10.005763053894,2,20,10,5,2.37932879175224,0.209345513264673,0.0410455763339996,172.855895996094,47.9995765686035,48.0015335083008,339.525085449219,339.525085449219,,,74.6526870727539,0,1,,,,,,1,1,1,48.0009918212891,0,48.0004491304096,,,,,,,,,,,,,,,,,,,,,,,,,,,,,,,,,
,3768711923.23254,47.9995231628418,339.525085449219,,,5,,,,25.0300001353025,,,,,0.000727731687825555,1.77704662853554E-7,0.0047996895733009,0.000182967510188533,0.000727622037588203,1.77677887382888E-7,0.000727622035035167,1.17681014527239E-7,6.09531789725289E-8,1.33118783365406E-7,1.00015069669648,10.005763053894,2,20,10,5,2.38051124860545,0.21001557709228,0.0410455763339996,172.855895996094,47.9955558776855,48.0014801025391,339.525085449219,339.525085449219,,,74.851676940918,0,1,,,,,,1,1,1,47.998462677002,0,47.9975488450792,,,,,,,,,,,,,,,,,,,,,,,,,,,,,,,,,
,3768712128.18099,48.0002021789551,339.525085449219,,,5,,,,25.0300001353025,,,,,0.000728519145931745,2.02328075768875E-7,-0.00558926567371021,0.000209738038794606,0.000728409354410355,2.02297583904135E-7,0.000728409350944505,1.32621258296016E-7,-7.10571254838837E-8,1.52760971132786E-7,1.00015072777515,10.005763053894,2,20,10,5,2.38312521640051,0.209810712001444,0.0410455763339996,172.855895996094,47.9997787475586,48.0006523132324,339.525085449219,339.525085449219,,,75.0506744384766,0,1,,,,,,1,1,1,48.0003471374512,0,48.0002157423231,,,,,,,,,,,,,,,,,,,,,,,,,,,,,,,,,
,3768712335.14046,48.0003452301025,339.525085449219,,,5,,,,25.0300001353025,,,,,0.000728700963615889,2.35651494884887E-7,-0.00761612089573127,0.000261966127429943,0.00072859105634411,2.35615952441297E-7,0.000728591049907218,1.38166398865263E-7,-9.68489756048594E-8,1.90853145820091E-7,1.00015084905424,10.005763053894,2,20,10,5,2.38372739937066,0.209778748356494,0.0410455763339996,172.855895996094,47.9999923706055,48.0009498596191,339.525085449219,339.525085449219,,,75.2372283935547,0,1,,,,,,1,1,1,48.0006713867188,0,48.0003626081679,,,,,,,,,,,,,,,,,,,,,,,,,,,,,,,,,
,3768712542.10331,48.0006465911865,339.525085449219,,,5,,,,25.0300001353025,,,,,0.000728922642930448,1.62954330172131E-7,-0.011459326949721,0.000147705216109193,0.000728812775777607,1.62929768816447E-7,0.000728812761200916,1.22315922242981E-7,-1.45764729934124E-7,1.07633288217121E-7,1.00015074811597,10.005763053894,2,20,10,5,2.3844666270577,0.209682625097291,0.0410455763339996,172.855895996094,47.9997253417969,48.0009841918945,339.525085449219,339.525085449219,,,75.4610977172852,0,1,,,,,,1,1,1,48.0004463195801,0,48.0002324846056,,,,,,,,,,,,,,,,,,,,,,,,,,,,,,,,,
,3768712748.83653,48.0003337860107,339.525085449219,,,5,,,,25.0300001353025,,,,,0.000728880199790302,1.74162680838198E-7,-0.0095205045525999,0.000171406951844823,0.000728770349467055,1.741364325922E-7,0.000728770339406189,1.21338283952891E-7,-1.21095505758649E-7,1.24902033623577E-7,1.00015073379883,10.005763053894,2,20,10,5,2.38432068984766,0.209751098348137,0.0410455763339996,172.855895996094,47.9996223449707,48.0005226135254,339.525085449219,339.525085449219,,,75.6476516723633,0,1,,,,,,1,1,1,48.0005035400391,0,48.0000962650075,,,,,,,,,,,,,,,,,,,,,,,,,,,,,,,,,
,3768712956.4516,47.9994812011719,339.525085449219,,,5,,,,25.0300001353025,,,,,0.000729493713368952,1.86384735422989E-7,-0.00205305083150797,0.000161874769185579,0.000729383715370055,1.86356631071237E-7,0.000729383714901803,1.44199679805339E-7,-2.61356395834793E-8,1.18047644145315E-7,1.0001508095075,10.005763053894,2,20,10,5,2.38630024112452,0.210238666942121,0.0410455763339996,172.855895996094,47.9992141723633,48.0005493164063,339.525085449219,339.525085449219,,,75.8342056274414,0,1,,,,,,1,1,1,47.9995346069336,0,47.9996628231472,,,,,,,,,,,,,,,,,,,,,,,,,,,,,,,,,
,3768713163.16407,48.0007419586182,339.525085449219,,,5,,,,25.0300001353025,,,,,0.000729609579164815,2.60716852706749E-7,-0.00677685253578986,0.000289617326560077,0.000729499605289467,2.60677554918617E-7,0.000729499600186699,1.52713404175031E-7,-8.62840383785673E-8,2.11261458443376E-7,1.00015075248095,10.005763053894,2,20,10,5,2.3866965865903,0.210075281834861,0.0410455763339996,172.855895996094,47.9998970031738,48.0010871887207,339.525085449219,339.525085449219,,,76.0456390380859,0,1,,,,,,1,1,1,48.0005645751953,0,48.0003441704644,,,,,,,,,,,,,,,,,,,,,,,,,,,,,,,,,
,3768713371.74019,48.0007362365723,339.525085449219,,,5,,,,25.0300001353025,,,,,0.00072956706319591,1.54704330254555E-7,-0.00477775621316123,0.000114381708678408,0.000729457095919999,1.54681011748789E-7,0.000729457093383863,1.30263290166674E-7,-6.08276595212662E-8,8.34127725865874E-8,1.00015075221905,10.005763053894,2,20,10,5,2.38655017797895,0.210146306674877,0.0410455763339996,172.855895996094,47.999454498291,48.0010299682617,339.525085449219,339.525085449219,,,76.2197570800781,0,1,,,,,,1,1,1,48.0010833740234,0,48.0001981398639,,,,,,,,,,,,,,,,,,,,,,,,,,,,,,,,,
,3768713576.87664,48.0004119873047,339.525085449219,,,5,,,,25.0300001353025,,,,,0.000730155548494108,2.63984059242277E-7,-0.0104109953165779,0.000188090975592637,0.000730045503349032,2.63944272974601E-7,0.00073004549129703,2.25438286005187E-7,-1.32653754587554E-7,1.37274026819112E-7,1.00015073737811,10.005763053894,2,20,10,5,2.38849588956945,0.210080984960392,0.0410455763339996,172.855895996094,47.9996719360352,48.000846862793,339.525085449219,339.525085449219,,,76.4063186645508,0,1,,,,,,1,1,1,48.0006523132324,0,48.0002156425925,,,,,,,,,,,,,,,,,,,,,,,,,,,,,,,,,
,3768713781.93329,48.0003242492676,339.525085449219,,,5,,,,25.0300001353025,,,,,0.000730193946961766,1.61591759795428E-7,-0.00519702189859306,0.000154798098192698,0.000730083898960894,1.61567406197049E-7,0.00073008389595754,1.15476019785089E-7,-6.62223646794227E-8,1.13001396450823E-7,1.00015073336233,10.005763053894,2,20,10,5,2.38860237064666,0.210309400147835,0.0410455763339996,172.855895996094,47.9993591308594,48.0004959106445,339.525085449219,339.525085449219,,,76.6053085327148,0,1,,,,,,1,1,1,48.0004234313965,0,47.9999786825741,,,,,,,,,,,,,,,,,,,,,,,,,,,,,,,,,
,3768713987.23282,48.0003147125244,339.525085449219,,,5,,,,25.0300001353025,,,,,0.000730315501203439,1.88252874244627E-7,-0.00593750318008546,0.000207472936133214,0.000730205351436718,1.8822448102259E-7,0.000730205347515893,1.11714099878276E-7,-7.56704355077501E-8,1.51487343182887E-7,1.00015084765745,10.005763053894,2,20,10,5,2.38900271572906,0.210313535706589,0.0410455763339996,172.855895996094,47.9993667602539,48.000373840332,339.525085449219,339.525085449219,,,76.791862487793,0,1,,,,,,1,1,1,48.0002632141113,0,47.9999237060547,,,,,,,,,,,,,,,,,,,,,,,,,,,,,,,,,
,3768714194.16426,48.0001754760742,339.525085449219,,,5,,,,25.0300001353025,,,,,0.000730604033740936,1.80801646964086E-7,-0.0130907183959845,0.000148658118244517,0.000730493845110966,1.80774378724581E-7,0.000730493826044585,1.44538617102613E-7,-1.66900410718151E-7,1.0857239137701E-7,1.00015084128457,10.005763053894,2,20,10,5,2.38997281012112,0.210098245722844,0.0410455763339996,172.855895996094,47.9996109008789,48.0007438659668,339.525085449219,339.525085449219,,,76.9784240722656,0,1,,,,,,1,1,1,48.0004425048828,0,48.0000873141819,,,,,,,,,,,,,,,,,,,,,,,,,,,,,,,,,
,3768714400.07214,47.9995727539063,339.525085449219,,,5,,,,25.0300001353025,,,,,0.000730804048285816,2.34698517121029E-7,-0.00654313530038042,0.000206956658593182,0.000730693849644328,2.34663126707132E-7,0.000730693844879667,1.79461123157928E-7,-8.34446926390988E-8,1.51196852847084E-7,1.00015081369789,10.005763053894,2,20,10,5,2.39060307129529,0.210428961860366,0.0410455763339996,172.855895996094,47.998607635498,48.0001792907715,339.525085449219,339.525085449219,,,77.1649780273437,0,1,,,,,,1,1,1,47.999080657959,0,47.9994513567756,,,,,,,,,,,,,,,,,,,,,,,,,,,,,,,,,
,3768714609.20398,47.99928855896,339.525085449219,,,5,,,,25.0300001353025,,,,,0.000730817282963607,2.34201600104408E-7,-0.0134425249649519,0.000167640655699253,0.000730707091829796,2.34166287666596E-7,0.000730707071718976,1.99592310882682E-7,-1.71435807617091E-7,1.22461258020919E-7,1.00015080069024,10.005763053894,2,20,10,5,2.39067168689543,0.210144896370093,0.0410455763339996,172.855895996094,47.9983978271484,47.9995956420898,339.525085449219,339.525085449219,,,77.3515319824219,0,1,,,,,,1,1,1,47.9991149902344,0,47.9991017509909,,,,,,,,,,,,,,,,,,,,,,,,,,,,,,,,,
,3768714815.50462,48.0003089904785,339.525085449219,,,5,,,,25.0300001353025,,,,,0.000730993961289273,2.55453192863424E-7,-0.012484490429677,0.000195180944822508,0.000730883709385263,2.55414664226541E-7,0.000730883692034657,2.11887215255855E-7,-1.59256243310892E-7,1.42619980062668E-7,1.00015084739555,10.005763053894,2,20,10,5,2.39124612793418,0.210235677737916,0.0410455763339996,172.855895996094,47.9998397827148,48.0004577636719,339.525085449219,339.525085449219,,,77.5505294799805,0,1,,,,,,1,1,1,48.0003623962402,0,48.0002019545611,,,,,,,,,,,,,,,,,,,,,,,,,,,,,,,,,
,3768715020.83949,47.9999713897705,339.525085449219,,,5,,,,25.0300001353025,,,,,0.000731170229180965,1.36700484282306E-7,-0.00861359920957483,0.000131237604961359,0.000731059961986074,1.36679868592087E-7,0.0007310599537248,9.73585453332943E-8,-1.09904386335428E-7,9.59307048287204E-8,1.00015083194351,10.005763053894,2,20,10,5,2.39180852754569,0.210447964038906,0.0410455763339996,172.855895996094,47.9994583129883,48.0002250671387,339.525085449219,339.525085449219,,,77.7122116088867,0,1,,,,,,1,1,1,48.0002250671387,0,47.9998029821059,,,,,,,,,,,,,,,,,,,,,,,,,,,,,,,,,
,3768715227.26084,48.0007495880127,339.525085449219,,,5,,,,25.0300001353025,,,,,0.000731444514685796,1.53452419815891E-7,-0.0146709261546629,0.000133254378887448,0.000731334263975719,1.53429289916209E-7,0.000731334240000878,1.18518056198796E-7,-1.8726249917707E-7,9.7437248314242E-8,1.00015075283015,10.005763053894,2,20,10,5,2.39272801573932,0.210273949148123,0.0410455763339996,172.855895996094,47.9992408752441,48.0008735656738,339.525085449219,339.525085449219,,,77.9112014770508,0,1,,,,,,1,1,1,48.0006446838379,0,47.9999546724207,,,,,,,,,,,,,,,,,,,,,,,,,,,,,,,,,
,3768715433.79239,48.0004863739014,339.525085449219,,,5,,,,25.0300001353025,,,,,0.000731602533850469,1.32261856824468E-7,-0.0127843527331537,0.000120258955614721,0.000731492184220727,1.32241907403499E-7,0.000731492166011483,9.875085134234E-8,-1.63217153278974E-7,8.79556219515203E-8,1.00015085551442,10.005763053894,2,20,10,5,2.39323800726516,0.210398178991123,0.0410455763339996,172.855895996094,47.9996452331543,48.0006103515625,339.525085449219,339.525085449219,,,78.0853271484375,0,1,,,,,,1,1,1,48.0004730224609,0,48.0001115237965,,,,,,,,,,,,,,,,,,,,,,,,,,,,,,,,,
,3768715641.30402,48.0013408660889,339.525085449219,,,5,,,,25.0300001353025,,,,,0.000731597922982965,2.9512473266901E-7,-0.0150809411712318,0.000236821408138863,0.000731487629356456,2.95080240501911E-7,0.000731487604017507,2.38904789414938E-7,-1.92536376539066E-7,1.73195987047246E-7,1.00015077989303,10.005763053894,2,20,10,5,2.39323135590463,0.210300920574294,0.0410455763339996,172.855895996094,48.0000839233398,48.0015106201172,339.525085449219,339.525085449219,,,78.2718811035156,0,1,,,,,,1,1,1,48.0014610290527,0,48.000671810574,,,,,,,,,,,,,,,,,,,,,,,,,,,,,,,,,
,3768715846.39644,48.0008754730225,339.525085449219,,,5,,,,25.0300001353025,,,,,0.000731887653557956,1.61938675684267E-7,-0.0049102327508459,0.000183661102019171,0.000731777331837807,1.61914265717556E-7,0.000731777329150559,9.03063144963491E-8,-6.27131186145719E-8,1.34391216249209E-7,1.00015075859192,10.005763053894,2,20,10,5,2.39414175008857,0.210809199429623,0.0410455763339996,172.855895996094,47.999870300293,48.001091003418,339.525085449219,339.525085449219,,,78.4708786010742,0,1,,,,,,1,1,1,48.0011329650879,0,48.0004121992323,,,,,,,,,,,,,,,,,,,,,,,,,,,,,,,,,
,3768716053.10865,47.9998970031738,339.525085449219,,,5,,,,25.0300001353025,,,,,0.000731992029773869,2.69583068896019E-7,-0.00781487935520264,0.000200443943645632,0.000731881641135343,2.69542414207533E-7,0.000731881634327491,2.26149316870037E-7,-9.98252708774177E-8,1.46661513479306E-7,1.00015082853883,10.005763053894,2,20,10,5,2.39449386928419,0.210717879220128,0.0410455763339996,172.855895996094,47.9992637634277,48.0001106262207,339.525085449219,339.525085449219,,,78.6449966430664,0,1,,,,,,1,1,1,47.9998588562012,0,47.9997649722629,,,,,,,,,,,,,,,,,,,,,,,,,,,,,,,,,
,3768716260.16036,48.0010242462158,339.525085449219,,,5,,,,25.0300001353025,,,,,0.000732216319029083,1.22393721775496E-7,-0.00581250286621238,0.000134149167881094,0.00073210594278283,1.22375271818532E-7,0.000732105939015575,7.30176899404318E-8,-7.42701804506495E-8,9.82045014672066E-8,1.00015076540129,10.005763053894,2,20,10,5,2.39522019717772,0.210866150146304,0.0410455763339996,172.855895996094,48.0000076293945,48.0014114379883,339.525085449219,339.525085449219,,,78.8191146850586,0,1,,,,,,1,1,1,48.0005989074707,0,48.0004564173081,,,,,,,,,,,,,,,,,,,,,,,,,,,,,,,,,
,3768716466.12905,47.9997406005859,339.525085449219,,,5,,,,25.0300001353025,,,,,0.000732271381550139,2.39344486235279E-7,-0.0160573008692104,0.000212963619041651,0.000732160956024182,2.39308393413077E-7,0.00073216092727163,1.81559344273071E-7,-2.05190132704077E-7,1.55899684621492E-7,1.00015082138026,10.005763053894,2,20,10,5,2.39543798552112,0.210453696550439,0.0410455763339996,172.855895996094,47.9993782043457,48.0006713867188,339.525085449219,339.525085449219,,,79.0181045532227,0,1,,,,,,1,1,1,47.999885559082,0,47.9998792012533,,,,,,,,,,,,,,,,,,,,,,,,,,,,,,,,,
,3768716672.08654,48.0001811981201,339.525085449219,,,5,,,,25.0300001353025,,,,,0.000732323429547103,1.60972842798596E-7,-0.00216830287124381,0.000134611143033338,0.000732212981408639,1.60948565068139E-7,0.000732212980884313,1.27253524387168E-7,-2.7709885842619E-8,9.85443104828349E-8,1.00015084154647,10.005763053894,2,20,10,5,2.3955571575216,0.211049363521724,0.0410455763339996,172.855895996094,47.999641418457,48.0005340576172,339.525085449219,339.525085449219,,,79.1922302246094,0,1,,,,,,1,1,1,48.0002593994141,0,48.0000843721278,,,,,,,,,,,,,,,,,,,,,,,,,,,,,,,,,
,3768716879.75599,48.0008411407471,339.525085449219,,,5,,,,25.0300001353025,,,,,0.000732398440243227,1.59205097550097E-7,-0.00336986119509763,0.000137972132990306,0.000732288042679744,1.59181099881754E-7,0.00073228804141317,1.23020719734796E-7,-4.30696480300838E-8,1.01017449361473E-7,1.00015075702053,10.005763053894,2,20,10,5,2.39580695655453,0.211020736620198,0.0410455763339996,172.855895996094,47.9994239807129,48.0015640258789,339.525085449219,339.525085449219,,,79.3787841796875,0,1,,,,,,1,1,1,48.0005950927734,0,48.0001828810748,,,,,,,,,,,,,,,,,,,,,,,,,,,,,,,,,
,3768717086.11023,48.0002059936523,339.525085449219,,,5,,,,25.0300001353025,,,,,0.000732497063828817,2.37838179818017E-7,0.00710025276897852,0.000286121536527575,0.000732386588671983,2.3780230908008E-7,0.000732386583048405,1.12429565815232E-7,9.07593881270789E-8,2.09546011497275E-7,1.00015084268137,10.005763053894,2,20,10,5,2.39609096515334,0.211487014631408,0.0410455763339996,172.855895996094,47.9997673034668,48.0004386901855,339.525085449219,339.525085449219,,,79.5529022216797,0,1,,,,,,1,1,1,48.0001678466797,0,48.0001795291901,,,,,,,,,,,,,,,,,,,,,,,,,,,,,,,,,
,3768717291.51192,48.001407623291,339.525085449219,,,5,,,,25.0300001353025,,,,,0.000732420271470363,1.49609033377227E-7,-0.00283387731005114,0.000116640259208327,0.000732309851631704,1.49586478286972E-7,0.000732309850735965,1.22815618916371E-7,-3.62204038282788E-8,8.53957741137558E-8,1.00015078294852,10.005763053894,2,20,10,5,2.39587639664495,0.21104943472593,0.0410455763339996,172.855895996094,47.999755859375,48.001579284668,339.525085449219,339.525085449219,,,79.7394561767578,0,1,,,,,,1,1,1,48.0015907287598,0,48.0005848407745,,,,,,,,,,,,,,,,,,,,,,,,,,,,,,,,,
,3768717495.51023,47.9997463226318,339.525085449219,,,5,,,,25.0300001353025,,,,,0.00073275683981685,2.80447674376337E-7,-0.0085203976132675,0.000164090877689907,0.000732646340892598,2.80405383175977E-7,0.000732646332791594,2.53354338326085E-7,-1.08951098394206E-7,1.20161383836148E-7,1.00015082164215,10.005763053894,2,20,10,5,2.39699831457904,0.210908530433838,0.0410455763339996,172.855895996094,47.9994125366211,48.0003547668457,339.525085449219,339.525085449219,,,79.9135818481445,0,1,,,,,,1,1,1,47.9994850158691,0,47.9998245239258,,,,,,,,,,,,,,,,,,,,,,,,,,,,,,,,,
,3768717703.08957,48.0001926422119,339.525085449219,,,5,,,,25.0300001353025,,,,,0.000732812293162332,1.70675646277533E-7,-0.00195542043567709,0.000171349015500962,0.000732701854961707,1.70649924668546E-7,0.000732701854534997,1.15595867207656E-7,-2.50060334696269E-8,1.25534824944676E-7,1.00015072733865,10.005763053894,2,20,10,5,2.39715553048654,0.211199158167265,0.0410455763339996,172.855895996094,47.9995384216309,48.0005187988281,339.525085449219,339.525085449219,,,80.0876998901367,0,1,,,,,,1,1,1,47.9998970031738,0,47.9999833948472,,,,,,,,,,,,,,,,,,,,,,,,,,,,,,,,,
,3768717910.7629,47.9997959136963,339.525085449219,,,5,,,,25.0300001353025,,,,,0.000732582546387366,1.30330032997186E-7,-0.00805563765913409,0.000110127519610624,0.000732472072084063,1.30310379076047E-7,0.000732472064844445,1.02353944058363E-7,-1.02983668934239E-7,8.06502636737196E-8,1.00015082391195,10.005763053894,2,20,10,5,2.39642645453839,0.210877801641074,0.0410455763339996,172.855895996094,47.9992942810059,47.9999351501465,339.525085449219,339.525085449219,,,80.2742538452148,0,1,,,,,,1,1,1,47.9996910095215,0,47.9995680416332,,,,,,,,,,,,,,,,,,,,,,,,,,,,,,,,,
,3768718115.90946,47.9998626708984,339.525085449219,,,5,,,,25.0300001353025,,,,,0.000732906246386958,2.00981138644382E-7,-0.00914194274276525,0.000178641284848697,0.000732795721030608,2.00950829840114E-7,0.000732795711702691,1.52479099565322E-7,-1.16922687016597E-7,1.30886822137215E-7,1.00015082696743,10.005763053894,2,20,10,5,2.39748934259283,0.210925524479885,0.0410455763339996,172.855895996094,47.9994277954102,48.0002593994141,339.525085449219,339.525085449219,,,80.448371887207,0,1,,,,,,1,1,1,47.9998054504395,0,47.9997960258933,,,,,,,,,,,,,,,,,,,,,,,,,,,,,,,,,
,3768718321.23422,48.0001125335693,339.525085449219,,,5,,,,25.0300001353025,,,,,0.000733054607654899,2.07525163381834E-7,-0.0099775174975294,0.00021119530501898,0.000732944135623357,2.07493889140931E-7,0.000732944124510119,1.38192446289199E-7,-1.27635280697473E-7,1.54779074229806E-7,1.00015072367207,10.005763053894,2,20,10,5,2.39797773980057,0.21093324956694,0.0410455763339996,172.855895996094,47.9989128112793,48.0005035400391,339.525085449219,339.525085449219,,,80.6224975585938,0,1,,,,,,1,1,1,48.0000915527344,0,47.9995839595795,,,,,,,,,,,,,,,,,,,,,,,,,,,,,,,,,
,3768718526.25404,48.0011157989502,339.525085449219,,,5,,,,25.0300001353025,,,,,0.000732849122367054,1.95126664522279E-7,-0.0109058657306518,0.000210753034178055,0.000732738647660341,1.95097249789592E-7,0.000732738634386576,1.1924342481101E-7,-1.39471865584174E-7,1.54414839036938E-7,1.00015076959168,10.005763053894,2,20,10,5,2.3973089705531,0.21083527392865,0.0410455763339996,172.855895996094,48.0002250671387,48.0014533996582,339.525085449219,339.525085449219,,,80.7966156005859,0,1,,,,,,1,1,1,48.0012092590332,0,48.0008316040039,,,,,,,,,,,,,,,,,,,,,,,,,,,,,,,,,
,3768718733.19816,47.999662399292,339.525085449219,,,5,,,,25.0300001353025,,,,,0.000733209198890207,2.52305983247697E-7,-0.0035632632149003,0.000238955304963899,0.000733098634566248,2.52267936752221E-7,0.000733098633148552,1.81548316746717E-7,-4.55918990536332E-8,1.75155132952638E-7,1.00015081780097,10.005763053894,2,20,10,5,2.39845980659688,0.211246242193469,0.0410455763339996,172.855895996094,47.9988288879395,47.9999160766602,339.525085449219,339.525085449219,,,80.9831695556641,0,1,,,,,,1,1,1,47.9998512268066,0,47.9993218814625,,,,,,,,,,,,,,,,,,,,,,,,,,,,,,,,,
,3768718939.86657,48.0003070831299,339.525085449219,,,5,,,,25.0300001353025,,,,,0.000733239722780404,2.34668264847298E-7,-0.00598726491798551,0.000133412135365963,0.000733129132224209,2.34632871110265E-7,0.000733129128221425,2.13299062197513E-7,-7.66101510972261E-8,9.77552774591096E-8,1.00015084730825,10.005763053894,2,20,10,5,2.39856859149761,0.211153556897713,0.0410455763339996,172.855895996094,47.9995307922363,48.0009155273438,339.525085449219,339.525085449219,,,81.1697235107422,0,1,,,,,,1,1,1,48.0007057189941,0,48.000254313151,,,,,,,,,,,,,,,,,,,,,,,,,,,,,,,,,
,3768719149.90933,47.9999980926514,339.525085449219,,,5,,,,25.0300001353025,,,,,0.000733319489683415,1.47919309869352E-7,-0.0155510178861711,0.00014838968192579,0.000733208897464285,1.47897002096327E-7,0.000733208870457673,1.00191969391763E-7,-1.99004963989887E-7,1.08789211314731E-7,1.00015083316571,10.005763053894,2,20,10,5,2.39886474018309,0.210776116707159,0.0410455763339996,172.855895996094,47.9991683959961,48.0003776550293,339.525085449219,339.525085449219,,,81.3438491821289,0,1,,,,,,1,1,1,48.0002403259277,0,47.9998020595974,,,,,,,,,,,,,,,,,,,,,,,,,,,,,,,,,
,3768719357.87079,48.0007019042969,339.525085449219,,,5,,,,25.0300001353025,,,,,0.000733363210501912,2.66521584411815E-7,-0.00716101913269185,0.000172513647273358,0.000733252588072108,2.6648138159711E-7,0.000733252582345097,2.3457095815438E-7,-9.16443731673263E-8,1.26446796434076E-7,1.00015086537928,10.005763053894,2,20,10,5,2.39897686956324,0.21113997282234,0.0410455763339996,172.855895996094,47.9999732971191,48.0007438659668,339.525085449219,339.525085449219,,,81.5179672241211,0,1,,,,,,1,1,1,48.0007400512695,0,48.0003931382123,,,,,,,,,,,,,,,,,,,,,,,,,,,,,,,,,
,3768719565.71645,47.9996032714844,339.525085449219,,,5,,,,25.0300001353025,,,,,0.000733530777670801,1.4058212291187E-7,-0.00786164286327917,9.96382865591718E-5,0.000733420166838898,1.40560924202778E-7,0.000733420159934844,1.20085110124845E-7,-1.00633719469776E-7,7.30543615333327E-8,1.00015081509468,10.005763053894,2,20,10,5,2.39952759702095,0.21115887838027,0.0410455763339996,172.855895996094,47.9991645812988,48.0003242492676,339.525085449219,339.525085449219,,,81.7169570922852,0,1,,,,,,1,1,1,47.9999351501465,0,47.9998207092285,,,,,,,,,,,,,,,,,,,,,,,,,,,,,,,,,
,3768719773.48122,47.9996566772461,339.525085449219,,,5,,,,25.0300001353025,,,,,0.000733905410844147,2.32099457663005E-7,0.000600845420086316,0.000227042976275003,0.000733794741727017,2.32064458272503E-7,0.000733794741686668,1.61566380121089E-7,7.69510797459956E-9,1.66583965638587E-7,1.00015081753907,10.005763053894,2,20,10,5,2.40072186805016,0.211621307121824,0.0410455763339996,172.855895996094,47.9989585876465,48.0001602172852,339.525085449219,339.525085449219,,,81.8537673950195,0,1,,,,,,1,1,1,48.0000152587891,0,47.9995626561782,,,,,,,,,,,,,,,,,,,,,,,,,,,,,,,,,
,3768719981.72144,48.0004348754883,339.525085449219,,,5,,,,25.0300001353025,,,,,0.000733549916195898,2.00744014848441E-7,-0.00980000779587975,0.000196170480411133,0.000733439274565623,2.00713736547564E-7,0.000733439263837055,1.3996263884531E-7,-1.25449215187999E-7,1.43862655913001E-7,1.00015085315733,10.005763053894,2,20,10,5,2.39959734579328,0.211083204230894,0.0410455763339996,172.855895996094,47.9992942810059,48.0007820129395,339.525085449219,339.525085449219,,,82.0403213500977,0,1,,,,,,1,1,1,48.000617980957,0,47.9999782337862,,,,,,,,,,,,,,,,,,,,,,,,,,,,,,,,,
,3768720189.42521,48.0007514953613,339.525085449219,,,5,,,,25.0300001353025,,,,,0.000733761671991897,2.17925507139326E-7,-0.00258753166382153,0.000187479833565177,0.000733651071952413,2.17892659185264E-7,0.000733651071204268,1.69013292876246E-7,-3.3132377190099E-8,1.37519881318861E-7,1.00015075291745,10.005763053894,2,20,10,5,2.40026344581784,0.211446287885366,0.0410455763339996,172.855895996094,47.9998397827148,48.0010833740234,339.525085449219,339.525085449219,,,82.2144470214844,0,1,,,,,,1,1,1,48.0007514953613,0,48.0005331600414,,,,,,,,,,,,,,,,,,,,,,,,,,,,,,,,,
,3768720397.89839,48.0004577636719,339.525085449219,,,5,,,,25.0300001353025,,,,,0.000733805932467239,2.33910407863296E-7,-0.0143996015783614,0.000194031705627065,0.000733695335618783,2.33875153645817E-7,0.000733695312447961,1.85576985446244E-7,-1.84392646218968E-7,1.4233330588987E-7,1.0001507394733,10.005763053894,2,20,10,5,2.40045177277191,0.210964172229783,0.0410455763339996,172.855895996094,47.9994621276855,48.0008506774902,339.525085449219,339.525085449219,,,82.3885650634766,0,1,,,,,,1,1,1,48.0004539489746,0,48.0001104018267,,,,,,,,,,,,,,,,,,,,,,,,,,,,,,,,,
,3768720605.9967,48.0008773803711,339.525085449219,,,5,,,,25.0300001353025,,,,,0.000733994002455684,1.20494596991374E-7,-0.00453003104218119,0.000115236472117891,0.00073388336316915,1.20476434123288E-7,0.000733883360875357,8.58151496253679E-8,-5.80237225374314E-8,8.45596314670221E-8,1.00015075867922,10.005763053894,2,20,10,5,2.40103060926551,0.211431834885887,0.0410455763339996,172.855895996094,47.9998512268066,48.0011901855469,339.525085449219,339.525085449219,,,82.5999908447266,0,1,,,,,,1,1,1,48.0009765625,0,48.0003823673024,,,,,,,,,,,,,,,,,,,,,,,,,,,,,,,,,
,3768720813.88976,48.001091003418,339.525085449219,,,5,,,,25.0300001353025,,,,,0.000733932330673262,2.0230983253186E-7,-0.00292704370695773,0.00020359033855745,0.00073382169350898,2.02279335188655E-7,0.000733821692551403,1.36386913090727E-7,-3.74884186467836E-8,1.49383865868932E-7,1.00015076845678,10.005763053894,2,20,10,5,2.40082295374547,0.211481237876467,0.0410455763339996,172.855895996094,47.9998207092285,48.0013732910156,339.525085449219,339.525085449219,,,82.7865524291992,0,1,,,,,,1,1,1,48.0011749267578,0,48.0005202823215,,,,,,,,,,,,,,,,,,,,,,,,,,,,,,,,,
,3768721021.3301,47.9998168945313,339.525085449219,,,5,,,,25.0300001353025,,,,,0.000733937827608456,1.7912781789821E-7,-0.00164558168962081,0.000158328630333334,0.000733827148222578,1.79100805042171E-7,0.000733827147919917,1.36317380464439E-7,-2.10761164008597E-8,1.16166562099716E-7,1.00015082487224,10.005763053894,2,20,10,5,2.4008362038961,0.211536526450984,0.0410455763339996,172.855895996094,47.9991455078125,48.0003051757812,339.525085449219,339.525085449219,,,82.9482345581055,0,1,,,,,,1,1,1,47.9994354248047,0,47.9997809560675,,,,,,,,,,,,,,,,,,,,,,,,,,,,,,,,,
,3768721233.33952,47.9991626739502,339.525085449219,,,5,,,,25.0300001353025,,,,,0.000733976657579944,2.40813927168193E-7,-0.00306900273314881,0.000229076630644533,0.00073386599430983,2.40777619124342E-7,0.000733865993257054,1.7239356760938E-7,-3.9308946668761E-8,1.68090213034837E-7,1.00015079492846,10.005763053894,2,20,10,5,2.4009684781564,0.211488070406114,0.0410455763339996,172.855895996094,47.9985733032227,47.9995498657227,339.525085449219,339.525085449219,,,83.1223526000977,0,1,,,,,,1,1,1,47.999340057373,0,47.9990950690375,,,,,,,,,,,,,,,,,,,,,,,,,,,,,,,,,
,3768721442.28933,47.9997596740723,339.525085449219,,,5,,,,25.0300001353025,,,,,0.00073392056664847,1.57607929919981E-7,-0.00679938868577867,0.000122102361852072,0.000733809891787132,1.57584162721483E-7,0.000733809886620018,1.29647619402009E-7,-8.7082481579286E-8,8.95782514007868E-8,1.00015082225325,10.005763053894,2,20,10,5,2.40079875817047,0.211315597354865,0.0410455763339996,172.855895996094,47.9992065429687,48.0001449584961,339.525085449219,339.525085449219,,,83.3089065551758,0,1,,,,,,1,1,1,47.999641418457,0,47.9998032064999,,,,,,,,,,,,,,,,,,,,,,,,,,,,,,,,,
,3768721647.72839,47.9998149871826,339.525085449219,,,5,,,,25.0300001353025,,,,,0.000734092545413091,1.8362221871135E-7,-0.00743810147928237,0.000119367807763759,0.000733981842759506,1.83594528106132E-7,0.000733981836574583,1.61358779496512E-7,-9.52850534796308E-8,8.75802205404239E-8,1.00015082478494,10.005763053894,2,20,10,5,2.40136369071928,0.211338344544347,0.0410455763339996,172.855895996094,47.9996604919434,48.0003356933594,339.525085449219,339.525085449219,,,83.483024597168,0,1,,,,,,1,1,1,47.9997749328613,0,47.999979355756,,,,,,,,,,,,,,,,,,,,,,,,,,,,,,,,,
,3768721855.51146,48.0009288787842,339.525085449219,,,5,,,,25.0300001353025,,,,,0.000733957941325629,2.04349645790087E-7,-0.0149231149050175,0.000170023860182983,0.00073384730574532,2.04318842469658E-7,0.000733847280853915,1.61814858276879E-7,-1.91136024950238E-7,1.24748310725936E-7,1.00015076103631,10.005763053894,2,20,10,5,2.40095095759673,0.210985933771256,0.0410455763339996,172.855895996094,47.9993171691895,48.0010604858398,339.525085449219,339.525085449219,,,83.6695861816406,0,1,,,,,,1,1,1,48.0009689331055,0,48.0002510968377,,,,,,,,,,,,,,,,,,,,,,,,,,,,,,,,,
,3768722064.03687,47.9998531341553,339.525085449219,,,5,,,,25.0300001353025,,,,,0.000734263703565637,1.68137429924856E-7,-0.00822913210043197,0.000118307128772336,0.000734153058037284,1.68112093448765E-7,0.00073415305046513,1.43953008450915E-7,-1.05443062771748E-7,8.68286088893345E-8,1.00015071179932,10.005763053894,2,20,10,5,2.40192650134326,0.211354460050875,0.0410455763339996,172.855895996094,47.9989051818848,48.0005798339844,339.525085449219,339.525085449219,,,83.8437042236328,0,1,,,,,,1,1,1,47.9993743896484,0,47.9994390275743,,,,,,,,,,,,,,,,,,,,,,,,,,,,,,,,,
,3768722271.91295,48.001220703125,339.525085449219,,,5,,,,25.0300001353025,,,,,0.000734065227965629,3.59058059499307E-7,-0.0137200691454389,0.000287003554950907,0.000733954566411274,3.59003930899485E-7,0.000733954545368329,2.90740525442577E-7,-1.75753037834788E-7,2.10603345810688E-7,1.00015077439316,10.005763053894,2,20,10,5,2.40129748658243,0.211067193467127,0.0410455763339996,172.855895996094,48.0000419616699,48.0014686584473,339.525085449219,339.525085449219,,,84.017822265625,0,1,,,,,,1,1,1,48.0013160705566,0,48.0007171630859,,,,,,,,,,,,,,,,,,,,,,,,,,,,,,,,,
,3768722479.99888,48.0002021789551,339.525085449219,,,5,,,,25.0300001353025,,,,,0.000734267656905866,1.72434941838903E-7,-0.00936291591022442,0.000107308899829288,0.000734156914836471,1.72408935242921E-7,0.000734156905033993,1.53373704623127E-7,-1.19971304803714E-7,7.87486360629551E-8,1.00015084250677,10.005763053894,2,20,10,5,2.40194361576042,0.2113080639211,0.0410455763339996,172.855895996094,47.9995880126953,48.0004386901855,339.525085449219,339.525085449219,,,84.1795043945313,0,1,,,,,,1,1,1,48.0001945495605,0,48.0000902063706,,,,,,,,,,,,,,,,,,,,,,,,,,,,,,,,,
,3768722636.56172,48.0000190734863,339.525085449219,,,5,,,,25.0300001353025,,,,,0.000734442769803586,1.54346746963911E-7,-0.00597041858437031,0.000150997977774825,0.000734332007477042,1.54323469718234E-7,0.00073433200349022,1.07347862961812E-7,-7.65199373123721E-8,1.10870057379829E-7,1.000150834126,10.005763053894,2,20,10,5,2.40250392790434,0.211500712365271,0.0410455763339996,172.855895996094,47.9994049072266,48.0002174377441,339.525085449219,339.525085449219,,,84.3163146972656,0,1,,,,,,1,1,1,47.9999580383301,0,47.9998204848346,,,,,,,,,,,,,,,,,,,,,,,,,,,,,,,,,