File: Experimental_Data/Fig3C/Lifetime_160Oe_48p5K.dat
[Header]
; MPMS3 Data File (default extension .dat)
; Copyright (c) 2007, Quantum Design, Inc. All rights reserved.
TITLE,160Oe_48p5K
FILEOPENTIME,3768433916.55172,05/31/2019,3:11 am
BYAPP,SQUID AC,0.9.1.0
INFO,MPMS3 Measurement Release 1.1.16 Build 347, MultiVu Release 2.3.3.2,APPNAME
INFO,0,MOMENT_UNITS
INFO,,SAMPLE_MATERIAL
INFO,,SAMPLE_COMMENT
INFO,,SAMPLE_MASS
INFO,,SAMPLE_VOLUME
INFO,,SAMPLE_MOLECULAR_WEIGHT
INFO,,SAMPLE_SIZE
INFO,,SAMPLE_SHAPE
INFO,Quartz,SAMPLE_HOLDER
INFO,Standard,SAMPLE_HOLDER_DETAIL
INFO,66.2,SAMPLE_OFFSET
DATATYPE,COMMENT,1
DATATYPE,TIME,2
STARTUPAXIS,X,2
STARTUPAXIS,Y1,5
FIELDGROUP, VSM,2,3,4,5,6,8,9,10,11,14,15
FIELDGROUP, DC, 2,3,4,14,56,57,58,59,60,61,62,63,64,65,66,67,68,69
FIELDGROUP, AC, 2,3,4,11,16,17,18,19,20,21,22,23,24,25,26,27,28,29,30
STARTUPGROUP, All
[Data]
Comment,Time Stamp (sec),Temperature (K),Magnetic Field (Oe),Moment (emu),M. Std. Err. (emu),Transport Action,Averaging Time (sec),Frequency (Hz),Peak Amplitude (mm),Center Position (mm),Lockin Signal' (V),Lockin Signal (V),Range,M. Quad. Signal (emu),AC Moment (emu),AC M. Std Err. (emu),AC Phase (deg),AC Phase Std. Err. (deg),AC Susceptibility (emu/Oe),AC Suscept. Std Err. (emu/Oe),AC X' (emu/Oe),AC X' Std Err. (emu/Oe),AC X'' (emu/Oe),AC X'' Std Err. (emu/Oe),AC Drive (Oe),AC Frequency (Hz),AC Averaging Time (sec),AC Cycles,AC Range,AC Measure Type,AC Signal' (V),AC Signal'' (V),AC Trim Coil Ratio,AC Trim Coil Phase,Min. Temperature (K),Max. Temperature (K),Min. Field (Oe),Max. Field (Oe),Mass (grams),Motor Lag (deg),Pressure (Torr),Measure Count,Measurement Number,SQUID Status (code),Motor Status (code),Measure Status (code),Motor Current (amps),Motor Temp. (C),Temp. Status (code),Field Status (code),Chamber Status (code),Chamber Temp (K),Redirection State,Average Temp (K),Rotation Angle (deg),Rotator state,DC Moment Fixed Ctr (emu),DC Moment Err Fixed Ctr (emu),DC Moment Free Ctr (emu),DC Moment Err Free Ctr (emu),DC Fixed Fit,DC Free Fit,DC Calculated Center (mm),DC Calculated Center Err (mm),DC Scan Length (mm),DC Scan Time (s),DC Number of Points,DC Squid Drift,DC Min V (V),DC Max V (V),DC Scans per Measure,Map 01,Map 02,Map 03,Map 04,Map 05,Map 06,Map 07,Map 08,Map 09,Map 10,Map 11,Map 12,Map 13,Map 14,Map 15,Map 16
,3768433920.51085,48.4607849121094,159.5322265625,,,5,,,,25.0300001353025,,,,,0.000567616782762606,1.32283960084961E-7,0.269363812844216,6.45746328337055E-5,0.000567531647766291,1.32264119243752E-7,0.000567525375961597,1.27154373700737E-7,2.66811843242939E-6,3.64082749948221E-8,1.00015000924909,10.005763053894,2,20,10,5,1.85600103229623,0.172020743332933,0.0410455763339996,172.855895996094,48.4121932983398,48.4749069213867,159.5322265625,159.5322265625,,,93.4078369140625,0,1,,,,,,1,1,1,48.4538078308105,0,48.4344340430366,,,,,,,,,,,,,,,,,,,,,,,,,,,,,,,,,
,3768434076.82218,48.4936428070068,159.5322265625,,,5,,,,25.0300001353025,,,,,0.000578437468045123,9.01713365831456E-8,0.113199694585617,8.10973877992455E-5,0.000578350238531278,9.01577385673055E-8,0.000578349109759798,7.70158667294754E-8,1.14265009271948E-6,4.68718902486158E-8,1.00015082472183,10.005763053894,2,20,10,5,1.89185343636652,0.170144140116788,0.0410455763339996,172.855895996094,48.4926872253418,48.497932434082,159.5322265625,159.5322265625,,,94.2411270141602,0,1,,,,,,1,1,1,48.4937515258789,0,48.4955421023899,,,,,,,,,,,,,,,,,,,,,,,,,,,,,,,,,
,3768434233.2222,48.4994411468506,159.5322265625,,,5,,,,25.0300001353025,,,,,0.000582392220100421,6.55865180149099E-8,0.0779201901816915,5.41345634707331E-5,0.00058230444009118,6.55766326061445E-8,0.000582303901604727,5.75153941676244E-8,7.91912757184234E-7,3.15003837707425E-8,1.00015074590403,10.005763053894,2,20,10,5,1.90489307894644,0.17013449540327,0.0410455763339996,172.855895996094,48.4986343383789,48.5002174377441,159.5322265625,159.5322265625,,,95.2360916137695,0,1,,,,,,1,1,1,48.4992713928223,0,48.499547958374,,,,,,,,,,,,,,,,,,,,,,,,,,,,,,,,,
,3768434389.9714,48.5000286102295,159.5322265625,,,5,,,,25.0300001353025,,,,,0.000585642601137257,3.83390261296474E-8,0.0636198390861278,3.87872564738749E-5,0.000585554382651429,3.83332509165281E-8,0.00058555402167648,3.08857530269809E-8,6.50185201457962E-7,2.27048097500473E-8,1.00015065805746,10.005763053894,2,20,10,5,1.915567092072,0.170605930434496,0.0410455763339996,172.855895996094,48.4997024536133,48.5005645751953,159.5322265625,159.5322265625,,,96.1315689086914,0,1,,,,,,1,1,1,48.4999885559082,0,48.5001947739545,,,,,,,,,,,,,,,,,,,,,,,,,,,,,,,,,
,3768434544.52172,48.5005340576172,159.5322265625,,,5,,,,25.0300001353025,,,,,0.000588561044077936,8.32893077151981E-8,0.0544783792233563,6.66382527026482E-5,0.000588472372359802,8.32767594738703E-8,0.00058847210634908,7.34795011760165E-8,5.59535388220947E-7,3.91890491769401E-8,1.00015068119133,10.005763053894,2,20,10,5,1.9251403019181,0.171148962419035,0.0410455763339996,172.855895996094,48.4992141723633,48.5010185241699,159.5322265625,159.5322265625,,,96.9897232055664,0,1,,,,,,1,1,1,48.500072479248,0,48.4999706043917,,,,,,,,,,,,,,,,,,,,,,,,,,,,,,,,,
,3768434700.1329,48.5000667572022,159.5322265625,,,5,,,,25.0300001353025,,,,,0.000590664187770111,5.83023793833888E-8,0.0468616413697633,7.52529385283114E-5,0.000590575211824797,5.82935968815423E-8,0.000590575014293952,3.77263744464899E-8,4.83025467635825E-7,4.44394431615766E-8,1.00015065980341,10.005763053894,2,20,10,5,1.93204234796541,0.171503702103259,0.0410455763339996,172.855895996094,48.4999046325684,48.5004959106445,159.5322265625,159.5322265625,,,97.83544921875,0,1,,,,,,1,1,1,48.4999084472656,0,48.5001808615292,,,,,,,,,,,,,,,,,,,,,,,,,,,,,,,,,
,3768434856.83377,48.4999179840088,159.5322265625,,,5,,,,25.0300001353025,,,,,0.000593257621201688,6.47419796374352E-8,0.0401275606359501,5.36748151499575E-5,0.000593168190581011,6.47322201076527E-8,0.000593168045106102,5.63706655071073E-8,4.15430085623854E-7,3.18215082978703E-8,1.00015076772844,10.005763053894,2,20,10,5,1.94054561220669,0.172028650167266,0.0410455763339996,172.855895996094,48.4997215270996,48.5009078979492,159.5322265625,159.5322265625,,,98.6687316894531,0,1,,,,,,1,1,1,48.4998168945313,0,48.500079907869,,,,,,,,,,,,,,,,,,,,,,,,,,,,,,,,,
,3768435012.78066,48.5001335144043,159.5322265625,,,5,,,,25.0300001353025,,,,,0.000595503508459776,6.54469017580903E-8,0.0368909673064364,7.77757983812079E-5,0.000595413801714222,6.54370428261447E-8,0.000595413678294743,4.62388509018359E-8,3.83368369569647E-7,4.63030802550811E-8,1.00015066285883,10.005763053894,2,20,10,5,1.94790166071749,0.172569860426616,0.0410455763339996,172.855895996094,48.4994010925293,48.5002288818359,159.5322265625,159.5322265625,,,99.4895858764648,0,1,,,,,,1,1,1,48.5001182556152,0,48.4998548171099,,,,,,,,,,,,,,,,,,,,,,,,,,,,,,,,,
,3768435168.47615,48.4996242523193,159.5322265625,,,5,,,,25.0300001353025,,,,,0.000597423241260456,8.4462605080798E-8,0.0331793095783528,0.000107211364500617,0.00059733319072262,8.44498739004733E-8,0.000597333090566829,5.50561436921546E-8,3.45908580302774E-7,6.4035944933722E-8,1.0001507542846,10.005763053894,2,20,10,5,1.95419234880623,0.172999585504368,0.0410455763339996,172.855895996094,48.4991302490234,48.5000839233398,159.5322265625,159.5322265625,,,100.297996520996,0,1,,,,,,1,1,1,48.4993667602539,0,48.499620549819,,,,,,,,,,,,,,,,,,,,,,,,,,,,,,,,,
,3768435324.61088,48.5004539489746,159.5322265625,,,5,,,,25.0300001353025,,,,,0.00059937045481418,6.8410607750024E-8,0.0343085431753627,6.57318397448059E-5,0.000599280156763478,6.8400301361917E-8,0.000599280049325165,5.5927019358297E-8,3.5884716253977E-7,3.93798137641322E-8,1.00015067752483,10.005763053894,2,20,10,5,1.96055833175785,0.173602089083095,0.0410455763339996,172.855895996094,48.4994621276855,48.5006561279297,159.5322265625,159.5322265625,,,101.118843078613,0,1,,,,,,1,1,1,48.5003509521484,0,48.5000040390912,,,,,,,,,,,,,,,,,,,,,,,,,,,,,,,,,
,3768435482.53944,48.5006580352783,159.5322265625,,,5,,,,25.0300001353025,,,,,0.000601237003406796,6.99076190066369E-8,0.0329919450602283,7.2838375638707E-5,0.000601146418537172,6.9897086433762E-8,0.000601146318877184,5.44902254617647E-8,3.46150950141286E-7,4.37769119634409E-8,1.00015068686568,10.005763053894,2,20,10,5,1.96666786815106,0.17409752430902,0.0410455763339996,172.855895996094,48.4997482299805,48.5008125305176,159.5322265625,159.5322265625,,,101.939697265625,0,1,,,,,,1,1,1,48.5007019042969,0,48.5003217061361,,,,,,,,,,,,,,,,,,,,,,,,,,,,,,,,,
,3768435640.43951,48.4995174407959,159.5322265625,,,5,,,,25.0300001353025,,,,,0.000603197198041199,5.10094930696292E-8,0.0324369170650414,5.56202482324149E-5,0.000603106280133785,5.10018045783974E-8,0.000603106183484706,3.84229400636014E-8,3.41437144434679E-7,3.35389586469516E-8,1.00015074939593,10.005763053894,2,20,10,5,1.97308142674718,0.174646021017523,0.0410455763339996,172.855895996094,48.4991340637207,48.4999923706055,159.5322265625,159.5322265625,,,102.760543823242,0,1,,,,,,1,1,1,48.4992828369141,0,48.4995092504165,,,,,,,,,,,,,,,,,,,,,,,,,,,,,,,,,
,3768435796.55273,48.5006561279297,159.5322265625,,,5,,,,25.0300001353025,,,,,0.000604796222911724,6.05716495872075E-8,0.0302805034237545,5.29997139630193E-5,0.000604705101848056,6.05625236156333E-8,0.00060470501739905,5.13952632458369E-8,3.19583295839528E-7,3.20366381286374E-8,1.00015068677838,10.005763053894,2,20,10,5,1.9783184885761,0.175034531827152,0.0410455763339996,172.855895996094,48.4997673034668,48.5010643005371,159.5322265625,159.5322265625,,,103.544082641602,0,1,,,,,,1,1,1,48.5004081726074,0,48.5002304525936,,,,,,,,,,,,,,,,,,,,,,,,,,,,,,,,,
,3768435951.16887,48.5004901885986,159.5322265625,,,5,,,,25.0300001353025,,,,,0.000606582508849638,6.79101741825926E-8,0.0351251629800586,7.94426957721232E-5,0.000606491123262392,6.78999430746112E-8,0.00060649100929362,4.78490093357552E-8,3.71809204747719E-7,4.81754561485644E-8,1.00015067918349,10.005763053894,2,20,10,5,1.98414666775572,0.17571927243203,0.0410455763339996,172.855895996094,48.4998970031738,48.5007171630859,159.5322265625,159.5322265625,,,104.340057373047,0,1,,,,,,1,1,1,48.5005226135254,0,48.5003032684326,,,,,,,,,,,,,,,,,,,,,,,,,,,,,,,,,
,3768436107.89355,48.4998321533203,159.5322265625,,,5,,,,25.0300001353025,,,,,0.000608078707754273,7.68863025789592E-8,0.0271258834768009,6.12604234376106E-5,0.000607987115063367,7.68747214739851E-8,0.000607987046925757,6.72597386789032E-8,2.87842964397438E-7,3.72270110880317E-8,1.00015064906581,10.005763053894,2,20,10,5,1.9890653457921,0.175875005674503,0.0410455763339996,172.855895996094,48.4994468688965,48.5001792907715,159.5322265625,159.5322265625,,,105.148468017578,0,1,,,,,,1,1,1,48.4998359680176,0,48.4998058992274,,,,,,,,,,,,,,,,,,,,,,,,,,,,,,,,,
,3768436264.36341,48.4994659423828,159.5322265625,,,5,,,,25.0300001353025,,,,,0.000609717361438062,5.75974967287699E-8,0.0279217078382308,7.785475067324E-5,0.000609625462204797,5.75888153853769E-8,0.000609625389815929,3.26184562826971E-8,2.97086164414639E-7,4.74605938355684E-8,1.0001507470389,10.005763053894,2,20,10,5,1.99442303967644,0.176376658643536,0.0410455763339996,172.855895996094,48.4985427856445,48.4999694824219,159.5322265625,159.5322265625,,,105.932006835938,0,1,,,,,,1,1,1,48.4992942810059,0,48.4995468987359,,,,,,,,,,,,,,,,,,,,,,,,,,,,,,,,,
,3768436419.34803,48.5013008117676,159.5322265625,,,5,,,,25.0300001353025,,,,,0.000611123358936546,5.10753782881934E-8,0.0308794935706533,6.31938245691233E-5,0.000611031266574042,5.10676815569466E-8,0.000611031177832187,3.34238202358435E-8,3.293145728107E-7,3.8610313912784E-8,1.00015071628498,10.005763053894,2,20,10,5,1.99901301603048,0.176886567676051,0.0410455763339996,172.855895996094,48.499584197998,48.5014877319336,159.5322265625,159.5322265625,,,106.727981567383,0,1,,,,,,1,1,1,48.5014152526855,0,48.5004886827971,,,,,,,,,,,,,,,,,,,,,,,,,,,,,,,,,
,3768436577.99125,48.4999732971191,159.5322265625,,,5,,,,25.0300001353025,,,,,0.000612844676621231,5.42183450449328E-8,0.0262110629046024,6.46644987918478E-5,0.000612752362091916,5.42101779820636E-8,0.00061275229797406,3.70007388525498E-8,2.80315413875619E-7,3.96192973336532E-8,1.00015065552583,10.005763053894,2,20,10,5,2.00465797262386,0.177221461124333,0.0410455763339996,172.855895996094,48.499683380127,48.5008163452148,159.5322265625,159.5322265625,,,107.499076843262,0,1,,,,,,1,1,1,48.500171661377,0,48.5000693377327,,,,,,,,,,,,,,,,,,,,,,,,,,,,,,,,,
,3768436732.43006,48.4997329711914,159.5322265625,,,5,,,,25.0300001353025,,,,,0.000614128746947443,5.48674767468015E-8,0.0270142593847149,5.40805846821969E-5,0.000614036175307692,5.48592062134374E-8,0.000614036107057351,4.36730568169446E-8,2.89510537036944E-7,3.31993465994796E-8,1.00015075926057,10.005763053894,2,20,10,5,2.00885576695069,0.177620948817656,0.0410455763339996,172.855895996094,48.499153137207,48.5002403259277,159.5322265625,159.5322265625,,,108.295051574707,0,1,,,,,,1,1,1,48.4998397827148,0,48.4996835920546,,,,,,,,,,,,,,,,,,,,,,,,,,,,,,,,,
,3768436889.19338,48.5008811950684,159.5322265625,,,5,,,,25.0300001353025,,,,,0.000615330755116851,5.93276130957221E-8,0.0275534480704875,5.35988172441066E-5,0.000615238040540944,5.93186739447988E-8,0.000615237969399968,4.93153239296337E-8,2.95866971209803E-7,3.29651923137823E-8,1.0001506970795,10.005763053894,2,20,10,5,2.01278594073555,0.177987535779369,0.0410455763339996,172.855895996094,48.4994888305664,48.501049041748,159.5322265625,159.5322265625,,,109.078590393066,0,1,,,,,,1,1,1,48.5010528564453,0,48.5002358380486,,,,,,,,,,,,,,,,,,,,,,,,,,,,,,,,,
,3768437044.47862,48.4994812011719,159.5322265625,,,5,,,,25.0300001353025,,,,,0.000616895134297954,7.81982075814798E-8,0.0268661218439332,6.1479611968065E-5,0.000616802152769074,7.81864211554047E-8,0.000616802084961131,6.83853532411436E-8,2.89219927252497E-7,3.79019777211469E-8,1.00015074773728,10.005763053894,2,20,10,5,2.01790526422584,0.178415838992472,0.0410455763339996,172.855895996094,48.499397277832,48.5026741027832,159.5322265625,159.5322265625,,,109.84969329834,0,1,,,,,,1,1,1,48.4995651245117,0,48.500753290513,,,,,,,,,,,,,,,,,,,,,,,,,,,,,,,,,
,3768437200.26307,48.5003337860107,159.5322265625,,,5,,,,25.0300001353025,,,,,0.000618178742973997,4.84378037114898E-8,0.0263086511612416,5.88221796319733E-5,0.000618085614762747,4.84305065889863E-8,0.000618085549604328,3.19984127675117E-8,2.83807959213676E-7,3.63540307094796E-8,1.00015067202508,10.005763053894,2,20,10,5,2.02210577382318,0.178767401415881,0.0410455763339996,172.855895996094,48.500244140625,48.5008125305176,159.5322265625,159.5322265625,,,110.633232116699,0,1,,,,,,1,1,1,48.500373840332,0,48.5004184947294,,,,,,,,,,,,,,,,,,,,,,,,,,,,,,,,,
,3768437354.1221,48.5002708435059,159.5322265625,,,5,,,,25.0300001353025,,,,,0.000619342538384061,6.40911699079474E-8,0.0274309815639642,5.94009576014055E-5,0.000619249236631494,6.40815148009494E-8,0.000619249165661804,5.24802462684669E-8,2.96472338608049E-7,3.67731463269784E-8,1.00015066914426,10.005763053894,2,20,10,5,2.02590912107148,0.17914363612316,0.0410455763339996,172.855895996094,48.4996681213379,48.5006332397461,159.5322265625,159.5322265625,,,111.429206848145,0,1,,,,,,1,1,1,48.5005264282227,0,48.5002089606391,,,,,,,,,,,,,,,,,,,,,,,,,,,,,,,,,
,3768437513.3436,48.499418258667,159.5322265625,,,5,,,,25.0300001353025,,,,,0.000620622811762488,7.29285030035246E-8,0.0243715835204616,8.73075190428594E-5,0.000620529270166729,7.2917511063786E-8,0.000620529214029044,4.88095356713448E-8,2.63951038055983E-7,5.4171880595795E-8,1.00015074485646,10.005763053894,2,20,10,5,2.03010655956056,0.179405555445005,0.0410455763339996,172.855895996094,48.4990234375,48.4996948242188,159.5322265625,159.5322265625,,,112.22518157959,0,1,,,,,,1,1,1,48.4996871948242,0,48.4993267059326,,,,,,,,,,,,,,,,,,,,,,,,,,,,,,,,,
,3768437668.04281,48.5005302429199,159.5322265625,,,5,,,,25.0300001353025,,,,,0.000621808742665443,7.03097126137073E-8,0.0272471263189695,8.85385508019753E-5,0.000621715062007779,7.02991198708494E-8,0.000621714991707422,4.37299035391153E-8,2.95657871040393E-7,5.50423636036437E-8,1.00015068101674,10.005763053894,2,20,10,5,2.03397681046169,0.179850453508639,0.0410455763339996,172.855895996094,48.4998054504395,48.5006980895996,159.5322265625,159.5322265625,,,112.996284484863,0,1,,,,,,1,1,1,48.5007019042969,0,48.5003089904785,,,,,,,,,,,,,,,,,,,,,,,,,,,,,,,,,
,3768437822.27608,48.4996471405029,159.5322265625,,,5,,,,25.0300001353025,,,,,0.000623079907855547,6.37425499324576E-8,0.0255639907967034,6.83615374152123E-5,0.000622985989395775,6.37329418516383E-8,0.000622985927385977,4.74205961350692E-8,2.77961268811194E-7,4.25813919366073E-8,1.00015075533217,10.005763053894,2,20,10,5,2.03814016735511,0.180158252881814,0.0410455763339996,172.855895996094,48.4989967346191,48.5000877380371,159.5322265625,159.5322265625,,,113.792259216309,0,1,,,,,,1,1,1,48.4997863769531,0,48.499620549819,,,,,,,,,,,,,,,,,,,,,,,,,,,,,,,,,
,3768437976.39053,48.5008525848389,159.5322265625,,,5,,,,25.0300001353025,,,,,0.000624279533885284,6.49281569888187E-8,0.0271994316788868,5.75669939053387E-5,0.000624185471774969,6.49183740644495E-8,0.000624185401442146,5.40750484619286E-8,2.96313089744239E-7,3.59205292974903E-8,1.00015069577004,10.005763053894,2,20,10,5,2.04205907959297,0.180563397528741,0.0410455763339996,172.855895996094,48.4996528625488,48.5010414123535,159.5322265625,159.5322265625,,,114.575798034668,0,1,,,,,,1,1,1,48.5011672973633,0,48.5002944048713,,,,,,,,,,,,,,,,,,,,,,,,,,,,,,,,,
,3768438130.62233,48.4999523162842,159.5322265625,,,5,,,,25.0300001353025,,,,,0.000625420443097682,5.97730259047269E-8,0.0289072860813429,5.70571612889351E-5,0.000625326163109926,5.97640153259831E-8,0.000625326083522223,4.79518698706327E-8,3.1549411977459E-7,3.56700953712526E-8,1.0001507692998,10.005763053894,2,20,10,5,2.04578567471524,0.180954373050713,0.0410455763339996,172.855895996094,48.4993286132812,48.5000305175781,159.5322265625,159.5322265625,,,115.359329223633,0,1,,,,,,1,1,1,48.4999618530273,0,48.4996737311868,,,,,,,,,,,,,,,,,,,,,,,,,,,,,,,,,
,3768438289.787,48.4992942810059,159.5322265625,,,5,,,,25.0300001353025,,,,,0.000626451656719219,8.17429427018573E-8,0.0289897714976552,6.52342268857168E-5,0.00062635724014113,8.17306226946389E-8,0.000626357159966602,7.07947739542031E-8,3.16916056420879E-7,4.08410904216172E-8,1.00015073918211,10.005763053894,2,20,10,5,2.04915857156071,0.18125569041765,0.0410455763339996,172.855895996094,48.4985046386719,48.5005264282227,159.5322265625,159.5322265625,,,116.217491149902,0,1,,,,,,1,1,1,48.4989585876465,0,48.4996000289917,,,,,,,,,,,,,,,,,,,,,,,,,,,,,,,,,
,3768438449.61409,48.5005302429199,159.5322265625,,,5,,,,25.0300001353025,,,,,0.000627718512054493,5.20944025460207E-8,0.0285945161908332,4.68580463372014E-5,0.000627623941040929,5.20865540910919E-8,0.000627623862879995,4.29959267925362E-8,3.13227297915726E-7,2.93999897335884E-8,1.00015068101674,10.005763053894,2,20,10,5,2.05330377978404,0.181608069930507,0.0410455763339996,172.855895996094,48.4994010925293,48.5010643005371,159.5322265625,159.5322265625,,,117.05078125,0,1,,,,,,1,1,1,48.4999961853027,0,48.5002048716826,,,,,,,,,,,,,,,,,,,,,,,,,,,,,,,,,
,3768438606.70641,48.5000171661377,159.5322265625,,,5,,,,25.0300001353025,,,,,0.000628772541156182,6.06330540187444E-8,0.0258815349021839,7.70743769751665E-5,0.000628677753985425,6.06239136137989E-8,0.000628677689844845,3.64365039169651E-8,2.83985047710765E-7,4.84524517869048E-8,1.00015077226792,10.005763053894,2,20,10,5,2.05676018175668,0.181815626526532,0.0410455763339996,172.855895996094,48.4993667602539,48.5003852844238,159.5322265625,159.5322265625,,,117.884063720703,0,1,,,,,,1,1,1,48.5002517700195,0,48.4998765833238,,,,,,,,,,,,,,,,,,,,,,,,,,,,,,,,,
,3768438762.9144,48.5002574920654,159.5322265625,,,5,,,,25.0300001353025,,,,,0.000629618983188509,5.68599461254448E-8,0.0250868833033264,6.18968849490774E-5,0.000629524133710684,5.68513804113492E-8,0.000629524073367178,4.14028808838782E-8,2.75636322755875E-7,3.89599911343847E-8,1.00015066853318,10.005763053894,2,20,10,5,2.05953147937139,0.18203181882672,0.0410455763339996,172.855895996094,48.4996452331543,48.5005836486816,159.5322265625,159.5322265625,,,118.717353820801,0,1,,,,,,1,1,1,48.5003395080566,0,48.500202627743,,,,,,,,,,,,,,,,,,,,,,,,,,,,,,,,,
,3768438918.83958,48.5002613067627,159.5322265625,,,5,,,,25.0300001353025,,,,,0.000630823770828504,6.57647404936264E-8,0.0262946795473198,6.35205325667661E-5,0.000630728739744332,6.57548332978636E-8,0.000630728673323683,5.21470618364966E-8,2.89459531777648E-7,4.00547380948925E-8,1.00015066870777,10.005763053894,2,20,10,5,2.06346858612307,0.182423638336443,0.0410455763339996,172.855895996094,48.499641418457,48.5005073547363,159.5322265625,159.5322265625,,,119.538200378418,0,1,,,,,,1,1,1,48.5002784729004,0,48.499989677878,,,,,,,,,,,,,,,,,,,,,,,,,,,,,,,,,
,3768439075.64037,48.5010890960693,159.5322265625,,,5,,,,25.0300001353025,,,,,0.000632003411590902,6.59349301867426E-8,0.026183946493104,7.4932519755634E-5,0.000631908178860949,6.59249948552463E-8,0.000631908112875387,4.58752934645146E-8,2.88779549009384E-7,4.73451412101487E-8,1.00015070659494,10.005763053894,2,20,10,5,2.06732762685857,0.182760772485935,0.0410455763339996,172.855895996094,48.4995460510254,48.5012435913086,159.5322265625,159.5322265625,,,120.359046936035,0,1,,,,,,1,1,1,48.5009803771973,0,48.5003632938161,,,,,,,,,,,,,,,,,,,,,,,,,,,,,,,,,
,3768439231.05369,48.4998779296875,159.5322265625,,,5,,,,25.0300001353025,,,,,0.000632843874161341,6.61291871162684E-8,0.0247395965652757,6.25290187175171E-5,0.000632748477270736,6.6119218593088E-8,0.000632748418285806,5.2982413123685E-8,2.73212821285993E-7,3.95552141563122E-8,1.00015076589519,10.005763053894,2,20,10,5,2.07008145130928,0.182951635061551,0.0410455763339996,172.855895996094,48.4996185302734,48.5001487731934,159.5322265625,159.5322265625,,,121.179893493652,0,1,,,,,,1,1,1,48.4999046325684,0,48.4998799492331,,,,,,,,,,,,,,,,,,,,,,,,,,,,,,,,,
,3768439385.19931,48.5001316070557,159.5322265625,,,5,,,,25.0300001353025,,,,,0.000633642375803253,6.39828991717112E-8,0.0242559305066905,6.52634868950138E-5,0.000633546923867807,6.39732607829377E-8,0.000633546867095127,4.88221226884674E-8,2.68209453290212E-7,4.13397923482204E-8,1.00015066277153,10.005763053894,2,20,10,5,2.07269495850949,0.183164980044819,0.0410455763339996,172.855895996094,48.4994850158691,48.5002937316895,159.5322265625,159.5322265625,,,121.988311767578,0,1,,,,,,1,1,1,48.5000610351562,0,48.4999442630344,,,,,,,,,,,,,,,,,,,,,,,,,,,,,,,,,
,3768439541.07861,48.5007228851318,159.5322265625,,,5,,,,25.0300001353025,,,,,0.000634756358419674,6.9500467680044E-8,0.0253971019977364,8.00734138282959E-5,0.000634660721501033,6.94899962440594E-8,0.000634660659151288,4.74000707395903E-8,2.81321638121776E-7,5.08142979079827E-8,1.0001506898338,10.005763053894,2,20,10,5,2.07633523020208,0.183528346981314,0.0410455763339996,172.855895996094,48.500415802002,48.5009956359863,159.5322265625,159.5322265625,,,122.809158325195,0,1,,,,,,1,1,1,48.5009078979492,0,48.5006801380831,,,,,,,,,,,,,,,,,,,,,,,,,,,,,,,,,
,3768439702.70424,48.499942779541,159.5322265625,,,5,,,,25.0300001353025,,,,,0.000635680776122199,5.90150835732402E-8,0.0214265118809545,5.84059610089423E-5,0.000635585022614169,5.90061940464666E-8,0.000635584978171376,4.58721626055024E-8,2.37685390385023E-7,3.71143588620848E-8,1.00015065412907,10.005763053894,2,20,10,5,2.07937180064896,0.183651532472401,0.0410455763339996,172.855895996094,48.4987678527832,48.5008430480957,159.5322265625,159.5322265625,,,123.679756164551,0,1,,,,,,1,1,1,48.4992218017578,0,48.4998249727137,,,,,,,,,,,,,,,,,,,,,,,,,,,,,,,,,
,3768439859.18428,48.4999771118164,159.5322265625,,,5,,,,25.0300001353025,,,,,0.000636551429758689,9.78382532379879E-8,0.0249889237033543,9.93854522772565E-5,0.000636455471090667,9.78235043457172E-8,0.000636455410558272,7.46311366035711E-8,2.77583040821052E-7,6.32426395063936E-8,1.00015077043467,10.005763053894,2,20,10,5,2.08220835286511,0.184032528212238,0.0410455763339996,172.855895996094,48.4994926452637,48.5003929138184,159.5322265625,159.5322265625,,,124.513038635254,0,1,,,,,,1,1,1,48.5002632141113,0,48.4999277451459,,,,,,,,,,,,,,,,,,,,,,,,,,,,,,,,,
,3768440016.10771,48.4998626708984,159.5322265625,,,5,,,,25.0300001353025,,,,,0.000637452396618491,5.66469656506784E-8,0.0271612155298122,5.46706588887469E-5,0.00063735630546966,5.66384265471531E-8,0.000637356233854425,4.46577632468794E-8,3.02140427809486E-7,3.48366982293518E-8,1.00015076519681,10.005763053894,2,20,10,5,2.08514849539575,0.184372063173324,0.0410455763339996,172.855895996094,48.4993438720703,48.5000495910645,159.5322265625,159.5322265625,,,125.358764648438,0,1,,,,,,1,1,1,48.4997673034668,0,48.4997836842256,,,,,,,,,,,,,,,,,,,,,,,,,,,,,,,,,
,3768440171.60857,48.5008068084717,159.5322265625,,,5,,,,25.0300001353025,,,,,0.000638517148516419,5.7282870023765E-8,0.0267759182488998,6.79696400025355E-5,0.000638420942518461,5.72742391581895E-8,0.000638420872804365,3.73853824716704E-8,2.98351929030603E-7,4.33897643298095E-8,1.00015069367489,10.005763053894,2,20,10,5,2.08863261069586,0.18466597537048,0.0410455763339996,172.855895996094,48.4993667602539,48.5011215209961,159.5322265625,159.5322265625,,,126.179611206055,0,1,,,,,,1,1,1,48.5006408691406,0,48.5001197391086,,,,,,,,,,,,,,,,,,,,,,,,,,,,,,,,,
,3768440326.48407,48.5006313323975,159.5322265625,,,5,,,,25.0300001353025,,,,,0.000639234921664598,5.26689482790447E-8,0.0240154269694104,5.95271812433897E-5,0.000639138612651458,5.26610130204098E-8,0.000639138556507837,3.64141519405845E-8,2.67893837145876E-7,3.80419745910198E-8,1.00015068564351,10.005763053894,2,20,10,5,2.0909893997184,0.184772820317775,0.0410455763339996,172.855895996094,48.5000038146973,48.5007171630859,159.5322265625,159.5322265625,,,127.012901306152,0,1,,,,,,1,1,1,48.5005798339844,0,48.5003691779243,,,,,,,,,,,,,,,,,,,,,,,,,,,,,,,,,
,3768440481.39878,48.5007762908936,159.5322265625,,,5,,,,25.0300001353025,,,,,0.000640043165884884,5.83798806397242E-8,0.0209402951116111,5.69687828174969E-5,0.000639946730854129,5.83710845680136E-8,0.000639946688114165,4.55919894267394E-8,2.33885867604041E-7,3.64493348877354E-8,1.00015069227813,10.005763053894,2,20,10,5,2.09364315883459,0.184894077085671,0.0410455763339996,172.855895996094,48.4995651245117,48.500904083252,159.5322265625,159.5322265625,,,127.821311950684,0,1,,,,,,1,1,1,48.5007553100586,0,48.5003128051758,,,,,,,,,,,,,,,,,,,,,,,,,,,,,,,,,
,3768440638.94418,48.4995784759521,159.5322265625,,,5,,,,25.0300001353025,,,,,0.00064079252648369,4.68112072760776E-8,0.0217504550470631,5.19424651268073E-5,0.000640696013666621,4.6804156817001E-8,0.000640695967501556,3.29147140999293E-8,2.4321912761834E-7,3.32753766480611E-8,1.00015063745522,10.005763053894,2,20,10,5,2.09609177169575,0.185140195154331,0.0410455763339996,172.855895996094,48.4989967346191,48.5001602172852,159.5322265625,159.5322265625,,,128.654602050781,0,1,,,,,,1,1,1,48.4992294311523,0,48.4995833004222,,,,,,,,,,,,,,,,,,,,,,,,,,,,,,,,,
,3768440794.20224,48.5004405975342,159.5322265625,,,5,,,,25.0300001353025,,,,,0.000641719016779097,5.02861996842625E-8,0.0214779056894621,5.6947605599621E-5,0.000641622339105249,5.02786238563922E-8,0.000641622294024816,3.45417700321031E-8,2.40518653937915E-7,3.65349988359365E-8,1.00015067691375,10.005763053894,2,20,10,5,2.09912328984864,0.185397888870826,0.0410455763339996,172.855895996094,48.500057220459,48.5010833740234,159.5322265625,159.5322265625,,,129.512756347656,0,1,,,,,,1,1,1,48.5007781982422,0,48.5004186630249,,,,,,,,,,,,,,,,,,,,,,,,,,,,,,,,,
,3768440948.15526,48.5004920959473,159.5322265625,,,5,,,,25.0300001353025,,,,,0.000642685689623186,9.17390586240366E-8,0.0230530579637085,9.80139829508801E-5,0.000642588864801623,9.17252375321327E-8,0.00064258881278825,6.66920015772623E-8,2.5854675638079E-7,6.29737733182997E-8,1.00015067927078,10.005763053894,2,20,10,5,2.10228026220588,0.185734965069013,0.0410455763339996,172.855895996094,48.4992713928223,48.5005569458008,159.5322265625,159.5322265625,,,130.308731079102,0,1,,,,,,1,1,1,48.5004272460937,0,48.5000026927275,,,,,,,,,,,,,,,,,,,,,,,,,,,,,,,,,
,3768441102.0355,48.4999771118164,159.5322265625,,,5,,,,25.0300001353025,,,,,0.00064325132171886,5.82840690762439E-8,0.022602653451278,6.0534988361436E-5,0.000643154426838203,5.8275289571676E-8,0.000643154376793415,4.336692571245E-8,2.53718447885183E-7,3.89271001862909E-8,1.00015065570043,10.005763053894,2,20,10,5,2.10413195465568,0.18588189278018,0.0410455763339996,172.855895996094,48.4994773864746,48.5000648498535,159.5322265625,159.5322265625,,,131.15446472168,0,1,,,,,,1,1,1,48.4999809265137,0,48.4998139774098,,,,,,,,,,,,,,,,,,,,,,,,,,,,,,,,,
,3768441256.0638,48.5000267028809,159.5322265625,,,5,,,,25.0300001353025,,,,,0.000644202058226935,8.31499085377503E-8,0.0218591107696557,6.98210705786046E-5,0.00064410494478249,8.31373736910819E-8,0.000644104897906943,6.99337459743733E-8,2.45734696575968E-7,4.49565799215468E-8,1.0001507727044,10.005763053894,2,20,10,5,2.10724431350874,0.186129282748376,0.0410455763339996,172.855895996094,48.499454498291,48.5003433227539,159.5322265625,159.5322265625,,,131.987747192383,0,1,,,,,,1,1,1,48.5000839233398,0,48.4999439015108,,,,,,,,,,,,,,,,,,,,,,,,,,,,,,,,,
,3768441409.95253,48.499963760376,159.5322265625,,,5,,,,25.0300001353025,,,,,0.000644804211354689,8.69850625557662E-8,0.0231403404370445,6.08760846237307E-5,0.000644707008992681,8.69719498102367E-8,0.00064470695641195,7.76246044459337E-8,2.60381120414886E-7,3.92242378945296E-8,1.00015076982358,10.005763053894,2,20,10,5,2.1092098453331,0.186350428138515,0.0410455763339996,172.855895996094,48.499626159668,48.5003890991211,159.5322265625,159.5322265625,,,132.821029663086,0,1,,,,,,1,1,1,48.5001373291016,0,48.4999313354492,,,,,,,,,,,,,,,,,,,,,,,,,,,,,,,,,
,3768441565.48013,48.4998302459717,159.5322265625,,,5,,,,25.0300001353025,,,,,0.000645576952098396,4.6205864404399E-8,0.019894682237668,5.49718712637126E-5,0.00064547971123925,4.61989045866148E-8,0.000645479672327448,2.9588319165742E-8,2.24128436632727E-7,3.5480560225979E-8,1.00015064897851,10.005763053894,2,20,10,5,2.11174811197001,0.186454129010112,0.0410455763339996,172.855895996094,48.4993286132812,48.5001754760742,159.5322265625,159.5322265625,,,133.666748046875,0,1,,,,,,1,1,1,48.4998397827148,0,48.4998251597087,,,,,,,,,,,,,,,,,,,,,,,,,,,,,,,,,
,3768441720.27172,48.5012130737305,159.5322265625,,,5,,,,25.0300001353025,,,,,0.000646504649360416,7.77305625120834E-8,0.0248551552033902,6.1162349127733E-5,0.000646407227860221,7.77188493279347E-8,0.000646407167037773,6.692136427715E-8,2.80414222577658E-7,3.95189896650104E-8,1.00015071226929,10.005763053894,2,20,10,5,2.11476653127865,0.18690514840566,0.0410455763339996,172.855895996094,48.4997787475586,48.5013771057129,159.5322265625,159.5322265625,,,134.512481689453,0,1,,,,,,1,1,1,48.5013771057129,0,48.5005264282227,,,,,,,,,,,,,,,,,,,,,,,,,,,,,,,,,
,3768441877.60933,48.4999904632568,159.5322265625,,,5,,,,25.0300001353025,,,,,0.000647131133181835,8.41483975912507E-8,0.0232435266265041,0.000105933975548811,0.000647033653478181,8.41357220137061E-8,0.000647033600236023,4.87966094807376E-8,2.62486062117691E-7,6.85398469647548E-8,1.00015065631151,10.005763053894,2,20,10,5,2.11682106921472,0.187026728612345,0.0410455763339996,172.855895996094,48.4997940063477,48.5009002685547,159.5322265625,159.5322265625,,,135.358200073242,0,1,,,,,,1,1,1,48.5,0,48.5002697215361,,,,,,,,,,,,,,,,,,,,,,,,,,,,,,,,,
,3768442031.61811,48.5011157989502,159.5322265625,,,5,,,,25.0300001353025,,,,,0.000647896690303468,6.34395462741874E-8,0.0231822295882003,8.2532523136336E-5,0.00064779906192092,6.34299868793255E-8,0.000647799008896558,3.41331447635296E-8,2.62103531854412E-7,5.3462993407247E-8,1.00015070781711,10.005763053894,2,20,10,5,2.11932547230095,0.187245712015274,0.0410455763339996,172.855895996094,48.4998817443848,48.5016250610352,159.5322265625,159.5322265625,,,136.203918457031,0,1,,,,,,1,1,1,48.5005493164063,0,48.500540116254,,,,,,,,,,,,,,,,,,,,,,,,,,,,,,,,,
,3768442189.463,48.5007362365723,159.5322265625,,,5,,,,25.0300001353025,,,,,0.000648508511277385,8.87874873649282E-8,0.0233183884378825,0.000105246654988156,0.000648410801965171,8.87741099548051E-8,0.000648410748265448,5.67838803959789E-8,2.63891942105324E-7,6.82380650769275E-8,1.00015069044488,10.005763053894,2,20,10,5,2.12132634574917,0.187427571373937,0.0410455763339996,172.855895996094,48.4998931884766,48.501091003418,159.5322265625,159.5322265625,,,137.062088012695,0,1,,,,,,1,1,1,48.5009117126465,0,48.5003415276023,,,,,,,,,,,,,,,,,,,,,,,,,,,,,,,,,
,3768442343.30674,48.5011291503906,159.5322265625,,,5,,,,25.0300001353025,,,,,0.000649126394597044,5.96525846456256E-8,0.0230705413752625,6.43446513775533E-5,0.000649028580519821,5.96435958530428E-8,0.000649028527905481,4.25885324785668E-8,2.61335833865002E-7,4.17561423937026E-8,1.00015070842819,10.005763053894,2,20,10,5,2.12334830608073,0.187596962035356,0.0410455763339996,172.855895996094,48.4999923706055,48.5014038085937,159.5322265625,159.5322265625,,,137.92024230957,0,1,,,,,,1,1,1,48.5011024475098,0,48.5005304673139,,,,,,,,,,,,,,,,,,,,,,,,,,,,,,,,,
,3768442497.29038,48.5001220703125,159.5322265625,,,5,,,,25.0300001353025,,,,,0.000650038932023262,8.51665174548177E-8,0.0200874403021922,7.53479932741012E-5,0.000649941010392995,8.51536880013457E-8,0.000649940970449333,6.96725251552722E-8,2.27864095570591E-7,4.89580414101554E-8,1.00015066233504,10.005763053894,2,20,10,5,2.1263430722326,0.187749981137608,0.0410455763339996,172.855895996094,48.4992370605469,48.5006217956543,159.5322265625,159.5322265625,,,138.765960693359,0,1,,,,,,1,1,1,48.5000343322754,0,48.4997823503282,,,,,,,,,,,,,,,,,,,,,,,,,,,,,,,,,
,3768442653.54652,48.4987087249756,159.5322265625,,,5,,,,25.0300001353025,,,,,0.00065052480317004,1.02484603454485E-7,0.0221059086769015,7.89708580928946E-5,0.000650426775801514,1.02469160083314E-7,0.000650426727390979,8.86785261124357E-8,2.50948231656001E-7,5.13424558694455E-8,1.00015071238174,10.005763053894,2,20,10,5,2.12792578496584,0.187965284042529,0.0410455763339996,172.855895996094,48.4985466003418,48.5003662109375,159.5322265625,159.5322265625,,,139.649002075195,0,1,,,,,,1,1,1,48.4988594055176,0,48.4993517258588,,,,,,,,,,,,,,,,,,,,,,,,,,,,,,,,,
,3768442808.5354,48.5003795623779,159.5322265625,,,5,,,,25.0300001353025,,,,,0.000651285304716121,6.57536941782434E-8,0.0203506219521366,5.08297042023306E-5,0.000651187187659518,6.57437882907825E-8,0.000651187146583725,5.68118414497161E-8,2.31292149441281E-7,3.30856520249419E-8,1.00015067412022,10.005763053894,2,20,10,5,2.13041921939693,0.188119753684119,0.0410455763339996,172.855895996094,48.4994773864746,48.5004539489746,159.5322265625,159.5322265625,,,140.50715637207,0,1,,,,,,1,1,1,48.5004501342773,0,48.4999831704532,,,,,,,,,,,,,,,,,,,,,,,,,,,,,,,,,
,3768442964.86369,48.5010013580322,159.5322265625,,,5,,,,25.0300001353025,,,,,0.000651931129881043,8.54362088146391E-8,0.0205047122932438,8.96686138331467E-5,0.000651832896982227,8.54233352976814E-8,0.000651832855240696,6.23044505802626E-8,2.33274524653968E-7,5.84405822290616E-8,1.00015070257925,10.005763053894,2,20,10,5,2.132531271657,0.188312029970981,0.0410455763339996,172.855895996094,48.5000267028809,48.5013885498047,159.5322265625,159.5322265625,,,141.37776184082,0,1,,,,,,1,1,1,48.5008354187012,0,48.5005376479205,,,,,,,,,,,,,,,,,,,,,,,,,,,,,,,,,
,3768443121.39688,48.50071144104,159.5322265625,,,5,,,,25.0300001353025,,,,,0.000652297204405964,9.45293958158612E-8,0.0203871025423377,0.000112534968553468,0.000652198924999965,9.45151533926107E-8,0.000652198883712727,5.95567563665015E-8,2.32066762934345E-7,7.33901014574167E-8,1.00015068931001,10.005763053894,2,20,10,5,2.13372912442566,0.188413391738352,0.0410455763339996,172.855895996094,48.4998207092285,48.5008735656738,159.5322265625,159.5322265625,,,142.260787963867,0,1,,,,,,1,1,1,48.5008277893066,0,48.5003361421473,,,,,,,,,,,,,,,,,,,,,,,,,,,,,,,,,
,3768443277.78489,48.5004825592041,159.5322265625,,,5,,,,25.0300001353025,,,,,0.000653185134948579,5.11198111483726E-8,0.0205826633890762,4.78452019752422E-5,0.000653086728601618,5.11121096352743E-8,0.00065308668646121,4.04538207084317E-8,2.34611765889147E-7,3.1239976655855E-8,1.0001506788343,10.005763053894,2,20,10,5,2.1366329896999,0.188677159484634,0.0410455763339996,172.855895996094,48.499698638916,48.5011138916016,159.5322265625,159.5322265625,,,143.131393432617,0,1,,,,,,1,1,1,48.5008506774902,0,48.5003415276023,,,,,,,,,,,,,,,,,,,,,,,,,,,,,,,,,
,3768443432.59014,48.5007305145264,159.5322265625,,,5,,,,25.0300001353025,,,,,0.000653964945484946,7.35899957657483E-8,0.0184887039049988,6.8297000943239E-5,0.000653866414235334,7.35789081466156E-8,0.000653866380192423,5.84851787614177E-8,2.10995337163656E-7,4.46468317945755E-8,1.00015069018299,10.005763053894,2,20,10,5,2.1391907291063,0.188824234057348,0.0410455763339996,172.855895996094,48.4995269775391,48.5008659362793,159.5322265625,159.5322265625,,,143.989547729492,0,1,,,,,,1,1,1,48.5007133483887,0,48.5001871320936,,,,,,,,,,,,,,,,,,,,,,,,,,,,,,,,,
,3768443587.94888,48.4995307922363,159.5322265625,,,5,,,,25.0300001353025,,,,,0.000654373989578907,6.42823174495595E-8,0.0195584572169887,6.50024560366816E-5,0.000654275432620642,6.4272635723545E-8,0.000654275394500497,4.81955536565553E-8,2.23343113877908E-7,4.25224683031172E-8,1.00015063527278,10.005763053894,2,20,10,5,2.14052522833896,0.188982312179359,0.0410455763339996,172.855895996094,48.4988174438477,48.5001602172852,159.5322265625,159.5322265625,,,144.885025024414,0,1,,,,,,1,1,1,48.4990730285645,0,48.4994872598087,,,,,,,,,,,,,,,,,,,,,,,,,,,,,,,,,
,3768443744.50446,48.5007514953613,159.5322265625,,,5,,,,25.0300001353025,,,,,0.000654840649487449,7.0241764889759E-8,0.0197941086127127,8.26066049226724E-5,0.000654741985669087,7.02311816727001E-8,0.00065474194659698,4.48057363128309E-8,2.2619525958066E-7,5.40820198643585E-8,1.00015069114326,10.005763053894,2,20,10,5,2.14205094410122,0.189125886187202,0.0410455763339996,172.855895996094,48.4999923706055,48.5008392333984,159.5322265625,159.5322265625,,,145.780487060547,0,1,,,,,,1,1,1,48.5007629394531,0,48.5003693524529,,,,,,,,,,,,,,,,,,,,,,,,,,,,,,,,,
,3768443898.3783,48.4995098114014,159.5322265625,,,5,,,,25.0300001353025,,,,,0.000655671555714751,4.17399533892599E-8,0.0231857473005297,3.64125413921227E-5,0.00065557280395613,4.1733666867043E-8,0.000655572750279176,3.42374384239821E-8,2.65289085582807E-7,2.38641312503379E-8,1.00015063431251,10.005763053894,2,20,10,5,2.14475770973482,0.189492827954777,0.0410455763339996,172.855895996094,48.4992027282715,48.5002975463867,159.5322265625,159.5322265625,,,146.651092529297,0,1,,,,,,1,1,1,48.4992179870605,0,48.499516879811,,,,,,,,,,,,,,,,,,,,,,,,,,,,,,,,,
,3768444054.69302,48.5005664825439,159.5322265625,,,5,,,,25.0300001353025,,,,,0.000656111544406866,7.92693881900174E-8,0.0179431354878474,8.80984696666477E-5,0.000656012619403171,7.92574363739178E-8,0.000656012587234464,5.4243180935285E-8,2.05441364430667E-7,5.77877023473642E-8,1.00015079740964,10.005763053894,2,20,10,5,2.14621429231432,0.189423601472538,0.0410455763339996,172.855895996094,48.4999237060547,48.5008506774902,159.5322265625,159.5322265625,,,147.54655456543,0,1,,,,,,1,1,1,48.5007438659668,0,48.5002634385053,,,,,,,,,,,,,,,,,,,,,,,,,,,,,,,,,
,3768444208.52186,48.5013217926025,159.5322265625,,,5,,,,25.0300001353025,,,,,0.000656666677151369,8.08981980472511E-8,0.0171460001715582,6.5700384582943E-5,0.000656567721073126,8.08860071310767E-8,0.000656567691674305,6.84329057508022E-8,1.96480616649345E-7,4.31217295584305E-8,1.00015071724525,10.005763053894,2,20,10,5,2.1480328312405,0.189553985001792,0.0410455763339996,172.855895996094,48.5000457763672,48.5015983581543,159.5322265625,159.5322265625,,,148.429595947266,0,1,,,,,,1,1,1,48.5012588500977,0,48.5006740794462,,,,,,,,,,,,,,,,,,,,,,,,,,,,,,,,,
,3768444361.65328,48.5005340576172,159.5322265625,,,5,,,,25.0300001353025,,,,,0.000657468379814758,4.09911177272582E-8,0.0167593891613063,4.94010901656565E-5,0.000657369326621477,4.09849420673608E-8,0.000657369298499196,2.50056886600262E-8,1.92284812320872E-7,3.24727733786747E-8,1.00015068119133,10.005763053894,2,20,10,5,2.15065657376998,0.189770897591377,0.0410455763339996,172.855895996094,48.4999008178711,48.500862121582,159.5322265625,159.5322265625,,,149.312637329102,0,1,,,,,,1,1,1,48.5002059936523,0,48.5003435471479,,,,,,,,,,,,,,,,,,,,,,,,,,,,,,,,,
,3768444517.696,48.4998092651367,159.5322265625,,,5,,,,25.0300001353025,,,,,0.000658081737986315,6.6746945144929E-8,0.0180822245639911,5.84337203801531E-5,0.000657982538727697,6.67368837086496E-8,0.000657982505960233,5.45559057181597E-8,2.07655571284089E-7,3.84378042870959E-8,1.00015076275247,10.005763053894,2,20,10,5,2.15265855438536,0.189997639143855,0.0410455763339996,172.855895996094,48.4994087219238,48.5006217956543,159.5322265625,159.5322265625,,,150.208099365234,0,1,,,,,,1,1,1,48.4996337890625,0,48.4998933892501,,,,,,,,,,,,,,,,,,,,,,,,,,,,,,,,,
,3768444674.55739,48.5011463165283,159.5322265625,,,5,,,,25.0300001353025,,,,,0.000658494667481426,6.78603459319021E-8,0.018485490207186,9.13114025958017E-5,0.000658395441222062,6.78501202936116E-8,0.000658395406955267,3.14551926778193E-8,2.12419874089351E-7,6.01182973599454E-8,1.00015070921387,10.005763053894,2,20,10,5,2.154007955103,0.190132012076937,0.0410455763339996,172.855895996094,48.5000457763672,48.5011787414551,159.5322265625,159.5322265625,,,151.128463745117,0,1,,,,,,1,1,1,48.5012054443359,0,48.5006832795985,,,,,,,,,,,,,,,,,,,,,,,,,,,,,,,,,
,3768444829.38658,48.5003700256348,159.5322265625,,,5,,,,25.0300001353025,,,,,0.000659161779165853,5.47843298767648E-8,0.0186511557531137,5.75668397438742E-5,0.000659062475794813,5.47760765635284E-8,0.00065906244087573,3.95139471172443E-8,2.14540700457376E-7,3.79350306037724E-8,1.00015067368374,10.005763053894,2,20,10,5,2.1561895996967,0.190330869336572,0.0410455763339996,172.855895996094,48.499828338623,48.5005683898926,159.5322265625,159.5322265625,,,152.048797607422,0,1,,,,,,1,1,1,48.5005187988281,0,48.5001917945014,,,,,,,,,,,,,,,,,,,,,,,,,,,,,,,,,
,3768444983.65352,48.4997596740723,159.5322265625,,,5,,,,25.0300001353025,,,,,0.000659733006670588,8.47361624908786E-8,0.0201270014528134,7.58589655402916E-5,0.000659633559996655,8.47233895517709E-8,0.000659633519297477,6.83770444721285E-8,2.31717684271927E-7,5.00263183374279E-8,1.00015076048274,10.005763053894,2,20,10,5,2.15805323892095,0.190551400329206,0.0410455763339996,172.855895996094,48.4994316101074,48.4999771118164,159.5322265625,159.5322265625,,,152.944274902344,0,1,,,,,,1,1,1,48.4998054504395,0,48.4997369978163,,,,,,,,,,,,,,,,,,,,,,,,,,,,,,,,,
,3768445137.41719,48.5008068084717,159.5322265625,,,5,,,,25.0300001353025,,,,,0.000660135454100524,5.47076605096918E-8,0.0169096779342679,5.07923815707031E-5,0.000660035990851501,5.46994176534311E-8,0.000660035962106454,4.32274160510212E-8,1.94796125703338E-7,3.35174102993713E-8,1.00015069367489,10.005763053894,2,20,10,5,2.15938038860911,0.190546380079917,0.0410455763339996,172.855895996094,48.4994659423828,48.5009574890137,159.5322265625,159.5322265625,,,153.839752197266,0,1,,,,,,1,1,1,48.500904083252,0,48.5002396527459,,,,,,,,,,,,,,,,,,,,,,,,,,,,,,,,,
,3768445293.6324,48.5006484985352,159.5322265625,,,5,,,,25.0300001353025,,,,,0.000660522127557537,6.41295155577425E-8,0.0203890127487023,5.42593855941202E-5,0.000660422610832554,6.41198535659684E-8,0.000660422569016884,5.31795274810396E-8,2.35014949827644E-7,3.58230858276417E-8,1.00015068642919,10.005763053894,2,20,10,5,2.16063366075734,0.190789200877642,0.0410455763339996,172.855895996094,48.4996795654297,48.5009384155273,159.5322265625,159.5322265625,,,154.76008605957,0,1,,,,,,1,1,1,48.5004463195801,0,48.5001945495605,,,,,,,,,,,,,,,,,,,,,,,,,,,,,,,,,
,3768445449.51706,48.5001964569092,159.5322265625,,,5,,,,25.0300001353025,,,,,0.000661336805802372,6.74863395521437E-8,0.0217798042402588,5.99323117305313E-5,0.00066123710415845,6.74761654639385E-8,0.000661237056384639,5.46201931360681E-8,2.51355587802826E-7,3.96190283512282E-8,1.00015078047389,10.005763053894,2,20,10,5,2.16329391690401,0.191077028863183,0.0410455763339996,172.855895996094,48.4997291564941,48.5007934570313,159.5322265625,159.5322265625,,,155.69287109375,0,1,,,,,,1,1,1,48.5004997253418,0,48.5002933078342,,,,,,,,,,,,,,,,,,,,,,,,,,,,,,,,,
,3768445607.80458,48.4995727539063,159.5322265625,,,5,,,,25.0300001353025,,,,,0.0006619246713465,6.83345711728302E-8,0.0193219340719093,5.53885297162242E-5,0.000661824975889658,6.83242789952063E-8,0.000661824938256638,5.76660002517959E-8,2.23188137373752E-7,3.66447747322133E-8,1.00015063719333,10.005763053894,2,20,10,5,2.16522508126151,0.191153998710759,0.0410455763339996,172.855895996094,48.4988594055176,48.5003433227539,159.5322265625,159.5322265625,,,156.62565612793,0,1,,,,,,1,1,1,48.4995040893555,0,48.4997338189019,,,,,,,,,,,,,,,,,,,,,,,,,,,,,,,,,
,3768445762.34647,48.5010833740234,159.5322265625,,,5,,,,25.0300001353025,,,,,0.000662141206382744,6.41147626175259E-8,0.0209597031808269,6.53723584180664E-5,0.000662041432546117,6.41051015727381E-8,0.000662041388248521,4.72963509551387E-8,2.42185231233646E-7,4.32726152893423E-8,1.00015070633305,10.005763053894,2,20,10,5,2.16592792407937,0.191278435102996,0.0410455763339996,172.855895996094,48.4996147155762,48.5014801025391,159.5322265625,159.5322265625,,,157.546005249023,0,1,,,,,,1,1,1,48.5013999938965,0,48.5004878324621,,,,,,,,,,,,,,,,,,,,,,,,,,,,,,,,,
,3768445916.28674,48.4989376068115,159.5322265625,,,5,,,,25.0300001353025,,,,,0.000662743903030759,5.47997836973687E-8,0.0195032133250681,5.35583497278683E-5,0.000662644027429471,5.47915253621019E-8,0.000662643989039537,4.17494673379768E-8,2.25560899699649E-7,3.54837037032645E-8,1.00015072285745,10.005763053894,2,20,10,5,2.16790426848328,0.19139744032904,0.0410455763339996,172.855895996094,48.4982948303223,48.5024375915527,159.5322265625,159.5322265625,,,158.466339111328,0,1,,,,,,1,1,1,48.4993515014648,0,48.5004386901855,,,,,,,,,,,,,,,,,,,,,,,,,,,,,,,,,
,3768446072.84032,48.5008354187012,159.5322265625,,,5,,,,25.0300001353025,,,,,0.000663199256750557,6.52946581740873E-8,0.0173557161345466,3.76148082988245E-5,0.000663099331007243,6.52848200791466E-8,0.000663099300585198,6.03410446305376E-8,2.008623266805E-7,2.49211971153477E-8,1.00015069498436,10.005763053894,2,20,10,5,2.16940095558272,0.191447627388954,0.0410455763339996,172.855895996094,48.4997940063477,48.5010643005371,159.5322265625,159.5322265625,,,159.42399597168,0,1,,,,,,1,1,1,48.5008506774902,0,48.500325732761,,,,,,,,,,,,,,,,,,,,,,,,,,,,,,,,,
,3768446226.91197,48.5002822875977,159.5322265625,,,5,,,,25.0300001353025,,,,,0.000663717551007823,7.3646923471362E-8,0.0184161449262543,8.41516994875073E-5,0.00066361756396975,7.36358287854826E-8,0.00066361752968981,4.80014129203772E-8,2.13301522853869E-7,5.5839946620429E-8,1.00015066966805,10.005763053894,2,20,10,5,2.17109280892087,0.191637430423154,0.0410455763339996,172.855895996094,48.4992446899414,48.5004501342773,159.5322265625,159.5322265625,,,160.344345092773,0,1,,,,,,1,1,1,48.500114440918,0,48.4998916177189,,,,,,,,,,,,,,,,,,,,,,,,,,,,,,,,,
,3768446380.68825,48.5001735687256,159.5322265625,,,5,,,,25.0300001353025,,,,,0.0006643886692915,4.82323468037838E-8,0.0181287105785639,4.56617135630185E-5,0.00066428858445647,4.82250809868063E-8,0.000664288551204655,3.74962055353567E-8,2.10184683578099E-7,3.0326440718197E-8,1.00015066469208,10.005763053894,2,20,10,5,2.17328907273438,0.191820301233833,0.0410455763339996,172.855895996094,48.4994583129883,48.5004081726074,159.5322265625,159.5322265625,,,161.277130126953,0,1,,,,,,1,1,1,48.5003051757812,0,48.4999690585666,,,,,,,,,,,,,,,,,,,,,,,,,,,,,,,,,
,3768446537.15033,48.499849319458,159.5322265625,,,5,,,,25.0300001353025,,,,,0.000664680903375892,7.46695995085914E-8,0.0186293783910516,8.33277874213895E-5,0.000664580708140749,7.46583436743364E-8,0.000664580673011473,5.00771311025295E-8,2.16084419662615E-7,5.53728202346188E-8,1.00015076458572,10.005763053894,2,20,10,5,2.17424332570807,0.191923674994009,0.0410455763339996,172.855895996094,48.499584197998,48.500545501709,159.5322265625,159.5322265625,,,162.222351074219,0,1,,,,,,1,1,1,48.4999084472656,0,48.4999883439806,,,,,,,,,,,,,,,,,,,,,,,,,,,,,,,,,
,3768446692.3077,48.5005283355713,159.5322265625,,,5,,,,25.0300001353025,,,,,0.000665259246188254,5.28418259645016E-8,0.0155677497068272,4.98107005881913E-5,0.000665159019408984,5.28338649086312E-8,0.000665158994856135,4.11597785534477E-8,1.80729350224172E-7,3.31253665732869E-8,1.00015068092944,10.005763053894,2,20,10,5,2.17614540935871,0.191974383221837,0.0410455763339996,172.855895996094,48.4994583129883,48.5006446838379,159.5322265625,159.5322265625,,,163.155136108398,0,1,,,,,,1,1,1,48.5005378723145,0,48.5000603993734,,,,,,,,,,,,,,,,,,,,,,,,,,,,,,,,,
,3768446847.10339,48.4998054504395,159.5322265625,,,5,,,,25.0300001353025,,,,,0.000665482290854362,5.85210749339571E-8,0.0177461288241672,5.14673771234813E-5,0.000665381976152363,5.85122534757857E-8,0.000665381944236762,4.74504150942782E-8,2.06087676572929E-7,3.42365581534606E-8,1.00015076257788,10.005763053894,2,20,10,5,2.17686771300317,0.192121514299172,0.0410455763339996,172.855895996094,48.4994163513184,48.4998970031738,159.5322265625,159.5322265625,,,164.11279296875,0,1,,,,,,1,1,1,48.4999237060547,0,48.4997150196749,,,,,,,,,,,,,,,,,,,,,,,,,,,,,,,,,
,3768447000.97149,48.5003318786621,159.5322265625,,,5,,,,25.0300001353025,,,,,0.000666000427498133,6.09603758791502E-8,0.0161163663617279,5.59967291315692E-5,0.000665900095040443,6.09511922449044E-8,0.00066590006869727,4.8220848250582E-8,1.87306811106602E-7,3.72799896736793E-8,1.00015067193778,10.005763053894,2,20,10,5,2.17856806486878,0.192209127106572,0.0410455763339996,172.855895996094,48.4992218017578,48.5004272460937,159.5322265625,159.5322265625,,,165.04557800293,0,1,,,,,,1,1,1,48.5004272460937,0,48.4998602025649,,,,,,,,,,,,,,,,,,,,,,,,,,,,,,,,,
,3768447155.5859,48.5000114440918,159.5322265625,,,5,,,,25.0300001353025,,,,,0.000666519102560202,5.360185335222E-8,0.0166468874363357,5.89576126699031E-5,0.000666418701736733,5.35937790596823E-8,0.000666418673608789,3.64536039621254E-8,1.93623283450859E-7,3.92864851071022E-8,1.00015065727178,10.005763053894,2,20,10,5,2.18026293225172,0.192379009603039,0.0410455763339996,172.855895996094,48.4976348876953,48.5007972717285,159.5322265625,159.5322265625,,,166.015670776367,0,1,,,,,,1,1,1,48.4994506835937,0,48.4988197750515,,,,,,,,,,,,,,,,,,,,,,,,,,,,,,,,,
,3768447311.11077,48.5002746582031,159.5322265625,,,5,,,,25.0300001353025,,,,,0.000667013630398888,9.72464541818814E-8,0.0173661185946976,5.72399929732762E-5,0.000666913070543048,9.7231793178016E-8,0.000666913039909345,8.94375346323713E-8,2.02138646100985E-7,3.81437937742939E-8,1.0001507840531,10.005763053894,2,20,10,5,2.18187817480238,0.192549132029299,0.0410455763339996,172.855895996094,48.4996452331543,48.5003356933594,159.5322265625,159.5322265625,,,167.010635375977,0,1,,,,,,1,1,1,48.5002746582031,0,48.4999984292423,,,,,,,,,,,,,,,,,,,,,,,,,,,,,,,,,
,3768447464.92625,48.5003070831299,159.5322265625,,,5,,,,25.0300001353025,,,,,0.000667347495760698,6.74408553977457E-8,0.0156197723059943,6.33083091685317E-5,0.00066724688458079,6.74306878252611E-8,0.000667246859785985,5.25662386246021E-8,1.81902478132092E-7,4.22337331696974E-8,1.00015078553716,10.005763053894,2,20,10,5,2.18297615752618,0.192578973450882,0.0410455763339996,172.855895996094,48.4994583129883,48.5006294250488,159.5322265625,159.5322265625,,,167.968292236328,0,1,,,,,,1,1,1,48.5004539489746,0,48.4999807021197,,,,,,,,,,,,,,,,,,,,,,,,,,,,,,,,,
,3768447618.68238,48.5013008117676,159.5322265625,,,5,,,,25.0300001353025,,,,,0.00066777050656578,8.37290300517939E-8,0.0166261829274932,6.76879391774558E-5,0.000667669877842199,8.37164126250912E-8,0.000667669849731501,7.04796285977065E-8,1.93745533488301E-7,4.51780886663423E-8,1.00015071628498,10.005763053894,2,20,10,5,2.18435649326706,0.192739408921799,0.0410455763339996,172.855895996094,48.4998588562012,48.5014762878418,159.5322265625,159.5322265625,,,168.913513183594,0,1,,,,,,1,1,1,48.5011863708496,0,48.5005084767061,,,,,,,,,,,,,,,,,,,,,,,,,,,,,,,,,
,3768447772.39296,48.5005531311035,159.5322265625,,,5,,,,25.0300001353025,,,,,0.00066821417857269,8.6665677082439E-8,0.0176883493420696,4.86078185525654E-5,0.000668113505850436,8.66526200867665E-8,0.000668113474012156,8.0348585027357E-8,2.06259954997503E-7,3.2446593842853E-8,1.00015068206431,10.005763053894,2,20,10,5,2.18580422089765,0.192907990879386,0.0410455763339996,172.855895996094,48.4994926452637,48.5007438659668,159.5322265625,159.5322265625,,,169.896041870117,0,1,,,,,,1,1,1,48.5003929138184,0,48.5002309013815,,,,,,,,,,,,,,,,,,,,,,,,,,,,,,,,,