File: Experimental_Data/Fig3C/Lifetime_260Oe_49K.dat
[Header]
; MPMS3 Data File (default extension .dat)
; Copyright (c) 2007, Quantum Design, Inc. All rights reserved.
TITLE,260Oe_49K
FILEOPENTIME,3768223621.24025,05/28/2019,4:46 pm
BYAPP,SQUID AC,0.9.1.0
INFO,MPMS3 Measurement Release 1.1.16 Build 347, MultiVu Release 2.3.3.2,APPNAME
INFO,0,MOMENT_UNITS
INFO,,SAMPLE_MATERIAL
INFO,,SAMPLE_COMMENT
INFO,,SAMPLE_MASS
INFO,,SAMPLE_VOLUME
INFO,,SAMPLE_MOLECULAR_WEIGHT
INFO,,SAMPLE_SIZE
INFO,,SAMPLE_SHAPE
INFO,Quartz,SAMPLE_HOLDER
INFO,Standard,SAMPLE_HOLDER_DETAIL
INFO,66.2,SAMPLE_OFFSET
DATATYPE,COMMENT,1
DATATYPE,TIME,2
STARTUPAXIS,X,2
STARTUPAXIS,Y1,5
FIELDGROUP, VSM,2,3,4,5,6,8,9,10,11,14,15
FIELDGROUP, DC, 2,3,4,14,56,57,58,59,60,61,62,63,64,65,66,67,68,69
FIELDGROUP, AC, 2,3,4,11,16,17,18,19,20,21,22,23,24,25,26,27,28,29,30
STARTUPGROUP, All
[Data]
Comment,Time Stamp (sec),Temperature (K),Magnetic Field (Oe),Moment (emu),M. Std. Err. (emu),Transport Action,Averaging Time (sec),Frequency (Hz),Peak Amplitude (mm),Center Position (mm),Lockin Signal' (V),Lockin Signal (V),Range,M. Quad. Signal (emu),AC Moment (emu),AC M. Std Err. (emu),AC Phase (deg),AC Phase Std. Err. (deg),AC Susceptibility (emu/Oe),AC Suscept. Std Err. (emu/Oe),AC X' (emu/Oe),AC X' Std Err. (emu/Oe),AC X'' (emu/Oe),AC X'' Std Err. (emu/Oe),AC Drive (Oe),AC Frequency (Hz),AC Averaging Time (sec),AC Cycles,AC Range,AC Measure Type,AC Signal' (V),AC Signal'' (V),AC Trim Coil Ratio,AC Trim Coil Phase,Min. Temperature (K),Max. Temperature (K),Min. Field (Oe),Max. Field (Oe),Mass (grams),Motor Lag (deg),Pressure (Torr),Measure Count,Measurement Number,SQUID Status (code),Motor Status (code),Measure Status (code),Motor Current (amps),Motor Temp. (C),Temp. Status (code),Field Status (code),Chamber Status (code),Chamber Temp (K),Redirection State,Average Temp (K),Rotation Angle (deg),Rotator state,DC Moment Fixed Ctr (emu),DC Moment Err Fixed Ctr (emu),DC Moment Free Ctr (emu),DC Moment Err Free Ctr (emu),DC Fixed Fit,DC Free Fit,DC Calculated Center (mm),DC Calculated Center Err (mm),DC Scan Length (mm),DC Scan Time (s),DC Number of Points,DC Squid Drift,DC Min V (V),DC Max V (V),DC Scans per Measure,Map 01,Map 02,Map 03,Map 04,Map 05,Map 06,Map 07,Map 08,Map 09,Map 10,Map 11,Map 12,Map 13,Map 14,Map 15,Map 16
,3768223625.60921,48.9802913665771,259.928985595703,,,5,,,,25.0300001353025,,,,,0.000600552464502777,2.81474514757699E-7,0.0565053877313133,0.00014398125770095,0.000600462442349394,2.81432322037764E-7,0.000600462150344405,2.67879059671082E-7,5.92179003609592E-7,8.62841890342889E-8,1.00014992137232,10.005763053894,2,20,10,5,1.96434405104965,0.174914836098804,0.0410455763339996,172.855895996094,48.9148941040039,48.990421295166,259.928985595703,259.928985595703,,,18.054313659668,0,1,,,,,,1,1,1,48.9748611450195,0,48.9484769035788,,,,,,,,,,,,,,,,,,,,,,,,,,,,,,,,,
,3768223834.08115,49.0002880096436,259.928985595703,,,5,,,,25.0300001353025,,,,,0.000608283222776334,2.03915557025289E-7,0.00561594354651263,0.00018643288145666,0.000608191624795742,2.03884850517966E-7,0.000608191621874211,1.69468902712032E-7,5.96129392753222E-8,1.13354855583311E-7,1.00015060710614,10.005763053894,2,20,10,5,1.98978713018231,0.175399142675775,0.0410455763339996,172.855895996094,48.9998054504395,49.0006828308105,259.928985595703,259.928985595703,,,18.2383193969727,0,1,,,,,,1,1,1,49.0003509521484,0,49.0002827114529,,,,,,,,,,,,,,,,,,,,,,,,,,,,,,,,,
,3768224040.73288,48.9999217987061,259.928985595703,,,5,,,,25.0300001353025,,,,,0.000612710876796129,1.83809234462839E-7,-0.00242178957847017,0.000222795229129656,0.000612618622346202,1.83781558734434E-7,0.000612618621798949,1.23086222877662E-7,-2.58942876306317E-8,1.36475063907546E-7,1.00015059034538,10.005763053894,2,20,10,5,2.00429542644384,0.17639469198124,0.0410455763339996,172.855895996094,48.9996147155762,49.0000686645508,259.928985595703,259.928985595703,,,18.1126575469971,0,1,,,,,,1,1,1,49.0000686645508,0,48.9999050813563,,,,,,,,,,,,,,,,,,,,,,,,,,,,,,,,,
,3768224245.7078,49.0007629394531,259.928985595703,,,5,,,,25.0300001353025,,,,,0.000616354206192343,2.15995615493045E-7,0.00285566076513,0.000234626794505934,0.000616261379453922,2.1596308522344E-7,0.000616261378688497,1.60435815832266E-7,3.07148878433713E-8,1.44569717359695E-7,1.00015062884275,10.005763053894,2,20,10,5,2.01619710692684,0.1776292866709,0.0410455763339996,172.855895996094,48.9998588562012,49.0009574890137,259.928985595703,259.928985595703,,,17.9453811645508,0,1,,,,,,1,1,1,49.0005950927734,0,49.0004333047306,,,,,,,,,,,,,,,,,,,,,,,,,,,,,,,,,
,3768224453.51453,48.9998455047607,259.928985595703,,,5,,,,25.0300001353025,,,,,0.000619551706212627,1.72488676204873E-7,0.00479289544783779,0.000170559696550309,0.000619458423917659,1.72462705588682E-7,0.00061945842175029,1.36327213910237E-7,5.18188160085884E-8,1.05632739084248E-7,1.00015058685356,10.005763053894,2,20,10,5,2.02665062286288,0.178619311186654,0.0410455763339996,172.855895996094,48.9992713928223,49.0003662109375,259.928985595703,259.928985595703,,,17.8095016479492,0,1,,,,,,1,1,1,48.9999618530273,0,48.9997960258933,,,,,,,,,,,,,,,,,,,,,,,,,,,,,,,,,
,3768224658.60112,48.9995784759521,259.928985595703,,,5,,,,25.0300001353025,,,,,0.000622435284238442,1.72774126230333E-7,0.00452266262039558,0.00016151506020428,0.000622341575384644,1.72748114746497E-7,0.000622341573445804,1.40510042523724E-7,4.91247523134694E-8,1.00492980344151E-7,1.00015057463217,10.005763053894,2,20,10,5,2.03608410404129,0.179441059093207,0.0410455763339996,172.855895996094,48.9984359741211,49.0001792907715,259.928985595703,259.928985595703,,,17.6752033233643,0,1,,,,,,1,1,1,48.9989852905273,0,48.9993005640367,,,,,,,,,,,,,,,,,,,,,,,,,,,,,,,,,
,3768224863.5914,49.0000762939453,259.928985595703,,,5,,,,25.0300001353025,,,,,0.000625118724228835,2.24647336428004E-7,0.00282080274166763,0.000219090309307167,0.000625024597139364,2.24613510213693E-7,0.00062502459638189,1.78065553465941E-7,3.07713955808147E-8,1.36908318371767E-7,1.00015059741633,10.005763053894,2,20,10,5,2.04486741214087,0.180153924426992,0.0410455763339996,172.855895996094,48.9990158081055,49.0009841918945,259.928985595703,259.928985595703,,,17.5408897399902,0,1,,,,,,1,1,1,48.9993553161621,0,48.9997731377097,,,,,,,,,,,,,,,,,,,,,,,,,,,,,,,,,
,3768225070.21569,49.000244140625,259.928985595703,,,5,,,,25.0300001353025,,,,,0.000627410303194741,1.67965304206529E-7,0.0108105061613841,0.00016162444804899,0.000627315826233038,1.67940011584569E-7,0.000627315815066899,1.33897863783372E-7,1.18361275856983E-7,1.01366708367563E-7,1.00015060509834,10.005763053894,2,20,10,5,2.05233831471374,0.181100529347193,0.0410455763339996,172.855895996094,48.9994087219238,49.0010566711426,259.928985595703,259.928985595703,,,17.4117107391357,0,1,,,,,,1,1,1,48.999942779541,0,48.9998949836282,,,,,,,,,,,,,,,,,,,,,,,,,,,,,,,,,
,3768225276.59888,49.0013790130615,259.928985595703,,,5,,,,25.0300001353025,,,,,0.000630199653452898,3.20925671286258E-7,0.00513166297675305,0.000312626860709551,0.000630104723740807,3.20877328857932E-7,0.000630104721213525,2.53326127280308E-7,5.64349609247668E-8,1.96947031996328E-7,1.00015065703924,10.005763053894,2,20,10,5,2.06148065149849,0.181701340873725,0.0410455763339996,172.855895996094,48.9997978210449,49.0016098022461,259.928985595703,259.928985595703,,,17.3007736206055,0,1,,,,,,1,1,1,49.0016212463379,0,49.0005847083198,,,,,,,,,,,,,,,,,,,,,,,,,,,,,,,,,
,3768225484.51236,49.0010089874268,259.928985595703,,,5,,,,25.0300001353025,,,,,0.000632119368235395,1.06130911879388E-7,0.00579715056289576,0.000117798226679614,0.000632024160050264,1.06114926715804E-7,0.000632024156815165,7.56225371846336E-8,6.39478027890531E-8,7.4441987759994E-8,1.00015064010389,10.005763053894,2,20,10,5,2.06775821866821,0.182278858004553,0.0410455763339996,172.855895996094,48.9998512268066,49.0012397766113,259.928985595703,259.928985595703,,,17.1710758209229,0,1,,,,,,1,1,1,49.0012397766113,0,49.0004853142632,,,,,,,,,,,,,,,,,,,,,,,,,,,,,,,,,
,3768225692.08048,49.0013198852539,259.928985595703,,,5,,,,25.0300001353025,,,,,0.000633909336319752,1.88962054854726E-7,0.00595669157464229,0.000194472271235392,0.000633813849516958,1.88933591190549E-7,0.000633813846091673,1.43206665065818E-7,6.58937471938242E-8,1.23238601748333E-7,1.00015065433308,10.005763053894,2,20,10,5,2.07361296649072,0.182800789310672,0.0410455763339996,172.855895996094,48.9990577697754,49.001350402832,259.928985595703,259.928985595703,,,17.053747177124,0,1,,,,,,1,1,1,49.0013732910156,0,48.9999784581801,,,,,,,,,,,,,,,,,,,,,,,,,,,,,,,,,
,3768225897.0294,48.999698638916,259.928985595703,,,5,,,,25.0300001353025,,,,,0.000635682890751891,1.97292333789061E-7,-0.00236475502701516,0.000238941144480802,0.000635587183949965,1.97262629956244E-7,0.000635587183408623,1.25906852971899E-7,-2.6232438073073E-8,1.51855225632728E-7,1.00015058013179,10.005763053894,2,20,10,5,2.07944113137733,0.183010228302537,0.0410455763339996,172.855895996094,48.9991035461426,49.0000190734863,259.928985595703,259.928985595703,,,16.9464511871338,0,1,,,,,,1,1,1,48.9994354248047,0,48.9996464252472,,,,,,,,,,,,,,,,,,,,,,,,,,,,,,,,,
,3768226103.64487,48.9999103546143,259.928985595703,,,5,,,,25.0300001353025,,,,,0.000637425006417504,1.67489983632096E-7,0.00936645426377414,0.000203252540347468,0.000637329031152396,1.67464765142987E-7,0.000637329022636333,1.06144856835065E-7,1.04187659988341E-7,1.29528826644339E-7,1.00015058982161,10.005763053894,2,20,10,5,2.08510230986171,0.183938698949087,0.0410455763339996,172.855895996094,48.9996490478516,49.0001602172852,259.928985595703,259.928985595703,,,16.8503913879395,0,1,,,,,,1,1,1,48.9998168945313,0,48.9999495113597,,,,,,,,,,,,,,,,,,,,,,,,,,,,,,,,,
,3768226308.65159,49.0004806518555,259.928985595703,,,5,,,,25.0300001353025,,,,,0.000639297941862402,1.35334956905603E-7,0.00665930873783882,0.000137832114842176,0.000639201667913205,1.35314576375787E-7,0.000639201663595818,1.02716133575782E-7,7.42924047629029E-8,8.80876295685197E-8,1.000150615923,10.005763053894,2,20,10,5,2.09123764610819,0.184380352171802,0.0410455763339996,172.855895996094,48.9999084472656,49.0007438659668,259.928985595703,259.928985595703,,,16.7652816772461,0,1,,,,,,1,1,1,49.0006141662598,0,49.0003159466912,,,,,,,,,,,,,,,,,,,,,,,,,,,,,,,,,
,3768226513.7253,49.000696182251,259.928985595703,,,5,,,,25.0300001353025,,,,,0.000640640356174029,1.41232279011516E-7,0.00421316966072638,0.000147280201519615,0.000640543873748676,1.41211008992096E-7,0.000640543872016901,1.05087237573842E-7,4.71015498129978E-8,9.43250844667771E-8,1.00015062578741,10.005763053894,2,20,10,5,2.09563676734754,0.184678048729616,0.0410455763339996,172.855895996094,49.0000114440918,49.0008544921875,259.928985595703,259.928985595703,,,16.6528816223145,0,1,,,,,,1,1,1,49.0008354187012,0,49.0004252265481,,,,,,,,,,,,,,,,,,,,,,,,,,,,,,,,,
,3768226721.30207,49.0008010864258,259.928985595703,,,5,,,,25.0300001353025,,,,,0.000642148983476073,1.43554856251688E-7,0.00181477045546341,0.000155728843942649,0.000642052270764573,1.43533235755892E-7,0.000642052270442512,1.02991002516284E-7,2.03361835994547E-8,9.99732122483186E-8,1.00015063058867,10.005763053894,2,20,10,5,2.100579474585,0.185025014772219,0.0410455763339996,172.855895996094,48.9996795654297,49.0014381408691,259.928985595703,259.928985595703,,,16.5511837005615,0,1,,,,,,1,1,1,49.0001640319824,0,49.0004501342773,,,,,,,,,,,,,,,,,,,,,,,,,,,,,,,,,
,3768226926.6844,49.0004634857178,259.928985595703,,,5,,,,25.0300001353025,,,,,0.000643658493225782,1.58454758003258E-7,0.00595852658371498,0.00019438305710845,0.000643561563112567,1.58430895912111E-7,0.00064356155963246,9.7227258374367E-8,6.69277686374041E-8,1.25088804489124E-7,1.00015061513734,10.005763053894,2,20,10,5,2.10550392171721,0.185612229056082,0.0410455763339996,172.855895996094,48.9993019104004,49.0008506774902,259.928985595703,259.928985595703,,,16.4603900909424,0,1,,,,,,1,1,1,49.0007133483887,0,49.0000644259983,,,,,,,,,,,,,,,,,,,,,,,,,,,,,,,,,
,3768227131.05418,49.0002994537354,259.928985595703,,,5,,,,25.0300001353025,,,,,0.000644854795562061,1.41227305679096E-7,-0.00199407624940662,0.000136938308191869,0.000644757690134479,1.41206038972237E-7,0.000644757689743993,1.10211486920276E-7,-2.24396283144437E-8,8.82755549008364E-8,1.00015060762992,10.005763053894,2,20,10,5,2.10944299711045,0.185664422657703,0.0410455763339996,172.855895996094,48.9996681213379,49.0005264282227,259.928985595703,259.928985595703,,,16.3718490600586,0,1,,,,,,1,1,1,49.0001564025879,0,49.0001205868191,,,,,,,,,,,,,,,,,,,,,,,,,,,,,,,,,
,3768227337.07313,49.0011768341064,259.928985595703,,,5,,,,25.0300001353025,,,,,0.000646283556411383,1.56380951723433E-7,-0.00174479402436489,0.000185692291004906,0.00064618620988958,1.56357396827791E-7,0.00064618620958996,1.00259873410756E-7,-1.96779212544032E-8,1.19981637455165E-7,1.00015064778591,10.005763053894,2,20,10,5,2.11411593698697,0.186084981421148,0.0410455763339996,172.855895996094,48.999137878418,49.0013160705566,259.928985595703,259.928985595703,,,16.292947769165,0,1,,,,,,1,1,1,49.0010375976562,0,49.0001238654642,,,,,,,,,,,,,,,,,,,,,,,,,,,,,,,,,
,3768227545.92536,49.0015506744385,259.928985595703,,,5,,,,25.0300001353025,,,,,0.000647535945877835,1.75102802518726E-7,0.00517816406625382,0.00020877842285582,0.000647438399638785,1.75076424647441E-7,0.000647438396994704,1.11280751532781E-7,5.85129006019217E-8,1.35160455776201E-7,1.00015066489585,10.005763053894,2,20,10,5,2.11819019706949,0.186701518733979,0.0410455763339996,172.855895996094,48.9996109008789,49.0023612976074,259.928985595703,259.928985595703,,,16.2066860198975,0,1,,,,,,1,1,1,49.0018768310547,0,49.0007882959702,,,,,,,,,,,,,,,,,,,,,,,,,,,,,,,,,
,3768227758.92146,48.9994888305664,259.928985595703,,,5,,,,25.0300001353025,,,,,0.000648852979930651,1.18879735070642E-7,0.0017738158233831,0.000104699524026539,0.000648755296502286,1.18861837980787E-7,0.000648755296191385,9.75538464653978E-8,2.00847675000698E-8,6.79071687524692E-8,1.00015057052928,10.005763053894,2,20,10,5,2.12250953036934,0.186955149876187,0.0410455763339996,172.855895996094,48.9994010925293,49.0002326965332,259.928985595703,259.928985595703,,,16.1483325958252,0,1,,,,,,1,1,1,48.9995536804199,0,48.9998081431669,,,,,,,,,,,,,,,,,,,,,,,,,,,,,,,,,
,3768227966.56976,49.0009002685547,259.928985595703,,,5,,,,25.0300001353025,,,,,0.000649920228882908,1.36738615975959E-7,0.00680508605917662,0.000162909304021051,0.000649822342811096,1.36718021439294E-7,0.000649822338227708,8.65260854882895E-8,7.71801517177859E-8,1.05853927259921E-7,1.00015063512804,10.005763053894,2,20,10,5,2.12598423338105,0.187449340227154,0.0410455763339996,172.855895996094,48.9995384216309,49.001220703125,259.928985595703,259.928985595703,,,16.082426071167,0,1,,,,,,1,1,1,49.0011558532715,0,49.0003647274441,,,,,,,,,,,,,,,,,,,,,,,,,,,,,,,,,
,3768228175.86822,48.9999351501465,259.928985595703,,,5,,,,25.0300001353025,,,,,0.000650950016660553,1.01577055953355E-7,0.0028828639391012,0.000122874576459402,0.000650852004234727,1.01561761670526E-7,0.000650852003410863,6.2609951302125E-8,3.27479229334845E-8,7.99674023059791E-8,1.00015059095645,10.005763053894,2,20,10,5,2.12936566688872,0.187600588459744,0.0410455763339996,172.855895996094,48.9987602233887,49.0000305175781,259.928985595703,259.928985595703,,,16.0085735321045,0,1,,,,,,1,1,1,48.999942779541,0,48.9995777732448,,,,,,,,,,,,,,,,,,,,,,,,,,,,,,,,,
,3768228387.41306,48.9998950958252,259.928985595703,,,5,,,,25.0300001353025,,,,,0.000652057698995986,1.34788964553766E-7,0.0038943093215531,0.000124330619009861,0.00065195952098333,1.34768669857932E-7,0.000651959519477395,1.07680019460615E-7,4.43127235454769E-8,8.10407785268487E-8,1.00015058912324,10.005763053894,2,20,10,5,2.13298576203808,0.187957472264504,0.0410455763339996,172.855895996094,48.9994697570801,49.0002326965332,259.928985595703,259.928985595703,,,15.9536743164062,0,1,,,,,,1,1,1,48.9995574951172,0,48.9997655083151,,,,,,,,,,,,,,,,,,,,,,,,,,,,,,,,,
,3768228595.98935,48.9991340637207,259.928985595703,,,5,,,,25.0300001353025,,,,,0.000652958532023868,1.6434206882582E-7,0.00269769573347034,0.000217449337005222,0.000652860166216452,1.64317311296054E-7,0.000652860165492798,8.27521522175686E-8,3.07390544167741E-8,1.41958656287402E-7,1.00015066902915,10.005763053894,2,20,10,5,2.13593646228701,0.188172532431228,0.0410455763339996,172.855895996094,48.9989471435547,49.001522064209,259.928985595703,259.928985595703,,,15.8921480178833,0,1,,,,,,1,1,1,48.9992523193359,0,49.0000828013701,,,,,,,,,,,,,,,,,,,,,,,,,,,,,,,,,
,3768228803.68186,49.0009155273438,259.928985595703,,,5,,,,25.0300001353025,,,,,0.000654111776573391,1.0751984495571E-7,0.00273663626537513,0.000109865544379014,0.00065401325874568,1.07503651054392E-7,0.000654013257999669,7.99729091059296E-8,3.12378401419673E-8,7.18426669825062E-8,1.0001506358264,10.005763053894,2,20,10,5,2.13970879029438,0.188506328270098,0.0410455763339996,172.855895996094,48.9995803833008,49.0011596679687,259.928985595703,259.928985595703,,,15.839958190918,0,1,,,,,,1,1,1,49.0007133483887,0,49.0003236134847,,,,,,,,,,,,,,,,,,,,,,,,,,,,,,,,,
,3768229010.25258,49.0009365081787,259.928985595703,,,5,,,,25.0300001353025,,,,,0.000654919308807784,1.83621921758099E-7,-0.0034177011884724,0.000197668314020855,0.000654820668726411,1.83594265707864E-7,0.000654820667561439,1.30218740408621E-7,-3.90601436167628E-8,1.29421536257309E-7,1.00015063678666,10.005763053894,2,20,10,5,2.14237062395357,0.188508927861869,0.0410455763339996,172.855895996094,49.0000801086426,49.0013389587402,259.928985595703,259.928985595703,,,15.7878818511963,0,1,,,,,,1,1,1,49.0012702941895,0,49.0005779266357,,,,,,,,,,,,,,,,,,,,,,,,,,,,,,,,,
,3768229216.52757,49.0011558532715,259.928985595703,,,5,,,,25.0300001353025,,,,,0.000655799580413853,1.58125603359257E-7,0.00395331244590214,0.000166699743568149,0.000655700801169579,1.58101785827092E-7,0.000655700799608759,1.14244184367854E-7,4.52422527108305E-8,1.09290626404278E-7,1.00015064682565,10.005763053894,2,20,10,5,2.14522586474275,0.189038283265684,0.0410455763339996,172.855895996094,49.0000152587891,49.0014572143555,259.928985595703,259.928985595703,,,15.7363033294678,0,1,,,,,,1,1,1,49.0011253356934,0,49.000696294448,,,,,,,,,,,,,,,,,,,,,,,,,,,,,,,,,
,3768229424.23745,49.0000896453857,259.928985595703,,,5,,,,25.0300001353025,,,,,0.000656764767489489,1.19160810544417E-7,0.00616504489590852,0.000105822364765476,0.000656665874904069,1.19142867863538E-7,0.000656665871102685,9.67912169989728E-8,7.06574659946527E-8,6.94728959710645E-8,1.0001505980274,10.005763053894,2,20,10,5,2.14837583678877,0.189399441280092,0.0410455763339996,172.855895996094,48.9994201660156,49.0006675720215,259.928985595703,259.928985595703,,,15.6946506500244,0,1,,,,,,1,1,1,48.9998016357422,0,48.9998773273669,,,,,,,,,,,,,,,,,,,,,,,,,,,,,,,,,
,3768229629.99065,49.0003890991211,259.928985595703,,,5,,,,25.0300001353025,,,,,0.000657441680042671,1.46782142797151E-7,-0.00209624051557888,0.000169558724134025,0.000657342676523108,1.46760039013368E-7,0.000657342676083163,9.54871417939172E-8,-2.40497356445734E-8,1.11448260655937E-7,1.00015061173281,10.005763053894,2,20,10,5,2.15061743387948,0.189284560748982,0.0410455763339996,172.855895996094,48.9998321533203,49.0008010864258,259.928985595703,259.928985595703,,,15.64501953125,0,1,,,,,,1,1,1,49.000301361084,0,49.0002100327436,,,,,,,,,,,,,,,,,,,,,,,,,,,,,,,,,
,3768229836.68593,49.0006237030029,259.928985595703,,,5,,,,25.0300001353025,,,,,0.000658303775589075,1.93414765740222E-7,-0.00151576364476647,0.000169626774117426,0.000658204635181045,1.93385637517803E-7,0.000658204634950716,1.57919137195908E-7,-1.74128472495959E-8,1.1162235844788E-7,1.00015062247017,10.005763053894,2,20,10,5,2.15343559303615,0.189554583127217,0.0410455763339996,172.855895996094,48.9995002746582,49.0010604858398,259.928985595703,259.928985595703,,,15.6042919158936,0,1,,,,,,1,1,1,49.0006141662598,0,49.0002632141113,,,,,,,,,,,,,,,,,,,,,,,,,,,,,,,,,
,3768230043.30616,48.9996223449707,259.928985595703,,,5,,,,25.0300001353025,,,,,0.00065880517997101,1.31474271059317E-7,0.00212490823809564,0.000138699045874508,0.00065870599423567,1.31454477085848E-7,0.000658705993782672,9.45275066972231E-8,2.44291953998794E-8,9.13500411796306E-8,1.00015057663997,10.005763053894,2,20,10,5,2.15506372262592,0.189835900737797,0.0410455763339996,172.855895996094,48.9989852905273,49.0005302429199,259.928985595703,259.928985595703,,,15.5555858612061,0,1,,,,,,1,1,1,48.9994659423828,0,48.9997901916504,,,,,,,,,,,,,,,,,,,,,,,,,,,,,,,,,
,3768230248.34624,49.0002117156982,259.928985595703,,,5,,,,25.0300001353025,,,,,0.00065954711260722,1.49287035119017E-7,0.00239129193484899,0.000156955540081069,0.000659447797385479,1.49264555337493E-7,0.000659447796811137,1.07562253926991E-7,2.75226589512403E-8,1.03490429558704E-7,1.00015060361432,10.005763053894,2,20,10,5,2.15748982702602,0.190059717891867,0.0410455763339996,172.855895996094,48.9995346069336,49.0002250671387,259.928985595703,259.928985595703,,,15.5167074203491,0,1,,,,,,1,1,1,49.0001983642578,0,48.9999735215131,,,,,,,,,,,,,,,,,,,,,,,,,,,,,,,,,
,3768230455.14659,48.9993782043457,259.928985595703,,,5,,,,25.0300001353025,,,,,0.000660570235368766,1.10727554496613E-7,0.00436377947792099,0.00013522640608559,0.000660470715507283,1.10710872559862E-7,0.000660470713591687,6.54297395756338E-8,5.03029817519802E-8,8.93075947612E-8,1.00015068020299,10.005763053894,2,20,10,5,2.16083007934306,0.19042894079066,0.0410455763339996,172.855895996094,48.9991035461426,49.0000114440918,259.928985595703,259.928985595703,,,15.4781827926636,0,1,,,,,,1,1,1,48.9994354248047,0,48.9994502597385,,,,,,,,,,,,,,,,,,,,,,,,,,,,,,,,,
,3768230661.50364,49.0004005432129,259.928985595703,,,5,,,,25.0300001353025,,,,,0.000660975999704622,1.54562840121279E-7,0.00292666770027594,0.000145630211886563,0.000660876463609114,1.54539564568727E-7,0.000660876462746946,1.20926618883336E-7,3.37575614733484E-8,9.62248921149632E-8,1.00015061225659,10.005763053894,2,20,10,5,2.16216217791699,0.190491678186336,0.0410455763339996,172.855895996094,48.9993858337402,49.0007019042969,259.928985595703,259.928985595703,,,15.4302453994751,0,1,,,,,,1,1,1,49.0005149841309,0,48.9999836192412,,,,,,,,,,,,,,,,,,,,,,,,,,,,,,,,,
,3768230867.86012,49.0005531311035,259.928985595703,,,5,,,,25.0300001353025,,,,,0.000661639619535616,1.11664593457765E-7,0.00283260604054369,0.000121690951371407,0.000661539978886611,1.11647777154396E-7,0.000661539978078161,7.73683839874287E-8,3.27054131284514E-8,8.04944675284669E-8,1.00015061924024,10.005763053894,2,20,10,5,2.16433330152032,0.190679378922052,0.0410455763339996,172.855895996094,48.9995727539063,49.000659942627,259.928985595703,259.928985595703,,,15.4097280502319,0,1,,,,,,1,1,1,49.0004463195801,0,49.0001110277678,,,,,,,,,,,,,,,,,,,,,,,,,,,,,,,,,
,3768231075.96293,48.9999179840088,259.928985595703,,,5,,,,25.0300001353025,,,,,0.000662308759847194,1.07349963530037E-7,0.00415456081731946,0.00010929142541501,0.000662209037675111,1.07333800114746E-7,0.000662209035934226,7.9272438170804E-8,4.80172840263181E-8,7.23631480349511E-8,1.00015059017079,10.005763053894,2,20,10,5,2.1665177661261,0.190922209547249,0.0410455763339996,172.855895996094,48.9996871948242,49.0003623962402,259.928985595703,259.928985595703,,,15.3634653091431,0,1,,,,,,1,1,1,48.9997634887695,0,49.0000330607096,,,,,,,,,,,,,,,,,,,,,,,,,,,,,,,,,
,3768231282.12999,49.0005264282227,259.928985595703,,,5,,,,25.0300001353025,,,,,0.000662827529270286,9.76643152093598E-8,0.00464823543210713,9.976507192002E-5,0.000662727710535987,9.76496074190224E-8,0.000662727708355085,7.18696195825218E-8,5.37651193290795E-8,6.61075155345652E-8,1.0001506180181,10.005763053894,2,20,10,5,2.16821309765827,0.191090432862316,0.0410455763339996,172.855895996094,48.9995727539063,49.0010147094727,259.928985595703,259.928985595703,,,15.3339614868164,0,1,,,,,,1,1,1,49.0005378723145,0,49.000207788804,,,,,,,,,,,,,,,,,,,,,,,,,,,,,,,,,
,3768231488.73241,49.0003299713135,259.928985595703,,,5,,,,25.0300001353025,,,,,0.000663541441061869,1.05998044450714E-7,0.00429278577875447,0.000112575584807245,0.000663441520780187,1.05982082592413E-7,0.000663441518918075,7.52022435112733E-8,4.97071921698105E-8,7.46781387120497E-8,1.00015060902665,10.005763053894,2,20,10,5,2.17054960221352,0.191282784146572,0.0410455763339996,172.855895996094,48.9996109008789,49.0008544921875,259.928985595703,259.928985595703,,,15.305588722229,0,1,,,,,,1,1,1,49.0007820129395,0,49.0000736012178,,,,,,,,,,,,,,,,,,,,,,,,,,,,,,,,,
,3768231693.83379,49.000207901001,259.928985595703,,,5,,,,25.0300001353025,,,,,0.00066388509045102,1.33175575551754E-7,0.000961113297995198,0.00013780465344636,0.000663785122128387,1.33155521872141E-7,0.000663785122034997,9.67750443973151E-8,1.11347242900042E-8,9.14602852988118E-8,1.00015060343973,10.005763053894,2,20,10,5,2.17168485878913,0.191255571481542,0.0410455763339996,172.855895996094,48.9999046325684,49.0006332397461,259.928985595703,259.928985595703,,,15.2604141235352,0,1,,,,,,1,1,1,49.0003089904785,0,49.000212725471,,,,,,,,,,,,,,,,,,,,,,,,,,,,,,,,,
,3768231900.33722,49.0005149841309,259.928985595703,,,5,,,,25.0300001353025,,,,,0.000664453340023483,1.18804489396669E-7,0.00104360031830009,0.000142526624187497,0.000664353276797586,1.18786598056911E-7,0.000664353276687384,7.17332307575044E-8,1.21007043971367E-8,9.46815688665153E-8,1.00015061749432,10.005763053894,2,20,10,5,2.17354342737297,0.191422406131901,0.0410455763339996,172.855895996094,48.9992523193359,49.001091003418,259.928985595703,259.928985595703,,,15.2486209869385,0,1,,,,,,1,1,1,49.0000305175781,0,48.9998140335083,,,,,,,,,,,,,,,,,,,,,,,,,,,,,,,,,
,3768232104.18971,49.0002918243408,259.928985595703,,,5,,,,25.0300001353025,,,,,0.00066509512978717,1.39073100000286E-7,0.00473381334652778,0.000144583723076617,0.000664994976702027,1.3905215773293E-7,0.000664994974432343,1.0046706026847E-7,5.4942303242175E-8,9.61346574924736E-8,1.00015060728073,10.005763053894,2,20,10,5,2.17563048906563,0.191747423779824,0.0410455763339996,172.855895996094,48.9998817443848,49.0007858276367,259.928985595703,259.928985595703,,,15.2144689559937,0,1,,,,,,1,1,1,49.0001487731934,0,49.0003298591165,,,,,,,,,,,,,,,,,,,,,,,,,,,,,,,,,
,3768232309.94211,48.9990882873535,259.928985595703,,,5,,,,25.0300001353025,,,,,0.000665613975064059,1.66212044565354E-7,0.00397521456739991,0.000143157626925381,0.000665513704154682,1.66187005678728E-7,0.000665513702552902,1.3618271757125E-7,4.61737285349863E-8,9.52490855146162E-8,1.00015066693406,10.005763053894,2,20,10,5,2.17733025336929,0.191868185014191,0.0410455763339996,172.855895996094,48.9982490539551,49.0001831054687,259.928985595703,259.928985595703,,,15.1888475418091,0,1,,,,,,1,1,1,48.9986915588379,0,48.9993663363986,,,,,,,,,,,,,,,,,,,,,,,,,,,,,,,,,
,3768232517.56742,48.9997177124023,259.928985595703,,,5,,,,25.0300001353025,,,,,0.000666187268771285,1.61768524064602E-7,0.00256963151740752,0.000140290844287511,0.000666086968726282,1.61744168465202E-7,0.000666086968056402,1.32035379998425E-7,2.98730217503874E-8,9.34228797520777E-8,1.00015058100475,10.005763053894,2,20,10,5,2.17921029991077,0.19197997632428,0.0410455763339996,172.855895996094,48.9996109008789,49.00048828125,259.928985595703,259.928985595703,,,15.1557703018188,0,1,,,,,,1,1,1,48.9998245239258,0,49.0000513862161,,,,,,,,,,,,,,,,,,,,,,,,,,,,,,,,,
,3768232724.18277,48.9998798370361,259.928985595703,,,5,,,,25.0300001353025,,,,,0.000666627685118018,1.50580817631387E-7,0.0081497117069409,0.000128946510848358,0.00066652731381969,1.50558145317431E-7,0.000666527307077094,1.23632133710285E-7,9.48063798115387E-8,8.59235161970632E-8,1.00015058842488,10.005763053894,2,20,10,5,2.18063225565811,0.192319271042034,0.0410455763339996,172.855895996094,48.9990196228027,49.0006790161133,259.928985595703,259.928985595703,,,15.1479654312134,0,1,,,,,,1,1,1,48.999210357666,0,48.9997069414924,,,,,,,,,,,,,,,,,,,,,,,,,,,,,,,,,
,3768232927.74184,49.0002021789551,259.928985595703,,,5,,,,25.0300001353025,,,,,0.000667182922229049,1.62876489551731E-7,-0.000868787638939494,0.000126290614752203,0.00066708245749107,1.62851963528506E-7,0.000667082457414381,1.39384385654214E-7,-1.01151079211181E-8,8.42184959547914E-8,1.00015060317784,10.005763053894,2,20,10,5,2.18247878399509,0.192135923873468,0.0410455763339996,172.855895996094,48.999397277832,49.0008316040039,259.928985595703,259.928985595703,,,15.1144399642944,0,1,,,,,,1,1,1,49.0006103515625,0,48.9998783784754,,,,,,,,,,,,,,,,,,,,,,,,,,,,,,,,,
,3768233134.06201,48.9991512298584,259.928985595703,,,5,,,,25.0300001353025,,,,,0.000667550796791017,1.36893476317212E-7,0.000456498800764926,0.000142526178344811,0.000667450232188137,1.36872853709691E-7,0.000667450232166953,9.84223942529491E-8,5.31784772194892E-9,9.5116824968832E-8,1.00015066981481,10.005763053894,2,20,10,5,2.18367772204722,0.192292379569992,0.0410455763339996,172.855895996094,48.9989318847656,48.9998779296875,259.928985595703,259.928985595703,,,15.0986032485962,0,1,,,,,,1,1,1,48.9993324279785,0,48.9994197172277,,,,,,,,,,,,,,,,,,,,,,,,,,,,,,,,,
,3768233340.57471,49.0015239715576,259.928985595703,,,5,,,,25.0300001353025,,,,,0.000668030159523302,1.54623362102991E-7,0.00199326133698463,0.000188819094165053,0.000667929526807015,1.54600069488566E-7,0.000667929526402826,8.94278452716012E-8,2.32365823915935E-8,1.26110435634598E-7,1.00015066367371,10.005763053894,2,20,10,5,2.18524064165106,0.19248906724226,0.0410455763339996,172.855895996094,49.0002174377441,49.001880645752,259.928985595703,259.928985595703,,,15.0823593139648,0,1,,,,,,1,1,1,49.0012588500977,0,49.0007910477488,,,,,,,,,,,,,,,,,,,,,,,,,,,,,,,,,
,3768233547.01465,48.999044418335,259.928985595703,,,5,,,,25.0300001353025,,,,,0.000668582889429329,1.94545921874713E-7,0.00303637544375235,0.000201453323660191,0.000668482172612088,1.94516615043252E-7,0.000668482171673391,1.40378207626984E-7,3.54260448117654E-8,1.34650185114318E-7,1.00015066492626,10.005763053894,2,20,10,5,2.1870452071268,0.192688157731765,0.0410455763339996,172.855895996094,48.99853515625,49.0003890991211,259.928985595703,259.928985595703,,,15.0506172180176,0,1,,,,,,1,1,1,48.9993095397949,0,48.999449561624,,,,,,,,,,,,,,,,,,,,,,,,,,,,,,,,,
,3768233754.12862,49.0008506774902,259.928985595703,,,5,,,,25.0300001353025,,,,,0.000669102049319867,1.52014112948171E-7,-0.00207579321940887,8.79652278155634E-5,0.000669001275745459,1.51991218076547E-7,0.000669001275306403,1.40152784739036E-7,-2.42375323883573E-8,5.88092450409445E-8,1.00015063285835,10.005763053894,2,20,10,5,2.18876066250466,0.192642487188818,0.0410455763339996,172.855895996094,48.9998207092285,49.0011749267578,259.928985595703,259.928985595703,,,15.0260896682739,0,1,,,,,,1,1,1,49.0005378723145,0,49.0003848605686,,,,,,,,,,,,,,,,,,,,,,,,,,,,,,,,,
,3768233962.38575,48.999532699585,259.928985595703,,,5,,,,25.0300001353025,,,,,0.000669519222508066,1.15367927408659E-7,0.000765927448145298,0.000116651150886158,0.000669418349681828,1.15350545549403E-7,0.000669418349622015,8.49099105818166E-8,8.94875491101571E-9,7.80772402402442E-8,1.00015068727394,10.005763053894,2,20,10,5,2.19011575221232,0.192871223867677,0.0410455763339996,172.855895996094,48.9991264343262,49.0002937316895,259.928985595703,259.928985595703,,,15.0032396316528,0,1,,,,,,1,1,1,48.9997024536133,0,48.999693477855,,,,,,,,,,,,,,,,,,,,,,,,,,,,,,,,,
,3768234170.09247,48.9994125366211,259.928985595703,,,5,,,,25.0300001353025,,,,,0.000669957280456147,9.74547236894024E-8,-0.00192438214342072,0.000110604966867617,0.0006698563453135,9.74400412510974E-8,0.000669856344935676,6.32952466509245E-8,-2.24983340883193E-8,7.40828818986829E-8,1.00015068177431,10.005763053894,2,20,10,5,2.19155777681423,0.19289451464859,0.0410455763339996,172.855895996094,48.9992980957031,49.0004463195801,259.928985595703,259.928985595703,,,14.9968566894531,0,1,,,,,,1,1,1,48.9993362426758,0,48.999797147863,,,,,,,,,,,,,,,,,,,,,,,,,,,,,,,,,
,3768234378.14774,48.9994068145752,259.928985595703,,,5,,,,25.0300001353025,,,,,0.000670197150341072,1.02296305189053E-7,-0.000680683368271318,0.000109823224331013,0.000670096256108472,1.02280905082973E-7,0.000670096256061184,7.10408284891426E-8,-7.96085471808685E-9,7.35838585028558E-8,1.00015056677556,10.005763053894,2,20,10,5,2.19233824740579,0.193011170357854,0.0410455763339996,172.855895996094,48.9963989257812,49.000602722168,259.928985595703,259.928985595703,,,14.9817028045654,0,1,,,,,,1,1,1,48.998348236084,0,48.9975886874729,,,,,,,,,,,,,,,,,,,,,,,,,,,,,,,,,
,3768234590.25843,48.9994697570801,259.928985595703,,,5,,,,25.0300001353025,,,,,0.000670780111530308,1.47134607569824E-7,0.00219559250046952,0.000162478786271673,0.000670679127604564,1.47112456897748E-7,0.000670679127112136,9.88418518729369E-8,2.57006375503349E-8,1.08960374874632E-7,1.00015056965632,10.005763053894,2,20,10,5,2.19423552043655,0.193289208924452,0.0410455763339996,172.855895996094,48.998477935791,49.0006790161133,259.928985595703,259.928985595703,,,14.9592409133911,0,1,,,,,,1,1,1,48.9986801147461,0,48.9995856814914,,,,,,,,,,,,,,,,,,,,,,,,,,,,,,,,,
,3768234796.97704,49.0003910064697,259.928985595703,,,5,,,,25.0300001353025,,,,,0.000671232057965126,1.17390007639885E-7,0.0045761167263505,0.000106142496005078,0.000671130977707043,1.17372329979636E-7,0.000671130975566489,9.32948654694857E-8,5.36020927805125E-8,7.1220305544691E-8,1.00015061182011,10.005763053894,2,20,10,5,2.19570587633717,0.193510661276161,0.0410455763339996,172.855895996094,48.9992980957031,49.0007934570313,259.928985595703,259.928985595703,,,14.9357566833496,0,1,,,,,,1,1,1,49.0001983642578,0,48.999953326057,,,,,,,,,,,,,,,,,,,,,,,,,,,,,,,,,
,3768235003.42846,49.0004749298096,259.928985595703,,,5,,,,25.0300001353025,,,,,0.000671445951592715,1.19020010778104E-7,0.00348659447189181,0.000151555570630175,0.000671344836546323,1.19002087200067E-7,0.000671344835303316,6.17258235077793E-8,4.08530473672402E-8,1.01741925823422E-7,1.00015061566111,10.005763053894,2,20,10,5,2.19640923670527,0.19353055795684,0.0410455763339996,172.855895996094,49.0000152587891,49.0008277893066,259.928985595703,259.928985595703,,,14.9228401184082,0,1,,,,,,1,1,1,49.0003890991211,0,49.0004785060883,,,,,,,,,,,,,,,,,,,,,,,,,,,,,,,,,
,3768235208.49935,48.9999980926514,259.928985595703,,,5,,,,25.0300001353025,,,,,0.000671773583121774,8.78821379448607E-8,0.00434637094098012,0.000103636473495384,0.000671672433392683,8.78689054292208E-8,0.00067167243146011,5.36292076684293E-8,5.09520521121263E-8,6.96049755849812E-8,1.00015059383721,10.005763053894,2,20,10,5,2.19747806692835,0.193657968295322,0.0410455763339996,172.855895996094,48.9994964599609,49.0001983642578,259.928985595703,259.928985595703,,,14.9177598953247,0,1,,,,,,1,1,1,48.9998741149902,0,48.999859978171,,,,,,,,,,,,,,,,,,,,,,,,,,,,,,,,,
,3768235418.65735,49.0001049041748,259.928985595703,,,5,,,,25.0300001353025,,,,,0.000672156237360206,1.18842827629914E-7,0.00239386955823573,0.000119830929858379,0.000672055026729538,1.18824932746453E-7,0.000672055026142953,8.73822709233377E-8,2.80790676582335E-8,8.05214466491977E-8,1.00015059872576,10.005763053894,2,20,10,5,2.19873639160976,0.193693351551318,0.0410455763339996,172.855895996094,48.9995079040527,49.000316619873,259.928985595703,259.928985595703,,,14.8954524993896,0,1,,,,,,1,1,1,48.9999465942383,0,48.9999519796932,,,,,,,,,,,,,,,,,,,,,,,,,,,,,,,,,
,3768235623.7197,48.9996528625488,259.928985595703,,,5,,,,25.0300001353025,,,,,0.000672582269864243,1.49423766391219E-7,0.00323270777783868,0.00019817988405496,0.00067248100899419,1.49401269841326E-7,0.000672481007923811,6.75292846008616E-8,3.79423162673709E-8,1.33268657798811E-7,1.0001505780367,10.005763053894,2,20,10,5,2.20012717790605,0.193848331791969,0.0410455763339996,172.855895996094,48.9993591308594,49.0001106262207,259.928985595703,259.928985595703,,,14.8825454711914,0,1,,,,,,1,1,1,48.9997673034668,0,48.9995979732937,,,,,,,,,,,,,,,,,,,,,,,,,,,,,,,,,
,3768235828.74921,49.0007133483887,259.928985595703,,,5,,,,25.0300001353025,,,,,0.000672893786295928,1.20674017412871E-7,0.0016975288734562,0.000109007042474717,0.000672792445875419,1.20655843436653E-7,0.000672792445580135,9.58198996740373E-8,1.99331366508223E-8,7.33237981958631E-8,1.00015062657307,10.005763053894,2,20,10,5,2.20115139511991,0.193879136109102,0.0410455763339996,172.855895996094,48.9993133544922,49.0011901855469,259.928985595703,259.928985595703,,,14.8694629669189,0,1,,,,,,1,1,1,49.0002708435059,0,48.9999160766602,,,,,,,,,,,,,,,,,,,,,,,,,,,,,,,,,
,3768236036.32753,49.0000324249268,259.928985595703,,,5,,,,25.0300001353025,,,,,0.000673136620710427,1.03022854651462E-7,0.00930414624565845,0.000116425910218252,0.000673035264689786,1.03007342218679E-7,0.000673035255815864,6.68689462862884E-8,1.09292840709288E-7,7.83521319015472E-8,1.00015059540853,10.005763053894,2,20,10,5,2.20191998001313,0.194241434054331,0.0410455763339996,172.855895996094,48.9991874694824,49.0001678466797,259.928985595703,259.928985595703,,,14.8560352325439,0,1,,,,,,1,1,1,49.0000305175781,0,48.9995922761805,,,,,,,,,,,,,,,,,,,,,,,,,,,,,,,,,
,3768236241.74661,48.9995613098145,259.928985595703,,,5,,,,25.0300001353025,,,,,0.000673561155996285,1.29444137647558E-7,-0.000677989162071846,0.000142212438425262,0.000673459673312154,1.29424634832681E-7,0.000673459673265004,8.70622787049414E-8,-7.96914473400569E-9,9.57647937828716E-8,1.00015068858337,10.005763053894,2,20,10,5,2.20334252046812,0.193980074481384,0.0410455763339996,172.855895996094,48.9989776611328,48.9995918273926,259.928985595703,259.928985595703,,,14.8514089584351,0,1,,,,,,1,1,1,48.9996032714844,0,48.9993674334358,,,,,,,,,,,,,,,,,,,,,,,,,,,,,,,,,
,3768236449.41825,48.9995002746582,259.928985595703,,,5,,,,25.0300001353025,,,,,0.000673772376878341,1.29941002390365E-7,1.38611376367948E-5,0.000128657654227118,0.000673670941535265,1.29921439982333E-7,0.000673670941535245,9.67969533079897E-8,1.62976151505142E-10,8.6659854588926E-8,1.00015057105305,10.005763053894,2,20,10,5,2.20403111967371,0.194067517756053,0.0410455763339996,172.855895996094,48.9992866516113,49.000244140625,259.928985595703,259.928985595703,,,14.8395080566406,0,1,,,,,,1,1,1,48.9997138977051,0,48.9997130001292,,,,,,,,,,,,,,,,,,,,,,,,,,,,,,,,,
,3768236656.09353,49.0009441375732,259.928985595703,,,5,,,,25.0300001353025,,,,,0.000674155250286,1.07618640614854E-7,0.00273320818266676,9.45314299357197E-5,0.000674053712765308,1.07602431692735E-7,0.000674053711998362,8.67178989656582E-8,3.21547090945442E-8,6.37047039485435E-8,1.00015063713584,10.005763053894,2,20,10,5,2.20527434973688,0.194282458031798,0.0410455763339996,172.855895996094,48.9999885559082,49.0011253356934,259.928985595703,259.928985595703,,,14.8095207214355,0,1,,,,,,1,1,1,49.001033782959,0,49.0005777147081,,,,,,,,,,,,,,,,,,,,,,,,,,,,,,,,,
,3768236863.25374,48.9996700286865,259.928985595703,,,5,,,,25.0300001353025,,,,,0.000674504385060768,1.84472951259467E-7,-7.55780104340076E-5,0.000156178639740981,0.000674402834276186,1.84445177721815E-7,0.0006744028342756,1.51432275782978E-7,-8.8959474639833E-10,1.05300946985391E-7,1.00015057882236,10.005763053894,2,20,10,5,2.20642595363273,0.194274917702854,0.0410455763339996,172.855895996094,48.9987373352051,49.0003814697266,259.928985595703,259.928985595703,,,14.8149909973145,0,1,,,,,,1,1,1,48.9989700317383,0,48.9996874192182,,,,,,,,,,,,,,,,,,,,,,,,,,,,,,,,,
,3768237067.37898,48.9992256164551,259.928985595703,,,5,,,,25.0300001353025,,,,,0.000674790372758267,1.06607968590809E-7,-0.000146280306057456,8.47642359854189E-5,0.000674688792637502,1.06591920273049E-7,0.000674688792635303,8.99619975075659E-8,-1.72252972067353E-9,5.71723400950551E-8,1.00015055848248,10.005763053894,2,20,10,5,2.20736171092917,0.19435456655803,0.0410455763339996,172.855895996094,48.9985084533691,48.9997940063477,259.928985595703,259.928985595703,,,14.8200035095215,0,1,,,,,,1,1,1,48.9987754821777,0,48.9991986891803,,,,,,,,,,,,,,,,,,,,,,,,,,,,,,,,,
,3768237272.34863,49.0006866455078,259.928985595703,,,5,,,,25.0300001353025,,,,,0.000675060974591715,1.12159306450319E-7,-0.00302597247365899,0.000124693743746092,0.000674959308608993,1.12142414959711E-7,0.000674959307667684,7.41202484215056E-8,-3.56467492911047E-8,8.4155273197408E-8,1.00015062535093,10.005763053894,2,20,10,5,2.20825666873657,0.194321510939605,0.0410455763339996,172.855895996094,48.9995574951172,49.0007858276367,259.928985595703,259.928985595703,,,14.8094997406006,0,1,,,,,,1,1,1,49.0007858276367,0,49.0002237207749,,,,,,,,,,,,,,,,,,,,,,,,,,,,,,,,,
,3768237426.18416,49.0009689331055,259.928985595703,,,5,,,,25.0300001353025,,,,,0.000675302134532386,1.37588608822354E-7,0.00266737788640459,0.000149290185545072,0.000675200423508225,1.37567885833931E-7,0.000675200422776536,9.36281418744845E-8,3.14336360062099E-8,1.00790348059469E-7,1.00015063827068,10.005763053894,2,20,10,5,2.20902622303899,0.194610437646303,0.0410455763339996,172.855895996094,48.9996910095215,49.0014915466309,259.928985595703,259.928985595703,,,14.798321723938,0,1,,,,,,1,1,1,49.0007553100586,0,49.0004337535185,,,,,,,,,,,,,,,,,,,,,,,,,,,,,,,,,