File: Experimental_Data/Fig3C/Lifetime_260Oe_48K.dat
[Header]
; MPMS3 Data File (default extension .dat)
; Copyright (c) 2007, Quantum Design, Inc. All rights reserved.
TITLE,260Oe_48K
FILEOPENTIME,3768548508.23176,06/01/2019,11:01 am
BYAPP,SQUID AC,0.9.1.0
INFO,MPMS3 Measurement Release 1.1.16 Build 347, MultiVu Release 2.3.3.2,APPNAME
INFO,0,MOMENT_UNITS
INFO,,SAMPLE_MATERIAL
INFO,,SAMPLE_COMMENT
INFO,,SAMPLE_MASS
INFO,,SAMPLE_VOLUME
INFO,,SAMPLE_MOLECULAR_WEIGHT
INFO,,SAMPLE_SIZE
INFO,,SAMPLE_SHAPE
INFO,Quartz,SAMPLE_HOLDER
INFO,Standard,SAMPLE_HOLDER_DETAIL
INFO,66.2,SAMPLE_OFFSET
DATATYPE,COMMENT,1
DATATYPE,TIME,2
STARTUPAXIS,X,2
STARTUPAXIS,Y1,5
FIELDGROUP, VSM,2,3,4,5,6,8,9,10,11,14,15
FIELDGROUP, DC, 2,3,4,14,56,57,58,59,60,61,62,63,64,65,66,67,68,69
FIELDGROUP, AC, 2,3,4,11,16,17,18,19,20,21,22,23,24,25,26,27,28,29,30
STARTUPGROUP, All
[Data]
Comment,Time Stamp (sec),Temperature (K),Magnetic Field (Oe),Moment (emu),M. Std. Err. (emu),Transport Action,Averaging Time (sec),Frequency (Hz),Peak Amplitude (mm),Center Position (mm),Lockin Signal' (V),Lockin Signal (V),Range,M. Quad. Signal (emu),AC Moment (emu),AC M. Std Err. (emu),AC Phase (deg),AC Phase Std. Err. (deg),AC Susceptibility (emu/Oe),AC Suscept. Std Err. (emu/Oe),AC X' (emu/Oe),AC X' Std Err. (emu/Oe),AC X'' (emu/Oe),AC X'' Std Err. (emu/Oe),AC Drive (Oe),AC Frequency (Hz),AC Averaging Time (sec),AC Cycles,AC Range,AC Measure Type,AC Signal' (V),AC Signal'' (V),AC Trim Coil Ratio,AC Trim Coil Phase,Min. Temperature (K),Max. Temperature (K),Min. Field (Oe),Max. Field (Oe),Mass (grams),Motor Lag (deg),Pressure (Torr),Measure Count,Measurement Number,SQUID Status (code),Motor Status (code),Measure Status (code),Motor Current (amps),Motor Temp. (C),Temp. Status (code),Field Status (code),Chamber Status (code),Chamber Temp (K),Redirection State,Average Temp (K),Rotation Angle (deg),Rotator state,DC Moment Fixed Ctr (emu),DC Moment Err Fixed Ctr (emu),DC Moment Free Ctr (emu),DC Moment Err Free Ctr (emu),DC Fixed Fit,DC Free Fit,DC Calculated Center (mm),DC Calculated Center Err (mm),DC Scan Length (mm),DC Scan Time (s),DC Number of Points,DC Squid Drift,DC Min V (V),DC Max V (V),DC Scans per Measure,Map 01,Map 02,Map 03,Map 04,Map 05,Map 06,Map 07,Map 08,Map 09,Map 10,Map 11,Map 12,Map 13,Map 14,Map 15,Map 16
,3768548511.97284,47.9873828887939,259.576843261719,,,5,,,,25.0300001353025,,,,,0.000601993185120118,1.49698909009737E-7,0.0410571460425953,0.000198936889019219,0.000601902745762073,1.49676419264727E-7,0.000601902591226466,8.98131613696228E-8,4.3131286512333E-7,1.1973565270505E-7,1.00015025576587,10.005763053894,2,20,10,5,1.96910341423312,0.174806465436294,0.0410455763339996,172.855895996094,47.922233581543,47.9983291625977,259.576843261719,259.576843261719,,,41.6321640014648,0,1,,,,,,1,1,3,47.9817848205566,0,47.9575520683737,,,,,,,,,,,,,,,,,,,,,,,,,,,,,,,,,
,3768548718.18714,47.999340057373,259.576843261719,,,5,,,,25.0300001353025,,,,,0.000605654987169729,1.26801712082209E-7,0.00371208044162596,8.27464629434778E-5,0.000605563735790323,1.26782607424634E-7,0.0006055637345194,1.16474996341918E-7,3.92332789136652E-8,5.00739929757858E-8,1.00015068831572,10.005763053894,2,20,10,5,1.98119528549836,0.17457841872735,0.0410455763339996,172.855895996094,47.9977760314941,48.0005760192871,259.576843261719,259.576843261719,,,41.7814064025879,0,1,,,,,,1,1,3,47.9983978271484,0,47.9991092681885,,,,,,,,,,,,,,,,,,,,,,,,,,,,,,,,,
,3768548924.97273,48.0006237030029,259.576843261719,,,5,,,,25.0300001353025,,,,,0.000606341359448794,7.82464434971133E-8,-0.00239666999645749,7.06186246295093E-5,0.000606249969043261,7.82346498530029E-8,0.000606249968512874,6.54886754409212E-8,-2.53593043516196E-8,4.28006288109843E-8,1.00015074706837,10.005763053894,2,20,10,5,1.98345914385439,0.174564783905901,0.0410455763339996,172.855895996094,48.0004234313965,48.0010871887207,259.576843261719,259.576843261719,,,41.9057807922363,0,1,,,,,,1,1,3,48.0006523132324,0,48.0006621865665,,,,,,,,,,,,,,,,,,,,,,,,,,,,,,,,,
,3768549130.0722,47.9999942779541,259.576843261719,,,5,,,,25.0300001353025,,,,,0.0006069747260017,1.22520768087953E-7,-0.00145989185703943,0.000131513111957412,0.000606883187995201,1.22502290701029E-7,0.000606883187798199,9.294491762308E-8,-1.54633348522671E-8,7.9800084680646E-8,1.00015083299111,10.005763053894,2,20,10,5,1.98552815002134,0.174779594817348,0.0410455763339996,172.855895996094,47.9997100830078,48.0003852844238,259.576843261719,259.576843261719,,,41.9804000854492,0,1,,,,,,1,1,3,48.0000114440918,0,48.0000020195456,,,,,,,,,,,,,,,,,,,,,,,,,,,,,,,,,
,3768549335.08397,48.0001430511475,259.576843261719,,,5,,,,25.0300001353025,,,,,0.000607469254504997,1.05089932893772E-7,0.000670074990686054,0.000124176528180842,0.000607377637783298,1.05074083539976E-7,0.000607377637741762,7.31667244989767E-8,7.10329047671575E-9,7.54134832629856E-8,1.00015083980048,10.005763053894,2,20,10,5,1.98713934146765,0.174995866483007,0.0410455763339996,172.855895996094,47.9998474121094,48.0007553100586,259.576843261719,259.576843261719,,,42.0550231933594,0,1,,,,,,1,1,3,48.0001945495605,0,48.0002184973823,,,,,,,,,,,,,,,,,,,,,,,,,,,,,,,,,
,3768549540.63923,48.0000705718994,259.576843261719,,,5,,,,25.0300001353025,,,,,0.000608079357523661,1.14239620766558E-7,0.00344706470358691,0.000138217791081504,0.000607987650804649,1.14222391862679E-7,0.00060798764970433,7.73715570129084E-8,3.65781352108599E-8,8.40261683538508E-8,1.00015083648309,10.005763053894,2,20,10,5,1.98912660381992,0.175268029611494,0.0410455763339996,172.855895996094,47.9997291564941,48.0004539489746,259.576843261719,259.576843261719,,,42.0923347473145,0,1,,,,,,1,1,3,48.0001640319824,0,48.0002008325913,,,,,,,,,,,,,,,,,,,,,,,,,,,,,,,,,
,3768549749.53982,47.9999103546143,259.576843261719,,,5,,,,25.0300001353025,,,,,0.000608536454971322,7.39073617465071E-8,-0.000183324678329377,7.44129357475246E-5,0.000608444753574214,7.38962245200134E-8,0.0006084447535711,5.84084453561562E-8,-1.9467915381888E-9,4.52670466165966E-8,1.00015071441831,10.005763053894,2,20,10,5,1.99063295346634,0.17527365218833,0.0410455763339996,172.855895996094,47.9987525939941,48.0008125305176,259.576843261719,259.576843261719,,,42.1420860290527,0,1,,,,,,1,1,3,47.9993858337402,0,47.9995197969324,,,,,,,,,,,,,,,,,,,,,,,,,,,,,,,,,
,3768549954.62611,47.9998512268066,259.576843261719,,,5,,,,25.0300001353025,,,,,0.000609059149738746,9.34874039351579E-8,-0.00395257382461267,0.000101034791966306,0.000608967301366391,9.3473305688886E-8,0.000608967299917357,7.0376708067179E-8,-4.20098693825622E-8,6.15172970637934E-8,1.00015082644363,10.005763053894,2,20,10,5,1.99235431904849,0.175293130551393,0.0410455763339996,172.855895996094,47.9994697570801,48.0004501342773,259.576843261719,259.576843261719,,,42.1918334960937,0,1,,,,,,1,1,3,48.0000267028809,0,47.9999963972304,,,,,,,,,,,,,,,,,,,,,,,,,,,,,,,,,
,3768550162.38948,47.9999294281006,259.576843261719,,,5,,,,25.0300001353025,,,,,0.000609580302070501,8.59466567069128E-8,0.000562682199092279,9.1641095680361E-5,0.000609488372925244,8.59336953256772E-8,0.000609488372895852,6.53141998011251E-8,5.98557626596098E-9,5.58449218520809E-8,1.00015083002292,10.005763053894,2,20,10,5,1.99404528039631,0.175600266766529,0.0410455763339996,172.855895996094,47.9996871948242,48.0002021789551,259.576843261719,259.576843261719,,,42.2415809631348,0,1,,,,,,1,1,3,48.0000076293945,0,47.9999001446892,,,,,,,,,,,,,,,,,,,,,,,,,,,,,,,,,
,3768550367.39263,48.0005054473877,259.576843261719,,,5,,,,25.0300001353025,,,,,0.000610013604396124,6.48572474712003E-8,-0.002050138824921,6.94241415525393E-5,0.000609921593827874,6.48474648169252E-8,0.000609921593437424,4.91204517029374E-8,-2.18240147882426E-8,4.23364490443134E-8,1.00015085638741,10.005763053894,2,20,10,5,1.99547070067298,0.17563408778561,0.0410455763339996,172.855895996094,47.9995613098145,48.0007019042969,259.576843261719,259.576843261719,,,42.2913284301758,0,1,,,,,,1,1,3,48.000358581543,0,48.0001328786214,,,,,,,,,,,,,,,,,,,,,,,,,,,,,,,,,
,3768550575.2387,48.000509262085,259.576843261719,,,5,,,,25.0300001353025,,,,,0.000610708036593086,8.39757859772031E-8,0.00176318722657509,9.450356001601E-5,0.000610615991220903,8.39631292214187E-8,0.000610615990931775,6.09983436220058E-8,1.87907438391239E-8,5.76975661880496E-8,1.00015074183039,10.005763053894,2,20,10,5,1.99773061341818,0.175966989046314,0.0410455763339996,172.855895996094,47.9996719360352,48.0014991760254,259.576843261719,259.576843261719,,,42.3286399841309,0,1,,,,,,1,1,3,47.9998512268066,0,48.0001731448703,,,,,,,,,,,,,,,,,,,,,,,,,,,,,,,,,
,3768550780.55364,48.0001602172852,259.576843261719,,,5,,,,25.0300001353025,,,,,0.00061097831550483,9.75825868059335E-8,0.00125168933399511,9.104151970898E-5,0.000610886239154394,9.75678808037218E-8,0.000610886239008621,8.01743291000371E-8,1.33454819232982E-8,5.56018733307449E-8,1.00015072585456,10.005763053894,2,20,10,5,1.99861631355192,0.176027024076532,0.0410455763339996,172.855895996094,47.9993705749512,48.0005264282227,259.576843261719,259.576843261719,,,42.3659515380859,0,1,,,,,,1,1,3,47.9997940063477,0,47.9998541439281,,,,,,,,,,,,,,,,,,,,,,,,,,,,,,,,,
,3768550985.64043,47.9998531341553,259.576843261719,,,5,,,,25.0300001353025,,,,,0.000611370792895471,8.81723187701818E-8,-0.0042612087271543,0.000111068934493268,0.000611278595865422,8.81590220507153E-8,0.000611278594174866,5.6242215337417E-8,-4.54620865124689E-8,6.7888337605793E-8,1.00015082653093,10.005763053894,2,20,10,5,1.99991711395468,0.175947672060124,0.0410455763339996,172.855895996094,47.9992065429687,48.0001182556152,259.576843261719,259.576843261719,,,42.403263092041,0,1,,,,,,1,1,3,47.9997367858887,0,47.9997641619514,,,,,,,,,,,,,,,,,,,,,,,,,,,,,,,,,
,3768551190.91144,48.000509262085,259.576843261719,,,5,,,,25.0300001353025,,,,,0.000611628543621189,7.46842187944636E-8,0.000794525095188625,6.62956339288778E-5,0.000611536359511005,7.46729624554222E-8,0.000611536359452207,6.2716362575532E-8,8.4802229477526E-9,4.05303489642428E-8,1.00015074183039,10.005763053894,2,20,10,5,2.00074472894285,0.176198393042787,0.0410455763339996,172.855895996094,47.999698638916,48.0008544921875,259.576843261719,259.576843261719,,,42.4281387329102,0,1,,,,,,1,1,3,48.0003623962402,0,48.00012476304,,,,,,,,,,,,,,,,,,,,,,,,,,,,,,,,,
,3768551395.94121,47.9998455047607,259.576843261719,,,5,,,,25.0300001353025,,,,,0.000612124398945934,8.2199965509773E-8,-0.00153223153339788,9.49081546910401E-5,0.000612032088482928,8.21875694724833E-8,0.000612032088264077,5.81509353878323E-8,-1.63672590421604E-8,5.807981826172E-8,1.00015082618174,10.005763053894,2,20,10,5,2.00237391831447,0.176259926798156,0.0410455763339996,172.855895996094,47.9996490478516,48.000904083252,259.576843261719,259.576843261719,,,42.4778861999512,0,1,,,,,,1,1,3,47.9996490478516,0,48.0002388424344,,,,,,,,,,,,,,,,,,,,,,,,,,,,,,,,,
,3768551601.01416,48.000467300415,259.576843261719,,,5,,,,25.0300001353025,,,,,0.000612624684173313,1.20372123578505E-7,-0.00737769064104921,8.10150907456259E-5,0.000612532351101958,1.203539814302E-7,0.000612532346023935,1.09659420422666E-7,-7.88727236103824E-8,4.95973019292961E-8,1.0001507399098,10.005763053894,2,20,10,5,2.00402843238174,0.176199523942393,0.0410455763339996,172.855895996094,47.9996299743652,48.0007591247559,259.576843261719,259.576843261719,,,42.5151977539063,0,1,,,,,,1,1,3,48.0006332397461,0,48.0001216215246,,,,,,,,,,,,,,,,,,,,,,,,,,,,,,,,,
,3768551807.22009,48.0003490447998,259.576843261719,,,5,,,,25.0300001353025,,,,,0.000613011390468898,9.63884182938298E-8,-0.00293225603382385,7.78971973135024E-5,0.000612919002431227,9.63738914237605E-8,0.000612919001628567,8.3725905866891E-8,-3.1367675902365E-8,4.7727346824722E-8,1.00015073449722,10.005763053894,2,20,10,5,2.00527974699862,0.176466332880419,0.0410455763339996,172.855895996094,47.9999542236328,48.0007553100586,259.576843261719,259.576843261719,,,42.5400733947754,0,1,,,,,,1,1,3,48.0002174377441,0,48.0002604590522,,,,,,,,,,,,,,,,,,,,,,,,,,,,,,,,,
,3768552013.90564,48.0004272460937,259.576843261719,,,5,,,,25.0300001353025,,,,,0.000613410044972975,9.13578282268218E-8,0.00452399127837477,0.000113383157643948,0.000613317524302161,9.13440487205666E-8,0.000613317522390312,5.92348682511126E-8,4.84266581502882E-8,6.95339170472841E-8,1.00015085280813,10.005763053894,2,20,10,5,2.00656082703993,0.176842220029304,0.0410455763339996,172.855895996094,47.9998741149902,48.000602722168,259.576843261719,259.576843261719,,,42.5649452209473,0,1,,,,,,1,1,3,48.0002517700195,0,48.0002362868365,,,,,,,,,,,,,,,,,,,,,,,,,,,,,,,,,
,3768552221.66483,47.99977684021,259.576843261719,,,5,,,,25.0300001353025,,,,,0.00061384620835366,8.99762142703907E-8,0.00201915045890022,9.03869026866134E-5,0.000613753640164485,8.99626458307546E-8,0.000613753639783369,7.08307743941656E-8,2.16291837630088E-8,5.5464214080726E-8,1.00015082303895,10.005763053894,2,20,10,5,2.00799532062074,0.176880180800785,0.0410455763339996,172.855895996094,47.9994506835937,48.0000915527344,259.576843261719,259.576843261719,,,42.6146965026855,0,1,,,,,,1,1,3,47.999626159668,0,47.999766405891,,,,,,,,,,,,,,,,,,,,,,,,,,,,,,,,,
,3768552426.06374,48.0007514953613,259.576843261719,,,5,,,,25.0300001353025,,,,,0.000614144289720669,1.1423109052023E-7,0.00151751751054618,6.74252755668844E-5,0.000614051719632471,1.14213872445746E-7,0.000614051719417095,1.0645860861801E-7,1.62635755152185E-8,4.13687479889148E-8,1.00015075291745,10.005763053894,2,20,10,5,2.00897194508733,0.1769484804666,0.0410455763339996,172.855895996094,47.9997787475586,48.0009384155273,259.576843261719,259.576843261719,,,42.6395683288574,0,1,,,,,,1,1,3,48.0006065368652,0,48.0002318488227,,,,,,,,,,,,,,,,,,,,,,,,,,,,,,,,,
,3768552632.04012,48.0004482269287,259.576843261719,,,5,,,,25.0300001353025,,,,,0.000614600302174312,9.59619943549333E-8,-0.00346829858471676,0.000114161834628555,0.000614507671879744,9.59475313164789E-8,0.000614507670753882,6.54635565280378E-8,-3.71981340595926E-8,7.01459302627537E-8,1.0001507390368,10.005763053894,2,20,10,5,2.01047904210086,0.176904919713401,0.0410455763339996,172.855895996094,47.9997367858887,48.0009651184082,259.576843261719,259.576843261719,,,42.6893196105957,0,1,,,,,,1,1,3,48.0003395080566,0,48.0002257403205,,,,,,,,,,,,,,,,,,,,,,,,,,,,,,,,,
,3768552837.34783,48.0001659393311,259.576843261719,,,5,,,,25.0300001353025,,,,,0.000614840920423939,9.46807372946435E-8,-0.00716632417838703,0.000122096526184056,0.000614748191285413,9.46664577258758E-8,0.000614748186476854,5.76956472707843E-8,-7.68902151743286E-8,7.505298464665E-8,1.00015084084808,10.005763053894,2,20,10,5,2.01127757002219,0.176844367104477,0.0410455763339996,172.855895996094,47.9992294311523,48.000415802002,259.576843261719,259.576843261719,,,42.7141914367676,0,1,,,,,,1,1,3,47.9999732971191,0,47.9998242995318,,,,,,,,,,,,,,,,,,,,,,,,,,,,,,,,,
,3768553042.35254,48.001163482666,259.576843261719,,,5,,,,25.0300001353025,,,,,0.000615291436350842,1.38873269116141E-7,-0.00298072241632585,0.000186237093046759,0.000615198681754129,1.38852334103381E-7,0.000615198680921631,7.84510948450839E-8,-3.20047395454809E-8,1.14566122407824E-7,1.00015077177417,10.005763053894,2,20,10,5,2.01273837163387,0.177120979111369,0.0410455763339996,172.855895996094,48.0000495910645,48.0012588500977,259.576843261719,259.576843261719,,,42.7639389038086,0,1,,,,,,1,1,3,48.0010681152344,0,48.0007173874799,,,,,,,,,,,,,,,,,,,,,,,,,,,,,,,,,
,3768553249.16889,48.0009365081787,259.576843261719,,,5,,,,25.0300001353025,,,,,0.000615505603970043,8.21785230985667E-8,-0.00367173148408373,8.95089535161208E-5,0.000615412823480115,8.21661356181189E-8,0.000615412822216446,6.09738433870664E-8,-3.9437994514382E-8,5.50768941120014E-8,1.00015076138551,10.005763053894,2,20,10,5,2.01344109247444,0.177158347473192,0.0410455763339996,172.855895996094,48.0000457763672,48.0011138916016,259.576843261719,259.576843261719,,,42.8012504577637,0,1,,,,,,1,1,3,48.0011138916016,0,48.0005310906304,,,,,,,,,,,,,,,,,,,,,,,,,,,,,,,,,
,3768553455.25106,47.9995994567871,259.576843261719,,,5,,,,25.0300001353025,,,,,0.000615980612431001,1.21081378827415E-7,0.00125169845244155,9.98700141626738E-5,0.000615887727372618,1.21063120702541E-7,0.000615887727225649,1.04286268738477E-7,1.34548429521359E-8,6.14870177097914E-8,1.00015081492008,10.005763053894,2,20,10,5,2.01497969645586,0.177468222150295,0.0410455763339996,172.855895996094,47.998664855957,48.0000801086426,259.576843261719,259.576843261719,,,42.8136863708496,0,1,,,,,,1,1,3,47.9993209838867,0,47.9994396633572,,,,,,,,,,,,,,,,,,,,,,,,,,,,,,,,,
,3768553661.1248,48.0008583068848,259.576843261719,,,5,,,,25.0300001353025,,,,,0.000616320449945001,1.11255180508736E-7,-0.000313932506191605,0.000137940472773488,0.000616227548831604,1.11238410450009E-7,0.000616227548822354,7.1761846009711E-8,-3.37640678653959E-9,8.49954199749795E-8,1.00015075780623,10.005763053894,2,20,10,5,2.01609621583485,0.177511035937929,0.0410455763339996,172.855895996094,47.9994163513184,48.001220703125,259.576843261719,259.576843261719,,,42.8634376525879,0,1,,,,,,1,1,3,48.0006256103516,0,48.0002755059136,,,,,,,,,,,,,,,,,,,,,,,,,,,,,,,,,
,3768553868.06915,48.0005226135254,259.576843261719,,,5,,,,25.0300001353025,,,,,0.000616413248758545,6.92338931681389E-8,-0.00281509798791557,6.926327415029E-5,0.000616320343125282,6.92234582550332E-8,0.000616320342381376,5.45004422750332E-8,-3.02815001713906E-8,4.26800769049459E-8,1.00015074244149,10.005763053894,2,20,10,5,2.01640752581735,0.177449740840026,0.0410455763339996,172.855895996094,47.9998207092285,48.0006103515625,259.576843261719,259.576843261719,,,42.8883094787598,0,1,,,,,,1,1,3,48.0005111694336,0,48.0002239451689,,,,,,,,,,,,,,,,,,,,,,,,,,,,,,,,,
,3768554073.74598,48.0000534057617,259.576843261719,,,5,,,,25.0300001353025,,,,,0.000616566419461226,9.43240186996068E-8,-0.00135635518537391,8.50853208272514E-5,0.000616473433260994,9.43097934161455E-8,0.000616473433088257,7.83869279433491E-8,-1.45936916274922E-8,5.24387896675756E-8,1.0001508356974,10.005763053894,2,20,10,5,2.01690405717423,0.17754518668576,0.0410455763339996,172.855895996094,47.999584197998,48.0002059936523,259.576843261719,259.576843261719,,,42.9131851196289,0,1,,,,,,1,1,3,48.000072479248,0,47.9998711480035,,,,,,,,,,,,,,,,,,,,,,,,,,,,,,,,,
,3768554282.54932,47.9997634887695,259.576843261719,,,5,,,,25.0300001353025,,,,,0.00061713319645279,1.58447736271641E-7,0.00328511535168108,0.000203863617082625,0.000617040132961855,1.584238424031E-7,0.000617040131947618,9.63153381304696E-8,3.53786619103918E-8,1.25783422924388E-7,1.00015082242785,10.005763053894,2,20,10,5,2.01874368792395,0.177871933542403,0.0410455763339996,172.855895996094,47.9994506835937,47.9999847412109,259.576843261719,259.576843261719,,,42.950496673584,0,1,,,,,,1,1,3,47.9995498657227,0,47.9996948242188,,,,,,,,,,,,,,,,,,,,,,,,,,,,,,,,,
,3768554487.58335,48.0002040863037,259.576843261719,,,5,,,,25.0300001353025,,,,,0.000617336188362325,9.71560219347034E-8,-0.00366667924255459,9.68018716328048E-5,0.000617243081814693,9.71413688786304E-8,0.000617243080550752,7.66011710140555E-8,-3.95008570158083E-8,5.97386486865042E-8,1.00015084259407,10.005763053894,2,20,10,5,2.01942928164425,0.177685418500131,0.0410455763339996,172.855895996094,47.9996452331543,48.000301361084,259.576843261719,259.576843261719,,,42.9753684997559,0,1,,,,,,1,1,3,48.0001792907715,0,47.9999892290901,,,,,,,,,,,,,,,,,,,,,,,,,,,,,,,,,
,3768554694.07715,47.9995250701904,259.576843261719,,,5,,,,25.0300001353025,,,,,0.000617740194007668,9.76092148163449E-8,-0.00220991445071839,0.000116060911849696,0.000617647045720723,9.75944964424421E-8,0.000617647045261297,6.62348346896855E-8,-2.38228215593377E-8,7.16772795904244E-8,1.0001508115154,10.005763053894,2,20,10,5,2.02074634267283,0.177853084009714,0.0410455763339996,172.855895996094,47.99853515625,48.0003395080566,259.576843261719,259.576843261719,,,43.0375556945801,0,1,,,,,,1,1,3,47.9991760253906,0,47.9998226165771,,,,,,,,,,,,,,,,,,,,,,,,,,,,,,,,,
,3768554902.92169,47.9996032714844,259.576843261719,,,5,,,,25.0300001353025,,,,,0.000617993579711852,1.07109150123099E-7,0.000429026315148739,0.00012495420715247,0.000617900391005879,1.07092998882333E-7,0.000617900390988556,7.42224386916169E-8,4.62678979381389E-9,7.72006476934007E-8,1.00015081509468,10.005763053894,2,20,10,5,2.02156701863622,0.17801914654751,0.0410455763339996,172.855895996094,47.998664855957,47.999942779541,259.576843261719,259.576843261719,,,43.0375556945801,0,1,,,,,,1,1,3,47.9990425109863,0,47.9994144439697,,,,,,,,,,,,,,,,,,,,,,,,,,,,,,,,,
,3768555108.59949,47.9998588562012,259.576843261719,,,5,,,,25.0300001353025,,,,,0.000618223891456396,1.01006402197784E-7,-0.00189405349402083,9.90946864769551E-5,0.000618130660791276,1.00991170023505E-7,0.000618130660453531,8.03042534876715E-8,-2.04338355733962E-8,6.12408629470906E-8,1.00015082679283,10.005763053894,2,20,10,5,2.02232762862552,0.178003489886728,0.0410455763339996,172.855895996094,47.9993553161621,48.0004920959473,259.576843261719,259.576843261719,,,43.062427520752,0,1,,,,,,1,1,3,48.0001373291016,0,47.9999580383301,,,,,,,,,,,,,,,,,,,,,,,,,,,,,,,,,
,3768555313.72533,47.9999103546143,259.576843261719,,,5,,,,25.0300001353025,,,,,0.000618453919381806,9.82652364813759E-8,-0.00101690826139222,0.000100474407768432,0.000618360652570232,9.82504174544316E-8,0.000618360652472839,7.61214476706117E-8,-1.0974910568098E-8,6.21181916551053E-8,1.00015082914992,10.005763053894,2,20,10,5,2.02307736718884,0.178100693744766,0.0410455763339996,172.855895996094,47.999382019043,48.0003929138184,259.576843261719,259.576843261719,,,43.1121788024902,0,1,,,,,,1,1,3,47.9998588562012,0,47.9999726239373,,,,,,,,,,,,,,,,,,,,,,,,,,,,,,,,,
,3768555518.77709,48.0017700195313,259.576843261719,,,5,,,,25.0300001353025,,,,,0.000618838482001237,1.01147661288298E-7,0.00281206589801464,0.000109134208884107,0.000618745175516207,1.01132410567765E-7,0.000618745174770982,7.52950951738663E-8,3.03678948382993E-8,6.75160211357679E-8,1.00015079953545,10.005763053894,2,20,10,5,2.02432342933422,0.178346714346422,0.0410455763339996,172.855895996094,47.9999923706055,48.0019683837891,259.576843261719,259.576843261719,,,43.1370506286621,0,1,,,,,,1,1,3,48.001636505127,0,48.0008376626407,,,,,,,,,,,,,,,,,,,,,,,,,,,,,,,,,
,3768555723.94925,48.0005378723145,259.576843261719,,,5,,,,25.0300001353025,,,,,0.000619167005076159,9.83058189517922E-8,0.00232758858408655,0.000103586807923439,0.000619073683965216,9.82910022574892E-8,0.000619073683454383,7.44989473500506E-8,2.51493015952509E-8,6.41172985123058E-8,1.00015074313989,10.005763053894,2,20,10,5,2.02539959120063,0.178424272025416,0.0410455763339996,172.855895996094,47.9993324279785,48.0007667541504,259.576843261719,259.576843261719,,,43.1494903564453,0,1,,,,,,1,1,3,48.0003967285156,0,48.0001054651597,,,,,,,,,,,,,,,,,,,,,,,,,,,,,,,,,
,3768555929.18158,48.0001602172852,259.576843261719,,,5,,,,25.0300001353025,,,,,0.000619292216696238,8.62240834912707E-8,-0.00182340514429491,0.000101710411780627,0.000619198816383815,8.62110793615249E-8,0.000619198816070254,5.88798563755746E-8,-1.97056452768426E-8,6.29723170756075E-8,1.00015084058618,10.005763053894,2,20,10,5,2.02582210324017,0.178313588223268,0.0410455763339996,172.855895996094,47.9996337890625,48.0004081726074,259.576843261719,259.576843261719,,,43.1992378234863,0,1,,,,,,1,1,3,48.0000152587891,0,47.9999966340906,,,,,,,,,,,,,,,,,,,,,,,,,,,,,,,,,
,3768556135.32676,47.9999389648438,259.576843261719,,,5,,,,25.0300001353025,,,,,0.000619648208155096,8.89392920718903E-8,0.000634127176341259,9.70752256360594E-5,0.000619554831497753,8.89258895417276E-8,0.000619554831459808,6.55104673556259E-8,6.85698945397067E-9,6.01347860862164E-8,1.0001507157278,10.005763053894,2,20,10,5,2.02697896410075,0.178503031980072,0.0410455763339996,172.855895996094,47.9993438720703,48.0004119873047,259.576843261719,259.576843261719,,,43.1992378234863,0,1,,,,,,1,1,3,47.9996910095215,0,47.9998457166884,,,,,,,,,,,,,,,,,,,,,,,,,,,,,,,,,
,3768556341.89162,48.00124168396,259.576843261719,,,5,,,,25.0300001353025,,,,,0.000619845011919059,8.21619850409984E-8,0.00212880873655319,7.93127327494799E-5,0.000619751568657243,8.21495989061874E-8,0.000619751568229468,6.58292205148956E-8,2.30266969881314E-8,4.91433650338345E-8,1.00015077535345,10.005763053894,2,20,10,5,2.02761808570351,0.178612615254578,0.0410455763339996,172.855895996094,48.0002365112305,48.0015144348145,259.576843261719,259.576843261719,,,43.2614250183105,0,1,,,,,,1,1,3,48.0009727478027,0,48.0008544921875,,,,,,,,,,,,,,,,,,,,,,,,,,,,,,,,,
,3768556548.19916,48.0007762908936,259.576843261719,,,5,,,,25.0300001353025,,,,,0.000620169748023492,1.06179267597616E-7,0.00140518852775617,0.000114220082795221,0.000620076269013177,1.06163263055501E-7,0.000620076268826695,7.90945908935285E-8,1.52074736894865E-8,7.08144343617661E-8,1.00015075405234,10.005763053894,2,20,10,5,2.02868260926873,0.178680569822464,0.0410455763339996,172.855895996094,47.9996566772461,48.0012054443359,259.576843261719,259.576843261719,,,43.2862968444824,0,1,,,,,,1,1,3,48.0007286071777,0,48.0002266378964,,,,,,,,,,,,,,,,,,,,,,,,,,,,,,,,,
,3768556754.70339,47.9998893737793,259.576843261719,,,5,,,,25.0300001353025,,,,,0.000620446042145614,1.09349523402233E-7,-0.00329390522064088,0.000138903591966472,0.000620352475504803,1.09333032898814E-7,0.000620352474479657,6.73030303225191E-8,-3.56637482541034E-8,8.61627192715E-8,1.00015082818963,10.005763053894,2,20,10,5,2.02960106911436,0.1785937201244,0.0410455763339996,172.855895996094,47.9995803833008,48.0005683898926,259.576843261719,259.576843261719,,,43.3236083984375,0,1,,,,,,1,1,3,48.0001983642578,0,47.9999780093922,,,,,,,,,,,,,,,,,,,,,,,,,,,,,,,,,
,3768556959.76179,48.0004768371582,259.576843261719,,,5,,,,25.0300001353025,,,,,0.00062063673562516,1.16854570380815E-7,-0.00436302517261744,0.000109872804523285,0.000620543123543907,1.16836944934383E-7,0.000620543121744737,9.48913257134433E-8,-4.7253834210981E-8,6.81652991333952E-8,1.00015085507792,10.005763053894,2,20,10,5,2.03022819831842,0.178610725756127,0.0410455763339996,172.855895996094,47.9999504089355,48.0005187988281,259.576843261719,259.576843261719,,,43.3484840393066,0,1,,,,,,1,1,3,48.0006103515625,0,48.0002048716826,,,,,,,,,,,,,,,,,,,,,,,,,,,,,,,,,
,3768557166.1818,48.0011119842529,259.576843261719,,,5,,,,25.0300001353025,,,,,0.000621043128985596,1.23958006711082E-7,0.00422412532644145,0.000125716660585832,0.000620949508790122,1.23939320451985E-7,0.00062094950710258,9.62772393149288E-8,4.5779437271583E-8,7.80490124472808E-8,1.00015076941708,10.005763053894,2,20,10,5,2.03153078388473,0.179032153643274,0.0410455763339996,172.855895996094,48.0003204345703,48.0012359619141,259.576843261719,259.576843261719,,,43.3609199523926,0,1,,,,,,1,1,3,48.0011901855469,0,48.0007791519165,,,,,,,,,,,,,,,,,,,,,,,,,,,,,,,,,
,3768557372.77175,47.9989242553711,259.576843261719,,,5,,,,25.0300001353025,,,,,0.000621257633662835,8.42347408068272E-8,-0.00541545460289061,7.34241494824758E-5,0.000621163972064527,8.42220414691781E-8,0.000621163969289924,7.0812317308962E-8,-5.87108739115768E-8,4.55957014045275E-8,1.00015078401601,10.005763053894,2,20,10,5,2.03226256457028,0.178752087319891,0.0410455763339996,172.855895996094,47.9982795715332,48.0020065307617,259.576843261719,259.576843261719,,,43.3982315063477,0,1,,,,,,1,1,3,47.9993629455566,0,48.0001467536478,,,,,,,,,,,,,,,,,,,,,,,,,,,,,,,,,
,3768557579.27547,48.0005760192871,259.576843261719,,,5,,,,25.0300001353025,,,,,0.000621462901781493,7.93896011235337E-8,-0.0020645885172268,7.35134857338813E-5,0.000621369233547292,7.93776353509513E-8,0.000621369233143887,6.49248990034675E-8,-2.23903365163086E-8,4.56680028389477E-8,1.00015074488588,10.005763053894,2,20,10,5,2.03292357852648,0.17893003726801,0.0410455763339996,172.855895996094,48.0000381469727,48.0007057189941,259.576843261719,259.576843261719,,,43.4231071472168,0,1,,,,,,1,1,3,48.0004119873047,0,48.0003372641171,,,,,,,,,,,,,,,,,,,,,,,,,,,,,,,,,
,3768557788.58444,48.0008430480957,259.576843261719,,,5,,,,25.0300001353025,,,,,0.000621747872212057,1.69560461089923E-7,-0.00421148904931545,0.000237646212540137,0.000621654153429816,1.69534902498346E-7,0.000621654151750452,8.31784322264011E-8,-4.56942846318342E-8,1.47727558625606E-7,1.00015075710783,10.005763053894,2,20,10,5,2.03386247749187,0.178935873983485,0.0410455763339996,172.855895996094,48.0000801086426,48.0012702941895,259.576843261719,259.576843261719,,,43.4604148864746,0,1,,,,,,1,1,3,48.0008087158203,0,48.0005620320638,,,,,,,,,,,,,,,,,,,,,,,,,,,,,,,,,
,3768557993.75166,48.0001583099365,259.576843261719,,,5,,,,25.0300001353025,,,,,0.00062195399226188,1.03382372043717E-7,-0.00268238231703322,9.53761189799452E-5,0.000621860190560504,1.03366780147032E-7,0.000621860189879015,8.46678560949978E-8,-2.91132574230218E-8,5.92962509965137E-8,1.00015084049888,10.005763053894,2,20,10,5,2.03453195972455,0.179049494202746,0.0410455763339996,172.855895996094,47.9992942810059,48.0002288818359,259.576843261719,259.576843261719,,,43.485294342041,0,1,,,,,,1,1,3,48.0002098083496,0,47.9998512268066,,,,,,,,,,,,,,,,,,,,,,,,,,,,,,,,,
,3768558198.70761,48.0003185272217,259.576843261719,,,5,,,,25.0300001353025,,,,,0.000622172340398678,1.26264069595942E-7,0.00173852856535017,9.63668307599682E-5,0.000622078501205408,1.26245025807492E-7,0.000622078500919034,1.11117613787107E-7,1.8875757573434E-8,5.99223034219622E-8,1.00015084783205,10.005763053894,2,20,10,5,2.0352323926047,0.179269389501365,0.0410455763339996,172.855895996094,48.000114440918,48.0008659362793,259.576843261719,259.576843261719,,,43.5226020812988,0,1,,,,,,1,1,3,48.0005111694336,0,48.0003915674546,,,,,,,,,,,,,,,,,,,,,,,,,,,,,,,,,
,3768558405.16321,48.0005931854248,259.576843261719,,,5,,,,25.0300001353025,,,,,0.00062247053521489,1.65080047024145E-7,-8.60200519134935E-5,0.000198450946120964,0.000622376714619071,1.65055165672349E-7,0.000622376714618369,1.09503736950074E-7,-9.34394780143236E-10,1.23499551857874E-7,1.00015074567158,10.005763053894,2,20,10,5,2.03621354949761,0.179290466778046,0.0410455763339996,172.855895996094,47.999439239502,48.0008392333984,259.576843261719,259.576843261719,,,43.547477722168,0,1,,,,,,1,1,3,48.000789642334,0,48.0000904307646,,,,,,,,,,,,,,,,,,,,,,,,,,,,,,,,,
,3768558611.67038,47.9998760223389,259.576843261719,,,5,,,,25.0300001353025,,,,,0.000622651707598754,1.28273649469923E-7,-0.00092215201039636,0.00010927560760532,0.000622557808711971,1.28254305183636E-7,0.000622557808631339,1.08737660792523E-7,-1.0019811925865E-8,6.80094693664595E-8,1.00015082757853,10.005763053894,2,20,10,5,2.03680881369565,0.179312930388328,0.0410455763339996,172.855895996094,47.9991569519043,48.0002136230469,259.576843261719,259.576843261719,,,43.5723533630371,0,1,,,,,,1,1,3,47.999755859375,0,47.9998218311983,,,,,,,,,,,,,,,,,,,,,,,,,,,,,,,,,
,3768558817.47314,48.0007438659668,259.576843261719,,,5,,,,25.0300001353025,,,,,0.000622858252936521,9.67456703402655E-8,-0.00418587279704052,8.02655901160756E-5,0.00062276436960839,9.67310878803382E-8,0.00062276436794643,8.28242128181175E-8,-4.54974599096905E-8,4.99705226465852E-8,1.00015075256825,10.005763053894,2,20,10,5,2.03749467613774,0.179256348328527,0.0410455763339996,172.855895996094,47.999755859375,48.0015106201172,259.576843261719,259.576843261719,,,43.597225189209,0,1,,,,,,1,1,3,48.0004348754883,0,48.0002799563938,,,,,,,,,,,,,,,,,,,,,,,,,,,,,,,,,
,3768559024.16099,48.0012245178223,259.576843261719,,,5,,,,25.0300001353025,,,,,0.000622790371235701,7.35518451410593E-8,-0.000736570074132636,8.78078846130959E-5,0.000622696484442417,7.35407570652004E-8,0.000622696484390962,4.91851621724721E-8,-8.00512009074812E-9,5.46723218072037E-8,1.00015077456775,10.005763053894,2,20,10,5,2.03726182761593,0.179359456577211,0.0410455763339996,172.855895996094,47.999626159668,48.0017852783203,259.576843261719,259.576843261719,,,43.6469764709473,0,1,,,,,,1,1,3,48.0010833740234,0,48.0004505830653,,,,,,,,,,,,,,,,,,,,,,,,,,,,,,,,,
,3768559229.69387,47.9998893737793,259.576843261719,,,5,,,,25.0300001353025,,,,,0.000623412530560537,9.68827626353356E-8,-0.00241369766522936,0.000103459879532734,0.000623318516557123,9.68681521873086E-8,0.000623318516004028,7.22905988768007E-8,-2.62585213160358E-8,6.44787424056726E-8,1.00015082818963,10.005763053894,2,20,10,5,2.03930227925991,0.179478945461124,0.0410455763339996,172.855895996094,47.9991683959961,48.0001449584961,259.576843261719,259.576843261719,,,43.6594123840332,0,1,,,,,,1,1,3,47.9999961853027,0,47.9996887655819,,,,,,,,,,,,,,,,,,,,,,,,,,,,,,,,,
,3768559434.74239,48.0004005432129,259.576843261719,,,5,,,,25.0300001353025,,,,,0.00062364229059221,8.49445151718641E-8,-0.00158554669950917,9.85197235737448E-5,0.000623548227353209,8.49317030897571E-8,0.000623548227114454,5.86545708570324E-8,-1.72554565474189E-8,6.14250397419816E-8,1.00015085158593,10.005763053894,2,20,10,5,2.04005127333612,0.179574577683689,0.0410455763339996,172.855895996094,47.9996719360352,48.0008087158203,259.576843261719,259.576843261719,,,43.6718482971191,0,1,,,,,,1,1,3,48.0004920959473,0,48.0001790663775,,,,,,,,,,,,,,,,,,,,,,,,,,,,,,,,,
,3768559640.43451,47.9997806549072,259.576843261719,,,5,,,,25.0300001353025,,,,,0.000623905663515791,9.5526971985549E-8,-0.0032242198871808,0.000120231421300723,0.000623811578248911,9.55125664733393E-8,0.000623811577261205,5.91459799223032E-8,-3.51039066485344E-8,7.4996022650235E-8,1.00015082321355,10.005763053894,2,20,10,5,2.04091795270972,0.179592046383788,0.0410455763339996,172.855895996094,47.9992179870605,48.0000419616699,259.576843261719,259.576843261719,,,43.696720123291,0,1,,,,,,1,1,3,47.9998626708984,0,47.9996809117934,,,,,,,,,,,,,,,,,,,,,,,,,,,,,,,,,
,3768559847.25568,47.9998226165771,259.576843261719,,,5,,,,25.0300001353025,,,,,0.000623995887632304,1.2311140253662E-7,-0.00417875756656017,0.000175470250459771,0.000623901787561505,1.23092837042961E-7,0.000623901785902165,5.62820318904082E-8,-4.55030778079639E-8,1.0947227693609E-7,1.00015082513414,10.005763053894,2,20,10,5,2.04121608551536,0.179584012567396,0.0410455763339996,172.855895996094,47.9991836547852,48.0002937316895,259.576843261719,259.576843261719,,,43.7215957641602,0,1,,,,,,1,1,3,47.9995269775391,0,47.999664094713,,,,,,,,,,,,,,,,,,,,,,,,,,,,,,,,,
,3768560055.83354,48.0013656616211,259.576843261719,,,5,,,,25.0300001353025,,,,,0.000624375515944908,7.46620208296776E-8,0.000251889839028685,8.29750408294429E-5,0.000624281386155787,7.46507649106088E-8,0.000624281386149754,5.37607526912664E-8,2.74453265499205E-9,5.17930320777561E-8,1.00015078102793,10.005763053894,2,20,10,5,2.04244402499955,0.17985120345261,0.0410455763339996,172.855895996094,47.9995956420898,48.0016098022461,259.576843261719,259.576843261719,,,43.7340354919434,0,1,,,,,,1,1,3,48.0011367797852,0,48.0006461673313,,,,,,,,,,,,,,,,,,,,,,,,,,,,,,,,,
,3768560260.91606,47.9996166229248,259.576843261719,,,5,,,,25.0300001353025,,,,,0.000624422187015225,1.15071875900113E-7,0.00010071532006517,9.30986469611206E-5,0.000624328028542963,1.15054523870892E-7,0.000624328028541998,9.93052264309847E-8,1.09745251316411E-9,5.81034892811834E-8,1.00015081570578,10.005763053894,2,20,10,5,2.0425971684464,0.179859263657406,0.0410455763339996,172.855895996094,47.9992294311523,48.0000228881836,259.576843261719,259.576843261719,,,43.7589073181152,0,1,,,,,,1,1,3,47.9996299743652,0,47.9995942957261,,,,,,,,,,,,,,,,,,,,,,,,,,,,,,,,,
,3768560468.68776,47.999885559082,259.576843261719,,,5,,,,25.0300001353025,,,,,0.000624757015926006,7.44916324982635E-8,-0.000236755489705587,7.7705402887566E-5,0.000624662799275929,7.44803987675589E-8,0.000624662799270596,5.64977976168283E-8,-2.58120839265737E-9,4.85317284363796E-8,1.00015082801503,10.005763053894,2,20,10,5,2.04369351408321,0.17994366852365,0.0410455763339996,172.855895996094,47.9995727539063,48.0004920959473,259.576843261719,259.576843261719,,,43.7962188720703,0,1,,,,,,1,1,3,48.0002136230469,0,48.0000085269704,,,,,,,,,,,,,,,,,,,,,,,,,,,,,,,,,
,3768560673.87167,48.0007057189941,259.576843261719,,,5,,,,25.0300001353025,,,,,0.000625091788152119,1.30100801573689E-7,0.000288848955787735,0.000133865603728497,0.000624997569254647,1.30081191727076E-7,0.000624997569246704,9.96171425230683E-8,3.15084107036352E-9,8.36513081587797E-8,1.00015075082225,10.005763053894,2,20,10,5,2.04478696321127,0.180058846531052,0.0410455763339996,172.855895996094,47.9995994567871,48.0008735656738,259.576843261719,259.576843261719,,,43.8210945129395,0,1,,,,,,1,1,3,48.0006217956543,0,48.0002427942613,,,,,,,,,,,,,,,,,,,,,,,,,,,,,,,,,
,3768560880.3182,48.0008716583252,259.576843261719,,,5,,,,25.0300001353025,,,,,0.000625195400065445,7.13845342068972E-8,-0.000774648289302071,9.13316599776927E-5,0.000625101160803775,7.13737740096891E-8,0.000625101160746643,4.28394287875895E-8,-8.45146970610751E-9,5.70876427744151E-8,1.00015075841732,10.005763053894,2,20,10,5,2.04512923873049,0.180050730742016,0.0410455763339996,172.855895996094,47.9995651245117,48.0012474060059,259.576843261719,259.576843261719,,,43.8459663391113,0,1,,,,,,1,1,3,48.0007972717285,0,48.0002957512351,,,,,,,,,,,,,,,,,,,,,,,,,,,,,,,,,
,3768561088.1752,47.9996528625488,259.576843261719,,,5,,,,25.0300001353025,,,,,0.000625386927632745,1.00401687518444E-7,-1.17418279454995E-5,7.6381658317513E-5,0.000625292622647373,1.00386547483924E-7,0.00062529262264736,8.83076958917584E-8,-1.28143441857513E-10,4.77410699715756E-8,1.00015081736447,10.005763053894,2,20,10,5,2.04575336186198,0.180133133841359,0.0410455763339996,172.855895996094,47.999095916748,47.9998054504395,259.576843261719,259.576843261719,,,43.8832817077637,0,1,,,,,,1,1,3,47.9995002746582,0,47.9994524787454,,,,,,,,,,,,,,,,,,,,,,,,,,,,,,,,,
,3768561296.92427,48.0030994415283,259.576843261719,,,5,,,,25.0300001353025,,,,,0.000625675037123541,8.95040945188456E-8,0.00354239671889101,9.63050515838551E-5,0.000625580733548195,8.9490604199398E-8,0.00062558073235255,6.6181471822134E-8,3.86774585378448E-8,6.02377043671935E-8,1.00015074565166,10.005763053894,2,20,10,5,2.04668463809128,0.180343065641229,0.0410455763339996,172.855895996094,48.0014419555664,48.0035552978516,259.576843261719,259.576843261719,,,43.8957176208496,0,1,,,,,,1,1,3,48.0027198791504,0,48.0024077097575,,,,,,,,,,,,,,,,,,,,,,,,,,,,,,,,,
,3768561505.03294,48.0009136199951,259.576843261719,,,5,,,,25.0300001353025,,,,,0.000625888186981522,8.31337306756667E-8,-0.00367599782018324,7.88845786870933E-5,0.000625793842090424,8.3121199295573E-8,0.000625793840802451,6.68822851277134E-8,-4.01498472903235E-8,4.93547739173184E-8,1.00015076033791,10.005763053894,2,20,10,5,2.04740459722444,0.180146570124066,0.0410455763339996,172.855895996094,47.9995307922363,48.0009422302246,259.576843261719,259.576843261719,,,43.9330253601074,0,1,,,,,,1,1,3,48.0009613037109,0,48.0002100327436,,,,,,,,,,,,,,,,,,,,,,,,,,,,,,,,,
,3768561710.19646,48.0006637573242,259.576843261719,,,5,,,,25.0300001353025,,,,,0.000626022167464011,1.20930862962311E-7,0.00484455467113154,0.000132362735168249,0.000625927809534203,1.2091263551531E-7,0.000625927807296736,8.80779088459589E-8,5.29243430428328E-8,8.28380794114709E-8,1.00015074890166,10.005763053894,2,20,10,5,2.04781605558272,0.180489670818586,0.0410455763339996,172.855895996094,47.999382019043,48.0009078979492,259.576843261719,259.576843261719,,,43.9703407287598,0,1,,,,,,1,1,3,48.0005836486816,0,48.0002110799154,,,,,,,,,,,,,,,,,,,,,,,,,,,,,,,,,
,3768561915.23334,48.0000686645508,259.576843261719,,,5,,,,25.0300001353025,,,,,0.000626045501576767,1.40702849627927E-7,-0.00314807014389018,0.000149875141230339,0.000625951085371107,1.40681629717946E-7,0.000625951084426276,1.04846500931426E-7,-3.43923747813054E-8,9.38004913768251E-8,1.00015083639579,10.005763053894,2,20,10,5,2.04791754386778,0.180210721854857,0.0410455763339996,172.855895996094,47.9995803833008,48.0004081726074,259.576843261719,259.576843261719,,,43.9703407287598,0,1,,,,,,1,1,3,48.0002326965332,0,47.999932233025,,,,,,,,,,,,,,,,,,,,,,,,,,,,,,,,,
,3768562127.80783,48.000057220459,259.576843261719,,,5,,,,25.0300001353025,,,,,0.000626303176779966,1.21046119649064E-7,-0.00169532145954054,0.000106354830637755,0.000626208722041325,1.21027864305616E-7,0.000626208721767201,1.01067224435916E-7,-1.85288531458204E-8,6.65819801688026E-8,1.000150835872,10.005763053894,2,20,10,5,2.04875587815418,0.180336841685624,0.0410455763339996,172.855895996094,47.9997329711914,48.0002784729004,259.576843261719,259.576843261719,,,44.0076484680176,0,1,,,,,,1,1,3,48.0002822875977,0,47.9999248280245,,,,,,,,,,,,,,,,,,,,,,,,,,,,,,,,,
,3768562283.04669,48.0003890991211,259.576843261719,,,5,,,,25.0300001353025,,,,,0.000626678130312478,8.90426126155683E-8,0.000243782235419765,0.000105420987329579,0.000626583609509468,8.90291824688319E-8,0.000626583609503796,5.96974231711783E-8,2.66598961217143E-9,6.60485654483868E-8,1.00015085106213,10.005763053894,2,20,10,5,2.04997631395546,0.180514182663274,0.0410455763339996,172.855895996094,47.9996452331543,48.0008888244629,259.576843261719,259.576843261719,,,44.0200843811035,0,1,,,,,,1,1,3,48.0006790161133,0,48.0002087487115,,,,,,,,,,,,,,,,,,,,,,,,,,,,,,,,,