File: Experimental_Data/Fig3C/Lifetime_340Oe_47p5K.dat
[Header]
; MPMS3 Data File (default extension .dat)
; Copyright (c) 2007, Quantum Design, Inc. All rights reserved.
TITLE,340Oe_47p5K
FILEOPENTIME,3768722919.29935,06/03/2019,11:28 am
BYAPP,SQUID AC,0.9.1.0
INFO,MPMS3 Measurement Release 1.1.16 Build 347, MultiVu Release 2.3.3.2,APPNAME
INFO,0,MOMENT_UNITS
INFO,,SAMPLE_MATERIAL
INFO,,SAMPLE_COMMENT
INFO,,SAMPLE_MASS
INFO,,SAMPLE_VOLUME
INFO,,SAMPLE_MOLECULAR_WEIGHT
INFO,,SAMPLE_SIZE
INFO,,SAMPLE_SHAPE
INFO,Quartz,SAMPLE_HOLDER
INFO,Standard,SAMPLE_HOLDER_DETAIL
INFO,66.2,SAMPLE_OFFSET
DATATYPE,COMMENT,1
DATATYPE,TIME,2
STARTUPAXIS,X,2
STARTUPAXIS,Y1,5
FIELDGROUP, VSM,2,3,4,5,6,8,9,10,11,14,15
FIELDGROUP, DC, 2,3,4,14,56,57,58,59,60,61,62,63,64,65,66,67,68,69
FIELDGROUP, AC, 2,3,4,11,16,17,18,19,20,21,22,23,24,25,26,27,28,29,30
STARTUPGROUP, All
[Data]
Comment,Time Stamp (sec),Temperature (K),Magnetic Field (Oe),Moment (emu),M. Std. Err. (emu),Transport Action,Averaging Time (sec),Frequency (Hz),Peak Amplitude (mm),Center Position (mm),Lockin Signal' (V),Lockin Signal (V),Range,M. Quad. Signal (emu),AC Moment (emu),AC M. Std Err. (emu),AC Phase (deg),AC Phase Std. Err. (deg),AC Susceptibility (emu/Oe),AC Suscept. Std Err. (emu/Oe),AC X' (emu/Oe),AC X' Std Err. (emu/Oe),AC X'' (emu/Oe),AC X'' Std Err. (emu/Oe),AC Drive (Oe),AC Frequency (Hz),AC Averaging Time (sec),AC Cycles,AC Range,AC Measure Type,AC Signal' (V),AC Signal'' (V),AC Trim Coil Ratio,AC Trim Coil Phase,Min. Temperature (K),Max. Temperature (K),Min. Field (Oe),Max. Field (Oe),Mass (grams),Motor Lag (deg),Pressure (Torr),Measure Count,Measurement Number,SQUID Status (code),Motor Status (code),Measure Status (code),Motor Current (amps),Motor Temp. (C),Temp. Status (code),Field Status (code),Chamber Status (code),Chamber Temp (K),Redirection State,Average Temp (K),Rotation Angle (deg),Rotator state,DC Moment Fixed Ctr (emu),DC Moment Err Fixed Ctr (emu),DC Moment Free Ctr (emu),DC Moment Err Free Ctr (emu),DC Fixed Fit,DC Free Fit,DC Calculated Center (mm),DC Calculated Center Err (mm),DC Scan Length (mm),DC Scan Time (s),DC Number of Points,DC Squid Drift,DC Min V (V),DC Max V (V),DC Scans per Measure,Map 01,Map 02,Map 03,Map 04,Map 05,Map 06,Map 07,Map 08,Map 09,Map 10,Map 11,Map 12,Map 13,Map 14,Map 15,Map 16
,3768722924.02751,47.4912090301514,339.537231445313,,,5,,,,25.0300001353025,,,,,0.000618316468692704,3.13539033427403E-7,0.0265843398580854,0.000326547123232338,0.00061822350217659,3.13491891497534E-7,0.000618223435630583,2.39870082324409E-7,2.86845963875433E-7,2.01840307273803E-7,1.00015037687145,10.005763053894,2,20,10,5,2.02253071660547,0.179210617025658,0.0410455763339996,172.855895996094,47.422435760498,47.5020980834961,339.537231445313,339.537231445313,,,83.8312683105469,0,1,,,,,,1,1,1,47.4847755432129,0,47.4604723313276,,,,,,,,,,,,,,,,,,,,,,,,,,,,,,,,,
,3768723131.98107,47.5002326965332,339.537231445313,,,5,,,,25.0300001353025,,,,,0.000652502019791633,2.82013143933894E-7,-0.00976434671907445,0.000237931858258331,0.000652403569076033,2.81970593267403E-7,0.000652403559602163,2.35423550283503E-7,-1.11182615412888E-7,1.5518752346591E-7,1.00015090462448,10.005763053894,2,20,10,5,2.13447217866127,0.187764687255938,0.0410455763339996,172.855895996094,47.4996147155762,47.5007057189941,339.537231445313,339.537231445313,,,84.1048812866211,0,1,,,,,,1,1,1,47.5000686645508,0,47.4999970330132,,,,,,,,,,,,,,,,,,,,,,,,,,,,,,,,,
,3768723343.4954,47.4999389648438,339.537231445313,,,5,,,,25.0300001353025,,,,,0.000670803883429567,1.75561122725E-7,-0.00293545373004456,0.00016348438670304,0.000670702680310689,1.75534636096624E-7,0.00067070267943044,1.37090879018455E-7,-3.43623335006385E-8,1.09628916621125E-7,1.00015089118003,10.005763053894,2,20,10,5,2.19431842496841,0.193292786874529,0.0410455763339996,172.855895996094,47.499267578125,47.5004425048828,339.537231445313,339.537231445313,,,84.4406890869141,0,1,,,,,,1,1,1,47.4999198913574,0,47.4997976091173,,,,,,,,,,,,,,,,,,,,,,,,,,,,,,,,,
,3768723553.03708,47.4994277954102,339.537231445313,,,5,,,,25.0300001353025,,,,,0.000681926726890203,1.57572195589997E-7,-0.00457271679016369,0.00015442900167666,0.000681823861635676,1.5754842660813E-7,0.000681823859464247,1.17209623530378E-7,-5.44156557991159E-8,1.05277779605026E-7,1.00015086778318,10.005763053894,2,20,10,5,2.23070883165606,0.196434104515287,0.0410455763339996,172.855895996094,47.4987525939941,47.5000915527344,339.537231445313,339.537231445313,,,84.7391738891602,0,1,,,,,,1,1,1,47.4991722106934,0,47.4996185302734,,,,,,,,,,,,,,,,,,,,,,,,,,,,,,,,,
,3768723761.33976,47.4992961883545,339.537231445313,,,5,,,,25.0300001353025,,,,,0.000689141323702822,3.26912694876404E-7,-0.015228685391385,0.00025704264425661,0.000689037374312261,3.26863383691266E-7,0.000689037349973843,2.74749138638373E-7,-1.83139724460231E-7,1.77066604461643E-7,1.00015086175937,10.005763053894,2,20,10,5,2.25434599676278,0.198093061293831,0.0410455763339996,172.855895996094,47.4980125427246,47.5003051757812,339.537231445313,339.537231445313,,,84.9879150390625,0,1,,,,,,1,1,1,47.4987678527832,0,47.4992073906793,,,,,,,,,,,,,,,,,,,,,,,,,,,,,,,,,
,3768723968.27467,47.5003070831299,339.537231445313,,,5,,,,25.0300001353025,,,,,0.000695133745166982,2.05834954129414E-7,-0.0110460173292406,0.000198983060358063,0.000695028859731493,2.05803896668957E-7,0.000695028846815166,1.52427317325796E-7,-1.33994176300638E-7,1.38279271103763E-7,1.00015090802924,10.005763053894,2,20,10,5,2.27393404752943,0.199981571160629,0.0410455763339996,172.855895996094,47.4990997314453,47.5005989074707,339.537231445313,339.537231445313,,,85.2490997314453,0,1,,,,,,1,1,1,47.5003051757812,0,47.4999207390679,,,,,,,,,,,,,,,,,,,,,,,,,,,,,,,,,
,3768724174.74623,47.5001010894775,339.537231445313,,,5,,,,25.0300001353025,,,,,0.000699327466936273,1.54936585797578E-7,-0.0078872602508353,0.000159437644974861,0.000699221955321661,1.54913209611023E-7,0.000699221948696565,1.07576043141289E-7,-9.62539573450204E-8,1.1146971541209E-7,1.00015089860067,10.005763053894,2,20,10,5,2.28764153059529,0.201314175185615,0.0410455763339996,172.855895996094,47.4992485046387,47.5002517700195,339.537231445313,339.537231445313,,,85.4854049682617,0,1,,,,,,1,1,1,47.5000076293945,0,47.4999362721163,,,,,,,,,,,,,,,,,,,,,,,,,,,,,,,,,
,3768724379.8067,47.500602722168,339.537231445313,,,5,,,,25.0300001353025,,,,,0.000702828607201103,1.88936631959575E-7,-0.010455144575154,0.000192988147430259,0.000702722551216726,1.88908121650971E-7,0.000702722539517188,1.31523628344165E-7,-1.28230489066667E-7,1.35601672603563E-7,1.000150921561,10.005763053894,2,20,10,5,2.29910353386362,0.202218998395367,0.0410455763339996,172.855895996094,47.4997100830078,47.5007286071777,339.537231445313,339.537231445313,,,85.7092742919922,0,1,,,,,,1,1,1,47.5006103515625,0,47.5001837786506,,,,,,,,,,,,,,,,,,,,,,,,,,,,,,,,,
,3768724586.27565,47.5015869140625,339.537231445313,,,5,,,,25.0300001353025,,,,,0.000705507542623876,2.07415130937754E-7,-0.0195151392177531,0.000195534041382356,0.000705401131537278,2.07383846694671E-7,0.00070540109062024,1.54883264854869E-7,-2.40262042634399E-7,1.3791023942324E-7,1.00015085187965,10.005763053894,2,20,10,5,2.30789897741928,0.202624844062347,0.0410455763339996,172.855895996094,47.4996070861816,47.5021438598633,339.537231445313,339.537231445313,,,85.9207000732422,0,1,,,,,,1,1,1,47.5014686584473,0,47.5006947236903,,,,,,,,,,,,,,,,,,,,,,,,,,,,,,,,,
,3768724794.09196,47.4988594055176,339.537231445313,,,5,,,,25.0300001353025,,,,,0.000707745400704557,2.38272170802759E-7,-0.00750265888826185,0.000265905691321924,0.000707638659238592,2.38236234828064E-7,0.000707638653171694,1.46136325504002E-7,-9.26625225515827E-8,1.88150678854052E-7,1.00015084176729,10.005763053894,2,20,10,5,2.31517692580312,0.203752976153287,0.0410455763339996,172.855895996094,47.498462677002,47.5001564025879,339.537231445313,339.537231445313,,,86.1072616577148,0,1,,,,,,1,1,1,47.4990882873535,0,47.499469981474,,,,,,,,,,,,,,,,,,,,,,,,,,,,,,,,,
,3768725000.74663,47.499828338623,339.537231445313,,,5,,,,25.0300001353025,,,,,0.000709689818412689,2.94908787191417E-7,-0.00666640856630085,0.000291477951568791,0.000709582752226849,2.9486429626285E-7,0.000709582747423859,2.10185316958354E-7,-8.25605056336029E-8,2.06802044829596E-7,1.00015088611653,10.005763053894,2,20,10,5,2.32153452361037,0.204346634234411,0.0410455763339996,172.855895996094,47.4995422363281,47.5004920959473,339.537231445313,339.537231445313,,,86.3311233520508,0,1,,,,,,1,1,1,47.5000038146973,0,47.5000006731819,,,,,,,,,,,,,,,,,,,,,,,,,,,,,,,,,
,3768725210.16052,47.4998359680176,339.537231445313,,,5,,,,25.0300001353025,,,,,0.000711082492571611,2.43353504707061E-7,-0.00742349550571397,0.000237499619178908,0.000710975216034038,2.43316791496338E-7,0.000710975210066487,1.75208292130428E-7,-9.21171044532329E-8,1.68834579967526E-7,1.00015088646574,10.005763053894,2,20,10,5,2.32609293884299,0.20471690428639,0.0410455763339996,172.855895996094,47.4994850158691,47.5007591247559,339.537231445313,339.537231445313,,,86.5176849365234,0,1,,,,,,1,1,1,47.4994773864746,0,47.4998581830193,,,,,,,,,,,,,,,,,,,,,,,,,,,,,,,,,
,3768725415.72554,47.5000782012939,339.537231445313,,,5,,,,25.0300001353025,,,,,0.000712546811437892,2.69079773285836E-7,-0.00406865296869086,0.000192234676291523,0.00071243930608991,2.69039175932514E-7,0.00071243930429363,2.31598448020254E-7,-5.05913056761322E-8,1.36909594481381E-7,1.00015089755305,10.005763053894,2,20,10,5,2.3308710031772,0.205274952087133,0.0410455763339996,172.855895996094,47.4995765686035,47.5005073547363,339.537231445313,339.537231445313,,,86.6793670654297,0,1,,,,,,1,1,1,47.4998664855957,0,47.4999716909308,,,,,,,,,,,,,,,,,,,,,,,,,,,,,,,,,
,3768725624.16171,47.4999980926514,339.537231445313,,,5,,,,25.0300001353025,,,,,0.000713638304306541,1.79746666721257E-7,-0.00142169436193385,0.000154085297889236,0.000713530636895692,1.7971954814018E-7,0.000713530636676032,1.42183608365458E-7,-1.77050123422433E-8,1.09922415802639E-7,1.00015089388638,10.005763053894,2,20,10,5,2.33443197572608,0.205697242926626,0.0410455763339996,172.855895996094,47.499439239502,47.500431060791,339.537231445313,339.537231445313,,,86.9032363891602,0,1,,,,,,1,1,1,47.4998474121094,0,47.499901453654,,,,,,,,,,,,,,,,,,,,,,,,,,,,,,,,,
,3768725830.27257,47.5000953674316,339.537231445313,,,5,,,,25.0300001353025,,,,,0.000714952940105908,1.84933245762097E-7,-0.00267539955876295,0.000166605335622737,0.000714845071172197,1.84905343852882E-7,0.000714845070392881,1.4145915280547E-7,-3.3379355400275E-8,1.19076841883346E-7,1.00015089833876,10.005763053894,2,20,10,5,2.33873688121484,0.206024994661778,0.0410455763339996,172.855895996094,47.4996223449707,47.5002250671387,339.537231445313,339.537231445313,,,87.0897903442383,0,1,,,,,,1,1,1,47.5000457763672,0,47.4999277451459,,,,,,,,,,,,,,,,,,,,,,,,,,,,,,,,,
,3768726034.80725,47.5001411437988,339.537231445313,,,5,,,,25.0300001353025,,,,,0.000715959592917111,2.91906910095372E-7,-0.00419689501298581,0.000287874199783201,0.000715851570604428,2.91862867861943E-7,0.000715851568683974,2.06705741353173E-7,-5.24358671712487E-8,2.060501641063E-7,1.000150900434,10.005763053894,2,20,10,5,2.34203529767923,0.206252883776534,0.0410455763339996,172.855895996094,47.4994125366211,47.5003395080566,339.537231445313,339.537231445313,,,87.2763442993164,0,1,,,,,,1,1,1,47.5002326965332,0,47.4997989430147,,,,,,,,,,,,,,,,,,,,,,,,,,,,,,,,,
,3768726239.98684,47.5003643035889,339.537231445313,,,5,,,,25.0300001353025,,,,,0.000716823834289631,2.60461964737545E-7,-0.00946805259559724,0.000175021544016201,0.000716715674262588,2.60422664184463E-7,0.000716715664476863,2.2824576784759E-7,-1.18436326842779E-7,1.25394710736129E-7,1.00015091064829,10.005763053894,2,20,10,5,2.34488137817087,0.206286125159099,0.0410455763339996,172.855895996094,47.499439239502,47.5007286071777,339.537231445313,339.537231445313,,,87.4629058837891,0,1,,,,,,1,1,1,47.5007286071777,0,47.4999598334817,,,,,,,,,,,,,,,,,,,,,,,,,,,,,,,,,
,3768726444.98291,47.5017185211182,339.537231445313,,,5,,,,25.0300001353025,,,,,0.00071728371937221,1.69707673638084E-7,-0.0107647453859459,0.000191988858252199,0.000717175527775676,1.69682075755881E-7,0.000717175515117891,9.91776216306306E-8,-1.34743116748319E-7,1.37680086434153E-7,1.00015085790346,10.005763053894,2,20,10,5,2.34639043032025,0.206365362601815,0.0410455763339996,172.855895996094,47.5001335144043,47.5021591186523,339.537231445313,339.537231445313,,,87.6494598388672,0,1,,,,,,1,1,1,47.501766204834,0,47.5009633232566,,,,,,,,,,,,,,,,,,,,,,,,,,,,,,,,,
,3768726651.37715,47.5006771087646,339.537231445313,,,5,,,,25.0300001353025,,,,,0.000717952281557998,1.84512433404453E-7,-0.00201635757022611,0.000163820452579727,0.000717844023330877,1.84484611236552E-7,0.000717844022886358,1.42162773805022E-7,-2.5262423213136E-8,1.17576857957524E-7,1.00015081023677,10.005763053894,2,20,10,5,2.34854587529211,0.206916313412798,0.0410455763339996,172.855895996094,47.4999160766602,47.5009613037109,339.537231445313,339.537231445313,,,87.8235778808594,0,1,,,,,,1,1,1,47.5006675720215,0,47.5003871917725,,,,,,,,,,,,,,,,,,,,,,,,,,,,,,,,,
,3768726858.30405,47.4998359680176,339.537231445313,,,5,,,,25.0300001353025,,,,,0.00071870024998148,1.66827286377394E-7,-0.00239004773375218,0.000146830022227871,0.00071859182420082,1.66802118195302E-7,0.000718591823575618,1.2920686455252E-7,-2.99754846695781E-8,1.05491861235577E-7,1.00015088646574,10.005763053894,2,20,10,5,2.35099395958594,0.2071165520578,0.0410455763339996,172.855895996094,47.4991073608398,47.5002975463867,339.537231445313,339.537231445313,,,87.9976959228516,0,1,,,,,,1,1,1,47.4996109008789,0,47.4997114293716,,,,,,,,,,,,,,,,,,,,,,,,,,,,,,,,,
,3768727065.94069,47.4999942779541,339.537231445313,,,5,,,,25.0300001353025,,,,,0.000719445929589832,2.31629951820775E-7,-0.00834562347857304,0.000229728451724434,0.000719337386101626,2.31595005590753E-7,0.000719337378470741,1.622784601265E-7,-1.04777681851177E-7,1.65233011210088E-7,1.00015089371177,10.005763053894,2,20,10,5,2.35345474622456,0.207086813361677,0.0410455763339996,172.855895996094,47.4996528625488,47.5004119873047,339.537231445313,339.537231445313,,,88.1718139648438,0,1,,,,,,1,1,1,47.5002136230469,0,47.499982532702,,,,,,,,,,,,,,,,,,,,,,,,,,,,,,,,,
,3768727275.13446,47.5002002716064,339.537231445313,,,5,,,,25.0300001353025,,,,,0.000719927301508069,2.66210650881732E-7,-0.00978226087899081,0.000146893085580492,0.000719818678608984,2.66170484919689E-7,0.000719818668117756,2.442939114568E-7,-1.22896557571164E-7,1.05675029536403E-7,1.00015090314035,10.005763053894,2,20,10,5,2.35503460741716,0.207166322496486,0.0410455763339996,172.855895996094,47.4992485046387,47.5006828308105,339.537231445313,339.537231445313,,,88.3583755493164,0,1,,,,,,1,1,1,47.5001640319824,0,47.4999452478745,,,,,,,,,,,,,,,,,,,,,,,,,,,,,,,,,
,3768727478.94427,47.5017108917236,339.537231445313,,,5,,,,25.0300001353025,,,,,0.000720805983101545,2.45030302326151E-7,-0.0144196273582509,0.000232119155141534,0.000720697260475472,2.44993343229583E-7,0.000720697237651791,1.79008621839025E-7,-1.81377859116006E-7,1.67265213161916E-7,1.00015085755425,10.005763053894,2,20,10,5,2.35792574178796,0.207228321342708,0.0410455763339996,172.855895996094,47.5002479553223,47.5017700195313,339.537231445313,339.537231445313,,,88.5324935913086,0,1,,,,,,1,1,1,47.501651763916,0,47.500924727496,,,,,,,,,,,,,,,,,,,,,,,,,,,,,,,,,
,3768727684.02069,47.5010528564453,339.537231445313,,,5,,,,25.0300001353025,,,,,0.000720779886287194,2.39233005313016E-7,-0.00286840458180482,0.000286540813566692,0.000720671189300097,2.39196927853883E-7,0.000720671188396983,1.20730838087033E-7,-3.60790368517044E-8,2.06492699700349E-7,1.00015082743519,10.005763053894,2,20,10,5,2.35779854763874,0.207696174340046,0.0410455763339996,172.855895996094,47.4996681213379,47.5013313293457,339.537231445313,339.537231445313,,,88.7190475463867,0,1,,,,,,1,1,1,47.5010032653809,0,47.5004391389735,,,,,,,,,,,,,,,,,,,,,,,,,,,,,,,,,
,3768727889.71864,47.5000057220459,339.537231445313,,,5,,,,25.0300001353025,,,,,0.000721503876033343,1.48930277581509E-7,-0.0017469852595946,0.000129140053842492,0.000721395021682993,1.4890780825161E-7,0.00072139502134766,1.16180095337286E-7,-2.19957993370539E-8,9.31435494584435E-8,1.00015089423558,10.005763053894,2,20,10,5,2.3601627760783,0.207950994874013,0.0410455763339996,172.855895996094,47.4997177124023,47.5002212524414,339.537231445313,339.537231445313,,,88.8931732177734,0,1,,,,,,1,1,1,47.4999198913574,0,47.4999607933892,,,,,,,,,,,,,,,,,,,,,,,,,,,,,,,,,
,3768728094.72691,47.5001697540283,339.537231445313,,,5,,,,25.0300001353025,,,,,0.00072175547866711,1.91146097055862E-7,-0.00423541869287458,0.000146022697698344,0.000721646580939838,1.91117257128544E-7,0.000721646578968133,1.59460090728999E-7,-5.33455595115879E-8,1.05348400258559E-7,1.00015090174352,10.005763053894,2,20,10,5,2.3609948440178,0.207920969285974,0.0410455763339996,172.855895996094,47.4993095397949,47.5004081726074,339.537231445313,339.537231445313,,,89.0548553466797,0,1,,,,,,1,1,1,47.5001678466797,0,47.499958487118,,,,,,,,,,,,,,,,,,,,,,,,,,,,,,,,,
,3768728299.76472,47.5001888275146,339.537231445313,,,5,,,,25.0300001353025,,,,,0.000722179208281996,2.39950884764608E-7,-0.0109241465045722,0.000174719281183016,0.000722070245992549,2.39914681011497E-7,0.000722070232868156,2.04088202933389E-7,-1.37671590701076E-7,1.26123192110999E-7,1.00015090261654,10.005763053894,2,20,10,5,2.36240521260716,0.20776724700534,0.0410455763339996,172.855895996094,47.4994354248047,47.5006675720215,339.537231445313,339.537231445313,,,89.2414093017578,0,1,,,,,,1,1,1,47.5006675720215,0,47.4999299890855,,,,,,,,,,,,,,,,,,,,,,,,,,,,,,,,,
,3768728508.37852,47.5002956390381,339.537231445313,,,5,,,,25.0300001353025,,,,,0.000722457190431681,1.47059038139426E-7,-0.00641268056470956,0.000109759317655038,0.00072234818266938,1.4703684917531E-7,0.000722348178145089,1.23844043507675E-7,-8.08469346547349E-8,7.92621467225816E-8,1.00015090750543,10.005763053894,2,20,10,5,2.36329817946375,0.208033307557176,0.0410455763339996,172.855895996094,47.4997940063477,47.5006790161133,339.537231445313,339.537231445313,,,89.4030914306641,0,1,,,,,,1,1,1,47.5006828308105,0,47.5001682954676,,,,,,,,,,,,,,,,,,,,,,,,,,,,,,,,,
,3768728716.02734,47.5010795593262,339.537231445313,,,5,,,,25.0300001353025,,,,,0.000723010348146363,2.35627120702075E-7,-0.0106743508099862,0.000234055847650192,0.000722901313911744,2.35591586739349E-7,0.000722901301366281,1.63955826234491E-7,-1.34678369796746E-7,1.69180030695498E-7,1.00015082865741,10.005763053894,2,20,10,5,2.36512314515619,0.208016670601135,0.0410455763339996,172.855895996094,47.4999694824219,47.501350402832,339.537231445313,339.537231445313,,,89.6020812988281,0,1,,,,,,1,1,1,47.5011749267578,0,47.5005731021657,,,,,,,,,,,,,,,,,,,,,,,,,,,,,,,,,
,3768728921.05842,47.5004272460937,339.537231445313,,,5,,,,25.0300001353025,,,,,0.000723030059202931,1.89635216708703E-7,-0.013500038401105,0.000194660393888246,0.000722920960649394,1.89606602507151E-7,0.00072292094058225,1.27088217906374E-7,-1.70334721376812E-7,1.40709802727765E-7,1.00015091352925,10.005763053894,2,20,10,5,2.36519788016633,0.207905700514474,0.0410455763339996,172.855895996094,47.4998893737793,47.5006980895996,339.537231445313,339.537231445313,,,89.7388916015625,0,1,,,,,,1,1,1,47.5002632141113,0,47.5002548694611,,,,,,,,,,,,,,,,,,,,,,,,,,,,,,,,,
,3768729127.23535,47.4992351531982,339.537231445313,,,5,,,,25.0300001353025,,,,,0.000723329406695087,1.36384592666214E-7,-0.00661791880523754,0.000127860708712044,0.000723220302428277,1.36364020931056E-7,0.000723220297603933,1.0023257564003E-7,-8.35351795507812E-8,9.24585149407611E-8,1.00015085896572,10.005763053894,2,20,10,5,2.36615211385641,0.208275999272371,0.0410455763339996,172.855895996094,47.4981307983398,47.5003356933594,339.537231445313,339.537231445313,,,89.9130096435547,0,1,,,,,,1,1,1,47.498462677002,0,47.4995502895779,,,,,,,,,,,,,,,,,,,,,,,,,,,,,,,,,
,3768729335.30094,47.5004425048828,339.537231445313,,,5,,,,25.0300001353025,,,,,0.000723659776102998,2.06203717432119E-7,-0.0040384797735733,0.000256388330150259,0.000723550582025739,2.06172603052965E-7,0.000723550580228402,8.99746909218329E-8,-5.09992954643622E-8,1.85503900883933E-7,1.00015091422766,10.005763053894,2,20,10,5,2.36722343454042,0.208477688306776,0.0410455763339996,172.855895996094,47.4993553161621,47.5007057189941,339.537231445313,339.537231445313,,,90.062255859375,0,1,,,,,,1,1,1,47.5004768371582,0,47.4999720255534,,,,,,,,,,,,,,,,,,,,,,,,,,,,,,,,,
,3768729541.71328,47.5007705688477,339.537231445313,,,5,,,,25.0300001353025,,,,,0.000723783071528057,2.32568554197033E-7,-0.0090910797430066,0.000250953522655374,0.00072367384798161,2.32533458098104E-7,0.000723673838872026,1.45243068552424E-7,-1.14824803645821E-7,1.81593667765532E-7,1.00015092924354,10.005763053894,2,20,10,5,2.36764513497961,0.208304417947205,0.0410455763339996,172.855895996094,47.4995994567871,47.5007934570313,339.537231445313,339.537231445313,,,90.2363739013672,0,1,,,,,,1,1,1,47.5007858276367,0,47.5002955268411,,,,,,,,,,,,,,,,,,,,,,,,,,,,,,,,,
,3768729746.97125,47.5010795593262,339.537231445313,,,5,,,,25.0300001353025,,,,,0.000724027794762375,1.8453810344702E-7,0.000963831011450367,0.000198381618081694,0.000723918607090792,1.84510274010112E-7,0.000723918606988364,1.15856866167425E-7,1.21777766037346E-8,1.43600932368666E-7,1.00015082865741,10.005763053894,2,20,10,5,2.36840907129663,0.208790486416339,0.0410455763339996,172.855895996094,47.5001182556152,47.5011787414551,339.537231445313,339.537231445313,,,90.3856201171875,0,1,,,,,,1,1,1,47.5010261535645,0,47.500607658835,,,,,,,,,,,,,,,,,,,,,,,,,,,,,,,,,
,3768729953.12923,47.5001983642578,339.537231445313,,,5,,,,25.0300001353025,,,,,0.000724331475188046,1.90661109566842E-7,-0.00521389020215235,0.000167029054883363,0.000724222187848814,1.90632342564339E-7,0.000724222184850202,1.47353385646929E-7,-6.59038937297749E-8,1.20944903861035E-7,1.00015090305305,10.005763053894,2,20,10,5,2.36942496530924,0.208622589561008,0.0410455763339996,172.855895996094,47.4991836547852,47.5002136230469,339.537231445313,339.537231445313,,,90.5348663330078,0,1,,,,,,1,1,1,47.5002670288086,0,47.4997839927673,,,,,,,,,,,,,,,,,,,,,,,,,,,,,,,,,
,3768730159.60953,47.5004978179932,339.537231445313,,,5,,,,25.0300001353025,,,,,0.00072465432869176,1.80193708157158E-7,-0.0100381593137673,0.00011941509035972,0.000724544982710924,1.80166518010106E-7,0.000724544971591091,1.58048980441997E-7,-1.2693950568514E-7,8.64898490756636E-8,1.00015091675941,10.005763053894,2,20,10,5,2.37049864548347,0.208515983122576,0.0410455763339996,172.855895996094,47.5002593994141,47.5006561279297,339.537231445313,339.537231445313,,,90.6592407226563,0,1,,,,,,1,1,1,47.5005187988281,0,47.5003967285156,,,,,,,,,,,,,,,,,,,,,,,,,,,,,,,,,
,3768730364.76503,47.4995403289795,339.537231445313,,,5,,,,25.0300001353025,,,,,0.000724873044367676,1.62617216919583E-7,-0.00619138806437913,8.9402439598578E-5,0.000724763697142245,1.6259268608399E-7,0.000724763692910717,1.49140731927487E-7,-7.83180425047572E-8,6.47566494511599E-8,1.00015087293398,10.005763053894,2,20,10,5,2.37120010153089,0.208738122321782,0.0410455763339996,172.855895996094,47.4990463256836,47.5000686645508,339.537231445313,339.537231445313,,,90.7960433959961,0,1,,,,,,1,1,1,47.4995422363281,0,47.4994930940516,,,,,,,,,,,,,,,,,,,,,,,,,,,,,,,,,
,3768730572.32792,47.5004997253418,339.537231445313,,,5,,,,25.0300001353025,,,,,0.000725114944297425,2.51963029200352E-7,-0.00457707674062036,0.000212716578986317,0.00072500552874918,2.51925009472315E-7,0.000725005526435824,1.9922744705894E-7,-5.79171095520548E-8,1.54190254996882E-7,1.00015091684671,10.005763053894,2,20,10,5,2.37198551939119,0.208874606869732,0.0410455763339996,172.855895996094,47.4997940063477,47.5008316040039,339.537231445313,339.537231445313,,,90.9701690673828,0,1,,,,,,1,1,1,47.5005950927734,0,47.5003253712374,,,,,,,,,,,,,,,,,,,,,,,,,,,,,,,,,
,3768730779.95049,47.4997329711914,339.537231445313,,,5,,,,25.0300001353025,,,,,0.000725371623763446,3.12179028402526E-7,-0.00813159815978626,0.00035232597129511,0.000725262194933215,3.12131933389733E-7,0.000725262187629033,1.79276140916301E-7,-1.02931503157866E-7,2.55512052826812E-7,1.00015088175145,10.005763053894,2,20,10,5,2.372838123332,0.208801343963399,0.0410455763339996,172.855895996094,47.4992408752441,47.5002212524414,339.537231445313,339.537231445313,,,91.1069717407227,0,1,,,,,,1,1,1,47.4996223449707,0,47.499775144789,,,,,,,,,,,,,,,,,,,,,,,,,,,,,,,,,
,3768730985.12758,47.5003929138184,339.537231445313,,,5,,,,25.0300001353025,,,,,0.000725556351252846,2.11814887276845E-7,-0.0091127562603921,0.000122640669022027,0.000725446872645003,2.11782926700744E-7,0.0007254468634695,1.92209772947361E-7,-1.15380584025335E-7,8.89236258002163E-8,1.00015091195782,10.005763053894,2,20,10,5,2.37344598102283,0.208813870987415,0.0410455763339996,172.855895996094,47.4994201660156,47.5004959106445,339.537231445313,339.537231445313,,,91.2686538696289,0,1,,,,,,1,1,1,47.5003852844238,0,47.5001537098604,,,,,,,,,,,,,,,,,,,,,,,,,,,,,,,,,
,3768731192.7788,47.50048828125,339.537231445313,,,5,,,,25.0300001353025,,,,,0.000725868841245598,2.0325151325078E-7,-0.00205143543226871,0.000226557007229766,0.000725759312318873,2.03220843908281E-7,0.00072575931185368,1.19441858021166E-7,-2.59853060892881E-8,1.64415187714655E-7,1.0001509163229,10.005763053894,2,20,10,5,2.37444243693513,0.209196439984073,0.0410455763339996,172.855895996094,47.4996452331543,47.5007133483887,339.537231445313,339.537231445313,,,91.4054641723633,0,1,,,,,,1,1,1,47.5005493164063,0,47.5001878177418,,,,,,,,,,,,,,,,,,,,,,,,,,,,,,,,,
,3768731398.47627,47.5002422332764,339.537231445313,,,5,,,,25.0300001353025,,,,,0.000726048944231748,2.45938716830353E-7,-0.00529878342640799,0.000158843182024843,0.000725939396302876,2.45901609033045E-7,0.000725939393198478,2.17214129196702E-7,-6.71357588449396E-8,1.15263278637903E-7,1.00015090506099,10.005763053894,2,20,10,5,2.3750434404985,0.209113738001614,0.0410455763339996,172.855895996094,47.4997177124023,47.5003776550293,339.537231445313,339.537231445313,,,91.5671463012695,0,1,,,,,,1,1,1,47.5001602172852,0,47.5000284980325,,,,,,,,,,,,,,,,,,,,,,,,,,,,,,,,,
,3768731606.03285,47.5009460449219,339.537231445313,,,5,,,,25.0300001353025,,,,,0.000726131397554964,2.02710798463346E-7,-0.00476517506019292,0.000159543884923584,0.000726021897083777,2.02680229715016E-7,0.000726021894572861,1.66338923795587E-7,-6.03817848810193E-8,1.15804308848409E-7,1.0001508225463,10.005763053894,2,20,10,5,2.37531121341505,0.209159603846563,0.0410455763339996,172.855895996094,47.4997444152832,47.5009956359863,339.537231445313,339.537231445313,,,91.7163925170898,0,1,,,,,,1,1,1,47.5009574890137,0,47.5004162507899,,,,,,,,,,,,,,,,,,,,,,,,,,,,,,,,,
,3768731813.73875,47.5000171661377,339.537231445313,,,5,,,,25.0300001353025,,,,,0.000726463076505828,2.35885127542255E-7,-0.000435343839535918,0.000192811863211743,0.000726353473573199,2.35849539082803E-7,0.000726353473552232,1.89788986101953E-7,-5.51896688953091E-9,1.40018376793774E-7,1.00015089475939,10.005763053894,2,20,10,5,2.37638037649168,0.209434731211137,0.0410455763339996,172.855895996094,47.499683380127,47.500316619873,339.537231445313,339.537231445313,,,91.8780746459961,0,1,,,,,,1,1,1,47.4998817443848,0,47.5000188490924,,,,,,,,,,,,,,,,,,,,,,,,,,,,,,,,,
,3768732021.39468,47.5006923675537,339.537231445313,,,5,,,,25.0300001353025,,,,,0.000726544532475314,2.08891492904522E-7,-0.00593221215569351,0.000181425322385911,0.000726434894806336,2.08859970574744E-7,0.000726434890912705,1.6204659471584E-7,-7.52126237257465E-8,1.31770210781812E-7,1.00015092566418,10.005763053894,2,20,10,5,2.3766669169638,0.209230196998836,0.0410455763339996,172.855895996094,47.4997596740723,47.5009803771973,339.537231445313,339.537231445313,,,92.0273208618164,0,1,,,,,,1,1,1,47.5008506774902,0,47.5004512562471,,,,,,,,,,,,,,,,,,,,,,,,,,,,,,,,,
,3768732226.48121,47.4999561309814,339.537231445313,,,5,,,,25.0300001353025,,,,,0.000726602849393357,1.64021017687783E-7,-0.0139800744648886,0.000146606032095578,0.000726493227402178,1.63996271967931E-7,0.000726493205776224,1.24716937812763E-7,-1.77263131819739E-7,1.06491608317215E-7,1.00015089196574,10.005763053894,2,20,10,5,2.37688705024241,0.208913135110652,0.0410455763339996,172.855895996094,47.499584197998,47.5003128051758,339.537231445313,339.537231445313,,,92.2138748168945,0,1,,,,,,1,1,1,47.5001182556152,0,47.4999046325684,,,,,,,,,,,,,,,,,,,,,,,,,,,,,,,,,
,3768732431.75093,47.5001354217529,339.537231445313,,,5,,,,25.0300001353025,,,,,0.000726857949006104,1.56724437425089E-7,-0.00623999881186865,0.000159898854863981,0.000726748282565195,1.56700791248722E-7,0.000726748278255191,1.05137819531986E-7,-7.91490830443129E-8,1.16194564769765E-7,1.00015090017209,10.005763053894,2,20,10,5,2.37769328686079,0.209307684983734,0.0410455763339996,172.855895996094,47.4996948242188,47.5003929138184,339.537231445313,339.537231445313,,,92.338249206543,0,1,,,,,,1,1,1,47.5002212524414,0,47.5000210930319,,,,,,,,,,,,,,,,,,,,,,,,,,,,,,,,,
,3768732638.24515,47.5003108978271,339.537231445313,,,5,,,,25.0300001353025,,,,,0.000727288606398416,8.40900749974109E-7,-0.00268173734759891,0.000658142853413985,0.000727178869141399,8.40773870299502E-7,0.000727178868344876,6.91352746928343E-7,-3.40357134089421E-8,4.78468473666801E-7,1.00015090820385,10.005763053894,2,20,10,5,2.37908903956105,0.209579449384079,0.0410455763339996,172.855895996094,47.4995384216309,47.5008316040039,339.537231445313,339.537231445313,,,92.4999313354492,0,1,,,,,,1,1,1,47.4999237060547,0,47.5000796847873,,,,,,,,,,,,,,,,,,,,,,,,,,,,,,,,,
,3768732846.81812,47.50124168396,339.537231445313,,,5,,,,25.0300001353025,,,,,0.000727155944083942,2.34817423761033E-7,-0.00449852723111643,0.000206546561009753,0.000727046279274614,2.34782010163422E-7,0.000727046277033688,1.80498303108685E-7,-5.70833927041984E-8,1.5014311463155E-7,1.00015083607805,10.005763053894,2,20,10,5,2.37866172122705,0.209465792482409,0.0410455763339996,172.855895996094,47.5000076293945,47.502311706543,339.537231445313,339.537231445313,,,92.6491775512695,0,1,,,,,,1,1,1,47.5006294250488,0,47.5006684695973,,,,,,,,,,,,,,,,,,,,,,,,,,,,,,,,,
,3768733054.27677,47.5014057159424,339.537231445313,,,5,,,,25.0300001353025,,,,,0.000727256541742928,1.53885547624692E-7,-0.00436541532566181,0.0001201283478545,0.00072714685630358,1.53862338477807E-7,0.000727146854193019,1.2667757527184E-7,-5.54019520184469E-8,8.73293256879191E-8,1.00015084358599,10.005763053894,2,20,10,5,2.37899030820402,0.209500296421728,0.0410455763339996,172.855895996094,47.4997215270996,47.5021362304687,339.537231445313,339.537231445313,,,92.8108596801758,0,1,,,,,,1,1,1,47.5009117126465,0,47.5006449082318,,,,,,,,,,,,,,,,,,,,,,,,,,,,,,,,,
,3768733262.34476,47.499885559082,339.537231445313,,,5,,,,25.0300001353025,,,,,0.000727467796838607,2.25029461839725E-7,-0.00265555240345972,0.000195590439926744,0.000727358046702627,2.24995512551325E-7,0.00072735804592139,1.74330549240605E-7,-3.37116874021124E-8,1.42238673607787E-7,1.00015088873558,10.005763053894,2,20,10,5,2.37967510734636,0.209632172075857,0.0410455763339996,172.855895996094,47.4992485046387,47.5005226135254,339.537231445313,339.537231445313,,,92.9476623535156,0,1,,,,,,1,1,1,47.5002021789551,0,47.4997704823812,,,,,,,,,,,,,,,,,,,,,,,,,,,,,,,,,
,3768733471.06743,47.5000476837158,339.537231445313,,,5,,,,25.0300001353025,,,,,0.000727578194797263,2.05140646477839E-7,0.00143193812798703,0.000152689871402034,0.000727468422608521,2.05109696213077E-7,0.000727468422381332,1.7245057291423E-7,1.81809162905871E-8,1.11044078555205E-7,1.00015089615622,10.005763053894,2,20,10,5,2.38002127485544,0.209833777986509,0.0410455763339996,172.855895996094,47.4994812011719,47.5003395080566,339.537231445313,339.537231445313,,,93.1342239379883,0,1,,,,,,1,1,1,47.4999504089355,0,47.4999129351448,,,,,,,,,,,,,,,,,,,,,,,,,,,,,,,,,
,3768733676.16619,47.4991054534912,339.537231445313,,,5,,,,25.0300001353025,,,,,0.000727573324759536,1.48742614434868E-7,-0.0115196484814746,0.000155560584953419,0.00072746350122559,1.4872016248534E-7,0.000727463486522304,9.65080495921942E-8,-1.46260751349918E-7,1.13154244699775E-7,1.00015096775819,10.005763053894,2,20,10,5,2.38005271534451,0.209294375372088,0.0410455763339996,172.855895996094,47.4984550476074,47.5026397705078,339.537231445313,339.537231445313,,,93.2834701538086,0,1,,,,,,1,1,1,47.4994735717773,0,47.500940435073,,,,,,,,,,,,,,,,,,,,,,,,,,,,,,,,,
,3768733882.35062,47.4997596740723,339.537231445313,,,5,,,,25.0300001353025,,,,,0.000727741591310537,1.7912585157794E-7,-0.0028311195463262,0.000158994057431867,0.000727631804060203,1.79098828614098E-7,0.000727631803171917,1.36736605373346E-7,-3.59540028894239E-8,1.15669750418663E-7,1.00015088297367,10.005763053894,2,20,10,5,2.3805713795695,0.209703778643529,0.0410455763339996,172.855895996094,47.4992485046387,47.5000038146973,339.537231445313,339.537231445313,,,93.4202728271484,0,1,,,,,,1,1,1,47.4996528625488,0,47.4996693929036,,,,,,,,,,,,,,,,,,,,,,,,,,,,,,,,,
,3768734089.13879,47.5000228881836,339.537231445313,,,5,,,,25.0300001353025,,,,,0.000727928017167849,1.54273617490433E-7,-0.00715227979968169,0.000168346060214344,0.000727818193026111,1.5425034188181E-7,0.000727818187355412,9.37174223671467E-8,-9.08541500009338E-8,1.22516173281379E-7,1.0001508950213,10.005763053894,2,20,10,5,2.38119702447376,0.20957791117991,0.0410455763339996,172.855895996094,47.4994277954102,47.5004463195801,339.537231445313,339.537231445313,,,93.5943984985352,0,1,,,,,,1,1,1,47.5000076293945,0,47.499888420105,,,,,,,,,,,,,,,,,,,,,,,,,,,,,,,,,
,3768734294.50987,47.5001239776611,339.537231445313,,,5,,,,25.0300001353025,,,,,0.000728002285132194,1.38802961402814E-7,-0.00670390033095814,0.000139125218423194,0.000727892529915817,1.38782035164842E-7,0.000727892524933319,9.49073140379933E-8,-8.5167162442678E-8,1.01257370233427E-7,1.00015078491929,10.005763053894,2,20,10,5,2.38143832908532,0.209617933522585,0.0410455763339996,172.855895996094,47.4987754821777,47.5011215209961,339.537231445313,339.537231445313,,,93.7436447143555,0,1,,,,,,1,1,1,47.4993019104004,0,47.4995655260588,,,,,,,,,,,,,,,,,,,,,,,,,,,,,,,,,
,3768734499.64263,47.5002975463867,339.537231445313,,,5,,,,25.0300001353025,,,,,0.00072817064882549,2.00805920866993E-7,-0.00866052585214572,0.000195446878082769,0.000728060778925978,2.00775622301152E-7,0.000728060770608706,1.41658708269381E-7,-1.10049801702609E-7,1.42280219573437E-7,1.00015090759273,10.005763053894,2,20,10,5,2.38199623882132,0.209585062666452,0.0410455763339996,172.855895996094,47.4995803833008,47.5006065368652,339.537231445313,339.537231445313,,,93.8928909301758,0,1,,,,,,1,1,1,47.5002937316895,0,47.5001086066751,,,,,,,,,,,,,,,,,,,,,,,,,,,,,,,,,
,3768734707.20847,47.5002994537354,339.537231445313,,,5,,,,25.0300001353025,,,,,0.000728083156809728,1.58829204446553E-7,-0.0131532905264695,0.000154256603758026,0.000727973300047889,1.5880523951628E-7,0.000727973280865221,1.12303300126946E-7,-1.6711953844264E-7,1.12281222287701E-7,1.00015090768004,10.005763053894,2,20,10,5,2.38172645937349,0.209373121904067,0.0410455763339996,172.855895996094,47.4995422363281,47.500560760498,339.537231445313,339.537231445313,,,94.054573059082,0,1,,,,,,1,1,1,47.5001907348633,0,47.5000329859117,,,,,,,,,,,,,,,,,,,,,,,,,,,,,,,,,
,3768734913.45675,47.5006580352783,339.537231445313,,,5,,,,25.0300001353025,,,,,0.000728284331338453,1.31979716437254E-7,-0.0122893376265099,0.000114559440024096,0.000728174515803025,1.31959815661413E-7,0.000728174499052934,1.0225948352178E-7,-1.56185717048576E-7,8.34049817412179E-8,1.00015080936375,10.005763053894,2,20,10,5,2.38238138919154,0.209466894642441,0.0410455763339996,172.855895996094,47.4998931884766,47.5010604858398,339.537231445313,339.537231445313,,,94.2038192749023,0,1,,,,,,1,1,1,47.500617980957,0,47.5005369186401,,,,,,,,,,,,,,,,,,,,,,,,,,,,,,,,,
,3768735120.09053,47.4998722076416,339.537231445313,,,5,,,,25.0300001353025,,,,,0.000728297368722705,1.42326652320325E-7,-0.00375924594153876,0.000152757326133339,0.000728187493877493,1.42305180158588E-7,0.000728187492310131,8.87652517157565E-8,-4.77772691520703E-8,1.11227219635333E-7,1.00015088812447,10.005763053894,2,20,10,5,2.38239282506346,0.209825336658807,0.0410455763339996,172.855895996094,47.4997024536133,47.5005722045898,339.537231445313,339.537231445313,,,94.3655014038086,0,1,,,,,,1,1,1,47.4998741149902,0,47.5000172783347,,,,,,,,,,,,,,,,,,,,,,,,,,,,,,,,,
,3768735326.4168,47.5013847351074,339.537231445313,,,5,,,,25.0300001353025,,,,,0.000728546032337903,2.87657017556357E-7,-0.00609068360463816,0.000154655781256379,0.000728436153115931,2.87613633160751E-7,0.000728436149000188,2.64661957533359E-7,-7.7434571344648E-8,1.12586190159083E-7,1.00015084262567,10.005763053894,2,20,10,5,2.38321478853545,0.209799994299427,0.0410455763339996,172.855895996094,47.5001258850098,47.5016021728516,339.537231445313,339.537231445313,,,94.5271835327148,0,1,,,,,,1,1,1,47.5014190673828,0,47.5007514953613,,,,,,,,,,,,,,,,,,,,,,,,,,,,,,,,,
,3768735535.68481,47.5001926422119,339.537231445313,,,5,,,,25.0300001353025,,,,,0.000728372048035566,2.03430077307179E-7,-0.00229923747878313,0.000176410340559909,0.000728262151244259,2.0339938377245E-7,0.000728262150657877,1.5770851912497E-7,-2.92246243318549E-8,1.28449726797769E-7,1.00015090279114,10.005763053894,2,20,10,5,2.38263176670092,0.209907564713485,0.0410455763339996,172.855895996094,47.4997825622559,47.5003089904785,339.537231445313,339.537231445313,,,94.6764221191406,0,1,,,,,,1,1,1,47.5001907348633,0,47.5001023610433,,,,,,,,,,,,,,,,,,,,,,,,,,,,,,,,,
,3768735742.25898,47.5008430480957,339.537231445313,,,5,,,,25.0300001353025,,,,,0.000728636083637194,1.7985385985849E-7,-0.00803172818913467,0.000119738498658954,0.000728526208893806,1.7982673877961E-7,0.000728526201735869,1.57269466913457E-7,-1.02124877592358E-7,8.72007497494551E-8,1.00015081783201,10.005763053894,2,20,10,5,2.38351647050632,0.20974518156521,0.0410455763339996,172.855895996094,47.4992980957031,47.5011940002441,339.537231445313,339.537231445313,,,94.8505477905273,0,1,,,,,,1,1,1,47.5008277893066,0,47.5002661810981,,,,,,,,,,,,,,,,,,,,,,,,,,,,,,,,,
,3768735947.74036,47.5003261566162,339.537231445313,,,5,,,,25.0300001353025,,,,,0.000728795440694389,2.10048683519378E-7,-0.00644904228723764,0.00019920237964157,0.000728685475569179,2.10016990085949E-7,0.00072868547095329,1.5179731930374E-7,-8.20186665764067E-8,1.45136866360549E-7,1.00015090890226,10.005763053894,2,20,10,5,2.38403196357356,0.209856910874227,0.0410455763339996,172.855895996094,47.4995994567871,47.500373840332,339.537231445313,339.537231445313,,,94.9873504638672,0,1,,,,,,1,1,1,47.5003318786621,0,47.4999939413632,,,,,,,,,,,,,,,,,,,,,,,,,,,,,,,,,
,3768736154.09672,47.4989070892334,339.537231445313,,,5,,,,25.0300001353025,,,,,0.000728748962006575,2.67260532421134E-7,-0.00818900481242402,0.000274423572443942,0.000728639051214086,2.6722022386709E-7,0.000728639043771919,1.77291065373627E-7,-1.04140806309044E-7,1.99936305313122E-7,1.00015084394984,10.005763053894,2,20,10,5,2.38388629374615,0.20977113808827,0.0410455763339996,172.855895996094,47.4984474182129,47.5002403259277,339.537231445313,339.537231445313,,,95.1365966796875,0,1,,,,,,1,1,1,47.4993591308594,0,47.4994515811696,,,,,,,,,,,,,,,,,,,,,,,,,,,,,,,,,
,3768736360.45907,47.5009269714355,339.537231445313,,,5,,,,25.0300001353025,,,,,0.000728799375253918,1.83899252690957E-7,-0.00492494967135748,0.000156389424393601,0.000728689473088284,1.83871520880509E-7,0.00072868947039631,1.44315385551281E-7,-6.26356602019718E-8,1.13937727220164E-7,1.00015082167328,10.005763053894,2,20,10,5,2.38403925122096,0.209921459332874,0.0410455763339996,172.855895996094,47.4997024536133,47.5018119812012,339.537231445313,339.537231445313,,,95.2982788085938,0,1,,,,,,1,1,1,47.5005493164063,0,47.5004336039225,,,,,,,,,,,,,,,,,,,,,,,,,,,,,,,,,
,3768736565.46736,47.5014991760254,339.537231445313,,,5,,,,25.0300001353025,,,,,0.000729038515822652,2.50213474752856E-7,-0.00339476751367407,0.000212489961182528,0.000728928558506758,2.50175736277471E-7,0.000728928557227289,1.96484582347531E-7,-4.31889226360061E-8,1.54860285165988E-7,1.00015084786377,10.005763053894,2,20,10,5,2.38481591614865,0.210054027626907,0.0410455763339996,172.855895996094,47.499927520752,47.5016632080078,339.537231445313,339.537231445313,,,95.4350891113281,0,1,,,,,,1,1,1,47.501335144043,0,47.500659942627,,,,,,,,,,,,,,,,,,,,,,,,,,,,,,,,,
,3768736720.02906,47.5014686584473,339.537231445313,,,5,,,,25.0300001353025,,,,,0.000728972551024696,3.7513035907208E-7,-0.0147257536731393,0.000310358460174419,0.000728862604675891,3.75073780517445E-7,0.000728862580603154,2.9921520828557E-7,-1.87327079779169E-7,2.26164983943739E-7,1.00015084646695,10.005763053894,2,20,10,5,2.38464162392916,0.209563432235899,0.0410455763339996,172.855895996094,47.4999198913574,47.501708984375,339.537231445313,339.537231445313,,,95.5967712402344,0,1,,,,,,1,1,1,47.5012283325195,0,47.5006590450511,,,,,,,,,,,,,,,,,,,,,,,,,,,,,,,,,