File: Experimental_Data/Fig3C/Lifetime_160Oe_49K.dat
[Header]
; MPMS3 Data File (default extension .dat)
; Copyright (c) 2007, Quantum Design, Inc. All rights reserved.
TITLE,160Oe_49K
FILEOPENTIME,3768165810.83781,05/28/2019,12:43 am
BYAPP,SQUID AC,0.9.1.0
INFO,MPMS3 Measurement Release 1.1.16 Build 347, MultiVu Release 2.3.3.2,APPNAME
INFO,0,MOMENT_UNITS
INFO,,SAMPLE_MATERIAL
INFO,,SAMPLE_COMMENT
INFO,,SAMPLE_MASS
INFO,,SAMPLE_VOLUME
INFO,,SAMPLE_MOLECULAR_WEIGHT
INFO,,SAMPLE_SIZE
INFO,,SAMPLE_SHAPE
INFO,Quartz,SAMPLE_HOLDER
INFO,Standard,SAMPLE_HOLDER_DETAIL
INFO,66.2,SAMPLE_OFFSET
DATATYPE,COMMENT,1
DATATYPE,TIME,2
STARTUPAXIS,X,2
STARTUPAXIS,Y1,5
FIELDGROUP, VSM,2,3,4,5,6,8,9,10,11,14,15
FIELDGROUP, DC, 2,3,4,14,56,57,58,59,60,61,62,63,64,65,66,67,68,69
FIELDGROUP, AC, 2,3,4,11,16,17,18,19,20,21,22,23,24,25,26,27,28,29,30
STARTUPGROUP, All
[Data]
Comment,Time Stamp (sec),Temperature (K),Magnetic Field (Oe),Moment (emu),M. Std. Err. (emu),Transport Action,Averaging Time (sec),Frequency (Hz),Peak Amplitude (mm),Center Position (mm),Lockin Signal' (V),Lockin Signal (V),Range,M. Quad. Signal (emu),AC Moment (emu),AC M. Std Err. (emu),AC Phase (deg),AC Phase Std. Err. (deg),AC Susceptibility (emu/Oe),AC Suscept. Std Err. (emu/Oe),AC X' (emu/Oe),AC X' Std Err. (emu/Oe),AC X'' (emu/Oe),AC X'' Std Err. (emu/Oe),AC Drive (Oe),AC Frequency (Hz),AC Averaging Time (sec),AC Cycles,AC Range,AC Measure Type,AC Signal' (V),AC Signal'' (V),AC Trim Coil Ratio,AC Trim Coil Phase,Min. Temperature (K),Max. Temperature (K),Min. Field (Oe),Max. Field (Oe),Mass (grams),Motor Lag (deg),Pressure (Torr),Measure Count,Measurement Number,SQUID Status (code),Motor Status (code),Measure Status (code),Motor Current (amps),Motor Temp. (C),Temp. Status (code),Field Status (code),Chamber Status (code),Chamber Temp (K),Redirection State,Average Temp (K),Rotation Angle (deg),Rotator state,DC Moment Fixed Ctr (emu),DC Moment Err Fixed Ctr (emu),DC Moment Free Ctr (emu),DC Moment Err Free Ctr (emu),DC Fixed Fit,DC Free Fit,DC Calculated Center (mm),DC Calculated Center Err (mm),DC Scan Length (mm),DC Scan Time (s),DC Number of Points,DC Squid Drift,DC Min V (V),DC Max V (V),DC Scans per Measure,Map 01,Map 02,Map 03,Map 04,Map 05,Map 06,Map 07,Map 08,Map 09,Map 10,Map 11,Map 12,Map 13,Map 14,Map 15,Map 16
,3768165814.82312,48.9752216339111,159.787231445313,,,5,,,,25.0300001353025,,,,,0.00056600629726129,1.18417968962842E-7,0.227561790370434,8.94643489880273E-5,0.000565921390065721,1.18400204959688E-7,0.000565916926530544,1.0707454850799E-7,2.24766548687957E-6,5.05336481594812E-8,1.0001500335507,10.005763053894,2,20,10,5,1.85085983025652,0.170181121876253,0.0410455763339996,172.855895996094,48.9137420654297,48.9875831604004,159.787231445313,159.787231445313,,,56.4571952819824,0,1,,,,,,1,1,1,48.9676055908203,0,48.9448880089654,,,,,,,,,,,,,,,,,,,,,,,,,,,,,,,,,
,3768166023.6543,48.9992904663086,159.787231445313,,,5,,,,25.0300001353025,,,,,0.000579937027101421,1.15745040742128E-7,0.0485412099324876,0.000132906305653605,0.000579849657565758,1.1572760334808E-7,0.000579849449470917,8.63472840339884E-8,4.91250853541407E-7,7.70520909297351E-8,1.00015067618739,10.005763053894,2,20,10,5,1.8969493600611,0.168443384250511,0.0410455763339996,172.855895996094,48.9986152648926,48.999641418457,159.787231445313,159.787231445313,,,57.0044288635254,0,1,,,,,,1,1,1,48.9989395141602,0,48.9991295758416,,,,,,,,,,,,,,,,,,,,,,,,,,,,,,,,,
,3768166231.34392,48.9997539520264,159.787231445313,,,5,,,,25.0300001353025,,,,,0.000586894557237849,8.42704523939184E-8,0.0360098265772049,0.00010994752666295,0.000586806194398216,8.42577646353102E-8,0.000586806078504077,5.41977828803061E-8,3.6880182245841E-7,6.45133415054477E-8,1.00015058266337,10.005763053894,2,20,10,5,1.91974438254576,0.170044333755976,0.0410455763339996,172.855895996094,48.9991569519043,49.0003700256348,159.787231445313,159.787231445313,,,57.4894752502441,0,1,,,,,,1,1,1,48.9996681213379,0,48.9997682010426,,,,,,,,,,,,,,,,,,,,,,,,,,,,,,,,,
,3768166436.47338,48.9998207092285,159.787231445313,,,5,,,,25.0300001353025,,,,,0.00059304807567795,7.18987255698409E-8,0.0311120784944752,8.84210558398669E-5,0.000592958784553209,7.18879002787106E-8,0.000592958697133917,4.91886605232277E-8,3.21981470523446E-7,5.24246686438026E-8,1.00015058571871,10.005763053894,2,20,10,5,1.93988735124023,0.171661403055289,0.0410455763339996,172.855895996094,48.999683380127,49.000072479248,159.787231445313,159.787231445313,,,57.9372062683105,0,1,,,,,,1,1,1,48.9998054504395,0,48.9998377631692,,,,,,,,,,,,,,,,,,,,,,,,,,,,,,,,,
,3768166642.70743,49.0004196166992,159.787231445313,,,5,,,,25.0300001353025,,,,,0.000598260868525027,8.47513898289627E-8,0.0347554267817243,8.69954930716657E-5,0.000598170776152431,8.47386270791452E-8,0.000598170666101133,6.68876938854624E-8,3.62848354891936E-7,5.20256794856456E-8,1.00015061312954,10.005763053894,2,20,10,5,1.95692761951505,0.173294713038344,0.0410455763339996,172.855895996094,49.0000610351562,49.0006637573242,159.787231445313,159.787231445313,,,58.3600730895996,0,1,,,,,,1,1,1,49.0007095336914,0,49.0002939436171,,,,,,,,,,,,,,,,,,,,,,,,,,,,,,,,,
,3768166849.31974,49.0002498626709,159.787231445313,,,5,,,,25.0300001353025,,,,,0.000602977164663228,1.05997873501238E-7,0.0271475562096768,9.7708647044726E-5,0.000602886366744786,1.05981912057195E-7,0.000602886299070812,8.81157309824513E-8,2.85656134813918E-7,5.88878904081921E-8,1.00015060536023,10.005763053894,2,20,10,5,1.97237792717775,0.174398960976304,0.0410455763339996,172.855895996094,48.9997444152832,49.0004501342773,159.787231445313,159.787231445313,,,58.7829322814941,0,1,,,,,,1,1,1,49.000244140625,0,49.0001337387983,,,,,,,,,,,,,,,,,,,,,,,,,,,,,,,,,
,3768167054.50986,49.0007820129395,159.787231445313,,,5,,,,25.0300001353025,,,,,0.000607518217673074,7.70941116819967E-8,0.0264124327380877,9.31653803882086E-5,0.000607426721158751,7.708250076682E-8,0.000607426656617789,5.23429842211098E-8,2.80013937920706E-7,5.6585545215147E-8,1.00015062971571,10.005763053894,2,20,10,5,1.98723426442004,0.175686870051898,0.0410455763339996,172.855895996094,48.9997634887695,49.0007858276367,159.787231445313,159.787231445313,,,59.1809196472168,0,1,,,,,,1,1,1,49.0007781982422,0,49.0003343469956,,,,,,,,,,,,,,,,,,,,,,,,,,,,,,,,,
,3768167262.10158,48.999870300293,159.787231445313,,,5,,,,25.0300001353025,,,,,0.000611430833477839,5.82475687952177E-8,0.0300803665317675,6.4223236162216E-5,0.000611338773201751,5.82387987316698E-8,0.000611338688951167,4.30200622131773E-8,3.20953719183245E-7,3.92559794793391E-8,1.0001505879884,10.005763053894,2,20,10,5,2.00002137847319,0.176946390882661,0.0410455763339996,172.855895996094,48.9995422363281,49.0002784729004,159.787231445313,159.787231445313,,,59.5913429260254,0,1,,,,,,1,1,1,48.9998817443848,0,48.9998554653592,,,,,,,,,,,,,,,,,,,,,,,,,,,,,,,,,
,3768167470.0542,49.0004405975342,159.787231445313,,,5,,,,25.0300001353025,,,,,0.000615277957616448,6.96822435657371E-8,0.0269357719059915,6.06141158737949E-5,0.000615185302042126,6.96717500185237E-8,0.000615185234060816,5.88618499481246E-8,2.89209615545335E-7,3.72751307352251E-8,1.00015061408979,10.005763053894,2,20,10,5,2.01261528693169,0.177949278081273,0.0410455763339996,172.855895996094,48.9996719360352,49.0009574890137,159.787231445313,159.787231445313,,,59.9768943786621,0,1,,,,,,1,1,1,49.0000801086426,0,49.0001305028012,,,,,,,,,,,,,,,,,,,,,,,,,,,,,,,,,
,3768167675.93306,48.9999485015869,159.787231445313,,,5,,,,25.0300001353025,,,,,0.0006189061083907,8.47033919275316E-8,0.0221303090949601,8.06910077472642E-5,0.000618812920383016,8.46906382315659E-8,0.000618812874223732,6.84144318711636E-8,2.39014478481749E-7,4.9919632568919E-8,1.00015059156752,10.005763053894,2,20,10,5,2.02449821611596,0.17882880693496,0.0410455763339996,172.855895996094,48.9996452331543,49.0002899169922,159.787231445313,159.787231445313,,,60.3748817443848,0,1,,,,,,1,1,1,49.0001411437988,0,48.9999775606043,,,,,,,,,,,,,,,,,,,,,,,,,,,,,,,,,
,3768167881.86556,49.0001678466797,159.787231445313,,,5,,,,25.0300001353025,,,,,0.000622369101762365,8.95755061620827E-8,0.023613495283576,0.000121764467831216,0.000622275386089523,8.95620179782921E-8,0.000622275333241602,4.77535765160768E-8,2.56460364156152E-7,7.576906356995E-8,1.00015060160652,10.005763053894,2,20,10,5,2.03582132671049,0.179882117366373,0.0410455763339996,172.855895996094,48.9991683959961,49.0006217956543,159.787231445313,159.787231445313,,,60.7479972839356,0,1,,,,,,1,1,1,48.999813079834,0,48.9996831681993,,,,,,,,,,,,,,,,,,,,,,,,,,,,,,,,,
,3768168090.44273,49.0002326965332,159.787231445313,,,5,,,,25.0300001353025,,,,,0.000625463213555119,8.01907771132406E-8,0.0258663633294738,8.07274291007075E-5,0.000625369030118389,8.01787018339613E-8,0.00062536896639016,6.22977313656478E-8,2.82324843750086E-7,5.04739229154309E-8,1.00015060457457,10.005763053894,2,20,10,5,2.04593531534817,0.180856846725729,0.0410455763339996,172.855895996094,48.9991874694824,49.0006484985352,159.787231445313,159.787231445313,,,61.1211051940918,0,1,,,,,,1,1,1,49.0003395080566,0,48.9998144261977,,,,,,,,,,,,,,,,,,,,,,,,,,,,,,,,,
,3768168295.886,49.0000152587891,159.787231445313,,,5,,,,25.0300001353025,,,,,0.000628659218787632,9.70143764633138E-8,0.0223630071103331,7.37004760709557E-5,0.000628564560344718,9.699976881971E-8,0.000628564512466825,8.52352266320318E-8,2.45333836014657E-7,4.6302389701433E-8,1.00015059462287,10.005763053894,2,20,10,5,2.05640079017146,0.181655255969256,0.0410455763339996,172.855895996094,48.9995307922363,49.0002975463867,159.787231445313,159.787231445313,,,61.5066566467285,0,1,,,,,,1,1,1,48.9999122619629,0,48.999844789505,,,,,,,,,,,,,,,,,,,,,,,,,,,,,,,,,
,3768168500.97895,49.0013217926025,159.787231445313,,,5,,,,25.0300001353025,,,,,0.000631511899962628,7.18860228268839E-8,0.0221468691058453,7.38645585022779E-5,0.000631416774234492,7.18751945111156E-8,0.00063141672706453,5.46955790396286E-8,2.44065172353421E-7,4.66308612351353E-8,1.00015065442037,10.005763053894,2,20,10,5,2.06573285542062,0.182471759504776,0.0410455763339996,172.855895996094,48.9996147155762,49.0016136169434,159.787231445313,159.787231445313,,,61.8797721862793,0,1,,,,,,1,1,1,49.0012702941895,0,49.0005322624655,,,,,,,,,,,,,,,,,,,,,,,,,,,,,,,,,
,3768168707.87668,48.9994316101074,159.787231445313,,,5,,,,25.0300001353025,,,,,0.000634515844485079,5.78900652209558E-8,0.0281544562695926,6.53852228332281E-5,0.000634420248362574,5.78813435068887E-8,0.000634420171768344,4.03721444574294E-8,3.11746459722514E-7,4.14769800982532E-8,1.00015068264727,10.005763053894,2,20,10,5,2.07553979558598,0.183557364335659,0.0410455763339996,172.855895996094,48.9989280700684,49.000129699707,159.787231445313,159.787231445313,,,62.265323638916,0,1,,,,,,1,1,1,48.999568939209,0,48.9995417875402,,,,,,,,,,,,,,,,,,,,,,,,,,,,,,,,,
,3768168914.22291,49.000072479248,159.787231445313,,,5,,,,25.0300001353025,,,,,0.000637171080727,6.89816680658111E-8,0.0189818874725161,6.85326867952904E-5,0.000637075138968292,6.89712811811061E-8,0.00063707510400646,5.3399941594678E-8,2.11060718276093E-7,4.36518483623338E-8,1.00015059724174,10.005763053894,2,20,10,5,2.0842547166713,0.18399181991256,0.0410455763339996,172.855895996094,48.9994049072266,49.0002174377441,159.787231445313,159.787231445313,,,62.6508750915527,0,1,,,,,,1,1,1,48.999927520752,0,48.9997471080107,,,,,,,,,,,,,,,,,,,,,,,,,,,,,,,,,
,3768169119.33911,49.0005168914795,159.787231445313,,,5,,,,25.0300001353025,,,,,0.000639851151075494,6.3509401148338E-8,0.0182168802732914,6.78978508221273E-5,0.00063975479275578,6.34998369564625E-8,0.000639754760419781,4.63239649170417E-8,2.03406540003207E-7,4.34317806204398E-8,1.00015061758162,10.005763053894,2,20,10,5,2.09302398023121,0.184737778957825,0.0410455763339996,172.855895996094,48.9998588562012,49.0008850097656,159.787231445313,159.787231445313,,,63.0115470886231,0,1,,,,,,1,1,1,49.0004386901855,0,49.000347773234,,,,,,,,,,,,,,,,,,,,,,,,,,,,,,,,,
,3768169324.42358,49.0000133514404,159.787231445313,,,5,,,,25.0300001353025,,,,,0.000642483204385446,7.12321927041648E-8,0.0219076597658683,8.23226821019482E-5,0.000642386390799863,7.12214589699013E-8,0.00064238634384149,4.77117153865167E-8,2.45623364662281E-7,5.28780524667595E-8,1.00015070927244,10.005763053894,2,20,10,5,2.10162176456357,0.185633085555098,0.0410455763339996,172.855895996094,48.9996032714844,49.0018653869629,159.787231445313,159.787231445313,,,63.3846626281738,0,1,,,,,,1,1,1,49.0000762939453,0,49.0005686142865,,,,,,,,,,,,,,,,,,,,,,,,,,,,,,,,,
,3768169529.91588,49.0003147125244,159.787231445313,,,5,,,,25.0300001353025,,,,,0.000644807903598962,7.47973490346889E-8,0.0182728071673219,6.39867212367648E-5,0.000644710804782428,7.47860856273538E-8,0.000644710771995538,6.23877491817384E-8,2.05611584568555E-7,4.12398757939255E-8,1.00015060832828,10.005763053894,2,20,10,5,2.10923788490778,0.186170951905457,0.0410455763339996,172.855895996094,48.9997177124023,49.0004081726074,159.787231445313,159.787231445313,,,63.7702140808105,0,1,,,,,,1,1,1,49.0002098083496,0,49.0001597934299,,,,,,,,,,,,,,,,,,,,,,,,,,,,,,,,,
,3768169736.15519,49.0006504058838,159.787231445313,,,5,,,,25.0300001353025,,,,,0.000647075354735089,9.06295019903689E-8,0.0191325708880763,9.59361068417936E-5,0.000646977904534264,9.06158530959936E-8,0.000646977868463042,6.6028959292497E-8,2.16042970296782E-7,6.20597241942345E-8,1.00015062369231,10.005763053894,2,20,10,5,2.11665216453072,0.186857377598082,0.0410455763339996,172.855895996094,49.0000305175781,49.000904083252,159.787231445313,159.787231445313,,,64.1184539794922,0,1,,,,,,1,1,1,49.000675201416,0,49.000417470932,,,,,,,,,,,,,,,,,,,,,,,,,,,,,,,,,
,3768169942.56218,49.0019435882568,159.787231445313,,,5,,,,25.0300001353025,,,,,0.000649309755391008,7.90186511813938E-8,0.0237412716107075,5.90609507452529E-5,0.000649211930268438,7.90067462174333E-8,0.000649211874534571,6.90890201175331E-8,2.69009627922614E-7,3.83245775849521E-8,1.00015068287875,10.005763053894,2,20,10,5,2.12394603771105,0.187673449328222,0.0410455763339996,172.855895996094,49.0005989074707,49.0022163391113,159.787231445313,159.787231445313,,,64.491569519043,0,1,,,,,,1,1,1,49.0021286010742,0,49.0013082167682,,,,,,,,,,,,,,,,,,,,,,,,,,,,,,,,,
,3768170148.74092,49.0006675720215,159.787231445313,,,5,,,,25.0300001353025,,,,,0.000651557352059326,6.03959109524458E-8,0.0182839321850796,6.50037278567868E-5,0.000651459226353436,6.03868152199269E-8,0.000651459193183,4.30549747933724E-8,2.07890288168764E-7,4.23419012084679E-8,1.00015062447797,10.005763053894,2,20,10,5,2.13131604010524,0.188120085407704,0.0410455763339996,172.855895996094,48.9997138977051,49.0008544921875,159.787231445313,159.787231445313,,,64.8646774291992,0,1,,,,,,1,1,1,49.0007781982422,0,49.0003415276023,,,,,,,,,,,,,,,,,,,,,,,,,,,,,,,,,
,3768170353.95738,48.9998950958252,159.787231445313,,,5,,,,25.0300001353025,,,,,0.000653527864107464,4.69876655919864E-8,0.0205398487997046,5.54448000499099E-5,0.000653429464737267,4.69805908260044E-8,0.000653429422749969,2.99133298295093E-8,2.34246610021947E-7,3.62266285054438E-8,1.00015058912324,10.005763053894,2,20,10,5,2.13775437135589,0.188773192580814,0.0410455763339996,172.855895996094,48.9992523193359,48.9999809265137,159.787231445313,159.787231445313,,,65.23779296875,0,1,,,,,,1,1,1,48.9999389648438,0,48.9997015560375,,,,,,,,,,,,,,,,,,,,,,,,,,,,,,,,,
,3768170559.36971,49.0006656646729,159.787231445313,,,5,,,,25.0300001353025,,,,,0.000655390463420557,8.69466696181298E-8,0.0195401743606309,6.09938071251105E-5,0.000655291760498416,8.69335753013206E-8,0.000655291722390402,7.72118749765716E-8,2.23480946028281E-7,3.99471260201864E-8,1.00015062439068,10.005763053894,2,20,10,5,2.14385042118319,0.189273800855826,0.0410455763339996,172.855895996094,48.9997444152832,49.0007781982422,159.787231445313,159.787231445313,,,65.5984725952148,0,1,,,,,,1,1,1,49.0007858276367,0,49.0002602471246,,,,,,,,,,,,,,,,,,,,,,,,,,,,,,,,,
,3768170767.78131,49.0003910064697,159.787231445313,,,5,,,,25.0300001353025,,,,,0.000657425252585259,6.89954350245023E-8,0.0221409541974493,7.51952524221802E-5,0.000657326251482119,6.89850450613054E-8,0.000657326202402817,4.81288387448503E-8,2.54012253403459E-7,4.94221744076739E-8,1.00015061182011,10.005763053894,2,20,10,5,2.15049780768221,0.189959057031013,0.0410455763339996,172.855895996094,48.9995040893555,49.0006484985352,159.787231445313,159.787231445313,,,65.9591445922852,0,1,,,,,,1,1,1,49.000186920166,0,49.0002047220866,,,,,,,,,,,,,,,,,,,,,,,,,,,,,,,,,
,3768170974.49985,48.9995708465576,159.787231445313,,,5,,,,25.0300001353025,,,,,0.000659268517701292,9.39141323957603E-8,0.0195858498870836,8.90522089908204E-5,0.000659169263762033,9.38999934715708E-8,0.000659169225249106,7.33000285789695E-8,2.2532881319537E-7,5.86882831942058E-8,1.00015057428299,10.005763053894,2,20,10,5,2.15653578816181,0.190395489376491,0.0410455763339996,172.855895996094,48.9993286132812,48.9999732971191,159.787231445313,159.787231445313,,,66.31982421875,0,1,,,,,,1,1,1,48.9995384216309,0,48.9995545779958,,,,,,,,,,,,,,,,,,,,,,,,,,,,,,,,,
,3768171179.737,49.0004901885986,159.787231445313,,,5,,,,25.0300001353025,,,,,0.000660821959310052,5.91870085479694E-8,0.0168931826246688,5.37549470616621E-5,0.000660722443700955,5.91780953586856E-8,0.000660722414982125,4.73411174081961E-8,1.94808497917227E-7,3.55086689813216E-8,1.00015061635948,10.005763053894,2,20,10,5,2.16162622378265,0.190742529818785,0.0410455763339996,172.855895996094,48.9994926452637,49.0008773803711,159.787231445313,159.787231445313,,,66.6556243896484,0,1,,,,,,1,1,1,49.0003509521484,0,49.0000805574305,,,,,,,,,,,,,,,,,,,,,,,,,,,,,,,,,
,3768171387.57176,48.9999656677246,159.787231445313,,,5,,,,25.0300001353025,,,,,0.000662759691083099,9.72435312845313E-8,0.0154608782825338,6.11133376093038E-5,0.000662659899569463,9.72288893572857E-8,0.000662659875443551,8.84060471984396E-8,1.78814286369633E-7,4.04700845612974E-8,1.00015059235318,10.005763053894,2,20,10,5,2.16796955333295,0.191247651380234,0.0410455763339996,172.855895996094,48.9991416931152,49.000373840332,159.787231445313,159.787231445313,,,66.9914245605469,0,1,,,,,,1,1,1,48.9998397827148,0,48.999771566952,,,,,,,,,,,,,,,,,,,,,,,,,,,,,,,,,
,3768171593.23788,49.0008373260498,159.787231445313,,,5,,,,25.0300001353025,,,,,0.000664383513954277,7.3146424473585E-8,0.0173427873015317,5.88770409928813E-5,0.000664283451445153,7.31354079227335E-8,0.000664283421014171,6.18075402709702E-8,2.01071117773881E-7,3.90975172827769E-8,1.00015063224728,10.005763053894,2,20,10,5,2.17327498250526,0.191787604306837,0.0410455763339996,172.855895996094,49.0001564025879,49.0009613037109,159.787231445313,159.787231445313,,,67.3396682739258,0,1,,,,,,1,1,1,49.0008735656738,0,49.0005338332232,,,,,,,,,,,,,,,,,,,,,,,,,,,,,,,,,
,3768171798.15442,48.9998321533203,159.787231445313,,,5,,,,25.0300001353025,,,,,0.000665923039398974,1.02931000077939E-7,0.0166782266873318,9.34263241210859E-5,0.000665822775649025,1.02915502419135E-7,0.000665822747440322,8.19992791359825E-8,1.93814328444622E-7,6.21909869624393E-8,1.00015058624249,10.005763053894,2,20,10,5,2.17831317667883,0.19220675731378,0.0410455763339996,172.855895996094,48.9987716674805,49.0000991821289,159.787231445313,159.787231445313,,,67.7003402709961,0,1,,,,,,1,1,1,48.9998741149902,0,48.9996192034553,,,,,,,,,,,,,,,,,,,,,,,,,,,,,,,,,
,3768172003.29612,49.0000133514404,159.787231445313,,,5,,,,25.0300001353025,,,,,0.000667433653445873,7.05565227048676E-8,0.0161551592856295,4.75444651551979E-5,0.000667333156719064,7.05458988779895E-8,0.000667333130191955,6.30172859317181E-8,1.88161735334571E-7,3.17103377828682E-8,1.00015059453557,10.005763053894,2,20,10,5,2.18325633283199,0.192622837533954,0.0410455763339996,172.855895996094,48.9996299743652,49.0002250671387,159.787231445313,159.787231445313,,,68.0237045288086,0,1,,,,,,1,1,1,48.999870300293,0,48.999984516817,,,,,,,,,,,,,,,,,,,,,,,,,,,,,,,,,
,3768172208.55488,49.0001468658447,159.787231445313,,,5,,,,25.0300001353025,,,,,0.000668922021518438,9.28175253972669E-8,0.0172352450283624,0.000114726662015893,0.000668821296598933,9.28035491227931E-8,0.000668821266338875,5.22038669488607E-8,2.01189317104781E-7,7.67284497782427E-8,1.00015060064627,10.005763053894,2,20,10,5,2.18812132557966,0.193093631053414,0.0410455763339996,172.855895996094,48.9994812011719,49.0002861022949,159.787231445313,159.787231445313,,,68.359504699707,0,1,,,,,,1,1,1,49.000186920166,0,48.9998527975643,,,,,,,,,,,,,,,,,,,,,,,,,,,,,,,,,
,3768172413.55736,49.0009956359863,159.787231445313,,,5,,,,25.0300001353025,,,,,0.000670369587003567,7.06447815517876E-8,0.0181530211563965,6.39676301118308E-5,0.000670268618078886,7.06341412605723E-8,0.000670268584437688,5.61401671313034E-8,2.12361194913377E-7,4.286564528953E-8,1.00015063949282,10.005763053894,2,20,10,5,2.19285338006438,0.193546613316075,0.0410455763339996,172.855895996094,48.999885559082,49.0011711120605,159.787231445313,159.787231445313,,,68.7201843261719,0,1,,,,,,1,1,1,49.0010108947754,0,49.000508925494,,,,,,,,,,,,,,,,,,,,,,,,,,,,,,,,,
,3768172619.05654,49.0004844665527,159.787231445313,,,5,,,,25.0300001353025,,,,,0.000671972150008704,5.26317653411288E-8,0.0186272465278021,5.32498367513249E-5,0.000671870955427311,5.26238393438065E-8,0.000671870919920806,3.85959725704761E-8,2.1842980072021E-7,3.57717677592514E-8,1.00015061609759,10.005763053894,2,20,10,5,2.19809393543383,0.194027496672366,0.0410455763339996,172.855895996094,48.9997062683105,49.0009155273438,159.787231445313,159.787231445313,,,69.0559844970703,0,1,,,,,,1,1,1,48.9999580383301,0,49.0001612769233,,,,,,,,,,,,,,,,,,,,,,,,,,,,,,,,,
,3768172825.91096,49,159.787231445313,,,5,,,,25.0300001353025,,,,,0.0006731007622753,7.34723018197319E-8,0.0150730993872195,8.86045169849165E-5,0.00067299941265256,7.34612390034514E-8,0.000672999389363898,4.29078901832117E-8,1.7704946164709E-7,5.96277334463391E-8,1.0001505939245,10.005763053894,2,20,10,5,2.20179780054901,0.19421679625937,0.0410455763339996,172.855895996094,48.9994277954102,49.0004959106445,159.787231445313,159.787231445313,,,69.4166641235352,0,1,,,,,,1,1,1,48.9997329711914,0,48.9998313056098,,,,,,,,,,,,,,,,,,,,,,,,,,,,,,,,,
,3768173032.7578,49.0005950927734,159.787231445313,,,5,,,,25.0300001353025,,,,,0.00067436803045894,9.40423001308729E-8,0.0159924562072362,0.000121868095603918,0.000674266471660331,9.40281375036599E-8,0.000674266445394772,4.57098678646773E-8,1.88201940381254E-7,8.21699374601254E-8,1.00015062116074,10.005763053894,2,20,10,5,2.20594007295997,0.194617847433276,0.0410455763339996,172.855895996094,48.999683380127,49.0009002685547,159.787231445313,159.787231445313,,,69.7524642944336,0,1,,,,,,1,1,1,49.0005073547363,0,49.0001792907715,,,,,,,,,,,,,,,,,,,,,,,,,,,,,,,,,
,3768173239.63527,49.0008602142334,159.787231445313,,,5,,,,25.0300001353025,,,,,0.000675806386390039,5.22730333113597E-8,0.016702800615132,6.0228843617904E-5,0.000675704602779389,5.2265160438038E-8,0.000675704574067603,3.27969429018143E-8,1.96980636113317E-7,4.06940724419293E-8,1.00015063329483,10.005763053894,2,20,10,5,2.21064269252955,0.195060353382944,0.0410455763339996,172.855895996094,48.9998817443848,49.0011825561523,159.787231445313,159.787231445313,,,70.1131362915039,0,1,,,,,,1,1,1,49.0006675720215,0,49.0004074994255,,,,,,,,,,,,,,,,,,,,,,,,,,,,,,,,,
,3768173445.72622,49.0001220703125,159.787231445313,,,5,,,,25.0300001353025,,,,,0.000676841331565035,5.45425013607916E-8,0.0179092676890873,4.97858076186673E-5,0.000676739414939784,5.45342885235841E-8,0.000676739381879859,4.28873541094632E-8,2.11532284638625E-7,3.36847663234142E-8,1.00015059951142,10.005763053894,2,20,10,5,2.21402400643797,0.195405695176569,0.0410455763339996,172.855895996094,48.9994773864746,49.0002708435059,159.787231445313,159.787231445313,,,70.4489440917969,0,1,,,,,,1,1,1,49.0002632141113,0,48.999871995714,,,,,,,,,,,,,,,,,,,,,,,,,,,,,,,,,
,3768173652.69445,49.0005493164063,159.787231445313,,,5,,,,25.0300001353025,,,,,0.000678154531715683,5.22759810986984E-8,0.0168672771873872,5.04789670502851E-5,0.00067805240409612,5.22681085250294E-8,0.00067805237471435,3.95074979355858E-8,1.99611520769263E-7,3.42215250340183E-8,1.00015061906564,10.005763053894,2,20,10,5,2.21832319185954,0.195744475909713,0.0410455763339996,172.855895996094,48.9992218017578,49.0008964538574,159.787231445313,159.787231445313,,,70.7723083496094,0,1,,,,,,1,1,1,49.0003890991211,0,49.0000383713666,,,,,,,,,,,,,,,,,,,,,,,,,,,,,,,,,
,3768173860.33442,49.0001220703125,159.787231445313,,,5,,,,25.0300001353025,,,,,0.000679360884912782,5.7618159361529E-8,0.0168120924878767,5.5498949860889E-5,0.000679258510976905,5.76094767925398E-8,0.000679258481735155,4.35682268932109E-8,1.99312354991907E-7,3.76916624957281E-8,1.00015071424829,10.005763053894,2,20,10,5,2.22226950383517,0.196090540870636,0.0410455763339996,172.855895996094,48.9995613098145,49.0003662109375,159.787231445313,159.787231445313,,,71.1205444335938,0,1,,,,,,1,1,1,49.0003662109375,0,48.9999560187845,,,,,,,,,,,,,,,,,,,,,,,,,,,,,,,,,
,3768174065.62353,48.9993343353271,159.787231445313,,,5,,,,25.0300001353025,,,,,0.000680325056994375,8.94423172860924E-8,0.0184966454868114,0.00010581822550479,0.000680222640321214,8.94288525687752E-8,0.00068022260487566,5.30749731817705E-8,2.19594478310749E-7,7.19761550343033E-8,1.00015056345833,10.005763053894,2,20,10,5,2.22541764953454,0.196434273111322,0.0410455763339996,172.855895996094,48.9985580444336,49.0000534057617,159.787231445313,159.787231445313,,,71.4439086914062,0,1,,,,,,1,1,1,48.9992904663086,0,48.9994269476997,,,,,,,,,,,,,,,,,,,,,,,,,,,,,,,,,
,3768174276.16149,49.0003509521484,159.787231445313,,,5,,,,25.0300001353025,,,,,0.000681344307084838,8.1430362822887E-8,0.015619571509788,8.75439495616025E-5,0.00068124170528053,8.14181004438458E-8,0.000681241679966331,5.54334626832454E-8,1.85715309045592E-7,5.96325271544766E-8,1.0001506099869,10.005763053894,2,20,10,5,2.22876160401793,0.196616649383293,0.0410455763339996,172.855895996094,48.9991912841797,49.001106262207,159.787231445313,159.787231445313,,,71.7797088623047,0,1,,,,,,1,1,1,48.9998207092285,0,48.9997614692239,,,,,,,,,,,,,,,,,,,,,,,,,,,,,,,,,
,3768174483.00473,49.0005645751953,159.787231445313,,,5,,,,25.0300001353025,,,,,0.000682596923337544,7.2298471719552E-8,0.0148672205164599,6.19800494289145E-5,0.000682494126233313,7.22875837807422E-8,0.000682494103256847,5.8626214198044E-8,1.77094903817778E-7,4.22902090047198E-8,1.00015061976401,10.005763053894,2,20,10,5,2.2328616534881,0.196948796339029,0.0410455763339996,172.855895996094,48.9999122619629,49.0009155273438,159.787231445313,159.787231445313,,,72.1155166625977,0,1,,,,,,1,1,1,49.0005416870117,0,49.0002670288086,,,,,,,,,,,,,,,,,,,,,,,,,,,,,,,,,
,3768174689.60989,48.9999961853027,159.787231445313,,,5,,,,25.0300001353025,,,,,0.000683418925779127,6.38275997746946E-8,0.0191830546082477,4.96407891163762E-5,0.0006833160226569,6.38179891843914E-8,0.000683315984358391,5.40644759975755E-8,2.28779300043048E-7,3.39082317239735E-8,1.00015059374991,10.005763053894,2,20,10,5,2.23553566846861,0.197354365924605,0.0410455763339996,172.855895996094,48.9977264404297,49.0010643005371,159.787231445313,159.787231445313,,,72.4513168334961,0,1,,,,,,1,1,1,48.9993286132812,0,48.9987573062672,,,,,,,,,,,,,,,,,,,,,,,,,,,,,,,,,
,3768174894.70903,49.0008239746094,159.787231445313,,,5,,,,25.0300001353025,,,,,0.000684431893202326,7.9857781738455E-8,0.0189401547111778,6.8620197645614E-5,0.000684328811633721,7.98457544418186E-8,0.000684328774243623,6.45860209065286E-8,2.26217243918317E-7,4.69466761959209E-8,1.00015063163621,10.005763053894,2,20,10,5,2.23885003054714,0.197637388790876,0.0410455763339996,172.855895996094,48.9996452331543,49.0013008117676,159.787231445313,159.787231445313,,,72.7871170043945,0,1,,,,,,1,1,1,49.0007019042969,0,49.0002786972943,,,,,,,,,,,,,,,,,,,,,,,,,,,,,,,,,
,3768175102.88504,49.0008697509766,159.787231445313,,,5,,,,25.0300001353025,,,,,0.000685497913711199,6.8506337043617E-8,0.017162883671932,6.16078385162791E-5,0.000685394670154614,6.84960192326601E-8,0.000685394639404554,5.39394738008172E-8,2.05309167922569E-7,4.22165585619185E-8,1.00015063373131,10.005763053894,2,20,10,5,2.24234323683883,0.197875658520984,0.0410455763339996,172.855895996094,48.9995994567871,49.001148223877,159.787231445313,159.787231445313,,,73.1353530883789,0,1,,,,,,1,1,1,49.0006980895996,0,49.0003821429084,,,,,,,,,,,,,,,,,,,,,,,,,,,,,,,,,
,3768175308.72996,48.9994850158691,159.787231445313,,,5,,,,25.0300001353025,,,,,0.000686738715092691,6.15257565100103E-8,0.0160061917352357,5.16228326076386E-5,0.000686635249397275,6.15164868925512E-8,0.000686635222603935,5.02845496892791E-8,1.91818933339786E-7,3.54364532952699E-8,1.00015068509155,10.005763053894,2,20,10,5,2.24640604330548,0.198188481422557,0.0410455763339996,172.855895996094,48.9991683959961,49.0005989074707,159.787231445313,159.787231445313,,,73.4462814331055,0,1,,,,,,1,1,1,48.9996871948242,0,49.0000383477462,,,,,,,,,,,,,,,,,,,,,,,,,,,,,,,,,
,3768175516.01744,48.9995861053467,159.787231445313,,,5,,,,25.0300001353025,,,,,0.000687871480936556,5.00700378221882E-8,0.0155637459948208,5.27481318435532E-5,0.000687767920294782,5.00624996622351E-8,0.000687767894920433,3.45023114724807E-8,1.86824320642502E-7,3.62745692667358E-8,1.00015057498135,10.005763053894,2,20,10,5,2.25011299120301,0.19849801647882,0.0410455763339996,172.855895996094,48.9985885620117,49.0003280639648,159.787231445313,159.787231445313,,,73.757209777832,0,1,,,,,,1,1,1,48.9992866516113,0,48.9997488657633,,,,,,,,,,,,,,,,,,,,,,,,,,,,,,,,,
,3768175727.97905,49.0001430511475,159.787231445313,,,5,,,,25.0300001353025,,,,,0.000688422967376827,8.40395677457292E-8,0.0178967692891634,0.000103249796391747,0.000688319306164655,8.40269132529599E-8,0.000688319272585949,4.48336833049697E-8,2.15001728296171E-7,7.10666095443572E-8,1.00015060047168,10.005763053894,2,20,10,5,2.2519088810326,0.198748851250549,0.0410455763339996,172.855895996094,48.9993171691895,49.0005760192871,159.787231445313,159.787231445313,,,74.1054534912109,0,1,,,,,,1,1,1,48.9998626708984,0,48.9999342525707,,,,,,,,,,,,,,,,,,,,,,,,,,,,,,,,,
,3768175937.67495,48.9995403289795,159.787231445313,,,5,,,,25.0300001353025,,,,,0.000689343298009504,6.6815866455765E-8,0.014589132094522,6.48725344996129E-5,0.000689239438156806,6.68057996486052E-8,0.000689239415813174,4.96428173941524E-8,1.75499926605759E-7,4.47057663826538E-8,1.00015068762312,10.005763053894,2,20,10,5,2.25493087106249,0.198884378052316,0.0410455763339996,172.855895996094,48.9992027282715,49.0001564025879,159.787231445313,159.787231445313,,,74.4412536621094,0,1,,,,,,1,1,1,48.9996757507324,0,48.9997127757353,,,,,,,,,,,,,,,,,,,,,,,,,,,,,,,,,
,3768176145.60438,49.0006294250488,159.787231445313,,,5,,,,25.0300001353025,,,,,0.000689972363408738,6.43068876692982E-8,0.0167623183227334,4.44839935774206E-5,0.000689868453537503,6.42972030489111E-8,0.000689868424014592,5.65090189851293E-8,2.01826287247033E-7,3.0673459101497E-8,1.00015062273206,10.005763053894,2,20,10,5,2.25698107345324,0.199151473378208,0.0410455763339996,172.855895996094,48.9998245239258,49.0008735656738,159.787231445313,159.787231445313,,,74.7770538330078,0,1,,,,,,1,1,1,49.0006294250488,0,49.0003810209386,,,,,,,,,,,,,,,,,,,,,,,,,,,,,,,,,
,3768176354.39537,49.0000743865967,159.787231445313,,,5,,,,25.0300001353025,,,,,0.000691322261167795,7.6711481256245E-8,0.0153153780621009,9.76347116701271E-5,0.000691218165558282,7.6699930451582E-8,0.000691218140864062,3.64494632255609E-8,1.84765221676279E-7,6.74856722708309E-8,1.00015059732903,10.005763053894,2,20,10,5,2.26140178663976,0.199483997297318,0.0410455763339996,172.855895996094,48.9992218017578,49.0003318786621,159.787231445313,159.787231445313,,,75.1004180908203,0,1,,,,,,1,1,1,48.9999580383301,0,48.9997963375515,,,,,,,,,,,,,,,,,,,,,,,,,,,,,,,,,
,3768176561.4669,49.0004940032959,159.787231445313,,,5,,,,25.0300001353025,,,,,0.000691958719820313,9.03133397281687E-8,0.0183125309818166,8.23323412339727E-5,0.000691854515091169,9.02997390944388E-8,0.000691854479753633,7.00761579427834E-8,2.21126357551647E-7,5.69506362431694E-8,1.00015061653407,10.005763053894,2,20,10,5,2.26347327515445,0.1997860507176,0.0410455763339996,172.855895996094,49.0000038146973,49.000659942627,159.787231445313,159.787231445313,,,75.4362182617187,0,1,,,,,,1,1,1,49.0005569458008,0,49.000389772303,,,,,,,,,,,,,,,,,,,,,,,,,,,,,,,,,
,3768176769.34665,49.0007057189941,159.787231445313,,,5,,,,25.0300001353025,,,,,0.000692706731905848,7.45428118767004E-8,0.0126427138168674,8.79934116539566E-5,0.000692602407820504,7.45315854654216E-8,0.00069260239095927,4.29080555080639E-8,1.52827556135986E-7,6.09414145266283E-8,1.00015062622389,10.005763053894,2,20,10,5,2.26593988580616,0.199777789711035,0.0410455763339996,172.855895996094,48.9998512268066,49.0010299682617,159.787231445313,159.787231445313,,,75.7471466064453,0,1,,,,,,1,1,1,49.0009269714355,0,49.0003812453326,,,,,,,,,,,,,,,,,,,,,,,,,,,,,,,,,
,3768176978.25047,49.0012474060059,159.787231445313,,,5,,,,25.0300001353025,,,,,0.000693318354440218,7.12377091355283E-8,0.0106167909688111,7.38402481023335E-5,0.000693213921058814,7.12269787188288E-8,0.000693213909157948,4.95353728760595E-8,1.28451123572803E-7,5.11813377261892E-8,1.00015065101584,10.005763053894,2,20,10,5,2.26794765695133,0.199873988622258,0.0410455763339996,172.855895996094,49.0003089904785,49.0014572143555,159.787231445313,159.787231445313,,,76.0829544067383,0,1,,,,,,1,1,1,49.0013618469238,0,49.0008008620318,,,,,,,,,,,,,,,,,,,,,,,,,,,,,,,,,
,3768177183.80631,49.000846862793,159.787231445313,,,5,,,,25.0300001353025,,,,,0.000694129998116405,7.40924932331362E-8,0.0160046001660428,7.14124770487928E-5,0.000694025455199489,7.40813341629545E-8,0.000694025428123159,5.50673410575919E-8,1.93864187999028E-7,4.95543340204486E-8,1.00015063268376,10.005763053894,2,20,10,5,2.2705838370276,0.200321491036592,0.0410455763339996,172.855895996094,49.0000076293945,49.0010871887207,159.787231445313,159.787231445313,,,76.3938751220703,0,1,,,,,,1,1,1,49.0009613037109,0,49.0004701053395,,,,,,,,,,,,,,,,,,,,,,,,,,,,,,,,,
,3768177395.13707,48.9996929168701,159.787231445313,,,5,,,,25.0300001353025,,,,,0.000695194634154815,7.92091525366294E-8,0.0153369278718616,8.15384253535109E-5,0.00069508996759792,7.91972270284864E-8,0.000695089942695445,5.532365862461E-8,1.86061602805502E-7,5.66700411627628E-8,1.00015057986991,10.005763053894,2,20,10,5,2.27406872857325,0.200602243885763,0.0410455763339996,172.855895996094,48.9993743896484,49.0005149841309,159.787231445313,159.787231445313,,,76.7296829223633,0,1,,,,,,1,1,1,48.9995956420898,0,48.9998968024003,,,,,,,,,,,,,,,,,,,,,,,,,,,,,,,,,
,3768177601.68168,49.0006675720215,159.787231445313,,,5,,,,25.0300001353025,,,,,0.000695710429274162,6.96460175692226E-8,0.0137352875138861,7.02415277556987E-5,0.000695605654035648,6.96355287540556E-8,0.000695605634047923,4.96222645558122E-8,1.66754753040239E-7,4.88542498172871E-8,1.00015062447797,10.005763053894,2,20,10,5,2.2757615703657,0.200687457946279,0.0410455763339996,172.855895996094,49.0000076293945,49.0009078979492,159.787231445313,159.787231445313,,,77.0530471801758,0,1,,,,,,1,1,1,49.0008544921875,0,49.0004229826086,,,,,,,,,,,,,,,,,,,,,,,,,,,,,,,,,
,3768177812.30561,48.999095916748,159.787231445313,,,5,,,,25.0300001353025,,,,,0.000696515599486824,7.09066057393034E-8,0.0133903060318366,6.90336251267797E-5,0.000696410673182677,7.08959240430352E-8,0.0006964106541644,5.21117151290547E-8,1.627546048263E-7,4.80687132366165E-8,1.00015066728324,10.005763053894,2,20,10,5,2.27839659855895,0.200906009265992,0.0410455763339996,172.855895996094,48.9984474182129,49.0022811889648,159.787231445313,159.787231445313,,,77.3639755249023,0,1,,,,,,1,1,1,48.999137878418,0,49.0002842953331,,,,,,,,,,,,,,,,,,,,,,,,,,,,,,,,,
,3768178020.56473,49.0003070831299,159.787231445313,,,5,,,,25.0300001353025,,,,,0.000697304063014103,7.7347732475145E-8,0.015141138278274,9.85337991544424E-5,0.000697199059272756,7.73360850436651E-8,0.000697199034928383,3.55195421499386E-8,1.8424371447209E-7,6.86966678619839E-8,1.0001506079791,10.005763053894,2,20,10,5,2.28096962224734,0.201203135761464,0.0410455763339996,172.855895996094,48.999195098877,49.001033782959,159.787231445313,159.787231445313,,,77.6749038696289,0,1,,,,,,1,1,1,48.9998359680176,0,48.9997319115533,,,,,,,,,,,,,,,,,,,,,,,,,,,,,,,,,
,3768178227.97606,49.0001163482666,159.787231445313,,,5,,,,25.0300001353025,,,,,0.00069782845505799,9.92580848785823E-8,0.0131644249815546,0.000128781129906802,0.000697723378440812,9.92431389363368E-8,0.000697723360024113,4.21389673916243E-8,1.60310708233729E-7,8.98527019799888E-8,1.00015059924954,10.005763053894,2,20,10,5,2.2826919202042,0.201275693257655,0.0410455763339996,172.855895996094,48.9993286132812,49.0004692077637,159.787231445313,159.787231445313,,,77.9982681274414,0,1,,,,,,1,1,1,48.9997749328613,0,48.9998806847466,,,,,,,,,,,,,,,,,,,,,,,,,,,,,,,,,
,3768178436.09525,48.9998683929443,159.787231445313,,,5,,,,25.0300001353025,,,,,0.000698529390427252,7.51035875537111E-8,0.0181836295674884,7.30428468084596E-5,0.000698424216190455,7.50922795649422E-8,0.000698424181017798,5.51098600593523E-8,2.21654843042707E-7,5.10073894107318E-8,1.00015058790111,10.005763053894,2,20,10,5,2.28496711670523,0.201678032720879,0.0410455763339996,172.855895996094,48.999210357666,49.0000190734863,159.787231445313,159.787231445313,,,78.2967529296875,0,1,,,,,,1,1,1,48.9997787475586,0,48.9996566772461,,,,,,,,,,,,,,,,,,,,,,,,,,,,,,,,,
,3768178643.83737,48.9998245239258,159.787231445313,,,5,,,,25.0300001353025,,,,,0.000699382406568383,5.64097716180185E-8,0.0107524134562889,5.62095727818019E-5,0.000699277105300813,5.64012783811299E-8,0.000699277092987187,4.04541344003387E-8,1.31229849327046E-7,3.93009823407131E-8,1.00015058589331,10.005763053894,2,20,10,5,2.28778359731339,0.201627591697371,0.0410455763339996,172.855895996094,48.999340057373,49.0002098083496,159.787231445313,159.787231445313,,,78.6201171875,0,1,,,,,,1,1,1,48.9998245239258,0,48.9997395409478,,,,,,,,,,,,,,,,,,,,,,,,,,,,,,,,,
,3768178852.36012,49.0005760192871,159.787231445313,,,5,,,,25.0300001353025,,,,,0.000699861251119152,5.70617220290476E-8,0.013647059504625,6.01640977494081E-5,0.000699755853691091,5.70531286703883E-8,0.000699755833841597,3.85095015919577E-8,1.66672131261531E-7,4.20960541882359E-8,1.00015062028778,10.005763053894,2,20,10,5,2.28933977276803,0.201881297136354,0.0410455763339996,172.855895996094,48.9994964599609,49.0007705688477,159.787231445313,159.787231445313,,,78.9434814453125,0,1,,,,,,1,1,1,49.0004806518555,0,49.0001311832004,,,,,,,,,,,,,,,,,,,,,,,,,,,,,,,,,
,3768179058.18447,49.0006008148193,159.787231445313,,,5,,,,25.0300001353025,,,,,0.000700494084147058,6.79803133058648E-8,0.0155483035348531,5.93508173154972E-5,0.000700388590621148,6.79700755563885E-8,0.000700388564832426,5.37842133295274E-8,1.90063811998267E-7,4.15594702524593E-8,1.00015062142263,10.005763053894,2,20,10,5,2.29140314786444,0.202139879786273,0.0410455763339996,172.855895996094,48.9992294311523,49.0011444091797,159.787231445313,159.787231445313,,,79.2668533325195,0,1,,,,,,1,1,1,49.0003395080566,0,49.000048743354,,,,,,,,,,,,,,,,,,,,,,,,,,,,,,,,,
,3768179267.35496,48.9998321533203,159.787231445313,,,5,,,,25.0300001353025,,,,,0.000701157693127799,7.36026426435607E-8,0.0150883561847799,7.82318816063797E-5,0.000701052124322608,7.35915607669459E-8,0.000701052100014067,4.90748518080708E-8,1.8461611175396E-7,5.48395544851614E-8,1.00015058624249,10.005763053894,2,20,10,5,2.29357551915446,0.202312966864547,0.0410455763339996,172.855895996094,48.9988441467285,49.0002365112305,159.787231445313,159.787231445313,,,79.590217590332,0,1,,,,,,1,1,1,48.999626159668,0,48.9995430840386,,,,,,,,,,,,,,,,,,,,,,,,,,,,,,,,,
,3768179480.01852,49.0006847381592,159.787231445313,,,5,,,,25.0300001353025,,,,,0.000701681527537119,6.73488366964761E-8,0.0126993711672796,6.27109182816796E-5,0.000701575852489379,6.73386937879716E-8,0.000701575835256263,5.09849861087412E-8,1.55501367736501E-7,4.39889858096509E-8,1.00015062526363,10.005763053894,2,20,10,5,2.29529748809393,0.202368406130983,0.0410455763339996,172.855895996094,48.9995079040527,49.0010948181152,159.787231445313,159.787231445313,,,79.9135818481445,0,1,,,,,,1,1,1,49.000804901123,0,49.0003217809341,,,,,,,,,,,,,,,,,,,,,,,,,,,,,,,,,
,3768179637.2639,48.9996356964111,159.787231445313,,,5,,,,25.0300001353025,,,,,0.000702177780963721,9.59871109426711E-8,0.0116208110006211,8.15035081322013E-5,0.00070207206488216,9.59726596434071E-8,0.000702072050441757,7.70584883986809E-8,1.423952477514E-7,5.72078732757967E-8,1.00015057725104,10.005763053894,2,20,10,5,2.2969246130482,0.202468295497333,0.0410455763339996,172.855895996094,48.9990158081055,49.0000152587891,159.787231445313,159.787231445313,,,80.1374435424805,0,1,,,,,,1,1,1,48.9994239807129,0,48.9995108211742,,,,,,,,,,,,,,,,,,,,,,,,,,,,,,,,,