File: Experimental_Data/Fig3C/Lifetime_300Oe_47p5K.dat
[Header]
; MPMS3 Data File (default extension .dat)
; Copyright (c) 2007, Quantum Design, Inc. All rights reserved.
TITLE,300Oe_47p5K
FILEOPENTIME,3768649132.85543,06/02/2019,2:58 pm
BYAPP,SQUID AC,0.9.1.0
INFO,MPMS3 Measurement Release 1.1.16 Build 347, MultiVu Release 2.3.3.2,APPNAME
INFO,0,MOMENT_UNITS
INFO,,SAMPLE_MATERIAL
INFO,,SAMPLE_COMMENT
INFO,,SAMPLE_MASS
INFO,,SAMPLE_VOLUME
INFO,,SAMPLE_MOLECULAR_WEIGHT
INFO,,SAMPLE_SIZE
INFO,,SAMPLE_SHAPE
INFO,Quartz,SAMPLE_HOLDER
INFO,Standard,SAMPLE_HOLDER_DETAIL
INFO,66.2,SAMPLE_OFFSET
DATATYPE,COMMENT,1
DATATYPE,TIME,2
STARTUPAXIS,X,2
STARTUPAXIS,Y1,5
FIELDGROUP, VSM,2,3,4,5,6,8,9,10,11,14,15
FIELDGROUP, DC, 2,3,4,14,56,57,58,59,60,61,62,63,64,65,66,67,68,69
FIELDGROUP, AC, 2,3,4,11,16,17,18,19,20,21,22,23,24,25,26,27,28,29,30
STARTUPGROUP, All
[Data]
Comment,Time Stamp (sec),Temperature (K),Magnetic Field (Oe),Moment (emu),M. Std. Err. (emu),Transport Action,Averaging Time (sec),Frequency (Hz),Peak Amplitude (mm),Center Position (mm),Lockin Signal' (V),Lockin Signal (V),Range,M. Quad. Signal (emu),AC Moment (emu),AC M. Std Err. (emu),AC Phase (deg),AC Phase Std. Err. (deg),AC Susceptibility (emu/Oe),AC Suscept. Std Err. (emu/Oe),AC X' (emu/Oe),AC X' Std Err. (emu/Oe),AC X'' (emu/Oe),AC X'' Std Err. (emu/Oe),AC Drive (Oe),AC Frequency (Hz),AC Averaging Time (sec),AC Cycles,AC Range,AC Measure Type,AC Signal' (V),AC Signal'' (V),AC Trim Coil Ratio,AC Trim Coil Phase,Min. Temperature (K),Max. Temperature (K),Min. Field (Oe),Max. Field (Oe),Mass (grams),Motor Lag (deg),Pressure (Torr),Measure Count,Measurement Number,SQUID Status (code),Motor Status (code),Measure Status (code),Motor Current (amps),Motor Temp. (C),Temp. Status (code),Field Status (code),Chamber Status (code),Chamber Temp (K),Redirection State,Average Temp (K),Rotation Angle (deg),Rotator state,DC Moment Fixed Ctr (emu),DC Moment Err Fixed Ctr (emu),DC Moment Free Ctr (emu),DC Moment Err Free Ctr (emu),DC Fixed Fit,DC Free Fit,DC Calculated Center (mm),DC Calculated Center Err (mm),DC Scan Length (mm),DC Scan Time (s),DC Number of Points,DC Squid Drift,DC Min V (V),DC Max V (V),DC Scans per Measure,Map 01,Map 02,Map 03,Map 04,Map 05,Map 06,Map 07,Map 08,Map 09,Map 10,Map 11,Map 12,Map 13,Map 14,Map 15,Map 16
,3768649137.68099,47.483922958374,299.890960693359,,,5,,,,25.0300001353025,,,,,0.000612474007138265,1.99361501597172E-7,0.0428837027330671,0.000119024493182894,0.000612381982760378,1.99331547480026E-7,0.0006123818112337,1.855610472934E-7,4.58344483294556E-7,7.28022221375036E-8,1.00015027283702,10.005763053894,2,20,10,5,2.00337461830159,0.178002194294849,0.0410455763339996,172.855895996094,47.4244918823242,47.4945297241211,299.890960693359,299.890960693359,,,58.1362037658691,0,1,,,,,,1,1,1,47.4791412353516,0,47.4560252918917,,,,,,,,,,,,,,,,,,,,,,,,,,,,,,,,,
,3768649343.30037,47.5002346038818,299.890960693359,,,5,,,,25.0300001353025,,,,,0.000618347771679308,1.21609456518764E-7,-0.00131174010065305,0.000134421639731278,0.000618254474166077,1.21591107847679E-7,0.00061825447400405,8.87668990391416E-8,-1.41544314955308E-8,8.30953376706591E-8,1.00015090471178,10.005763053894,2,20,10,5,2.02272546081979,0.17814900100952,0.0410455763339996,172.855895996094,47.499095916748,47.5002861022949,299.890960693359,299.890960693359,,,58.3227577209473,0,1,,,,,,1,1,1,47.5001602172852,0,47.4998229531681,,,,,,,,,,,,,,,,,,,,,,,,,,,,,,,,,
,3768649549.7928,47.4999084472656,299.890960693359,,,5,,,,25.0300001353025,,,,,0.000620889410038782,7.86894468946812E-8,-0.00254071445679038,9.42158555018254E-5,0.000620795738304418,7.86775752524087E-8,0.00062079573769406,5.26297771619E-8,-2.75284623040488E-8,5.84830522757422E-8,1.0001508897832,10.005763053894,2,20,10,5,2.03104344819257,0.178837693171274,0.0410455763339996,172.855895996094,47.4992485046387,47.5004615783691,299.890960693359,299.890960693359,,,58.4720039367676,0,1,,,,,,1,1,1,47.5004234313965,0,47.4998488956028,,,,,,,,,,,,,,,,,,,,,,,,,,,,,,,,,
,3768649755.92309,47.4998474121094,299.890960693359,,,5,,,,25.0300001353025,,,,,0.00062310976948135,1.23790695388883E-7,-0.0047952662884061,0.000151227917165475,0.000623015764508204,1.23772019801425E-7,0.000623015762326231,8.02756695919427E-8,-5.21421737271571E-8,9.42089685607991E-8,1.00015088698955,10.005763053894,2,20,10,5,2.03831371285349,0.179397029297628,0.0410455763339996,172.855895996094,47.4995880126953,47.5004463195801,299.890960693359,299.890960693359,,,58.596378326416,0,1,,,,,,1,1,1,47.5,0,47.4999988780302,,,,,,,,,,,,,,,,,,,,,,,,,,,,,,,,,
,3768649961.25842,47.5010681152344,299.890960693359,,,5,,,,25.0300001353025,,,,,0.000624932606264604,1.09613270763599E-7,-0.00253989148443345,0.000124970452966099,0.0006248383630605,1.09596740491781E-7,0.000624838362446564,7.69116315125662E-8,-2.76987528654281E-8,7.80771827392492E-8,1.0001508281336,10.005763053894,2,20,10,5,2.04426948421955,0.180002301418275,0.0410455763339996,172.855895996094,47.4999122619629,47.5016021728516,299.890960693359,299.890960693359,,,58.708309173584,0,1,,,,,,1,1,1,47.5008850097656,0,47.5006000294405,,,,,,,,,,,,,,,,,,,,,,,,,,,,,,,,,
,3768650167.74866,47.4998817443848,299.890960693359,,,5,,,,25.0300001353025,,,,,0.000626504732177411,1.01794575100916E-7,0.00276329584416946,0.000118847241961374,0.000626410214041634,1.01779217781208E-7,0.000626410213313119,6.94103370455255E-8,3.02108943319339E-8,7.44393329052669E-8,1.00015088856098,10.005763053894,2,20,10,5,2.04939548522656,0.180644824058036,0.0410455763339996,172.855895996094,47.4991607666016,47.5008697509766,299.890960693359,299.890960693359,,,58.7704963684082,0,1,,,,,,1,1,1,47.4992332458496,0,47.4996560414632,,,,,,,,,,,,,,,,,,,,,,,,,,,,,,,,,
,3768650374.92512,47.5000629425049,299.890960693359,,,5,,,,25.0300001353025,,,,,0.000627933056258072,1.13242965494571E-7,-0.00162420453901291,0.000136595007537622,0.000627838317430754,1.13225880065406E-7,0.000627838317178491,7.39372767749788E-8,-1.77977828989628E-8,8.57518455759758E-8,1.00015089685463,10.005763053894,2,20,10,5,2.05408161660836,0.180899368830661,0.0410455763339996,172.855895996094,47.4990577697754,47.5005493164063,299.890960693359,299.890960693359,,,58.8451194763184,0,1,,,,,,1,1,1,47.49951171875,0,47.4997458457947,,,,,,,,,,,,,,,,,,,,,,,,,,,,,,,,,
,3768650578.96298,47.5005950927734,299.890960693359,,,5,,,,25.0300001353025,,,,,0.000629259739742725,8.84547384497202E-8,-0.00329793241770115,0.000102329898416163,0.00062916485760345,8.84414009131148E-8,0.000629164856561199,6.06438962391498E-8,-3.62145902622587E-8,6.43754552947748E-8,1.0001508064828,10.005763053894,2,20,10,5,2.05842673122507,0.181221434638126,0.0410455763339996,172.855895996094,47.4994201660156,47.5009918212891,299.890960693359,299.890960693359,,,58.9197425842285,0,1,,,,,,1,1,1,47.5003929138184,0,47.5001436121324,,,,,,,,,,,,,,,,,,,,,,,,,,,,,,,,,
,3768650785.66146,47.4992771148682,299.890960693359,,,5,,,,25.0300001353025,,,,,0.000630389061749898,9.80590548478913E-8,-0.000931332525076378,8.94775147352649E-5,0.000630293975042159,9.8044263803352E-8,0.000630293974958892,8.02096763701781E-8,-1.02453144765499E-8,5.63833794777554E-8,1.00015086088635,10.005763053894,2,20,10,5,2.062113454713,0.181631848219026,0.0410455763339996,172.855895996094,47.4986267089844,47.4998207092285,299.890960693359,299.890960693359,,,58.9943656921387,0,1,,,,,,1,1,1,47.4997215270996,0,47.4994834451114,,,,,,,,,,,,,,,,,,,,,,,,,,,,,,,,,
,3768650992.00783,47.5013103485107,299.890960693359,,,5,,,,25.0300001353025,,,,,0.000631635938639901,1.27198585436961E-7,-0.00132748402142724,0.000139390845541134,0.000631540677536128,1.27179401795078E-7,0.000631540677366622,9.1799672554498E-8,-1.46321450787508E-8,8.80194317173249E-8,1.00015083922091,10.005763053894,2,20,10,5,2.06619346705059,0.181976814602595,0.0410455763339996,172.855895996094,47.4994583129883,47.5017051696777,299.890960693359,299.890960693359,,,59.0441093444824,0,1,,,,,,1,1,1,47.5011596679687,0,47.5003599279067,,,,,,,,,,,,,,,,,,,,,,,,,,,,,,,,,
,3768651198.92041,47.4999942779541,299.890960693359,,,5,,,,25.0300001353025,,,,,0.000632650022026569,1.63499591256186E-7,0.0052890278148725,0.000185355431453593,0.000632554573519072,1.63474923918135E-7,0.000632554570823975,1.13930816001555E-7,5.83917132718616E-8,1.17234039064001E-7,1.00015089371177,10.005763053894,2,20,10,5,2.06948965134341,0.182507968131089,0.0410455763339996,172.855895996094,47.4996070861816,47.5003051757812,299.890960693359,299.890960693359,,,59.1062965393066,0,1,,,,,,1,1,1,47.499641418457,0,47.4999526528751,,,,,,,,,,,,,,,,,,,,,,,,,,,,,,,,,
,3768651405.71802,47.5004272460937,299.890960693359,,,5,,,,25.0300001353025,,,,,0.00063369069795825,1.06047489510907E-7,0.00278856800890726,0.000117222257277657,0.000633595079888631,1.06031487924853E-7,0.00063359507913822,7.56823598385886E-8,3.08368781207965E-8,7.42620821201556E-8,1.00015091352925,10.005763053894,2,20,10,5,2.07290182889504,0.182717718274805,0.0410455763339996,172.855895996094,47.499755859375,47.5007781982422,299.890960693359,299.890960693359,,,59.1684837341309,0,1,,,,,,1,1,1,47.5001106262207,0,47.5001341875862,,,,,,,,,,,,,,,,,,,,,,,,,,,,,,,,,
,3768651610.33249,47.4984283447266,299.890960693359,,,5,,,,25.0300001353025,,,,,0.000634507491050782,1.20664761738372E-7,-0.0040498850073778,0.000171700804050638,0.000634411734995123,1.20646551738011E-7,0.000634411733410298,5.18730070199963E-8,-4.48426497336542E-8,1.08925578212723E-7,1.0001509367661,10.005763053894,2,20,10,5,2.07559550835682,0.182705507607916,0.0410455763339996,172.855895996094,47.4972496032715,47.5027503967285,299.890960693359,299.890960693359,,,59.1933555603027,0,1,,,,,,1,1,1,47.4990692138672,0,47.5004997253418,,,,,,,,,,,,,,,,,,,,,,,,,,,,,,,,,
,3768651815.25689,47.4995040893555,299.890960693359,,,5,,,,25.0300001353025,,,,,0.000635591420326677,1.231092038786E-7,0.000864789623539863,0.000126585377937394,0.000635495542303794,1.23090633037822E-7,0.000635495542231407,9.31778248857411E-8,9.5918051109473E-9,8.04313178507844E-8,1.00015087127525,10.005763053894,2,20,10,5,2.07912554223242,0.183195965317695,0.0410455763339996,172.855895996094,47.4983901977539,47.4998512268066,299.890960693359,299.890960693359,,,59.2679786682129,0,1,,,,,,1,1,1,47.4991874694824,0,47.4994661667768,,,,,,,,,,,,,,,,,,,,,,,,,,,,,,,,,
,3768652020.25954,47.5000305175781,299.890960693359,,,5,,,,25.0300001353025,,,,,0.000636120999550876,1.01029675856295E-7,-0.00275618568869973,0.000102182389430852,0.00063602502631888,1.01014433245964E-7,0.000636025025582985,7.73406436057469E-8,-3.05956754479379E-8,6.49795396309644E-8,1.0001508953705,10.005763053894,2,20,10,5,2.08086946768179,0.183217094922519,0.0410455763339996,172.855895996094,47.499698638916,47.5005226135254,299.890960693359,299.890960693359,,,59.3177299499512,0,1,,,,,,1,1,1,47.5001945495605,0,47.5000953674316,,,,,,,,,,,,,,,,,,,,,,,,,,,,,,,,,
,3768652225.3835,47.5009174346924,299.890960693359,,,5,,,,25.0300001353025,,,,,0.000637409207522446,1.9009435523772E-7,-0.0051305625014777,0.000245899654242282,0.00063731301406717,1.90065667492638E-7,0.000637313011512073,1.07556123584099E-7,-5.70683264124275E-8,1.56705578199961E-7,1.00015093596577,10.005763053894,2,20,10,5,2.08509104102128,0.183501714362171,0.0410455763339996,172.855895996094,47.499137878418,47.5022926330566,299.890960693359,299.890960693359,,,59.3799133300781,0,1,,,,,,1,1,1,47.5015754699707,0,47.5003501044379,,,,,,,,,,,,,,,,,,,,,,,,,,,,,,,,,
,3768652430.42002,47.5002555847168,299.890960693359,,,5,,,,25.0300001353025,,,,,0.000637943514698305,1.2288552009806E-7,-0.00462154482619592,0.000114508244933693,0.000637847259928849,1.2286697877405E-7,0.00063784725785386,9.88126023034065E-8,-5.14495086005033E-8,7.30230381392858E-8,1.0001509056721,10.005763053894,2,20,10,5,2.08683723281266,0.183674079640084,0.0410455763339996,172.855895996094,47.4993362426758,47.5004386901855,299.890960693359,299.890960693359,,,59.4047889709473,0,1,,,,,,1,1,1,47.5002212524414,0,47.4999447990866,,,,,,,,,,,,,,,,,,,,,,,,,,,,,,,,,
,3768652638.1151,47.5013065338135,299.890960693359,,,5,,,,25.0300001353025,,,,,0.000639049551090436,1.50396558199034E-7,-0.00149786811890706,0.000186140066609531,0.000638953172003336,1.50373875946997E-7,0.000638953171784992,9.20265224923637E-8,-1.67039805347407E-8,1.18926118768273E-7,1.00015083904631,10.005763053894,2,20,10,5,2.09044525887584,0.184106491656964,0.0410455763339996,172.855895996094,47.5001602172852,47.5024452209473,299.890960693359,299.890960693359,,,59.454532623291,0,1,,,,,,1,1,1,47.5005836486816,0,47.5006970299615,,,,,,,,,,,,,,,,,,,,,,,,,,,,,,,,,
,3768652845.83563,47.5015525817871,299.890960693359,,,5,,,,25.0300001353025,,,,,0.000639868158484524,1.09879035764835E-7,0.00162656803684769,0.000105133160008453,0.000639771648734123,1.09862462978434E-7,0.000639771648476316,8.68765713842249E-8,1.81624567012808E-8,6.72474692178773E-8,1.00015085030822,10.005763053894,2,20,10,5,2.09311301471666,0.184456464469107,0.0410455763339996,172.855895996094,47.4999809265137,47.501651763916,299.890960693359,299.890960693359,,,59.5042839050293,0,1,,,,,,1,1,1,47.501651763916,0,47.5008629246762,,,,,,,,,,,,,,,,,,,,,,,,,,,,,,,,,
,3768653054.10834,47.5001487731934,299.890960693359,,,5,,,,25.0300001353025,,,,,0.00064048177011139,1.4023967457314E-7,-0.000490076754871893,0.000141673014455191,0.00064038513549289,1.40218515489332E-7,0.000640385135469465,1.06924828049676E-7,-5.47750413265724E-9,9.07100503394166E-8,1.00015090078321,10.005763053894,2,20,10,5,2.09512705714157,0.184555959285635,0.0410455763339996,172.855895996094,47.4993019104004,47.5002365112305,299.890960693359,299.890960693359,,,59.5415954589844,0,1,,,,,,1,1,1,47.5001640319824,0,47.499786825741,,,,,,,,,,,,,,,,,,,,,,,,,,,,,,,,,
,3768653261.33823,47.5001411437988,299.890960693359,,,5,,,,25.0300001353025,,,,,0.00064117892065917,1.52212305943991E-7,0.000354393091980931,0.000156156302654483,0.000641082181079816,1.52189340506458E-7,0.000641082181067553,1.14642784751072E-7,3.9653024759604E-9,1.00093093010008E-7,1.000150900434,10.005763053894,2,20,10,5,2.09740483421976,0.184787758440778,0.0410455763339996,172.855895996094,47.4993095397949,47.5003318786621,299.890960693359,299.890960693359,,,59.5789070129395,0,1,,,,,,1,1,1,47.4999809265137,0,47.4998920665068,,,,,,,,,,,,,,,,,,,,,,,,,,,,,,,,,
,3768653468.73764,47.498966217041,299.890960693359,,,5,,,,25.0300001353025,,,,,0.000641654825721987,1.21932754534513E-7,-0.000138886569765795,0.000102606332374875,0.000641558048835571,1.21914364160338E-7,0.000641558048833686,1.02627255975127E-7,-1.55515462858789E-9,6.58084988404639E-8,1.00015084665619,10.005763053894,2,20,10,5,2.09896319177548,0.184906849191365,0.0410455763339996,172.855895996094,47.4980278015137,47.5024185180664,299.890960693359,299.890960693359,,,59.6037788391113,0,1,,,,,,1,1,1,47.4986610412598,0,47.5002028942108,,,,,,,,,,,,,,,,,,,,,,,,,,,,,,,,,
,3768653675.29711,47.500358581543,299.890960693359,,,5,,,,25.0300001353025,,,,,0.000642391486058129,1.37739221395042E-7,0.00166011830586665,0.000147498201367455,0.000642294557138337,1.37718438252313E-7,0.000642294556868726,9.99682019059168E-8,1.86101831753805E-8,9.47244785805339E-8,1.00015091038639,10.005763053894,2,20,10,5,2.10136712135085,0.185185107901774,0.0410455763339996,172.855895996094,47.4998168945313,47.5006866455078,299.890960693359,299.890960693359,,,59.6410942077637,0,1,,,,,,1,1,1,47.5000762939453,0,47.5001685198616,,,,,,,,,,,,,,,,,,,,,,,,,,,,,,,,,
,3768653880.27923,47.4995555877686,299.890960693359,,,5,,,,25.0300001353025,,,,,0.000643037417689277,1.19586705493246E-7,-0.0101196157106953,0.000113325101055387,0.000642940414933463,1.19568665734326E-7,0.000642940404905251,9.48153312199269E-8,-1.13556529738614E-7,7.28472291246727E-8,1.00015087363239,10.005763053894,2,20,10,5,2.10351813566234,0.184938846411657,0.0410455763339996,172.855895996094,47.4995193481445,47.4999885559082,299.890960693359,299.890960693359,,,59.6908378601074,0,1,,,,,,1,1,1,47.4995918273926,0,47.4997392542222,,,,,,,,,,,,,,,,,,,,,,,,,,,,,,,,,
,3768654087.84315,47.5001430511475,299.890960693359,,,5,,,,25.0300001353025,,,,,0.000643745150679709,1.83196076817676E-7,-0.00630417302057573,8.93594444001794E-5,0.000643648023857375,1.83168436605107E-7,0.000643648019961281,1.73923508588078E-7,-7.081967525435E-8,5.74568475359712E-8,1.0001509005213,10.005763053894,2,20,10,5,2.10582095390622,0.185282620851918,0.0410455763339996,172.855895996094,47.4995651245117,47.5002021789551,299.890960693359,299.890960693359,,,59.5167198181152,0,1,,,,,,1,1,1,47.500129699707,0,47.4999201157514,,,,,,,,,,,,,,,,,,,,,,,,,,,,,,,,,
,3768654293.05785,47.4986381530762,299.890960693359,,,5,,,,25.0300001353025,,,,,0.000644203308187092,1.2858132624977E-7,0.00281750638040013,0.00011786292669388,0.000644106156598963,1.28561935042227E-7,0.000644106155820188,1.03766852516517E-7,3.16737676066841E-8,7.58986920876588E-8,1.0001508316403,10.005763053894,2,20,10,5,2.10729013379573,0.185749987982322,0.0410455763339996,172.855895996094,47.4954528808594,47.5010643005371,299.890960693359,299.890960693359,,,59.5789070129395,0,1,,,,,,1,1,1,47.4977149963379,0,47.4971042209201,,,,,,,,,,,,,,,,,,,,,,,,,,,,,,,,,
,3768654497.98319,47.4996166229248,299.890960693359,,,5,,,,25.0300001353025,,,,,0.000645047804219138,1.50493979627531E-7,0.0007654800791288,0.000120196402797054,0.000644950496393265,1.50471277059026E-7,0.000644950496335706,1.28981446092332E-7,8.61663391604373E-9,7.74944629228763E-8,1.00015087642605,10.005763053894,2,20,10,5,2.11005927351697,0.18591791167983,0.0410455763339996,172.855895996094,47.4990615844727,47.5001564025879,299.890960693359,299.890960693359,,,59.6659660339356,0,1,,,,,,1,1,1,47.4995765686035,0,47.4996371549719,,,,,,,,,,,,,,,,,,,,,,,,,,,,,,,,,
,3768654704.71686,47.500732421875,299.890960693359,,,5,,,,25.0300001353025,,,,,0.000645263369376985,1.1169448406654E-7,-0.00271897012157396,0.000114206550033219,0.000645165996087717,1.11677628841491E-7,0.000645165995361268,8.39316292359093E-8,-3.06163400003848E-8,7.36707160102559E-8,1.00015092749751,10.005763053894,2,20,10,5,2.11077573017787,0.185851670612805,0.0410455763339996,172.855895996094,47.499584197998,47.5010719299316,299.890960693359,299.890960693359,,,59.7654609680176,0,1,,,,,,1,1,1,47.5008010864258,0,47.5003278520372,,,,,,,,,,,,,,,,,,,,,,,,,,,,,,,,,
,3768654910.64999,47.5001735687256,299.890960693359,,,5,,,,25.0300001353025,,,,,0.000646145479940516,1.85462626226974E-7,-0.00782573134578257,0.00011356409575574,0.000646047990059613,1.8543464378354E-7,0.000646047984033471,1.70322075711019E-7,-8.82403212581356E-8,7.33239227034271E-8,1.00015090191813,10.005763053894,2,20,10,5,2.1136778559223,0.185917350255247,0.0410455763339996,172.855895996094,47.4996643066406,47.5007553100586,299.890960693359,299.890960693359,,,59.8027763366699,0,1,,,,,,1,1,1,47.5005416870117,0,47.5001422657686,,,,,,,,,,,,,,,,,,,,,,,,,,,,,,,,,
,3768655116.44192,47.4997367858887,299.890960693359,,,5,,,,25.0300001353025,,,,,0.00064645689841607,1.12243864141125E-7,0.000485158113979978,8.08571484203511E-5,0.000646359374468729,1.12226931125602E-7,0.000646359374445557,9.93272260474235E-8,5.47311682870426E-9,5.22396998038332E-8,1.00015088192605,10.005763053894,2,20,10,5,2.11466956793362,0.18631369950061,0.0410455763339996,172.855895996094,47.4988212585449,47.5001602172852,299.890960693359,299.890960693359,,,59.8773994445801,0,1,,,,,,1,1,1,47.4995956420898,0,47.4994920094808,,,,,,,,,,,,,,,,,,,,,,,,,,,,,,,,,
,3768655324.57916,47.5013847351074,299.890960693359,,,5,,,,25.0300001353025,,,,,0.000647403861268322,1.08460547926549E-7,0.00157685633846416,0.000100956431520028,0.000647306219898497,1.08444189920203E-7,0.000647306219653355,8.6552826499408E-8,1.78147312824728E-8,6.5335675954354E-8,1.00015084262567,10.005763053894,2,20,10,5,2.11776368825137,0.186626965513746,0.0410455763339996,172.855895996094,47.4997940063477,47.5017127990723,299.890960693359,299.890960693359,,,59.9271430969238,0,1,,,,,,1,1,1,47.5012397766113,0,47.5005719801959,,,,,,,,,,,,,,,,,,,,,,,,,,,,,,,,,
,3768655532.52973,47.5007915496826,299.890960693359,,,5,,,,25.0300001353025,,,,,0.000647857729146973,1.11182075777526E-7,0.0027927448378513,0.000148382708291188,0.000647759962603765,1.11165297576501E-7,0.000647759961834278,5.58574716870211E-8,3.15734999398871E-8,9.61127787653941E-8,1.00015093020386,10.005763053894,2,20,10,5,2.1192444002353,0.186802777277111,0.0410455763339996,172.855895996094,47.4997749328613,47.5008773803711,299.890960693359,299.890960693359,,,59.989330291748,0,1,,,,,,1,1,1,47.5007057189941,0,47.500239203958,,,,,,,,,,,,,,,,,,,,,,,,,,,,,,,,,
,3768655737.60684,47.5009574890137,299.890960693359,,,5,,,,25.0300001353025,,,,,0.000648562584765003,1.19752525850128E-7,-0.0111993307903768,0.000136452919079228,0.000648464781315828,1.19734467130197E-7,0.000648464768927997,8.06744467310553E-8,-1.26752294974222E-7,8.84758513018689E-8,1.00015082307011,10.005763053894,2,20,10,5,2.12159569886168,0.186487908869291,0.0410455763339996,172.855895996094,47.4996681213379,47.5015335083008,299.890960693359,299.890960693359,,,60.0266456604004,0,1,,,,,,1,1,1,47.5010032653809,0,47.50045709049,,,,,,,,,,,,,,,,,,,,,,,,,,,,,,,,,
,3768655945.74518,47.4997901916504,299.890960693359,,,5,,,,25.0300001353025,,,,,0.000648916818993118,1.01390791580689E-7,-0.00213661804870302,0.000103181194659737,0.000648818922358452,1.01375495602851E-7,0.000648818921907321,7.61355993616132E-8,-2.419511927948E-8,6.69355034236059E-8,1.0001508843705,10.005763053894,2,20,10,5,2.12272493886921,0.186925533320695,0.0410455763339996,172.855895996094,47.4994697570801,47.5001449584961,299.890960693359,299.890960693359,,,60.0763893127441,0,1,,,,,,1,1,1,47.4997940063477,0,47.4998270670573,,,,,,,,,,,,,,,,,,,,,,,,,,,,,,,,,
,3768656152.61253,47.4972991943359,299.890960693359,,,5,,,,25.0300001353025,,,,,0.000649395796211906,1.2319570669851E-7,0.000487759442115987,0.000124150163935613,0.000649297826855069,1.23177121108303E-7,0.000649297826831541,9.31486361174809E-8,5.52747773887627E-9,8.059736195424E-8,1.00015088508352,10.005763053894,2,20,10,5,2.12428318903773,0.187160817790364,0.0410455763339996,172.855895996094,47.496509552002,47.5021362304687,299.890960693359,299.890960693359,,,60.1510124206543,0,1,,,,,,1,1,1,47.4973754882812,0,47.4994841182933,,,,,,,,,,,,,,,,,,,,,,,,,,,,,,,,,
,3768656356.56892,47.5014247894287,299.890960693359,,,5,,,,25.0300001353025,,,,,0.000649817623510244,1.12850741612412E-7,0.000413846979791188,0.000130832697259253,0.000649719616906125,1.12833721270769E-7,0.000649719616889176,7.42091554505031E-8,4.69291985291788E-9,8.4996764074479E-8,1.00015084445901,10.005763053894,2,20,10,5,2.12566330045976,0.18727963193649,0.0410455763339996,172.855895996094,47.5000267028809,47.5014762878418,299.890960693359,299.890960693359,,,60.1510124206543,0,1,,,,,,1,1,1,47.5014419555664,0,47.5006675720215,,,,,,,,,,,,,,,,,,,,,,,,,,,,,,,,,
,3768656561.60399,47.5008659362793,299.890960693359,,,5,,,,25.0300001353025,,,,,0.00065045483600423,1.05949504652929E-7,-0.00474052457402063,0.000116105468410109,0.000650356749927846,1.0593352787694E-7,0.000650356747701825,7.43067207446304E-8,-5.38090619866982E-8,7.55011495318706E-8,1.00015081887963,10.005763053894,2,20,10,5,2.1277645856734,0.187271867573794,0.0410455763339996,172.855895996094,47.5000495910645,47.5015716552734,299.890960693359,299.890960693359,,,60.1883277893066,0,1,,,,,,1,1,1,47.5006561279297,0,47.5004813250373,,,,,,,,,,,,,,,,,,,,,,,,,,,,,,,,,
,3768656769.31463,47.5001831054687,299.890960693359,,,5,,,,25.0300001353025,,,,,0.000650891994091751,1.38360211089885E-7,0.00348924725835964,0.000147191362315759,0.000650793787776794,1.38339335358441E-7,0.000650793786570004,9.98210398118386E-8,3.96325952391586E-8,9.57785556285882E-8,1.00015090235464,10.005763053894,2,20,10,5,2.12916767571039,0.187703559504469,0.0410455763339996,172.855895996094,47.4998207092285,47.5004653930664,299.890960693359,299.890960693359,,,60.2256355285645,0,1,,,,,,1,1,1,47.5002479553223,0,47.5001360575358,,,,,,,,,,,,,,,,,,,,,,,,,,,,,,,,,
,3768656976.97775,47.4998760223389,299.890960693359,,,5,,,,25.0300001353025,,,,,0.000651504251584072,1.22564163165537E-7,-0.00172367995225553,0.000153275504277189,0.000651405962046454,1.22545672457462E-7,0.000651405961751679,7.10615151049705E-8,-1.95968255765411E-8,9.98383839464438E-8,1.00015088829907,10.005763053894,2,20,10,5,2.13118754875515,0.187686224178533,0.0410455763339996,172.855895996094,47.4993171691895,47.500301361084,299.890960693359,299.890960693359,,,60.2753868103027,0,1,,,,,,1,1,1,47.4995536804199,0,47.4996973673503,,,,,,,,,,,,,,,,,,,,,,,,,,,,,,,,,
,3768657182.24477,47.5002517700195,299.890960693359,,,5,,,,25.0300001353025,,,,,0.000651943474147586,9.85318950780219E-8,-0.00530378223765737,0.000114299413059351,0.000651845107137404,9.8517028316852E-8,0.0006518451043446,6.44635907971572E-8,-6.03402995016826E-8,7.44986599202971E-8,1.00015090549749,10.005763053894,2,20,10,5,2.13263605631171,0.187679495721481,0.0410455763339996,172.855895996094,47.4992370605469,47.5004425048828,299.890960693359,299.890960693359,,,60.3002586364746,0,1,,,,,,1,1,1,47.500431060791,0,47.499896105598,,,,,,,,,,,,,,,,,,,,,,,,,,,,,,,,,
,3768657390.08597,47.5001792907715,299.890960693359,,,5,,,,25.0300001353025,,,,,0.000652323913471443,1.18931722714644E-7,-0.00691241955917299,0.000141543077689689,0.000652225491222945,1.18913778366253E-7,0.000652225486476344,7.49618655100767E-8,-7.86874054231944E-8,9.23103753897004E-8,1.00015090218003,10.005763053894,2,20,10,5,2.13388581991883,0.187729106688552,0.0410455763339996,172.855895996094,47.4997062683105,47.5005798339844,299.890960693359,299.890960693359,,,60.3624458312988,0,1,,,,,,1,1,1,47.4999237060547,0,47.5000369423314,,,,,,,,,,,,,,,,,,,,,,,,,,,,,,,,,
,3768657596.90692,47.499605178833,299.890960693359,,,5,,,,25.0300001353025,,,,,0.000652870889804918,9.96389097411476E-8,0.000645260737670128,0.000108265641053973,0.000652772402179784,9.96238788985345E-8,0.000652772402138388,7.02243731209693E-8,7.35147344764112E-9,7.06643804653854E-8,1.00015087590224,10.005763053894,2,20,10,5,2.1356502900788,0.188168226167219,0.0410455763339996,172.855895996094,47.4991607666016,47.5001373291016,299.890960693359,299.890960693359,,,60.3873176574707,0,1,,,,,,1,1,1,47.4998664855957,0,47.4996602800157,,,,,,,,,,,,,,,,,,,,,,,,,,,,,,,,,
,3768657803.77133,47.5001907348633,299.890960693359,,,5,,,,25.0300001353025,,,,,0.000653239115935755,1.4330537433738E-7,-0.00298237091183573,0.000169617238437567,0.000653140555259977,1.43283752431721E-7,0.000653140554375158,9.08800542430544E-8,-3.39973975225035E-8,1.10774769021173E-7,1.00015090270384,10.005763053894,2,20,10,5,2.13686673583575,0.188139060256648,0.0410455763339996,172.855895996094,47.4996452331543,47.5003356933594,299.890960693359,299.890960693359,,,60.437068939209,0,1,,,,,,1,1,1,47.5001754760742,0,47.5000332726373,,,,,,,,,,,,,,,,,,,,,,,,,,,,,,,,,
,3768658010.44618,47.5000762939453,299.890960693359,,,5,,,,25.0300001353025,,,,,0.000653547914515661,1.56346109651541E-7,-0.000130302911835578,0.000167281996005162,0.000653449310670689,1.56322520979286E-7,0.000653449310668999,1.11763185280502E-7,-1.48608411720495E-9,1.09296482016923E-7,1.00015089746574,10.005763053894,2,20,10,5,2.13786750110397,0.188334417304901,0.0410455763339996,172.855895996094,47.4993934631348,47.5007629394531,299.890960693359,299.890960693359,,,60.4992523193359,0,1,,,,,,1,1,1,47.4999046325684,0,47.4999353745404,,,,,,,,,,,,,,,,,,,,,,,,,,,,,,,,,
,3768658218.17075,47.501091003418,299.890960693359,,,5,,,,25.0300001353025,,,,,0.000654131567055785,1.22349408389935E-7,0.00200926755330144,0.000103560158494925,0.000654032919805998,1.22330957311805E-7,0.000654032919403837,1.01881472981766E-7,2.29358451085877E-8,6.771283910669E-8,1.00015082918122,10.005763053894,2,20,10,5,2.13976968852197,0.188582510467497,0.0410455763339996,172.855895996094,47.4999771118164,47.5013656616211,299.890960693359,299.890960693359,,,60.536563873291,0,1,,,,,,1,1,1,47.5008087158203,0,47.5005499895881,,,,,,,,,,,,,,,,,,,,,,,,,,,,,,,,,
,3768658423.69883,47.5005474090576,299.890960693359,,,5,,,,25.0300001353025,,,,,0.000654542874194363,1.06791934788104E-7,0.000383288415668481,0.000120425447947556,0.000654444106125168,1.06775820284959E-7,0.000654444106110525,7.20488771623988E-8,4.3779986363768E-9,7.88037759067634E-8,1.00015091902925,10.005763053894,2,20,10,5,2.14112049462217,0.188640326020908,0.0410455763339996,172.855895996094,47.4995422363281,47.5010833740234,299.890960693359,299.890960693359,,,60.5614356994629,0,1,,,,,,1,1,1,47.5007858276367,0,47.5003406300264,,,,,,,,,,,,,,,,,,,,,,,,,,,,,,,,,
,3768658628.67325,47.5013675689697,299.890960693359,,,5,,,,25.0300001353025,,,,,0.000654877759691579,1.38276617938299E-7,-0.00117585033685774,0.000162649282758547,0.000654778991623715,1.38255763184595E-7,0.000654778991485828,8.81727451960986E-8,-1.34376755907174E-8,1.06490483416777E-7,1.00015084183996,10.005763053894,2,20,10,5,2.14222109688797,0.188678546227131,0.0410455763339996,172.855895996094,47.4999237060547,47.5020484924316,299.890960693359,299.890960693359,,,60.5987510681152,0,1,,,,,,1,1,1,47.5008010864258,0,47.5005623312557,,,,,,,,,,,,,,,,,,,,,,,,,,,,,,,,,
,3768658836.30925,47.5003509521484,299.890960693359,,,5,,,,25.0300001353025,,,,,0.00065529680838071,1.14790418151635E-7,-0.00273296745816598,0.000141682061407768,0.000655197932436365,1.14773097739188E-7,0.000655197931691005,6.75027393176265E-8,-3.12524699470813E-8,9.28237262194622E-8,1.00015091003718,10.005763053894,2,20,10,5,2.14359700946817,0.188741023875438,0.0410455763339996,172.855895996094,47.4996643066406,47.5006828308105,299.890960693359,299.890960693359,,,60.648494720459,0,1,,,,,,1,1,1,47.5006828308105,0,47.5001489975873,,,,,,,,,,,,,,,,,,,,,,,,,,,,,,,,,
,3768659041.62258,47.5003070831299,299.890960693359,,,5,,,,25.0300001353025,,,,,0.000655697518508113,1.73493648822366E-7,-0.00082909162272049,0.000172550400969118,0.000655598583417915,1.73467471188151E-7,0.000655598583349277,1.31522423903999E-7,-9.48675972260987E-9,1.13105329542108E-7,1.00015090802924,10.005763053894,2,20,10,5,2.14490152939273,0.188927714146653,0.0410455763339996,172.855895996094,47.4994773864746,47.5009155273438,299.890960693359,299.890960693359,,,60.6609382629395,0,1,,,,,,1,1,1,47.4998970031738,0,47.5000868404613,,,,,,,,,,,,,,,,,,,,,,,,,,,,,,,,,
,3768659246.73785,47.5000953674316,299.890960693359,,,5,,,,25.0300001353025,,,,,0.00065614044621049,1.87792617795021E-7,-0.0048346918456863,0.000193730250143686,0.00065604145064543,1.87764284476415E-7,0.000656041448309856,1.38227470274722E-7,-5.53576245066975E-8,1.27077114329808E-7,1.00015089833876,10.005763053894,2,20,10,5,2.14636363548355,0.188905280603562,0.0410455763339996,172.855895996094,47.4991073608398,47.500373840332,299.890960693359,299.890960693359,,,60.7106819152832,0,1,,,,,,1,1,1,47.5002632141113,0,47.4998568366556,,,,,,,,,,,,,,,,,,,,,,,,,,,,,,,,,
,3768659454.40774,47.5012760162354,299.890960693359,,,5,,,,25.0300001353025,,,,,0.000656382722973742,1.0419913527303E-7,-0.00317465171018494,0.0001164544706491,0.000656283730678414,1.04183420490768E-7,0.000656283729670998,7.08116405643564E-8,-3.63634509313726E-8,7.64192165998884E-8,1.00015083764948,10.005763053894,2,20,10,5,2.14715069430768,0.189037239626039,0.0410455763339996,172.855895996094,47.5000267028809,47.5016098022461,299.890960693359,299.890960693359,,,60.7728691101074,0,1,,,,,,1,1,1,47.5009956359863,0,47.500711777631,,,,,,,,,,,,,,,,,,,,,,,,,,,,,,,,,
,3768659662.01649,47.4998760223389,299.890960693359,,,5,,,,25.0300001353025,,,,,0.000656769037140369,1.3539015092035E-7,-0.00377309936516124,0.000106533631668762,0.00065666995332806,1.35369725212767E-7,0.000656669951904197,1.15905459991517E-7,-4.32436909539915E-8,6.99348757654932E-8,1.00015088829907,10.005763053894,2,20,10,5,2.14841637511443,0.189126064555715,0.0410455763339996,172.855895996094,47.4991493225098,47.5003776550293,299.890960693359,299.890960693359,,,60.7977409362793,0,1,,,,,,1,1,1,47.499397277832,0,47.4998211330838,,,,,,,,,,,,,,,,,,,,,,,,,,,,,,,,,
,3768659868.86352,47.4979991912842,299.890960693359,,,5,,,,25.0300001353025,,,,,0.000656968319305298,1.30031035927903E-7,0.00296684786316348,0.00013769824612339,0.000656869186497332,1.30011414979167E-7,0.0006568691856167,9.34020056724256E-8,3.40135164933338E-8,9.04380083883618E-8,1.00015091712323,10.005763053894,2,20,10,5,2.14904599515711,0.189436258777022,0.0410455763339996,172.855895996094,47.4968414306641,47.5026931762695,299.890960693359,299.890960693359,,,60.7977409362793,0,1,,,,,,1,1,1,47.4981842041016,0,47.5000664206112,,,,,,,,,,,,,,,,,,,,,,,,,,,,,,,,,
,3768660077.39126,47.5001354217529,299.890960693359,,,5,,,,25.0300001353025,,,,,0.000657415730251041,1.42655150612774E-7,-0.00584345658807806,0.000172183732889881,0.000657316541071873,1.42633627173887E-7,0.000657316537653347,8.68142652935605E-8,-6.70381081881159E-8,1.1317082195654E-7,1.00015090017209,10.005763053894,2,20,10,5,2.15053867079564,0.189234577522775,0.0410455763339996,172.855895996094,47.4994888305664,47.5002975463867,299.890960693359,299.890960693359,,,60.8474922180176,0,1,,,,,,1,1,1,47.5000762939453,0,47.4998705246869,,,,,,,,,,,,,,,,,,,,,,,,,,,,,,,,,
,3768660285.14683,47.5013885498047,299.890960693359,,,5,,,,25.0300001353025,,,,,0.000657892953923346,1.23138610367816E-7,-0.000616099062758835,0.000142929371643816,0.000657793730475036,1.23120038596424E-7,0.000657793730437007,7.95027001007129E-8,-7.07322780614169E-9,9.40099174591755E-8,1.00015084280028,10.005763053894,2,20,10,5,2.15208247942017,0.18956828373334,0.0410455763339996,172.855895996094,47.4999237060547,47.5015144348145,299.890960693359,299.890960693359,,,60.8599281311035,0,1,,,,,,1,1,1,47.5014381408691,0,47.5006709628635,,,,,,,,,,,,,,,,,,,,,,,,,,,,,,,,,
,3768660490.25755,47.5000591278076,299.890960693359,,,5,,,,25.0300001353025,,,,,0.000658341119366537,9.2090362290549E-8,-0.00201521143840377,9.26236086684979E-5,0.000658241792865337,9.20764682571802E-8,0.00065824179245819,6.90075021917655E-8,-2.31517295203438E-8,6.09593360197516E-8,1.00015089668003,10.005763053894,2,20,10,5,2.15355313776462,0.189644838001759,0.0410455763339996,172.855895996094,47.4995002746582,47.5002365112305,299.890960693359,299.890960693359,,,60.8847999572754,0,1,,,,,,1,1,1,47.5001487731934,0,47.4998815199908,,,,,,,,,,,,,,,,,,,,,,,,,,,,,,,,,
,3768660695.29663,47.4998035430908,299.890960693359,,,5,,,,25.0300001353025,,,,,0.00065865533403041,1.22807335464332E-7,4.02174906506403E-5,0.000123406587279895,0.000658555967825317,1.22788808477223E-7,0.000658555967825155,9.2056008402428E-8,4.62258628890606E-10,8.12575092177228E-8,1.00015088498161,10.005763053894,2,20,10,5,2.15457418279618,0.189812647012306,0.0410455763339996,172.855895996094,47.4997787475586,47.5002555847168,299.890960693359,299.890960693359,,,60.9345512390137,0,1,,,,,,1,1,1,47.4997978210449,0,47.499994614545,,,,,,,,,,,,,,,,,,,,,,,,,,,,,,,,,
,3768660900.32601,47.5003032684326,299.890960693359,,,5,,,,25.0300001353025,,,,,0.000659058991479304,1.38936613979242E-7,-0.00233477652617609,0.000136652475192897,0.000658959549307424,1.38915650516447E-7,0.000658959548760315,1.05789977868148E-7,-2.6852296976699E-8,9.00335412002902E-8,1.00015090785464,10.005763053894,2,20,10,5,2.15590248649288,0.189839606452767,0.0410455763339996,172.855895996094,47.4992218017578,47.5004959106445,299.890960693359,299.890960693359,,,60.9718627929688,0,1,,,,,,1,1,1,47.5003089904785,0,47.4998404558967,,,,,,,,,,,,,,,,,,,,,,,,,,,,,,,,,
,3768661105.37935,47.4997539520264,299.890960693359,,,5,,,,25.0300001353025,,,,,0.000659266312892421,1.53735910125663E-7,-0.00287770749134442,9.54257018787854E-5,0.00065916685600968,1.53712717534009E-7,0.000659166855178274,1.40269895240888E-7,-3.31069655550174E-8,6.28645847898487E-8,1.00015088271177,10.005763053894,2,20,10,5,2.1565824719557,0.189878890916647,0.0410455763339996,172.855895996094,47.4996299743652,47.5007362365723,299.890960693359,299.890960693359,,,61.0216102600098,0,1,,,,,,1,1,1,47.4998779296875,0,47.5000641766716,,,,,,,,,,,,,,,,,,,,,,,,,,,,,,,,,
,3768661310.48201,47.5008430480957,299.890960693359,,,5,,,,25.0300001353025,,,,,0.000659595969239696,9.231704639614E-8,-0.0095398649073859,9.71964098063373E-5,0.000659496505406533,9.23031254388736E-8,0.000659496496264944,6.64230291820976E-8,-1.09807521476604E-7,6.40924969092222E-8,1.00015081783201,10.005763053894,2,20,10,5,2.15768291411822,0.189722948741705,0.0410455763339996,172.855895996094,47.4995574951172,47.501953125,299.890960693359,299.890960693359,,,61.0216102600098,0,1,,,,,,1,1,1,47.5002403259277,0,47.5002341800266,,,,,,,,,,,,,,,,,,,,,,,,,,,,,,,,,
,3768661518.24955,47.5000381469727,299.890960693359,,,5,,,,25.0300001353025,,,,,0.000660168005319411,1.01580067467274E-7,0.000164620806990534,0.000124032548292708,0.000660068403822558,1.01564741782466E-7,0.000660068403819833,6.01129948563448E-8,1.89649210167851E-9,8.18646726173138E-8,1.00015089571971,10.005763053894,2,20,10,5,2.15952197620896,0.190253258982184,0.0410455763339996,172.855895996094,47.499439239502,47.5002212524414,299.890960693359,299.890960693359,,,61.071361541748,0,1,,,,,,1,1,1,47.5001640319824,0,47.4998881022135,,,,,,,,,,,,,,,,,,,,,,,,,,,,,,,,,
,3768661723.31604,47.4994487762451,299.890960693359,,,5,,,,25.0300001353025,,,,,0.000660269176586188,1.16868864217643E-7,-0.00177046410447801,0.000106602571617192,0.000660169577631512,1.16851235018639E-7,0.000660169577316335,9.32928195468899E-8,-2.03995224397309E-8,7.0360933381903E-8,1.0001508687435,10.005763053894,2,20,10,5,2.15985934973889,0.190209471596083,0.0410455763339996,172.855895996094,47.499153137207,47.5001983642578,299.890960693359,299.890960693359,,,61.0962333679199,0,1,,,,,,1,1,1,47.4996452331543,0,47.4996611277262,,,,,,,,,,,,,,,,,,,,,,,,,,,,,,,,,
,3768661933.81772,47.5002021789551,299.890960693359,,,5,,,,25.0300001353025,,,,,0.000660672118202949,1.84058822328406E-7,-0.00268333604383386,0.000176717469272494,0.000660572435690306,1.84031051448755E-7,0.000660572434965878,1.42285923659586E-7,-3.09366211729127E-8,1.16713940151434E-7,1.00015090322765,10.005763053894,2,20,10,5,2.16118047674171,0.190291113689338,0.0410455763339996,172.855895996094,47.4998245239258,47.5006561279297,299.890960693359,299.890960693359,,,61.1211051940918,0,1,,,,,,1,1,1,47.5004539489746,0,47.5001409194049,,,,,,,,,,,,,,,,,,,,,,,,,,,,,,,,,
,3768662141.46995,47.5005722045898,299.890960693359,,,5,,,,25.0300001353025,,,,,0.000661039732068617,1.4094818613685E-7,-0.00150368600056971,0.000154847224648802,0.00066093998289789,1.40926917423336E-7,0.000660939982670275,9.68928532164954E-8,-1.73458884377222E-8,1.02333626193986E-7,1.00015092016417,10.005763053894,2,20,10,5,2.16237908907121,0.190441516992664,0.0410455763339996,172.855895996094,47.4995079040527,47.5010795593262,299.890960693359,299.890960693359,,,61.1459846496582,0,1,,,,,,1,1,1,47.5004615783691,0,47.5001476512236,,,,,,,,,,,,,,,,,,,,,,,,,,,,,,,,,
,3768662350.88117,47.5006198883057,299.890960693359,,,5,,,,25.0300001353025,,,,,0.000661382742244628,1.27692802132027E-7,-0.00145688864173099,0.000133455060334504,0.000661283015728389,1.27673547988409E-7,0.00066128301551461,9.22727005664924E-8,-1.68147762831381E-8,8.82399205921851E-8,1.00015080761772,10.005763053894,2,20,10,5,2.1635009809332,0.190542104217451,0.0410455763339996,172.855895996094,47.4994735717773,47.5012969970703,299.890960693359,299.890960693359,,,61.195728302002,0,1,,,,,,1,1,1,47.5002326965332,0,47.5001238654642,,,,,,,,,,,,,,,,,,,,,,,,,,,,,,,,,
,3768662560.32813,47.5006675720215,299.890960693359,,,5,,,,25.0300001353025,,,,,0.000661552345882165,1.12304656382568E-7,-0.00293374999430451,0.000128614224898952,0.000661452592348831,1.12287722293598E-7,0.000661452591481731,7.32977565710743E-8,-3.38687518466357E-8,8.50645135149296E-8,1.00015080980026,10.005763053894,2,20,10,5,2.16406069680806,0.190535183952278,0.0410455763339996,172.855895996094,47.5001182556152,47.5009994506836,299.890960693359,299.890960693359,,,61.2206077575684,0,1,,,,,,1,1,1,47.5005798339844,0,47.5004609051873,,,,,,,,,,,,,,,,,,,,,,,,,,,,,,,,,
,3768662768.44775,47.5006256103516,299.890960693359,,,5,,,,25.0300001353025,,,,,0.000661852130081644,1.12278202999394E-7,-0.00631492469330208,0.000113851100771014,0.000661752256704804,1.12261260237152E-7,0.000661752252685448,8.32342225000401E-8,-7.29358373996593E-8,7.53303043591848E-8,1.00015092260862,10.005763053894,2,20,10,5,2.1650525919838,0.19049376007278,0.0410455763339996,172.855895996094,47.4996452331543,47.5007476806641,299.890960693359,299.890960693359,,,61.2330436706543,0,1,,,,,,1,1,1,47.5006446838379,0,47.5001691930434,,,,,,,,,,,,,,,,,,,,,,,,,,,,,,,,,
,3768662922.6227,47.5009117126465,299.890960693359,,,5,,,,25.0300001353025,,,,,0.000662001449606314,1.2884114481219E-7,-0.00123512704411866,0.000147259582498818,0.000661901545030726,1.28821701018074E-7,0.000661901544876932,8.42382743606262E-8,-1.426863384521E-8,9.74625250336448E-8,1.00015093570386,10.005763053894,2,20,10,5,2.16552414524425,0.190728729849024,0.0410455763339996,172.855895996094,47.4997940063477,47.5011405944824,299.890960693359,299.890960693359,,,61.2579154968262,0,1,,,,,,1,1,1,47.5010147094727,0,47.5004302978516,,,,,,,,,,,,,,,,,,,,,,,,,,,,,,,,,