File: Experimental_Data/Fig3C/Lifetime_160Oe_48K.dat
[Header]
; MPMS3 Data File (default extension .dat)
; Copyright (c) 2007, Quantum Design, Inc. All rights reserved.
TITLE,160Oe_48K
FILEOPENTIME,3768462182.765,05/31/2019,11:02 am
BYAPP,SQUID AC,0.9.1.0
INFO,MPMS3 Measurement Release 1.1.16 Build 347, MultiVu Release 2.3.3.2,APPNAME
INFO,0,MOMENT_UNITS
INFO,,SAMPLE_MATERIAL
INFO,,SAMPLE_COMMENT
INFO,,SAMPLE_MASS
INFO,,SAMPLE_VOLUME
INFO,,SAMPLE_MOLECULAR_WEIGHT
INFO,,SAMPLE_SIZE
INFO,,SAMPLE_SHAPE
INFO,Quartz,SAMPLE_HOLDER
INFO,Standard,SAMPLE_HOLDER_DETAIL
INFO,66.2,SAMPLE_OFFSET
DATATYPE,COMMENT,1
DATATYPE,TIME,2
STARTUPAXIS,X,2
STARTUPAXIS,Y1,5
FIELDGROUP, VSM,2,3,4,5,6,8,9,10,11,14,15
FIELDGROUP, DC, 2,3,4,14,56,57,58,59,60,61,62,63,64,65,66,67,68,69
FIELDGROUP, AC, 2,3,4,11,16,17,18,19,20,21,22,23,24,25,26,27,28,29,30
STARTUPGROUP, All
[Data]
Comment,Time Stamp (sec),Temperature (K),Magnetic Field (Oe),Moment (emu),M. Std. Err. (emu),Transport Action,Averaging Time (sec),Frequency (Hz),Peak Amplitude (mm),Center Position (mm),Lockin Signal' (V),Lockin Signal (V),Range,M. Quad. Signal (emu),AC Moment (emu),AC M. Std Err. (emu),AC Phase (deg),AC Phase Std. Err. (deg),AC Susceptibility (emu/Oe),AC Suscept. Std Err. (emu/Oe),AC X' (emu/Oe),AC X' Std Err. (emu/Oe),AC X'' (emu/Oe),AC X'' Std Err. (emu/Oe),AC Drive (Oe),AC Frequency (Hz),AC Averaging Time (sec),AC Cycles,AC Range,AC Measure Type,AC Signal' (V),AC Signal'' (V),AC Trim Coil Ratio,AC Trim Coil Phase,Min. Temperature (K),Max. Temperature (K),Min. Field (Oe),Max. Field (Oe),Mass (grams),Motor Lag (deg),Pressure (Torr),Measure Count,Measurement Number,SQUID Status (code),Motor Status (code),Measure Status (code),Motor Current (amps),Motor Temp. (C),Temp. Status (code),Field Status (code),Chamber Status (code),Chamber Temp (K),Redirection State,Average Temp (K),Rotation Angle (deg),Rotator state,DC Moment Fixed Ctr (emu),DC Moment Err Fixed Ctr (emu),DC Moment Free Ctr (emu),DC Moment Err Free Ctr (emu),DC Fixed Fit,DC Free Fit,DC Calculated Center (mm),DC Calculated Center Err (mm),DC Scan Length (mm),DC Scan Time (s),DC Number of Points,DC Squid Drift,DC Min V (V),DC Max V (V),DC Scans per Measure,Map 01,Map 02,Map 03,Map 04,Map 05,Map 06,Map 07,Map 08,Map 09,Map 10,Map 11,Map 12,Map 13,Map 14,Map 15,Map 16
,3768462186.60951,47.9709968566895,160.224365234375,,,5,,,,25.0300001353025,,,,,0.000567137866550959,1.35602696857999E-7,0.243479237735288,0.000130123023078499,0.000567052763594306,1.35582348736117E-7,0.000567047643577056,1.13787887612023E-7,2.40969160851641E-6,7.37217059053557E-8,1.00015007943196,10.005763053894,2,20,10,5,1.85451227057871,0.171040915188833,0.0410455763339996,172.855895996094,47.920280456543,47.9838066101074,160.224365234375,160.224365234375,,,301.430877685547,0,1,,,,,,1,1,1,47.964973449707,0,47.944398094626,,,,,,,,,,,,,,,,,,,,,,,,,,,,,,,,,
,3768462394.50534,47.9994029998779,160.224365234375,,,5,,,,25.0300001353025,,,,,0.000579272088149111,1.66234758747095E-7,0.0999705573858041,0.000183900165677761,0.000579184743656234,1.66209693340011E-7,0.000579183862027025,1.27619005178051E-7,1.01056993666447E-6,1.06484983342936E-7,1.00015080592822,10.005763053894,2,20,10,5,1.89462220589028,0.169955380380549,0.0410455763339996,172.855895996094,47.9992790222168,47.9999313354492,160.224365234375,160.224365234375,,,304.490417480469,0,1,,,,,,1,1,1,47.9994964599609,0,47.999620998607,,,,,,,,,,,,,,,,,,,,,,,,,,,,,,,,,
,3768462602.52996,47.9995536804199,160.224365234375,,,5,,,,25.0300001353025,,,,,0.000582592437278405,9.04515624225549E-8,0.0914710524035369,8.43710298151868E-5,0.000582504588115959,9.04379232238763E-8,0.000582503845795638,7.59347881590374E-8,9.29951307479476E-7,4.91215421611523E-8,1.00015081282489,10.005763053894,2,20,10,5,1.90550738996554,0.170646884173109,0.0410455763339996,172.855895996094,47.9991340637207,48.0000152587891,160.224365234375,160.224365234375,,,308.209106445313,0,1,,,,,,1,1,1,47.999439239502,0,47.9997094098259,,,,,,,,,,,,,,,,,,,,,,,,,,,,,,,,,
,3768462808.13465,47.9996891021729,160.224365234375,,,5,,,,25.0300001353025,,,,,0.000584829491815251,1.12305137668266E-7,0.0853463952833087,0.000102931506596054,0.000584741301703324,1.12288202471256E-7,0.000584740652981072,9.48143475009112E-8,8.71016054627261E-7,6.01571269443808E-8,1.00015081902317,10.005763053894,2,20,10,5,1.91284251045337,0.171097664791952,0.0410455763339996,172.855895996094,47.9995002746582,48.0003280639648,160.224365234375,160.224365234375,,,311.592010498047,0,1,,,,,,1,1,1,47.9996681213379,0,47.9997646107393,,,,,,,,,,,,,,,,,,,,,,,,,,,,,,,,,
,3768463016.7552,48.0005702972412,160.224365234375,,,5,,,,25.0300001353025,,,,,0.000587028624397966,1.08641331790834E-7,0.075747546292515,0.000111395043004079,0.000586940146326309,1.08624957162512E-7,0.000586939633399226,8.67596780826889E-8,7.75960521553707E-7,6.5361606295636E-8,1.00015074462398,10.005763053894,2,20,10,5,1.92006411172465,0.171419371480701,0.0410455763339996,172.855895996094,47.9997520446777,48.0014877319336,160.224365234375,160.224365234375,,,314.962463378906,0,1,,,,,,1,1,1,48.0003356933594,0,48.0002212524414,,,,,,,,,,,,,,,,,,,,,,,,,,,,,,,,,
,3768463224.28863,47.9993686676025,160.224365234375,,,5,,,,25.0300001353025,,,,,0.000588818537808133,1.08826793312544E-7,0.0630227211882568,0.000100256120750568,0.000588729754796117,1.08810384232534E-7,0.000588729398644448,9.14274210910957E-8,6.4757551123625E-7,5.89976812210717E-8,1.00015080435683,10.005763053894,2,20,10,5,1.9259567326707,0.17151431766004,0.0410455763339996,172.855895996094,47.9988708496094,48.0000114440918,160.224365234375,160.224365234375,,,318.357788085937,0,1,,,,,,1,1,1,47.9998664855957,0,47.9993963802562,,,,,,,,,,,,,,,,,,,,,,,,,,,,,,,,,
,3768463432.58232,48.000129699707,160.224365234375,,,5,,,,25.0300001353025,,,,,0.000590509880521889,8.44270905974927E-8,0.0627299081367969,0.000108959984089827,0.000590420821923715,8.44143576042195E-8,0.0005904204680603,5.46596175171337E-8,6.4641823249122E-7,6.43281430061034E-8,1.00015083918938,10.005763053894,2,20,10,5,1.93148979653188,0.171997108485191,0.0410455763339996,172.855895996094,47.9993743896484,48.000358581543,160.224365234375,160.224365234375,,,321.740661621094,0,1,,,,,,1,1,1,48.000358581543,0,47.9998643875122,,,,,,,,,,,,,,,,,,,,,,,,,,,,,,,,,
,3768463640.44052,48.000846862793,160.224365234375,,,5,,,,25.0300001353025,,,,,0.000591980733140164,8.15283378180022E-8,0.0621204026006135,8.65498060086203E-5,0.000591891501185953,8.1516048680029E-8,0.000591891153301256,6.34179538980822E-8,6.41731929619321E-7,5.12155183102306E-8,1.00015075728243,10.005763053894,2,20,10,5,1.9363026203033,0.17240492210473,0.0410455763339996,172.855895996094,48.0000076293945,48.001033782959,160.224365234375,160.224365234375,,,325.136016845703,0,1,,,,,,1,1,1,48.0008163452148,0,48.0004981545841,,,,,,,,,,,,,,,,,,,,,,,,,,,,,,,,,
,3768463845.50959,48.0012283325195,160.224365234375,,,5,,,,25.0300001353025,,,,,0.000593646840649113,7.42890287591702E-8,0.0529444477929957,6.69832747969861E-5,0.000593557347193018,7.42778295385589E-8,0.000593557093780397,6.2752243582483E-8,5.48479517608631E-7,3.97410604579689E-8,1.00015077474235,10.005763053894,2,20,10,5,1.94177993481188,0.17257917373087,0.0410455763339996,172.855895996094,47.9994201660156,48.0015106201172,160.224365234375,160.224365234375,,,328.531341552734,0,1,,,,,,1,1,1,48.0009460449219,0,48.0002562578987,,,,,,,,,,,,,,,,,,,,,,,,,,,,,,,,,
,3768464050.57305,48.0001468658447,160.224365234375,,,5,,,,25.0300001353025,,,,,0.000594840778713643,1.18909839968673E-7,0.0520042890667982,0.000169143235999827,0.000594751066477597,1.18891906316487E-7,0.000594750821493289,6.33664729877401E-8,5.3982339362501E-7,1.005980888917E-7,1.00015083997508,10.005763053894,2,20,10,5,1.94568806505489,0.172894339701699,0.0410455763339996,172.855895996094,47.9994125366211,48.0004768371582,160.224365234375,160.224365234375,,,331.926666259766,0,1,,,,,,1,1,1,48.0002746582031,0,47.9998431486242,,,,,,,,,,,,,,,,,,,,,,,,,,,,,,,,,
,3768464256.1555,48.0000801086426,160.224365234375,,,5,,,,25.0300001353025,,,,,0.000596435797440877,8.44257356191672E-8,0.0494700117036402,7.99392274961771E-5,0.000596345846470384,8.44130030218179E-8,0.000596345624187032,6.96750003951128E-8,5.14893637708824E-7,4.76544793183439E-8,1.00015083691959,10.005763053894,2,20,10,5,1.95091294032252,0.173271651775413,0.0410455763339996,172.855895996094,47.9993743896484,48.0002479553223,160.224365234375,160.224365234375,,,335.421478271484,0,1,,,,,,1,1,1,47.9999809265137,0,47.9998750125661,,,,,,,,,,,,,,,,,,,,,,,,,,,,,,,,,
,3768464464.22431,48.0007610321045,160.224365234375,,,5,,,,25.0300001353025,,,,,0.000597566421377451,7.41119839269731E-8,0.0487895544952615,7.27077355902033E-5,0.000597476281274725,7.41008044804623E-8,0.000597476064654457,6.00413219247427E-8,5.08773915106398E-7,4.34277432775538E-8,1.00015086808556,10.005763053894,2,20,10,5,1.95461321893383,0.173576895063507,0.0410455763339996,172.855895996094,47.9997711181641,48.0010070800781,160.224365234375,160.224365234375,,,339.028228759766,0,1,,,,,,1,1,1,48.0007514953613,0,48.0003623962402,,,,,,,,,,,,,,,,,,,,,,,,,,,,,,,,,
,3768464674.40337,47.9996013641357,160.224365234375,,,5,,,,25.0300001353025,,,,,0.000598833247788287,8.72822151578987E-8,0.0433222526976289,8.99601916851822E-5,0.000598742948366109,8.72690536749245E-8,0.000598742777212055,6.8673738950801E-8,4.5271904944629E-7,5.3849840369625E-8,1.00015081500738,10.005763053894,2,20,10,5,1.95877354079513,0.173757967928872,0.0410455763339996,172.855895996094,47.9990882873535,48.0002555847168,160.224365234375,160.224365234375,,,342.746948242188,0,1,,,,,,1,1,1,47.9996643066406,0,47.9995788998074,,,,,,,,,,,,,,,,,,,,,,,,,,,,,,,,,
,3768464881.65007,48.000825881958,160.224365234375,,,5,,,,25.0300001353025,,,,,0.000600196686998843,6.12147851768922E-8,0.0421671780962853,6.25683483600548E-5,0.000600106217192651,6.12055580520662E-8,0.000600106054674481,4.83425061754074E-8,4.41651787754486E-7,3.75382795709332E-8,1.00015075632213,10.005763053894,2,20,10,5,1.96323683854543,0.174114001912436,0.0410455763339996,172.855895996094,48.0000610351562,48.0009078979492,160.224365234375,160.224365234375,,,346.478057861328,0,1,,,,,,1,1,1,48.0007553100586,0,48.0004113515218,,,,,,,,,,,,,,,,,,,,,,,,,,,,,,,,,
,3768465088.84279,48.0008792877197,160.224365234375,,,5,,,,25.0300001353025,,,,,0.000601140523611991,2.00817247197769E-7,0.0444015874284798,0.000149252560699664,0.000601049910068931,2.00786976800813E-7,0.000601049729587615,1.79664319335114E-7,4.65785921517884E-7,8.96445336351327E-8,1.00015075876652,10.005763053894,2,20,10,5,1.96631731561618,0.174464486229675,0.0410455763339996,172.855895996094,47.9999961853027,48.0014152526855,160.224365234375,160.224365234375,,,350.258941650391,0,1,,,,,,1,1,1,48.0007705688477,0,48.0004766127642,,,,,,,,,,,,,,,,,,,,,,,,,,,,,,,,,
,3768465295.74741,47.9984474182129,160.224365234375,,,5,,,,25.0300001353025,,,,,0.000602241720530762,7.66522046667981E-8,0.0442623482073765,9.09983557226786E-5,0.000602150869860513,7.66406413626751E-8,0.000602150690180845,5.35912408793398E-8,4.65175778227092E-7,5.47883820667737E-8,1.00015087692271,10.005763053894,2,20,10,5,1.96991973039048,0.174779298412868,0.0410455763339996,172.855895996094,47.9974899291992,48.0027389526367,160.224365234375,160.224365234375,,,354.126892089844,0,1,,,,,,1,1,1,47.998851776123,0,48.0003564622667,,,,,,,,,,,,,,,,,,,,,,,,,,,,,,,,,
,3768465504.73916,48.0010719299316,160.224365234375,,,5,,,,25.0300001353025,,,,,0.000603494313217504,1.12802903058123E-7,0.0422590463943973,0.000135381735313635,0.000603403339553952,1.12785898600707E-7,0.000603403175430057,7.77743970444284E-8,4.4504582406486E-7,8.16810999408337E-8,1.00015076758378,10.005763053894,2,20,10,5,1.97402305736186,0.175073791478603,0.0410455763339996,172.855895996094,47.9997673034668,48.0017204284668,160.224365234375,160.224365234375,,,358.119201660156,0,1,,,,,,1,1,1,48.0007972717285,0,48.0004745932186,,,,,,,,,,,,,,,,,,,,,,,,,,,,,,,,,
,3768465714.01434,48.001012802124,160.224365234375,,,5,,,,25.0300001353025,,,,,0.00060451696161465,1.53657632425928E-7,0.0395988307712702,0.000127726248971878,0.000604425835427616,1.53634469743918E-7,0.000604425691072405,1.32850991108689E-7,4.17736780420001E-7,7.71632325329484E-8,1.0001507648775,10.005763053894,2,20,10,5,1.97737626900063,0.175278652504217,0.0410455763339996,172.855895996094,47.9996643066406,48.001277923584,160.224365234375,160.224365234375,,,362.210998535156,0,1,,,,,,1,1,1,48.0010528564453,0,48.0004252265481,,,,,,,,,,,,,,,,,,,,,,,,,,,,,,,,,
,3768465921.921,48.0000457763672,160.224365234375,,,5,,,,25.0300001353025,,,,,0.000605489877023353,8.63573978042481E-8,0.0407644081446277,0.000107877983964434,0.000605398561520527,8.63443740205277E-8,0.000605398408295965,5.64864246761849E-8,4.30724779027086E-7,6.53041710176193E-8,1.0001508353482,10.005763053894,2,20,10,5,1.98055510518699,0.175601041945051,0.0410455763339996,172.855895996094,47.9996910095215,48.0003776550293,160.224365234375,160.224365234375,,,366.352569580078,0,1,,,,,,1,1,1,48.0001449584961,0,47.9999775606043,,,,,,,,,,,,,,,,,,,,,,,,,,,,,,,,,
,3768466128.68965,47.9989910125732,160.224365234375,,,5,,,,25.0300001353025,,,,,0.000606782162649282,1.05157989272176E-7,0.0403695463585505,0.000131498593465849,0.000606690681538109,1.05142135197519E-7,0.000606690530946843,6.84918620800943E-8,4.27462995972109E-7,7.97730118692702E-8,1.0001507870715,10.005763053894,2,20,10,5,1.98478337888922,0.175962150206307,0.0410455763339996,172.855895996094,47.9989433288574,48.0000381469727,160.224365234375,160.224365234375,,,370.581176757812,0,1,,,,,,1,1,1,47.9989356994629,0,47.9992898305257,,,,,,,,,,,,,,,,,,,,,,,,,,,,,,,,,
,3768466337.95362,48.0010452270508,160.224365234375,,,5,,,,25.0300001353025,,,,,0.00060763217429057,7.30806196846623E-8,0.0385965112708506,8.44620335833222E-5,0.000607540577608166,7.3069603246438E-8,0.000607540439761549,5.20260353222049E-8,4.09261295979617E-7,5.13074903619788E-8,1.00015076636159,10.005763053894,2,20,10,5,1.98756921800101,0.176147133880756,0.0410455763339996,172.855895996094,47.9998664855957,48.0016479492188,160.224365234375,160.224365234375,,,374.909301757812,0,1,,,,,,1,1,1,48.0008239746094,0,48.0006327909582,,,,,,,,,,,,,,,,,,,,,,,,,,,,,,,,,
,3768466546.08997,47.9999732971191,160.224365234375,,,5,,,,25.0300001353025,,,,,0.000608572772345514,9.06968010436677E-8,0.0299396800843308,9.80176781748861E-5,0.00060848099392149,9.06831231240466E-8,0.000608480910847311,6.83193021408186E-8,3.17959291611941E-7,5.963138246362E-8,1.00015083203081,10.005763053894,2,20,10,5,1.99067255334056,0.176119038553533,0.0410455763339996,172.855895996094,47.9997520446777,48.0002136230469,160.224365234375,160.224365234375,,,379.411560058594,0,1,,,,,,1,1,1,48.0000953674316,0,47.9999622768826,,,,,,,,,,,,,,,,,,,,,,,,,,,,,,,,,
,3768466754.35279,48.0004749298096,160.224365234375,,,5,,,,25.0300001353025,,,,,0.000609520532430839,1.30557700915302E-7,0.0317517746852456,0.000117708680704749,0.000609428666995735,1.30538023579818E-7,0.000609428573415611,1.09077354175596E-7,3.3772890246331E-7,7.17098766292127E-8,1.000150740259,10.005763053894,2,20,10,5,1.99376714528464,0.176456372163055,0.0410455763339996,172.855895996094,48.0001525878906,48.0009536743164,160.224365234375,160.224365234375,,,383.988403320313,0,1,,,,,,1,1,1,48.0006523132324,0,48.0004099677591,,,,,,,,,,,,,,,,,,,,,,,,,,,,,,,,,
,3768466963.59482,48.0006790161133,160.224365234375,,,5,,,,25.0300001353025,,,,,0.000610460512935042,6.87450024879555E-8,0.0307375443200879,6.66996139391392E-5,0.000610368430109755,6.87346328835023E-8,0.000610368342277278,5.53888914179205E-8,3.27445161434257E-7,4.07003742626975E-8,1.00015086433168,10.005763053894,2,20,10,5,1.99684498891551,0.176693149055043,0.0410455763339996,172.855895996094,47.9997863769531,48.0007247924805,160.224365234375,160.224365234375,,,388.739379882812,0,1,,,,,,1,1,1,48.0007286071777,0,48.0002691745758,,,,,,,,,,,,,,,,,,,,,,,,,,,,,,,,,
,3768467170.78992,47.9999504089355,160.224365234375,,,5,,,,25.0300001353025,,,,,0.000611345831091087,9.76151754135361E-8,0.0334092025007919,9.1510093656074E-5,0.00061125363510431,9.76004542410605E-8,0.000611253531189272,7.99934410764232E-8,3.56422331467586E-7,5.59186735609327E-8,1.00015083098322,10.005763053894,2,20,10,5,1.99973265270608,0.177042646728305,0.0410455763339996,172.855895996094,47.9993743896484,48.0001525878906,160.224365234375,160.224365234375,,,393.577423095703,0,1,,,,,,1,1,1,47.9999885559082,0,47.9997823503282,,,,,,,,,,,,,,,,,,,,,,,,,,,,,,,,,
,3768467377.76206,47.9987316131592,160.224365234375,,,5,,,,25.0300001353025,,,,,0.000612129293000062,8.33517060522077E-8,0.0337475058688277,9.56568887472974E-5,0.000612037012997788,8.3339140576724E-8,0.000612036906831709,5.93187014193759E-8,3.60492896149295E-7,5.85380561172465E-8,1.00015077519874,10.005763053894,2,20,10,5,2.00229433564664,0.177281360671611,0.0410455763339996,172.855895996094,47.9975891113281,48.0015525817871,160.224365234375,160.224365234375,,,398.527404785156,0,1,,,,,,1,1,1,47.9987602233887,0,47.9999321831597,,,,,,,,,,,,,,,,,,,,,,,,,,,,,,,,,
,3768467587.7266,48.0008773803711,160.224365234375,,,5,,,,25.0300001353025,,,,,0.000613140870623797,9.08425227945097E-8,0.0298573939884861,0.000101102187941069,0.00061304844824944,9.08288295601299E-8,0.000613048365011116,6.64035210940305E-8,3.19465558903998E-7,6.19713535883941E-8,1.00015075867922,10.005763053894,2,20,10,5,2.0056152905106,0.177438150678934,0.0410455763339996,172.855895996094,47.9998474121094,48.001823425293,160.224365234375,160.224365234375,,,403.775817871094,0,1,,,,,,1,1,1,48.0002746582031,0,48.0002840827493,,,,,,,,,,,,,,,,,,,,,,,,,,,,,,,,,
,3768467797.12778,47.999963760376,160.224365234375,,,5,,,,25.0300001353025,,,,,0.000613793054048515,1.32025986443207E-7,0.028499259814045,0.000202316052301922,0.000613700488625384,1.32006075756341E-7,0.000613700412706754,4.48198429544634E-8,3.05258242418003E-7,1.24164349610209E-7,1.00015083159431,10.005763053894,2,20,10,5,2.00775282565131,0.177579298529372,0.0410455763339996,172.855895996094,47.9990043640137,48.0003280639648,160.224365234375,160.224365234375,,,409.173522949219,0,1,,,,,,1,1,1,47.9995994567871,0,47.9995492299398,,,,,,,,,,,,,,,,,,,,,,,,,,,,,,,,,
,3768468007.47184,47.9995288848877,160.224365234375,,,5,,,,25.0300001353025,,,,,0.000614793184957907,1.22698136595465E-7,0.0341628511151439,0.000127839731105736,0.000614700480939535,1.22679635072371E-7,0.000614700371670654,9.42203049123302E-8,3.66517742578886E-7,7.85673405666614E-8,1.00015081169,10.005763053894,2,20,10,5,2.01100672022469,0.178067436899326,0.0410455763339996,172.855895996094,47.9992408752441,48.0002098083496,160.224365234375,160.224365234375,,,414.757781982422,0,1,,,,,,1,1,1,47.9995002746582,0,47.999593310886,,,,,,,,,,,,,,,,,,,,,,,,,,,,,,,,,
,3768468215.29234,47.9997444152832,160.224365234375,,,5,,,,25.0300001353025,,,,,0.000615513379454358,1.0546003512181E-7,0.0294383111823455,0.000128277023024673,0.000615420560768493,1.05444131873891E-7,0.000615420479537359,6.99094867880311E-8,3.16200273960447E-7,7.89374980834365E-8,1.00015082155485,10.005763053894,2,20,10,5,2.01337719148998,0.178110010834776,0.0410455763339996,172.855895996094,47.9995040893555,48.0000839233398,160.224365234375,160.224365234375,,,420.466430664063,0,1,,,,,,1,1,1,47.9999351501465,0,47.9997744840734,,,,,,,,,,,,,,,,,,,,,,,,,,,,,,,,,
,3768468423.41572,47.9988040924072,160.224365234375,,,5,,,,25.0300001353025,,,,,0.000616356696282,8.86616350224858E-8,0.030886537833978,9.81625844786325E-5,0.000616263776944167,8.86482687680634E-8,0.00061626368740154,6.48079714408665E-8,3.32210394939523E-7,6.04850592567672E-8,1.00015077851613,10.005763053894,2,20,10,5,2.0161312168559,0.178405003825181,0.0410455763339996,172.855895996094,47.9982795715332,48.0003509521484,160.224365234375,160.224365234375,,,426.39892578125,0,1,,,,,,1,1,1,47.9990539550781,0,47.9994733598497,,,,,,,,,,,,,,,,,,,,,,,,,,,,,,,,,
,3768468631.85529,48.0009994506836,160.224365234375,,,5,,,,25.0300001353025,,,,,0.000617123670501091,8.40817230208206E-8,0.0265845733210615,7.6432358258051E-5,0.000617030644328653,8.40690484124099E-8,0.000617030577909879,6.96049201997027E-8,2.86295010842463E-7,4.7146155569263E-8,1.0001507642664,10.005763053894,2,20,10,5,2.01865343187811,0.178475430594091,0.0410455763339996,172.855895996094,48.0000038146973,48.0011405944824,160.224365234375,160.224365234375,,,432.580169677734,0,1,,,,,,1,1,1,48.0010032653809,0,48.0005476209852,,,,,,,,,,,,,,,,,,,,,,,,,,,,,,,,,
,3768468839.70769,48.0006408691406,160.224365234375,,,5,,,,25.0300001353025,,,,,0.000617834757364149,8.18778786119216E-8,0.0314349844486292,8.91802978518811E-5,0.000617741634138434,8.18655375578127E-8,0.000617741541165166,6.05638715754064E-8,3.38920211108642E-7,5.50816094484113E-8,1.00015074785407,10.005763053894,2,20,10,5,2.02096431171136,0.178852167113428,0.0410455763339996,172.855895996094,47.999439239502,48.0010299682617,160.224365234375,160.224365234375,,,439.010162353516,0,1,,,,,,1,1,1,48.0010643005371,0,48.0001460804659,,,,,,,,,,,,,,,,,,,,,,,,,,,,,,,,,
,3768469046.51675,48.000150680542,160.224365234375,,,5,,,,25.0300001353025,,,,,0.000618750847228018,1.23869428890375E-7,0.0328246079610714,0.000155965620905761,0.000618657528833769,1.23850747225126E-7,0.000618657427308506,7.76528692568193E-8,3.54427322708031E-7,9.64833637701619E-8,1.00015084014968,10.005763053894,2,20,10,5,2.02395653634097,0.179166449836582,0.0410455763339996,172.855895996094,47.9995994567871,48.00048828125,160.224365234375,160.224365234375,,,445.651580810547,0,1,,,,,,1,1,1,48.0003242492676,0,48.0000412884881,,,,,,,,,,,,,,,,,,,,,,,,,,,,,,,,,
,3768469253.14004,48.0001850128174,160.224365234375,,,5,,,,25.0300001353025,,,,,0.000619453744877974,7.06925786395944E-8,0.0337403707461545,8.3102973712817E-5,0.000619360319501417,7.06819168576069E-8,0.000619360212110437,4.84484171848708E-8,3.6472923093505E-7,5.14653693559695E-8,1.00015084172107,10.005763053894,2,20,10,5,2.02625287287926,0.179402368944642,0.0410455763339996,172.855895996094,47.9993133544922,48.0003509521484,160.224365234375,160.224365234375,,,452.554168701172,0,1,,,,,,1,1,1,48.0000190734863,0,47.9998617733226,,,,,,,,,,,,,,,,,,,,,,,,,,,,,,,,,
,3768469460.78841,48.0009441375732,160.224365234375,,,5,,,,25.0300001353025,,,,,0.000620277535414772,8.29233393007134E-8,0.0299805438870679,6.7168209221346E-5,0.000620184035393757,8.29108395187214E-8,0.000620183950490504,7.16974126554823E-8,3.24516988872699E-7,4.16375831216061E-8,1.00015076173471,10.005763053894,2,20,10,5,2.02895930224388,0.179507802512554,0.0410455763339996,172.855895996094,47.99951171875,48.0012092590332,160.224365234375,160.224365234375,,,459.755249023438,0,1,,,,,,1,1,1,48.0012550354004,0,48.0003695768468,,,,,,,,,,,,,,,,,,,,,,,,,,,,,,,,,
,3768469669.72537,48.0006084442139,160.224365234375,,,5,,,,25.0300001353025,,,,,0.000620900069291573,7.6445366620986E-8,0.02830415544038,8.28385774203212E-5,0.000620806484967508,7.64338444963851E-8,0.000620806409217728,5.65531610978915E-8,3.06678828415736E-7,5.14186012483178E-8,1.00015074636997,10.005763053894,2,20,10,5,2.03100089835551,0.179628542975372,0.0410455763339996,172.855895996094,47.9995460510254,48.0010299682617,160.224365234375,160.224365234375,,,467.366760253906,0,1,,,,,,1,1,1,48.0003356933594,0,48.0002691480849,,,,,,,,,,,,,,,,,,,,,,,,,,,,,,,,,
,3768469876.69611,48.0002193450928,160.224365234375,,,5,,,,25.0300001353025,,,,,0.000621587050809201,8.36362383056441E-8,0.0294737972401835,9.73781803695315E-5,0.00062149337400736,8.36236338356631E-8,0.000621493291776768,5.77151881157555E-8,3.19705378640418E-7,6.05133803108372E-8,1.00015072856085,10.005763053894,2,20,10,5,2.03324438406296,0.179868796954616,0.0410455763339996,172.855895996094,47.9994125366211,48.0006561279297,160.224365234375,160.224365234375,,,475.264312744141,0,1,,,,,,1,1,1,48.0000953674316,0,48.0000444300034,,,,,,,,,,,,,,,,,,,,,,,,,,,,,,,,,
,3768470082.1634,48.0008506774902,160.224365234375,,,5,,,,25.0300001353025,,,,,0.000622188022537694,9.43993686411187E-8,0.0293602739356711,0.000100638703212641,0.000622094165829351,9.43851285501986E-8,0.000622094084152109,7.06418732236969E-8,3.18781845336561E-7,6.25961519494981E-8,1.00015087218865,10.005763053894,2,20,10,5,2.03521055164409,0.180038664595531,0.0410455763339996,172.855895996094,47.9996337890625,48.0010795593262,160.224365234375,160.224365234375,,,483.497680664063,0,1,,,,,,1,1,1,48.0009078979492,0,48.000358581543,,,,,,,,,,,,,,,,,,,,,,,,,,,,,,,,,
,3768470289.04477,48.0012302398682,160.224365234375,,,5,,,,25.0300001353025,,,,,0.000622850866160327,8.91075830073779E-8,0.0310471500445528,0.000115882751784637,0.000622756970084246,8.90941498521108E-8,0.000622756878654649,5.22508431430251E-8,3.3745641144253E-7,7.21638200812108E-8,1.00015077482965,10.005763053894,2,20,10,5,2.03737344167858,0.180290451344532,0.0410455763339996,172.855895996094,47.999267578125,48.0018043518066,160.224365234375,160.224365234375,,,492.153900146484,0,1,,,,,,1,1,1,48.0008239746094,0,48.0002382066515,,,,,,,,,,,,,,,,,,,,,,,,,,,,,,,,,
,3768470498.09873,48.000072479248,160.224365234375,,,5,,,,25.0300001353025,,,,,0.000623665239274697,1.0435651352233E-7,0.0269690466855295,0.00010789053652625,0.000623571253468766,1.04340787087041E-7,0.000623571184390408,7.9765062929884E-8,2.93514143074377E-7,6.72646607494215E-8,1.00015072183878,10.005763053894,2,20,10,5,2.04005013667189,0.180380981830466,0.0410455763339996,172.855895996094,47.9985809326172,48.000659942627,160.224365234375,160.224365234375,,,501.444427490234,0,1,,,,,,1,1,1,47.9996109008789,0,47.9992184358485,,,,,,,,,,,,,,,,,,,,,,,,,,,,,,,,,
,3768470705.75631,47.9994258880615,160.224365234375,,,5,,,,25.0300001353025,,,,,0.000624391163546431,1.02707927684E-7,0.0290092893802045,0.000107771367597511,0.000624297015201559,1.02692440947542E-7,0.000624296935183102,7.75923702900182E-8,3.16086318282576E-7,6.72693206487254E-8,1.00015080697581,10.005763053894,2,20,10,5,2.04241825101377,0.18066366614086,0.0410455763339996,172.855895996094,47.9985656738281,48.0021476745605,160.224365234375,160.224365234375,,,511.170227050781,0,1,,,,,,1,1,1,47.999927520752,0,48.0007391536937,,,,,,,,,,,,,,,,,,,,,,,,,,,,,,,,,
,3768470911.65411,48.0007972717285,160.224365234375,,,5,,,,25.0300001353025,,,,,0.000624883508301029,9.33477897961273E-8,0.0314442899475988,8.92021252027869E-5,0.000624789318179471,9.33337192700992E-8,0.000624789224089809,7.48778857233102E-8,3.42888353344034E-7,5.57179089916033E-8,1.00015075501264,10.005763053894,2,20,10,5,2.04402105238524,0.180892989804273,0.0410455763339996,172.855895996094,47.9997520446777,48.0013999938965,160.224365234375,160.224365234375,,,521.331359863281,0,1,,,,,,1,1,1,48.0003700256348,0,48.0002657572428,,,,,,,,,,,,,,,,,,,,,,,,,,,,,,,,,
,3768471116.35033,47.9993762969971,160.224365234375,,,5,,,,25.0300001353025,,,,,0.00062577247623212,1.0865637325374E-7,0.0298788054722001,0.000132418957925351,0.000625678121027013,1.08639989832011E-7,0.000625678035951973,7.02800501461857E-8,3.26280821692909E-7,8.28454099039236E-8,1.00015080470602,10.005763053894,2,20,10,5,2.04693385341154,0.181094407145431,0.0410455763339996,172.855895996094,47.9987602233887,47.999584197998,160.224365234375,160.224365234375,,,532.126770019531,0,1,,,,,,1,1,1,47.9992446899414,0,47.9991965823703,,,,,,,,,,,,,,,,,,,,,,,,,,,,,,,,,
,3768471322.96087,48.0007591247559,160.224365234375,,,5,,,,25.0300001353025,,,,,0.000626214437114558,9.67229244611787E-8,0.0269984202856497,0.000119610355173894,0.000626119975647159,9.67083342683722E-8,0.000626119906135284,6.11938278972676E-8,2.95034813556079E-7,7.48853613481487E-8,1.00015086799826,10.005763053894,2,20,10,5,2.04838863861856,0.181119323774266,0.0410455763339996,172.855895996094,47.9998435974121,48.001033782959,160.224365234375,160.224365234375,,,543.805236816406,0,1,,,,,,1,1,1,48.001033782959,0,48.0003967285156,,,,,,,,,,,,,,,,,,,,,,,,,,,,,,,,,
,3768471529.82665,48.0036010742188,160.224365234375,,,5,,,,25.0300001353025,,,,,0.000626860355584059,1.06286680036687E-7,0.026677660980071,8.73038906455955E-5,0.000626765858965791,1.06270657757178E-7,0.000626765791025788,9.11139934495156E-8,2.91830334403503E-7,5.46963700607708E-8,1.00015076861146,10.005763053894,2,20,10,5,2.05050249635139,0.181294652411327,0.0410455763339996,172.855895996094,48.0015068054199,48.0039367675781,160.224365234375,160.224365234375,,,556.36669921875,0,1,,,,,,1,1,1,48.0036201477051,0,48.0027591480928,,,,,,,,,,,,,,,,,,,,,,,,,,,,,,,,,
,3768471734.818,48.0010871887207,160.224365234375,,,5,,,,25.0300001353025,,,,,0.000627618312490149,1.1649274603657E-7,0.0238476007191224,0.000107908052157151,0.000627523701819597,1.16475185272969E-7,0.000627523647464003,9.47823819135888E-8,2.61187375019113E-7,6.76961510217466E-8,1.00015076828218,10.005763053894,2,20,10,5,2.05299078674395,0.18141246692829,0.0410455763339996,172.855895996094,47.999683380127,48.0012550354004,160.224365234375,160.224365234375,,,569.761474609375,0,1,,,,,,1,1,1,48.0010452270508,0,48.0003668841194,,,,,,,,,,,,,,,,,,,,,,,,,,,,,,,,,
,3768471940.22894,48.0000343322754,160.224365234375,,,5,,,,25.0300001353025,,,,,0.000628224392747453,9.80651258889935E-8,0.031032289941364,8.27065630422964E-5,0.000628129648922157,9.80503364837076E-8,0.00062812955679203,8.31693313438693E-8,3.40204821345801E-7,5.19300568879137E-8,1.0001508348244,10.005763053894,2,20,10,5,2.05495053779918,0.181845343083148,0.0410455763339996,172.855895996094,47.9989395141602,48.0002212524414,160.224365234375,160.224365234375,,,584.263122558594,0,1,,,,,,1,1,1,47.9999847412109,0,47.9997112049776,,,,,,,,,,,,,,,,,,,,,,,,,,,,,,,,,
,3768472146.69974,47.9999961853027,160.224365234375,,,5,,,,25.0300001353025,,,,,0.000628591535017531,1.2415730831521E-7,0.0322501471945396,0.000108459228026389,0.000628496736919932,1.2413858411042E-7,0.000628496637358494,1.03764281964714E-7,3.5376272700919E-7,6.81422178483131E-8,1.00015083307841,10.005763053894,2,20,10,5,2.05614760876612,0.181995321904204,0.0410455763339996,172.855895996094,47.999153137207,48.0004577636719,160.224365234375,160.224365234375,,,600.20751953125,0,1,,,,,,1,1,1,47.999641418457,0,47.9999605066636,,,,,,,,,,,,,,,,,,,,,,,,,,,,,,,,,
,3768472353.73346,48.0009860992432,160.224365234375,,,5,,,,25.0300001353025,,,,,0.000629292022207788,9.39623533370748E-8,0.025474762907348,8.24643211593434E-5,0.000629197162143719,9.39481893646373E-8,0.00062919709995211,7.83317016887338E-8,2.79752682234162E-7,5.18691314313336E-8,1.0001507636553,10.005763053894,2,20,10,5,2.05846046139087,0.181954710596928,0.0410455763339996,172.855895996094,47.9994163513184,48.0011177062988,160.224365234375,160.224365234375,,,617.855773925781,0,1,,,,,,1,1,1,48.000919342041,0,48.0003615485297,,,,,,,,,,,,,,,,,,,,,,,,,,,,,,,,,
,3768472560.45199,47.9999294281006,160.224365234375,,,5,,,,25.0300001353025,,,,,0.000629927206348436,1.14563125601597E-7,0.0263335865204359,0.000104937554741378,0.000629832208741955,1.1454584864862E-7,0.000629832142219293,9.35680217197883E-8,2.89475778482947E-7,6.60740248061042E-8,1.00015083002292,10.005763053894,2,20,10,5,2.06053546466527,0.1821692591946,0.0410455763339996,172.855895996094,47.9995384216309,48.0003433227539,160.224365234375,160.224365234375,,,637.493957519531,0,1,,,,,,1,1,1,47.9998664855957,0,47.9999317842371,,,,,,,,,,,,,,,,,,,,,,,,,,,,,,,,,
,3768472765.57733,48.0006046295166,160.224365234375,,,5,,,,25.0300001353025,,,,,0.000630594137362025,6.53469581368582E-8,0.0307790913605759,6.12628693045605E-5,0.000630499092022716,6.53371088162874E-8,0.000630499001047984,5.27045062281522E-8,3.38701879748806E-7,3.86157068007054E-8,1.00015074619537,10.005763053894,2,20,10,5,2.06270288690896,0.182522170222949,0.0410455763339996,172.855895996094,48,48.0014495849609,160.224365234375,160.224365234375,,,659.470336914062,0,1,,,,,,1,1,1,48.0004577636719,0,48.0004976060655,,,,,,,,,,,,,,,,,,,,,,,,,,,,,,,,,
,3768472970.80634,48.0001373291016,160.224365234375,,,5,,,,25.0300001353025,,,,,0.000631239789759483,9.32932036203688E-8,0.0310020704816383,9.67267060713282E-5,0.000631144588201021,9.32791334389216E-8,0.000631144495808889,7.05366618128736E-8,3.41504875560031E-7,6.10374972898827E-8,1.00015083953858,10.005763053894,2,20,10,5,2.06481413491698,0.182717087527432,0.0410455763339996,172.855895996094,47.999870300293,48.0006294250488,160.224365234375,160.224365234375,,,684.568481445313,0,1,,,,,,1,1,1,48.0002288818359,0,48.00018714456,,,,,,,,,,,,,,,,,,,,,,,,,,,,,,,,,
,3768473178.47248,48.0000991821289,160.224365234375,,,5,,,,25.0300001353025,,,,,0.00063171081199647,9.15880982863473E-8,0.033210389516583,8.3819571177864E-5,0.000631615540502576,9.15742854232762E-8,0.000631615434400111,7.47307929453584E-8,3.66103701328648E-7,5.29259703410492E-8,1.00015083779259,10.005763053894,2,20,10,5,2.06634782084498,0.18293307215139,0.0410455763339996,172.855895996094,47.999626159668,48.0003852844238,160.224365234375,160.224365234375,,,711.867919921875,0,1,,,,,,1,1,1,47.9998588562012,0,48.0000525081859,,,,,,,,,,,,,,,,,,,,,,,,,,,,,,,,,
,3768473383.47431,47.9999408721924,160.224365234375,,,5,,,,25.0300001353025,,,,,0.000631977525419792,8.54452901837789E-8,0.026699094175747,7.34224437454989E-5,0.000631882218279347,8.54324043675207E-8,0.000631882149674639,7.17480204375429E-8,2.94448952202613E-7,4.63779826998706E-8,1.00015083054672,10.005763053894,2,20,10,5,2.06724103418544,0.182775381039645,0.0410455763339996,172.855895996094,47.9994087219238,48.0001411437988,160.224365234375,160.224365234375,,,736.169982910156,0,1,,,,,,1,1,1,47.9997406005859,0,47.9997998405905,,,,,,,,,,,,,,,,,,,,,,,,,,,,,,,,,
,3768473588.59912,48.0001430511475,160.224365234375,,,5,,,,25.0300001353025,,,,,0.00063274301194023,8.68229622969754E-8,0.0258177573020637,0.000109411496527212,0.00063264758350496,8.68098679138196E-8,0.000632647519277076,5.23946554401055E-8,2.85074072728144E-7,6.92152674525457E-8,1.00015083980048,10.005763053894,2,20,10,5,2.06974780690668,0.182964930133693,0.0410455763339996,172.855895996094,47.9995918273926,48.0004386901855,160.224365234375,160.224365234375,,,750.858215332031,0,1,,,,,,1,1,1,48.0000762939453,0,48.0000660419464,,,,,,,,,,,,,,,,,,,,,,,,,,,,,,,,,
,3768473794.18046,48.000093460083,160.224365234375,,,5,,,,25.0300001353025,,,,,0.000633371986895726,9.65005014904234E-8,0.0272911161428544,7.95212914285068E-5,0.000633276465037496,9.64859477883128E-8,0.000633276393198431,8.23136910937241E-8,3.01642128813443E-7,5.03387959643056E-8,1.00015083753069,10.005763053894,2,20,10,5,2.07180051889892,0.183200081082105,0.0410455763339996,172.855895996094,47.9997444152832,48.0002479553223,160.224365234375,160.224365234375,,,756.218566894531,0,1,,,,,,1,1,1,48.0002593994141,0,47.9999869851505,,,,,,,,,,,,,,,,,,,,,,,,,,,,,,,,,
,3768473999.55024,48.0003452301025,160.224365234375,,,5,,,,25.0300001353025,,,,,0.000633910714830817,8.1874669722044E-8,0.0291669982260734,7.17873925843879E-5,0.000633815177129423,8.18623302591439E-8,0.000633815095005283,6.80630050759069E-8,3.2265003645396E-7,4.54848156585713E-8,1.00015073432262,10.005763053894,2,20,10,5,2.07355672829144,0.183423795915441,0.0410455763339996,172.855895996094,47.9994659423828,48.0013961791992,160.224365234375,160.224365234375,,,757.623962402344,0,1,,,,,,1,1,1,47.9999809265137,0,48.0000491422765,,,,,,,,,,,,,,,,,,,,,,,,,,,,,,,,,
,3768474207.15163,47.9992847442627,160.224365234375,,,5,,,,25.0300001353025,,,,,0.000634527036029941,1.15378325382287E-7,0.0283894138445477,6.88577114095764E-5,0.000634431363453193,1.15360928894725E-7,0.000634431285573859,1.06786603495139E-7,3.14353586758306E-7,4.36436161359901E-8,1.00015080051564,10.005763053894,2,20,10,5,2.0755752399558,0.1835739654537,0.0410455763339996,172.855895996094,47.9983787536621,47.9999580383301,160.224365234375,160.224365234375,,,758.009521484375,0,1,,,,,,1,1,1,47.9990463256836,0,47.9993903216194,,,,,,,,,,,,,,,,,,,,,,,,,,,,,,,,,
,3768474416.48401,48.0002422332764,160.224365234375,,,5,,,,25.0300001353025,,,,,0.000635127436914225,1.15324528515735E-7,0.0252280179871294,9.22796087753013E-5,0.000635031718831896,1.15307148314418E-7,0.000635031657273625,9.93209745718451E-8,2.7961206294028E-7,5.85754424866104E-8,1.00015072960844,10.005763053894,2,20,10,5,2.0775493224854,0.183633028739124,0.0410455763339996,172.855895996094,47.9996109008789,48.0006294250488,160.224365234375,160.224365234375,,,758.071716308594,0,1,,,,,,1,1,1,48.0004119873047,0,48.0000679913689,,,,,,,,,,,,,,,,,,,,,,,,,,,,,,,,,
,3768474624.35008,48.0005664825439,160.224365234375,,,5,,,,25.0300001353025,,,,,0.000635442978627918,9.50228609786796E-8,0.0277463550085244,9.59054447556865E-5,0.00063534720356355,9.50085389687861E-8,0.000635347129065015,7.29054684618759E-8,3.07676560551924E-7,6.09213849591239E-8,1.00015074444938,10.005763053894,2,20,10,5,2.07857340579173,0.183815620206637,0.0410455763339996,172.855895996094,47.9996528625488,48.0005989074707,160.224365234375,160.224365234375,,,758.059265136719,0,1,,,,,,1,1,1,48.0005874633789,0,48.0001106262207,,,,,,,,,,,,,,,,,,,,,,,,,,,,,,,,,
,3768474832.25953,48.0009441375732,160.224365234375,,,5,,,,25.0300001353025,,,,,0.000635962337538855,1.03250158524238E-7,0.0315933857078878,9.0855786916058E-5,0.000635866473206311,1.03234594697659E-7,0.000635866376538253,8.55684680317844E-8,3.50622225570918E-7,5.77530849486282E-8,1.00015076173471,10.005763053894,2,20,10,5,2.08025990430111,0.184105531327833,0.0410455763339996,172.855895996094,47.9996757507324,48.001335144043,160.224365234375,160.224365234375,,,758.071716308594,0,1,,,,,,1,1,1,48.0007629394531,0,48.0003018098719,,,,,,,,,,,,,,,,,,,,,,,,,,,,,,,,,
,3768475038.56075,47.9998931884766,160.224365234375,,,5,,,,25.0300001353025,,,,,0.000636496062276128,1.14014505289249E-7,0.0291834894036107,0.00013901649273893,0.000636400075093807,1.13997311261265E-7,0.000636399992541467,7.1898906194039E-8,3.24149076995478E-7,8.84643106732798E-8,1.00015082836423,10.005763053894,2,20,10,5,2.08201348855737,0.184172473239911,0.0410455763339996,172.855895996094,47.9991722106934,48.0004272460937,160.224365234375,160.224365234375,,,758.071716308594,0,1,,,,,,1,1,1,47.9998016357422,0,47.9996589211857,,,,,,,,,,,,,,,,,,,,,,,,,,,,,,,,,
,3768475245.69485,48.0000534057617,160.224365234375,,,5,,,,25.0300001353025,,,,,0.000636858316975141,9.36025771401491E-8,0.0289110629501188,9.44252801217387E-5,0.000636762270493995,9.35884606594172E-8,0.000636762189429596,7.17287556240353E-8,3.21305922735369E-7,6.01147701087404E-8,1.0001508356974,10.005763053894,2,20,10,5,2.08319931977934,0.184267386911021,0.0410455763339996,172.855895996094,47.999195098877,48.0001983642578,160.224365234375,160.224365234375,,,758.071716308594,0,1,,,,,,1,1,1,48.0000457763672,0,47.9996793410357,,,,,,,,,,,,,,,,,,,,,,,,,,,,,,,,,
,3768475450.06072,48.0000991821289,160.224365234375,,,5,,,,25.0300001353025,,,,,0.000637406569542781,1.37478565579593E-7,0.0211465290592416,0.000121748588901406,0.000637310439042962,1.37457831743679E-7,0.000637310395636544,1.13480399109579E-7,2.35216337530373E-7,7.75683861222099E-8,1.00015083779259,10.005763053894,2,20,10,5,2.08501765840993,0.184143463892752,0.0410455763339996,172.855895996094,47.9997329711914,48.000545501709,160.224365234375,160.224365234375,,,758.046813964844,0,1,,,,,,1,1,1,48.0001449584961,0,48.0001018748564,,,,,,,,,,,,,,,,,,,,,,,,,,,,,,,,,
,3768475656.71924,48.0001277923584,160.224365234375,,,5,,,,25.0300001353025,,,,,0.000638022609707571,9.69286151599752E-8,0.0239832330294583,0.000109081602259031,0.000637926385464393,9.69139967397277E-8,0.000637926329577399,6.74625763572215E-8,2.6702728964453E-7,6.95781830411948E-8,1.00015083910208,10.005763053894,2,20,10,5,2.08702365625563,0.184424762957983,0.0410455763339996,172.855895996094,47.9994621276855,48.0004730224609,160.224365234375,160.224365234375,,,758.02197265625,0,1,,,,,,1,1,1,48.0001831054687,0,48.0000502642463,,,,,,,,,,,,,,,,,,,,,,,,,,,,,,,,,
,3768475864.61544,48.0008296966553,160.224365234375,,,5,,,,25.0300001353025,,,,,0.000638491133526854,1.07625083550034E-7,0.0283455226469069,0.000132668571459788,0.000638394891349503,1.07608860815161E-7,0.000638394813225755,6.63872642770071E-8,3.15828430401797E-7,8.46900116173771E-8,1.00015075649673,10.005763053894,2,20,10,5,2.08854217817486,0.184719203759753,0.0410455763339996,172.855895996094,47.999439239502,48.0011177062988,160.224365234375,160.224365234375,,,757.9970703125,0,1,,,,,,1,1,1,48.0010757446289,0,48.0001810859231,,,,,,,,,,,,,,,,,,,,,,,,,,,,,,,,,
,3768476019.44365,47.9991989135742,160.224365234375,,,5,,,,25.0300001353025,,,,,0.000638789735089432,1.07595533771448E-7,0.0275232232127678,0.000149345036391282,0.000638693422301109,1.07579311178474E-7,0.000638693348609887,4.97484413141593E-8,3.06809700467255E-7,9.5385537585352E-8,1.00015079658716,10.005763053894,2,20,10,5,2.08952157291602,0.18477560996756,0.0410455763339996,172.855895996094,47.9982719421387,48.0000114440918,160.224365234375,160.224365234375,,,757.9970703125,0,1,,,,,,1,1,1,47.9992370605469,0,47.9994678497314,,,,,,,,,,,,,,,,,,,,,,,,,,,,,,,,,